/*       */package com.parzivail.pswm.world.gen;

/*       */
/*       *//*       */
import java.util.Random;



/*       */
import net.minecraft.block.Block;
/*       */
import net.minecraft.init.Blocks;
/*       */
import net.minecraft.tileentity.TileEntityChest;
/*       */
import net.minecraft.world.World;
/*       */
import net.minecraft.world.chunk.IChunkProvider;
/*       */
import net.minecraft.world.gen.feature.WorldGenerator;



import com.parzivail.pswm.utils.LootGenUtils;


/*       */
import cpw.mods.fml.common.IWorldGenerator;
/*       */

/*       */
/*       */
/*       */
/*       */
/*       */
/*       */
/*       */
/*       */
/*       */
/*       */
/*       */public class WorldGenYavinTempleRuins
/*       */extends WorldGenerator
/*       */implements IWorldGenerator
/*       */
{
	/*       */public void generate(Random random, int chunkX, int chunkZ, World world, IChunkProvider chunkGenerator, IChunkProvider chunkProvider)
	{
	}

	/*       */
	/*       */public boolean generate(World world, Random rand, int i, int j, int k)
	/*       */
	{
		k -= 10;
		i -= 10;
		/*       */
		setBlock(world, i + 0, j + 0, k + 20, Blocks.stonebrick, 0);
		setBlock(world, i + 0, j + 0, k + 21, Blocks.stonebrick, 0);
		setBlock(world, i + 0, j + 0, k + 26, Blocks.stonebrick, 0);
		setBlock(world, i + 0, j + 0, k + 27, Blocks.stonebrick, 0);
		setBlock(world, i + 1, j + 0, k + 20, Blocks.stonebrick, 0);
		setBlock(world, i + 1, j + 0, k + 21, Blocks.stonebrick, 0);
		setBlock(world, i + 1, j + 0, k + 22, Blocks.stone_brick_stairs, 0);
		setBlock(world, i + 1, j + 0, k + 23, Blocks.stone_brick_stairs, 0);
		setBlock(world, i + 1, j + 0, k + 24, Blocks.stone_brick_stairs, 0);
		setBlock(world, i + 1, j + 0, k + 25, Blocks.stone_brick_stairs, 0);
		setBlock(world, i + 1, j + 0, k + 26, Blocks.stonebrick, 0);
		setBlock(world, i + 1, j + 0, k + 27, Blocks.stonebrick, 0);
		setBlock(world, i + 1, j + 1, k + 20, Blocks.stonebrick, 0);
		setBlock(world, i + 1, j + 1, k + 21, Blocks.stonebrick, 0);
		setBlock(world, i + 1, j + 1, k + 26, Blocks.stonebrick, 0);
		setBlock(world, i + 1, j + 1, k + 27, Blocks.stonebrick, 0);
		setBlock(world, i + 2, j + 0, k + 20, Blocks.stonebrick, 0);
		setBlock(world, i + 2, j + 0, k + 21, Blocks.stonebrick, 0);
		setBlock(world, i + 2, j + 0, k + 26, Blocks.stonebrick, 0);
		setBlock(world, i + 2, j + 0, k + 27, Blocks.stonebrick, 0);
		setBlock(world, i + 2, j + 1, k + 20, Blocks.stonebrick, 0);
		setBlock(world, i + 2, j + 1, k + 21, Blocks.stonebrick, 0);
		setBlock(world, i + 2, j + 1, k + 22, Blocks.stone_brick_stairs, 0);
		setBlock(world, i + 2, j + 1, k + 23, Blocks.stone_brick_stairs, 0);
		setBlock(world, i + 2, j + 1, k + 24, Blocks.stone_brick_stairs, 0);
		setBlock(world, i + 2, j + 1, k + 25, Blocks.stone_brick_stairs, 0);
		setBlock(world, i + 2, j + 1, k + 26, Blocks.stonebrick, 0);
		setBlock(world, i + 2, j + 1, k + 27, Blocks.stonebrick, 0);
		setBlock(world, i + 2, j + 2, k + 20, Blocks.stonebrick, 0);
		setBlock(world, i + 2, j + 2, k + 21, Blocks.stonebrick, 0);
		setBlock(world, i + 2, j + 2, k + 26, Blocks.stonebrick, 0);
		setBlock(world, i + 2, j + 2, k + 27, Blocks.stonebrick, 0);
		setBlock(world, i + 3, j + 0, k + 20, Blocks.stonebrick, 0);
		setBlock(world, i + 3, j + 0, k + 21, Blocks.stonebrick, 0);
		setBlock(world, i + 3, j + 0, k + 26, Blocks.stonebrick, 0);
		setBlock(world, i + 3, j + 0, k + 27, Blocks.stonebrick, 0);
		setBlock(world, i + 3, j + 1, k + 20, Blocks.stonebrick, 0);
		setBlock(world, i + 3, j + 1, k + 21, Blocks.stonebrick, 0);
		setBlock(world, i + 3, j + 1, k + 22, Blocks.stonebrick, 0);
		setBlock(world, i + 3, j + 1, k + 23, Blocks.stonebrick, 0);
		setBlock(world, i + 3, j + 1, k + 24, Blocks.stonebrick, 0);
		setBlock(world, i + 3, j + 1, k + 25, Blocks.stonebrick, 0);
		setBlock(world, i + 3, j + 1, k + 26, Blocks.stonebrick, 0);
		setBlock(world, i + 3, j + 1, k + 27, Blocks.stonebrick, 0);
		setBlock(world, i + 3, j + 2, k + 20, Blocks.stonebrick, 0);
		setBlock(world, i + 3, j + 2, k + 21, Blocks.stonebrick, 0);
		setBlock(world, i + 3, j + 2, k + 22, Blocks.stone_brick_stairs, 0);
		setBlock(world, i + 3, j + 2, k + 23, Blocks.stone_brick_stairs, 0);
		setBlock(world, i + 3, j + 2, k + 24, Blocks.stone_brick_stairs, 0);
		setBlock(world, i + 3, j + 2, k + 25, Blocks.stone_brick_stairs, 0);
		setBlock(world, i + 3, j + 2, k + 26, Blocks.stonebrick, 0);
		setBlock(world, i + 3, j + 2, k + 27, Blocks.stonebrick, 0);
		setBlock(world, i + 3, j + 3, k + 20, Blocks.stonebrick, 0);
		setBlock(world, i + 3, j + 3, k + 21, Blocks.stonebrick, 0);
		setBlock(world, i + 3, j + 3, k + 26, Blocks.stonebrick, 0);
		setBlock(world, i + 3, j + 3, k + 27, Blocks.stonebrick, 0);
		setBlock(world, i + 4, j + 0, k + 20, Blocks.stonebrick, 0);
		setBlock(world, i + 4, j + 0, k + 21, Blocks.stonebrick, 0);
		setBlock(world, i + 4, j + 0, k + 26, Blocks.stonebrick, 0);
		setBlock(world, i + 4, j + 0, k + 27, Blocks.stonebrick, 0);
		setBlock(world, i + 4, j + 1, k + 20, Blocks.stonebrick, 0);
		setBlock(world, i + 4, j + 1, k + 21, Blocks.stonebrick, 0);
		setBlock(world, i + 4, j + 1, k + 26, Blocks.stonebrick, 0);
		setBlock(world, i + 4, j + 1, k + 27, Blocks.stonebrick, 0);
		setBlock(world, i + 4, j + 2, k + 20, Blocks.stonebrick, 0);
		setBlock(world, i + 4, j + 2, k + 21, Blocks.stonebrick, 0);
		setBlock(world, i + 4, j + 2, k + 22, Blocks.stonebrick, 0);
		setBlock(world, i + 4, j + 2, k + 23, Blocks.stonebrick, 0);
		setBlock(world, i + 4, j + 2, k + 24, Blocks.stonebrick, 0);
		setBlock(world, i + 4, j + 2, k + 25, Blocks.stonebrick, 0);
		setBlock(world, i + 4, j + 2, k + 26, Blocks.stonebrick, 0);
		setBlock(world, i + 4, j + 2, k + 27, Blocks.stonebrick, 0);
		setBlock(world, i + 4, j + 3, k + 20, Blocks.stonebrick, 0);
		setBlock(world, i + 4, j + 3, k + 21, Blocks.stonebrick, 0);
		setBlock(world, i + 4, j + 3, k + 22, Blocks.stone_brick_stairs, 0);
		setBlock(world, i + 4, j + 3, k + 23, Blocks.stone_brick_stairs, 0);
		setBlock(world, i + 4, j + 3, k + 24, Blocks.stone_brick_stairs, 0);
		setBlock(world, i + 4, j + 3, k + 25, Blocks.stone_brick_stairs, 0);
		setBlock(world, i + 4, j + 3, k + 26, Blocks.stonebrick, 0);
		setBlock(world, i + 4, j + 3, k + 27, Blocks.stonebrick, 0);
		setBlock(world, i + 4, j + 4, k + 20, Blocks.stonebrick, 0);
		setBlock(world, i + 4, j + 4, k + 21, Blocks.stonebrick, 0);
		setBlock(world, i + 4, j + 4, k + 26, Blocks.stonebrick, 0);
		setBlock(world, i + 4, j + 4, k + 27, Blocks.stonebrick, 0);
		setBlock(world, i + 5, j + 0, k + 20, Blocks.stonebrick, 0);
		setBlock(world, i + 5, j + 0, k + 21, Blocks.stonebrick, 0);
		setBlock(world, i + 5, j + 0, k + 26, Blocks.stonebrick, 0);
		setBlock(world, i + 5, j + 0, k + 27, Blocks.stonebrick, 0);
		setBlock(world, i + 5, j + 1, k + 20, Blocks.stonebrick, 0);
		setBlock(world, i + 5, j + 1, k + 21, Blocks.stonebrick, 0);
		setBlock(world, i + 5, j + 1, k + 26, Blocks.stonebrick, 0);
		setBlock(world, i + 5, j + 1, k + 27, Blocks.stonebrick, 0);
		setBlock(world, i + 5, j + 2, k + 20, Blocks.stonebrick, 0);
		setBlock(world, i + 5, j + 2, k + 21, Blocks.stonebrick, 0);
		setBlock(world, i + 5, j + 2, k + 26, Blocks.stonebrick, 0);
		setBlock(world, i + 5, j + 2, k + 27, Blocks.stonebrick, 0);
		setBlock(world, i + 5, j + 3, k + 20, Blocks.stonebrick, 0);
		setBlock(world, i + 5, j + 3, k + 21, Blocks.stonebrick, 0);
		setBlock(world, i + 5, j + 3, k + 22, Blocks.stonebrick, 0);
		setBlock(world, i + 5, j + 3, k + 23, Blocks.stonebrick, 0);
		setBlock(world, i + 5, j + 3, k + 24, Blocks.stonebrick, 0);
		setBlock(world, i + 5, j + 3, k + 25, Blocks.stonebrick, 0);
		setBlock(world, i + 5, j + 3, k + 26, Blocks.stonebrick, 0);
		setBlock(world, i + 5, j + 3, k + 27, Blocks.stonebrick, 0);
		setBlock(world, i + 5, j + 4, k + 20, Blocks.stonebrick, 0);
		setBlock(world, i + 5, j + 4, k + 21, Blocks.stonebrick, 0);
		setBlock(world, i + 5, j + 4, k + 22, Blocks.stone_brick_stairs, 0);
		setBlock(world, i + 5, j + 4, k + 23, Blocks.stone_brick_stairs, 0);
		setBlock(world, i + 5, j + 4, k + 24, Blocks.stone_brick_stairs, 0);
		setBlock(world, i + 5, j + 4, k + 25, Blocks.stone_brick_stairs, 0);
		setBlock(world, i + 5, j + 4, k + 26, Blocks.stonebrick, 0);
		setBlock(world, i + 5, j + 4, k + 27, Blocks.stonebrick, 0);
		setBlock(world, i + 5, j + 5, k + 20, Blocks.stonebrick, 0);
		setBlock(world, i + 5, j + 5, k + 21, Blocks.stonebrick, 0);
		setBlock(world, i + 5, j + 5, k + 26, Blocks.stonebrick, 0);
		setBlock(world, i + 5, j + 5, k + 27, Blocks.stonebrick, 0);
		setBlock(world, i + 6, j + 0, k + 20, Blocks.stonebrick, 0);
		setBlock(world, i + 6, j + 0, k + 21, Blocks.stonebrick, 0);
		setBlock(world, i + 6, j + 0, k + 26, Blocks.stonebrick, 0);
		setBlock(world, i + 6, j + 0, k + 27, Blocks.stonebrick, 0);
		setBlock(world, i + 6, j + 1, k + 20, Blocks.stonebrick, 0);
		setBlock(world, i + 6, j + 1, k + 21, Blocks.stonebrick, 0);
		setBlock(world, i + 6, j + 1, k + 26, Blocks.stonebrick, 0);
		setBlock(world, i + 6, j + 1, k + 27, Blocks.stonebrick, 0);
		setBlock(world, i + 6, j + 2, k + 20, Blocks.stonebrick, 0);
		setBlock(world, i + 6, j + 2, k + 21, Blocks.stonebrick, 0);
		setBlock(world, i + 6, j + 2, k + 26, Blocks.stonebrick, 0);
		setBlock(world, i + 6, j + 2, k + 27, Blocks.stonebrick, 0);
		setBlock(world, i + 6, j + 3, k + 20, Blocks.stonebrick, 0);
		setBlock(world, i + 6, j + 3, k + 21, Blocks.stonebrick, 0);
		setBlock(world, i + 6, j + 3, k + 26, Blocks.stonebrick, 0);
		setBlock(world, i + 6, j + 3, k + 27, Blocks.stonebrick, 0);
		setBlock(world, i + 6, j + 4, k + 20, Blocks.stonebrick, 0);
		setBlock(world, i + 6, j + 4, k + 21, Blocks.stonebrick, 0);
		setBlock(world, i + 6, j + 4, k + 22, Blocks.stonebrick, 0);
		setBlock(world, i + 6, j + 4, k + 23, Blocks.stonebrick, 0);
		setBlock(world, i + 6, j + 4, k + 24, Blocks.stonebrick, 0);
		setBlock(world, i + 6, j + 4, k + 25, Blocks.stonebrick, 0);
		setBlock(world, i + 6, j + 4, k + 26, Blocks.stonebrick, 0);
		setBlock(world, i + 6, j + 4, k + 27, Blocks.stonebrick, 0);
		setBlock(world, i + 6, j + 5, k + 20, Blocks.stonebrick, 0);
		setBlock(world, i + 6, j + 5, k + 21, Blocks.stonebrick, 0);
		setBlock(world, i + 6, j + 5, k + 22, Blocks.stone_brick_stairs, 0);
		setBlock(world, i + 6, j + 5, k + 23, Blocks.stone_brick_stairs, 0);
		setBlock(world, i + 6, j + 5, k + 24, Blocks.stone_brick_stairs, 0);
		setBlock(world, i + 6, j + 5, k + 25, Blocks.stone_brick_stairs, 0);
		setBlock(world, i + 6, j + 5, k + 26, Blocks.stonebrick, 0);
		setBlock(world, i + 6, j + 5, k + 27, Blocks.stonebrick, 0);
		setBlock(world, i + 6, j + 6, k + 20, Blocks.stonebrick, 0);
		setBlock(world, i + 6, j + 6, k + 21, Blocks.stonebrick, 0);
		setBlock(world, i + 6, j + 6, k + 26, Blocks.stonebrick, 0);
		setBlock(world, i + 6, j + 6, k + 27, Blocks.stonebrick, 0);
		setBlock(world, i + 7, j + 0, k + 20, Blocks.stonebrick, 0);
		setBlock(world, i + 7, j + 0, k + 21, Blocks.stonebrick, 0);
		setBlock(world, i + 7, j + 0, k + 26, Blocks.stonebrick, 0);
		setBlock(world, i + 7, j + 0, k + 27, Blocks.stonebrick, 0);
		setBlock(world, i + 7, j + 1, k + 20, Blocks.stonebrick, 0);
		setBlock(world, i + 7, j + 1, k + 21, Blocks.stonebrick, 0);
		setBlock(world, i + 7, j + 1, k + 26, Blocks.stonebrick, 0);
		setBlock(world, i + 7, j + 1, k + 27, Blocks.stonebrick, 0);
		setBlock(world, i + 7, j + 2, k + 20, Blocks.stonebrick, 0);
		setBlock(world, i + 7, j + 2, k + 21, Blocks.stonebrick, 0);
		setBlock(world, i + 7, j + 2, k + 26, Blocks.stonebrick, 0);
		setBlock(world, i + 7, j + 2, k + 27, Blocks.stonebrick, 0);
		setBlock(world, i + 7, j + 3, k + 20, Blocks.stonebrick, 0);
		setBlock(world, i + 7, j + 3, k + 21, Blocks.stonebrick, 0);
		setBlock(world, i + 7, j + 3, k + 26, Blocks.stonebrick, 0);
		setBlock(world, i + 7, j + 3, k + 27, Blocks.stonebrick, 0);
		setBlock(world, i + 7, j + 4, k + 20, Blocks.stonebrick, 0);
		setBlock(world, i + 7, j + 4, k + 21, Blocks.stonebrick, 0);
		setBlock(world, i + 7, j + 4, k + 26, Blocks.stonebrick, 0);
		setBlock(world, i + 7, j + 4, k + 27, Blocks.stonebrick, 0);
		setBlock(world, i + 7, j + 5, k + 20, Blocks.stonebrick, 0);
		setBlock(world, i + 7, j + 5, k + 21, Blocks.stonebrick, 0);
		setBlock(world, i + 7, j + 5, k + 22, Blocks.stonebrick, 0);
		setBlock(world, i + 7, j + 5, k + 23, Blocks.stonebrick, 0);
		setBlock(world, i + 7, j + 5, k + 24, Blocks.stonebrick, 0);
		setBlock(world, i + 7, j + 5, k + 25, Blocks.stonebrick, 0);
		setBlock(world, i + 7, j + 5, k + 26, Blocks.stonebrick, 0);
		setBlock(world, i + 7, j + 5, k + 27, Blocks.stonebrick, 0);
		setBlock(world, i + 7, j + 6, k + 20, Blocks.stonebrick, 0);
		setBlock(world, i + 7, j + 6, k + 21, Blocks.stonebrick, 0);
		setBlock(world, i + 7, j + 6, k + 22, Blocks.stone_brick_stairs, 0);
		setBlock(world, i + 7, j + 6, k + 23, Blocks.stone_brick_stairs, 0);
		setBlock(world, i + 7, j + 6, k + 24, Blocks.stone_brick_stairs, 0);
		setBlock(world, i + 7, j + 6, k + 25, Blocks.stone_brick_stairs, 0);
		setBlock(world, i + 7, j + 6, k + 26, Blocks.stonebrick, 0);
		setBlock(world, i + 7, j + 6, k + 27, Blocks.stonebrick, 0);
		setBlock(world, i + 7, j + 7, k + 20, Blocks.stonebrick, 0);
		setBlock(world, i + 7, j + 7, k + 21, Blocks.stonebrick, 0);
		setBlock(world, i + 7, j + 7, k + 26, Blocks.stonebrick, 0);
		setBlock(world, i + 7, j + 7, k + 27, Blocks.stonebrick, 0);
		setBlock(world, i + 8, j + 0, k + 8, Blocks.stone_brick_stairs, 0);
		setBlock(world, i + 8, j + 0, k + 9, Blocks.stone_brick_stairs, 0);
		setBlock(world, i + 8, j + 0, k + 10, Blocks.stone_brick_stairs, 0);
		setBlock(world, i + 8, j + 0, k + 11, Blocks.stone_brick_stairs, 0);
		setBlock(world, i + 8, j + 0, k + 12, Blocks.stone_brick_stairs, 0);
		setBlock(world, i + 8, j + 0, k + 13, Blocks.stone_brick_stairs, 0);
		setBlock(world, i + 8, j + 0, k + 14, Blocks.stone_brick_stairs, 0);
		setBlock(world, i + 8, j + 0, k + 15, Blocks.stone_brick_stairs, 0);
		setBlock(world, i + 8, j + 0, k + 16, Blocks.stone_brick_stairs, 0);
		setBlock(world, i + 8, j + 0, k + 17, Blocks.stone_brick_stairs, 0);
		setBlock(world, i + 8, j + 0, k + 18, Blocks.stone_brick_stairs, 0);
		setBlock(world, i + 8, j + 0, k + 19, Blocks.stone_brick_stairs, 0);
		setBlock(world, i + 8, j + 0, k + 20, Blocks.stonebrick, 0);
		setBlock(world, i + 8, j + 0, k + 21, Blocks.stonebrick, 0);
		setBlock(world, i + 8, j + 0, k + 26, Blocks.stonebrick, 0);
		setBlock(world, i + 8, j + 0, k + 27, Blocks.stonebrick, 0);
		setBlock(world, i + 8, j + 0, k + 28, Blocks.stone_brick_stairs, 0);
		setBlock(world, i + 8, j + 0, k + 29, Blocks.stone_brick_stairs, 0);
		setBlock(world, i + 8, j + 0, k + 30, Blocks.stone_brick_stairs, 0);
		setBlock(world, i + 8, j + 0, k + 31, Blocks.stone_brick_stairs, 0);
		setBlock(world, i + 8, j + 0, k + 32, Blocks.stone_brick_stairs, 0);
		setBlock(world, i + 8, j + 0, k + 33, Blocks.stone_brick_stairs, 0);
		setBlock(world, i + 8, j + 0, k + 34, Blocks.stone_brick_stairs, 0);
		setBlock(world, i + 8, j + 0, k + 35, Blocks.stone_brick_stairs, 0);
		setBlock(world, i + 8, j + 0, k + 36, Blocks.stone_brick_stairs, 0);
		setBlock(world, i + 8, j + 0, k + 37, Blocks.stone_brick_stairs, 0);
		setBlock(world, i + 8, j + 0, k + 38, Blocks.stone_brick_stairs, 0);
		setBlock(world, i + 8, j + 1, k + 20, Blocks.stonebrick, 0);
		setBlock(world, i + 8, j + 1, k + 21, Blocks.stonebrick, 0);
		setBlock(world, i + 8, j + 1, k + 26, Blocks.stonebrick, 0);
		setBlock(world, i + 8, j + 1, k + 27, Blocks.stonebrick, 0);
		setBlock(world, i + 8, j + 2, k + 20, Blocks.stonebrick, 0);
		setBlock(world, i + 8, j + 2, k + 21, Blocks.stonebrick, 0);
		setBlock(world, i + 8, j + 2, k + 26, Blocks.stonebrick, 0);
		setBlock(world, i + 8, j + 2, k + 27, Blocks.stonebrick, 0);
		setBlock(world, i + 8, j + 3, k + 20, Blocks.stonebrick, 0);
		setBlock(world, i + 8, j + 3, k + 21, Blocks.stonebrick, 0);
		setBlock(world, i + 8, j + 3, k + 26, Blocks.stonebrick, 0);
		setBlock(world, i + 8, j + 3, k + 27, Blocks.stonebrick, 0);
		setBlock(world, i + 8, j + 4, k + 20, Blocks.stonebrick, 0);
		setBlock(world, i + 8, j + 4, k + 21, Blocks.stonebrick, 0);
		setBlock(world, i + 8, j + 4, k + 26, Blocks.stonebrick, 0);
		setBlock(world, i + 8, j + 4, k + 27, Blocks.stonebrick, 0);
		setBlock(world, i + 8, j + 5, k + 20, Blocks.stonebrick, 0);
		setBlock(world, i + 8, j + 5, k + 21, Blocks.stonebrick, 0);
		setBlock(world, i + 8, j + 5, k + 26, Blocks.stonebrick, 0);
		setBlock(world, i + 8, j + 5, k + 27, Blocks.stonebrick, 0);
		setBlock(world, i + 8, j + 6, k + 20, Blocks.stonebrick, 0);
		setBlock(world, i + 8, j + 6, k + 21, Blocks.stonebrick, 0);
		setBlock(world, i + 8, j + 6, k + 22, Blocks.stonebrick, 0);
		setBlock(world, i + 8, j + 6, k + 23, Blocks.stonebrick, 0);
		setBlock(world, i + 8, j + 6, k + 24, Blocks.stonebrick, 0);
		setBlock(world, i + 8, j + 6, k + 25, Blocks.stonebrick, 0);
		setBlock(world, i + 8, j + 6, k + 26, Blocks.stonebrick, 0);
		setBlock(world, i + 8, j + 6, k + 27, Blocks.stonebrick, 0);
		setBlock(world, i + 8, j + 7, k + 20, Blocks.stonebrick, 0);
		setBlock(world, i + 8, j + 7, k + 21, Blocks.stonebrick, 0);
		setBlock(world, i + 8, j + 7, k + 22, Blocks.stone_brick_stairs, 0);
		setBlock(world, i + 8, j + 7, k + 23, Blocks.stone_brick_stairs, 0);
		setBlock(world, i + 8, j + 7, k + 24, Blocks.stone_brick_stairs, 0);
		setBlock(world, i + 8, j + 7, k + 25, Blocks.stone_brick_stairs, 0);
		setBlock(world, i + 8, j + 7, k + 26, Blocks.stonebrick, 0);
		setBlock(world, i + 8, j + 7, k + 27, Blocks.stonebrick, 0);
		setBlock(world, i + 8, j + 8, k + 20, Blocks.stonebrick, 0);
		setBlock(world, i + 8, j + 8, k + 21, Blocks.stonebrick, 0);
		setBlock(world, i + 8, j + 8, k + 26, Blocks.stonebrick, 0);
		setBlock(world, i + 8, j + 8, k + 27, Blocks.stonebrick, 0);
		setBlock(world, i + 9, j + 0, k + 26, Blocks.stonebrick, 0);
		setBlock(world, i + 9, j + 1, k + 26, Blocks.stonebrick, 0);
		setBlock(world, i + 9, j + 1, k + 28, Blocks.stonebrick, 0);
		setBlock(world, i + 9, j + 1, k + 30, Blocks.stonebrick, 0);
		setBlock(world, i + 9, j + 2, k + 10, Blocks.stone_brick_stairs, 0);
		setBlock(world, i + 9, j + 2, k + 11, Blocks.stone_brick_stairs, 0);
		setBlock(world, i + 9, j + 2, k + 12, Blocks.stone_brick_stairs, 0);
		setBlock(world, i + 9, j + 2, k + 13, Blocks.stone_brick_stairs, 0);
		setBlock(world, i + 9, j + 2, k + 14, Blocks.stone_brick_stairs, 0);
		setBlock(world, i + 9, j + 2, k + 15, Blocks.stone_brick_stairs, 0);
		setBlock(world, i + 9, j + 2, k + 16, Blocks.stone_brick_stairs, 0);
		setBlock(world, i + 9, j + 2, k + 17, Blocks.stone_brick_stairs, 0);
		setBlock(world, i + 9, j + 2, k + 18, Blocks.stone_brick_stairs, 0);
		setBlock(world, i + 9, j + 2, k + 19, Blocks.stone_brick_stairs, 0);
		setBlock(world, i + 9, j + 2, k + 20, Blocks.stonebrick, 0);
		setBlock(world, i + 9, j + 2, k + 21, Blocks.stonebrick, 0);
		setBlock(world, i + 9, j + 2, k + 26, Blocks.stonebrick, 0);
		setBlock(world, i + 9, j + 2, k + 27, Blocks.stonebrick, 0);
		setBlock(world, i + 9, j + 2, k + 28, Blocks.stone_brick_stairs, 0);
		setBlock(world, i + 9, j + 2, k + 29, Blocks.stone_brick_stairs, 0);
		setBlock(world, i + 9, j + 2, k + 30, Blocks.stone_brick_stairs, 0);
		setBlock(world, i + 9, j + 2, k + 31, Blocks.stone_brick_stairs, 0);
		setBlock(world, i + 9, j + 2, k + 32, Blocks.stone_brick_stairs, 0);
		setBlock(world, i + 9, j + 2, k + 33, Blocks.stone_brick_stairs, 0);
		setBlock(world, i + 9, j + 2, k + 34, Blocks.stone_brick_stairs, 0);
		setBlock(world, i + 9, j + 2, k + 35, Blocks.stone_brick_stairs, 0);
		setBlock(world, i + 9, j + 2, k + 36, Blocks.stone_brick_stairs, 0);
		setBlock(world, i + 9, j + 2, k + 37, Blocks.stone_brick_stairs, 0);
		setBlock(world, i + 9, j + 3, k + 20, Blocks.stonebrick, 0);
		setBlock(world, i + 9, j + 3, k + 21, Blocks.stonebrick, 0);
		setBlock(world, i + 9, j + 3, k + 26, Blocks.stonebrick, 0);
		setBlock(world, i + 9, j + 3, k + 27, Blocks.stonebrick, 0);
		setBlock(world, i + 9, j + 4, k + 20, Blocks.stonebrick, 0);
		setBlock(world, i + 9, j + 4, k + 21, Blocks.stonebrick, 0);
		setBlock(world, i + 9, j + 4, k + 26, Blocks.stonebrick, 0);
		setBlock(world, i + 9, j + 4, k + 27, Blocks.stonebrick, 0);
		setBlock(world, i + 9, j + 5, k + 20, Blocks.stonebrick, 0);
		setBlock(world, i + 9, j + 5, k + 21, Blocks.stonebrick, 0);
		setBlock(world, i + 9, j + 5, k + 26, Blocks.stonebrick, 0);
		setBlock(world, i + 9, j + 5, k + 27, Blocks.stonebrick, 0);
		setBlock(world, i + 9, j + 6, k + 20, Blocks.stonebrick, 0);
		setBlock(world, i + 9, j + 6, k + 21, Blocks.stonebrick, 0);
		setBlock(world, i + 9, j + 6, k + 26, Blocks.stonebrick, 0);
		setBlock(world, i + 9, j + 6, k + 27, Blocks.stonebrick, 0);
		setBlock(world, i + 9, j + 7, k + 20, Blocks.stonebrick, 0);
		setBlock(world, i + 9, j + 7, k + 21, Blocks.stonebrick, 0);
		setBlock(world, i + 9, j + 7, k + 22, Blocks.stonebrick, 0);
		setBlock(world, i + 9, j + 7, k + 23, Blocks.stonebrick, 0);
		setBlock(world, i + 9, j + 7, k + 24, Blocks.stonebrick, 0);
		setBlock(world, i + 9, j + 7, k + 25, Blocks.stonebrick, 0);
		setBlock(world, i + 9, j + 7, k + 26, Blocks.stonebrick, 0);
		setBlock(world, i + 9, j + 7, k + 27, Blocks.stonebrick, 0);
		setBlock(world, i + 9, j + 8, k + 20, Blocks.stonebrick, 0);
		setBlock(world, i + 9, j + 8, k + 21, Blocks.stonebrick, 0);
		setBlock(world, i + 9, j + 8, k + 22, Blocks.stone_brick_stairs, 0);
		setBlock(world, i + 9, j + 8, k + 23, Blocks.stone_brick_stairs, 0);
		setBlock(world, i + 9, j + 8, k + 24, Blocks.stone_brick_stairs, 0);
		setBlock(world, i + 9, j + 8, k + 25, Blocks.stone_brick_stairs, 0);
		setBlock(world, i + 9, j + 8, k + 26, Blocks.stonebrick, 0);
		setBlock(world, i + 9, j + 8, k + 27, Blocks.stonebrick, 0);
		setBlock(world, i + 9, j + 9, k + 20, Blocks.stonebrick, 0);
		setBlock(world, i + 9, j + 9, k + 21, Blocks.stonebrick, 0);
		setBlock(world, i + 9, j + 9, k + 26, Blocks.stonebrick, 0);
		setBlock(world, i + 9, j + 9, k + 27, Blocks.stonebrick, 0);
		setBlock(world, i + 10, j + 0, k + 31, Blocks.stonebrick, 0);
		setBlock(world, i + 10, j + 0, k + 33, Blocks.stonebrick, 0);
		setBlock(world, i + 10, j + 1, k + 17, Blocks.stonebrick, 0);
		setBlock(world, i + 10, j + 1, k + 18, Blocks.stonebrick, 0);
		setBlock(world, i + 10, j + 1, k + 21, Blocks.stonebrick, 0);
		setBlock(world, i + 10, j + 1, k + 23, Blocks.stonebrick, 0);
		setBlock(world, i + 10, j + 1, k + 25, Blocks.stonebrick, 0);
		setBlock(world, i + 10, j + 1, k + 27, Blocks.stonebrick, 0);
		setBlock(world, i + 10, j + 1, k + 33, Blocks.stonebrick, 0);
		setBlock(world, i + 10, j + 1, k + 36, Blocks.stonebrick, 0);
		setBlock(world, i + 10, j + 2, k + 14, Blocks.stonebrick, 0);
		setBlock(world, i + 10, j + 2, k + 19, Blocks.stonebrick, 0);
		setBlock(world, i + 10, j + 2, k + 21, Blocks.stonebrick, 0);
		setBlock(world, i + 10, j + 2, k + 26, Blocks.stonebrick, 0);
		setBlock(world, i + 10, j + 2, k + 27, Blocks.stonebrick, 0);
		setBlock(world, i + 10, j + 3, k + 12, Blocks.stonebrick, 0);
		setBlock(world, i + 10, j + 3, k + 14, Blocks.stonebrick, 0);
		setBlock(world, i + 10, j + 3, k + 17, Blocks.stonebrick, 0);
		setBlock(world, i + 10, j + 3, k + 19, Blocks.stonebrick, 0);
		setBlock(world, i + 10, j + 3, k + 25, Blocks.stonebrick, 0);
		setBlock(world, i + 10, j + 3, k + 26, Blocks.stonebrick, 0);
		setBlock(world, i + 10, j + 3, k + 27, Blocks.stonebrick, 0);
		setBlock(world, i + 10, j + 3, k + 29, Blocks.stonebrick, 0);
		setBlock(world, i + 10, j + 3, k + 31, Blocks.stonebrick, 0);
		setBlock(world, i + 10, j + 4, k + 11, Blocks.stone_brick_stairs, 0);
		setBlock(world, i + 10, j + 4, k + 12, Blocks.stone_brick_stairs, 0);
		setBlock(world, i + 10, j + 4, k + 13, Blocks.stone_brick_stairs, 0);
		setBlock(world, i + 10, j + 4, k + 14, Blocks.stone_brick_stairs, 0);
		setBlock(world, i + 10, j + 4, k + 15, Blocks.stone_brick_stairs, 0);
		setBlock(world, i + 10, j + 4, k + 16, Blocks.stone_brick_stairs, 0);
		setBlock(world, i + 10, j + 4, k + 17, Blocks.stone_brick_stairs, 0);
		setBlock(world, i + 10, j + 4, k + 18, Blocks.stone_brick_stairs, 0);
		setBlock(world, i + 10, j + 4, k + 19, Blocks.stone_brick_stairs, 0);
		setBlock(world, i + 10, j + 4, k + 20, Blocks.stonebrick, 0);
		setBlock(world, i + 10, j + 4, k + 21, Blocks.stonebrick, 0);
		setBlock(world, i + 10, j + 4, k + 26, Blocks.stonebrick, 0);
		setBlock(world, i + 10, j + 4, k + 27, Blocks.stonebrick, 0);
		setBlock(world, i + 10, j + 4, k + 28, Blocks.stone_brick_stairs, 0);
		setBlock(world, i + 10, j + 4, k + 29, Blocks.stone_brick_stairs, 0);
		setBlock(world, i + 10, j + 4, k + 30, Blocks.stone_brick_stairs, 0);
		setBlock(world, i + 10, j + 4, k + 31, Blocks.stone_brick_stairs, 0);
		setBlock(world, i + 10, j + 4, k + 32, Blocks.stone_brick_stairs, 0);
		setBlock(world, i + 10, j + 4, k + 33, Blocks.stone_brick_stairs, 0);
		setBlock(world, i + 10, j + 4, k + 34, Blocks.stone_brick_stairs, 0);
		setBlock(world, i + 10, j + 4, k + 35, Blocks.stone_brick_stairs, 0);
		setBlock(world, i + 10, j + 4, k + 36, Blocks.stone_brick_stairs, 0);
		setBlock(world, i + 10, j + 5, k + 20, Blocks.stonebrick, 0);
		setBlock(world, i + 10, j + 5, k + 21, Blocks.stonebrick, 0);
		setBlock(world, i + 10, j + 5, k + 26, Blocks.stonebrick, 0);
		setBlock(world, i + 10, j + 5, k + 27, Blocks.stonebrick, 0);
		setBlock(world, i + 10, j + 6, k + 20, Blocks.stonebrick, 0);
		setBlock(world, i + 10, j + 6, k + 21, Blocks.stonebrick, 0);
		setBlock(world, i + 10, j + 6, k + 26, Blocks.stonebrick, 0);
		setBlock(world, i + 10, j + 6, k + 27, Blocks.stonebrick, 0);
		setBlock(world, i + 10, j + 7, k + 20, Blocks.stonebrick, 0);
		setBlock(world, i + 10, j + 7, k + 21, Blocks.stonebrick, 0);
		setBlock(world, i + 10, j + 7, k + 26, Blocks.stonebrick, 0);
		setBlock(world, i + 10, j + 7, k + 27, Blocks.stonebrick, 0);
		setBlock(world, i + 10, j + 8, k + 20, Blocks.stonebrick, 0);
		setBlock(world, i + 10, j + 8, k + 21, Blocks.stonebrick, 0);
		setBlock(world, i + 10, j + 8, k + 22, Blocks.stonebrick, 0);
		setBlock(world, i + 10, j + 8, k + 23, Blocks.stonebrick, 0);
		setBlock(world, i + 10, j + 8, k + 24, Blocks.stonebrick, 0);
		setBlock(world, i + 10, j + 8, k + 25, Blocks.stonebrick, 0);
		setBlock(world, i + 10, j + 8, k + 26, Blocks.stonebrick, 0);
		setBlock(world, i + 10, j + 8, k + 27, Blocks.stonebrick, 0);
		setBlock(world, i + 10, j + 9, k + 20, Blocks.stonebrick, 0);
		setBlock(world, i + 10, j + 9, k + 21, Blocks.stonebrick, 0);
		setBlock(world, i + 10, j + 9, k + 22, Blocks.stone_brick_stairs, 0);
		setBlock(world, i + 10, j + 9, k + 23, Blocks.stone_brick_stairs, 0);
		setBlock(world, i + 10, j + 9, k + 24, Blocks.stone_brick_stairs, 0);
		setBlock(world, i + 10, j + 9, k + 25, Blocks.stone_brick_stairs, 0);
		setBlock(world, i + 10, j + 9, k + 26, Blocks.stonebrick, 0);
		setBlock(world, i + 10, j + 9, k + 27, Blocks.stonebrick, 0);
		setBlock(world, i + 10, j + 10, k + 20, Blocks.stonebrick, 0);
		setBlock(world, i + 10, j + 10, k + 21, Blocks.stonebrick, 0);
		setBlock(world, i + 10, j + 10, k + 26, Blocks.stonebrick, 0);
		setBlock(world, i + 10, j + 10, k + 27, Blocks.stonebrick, 0);
		setBlock(world, i + 11, j + 1, k + 10, Blocks.stonebrick, 0);
		setBlock(world, i + 11, j + 2, k + 11, Blocks.stonebrick, 0);
		setBlock(world, i + 11, j + 2, k + 13, Blocks.stonebrick, 0);
		setBlock(world, i + 11, j + 2, k + 14, Blocks.stonebrick, 0);
		setBlock(world, i + 11, j + 2, k + 20, Blocks.stonebrick, 0);
		setBlock(world, i + 11, j + 2, k + 22, Blocks.stonebrick, 0);
		setBlock(world, i + 11, j + 2, k + 25, Blocks.stonebrick, 0);
		setBlock(world, i + 11, j + 2, k + 28, Blocks.stonebrick, 0);
		setBlock(world, i + 11, j + 2, k + 30, Blocks.stonebrick, 0);
		setBlock(world, i + 11, j + 2, k + 36, Blocks.stonebrick, 0);
		setBlock(world, i + 11, j + 3, k + 13, Blocks.stonebrick, 0);
		setBlock(world, i + 11, j + 3, k + 14, Blocks.stonebrick, 0);
		setBlock(world, i + 11, j + 3, k + 16, Blocks.stonebrick, 0);
		setBlock(world, i + 11, j + 3, k + 17, Blocks.stonebrick, 0);
		setBlock(world, i + 11, j + 3, k + 18, Blocks.stonebrick, 0);
		setBlock(world, i + 11, j + 3, k + 21, Blocks.stonebrick, 0);
		setBlock(world, i + 11, j + 3, k + 23, Blocks.stonebrick, 0);
		setBlock(world, i + 11, j + 3, k + 24, Blocks.stonebrick, 0);
		setBlock(world, i + 11, j + 3, k + 27, Blocks.stonebrick, 0);
		setBlock(world, i + 11, j + 3, k + 28, Blocks.stonebrick, 0);
		setBlock(world, i + 11, j + 3, k + 29, Blocks.stonebrick, 0);
		setBlock(world, i + 11, j + 3, k + 30, Blocks.stonebrick, 0);
		setBlock(world, i + 11, j + 3, k + 35, Blocks.stonebrick, 0);
		setBlock(world, i + 11, j + 4, k + 12, Blocks.stonebrick, 0);
		setBlock(world, i + 11, j + 4, k + 13, Blocks.stonebrick, 0);
		setBlock(world, i + 11, j + 4, k + 14, Blocks.stonebrick, 0);
		setBlock(world, i + 11, j + 4, k + 15, Blocks.stonebrick, 0);
		setBlock(world, i + 11, j + 4, k + 20, Blocks.stonebrick, 0);
		setBlock(world, i + 11, j + 4, k + 24, Blocks.stonebrick, 0);
		setBlock(world, i + 11, j + 4, k + 26, Blocks.stonebrick, 0);
		setBlock(world, i + 11, j + 4, k + 29, Blocks.stonebrick, 0);
		setBlock(world, i + 11, j + 4, k + 30, Blocks.stonebrick, 0);
		setBlock(world, i + 11, j + 5, k + 14, Blocks.stonebrick, 0);
		setBlock(world, i + 11, j + 5, k + 15, Blocks.stonebrick, 0);
		setBlock(world, i + 11, j + 5, k + 16, Blocks.stonebrick, 0);
		setBlock(world, i + 11, j + 5, k + 17, Blocks.stonebrick, 0);
		setBlock(world, i + 11, j + 5, k + 20, Blocks.stonebrick, 0);
		setBlock(world, i + 11, j + 5, k + 21, Blocks.stonebrick, 0);
		setBlock(world, i + 11, j + 5, k + 24, Blocks.stonebrick, 0);
		setBlock(world, i + 11, j + 5, k + 25, Blocks.stonebrick, 0);
		setBlock(world, i + 11, j + 6, k + 12, Blocks.stone_brick_stairs, 0);
		setBlock(world, i + 11, j + 6, k + 13, Blocks.stone_brick_stairs, 0);
		setBlock(world, i + 11, j + 6, k + 14, Blocks.stone_brick_stairs, 0);
		setBlock(world, i + 11, j + 6, k + 15, Blocks.stone_brick_stairs, 0);
		setBlock(world, i + 11, j + 6, k + 16, Blocks.stone_brick_stairs, 0);
		setBlock(world, i + 11, j + 6, k + 17, Blocks.stone_brick_stairs, 0);
		setBlock(world, i + 11, j + 6, k + 18, Blocks.stone_brick_stairs, 0);
		setBlock(world, i + 11, j + 6, k + 19, Blocks.stone_brick_stairs, 0);
		setBlock(world, i + 11, j + 6, k + 20, Blocks.stonebrick, 0);
		setBlock(world, i + 11, j + 6, k + 21, Blocks.stonebrick, 0);
		setBlock(world, i + 11, j + 6, k + 26, Blocks.stonebrick, 0);
		setBlock(world, i + 11, j + 6, k + 27, Blocks.stonebrick, 0);
		setBlock(world, i + 11, j + 6, k + 28, Blocks.stone_brick_stairs, 0);
		setBlock(world, i + 11, j + 6, k + 29, Blocks.stone_brick_stairs, 0);
		setBlock(world, i + 11, j + 6, k + 30, Blocks.stone_brick_stairs, 0);
		setBlock(world, i + 11, j + 6, k + 31, Blocks.stone_brick_stairs, 0);
		setBlock(world, i + 11, j + 6, k + 32, Blocks.stone_brick_stairs, 0);
		setBlock(world, i + 11, j + 6, k + 33, Blocks.stone_brick_stairs, 0);
		setBlock(world, i + 11, j + 6, k + 34, Blocks.stone_brick_stairs, 0);
		setBlock(world, i + 11, j + 6, k + 35, Blocks.stone_brick_stairs, 0);
		setBlock(world, i + 11, j + 7, k + 20, Blocks.stonebrick, 0);
		setBlock(world, i + 11, j + 7, k + 21, Blocks.stonebrick, 0);
		setBlock(world, i + 11, j + 7, k + 26, Blocks.stonebrick, 0);
		setBlock(world, i + 11, j + 7, k + 27, Blocks.stonebrick, 0);
		setBlock(world, i + 11, j + 8, k + 20, Blocks.stonebrick, 0);
		setBlock(world, i + 11, j + 8, k + 21, Blocks.stonebrick, 0);
		setBlock(world, i + 11, j + 8, k + 26, Blocks.stonebrick, 0);
		setBlock(world, i + 11, j + 8, k + 27, Blocks.stonebrick, 0);
		setBlock(world, i + 11, j + 9, k + 20, Blocks.stonebrick, 0);
		setBlock(world, i + 11, j + 9, k + 21, Blocks.stonebrick, 0);
		setBlock(world, i + 11, j + 9, k + 22, Blocks.stonebrick, 0);
		setBlock(world, i + 11, j + 9, k + 23, Blocks.stonebrick, 0);
		setBlock(world, i + 11, j + 9, k + 24, Blocks.stonebrick, 0);
		setBlock(world, i + 11, j + 9, k + 25, Blocks.stonebrick, 0);
		setBlock(world, i + 11, j + 9, k + 26, Blocks.stonebrick, 0);
		setBlock(world, i + 11, j + 9, k + 27, Blocks.stonebrick, 0);
		setBlock(world, i + 11, j + 10, k + 20, Blocks.stonebrick, 0);
		setBlock(world, i + 11, j + 10, k + 21, Blocks.stonebrick, 0);
		setBlock(world, i + 11, j + 10, k + 22, Blocks.stone_brick_stairs, 0);
		setBlock(world, i + 11, j + 10, k + 23, Blocks.stone_brick_stairs, 0);
		setBlock(world, i + 11, j + 10, k + 24, Blocks.stone_brick_stairs, 0);
		setBlock(world, i + 11, j + 10, k + 25, Blocks.stone_brick_stairs, 0);
		setBlock(world, i + 11, j + 10, k + 26, Blocks.stonebrick, 0);
		setBlock(world, i + 11, j + 10, k + 27, Blocks.stonebrick, 0);
		setBlock(world, i + 11, j + 11, k + 20, Blocks.stonebrick, 0);
		setBlock(world, i + 11, j + 11, k + 21, Blocks.stonebrick, 0);
		setBlock(world, i + 11, j + 11, k + 26, Blocks.stonebrick, 0);
		setBlock(world, i + 11, j + 11, k + 27, Blocks.stonebrick, 0);
		setBlock(world, i + 12, j + 3, k + 11, Blocks.stonebrick, 0);
		setBlock(world, i + 12, j + 3, k + 14, Blocks.stonebrick, 0);
		setBlock(world, i + 12, j + 3, k + 16, Blocks.stonebrick, 0);
		setBlock(world, i + 12, j + 3, k + 17, Blocks.stonebrick, 0);
		setBlock(world, i + 12, j + 3, k + 19, Blocks.stonebrick, 0);
		setBlock(world, i + 12, j + 3, k + 21, Blocks.stonebrick, 0);
		setBlock(world, i + 12, j + 3, k + 37, Blocks.stonebrick, 0);
		setBlock(world, i + 12, j + 4, k + 15, Blocks.stonebrick, 0);
		setBlock(world, i + 12, j + 4, k + 18, Blocks.stonebrick, 0);
		setBlock(world, i + 12, j + 4, k + 22, Blocks.stonebrick, 0);
		setBlock(world, i + 12, j + 4, k + 23, Blocks.stonebrick, 0);
		setBlock(world, i + 12, j + 4, k + 26, Blocks.stonebrick, 0);
		setBlock(world, i + 12, j + 4, k + 36, Blocks.stonebrick, 0);
		setBlock(world, i + 12, j + 5, k + 21, Blocks.stonebrick, 0);
		setBlock(world, i + 12, j + 5, k + 22, Blocks.stonebrick, 0);
		setBlock(world, i + 12, j + 5, k + 23, Blocks.stonebrick, 0);
		setBlock(world, i + 12, j + 5, k + 26, Blocks.stonebrick, 0);
		setBlock(world, i + 12, j + 5, k + 29, Blocks.stonebrick, 0);
		setBlock(world, i + 12, j + 5, k + 30, Blocks.stonebrick, 0);
		setBlock(world, i + 12, j + 5, k + 32, Blocks.stonebrick, 0);
		setBlock(world, i + 12, j + 6, k + 16, Blocks.stonebrick, 0);
		setBlock(world, i + 12, j + 6, k + 17, Blocks.stonebrick, 0);
		setBlock(world, i + 12, j + 6, k + 21, Blocks.stonebrick, 0);
		setBlock(world, i + 12, j + 6, k + 27, Blocks.stonebrick, 0);
		setBlock(world, i + 12, j + 6, k + 28, Blocks.stonebrick, 0);
		setBlock(world, i + 12, j + 6, k + 32, Blocks.stonebrick, 0);
		setBlock(world, i + 12, j + 7, k + 15, Blocks.stonebrick, 0);
		setBlock(world, i + 12, j + 7, k + 16, Blocks.stonebrick, 0);
		setBlock(world, i + 12, j + 7, k + 21, Blocks.stonebrick, 0);
		setBlock(world, i + 12, j + 7, k + 24, Blocks.stonebrick, 0);
		setBlock(world, i + 12, j + 7, k + 25, Blocks.stonebrick, 0);
		setBlock(world, i + 12, j + 7, k + 26, Blocks.stonebrick, 0);
		setBlock(world, i + 12, j + 7, k + 29, Blocks.stonebrick, 0);
		setBlock(world, i + 12, j + 7, k + 32, Blocks.stonebrick, 0);
		setBlock(world, i + 12, j + 7, k + 33, Blocks.stonebrick, 0);
		setBlock(world, i + 12, j + 7, k + 34, Blocks.stonebrick, 0);
		setBlock(world, i + 12, j + 8, k + 13, Blocks.stone_brick_stairs, 0);
		setBlock(world, i + 12, j + 8, k + 14, Blocks.stone_brick_stairs, 0);
		setBlock(world, i + 12, j + 8, k + 15, Blocks.stone_brick_stairs, 0);
		setBlock(world, i + 12, j + 8, k + 16, Blocks.stone_brick_stairs, 0);
		setBlock(world, i + 12, j + 8, k + 17, Blocks.stone_brick_stairs, 0);
		setBlock(world, i + 12, j + 8, k + 18, Blocks.stone_brick_stairs, 0);
		setBlock(world, i + 12, j + 8, k + 19, Blocks.stone_brick_stairs, 0);
		setBlock(world, i + 12, j + 8, k + 20, Blocks.stonebrick, 0);
		setBlock(world, i + 12, j + 8, k + 21, Blocks.stonebrick, 0);
		setBlock(world, i + 12, j + 8, k + 26, Blocks.stonebrick, 0);
		setBlock(world, i + 12, j + 8, k + 27, Blocks.stonebrick, 0);
		setBlock(world, i + 12, j + 8, k + 28, Blocks.stone_brick_stairs, 0);
		setBlock(world, i + 12, j + 8, k + 29, Blocks.stone_brick_stairs, 0);
		setBlock(world, i + 12, j + 8, k + 30, Blocks.stone_brick_stairs, 0);
		setBlock(world, i + 12, j + 8, k + 31, Blocks.stone_brick_stairs, 0);
		setBlock(world, i + 12, j + 8, k + 32, Blocks.stone_brick_stairs, 0);
		setBlock(world, i + 12, j + 8, k + 33, Blocks.stone_brick_stairs, 0);
		setBlock(world, i + 12, j + 8, k + 34, Blocks.stone_brick_stairs, 0);
		setBlock(world, i + 12, j + 9, k + 20, Blocks.stonebrick, 0);
		setBlock(world, i + 12, j + 9, k + 21, Blocks.stonebrick, 0);
		setBlock(world, i + 12, j + 9, k + 26, Blocks.stonebrick, 0);
		setBlock(world, i + 12, j + 9, k + 27, Blocks.stonebrick, 0);
		setBlock(world, i + 12, j + 10, k + 20, Blocks.stonebrick, 0);
		setBlock(world, i + 12, j + 10, k + 21, Blocks.stonebrick, 0);
		setBlock(world, i + 12, j + 10, k + 22, Blocks.stonebrick, 0);
		setBlock(world, i + 12, j + 10, k + 23, Blocks.stonebrick, 0);
		setBlock(world, i + 12, j + 10, k + 24, Blocks.stonebrick, 0);
		setBlock(world, i + 12, j + 10, k + 25, Blocks.stonebrick, 0);
		setBlock(world, i + 12, j + 10, k + 26, Blocks.stonebrick, 0);
		setBlock(world, i + 12, j + 10, k + 27, Blocks.stonebrick, 0);
		setBlock(world, i + 12, j + 11, k + 20, Blocks.stonebrick, 0);
		setBlock(world, i + 12, j + 11, k + 21, Blocks.stonebrick, 0);
		setBlock(world, i + 12, j + 11, k + 22, Blocks.stone_brick_stairs, 0);
		setBlock(world, i + 12, j + 11, k + 23, Blocks.stone_brick_stairs, 0);
		setBlock(world, i + 12, j + 11, k + 24, Blocks.stone_brick_stairs, 0);
		setBlock(world, i + 12, j + 11, k + 25, Blocks.stone_brick_stairs, 0);
		setBlock(world, i + 12, j + 11, k + 26, Blocks.stonebrick, 0);
		setBlock(world, i + 12, j + 11, k + 27, Blocks.stonebrick, 0);
		setBlock(world, i + 12, j + 12, k + 20, Blocks.stonebrick, 0);
		setBlock(world, i + 12, j + 12, k + 21, Blocks.stonebrick, 0);
		setBlock(world, i + 12, j + 12, k + 26, Blocks.stonebrick, 0);
		setBlock(world, i + 12, j + 12, k + 27, Blocks.stonebrick, 0);
		setBlock(world, i + 13, j + 2, k + 36, Blocks.stonebrick, 0);
		setBlock(world, i + 13, j + 3, k + 36, Blocks.stonebrick, 0);
		setBlock(world, i + 13, j + 4, k + 36, Blocks.stonebrick, 0);
		setBlock(world, i + 13, j + 5, k + 27, Blocks.stonebrick, 0);
		setBlock(world, i + 13, j + 5, k + 28, Blocks.stonebrick, 0);
		setBlock(world, i + 13, j + 6, k + 16, Blocks.stonebrick, 0);
		setBlock(world, i + 13, j + 6, k + 17, Blocks.stonebrick, 0);
		setBlock(world, i + 13, j + 6, k + 18, Blocks.stonebrick, 0);
		setBlock(world, i + 13, j + 6, k + 22, Blocks.stonebrick, 0);
		setBlock(world, i + 13, j + 6, k + 23, Blocks.stonebrick, 0);
		setBlock(world, i + 13, j + 6, k + 24, Blocks.stonebrick, 0);
		setBlock(world, i + 13, j + 6, k + 25, Blocks.stonebrick, 0);
		setBlock(world, i + 13, j + 6, k + 30, Blocks.stonebrick, 0);
		setBlock(world, i + 13, j + 6, k + 31, Blocks.stonebrick, 0);
		setBlock(world, i + 13, j + 7, k + 12, Blocks.stonebrick, 0);
		setBlock(world, i + 13, j + 7, k + 16, Blocks.stonebrick, 0);
		setBlock(world, i + 13, j + 7, k + 17, Blocks.stonebrick, 0);
		setBlock(world, i + 13, j + 7, k + 19, Blocks.stonebrick, 0);
		setBlock(world, i + 13, j + 7, k + 20, Blocks.stonebrick, 0);
		setBlock(world, i + 13, j + 7, k + 21, Blocks.stonebrick, 0);
		setBlock(world, i + 13, j + 7, k + 29, Blocks.stonebrick, 0);
		setBlock(world, i + 13, j + 7, k + 30, Blocks.stonebrick, 0);
		setBlock(world, i + 13, j + 7, k + 33, Blocks.stonebrick, 0);
		setBlock(world, i + 13, j + 8, k + 15, Blocks.stonebrick, 0);
		setBlock(world, i + 13, j + 8, k + 18, Blocks.stonebrick, 0);
		setBlock(world, i + 13, j + 8, k + 26, Blocks.stonebrick, 0);
		setBlock(world, i + 13, j + 8, k + 29, Blocks.stonebrick, 0);
		setBlock(world, i + 13, j + 9, k + 17, Blocks.stonebrick, 0);
		setBlock(world, i + 13, j + 9, k + 23, Blocks.stonebrick, 0);
		setBlock(world, i + 13, j + 9, k + 25, Blocks.stonebrick, 0);
		setBlock(world, i + 13, j + 9, k + 29, Blocks.stonebrick, 0);
		setBlock(world, i + 13, j + 9, k + 30, Blocks.stonebrick, 0);
		setBlock(world, i + 13, j + 9, k + 31, Blocks.stonebrick, 0);
		setBlock(world, i + 13, j + 9, k + 32, Blocks.stonebrick, 0);
		setBlock(world, i + 13, j + 10, k + 14, Blocks.stone_brick_stairs, 0);
		setBlock(world, i + 13, j + 10, k + 15, Blocks.stone_brick_stairs, 0);
		setBlock(world, i + 13, j + 10, k + 16, Blocks.stone_brick_stairs, 0);
		setBlock(world, i + 13, j + 10, k + 17, Blocks.stone_brick_stairs, 0);
		setBlock(world, i + 13, j + 10, k + 18, Blocks.stone_brick_stairs, 0);
		setBlock(world, i + 13, j + 10, k + 19, Blocks.stone_brick_stairs, 0);
		setBlock(world, i + 13, j + 10, k + 20, Blocks.stonebrick, 0);
		setBlock(world, i + 13, j + 10, k + 21, Blocks.stonebrick, 0);
		setBlock(world, i + 13, j + 10, k + 26, Blocks.stonebrick, 0);
		setBlock(world, i + 13, j + 10, k + 27, Blocks.stonebrick, 0);
		setBlock(world, i + 13, j + 10, k + 28, Blocks.stone_brick_stairs, 0);
		setBlock(world, i + 13, j + 10, k + 29, Blocks.stone_brick_stairs, 0);
		setBlock(world, i + 13, j + 10, k + 30, Blocks.stone_brick_stairs, 0);
		setBlock(world, i + 13, j + 10, k + 31, Blocks.stone_brick_stairs, 0);
		setBlock(world, i + 13, j + 10, k + 32, Blocks.stone_brick_stairs, 0);
		setBlock(world, i + 13, j + 10, k + 33, Blocks.stone_brick_stairs, 0);
		setBlock(world, i + 13, j + 11, k + 20, Blocks.stonebrick, 0);
		setBlock(world, i + 13, j + 11, k + 21, Blocks.stonebrick, 0);
		setBlock(world, i + 13, j + 11, k + 22, Blocks.stonebrick, 0);
		setBlock(world, i + 13, j + 11, k + 23, Blocks.stonebrick, 0);
		setBlock(world, i + 13, j + 11, k + 24, Blocks.stonebrick, 0);
		setBlock(world, i + 13, j + 11, k + 25, Blocks.stonebrick, 0);
		setBlock(world, i + 13, j + 11, k + 26, Blocks.stonebrick, 0);
		setBlock(world, i + 13, j + 11, k + 27, Blocks.stonebrick, 0);
		setBlock(world, i + 13, j + 12, k + 20, Blocks.stonebrick, 0);
		setBlock(world, i + 13, j + 12, k + 21, Blocks.stonebrick, 0);
		setBlock(world, i + 13, j + 12, k + 22, Blocks.stone_brick_stairs, 0);
		setBlock(world, i + 13, j + 12, k + 23, Blocks.stone_brick_stairs, 0);
		setBlock(world, i + 13, j + 12, k + 24, Blocks.stone_brick_stairs, 0);
		setBlock(world, i + 13, j + 12, k + 25, Blocks.stone_brick_stairs, 0);
		setBlock(world, i + 13, j + 12, k + 26, Blocks.stonebrick, 0);
		setBlock(world, i + 13, j + 12, k + 27, Blocks.stonebrick, 0);
		setBlock(world, i + 13, j + 13, k + 20, Blocks.stonebrick, 0);
		setBlock(world, i + 13, j + 13, k + 21, Blocks.stonebrick, 0);
		setBlock(world, i + 13, j + 13, k + 26, Blocks.stonebrick, 0);
		setBlock(world, i + 13, j + 13, k + 27, Blocks.stonebrick, 0);
		setBlock(world, i + 14, j + 0, k + 10, Blocks.stonebrick, 0);
		setBlock(world, i + 14, j + 1, k + 10, Blocks.stonebrick, 0);
		setBlock(world, i + 14, j + 2, k + 36, Blocks.stonebrick, 0);
		setBlock(world, i + 14, j + 2, k + 37, Blocks.stonebrick, 0);
		setBlock(world, i + 14, j + 3, k + 35, Blocks.stonebrick, 0);
		setBlock(world, i + 14, j + 3, k + 36, Blocks.stonebrick, 0);
		setBlock(world, i + 14, j + 3, k + 37, Blocks.stonebrick, 0);
		setBlock(world, i + 14, j + 4, k + 36, Blocks.stonebrick, 0);
		setBlock(world, i + 14, j + 5, k + 36, Blocks.stonebrick, 0);
		setBlock(world, i + 14, j + 7, k + 12, Blocks.stonebrick, 0);
		setBlock(world, i + 14, j + 7, k + 13, Blocks.stonebrick, 0);
		setBlock(world, i + 14, j + 7, k + 16, Blocks.stonebrick, 0);
		setBlock(world, i + 14, j + 7, k + 24, Blocks.stonebrick, 0);
		setBlock(world, i + 14, j + 7, k + 27, Blocks.stonebrick, 0);
		setBlock(world, i + 14, j + 7, k + 30, Blocks.stonebrick, 0);
		setBlock(world, i + 14, j + 7, k + 32, Blocks.stonebrick, 0);
		setBlock(world, i + 14, j + 8, k + 15, Blocks.stonebrick, 0);
		setBlock(world, i + 14, j + 8, k + 22, Blocks.stonebrick, 0);
		setBlock(world, i + 14, j + 8, k + 25, Blocks.stonebrick, 0);
		setBlock(world, i + 14, j + 8, k + 28, Blocks.stonebrick, 0);
		setBlock(world, i + 14, j + 8, k + 29, Blocks.stonebrick, 0);
		setBlock(world, i + 14, j + 8, k + 31, Blocks.stonebrick, 0);
		setBlock(world, i + 14, j + 9, k + 14, Blocks.stonebrick, 0);
		setBlock(world, i + 14, j + 9, k + 21, Blocks.stonebrick, 0);
		setBlock(world, i + 14, j + 9, k + 24, Blocks.stonebrick, 0);
		setBlock(world, i + 14, j + 9, k + 25, Blocks.stonebrick, 0);
		setBlock(world, i + 14, j + 9, k + 26, Blocks.stonebrick, 0);
		setBlock(world, i + 14, j + 9, k + 29, Blocks.stonebrick, 0);
		setBlock(world, i + 14, j + 9, k + 30, Blocks.stonebrick, 0);
		setBlock(world, i + 14, j + 9, k + 31, Blocks.stonebrick, 0);
		setBlock(world, i + 14, j + 9, k + 33, Blocks.stonebrick, 0);
		setBlock(world, i + 14, j + 10, k + 23, Blocks.stonebrick, 0);
		setBlock(world, i + 14, j + 10, k + 27, Blocks.stonebrick, 0);
		setBlock(world, i + 14, j + 10, k + 29, Blocks.stonebrick, 0);
		setBlock(world, i + 14, j + 11, k + 21, Blocks.stonebrick, 0);
		setBlock(world, i + 14, j + 11, k + 26, Blocks.stonebrick, 0);
		setBlock(world, i + 14, j + 12, k + 15, Blocks.stone_brick_stairs, 0);
		setBlock(world, i + 14, j + 12, k + 16, Blocks.stone_brick_stairs, 0);
		setBlock(world, i + 14, j + 12, k + 17, Blocks.stone_brick_stairs, 0);
		setBlock(world, i + 14, j + 12, k + 18, Blocks.stone_brick_stairs, 0);
		setBlock(world, i + 14, j + 12, k + 19, Blocks.stone_brick_stairs, 0);
		setBlock(world, i + 14, j + 12, k + 20, Blocks.stonebrick, 0);
		setBlock(world, i + 14, j + 12, k + 21, Blocks.stonebrick, 0);
		setBlock(world, i + 14, j + 12, k + 22, Blocks.stonebrick, 0);
		setBlock(world, i + 14, j + 12, k + 23, Blocks.stonebrick, 0);
		setBlock(world, i + 14, j + 12, k + 24, Blocks.stonebrick, 0);
		setBlock(world, i + 14, j + 12, k + 25, Blocks.stonebrick, 0);
		setBlock(world, i + 14, j + 12, k + 26, Blocks.stonebrick, 0);
		setBlock(world, i + 14, j + 12, k + 27, Blocks.stonebrick, 0);
		setBlock(world, i + 14, j + 12, k + 28, Blocks.stone_brick_stairs, 0);
		setBlock(world, i + 14, j + 12, k + 29, Blocks.stone_brick_stairs, 0);
		setBlock(world, i + 14, j + 12, k + 30, Blocks.stone_brick_stairs, 0);
		setBlock(world, i + 14, j + 12, k + 31, Blocks.stone_brick_stairs, 0);
		setBlock(world, i + 14, j + 12, k + 32, Blocks.stone_brick_stairs, 0);
		setBlock(world, i + 14, j + 13, k + 20, Blocks.stonebrick, 0);
		setBlock(world, i + 14, j + 13, k + 21, Blocks.stonebrick, 0);
		setBlock(world, i + 14, j + 13, k + 22, Blocks.stone_brick_stairs, 0);
		setBlock(world, i + 14, j + 13, k + 23, Blocks.stone_brick_stairs, 0);
		setBlock(world, i + 14, j + 13, k + 24, Blocks.stone_brick_stairs, 0);
		setBlock(world, i + 14, j + 13, k + 25, Blocks.stone_brick_stairs, 0);
		setBlock(world, i + 14, j + 13, k + 26, Blocks.stonebrick, 0);
		setBlock(world, i + 14, j + 13, k + 27, Blocks.stonebrick, 0);
		setBlock(world, i + 14, j + 14, k + 20, Blocks.stonebrick, 0);
		setBlock(world, i + 14, j + 14, k + 21, Blocks.stonebrick, 0);
		setBlock(world, i + 14, j + 14, k + 26, Blocks.stonebrick, 0);
		setBlock(world, i + 14, j + 14, k + 27, Blocks.stonebrick, 0);
		setBlock(world, i + 15, j + 4, k + 35, Blocks.stonebrick, 0);
		setBlock(world, i + 15, j + 4, k + 36, Blocks.stonebrick, 0);
		setBlock(world, i + 15, j + 5, k + 12, Blocks.stonebrick, 0);
		setBlock(world, i + 15, j + 5, k + 36, Blocks.stonebrick, 0);
		setBlock(world, i + 15, j + 6, k + 12, Blocks.stonebrick, 0);
		setBlock(world, i + 15, j + 7, k + 12, Blocks.stonebrick, 0);
		setBlock(world, i + 15, j + 7, k + 14, Blocks.stonebrick, 0);
		setBlock(world, i + 15, j + 7, k + 35, Blocks.stonebrick, 0);
		setBlock(world, i + 15, j + 8, k + 33, Blocks.stonebrick, 0);
		setBlock(world, i + 15, j + 8, k + 34, Blocks.stonebrick, 0);
		setBlock(world, i + 15, j + 9, k + 13, Blocks.stonebrick, 0);
		setBlock(world, i + 15, j + 9, k + 15, Blocks.stonebrick, 0);
		setBlock(world, i + 15, j + 9, k + 27, Blocks.stonebrick, 0);
		setBlock(world, i + 15, j + 9, k + 32, Blocks.stonebrick, 0);
		setBlock(world, i + 15, j + 10, k + 22, Blocks.stonebrick, 0);
		setBlock(world, i + 15, j + 10, k + 26, Blocks.stonebrick, 0);
		setBlock(world, i + 15, j + 10, k + 27, Blocks.stonebrick, 0);
		setBlock(world, i + 15, j + 10, k + 28, Blocks.stonebrick, 0);
		setBlock(world, i + 15, j + 10, k + 29, Blocks.stonebrick, 0);
		setBlock(world, i + 15, j + 10, k + 30, Blocks.stonebrick, 0);
		setBlock(world, i + 15, j + 10, k + 31, Blocks.stonebrick, 0);
		setBlock(world, i + 15, j + 11, k + 20, Blocks.stonebrick, 0);
		setBlock(world, i + 15, j + 11, k + 21, Blocks.stonebrick, 0);
		setBlock(world, i + 15, j + 11, k + 22, Blocks.stonebrick, 0);
		setBlock(world, i + 15, j + 11, k + 23, Blocks.stonebrick, 0);
		setBlock(world, i + 15, j + 11, k + 24, Blocks.stonebrick, 0);
		setBlock(world, i + 15, j + 11, k + 25, Blocks.stonebrick, 0);
		setBlock(world, i + 15, j + 11, k + 30, Blocks.stonebrick, 0);
		setBlock(world, i + 15, j + 12, k + 21, Blocks.stonebrick, 0);
		setBlock(world, i + 15, j + 12, k + 24, Blocks.stonebrick, 0);
		setBlock(world, i + 15, j + 13, k + 19, Blocks.stonebrick, 0);
		setBlock(world, i + 15, j + 13, k + 20, Blocks.stonebrick, 0);
		setBlock(world, i + 15, j + 13, k + 21, Blocks.stonebrick, 0);
		setBlock(world, i + 15, j + 13, k + 22, Blocks.stonebrick, 0);
		setBlock(world, i + 15, j + 13, k + 23, Blocks.stonebrick, 0);
		setBlock(world, i + 15, j + 13, k + 25, Blocks.stonebrick, 0);
		setBlock(world, i + 15, j + 13, k + 26, Blocks.stonebrick, 0);
		setBlock(world, i + 15, j + 13, k + 30, Blocks.stonebrick, 0);
		setBlock(world, i + 15, j + 14, k + 19, Blocks.stonebrick, 0);
		setBlock(world, i + 15, j + 14, k + 20, Blocks.stonebrick, 0);
		setBlock(world, i + 15, j + 14, k + 21, Blocks.stonebrick, 0);
		setBlock(world, i + 15, j + 14, k + 22, Blocks.stone_brick_stairs, 0);
		setBlock(world, i + 15, j + 14, k + 23, Blocks.stone_brick_stairs, 0);
		setBlock(world, i + 15, j + 14, k + 24, Blocks.stone_brick_stairs, 0);
		setBlock(world, i + 15, j + 14, k + 25, Blocks.stone_brick_stairs, 0);
		setBlock(world, i + 15, j + 14, k + 26, Blocks.stonebrick, 0);
		setBlock(world, i + 15, j + 14, k + 27, Blocks.stonebrick, 0);
		setBlock(world, i + 15, j + 14, k + 28, Blocks.stonebrick, 0);
		setBlock(world, i + 15, j + 15, k + 19, Blocks.stone_brick_stairs, 0);
		setBlock(world, i + 15, j + 15, k + 20, Blocks.stonebrick, 0);
		setBlock(world, i + 15, j + 15, k + 21, Blocks.stonebrick, 0);
		setBlock(world, i + 15, j + 15, k + 26, Blocks.stonebrick, 0);
		setBlock(world, i + 15, j + 15, k + 27, Blocks.stonebrick, 0);
		setBlock(world, i + 15, j + 15, k + 28, Blocks.stone_brick_stairs, 0);
		setBlock(world, i + 16, j + 0, k + 10, Blocks.stonebrick, 0);
		setBlock(world, i + 16, j + 3, k + 10, Blocks.stonebrick, 0);
		setBlock(world, i + 16, j + 3, k + 35, Blocks.stonebrick, 0);
		setBlock(world, i + 16, j + 3, k + 36, Blocks.stonebrick, 0);
		setBlock(world, i + 16, j + 5, k + 36, Blocks.stonebrick, 0);
		setBlock(world, i + 16, j + 6, k + 13, Blocks.stonebrick, 0);
		setBlock(world, i + 16, j + 6, k + 34, Blocks.stonebrick, 0);
		setBlock(world, i + 16, j + 6, k + 35, Blocks.stonebrick, 0);
		setBlock(world, i + 16, j + 7, k + 33, Blocks.stonebrick, 0);
		setBlock(world, i + 16, j + 7, k + 34, Blocks.stonebrick, 0);
		setBlock(world, i + 16, j + 7, k + 35, Blocks.stonebrick, 0);
		setBlock(world, i + 16, j + 8, k + 14, Blocks.stonebrick, 0);
		setBlock(world, i + 16, j + 9, k + 13, Blocks.stonebrick, 0);
		setBlock(world, i + 16, j + 9, k + 14, Blocks.stonebrick, 0);
		setBlock(world, i + 16, j + 10, k + 15, Blocks.stonebrick, 0);
		setBlock(world, i + 16, j + 11, k + 21, Blocks.stonebrick, 0);
		setBlock(world, i + 16, j + 11, k + 22, Blocks.stonebrick, 0);
		setBlock(world, i + 16, j + 11, k + 23, Blocks.stonebrick, 0);
		setBlock(world, i + 16, j + 11, k + 29, Blocks.stonebrick, 0);
		setBlock(world, i + 16, j + 12, k + 23, Blocks.stonebrick, 0);
		setBlock(world, i + 16, j + 13, k + 19, Blocks.stonebrick, 0);
		setBlock(world, i + 16, j + 13, k + 20, Blocks.stonebrick, 0);
		setBlock(world, i + 16, j + 13, k + 22, Blocks.stonebrick, 0);
		setBlock(world, i + 16, j + 13, k + 23, Blocks.stonebrick, 0);
		setBlock(world, i + 16, j + 14, k + 18, Blocks.stonebrick, 0);
		setBlock(world, i + 16, j + 14, k + 19, Blocks.stonebrick, 0);
		setBlock(world, i + 16, j + 14, k + 20, Blocks.stonebrick, 0);
		setBlock(world, i + 16, j + 14, k + 21, Blocks.stonebrick, 0);
		setBlock(world, i + 16, j + 14, k + 22, Blocks.stonebrick, 0);
		setBlock(world, i + 16, j + 14, k + 23, Blocks.stonebrick, 0);
		setBlock(world, i + 16, j + 14, k + 24, Blocks.stonebrick, 0);
		setBlock(world, i + 16, j + 14, k + 25, Blocks.stonebrick, 0);
		setBlock(world, i + 16, j + 14, k + 26, Blocks.stonebrick, 0);
		setBlock(world, i + 16, j + 14, k + 27, Blocks.stonebrick, 0);
		setBlock(world, i + 16, j + 14, k + 28, Blocks.stonebrick, 0);
		setBlock(world, i + 16, j + 14, k + 29, Blocks.stonebrick, 0);
		setBlock(world, i + 16, j + 15, k + 18, Blocks.stone_brick_stairs, 0);
		setBlock(world, i + 16, j + 15, k + 19, Blocks.stonebrick, 0);
		setBlock(world, i + 16, j + 15, k + 20, Blocks.stonebrick, 0);
		setBlock(world, i + 16, j + 15, k + 21, Blocks.stonebrick, 0);
		setBlock(world, i + 16, j + 15, k + 26, Blocks.stonebrick, 0);
		setBlock(world, i + 16, j + 15, k + 27, Blocks.stonebrick, 0);
		setBlock(world, i + 16, j + 15, k + 28, Blocks.stonebrick, 0);
		setBlock(world, i + 16, j + 15, k + 29, Blocks.stone_brick_stairs, 0);
		setBlock(world, i + 16, j + 16, k + 19, Blocks.stone_brick_stairs, 0);
		setBlock(world, i + 16, j + 16, k + 20, Blocks.stonebrick, 0);
		setBlock(world, i + 16, j + 16, k + 21, Blocks.stonebrick, 0);
		setBlock(world, i + 16, j + 16, k + 26, Blocks.stonebrick, 0);
		setBlock(world, i + 16, j + 16, k + 27, Blocks.stonebrick, 0);
		setBlock(world, i + 16, j + 16, k + 28, Blocks.stone_brick_stairs, 0);
		setBlock(world, i + 17, j + 1, k + 9, Blocks.stonebrick, 0);
		setBlock(world, i + 17, j + 1, k + 37, Blocks.stonebrick, 0);
		setBlock(world, i + 17, j + 2, k + 11, Blocks.stonebrick, 0);
		setBlock(world, i + 17, j + 3, k + 11, Blocks.stonebrick, 0);
		setBlock(world, i + 17, j + 3, k + 35, Blocks.stonebrick, 0);
		setBlock(world, i + 17, j + 3, k + 36, Blocks.stonebrick, 0);
		setBlock(world, i + 17, j + 3, k + 37, Blocks.stonebrick, 0);
		setBlock(world, i + 17, j + 4, k + 11, Blocks.stonebrick, 0);
		setBlock(world, i + 17, j + 5, k + 12, Blocks.stonebrick, 0);
		setBlock(world, i + 17, j + 5, k + 36, Blocks.stonebrick, 0);
		setBlock(world, i + 17, j + 6, k + 13, Blocks.stonebrick, 0);
		setBlock(world, i + 17, j + 6, k + 34, Blocks.stonebrick, 0);
		setBlock(world, i + 17, j + 6, k + 35, Blocks.stonebrick, 0);
		setBlock(world, i + 17, j + 7, k + 13, Blocks.stonebrick, 0);
		setBlock(world, i + 17, j + 7, k + 14, Blocks.stonebrick, 0);
		setBlock(world, i + 17, j + 7, k + 34, Blocks.stonebrick, 0);
		setBlock(world, i + 17, j + 9, k + 13, Blocks.stonebrick, 0);
		setBlock(world, i + 17, j + 9, k + 14, Blocks.stonebrick, 0);
		setBlock(world, i + 17, j + 9, k + 34, Blocks.stonebrick, 0);
		setBlock(world, i + 17, j + 10, k + 15, Blocks.stonebrick, 0);
		setBlock(world, i + 17, j + 11, k + 15, Blocks.stonebrick, 0);
		setBlock(world, i + 17, j + 11, k + 22, Blocks.stonebrick, 0);
		setBlock(world, i + 17, j + 12, k + 17, Blocks.stonebrick, 0);
		setBlock(world, i + 17, j + 12, k + 18, Blocks.stonebrick, 0);
		setBlock(world, i + 17, j + 12, k + 23, Blocks.stonebrick, 0);
		setBlock(world, i + 17, j + 12, k + 29, Blocks.stonebrick, 0);
		setBlock(world, i + 17, j + 12, k + 30, Blocks.stonebrick, 0);
		setBlock(world, i + 17, j + 13, k + 15, Blocks.stonebrick, 0);
		setBlock(world, i + 17, j + 13, k + 17, Blocks.stonebrick, 0);
		setBlock(world, i + 17, j + 13, k + 22, Blocks.stonebrick, 0);
		setBlock(world, i + 17, j + 13, k + 24, Blocks.stonebrick, 0);
		setBlock(world, i + 17, j + 13, k + 26, Blocks.stonebrick, 0);
		setBlock(world, i + 17, j + 13, k + 29, Blocks.stonebrick, 0);
		setBlock(world, i + 17, j + 13, k + 30, Blocks.stonebrick, 0);
		setBlock(world, i + 17, j + 14, k + 16, Blocks.stone_brick_stairs, 0);
		setBlock(world, i + 17, j + 14, k + 17, Blocks.stonebrick, 0);
		setBlock(world, i + 17, j + 14, k + 18, Blocks.stonebrick, 0);
		setBlock(world, i + 17, j + 14, k + 19, Blocks.stonebrick, 0);
		setBlock(world, i + 17, j + 14, k + 20, Blocks.stonebrick, 0);
		setBlock(world, i + 17, j + 14, k + 21, Blocks.stonebrick, 0);
		setBlock(world, i + 17, j + 14, k + 22, Blocks.stonebrick, 0);
		setBlock(world, i + 17, j + 14, k + 23, Blocks.stonebrick, 0);
		setBlock(world, i + 17, j + 14, k + 24, Blocks.stonebrick, 0);
		setBlock(world, i + 17, j + 14, k + 25, Blocks.stonebrick, 0);
		setBlock(world, i + 17, j + 14, k + 26, Blocks.stonebrick, 0);
		setBlock(world, i + 17, j + 14, k + 27, Blocks.stonebrick, 0);
		setBlock(world, i + 17, j + 14, k + 28, Blocks.stonebrick, 0);
		setBlock(world, i + 17, j + 14, k + 29, Blocks.stonebrick, 0);
		setBlock(world, i + 17, j + 14, k + 30, Blocks.stonebrick, 0);
		setBlock(world, i + 17, j + 14, k + 31, Blocks.stone_brick_stairs, 0);
		setBlock(world, i + 17, j + 15, k + 17, Blocks.stonebrick, 0);
		setBlock(world, i + 17, j + 15, k + 18, Blocks.stonebrick, 0);
		setBlock(world, i + 17, j + 15, k + 19, Blocks.stonebrick, 0);
		setBlock(world, i + 17, j + 15, k + 20, Blocks.stonebrick, 0);
		setBlock(world, i + 17, j + 15, k + 21, Blocks.stonebrick, 0);
		setBlock(world, i + 17, j + 15, k + 26, Blocks.stonebrick, 0);
		setBlock(world, i + 17, j + 15, k + 27, Blocks.stonebrick, 0);
		setBlock(world, i + 17, j + 15, k + 28, Blocks.stonebrick, 0);
		setBlock(world, i + 17, j + 15, k + 29, Blocks.stonebrick, 0);
		setBlock(world, i + 17, j + 15, k + 30, Blocks.stonebrick, 0);
		setBlock(world, i + 17, j + 16, k + 18, Blocks.stone_brick_stairs, 0);
		setBlock(world, i + 17, j + 16, k + 19, Blocks.stonebrick, 0);
		setBlock(world, i + 17, j + 16, k + 20, Blocks.stonebrick, 0);
		setBlock(world, i + 17, j + 16, k + 21, Blocks.stonebrick, 0);
		setBlock(world, i + 17, j + 16, k + 26, Blocks.stonebrick, 0);
		setBlock(world, i + 17, j + 16, k + 27, Blocks.stonebrick, 0);
		setBlock(world, i + 17, j + 16, k + 28, Blocks.stonebrick, 0);
		setBlock(world, i + 17, j + 16, k + 29, Blocks.stone_brick_stairs, 0);
		setBlock(world, i + 17, j + 17, k + 19, Blocks.stone_brick_stairs, 0);
		setBlock(world, i + 17, j + 17, k + 20, Blocks.stonebrick, 0);
		setBlock(world, i + 17, j + 17, k + 21, Blocks.stonebrick, 0);
		setBlock(world, i + 17, j + 17, k + 26, Blocks.stonebrick, 0);
		setBlock(world, i + 17, j + 17, k + 27, Blocks.stonebrick, 0);
		setBlock(world, i + 17, j + 17, k + 28, Blocks.stone_brick_stairs, 0);
		setBlock(world, i + 18, j + 0, k + 20, Blocks.stonebrick, 0);
		setBlock(world, i + 18, j + 1, k + 20, Blocks.stonebrick, 0);
		setBlock(world, i + 18, j + 1, k + 37, Blocks.stonebrick, 0);
		setBlock(world, i + 18, j + 3, k + 10, Blocks.stonebrick, 0);
		setBlock(world, i + 18, j + 3, k + 11, Blocks.stonebrick, 0);
		setBlock(world, i + 18, j + 3, k + 36, Blocks.stonebrick, 0);
		setBlock(world, i + 18, j + 4, k + 11, Blocks.stonebrick, 0);
		setBlock(world, i + 18, j + 4, k + 35, Blocks.stonebrick, 0);
		setBlock(world, i + 18, j + 5, k + 12, Blocks.stonebrick, 0);
		setBlock(world, i + 18, j + 6, k + 34, Blocks.stonebrick, 0);
		setBlock(world, i + 18, j + 7, k + 12, Blocks.stonebrick, 0);
		setBlock(world, i + 18, j + 7, k + 13, Blocks.stonebrick, 0);
		setBlock(world, i + 18, j + 8, k + 13, Blocks.stonebrick, 0);
		setBlock(world, i + 18, j + 8, k + 14, Blocks.stonebrick, 0);
		setBlock(world, i + 18, j + 8, k + 34, Blocks.stonebrick, 0);
		setBlock(world, i + 18, j + 9, k + 13, Blocks.stonebrick, 0);
		setBlock(world, i + 18, j + 9, k + 14, Blocks.stonebrick, 0);
		setBlock(world, i + 18, j + 10, k + 14, Blocks.stonebrick, 0);
		setBlock(world, i + 18, j + 10, k + 15, Blocks.stonebrick, 0);
		setBlock(world, i + 18, j + 11, k + 16, Blocks.stonebrick, 0);
		setBlock(world, i + 18, j + 12, k + 17, Blocks.stonebrick, 0);
		setBlock(world, i + 18, j + 12, k + 18, Blocks.stonebrick, 0);
		setBlock(world, i + 18, j + 12, k + 22, Blocks.stonebrick, 0);
		setBlock(world, i + 18, j + 12, k + 29, Blocks.stonebrick, 0);
		setBlock(world, i + 18, j + 12, k + 30, Blocks.stonebrick, 0);
		setBlock(world, i + 18, j + 13, k + 17, Blocks.stonebrick, 0);
		setBlock(world, i + 18, j + 13, k + 23, Blocks.stonebrick, 0);
		setBlock(world, i + 18, j + 14, k + 15, Blocks.stone_brick_stairs, 0);
		setBlock(world, i + 18, j + 14, k + 16, Blocks.stonebrick, 0);
		setBlock(world, i + 18, j + 14, k + 17, Blocks.stonebrick, 0);
		setBlock(world, i + 18, j + 14, k + 18, Blocks.stonebrick, 0);
		setBlock(world, i + 18, j + 14, k + 19, Blocks.stonebrick, 0);
		setBlock(world, i + 18, j + 14, k + 20, Blocks.stonebrick, 0);
		setBlock(world, i + 18, j + 14, k + 21, Blocks.stonebrick, 0);
		setBlock(world, i + 18, j + 14, k + 26, Blocks.stonebrick, 0);
		setBlock(world, i + 18, j + 14, k + 27, Blocks.stonebrick, 0);
		setBlock(world, i + 18, j + 14, k + 28, Blocks.stonebrick, 0);
		setBlock(world, i + 18, j + 14, k + 29, Blocks.stonebrick, 0);
		setBlock(world, i + 18, j + 14, k + 30, Blocks.stonebrick, 0);
		setBlock(world, i + 18, j + 14, k + 31, Blocks.stonebrick, 0);
		setBlock(world, i + 18, j + 14, k + 32, Blocks.stone_brick_stairs, 0);
		setBlock(world, i + 18, j + 15, k + 17, Blocks.stonebrick, 0);
		setBlock(world, i + 18, j + 15, k + 18, Blocks.stonebrick, 0);
		setBlock(world, i + 18, j + 15, k + 19, Blocks.stonebrick, 0);
		setBlock(world, i + 18, j + 15, k + 20, Blocks.stonebrick, 0);
		setBlock(world, i + 18, j + 15, k + 21, Blocks.stonebrick, 0);
		setBlock(world, i + 18, j + 15, k + 26, Blocks.stonebrick, 0);
		setBlock(world, i + 18, j + 15, k + 27, Blocks.stonebrick, 0);
		setBlock(world, i + 18, j + 15, k + 28, Blocks.stonebrick, 0);
		setBlock(world, i + 18, j + 15, k + 29, Blocks.stonebrick, 0);
		setBlock(world, i + 18, j + 15, k + 30, Blocks.stonebrick, 0);
		setBlock(world, i + 18, j + 16, k + 18, Blocks.stonebrick, 0);
		setBlock(world, i + 18, j + 16, k + 19, Blocks.stonebrick, 0);
		setBlock(world, i + 18, j + 16, k + 20, Blocks.stonebrick, 0);
		setBlock(world, i + 18, j + 16, k + 21, Blocks.stonebrick, 0);
		setBlock(world, i + 18, j + 16, k + 26, Blocks.stonebrick, 0);
		setBlock(world, i + 18, j + 16, k + 27, Blocks.stonebrick, 0);
		setBlock(world, i + 18, j + 16, k + 28, Blocks.stonebrick, 0);
		setBlock(world, i + 18, j + 16, k + 29, Blocks.stonebrick, 0);
		setBlock(world, i + 18, j + 17, k + 18, Blocks.stonebrick, 0);
		setBlock(world, i + 18, j + 17, k + 19, Blocks.stonebrick, 0);
		setBlock(world, i + 18, j + 17, k + 20, Blocks.stonebrick, 0);
		setBlock(world, i + 18, j + 17, k + 21, Blocks.stonebrick, 0);
		setBlock(world, i + 18, j + 17, k + 26, Blocks.stonebrick, 0);
		setBlock(world, i + 18, j + 17, k + 27, Blocks.stonebrick, 0);
		setBlock(world, i + 18, j + 17, k + 28, Blocks.stonebrick, 0);
		setBlock(world, i + 18, j + 17, k + 29, Blocks.stonebrick, 0);
		setBlock(world, i + 18, j + 18, k + 19, Blocks.stone_brick_stairs, 0);
		setBlock(world, i + 18, j + 18, k + 20, Blocks.stonebrick, 0);
		setBlock(world, i + 18, j + 18, k + 21, Blocks.stonebrick, 0);
		setBlock(world, i + 18, j + 18, k + 26, Blocks.stonebrick, 0);
		setBlock(world, i + 18, j + 18, k + 27, Blocks.stonebrick, 0);
		setBlock(world, i + 18, j + 18, k + 28, Blocks.stone_brick_stairs, 0);
		setBlock(world, i + 19, j + 0, k + 20, Blocks.stonebrick, 0);
		setBlock(world, i + 19, j + 1, k + 9, Blocks.stonebrick, 0);
		setBlock(world, i + 19, j + 1, k + 20, Blocks.stonebrick, 0);
		setBlock(world, i + 19, j + 2, k + 11, Blocks.stonebrick, 0);
		setBlock(world, i + 19, j + 2, k + 37, Blocks.stonebrick, 0);
		setBlock(world, i + 19, j + 3, k + 11, Blocks.stonebrick, 0);
		setBlock(world, i + 19, j + 3, k + 35, Blocks.stonebrick, 0);
		setBlock(world, i + 19, j + 3, k + 37, Blocks.stonebrick, 0);
		setBlock(world, i + 19, j + 5, k + 13, Blocks.stonebrick, 0);
		setBlock(world, i + 19, j + 6, k + 12, Blocks.stonebrick, 0);
		/* 1000 */setBlock(world, i + 19, j + 7, k + 34, Blocks.stonebrick, 0);
		/* 1001 */setBlock(world, i + 19, j + 8, k + 14, Blocks.stonebrick, 0);
		/* 1002 */setBlock(world, i + 19, j + 10, k + 15, Blocks.stonebrick, 0);
		/* 1003 */setBlock(world, i + 19, j + 11, k + 24, Blocks.stonebrick, 0);
		/* 1004 */setBlock(world, i + 19, j + 12, k + 25, Blocks.stonebrick, 0);
		/* 1005 */setBlock(world, i + 19, j + 13, k + 20, Blocks.stonebrick, 0);
		/* 1006 */setBlock(world, i + 19, j + 13, k + 27, Blocks.stonebrick, 0);
		/* 1007 */setBlock(world, i + 19, j + 13, k + 31, Blocks.stonebrick, 0);
		/* 1008 */setBlock(world, i + 19, j + 13, k + 32, Blocks.stonebrick, 0);
		/* 1009 */setBlock(world, i + 19, j + 14, k + 15, Blocks.stonebrick, 0);
		/* 1010 */setBlock(world, i + 19, j + 14, k + 16, Blocks.stonebrick, 0);
		/* 1011 */setBlock(world, i + 19, j + 14, k + 17, Blocks.stonebrick, 0);
		/* 1012 */setBlock(world, i + 19, j + 14, k + 18, Blocks.stonebrick, 0);
		/* 1013 */setBlock(world, i + 19, j + 14, k + 21, Blocks.stonebrick, 0);
		/* 1014 */setBlock(world, i + 19, j + 14, k + 27, Blocks.stonebrick, 0);
		/* 1015 */setBlock(world, i + 19, j + 14, k + 29, Blocks.stonebrick, 0);
		/* 1016 */setBlock(world, i + 19, j + 14, k + 30, Blocks.stonebrick, 0);
		/* 1017 */setBlock(world, i + 19, j + 14, k + 31, Blocks.stonebrick, 0);
		/* 1018 */setBlock(world, i + 19, j + 14, k + 32, Blocks.stonebrick, 0);
		/* 1019 */setBlock(world, i + 19, j + 15, k + 16, Blocks.stonebrick, 0);
		/* 1020 */setBlock(world, i + 19, j + 15, k + 17, Blocks.stonebrick, 0);
		/* 1021 */setBlock(world, i + 19, j + 15, k + 18, Blocks.stonebrick, 0);
		/* 1022 */setBlock(world, i + 19, j + 15, k + 19, Blocks.stonebrick, 0);
		/* 1023 */setBlock(world, i + 19, j + 15, k + 21, Blocks.stonebrick, 0);
		/* 1024 */setBlock(world, i + 19, j + 15, k + 28, Blocks.stonebrick, 0);
		/* 1025 */setBlock(world, i + 19, j + 15, k + 29, Blocks.stonebrick, 0);
		/* 1026 */setBlock(world, i + 19, j + 15, k + 30, Blocks.stonebrick, 0);
		/* 1027 */setBlock(world, i + 19, j + 15, k + 31, Blocks.stonebrick, 0);
		/* 1028 */setBlock(world, i + 19, j + 16, k + 17, Blocks.stonebrick, 0);
		/* 1029 */setBlock(world, i + 19, j + 16, k + 18, Blocks.stonebrick, 0);
		/* 1030 */setBlock(world, i + 19, j + 16, k + 20, Blocks.stonebrick, 0);
		/* 1031 */setBlock(world, i + 19, j + 16, k + 21, Blocks.stonebrick, 0);
		/* 1032 */setBlock(world, i + 19, j + 16, k + 29, Blocks.stonebrick, 0);
		/* 1033 */setBlock(world, i + 19, j + 16, k + 30, Blocks.stonebrick, 0);
		/* 1034 */setBlock(world, i + 19, j + 17, k + 18, Blocks.stonebrick, 0);
		/* 1035 */setBlock(world, i + 19, j + 17, k + 20, Blocks.stonebrick, 0);
		/* 1036 */setBlock(world, i + 19, j + 17, k + 29, Blocks.stonebrick, 0);
		/* 1037 */setBlock(world, i + 19, j + 18, k + 20, Blocks.stonebrick, 0);
		/* 1038 */setBlock(world, i + 19, j + 19, k + 21, Blocks.stonebrick, 0);
		/* 1039 */setBlock(world, i + 19, j + 19, k + 22, Blocks.stonebrick, 0);
		/* 1040 */setBlock(world, i + 19, j + 19, k + 26, Blocks.stonebrick, 0);
		/* 1041 */setBlock(world, i + 19, j + 19, k + 27, Blocks.stonebrick, 0);
		/* 1042 */setBlock(world, i + 20, j + 0, k + 0, Blocks.stonebrick, 0);
		/* 1043 */setBlock(world, i + 20, j + 0, k + 1, Blocks.stonebrick, 0);
		/* 1044 */setBlock(world, i + 20, j + 0, k + 2, Blocks.stonebrick, 0);
		/* 1045 */setBlock(world, i + 20, j + 0, k + 3, Blocks.stonebrick, 0);
		/* 1046 */setBlock(world, i + 20, j + 0, k + 4, Blocks.stonebrick, 0);
		/* 1047 */setBlock(world, i + 20, j + 0, k + 5, Blocks.stonebrick, 0);
		/* 1048 */setBlock(world, i + 20, j + 0, k + 6, Blocks.stonebrick, 0);
		/* 1049 */setBlock(world, i + 20, j + 0, k + 7, Blocks.stonebrick, 0);
		/* 1050 */setBlock(world, i + 20, j + 0, k + 8, Blocks.stonebrick, 0);
		/* 1051 */setBlock(world, i + 20, j + 0, k + 18, Blocks.stonebrick, 0);
		/* 1052 */setBlock(world, i + 20, j + 0, k + 19, Blocks.stonebrick, 0);
		/* 1053 */setBlock(world, i + 20, j + 0, k + 39, Blocks.stonebrick, 0);
		/* 1054 */setBlock(world, i + 20, j + 0, k + 40, Blocks.stonebrick, 0);
		/* 1055 */setBlock(world, i + 20, j + 0, k + 41, Blocks.stonebrick, 0);
		/* 1056 */setBlock(world, i + 20, j + 0, k + 42, Blocks.stonebrick, 0);
		/* 1057 */setBlock(world, i + 20, j + 0, k + 43, Blocks.stonebrick, 0);
		/* 1058 */setBlock(world, i + 20, j + 0, k + 44, Blocks.stonebrick, 0);
		/* 1059 */setBlock(world, i + 20, j + 0, k + 45, Blocks.stonebrick, 0);
		/* 1060 */setBlock(world, i + 20, j + 0, k + 46, Blocks.stonebrick, 0);
		/* 1061 */setBlock(world, i + 20, j + 0, k + 47, Blocks.stonebrick, 0);
		/* 1062 */setBlock(world, i + 20, j + 1, k + 1, Blocks.stonebrick, 0);
		/* 1063 */setBlock(world, i + 20, j + 1, k + 2, Blocks.stonebrick, 0);
		/* 1064 */setBlock(world, i + 20, j + 1, k + 3, Blocks.stonebrick, 0);
		/* 1065 */setBlock(world, i + 20, j + 1, k + 4, Blocks.stonebrick, 0);
		/* 1066 */setBlock(world, i + 20, j + 1, k + 5, Blocks.stonebrick, 0);
		/* 1067 */setBlock(world, i + 20, j + 1, k + 6, Blocks.stonebrick, 0);
		/* 1068 */setBlock(world, i + 20, j + 1, k + 7, Blocks.stonebrick, 0);
		/* 1069 */setBlock(world, i + 20, j + 1, k + 8, Blocks.stonebrick, 0);
		/* 1070 */setBlock(world, i + 20, j + 1, k + 10, Blocks.stonebrick, 0);
		/* 1071 */setBlock(world, i + 20, j + 1, k + 18, Blocks.stonebrick, 0);
		/* 1072 */setBlock(world, i + 20, j + 1, k + 19, Blocks.stonebrick, 0);
		/* 1073 */setBlock(world, i + 20, j + 1, k + 39, Blocks.stonebrick, 0);
		/* 1074 */setBlock(world, i + 20, j + 1, k + 40, Blocks.stonebrick, 0);
		/* 1075 */setBlock(world, i + 20, j + 1, k + 41, Blocks.stonebrick, 0);
		/* 1076 */setBlock(world, i + 20, j + 1, k + 42, Blocks.stonebrick, 0);
		/* 1077 */setBlock(world, i + 20, j + 1, k + 43, Blocks.stonebrick, 0);
		/* 1078 */setBlock(world, i + 20, j + 1, k + 44, Blocks.stonebrick, 0);
		/* 1079 */setBlock(world, i + 20, j + 1, k + 45, Blocks.stonebrick, 0);
		/* 1080 */setBlock(world, i + 20, j + 1, k + 46, Blocks.stonebrick, 0);
		/* 1081 */setBlock(world, i + 20, j + 2, k + 2, Blocks.stonebrick, 0);
		/* 1082 */setBlock(world, i + 20, j + 2, k + 3, Blocks.stonebrick, 0);
		/* 1083 */setBlock(world, i + 20, j + 2, k + 4, Blocks.stonebrick, 0);
		/* 1084 */setBlock(world, i + 20, j + 2, k + 5, Blocks.stonebrick, 0);
		/* 1085 */setBlock(world, i + 20, j + 2, k + 6, Blocks.stonebrick, 0);
		/* 1086 */setBlock(world, i + 20, j + 2, k + 7, Blocks.stonebrick, 0);
		/* 1087 */setBlock(world, i + 20, j + 2, k + 8, Blocks.stonebrick, 0);
		/* 1088 */setBlock(world, i + 20, j + 2, k + 9, Blocks.stonebrick, 0);
		/* 1089 */setBlock(world, i + 20, j + 2, k + 10, Blocks.stonebrick, 0);
		/* 1090 */setBlock(world, i + 20, j + 2, k + 36, Blocks.stonebrick, 0);
		/* 1091 */setBlock(world, i + 20, j + 2, k + 38, Blocks.stonebrick, 0);
		/* 1092 */setBlock(world, i + 20, j + 2, k + 39, Blocks.stonebrick, 0);
		/* 1093 */setBlock(world, i + 20, j + 2, k + 40, Blocks.stonebrick, 0);
		/* 1094 */setBlock(world, i + 20, j + 2, k + 41, Blocks.stonebrick, 0);
		/* 1095 */setBlock(world, i + 20, j + 2, k + 42, Blocks.stonebrick, 0);
		/* 1096 */setBlock(world, i + 20, j + 2, k + 43, Blocks.stonebrick, 0);
		/* 1097 */setBlock(world, i + 20, j + 2, k + 44, Blocks.stonebrick, 0);
		/* 1098 */setBlock(world, i + 20, j + 2, k + 45, Blocks.stonebrick, 0);
		/* 1099 */setBlock(world, i + 20, j + 3, k + 3, Blocks.stonebrick, 0);
		/* 1100 */setBlock(world, i + 20, j + 3, k + 4, Blocks.stonebrick, 0);
		/* 1101 */setBlock(world, i + 20, j + 3, k + 5, Blocks.stonebrick, 0);
		/* 1102 */setBlock(world, i + 20, j + 3, k + 6, Blocks.stonebrick, 0);
		/* 1103 */setBlock(world, i + 20, j + 3, k + 7, Blocks.stonebrick, 0);
		/* 1104 */setBlock(world, i + 20, j + 3, k + 8, Blocks.stonebrick, 0);
		/* 1105 */setBlock(world, i + 20, j + 3, k + 9, Blocks.stonebrick, 0);
		/* 1106 */setBlock(world, i + 20, j + 3, k + 10, Blocks.stonebrick, 0);
		/* 1107 */setBlock(world, i + 20, j + 3, k + 11, Blocks.stonebrick, 0);
		/* 1108 */setBlock(world, i + 20, j + 3, k + 38, Blocks.stonebrick, 0);
		/* 1109 */setBlock(world, i + 20, j + 3, k + 39, Blocks.stonebrick, 0);
		/* 1110 */setBlock(world, i + 20, j + 3, k + 40, Blocks.stonebrick, 0);
		/* 1111 */setBlock(world, i + 20, j + 3, k + 41, Blocks.stonebrick, 0);
		/* 1112 */setBlock(world, i + 20, j + 3, k + 42, Blocks.stonebrick, 0);
		/* 1113 */setBlock(world, i + 20, j + 3, k + 43, Blocks.stonebrick, 0);
		/* 1114 */setBlock(world, i + 20, j + 3, k + 44, Blocks.stonebrick, 0);
		/* 1115 */setBlock(world, i + 20, j + 4, k + 4, Blocks.stonebrick, 0);
		/* 1116 */setBlock(world, i + 20, j + 4, k + 5, Blocks.stonebrick, 0);
		/* 1117 */setBlock(world, i + 20, j + 4, k + 6, Blocks.stonebrick, 0);
		/* 1118 */setBlock(world, i + 20, j + 4, k + 7, Blocks.stonebrick, 0);
		/* 1119 */setBlock(world, i + 20, j + 4, k + 8, Blocks.stonebrick, 0);
		/* 1120 */setBlock(world, i + 20, j + 4, k + 9, Blocks.stonebrick, 0);
		/* 1121 */setBlock(world, i + 20, j + 4, k + 10, Blocks.stonebrick, 0);
		/* 1122 */setBlock(world, i + 20, j + 4, k + 36, Blocks.stonebrick, 0);
		/* 1123 */setBlock(world, i + 20, j + 4, k + 37, Blocks.stonebrick, 0);
		/* 1124 */setBlock(world, i + 20, j + 4, k + 38, Blocks.stonebrick, 0);
		/* 1125 */setBlock(world, i + 20, j + 4, k + 39, Blocks.stonebrick, 0);
		/* 1126 */setBlock(world, i + 20, j + 4, k + 40, Blocks.stonebrick, 0);
		/* 1127 */setBlock(world, i + 20, j + 4, k + 41, Blocks.stonebrick, 0);
		/* 1128 */setBlock(world, i + 20, j + 4, k + 42, Blocks.stonebrick, 0);
		/* 1129 */setBlock(world, i + 20, j + 4, k + 43, Blocks.stonebrick, 0);
		/* 1130 */setBlock(world, i + 20, j + 5, k + 5, Blocks.stonebrick, 0);
		/* 1131 */setBlock(world, i + 20, j + 5, k + 6, Blocks.stonebrick, 0);
		/* 1132 */setBlock(world, i + 20, j + 5, k + 7, Blocks.stonebrick, 0);
		/* 1133 */setBlock(world, i + 20, j + 5, k + 8, Blocks.stonebrick, 0);
		/* 1134 */setBlock(world, i + 20, j + 5, k + 9, Blocks.stonebrick, 0);
		/* 1135 */setBlock(world, i + 20, j + 5, k + 10, Blocks.stonebrick, 0);
		/* 1136 */setBlock(world, i + 20, j + 5, k + 13, Blocks.stonebrick, 0);
		/* 1137 */setBlock(world, i + 20, j + 5, k + 36, Blocks.stonebrick, 0);
		/* 1138 */setBlock(world, i + 20, j + 5, k + 37, Blocks.stonebrick, 0);
		/* 1139 */setBlock(world, i + 20, j + 5, k + 38, Blocks.stonebrick, 0);
		/* 1140 */setBlock(world, i + 20, j + 5, k + 39, Blocks.stonebrick, 0);
		/* 1141 */setBlock(world, i + 20, j + 5, k + 40, Blocks.stonebrick, 0);
		/* 1142 */setBlock(world, i + 20, j + 5, k + 41, Blocks.stonebrick, 0);
		/* 1143 */setBlock(world, i + 20, j + 5, k + 42, Blocks.stonebrick, 0);
		/* 1144 */setBlock(world, i + 20, j + 6, k + 6, Blocks.stonebrick, 0);
		/* 1145 */setBlock(world, i + 20, j + 6, k + 7, Blocks.stonebrick, 0);
		/* 1146 */setBlock(world, i + 20, j + 6, k + 8, Blocks.stonebrick, 0);
		/* 1147 */setBlock(world, i + 20, j + 6, k + 9, Blocks.stonebrick, 0);
		/* 1148 */setBlock(world, i + 20, j + 6, k + 10, Blocks.stonebrick, 0);
		/* 1149 */setBlock(world, i + 20, j + 6, k + 11, Blocks.stonebrick, 0);
		/* 1150 */setBlock(world, i + 20, j + 6, k + 12, Blocks.stonebrick, 0);
		/* 1151 */setBlock(world, i + 20, j + 6, k + 36, Blocks.stonebrick, 0);
		/* 1152 */setBlock(world, i + 20, j + 6, k + 37, Blocks.stonebrick, 0);
		/* 1153 */setBlock(world, i + 20, j + 6, k + 38, Blocks.stonebrick, 0);
		/* 1154 */setBlock(world, i + 20, j + 6, k + 39, Blocks.stonebrick, 0);
		/* 1155 */setBlock(world, i + 20, j + 6, k + 40, Blocks.stonebrick, 0);
		/* 1156 */setBlock(world, i + 20, j + 6, k + 41, Blocks.stonebrick, 0);
		/* 1157 */setBlock(world, i + 20, j + 7, k + 7, Blocks.stonebrick, 0);
		/* 1158 */setBlock(world, i + 20, j + 7, k + 8, Blocks.stonebrick, 0);
		/* 1159 */setBlock(world, i + 20, j + 7, k + 9, Blocks.stonebrick, 0);
		/* 1160 */setBlock(world, i + 20, j + 7, k + 10, Blocks.stonebrick, 0);
		/* 1161 */setBlock(world, i + 20, j + 7, k + 11, Blocks.stonebrick, 0);
		/* 1162 */setBlock(world, i + 20, j + 7, k + 14, Blocks.stonebrick, 0);
		/* 1163 */setBlock(world, i + 20, j + 7, k + 34, Blocks.stonebrick, 0);
		/* 1164 */setBlock(world, i + 20, j + 7, k + 36, Blocks.stonebrick, 0);
		/* 1165 */setBlock(world, i + 20, j + 7, k + 37, Blocks.stonebrick, 0);
		/* 1166 */setBlock(world, i + 20, j + 7, k + 38, Blocks.stonebrick, 0);
		/* 1167 */setBlock(world, i + 20, j + 7, k + 39, Blocks.stonebrick, 0);
		/* 1168 */setBlock(world, i + 20, j + 7, k + 40, Blocks.stonebrick, 0);
		/* 1169 */setBlock(world, i + 20, j + 8, k + 8, Blocks.stonebrick, 0);
		/* 1170 */setBlock(world, i + 20, j + 8, k + 9, Blocks.stonebrick, 0);
		/* 1171 */setBlock(world, i + 20, j + 8, k + 10, Blocks.stonebrick, 0);
		/* 1172 */setBlock(world, i + 20, j + 8, k + 11, Blocks.stonebrick, 0);
		/* 1173 */setBlock(world, i + 20, j + 8, k + 12, Blocks.stonebrick, 0);
		/* 1174 */setBlock(world, i + 20, j + 8, k + 35, Blocks.stonebrick, 0);
		/* 1175 */setBlock(world, i + 20, j + 8, k + 36, Blocks.stonebrick, 0);
		/* 1176 */setBlock(world, i + 20, j + 8, k + 37, Blocks.stonebrick, 0);
		/* 1177 */setBlock(world, i + 20, j + 8, k + 38, Blocks.stonebrick, 0);
		/* 1178 */setBlock(world, i + 20, j + 8, k + 39, Blocks.stonebrick, 0);
		/* 1179 */setBlock(world, i + 20, j + 9, k + 9, Blocks.stonebrick, 0);
		/* 1180 */setBlock(world, i + 20, j + 9, k + 10, Blocks.stonebrick, 0);
		/* 1181 */setBlock(world, i + 20, j + 9, k + 11, Blocks.stonebrick, 0);
		/* 1182 */setBlock(world, i + 20, j + 9, k + 12, Blocks.stonebrick, 0);
		/* 1183 */setBlock(world, i + 20, j + 9, k + 15, Blocks.stonebrick, 0);
		/* 1184 */setBlock(world, i + 20, j + 9, k + 35, Blocks.stonebrick, 0);
		/* 1185 */setBlock(world, i + 20, j + 9, k + 36, Blocks.stonebrick, 0);
		/* 1186 */setBlock(world, i + 20, j + 9, k + 37, Blocks.stonebrick, 0);
		/* 1187 */setBlock(world, i + 20, j + 9, k + 38, Blocks.stonebrick, 0);
		/* 1188 */setBlock(world, i + 20, j + 10, k + 10, Blocks.stonebrick, 0);
		/* 1189 */setBlock(world, i + 20, j + 10, k + 11, Blocks.stonebrick, 0);
		/* 1190 */setBlock(world, i + 20, j + 10, k + 12, Blocks.stonebrick, 0);
		/* 1191 */setBlock(world, i + 20, j + 10, k + 13, Blocks.stonebrick, 0);
		/* 1192 */setBlock(world, i + 20, j + 10, k + 14, Blocks.stonebrick, 0);
		/* 1193 */setBlock(world, i + 20, j + 10, k + 15, Blocks.stonebrick, 0);
		/* 1194 */setBlock(world, i + 20, j + 10, k + 34, Blocks.stonebrick, 0);
		/* 1195 */setBlock(world, i + 20, j + 10, k + 35, Blocks.stonebrick, 0);
		/* 1196 */setBlock(world, i + 20, j + 10, k + 36, Blocks.stonebrick, 0);
		/* 1197 */setBlock(world, i + 20, j + 10, k + 37, Blocks.stonebrick, 0);
		/* 1198 */setBlock(world, i + 20, j + 11, k + 11, Blocks.stonebrick, 0);
		/* 1199 */setBlock(world, i + 20, j + 11, k + 12, Blocks.stonebrick, 0);
		/* 1200 */setBlock(world, i + 20, j + 11, k + 13, Blocks.stonebrick, 0);
		/* 1201 */setBlock(world, i + 20, j + 11, k + 32, Blocks.stonebrick, 0);
		/* 1202 */setBlock(world, i + 20, j + 11, k + 34, Blocks.stonebrick, 0);
		/* 1203 */setBlock(world, i + 20, j + 11, k + 35, Blocks.stonebrick, 0);
		/* 1204 */setBlock(world, i + 20, j + 11, k + 36, Blocks.stonebrick, 0);
		/* 1205 */setBlock(world, i + 20, j + 12, k + 12, Blocks.stonebrick, 0);
		/* 1206 */setBlock(world, i + 20, j + 12, k + 13, Blocks.stonebrick, 0);
		/* 1207 */setBlock(world, i + 20, j + 12, k + 14, Blocks.stonebrick, 0);
		/* 1208 */setBlock(world, i + 20, j + 12, k + 19, Blocks.stonebrick, 0);
		/* 1209 */setBlock(world, i + 20, j + 12, k + 33, Blocks.stonebrick, 0);
		/* 1210 */setBlock(world, i + 20, j + 12, k + 34, Blocks.stonebrick, 0);
		/* 1211 */setBlock(world, i + 20, j + 12, k + 35, Blocks.stonebrick, 0);
		/* 1212 */setBlock(world, i + 20, j + 13, k + 13, Blocks.stonebrick, 0);
		/* 1213 */setBlock(world, i + 20, j + 13, k + 14, Blocks.stonebrick, 0);
		/* 1214 */setBlock(world, i + 20, j + 13, k + 31, Blocks.stonebrick, 0);
		/* 1215 */setBlock(world, i + 20, j + 13, k + 32, Blocks.stonebrick, 0);
		/* 1216 */setBlock(world, i + 20, j + 13, k + 33, Blocks.stonebrick, 0);
		/* 1217 */setBlock(world, i + 20, j + 13, k + 34, Blocks.stonebrick, 0);
		/* 1218 */setBlock(world, i + 20, j + 14, k + 14, Blocks.stonebrick, 0);
		/* 1219 */setBlock(world, i + 20, j + 14, k + 15, Blocks.stonebrick, 0);
		/* 1220 */setBlock(world, i + 20, j + 14, k + 16, Blocks.stonebrick, 0);
		/* 1221 */setBlock(world, i + 20, j + 14, k + 17, Blocks.stonebrick, 0);
		/* 1222 */setBlock(world, i + 20, j + 14, k + 18, Blocks.stonebrick, 0);
		/* 1223 */setBlock(world, i + 20, j + 14, k + 29, Blocks.stonebrick, 0);
		/* 1224 */setBlock(world, i + 20, j + 14, k + 30, Blocks.stonebrick, 0);
		/* 1225 */setBlock(world, i + 20, j + 14, k + 31, Blocks.stonebrick, 0);
		/* 1226 */setBlock(world, i + 20, j + 14, k + 32, Blocks.stonebrick, 0);
		/* 1227 */setBlock(world, i + 20, j + 14, k + 33, Blocks.stonebrick, 0);
		/* 1228 */setBlock(world, i + 20, j + 15, k + 15, Blocks.stonebrick, 0);
		/* 1229 */setBlock(world, i + 20, j + 15, k + 16, Blocks.stonebrick, 0);
		/* 1230 */setBlock(world, i + 20, j + 15, k + 17, Blocks.stonebrick, 0);
		/* 1231 */setBlock(world, i + 20, j + 15, k + 18, Blocks.stonebrick, 0);
		/* 1232 */setBlock(world, i + 20, j + 15, k + 19, Blocks.stonebrick, 0);
		/* 1233 */setBlock(world, i + 20, j + 15, k + 28, Blocks.stonebrick, 0);
		/* 1234 */setBlock(world, i + 20, j + 15, k + 29, Blocks.stonebrick, 0);
		/* 1235 */setBlock(world, i + 20, j + 15, k + 30, Blocks.stonebrick, 0);
		/* 1236 */setBlock(world, i + 20, j + 15, k + 31, Blocks.stonebrick, 0);
		/* 1237 */setBlock(world, i + 20, j + 15, k + 32, Blocks.stonebrick, 0);
		/* 1238 */setBlock(world, i + 20, j + 16, k + 16, Blocks.stonebrick, 0);
		/* 1239 */setBlock(world, i + 20, j + 16, k + 17, Blocks.stonebrick, 0);
		/* 1240 */setBlock(world, i + 20, j + 16, k + 18, Blocks.stonebrick, 0);
		/* 1241 */setBlock(world, i + 20, j + 16, k + 19, Blocks.stonebrick, 0);
		/* 1242 */setBlock(world, i + 20, j + 16, k + 28, Blocks.stonebrick, 0);
		/* 1243 */setBlock(world, i + 20, j + 16, k + 29, Blocks.stonebrick, 0);
		/* 1244 */setBlock(world, i + 20, j + 16, k + 30, Blocks.stonebrick, 0);
		/* 1245 */setBlock(world, i + 20, j + 16, k + 31, Blocks.stonebrick, 0);
		/* 1246 */setBlock(world, i + 20, j + 17, k + 17, Blocks.stonebrick, 0);
		/* 1247 */setBlock(world, i + 20, j + 17, k + 18, Blocks.stonebrick, 0);
		/* 1248 */setBlock(world, i + 20, j + 17, k + 29, Blocks.stonebrick, 0);
		/* 1249 */setBlock(world, i + 20, j + 17, k + 30, Blocks.stonebrick, 0);
		/* 1250 */setBlock(world, i + 20, j + 18, k + 18, Blocks.stonebrick, 0);
		/* 1251 */setBlock(world, i + 20, j + 18, k + 29, Blocks.stonebrick, 0);
		/* 1252 */setBlock(world, i + 20, j + 19, k + 20, Blocks.stonebrick, 0);
		/* 1253 */setBlock(world, i + 20, j + 19, k + 26, Blocks.stonebrick, 0);
		/* 1254 */setBlock(world, i + 21, j + 0, k + 0, Blocks.stonebrick, 0);
		/* 1255 */setBlock(world, i + 21, j + 0, k + 1, Blocks.stonebrick, 0);
		/* 1256 */setBlock(world, i + 21, j + 0, k + 2, Blocks.stonebrick, 0);
		/* 1257 */setBlock(world, i + 21, j + 0, k + 3, Blocks.stonebrick, 0);
		/* 1258 */setBlock(world, i + 21, j + 0, k + 4, Blocks.stonebrick, 0);
		/* 1259 */setBlock(world, i + 21, j + 0, k + 5, Blocks.stonebrick, 0);
		/* 1260 */setBlock(world, i + 21, j + 0, k + 6, Blocks.stonebrick, 0);
		/* 1261 */setBlock(world, i + 21, j + 0, k + 7, Blocks.stonebrick, 0);
		/* 1262 */setBlock(world, i + 21, j + 0, k + 8, Blocks.stonebrick, 0);
		/* 1263 */setBlock(world, i + 21, j + 0, k + 9, Blocks.stonebrick, 0);
		/* 1264 */setBlock(world, i + 21, j + 0, k + 39, Blocks.stonebrick, 0);
		/* 1265 */setBlock(world, i + 21, j + 0, k + 40, Blocks.stonebrick, 0);
		/* 1266 */setBlock(world, i + 21, j + 0, k + 41, Blocks.stonebrick, 0);
		/* 1267 */setBlock(world, i + 21, j + 0, k + 42, Blocks.stonebrick, 0);
		/* 1268 */setBlock(world, i + 21, j + 0, k + 43, Blocks.stonebrick, 0);
		/* 1269 */setBlock(world, i + 21, j + 0, k + 44, Blocks.stonebrick, 0);
		/* 1270 */setBlock(world, i + 21, j + 0, k + 45, Blocks.stonebrick, 0);
		/* 1271 */setBlock(world, i + 21, j + 0, k + 46, Blocks.stonebrick, 0);
		/* 1272 */setBlock(world, i + 21, j + 0, k + 47, Blocks.stonebrick, 0);
		/* 1273 */setBlock(world, i + 21, j + 1, k + 1, Blocks.stonebrick, 0);
		/* 1274 */setBlock(world, i + 21, j + 1, k + 2, Blocks.stonebrick, 0);
		/* 1275 */setBlock(world, i + 21, j + 1, k + 3, Blocks.stonebrick, 0);
		/* 1276 */setBlock(world, i + 21, j + 1, k + 4, Blocks.stonebrick, 0);
		/* 1277 */setBlock(world, i + 21, j + 1, k + 5, Blocks.stonebrick, 0);
		/* 1278 */setBlock(world, i + 21, j + 1, k + 6, Blocks.stonebrick, 0);
		/* 1279 */setBlock(world, i + 21, j + 1, k + 7, Blocks.stonebrick, 0);
		/* 1280 */setBlock(world, i + 21, j + 1, k + 8, Blocks.stonebrick, 0);
		/* 1281 */setBlock(world, i + 21, j + 1, k + 9, Blocks.stonebrick, 0);
		/* 1282 */setBlock(world, i + 21, j + 1, k + 37, Blocks.stonebrick, 0);
		/* 1283 */setBlock(world, i + 21, j + 1, k + 39, Blocks.stonebrick, 0);
		/* 1284 */setBlock(world, i + 21, j + 1, k + 40, Blocks.stonebrick, 0);
		/* 1285 */setBlock(world, i + 21, j + 1, k + 41, Blocks.stonebrick, 0);
		/* 1286 */setBlock(world, i + 21, j + 1, k + 42, Blocks.stonebrick, 0);
		/* 1287 */setBlock(world, i + 21, j + 1, k + 43, Blocks.stonebrick, 0);
		/* 1288 */setBlock(world, i + 21, j + 1, k + 44, Blocks.stonebrick, 0);
		/* 1289 */setBlock(world, i + 21, j + 1, k + 45, Blocks.stonebrick, 0);
		/* 1290 */setBlock(world, i + 21, j + 1, k + 46, Blocks.stonebrick, 0);
		/* 1291 */setBlock(world, i + 21, j + 2, k + 2, Blocks.stonebrick, 0);
		/* 1292 */setBlock(world, i + 21, j + 2, k + 3, Blocks.stonebrick, 0);
		/* 1293 */setBlock(world, i + 21, j + 2, k + 4, Blocks.stonebrick, 0);
		/* 1294 */setBlock(world, i + 21, j + 2, k + 5, Blocks.stonebrick, 0);
		/* 1295 */setBlock(world, i + 21, j + 2, k + 6, Blocks.stonebrick, 0);
		/* 1296 */setBlock(world, i + 21, j + 2, k + 7, Blocks.stonebrick, 0);
		/* 1297 */setBlock(world, i + 21, j + 2, k + 8, Blocks.stonebrick, 0);
		/* 1298 */setBlock(world, i + 21, j + 2, k + 9, Blocks.stonebrick, 0);
		/* 1299 */setBlock(world, i + 21, j + 2, k + 10, Blocks.stonebrick, 0);
		/* 1300 */setBlock(world, i + 21, j + 2, k + 37, Blocks.stonebrick, 0);
		/* 1301 */setBlock(world, i + 21, j + 2, k + 38, Blocks.stonebrick, 0);
		/* 1302 */setBlock(world, i + 21, j + 2, k + 39, Blocks.stonebrick, 0);
		/* 1303 */setBlock(world, i + 21, j + 2, k + 40, Blocks.stonebrick, 0);
		/* 1304 */setBlock(world, i + 21, j + 2, k + 41, Blocks.stonebrick, 0);
		/* 1305 */setBlock(world, i + 21, j + 2, k + 42, Blocks.stonebrick, 0);
		/* 1306 */setBlock(world, i + 21, j + 2, k + 43, Blocks.stonebrick, 0);
		/* 1307 */setBlock(world, i + 21, j + 2, k + 44, Blocks.stonebrick, 0);
		/* 1308 */setBlock(world, i + 21, j + 2, k + 45, Blocks.stonebrick, 0);
		/* 1309 */setBlock(world, i + 21, j + 3, k + 3, Blocks.stonebrick, 0);
		/* 1310 */setBlock(world, i + 21, j + 3, k + 4, Blocks.stonebrick, 0);
		/* 1311 */setBlock(world, i + 21, j + 3, k + 5, Blocks.stonebrick, 0);
		/* 1312 */setBlock(world, i + 21, j + 3, k + 6, Blocks.stonebrick, 0);
		/* 1313 */setBlock(world, i + 21, j + 3, k + 7, Blocks.stonebrick, 0);
		/* 1314 */setBlock(world, i + 21, j + 3, k + 8, Blocks.stonebrick, 0);
		/* 1315 */setBlock(world, i + 21, j + 3, k + 9, Blocks.stonebrick, 0);
		/* 1316 */setBlock(world, i + 21, j + 3, k + 10, Blocks.stonebrick, 0);
		/* 1317 */setBlock(world, i + 21, j + 3, k + 38, Blocks.stonebrick, 0);
		/* 1318 */setBlock(world, i + 21, j + 3, k + 39, Blocks.stonebrick, 0);
		/* 1319 */setBlock(world, i + 21, j + 3, k + 40, Blocks.stonebrick, 0);
		/* 1320 */setBlock(world, i + 21, j + 3, k + 41, Blocks.stonebrick, 0);
		/* 1321 */setBlock(world, i + 21, j + 3, k + 42, Blocks.stonebrick, 0);
		/* 1322 */setBlock(world, i + 21, j + 3, k + 43, Blocks.stonebrick, 0);
		/* 1323 */setBlock(world, i + 21, j + 3, k + 44, Blocks.stonebrick, 0);
		/* 1324 */setBlock(world, i + 21, j + 4, k + 4, Blocks.stonebrick, 0);
		/* 1325 */setBlock(world, i + 21, j + 4, k + 5, Blocks.stonebrick, 0);
		/* 1326 */setBlock(world, i + 21, j + 4, k + 6, Blocks.stonebrick, 0);
		/* 1327 */setBlock(world, i + 21, j + 4, k + 7, Blocks.stonebrick, 0);
		/* 1328 */setBlock(world, i + 21, j + 4, k + 8, Blocks.stonebrick, 0);
		/* 1329 */setBlock(world, i + 21, j + 4, k + 9, Blocks.stonebrick, 0);
		/* 1330 */setBlock(world, i + 21, j + 4, k + 10, Blocks.stonebrick, 0);
		/* 1331 */setBlock(world, i + 21, j + 4, k + 11, Blocks.stonebrick, 0);
		/* 1332 */setBlock(world, i + 21, j + 4, k + 12, Blocks.stonebrick, 0);
		/* 1333 */setBlock(world, i + 21, j + 4, k + 37, Blocks.stonebrick, 0);
		/* 1334 */setBlock(world, i + 21, j + 4, k + 38, Blocks.stonebrick, 0);
		/* 1335 */setBlock(world, i + 21, j + 4, k + 39, Blocks.stonebrick, 0);
		/* 1336 */setBlock(world, i + 21, j + 4, k + 40, Blocks.stonebrick, 0);
		/* 1337 */setBlock(world, i + 21, j + 4, k + 41, Blocks.stonebrick, 0);
		/* 1338 */setBlock(world, i + 21, j + 4, k + 42, Blocks.stonebrick, 0);
		/* 1339 */setBlock(world, i + 21, j + 4, k + 43, Blocks.stonebrick, 0);
		/* 1340 */setBlock(world, i + 21, j + 5, k + 5, Blocks.stonebrick, 0);
		/* 1341 */setBlock(world, i + 21, j + 5, k + 6, Blocks.stonebrick, 0);
		/* 1342 */setBlock(world, i + 21, j + 5, k + 7, Blocks.stonebrick, 0);
		/* 1343 */setBlock(world, i + 21, j + 5, k + 8, Blocks.stonebrick, 0);
		/* 1344 */setBlock(world, i + 21, j + 5, k + 9, Blocks.stonebrick, 0);
		/* 1345 */setBlock(world, i + 21, j + 5, k + 10, Blocks.stonebrick, 0);
		/* 1346 */setBlock(world, i + 21, j + 5, k + 12, Blocks.stonebrick, 0);
		/* 1347 */setBlock(world, i + 21, j + 5, k + 35, Blocks.stonebrick, 0);
		/* 1348 */setBlock(world, i + 21, j + 5, k + 36, Blocks.stonebrick, 0);
		/* 1349 */setBlock(world, i + 21, j + 5, k + 37, Blocks.stonebrick, 0);
		/* 1350 */setBlock(world, i + 21, j + 5, k + 38, Blocks.stonebrick, 0);
		/* 1351 */setBlock(world, i + 21, j + 5, k + 39, Blocks.stonebrick, 0);
		/* 1352 */setBlock(world, i + 21, j + 5, k + 40, Blocks.stonebrick, 0);
		/* 1353 */setBlock(world, i + 21, j + 5, k + 41, Blocks.stonebrick, 0);
		/* 1354 */setBlock(world, i + 21, j + 5, k + 42, Blocks.stonebrick, 0);
		/* 1355 */setBlock(world, i + 21, j + 6, k + 6, Blocks.stonebrick, 0);
		/* 1356 */setBlock(world, i + 21, j + 6, k + 7, Blocks.stonebrick, 0);
		/* 1357 */setBlock(world, i + 21, j + 6, k + 8, Blocks.stonebrick, 0);
		/* 1358 */setBlock(world, i + 21, j + 6, k + 9, Blocks.stonebrick, 0);
		/* 1359 */setBlock(world, i + 21, j + 6, k + 10, Blocks.stonebrick, 0);
		/* 1360 */setBlock(world, i + 21, j + 6, k + 11, Blocks.stonebrick, 0);
		/* 1361 */setBlock(world, i + 21, j + 6, k + 35, Blocks.stonebrick, 0);
		/* 1362 */setBlock(world, i + 21, j + 6, k + 36, Blocks.stonebrick, 0);
		/* 1363 */setBlock(world, i + 21, j + 6, k + 37, Blocks.stonebrick, 0);
		/* 1364 */setBlock(world, i + 21, j + 6, k + 38, Blocks.stonebrick, 0);
		/* 1365 */setBlock(world, i + 21, j + 6, k + 39, Blocks.stonebrick, 0);
		/* 1366 */setBlock(world, i + 21, j + 6, k + 40, Blocks.stonebrick, 0);
		/* 1367 */setBlock(world, i + 21, j + 6, k + 41, Blocks.stonebrick, 0);
		/* 1368 */setBlock(world, i + 21, j + 7, k + 7, Blocks.stonebrick, 0);
		/* 1369 */setBlock(world, i + 21, j + 7, k + 8, Blocks.stonebrick, 0);
		/* 1370 */setBlock(world, i + 21, j + 7, k + 9, Blocks.stonebrick, 0);
		/* 1371 */setBlock(world, i + 21, j + 7, k + 10, Blocks.stonebrick, 0);
		/* 1372 */setBlock(world, i + 21, j + 7, k + 11, Blocks.stonebrick, 0);
		/* 1373 */setBlock(world, i + 21, j + 7, k + 12, Blocks.stonebrick, 0);
		/* 1374 */setBlock(world, i + 21, j + 7, k + 34, Blocks.stonebrick, 0);
		/* 1375 */setBlock(world, i + 21, j + 7, k + 35, Blocks.stonebrick, 0);
		/* 1376 */setBlock(world, i + 21, j + 7, k + 36, Blocks.stonebrick, 0);
		/* 1377 */setBlock(world, i + 21, j + 7, k + 37, Blocks.stonebrick, 0);
		/* 1378 */setBlock(world, i + 21, j + 7, k + 38, Blocks.stonebrick, 0);
		/* 1379 */setBlock(world, i + 21, j + 7, k + 39, Blocks.stonebrick, 0);
		/* 1380 */setBlock(world, i + 21, j + 7, k + 40, Blocks.stonebrick, 0);
		/* 1381 */setBlock(world, i + 21, j + 8, k + 8, Blocks.stonebrick, 0);
		/* 1382 */setBlock(world, i + 21, j + 8, k + 9, Blocks.stonebrick, 0);
		/* 1383 */setBlock(world, i + 21, j + 8, k + 10, Blocks.stonebrick, 0);
		/* 1384 */setBlock(world, i + 21, j + 8, k + 11, Blocks.stonebrick, 0);
		/* 1385 */setBlock(world, i + 21, j + 8, k + 12, Blocks.stonebrick, 0);
		/* 1386 */setBlock(world, i + 21, j + 8, k + 13, Blocks.stonebrick, 0);
		/* 1387 */setBlock(world, i + 21, j + 8, k + 35, Blocks.stonebrick, 0);
		/* 1388 */setBlock(world, i + 21, j + 8, k + 36, Blocks.stonebrick, 0);
		/* 1389 */setBlock(world, i + 21, j + 8, k + 37, Blocks.stonebrick, 0);
		/* 1390 */setBlock(world, i + 21, j + 8, k + 38, Blocks.stonebrick, 0);
		/* 1391 */setBlock(world, i + 21, j + 8, k + 39, Blocks.stonebrick, 0);
		/* 1392 */setBlock(world, i + 21, j + 9, k + 9, Blocks.stonebrick, 0);
		/* 1393 */setBlock(world, i + 21, j + 9, k + 10, Blocks.stonebrick, 0);
		/* 1394 */setBlock(world, i + 21, j + 9, k + 11, Blocks.stonebrick, 0);
		/* 1395 */setBlock(world, i + 21, j + 9, k + 12, Blocks.stonebrick, 0);
		/* 1396 */setBlock(world, i + 21, j + 9, k + 14, Blocks.stonebrick, 0);
		/* 1397 */setBlock(world, i + 21, j + 9, k + 33, Blocks.stonebrick, 0);
		/* 1398 */setBlock(world, i + 21, j + 9, k + 35, Blocks.stonebrick, 0);
		/* 1399 */setBlock(world, i + 21, j + 9, k + 36, Blocks.stonebrick, 0);
		/* 1400 */setBlock(world, i + 21, j + 9, k + 37, Blocks.stonebrick, 0);
		/* 1401 */setBlock(world, i + 21, j + 9, k + 38, Blocks.stonebrick, 0);
		/* 1402 */setBlock(world, i + 21, j + 10, k + 10, Blocks.stonebrick, 0);
		/* 1403 */setBlock(world, i + 21, j + 10, k + 11, Blocks.stonebrick, 0);
		/* 1404 */setBlock(world, i + 21, j + 10, k + 12, Blocks.stonebrick, 0);
		/* 1405 */setBlock(world, i + 21, j + 10, k + 13, Blocks.stonebrick, 0);
		/* 1406 */setBlock(world, i + 21, j + 10, k + 15, Blocks.stonebrick, 0);
		/* 1407 */setBlock(world, i + 21, j + 10, k + 34, Blocks.stonebrick, 0);
		/* 1408 */setBlock(world, i + 21, j + 10, k + 35, Blocks.stonebrick, 0);
		/* 1409 */setBlock(world, i + 21, j + 10, k + 36, Blocks.stonebrick, 0);
		/* 1410 */setBlock(world, i + 21, j + 10, k + 37, Blocks.stonebrick, 0);
		/* 1411 */setBlock(world, i + 21, j + 11, k + 11, Blocks.stonebrick, 0);
		/* 1412 */setBlock(world, i + 21, j + 11, k + 12, Blocks.stonebrick, 0);
		/* 1413 */setBlock(world, i + 21, j + 11, k + 13, Blocks.stonebrick, 0);
		/* 1414 */setBlock(world, i + 21, j + 11, k + 14, Blocks.stonebrick, 0);
		/* 1415 */setBlock(world, i + 21, j + 11, k + 31, Blocks.stonebrick, 0);
		/* 1416 */setBlock(world, i + 21, j + 11, k + 32, Blocks.stonebrick, 0);
		/* 1417 */setBlock(world, i + 21, j + 11, k + 33, Blocks.stonebrick, 0);
		/* 1418 */setBlock(world, i + 21, j + 11, k + 34, Blocks.stonebrick, 0);
		/* 1419 */setBlock(world, i + 21, j + 11, k + 35, Blocks.stonebrick, 0);
		/* 1420 */setBlock(world, i + 21, j + 11, k + 36, Blocks.stonebrick, 0);
		/* 1421 */setBlock(world, i + 21, j + 12, k + 12, Blocks.stonebrick, 0);
		/* 1422 */setBlock(world, i + 21, j + 12, k + 13, Blocks.stonebrick, 0);
		/* 1423 */setBlock(world, i + 21, j + 12, k + 14, Blocks.stonebrick, 0);
		/* 1424 */setBlock(world, i + 21, j + 12, k + 32, Blocks.stonebrick, 0);
		/* 1425 */setBlock(world, i + 21, j + 12, k + 33, Blocks.stonebrick, 0);
		/* 1426 */setBlock(world, i + 21, j + 12, k + 34, Blocks.stonebrick, 0);
		/* 1427 */setBlock(world, i + 21, j + 12, k + 35, Blocks.stonebrick, 0);
		/* 1428 */setBlock(world, i + 21, j + 13, k + 13, Blocks.stonebrick, 0);
		/* 1429 */setBlock(world, i + 21, j + 13, k + 14, Blocks.stonebrick, 0);
		/* 1430 */setBlock(world, i + 21, j + 13, k + 15, Blocks.stonebrick, 0);
		/* 1431 */setBlock(world, i + 21, j + 13, k + 17, Blocks.stonebrick, 0);
		/* 1432 */setBlock(world, i + 21, j + 13, k + 19, Blocks.stonebrick, 0);
		/* 1433 */setBlock(world, i + 21, j + 13, k + 32, Blocks.stonebrick, 0);
		/* 1434 */setBlock(world, i + 21, j + 13, k + 33, Blocks.stonebrick, 0);
		/* 1435 */setBlock(world, i + 21, j + 13, k + 34, Blocks.stonebrick, 0);
		/* 1436 */setBlock(world, i + 21, j + 14, k + 14, Blocks.stonebrick, 0);
		/* 1437 */setBlock(world, i + 21, j + 14, k + 15, Blocks.stonebrick, 0);
		/* 1438 */setBlock(world, i + 21, j + 14, k + 16, Blocks.stonebrick, 0);
		/* 1439 */setBlock(world, i + 21, j + 14, k + 17, Blocks.stonebrick, 0);
		/* 1440 */setBlock(world, i + 21, j + 14, k + 18, Blocks.stonebrick, 0);
		/* 1441 */setBlock(world, i + 21, j + 14, k + 29, Blocks.stonebrick, 0);
		/* 1442 */setBlock(world, i + 21, j + 14, k + 30, Blocks.stonebrick, 0);
		/* 1443 */setBlock(world, i + 21, j + 14, k + 31, Blocks.stonebrick, 0);
		/* 1444 */setBlock(world, i + 21, j + 14, k + 32, Blocks.stonebrick, 0);
		/* 1445 */setBlock(world, i + 21, j + 14, k + 33, Blocks.stonebrick, 0);
		/* 1446 */setBlock(world, i + 21, j + 15, k + 15, Blocks.stonebrick, 0);
		/* 1447 */setBlock(world, i + 21, j + 15, k + 16, Blocks.stonebrick, 0);
		/* 1448 */setBlock(world, i + 21, j + 15, k + 17, Blocks.stonebrick, 0);
		/* 1449 */setBlock(world, i + 21, j + 15, k + 18, Blocks.stonebrick, 0);
		/* 1450 */setBlock(world, i + 21, j + 15, k + 29, Blocks.stonebrick, 0);
		/* 1451 */setBlock(world, i + 21, j + 15, k + 30, Blocks.stonebrick, 0);
		/* 1452 */setBlock(world, i + 21, j + 15, k + 31, Blocks.stonebrick, 0);
		/* 1453 */setBlock(world, i + 21, j + 15, k + 32, Blocks.stonebrick, 0);
		/* 1454 */setBlock(world, i + 21, j + 16, k + 16, Blocks.stonebrick, 0);
		/* 1455 */setBlock(world, i + 21, j + 16, k + 17, Blocks.stonebrick, 0);
		/* 1456 */setBlock(world, i + 21, j + 16, k + 18, Blocks.stonebrick, 0);
		/* 1457 */setBlock(world, i + 21, j + 16, k + 29, Blocks.stonebrick, 0);
		/* 1458 */setBlock(world, i + 21, j + 16, k + 30, Blocks.stonebrick, 0);
		/* 1459 */setBlock(world, i + 21, j + 16, k + 31, Blocks.stonebrick, 0);
		/* 1460 */setBlock(world, i + 21, j + 17, k + 17, Blocks.stonebrick, 0);
		/* 1461 */setBlock(world, i + 21, j + 17, k + 18, Blocks.stonebrick, 0);
		/* 1462 */setBlock(world, i + 21, j + 17, k + 19, Blocks.stonebrick, 0);
		/* 1463 */setBlock(world, i + 21, j + 17, k + 29, Blocks.stonebrick, 0);
		/* 1464 */setBlock(world, i + 21, j + 17, k + 30, Blocks.stonebrick, 0);
		/* 1465 */setBlock(world, i + 21, j + 18, k + 18, Blocks.stonebrick, 0);
		/* 1466 */setBlock(world, i + 21, j + 18, k + 29, Blocks.stonebrick, 0);
		/* 1467 */setBlock(world, i + 21, j + 19, k + 19, Blocks.stonebrick, 0);
		/* 1468 */setBlock(world, i + 22, j + 0, k + 37, Blocks.stonebrick, 0);
		/* 1469 */setBlock(world, i + 22, j + 1, k + 3, Blocks.stonebrick, 0);
		/* 1470 */setBlock(world, i + 22, j + 1, k + 10, Blocks.stonebrick, 0);
		/* 1471 */setBlock(world, i + 22, j + 1, k + 37, Blocks.stonebrick, 0);
		/* 1472 */setBlock(world, i + 22, j + 1, k + 44, Blocks.stonebrick, 0);
		/* 1473 */setBlock(world, i + 22, j + 2, k + 4, Blocks.stonebrick, 0);
		/* 1474 */setBlock(world, i + 22, j + 2, k + 11, Blocks.stonebrick, 0);
		/* 1475 */setBlock(world, i + 22, j + 2, k + 37, Blocks.stonebrick, 0);
		/* 1476 */setBlock(world, i + 22, j + 2, k + 43, Blocks.stonebrick, 0);
		/* 1477 */setBlock(world, i + 22, j + 3, k + 5, Blocks.stonebrick, 0);
		/* 1478 */setBlock(world, i + 22, j + 3, k + 10, Blocks.stonebrick, 0);
		/* 1479 */setBlock(world, i + 22, j + 3, k + 42, Blocks.stonebrick, 0);
		/* 1480 */setBlock(world, i + 22, j + 4, k + 6, Blocks.stonebrick, 0);
