/*       */package com.parzivail.pswm.world.gen;

/*       */
/*       *//*       */
import java.util.Random;

/*       */
import net.minecraft.block.Block;
/*       */
import net.minecraft.init.Blocks;
/*       */
import net.minecraft.world.World;
/*       */
import net.minecraft.world.chunk.IChunkProvider;
/*       */
import net.minecraft.world.gen.feature.WorldGenerator;
import cpw.mods.fml.common.IWorldGenerator;

/*       */
/*       */
/*       */
/*       */
/*       */
/*       */
/*       */
/*       */
/*       */
/*       */public class WorldGenEndorTree2
/*       */extends WorldGenerator
/*       */implements IWorldGenerator
/*       */
{
	/*       */public void generate(Random random, int chunkX, int chunkZ, World world, IChunkProvider chunkGenerator, IChunkProvider chunkProvider)
	{
	}

	/*       */
	/*       */public boolean generate(World world, Random rand, int i, int j, int k)
	/*       */
	{
		if ((!locationIsValidSpawn(world, i, j, k)) || (!locationIsValidSpawn(world, i + 36, j, k)) || (!locationIsValidSpawn(world, i + 36, j, k + 37)) || (!locationIsValidSpawn(world, i, j, k + 37))) { return false;
		/*       */}
		k -= 10;
		i -= 10;
		/*       */
		setBlock(world, i + 2, j + 39, k + 20, Blocks.log, 0);
		setBlock(world, i + 4, j + 42, k + 10, Blocks.log, 0);
		setBlock(world, i + 4, j + 42, k + 22, Blocks.log, 0);
		setBlock(world, i + 8, j + 39, k + 23, Blocks.log, 0);
		setBlock(world, i + 8, j + 40, k + 11, Blocks.log, 0);
		setBlock(world, i + 9, j + 40, k + 23, Blocks.log, 0);
		setBlock(world, i + 9, j + 42, k + 16, Blocks.log, 0);
		setBlock(world, i + 9, j + 46, k + 18, Blocks.log, 0);
		setBlock(world, i + 10, j + 40, k + 13, Blocks.log, 0);
		setBlock(world, i + 10, j + 40, k + 21, Blocks.log, 0);
		setBlock(world, i + 10, j + 44, k + 15, Blocks.log, 0);
		setBlock(world, i + 10, j + 45, k + 15, Blocks.log, 0);
		setBlock(world, i + 10, j + 45, k + 21, Blocks.log, 0);
		setBlock(world, i + 10, j + 46, k + 17, Blocks.log, 0);
		setBlock(world, i + 11, j + 42, k + 18, Blocks.log, 0);
		setBlock(world, i + 11, j + 42, k + 24, Blocks.log, 0);
		setBlock(world, i + 11, j + 43, k + 17, Blocks.log, 0);
		setBlock(world, i + 11, j + 43, k + 19, Blocks.log, 0);
		setBlock(world, i + 11, j + 45, k + 11, Blocks.log, 0);
		setBlock(world, i + 12, j + 41, k + 15, Blocks.log, 0);
		setBlock(world, i + 12, j + 42, k + 12, Blocks.log, 0);
		setBlock(world, i + 12, j + 42, k + 20, Blocks.log, 0);
		setBlock(world, i + 12, j + 45, k + 17, Blocks.log, 0);
		setBlock(world, i + 12, j + 46, k + 17, Blocks.log, 0);
		setBlock(world, i + 12, j + 47, k + 14, Blocks.log, 0);
		setBlock(world, i + 13, j + 40, k + 17, Blocks.log, 0);
		setBlock(world, i + 13, j + 40, k + 30, Blocks.log, 0);
		setBlock(world, i + 13, j + 41, k + 16, Blocks.log, 0);
		setBlock(world, i + 13, j + 42, k + 17, Blocks.log, 0);
		setBlock(world, i + 13, j + 43, k + 14, Blocks.log, 0);
		setBlock(world, i + 13, j + 43, k + 16, Blocks.log, 0);
		setBlock(world, i + 13, j + 44, k + 16, Blocks.log, 0);
		setBlock(world, i + 13, j + 44, k + 24, Blocks.log, 0);
		setBlock(world, i + 13, j + 45, k + 19, Blocks.log, 0);
		setBlock(world, i + 13, j + 47, k + 21, Blocks.log, 0);
		setBlock(world, i + 13, j + 48, k + 15, Blocks.log, 0);
		setBlock(world, i + 14, j + 39, k + 35, Blocks.log, 0);
		setBlock(world, i + 14, j + 40, k + 29, Blocks.log, 0);
		setBlock(world, i + 14, j + 41, k + 20, Blocks.log, 0);
		setBlock(world, i + 14, j + 41, k + 30, Blocks.log, 0);
		setBlock(world, i + 14, j + 43, k + 14, Blocks.log, 0);
		setBlock(world, i + 14, j + 45, k + 16, Blocks.log, 0);
		setBlock(world, i + 14, j + 45, k + 18, Blocks.log, 0);
		setBlock(world, i + 14, j + 47, k + 13, Blocks.log, 0);
		setBlock(world, i + 14, j + 47, k + 16, Blocks.log, 0);
		setBlock(world, i + 15, j + 38, k + 17, Blocks.log, 0);
		setBlock(world, i + 15, j + 44, k + 7, Blocks.log, 0);
		setBlock(world, i + 15, j + 45, k + 13, Blocks.log, 0);
		setBlock(world, i + 15, j + 45, k + 15, Blocks.log, 0);
		setBlock(world, i + 15, j + 45, k + 16, Blocks.log, 0);
		setBlock(world, i + 15, j + 46, k + 16, Blocks.log, 0);
		setBlock(world, i + 15, j + 46, k + 21, Blocks.log, 0);
		setBlock(world, i + 15, j + 47, k + 12, Blocks.log, 0);
		setBlock(world, i + 15, j + 47, k + 16, Blocks.log, 0);
		setBlock(world, i + 16, j + 37, k + 17, Blocks.log, 0);
		setBlock(world, i + 16, j + 41, k + 11, Blocks.log, 0);
		setBlock(world, i + 16, j + 41, k + 26, Blocks.log, 0);
		setBlock(world, i + 16, j + 42, k + 6, Blocks.log, 0);
		setBlock(world, i + 16, j + 42, k + 9, Blocks.log, 0);
		setBlock(world, i + 16, j + 42, k + 22, Blocks.log, 0);
		setBlock(world, i + 16, j + 43, k + 6, Blocks.log, 0);
		setBlock(world, i + 16, j + 43, k + 14, Blocks.log, 0);
		setBlock(world, i + 16, j + 43, k + 17, Blocks.log, 0);
		setBlock(world, i + 16, j + 43, k + 22, Blocks.log, 0);
		setBlock(world, i + 16, j + 43, k + 28, Blocks.log, 0);
		setBlock(world, i + 16, j + 44, k + 13, Blocks.log, 0);
		setBlock(world, i + 16, j + 45, k + 11, Blocks.log, 0);
		setBlock(world, i + 16, j + 45, k + 16, Blocks.log, 0);
		setBlock(world, i + 16, j + 45, k + 25, Blocks.log, 0);
		setBlock(world, i + 16, j + 46, k + 10, Blocks.log, 0);
		setBlock(world, i + 16, j + 46, k + 16, Blocks.log, 0);
		setBlock(world, i + 16, j + 46, k + 18, Blocks.log, 0);
		setBlock(world, i + 16, j + 46, k + 21, Blocks.log, 0);
		setBlock(world, i + 16, j + 47, k + 14, Blocks.log, 0);
		setBlock(world, i + 16, j + 47, k + 17, Blocks.log, 0);
		setBlock(world, i + 17, j + 42, k + 11, Blocks.log, 0);
		setBlock(world, i + 17, j + 42, k + 19, Blocks.log, 0);
		setBlock(world, i + 17, j + 42, k + 26, Blocks.log, 0);
		setBlock(world, i + 17, j + 43, k + 13, Blocks.log, 0);
		setBlock(world, i + 17, j + 44, k + 12, Blocks.log, 0);
		setBlock(world, i + 17, j + 44, k + 14, Blocks.log, 0);
		setBlock(world, i + 17, j + 44, k + 16, Blocks.log, 0);
		setBlock(world, i + 17, j + 44, k + 17, Blocks.log, 0);
		setBlock(world, i + 17, j + 44, k + 23, Blocks.log, 0);
		setBlock(world, i + 17, j + 45, k + 13, Blocks.log, 0);
		setBlock(world, i + 17, j + 45, k + 16, Blocks.log, 0);
		setBlock(world, i + 17, j + 46, k + 17, Blocks.log, 0);
		setBlock(world, i + 17, j + 47, k + 17, Blocks.log, 0);
		setBlock(world, i + 17, j + 48, k + 14, Blocks.log, 0);
		setBlock(world, i + 17, j + 48, k + 16, Blocks.log, 0);
		setBlock(world, i + 18, j + 0, k + 13, Blocks.log, 0);
		setBlock(world, i + 18, j + 0, k + 14, Blocks.log, 0);
		setBlock(world, i + 18, j + 0, k + 15, Blocks.log, 0);
		setBlock(world, i + 18, j + 0, k + 16, Blocks.log, 0);
		setBlock(world, i + 18, j + 1, k + 13, Blocks.log, 0);
		setBlock(world, i + 18, j + 1, k + 14, Blocks.log, 0);
		setBlock(world, i + 18, j + 1, k + 15, Blocks.log, 0);
		setBlock(world, i + 18, j + 1, k + 16, Blocks.log, 0);
		setBlock(world, i + 18, j + 2, k + 13, Blocks.log, 0);
		setBlock(world, i + 18, j + 2, k + 14, Blocks.log, 0);
		setBlock(world, i + 18, j + 2, k + 15, Blocks.log, 0);
		setBlock(world, i + 18, j + 2, k + 16, Blocks.log, 0);
		setBlock(world, i + 18, j + 3, k + 13, Blocks.log, 0);
		setBlock(world, i + 18, j + 3, k + 14, Blocks.log, 0);
		setBlock(world, i + 18, j + 3, k + 15, Blocks.log, 0);
		setBlock(world, i + 18, j + 3, k + 16, Blocks.log, 0);
		setBlock(world, i + 18, j + 4, k + 13, Blocks.log, 0);
		setBlock(world, i + 18, j + 4, k + 14, Blocks.log, 0);
		setBlock(world, i + 18, j + 4, k + 15, Blocks.log, 0);
		setBlock(world, i + 18, j + 4, k + 16, Blocks.log, 0);
		setBlock(world, i + 18, j + 5, k + 14, Blocks.log, 0);
		setBlock(world, i + 18, j + 5, k + 15, Blocks.log, 0);
		setBlock(world, i + 18, j + 5, k + 16, Blocks.log, 0);
		setBlock(world, i + 18, j + 6, k + 15, Blocks.log, 0);
		setBlock(world, i + 18, j + 14, k + 15, Blocks.log, 0);
		setBlock(world, i + 18, j + 14, k + 16, Blocks.log, 0);
		setBlock(world, i + 18, j + 15, k + 15, Blocks.log, 0);
		setBlock(world, i + 18, j + 15, k + 16, Blocks.log, 0);
		setBlock(world, i + 18, j + 16, k + 15, Blocks.log, 0);
		setBlock(world, i + 18, j + 16, k + 16, Blocks.log, 0);
		setBlock(world, i + 18, j + 16, k + 17, Blocks.log, 0);
		setBlock(world, i + 18, j + 17, k + 15, Blocks.log, 0);
		setBlock(world, i + 18, j + 17, k + 16, Blocks.log, 0);
		setBlock(world, i + 18, j + 17, k + 17, Blocks.log, 0);
		setBlock(world, i + 18, j + 18, k + 15, Blocks.log, 0);
		setBlock(world, i + 18, j + 18, k + 16, Blocks.log, 0);
		setBlock(world, i + 18, j + 18, k + 17, Blocks.log, 0);
		setBlock(world, i + 18, j + 19, k + 15, Blocks.log, 0);
		setBlock(world, i + 18, j + 19, k + 16, Blocks.log, 0);
		setBlock(world, i + 18, j + 19, k + 17, Blocks.log, 0);
		setBlock(world, i + 18, j + 20, k + 15, Blocks.log, 0);
		setBlock(world, i + 18, j + 20, k + 16, Blocks.log, 0);
		setBlock(world, i + 18, j + 20, k + 17, Blocks.log, 0);
		setBlock(world, i + 18, j + 21, k + 15, Blocks.log, 0);
		setBlock(world, i + 18, j + 21, k + 16, Blocks.log, 0);
		setBlock(world, i + 18, j + 21, k + 17, Blocks.log, 0);
		setBlock(world, i + 18, j + 22, k + 15, Blocks.log, 0);
		setBlock(world, i + 18, j + 22, k + 16, Blocks.log, 0);
		setBlock(world, i + 18, j + 22, k + 17, Blocks.log, 0);
		setBlock(world, i + 18, j + 23, k + 16, Blocks.log, 0);
		setBlock(world, i + 18, j + 24, k + 16, Blocks.log, 0);
		setBlock(world, i + 18, j + 25, k + 16, Blocks.log, 0);
		setBlock(world, i + 18, j + 26, k + 16, Blocks.log, 0);
		setBlock(world, i + 18, j + 35, k + 17, Blocks.log, 0);
		setBlock(world, i + 18, j + 41, k + 21, Blocks.log, 0);
		setBlock(world, i + 18, j + 42, k + 13, Blocks.log, 0);
		setBlock(world, i + 18, j + 42, k + 15, Blocks.log, 0);
		setBlock(world, i + 18, j + 42, k + 22, Blocks.log, 0);
		setBlock(world, i + 18, j + 43, k + 15, Blocks.log, 0);
		setBlock(world, i + 18, j + 43, k + 16, Blocks.log, 0);
		setBlock(world, i + 18, j + 43, k + 17, Blocks.log, 0);
		setBlock(world, i + 18, j + 43, k + 18, Blocks.log, 0);
		setBlock(world, i + 18, j + 44, k + 8, Blocks.log, 0);
		setBlock(world, i + 18, j + 45, k + 17, Blocks.log, 0);
		setBlock(world, i + 18, j + 46, k + 10, Blocks.log, 0);
		setBlock(world, i + 18, j + 46, k + 20, Blocks.log, 0);
		setBlock(world, i + 18, j + 47, k + 14, Blocks.log, 0);
		setBlock(world, i + 18, j + 47, k + 16, Blocks.log, 0);
		setBlock(world, i + 18, j + 48, k + 10, Blocks.log, 0);
		setBlock(world, i + 18, j + 48, k + 14, Blocks.log, 0);
		setBlock(world, i + 18, j + 48, k + 20, Blocks.log, 0);
		setBlock(world, i + 19, j + 0, k + 13, Blocks.log, 0);
		setBlock(world, i + 19, j + 0, k + 14, Blocks.log, 0);
		setBlock(world, i + 19, j + 0, k + 15, Blocks.log, 0);
		setBlock(world, i + 19, j + 0, k + 16, Blocks.log, 0);
		setBlock(world, i + 19, j + 0, k + 17, Blocks.log, 0);
		setBlock(world, i + 19, j + 1, k + 13, Blocks.log, 0);
		setBlock(world, i + 19, j + 1, k + 14, Blocks.log, 0);
		setBlock(world, i + 19, j + 1, k + 15, Blocks.log, 0);
		setBlock(world, i + 19, j + 1, k + 16, Blocks.log, 0);
		setBlock(world, i + 19, j + 1, k + 17, Blocks.log, 0);
		setBlock(world, i + 19, j + 2, k + 13, Blocks.log, 0);
		setBlock(world, i + 19, j + 2, k + 14, Blocks.log, 0);
		setBlock(world, i + 19, j + 2, k + 15, Blocks.log, 0);
		setBlock(world, i + 19, j + 2, k + 16, Blocks.log, 0);
		setBlock(world, i + 19, j + 2, k + 17, Blocks.log, 0);
		setBlock(world, i + 19, j + 3, k + 13, Blocks.log, 0);
		setBlock(world, i + 19, j + 3, k + 14, Blocks.log, 0);
		setBlock(world, i + 19, j + 3, k + 15, Blocks.log, 0);
		setBlock(world, i + 19, j + 3, k + 16, Blocks.log, 0);
		setBlock(world, i + 19, j + 3, k + 17, Blocks.log, 0);
		setBlock(world, i + 19, j + 4, k + 13, Blocks.log, 0);
		setBlock(world, i + 19, j + 4, k + 14, Blocks.log, 0);
		setBlock(world, i + 19, j + 4, k + 15, Blocks.log, 0);
		setBlock(world, i + 19, j + 4, k + 16, Blocks.log, 0);
		setBlock(world, i + 19, j + 4, k + 17, Blocks.log, 0);
		setBlock(world, i + 19, j + 5, k + 13, Blocks.log, 0);
		setBlock(world, i + 19, j + 5, k + 14, Blocks.log, 0);
		setBlock(world, i + 19, j + 5, k + 15, Blocks.log, 0);
		setBlock(world, i + 19, j + 5, k + 16, Blocks.log, 0);
		setBlock(world, i + 19, j + 5, k + 17, Blocks.log, 0);
		setBlock(world, i + 19, j + 6, k + 13, Blocks.log, 0);
		setBlock(world, i + 19, j + 6, k + 14, Blocks.log, 0);
		setBlock(world, i + 19, j + 6, k + 15, Blocks.log, 0);
		setBlock(world, i + 19, j + 6, k + 16, Blocks.log, 0);
		setBlock(world, i + 19, j + 7, k + 14, Blocks.log, 0);
		setBlock(world, i + 19, j + 7, k + 15, Blocks.log, 0);
		setBlock(world, i + 19, j + 8, k + 14, Blocks.log, 0);
		setBlock(world, i + 19, j + 8, k + 15, Blocks.log, 0);
		setBlock(world, i + 19, j + 9, k + 14, Blocks.log, 0);
		setBlock(world, i + 19, j + 9, k + 15, Blocks.log, 0);
		setBlock(world, i + 19, j + 10, k + 14, Blocks.log, 0);
		setBlock(world, i + 19, j + 10, k + 15, Blocks.log, 0);
		setBlock(world, i + 19, j + 11, k + 14, Blocks.log, 0);
		setBlock(world, i + 19, j + 11, k + 15, Blocks.log, 0);
		setBlock(world, i + 19, j + 11, k + 16, Blocks.log, 0);
		setBlock(world, i + 19, j + 12, k + 14, Blocks.log, 0);
		setBlock(world, i + 19, j + 12, k + 15, Blocks.log, 0);
		setBlock(world, i + 19, j + 12, k + 16, Blocks.log, 0);
		setBlock(world, i + 19, j + 13, k + 14, Blocks.log, 0);
		setBlock(world, i + 19, j + 13, k + 15, Blocks.log, 0);
		setBlock(world, i + 19, j + 13, k + 16, Blocks.log, 0);
		setBlock(world, i + 19, j + 14, k + 14, Blocks.log, 0);
		setBlock(world, i + 19, j + 14, k + 15, Blocks.log, 0);
		setBlock(world, i + 19, j + 14, k + 16, Blocks.log, 0);
		setBlock(world, i + 19, j + 15, k + 14, Blocks.log, 0);
		setBlock(world, i + 19, j + 15, k + 15, Blocks.log, 0);
		setBlock(world, i + 19, j + 15, k + 16, Blocks.log, 0);
		setBlock(world, i + 19, j + 15, k + 17, Blocks.log, 0);
		setBlock(world, i + 19, j + 15, k + 18, Blocks.log, 0);
		setBlock(world, i + 19, j + 16, k + 14, Blocks.log, 0);
		setBlock(world, i + 19, j + 16, k + 15, Blocks.log, 0);
		setBlock(world, i + 19, j + 16, k + 16, Blocks.log, 0);
		setBlock(world, i + 19, j + 16, k + 17, Blocks.log, 0);
		setBlock(world, i + 19, j + 16, k + 18, Blocks.log, 0);
		setBlock(world, i + 19, j + 17, k + 14, Blocks.log, 0);
		setBlock(world, i + 19, j + 17, k + 15, Blocks.log, 0);
		setBlock(world, i + 19, j + 17, k + 16, Blocks.log, 0);
		setBlock(world, i + 19, j + 17, k + 17, Blocks.log, 0);
		setBlock(world, i + 19, j + 17, k + 18, Blocks.log, 0);
		setBlock(world, i + 19, j + 18, k + 14, Blocks.log, 0);
		setBlock(world, i + 19, j + 18, k + 15, Blocks.log, 0);
		setBlock(world, i + 19, j + 18, k + 16, Blocks.log, 0);
		setBlock(world, i + 19, j + 18, k + 17, Blocks.log, 0);
		setBlock(world, i + 19, j + 18, k + 18, Blocks.log, 0);
		setBlock(world, i + 19, j + 19, k + 14, Blocks.log, 0);
		setBlock(world, i + 19, j + 19, k + 15, Blocks.log, 0);
		setBlock(world, i + 19, j + 19, k + 16, Blocks.log, 0);
		setBlock(world, i + 19, j + 19, k + 17, Blocks.log, 0);
		setBlock(world, i + 19, j + 19, k + 18, Blocks.log, 0);
		setBlock(world, i + 19, j + 20, k + 14, Blocks.log, 0);
		setBlock(world, i + 19, j + 20, k + 15, Blocks.log, 0);
		setBlock(world, i + 19, j + 20, k + 16, Blocks.log, 0);
		setBlock(world, i + 19, j + 20, k + 17, Blocks.log, 0);
		setBlock(world, i + 19, j + 20, k + 18, Blocks.log, 0);
		setBlock(world, i + 19, j + 21, k + 14, Blocks.log, 0);
		setBlock(world, i + 19, j + 21, k + 15, Blocks.log, 0);
		setBlock(world, i + 19, j + 21, k + 16, Blocks.log, 0);
		setBlock(world, i + 19, j + 21, k + 17, Blocks.log, 0);
		setBlock(world, i + 19, j + 21, k + 18, Blocks.log, 0);
		setBlock(world, i + 19, j + 22, k + 14, Blocks.log, 0);
		setBlock(world, i + 19, j + 22, k + 15, Blocks.log, 0);
		setBlock(world, i + 19, j + 22, k + 16, Blocks.log, 0);
		setBlock(world, i + 19, j + 22, k + 17, Blocks.log, 0);
		setBlock(world, i + 19, j + 22, k + 18, Blocks.log, 0);
		setBlock(world, i + 19, j + 23, k + 15, Blocks.log, 0);
		setBlock(world, i + 19, j + 23, k + 16, Blocks.log, 0);
		setBlock(world, i + 19, j + 23, k + 17, Blocks.log, 0);
		setBlock(world, i + 19, j + 24, k + 15, Blocks.log, 0);
		setBlock(world, i + 19, j + 24, k + 16, Blocks.log, 0);
		setBlock(world, i + 19, j + 24, k + 17, Blocks.log, 0);
		setBlock(world, i + 19, j + 25, k + 15, Blocks.log, 0);
		setBlock(world, i + 19, j + 25, k + 16, Blocks.log, 0);
		setBlock(world, i + 19, j + 25, k + 17, Blocks.log, 0);
		setBlock(world, i + 19, j + 26, k + 15, Blocks.log, 0);
		setBlock(world, i + 19, j + 26, k + 16, Blocks.log, 0);
		setBlock(world, i + 19, j + 26, k + 17, Blocks.log, 0);
		setBlock(world, i + 19, j + 27, k + 15, Blocks.log, 0);
		setBlock(world, i + 19, j + 27, k + 16, Blocks.log, 0);
		setBlock(world, i + 19, j + 27, k + 17, Blocks.log, 0);
		setBlock(world, i + 19, j + 28, k + 15, Blocks.log, 0);
		setBlock(world, i + 19, j + 28, k + 17, Blocks.log, 0);
		setBlock(world, i + 19, j + 33, k + 16, Blocks.log, 0);
		setBlock(world, i + 19, j + 34, k + 16, Blocks.log, 0);
		setBlock(world, i + 19, j + 35, k + 16, Blocks.log, 0);
		setBlock(world, i + 19, j + 36, k + 16, Blocks.log, 0);
		setBlock(world, i + 19, j + 40, k + 15, Blocks.log, 0);
		setBlock(world, i + 19, j + 41, k + 14, Blocks.log, 0);
		setBlock(world, i + 19, j + 42, k + 16, Blocks.log, 0);
		setBlock(world, i + 19, j + 43, k + 17, Blocks.log, 0);
		setBlock(world, i + 19, j + 44, k + 17, Blocks.log, 0);
		setBlock(world, i + 19, j + 44, k + 18, Blocks.log, 0);
		setBlock(world, i + 19, j + 44, k + 27, Blocks.log, 0);
		setBlock(world, i + 19, j + 45, k + 9, Blocks.log, 0);
		setBlock(world, i + 19, j + 45, k + 19, Blocks.log, 0);
		setBlock(world, i + 19, j + 46, k + 20, Blocks.log, 0);
		setBlock(world, i + 19, j + 46, k + 22, Blocks.log, 0);
		setBlock(world, i + 19, j + 47, k + 15, Blocks.log, 0);
		setBlock(world, i + 19, j + 47, k + 21, Blocks.log, 0);
		setBlock(world, i + 19, j + 48, k + 13, Blocks.log, 0);
		setBlock(world, i + 19, j + 48, k + 15, Blocks.log, 0);
		setBlock(world, i + 19, j + 48, k + 16, Blocks.log, 0);
		setBlock(world, i + 20, j + 0, k + 13, Blocks.log, 0);
		setBlock(world, i + 20, j + 0, k + 14, Blocks.log, 0);
		setBlock(world, i + 20, j + 0, k + 15, Blocks.log, 0);
		setBlock(world, i + 20, j + 0, k + 16, Blocks.log, 0);
		setBlock(world, i + 20, j + 0, k + 17, Blocks.log, 0);
		setBlock(world, i + 20, j + 1, k + 13, Blocks.log, 0);
		setBlock(world, i + 20, j + 1, k + 14, Blocks.log, 0);
		setBlock(world, i + 20, j + 1, k + 15, Blocks.log, 0);
		setBlock(world, i + 20, j + 1, k + 16, Blocks.log, 0);
		setBlock(world, i + 20, j + 1, k + 17, Blocks.log, 0);
		setBlock(world, i + 20, j + 2, k + 13, Blocks.log, 0);
		setBlock(world, i + 20, j + 2, k + 14, Blocks.log, 0);
		setBlock(world, i + 20, j + 2, k + 15, Blocks.log, 0);
		setBlock(world, i + 20, j + 2, k + 16, Blocks.log, 0);
		setBlock(world, i + 20, j + 2, k + 17, Blocks.log, 0);
		setBlock(world, i + 20, j + 3, k + 13, Blocks.log, 0);
		setBlock(world, i + 20, j + 3, k + 14, Blocks.log, 0);
		setBlock(world, i + 20, j + 3, k + 15, Blocks.log, 0);
		setBlock(world, i + 20, j + 3, k + 16, Blocks.log, 0);
		setBlock(world, i + 20, j + 3, k + 17, Blocks.log, 0);
		setBlock(world, i + 20, j + 4, k + 13, Blocks.log, 0);
		setBlock(world, i + 20, j + 4, k + 14, Blocks.log, 0);
		setBlock(world, i + 20, j + 4, k + 15, Blocks.log, 0);
		setBlock(world, i + 20, j + 4, k + 16, Blocks.log, 0);
		setBlock(world, i + 20, j + 4, k + 17, Blocks.log, 0);
		setBlock(world, i + 20, j + 5, k + 13, Blocks.log, 0);
		setBlock(world, i + 20, j + 5, k + 14, Blocks.log, 0);
		setBlock(world, i + 20, j + 5, k + 15, Blocks.log, 0);
		setBlock(world, i + 20, j + 5, k + 16, Blocks.log, 0);
		setBlock(world, i + 20, j + 5, k + 17, Blocks.log, 0);
		setBlock(world, i + 20, j + 6, k + 13, Blocks.log, 0);
		setBlock(world, i + 20, j + 6, k + 14, Blocks.log, 0);
		setBlock(world, i + 20, j + 6, k + 15, Blocks.log, 0);
		setBlock(world, i + 20, j + 6, k + 16, Blocks.log, 0);
		setBlock(world, i + 20, j + 7, k + 14, Blocks.log, 0);
		setBlock(world, i + 20, j + 7, k + 15, Blocks.log, 0);
		setBlock(world, i + 20, j + 7, k + 16, Blocks.log, 0);
		setBlock(world, i + 20, j + 8, k + 14, Blocks.log, 0);
		setBlock(world, i + 20, j + 8, k + 15, Blocks.log, 0);
		setBlock(world, i + 20, j + 8, k + 16, Blocks.log, 0);
		setBlock(world, i + 20, j + 9, k + 14, Blocks.log, 0);
		setBlock(world, i + 20, j + 9, k + 15, Blocks.log, 0);
		setBlock(world, i + 20, j + 9, k + 16, Blocks.log, 0);
		setBlock(world, i + 20, j + 10, k + 14, Blocks.log, 0);
		setBlock(world, i + 20, j + 10, k + 15, Blocks.log, 0);
		setBlock(world, i + 20, j + 10, k + 16, Blocks.log, 0);
		setBlock(world, i + 20, j + 11, k + 14, Blocks.log, 0);
		setBlock(world, i + 20, j + 11, k + 15, Blocks.log, 0);
		setBlock(world, i + 20, j + 11, k + 16, Blocks.log, 0);
		setBlock(world, i + 20, j + 12, k + 14, Blocks.log, 0);
		setBlock(world, i + 20, j + 12, k + 15, Blocks.log, 0);
		setBlock(world, i + 20, j + 12, k + 16, Blocks.log, 0);
		setBlock(world, i + 20, j + 13, k + 14, Blocks.log, 0);
		setBlock(world, i + 20, j + 13, k + 15, Blocks.log, 0);
		setBlock(world, i + 20, j + 13, k + 16, Blocks.log, 0);
		setBlock(world, i + 20, j + 13, k + 17, Blocks.log, 0);
		setBlock(world, i + 20, j + 14, k + 14, Blocks.log, 0);
		setBlock(world, i + 20, j + 14, k + 15, Blocks.log, 0);
		setBlock(world, i + 20, j + 14, k + 16, Blocks.log, 0);
		setBlock(world, i + 20, j + 14, k + 17, Blocks.log, 0);
		setBlock(world, i + 20, j + 15, k + 14, Blocks.log, 0);
		setBlock(world, i + 20, j + 15, k + 15, Blocks.log, 0);
		setBlock(world, i + 20, j + 15, k + 16, Blocks.log, 0);
		setBlock(world, i + 20, j + 15, k + 17, Blocks.log, 0);
		setBlock(world, i + 20, j + 15, k + 18, Blocks.log, 0);
		setBlock(world, i + 20, j + 16, k + 14, Blocks.log, 0);
		setBlock(world, i + 20, j + 16, k + 15, Blocks.log, 0);
		setBlock(world, i + 20, j + 16, k + 16, Blocks.log, 0);
		setBlock(world, i + 20, j + 16, k + 17, Blocks.log, 0);
		setBlock(world, i + 20, j + 16, k + 18, Blocks.log, 0);
		setBlock(world, i + 20, j + 17, k + 14, Blocks.log, 0);
		setBlock(world, i + 20, j + 17, k + 15, Blocks.log, 0);
		setBlock(world, i + 20, j + 17, k + 16, Blocks.log, 0);
		setBlock(world, i + 20, j + 17, k + 17, Blocks.log, 0);
		setBlock(world, i + 20, j + 17, k + 18, Blocks.log, 0);
		setBlock(world, i + 20, j + 18, k + 14, Blocks.log, 0);
		setBlock(world, i + 20, j + 18, k + 15, Blocks.log, 0);
		setBlock(world, i + 20, j + 18, k + 16, Blocks.log, 0);
		setBlock(world, i + 20, j + 18, k + 17, Blocks.log, 0);
		setBlock(world, i + 20, j + 18, k + 18, Blocks.log, 0);
		setBlock(world, i + 20, j + 19, k + 14, Blocks.log, 0);
		setBlock(world, i + 20, j + 19, k + 15, Blocks.log, 0);
		setBlock(world, i + 20, j + 19, k + 16, Blocks.log, 0);
		setBlock(world, i + 20, j + 19, k + 17, Blocks.log, 0);
		setBlock(world, i + 20, j + 19, k + 18, Blocks.log, 0);
		setBlock(world, i + 20, j + 20, k + 14, Blocks.log, 0);
		setBlock(world, i + 20, j + 20, k + 15, Blocks.log, 0);
		setBlock(world, i + 20, j + 20, k + 16, Blocks.log, 0);
		setBlock(world, i + 20, j + 20, k + 17, Blocks.log, 0);
		setBlock(world, i + 20, j + 20, k + 18, Blocks.log, 0);
		setBlock(world, i + 20, j + 21, k + 14, Blocks.log, 0);
		setBlock(world, i + 20, j + 21, k + 15, Blocks.log, 0);
		setBlock(world, i + 20, j + 21, k + 16, Blocks.log, 0);
		setBlock(world, i + 20, j + 21, k + 17, Blocks.log, 0);
		setBlock(world, i + 20, j + 21, k + 18, Blocks.log, 0);
		setBlock(world, i + 20, j + 22, k + 14, Blocks.log, 0);
		setBlock(world, i + 20, j + 22, k + 15, Blocks.log, 0);
		setBlock(world, i + 20, j + 22, k + 16, Blocks.log, 0);
		setBlock(world, i + 20, j + 22, k + 17, Blocks.log, 0);
		setBlock(world, i + 20, j + 22, k + 18, Blocks.log, 0);
		setBlock(world, i + 20, j + 23, k + 14, Blocks.log, 0);
		setBlock(world, i + 20, j + 23, k + 15, Blocks.log, 0);
		setBlock(world, i + 20, j + 23, k + 16, Blocks.log, 0);
		setBlock(world, i + 20, j + 23, k + 17, Blocks.log, 0);
		setBlock(world, i + 20, j + 23, k + 18, Blocks.log, 0);
		setBlock(world, i + 20, j + 24, k + 14, Blocks.log, 0);
		setBlock(world, i + 20, j + 24, k + 15, Blocks.log, 0);
		setBlock(world, i + 20, j + 24, k + 16, Blocks.log, 0);
		setBlock(world, i + 20, j + 24, k + 17, Blocks.log, 0);
		setBlock(world, i + 20, j + 24, k + 18, Blocks.log, 0);
		setBlock(world, i + 20, j + 25, k + 14, Blocks.log, 0);
		setBlock(world, i + 20, j + 25, k + 15, Blocks.log, 0);
		setBlock(world, i + 20, j + 25, k + 16, Blocks.log, 0);
		setBlock(world, i + 20, j + 25, k + 17, Blocks.log, 0);
		setBlock(world, i + 20, j + 25, k + 18, Blocks.log, 0);
		setBlock(world, i + 20, j + 26, k + 14, Blocks.log, 0);
		setBlock(world, i + 20, j + 26, k + 15, Blocks.log, 0);
		setBlock(world, i + 20, j + 26, k + 16, Blocks.log, 0);
		setBlock(world, i + 20, j + 26, k + 17, Blocks.log, 0);
		setBlock(world, i + 20, j + 26, k + 18, Blocks.log, 0);
		setBlock(world, i + 20, j + 27, k + 15, Blocks.log, 0);
		setBlock(world, i + 20, j + 27, k + 16, Blocks.log, 0);
		setBlock(world, i + 20, j + 27, k + 17, Blocks.log, 0);
		setBlock(world, i + 20, j + 28, k + 16, Blocks.log, 0);
		setBlock(world, i + 20, j + 28, k + 17, Blocks.log, 0);
		setBlock(world, i + 20, j + 31, k + 13, Blocks.log, 0);
		setBlock(world, i + 20, j + 31, k + 16, Blocks.log, 0);
		setBlock(world, i + 20, j + 32, k + 12, Blocks.log, 0);
		setBlock(world, i + 20, j + 33, k + 11, Blocks.log, 0);
		setBlock(world, i + 20, j + 35, k + 16, Blocks.log, 0);
		setBlock(world, i + 20, j + 36, k + 16, Blocks.log, 0);
		setBlock(world, i + 20, j + 38, k + 16, Blocks.log, 0);
		setBlock(world, i + 20, j + 39, k + 16, Blocks.log, 0);
		setBlock(world, i + 20, j + 40, k + 15, Blocks.log, 0);
		setBlock(world, i + 20, j + 40, k + 16, Blocks.log, 0);
		setBlock(world, i + 20, j + 41, k + 16, Blocks.log, 0);
		setBlock(world, i + 20, j + 42, k + 8, Blocks.log, 0);
		setBlock(world, i + 20, j + 42, k + 11, Blocks.log, 0);
		setBlock(world, i + 20, j + 42, k + 16, Blocks.log, 0);
		setBlock(world, i + 20, j + 43, k + 16, Blocks.log, 0);
		setBlock(world, i + 20, j + 43, k + 22, Blocks.log, 0);
		setBlock(world, i + 20, j + 43, k + 25, Blocks.log, 0);
		setBlock(world, i + 20, j + 43, k + 31, Blocks.log, 0);
		setBlock(world, i + 20, j + 44, k + 8, Blocks.log, 0);
		setBlock(world, i + 20, j + 44, k + 11, Blocks.log, 0);
		setBlock(world, i + 20, j + 44, k + 12, Blocks.log, 0);
		setBlock(world, i + 20, j + 44, k + 18, Blocks.log, 0);
		setBlock(world, i + 20, j + 44, k + 22, Blocks.log, 0);
		setBlock(world, i + 20, j + 45, k + 6, Blocks.log, 0);
		setBlock(world, i + 20, j + 45, k + 13, Blocks.log, 0);
		setBlock(world, i + 20, j + 46, k + 11, Blocks.log, 0);
		setBlock(world, i + 20, j + 47, k + 11, Blocks.log, 0);
		setBlock(world, i + 20, j + 47, k + 19, Blocks.log, 0);
		setBlock(world, i + 20, j + 48, k + 19, Blocks.log, 0);
		setBlock(world, i + 20, j + 48, k + 20, Blocks.log, 0);
		setBlock(world, i + 21, j + 0, k + 13, Blocks.log, 0);
		setBlock(world, i + 21, j + 0, k + 14, Blocks.log, 0);
		setBlock(world, i + 21, j + 0, k + 15, Blocks.log, 0);
		setBlock(world, i + 21, j + 0, k + 16, Blocks.log, 0);
		setBlock(world, i + 21, j + 0, k + 17, Blocks.log, 0);
		setBlock(world, i + 21, j + 1, k + 13, Blocks.log, 0);
		setBlock(world, i + 21, j + 1, k + 14, Blocks.log, 0);
		setBlock(world, i + 21, j + 1, k + 15, Blocks.log, 0);
		setBlock(world, i + 21, j + 1, k + 16, Blocks.log, 0);
		setBlock(world, i + 21, j + 1, k + 17, Blocks.log, 0);
		setBlock(world, i + 21, j + 2, k + 13, Blocks.log, 0);
		setBlock(world, i + 21, j + 2, k + 14, Blocks.log, 0);
		setBlock(world, i + 21, j + 2, k + 15, Blocks.log, 0);
		setBlock(world, i + 21, j + 2, k + 16, Blocks.log, 0);
		setBlock(world, i + 21, j + 2, k + 17, Blocks.log, 0);
		setBlock(world, i + 21, j + 3, k + 14, Blocks.log, 0);
		setBlock(world, i + 21, j + 3, k + 15, Blocks.log, 0);
		setBlock(world, i + 21, j + 3, k + 16, Blocks.log, 0);
		setBlock(world, i + 21, j + 3, k + 17, Blocks.log, 0);
		setBlock(world, i + 21, j + 4, k + 14, Blocks.log, 0);
		setBlock(world, i + 21, j + 4, k + 15, Blocks.log, 0);
		setBlock(world, i + 21, j + 4, k + 16, Blocks.log, 0);
		setBlock(world, i + 21, j + 4, k + 17, Blocks.log, 0);
		setBlock(world, i + 21, j + 5, k + 14, Blocks.log, 0);
		setBlock(world, i + 21, j + 5, k + 15, Blocks.log, 0);
		setBlock(world, i + 21, j + 5, k + 16, Blocks.log, 0);
		setBlock(world, i + 21, j + 5, k + 17, Blocks.log, 0);
		setBlock(world, i + 21, j + 6, k + 14, Blocks.log, 0);
		setBlock(world, i + 21, j + 6, k + 15, Blocks.log, 0);
		setBlock(world, i + 21, j + 6, k + 16, Blocks.log, 0);
		setBlock(world, i + 21, j + 6, k + 17, Blocks.log, 0);
		setBlock(world, i + 21, j + 7, k + 14, Blocks.log, 0);
		setBlock(world, i + 21, j + 7, k + 15, Blocks.log, 0);
		setBlock(world, i + 21, j + 7, k + 16, Blocks.log, 0);
		setBlock(world, i + 21, j + 8, k + 15, Blocks.log, 0);
		setBlock(world, i + 21, j + 8, k + 16, Blocks.log, 0);
		setBlock(world, i + 21, j + 9, k + 15, Blocks.log, 0);
		setBlock(world, i + 21, j + 9, k + 16, Blocks.log, 0);
		setBlock(world, i + 21, j + 10, k + 15, Blocks.log, 0);
		setBlock(world, i + 21, j + 10, k + 16, Blocks.log, 0);
		setBlock(world, i + 21, j + 11, k + 15, Blocks.log, 0);
		setBlock(world, i + 21, j + 11, k + 16, Blocks.log, 0);
		setBlock(world, i + 21, j + 11, k + 17, Blocks.log, 0);
		setBlock(world, i + 21, j + 12, k + 14, Blocks.log, 0);
		setBlock(world, i + 21, j + 12, k + 15, Blocks.log, 0);
		setBlock(world, i + 21, j + 12, k + 16, Blocks.log, 0);
		setBlock(world, i + 21, j + 12, k + 17, Blocks.log, 0);
		setBlock(world, i + 21, j + 13, k + 14, Blocks.log, 0);
		setBlock(world, i + 21, j + 13, k + 15, Blocks.log, 0);
		setBlock(world, i + 21, j + 13, k + 16, Blocks.log, 0);
		setBlock(world, i + 21, j + 13, k + 17, Blocks.log, 0);
		setBlock(world, i + 21, j + 13, k + 18, Blocks.log, 0);
		setBlock(world, i + 21, j + 14, k + 14, Blocks.log, 0);
		setBlock(world, i + 21, j + 14, k + 15, Blocks.log, 0);
		setBlock(world, i + 21, j + 14, k + 16, Blocks.log, 0);
		setBlock(world, i + 21, j + 14, k + 17, Blocks.log, 0);
		setBlock(world, i + 21, j + 14, k + 18, Blocks.log, 0);
		setBlock(world, i + 21, j + 15, k + 14, Blocks.log, 0);
		setBlock(world, i + 21, j + 15, k + 15, Blocks.log, 0);
		setBlock(world, i + 21, j + 15, k + 16, Blocks.log, 0);
		setBlock(world, i + 21, j + 15, k + 17, Blocks.log, 0);
		setBlock(world, i + 21, j + 15, k + 18, Blocks.log, 0);
		setBlock(world, i + 21, j + 16, k + 14, Blocks.log, 0);
		setBlock(world, i + 21, j + 16, k + 15, Blocks.log, 0);
		setBlock(world, i + 21, j + 16, k + 16, Blocks.log, 0);
		setBlock(world, i + 21, j + 16, k + 17, Blocks.log, 0);
		setBlock(world, i + 21, j + 16, k + 18, Blocks.log, 0);
		setBlock(world, i + 21, j + 17, k + 14, Blocks.log, 0);
		setBlock(world, i + 21, j + 17, k + 15, Blocks.log, 0);
		setBlock(world, i + 21, j + 17, k + 16, Blocks.log, 0);
		setBlock(world, i + 21, j + 17, k + 17, Blocks.log, 0);
		setBlock(world, i + 21, j + 17, k + 18, Blocks.log, 0);
		setBlock(world, i + 21, j + 18, k + 14, Blocks.log, 0);
		setBlock(world, i + 21, j + 18, k + 15, Blocks.log, 0);
		setBlock(world, i + 21, j + 18, k + 16, Blocks.log, 0);
		setBlock(world, i + 21, j + 18, k + 17, Blocks.log, 0);
		setBlock(world, i + 21, j + 18, k + 18, Blocks.log, 0);
		setBlock(world, i + 21, j + 19, k + 14, Blocks.log, 0);
		setBlock(world, i + 21, j + 19, k + 15, Blocks.log, 0);
		setBlock(world, i + 21, j + 19, k + 16, Blocks.log, 0);
		setBlock(world, i + 21, j + 19, k + 17, Blocks.log, 0);
		setBlock(world, i + 21, j + 19, k + 18, Blocks.log, 0);
		setBlock(world, i + 21, j + 20, k + 14, Blocks.log, 0);
		setBlock(world, i + 21, j + 20, k + 15, Blocks.log, 0);
		setBlock(world, i + 21, j + 20, k + 16, Blocks.log, 0);
		setBlock(world, i + 21, j + 20, k + 17, Blocks.log, 0);
		setBlock(world, i + 21, j + 20, k + 18, Blocks.log, 0);
		setBlock(world, i + 21, j + 21, k + 14, Blocks.log, 0);
		setBlock(world, i + 21, j + 21, k + 15, Blocks.log, 0);
		setBlock(world, i + 21, j + 21, k + 16, Blocks.log, 0);
		setBlock(world, i + 21, j + 21, k + 17, Blocks.log, 0);
		setBlock(world, i + 21, j + 21, k + 18, Blocks.log, 0);
		setBlock(world, i + 21, j + 22, k + 14, Blocks.log, 0);
		setBlock(world, i + 21, j + 22, k + 15, Blocks.log, 0);
		setBlock(world, i + 21, j + 22, k + 16, Blocks.log, 0);
		setBlock(world, i + 21, j + 22, k + 17, Blocks.log, 0);
		setBlock(world, i + 21, j + 22, k + 18, Blocks.log, 0);
		setBlock(world, i + 21, j + 23, k + 15, Blocks.log, 0);
		setBlock(world, i + 21, j + 23, k + 16, Blocks.log, 0);
		setBlock(world, i + 21, j + 23, k + 17, Blocks.log, 0);
		setBlock(world, i + 21, j + 24, k + 15, Blocks.log, 0);
		setBlock(world, i + 21, j + 24, k + 16, Blocks.log, 0);
		setBlock(world, i + 21, j + 24, k + 17, Blocks.log, 0);
		setBlock(world, i + 21, j + 25, k + 15, Blocks.log, 0);
		setBlock(world, i + 21, j + 25, k + 16, Blocks.log, 0);
		setBlock(world, i + 21, j + 25, k + 17, Blocks.log, 0);
		setBlock(world, i + 21, j + 26, k + 15, Blocks.log, 0);
		setBlock(world, i + 21, j + 26, k + 16, Blocks.log, 0);
		setBlock(world, i + 21, j + 26, k + 17, Blocks.log, 0);
		setBlock(world, i + 21, j + 27, k + 15, Blocks.log, 0);
		setBlock(world, i + 21, j + 27, k + 16, Blocks.log, 0);
		setBlock(world, i + 21, j + 27, k + 17, Blocks.log, 0);
		setBlock(world, i + 21, j + 28, k + 15, Blocks.log, 0);
		setBlock(world, i + 21, j + 28, k + 16, Blocks.log, 0);
		setBlock(world, i + 21, j + 28, k + 17, Blocks.log, 0);
		setBlock(world, i + 21, j + 29, k + 16, Blocks.log, 0);
		setBlock(world, i + 21, j + 29, k + 17, Blocks.log, 0);
		setBlock(world, i + 21, j + 30, k + 16, Blocks.log, 0);
		setBlock(world, i + 21, j + 34, k + 10, Blocks.log, 0);
		setBlock(world, i + 21, j + 35, k + 9, Blocks.log, 0);
		setBlock(world, i + 21, j + 36, k + 8, Blocks.log, 0);
		setBlock(world, i + 21, j + 36, k + 16, Blocks.log, 0);
		setBlock(world, i + 21, j + 37, k + 7, Blocks.log, 0);
		setBlock(world, i + 21, j + 38, k + 6, Blocks.log, 0);
		setBlock(world, i + 21, j + 38, k + 14, Blocks.log, 0);
		setBlock(world, i + 21, j + 38, k + 16, Blocks.log, 0);
		setBlock(world, i + 21, j + 39, k + 5, Blocks.log, 0);
		setBlock(world, i + 21, j + 40, k + 4, Blocks.log, 0);
		setBlock(world, i + 21, j + 40, k + 6, Blocks.log, 0);
		setBlock(world, i + 21, j + 40, k + 16, Blocks.log, 0);
		setBlock(world, i + 21, j + 41, k + 14, Blocks.log, 0);
		setBlock(world, i + 21, j + 41, k + 24, Blocks.log, 0);
		setBlock(world, i + 21, j + 41, k + 25, Blocks.log, 0);
		setBlock(world, i + 21, j + 42, k + 9, Blocks.log, 0);
		setBlock(world, i + 21, j + 42, k + 13, Blocks.log, 0);
		setBlock(world, i + 21, j + 42, k + 15, Blocks.log, 0);
		setBlock(world, i + 21, j + 42, k + 17, Blocks.log, 0);
		setBlock(world, i + 21, j + 43, k + 9, Blocks.log, 0);
		setBlock(world, i + 21, j + 43, k + 12, Blocks.log, 0);
		setBlock(world, i + 21, j + 43, k + 14, Blocks.log, 0);
		setBlock(world, i + 21, j + 44, k + 12, Blocks.log, 0);
		setBlock(world, i + 21, j + 46, k + 13, Blocks.log, 0);
		setBlock(world, i + 21, j + 47, k + 7, Blocks.log, 0);
		setBlock(world, i + 21, j + 47, k + 8, Blocks.log, 0);
		setBlock(world, i + 21, j + 47, k + 13, Blocks.log, 0);
		setBlock(world, i + 21, j + 47, k + 18, Blocks.log, 0);
		setBlock(world, i + 21, j + 48, k + 17, Blocks.log, 0);
		setBlock(world, i + 21, j + 48, k + 21, Blocks.log, 0);
		setBlock(world, i + 21, j + 48, k + 22, Blocks.log, 0);
		setBlock(world, i + 22, j + 0, k + 14, Blocks.log, 0);
		setBlock(world, i + 22, j + 0, k + 15, Blocks.log, 0);
		setBlock(world, i + 22, j + 0, k + 16, Blocks.log, 0);
		setBlock(world, i + 22, j + 1, k + 14, Blocks.log, 0);
		setBlock(world, i + 22, j + 1, k + 15, Blocks.log, 0);
		setBlock(world, i + 22, j + 1, k + 16, Blocks.log, 0);
		setBlock(world, i + 22, j + 2, k + 14, Blocks.log, 0);
		setBlock(world, i + 22, j + 2, k + 15, Blocks.log, 0);
		setBlock(world, i + 22, j + 2, k + 16, Blocks.log, 0);
		setBlock(world, i + 22, j + 3, k + 14, Blocks.log, 0);
		setBlock(world, i + 22, j + 3, k + 15, Blocks.log, 0);
		setBlock(world, i + 22, j + 3, k + 16, Blocks.log, 0);
		setBlock(world, i + 22, j + 4, k + 14, Blocks.log, 0);
		setBlock(world, i + 22, j + 4, k + 15, Blocks.log, 0);
		setBlock(world, i + 22, j + 4, k + 16, Blocks.log, 0);
		setBlock(world, i + 22, j + 5, k + 14, Blocks.log, 0);
		setBlock(world, i + 22, j + 5, k + 15, Blocks.log, 0);
		setBlock(world, i + 22, j + 5, k + 16, Blocks.log, 0);
		setBlock(world, i + 22, j + 6, k + 14, Blocks.log, 0);
		setBlock(world, i + 22, j + 6, k + 15, Blocks.log, 0);
		setBlock(world, i + 22, j + 6, k + 16, Blocks.log, 0);
		setBlock(world, i + 22, j + 7, k + 14, Blocks.log, 0);
		setBlock(world, i + 22, j + 7, k + 15, Blocks.log, 0);
		setBlock(world, i + 22, j + 7, k + 16, Blocks.log, 0);
		setBlock(world, i + 22, j + 8, k + 15, Blocks.log, 0);
		setBlock(world, i + 22, j + 8, k + 16, Blocks.log, 0);
		setBlock(world, i + 22, j + 9, k + 15, Blocks.log, 0);
		setBlock(world, i + 22, j + 9, k + 16, Blocks.log, 0);
		setBlock(world, i + 22, j + 10, k + 15, Blocks.log, 0);
		setBlock(world, i + 22, j + 10, k + 16, Blocks.log, 0);
		setBlock(world, i + 22, j + 10, k + 17, Blocks.log, 0);
		setBlock(world, i + 22, j + 11, k + 15, Blocks.log, 0);
		setBlock(world, i + 22, j + 11, k + 16, Blocks.log, 0);
		setBlock(world, i + 22, j + 11, k + 17, Blocks.log, 0);
		setBlock(world, i + 22, j + 12, k + 15, Blocks.log, 0);
		setBlock(world, i + 22, j + 12, k + 16, Blocks.log, 0);
		setBlock(world, i + 22, j + 12, k + 17, Blocks.log, 0);
		setBlock(world, i + 22, j + 13, k + 15, Blocks.log, 0);
		setBlock(world, i + 22, j + 13, k + 16, Blocks.log, 0);
		setBlock(world, i + 22, j + 13, k + 17, Blocks.log, 0);
		setBlock(world, i + 22, j + 13, k + 18, Blocks.log, 0);
		setBlock(world, i + 22, j + 14, k + 15, Blocks.log, 0);
		setBlock(world, i + 22, j + 14, k + 16, Blocks.log, 0);
		setBlock(world, i + 22, j + 14, k + 17, Blocks.log, 0);
		setBlock(world, i + 22, j + 14, k + 18, Blocks.log, 0);
		setBlock(world, i + 22, j + 15, k + 15, Blocks.log, 0);
		setBlock(world, i + 22, j + 15, k + 16, Blocks.log, 0);
		setBlock(world, i + 22, j + 15, k + 17, Blocks.log, 0);
		setBlock(world, i + 22, j + 15, k + 18, Blocks.log, 0);
		setBlock(world, i + 22, j + 16, k + 15, Blocks.log, 0);
		setBlock(world, i + 22, j + 16, k + 16, Blocks.log, 0);
		setBlock(world, i + 22, j + 16, k + 17, Blocks.log, 0);
		setBlock(world, i + 22, j + 17, k + 15, Blocks.log, 0);
		setBlock(world, i + 22, j + 17, k + 16, Blocks.log, 0);
		setBlock(world, i + 22, j + 17, k + 17, Blocks.log, 0);
		setBlock(world, i + 22, j + 18, k + 15, Blocks.log, 0);
		setBlock(world, i + 22, j + 18, k + 16, Blocks.log, 0);
		setBlock(world, i + 22, j + 18, k + 17, Blocks.log, 0);
		setBlock(world, i + 22, j + 19, k + 15, Blocks.log, 0);
		setBlock(world, i + 22, j + 19, k + 16, Blocks.log, 0);
		setBlock(world, i + 22, j + 19, k + 17, Blocks.log, 0);
		setBlock(world, i + 22, j + 20, k + 15, Blocks.log, 0);
		setBlock(world, i + 22, j + 20, k + 16, Blocks.log, 0);
		setBlock(world, i + 22, j + 20, k + 17, Blocks.log, 0);
		setBlock(world, i + 22, j + 21, k + 15, Blocks.log, 0);
		setBlock(world, i + 22, j + 21, k + 16, Blocks.log, 0);
		setBlock(world, i + 22, j + 21, k + 17, Blocks.log, 0);
		setBlock(world, i + 22, j + 22, k + 15, Blocks.log, 0);
		setBlock(world, i + 22, j + 22, k + 16, Blocks.log, 0);
		setBlock(world, i + 22, j + 22, k + 17, Blocks.log, 0);
		setBlock(world, i + 22, j + 23, k + 16, Blocks.log, 0);
		setBlock(world, i + 22, j + 24, k + 16, Blocks.log, 0);
		setBlock(world, i + 22, j + 25, k + 16, Blocks.log, 0);
		setBlock(world, i + 22, j + 26, k + 16, Blocks.log, 0);
		setBlock(world, i + 22, j + 30, k + 15, Blocks.log, 0);
		setBlock(world, i + 22, j + 31, k + 14, Blocks.log, 0);
		setBlock(world, i + 22, j + 40, k + 12, Blocks.log, 0);
		setBlock(world, i + 22, j + 41, k + 3, Blocks.log, 0);
		setBlock(world, i + 22, j + 42, k + 23, Blocks.log, 0);
		setBlock(world, i + 22, j + 42, k + 24, Blocks.log, 0);
		setBlock(world, i + 22, j + 43, k + 14, Blocks.log, 0);
		setBlock(world, i + 22, j + 43, k + 18, Blocks.log, 0);
		setBlock(world, i + 22, j + 44, k + 11, Blocks.log, 0);
		setBlock(world, i + 22, j + 44, k + 12, Blocks.log, 0);
		setBlock(world, i + 22, j + 44, k + 13, Blocks.log, 0);
		setBlock(world, i + 22, j + 46, k + 13, Blocks.log, 0);
		setBlock(world, i + 22, j + 47, k + 11, Blocks.log, 0);
		setBlock(world, i + 22, j + 47, k + 13, Blocks.log, 0);
		setBlock(world, i + 22, j + 47, k + 24, Blocks.log, 0);
		setBlock(world, i + 22, j + 48, k + 16, Blocks.log, 0);
		setBlock(world, i + 23, j + 40, k + 13, Blocks.log, 0);
		setBlock(world, i + 23, j + 41, k + 5, Blocks.log, 0);
		setBlock(world, i + 23, j + 41, k + 11, Blocks.log, 0);
		setBlock(world, i + 23, j + 41, k + 20, Blocks.log, 0);
		setBlock(world, i + 23, j + 41, k + 24, Blocks.log, 0);
		setBlock(world, i + 23, j + 43, k + 3, Blocks.log, 0);
		setBlock(world, i + 23, j + 43, k + 18, Blocks.log, 0);
		setBlock(world, i + 23, j + 44, k + 15, Blocks.log, 0);
		setBlock(world, i + 23, j + 44, k + 18, Blocks.log, 0);
		setBlock(world, i + 23, j + 44, k + 19, Blocks.log, 0);
		setBlock(world, i + 23, j + 45, k + 12, Blocks.log, 0);
		setBlock(world, i + 23, j + 45, k + 14, Blocks.log, 0);
		setBlock(world, i + 23, j + 45, k + 19, Blocks.log, 0);
		setBlock(world, i + 23, j + 46, k + 12, Blocks.log, 0);
		setBlock(world, i + 23, j + 47, k + 20, Blocks.log, 0);
		setBlock(world, i + 23, j + 48, k + 13, Blocks.log, 0);
		setBlock(world, i + 23, j + 48, k + 16, Blocks.log, 0);
		setBlock(world, i + 23, j + 48, k + 18, Blocks.log, 0);
		setBlock(world, i + 24, j + 43, k + 23, Blocks.log, 0);
		setBlock(world, i + 24, j + 44, k + 19, Blocks.log, 0);
		setBlock(world, i + 24, j + 44, k + 21, Blocks.log, 0);
		setBlock(world, i + 24, j + 45, k + 18, Blocks.log, 0);
		setBlock(world, i + 24, j + 46, k + 11, Blocks.log, 0);
		setBlock(world, i + 24, j + 46, k + 17, Blocks.log, 0);
		setBlock(world, i + 24, j + 46, k + 19, Blocks.log, 0);
		setBlock(world, i + 24, j + 47, k + 19, Blocks.log, 0);
		setBlock(world, i + 24, j + 48, k + 17, Blocks.log, 0);
		setBlock(world, i + 24, j + 48, k + 22, Blocks.log, 0);
		setBlock(world, i + 25, j + 35, k + 11, Blocks.log, 0);
		setBlock(world, i + 25, j + 41, k + 11, Blocks.log, 0);
		setBlock(world, i + 25, j + 41, k + 17, Blocks.log, 0);
		setBlock(world, i + 25, j + 45, k + 15, Blocks.log, 0);
		setBlock(world, i + 25, j + 45, k + 16, Blocks.log, 0);
		setBlock(world, i + 25, j + 45, k + 19, Blocks.log, 0);
		setBlock(world, i + 25, j + 46, k + 11, Blocks.log, 0);
		setBlock(world, i + 25, j + 47, k + 17, Blocks.log, 0);
		setBlock(world, i + 25, j + 48, k + 14, Blocks.log, 0);
		setBlock(world, i + 25, j + 48, k + 15, Blocks.log, 0);
		setBlock(world, i + 25, j + 48, k + 19, Blocks.log, 0);
		setBlock(world, i + 26, j + 40, k + 33, Blocks.log, 0);
		setBlock(world, i + 26, j + 41, k + 14, Blocks.log, 0);
		setBlock(world, i + 26, j + 42, k + 20, Blocks.log, 0);
		setBlock(world, i + 26, j + 43, k + 14, Blocks.log, 0);
		setBlock(world, i + 26, j + 43, k + 18, Blocks.log, 0);
		setBlock(world, i + 26, j + 45, k + 14, Blocks.log, 0);
		setBlock(world, i + 26, j + 46, k + 16, Blocks.log, 0);
		setBlock(world, i + 26, j + 47, k + 17, Blocks.log, 0);
		setBlock(world, i + 26, j + 48, k + 21, Blocks.log, 0);
		setBlock(world, i + 27, j + 38, k + 8, Blocks.log, 0);
		setBlock(world, i + 27, j + 41, k + 14, Blocks.log, 0);
		setBlock(world, i + 27, j + 41, k + 20, Blocks.log, 0);
		setBlock(world, i + 27, j + 41, k + 23, Blocks.log, 0);
		setBlock(world, i + 27, j + 42, k + 2, Blocks.log, 0);
		setBlock(world, i + 27, j + 42, k + 15, Blocks.log, 0);
		setBlock(world, i + 27, j + 43, k + 23, Blocks.log, 0);
		setBlock(world, i + 27, j + 45, k + 15, Blocks.log, 0);
		setBlock(world, i + 27, j + 45, k + 18, Blocks.log, 0);
		setBlock(world, i + 27, j + 46, k + 17, Blocks.log, 0);
		setBlock(world, i + 28, j + 39, k + 7, Blocks.log, 0);
		setBlock(world, i + 28, j + 40, k + 13, Blocks.log, 0);
		setBlock(world, i + 28, j + 42, k + 23, Blocks.log, 0);
		setBlock(world, i + 28, j + 43, k + 13, Blocks.log, 0);
		setBlock(world, i + 28, j + 46, k + 12, Blocks.log, 0);
		setBlock(world, i + 29, j + 39, k + 24, Blocks.log, 0);
		setBlock(world, i + 29, j + 41, k + 17, Blocks.log, 0);
		setBlock(world, i + 29, j + 41, k + 23, Blocks.log, 0);
		setBlock(world, i + 29, j + 43, k + 20, Blocks.log, 0);
		setBlock(world, i + 29, j + 44, k + 22, Blocks.log, 0);
		setBlock(world, i + 29, j + 47, k + 16, Blocks.log, 0);
		setBlock(world, i + 30, j + 39, k + 16, Blocks.log, 0);
		setBlock(world, i + 30, j + 42, k + 16, Blocks.log, 0);
		setBlock(world, i + 30, j + 44, k + 13, Blocks.log, 0);
		setBlock(world, i + 30, j + 44, k + 14, Blocks.log, 0);
		setBlock(world, i + 30, j + 44, k + 21, Blocks.log, 0);
		setBlock(world, i + 31, j + 39, k + 23, Blocks.log, 0);
		setBlock(world, i + 31, j + 42, k + 13, Blocks.log, 0);
		setBlock(world, i + 32, j + 40, k + 9, Blocks.log, 0);
		setBlock(world, i + 32, j + 40, k + 15, Blocks.log, 0);
		setBlock(world, i + 33, j + 40, k + 23, Blocks.log, 0);
		setBlock(world, i + 33, j + 43, k + 15, Blocks.log, 0);
		setBlock(world, i + 33, j + 43, k + 16, Blocks.log, 0);
		setBlock(world, i + 34, j + 40, k + 26, Blocks.log, 0);
		setBlock(world, i + 34, j + 41, k + 15, Blocks.log, 0);
		setBlock(world, i + 34, j + 42, k + 23, Blocks.log, 0);
		setBlock(world, i + 0, j + 37, k + 18, Blocks.leaves, 4);
		world.setBlockMetadataWithNotify(i + 0, j + 37, k + 18, 4, 2);
		setBlock(world, i + 0, j + 39, k + 19, Blocks.leaves, 4);
		world.setBlockMetadataWithNotify(i + 0, j + 39, k + 19, 4, 2);
		setBlock(world, i + 0, j + 39, k + 20, Blocks.leaves, 4);
		world.setBlockMetadataWithNotify(i + 0, j + 39, k + 20, 4, 2);
		setBlock(world, i + 0, j + 39, k + 21, Blocks.leaves, 4);
		world.setBlockMetadataWithNotify(i + 0, j + 39, k + 21, 4, 2);
		setBlock(world, i + 0, j + 40, k + 20, Blocks.leaves, 4);
		world.setBlockMetadataWithNotify(i + 0, j + 40, k + 20, 4, 2);
		setBlock(world, i + 1, j + 36, k + 18, Blocks.leaves, 4);
		world.setBlockMetadataWithNotify(i + 1, j + 36, k + 18, 4, 2);
		setBlock(world, i + 1, j + 37, k + 17, Blocks.leaves, 4);
		world.setBlockMetadataWithNotify(i + 1, j + 37, k + 17, 4, 2);
		setBlock(world, i + 1, j + 37, k + 18, Blocks.leaves, 4);
		world.setBlockMetadataWithNotify(i + 1, j + 37, k + 18, 4, 2);
		setBlock(world, i + 1, j + 37, k + 19, Blocks.leaves, 4);
		world.setBlockMetadataWithNotify(i + 1, j + 37, k + 19, 4, 2);
		setBlock(world, i + 1, j + 38, k + 18, Blocks.leaves, 4);
		world.setBlockMetadataWithNotify(i + 1, j + 38, k + 18, 4, 2);
		setBlock(world, i + 1, j + 39, k + 18, Blocks.leaves, 4);
		world.setBlockMetadataWithNotify(i + 1, j + 39, k + 18, 4, 2);
		setBlock(world, i + 1, j + 39, k + 19, Blocks.leaves, 4);
		world.setBlockMetadataWithNotify(i + 1, j + 39, k + 19, 4, 2);
		setBlock(world, i + 1, j + 39, k + 20, Blocks.leaves, 4);
		world.setBlockMetadataWithNotify(i + 1, j + 39, k + 20, 4, 2);
		setBlock(world, i + 1, j + 39, k + 21, Blocks.leaves, 4);
		world.setBlockMetadataWithNotify(i + 1, j + 39, k + 21, 4, 2);
		setBlock(world, i + 1, j + 39, k + 22, Blocks.leaves, 4);
		world.setBlockMetadataWithNotify(i + 1, j + 39, k + 22, 4, 2);
		setBlock(world, i + 1, j + 40, k + 19, Blocks.leaves, 4);
		world.setBlockMetadataWithNotify(i + 1, j + 40, k + 19, 4, 2);
		setBlock(world, i + 1, j + 40, k + 20, Blocks.leaves, 4);
		world.setBlockMetadataWithNotify(i + 1, j + 40, k + 20, 4, 2);
		setBlock(world, i + 1, j + 40, k + 21, Blocks.leaves, 4);
		world.setBlockMetadataWithNotify(i + 1, j + 40, k + 21, 4, 2);
		setBlock(world, i + 2, j + 36, k + 18, Blocks.leaves, 4);
		world.setBlockMetadataWithNotify(i + 2, j + 36, k + 18, 4, 2);
		setBlock(world, i + 2, j + 37, k + 17, Blocks.leaves, 4);
		world.setBlockMetadataWithNotify(i + 2, j + 37, k + 17, 4, 2);
		setBlock(world, i + 2, j + 37, k + 18, Blocks.leaves, 4);
		world.setBlockMetadataWithNotify(i + 2, j + 37, k + 18, 4, 2);
		setBlock(world, i + 2, j + 37, k + 19, Blocks.leaves, 4);
		world.setBlockMetadataWithNotify(i + 2, j + 37, k + 19, 4, 2);
		setBlock(world, i + 2, j + 38, k + 18, Blocks.leaves, 4);
		world.setBlockMetadataWithNotify(i + 2, j + 38, k + 18, 4, 2);
		setBlock(world, i + 2, j + 39, k + 18, Blocks.leaves, 4);
		world.setBlockMetadataWithNotify(i + 2, j + 39, k + 18, 4, 2);
		setBlock(world, i + 2, j + 39, k + 19, Blocks.leaves, 4);
		world.setBlockMetadataWithNotify(i + 2, j + 39, k + 19, 4, 2);
		setBlock(world, i + 2, j + 39, k + 21, Blocks.leaves, 4);
		world.setBlockMetadataWithNotify(i + 2, j + 39, k + 21, 4, 2);
		setBlock(world, i + 2, j + 39, k + 22, Blocks.leaves, 4);
		world.setBlockMetadataWithNotify(i + 2, j + 39, k + 22, 4, 2);
		setBlock(world, i + 2, j + 40, k + 18, Blocks.leaves, 4);
		world.setBlockMetadataWithNotify(i + 2, j + 40, k + 18, 4, 2);
		setBlock(world, i + 2, j + 40, k + 19, Blocks.leaves, 4);
		world.setBlockMetadataWithNotify(i + 2, j + 40, k + 19, 4, 2);
		setBlock(world, i + 2, j + 40, k + 20, Blocks.leaves, 4);
		world.setBlockMetadataWithNotify(i + 2, j + 40, k + 20, 4, 2);
		setBlock(world, i + 2, j + 40, k + 21, Blocks.leaves, 4);
		world.setBlockMetadataWithNotify(i + 2, j + 40, k + 21, 4, 2);
		setBlock(world, i + 2, j + 40, k + 22, Blocks.leaves, 4);
		world.setBlockMetadataWithNotify(i + 2, j + 40, k + 22, 4, 2);
		setBlock(world, i + 2, j + 42, k + 9, Blocks.leaves, 4);
		world.setBlockMetadataWithNotify(i + 2, j + 42, k + 9, 4, 2);
		setBlock(world, i + 2, j + 42, k + 10, Blocks.leaves, 4);
		world.setBlockMetadataWithNotify(i + 2, j + 42, k + 10, 4, 2);
		setBlock(world, i + 2, j + 42, k + 11, Blocks.leaves, 4);
		world.setBlockMetadataWithNotify(i + 2, j + 42, k + 11, 4, 2);
		setBlock(world, i + 2, j + 42, k + 21, Blocks.leaves, 4);
		world.setBlockMetadataWithNotify(i + 2, j + 42, k + 21, 4, 2);
		setBlock(world, i + 2, j + 42, k + 22, Blocks.leaves, 4);
		world.setBlockMetadataWithNotify(i + 2, j + 42, k + 22, 4, 2);
		setBlock(world, i + 2, j + 42, k + 23, Blocks.leaves, 4);
		world.setBlockMetadataWithNotify(i + 2, j + 42, k + 23, 4, 2);
		setBlock(world, i + 2, j + 43, k + 10, Blocks.leaves, 4);
		world.setBlockMetadataWithNotify(i + 2, j + 43, k + 10, 4, 2);
		setBlock(world, i + 2, j + 43, k + 22, Blocks.leaves, 4);
		world.setBlockMetadataWithNotify(i + 2, j + 43, k + 22, 4, 2);
		setBlock(world, i + 3, j + 36, k + 19, Blocks.leaves, 4);
		world.setBlockMetadataWithNotify(i + 3, j + 36, k + 19, 4, 2);
		setBlock(world, i + 3, j + 37, k + 18, Blocks.leaves, 4);
		world.setBlockMetadataWithNotify(i + 3, j + 37, k + 18, 4, 2);
		setBlock(world, i + 3, j + 37, k + 19, Blocks.leaves, 4);
		world.setBlockMetadataWithNotify(i + 3, j + 37, k + 19, 4, 2);
		setBlock(world, i + 3, j + 37, k + 20, Blocks.leaves, 4);
		world.setBlockMetadataWithNotify(i + 3, j + 37, k + 20, 4, 2);
		setBlock(world, i + 3, j + 38, k + 18, Blocks.leaves, 4);
		world.setBlockMetadataWithNotify(i + 3, j + 38, k + 18, 4, 2);
		setBlock(world, i + 3, j + 38, k + 19, Blocks.leaves, 4);
		world.setBlockMetadataWithNotify(i + 3, j + 38, k + 19, 4, 2);
		setBlock(world, i + 3, j + 39, k + 18, Blocks.leaves, 4);
		world.setBlockMetadataWithNotify(i + 3, j + 39, k + 18, 4, 2);
		setBlock(world, i + 3, j + 39, k + 19, Blocks.leaves, 4);
		world.setBlockMetadataWithNotify(i + 3, j + 39, k + 19, 4, 2);
		setBlock(world, i + 3, j + 39, k + 20, Blocks.leaves, 4);
		world.setBlockMetadataWithNotify(i + 3, j + 39, k + 20, 4, 2);
		setBlock(world, i + 3, j + 39, k + 21, Blocks.leaves, 4);
		world.setBlockMetadataWithNotify(i + 3, j + 39, k + 21, 4, 2);
		setBlock(world, i + 3, j + 39, k + 22, Blocks.leaves, 4);
		world.setBlockMetadataWithNotify(i + 3, j + 39, k + 22, 4, 2);
		setBlock(world, i + 3, j + 40, k + 17, Blocks.leaves, 4);
		world.setBlockMetadataWithNotify(i + 3, j + 40, k + 17, 4, 2);
		setBlock(world, i + 3, j + 40, k + 19, Blocks.leaves, 4);
		world.setBlockMetadataWithNotify(i + 3, j + 40, k + 19, 4, 2);
		setBlock(world, i + 3, j + 40, k + 20, Blocks.leaves, 4);
		world.setBlockMetadataWithNotify(i + 3, j + 40, k + 20, 4, 2);
		setBlock(world, i + 3, j + 40, k + 21, Blocks.leaves, 4);
		world.setBlockMetadataWithNotify(i + 3, j + 40, k + 21, 4, 2);
		setBlock(world, i + 3, j + 42, k + 8, Blocks.leaves, 4);
		world.setBlockMetadataWithNotify(i + 3, j + 42, k + 8, 4, 2);
		setBlock(world, i + 3, j + 42, k + 9, Blocks.leaves, 4);
		world.setBlockMetadataWithNotify(i + 3, j + 42, k + 9, 4, 2);
		setBlock(world, i + 3, j + 42, k + 10, Blocks.leaves, 4);
		world.setBlockMetadataWithNotify(i + 3, j + 42, k + 10, 4, 2);
		setBlock(world, i + 3, j + 42, k + 11, Blocks.leaves, 4);
		world.setBlockMetadataWithNotify(i + 3, j + 42, k + 11, 4, 2);
		setBlock(world, i + 3, j + 42, k + 12, Blocks.leaves, 4);
		world.setBlockMetadataWithNotify(i + 3, j + 42, k + 12, 4, 2);
		setBlock(world, i + 3, j + 42, k + 20, Blocks.leaves, 4);
		world.setBlockMetadataWithNotify(i + 3, j + 42, k + 20, 4, 2);
		setBlock(world, i + 3, j + 42, k + 21, Blocks.leaves, 4);
		world.setBlockMetadataWithNotify(i + 3, j + 42, k + 21, 4, 2);
		setBlock(world, i + 3, j + 42, k + 22, Blocks.leaves, 4);
		world.setBlockMetadataWithNotify(i + 3, j + 42, k + 22, 4, 2);
		setBlock(world, i + 3, j + 42, k + 23, Blocks.leaves, 4);
		world.setBlockMetadataWithNotify(i + 3, j + 42, k + 23, 4, 2);
		setBlock(world, i + 3, j + 42, k + 24, Blocks.leaves, 4);
		world.setBlockMetadataWithNotify(i + 3, j + 42, k + 24, 4, 2);
		setBlock(world, i + 3, j + 43, k + 9, Blocks.leaves, 4);
		world.setBlockMetadataWithNotify(i + 3, j + 43, k + 9, 4, 2);
		setBlock(world, i + 3, j + 43, k + 10, Blocks.leaves, 4);
		world.setBlockMetadataWithNotify(i + 3, j + 43, k + 10, 4, 2);
		setBlock(world, i + 3, j + 43, k + 11, Blocks.leaves, 4);
		world.setBlockMetadataWithNotify(i + 3, j + 43, k + 11, 4, 2);
		setBlock(world, i + 3, j + 43, k + 21, Blocks.leaves, 4);
		world.setBlockMetadataWithNotify(i + 3, j + 43, k + 21, 4, 2);
		setBlock(world, i + 3, j + 43, k + 22, Blocks.leaves, 4);
		world.setBlockMetadataWithNotify(i + 3, j + 43, k + 22, 4, 2);
		setBlock(world, i + 3, j + 43, k + 23, Blocks.leaves, 4);
		world.setBlockMetadataWithNotify(i + 3, j + 43, k + 23, 4, 2);
		setBlock(world, i + 3, j + 45, k + 11, Blocks.leaves, 4);
		world.setBlockMetadataWithNotify(i + 3, j + 45, k + 11, 4, 2);
		setBlock(world, i + 4, j + 36, k + 19, Blocks.leaves, 4);
		world.setBlockMetadataWithNotify(i + 4, j + 36, k + 19, 4, 2);
		setBlock(world, i + 4, j + 37, k + 18, Blocks.leaves, 4);
		world.setBlockMetadataWithNotify(i + 4, j + 37, k + 18, 4, 2);
		setBlock(world, i + 4, j + 37, k + 19, Blocks.leaves, 4);
		world.setBlockMetadataWithNotify(i + 4, j + 37, k + 19, 4, 2);
		setBlock(world, i + 4, j + 37, k + 20, Blocks.leaves, 4);
		world.setBlockMetadataWithNotify(i + 4, j + 37, k + 20, 4, 2);
		setBlock(world, i + 4, j + 38, k + 17, Blocks.leaves, 4);
		world.setBlockMetadataWithNotify(i + 4, j + 38, k + 17, 4, 2);
		setBlock(world, i + 4, j + 38, k + 18, Blocks.leaves, 4);
		world.setBlockMetadataWithNotify(i + 4, j + 38, k + 18, 4, 2);
		setBlock(world, i + 4, j + 38, k + 19, Blocks.leaves, 4);
		world.setBlockMetadataWithNotify(i + 4, j + 38, k + 19, 4, 2);
		setBlock(world, i + 4, j + 39, k + 17, Blocks.leaves, 4);
		world.setBlockMetadataWithNotify(i + 4, j + 39, k + 17, 4, 2);
		setBlock(world, i + 4, j + 39, k + 18, Blocks.leaves, 4);
		world.setBlockMetadataWithNotify(i + 4, j + 39, k + 18, 4, 2);
		setBlock(world, i + 4, j + 39, k + 19, Blocks.leaves, 4);
		world.setBlockMetadataWithNotify(i + 4, j + 39, k + 19, 4, 2);
		setBlock(world, i + 4, j + 39, k + 20, Blocks.leaves, 4);
		world.setBlockMetadataWithNotify(i + 4, j + 39, k + 20, 4, 2);
		setBlock(world, i + 4, j + 39, k + 21, Blocks.leaves, 4);
		world.setBlockMetadataWithNotify(i + 4, j + 39, k + 21, 4, 2);
		setBlock(world, i + 4, j + 40, k + 16, Blocks.leaves, 4);
		world.setBlockMetadataWithNotify(i + 4, j + 40, k + 16, 4, 2);
		setBlock(world, i + 4, j + 40, k + 17, Blocks.leaves, 4);
		world.setBlockMetadataWithNotify(i + 4, j + 40, k + 17, 4, 2);
		setBlock(world, i + 4, j + 40, k + 18, Blocks.leaves, 4);
		world.setBlockMetadataWithNotify(i + 4, j + 40, k + 18, 4, 2);
		setBlock(world, i + 4, j + 40, k + 20, Blocks.leaves, 4);
		world.setBlockMetadataWithNotify(i + 4, j + 40, k + 20, 4, 2);
		setBlock(world, i + 4, j + 41, k + 17, Blocks.leaves, 4);
		world.setBlockMetadataWithNotify(i + 4, j + 41, k + 17, 4, 2);
		setBlock(world, i + 4, j + 42, k + 8, Blocks.leaves, 4);
		world.setBlockMetadataWithNotify(i + 4, j + 42, k + 8, 4, 2);
		setBlock(world, i + 4, j + 42, k + 9, Blocks.leaves, 4);
		world.setBlockMetadataWithNotify(i + 4, j + 42, k + 9, 4, 2);
		setBlock(world, i + 4, j + 42, k + 11, Blocks.leaves, 4);
		world.setBlockMetadataWithNotify(i + 4, j + 42, k + 11, 4, 2);
		setBlock(world, i + 4, j + 42, k + 12, Blocks.leaves, 4);
		world.setBlockMetadataWithNotify(i + 4, j + 42, k + 12, 4, 2);
		setBlock(world, i + 4, j + 42, k + 20, Blocks.leaves, 4);
		world.setBlockMetadataWithNotify(i + 4, j + 42, k + 20, 4, 2);
		setBlock(world, i + 4, j + 42, k + 21, Blocks.leaves, 4);
		world.setBlockMetadataWithNotify(i + 4, j + 42, k + 21, 4, 2);
		setBlock(world, i + 4, j + 42, k + 23, Blocks.leaves, 4);
		world.setBlockMetadataWithNotify(i + 4, j + 42, k + 23, 4, 2);
		setBlock(world, i + 4, j + 42, k + 24, Blocks.leaves, 4);
		world.setBlockMetadataWithNotify(i + 4, j + 42, k + 24, 4, 2);
		setBlock(world, i + 4, j + 43, k + 8, Blocks.leaves, 4);
		world.setBlockMetadataWithNotify(i + 4, j + 43, k + 8, 4, 2);
		setBlock(world, i + 4, j + 43, k + 9, Blocks.leaves, 4);
		world.setBlockMetadataWithNotify(i + 4, j + 43, k + 9, 4, 2);
		/* 1000 */setBlock(world, i + 4, j + 43, k + 10, Blocks.leaves, 4);
		/* 1001 */world.setBlockMetadataWithNotify(i + 4, j + 43, k + 10, 4, 2);
		/* 1002 */setBlock(world, i + 4, j + 43, k + 11, Blocks.leaves, 4);
		/* 1003 */world.setBlockMetadataWithNotify(i + 4, j + 43, k + 11, 4, 2);
		/* 1004 */setBlock(world, i + 4, j + 43, k + 12, Blocks.leaves, 4);
		/* 1005 */world.setBlockMetadataWithNotify(i + 4, j + 43, k + 12, 4, 2);
		/* 1006 */setBlock(world, i + 4, j + 43, k + 20, Blocks.leaves, 4);
		/* 1007 */world.setBlockMetadataWithNotify(i + 4, j + 43, k + 20, 4, 2);
		/* 1008 */setBlock(world, i + 4, j + 43, k + 21, Blocks.leaves, 4);
		/* 1009 */world.setBlockMetadataWithNotify(i + 4, j + 43, k + 21, 4, 2);
		/* 1010 */setBlock(world, i + 4, j + 43, k + 22, Blocks.leaves, 4);
		/* 1011 */world.setBlockMetadataWithNotify(i + 4, j + 43, k + 22, 4, 2);
		/* 1012 */setBlock(world, i + 4, j + 43, k + 23, Blocks.leaves, 4);
		/* 1013 */world.setBlockMetadataWithNotify(i + 4, j + 43, k + 23, 4, 2);
		/* 1014 */setBlock(world, i + 4, j + 43, k + 24, Blocks.leaves, 4);
		/* 1015 */world.setBlockMetadataWithNotify(i + 4, j + 43, k + 24, 4, 2);
		/* 1016 */setBlock(world, i + 4, j + 44, k + 11, Blocks.leaves, 4);
		/* 1017 */world.setBlockMetadataWithNotify(i + 4, j + 44, k + 11, 4, 2);
		/* 1018 */setBlock(world, i + 4, j + 45, k + 10, Blocks.leaves, 4);
		/* 1019 */world.setBlockMetadataWithNotify(i + 4, j + 45, k + 10, 4, 2);
		/* 1020 */setBlock(world, i + 4, j + 45, k + 11, Blocks.leaves, 4);
		/* 1021 */world.setBlockMetadataWithNotify(i + 4, j + 45, k + 11, 4, 2);
		/* 1022 */setBlock(world, i + 4, j + 45, k + 12, Blocks.leaves, 4);
		/* 1023 */world.setBlockMetadataWithNotify(i + 4, j + 45, k + 12, 4, 2);
		/* 1024 */setBlock(world, i + 4, j + 46, k + 11, Blocks.leaves, 4);
		/* 1025 */world.setBlockMetadataWithNotify(i + 4, j + 46, k + 11, 4, 2);
		/* 1026 */setBlock(world, i + 5, j + 35, k + 19, Blocks.leaves, 4);
		/* 1027 */world.setBlockMetadataWithNotify(i + 5, j + 35, k + 19, 4, 2);
		/* 1028 */setBlock(world, i + 5, j + 36, k + 15, Blocks.leaves, 4);
		/* 1029 */world.setBlockMetadataWithNotify(i + 5, j + 36, k + 15, 4, 2);
		/* 1030 */setBlock(world, i + 5, j + 36, k + 18, Blocks.leaves, 4);
		/* 1031 */world.setBlockMetadataWithNotify(i + 5, j + 36, k + 18, 4, 2);
		/* 1032 */setBlock(world, i + 5, j + 36, k + 19, Blocks.leaves, 4);
		/* 1033 */world.setBlockMetadataWithNotify(i + 5, j + 36, k + 19, 4, 2);
		/* 1034 */setBlock(world, i + 5, j + 36, k + 20, Blocks.leaves, 4);
		/* 1035 */world.setBlockMetadataWithNotify(i + 5, j + 36, k + 20, 4, 2);
		/* 1036 */setBlock(world, i + 5, j + 37, k + 17, Blocks.leaves, 4);
		/* 1037 */world.setBlockMetadataWithNotify(i + 5, j + 37, k + 17, 4, 2);
		/* 1038 */setBlock(world, i + 5, j + 37, k + 18, Blocks.leaves, 4);
		/* 1039 */world.setBlockMetadataWithNotify(i + 5, j + 37, k + 18, 4, 2);
		/* 1040 */setBlock(world, i + 5, j + 37, k + 19, Blocks.leaves, 4);
		/* 1041 */world.setBlockMetadataWithNotify(i + 5, j + 37, k + 19, 4, 2);
		/* 1042 */setBlock(world, i + 5, j + 37, k + 22, Blocks.leaves, 4);
		/* 1043 */world.setBlockMetadataWithNotify(i + 5, j + 37, k + 22, 4, 2);
		/* 1044 */setBlock(world, i + 5, j + 38, k + 10, Blocks.leaves, 4);
		/* 1045 */world.setBlockMetadataWithNotify(i + 5, j + 38, k + 10, 4, 2);
		/* 1046 */setBlock(world, i + 5, j + 38, k + 11, Blocks.leaves, 4);
		/* 1047 */world.setBlockMetadataWithNotify(i + 5, j + 38, k + 11, 4, 2);
		/* 1048 */setBlock(world, i + 5, j + 38, k + 16, Blocks.leaves, 4);
		/* 1049 */world.setBlockMetadataWithNotify(i + 5, j + 38, k + 16, 4, 2);
		/* 1050 */setBlock(world, i + 5, j + 38, k + 17, Blocks.leaves, 4);
		/* 1051 */world.setBlockMetadataWithNotify(i + 5, j + 38, k + 17, 4, 2);
		/* 1052 */setBlock(world, i + 5, j + 38, k + 18, Blocks.leaves, 4);
		/* 1053 */world.setBlockMetadataWithNotify(i + 5, j + 38, k + 18, 4, 2);
		/* 1054 */setBlock(world, i + 5, j + 39, k + 11, Blocks.leaves, 4);
		/* 1055 */world.setBlockMetadataWithNotify(i + 5, j + 39, k + 11, 4, 2);
		/* 1056 */setBlock(world, i + 5, j + 39, k + 17, Blocks.leaves, 4);
		/* 1057 */world.setBlockMetadataWithNotify(i + 5, j + 39, k + 17, 4, 2);
		/* 1058 */setBlock(world, i + 5, j + 40, k + 17, Blocks.leaves, 4);
		/* 1059 */world.setBlockMetadataWithNotify(i + 5, j + 40, k + 17, 4, 2);
		/* 1060 */setBlock(world, i + 5, j + 42, k + 8, Blocks.leaves, 4);
		/* 1061 */world.setBlockMetadataWithNotify(i + 5, j + 42, k + 8, 4, 2);
		/* 1062 */setBlock(world, i + 5, j + 42, k + 9, Blocks.leaves, 4);
		/* 1063 */world.setBlockMetadataWithNotify(i + 5, j + 42, k + 9, 4, 2);
		/* 1064 */setBlock(world, i + 5, j + 42, k + 10, Blocks.leaves, 4);
		/* 1065 */world.setBlockMetadataWithNotify(i + 5, j + 42, k + 10, 4, 2);
		/* 1066 */setBlock(world, i + 5, j + 42, k + 11, Blocks.leaves, 4);
		/* 1067 */world.setBlockMetadataWithNotify(i + 5, j + 42, k + 11, 4, 2);
		/* 1068 */setBlock(world, i + 5, j + 42, k + 12, Blocks.leaves, 4);
		/* 1069 */world.setBlockMetadataWithNotify(i + 5, j + 42, k + 12, 4, 2);
		/* 1070 */setBlock(world, i + 5, j + 42, k + 20, Blocks.leaves, 4);
		/* 1071 */world.setBlockMetadataWithNotify(i + 5, j + 42, k + 20, 4, 2);
		/* 1072 */setBlock(world, i + 5, j + 42, k + 21, Blocks.leaves, 4);
		/* 1073 */world.setBlockMetadataWithNotify(i + 5, j + 42, k + 21, 4, 2);
		/* 1074 */setBlock(world, i + 5, j + 42, k + 22, Blocks.leaves, 4);
		/* 1075 */world.setBlockMetadataWithNotify(i + 5, j + 42, k + 22, 4, 2);
		/* 1076 */setBlock(world, i + 5, j + 42, k + 23, Blocks.leaves, 4);
		/* 1077 */world.setBlockMetadataWithNotify(i + 5, j + 42, k + 23, 4, 2);
		/* 1078 */setBlock(world, i + 5, j + 42, k + 24, Blocks.leaves, 4);
		/* 1079 */world.setBlockMetadataWithNotify(i + 5, j + 42, k + 24, 4, 2);
		/* 1080 */setBlock(world, i + 5, j + 43, k + 9, Blocks.leaves, 4);
		/* 1081 */world.setBlockMetadataWithNotify(i + 5, j + 43, k + 9, 4, 2);
		/* 1082 */setBlock(world, i + 5, j + 43, k + 10, Blocks.leaves, 4);
		/* 1083 */world.setBlockMetadataWithNotify(i + 5, j + 43, k + 10, 4, 2);
		/* 1084 */setBlock(world, i + 5, j + 43, k + 11, Blocks.leaves, 4);
		/* 1085 */world.setBlockMetadataWithNotify(i + 5, j + 43, k + 11, 4, 2);
		/* 1086 */setBlock(world, i + 5, j + 43, k + 21, Blocks.leaves, 4);
		/* 1087 */world.setBlockMetadataWithNotify(i + 5, j + 43, k + 21, 4, 2);
		/* 1088 */setBlock(world, i + 5, j + 43, k + 22, Blocks.leaves, 4);
		/* 1089 */world.setBlockMetadataWithNotify(i + 5, j + 43, k + 22, 4, 2);
		/* 1090 */setBlock(world, i + 5, j + 43, k + 23, Blocks.leaves, 4);
		/* 1091 */world.setBlockMetadataWithNotify(i + 5, j + 43, k + 23, 4, 2);
		/* 1092 */setBlock(world, i + 5, j + 44, k + 9, Blocks.leaves, 4);
		/* 1093 */world.setBlockMetadataWithNotify(i + 5, j + 44, k + 9, 4, 2);
		/* 1094 */setBlock(world, i + 5, j + 45, k + 11, Blocks.leaves, 4);
		/* 1095 */world.setBlockMetadataWithNotify(i + 5, j + 45, k + 11, 4, 2);
		/* 1096 */setBlock(world, i + 6, j + 34, k + 19, Blocks.leaves, 4);
		/* 1097 */world.setBlockMetadataWithNotify(i + 6, j + 34, k + 19, 4, 2);
		/* 1098 */setBlock(world, i + 6, j + 35, k + 15, Blocks.leaves, 4);
		/* 1099 */world.setBlockMetadataWithNotify(i + 6, j + 35, k + 15, 4, 2);
		/* 1100 */setBlock(world, i + 6, j + 35, k + 18, Blocks.leaves, 4);
		/* 1101 */world.setBlockMetadataWithNotify(i + 6, j + 35, k + 18, 4, 2);
		/* 1102 */setBlock(world, i + 6, j + 35, k + 19, Blocks.leaves, 4);
		/* 1103 */world.setBlockMetadataWithNotify(i + 6, j + 35, k + 19, 4, 2);
		/* 1104 */setBlock(world, i + 6, j + 35, k + 20, Blocks.leaves, 4);
		/* 1105 */world.setBlockMetadataWithNotify(i + 6, j + 35, k + 20, 4, 2);
		/* 1106 */setBlock(world, i + 6, j + 36, k + 14, Blocks.leaves, 4);
		/* 1107 */world.setBlockMetadataWithNotify(i + 6, j + 36, k + 14, 4, 2);
		/* 1108 */setBlock(world, i + 6, j + 36, k + 15, Blocks.leaves, 4);
		/* 1109 */world.setBlockMetadataWithNotify(i + 6, j + 36, k + 15, 4, 2);
		/* 1110 */setBlock(world, i + 6, j + 36, k + 16, Blocks.leaves, 4);
		/* 1111 */world.setBlockMetadataWithNotify(i + 6, j + 36, k + 16, 4, 2);
		/* 1112 */setBlock(world, i + 6, j + 36, k + 17, Blocks.leaves, 4);
		/* 1113 */world.setBlockMetadataWithNotify(i + 6, j + 36, k + 17, 4, 2);
		/* 1114 */setBlock(world, i + 6, j + 36, k + 18, Blocks.leaves, 4);
		/* 1115 */world.setBlockMetadataWithNotify(i + 6, j + 36, k + 18, 4, 2);
		/* 1116 */setBlock(world, i + 6, j + 36, k + 19, Blocks.leaves, 4);
		/* 1117 */world.setBlockMetadataWithNotify(i + 6, j + 36, k + 19, 4, 2);
		/* 1118 */setBlock(world, i + 6, j + 36, k + 20, Blocks.leaves, 4);
		/* 1119 */world.setBlockMetadataWithNotify(i + 6, j + 36, k + 20, 4, 2);
		/* 1120 */setBlock(world, i + 6, j + 36, k + 21, Blocks.leaves, 4);
		/* 1121 */world.setBlockMetadataWithNotify(i + 6, j + 36, k + 21, 4, 2);
		/* 1122 */setBlock(world, i + 6, j + 36, k + 22, Blocks.leaves, 4);
		/* 1123 */world.setBlockMetadataWithNotify(i + 6, j + 36, k + 22, 4, 2);
		/* 1124 */setBlock(world, i + 6, j + 37, k + 10, Blocks.leaves, 4);
		/* 1125 */world.setBlockMetadataWithNotify(i + 6, j + 37, k + 10, 4, 2);
		/* 1126 */setBlock(world, i + 6, j + 37, k + 11, Blocks.leaves, 4);
		/* 1127 */world.setBlockMetadataWithNotify(i + 6, j + 37, k + 11, 4, 2);
		/* 1128 */setBlock(world, i + 6, j + 37, k + 15, Blocks.leaves, 4);
		/* 1129 */world.setBlockMetadataWithNotify(i + 6, j + 37, k + 15, 4, 2);
		/* 1130 */setBlock(world, i + 6, j + 37, k + 16, Blocks.leaves, 4);
		/* 1131 */world.setBlockMetadataWithNotify(i + 6, j + 37, k + 16, 4, 2);
		/* 1132 */setBlock(world, i + 6, j + 37, k + 17, Blocks.leaves, 4);
		/* 1133 */world.setBlockMetadataWithNotify(i + 6, j + 37, k + 17, 4, 2);
		/* 1134 */setBlock(world, i + 6, j + 37, k + 18, Blocks.leaves, 4);
		/* 1135 */world.setBlockMetadataWithNotify(i + 6, j + 37, k + 18, 4, 2);
		/* 1136 */setBlock(world, i + 6, j + 37, k + 19, Blocks.leaves, 4);
		/* 1137 */world.setBlockMetadataWithNotify(i + 6, j + 37, k + 19, 4, 2);
		/* 1138 */setBlock(world, i + 6, j + 37, k + 20, Blocks.leaves, 4);
		/* 1139 */world.setBlockMetadataWithNotify(i + 6, j + 37, k + 20, 4, 2);
		/* 1140 */setBlock(world, i + 6, j + 37, k + 21, Blocks.leaves, 4);
		/* 1141 */world.setBlockMetadataWithNotify(i + 6, j + 37, k + 21, 4, 2);
		/* 1142 */setBlock(world, i + 6, j + 37, k + 22, Blocks.leaves, 4);
		/* 1143 */world.setBlockMetadataWithNotify(i + 6, j + 37, k + 22, 4, 2);
		/* 1144 */setBlock(world, i + 6, j + 37, k + 23, Blocks.leaves, 4);
		/* 1145 */world.setBlockMetadataWithNotify(i + 6, j + 37, k + 23, 4, 2);
		/* 1146 */setBlock(world, i + 6, j + 38, k + 9, Blocks.leaves, 4);
		/* 1147 */world.setBlockMetadataWithNotify(i + 6, j + 38, k + 9, 4, 2);
		/* 1148 */setBlock(world, i + 6, j + 38, k + 10, Blocks.leaves, 4);
		/* 1149 */world.setBlockMetadataWithNotify(i + 6, j + 38, k + 10, 4, 2);
		/* 1150 */setBlock(world, i + 6, j + 38, k + 11, Blocks.leaves, 4);
		/* 1151 */world.setBlockMetadataWithNotify(i + 6, j + 38, k + 11, 4, 2);
		/* 1152 */setBlock(world, i + 6, j + 38, k + 12, Blocks.leaves, 4);
		/* 1153 */world.setBlockMetadataWithNotify(i + 6, j + 38, k + 12, 4, 2);
		/* 1154 */setBlock(world, i + 6, j + 38, k + 13, Blocks.leaves, 4);
		/* 1155 */world.setBlockMetadataWithNotify(i + 6, j + 38, k + 13, 4, 2);
		/* 1156 */setBlock(world, i + 6, j + 38, k + 17, Blocks.leaves, 4);
		/* 1157 */world.setBlockMetadataWithNotify(i + 6, j + 38, k + 17, 4, 2);
		/* 1158 */setBlock(world, i + 6, j + 38, k + 18, Blocks.leaves, 4);
		/* 1159 */world.setBlockMetadataWithNotify(i + 6, j + 38, k + 18, 4, 2);
		/* 1160 */setBlock(world, i + 6, j + 38, k + 22, Blocks.leaves, 4);
		/* 1161 */world.setBlockMetadataWithNotify(i + 6, j + 38, k + 22, 4, 2);
		/* 1162 */setBlock(world, i + 6, j + 38, k + 25, Blocks.leaves, 4);
		/* 1163 */world.setBlockMetadataWithNotify(i + 6, j + 38, k + 25, 4, 2);
		/* 1164 */setBlock(world, i + 6, j + 39, k + 10, Blocks.leaves, 4);
		/* 1165 */world.setBlockMetadataWithNotify(i + 6, j + 39, k + 10, 4, 2);
		/* 1166 */setBlock(world, i + 6, j + 39, k + 11, Blocks.leaves, 4);
		/* 1167 */world.setBlockMetadataWithNotify(i + 6, j + 39, k + 11, 4, 2);
		/* 1168 */setBlock(world, i + 6, j + 39, k + 12, Blocks.leaves, 4);
		/* 1169 */world.setBlockMetadataWithNotify(i + 6, j + 39, k + 12, 4, 2);
		/* 1170 */setBlock(world, i + 6, j + 39, k + 22, Blocks.leaves, 4);
		/* 1171 */world.setBlockMetadataWithNotify(i + 6, j + 39, k + 22, 4, 2);
		/* 1172 */setBlock(world, i + 6, j + 39, k + 23, Blocks.leaves, 4);
		/* 1173 */world.setBlockMetadataWithNotify(i + 6, j + 39, k + 23, 4, 2);
		/* 1174 */setBlock(world, i + 6, j + 39, k + 24, Blocks.leaves, 4);
		/* 1175 */world.setBlockMetadataWithNotify(i + 6, j + 39, k + 24, 4, 2);
		/* 1176 */setBlock(world, i + 6, j + 40, k + 10, Blocks.leaves, 4);
		/* 1177 */world.setBlockMetadataWithNotify(i + 6, j + 40, k + 10, 4, 2);
		/* 1178 */setBlock(world, i + 6, j + 40, k + 11, Blocks.leaves, 4);
		/* 1179 */world.setBlockMetadataWithNotify(i + 6, j + 40, k + 11, 4, 2);
		/* 1180 */setBlock(world, i + 6, j + 40, k + 12, Blocks.leaves, 4);
		/* 1181 */world.setBlockMetadataWithNotify(i + 6, j + 40, k + 12, 4, 2);
		/* 1182 */setBlock(world, i + 6, j + 40, k + 15, Blocks.leaves, 4);
		/* 1183 */world.setBlockMetadataWithNotify(i + 6, j + 40, k + 15, 4, 2);
		/* 1184 */setBlock(world, i + 6, j + 40, k + 16, Blocks.leaves, 4);
		/* 1185 */world.setBlockMetadataWithNotify(i + 6, j + 40, k + 16, 4, 2);
		/* 1186 */setBlock(world, i + 6, j + 40, k + 17, Blocks.leaves, 4);
		/* 1187 */world.setBlockMetadataWithNotify(i + 6, j + 40, k + 17, 4, 2);
		/* 1188 */setBlock(world, i + 6, j + 40, k + 21, Blocks.leaves, 4);
		/* 1189 */world.setBlockMetadataWithNotify(i + 6, j + 40, k + 21, 4, 2);
		/* 1190 */setBlock(world, i + 6, j + 40, k + 23, Blocks.leaves, 4);
		/* 1191 */world.setBlockMetadataWithNotify(i + 6, j + 40, k + 23, 4, 2);
		/* 1192 */setBlock(world, i + 6, j + 41, k + 11, Blocks.leaves, 4);
		/* 1193 */world.setBlockMetadataWithNotify(i + 6, j + 41, k + 11, 4, 2);
		/* 1194 */setBlock(world, i + 6, j + 41, k + 16, Blocks.leaves, 4);
		/* 1195 */world.setBlockMetadataWithNotify(i + 6, j + 41, k + 16, 4, 2);
		/* 1196 */setBlock(world, i + 6, j + 42, k + 9, Blocks.leaves, 4);
		/* 1197 */world.setBlockMetadataWithNotify(i + 6, j + 42, k + 9, 4, 2);
		/* 1198 */setBlock(world, i + 6, j + 42, k + 10, Blocks.leaves, 4);
		/* 1199 */world.setBlockMetadataWithNotify(i + 6, j + 42, k + 10, 4, 2);
		/* 1200 */setBlock(world, i + 6, j + 42, k + 11, Blocks.leaves, 4);
		/* 1201 */world.setBlockMetadataWithNotify(i + 6, j + 42, k + 11, 4, 2);
		/* 1202 */setBlock(world, i + 6, j + 42, k + 21, Blocks.leaves, 4);
		/* 1203 */world.setBlockMetadataWithNotify(i + 6, j + 42, k + 21, 4, 2);
		/* 1204 */setBlock(world, i + 6, j + 42, k + 22, Blocks.leaves, 4);
		/* 1205 */world.setBlockMetadataWithNotify(i + 6, j + 42, k + 22, 4, 2);
		/* 1206 */setBlock(world, i + 6, j + 42, k + 23, Blocks.leaves, 4);
		/* 1207 */world.setBlockMetadataWithNotify(i + 6, j + 42, k + 23, 4, 2);
		/* 1208 */setBlock(world, i + 6, j + 43, k + 9, Blocks.leaves, 4);
		/* 1209 */world.setBlockMetadataWithNotify(i + 6, j + 43, k + 9, 4, 2);
		/* 1210 */setBlock(world, i + 6, j + 43, k + 10, Blocks.leaves, 4);
		/* 1211 */world.setBlockMetadataWithNotify(i + 6, j + 43, k + 10, 4, 2);
		/* 1212 */setBlock(world, i + 6, j + 43, k + 22, Blocks.leaves, 4);
		/* 1213 */world.setBlockMetadataWithNotify(i + 6, j + 43, k + 22, 4, 2);
		/* 1214 */setBlock(world, i + 6, j + 44, k + 8, Blocks.leaves, 4);
		/* 1215 */world.setBlockMetadataWithNotify(i + 6, j + 44, k + 8, 4, 2);
		/* 1216 */setBlock(world, i + 6, j + 44, k + 9, Blocks.leaves, 4);
		/* 1217 */world.setBlockMetadataWithNotify(i + 6, j + 44, k + 9, 4, 2);
		/* 1218 */setBlock(world, i + 6, j + 44, k + 10, Blocks.leaves, 4);
		/* 1219 */world.setBlockMetadataWithNotify(i + 6, j + 44, k + 10, 4, 2);
		/* 1220 */setBlock(world, i + 6, j + 45, k + 9, Blocks.leaves, 4);
		/* 1221 */world.setBlockMetadataWithNotify(i + 6, j + 45, k + 9, 4, 2);
		/* 1222 */setBlock(world, i + 7, j + 35, k + 10, Blocks.leaves, 4);
		/* 1223 */world.setBlockMetadataWithNotify(i + 7, j + 35, k + 10, 4, 2);
		/* 1224 */setBlock(world, i + 7, j + 35, k + 17, Blocks.leaves, 4);
		/* 1225 */world.setBlockMetadataWithNotify(i + 7, j + 35, k + 17, 4, 2);
		/* 1226 */setBlock(world, i + 7, j + 35, k + 18, Blocks.leaves, 4);
		/* 1227 */world.setBlockMetadataWithNotify(i + 7, j + 35, k + 18, 4, 2);
		/* 1228 */setBlock(world, i + 7, j + 35, k + 19, Blocks.leaves, 4);
		/* 1229 */world.setBlockMetadataWithNotify(i + 7, j + 35, k + 19, 4, 2);
		/* 1230 */setBlock(world, i + 7, j + 35, k + 22, Blocks.leaves, 4);
		/* 1231 */world.setBlockMetadataWithNotify(i + 7, j + 35, k + 22, 4, 2);
		/* 1232 */setBlock(world, i + 7, j + 36, k + 15, Blocks.leaves, 4);
		/* 1233 */world.setBlockMetadataWithNotify(i + 7, j + 36, k + 15, 4, 2);
		/* 1234 */setBlock(world, i + 7, j + 36, k + 16, Blocks.leaves, 4);
		/* 1235 */world.setBlockMetadataWithNotify(i + 7, j + 36, k + 16, 4, 2);
		/* 1236 */setBlock(world, i + 7, j + 36, k + 17, Blocks.leaves, 4);
		/* 1237 */world.setBlockMetadataWithNotify(i + 7, j + 36, k + 17, 4, 2);
		/* 1238 */setBlock(world, i + 7, j + 36, k + 18, Blocks.leaves, 4);
		/* 1239 */world.setBlockMetadataWithNotify(i + 7, j + 36, k + 18, 4, 2);
		/* 1240 */setBlock(world, i + 7, j + 36, k + 19, Blocks.leaves, 4);
		/* 1241 */world.setBlockMetadataWithNotify(i + 7, j + 36, k + 19, 4, 2);
		/* 1242 */setBlock(world, i + 7, j + 36, k + 20, Blocks.leaves, 4);
		/* 1243 */world.setBlockMetadataWithNotify(i + 7, j + 36, k + 20, 4, 2);
		/* 1244 */setBlock(world, i + 7, j + 36, k + 21, Blocks.leaves, 4);
		/* 1245 */world.setBlockMetadataWithNotify(i + 7, j + 36, k + 21, 4, 2);
		/* 1246 */setBlock(world, i + 7, j + 37, k + 9, Blocks.leaves, 4);
		/* 1247 */world.setBlockMetadataWithNotify(i + 7, j + 37, k + 9, 4, 2);
		/* 1248 */setBlock(world, i + 7, j + 37, k + 11, Blocks.leaves, 4);
		/* 1249 */world.setBlockMetadataWithNotify(i + 7, j + 37, k + 11, 4, 2);
		/* 1250 */setBlock(world, i + 7, j + 37, k + 12, Blocks.leaves, 4);
		/* 1251 */world.setBlockMetadataWithNotify(i + 7, j + 37, k + 12, 4, 2);
		/* 1252 */setBlock(world, i + 7, j + 37, k + 13, Blocks.leaves, 4);
		/* 1253 */world.setBlockMetadataWithNotify(i + 7, j + 37, k + 13, 4, 2);
		/* 1254 */setBlock(world, i + 7, j + 37, k + 15, Blocks.leaves, 4);
		/* 1255 */world.setBlockMetadataWithNotify(i + 7, j + 37, k + 15, 4, 2);
		/* 1256 */setBlock(world, i + 7, j + 37, k + 16, Blocks.leaves, 4);
		/* 1257 */world.setBlockMetadataWithNotify(i + 7, j + 37, k + 16, 4, 2);
		/* 1258 */setBlock(world, i + 7, j + 37, k + 17, Blocks.leaves, 4);
		/* 1259 */world.setBlockMetadataWithNotify(i + 7, j + 37, k + 17, 4, 2);
		/* 1260 */setBlock(world, i + 7, j + 37, k + 18, Blocks.leaves, 4);
		/* 1261 */world.setBlockMetadataWithNotify(i + 7, j + 37, k + 18, 4, 2);
		/* 1262 */setBlock(world, i + 7, j + 37, k + 19, Blocks.leaves, 4);
		/* 1263 */world.setBlockMetadataWithNotify(i + 7, j + 37, k + 19, 4, 2);
		/* 1264 */setBlock(world, i + 7, j + 37, k + 20, Blocks.leaves, 4);
		/* 1265 */world.setBlockMetadataWithNotify(i + 7, j + 37, k + 20, 4, 2);
		/* 1266 */setBlock(world, i + 7, j + 37, k + 21, Blocks.leaves, 4);
		/* 1267 */world.setBlockMetadataWithNotify(i + 7, j + 37, k + 21, 4, 2);
		/* 1268 */setBlock(world, i + 7, j + 37, k + 22, Blocks.leaves, 4);
		/* 1269 */world.setBlockMetadataWithNotify(i + 7, j + 37, k + 22, 4, 2);
		/* 1270 */setBlock(world, i + 7, j + 37, k + 25, Blocks.leaves, 4);
		/* 1271 */world.setBlockMetadataWithNotify(i + 7, j + 37, k + 25, 4, 2);
		/* 1272 */setBlock(world, i + 7, j + 38, k + 8, Blocks.leaves, 4);
		/* 1273 */world.setBlockMetadataWithNotify(i + 7, j + 38, k + 8, 4, 2);
		/* 1274 */setBlock(world, i + 7, j + 38, k + 9, Blocks.leaves, 4);
		/* 1275 */world.setBlockMetadataWithNotify(i + 7, j + 38, k + 9, 4, 2);
		/* 1276 */setBlock(world, i + 7, j + 38, k + 10, Blocks.leaves, 4);
		/* 1277 */world.setBlockMetadataWithNotify(i + 7, j + 38, k + 10, 4, 2);
		/* 1278 */setBlock(world, i + 7, j + 38, k + 11, Blocks.leaves, 4);
		/* 1279 */world.setBlockMetadataWithNotify(i + 7, j + 38, k + 11, 4, 2);
		/* 1280 */setBlock(world, i + 7, j + 38, k + 12, Blocks.leaves, 4);
		/* 1281 */world.setBlockMetadataWithNotify(i + 7, j + 38, k + 12, 4, 2);
		/* 1282 */setBlock(world, i + 7, j + 38, k + 13, Blocks.leaves, 4);
		/* 1283 */world.setBlockMetadataWithNotify(i + 7, j + 38, k + 13, 4, 2);
		/* 1284 */setBlock(world, i + 7, j + 38, k + 14, Blocks.leaves, 4);
		/* 1285 */world.setBlockMetadataWithNotify(i + 7, j + 38, k + 14, 4, 2);
		/* 1286 */setBlock(world, i + 7, j + 38, k + 16, Blocks.leaves, 4);
		/* 1287 */world.setBlockMetadataWithNotify(i + 7, j + 38, k + 16, 4, 2);
		/* 1288 */setBlock(world, i + 7, j + 38, k + 17, Blocks.leaves, 4);
		/* 1289 */world.setBlockMetadataWithNotify(i + 7, j + 38, k + 17, 4, 2);
		/* 1290 */setBlock(world, i + 7, j + 38, k + 18, Blocks.leaves, 4);
		/* 1291 */world.setBlockMetadataWithNotify(i + 7, j + 38, k + 18, 4, 2);
		/* 1292 */setBlock(world, i + 7, j + 38, k + 19, Blocks.leaves, 4);
		/* 1293 */world.setBlockMetadataWithNotify(i + 7, j + 38, k + 19, 4, 2);
		/* 1294 */setBlock(world, i + 7, j + 38, k + 21, Blocks.leaves, 4);
		/* 1295 */world.setBlockMetadataWithNotify(i + 7, j + 38, k + 21, 4, 2);
		/* 1296 */setBlock(world, i + 7, j + 38, k + 24, Blocks.leaves, 4);
		/* 1297 */world.setBlockMetadataWithNotify(i + 7, j + 38, k + 24, 4, 2);
		/* 1298 */setBlock(world, i + 7, j + 38, k + 25, Blocks.leaves, 4);
		/* 1299 */world.setBlockMetadataWithNotify(i + 7, j + 38, k + 25, 4, 2);
		/* 1300 */setBlock(world, i + 7, j + 38, k + 26, Blocks.leaves, 4);
		/* 1301 */world.setBlockMetadataWithNotify(i + 7, j + 38, k + 26, 4, 2);
		/* 1302 */setBlock(world, i + 7, j + 39, k + 9, Blocks.leaves, 4);
		/* 1303 */world.setBlockMetadataWithNotify(i + 7, j + 39, k + 9, 4, 2);
		/* 1304 */setBlock(world, i + 7, j + 39, k + 11, Blocks.leaves, 4);
		/* 1305 */world.setBlockMetadataWithNotify(i + 7, j + 39, k + 11, 4, 2);
		/* 1306 */setBlock(world, i + 7, j + 39, k + 12, Blocks.leaves, 4);
		/* 1307 */world.setBlockMetadataWithNotify(i + 7, j + 39, k + 12, 4, 2);
		/* 1308 */setBlock(world, i + 7, j + 39, k + 13, Blocks.leaves, 4);
		/* 1309 */world.setBlockMetadataWithNotify(i + 7, j + 39, k + 13, 4, 2);
		/* 1310 */setBlock(world, i + 7, j + 39, k + 15, Blocks.leaves, 4);
		/* 1311 */world.setBlockMetadataWithNotify(i + 7, j + 39, k + 15, 4, 2);
		/* 1312 */setBlock(world, i + 7, j + 39, k + 16, Blocks.leaves, 4);
		/* 1313 */world.setBlockMetadataWithNotify(i + 7, j + 39, k + 16, 4, 2);
		/* 1314 */setBlock(world, i + 7, j + 39, k + 17, Blocks.leaves, 4);
		/* 1315 */world.setBlockMetadataWithNotify(i + 7, j + 39, k + 17, 4, 2);
		/* 1316 */setBlock(world, i + 7, j + 39, k + 18, Blocks.leaves, 4);
		/* 1317 */world.setBlockMetadataWithNotify(i + 7, j + 39, k + 18, 4, 2);
		/* 1318 */setBlock(world, i + 7, j + 39, k + 19, Blocks.leaves, 4);
		/* 1319 */world.setBlockMetadataWithNotify(i + 7, j + 39, k + 19, 4, 2);
		/* 1320 */setBlock(world, i + 7, j + 39, k + 21, Blocks.leaves, 4);
		/* 1321 */world.setBlockMetadataWithNotify(i + 7, j + 39, k + 21, 4, 2);
		/* 1322 */setBlock(world, i + 7, j + 39, k + 22, Blocks.leaves, 4);
		/* 1323 */world.setBlockMetadataWithNotify(i + 7, j + 39, k + 22, 4, 2);
		/* 1324 */setBlock(world, i + 7, j + 39, k + 23, Blocks.leaves, 4);
		/* 1325 */world.setBlockMetadataWithNotify(i + 7, j + 39, k + 23, 4, 2);
		/* 1326 */setBlock(world, i + 7, j + 39, k + 24, Blocks.leaves, 4);
		/* 1327 */world.setBlockMetadataWithNotify(i + 7, j + 39, k + 24, 4, 2);
		/* 1328 */setBlock(world, i + 7, j + 39, k + 25, Blocks.leaves, 4);
		/* 1329 */world.setBlockMetadataWithNotify(i + 7, j + 39, k + 25, 4, 2);
		/* 1330 */setBlock(world, i + 7, j + 40, k + 9, Blocks.leaves, 4);
		/* 1331 */world.setBlockMetadataWithNotify(i + 7, j + 40, k + 9, 4, 2);
		/* 1332 */setBlock(world, i + 7, j + 40, k + 10, Blocks.leaves, 4);
		/* 1333 */world.setBlockMetadataWithNotify(i + 7, j + 40, k + 10, 4, 2);
		/* 1334 */setBlock(world, i + 7, j + 40, k + 11, Blocks.leaves, 4);
		/* 1335 */world.setBlockMetadataWithNotify(i + 7, j + 40, k + 11, 4, 2);
		/* 1336 */setBlock(world, i + 7, j + 40, k + 12, Blocks.leaves, 4);
		/* 1337 */world.setBlockMetadataWithNotify(i + 7, j + 40, k + 12, 4, 2);
		/* 1338 */setBlock(world, i + 7, j + 40, k + 13, Blocks.leaves, 4);
		/* 1339 */world.setBlockMetadataWithNotify(i + 7, j + 40, k + 13, 4, 2);
		/* 1340 */setBlock(world, i + 7, j + 40, k + 14, Blocks.leaves, 4);
		/* 1341 */world.setBlockMetadataWithNotify(i + 7, j + 40, k + 14, 4, 2);
		/* 1342 */setBlock(world, i + 7, j + 40, k + 15, Blocks.leaves, 4);
		/* 1343 */world.setBlockMetadataWithNotify(i + 7, j + 40, k + 15, 4, 2);
		/* 1344 */setBlock(world, i + 7, j + 40, k + 16, Blocks.leaves, 4);
		/* 1345 */world.setBlockMetadataWithNotify(i + 7, j + 40, k + 16, 4, 2);
		/* 1346 */setBlock(world, i + 7, j + 40, k + 17, Blocks.leaves, 4);
		/* 1347 */world.setBlockMetadataWithNotify(i + 7, j + 40, k + 17, 4, 2);
		/* 1348 */setBlock(world, i + 7, j + 40, k + 18, Blocks.leaves, 4);
		/* 1349 */world.setBlockMetadataWithNotify(i + 7, j + 40, k + 18, 4, 2);
		/* 1350 */setBlock(world, i + 7, j + 40, k + 20, Blocks.leaves, 4);
		/* 1351 */world.setBlockMetadataWithNotify(i + 7, j + 40, k + 20, 4, 2);
		/* 1352 */setBlock(world, i + 7, j + 40, k + 21, Blocks.leaves, 4);
		/* 1353 */world.setBlockMetadataWithNotify(i + 7, j + 40, k + 21, 4, 2);
		/* 1354 */setBlock(world, i + 7, j + 40, k + 22, Blocks.leaves, 4);
		/* 1355 */world.setBlockMetadataWithNotify(i + 7, j + 40, k + 22, 4, 2);
		/* 1356 */setBlock(world, i + 7, j + 40, k + 23, Blocks.leaves, 4);
		/* 1357 */world.setBlockMetadataWithNotify(i + 7, j + 40, k + 23, 4, 2);
		/* 1358 */setBlock(world, i + 7, j + 40, k + 24, Blocks.leaves, 4);
		/* 1359 */world.setBlockMetadataWithNotify(i + 7, j + 40, k + 24, 4, 2);
		/* 1360 */setBlock(world, i + 7, j + 41, k + 10, Blocks.leaves, 4);
		/* 1361 */world.setBlockMetadataWithNotify(i + 7, j + 41, k + 10, 4, 2);
		/* 1362 */setBlock(world, i + 7, j + 41, k + 11, Blocks.leaves, 4);
		/* 1363 */world.setBlockMetadataWithNotify(i + 7, j + 41, k + 11, 4, 2);
		/* 1364 */setBlock(world, i + 7, j + 41, k + 12, Blocks.leaves, 4);
		/* 1365 */world.setBlockMetadataWithNotify(i + 7, j + 41, k + 12, 4, 2);
		/* 1366 */setBlock(world, i + 7, j + 41, k + 15, Blocks.leaves, 4);
		/* 1367 */world.setBlockMetadataWithNotify(i + 7, j + 41, k + 15, 4, 2);
		/* 1368 */setBlock(world, i + 7, j + 41, k + 16, Blocks.leaves, 4);
		/* 1369 */world.setBlockMetadataWithNotify(i + 7, j + 41, k + 16, 4, 2);
		/* 1370 */setBlock(world, i + 7, j + 41, k + 17, Blocks.leaves, 4);
		/* 1371 */world.setBlockMetadataWithNotify(i + 7, j + 41, k + 17, 4, 2);
		/* 1372 */setBlock(world, i + 7, j + 41, k + 21, Blocks.leaves, 4);
		/* 1373 */world.setBlockMetadataWithNotify(i + 7, j + 41, k + 21, 4, 2);
		/* 1374 */setBlock(world, i + 7, j + 41, k + 23, Blocks.leaves, 4);
		/* 1375 */world.setBlockMetadataWithNotify(i + 7, j + 41, k + 23, 4, 2);
		/* 1376 */setBlock(world, i + 7, j + 42, k + 10, Blocks.leaves, 4);
		/* 1377 */world.setBlockMetadataWithNotify(i + 7, j + 42, k + 10, 4, 2);
		/* 1378 */setBlock(world, i + 7, j + 42, k + 15, Blocks.leaves, 4);
		/* 1379 */world.setBlockMetadataWithNotify(i + 7, j + 42, k + 15, 4, 2);
		/* 1380 */setBlock(world, i + 7, j + 42, k + 16, Blocks.leaves, 4);
		/* 1381 */world.setBlockMetadataWithNotify(i + 7, j + 42, k + 16, 4, 2);
		/* 1382 */setBlock(world, i + 7, j + 42, k + 17, Blocks.leaves, 4);
		/* 1383 */world.setBlockMetadataWithNotify(i + 7, j + 42, k + 17, 4, 2);
		/* 1384 */setBlock(world, i + 7, j + 43, k + 9, Blocks.leaves, 4);
		/* 1385 */world.setBlockMetadataWithNotify(i + 7, j + 43, k + 9, 4, 2);
		/* 1386 */setBlock(world, i + 7, j + 43, k + 10, Blocks.leaves, 4);
		/* 1387 */world.setBlockMetadataWithNotify(i + 7, j + 43, k + 10, 4, 2);
		/* 1388 */setBlock(world, i + 7, j + 43, k + 11, Blocks.leaves, 4);
		/* 1389 */world.setBlockMetadataWithNotify(i + 7, j + 43, k + 11, 4, 2);
		/* 1390 */setBlock(world, i + 7, j + 43, k + 16, Blocks.leaves, 4);
		/* 1391 */world.setBlockMetadataWithNotify(i + 7, j + 43, k + 16, 4, 2);
		/* 1392 */setBlock(world, i + 7, j + 44, k + 9, Blocks.leaves, 4);
		/* 1393 */world.setBlockMetadataWithNotify(i + 7, j + 44, k + 9, 4, 2);
		/* 1394 */setBlock(world, i + 7, j + 44, k + 10, Blocks.leaves, 4);
		/* 1395 */world.setBlockMetadataWithNotify(i + 7, j + 44, k + 10, 4, 2);
		/* 1396 */setBlock(world, i + 7, j + 44, k + 13, Blocks.leaves, 4);
		/* 1397 */world.setBlockMetadataWithNotify(i + 7, j + 44, k + 13, 4, 2);
		/* 1398 */setBlock(world, i + 7, j + 44, k + 17, Blocks.leaves, 4);
		/* 1399 */world.setBlockMetadataWithNotify(i + 7, j + 44, k + 17, 4, 2);
		/* 1400 */setBlock(world, i + 7, j + 45, k + 15, Blocks.leaves, 4);
		/* 1401 */world.setBlockMetadataWithNotify(i + 7, j + 45, k + 15, 4, 2);
		/* 1402 */setBlock(world, i + 7, j + 46, k + 17, Blocks.leaves, 4);
		/* 1403 */world.setBlockMetadataWithNotify(i + 7, j + 46, k + 17, 4, 2);
		/* 1404 */setBlock(world, i + 7, j + 46, k + 18, Blocks.leaves, 4);
		/* 1405 */world.setBlockMetadataWithNotify(i + 7, j + 46, k + 18, 4, 2);
		/* 1406 */setBlock(world, i + 7, j + 46, k + 19, Blocks.leaves, 4);
		/* 1407 */world.setBlockMetadataWithNotify(i + 7, j + 46, k + 19, 4, 2);
		/* 1408 */setBlock(world, i + 7, j + 47, k + 18, Blocks.leaves, 4);
		/* 1409 */world.setBlockMetadataWithNotify(i + 7, j + 47, k + 18, 4, 2);
		/* 1410 */setBlock(world, i + 7, j + 48, k + 16, Blocks.leaves, 4);
		/* 1411 */world.setBlockMetadataWithNotify(i + 7, j + 48, k + 16, 4, 2);
		/* 1412 */setBlock(world, i + 7, j + 49, k + 17, Blocks.leaves, 4);
		/* 1413 */world.setBlockMetadataWithNotify(i + 7, j + 49, k + 17, 4, 2);
		/* 1414 */setBlock(world, i + 8, j + 34, k + 10, Blocks.leaves, 4);
		/* 1415 */world.setBlockMetadataWithNotify(i + 8, j + 34, k + 10, 4, 2);
		/* 1416 */setBlock(world, i + 8, j + 34, k + 18, Blocks.leaves, 4);
		/* 1417 */world.setBlockMetadataWithNotify(i + 8, j + 34, k + 18, 4, 2);
		/* 1418 */setBlock(world, i + 8, j + 34, k + 22, Blocks.leaves, 4);
		/* 1419 */world.setBlockMetadataWithNotify(i + 8, j + 34, k + 22, 4, 2);
		/* 1420 */setBlock(world, i + 8, j + 35, k + 9, Blocks.leaves, 4);
		/* 1421 */world.setBlockMetadataWithNotify(i + 8, j + 35, k + 9, 4, 2);
		/* 1422 */setBlock(world, i + 8, j + 35, k + 10, Blocks.leaves, 4);
		/* 1423 */world.setBlockMetadataWithNotify(i + 8, j + 35, k + 10, 4, 2);
		/* 1424 */setBlock(world, i + 8, j + 35, k + 11, Blocks.leaves, 4);
		/* 1425 */world.setBlockMetadataWithNotify(i + 8, j + 35, k + 11, 4, 2);
		/* 1426 */setBlock(world, i + 8, j + 35, k + 17, Blocks.leaves, 4);
		/* 1427 */world.setBlockMetadataWithNotify(i + 8, j + 35, k + 17, 4, 2);
		/* 1428 */setBlock(world, i + 8, j + 35, k + 18, Blocks.leaves, 4);
		/* 1429 */world.setBlockMetadataWithNotify(i + 8, j + 35, k + 18, 4, 2);
		/* 1430 */setBlock(world, i + 8, j + 35, k + 19, Blocks.leaves, 4);
		/* 1431 */world.setBlockMetadataWithNotify(i + 8, j + 35, k + 19, 4, 2);
		/* 1432 */setBlock(world, i + 8, j + 35, k + 21, Blocks.leaves, 4);
		/* 1433 */world.setBlockMetadataWithNotify(i + 8, j + 35, k + 21, 4, 2);
		/* 1434 */setBlock(world, i + 8, j + 35, k + 22, Blocks.leaves, 4);
		/* 1435 */world.setBlockMetadataWithNotify(i + 8, j + 35, k + 22, 4, 2);
		/* 1436 */setBlock(world, i + 8, j + 35, k + 23, Blocks.leaves, 4);
		/* 1437 */world.setBlockMetadataWithNotify(i + 8, j + 35, k + 23, 4, 2);
		/* 1438 */setBlock(world, i + 8, j + 36, k + 10, Blocks.leaves, 4);
		/* 1439 */world.setBlockMetadataWithNotify(i + 8, j + 36, k + 10, 4, 2);
		/* 1440 */setBlock(world, i + 8, j + 36, k + 11, Blocks.leaves, 4);
		/* 1441 */world.setBlockMetadataWithNotify(i + 8, j + 36, k + 11, 4, 2);
		/* 1442 */setBlock(world, i + 8, j + 36, k + 12, Blocks.leaves, 4);
		/* 1443 */world.setBlockMetadataWithNotify(i + 8, j + 36, k + 12, 4, 2);
		/* 1444 */setBlock(world, i + 8, j + 36, k + 13, Blocks.leaves, 4);
		/* 1445 */world.setBlockMetadataWithNotify(i + 8, j + 36, k + 13, 4, 2);
		/* 1446 */setBlock(world, i + 8, j + 36, k + 15, Blocks.leaves, 4);
		/* 1447 */world.setBlockMetadataWithNotify(i + 8, j + 36, k + 15, 4, 2);
		/* 1448 */setBlock(world, i + 8, j + 36, k + 16, Blocks.leaves, 4);
		/* 1449 */world.setBlockMetadataWithNotify(i + 8, j + 36, k + 16, 4, 2);
		/* 1450 */setBlock(world, i + 8, j + 36, k + 17, Blocks.leaves, 4);
		/* 1451 */world.setBlockMetadataWithNotify(i + 8, j + 36, k + 17, 4, 2);
		/* 1452 */setBlock(world, i + 8, j + 36, k + 18, Blocks.leaves, 4);
		/* 1453 */world.setBlockMetadataWithNotify(i + 8, j + 36, k + 18, 4, 2);
		/* 1454 */setBlock(world, i + 8, j + 36, k + 19, Blocks.leaves, 4);
		/* 1455 */world.setBlockMetadataWithNotify(i + 8, j + 36, k + 19, 4, 2);
		/* 1456 */setBlock(world, i + 8, j + 36, k + 20, Blocks.leaves, 4);
		/* 1457 */world.setBlockMetadataWithNotify(i + 8, j + 36, k + 20, 4, 2);
		/* 1458 */setBlock(world, i + 8, j + 36, k + 22, Blocks.leaves, 4);
		/* 1459 */world.setBlockMetadataWithNotify(i + 8, j + 36, k + 22, 4, 2);
		/* 1460 */setBlock(world, i + 8, j + 36, k + 23, Blocks.leaves, 4);
		/* 1461 */world.setBlockMetadataWithNotify(i + 8, j + 36, k + 23, 4, 2);
		/* 1462 */setBlock(world, i + 8, j + 37, k + 9, Blocks.leaves, 4);
		/* 1463 */world.setBlockMetadataWithNotify(i + 8, j + 37, k + 9, 4, 2);
		/* 1464 */setBlock(world, i + 8, j + 37, k + 10, Blocks.leaves, 4);
		/* 1465 */world.setBlockMetadataWithNotify(i + 8, j + 37, k + 10, 4, 2);
		/* 1466 */setBlock(world, i + 8, j + 37, k + 11, Blocks.leaves, 4);
		/* 1467 */world.setBlockMetadataWithNotify(i + 8, j + 37, k + 11, 4, 2);
		/* 1468 */setBlock(world, i + 8, j + 37, k + 12, Blocks.leaves, 4);
		/* 1469 */world.setBlockMetadataWithNotify(i + 8, j + 37, k + 12, 4, 2);
		/* 1470 */setBlock(world, i + 8, j + 37, k + 13, Blocks.leaves, 4);
		/* 1471 */world.setBlockMetadataWithNotify(i + 8, j + 37, k + 13, 4, 2);
		/* 1472 */setBlock(world, i + 8, j + 37, k + 14, Blocks.leaves, 4);
		/* 1473 */world.setBlockMetadataWithNotify(i + 8, j + 37, k + 14, 4, 2);
		/* 1474 */setBlock(world, i + 8, j + 37, k + 16, Blocks.leaves, 4);
		/* 1475 */world.setBlockMetadataWithNotify(i + 8, j + 37, k + 16, 4, 2);
		/* 1476 */setBlock(world, i + 8, j + 37, k + 17, Blocks.leaves, 4);
		/* 1477 */world.setBlockMetadataWithNotify(i + 8, j + 37, k + 17, 4, 2);
		/* 1478 */setBlock(world, i + 8, j + 37, k + 18, Blocks.leaves, 4);
		/* 1479 */world.setBlockMetadataWithNotify(i + 8, j + 37, k + 18, 4, 2);
		/* 1480 */setBlock(world, i + 8, j + 37, k + 19, Blocks.leaves, 4);
		/* 1481 */world.setBlockMetadataWithNotify(i + 8, j + 37, k + 19, 4, 2);
		/* 1482 */setBlock(world, i + 8, j + 37, k + 20, Blocks.leaves, 4);
		/* 1483 */world.setBlockMetadataWithNotify(i + 8, j + 37, k + 20, 4, 2);
		/* 1484 */setBlock(world, i + 8, j + 37, k + 21, Blocks.leaves, 4);
		/* 1485 */world.setBlockMetadataWithNotify(i + 8, j + 37, k + 21, 4, 2);
		/* 1486 */setBlock(world, i + 8, j + 37, k + 22, Blocks.leaves, 4);
		/* 1487 */world.setBlockMetadataWithNotify(i + 8, j + 37, k + 22, 4, 2);
		/* 1488 */setBlock(world, i + 8, j + 37, k + 23, Blocks.leaves, 4);
		/* 1489 */world.setBlockMetadataWithNotify(i + 8, j + 37, k + 23, 4, 2);
		/* 1490 */setBlock(world, i + 8, j + 38, k + 9, Blocks.leaves, 4);
		/* 1491 */world.setBlockMetadataWithNotify(i + 8, j + 38, k + 9, 4, 2);
		/* 1492 */setBlock(world, i + 8, j + 38, k + 10, Blocks.leaves, 4);
		/* 1493 */world.setBlockMetadataWithNotify(i + 8, j + 38, k + 10, 4, 2);
		/* 1494 */setBlock(world, i + 8, j + 38, k + 11, Blocks.leaves, 4);
		/* 1495 */world.setBlockMetadataWithNotify(i + 8, j + 38, k + 11, 4, 2);
		/* 1496 */setBlock(world, i + 8, j + 38, k + 12, Blocks.leaves, 4);
		/* 1497 */world.setBlockMetadataWithNotify(i + 8, j + 38, k + 12, 4, 2);
		/* 1498 */setBlock(world, i + 8, j + 38, k + 13, Blocks.leaves, 4);
		/* 1499 */world.setBlockMetadataWithNotify(i + 8, j + 38, k + 13, 4, 2);
		/* 1500 */setBlock(world, i + 8, j + 38, k + 15, Blocks.leaves, 4);
		/* 1501 */world.setBlockMetadataWithNotify(i + 8, j + 38, k + 15, 4, 2);
		/* 1502 */setBlock(world, i + 8, j + 38, k + 16, Blocks.leaves, 4);
		/* 1503 */world.setBlockMetadataWithNotify(i + 8, j + 38, k + 16, 4, 2);
		/* 1504 */setBlock(world, i + 8, j + 38, k + 18, Blocks.leaves, 4);
		/* 1505 */world.setBlockMetadataWithNotify(i + 8, j + 38, k + 18, 4, 2);
		/* 1506 */setBlock(world, i + 8, j + 38, k + 19, Blocks.leaves, 4);
		/* 1507 */world.setBlockMetadataWithNotify(i + 8, j + 38, k + 19, 4, 2);
		/* 1508 */setBlock(world, i + 8, j + 38, k + 20, Blocks.leaves, 4);
		/* 1509 */world.setBlockMetadataWithNotify(i + 8, j + 38, k + 20, 4, 2);
		/* 1510 */setBlock(world, i + 8, j + 38, k + 22, Blocks.leaves, 4);
		/* 1511 */world.setBlockMetadataWithNotify(i + 8, j + 38, k + 22, 4, 2);
		/* 1512 */setBlock(world, i + 8, j + 38, k + 25, Blocks.leaves, 4);
		/* 1513 */world.setBlockMetadataWithNotify(i + 8, j + 38, k + 25, 4, 2);
		/* 1514 */setBlock(world, i + 8, j + 39, k + 8, Blocks.leaves, 4);
		/* 1515 */world.setBlockMetadataWithNotify(i + 8, j + 39, k + 8, 4, 2);
		/* 1516 */setBlock(world, i + 8, j + 39, k + 10, Blocks.leaves, 4);
		/* 1517 */world.setBlockMetadataWithNotify(i + 8, j + 39, k + 10, 4, 2);
		/* 1518 */setBlock(world, i + 8, j + 39, k + 12, Blocks.leaves, 4);
		/* 1519 */world.setBlockMetadataWithNotify(i + 8, j + 39, k + 12, 4, 2);
		/* 1520 */setBlock(world, i + 8, j + 39, k + 13, Blocks.leaves, 4);
		/* 1521 */world.setBlockMetadataWithNotify(i + 8, j + 39, k + 13, 4, 2);
		/* 1522 */setBlock(world, i + 8, j + 39, k + 14, Blocks.leaves, 4);
		/* 1523 */world.setBlockMetadataWithNotify(i + 8, j + 39, k + 14, 4, 2);
		/* 1524 */setBlock(world, i + 8, j + 39, k + 17, Blocks.leaves, 4);
		/* 1525 */world.setBlockMetadataWithNotify(i + 8, j + 39, k + 17, 4, 2);
		/* 1526 */setBlock(world, i + 8, j + 39, k + 18, Blocks.leaves, 4);
		/* 1527 */world.setBlockMetadataWithNotify(i + 8, j + 39, k + 18, 4, 2);
		/* 1528 */setBlock(world, i + 8, j + 39, k + 19, Blocks.leaves, 4);
		/* 1529 */world.setBlockMetadataWithNotify(i + 8, j + 39, k + 19, 4, 2);
		/* 1530 */setBlock(world, i + 8, j + 39, k + 20, Blocks.leaves, 4);
		/* 1531 */world.setBlockMetadataWithNotify(i + 8, j + 39, k + 20, 4, 2);
		/*       */
		/* 1533 */generate2(world, rand, i, j, k);
		/* 1534 */return true;
		/*       */}

	/*       */
	/*       */public boolean generate10(World world, Random rand, int i, int j, int k)
	/*       */
	{
		/* 1539 */setBlock(world, i + 29, j + 43, k + 18, Blocks.leaves, 4);
		/* 1540 */world.setBlockMetadataWithNotify(i + 29, j + 43, k + 18, 4, 2);
		/* 1541 */setBlock(world, i + 29, j + 43, k + 19, Blocks.leaves, 4);
		/* 1542 */world.setBlockMetadataWithNotify(i + 29, j + 43, k + 19, 4, 2);
		/* 1543 */setBlock(world, i + 29, j + 43, k + 21, Blocks.leaves, 4);
		/* 1544 */world.setBlockMetadataWithNotify(i + 29, j + 43, k + 21, 4, 2);
		/* 1545 */setBlock(world, i + 29, j + 43, k + 22, Blocks.leaves, 4);
		/* 1546 */world.setBlockMetadataWithNotify(i + 29, j + 43, k + 22, 4, 2);
		/* 1547 */setBlock(world, i + 29, j + 43, k + 23, Blocks.leaves, 4);
		/* 1548 */world.setBlockMetadataWithNotify(i + 29, j + 43, k + 23, 4, 2);
		/* 1549 */setBlock(world, i + 29, j + 43, k + 24, Blocks.leaves, 4);
		/* 1550 */world.setBlockMetadataWithNotify(i + 29, j + 43, k + 24, 4, 2);
		/* 1551 */setBlock(world, i + 29, j + 44, k + 9, Blocks.leaves, 4);
		/* 1552 */world.setBlockMetadataWithNotify(i + 29, j + 44, k + 9, 4, 2);
		/* 1553 */setBlock(world, i + 29, j + 44, k + 10, Blocks.leaves, 4);
		/* 1554 */world.setBlockMetadataWithNotify(i + 29, j + 44, k + 10, 4, 2);
		/* 1555 */setBlock(world, i + 29, j + 44, k + 11, Blocks.leaves, 4);
		/* 1556 */world.setBlockMetadataWithNotify(i + 29, j + 44, k + 11, 4, 2);
		/* 1557 */setBlock(world, i + 29, j + 44, k + 12, Blocks.leaves, 4);
		/* 1558 */world.setBlockMetadataWithNotify(i + 29, j + 44, k + 12, 4, 2);
		/* 1559 */setBlock(world, i + 29, j + 44, k + 13, Blocks.leaves, 4);
		/* 1560 */world.setBlockMetadataWithNotify(i + 29, j + 44, k + 13, 4, 2);
		/* 1561 */setBlock(world, i + 29, j + 44, k + 14, Blocks.leaves, 4);
		/* 1562 */world.setBlockMetadataWithNotify(i + 29, j + 44, k + 14, 4, 2);
		/* 1563 */setBlock(world, i + 29, j + 44, k + 15, Blocks.leaves, 4);
		/* 1564 */world.setBlockMetadataWithNotify(i + 29, j + 44, k + 15, 4, 2);
		/* 1565 */setBlock(world, i + 29, j + 44, k + 16, Blocks.leaves, 4);
		/* 1566 */world.setBlockMetadataWithNotify(i + 29, j + 44, k + 16, 4, 2);
		/* 1567 */setBlock(world, i + 29, j + 44, k + 18, Blocks.leaves, 4);
		/* 1568 */world.setBlockMetadataWithNotify(i + 29, j + 44, k + 18, 4, 2);
		/* 1569 */setBlock(world, i + 29, j + 44, k + 19, Blocks.leaves, 4);
		/* 1570 */world.setBlockMetadataWithNotify(i + 29, j + 44, k + 19, 4, 2);
		/* 1571 */setBlock(world, i + 29, j + 44, k + 20, Blocks.leaves, 4);
		/* 1572 */world.setBlockMetadataWithNotify(i + 29, j + 44, k + 20, 4, 2);
		/* 1573 */setBlock(world, i + 29, j + 44, k + 21, Blocks.leaves, 4);
		/* 1574 */world.setBlockMetadataWithNotify(i + 29, j + 44, k + 21, 4, 2);
		/* 1575 */setBlock(world, i + 29, j + 44, k + 23, Blocks.leaves, 4);
		/* 1576 */world.setBlockMetadataWithNotify(i + 29, j + 44, k + 23, 4, 2);
		/* 1577 */setBlock(world, i + 29, j + 44, k + 24, Blocks.leaves, 4);
		/* 1578 */world.setBlockMetadataWithNotify(i + 29, j + 44, k + 24, 4, 2);
		/* 1579 */setBlock(world, i + 29, j + 45, k + 11, Blocks.leaves, 4);
		/* 1580 */world.setBlockMetadataWithNotify(i + 29, j + 45, k + 11, 4, 2);
		/* 1581 */setBlock(world, i + 29, j + 45, k + 12, Blocks.leaves, 4);
		/* 1582 */world.setBlockMetadataWithNotify(i + 29, j + 45, k + 12, 4, 2);
