/*      */package com.parzivail.pswm.world.gen;

/*      */
/*      *//*      */
import java.util.Random;

/*      */
import net.minecraft.block.Block;
/*      */
import net.minecraft.init.Blocks;
/*      */
import net.minecraft.world.World;
/*      */
import net.minecraft.world.chunk.IChunkProvider;
/*      */
import net.minecraft.world.gen.feature.WorldGenerator;
import cpw.mods.fml.common.IWorldGenerator;

/*      */
/*      */
/*      */
/*      */
/*      */
/*      */
/*      */
/*      */
/*      */
/*      */public class WorldGenEndorTree3
/*      */extends WorldGenerator
/*      */implements IWorldGenerator
/*      */
{
	/*      */public void generate(Random random, int chunkX, int chunkZ, World world, IChunkProvider chunkGenerator, IChunkProvider chunkProvider)
	{
	}

	/*      */
	/*      */public boolean generate(World world, Random rand, int i, int j, int k)
	/*      */
	{
		if ((!locationIsValidSpawn(world, i, j, k)) || (!locationIsValidSpawn(world, i + 36, j, k)) || (!locationIsValidSpawn(world, i + 36, j, k + 31)) || (!locationIsValidSpawn(world, i, j, k + 31))) { return false;
		/*      */}
		k -= 10;
		i -= 10;
		/*      */
		setBlock(world, i + 2, j + 40, k + 8, Blocks.log, 0);
		setBlock(world, i + 2, j + 40, k + 23, Blocks.log, 0);
		setBlock(world, i + 4, j + 39, k + 10, Blocks.log, 0);
		setBlock(world, i + 4, j + 42, k + 16, Blocks.log, 0);
		setBlock(world, i + 5, j + 40, k + 20, Blocks.log, 0);
		setBlock(world, i + 5, j + 41, k + 16, Blocks.log, 0);
		setBlock(world, i + 6, j + 39, k + 17, Blocks.log, 0);
		setBlock(world, i + 6, j + 40, k + 16, Blocks.log, 0);
		setBlock(world, i + 6, j + 42, k + 11, Blocks.log, 0);
		setBlock(world, i + 7, j + 39, k + 10, Blocks.log, 0);
		setBlock(world, i + 7, j + 39, k + 16, Blocks.log, 0);
		setBlock(world, i + 7, j + 42, k + 8, Blocks.log, 0);
		setBlock(world, i + 8, j + 41, k + 23, Blocks.log, 0);
		setBlock(world, i + 9, j + 41, k + 22, Blocks.log, 0);
		setBlock(world, i + 9, j + 43, k + 11, Blocks.log, 0);
		setBlock(world, i + 10, j + 39, k + 10, Blocks.log, 0);
		setBlock(world, i + 10, j + 39, k + 16, Blocks.log, 0);
		setBlock(world, i + 10, j + 43, k + 7, Blocks.log, 0);
		setBlock(world, i + 10, j + 43, k + 8, Blocks.log, 0);
		setBlock(world, i + 10, j + 44, k + 21, Blocks.log, 0);
		setBlock(world, i + 11, j + 40, k + 21, Blocks.log, 0);
		setBlock(world, i + 11, j + 41, k + 17, Blocks.log, 0);
		setBlock(world, i + 11, j + 42, k + 10, Blocks.log, 0);
		setBlock(world, i + 11, j + 42, k + 15, Blocks.log, 0);
		setBlock(world, i + 11, j + 45, k + 19, Blocks.log, 0);
		setBlock(world, i + 11, j + 45, k + 21, Blocks.log, 0);
		setBlock(world, i + 12, j + 40, k + 15, Blocks.log, 0);
		setBlock(world, i + 12, j + 40, k + 16, Blocks.log, 0);
		setBlock(world, i + 12, j + 40, k + 17, Blocks.log, 0);
		setBlock(world, i + 12, j + 41, k + 11, Blocks.log, 0);
		setBlock(world, i + 12, j + 42, k + 10, Blocks.log, 0);
		setBlock(world, i + 12, j + 43, k + 9, Blocks.log, 0);
		setBlock(world, i + 12, j + 46, k + 13, Blocks.log, 0);
		setBlock(world, i + 12, j + 47, k + 16, Blocks.log, 0);
		setBlock(world, i + 13, j + 39, k + 17, Blocks.log, 0);
		setBlock(world, i + 13, j + 39, k + 18, Blocks.log, 0);
		setBlock(world, i + 13, j + 39, k + 24, Blocks.log, 0);
		setBlock(world, i + 13, j + 40, k + 8, Blocks.log, 0);
		setBlock(world, i + 13, j + 40, k + 12, Blocks.log, 0);
		setBlock(world, i + 13, j + 41, k + 14, Blocks.log, 0);
		setBlock(world, i + 13, j + 41, k + 18, Blocks.log, 0);
		setBlock(world, i + 13, j + 43, k + 6, Blocks.log, 0);
		setBlock(world, i + 13, j + 43, k + 7, Blocks.log, 0);
		setBlock(world, i + 13, j + 43, k + 11, Blocks.log, 0);
		setBlock(world, i + 13, j + 44, k + 22, Blocks.log, 0);
		setBlock(world, i + 13, j + 46, k + 13, Blocks.log, 0);
		setBlock(world, i + 13, j + 46, k + 14, Blocks.log, 0);
		setBlock(world, i + 13, j + 47, k + 14, Blocks.log, 0);
		setBlock(world, i + 13, j + 47, k + 16, Blocks.log, 0);
		setBlock(world, i + 14, j + 40, k + 7, Blocks.log, 0);
		setBlock(world, i + 14, j + 44, k + 16, Blocks.log, 0);
		setBlock(world, i + 14, j + 45, k + 18, Blocks.log, 0);
		setBlock(world, i + 14, j + 45, k + 19, Blocks.log, 0);
		setBlock(world, i + 14, j + 46, k + 13, Blocks.log, 0);
		setBlock(world, i + 14, j + 46, k + 19, Blocks.log, 0);
		setBlock(world, i + 14, j + 47, k + 15, Blocks.log, 0);
		setBlock(world, i + 15, j + 39, k + 6, Blocks.log, 0);
		setBlock(world, i + 15, j + 39, k + 19, Blocks.log, 0);
		setBlock(world, i + 15, j + 40, k + 2, Blocks.log, 0);
		setBlock(world, i + 15, j + 42, k + 23, Blocks.log, 0);
		setBlock(world, i + 15, j + 43, k + 10, Blocks.log, 0);
		setBlock(world, i + 15, j + 43, k + 19, Blocks.log, 0);
		setBlock(world, i + 15, j + 44, k + 13, Blocks.log, 0);
		setBlock(world, i + 15, j + 44, k + 16, Blocks.log, 0);
		setBlock(world, i + 15, j + 44, k + 20, Blocks.log, 0);
		setBlock(world, i + 15, j + 45, k + 18, Blocks.log, 0);
		setBlock(world, i + 15, j + 45, k + 22, Blocks.log, 0);
		setBlock(world, i + 15, j + 46, k + 15, Blocks.log, 0);
		setBlock(world, i + 15, j + 47, k + 15, Blocks.log, 0);
		setBlock(world, i + 15, j + 47, k + 18, Blocks.log, 0);
		setBlock(world, i + 16, j + 40, k + 29, Blocks.log, 0);
		setBlock(world, i + 16, j + 41, k + 6, Blocks.log, 0);
		setBlock(world, i + 16, j + 41, k + 10, Blocks.log, 0);
		setBlock(world, i + 16, j + 42, k + 14, Blocks.log, 0);
		setBlock(world, i + 16, j + 42, k + 21, Blocks.log, 0);
		setBlock(world, i + 16, j + 43, k + 16, Blocks.log, 0);
		setBlock(world, i + 16, j + 44, k + 9, Blocks.log, 0);
		setBlock(world, i + 16, j + 44, k + 16, Blocks.log, 0);
		setBlock(world, i + 16, j + 45, k + 13, Blocks.log, 0);
		setBlock(world, i + 16, j + 45, k + 20, Blocks.log, 0);
		setBlock(world, i + 16, j + 46, k + 16, Blocks.log, 0);
		setBlock(world, i + 16, j + 47, k + 13, Blocks.log, 0);
		setBlock(world, i + 16, j + 48, k + 11, Blocks.log, 0);
		setBlock(world, i + 17, j + 0, k + 15, Blocks.log, 0);
		setBlock(world, i + 17, j + 0, k + 16, Blocks.log, 0);
		setBlock(world, i + 17, j + 0, k + 17, Blocks.log, 0);
		setBlock(world, i + 17, j + 0, k + 18, Blocks.log, 0);
		setBlock(world, i + 17, j + 1, k + 15, Blocks.log, 0);
		setBlock(world, i + 17, j + 1, k + 16, Blocks.log, 0);
		setBlock(world, i + 17, j + 1, k + 17, Blocks.log, 0);
		setBlock(world, i + 17, j + 1, k + 18, Blocks.log, 0);
		setBlock(world, i + 17, j + 2, k + 15, Blocks.log, 0);
		setBlock(world, i + 17, j + 2, k + 16, Blocks.log, 0);
		setBlock(world, i + 17, j + 2, k + 17, Blocks.log, 0);
		setBlock(world, i + 17, j + 2, k + 18, Blocks.log, 0);
		setBlock(world, i + 17, j + 3, k + 15, Blocks.log, 0);
		setBlock(world, i + 17, j + 3, k + 16, Blocks.log, 0);
		setBlock(world, i + 17, j + 3, k + 17, Blocks.log, 0);
		setBlock(world, i + 17, j + 3, k + 18, Blocks.log, 0);
		setBlock(world, i + 17, j + 4, k + 15, Blocks.log, 0);
		setBlock(world, i + 17, j + 4, k + 16, Blocks.log, 0);
		setBlock(world, i + 17, j + 4, k + 17, Blocks.log, 0);
		setBlock(world, i + 17, j + 4, k + 18, Blocks.log, 0);
		setBlock(world, i + 17, j + 5, k + 15, Blocks.log, 0);
		setBlock(world, i + 17, j + 5, k + 16, Blocks.log, 0);
		setBlock(world, i + 17, j + 5, k + 17, Blocks.log, 0);
		setBlock(world, i + 17, j + 5, k + 18, Blocks.log, 0);
		setBlock(world, i + 17, j + 6, k + 15, Blocks.log, 0);
		setBlock(world, i + 17, j + 6, k + 16, Blocks.log, 0);
		setBlock(world, i + 17, j + 6, k + 17, Blocks.log, 0);
		setBlock(world, i + 17, j + 6, k + 18, Blocks.log, 0);
		setBlock(world, i + 17, j + 7, k + 15, Blocks.log, 0);
		setBlock(world, i + 17, j + 7, k + 16, Blocks.log, 0);
		setBlock(world, i + 17, j + 7, k + 17, Blocks.log, 0);
		setBlock(world, i + 17, j + 7, k + 18, Blocks.log, 0);
		setBlock(world, i + 17, j + 8, k + 15, Blocks.log, 0);
		setBlock(world, i + 17, j + 8, k + 18, Blocks.log, 0);
		setBlock(world, i + 17, j + 39, k + 6, Blocks.log, 0);
		setBlock(world, i + 17, j + 40, k + 13, Blocks.log, 0);
		setBlock(world, i + 17, j + 40, k + 23, Blocks.log, 0);
		setBlock(world, i + 17, j + 41, k + 10, Blocks.log, 0);
		setBlock(world, i + 17, j + 41, k + 11, Blocks.log, 0);
		setBlock(world, i + 17, j + 41, k + 20, Blocks.log, 0);
		setBlock(world, i + 17, j + 42, k + 15, Blocks.log, 0);
		setBlock(world, i + 17, j + 42, k + 29, Blocks.log, 0);
		setBlock(world, i + 17, j + 43, k + 3, Blocks.log, 0);
		setBlock(world, i + 17, j + 43, k + 4, Blocks.log, 0);
		setBlock(world, i + 17, j + 43, k + 9, Blocks.log, 0);
		setBlock(world, i + 17, j + 43, k + 19, Blocks.log, 0);
		setBlock(world, i + 17, j + 43, k + 22, Blocks.log, 0);
		setBlock(world, i + 17, j + 45, k + 19, Blocks.log, 0);
		setBlock(world, i + 17, j + 46, k + 15, Blocks.log, 0);
		setBlock(world, i + 17, j + 47, k + 9, Blocks.log, 0);
		setBlock(world, i + 17, j + 47, k + 14, Blocks.log, 0);
		setBlock(world, i + 17, j + 47, k + 20, Blocks.log, 0);
		setBlock(world, i + 17, j + 48, k + 13, Blocks.log, 0);
		setBlock(world, i + 17, j + 48, k + 19, Blocks.log, 0);
		setBlock(world, i + 18, j + 0, k + 14, Blocks.log, 0);
		setBlock(world, i + 18, j + 0, k + 15, Blocks.log, 0);
		setBlock(world, i + 18, j + 0, k + 16, Blocks.log, 0);
		setBlock(world, i + 18, j + 0, k + 17, Blocks.log, 0);
		setBlock(world, i + 18, j + 0, k + 18, Blocks.log, 0);
		setBlock(world, i + 18, j + 1, k + 14, Blocks.log, 0);
		setBlock(world, i + 18, j + 1, k + 15, Blocks.log, 0);
		setBlock(world, i + 18, j + 1, k + 16, Blocks.log, 0);
		setBlock(world, i + 18, j + 1, k + 17, Blocks.log, 0);
		setBlock(world, i + 18, j + 1, k + 18, Blocks.log, 0);
		setBlock(world, i + 18, j + 2, k + 14, Blocks.log, 0);
		setBlock(world, i + 18, j + 2, k + 15, Blocks.log, 0);
		setBlock(world, i + 18, j + 2, k + 16, Blocks.log, 0);
		setBlock(world, i + 18, j + 2, k + 17, Blocks.log, 0);
		setBlock(world, i + 18, j + 2, k + 18, Blocks.log, 0);
		setBlock(world, i + 18, j + 3, k + 14, Blocks.log, 0);
		setBlock(world, i + 18, j + 3, k + 15, Blocks.log, 0);
		setBlock(world, i + 18, j + 3, k + 16, Blocks.log, 0);
		setBlock(world, i + 18, j + 3, k + 17, Blocks.log, 0);
		setBlock(world, i + 18, j + 3, k + 18, Blocks.log, 0);
		setBlock(world, i + 18, j + 4, k + 14, Blocks.log, 0);
		setBlock(world, i + 18, j + 4, k + 15, Blocks.log, 0);
		setBlock(world, i + 18, j + 4, k + 16, Blocks.log, 0);
		setBlock(world, i + 18, j + 4, k + 17, Blocks.log, 0);
		setBlock(world, i + 18, j + 4, k + 18, Blocks.log, 0);
		setBlock(world, i + 18, j + 5, k + 14, Blocks.log, 0);
		setBlock(world, i + 18, j + 5, k + 15, Blocks.log, 0);
		setBlock(world, i + 18, j + 5, k + 16, Blocks.log, 0);
		setBlock(world, i + 18, j + 5, k + 17, Blocks.log, 0);
		setBlock(world, i + 18, j + 5, k + 18, Blocks.log, 0);
		setBlock(world, i + 18, j + 6, k + 14, Blocks.log, 0);
		setBlock(world, i + 18, j + 6, k + 15, Blocks.log, 0);
		setBlock(world, i + 18, j + 6, k + 16, Blocks.log, 0);
		setBlock(world, i + 18, j + 6, k + 17, Blocks.log, 0);
		setBlock(world, i + 18, j + 6, k + 18, Blocks.log, 0);
		setBlock(world, i + 18, j + 7, k + 14, Blocks.log, 0);
		setBlock(world, i + 18, j + 7, k + 15, Blocks.log, 0);
		setBlock(world, i + 18, j + 7, k + 16, Blocks.log, 0);
		setBlock(world, i + 18, j + 7, k + 17, Blocks.log, 0);
		setBlock(world, i + 18, j + 7, k + 18, Blocks.log, 0);
		setBlock(world, i + 18, j + 8, k + 14, Blocks.log, 0);
		setBlock(world, i + 18, j + 8, k + 15, Blocks.log, 0);
		setBlock(world, i + 18, j + 8, k + 16, Blocks.log, 0);
		setBlock(world, i + 18, j + 8, k + 17, Blocks.log, 0);
		setBlock(world, i + 18, j + 8, k + 18, Blocks.log, 0);
		setBlock(world, i + 18, j + 9, k + 14, Blocks.log, 0);
		setBlock(world, i + 18, j + 9, k + 15, Blocks.log, 0);
		setBlock(world, i + 18, j + 9, k + 16, Blocks.log, 0);
		setBlock(world, i + 18, j + 9, k + 17, Blocks.log, 0);
		setBlock(world, i + 18, j + 10, k + 14, Blocks.log, 0);
		setBlock(world, i + 18, j + 10, k + 15, Blocks.log, 0);
		setBlock(world, i + 18, j + 10, k + 16, Blocks.log, 0);
		setBlock(world, i + 18, j + 10, k + 17, Blocks.log, 0);
		setBlock(world, i + 18, j + 11, k + 14, Blocks.log, 0);
		setBlock(world, i + 18, j + 11, k + 15, Blocks.log, 0);
		setBlock(world, i + 18, j + 11, k + 16, Blocks.log, 0);
		setBlock(world, i + 18, j + 11, k + 17, Blocks.log, 0);
		setBlock(world, i + 18, j + 12, k + 14, Blocks.log, 0);
		setBlock(world, i + 18, j + 12, k + 15, Blocks.log, 0);
		setBlock(world, i + 18, j + 12, k + 16, Blocks.log, 0);
		setBlock(world, i + 18, j + 12, k + 17, Blocks.log, 0);
		setBlock(world, i + 18, j + 13, k + 14, Blocks.log, 0);
		setBlock(world, i + 18, j + 13, k + 15, Blocks.log, 0);
		setBlock(world, i + 18, j + 13, k + 16, Blocks.log, 0);
		setBlock(world, i + 18, j + 13, k + 17, Blocks.log, 0);
		setBlock(world, i + 18, j + 14, k + 14, Blocks.log, 0);
		setBlock(world, i + 18, j + 14, k + 15, Blocks.log, 0);
		setBlock(world, i + 18, j + 14, k + 16, Blocks.log, 0);
		setBlock(world, i + 18, j + 14, k + 17, Blocks.log, 0);
		setBlock(world, i + 18, j + 15, k + 14, Blocks.log, 0);
		setBlock(world, i + 18, j + 15, k + 15, Blocks.log, 0);
		setBlock(world, i + 18, j + 15, k + 16, Blocks.log, 0);
		setBlock(world, i + 18, j + 15, k + 17, Blocks.log, 0);
		setBlock(world, i + 18, j + 16, k + 15, Blocks.log, 0);
		setBlock(world, i + 18, j + 16, k + 16, Blocks.log, 0);
		setBlock(world, i + 18, j + 16, k + 17, Blocks.log, 0);
		setBlock(world, i + 18, j + 17, k + 15, Blocks.log, 0);
		setBlock(world, i + 18, j + 17, k + 16, Blocks.log, 0);
		setBlock(world, i + 18, j + 17, k + 17, Blocks.log, 0);
		setBlock(world, i + 18, j + 18, k + 15, Blocks.log, 0);
		setBlock(world, i + 18, j + 18, k + 16, Blocks.log, 0);
		setBlock(world, i + 18, j + 18, k + 17, Blocks.log, 0);
		setBlock(world, i + 18, j + 19, k + 15, Blocks.log, 0);
		setBlock(world, i + 18, j + 19, k + 16, Blocks.log, 0);
		setBlock(world, i + 18, j + 19, k + 17, Blocks.log, 0);
		setBlock(world, i + 18, j + 20, k + 15, Blocks.log, 0);
		setBlock(world, i + 18, j + 20, k + 16, Blocks.log, 0);
		setBlock(world, i + 18, j + 20, k + 17, Blocks.log, 0);
		setBlock(world, i + 18, j + 21, k + 15, Blocks.log, 0);
		setBlock(world, i + 18, j + 21, k + 16, Blocks.log, 0);
		setBlock(world, i + 18, j + 21, k + 17, Blocks.log, 0);
		setBlock(world, i + 18, j + 22, k + 15, Blocks.log, 0);
		setBlock(world, i + 18, j + 22, k + 16, Blocks.log, 0);
		setBlock(world, i + 18, j + 22, k + 17, Blocks.log, 0);
		setBlock(world, i + 18, j + 23, k + 16, Blocks.log, 0);
		setBlock(world, i + 18, j + 24, k + 16, Blocks.log, 0);
		setBlock(world, i + 18, j + 25, k + 16, Blocks.log, 0);
		setBlock(world, i + 18, j + 26, k + 16, Blocks.log, 0);
		setBlock(world, i + 18, j + 27, k + 16, Blocks.log, 0);
		setBlock(world, i + 18, j + 39, k + 27, Blocks.log, 0);
		setBlock(world, i + 18, j + 40, k + 11, Blocks.log, 0);
		setBlock(world, i + 18, j + 40, k + 22, Blocks.log, 0);
		setBlock(world, i + 18, j + 40, k + 27, Blocks.log, 0);
		setBlock(world, i + 18, j + 42, k + 20, Blocks.log, 0);
		setBlock(world, i + 18, j + 43, k + 21, Blocks.log, 0);
		setBlock(world, i + 18, j + 44, k + 14, Blocks.log, 0);
		setBlock(world, i + 18, j + 44, k + 22, Blocks.log, 0);
		setBlock(world, i + 18, j + 45, k + 9, Blocks.log, 0);
		setBlock(world, i + 18, j + 45, k + 14, Blocks.log, 0);
		setBlock(world, i + 18, j + 45, k + 16, Blocks.log, 0);
		setBlock(world, i + 18, j + 45, k + 22, Blocks.log, 0);
		setBlock(world, i + 18, j + 46, k + 9, Blocks.log, 0);
		setBlock(world, i + 18, j + 46, k + 17, Blocks.log, 0);
		setBlock(world, i + 18, j + 47, k + 15, Blocks.log, 0);
		setBlock(world, i + 18, j + 47, k + 16, Blocks.log, 0);
		setBlock(world, i + 18, j + 48, k + 17, Blocks.log, 0);
		setBlock(world, i + 18, j + 48, k + 18, Blocks.log, 0);
		setBlock(world, i + 19, j + 0, k + 14, Blocks.log, 0);
		setBlock(world, i + 19, j + 0, k + 15, Blocks.log, 0);
		setBlock(world, i + 19, j + 0, k + 16, Blocks.log, 0);
		setBlock(world, i + 19, j + 0, k + 17, Blocks.log, 0);
		setBlock(world, i + 19, j + 0, k + 18, Blocks.log, 0);
		setBlock(world, i + 19, j + 1, k + 14, Blocks.log, 0);
		setBlock(world, i + 19, j + 1, k + 15, Blocks.log, 0);
		setBlock(world, i + 19, j + 1, k + 16, Blocks.log, 0);
		setBlock(world, i + 19, j + 1, k + 17, Blocks.log, 0);
		setBlock(world, i + 19, j + 1, k + 18, Blocks.log, 0);
		setBlock(world, i + 19, j + 2, k + 14, Blocks.log, 0);
		setBlock(world, i + 19, j + 2, k + 15, Blocks.log, 0);
		setBlock(world, i + 19, j + 2, k + 16, Blocks.log, 0);
		setBlock(world, i + 19, j + 2, k + 17, Blocks.log, 0);
		setBlock(world, i + 19, j + 2, k + 18, Blocks.log, 0);
		setBlock(world, i + 19, j + 3, k + 14, Blocks.log, 0);
		setBlock(world, i + 19, j + 3, k + 15, Blocks.log, 0);
		setBlock(world, i + 19, j + 3, k + 16, Blocks.log, 0);
		setBlock(world, i + 19, j + 3, k + 17, Blocks.log, 0);
		setBlock(world, i + 19, j + 3, k + 18, Blocks.log, 0);
		setBlock(world, i + 19, j + 4, k + 14, Blocks.log, 0);
		setBlock(world, i + 19, j + 4, k + 15, Blocks.log, 0);
		setBlock(world, i + 19, j + 4, k + 16, Blocks.log, 0);
		setBlock(world, i + 19, j + 4, k + 17, Blocks.log, 0);
		setBlock(world, i + 19, j + 4, k + 18, Blocks.log, 0);
		setBlock(world, i + 19, j + 5, k + 14, Blocks.log, 0);
		setBlock(world, i + 19, j + 5, k + 15, Blocks.log, 0);
		setBlock(world, i + 19, j + 5, k + 16, Blocks.log, 0);
		setBlock(world, i + 19, j + 5, k + 17, Blocks.log, 0);
		setBlock(world, i + 19, j + 5, k + 18, Blocks.log, 0);
		setBlock(world, i + 19, j + 6, k + 14, Blocks.log, 0);
		setBlock(world, i + 19, j + 6, k + 15, Blocks.log, 0);
		setBlock(world, i + 19, j + 6, k + 16, Blocks.log, 0);
		setBlock(world, i + 19, j + 6, k + 17, Blocks.log, 0);
		setBlock(world, i + 19, j + 6, k + 18, Blocks.log, 0);
		setBlock(world, i + 19, j + 7, k + 14, Blocks.log, 0);
		setBlock(world, i + 19, j + 7, k + 15, Blocks.log, 0);
		setBlock(world, i + 19, j + 7, k + 16, Blocks.log, 0);
		setBlock(world, i + 19, j + 7, k + 17, Blocks.log, 0);
		setBlock(world, i + 19, j + 7, k + 18, Blocks.log, 0);
		setBlock(world, i + 19, j + 8, k + 14, Blocks.log, 0);
		setBlock(world, i + 19, j + 8, k + 15, Blocks.log, 0);
		setBlock(world, i + 19, j + 8, k + 16, Blocks.log, 0);
		setBlock(world, i + 19, j + 8, k + 17, Blocks.log, 0);
		setBlock(world, i + 19, j + 8, k + 18, Blocks.log, 0);
		setBlock(world, i + 19, j + 9, k + 14, Blocks.log, 0);
		setBlock(world, i + 19, j + 9, k + 15, Blocks.log, 0);
		setBlock(world, i + 19, j + 9, k + 16, Blocks.log, 0);
		setBlock(world, i + 19, j + 9, k + 17, Blocks.log, 0);
		setBlock(world, i + 19, j + 9, k + 18, Blocks.log, 0);
		setBlock(world, i + 19, j + 10, k + 14, Blocks.log, 0);
		setBlock(world, i + 19, j + 10, k + 15, Blocks.log, 0);
		setBlock(world, i + 19, j + 10, k + 16, Blocks.log, 0);
		setBlock(world, i + 19, j + 10, k + 17, Blocks.log, 0);
		setBlock(world, i + 19, j + 10, k + 18, Blocks.log, 0);
		setBlock(world, i + 19, j + 11, k + 14, Blocks.log, 0);
		setBlock(world, i + 19, j + 11, k + 15, Blocks.log, 0);
		setBlock(world, i + 19, j + 11, k + 16, Blocks.log, 0);
		setBlock(world, i + 19, j + 11, k + 17, Blocks.log, 0);
		setBlock(world, i + 19, j + 12, k + 14, Blocks.log, 0);
		setBlock(world, i + 19, j + 12, k + 15, Blocks.log, 0);
		setBlock(world, i + 19, j + 12, k + 16, Blocks.log, 0);
		setBlock(world, i + 19, j + 12, k + 17, Blocks.log, 0);
		setBlock(world, i + 19, j + 13, k + 14, Blocks.log, 0);
		setBlock(world, i + 19, j + 13, k + 15, Blocks.log, 0);
		setBlock(world, i + 19, j + 13, k + 16, Blocks.log, 0);
		setBlock(world, i + 19, j + 13, k + 17, Blocks.log, 0);
		setBlock(world, i + 19, j + 14, k + 14, Blocks.log, 0);
		setBlock(world, i + 19, j + 14, k + 15, Blocks.log, 0);
		setBlock(world, i + 19, j + 14, k + 16, Blocks.log, 0);
		setBlock(world, i + 19, j + 14, k + 17, Blocks.log, 0);
		setBlock(world, i + 19, j + 15, k + 14, Blocks.log, 0);
		setBlock(world, i + 19, j + 15, k + 15, Blocks.log, 0);
		setBlock(world, i + 19, j + 15, k + 16, Blocks.log, 0);
		setBlock(world, i + 19, j + 15, k + 17, Blocks.log, 0);
		setBlock(world, i + 19, j + 15, k + 18, Blocks.log, 0);
		setBlock(world, i + 19, j + 16, k + 14, Blocks.log, 0);
		setBlock(world, i + 19, j + 16, k + 15, Blocks.log, 0);
		setBlock(world, i + 19, j + 16, k + 16, Blocks.log, 0);
		setBlock(world, i + 19, j + 16, k + 17, Blocks.log, 0);
		setBlock(world, i + 19, j + 16, k + 18, Blocks.log, 0);
		setBlock(world, i + 19, j + 17, k + 14, Blocks.log, 0);
		setBlock(world, i + 19, j + 17, k + 15, Blocks.log, 0);
		setBlock(world, i + 19, j + 17, k + 16, Blocks.log, 0);
		setBlock(world, i + 19, j + 17, k + 17, Blocks.log, 0);
		setBlock(world, i + 19, j + 17, k + 18, Blocks.log, 0);
		setBlock(world, i + 19, j + 18, k + 14, Blocks.log, 0);
		setBlock(world, i + 19, j + 18, k + 15, Blocks.log, 0);
		setBlock(world, i + 19, j + 18, k + 16, Blocks.log, 0);
		setBlock(world, i + 19, j + 18, k + 17, Blocks.log, 0);
		setBlock(world, i + 19, j + 18, k + 18, Blocks.log, 0);
		setBlock(world, i + 19, j + 19, k + 14, Blocks.log, 0);
		setBlock(world, i + 19, j + 19, k + 15, Blocks.log, 0);
		setBlock(world, i + 19, j + 19, k + 16, Blocks.log, 0);
		setBlock(world, i + 19, j + 19, k + 17, Blocks.log, 0);
		setBlock(world, i + 19, j + 19, k + 18, Blocks.log, 0);
		setBlock(world, i + 19, j + 20, k + 14, Blocks.log, 0);
		setBlock(world, i + 19, j + 20, k + 15, Blocks.log, 0);
		setBlock(world, i + 19, j + 20, k + 16, Blocks.log, 0);
		setBlock(world, i + 19, j + 20, k + 17, Blocks.log, 0);
		setBlock(world, i + 19, j + 20, k + 18, Blocks.log, 0);
		setBlock(world, i + 19, j + 21, k + 14, Blocks.log, 0);
		setBlock(world, i + 19, j + 21, k + 15, Blocks.log, 0);
		setBlock(world, i + 19, j + 21, k + 16, Blocks.log, 0);
		setBlock(world, i + 19, j + 21, k + 17, Blocks.log, 0);
		setBlock(world, i + 19, j + 21, k + 18, Blocks.log, 0);
		setBlock(world, i + 19, j + 22, k + 14, Blocks.log, 0);
		setBlock(world, i + 19, j + 22, k + 15, Blocks.log, 0);
		setBlock(world, i + 19, j + 22, k + 16, Blocks.log, 0);
		setBlock(world, i + 19, j + 22, k + 17, Blocks.log, 0);
		setBlock(world, i + 19, j + 22, k + 18, Blocks.log, 0);
		setBlock(world, i + 19, j + 23, k + 15, Blocks.log, 0);
		setBlock(world, i + 19, j + 23, k + 16, Blocks.log, 0);
		setBlock(world, i + 19, j + 23, k + 17, Blocks.log, 0);
		setBlock(world, i + 19, j + 24, k + 15, Blocks.log, 0);
		setBlock(world, i + 19, j + 24, k + 16, Blocks.log, 0);
		setBlock(world, i + 19, j + 24, k + 17, Blocks.log, 0);
		setBlock(world, i + 19, j + 25, k + 15, Blocks.log, 0);
		setBlock(world, i + 19, j + 25, k + 16, Blocks.log, 0);
		setBlock(world, i + 19, j + 25, k + 17, Blocks.log, 0);
		setBlock(world, i + 19, j + 26, k + 15, Blocks.log, 0);
		setBlock(world, i + 19, j + 26, k + 16, Blocks.log, 0);
		setBlock(world, i + 19, j + 26, k + 17, Blocks.log, 0);
		setBlock(world, i + 19, j + 27, k + 15, Blocks.log, 0);
		setBlock(world, i + 19, j + 27, k + 16, Blocks.log, 0);
		setBlock(world, i + 19, j + 27, k + 17, Blocks.log, 0);
		setBlock(world, i + 19, j + 28, k + 15, Blocks.log, 0);
		setBlock(world, i + 19, j + 28, k + 16, Blocks.log, 0);
		setBlock(world, i + 19, j + 28, k + 17, Blocks.log, 0);
		setBlock(world, i + 19, j + 29, k + 15, Blocks.log, 0);
		setBlock(world, i + 19, j + 29, k + 16, Blocks.log, 0);
		setBlock(world, i + 19, j + 29, k + 17, Blocks.log, 0);
		setBlock(world, i + 19, j + 30, k + 15, Blocks.log, 0);
		setBlock(world, i + 19, j + 30, k + 16, Blocks.log, 0);
		setBlock(world, i + 19, j + 30, k + 17, Blocks.log, 0);
		setBlock(world, i + 19, j + 31, k + 15, Blocks.log, 0);
		setBlock(world, i + 19, j + 31, k + 16, Blocks.log, 0);
		setBlock(world, i + 19, j + 31, k + 17, Blocks.log, 0);
		setBlock(world, i + 19, j + 32, k + 15, Blocks.log, 0);
		setBlock(world, i + 19, j + 32, k + 16, Blocks.log, 0);
		setBlock(world, i + 19, j + 32, k + 17, Blocks.log, 0);
		setBlock(world, i + 19, j + 33, k + 15, Blocks.log, 0);
		setBlock(world, i + 19, j + 33, k + 16, Blocks.log, 0);
		setBlock(world, i + 19, j + 33, k + 17, Blocks.log, 0);
		setBlock(world, i + 19, j + 34, k + 15, Blocks.log, 0);
		setBlock(world, i + 19, j + 34, k + 16, Blocks.log, 0);
		setBlock(world, i + 19, j + 35, k + 15, Blocks.log, 0);
		setBlock(world, i + 19, j + 35, k + 16, Blocks.log, 0);
		setBlock(world, i + 19, j + 36, k + 15, Blocks.log, 0);
		setBlock(world, i + 19, j + 36, k + 16, Blocks.log, 0);
		setBlock(world, i + 19, j + 37, k + 15, Blocks.log, 0);
		setBlock(world, i + 19, j + 37, k + 16, Blocks.log, 0);
		setBlock(world, i + 19, j + 38, k + 15, Blocks.log, 0);
		setBlock(world, i + 19, j + 38, k + 16, Blocks.log, 0);
		setBlock(world, i + 19, j + 39, k + 5, Blocks.log, 0);
		setBlock(world, i + 19, j + 41, k + 8, Blocks.log, 0);
		setBlock(world, i + 19, j + 41, k + 24, Blocks.log, 0);
		setBlock(world, i + 19, j + 42, k + 6, Blocks.log, 0);
		setBlock(world, i + 19, j + 42, k + 11, Blocks.log, 0);
		setBlock(world, i + 19, j + 42, k + 22, Blocks.log, 0);
		setBlock(world, i + 19, j + 43, k + 9, Blocks.log, 0);
		setBlock(world, i + 19, j + 43, k + 12, Blocks.log, 0);
		setBlock(world, i + 19, j + 43, k + 23, Blocks.log, 0);
		setBlock(world, i + 19, j + 44, k + 16, Blocks.log, 0);
		setBlock(world, i + 19, j + 45, k + 6, Blocks.log, 0);
		setBlock(world, i + 19, j + 45, k + 13, Blocks.log, 0);
		setBlock(world, i + 19, j + 46, k + 6, Blocks.log, 0);
		setBlock(world, i + 19, j + 46, k + 12, Blocks.log, 0);
		setBlock(world, i + 19, j + 46, k + 15, Blocks.log, 0);
		setBlock(world, i + 19, j + 47, k + 14, Blocks.log, 0);
		setBlock(world, i + 19, j + 48, k + 9, Blocks.log, 0);
		setBlock(world, i + 19, j + 48, k + 13, Blocks.log, 0);
		setBlock(world, i + 20, j + 0, k + 14, Blocks.log, 0);
		setBlock(world, i + 20, j + 0, k + 15, Blocks.log, 0);
		setBlock(world, i + 20, j + 0, k + 16, Blocks.log, 0);
		setBlock(world, i + 20, j + 0, k + 17, Blocks.log, 0);
		setBlock(world, i + 20, j + 0, k + 18, Blocks.log, 0);
		setBlock(world, i + 20, j + 1, k + 14, Blocks.log, 0);
		setBlock(world, i + 20, j + 1, k + 15, Blocks.log, 0);
		setBlock(world, i + 20, j + 1, k + 16, Blocks.log, 0);
		setBlock(world, i + 20, j + 1, k + 17, Blocks.log, 0);
		setBlock(world, i + 20, j + 1, k + 18, Blocks.log, 0);
		setBlock(world, i + 20, j + 2, k + 14, Blocks.log, 0);
		setBlock(world, i + 20, j + 2, k + 15, Blocks.log, 0);
		setBlock(world, i + 20, j + 2, k + 16, Blocks.log, 0);
		setBlock(world, i + 20, j + 2, k + 17, Blocks.log, 0);
		setBlock(world, i + 20, j + 2, k + 18, Blocks.log, 0);
		setBlock(world, i + 20, j + 3, k + 14, Blocks.log, 0);
		setBlock(world, i + 20, j + 3, k + 15, Blocks.log, 0);
		setBlock(world, i + 20, j + 3, k + 16, Blocks.log, 0);
		setBlock(world, i + 20, j + 3, k + 17, Blocks.log, 0);
		setBlock(world, i + 20, j + 3, k + 18, Blocks.log, 0);
		setBlock(world, i + 20, j + 4, k + 14, Blocks.log, 0);
		setBlock(world, i + 20, j + 4, k + 15, Blocks.log, 0);
		setBlock(world, i + 20, j + 4, k + 16, Blocks.log, 0);
		setBlock(world, i + 20, j + 4, k + 17, Blocks.log, 0);
		setBlock(world, i + 20, j + 4, k + 18, Blocks.log, 0);
		setBlock(world, i + 20, j + 5, k + 14, Blocks.log, 0);
		setBlock(world, i + 20, j + 5, k + 15, Blocks.log, 0);
		setBlock(world, i + 20, j + 5, k + 16, Blocks.log, 0);
		setBlock(world, i + 20, j + 5, k + 17, Blocks.log, 0);
		setBlock(world, i + 20, j + 5, k + 18, Blocks.log, 0);
		setBlock(world, i + 20, j + 6, k + 14, Blocks.log, 0);
		setBlock(world, i + 20, j + 6, k + 15, Blocks.log, 0);
		setBlock(world, i + 20, j + 6, k + 16, Blocks.log, 0);
		setBlock(world, i + 20, j + 6, k + 17, Blocks.log, 0);
		setBlock(world, i + 20, j + 6, k + 18, Blocks.log, 0);
		setBlock(world, i + 20, j + 7, k + 14, Blocks.log, 0);
		setBlock(world, i + 20, j + 7, k + 15, Blocks.log, 0);
		setBlock(world, i + 20, j + 7, k + 16, Blocks.log, 0);
		setBlock(world, i + 20, j + 7, k + 17, Blocks.log, 0);
		setBlock(world, i + 20, j + 7, k + 18, Blocks.log, 0);
		setBlock(world, i + 20, j + 8, k + 14, Blocks.log, 0);
		setBlock(world, i + 20, j + 8, k + 15, Blocks.log, 0);
		setBlock(world, i + 20, j + 8, k + 16, Blocks.log, 0);
		setBlock(world, i + 20, j + 8, k + 17, Blocks.log, 0);
		setBlock(world, i + 20, j + 8, k + 18, Blocks.log, 0);
		setBlock(world, i + 20, j + 9, k + 14, Blocks.log, 0);
		setBlock(world, i + 20, j + 9, k + 15, Blocks.log, 0);
		setBlock(world, i + 20, j + 9, k + 16, Blocks.log, 0);
		setBlock(world, i + 20, j + 9, k + 17, Blocks.log, 0);
		setBlock(world, i + 20, j + 9, k + 18, Blocks.log, 0);
		setBlock(world, i + 20, j + 10, k + 14, Blocks.log, 0);
		setBlock(world, i + 20, j + 10, k + 15, Blocks.log, 0);
		setBlock(world, i + 20, j + 10, k + 16, Blocks.log, 0);
		setBlock(world, i + 20, j + 10, k + 17, Blocks.log, 0);
		setBlock(world, i + 20, j + 10, k + 18, Blocks.log, 0);
		setBlock(world, i + 20, j + 11, k + 14, Blocks.log, 0);
		setBlock(world, i + 20, j + 11, k + 15, Blocks.log, 0);
		setBlock(world, i + 20, j + 11, k + 16, Blocks.log, 0);
		setBlock(world, i + 20, j + 11, k + 17, Blocks.log, 0);
		setBlock(world, i + 20, j + 11, k + 18, Blocks.log, 0);
		setBlock(world, i + 20, j + 12, k + 14, Blocks.log, 0);
		setBlock(world, i + 20, j + 12, k + 15, Blocks.log, 0);
		setBlock(world, i + 20, j + 12, k + 16, Blocks.log, 0);
		setBlock(world, i + 20, j + 12, k + 17, Blocks.log, 0);
		setBlock(world, i + 20, j + 13, k + 14, Blocks.log, 0);
		setBlock(world, i + 20, j + 13, k + 15, Blocks.log, 0);
		setBlock(world, i + 20, j + 13, k + 16, Blocks.log, 0);
		setBlock(world, i + 20, j + 13, k + 17, Blocks.log, 0);
		setBlock(world, i + 20, j + 14, k + 14, Blocks.log, 0);
		setBlock(world, i + 20, j + 14, k + 15, Blocks.log, 0);
		setBlock(world, i + 20, j + 14, k + 16, Blocks.log, 0);
		setBlock(world, i + 20, j + 14, k + 17, Blocks.log, 0);
		setBlock(world, i + 20, j + 14, k + 18, Blocks.log, 0);
		setBlock(world, i + 20, j + 15, k + 14, Blocks.log, 0);
		setBlock(world, i + 20, j + 15, k + 15, Blocks.log, 0);
		setBlock(world, i + 20, j + 15, k + 16, Blocks.log, 0);
		setBlock(world, i + 20, j + 15, k + 17, Blocks.log, 0);
		setBlock(world, i + 20, j + 15, k + 18, Blocks.log, 0);
		setBlock(world, i + 20, j + 16, k + 14, Blocks.log, 0);
		setBlock(world, i + 20, j + 16, k + 15, Blocks.log, 0);
		setBlock(world, i + 20, j + 16, k + 16, Blocks.log, 0);
		setBlock(world, i + 20, j + 16, k + 17, Blocks.log, 0);
		setBlock(world, i + 20, j + 16, k + 18, Blocks.log, 0);
		setBlock(world, i + 20, j + 17, k + 14, Blocks.log, 0);
		setBlock(world, i + 20, j + 17, k + 15, Blocks.log, 0);
		setBlock(world, i + 20, j + 17, k + 16, Blocks.log, 0);
		setBlock(world, i + 20, j + 17, k + 17, Blocks.log, 0);
		setBlock(world, i + 20, j + 17, k + 18, Blocks.log, 0);
		setBlock(world, i + 20, j + 18, k + 14, Blocks.log, 0);
		setBlock(world, i + 20, j + 18, k + 15, Blocks.log, 0);
		setBlock(world, i + 20, j + 18, k + 16, Blocks.log, 0);
		setBlock(world, i + 20, j + 18, k + 17, Blocks.log, 0);
		setBlock(world, i + 20, j + 18, k + 18, Blocks.log, 0);
		setBlock(world, i + 20, j + 19, k + 14, Blocks.log, 0);
		setBlock(world, i + 20, j + 19, k + 15, Blocks.log, 0);
		setBlock(world, i + 20, j + 19, k + 16, Blocks.log, 0);
		setBlock(world, i + 20, j + 19, k + 17, Blocks.log, 0);
		setBlock(world, i + 20, j + 19, k + 18, Blocks.log, 0);
		setBlock(world, i + 20, j + 20, k + 14, Blocks.log, 0);
		setBlock(world, i + 20, j + 20, k + 15, Blocks.log, 0);
		setBlock(world, i + 20, j + 20, k + 16, Blocks.log, 0);
		setBlock(world, i + 20, j + 20, k + 17, Blocks.log, 0);
		setBlock(world, i + 20, j + 20, k + 18, Blocks.log, 0);
		setBlock(world, i + 20, j + 21, k + 14, Blocks.log, 0);
		setBlock(world, i + 20, j + 21, k + 15, Blocks.log, 0);
		setBlock(world, i + 20, j + 21, k + 16, Blocks.log, 0);
		setBlock(world, i + 20, j + 21, k + 17, Blocks.log, 0);
		setBlock(world, i + 20, j + 21, k + 18, Blocks.log, 0);
		setBlock(world, i + 20, j + 22, k + 14, Blocks.log, 0);
		setBlock(world, i + 20, j + 22, k + 15, Blocks.log, 0);
		setBlock(world, i + 20, j + 22, k + 16, Blocks.log, 0);
		setBlock(world, i + 20, j + 22, k + 17, Blocks.log, 0);
		setBlock(world, i + 20, j + 22, k + 18, Blocks.log, 0);
		setBlock(world, i + 20, j + 23, k + 14, Blocks.log, 0);
		setBlock(world, i + 20, j + 23, k + 15, Blocks.log, 0);
		setBlock(world, i + 20, j + 23, k + 16, Blocks.log, 0);
		setBlock(world, i + 20, j + 23, k + 17, Blocks.log, 0);
		setBlock(world, i + 20, j + 23, k + 18, Blocks.log, 0);
		setBlock(world, i + 20, j + 24, k + 14, Blocks.log, 0);
		setBlock(world, i + 20, j + 24, k + 15, Blocks.log, 0);
		setBlock(world, i + 20, j + 24, k + 16, Blocks.log, 0);
		setBlock(world, i + 20, j + 24, k + 17, Blocks.log, 0);
		setBlock(world, i + 20, j + 24, k + 18, Blocks.log, 0);
		setBlock(world, i + 20, j + 25, k + 14, Blocks.log, 0);
		setBlock(world, i + 20, j + 25, k + 15, Blocks.log, 0);
		setBlock(world, i + 20, j + 25, k + 16, Blocks.log, 0);
		setBlock(world, i + 20, j + 25, k + 17, Blocks.log, 0);
		setBlock(world, i + 20, j + 25, k + 18, Blocks.log, 0);
		setBlock(world, i + 20, j + 26, k + 14, Blocks.log, 0);
		setBlock(world, i + 20, j + 26, k + 15, Blocks.log, 0);
		setBlock(world, i + 20, j + 26, k + 16, Blocks.log, 0);
		setBlock(world, i + 20, j + 26, k + 17, Blocks.log, 0);
		setBlock(world, i + 20, j + 26, k + 18, Blocks.log, 0);
		setBlock(world, i + 20, j + 27, k + 14, Blocks.log, 0);
		setBlock(world, i + 20, j + 27, k + 15, Blocks.log, 0);
		setBlock(world, i + 20, j + 27, k + 16, Blocks.log, 0);
		setBlock(world, i + 20, j + 27, k + 17, Blocks.log, 0);
		setBlock(world, i + 20, j + 28, k + 14, Blocks.log, 0);
		setBlock(world, i + 20, j + 28, k + 15, Blocks.log, 0);
		setBlock(world, i + 20, j + 28, k + 16, Blocks.log, 0);
		setBlock(world, i + 20, j + 28, k + 17, Blocks.log, 0);
		setBlock(world, i + 20, j + 29, k + 14, Blocks.log, 0);
		setBlock(world, i + 20, j + 29, k + 15, Blocks.log, 0);
		setBlock(world, i + 20, j + 29, k + 16, Blocks.log, 0);
		setBlock(world, i + 20, j + 29, k + 17, Blocks.log, 0);
		setBlock(world, i + 20, j + 30, k + 14, Blocks.log, 0);
		setBlock(world, i + 20, j + 30, k + 15, Blocks.log, 0);
		setBlock(world, i + 20, j + 30, k + 16, Blocks.log, 0);
		setBlock(world, i + 20, j + 30, k + 17, Blocks.log, 0);
		setBlock(world, i + 20, j + 31, k + 14, Blocks.log, 0);
		setBlock(world, i + 20, j + 31, k + 15, Blocks.log, 0);
		setBlock(world, i + 20, j + 31, k + 16, Blocks.log, 0);
		setBlock(world, i + 20, j + 31, k + 17, Blocks.log, 0);
		setBlock(world, i + 20, j + 32, k + 14, Blocks.log, 0);
		setBlock(world, i + 20, j + 32, k + 15, Blocks.log, 0);
		setBlock(world, i + 20, j + 32, k + 16, Blocks.log, 0);
		setBlock(world, i + 20, j + 32, k + 17, Blocks.log, 0);
		setBlock(world, i + 20, j + 33, k + 14, Blocks.log, 0);
		setBlock(world, i + 20, j + 33, k + 15, Blocks.log, 0);
		setBlock(world, i + 20, j + 33, k + 16, Blocks.log, 0);
		setBlock(world, i + 20, j + 33, k + 17, Blocks.log, 0);
		setBlock(world, i + 20, j + 34, k + 14, Blocks.log, 0);
		setBlock(world, i + 20, j + 34, k + 15, Blocks.log, 0);
		setBlock(world, i + 20, j + 34, k + 16, Blocks.log, 0);
		setBlock(world, i + 20, j + 34, k + 17, Blocks.log, 0);
		setBlock(world, i + 20, j + 35, k + 14, Blocks.log, 0);
		setBlock(world, i + 20, j + 35, k + 15, Blocks.log, 0);
		setBlock(world, i + 20, j + 35, k + 16, Blocks.log, 0);
		setBlock(world, i + 20, j + 35, k + 17, Blocks.log, 0);
		setBlock(world, i + 20, j + 36, k + 14, Blocks.log, 0);
		setBlock(world, i + 20, j + 36, k + 15, Blocks.log, 0);
		setBlock(world, i + 20, j + 36, k + 16, Blocks.log, 0);
		setBlock(world, i + 20, j + 36, k + 17, Blocks.log, 0);
		setBlock(world, i + 20, j + 37, k + 14, Blocks.log, 0);
		setBlock(world, i + 20, j + 37, k + 15, Blocks.log, 0);
		setBlock(world, i + 20, j + 37, k + 16, Blocks.log, 0);
		setBlock(world, i + 20, j + 38, k + 14, Blocks.log, 0);
		setBlock(world, i + 20, j + 38, k + 15, Blocks.log, 0);
		setBlock(world, i + 20, j + 38, k + 16, Blocks.log, 0);
		setBlock(world, i + 20, j + 39, k + 14, Blocks.log, 0);
		setBlock(world, i + 20, j + 39, k + 15, Blocks.log, 0);
		setBlock(world, i + 20, j + 39, k + 16, Blocks.log, 0);
		setBlock(world, i + 20, j + 39, k + 21, Blocks.log, 0);
		setBlock(world, i + 20, j + 40, k + 15, Blocks.log, 0);
		setBlock(world, i + 20, j + 40, k + 16, Blocks.log, 0);
		setBlock(world, i + 20, j + 40, k + 29, Blocks.log, 0);
		setBlock(world, i + 20, j + 41, k + 6, Blocks.log, 0);
		setBlock(world, i + 20, j + 41, k + 10, Blocks.log, 0);
		setBlock(world, i + 20, j + 41, k + 16, Blocks.log, 0);
		setBlock(world, i + 20, j + 41, k + 22, Blocks.log, 0);
		setBlock(world, i + 20, j + 42, k + 16, Blocks.log, 0);
		setBlock(world, i + 20, j + 42, k + 23, Blocks.log, 0);
		setBlock(world, i + 20, j + 43, k + 16, Blocks.log, 0);
		setBlock(world, i + 20, j + 43, k + 18, Blocks.log, 0);
		setBlock(world, i + 20, j + 44, k + 9, Blocks.log, 0);
		setBlock(world, i + 20, j + 44, k + 11, Blocks.log, 0);
		setBlock(world, i + 20, j + 45, k + 10, Blocks.log, 0);
		setBlock(world, i + 20, j + 46, k + 11, Blocks.log, 0);
		setBlock(world, i + 20, j + 47, k + 18, Blocks.log, 0);
		setBlock(world, i + 20, j + 47, k + 20, Blocks.log, 0);
		setBlock(world, i + 20, j + 47, k + 21, Blocks.log, 0);
		setBlock(world, i + 20, j + 48, k + 12, Blocks.log, 0);
		setBlock(world, i + 20, j + 48, k + 13, Blocks.log, 0);
		setBlock(world, i + 20, j + 48, k + 17, Blocks.log, 0);
		setBlock(world, i + 21, j + 0, k + 14, Blocks.log, 0);
		setBlock(world, i + 21, j + 0, k + 15, Blocks.log, 0);
		setBlock(world, i + 21, j + 0, k + 16, Blocks.log, 0);
		setBlock(world, i + 21, j + 0, k + 17, Blocks.log, 0);
		setBlock(world, i + 21, j + 0, k + 18, Blocks.log, 0);
		setBlock(world, i + 21, j + 1, k + 14, Blocks.log, 0);
		setBlock(world, i + 21, j + 1, k + 15, Blocks.log, 0);
		setBlock(world, i + 21, j + 1, k + 16, Blocks.log, 0);
		setBlock(world, i + 21, j + 1, k + 17, Blocks.log, 0);
		setBlock(world, i + 21, j + 1, k + 18, Blocks.log, 0);
		setBlock(world, i + 21, j + 2, k + 14, Blocks.log, 0);
		setBlock(world, i + 21, j + 2, k + 15, Blocks.log, 0);
		setBlock(world, i + 21, j + 2, k + 16, Blocks.log, 0);
		setBlock(world, i + 21, j + 2, k + 17, Blocks.log, 0);
		setBlock(world, i + 21, j + 2, k + 18, Blocks.log, 0);
		setBlock(world, i + 21, j + 3, k + 14, Blocks.log, 0);
		setBlock(world, i + 21, j + 3, k + 15, Blocks.log, 0);
		setBlock(world, i + 21, j + 3, k + 16, Blocks.log, 0);
		setBlock(world, i + 21, j + 3, k + 17, Blocks.log, 0);
		setBlock(world, i + 21, j + 3, k + 18, Blocks.log, 0);
		setBlock(world, i + 21, j + 4, k + 14, Blocks.log, 0);
		setBlock(world, i + 21, j + 4, k + 15, Blocks.log, 0);
		setBlock(world, i + 21, j + 4, k + 16, Blocks.log, 0);
		setBlock(world, i + 21, j + 4, k + 17, Blocks.log, 0);
		setBlock(world, i + 21, j + 4, k + 18, Blocks.log, 0);
		setBlock(world, i + 21, j + 5, k + 14, Blocks.log, 0);
		setBlock(world, i + 21, j + 5, k + 15, Blocks.log, 0);
		setBlock(world, i + 21, j + 5, k + 16, Blocks.log, 0);
		setBlock(world, i + 21, j + 5, k + 17, Blocks.log, 0);
		setBlock(world, i + 21, j + 5, k + 18, Blocks.log, 0);
		setBlock(world, i + 21, j + 6, k + 14, Blocks.log, 0);
		setBlock(world, i + 21, j + 6, k + 15, Blocks.log, 0);
		setBlock(world, i + 21, j + 6, k + 16, Blocks.log, 0);
		setBlock(world, i + 21, j + 6, k + 17, Blocks.log, 0);
		setBlock(world, i + 21, j + 6, k + 18, Blocks.log, 0);
		setBlock(world, i + 21, j + 7, k + 14, Blocks.log, 0);
		setBlock(world, i + 21, j + 7, k + 15, Blocks.log, 0);
		setBlock(world, i + 21, j + 7, k + 16, Blocks.log, 0);
		setBlock(world, i + 21, j + 7, k + 17, Blocks.log, 0);
		setBlock(world, i + 21, j + 7, k + 18, Blocks.log, 0);
		setBlock(world, i + 21, j + 8, k + 14, Blocks.log, 0);
		setBlock(world, i + 21, j + 8, k + 15, Blocks.log, 0);
		setBlock(world, i + 21, j + 8, k + 16, Blocks.log, 0);
		setBlock(world, i + 21, j + 8, k + 17, Blocks.log, 0);
		setBlock(world, i + 21, j + 8, k + 18, Blocks.log, 0);
		setBlock(world, i + 21, j + 9, k + 14, Blocks.log, 0);
		setBlock(world, i + 21, j + 9, k + 15, Blocks.log, 0);
		setBlock(world, i + 21, j + 9, k + 16, Blocks.log, 0);
		setBlock(world, i + 21, j + 9, k + 17, Blocks.log, 0);
		setBlock(world, i + 21, j + 9, k + 18, Blocks.log, 0);
		setBlock(world, i + 21, j + 10, k + 14, Blocks.log, 0);
		setBlock(world, i + 21, j + 10, k + 15, Blocks.log, 0);
		setBlock(world, i + 21, j + 10, k + 16, Blocks.log, 0);
		setBlock(world, i + 21, j + 10, k + 17, Blocks.log, 0);
		setBlock(world, i + 21, j + 10, k + 18, Blocks.log, 0);
		setBlock(world, i + 21, j + 11, k + 14, Blocks.log, 0);
		setBlock(world, i + 21, j + 11, k + 15, Blocks.log, 0);
		setBlock(world, i + 21, j + 11, k + 16, Blocks.log, 0);
		setBlock(world, i + 21, j + 11, k + 17, Blocks.log, 0);
		setBlock(world, i + 21, j + 11, k + 18, Blocks.log, 0);
		setBlock(world, i + 21, j + 12, k + 14, Blocks.log, 0);
		setBlock(world, i + 21, j + 12, k + 15, Blocks.log, 0);
		setBlock(world, i + 21, j + 12, k + 16, Blocks.log, 0);
		setBlock(world, i + 21, j + 12, k + 17, Blocks.log, 0);
		setBlock(world, i + 21, j + 12, k + 18, Blocks.log, 0);
		setBlock(world, i + 21, j + 13, k + 14, Blocks.log, 0);
		setBlock(world, i + 21, j + 13, k + 15, Blocks.log, 0);
		setBlock(world, i + 21, j + 13, k + 16, Blocks.log, 0);
		setBlock(world, i + 21, j + 13, k + 17, Blocks.log, 0);
		setBlock(world, i + 21, j + 13, k + 18, Blocks.log, 0);
		setBlock(world, i + 21, j + 14, k + 14, Blocks.log, 0);
		setBlock(world, i + 21, j + 14, k + 15, Blocks.log, 0);
		setBlock(world, i + 21, j + 14, k + 16, Blocks.log, 0);
		setBlock(world, i + 21, j + 14, k + 17, Blocks.log, 0);
		setBlock(world, i + 21, j + 14, k + 18, Blocks.log, 0);
		setBlock(world, i + 21, j + 15, k + 14, Blocks.log, 0);
		setBlock(world, i + 21, j + 15, k + 15, Blocks.log, 0);
		setBlock(world, i + 21, j + 15, k + 16, Blocks.log, 0);
		setBlock(world, i + 21, j + 15, k + 17, Blocks.log, 0);
		setBlock(world, i + 21, j + 15, k + 18, Blocks.log, 0);
		setBlock(world, i + 21, j + 16, k + 14, Blocks.log, 0);
		setBlock(world, i + 21, j + 16, k + 15, Blocks.log, 0);
		setBlock(world, i + 21, j + 16, k + 16, Blocks.log, 0);
		setBlock(world, i + 21, j + 16, k + 17, Blocks.log, 0);
		setBlock(world, i + 21, j + 16, k + 18, Blocks.log, 0);
		setBlock(world, i + 21, j + 17, k + 14, Blocks.log, 0);
		setBlock(world, i + 21, j + 17, k + 15, Blocks.log, 0);
		setBlock(world, i + 21, j + 17, k + 16, Blocks.log, 0);
		setBlock(world, i + 21, j + 17, k + 17, Blocks.log, 0);
		setBlock(world, i + 21, j + 17, k + 18, Blocks.log, 0);
		setBlock(world, i + 21, j + 18, k + 14, Blocks.log, 0);
		setBlock(world, i + 21, j + 18, k + 15, Blocks.log, 0);
		setBlock(world, i + 21, j + 18, k + 16, Blocks.log, 0);
		setBlock(world, i + 21, j + 18, k + 17, Blocks.log, 0);
		setBlock(world, i + 21, j + 18, k + 18, Blocks.log, 0);
		setBlock(world, i + 21, j + 19, k + 14, Blocks.log, 0);
		setBlock(world, i + 21, j + 19, k + 15, Blocks.log, 0);
		setBlock(world, i + 21, j + 19, k + 16, Blocks.log, 0);
		setBlock(world, i + 21, j + 19, k + 17, Blocks.log, 0);
		setBlock(world, i + 21, j + 19, k + 18, Blocks.log, 0);
		setBlock(world, i + 21, j + 20, k + 14, Blocks.log, 0);
		setBlock(world, i + 21, j + 20, k + 15, Blocks.log, 0);
		setBlock(world, i + 21, j + 20, k + 16, Blocks.log, 0);
		setBlock(world, i + 21, j + 20, k + 17, Blocks.log, 0);
		setBlock(world, i + 21, j + 20, k + 18, Blocks.log, 0);
		setBlock(world, i + 21, j + 21, k + 14, Blocks.log, 0);
		setBlock(world, i + 21, j + 21, k + 15, Blocks.log, 0);
		setBlock(world, i + 21, j + 21, k + 16, Blocks.log, 0);
		setBlock(world, i + 21, j + 21, k + 17, Blocks.log, 0);
		setBlock(world, i + 21, j + 21, k + 18, Blocks.log, 0);
		setBlock(world, i + 21, j + 22, k + 14, Blocks.log, 0);
		setBlock(world, i + 21, j + 22, k + 15, Blocks.log, 0);
		setBlock(world, i + 21, j + 22, k + 16, Blocks.log, 0);
		setBlock(world, i + 21, j + 22, k + 17, Blocks.log, 0);
		setBlock(world, i + 21, j + 22, k + 18, Blocks.log, 0);
		setBlock(world, i + 21, j + 23, k + 15, Blocks.log, 0);
		setBlock(world, i + 21, j + 23, k + 16, Blocks.log, 0);
		setBlock(world, i + 21, j + 23, k + 17, Blocks.log, 0);
		setBlock(world, i + 21, j + 23, k + 18, Blocks.log, 0);
		setBlock(world, i + 21, j + 24, k + 15, Blocks.log, 0);
		setBlock(world, i + 21, j + 24, k + 16, Blocks.log, 0);
		setBlock(world, i + 21, j + 24, k + 17, Blocks.log, 0);
		setBlock(world, i + 21, j + 24, k + 18, Blocks.log, 0);
		setBlock(world, i + 21, j + 25, k + 15, Blocks.log, 0);
		setBlock(world, i + 21, j + 25, k + 16, Blocks.log, 0);
		setBlock(world, i + 21, j + 25, k + 17, Blocks.log, 0);
		setBlock(world, i + 21, j + 25, k + 18, Blocks.log, 0);
		setBlock(world, i + 21, j + 26, k + 15, Blocks.log, 0);
		setBlock(world, i + 21, j + 26, k + 16, Blocks.log, 0);
		setBlock(world, i + 21, j + 26, k + 17, Blocks.log, 0);
		setBlock(world, i + 21, j + 26, k + 18, Blocks.log, 0);
		setBlock(world, i + 21, j + 27, k + 15, Blocks.log, 0);
		setBlock(world, i + 21, j + 27, k + 16, Blocks.log, 0);
		setBlock(world, i + 21, j + 27, k + 17, Blocks.log, 0);
		setBlock(world, i + 21, j + 27, k + 18, Blocks.log, 0);
		setBlock(world, i + 21, j + 28, k + 14, Blocks.log, 0);
		setBlock(world, i + 21, j + 28, k + 15, Blocks.log, 0);
		setBlock(world, i + 21, j + 28, k + 16, Blocks.log, 0);
		setBlock(world, i + 21, j + 28, k + 17, Blocks.log, 0);
		setBlock(world, i + 21, j + 28, k + 18, Blocks.log, 0);
		setBlock(world, i + 21, j + 29, k + 14, Blocks.log, 0);
		setBlock(world, i + 21, j + 29, k + 15, Blocks.log, 0);
		setBlock(world, i + 21, j + 29, k + 16, Blocks.log, 0);
		setBlock(world, i + 21, j + 29, k + 17, Blocks.log, 0);
		setBlock(world, i + 21, j + 29, k + 18, Blocks.log, 0);
		setBlock(world, i + 21, j + 30, k + 14, Blocks.log, 0);
		setBlock(world, i + 21, j + 30, k + 15, Blocks.log, 0);
		setBlock(world, i + 21, j + 30, k + 16, Blocks.log, 0);
		setBlock(world, i + 21, j + 30, k + 17, Blocks.log, 0);
		setBlock(world, i + 21, j + 30, k + 18, Blocks.log, 0);
		setBlock(world, i + 21, j + 31, k + 14, Blocks.log, 0);
		setBlock(world, i + 21, j + 31, k + 15, Blocks.log, 0);
		setBlock(world, i + 21, j + 31, k + 16, Blocks.log, 0);
		setBlock(world, i + 21, j + 31, k + 17, Blocks.log, 0);
		setBlock(world, i + 21, j + 32, k + 14, Blocks.log, 0);
		setBlock(world, i + 21, j + 32, k + 15, Blocks.log, 0);
		setBlock(world, i + 21, j + 32, k + 16, Blocks.log, 0);
		setBlock(world, i + 21, j + 32, k + 17, Blocks.log, 0);
		setBlock(world, i + 21, j + 33, k + 14, Blocks.log, 0);
		setBlock(world, i + 21, j + 33, k + 15, Blocks.log, 0);
		setBlock(world, i + 21, j + 33, k + 16, Blocks.log, 0);
		setBlock(world, i + 21, j + 33, k + 17, Blocks.log, 0);
		setBlock(world, i + 21, j + 34, k + 14, Blocks.log, 0);
		setBlock(world, i + 21, j + 34, k + 15, Blocks.log, 0);
		setBlock(world, i + 21, j + 34, k + 16, Blocks.log, 0);
		setBlock(world, i + 21, j + 34, k + 17, Blocks.log, 0);
		setBlock(world, i + 21, j + 35, k + 14, Blocks.log, 0);
		setBlock(world, i + 21, j + 35, k + 15, Blocks.log, 0);
		setBlock(world, i + 21, j + 35, k + 16, Blocks.log, 0);
		setBlock(world, i + 21, j + 35, k + 17, Blocks.log, 0);
		setBlock(world, i + 21, j + 36, k + 14, Blocks.log, 0);
		setBlock(world, i + 21, j + 36, k + 15, Blocks.log, 0);
		setBlock(world, i + 21, j + 36, k + 16, Blocks.log, 0);
		setBlock(world, i + 21, j + 36, k + 17, Blocks.log, 0);
		setBlock(world, i + 21, j + 37, k + 14, Blocks.log, 0);
		setBlock(world, i + 21, j + 37, k + 15, Blocks.log, 0);
		setBlock(world, i + 21, j + 37, k + 16, Blocks.log, 0);
		setBlock(world, i + 21, j + 37, k + 17, Blocks.log, 0);
		setBlock(world, i + 21, j + 38, k + 14, Blocks.log, 0);
		setBlock(world, i + 21, j + 38, k + 15, Blocks.log, 0);
		setBlock(world, i + 21, j + 38, k + 16, Blocks.log, 0);
		setBlock(world, i + 21, j + 38, k + 17, Blocks.log, 0);
		setBlock(world, i + 21, j + 39, k + 14, Blocks.log, 0);
		setBlock(world, i + 21, j + 39, k + 15, Blocks.log, 0);
		setBlock(world, i + 21, j + 39, k + 16, Blocks.log, 0);
		setBlock(world, i + 21, j + 39, k + 17, Blocks.log, 0);
		setBlock(world, i + 21, j + 40, k + 7, Blocks.log, 0);
		setBlock(world, i + 21, j + 40, k + 8, Blocks.log, 0);
		setBlock(world, i + 21, j + 40, k + 9, Blocks.log, 0);
		setBlock(world, i + 21, j + 40, k + 14, Blocks.log, 0);
		setBlock(world, i + 21, j + 40, k + 15, Blocks.log, 0);
		setBlock(world, i + 21, j + 40, k + 16, Blocks.log, 0);
		setBlock(world, i + 21, j + 40, k + 17, Blocks.log, 0);
		setBlock(world, i + 21, j + 41, k + 9, Blocks.log, 0);
		setBlock(world, i + 21, j + 41, k + 15, Blocks.log, 0);
		setBlock(world, i + 21, j + 41, k + 16, Blocks.log, 0);
		setBlock(world, i + 21, j + 42, k + 9, Blocks.log, 0);
		setBlock(world, i + 21, j + 42, k + 24, Blocks.log, 0);
		setBlock(world, i + 21, j + 42, k + 28, Blocks.log, 0);
		setBlock(world, i + 21, j + 44, k + 7, Blocks.log, 0);
		setBlock(world, i + 21, j + 44, k + 16, Blocks.log, 0);
		setBlock(world, i + 21, j + 44, k + 22, Blocks.log, 0);
		setBlock(world, i + 21, j + 45, k + 14, Blocks.log, 0);
		setBlock(world, i + 21, j + 46, k + 9, Blocks.log, 0);
		setBlock(world, i + 21, j + 46, k + 23, Blocks.log, 0);
		setBlock(world, i + 21, j + 47, k + 16, Blocks.log, 0);
		setBlock(world, i + 21, j + 47, k + 20, Blocks.log, 0);
		setBlock(world, i + 21, j + 48, k + 13, Blocks.log, 0);
		setBlock(world, i + 21, j + 48, k + 18, Blocks.log, 0);
		setBlock(world, i + 21, j + 48, k + 19, Blocks.log, 0);
		setBlock(world, i + 22, j + 0, k + 14, Blocks.log, 0);
		setBlock(world, i + 22, j + 0, k + 15, Blocks.log, 0);
		setBlock(world, i + 22, j + 0, k + 16, Blocks.log, 0);
		setBlock(world, i + 22, j + 0, k + 17, Blocks.log, 0);
		setBlock(world, i + 22, j + 1, k + 14, Blocks.log, 0);
		setBlock(world, i + 22, j + 1, k + 15, Blocks.log, 0);
		setBlock(world, i + 22, j + 1, k + 16, Blocks.log, 0);
		setBlock(world, i + 22, j + 1, k + 17, Blocks.log, 0);
		setBlock(world, i + 22, j + 2, k + 14, Blocks.log, 0);
		setBlock(world, i + 22, j + 2, k + 15, Blocks.log, 0);
		setBlock(world, i + 22, j + 2, k + 16, Blocks.log, 0);
		setBlock(world, i + 22, j + 2, k + 17, Blocks.log, 0);
		setBlock(world, i + 22, j + 3, k + 14, Blocks.log, 0);
		setBlock(world, i + 22, j + 3, k + 15, Blocks.log, 0);
		setBlock(world, i + 22, j + 3, k + 16, Blocks.log, 0);
		setBlock(world, i + 22, j + 3, k + 17, Blocks.log, 0);
		setBlock(world, i + 22, j + 4, k + 14, Blocks.log, 0);
		setBlock(world, i + 22, j + 4, k + 15, Blocks.log, 0);
		setBlock(world, i + 22, j + 4, k + 16, Blocks.log, 0);
		setBlock(world, i + 22, j + 4, k + 17, Blocks.log, 0);
		setBlock(world, i + 22, j + 5, k + 14, Blocks.log, 0);
		setBlock(world, i + 22, j + 5, k + 15, Blocks.log, 0);
		setBlock(world, i + 22, j + 5, k + 16, Blocks.log, 0);
		setBlock(world, i + 22, j + 5, k + 17, Blocks.log, 0);
		setBlock(world, i + 22, j + 6, k + 14, Blocks.log, 0);
		setBlock(world, i + 22, j + 6, k + 15, Blocks.log, 0);
		setBlock(world, i + 22, j + 6, k + 16, Blocks.log, 0);
		setBlock(world, i + 22, j + 6, k + 17, Blocks.log, 0);
		setBlock(world, i + 22, j + 7, k + 14, Blocks.log, 0);
		setBlock(world, i + 22, j + 7, k + 15, Blocks.log, 0);
		setBlock(world, i + 22, j + 7, k + 16, Blocks.log, 0);
		setBlock(world, i + 22, j + 7, k + 17, Blocks.log, 0);
		setBlock(world, i + 22, j + 8, k + 15, Blocks.log, 0);
		setBlock(world, i + 22, j + 8, k + 16, Blocks.log, 0);
		setBlock(world, i + 22, j + 8, k + 17, Blocks.log, 0);
		setBlock(world, i + 22, j + 8, k + 18, Blocks.log, 0);
		setBlock(world, i + 22, j + 9, k + 15, Blocks.log, 0);
		setBlock(world, i + 22, j + 9, k + 16, Blocks.log, 0);
		setBlock(world, i + 22, j + 9, k + 17, Blocks.log, 0);
		setBlock(world, i + 22, j + 9, k + 18, Blocks.log, 0);
		setBlock(world, i + 22, j + 10, k + 16, Blocks.log, 0);
		setBlock(world, i + 22, j + 10, k + 17, Blocks.log, 0);
		setBlock(world, i + 22, j + 10, k + 18, Blocks.log, 0);
		setBlock(world, i + 22, j + 11, k + 17, Blocks.log, 0);
		setBlock(world, i + 22, j + 11, k + 18, Blocks.log, 0);
		setBlock(world, i + 22, j + 12, k + 17, Blocks.log, 0);
		setBlock(world, i + 22, j + 12, k + 18, Blocks.log, 0);
		setBlock(world, i + 22, j + 13, k + 17, Blocks.log, 0);
		setBlock(world, i + 22, j + 13, k + 18, Blocks.log, 0);
		setBlock(world, i + 22, j + 14, k + 16, Blocks.log, 0);
		setBlock(world, i + 22, j + 14, k + 17, Blocks.log, 0);
		setBlock(world, i + 22, j + 14, k + 18, Blocks.log, 0);
		setBlock(world, i + 22, j + 15, k + 15, Blocks.log, 0);
		setBlock(world, i + 22, j + 15, k + 16, Blocks.log, 0);
		setBlock(world, i + 22, j + 15, k + 17, Blocks.log, 0);
		setBlock(world, i + 22, j + 15, k + 18, Blocks.log, 0);
		setBlock(world, i + 22, j + 16, k + 15, Blocks.log, 0);
		setBlock(world, i + 22, j + 16, k + 16, Blocks.log, 0);
		setBlock(world, i + 22, j + 16, k + 17, Blocks.log, 0);
		setBlock(world, i + 22, j + 16, k + 18, Blocks.log, 0);
		setBlock(world, i + 22, j + 17, k + 15, Blocks.log, 0);
		setBlock(world, i + 22, j + 17, k + 16, Blocks.log, 0);
		setBlock(world, i + 22, j + 17, k + 17, Blocks.log, 0);
		setBlock(world, i + 22, j + 17, k + 18, Blocks.log, 0);
		setBlock(world, i + 22, j + 18, k + 15, Blocks.log, 0);
		setBlock(world, i + 22, j + 18, k + 16, Blocks.log, 0);
		setBlock(world, i + 22, j + 18, k + 17, Blocks.log, 0);
		setBlock(world, i + 22, j + 18, k + 18, Blocks.log, 0);
		setBlock(world, i + 22, j + 19, k + 15, Blocks.log, 0);
		setBlock(world, i + 22, j + 19, k + 16, Blocks.log, 0);
		setBlock(world, i + 22, j + 19, k + 17, Blocks.log, 0);
		setBlock(world, i + 22, j + 19, k + 18, Blocks.log, 0);
		setBlock(world, i + 22, j + 20, k + 15, Blocks.log, 0);
		setBlock(world, i + 22, j + 20, k + 16, Blocks.log, 0);
		setBlock(world, i + 22, j + 20, k + 17, Blocks.log, 0);
		setBlock(world, i + 22, j + 20, k + 18, Blocks.log, 0);
		setBlock(world, i + 22, j + 21, k + 15, Blocks.log, 0);
		setBlock(world, i + 22, j + 21, k + 16, Blocks.log, 0);
		setBlock(world, i + 22, j + 21, k + 17, Blocks.log, 0);
		setBlock(world, i + 22, j + 21, k + 18, Blocks.log, 0);
		setBlock(world, i + 22, j + 22, k + 15, Blocks.log, 0);
		setBlock(world, i + 22, j + 22, k + 16, Blocks.log, 0);
		setBlock(world, i + 22, j + 22, k + 17, Blocks.log, 0);
		setBlock(world, i + 22, j + 22, k + 18, Blocks.log, 0);
		setBlock(world, i + 22, j + 23, k + 15, Blocks.log, 0);
		setBlock(world, i + 22, j + 23, k + 16, Blocks.log, 0);
		setBlock(world, i + 22, j + 23, k + 17, Blocks.log, 0);
		setBlock(world, i + 22, j + 23, k + 18, Blocks.log, 0);
		setBlock(world, i + 22, j + 24, k + 15, Blocks.log, 0);
		setBlock(world, i + 22, j + 24, k + 16, Blocks.log, 0);
		setBlock(world, i + 22, j + 24, k + 17, Blocks.log, 0);
		setBlock(world, i + 22, j + 24, k + 18, Blocks.log, 0);
		setBlock(world, i + 22, j + 25, k + 15, Blocks.log, 0);
		setBlock(world, i + 22, j + 25, k + 16, Blocks.log, 0);
		setBlock(world, i + 22, j + 25, k + 17, Blocks.log, 0);
		setBlock(world, i + 22, j + 25, k + 18, Blocks.log, 0);
		setBlock(world, i + 22, j + 26, k + 15, Blocks.log, 0);
		setBlock(world, i + 22, j + 26, k + 16, Blocks.log, 0);
		setBlock(world, i + 22, j + 26, k + 17, Blocks.log, 0);
		setBlock(world, i + 22, j + 26, k + 18, Blocks.log, 0);
		setBlock(world, i + 22, j + 27, k + 15, Blocks.log, 0);
		setBlock(world, i + 22, j + 27, k + 16, Blocks.log, 0);
		setBlock(world, i + 22, j + 27, k + 17, Blocks.log, 0);
		setBlock(world, i + 22, j + 27, k + 18, Blocks.log, 0);
		setBlock(world, i + 22, j + 28, k + 15, Blocks.log, 0);
		setBlock(world, i + 22, j + 28, k + 16, Blocks.log, 0);
		setBlock(world, i + 22, j + 28, k + 17, Blocks.log, 0);
		setBlock(world, i + 22, j + 28, k + 18, Blocks.log, 0);
		setBlock(world, i + 22, j + 29, k + 14, Blocks.log, 0);
		setBlock(world, i + 22, j + 29, k + 15, Blocks.log, 0);
		setBlock(world, i + 22, j + 29, k + 16, Blocks.log, 0);
		setBlock(world, i + 22, j + 29, k + 17, Blocks.log, 0);
		setBlock(world, i + 22, j + 29, k + 18, Blocks.log, 0);
		setBlock(world, i + 22, j + 30, k + 14, Blocks.log, 0);
		setBlock(world, i + 22, j + 30, k + 15, Blocks.log, 0);
		setBlock(world, i + 22, j + 30, k + 16, Blocks.log, 0);
		setBlock(world, i + 22, j + 30, k + 17, Blocks.log, 0);
		setBlock(world, i + 22, j + 30, k + 18, Blocks.log, 0);
		setBlock(world, i + 22, j + 31, k + 14, Blocks.log, 0);
		setBlock(world, i + 22, j + 31, k + 15, Blocks.log, 0);
		setBlock(world, i + 22, j + 31, k + 16, Blocks.log, 0);
		setBlock(world, i + 22, j + 31, k + 17, Blocks.log, 0);
		setBlock(world, i + 22, j + 31, k + 18, Blocks.log, 0);
		setBlock(world, i + 22, j + 32, k + 14, Blocks.log, 0);
		setBlock(world, i + 22, j + 32, k + 15, Blocks.log, 0);
		setBlock(world, i + 22, j + 32, k + 16, Blocks.log, 0);
		setBlock(world, i + 22, j + 32, k + 17, Blocks.log, 0);
		setBlock(world, i + 22, j + 32, k + 18, Blocks.log, 0);
		/* 1000 */setBlock(world, i + 22, j + 33, k + 14, Blocks.log, 0);
		/* 1001 */setBlock(world, i + 22, j + 33, k + 15, Blocks.log, 0);
		/* 1002 */setBlock(world, i + 22, j + 33, k + 16, Blocks.log, 0);
		/* 1003 */setBlock(world, i + 22, j + 33, k + 17, Blocks.log, 0);
		/* 1004 */setBlock(world, i + 22, j + 33, k + 18, Blocks.log, 0);
		/* 1005 */setBlock(world, i + 22, j + 34, k + 14, Blocks.log, 0);
		/* 1006 */setBlock(world, i + 22, j + 34, k + 15, Blocks.log, 0);
		/* 1007 */setBlock(world, i + 22, j + 34, k + 16, Blocks.log, 0);
		/* 1008 */setBlock(world, i + 22, j + 34, k + 17, Blocks.log, 0);
		/* 1009 */setBlock(world, i + 22, j + 34, k + 18, Blocks.log, 0);
		/* 1010 */setBlock(world, i + 22, j + 35, k + 14, Blocks.log, 0);
		/* 1011 */setBlock(world, i + 22, j + 35, k + 15, Blocks.log, 0);
		/* 1012 */setBlock(world, i + 22, j + 35, k + 16, Blocks.log, 0);
		/* 1013 */setBlock(world, i + 22, j + 35, k + 17, Blocks.log, 0);
		/* 1014 */setBlock(world, i + 22, j + 36, k + 14, Blocks.log, 0);
		/* 1015 */setBlock(world, i + 22, j + 36, k + 15, Blocks.log, 0);
		/* 1016 */setBlock(world, i + 22, j + 36, k + 16, Blocks.log, 0);
		/* 1017 */setBlock(world, i + 22, j + 36, k + 17, Blocks.log, 0);
		/* 1018 */setBlock(world, i + 22, j + 37, k + 14, Blocks.log, 0);
		/* 1019 */setBlock(world, i + 22, j + 37, k + 15, Blocks.log, 0);
		/* 1020 */setBlock(world, i + 22, j + 37, k + 16, Blocks.log, 0);
		/* 1021 */setBlock(world, i + 22, j + 37, k + 17, Blocks.log, 0);
		/* 1022 */setBlock(world, i + 22, j + 38, k + 14, Blocks.log, 0);
		/* 1023 */setBlock(world, i + 22, j + 38, k + 15, Blocks.log, 0);
		/* 1024 */setBlock(world, i + 22, j + 38, k + 16, Blocks.log, 0);
		/* 1025 */setBlock(world, i + 22, j + 38, k + 17, Blocks.log, 0);
		/* 1026 */setBlock(world, i + 22, j + 39, k + 4, Blocks.log, 0);
		/* 1027 */setBlock(world, i + 22, j + 39, k + 14, Blocks.log, 0);
		/* 1028 */setBlock(world, i + 22, j + 39, k + 15, Blocks.log, 0);
		/* 1029 */setBlock(world, i + 22, j + 39, k + 16, Blocks.log, 0);
		/* 1030 */setBlock(world, i + 22, j + 39, k + 17, Blocks.log, 0);
		/* 1031 */setBlock(world, i + 22, j + 40, k + 14, Blocks.log, 0);
		/* 1032 */setBlock(world, i + 22, j + 40, k + 15, Blocks.log, 0);
		/* 1033 */setBlock(world, i + 22, j + 40, k + 16, Blocks.log, 0);
		/* 1034 */setBlock(world, i + 22, j + 40, k + 17, Blocks.log, 0);
		/* 1035 */setBlock(world, i + 22, j + 41, k + 8, Blocks.log, 0);
		/* 1036 */setBlock(world, i + 22, j + 41, k + 15, Blocks.log, 0);
		/* 1037 */setBlock(world, i + 22, j + 41, k + 16, Blocks.log, 0);
		/* 1038 */setBlock(world, i + 22, j + 43, k + 10, Blocks.log, 0);
		/* 1039 */setBlock(world, i + 22, j + 44, k + 20, Blocks.log, 0);
		/* 1040 */setBlock(world, i + 22, j + 45, k + 16, Blocks.log, 0);
		/* 1041 */setBlock(world, i + 22, j + 45, k + 18, Blocks.log, 0);
		/* 1042 */setBlock(world, i + 22, j + 45, k + 19, Blocks.log, 0);
		/* 1043 */setBlock(world, i + 22, j + 46, k + 15, Blocks.log, 0);
		/* 1044 */setBlock(world, i + 22, j + 46, k + 19, Blocks.log, 0);
		/* 1045 */setBlock(world, i + 22, j + 46, k + 20, Blocks.log, 0);
		/* 1046 */setBlock(world, i + 22, j + 47, k + 18, Blocks.log, 0);
		/* 1047 */setBlock(world, i + 22, j + 47, k + 19, Blocks.log, 0);
		/* 1048 */setBlock(world, i + 22, j + 48, k + 11, Blocks.log, 0);
		/* 1049 */setBlock(world, i + 22, j + 48, k + 16, Blocks.log, 0);
		/* 1050 */setBlock(world, i + 23, j + 21, k + 16, Blocks.log, 0);
		/* 1051 */setBlock(world, i + 23, j + 21, k + 17, Blocks.log, 0);
		/* 1052 */setBlock(world, i + 23, j + 22, k + 15, Blocks.log, 0);
		/* 1053 */setBlock(world, i + 23, j + 22, k + 16, Blocks.log, 0);
		/* 1054 */setBlock(world, i + 23, j + 22, k + 17, Blocks.log, 0);
		/* 1055 */setBlock(world, i + 23, j + 22, k + 18, Blocks.log, 0);
		/* 1056 */setBlock(world, i + 23, j + 23, k + 15, Blocks.log, 0);
		/* 1057 */setBlock(world, i + 23, j + 23, k + 16, Blocks.log, 0);
		/* 1058 */setBlock(world, i + 23, j + 23, k + 17, Blocks.log, 0);
		/* 1059 */setBlock(world, i + 23, j + 23, k + 18, Blocks.log, 0);
		/* 1060 */setBlock(world, i + 23, j + 24, k + 15, Blocks.log, 0);
		/* 1061 */setBlock(world, i + 23, j + 24, k + 16, Blocks.log, 0);
		/* 1062 */setBlock(world, i + 23, j + 24, k + 17, Blocks.log, 0);
		/* 1063 */setBlock(world, i + 23, j + 24, k + 18, Blocks.log, 0);
		/* 1064 */setBlock(world, i + 23, j + 25, k + 15, Blocks.log, 0);
		/* 1065 */setBlock(world, i + 23, j + 25, k + 16, Blocks.log, 0);
		/* 1066 */setBlock(world, i + 23, j + 25, k + 17, Blocks.log, 0);
		/* 1067 */setBlock(world, i + 23, j + 25, k + 18, Blocks.log, 0);
		/* 1068 */setBlock(world, i + 23, j + 26, k + 15, Blocks.log, 0);
		/* 1069 */setBlock(world, i + 23, j + 26, k + 16, Blocks.log, 0);
		/* 1070 */setBlock(world, i + 23, j + 26, k + 17, Blocks.log, 0);
		/* 1071 */setBlock(world, i + 23, j + 26, k + 18, Blocks.log, 0);
		/* 1072 */setBlock(world, i + 23, j + 27, k + 15, Blocks.log, 0);
		/* 1073 */setBlock(world, i + 23, j + 27, k + 16, Blocks.log, 0);
		/* 1074 */setBlock(world, i + 23, j + 27, k + 17, Blocks.log, 0);
		/* 1075 */setBlock(world, i + 23, j + 27, k + 18, Blocks.log, 0);
		/* 1076 */setBlock(world, i + 23, j + 28, k + 15, Blocks.log, 0);
		/* 1077 */setBlock(world, i + 23, j + 28, k + 16, Blocks.log, 0);
		/* 1078 */setBlock(world, i + 23, j + 28, k + 17, Blocks.log, 0);
		/* 1079 */setBlock(world, i + 23, j + 28, k + 18, Blocks.log, 0);
		/* 1080 */setBlock(world, i + 23, j + 29, k + 15, Blocks.log, 0);
		/* 1081 */setBlock(world, i + 23, j + 29, k + 16, Blocks.log, 0);
		/* 1082 */setBlock(world, i + 23, j + 29, k + 17, Blocks.log, 0);
		/* 1083 */setBlock(world, i + 23, j + 29, k + 18, Blocks.log, 0);
		/* 1084 */setBlock(world, i + 23, j + 30, k + 14, Blocks.log, 0);
		/* 1085 */setBlock(world, i + 23, j + 30, k + 15, Blocks.log, 0);
		/* 1086 */setBlock(world, i + 23, j + 30, k + 16, Blocks.log, 0);
		/* 1087 */setBlock(world, i + 23, j + 30, k + 17, Blocks.log, 0);
		/* 1088 */setBlock(world, i + 23, j + 30, k + 18, Blocks.log, 0);
		/* 1089 */setBlock(world, i + 23, j + 31, k + 14, Blocks.log, 0);
		/* 1090 */setBlock(world, i + 23, j + 31, k + 15, Blocks.log, 0);
		/* 1091 */setBlock(world, i + 23, j + 31, k + 16, Blocks.log, 0);
		/* 1092 */setBlock(world, i + 23, j + 31, k + 17, Blocks.log, 0);
		/* 1093 */setBlock(world, i + 23, j + 31, k + 18, Blocks.log, 0);
		/* 1094 */setBlock(world, i + 23, j + 32, k + 14, Blocks.log, 0);
		/* 1095 */setBlock(world, i + 23, j + 32, k + 15, Blocks.log, 0);
		/* 1096 */setBlock(world, i + 23, j + 32, k + 16, Blocks.log, 0);
		/* 1097 */setBlock(world, i + 23, j + 32, k + 17, Blocks.log, 0);
		/* 1098 */setBlock(world, i + 23, j + 32, k + 18, Blocks.log, 0);
		/* 1099 */setBlock(world, i + 23, j + 33, k + 14, Blocks.log, 0);
		/* 1100 */setBlock(world, i + 23, j + 33, k + 15, Blocks.log, 0);
		/* 1101 */setBlock(world, i + 23, j + 33, k + 16, Blocks.log, 0);
		/* 1102 */setBlock(world, i + 23, j + 33, k + 17, Blocks.log, 0);
		/* 1103 */setBlock(world, i + 23, j + 33, k + 18, Blocks.log, 0);
		/* 1104 */setBlock(world, i + 23, j + 34, k + 14, Blocks.log, 0);
		/* 1105 */setBlock(world, i + 23, j + 34, k + 15, Blocks.log, 0);
		/* 1106 */setBlock(world, i + 23, j + 34, k + 16, Blocks.log, 0);
		/* 1107 */setBlock(world, i + 23, j + 34, k + 17, Blocks.log, 0);
		/* 1108 */setBlock(world, i + 23, j + 34, k + 18, Blocks.log, 0);
		/* 1109 */setBlock(world, i + 23, j + 35, k + 14, Blocks.log, 0);
		/* 1110 */setBlock(world, i + 23, j + 35, k + 15, Blocks.log, 0);
		/* 1111 */setBlock(world, i + 23, j + 35, k + 16, Blocks.log, 0);
		/* 1112 */setBlock(world, i + 23, j + 35, k + 17, Blocks.log, 0);
		/* 1113 */setBlock(world, i + 23, j + 36, k + 14, Blocks.log, 0);
		/* 1114 */setBlock(world, i + 23, j + 36, k + 15, Blocks.log, 0);
		/* 1115 */setBlock(world, i + 23, j + 36, k + 16, Blocks.log, 0);
		/* 1116 */setBlock(world, i + 23, j + 36, k + 17, Blocks.log, 0);
		/* 1117 */setBlock(world, i + 23, j + 37, k + 15, Blocks.log, 0);
		/* 1118 */setBlock(world, i + 23, j + 37, k + 16, Blocks.log, 0);
		/* 1119 */setBlock(world, i + 23, j + 38, k + 15, Blocks.log, 0);
		/* 1120 */setBlock(world, i + 23, j + 38, k + 16, Blocks.log, 0);
		/* 1121 */setBlock(world, i + 23, j + 39, k + 15, Blocks.log, 0);
		/* 1122 */setBlock(world, i + 23, j + 39, k + 16, Blocks.log, 0);
		/* 1123 */setBlock(world, i + 23, j + 39, k + 22, Blocks.log, 0);
		/* 1124 */setBlock(world, i + 23, j + 40, k + 15, Blocks.log, 0);
		/* 1125 */setBlock(world, i + 23, j + 40, k + 16, Blocks.log, 0);
		/* 1126 */setBlock(world, i + 23, j + 41, k + 11, Blocks.log, 0);
		/* 1127 */setBlock(world, i + 23, j + 41, k + 21, Blocks.log, 0);
		/* 1128 */setBlock(world, i + 23, j + 42, k + 22, Blocks.log, 0);
		/* 1129 */setBlock(world, i + 23, j + 45, k + 9, Blocks.log, 0);
		/* 1130 */setBlock(world, i + 23, j + 45, k + 15, Blocks.log, 0);
		/* 1131 */setBlock(world, i + 23, j + 46, k + 13, Blocks.log, 0);
		/* 1132 */setBlock(world, i + 23, j + 46, k + 16, Blocks.log, 0);
		/* 1133 */setBlock(world, i + 23, j + 47, k + 14, Blocks.log, 0);
		/* 1134 */setBlock(world, i + 23, j + 47, k + 17, Blocks.log, 0);
		/* 1135 */setBlock(world, i + 23, j + 48, k + 11, Blocks.log, 0);
		/* 1136 */setBlock(world, i + 24, j + 22, k + 16, Blocks.log, 0);
		/* 1137 */setBlock(world, i + 24, j + 22, k + 17, Blocks.log, 0);
		/* 1138 */setBlock(world, i + 24, j + 23, k + 16, Blocks.log, 0);
		/* 1139 */setBlock(world, i + 24, j + 23, k + 17, Blocks.log, 0);
		/* 1140 */setBlock(world, i + 24, j + 24, k + 16, Blocks.log, 0);
		/* 1141 */setBlock(world, i + 24, j + 24, k + 17, Blocks.log, 0);
		/* 1142 */setBlock(world, i + 24, j + 25, k + 16, Blocks.log, 0);
		/* 1143 */setBlock(world, i + 24, j + 25, k + 17, Blocks.log, 0);
		/* 1144 */setBlock(world, i + 24, j + 26, k + 16, Blocks.log, 0);
		/* 1145 */setBlock(world, i + 24, j + 26, k + 17, Blocks.log, 0);
		/* 1146 */setBlock(world, i + 24, j + 27, k + 16, Blocks.log, 0);
		/* 1147 */setBlock(world, i + 24, j + 27, k + 17, Blocks.log, 0);
		/* 1148 */setBlock(world, i + 24, j + 28, k + 16, Blocks.log, 0);
		/* 1149 */setBlock(world, i + 24, j + 28, k + 17, Blocks.log, 0);
		/* 1150 */setBlock(world, i + 24, j + 29, k + 16, Blocks.log, 0);
		/* 1151 */setBlock(world, i + 24, j + 29, k + 17, Blocks.log, 0);
		/* 1152 */setBlock(world, i + 24, j + 30, k + 15, Blocks.log, 0);
		/* 1153 */setBlock(world, i + 24, j + 30, k + 16, Blocks.log, 0);
		/* 1154 */setBlock(world, i + 24, j + 30, k + 17, Blocks.log, 0);
		/* 1155 */setBlock(world, i + 24, j + 31, k + 15, Blocks.log, 0);
		/* 1156 */setBlock(world, i + 24, j + 31, k + 16, Blocks.log, 0);
		/* 1157 */setBlock(world, i + 24, j + 32, k + 15, Blocks.log, 0);
		/* 1158 */setBlock(world, i + 24, j + 32, k + 16, Blocks.log, 0);
		/* 1159 */setBlock(world, i + 24, j + 33, k + 15, Blocks.log, 0);
		/* 1160 */setBlock(world, i + 24, j + 33, k + 16, Blocks.log, 0);
		/* 1161 */setBlock(world, i + 24, j + 34, k + 15, Blocks.log, 0);
		/* 1162 */setBlock(world, i + 24, j + 34, k + 16, Blocks.log, 0);
		/* 1163 */setBlock(world, i + 24, j + 35, k + 15, Blocks.log, 0);
		/* 1164 */setBlock(world, i + 24, j + 35, k + 16, Blocks.log, 0);
		/* 1165 */setBlock(world, i + 24, j + 36, k + 15, Blocks.log, 0);
		/* 1166 */setBlock(world, i + 24, j + 36, k + 16, Blocks.log, 0);
		/* 1167 */setBlock(world, i + 24, j + 39, k + 25, Blocks.log, 0);
		/* 1168 */setBlock(world, i + 24, j + 40, k + 18, Blocks.log, 0);
		/* 1169 */setBlock(world, i + 24, j + 42, k + 19, Blocks.log, 0);
		/* 1170 */setBlock(world, i + 24, j + 43, k + 16, Blocks.log, 0);
		/* 1171 */setBlock(world, i + 24, j + 43, k + 21, Blocks.log, 0);
		/* 1172 */setBlock(world, i + 24, j + 44, k + 15, Blocks.log, 0);
		/* 1173 */setBlock(world, i + 24, j + 45, k + 5, Blocks.log, 0);
		/* 1174 */setBlock(world, i + 24, j + 45, k + 12, Blocks.log, 0);
		/* 1175 */setBlock(world, i + 24, j + 47, k + 11, Blocks.log, 0);
		/* 1176 */setBlock(world, i + 24, j + 47, k + 14, Blocks.log, 0);
		/* 1177 */setBlock(world, i + 24, j + 47, k + 16, Blocks.log, 0);
		/* 1178 */setBlock(world, i + 24, j + 48, k + 15, Blocks.log, 0);
		/* 1179 */setBlock(world, i + 24, j + 48, k + 19, Blocks.log, 0);
		/* 1180 */setBlock(world, i + 24, j + 48, k + 22, Blocks.log, 0);
		/* 1181 */setBlock(world, i + 25, j + 39, k + 21, Blocks.log, 0);
		/* 1182 */setBlock(world, i + 25, j + 40, k + 22, Blocks.log, 0);
		/* 1183 */setBlock(world, i + 25, j + 43, k + 10, Blocks.log, 0);
		/* 1184 */setBlock(world, i + 25, j + 44, k + 19, Blocks.log, 0);
		/* 1185 */setBlock(world, i + 25, j + 45, k + 15, Blocks.log, 0);
		/* 1186 */setBlock(world, i + 25, j + 46, k + 10, Blocks.log, 0);
		/* 1187 */setBlock(world, i + 25, j + 46, k + 15, Blocks.log, 0);
		/* 1188 */setBlock(world, i + 25, j + 46, k + 20, Blocks.log, 0);
		/* 1189 */setBlock(world, i + 25, j + 48, k + 16, Blocks.log, 0);
		/* 1190 */setBlock(world, i + 25, j + 48, k + 18, Blocks.log, 0);
		/* 1191 */setBlock(world, i + 25, j + 48, k + 21, Blocks.log, 0);
		/* 1192 */setBlock(world, i + 26, j + 39, k + 12, Blocks.log, 0);
		/* 1193 */setBlock(world, i + 26, j + 39, k + 23, Blocks.log, 0);
		/* 1194 */setBlock(world, i + 26, j + 40, k + 16, Blocks.log, 0);
		/* 1195 */setBlock(world, i + 26, j + 41, k + 23, Blocks.log, 0);
		/* 1196 */setBlock(world, i + 26, j + 43, k + 14, Blocks.log, 0);
		/* 1197 */setBlock(world, i + 26, j + 44, k + 12, Blocks.log, 0);
		/* 1198 */setBlock(world, i + 26, j + 44, k + 19, Blocks.log, 0);
		/* 1199 */setBlock(world, i + 26, j + 47, k + 13, Blocks.log, 0);
		/* 1200 */setBlock(world, i + 27, j + 39, k + 8, Blocks.log, 0);
		/* 1201 */setBlock(world, i + 27, j + 41, k + 16, Blocks.log, 0);
		/* 1202 */setBlock(world, i + 27, j + 41, k + 24, Blocks.log, 0);
		/* 1203 */setBlock(world, i + 27, j + 42, k + 12, Blocks.log, 0);
		/* 1204 */setBlock(world, i + 27, j + 44, k + 18, Blocks.log, 0);
		/* 1205 */setBlock(world, i + 27, j + 45, k + 13, Blocks.log, 0);
		/* 1206 */setBlock(world, i + 27, j + 45, k + 16, Blocks.log, 0);
		/* 1207 */setBlock(world, i + 27, j + 46, k + 17, Blocks.log, 0);
		/* 1208 */setBlock(world, i + 27, j + 46, k + 19, Blocks.log, 0);
		/* 1209 */setBlock(world, i + 27, j + 48, k + 18, Blocks.log, 0);
		/* 1210 */setBlock(world, i + 28, j + 40, k + 22, Blocks.log, 0);
		/* 1211 */setBlock(world, i + 28, j + 41, k + 5, Blocks.log, 0);
		/* 1212 */setBlock(world, i + 28, j + 44, k + 13, Blocks.log, 0);
		/* 1213 */setBlock(world, i + 28, j + 44, k + 17, Blocks.log, 0);
		/* 1214 */setBlock(world, i + 28, j + 47, k + 20, Blocks.log, 0);
		/* 1215 */setBlock(world, i + 29, j + 44, k + 13, Blocks.log, 0);
		/* 1216 */setBlock(world, i + 29, j + 44, k + 16, Blocks.log, 0);
		/* 1217 */setBlock(world, i + 29, j + 44, k + 23, Blocks.log, 0);
		/* 1218 */setBlock(world, i + 30, j + 39, k + 22, Blocks.log, 0);
		/* 1219 */setBlock(world, i + 30, j + 42, k + 12, Blocks.log, 0);
		/* 1220 */setBlock(world, i + 30, j + 42, k + 14, Blocks.log, 0);
		/* 1221 */setBlock(world, i + 30, j + 42, k + 21, Blocks.log, 0);
		/* 1222 */setBlock(world, i + 30, j + 43, k + 10, Blocks.log, 0);
		/* 1223 */setBlock(world, i + 31, j + 39, k + 17, Blocks.log, 0);
		/* 1224 */setBlock(world, i + 31, j + 41, k + 8, Blocks.log, 0);
		/* 1225 */setBlock(world, i + 31, j + 42, k + 21, Blocks.log, 0);
		/* 1226 */setBlock(world, i + 31, j + 43, k + 25, Blocks.log, 0);
		/* 1227 */setBlock(world, i + 31, j + 44, k + 21, Blocks.log, 0);
		/* 1228 */setBlock(world, i + 32, j + 39, k + 19, Blocks.log, 0);
		/* 1229 */setBlock(world, i + 32, j + 40, k + 16, Blocks.log, 0);
		/* 1230 */setBlock(world, i + 33, j + 40, k + 4, Blocks.log, 0);
		/* 1231 */setBlock(world, i + 33, j + 40, k + 18, Blocks.log, 0);
		/* 1232 */setBlock(world, i + 33, j + 41, k + 9, Blocks.log, 0);
		/* 1233 */setBlock(world, i + 33, j + 42, k + 6, Blocks.log, 0);
		/* 1234 */setBlock(world, i + 34, j + 41, k + 7, Blocks.log, 0);
		/* 1235 */setBlock(world, i + 0, j + 40, k + 9, Blocks.leaves, 12);
		/* 1236 */world.setBlockMetadataWithNotify(i + 0, j + 40, k + 9, 12, 2);
		/* 1237 */setBlock(world, i + 0, j + 40, k + 22, Blocks.leaves, 12);
		/* 1238 */world.setBlockMetadataWithNotify(i + 0, j + 40, k + 22, 12, 2);
		/* 1239 */setBlock(world, i + 0, j + 40, k + 23, Blocks.leaves, 12);
		/* 1240 */world.setBlockMetadataWithNotify(i + 0, j + 40, k + 23, 12, 2);
		/* 1241 */setBlock(world, i + 0, j + 41, k + 8, Blocks.leaves, 12);
		/* 1242 */world.setBlockMetadataWithNotify(i + 0, j + 41, k + 8, 12, 2);
		/* 1243 */setBlock(world, i + 0, j + 41, k + 23, Blocks.leaves, 12);
		/* 1244 */world.setBlockMetadataWithNotify(i + 0, j + 41, k + 23, 12, 2);
		/* 1245 */setBlock(world, i + 1, j + 40, k + 7, Blocks.leaves, 12);
		/* 1246 */world.setBlockMetadataWithNotify(i + 1, j + 40, k + 7, 12, 2);
		/* 1247 */setBlock(world, i + 1, j + 40, k + 8, Blocks.leaves, 12);
		/* 1248 */world.setBlockMetadataWithNotify(i + 1, j + 40, k + 8, 12, 2);
		/* 1249 */setBlock(world, i + 1, j + 40, k + 22, Blocks.leaves, 12);
		/* 1250 */world.setBlockMetadataWithNotify(i + 1, j + 40, k + 22, 12, 2);
		/* 1251 */setBlock(world, i + 1, j + 40, k + 23, Blocks.leaves, 12);
		/* 1252 */world.setBlockMetadataWithNotify(i + 1, j + 40, k + 23, 12, 2);
		/* 1253 */setBlock(world, i + 1, j + 40, k + 24, Blocks.leaves, 12);
		/* 1254 */world.setBlockMetadataWithNotify(i + 1, j + 40, k + 24, 12, 2);
		/* 1255 */setBlock(world, i + 1, j + 41, k + 7, Blocks.leaves, 12);
		/* 1256 */world.setBlockMetadataWithNotify(i + 1, j + 41, k + 7, 12, 2);
		/* 1257 */setBlock(world, i + 1, j + 41, k + 8, Blocks.leaves, 12);
		/* 1258 */world.setBlockMetadataWithNotify(i + 1, j + 41, k + 8, 12, 2);
		/* 1259 */setBlock(world, i + 1, j + 41, k + 9, Blocks.leaves, 12);
		/* 1260 */world.setBlockMetadataWithNotify(i + 1, j + 41, k + 9, 12, 2);
		/* 1261 */setBlock(world, i + 1, j + 41, k + 22, Blocks.leaves, 12);
		/* 1262 */world.setBlockMetadataWithNotify(i + 1, j + 41, k + 22, 12, 2);
		/* 1263 */setBlock(world, i + 1, j + 41, k + 23, Blocks.leaves, 12);
		/* 1264 */world.setBlockMetadataWithNotify(i + 1, j + 41, k + 23, 12, 2);
		/* 1265 */setBlock(world, i + 1, j + 41, k + 24, Blocks.leaves, 12);
		/* 1266 */world.setBlockMetadataWithNotify(i + 1, j + 41, k + 24, 12, 2);
		/* 1267 */setBlock(world, i + 2, j + 39, k + 9, Blocks.leaves, 12);
		/* 1268 */world.setBlockMetadataWithNotify(i + 2, j + 39, k + 9, 12, 2);
		/* 1269 */setBlock(world, i + 2, j + 39, k + 10, Blocks.leaves, 12);
		/* 1270 */world.setBlockMetadataWithNotify(i + 2, j + 39, k + 10, 12, 2);
		/* 1271 */setBlock(world, i + 2, j + 39, k + 11, Blocks.leaves, 12);
		/* 1272 */world.setBlockMetadataWithNotify(i + 2, j + 39, k + 11, 12, 2);
		/* 1273 */setBlock(world, i + 2, j + 40, k + 6, Blocks.leaves, 12);
		/* 1274 */world.setBlockMetadataWithNotify(i + 2, j + 40, k + 6, 12, 2);
		/* 1275 */setBlock(world, i + 2, j + 40, k + 7, Blocks.leaves, 12);
		/* 1276 */world.setBlockMetadataWithNotify(i + 2, j + 40, k + 7, 12, 2);
		/* 1277 */setBlock(world, i + 2, j + 40, k + 9, Blocks.leaves, 12);
		/* 1278 */world.setBlockMetadataWithNotify(i + 2, j + 40, k + 9, 12, 2);
		/* 1279 */setBlock(world, i + 2, j + 40, k + 21, Blocks.leaves, 12);
		/* 1280 */world.setBlockMetadataWithNotify(i + 2, j + 40, k + 21, 12, 2);
		/* 1281 */setBlock(world, i + 2, j + 40, k + 22, Blocks.leaves, 12);
		/* 1282 */world.setBlockMetadataWithNotify(i + 2, j + 40, k + 22, 12, 2);
		/* 1283 */setBlock(world, i + 2, j + 41, k + 6, Blocks.leaves, 12);
		/* 1284 */world.setBlockMetadataWithNotify(i + 2, j + 41, k + 6, 12, 2);
		/* 1285 */setBlock(world, i + 2, j + 41, k + 7, Blocks.leaves, 12);
		/* 1286 */world.setBlockMetadataWithNotify(i + 2, j + 41, k + 7, 12, 2);
		/* 1287 */setBlock(world, i + 2, j + 41, k + 8, Blocks.leaves, 12);
		/* 1288 */world.setBlockMetadataWithNotify(i + 2, j + 41, k + 8, 12, 2);
		/* 1289 */setBlock(world, i + 2, j + 41, k + 9, Blocks.leaves, 12);
		/* 1290 */world.setBlockMetadataWithNotify(i + 2, j + 41, k + 9, 12, 2);
		/* 1291 */setBlock(world, i + 2, j + 41, k + 10, Blocks.leaves, 12);
		/* 1292 */world.setBlockMetadataWithNotify(i + 2, j + 41, k + 10, 12, 2);
		/* 1293 */setBlock(world, i + 2, j + 41, k + 21, Blocks.leaves, 12);
		/* 1294 */world.setBlockMetadataWithNotify(i + 2, j + 41, k + 21, 12, 2);
		/* 1295 */setBlock(world, i + 2, j + 41, k + 22, Blocks.leaves, 12);
		/* 1296 */world.setBlockMetadataWithNotify(i + 2, j + 41, k + 22, 12, 2);
		/* 1297 */setBlock(world, i + 2, j + 41, k + 23, Blocks.leaves, 12);
		/* 1298 */world.setBlockMetadataWithNotify(i + 2, j + 41, k + 23, 12, 2);
		/* 1299 */setBlock(world, i + 2, j + 42, k + 16, Blocks.leaves, 12);
		/* 1300 */world.setBlockMetadataWithNotify(i + 2, j + 42, k + 16, 12, 2);
		/* 1301 */setBlock(world, i + 2, j + 42, k + 17, Blocks.leaves, 12);
		/* 1302 */world.setBlockMetadataWithNotify(i + 2, j + 42, k + 17, 12, 2);
		/* 1303 */setBlock(world, i + 3, j + 39, k + 9, Blocks.leaves, 12);
		/* 1304 */world.setBlockMetadataWithNotify(i + 3, j + 39, k + 9, 12, 2);
		/* 1305 */setBlock(world, i + 3, j + 39, k + 10, Blocks.leaves, 12);
		/* 1306 */world.setBlockMetadataWithNotify(i + 3, j + 39, k + 10, 12, 2);
		/* 1307 */setBlock(world, i + 3, j + 39, k + 11, Blocks.leaves, 12);
		/* 1308 */world.setBlockMetadataWithNotify(i + 3, j + 39, k + 11, 12, 2);
		/* 1309 */setBlock(world, i + 3, j + 39, k + 12, Blocks.leaves, 4);
		/* 1310 */world.setBlockMetadataWithNotify(i + 3, j + 39, k + 12, 4, 2);
		/* 1311 */setBlock(world, i + 3, j + 40, k + 6, Blocks.leaves, 4);
		/* 1312 */world.setBlockMetadataWithNotify(i + 3, j + 40, k + 6, 4, 2);
		/* 1313 */setBlock(world, i + 3, j + 40, k + 7, Blocks.leaves, 12);
		/* 1314 */world.setBlockMetadataWithNotify(i + 3, j + 40, k + 7, 12, 2);
		/* 1315 */setBlock(world, i + 3, j + 40, k + 8, Blocks.leaves, 12);
		/* 1316 */world.setBlockMetadataWithNotify(i + 3, j + 40, k + 8, 12, 2);
		/* 1317 */setBlock(world, i + 3, j + 40, k + 9, Blocks.leaves, 12);
		/* 1318 */world.setBlockMetadataWithNotify(i + 3, j + 40, k + 9, 12, 2);
		/* 1319 */setBlock(world, i + 3, j + 40, k + 10, Blocks.leaves, 12);
		/* 1320 */world.setBlockMetadataWithNotify(i + 3, j + 40, k + 10, 12, 2);
		/* 1321 */setBlock(world, i + 3, j + 40, k + 11, Blocks.leaves, 12);
		/* 1322 */world.setBlockMetadataWithNotify(i + 3, j + 40, k + 11, 12, 2);
		/* 1323 */setBlock(world, i + 3, j + 40, k + 20, Blocks.leaves, 12);
		/* 1324 */world.setBlockMetadataWithNotify(i + 3, j + 40, k + 20, 12, 2);
		/* 1325 */setBlock(world, i + 3, j + 40, k + 21, Blocks.leaves, 12);
		/* 1326 */world.setBlockMetadataWithNotify(i + 3, j + 40, k + 21, 12, 2);
		/* 1327 */setBlock(world, i + 3, j + 40, k + 22, Blocks.leaves, 12);
		/* 1328 */world.setBlockMetadataWithNotify(i + 3, j + 40, k + 22, 12, 2);
		/* 1329 */setBlock(world, i + 3, j + 40, k + 23, Blocks.leaves, 12);
		/* 1330 */world.setBlockMetadataWithNotify(i + 3, j + 40, k + 23, 12, 2);
		/* 1331 */setBlock(world, i + 3, j + 40, k + 24, Blocks.leaves, 12);
		/* 1332 */world.setBlockMetadataWithNotify(i + 3, j + 40, k + 24, 12, 2);
		/* 1333 */setBlock(world, i + 3, j + 40, k + 25, Blocks.leaves, 12);
		/* 1334 */world.setBlockMetadataWithNotify(i + 3, j + 40, k + 25, 12, 2);
		/* 1335 */setBlock(world, i + 3, j + 41, k + 7, Blocks.leaves, 4);
		/* 1336 */world.setBlockMetadataWithNotify(i + 3, j + 41, k + 7, 4, 2);
		/* 1337 */setBlock(world, i + 3, j + 41, k + 8, Blocks.leaves, 4);
		/* 1338 */world.setBlockMetadataWithNotify(i + 3, j + 41, k + 8, 4, 2);
		/* 1339 */setBlock(world, i + 3, j + 41, k + 9, Blocks.leaves, 12);
		/* 1340 */world.setBlockMetadataWithNotify(i + 3, j + 41, k + 9, 12, 2);
		/* 1341 */setBlock(world, i + 3, j + 41, k + 22, Blocks.leaves, 12);
		/* 1342 */world.setBlockMetadataWithNotify(i + 3, j + 41, k + 22, 12, 2);
		/* 1343 */setBlock(world, i + 3, j + 41, k + 24, Blocks.leaves, 12);
		/* 1344 */world.setBlockMetadataWithNotify(i + 3, j + 41, k + 24, 12, 2);
		/* 1345 */setBlock(world, i + 3, j + 42, k + 14, Blocks.leaves, 12);
		/* 1346 */world.setBlockMetadataWithNotify(i + 3, j + 42, k + 14, 12, 2);
		/* 1347 */setBlock(world, i + 3, j + 42, k + 15, Blocks.leaves, 12);
		/* 1348 */world.setBlockMetadataWithNotify(i + 3, j + 42, k + 15, 12, 2);
		/* 1349 */setBlock(world, i + 3, j + 42, k + 16, Blocks.leaves, 12);
		/* 1350 */world.setBlockMetadataWithNotify(i + 3, j + 42, k + 16, 12, 2);
		/* 1351 */setBlock(world, i + 3, j + 42, k + 17, Blocks.leaves, 12);
		/* 1352 */world.setBlockMetadataWithNotify(i + 3, j + 42, k + 17, 12, 2);
		/* 1353 */setBlock(world, i + 3, j + 42, k + 18, Blocks.leaves, 4);
		/* 1354 */world.setBlockMetadataWithNotify(i + 3, j + 42, k + 18, 4, 2);
		/* 1355 */setBlock(world, i + 3, j + 43, k + 16, Blocks.leaves, 12);
		/* 1356 */world.setBlockMetadataWithNotify(i + 3, j + 43, k + 16, 12, 2);
		/* 1357 */setBlock(world, i + 3, j + 43, k + 17, Blocks.leaves, 12);
		/* 1358 */world.setBlockMetadataWithNotify(i + 3, j + 43, k + 17, 12, 2);
		/* 1359 */setBlock(world, i + 4, j + 39, k + 8, Blocks.leaves, 12);
		/* 1360 */world.setBlockMetadataWithNotify(i + 4, j + 39, k + 8, 12, 2);
		/* 1361 */setBlock(world, i + 4, j + 39, k + 9, Blocks.leaves, 12);
		/* 1362 */world.setBlockMetadataWithNotify(i + 4, j + 39, k + 9, 12, 2);
		/* 1363 */setBlock(world, i + 4, j + 39, k + 11, Blocks.leaves, 4);
		/* 1364 */world.setBlockMetadataWithNotify(i + 4, j + 39, k + 11, 4, 2);
		/* 1365 */setBlock(world, i + 4, j + 39, k + 12, Blocks.leaves, 4);
		/* 1366 */world.setBlockMetadataWithNotify(i + 4, j + 39, k + 12, 4, 2);
		/* 1367 */setBlock(world, i + 4, j + 39, k + 17, Blocks.leaves, 12);
		/* 1368 */world.setBlockMetadataWithNotify(i + 4, j + 39, k + 17, 12, 2);
		/* 1369 */setBlock(world, i + 4, j + 39, k + 18, Blocks.leaves, 12);
		/* 1370 */world.setBlockMetadataWithNotify(i + 4, j + 39, k + 18, 12, 2);
		/* 1371 */setBlock(world, i + 4, j + 40, k + 7, Blocks.leaves, 12);
		/* 1372 */world.setBlockMetadataWithNotify(i + 4, j + 40, k + 7, 12, 2);
		/* 1373 */setBlock(world, i + 4, j + 40, k + 8, Blocks.leaves, 12);
		/* 1374 */world.setBlockMetadataWithNotify(i + 4, j + 40, k + 8, 12, 2);
		/* 1375 */setBlock(world, i + 4, j + 40, k + 9, Blocks.leaves, 12);
		/* 1376 */world.setBlockMetadataWithNotify(i + 4, j + 40, k + 9, 12, 2);
		/* 1377 */setBlock(world, i + 4, j + 40, k + 10, Blocks.leaves, 4);
		/* 1378 */world.setBlockMetadataWithNotify(i + 4, j + 40, k + 10, 4, 2);
		/* 1379 */setBlock(world, i + 4, j + 40, k + 11, Blocks.leaves, 4);
		/* 1380 */world.setBlockMetadataWithNotify(i + 4, j + 40, k + 11, 4, 2);
		/* 1381 */setBlock(world, i + 4, j + 40, k + 12, Blocks.leaves, 4);
		/* 1382 */world.setBlockMetadataWithNotify(i + 4, j + 40, k + 12, 4, 2);
		/* 1383 */setBlock(world, i + 4, j + 40, k + 17, Blocks.leaves, 12);
		/* 1384 */world.setBlockMetadataWithNotify(i + 4, j + 40, k + 17, 12, 2);
		/* 1385 */setBlock(world, i + 4, j + 40, k + 18, Blocks.leaves, 12);
		/* 1386 */world.setBlockMetadataWithNotify(i + 4, j + 40, k + 18, 12, 2);
		/* 1387 */setBlock(world, i + 4, j + 40, k + 19, Blocks.leaves, 12);
		/* 1388 */world.setBlockMetadataWithNotify(i + 4, j + 40, k + 19, 12, 2);
		/* 1389 */setBlock(world, i + 4, j + 40, k + 20, Blocks.leaves, 12);
		/* 1390 */world.setBlockMetadataWithNotify(i + 4, j + 40, k + 20, 12, 2);
		/* 1391 */setBlock(world, i + 4, j + 40, k + 21, Blocks.leaves, 12);
		/* 1392 */world.setBlockMetadataWithNotify(i + 4, j + 40, k + 21, 12, 2);
		/* 1393 */setBlock(world, i + 4, j + 40, k + 23, Blocks.leaves, 12);
		/* 1394 */world.setBlockMetadataWithNotify(i + 4, j + 40, k + 23, 12, 2);
		/* 1395 */setBlock(world, i + 4, j + 41, k + 8, Blocks.leaves, 4);
		/* 1396 */world.setBlockMetadataWithNotify(i + 4, j + 41, k + 8, 4, 2);
		/* 1397 */setBlock(world, i + 4, j + 41, k + 19, Blocks.leaves, 12);
		/* 1398 */world.setBlockMetadataWithNotify(i + 4, j + 41, k + 19, 12, 2);
		/* 1399 */setBlock(world, i + 4, j + 41, k + 20, Blocks.leaves, 12);
		/* 1400 */world.setBlockMetadataWithNotify(i + 4, j + 41, k + 20, 12, 2);
		/* 1401 */setBlock(world, i + 4, j + 41, k + 21, Blocks.leaves, 12);
		/* 1402 */world.setBlockMetadataWithNotify(i + 4, j + 41, k + 21, 12, 2);
		/* 1403 */setBlock(world, i + 4, j + 42, k + 10, Blocks.leaves, 4);
		/* 1404 */world.setBlockMetadataWithNotify(i + 4, j + 42, k + 10, 4, 2);
		/* 1405 */setBlock(world, i + 4, j + 42, k + 11, Blocks.leaves, 4);
		/* 1406 */world.setBlockMetadataWithNotify(i + 4, j + 42, k + 11, 4, 2);
		/* 1407 */setBlock(world, i + 4, j + 42, k + 12, Blocks.leaves, 4);
		/* 1408 */world.setBlockMetadataWithNotify(i + 4, j + 42, k + 12, 4, 2);
		/* 1409 */setBlock(world, i + 4, j + 42, k + 14, Blocks.leaves, 12);
		/* 1410 */world.setBlockMetadataWithNotify(i + 4, j + 42, k + 14, 12, 2);
		/* 1411 */setBlock(world, i + 4, j + 42, k + 15, Blocks.leaves, 12);
		/* 1412 */world.setBlockMetadataWithNotify(i + 4, j + 42, k + 15, 12, 2);
		/* 1413 */setBlock(world, i + 4, j + 42, k + 17, Blocks.leaves, 4);
		/* 1414 */world.setBlockMetadataWithNotify(i + 4, j + 42, k + 17, 4, 2);
		/* 1415 */setBlock(world, i + 4, j + 42, k + 18, Blocks.leaves, 4);
		/* 1416 */world.setBlockMetadataWithNotify(i + 4, j + 42, k + 18, 4, 2);
		/* 1417 */setBlock(world, i + 4, j + 43, k + 11, Blocks.leaves, 4);
		/* 1418 */world.setBlockMetadataWithNotify(i + 4, j + 43, k + 11, 4, 2);
		/* 1419 */setBlock(world, i + 4, j + 43, k + 14, Blocks.leaves, 12);
		/* 1420 */world.setBlockMetadataWithNotify(i + 4, j + 43, k + 14, 12, 2);
		/* 1421 */setBlock(world, i + 4, j + 43, k + 16, Blocks.leaves, 12);
		/* 1422 */world.setBlockMetadataWithNotify(i + 4, j + 43, k + 16, 12, 2);
		/* 1423 */setBlock(world, i + 4, j + 43, k + 17, Blocks.leaves, 4);
		/* 1424 */world.setBlockMetadataWithNotify(i + 4, j + 43, k + 17, 4, 2);
		/* 1425 */setBlock(world, i + 4, j + 43, k + 18, Blocks.leaves, 4);
		/* 1426 */world.setBlockMetadataWithNotify(i + 4, j + 43, k + 18, 4, 2);
		/* 1427 */setBlock(world, i + 5, j + 39, k + 8, Blocks.leaves, 4);
		/* 1428 */world.setBlockMetadataWithNotify(i + 5, j + 39, k + 8, 4, 2);
		/* 1429 */setBlock(world, i + 5, j + 39, k + 9, Blocks.leaves, 4);
		/* 1430 */world.setBlockMetadataWithNotify(i + 5, j + 39, k + 9, 4, 2);
		/* 1431 */setBlock(world, i + 5, j + 39, k + 10, Blocks.leaves, 4);
		/* 1432 */world.setBlockMetadataWithNotify(i + 5, j + 39, k + 10, 4, 2);
		/* 1433 */setBlock(world, i + 5, j + 39, k + 11, Blocks.leaves, 4);
		/* 1434 */world.setBlockMetadataWithNotify(i + 5, j + 39, k + 11, 4, 2);
		/* 1435 */setBlock(world, i + 5, j + 39, k + 12, Blocks.leaves, 4);
		/* 1436 */world.setBlockMetadataWithNotify(i + 5, j + 39, k + 12, 4, 2);
		/* 1437 */setBlock(world, i + 5, j + 39, k + 15, Blocks.leaves, 12);
		/* 1438 */world.setBlockMetadataWithNotify(i + 5, j + 39, k + 15, 12, 2);
		/* 1439 */setBlock(world, i + 5, j + 39, k + 16, Blocks.leaves, 12);
		/* 1440 */world.setBlockMetadataWithNotify(i + 5, j + 39, k + 16, 12, 2);
		/* 1441 */setBlock(world, i + 5, j + 39, k + 17, Blocks.leaves, 12);
		/* 1442 */world.setBlockMetadataWithNotify(i + 5, j + 39, k + 17, 12, 2);
		/* 1443 */setBlock(world, i + 5, j + 39, k + 18, Blocks.leaves, 4);
		/* 1444 */world.setBlockMetadataWithNotify(i + 5, j + 39, k + 18, 4, 2);
		/* 1445 */setBlock(world, i + 5, j + 39, k + 19, Blocks.leaves, 4);
		/* 1446 */world.setBlockMetadataWithNotify(i + 5, j + 39, k + 19, 4, 2);
		/* 1447 */setBlock(world, i + 5, j + 40, k + 9, Blocks.leaves, 4);
		/* 1448 */world.setBlockMetadataWithNotify(i + 5, j + 40, k + 9, 4, 2);
		/* 1449 */setBlock(world, i + 5, j + 40, k + 10, Blocks.leaves, 4);
		/* 1450 */world.setBlockMetadataWithNotify(i + 5, j + 40, k + 10, 4, 2);
		/* 1451 */setBlock(world, i + 5, j + 40, k + 11, Blocks.leaves, 4);
		/* 1452 */world.setBlockMetadataWithNotify(i + 5, j + 40, k + 11, 4, 2);
		/* 1453 */setBlock(world, i + 5, j + 40, k + 16, Blocks.leaves, 12);
		/* 1454 */world.setBlockMetadataWithNotify(i + 5, j + 40, k + 16, 12, 2);
		/* 1455 */setBlock(world, i + 5, j + 40, k + 17, Blocks.leaves, 12);
		/* 1456 */world.setBlockMetadataWithNotify(i + 5, j + 40, k + 17, 12, 2);
		/* 1457 */setBlock(world, i + 5, j + 40, k + 18, Blocks.leaves, 4);
		/* 1458 */world.setBlockMetadataWithNotify(i + 5, j + 40, k + 18, 4, 2);
		/* 1459 */setBlock(world, i + 5, j + 40, k + 19, Blocks.leaves, 4);
		/* 1460 */world.setBlockMetadataWithNotify(i + 5, j + 40, k + 19, 4, 2);
		/* 1461 */setBlock(world, i + 5, j + 40, k + 21, Blocks.leaves, 12);
		/* 1462 */world.setBlockMetadataWithNotify(i + 5, j + 40, k + 21, 12, 2);
		/* 1463 */setBlock(world, i + 5, j + 40, k + 22, Blocks.leaves, 12);
		/* 1464 */world.setBlockMetadataWithNotify(i + 5, j + 40, k + 22, 12, 2);
		/* 1465 */setBlock(world, i + 5, j + 41, k + 18, Blocks.leaves, 4);
		/* 1466 */world.setBlockMetadataWithNotify(i + 5, j + 41, k + 18, 4, 2);
		/* 1467 */setBlock(world, i + 5, j + 41, k + 19, Blocks.leaves, 4);
		/* 1468 */world.setBlockMetadataWithNotify(i + 5, j + 41, k + 19, 4, 2);
		/* 1469 */setBlock(world, i + 5, j + 41, k + 20, Blocks.leaves, 12);
		/* 1470 */world.setBlockMetadataWithNotify(i + 5, j + 41, k + 20, 12, 2);
		/* 1471 */setBlock(world, i + 5, j + 41, k + 21, Blocks.leaves, 12);
		/* 1472 */world.setBlockMetadataWithNotify(i + 5, j + 41, k + 21, 12, 2);
		/* 1473 */setBlock(world, i + 5, j + 41, k + 22, Blocks.leaves, 12);
		/* 1474 */world.setBlockMetadataWithNotify(i + 5, j + 41, k + 22, 12, 2);
		/* 1475 */setBlock(world, i + 5, j + 42, k + 7, Blocks.leaves, 12);
		/* 1476 */world.setBlockMetadataWithNotify(i + 5, j + 42, k + 7, 12, 2);
		/* 1477 */setBlock(world, i + 5, j + 42, k + 8, Blocks.leaves, 12);
		/* 1478 */world.setBlockMetadataWithNotify(i + 5, j + 42, k + 8, 12, 2);
		/* 1479 */setBlock(world, i + 5, j + 42, k + 9, Blocks.leaves, 4);
		/* 1480 */world.setBlockMetadataWithNotify(i + 5, j + 42, k + 9, 4, 2);
		/* 1481 */setBlock(world, i + 5, j + 42, k + 10, Blocks.leaves, 4);
		/* 1482 */world.setBlockMetadataWithNotify(i + 5, j + 42, k + 10, 4, 2);
		/* 1483 */setBlock(world, i + 5, j + 42, k + 11, Blocks.leaves, 4);
		/* 1484 */world.setBlockMetadataWithNotify(i + 5, j + 42, k + 11, 4, 2);
		/* 1485 */setBlock(world, i + 5, j + 42, k + 12, Blocks.leaves, 4);
		/* 1486 */world.setBlockMetadataWithNotify(i + 5, j + 42, k + 12, 4, 2);
		/* 1487 */setBlock(world, i + 5, j + 42, k + 13, Blocks.leaves, 4);
		/* 1488 */world.setBlockMetadataWithNotify(i + 5, j + 42, k + 13, 4, 2);
		/* 1489 */setBlock(world, i + 5, j + 42, k + 14, Blocks.leaves, 12);
		/* 1490 */world.setBlockMetadataWithNotify(i + 5, j + 42, k + 14, 12, 2);
		/* 1491 */setBlock(world, i + 5, j + 42, k + 15, Blocks.leaves, 12);
		/* 1492 */world.setBlockMetadataWithNotify(i + 5, j + 42, k + 15, 12, 2);
		/* 1493 */setBlock(world, i + 5, j + 42, k + 16, Blocks.leaves, 12);
		/* 1494 */world.setBlockMetadataWithNotify(i + 5, j + 42, k + 16, 12, 2);
		/* 1495 */setBlock(world, i + 5, j + 42, k + 17, Blocks.leaves, 4);
		/* 1496 */world.setBlockMetadataWithNotify(i + 5, j + 42, k + 17, 4, 2);
		/* 1497 */setBlock(world, i + 5, j + 42, k + 18, Blocks.leaves, 4);
		/* 1498 */world.setBlockMetadataWithNotify(i + 5, j + 42, k + 18, 4, 2);
		/* 1499 */setBlock(world, i + 5, j + 43, k + 8, Blocks.leaves, 12);
		/* 1500 */world.setBlockMetadataWithNotify(i + 5, j + 43, k + 8, 12, 2);
		/* 1501 */setBlock(world, i + 5, j + 43, k + 10, Blocks.leaves, 4);
		/* 1502 */world.setBlockMetadataWithNotify(i + 5, j + 43, k + 10, 4, 2);
		/* 1503 */setBlock(world, i + 5, j + 43, k + 11, Blocks.leaves, 4);
		/* 1504 */world.setBlockMetadataWithNotify(i + 5, j + 43, k + 11, 4, 2);
		/* 1505 */setBlock(world, i + 5, j + 43, k + 12, Blocks.leaves, 4);
		/* 1506 */world.setBlockMetadataWithNotify(i + 5, j + 43, k + 12, 4, 2);
		/* 1507 */setBlock(world, i + 5, j + 43, k + 15, Blocks.leaves, 12);
		/* 1508 */world.setBlockMetadataWithNotify(i + 5, j + 43, k + 15, 12, 2);
		/* 1509 */setBlock(world, i + 5, j + 43, k + 16, Blocks.leaves, 12);
		/* 1510 */world.setBlockMetadataWithNotify(i + 5, j + 43, k + 16, 12, 2);
		/* 1511 */setBlock(world, i + 5, j + 43, k + 17, Blocks.leaves, 4);
		/* 1512 */world.setBlockMetadataWithNotify(i + 5, j + 43, k + 17, 4, 2);
		/* 1513 */setBlock(world, i + 6, j + 39, k + 8, Blocks.leaves, 4);
		/* 1514 */world.setBlockMetadataWithNotify(i + 6, j + 39, k + 8, 4, 2);
		/* 1515 */setBlock(world, i + 6, j + 39, k + 9, Blocks.leaves, 4);
		/* 1516 */world.setBlockMetadataWithNotify(i + 6, j + 39, k + 9, 4, 2);
		/* 1517 */setBlock(world, i + 6, j + 39, k + 10, Blocks.leaves, 4);
		/* 1518 */world.setBlockMetadataWithNotify(i + 6, j + 39, k + 10, 4, 2);
		/* 1519 */setBlock(world, i + 6, j + 39, k + 11, Blocks.leaves, 4);
		/* 1520 */world.setBlockMetadataWithNotify(i + 6, j + 39, k + 11, 4, 2);
		/* 1521 */setBlock(world, i + 6, j + 39, k + 12, Blocks.leaves, 4);
		/* 1522 */world.setBlockMetadataWithNotify(i + 6, j + 39, k + 12, 4, 2);
		/* 1523 */setBlock(world, i + 6, j + 39, k + 15, Blocks.leaves, 4);
		/* 1524 */world.setBlockMetadataWithNotify(i + 6, j + 39, k + 15, 4, 2);
		/* 1525 */setBlock(world, i + 6, j + 39, k + 16, Blocks.leaves, 4);
		/* 1526 */world.setBlockMetadataWithNotify(i + 6, j + 39, k + 16, 4, 2);
		/* 1527 */setBlock(world, i + 6, j + 39, k + 18, Blocks.leaves, 4);
		/* 1528 */world.setBlockMetadataWithNotify(i + 6, j + 39, k + 18, 4, 2);
		/* 1529 */setBlock(world, i + 6, j + 39, k + 19, Blocks.leaves, 4);
		/* 1530 */world.setBlockMetadataWithNotify(i + 6, j + 39, k + 19, 4, 2);
		/* 1531 */setBlock(world, i + 6, j + 40, k + 9, Blocks.leaves, 4);
		/* 1532 */world.setBlockMetadataWithNotify(i + 6, j + 40, k + 9, 4, 2);
		/* 1533 */setBlock(world, i + 6, j + 40, k + 10, Blocks.leaves, 4);
		/* 1534 */world.setBlockMetadataWithNotify(i + 6, j + 40, k + 10, 4, 2);
		/* 1535 */setBlock(world, i + 6, j + 40, k + 11, Blocks.leaves, 4);
		/* 1536 */world.setBlockMetadataWithNotify(i + 6, j + 40, k + 11, 4, 2);
		/* 1537 */setBlock(world, i + 6, j + 40, k + 15, Blocks.leaves, 4);
		/* 1538 */world.setBlockMetadataWithNotify(i + 6, j + 40, k + 15, 4, 2);
		/* 1539 */setBlock(world, i + 6, j + 40, k + 17, Blocks.leaves, 4);
		/* 1540 */world.setBlockMetadataWithNotify(i + 6, j + 40, k + 17, 4, 2);
		/* 1541 */setBlock(world, i + 6, j + 40, k + 18, Blocks.leaves, 4);
		/* 1542 */world.setBlockMetadataWithNotify(i + 6, j + 40, k + 18, 4, 2);
		/* 1543 */setBlock(world, i + 6, j + 40, k + 19, Blocks.leaves, 4);
		/* 1544 */world.setBlockMetadataWithNotify(i + 6, j + 40, k + 19, 4, 2);
		/* 1545 */setBlock(world, i + 6, j + 40, k + 20, Blocks.leaves, 12);
		/* 1546 */world.setBlockMetadataWithNotify(i + 6, j + 40, k + 20, 12, 2);
		/* 1547 */setBlock(world, i + 6, j + 40, k + 21, Blocks.leaves, 12);
		/* 1548 */world.setBlockMetadataWithNotify(i + 6, j + 40, k + 21, 12, 2);
		/* 1549 */setBlock(world, i + 6, j + 40, k + 22, Blocks.leaves, 12);
		/* 1550 */world.setBlockMetadataWithNotify(i + 6, j + 40, k + 22, 12, 2);
		/* 1551 */setBlock(world, i + 6, j + 41, k + 19, Blocks.leaves, 4);
		/* 1552 */world.setBlockMetadataWithNotify(i + 6, j + 41, k + 19, 4, 2);
		/* 1553 */setBlock(world, i + 6, j + 41, k + 20, Blocks.leaves, 12);
		/* 1554 */world.setBlockMetadataWithNotify(i + 6, j + 41, k + 20, 12, 2);
		/* 1555 */setBlock(world, i + 6, j + 41, k + 22, Blocks.leaves, 12);
		/* 1556 */world.setBlockMetadataWithNotify(i + 6, j + 41, k + 22, 12, 2);
		/* 1557 */setBlock(world, i + 6, j + 41, k + 23, Blocks.leaves, 12);
		/* 1558 */world.setBlockMetadataWithNotify(i + 6, j + 41, k + 23, 12, 2);
		/* 1559 */setBlock(world, i + 6, j + 41, k + 24, Blocks.leaves, 12);
		/* 1560 */world.setBlockMetadataWithNotify(i + 6, j + 41, k + 24, 12, 2);
		/* 1561 */setBlock(world, i + 6, j + 42, k + 6, Blocks.leaves, 12);
		/* 1562 */world.setBlockMetadataWithNotify(i + 6, j + 42, k + 6, 12, 2);
		/* 1563 */setBlock(world, i + 6, j + 42, k + 7, Blocks.leaves, 12);
		/* 1564 */world.setBlockMetadataWithNotify(i + 6, j + 42, k + 7, 12, 2);
		/* 1565 */setBlock(world, i + 6, j + 42, k + 8, Blocks.leaves, 12);
		/* 1566 */world.setBlockMetadataWithNotify(i + 6, j + 42, k + 8, 12, 2);
		/* 1567 */setBlock(world, i + 6, j + 42, k + 9, Blocks.leaves, 4);
		/* 1568 */world.setBlockMetadataWithNotify(i + 6, j + 42, k + 9, 4, 2);
		/* 1569 */setBlock(world, i + 6, j + 42, k + 10, Blocks.leaves, 4);
		/* 1570 */world.setBlockMetadataWithNotify(i + 6, j + 42, k + 10, 4, 2);
		/* 1571 */setBlock(world, i + 6, j + 42, k + 12, Blocks.leaves, 4);
		/* 1572 */world.setBlockMetadataWithNotify(i + 6, j + 42, k + 12, 4, 2);
		/* 1573 */setBlock(world, i + 6, j + 42, k + 13, Blocks.leaves, 4);
		/* 1574 */world.setBlockMetadataWithNotify(i + 6, j + 42, k + 13, 4, 2);
		/* 1575 */setBlock(world, i + 6, j + 42, k + 15, Blocks.leaves, 4);
		/* 1576 */world.setBlockMetadataWithNotify(i + 6, j + 42, k + 15, 4, 2);
		/* 1577 */setBlock(world, i + 6, j + 42, k + 16, Blocks.leaves, 4);
		/* 1578 */world.setBlockMetadataWithNotify(i + 6, j + 42, k + 16, 4, 2);
		/* 1579 */setBlock(world, i + 6, j + 42, k + 17, Blocks.leaves, 4);
		/* 1580 */world.setBlockMetadataWithNotify(i + 6, j + 42, k + 17, 4, 2);
		/* 1581 */setBlock(world, i + 6, j + 42, k + 23, Blocks.leaves, 12);
		/* 1582 */world.setBlockMetadataWithNotify(i + 6, j + 42, k + 23, 12, 2);
		/* 1583 */setBlock(world, i + 6, j + 43, k + 8, Blocks.leaves, 12);
		/* 1584 */world.setBlockMetadataWithNotify(i + 6, j + 43, k + 8, 12, 2);
		/* 1585 */setBlock(world, i + 6, j + 43, k + 9, Blocks.leaves, 4);
		/* 1586 */world.setBlockMetadataWithNotify(i + 6, j + 43, k + 9, 4, 2);
		/* 1587 */setBlock(world, i + 6, j + 43, k + 10, Blocks.leaves, 4);
		/* 1588 */world.setBlockMetadataWithNotify(i + 6, j + 43, k + 10, 4, 2);
		/* 1589 */setBlock(world, i + 6, j + 43, k + 11, Blocks.leaves, 4);
		/* 1590 */world.setBlockMetadataWithNotify(i + 6, j + 43, k + 11, 4, 2);
		/* 1591 */setBlock(world, i + 6, j + 43, k + 12, Blocks.leaves, 4);
		/* 1592 */world.setBlockMetadataWithNotify(i + 6, j + 43, k + 12, 4, 2);
		/* 1593 */setBlock(world, i + 6, j + 43, k + 13, Blocks.leaves, 4);
		/* 1594 */world.setBlockMetadataWithNotify(i + 6, j + 43, k + 13, 4, 2);
		/* 1595 */setBlock(world, i + 6, j + 43, k + 16, Blocks.leaves, 4);
		/* 1596 */world.setBlockMetadataWithNotify(i + 6, j + 43, k + 16, 4, 2);
		/* 1597 */setBlock(world, i + 7, j + 39, k + 8, Blocks.leaves, 4);
		/* 1598 */world.setBlockMetadataWithNotify(i + 7, j + 39, k + 8, 4, 2);
		/* 1599 */setBlock(world, i + 7, j + 39, k + 9, Blocks.leaves, 4);
		/* 1600 */world.setBlockMetadataWithNotify(i + 7, j + 39, k + 9, 4, 2);
		/* 1601 */setBlock(world, i + 7, j + 39, k + 11, Blocks.leaves, 4);
		/* 1602 */world.setBlockMetadataWithNotify(i + 7, j + 39, k + 11, 4, 2);
		/* 1603 */setBlock(world, i + 7, j + 39, k + 12, Blocks.leaves, 4);
		/* 1604 */world.setBlockMetadataWithNotify(i + 7, j + 39, k + 12, 4, 2);
		/* 1605 */setBlock(world, i + 7, j + 39, k + 15, Blocks.leaves, 4);
