/*      */package com.parzivail.pswm.world.gen;

/*      */
/*      *//*      */
import java.util.Random;

/*      */
import net.minecraft.block.Block;
/*      */
import net.minecraft.init.Blocks;
/*      */
import net.minecraft.world.World;
/*      */
import net.minecraft.world.chunk.IChunkProvider;
/*      */
import net.minecraft.world.gen.feature.WorldGenerator;
import cpw.mods.fml.common.IWorldGenerator;

/*      */
/*      */
/*      */
/*      */
/*      */
/*      */
/*      */
/*      */
/*      */
/*      */public class WorldGenEndorTree4
/*      */extends WorldGenerator
/*      */implements IWorldGenerator
/*      */
{
	/*      */public void generate(Random random, int chunkX, int chunkZ, World world, IChunkProvider chunkGenerator, IChunkProvider chunkProvider)
	{
	}

	/*      */
	/*      */public boolean generate(World world, Random rand, int i, int j, int k)
	/*      */
	{
		if ((!locationIsValidSpawn(world, i, j, k)) || (!locationIsValidSpawn(world, i + 15, j, k)) || (!locationIsValidSpawn(world, i + 15, j, k + 15)) || (!locationIsValidSpawn(world, i, j, k + 15))) { return false;
		/*      */}
		k -= 10;
		i -= 10;
		/*      */
		setBlock(world, i + 0, j + 3, k + 13, Blocks.log, 0);
		setBlock(world, i + 0, j + 3, k + 14, Blocks.log, 0);
		setBlock(world, i + 0, j + 3, k + 15, Blocks.log, 0);
		setBlock(world, i + 0, j + 4, k + 12, Blocks.log, 0);
		setBlock(world, i + 0, j + 4, k + 13, Blocks.log, 0);
		setBlock(world, i + 0, j + 4, k + 14, Blocks.log, 0);
		setBlock(world, i + 0, j + 4, k + 15, Blocks.log, 0);
		setBlock(world, i + 0, j + 5, k + 12, Blocks.log, 0);
		setBlock(world, i + 0, j + 5, k + 13, Blocks.log, 0);
		setBlock(world, i + 0, j + 5, k + 14, Blocks.log, 0);
		setBlock(world, i + 0, j + 6, k + 12, Blocks.log, 0);
		setBlock(world, i + 1, j + 3, k + 14, Blocks.log, 0);
		setBlock(world, i + 1, j + 4, k + 13, Blocks.log, 0);
		setBlock(world, i + 1, j + 4, k + 14, Blocks.log, 0);
		setBlock(world, i + 1, j + 4, k + 15, Blocks.log, 0);
		setBlock(world, i + 1, j + 5, k + 11, Blocks.log, 0);
		setBlock(world, i + 1, j + 5, k + 12, Blocks.log, 0);
		setBlock(world, i + 1, j + 5, k + 13, Blocks.log, 0);
		setBlock(world, i + 1, j + 5, k + 14, Blocks.log, 0);
		setBlock(world, i + 1, j + 5, k + 15, Blocks.log, 0);
		setBlock(world, i + 1, j + 6, k + 11, Blocks.log, 0);
		setBlock(world, i + 1, j + 6, k + 12, Blocks.log, 0);
		setBlock(world, i + 1, j + 6, k + 13, Blocks.log, 0);
		setBlock(world, i + 1, j + 7, k + 12, Blocks.log, 0);
		setBlock(world, i + 1, j + 33, k + 2, Blocks.log, 0);
		setBlock(world, i + 1, j + 34, k + 2, Blocks.log, 0);
		setBlock(world, i + 1, j + 35, k + 2, Blocks.log, 0);
		setBlock(world, i + 1, j + 36, k + 2, Blocks.log, 0);
		setBlock(world, i + 1, j + 37, k + 2, Blocks.log, 0);
		setBlock(world, i + 1, j + 43, k + 0, Blocks.log, 0);
		setBlock(world, i + 1, j + 46, k + 8, Blocks.log, 0);
		setBlock(world, i + 1, j + 47, k + 6, Blocks.log, 0);
		setBlock(world, i + 1, j + 47, k + 7, Blocks.log, 0);
		setBlock(world, i + 1, j + 47, k + 8, Blocks.log, 0);
		setBlock(world, i + 2, j + 4, k + 14, Blocks.log, 0);
		setBlock(world, i + 2, j + 5, k + 12, Blocks.log, 0);
		setBlock(world, i + 2, j + 5, k + 13, Blocks.log, 0);
		setBlock(world, i + 2, j + 5, k + 14, Blocks.log, 0);
		setBlock(world, i + 2, j + 6, k + 10, Blocks.log, 0);
		setBlock(world, i + 2, j + 6, k + 11, Blocks.log, 0);
		setBlock(world, i + 2, j + 6, k + 12, Blocks.log, 0);
		setBlock(world, i + 2, j + 6, k + 13, Blocks.log, 0);
		setBlock(world, i + 2, j + 6, k + 14, Blocks.log, 0);
		setBlock(world, i + 2, j + 7, k + 11, Blocks.log, 0);
		setBlock(world, i + 2, j + 7, k + 12, Blocks.log, 0);
		setBlock(world, i + 2, j + 7, k + 13, Blocks.log, 0);
		setBlock(world, i + 2, j + 8, k + 11, Blocks.log, 0);
		setBlock(world, i + 2, j + 29, k + 1, Blocks.log, 0);
		setBlock(world, i + 2, j + 30, k + 0, Blocks.log, 0);
		setBlock(world, i + 2, j + 35, k + 3, Blocks.log, 0);
		setBlock(world, i + 2, j + 36, k + 3, Blocks.log, 0);
		setBlock(world, i + 2, j + 43, k + 4, Blocks.log, 0);
		setBlock(world, i + 2, j + 44, k + 8, Blocks.log, 0);
		setBlock(world, i + 2, j + 45, k + 1, Blocks.log, 0);
		setBlock(world, i + 2, j + 45, k + 8, Blocks.log, 0);
		setBlock(world, i + 2, j + 46, k + 3, Blocks.log, 0);
		setBlock(world, i + 3, j + 5, k + 13, Blocks.log, 0);
		setBlock(world, i + 3, j + 6, k + 11, Blocks.log, 0);
		setBlock(world, i + 3, j + 6, k + 12, Blocks.log, 0);
		setBlock(world, i + 3, j + 6, k + 13, Blocks.log, 0);
		setBlock(world, i + 3, j + 7, k + 10, Blocks.log, 0);
		setBlock(world, i + 3, j + 7, k + 11, Blocks.log, 0);
		setBlock(world, i + 3, j + 7, k + 12, Blocks.log, 0);
		setBlock(world, i + 3, j + 7, k + 13, Blocks.log, 0);
		setBlock(world, i + 3, j + 7, k + 14, Blocks.log, 0);
		setBlock(world, i + 3, j + 8, k + 10, Blocks.log, 0);
		setBlock(world, i + 3, j + 8, k + 11, Blocks.log, 0);
		setBlock(world, i + 3, j + 8, k + 12, Blocks.log, 0);
		setBlock(world, i + 3, j + 9, k + 10, Blocks.log, 0);
		setBlock(world, i + 3, j + 29, k + 2, Blocks.log, 0);
		setBlock(world, i + 3, j + 35, k + 4, Blocks.log, 0);
		setBlock(world, i + 3, j + 36, k + 4, Blocks.log, 0);
		setBlock(world, i + 3, j + 40, k + 12, Blocks.log, 0);
		setBlock(world, i + 3, j + 41, k + 12, Blocks.log, 0);
		setBlock(world, i + 3, j + 42, k + 8, Blocks.log, 0);
		setBlock(world, i + 3, j + 43, k + 8, Blocks.log, 0);
		setBlock(world, i + 3, j + 45, k + 13, Blocks.log, 0);
		setBlock(world, i + 4, j + 0, k + 7, Blocks.log, 0);
		setBlock(world, i + 4, j + 0, k + 8, Blocks.log, 0);
		setBlock(world, i + 4, j + 0, k + 9, Blocks.log, 0);
		setBlock(world, i + 4, j + 1, k + 8, Blocks.log, 0);
		setBlock(world, i + 4, j + 2, k + 8, Blocks.log, 0);
		setBlock(world, i + 4, j + 3, k + 8, Blocks.log, 0);
		setBlock(world, i + 4, j + 6, k + 12, Blocks.log, 0);
		setBlock(world, i + 4, j + 7, k + 11, Blocks.log, 0);
		setBlock(world, i + 4, j + 7, k + 12, Blocks.log, 0);
		setBlock(world, i + 4, j + 7, k + 13, Blocks.log, 0);
		setBlock(world, i + 4, j + 8, k + 9, Blocks.log, 0);
		setBlock(world, i + 4, j + 8, k + 10, Blocks.log, 0);
		setBlock(world, i + 4, j + 8, k + 11, Blocks.log, 0);
		setBlock(world, i + 4, j + 8, k + 12, Blocks.log, 0);
		setBlock(world, i + 4, j + 8, k + 13, Blocks.log, 0);
		setBlock(world, i + 4, j + 9, k + 9, Blocks.log, 0);
		setBlock(world, i + 4, j + 9, k + 10, Blocks.log, 0);
		setBlock(world, i + 4, j + 9, k + 11, Blocks.log, 0);
		setBlock(world, i + 4, j + 10, k + 10, Blocks.log, 0);
		setBlock(world, i + 4, j + 28, k + 3, Blocks.log, 0);
		setBlock(world, i + 4, j + 32, k + 5, Blocks.log, 0);
		setBlock(world, i + 4, j + 33, k + 5, Blocks.log, 0);
		setBlock(world, i + 4, j + 34, k + 5, Blocks.log, 0);
		setBlock(world, i + 4, j + 35, k + 5, Blocks.log, 0);
		setBlock(world, i + 4, j + 36, k + 5, Blocks.log, 0);
		setBlock(world, i + 4, j + 39, k + 11, Blocks.log, 0);
		setBlock(world, i + 4, j + 40, k + 8, Blocks.log, 0);
		setBlock(world, i + 4, j + 41, k + 8, Blocks.log, 0);
		setBlock(world, i + 4, j + 42, k + 8, Blocks.log, 0);
		setBlock(world, i + 5, j + 0, k + 6, Blocks.log, 0);
		setBlock(world, i + 5, j + 0, k + 7, Blocks.log, 0);
		setBlock(world, i + 5, j + 0, k + 8, Blocks.log, 0);
		setBlock(world, i + 5, j + 0, k + 9, Blocks.log, 0);
		setBlock(world, i + 5, j + 0, k + 10, Blocks.log, 0);
		setBlock(world, i + 5, j + 1, k + 6, Blocks.log, 0);
		setBlock(world, i + 5, j + 1, k + 7, Blocks.log, 0);
		setBlock(world, i + 5, j + 1, k + 8, Blocks.log, 0);
		setBlock(world, i + 5, j + 1, k + 9, Blocks.log, 0);
		setBlock(world, i + 5, j + 1, k + 10, Blocks.log, 0);
		setBlock(world, i + 5, j + 2, k + 6, Blocks.log, 0);
		setBlock(world, i + 5, j + 2, k + 7, Blocks.log, 0);
		setBlock(world, i + 5, j + 2, k + 8, Blocks.log, 0);
		setBlock(world, i + 5, j + 2, k + 9, Blocks.log, 0);
		setBlock(world, i + 5, j + 2, k + 10, Blocks.log, 0);
		setBlock(world, i + 5, j + 3, k + 6, Blocks.log, 0);
		setBlock(world, i + 5, j + 3, k + 7, Blocks.log, 0);
		setBlock(world, i + 5, j + 3, k + 8, Blocks.log, 0);
		setBlock(world, i + 5, j + 3, k + 9, Blocks.log, 0);
		setBlock(world, i + 5, j + 3, k + 10, Blocks.log, 0);
		setBlock(world, i + 5, j + 4, k + 6, Blocks.log, 0);
		setBlock(world, i + 5, j + 4, k + 7, Blocks.log, 0);
		setBlock(world, i + 5, j + 4, k + 8, Blocks.log, 0);
		setBlock(world, i + 5, j + 4, k + 9, Blocks.log, 0);
		setBlock(world, i + 5, j + 4, k + 10, Blocks.log, 0);
		setBlock(world, i + 5, j + 5, k + 6, Blocks.log, 0);
		setBlock(world, i + 5, j + 5, k + 7, Blocks.log, 0);
		setBlock(world, i + 5, j + 5, k + 8, Blocks.log, 0);
		setBlock(world, i + 5, j + 5, k + 9, Blocks.log, 0);
		setBlock(world, i + 5, j + 5, k + 10, Blocks.log, 0);
		setBlock(world, i + 5, j + 6, k + 6, Blocks.log, 0);
		setBlock(world, i + 5, j + 6, k + 7, Blocks.log, 0);
		setBlock(world, i + 5, j + 6, k + 8, Blocks.log, 0);
		setBlock(world, i + 5, j + 6, k + 9, Blocks.log, 0);
		setBlock(world, i + 5, j + 6, k + 10, Blocks.log, 0);
		setBlock(world, i + 5, j + 7, k + 7, Blocks.log, 0);
		setBlock(world, i + 5, j + 7, k + 8, Blocks.log, 0);
		setBlock(world, i + 5, j + 7, k + 9, Blocks.log, 0);
		setBlock(world, i + 5, j + 7, k + 12, Blocks.log, 0);
		setBlock(world, i + 5, j + 8, k + 7, Blocks.log, 0);
		setBlock(world, i + 5, j + 8, k + 8, Blocks.log, 0);
		setBlock(world, i + 5, j + 8, k + 9, Blocks.log, 0);
		setBlock(world, i + 5, j + 8, k + 10, Blocks.log, 0);
		setBlock(world, i + 5, j + 8, k + 11, Blocks.log, 0);
		setBlock(world, i + 5, j + 8, k + 12, Blocks.log, 0);
		setBlock(world, i + 5, j + 9, k + 7, Blocks.log, 0);
		setBlock(world, i + 5, j + 9, k + 8, Blocks.log, 0);
		setBlock(world, i + 5, j + 9, k + 9, Blocks.log, 0);
		setBlock(world, i + 5, j + 9, k + 10, Blocks.log, 0);
		setBlock(world, i + 5, j + 9, k + 11, Blocks.log, 0);
		setBlock(world, i + 5, j + 9, k + 12, Blocks.log, 0);
		setBlock(world, i + 5, j + 10, k + 7, Blocks.log, 0);
		setBlock(world, i + 5, j + 10, k + 8, Blocks.log, 0);
		setBlock(world, i + 5, j + 10, k + 9, Blocks.log, 0);
		setBlock(world, i + 5, j + 10, k + 10, Blocks.log, 0);
		setBlock(world, i + 5, j + 10, k + 11, Blocks.log, 0);
		setBlock(world, i + 5, j + 11, k + 7, Blocks.log, 0);
		setBlock(world, i + 5, j + 11, k + 8, Blocks.log, 0);
		setBlock(world, i + 5, j + 11, k + 9, Blocks.log, 0);
		setBlock(world, i + 5, j + 12, k + 7, Blocks.log, 0);
		setBlock(world, i + 5, j + 12, k + 8, Blocks.log, 0);
		setBlock(world, i + 5, j + 12, k + 9, Blocks.log, 0);
		setBlock(world, i + 5, j + 13, k + 8, Blocks.log, 0);
		setBlock(world, i + 5, j + 14, k + 8, Blocks.log, 0);
		setBlock(world, i + 5, j + 15, k + 8, Blocks.log, 0);
		setBlock(world, i + 5, j + 25, k + 10, Blocks.log, 0);
		setBlock(world, i + 5, j + 28, k + 4, Blocks.log, 0);
		setBlock(world, i + 5, j + 34, k + 6, Blocks.log, 0);
		setBlock(world, i + 5, j + 35, k + 6, Blocks.log, 0);
		setBlock(world, i + 5, j + 36, k + 6, Blocks.log, 0);
		setBlock(world, i + 5, j + 38, k + 8, Blocks.log, 0);
		setBlock(world, i + 5, j + 38, k + 11, Blocks.log, 0);
		setBlock(world, i + 5, j + 39, k + 8, Blocks.log, 0);
		setBlock(world, i + 5, j + 40, k + 8, Blocks.log, 0);
		setBlock(world, i + 5, j + 43, k + 6, Blocks.log, 0);
		setBlock(world, i + 5, j + 44, k + 6, Blocks.log, 0);
		setBlock(world, i + 5, j + 45, k + 6, Blocks.log, 0);
		setBlock(world, i + 5, j + 46, k + 6, Blocks.log, 0);
		setBlock(world, i + 5, j + 47, k + 5, Blocks.log, 0);
		setBlock(world, i + 6, j + 0, k + 5, Blocks.log, 0);
		setBlock(world, i + 6, j + 0, k + 6, Blocks.log, 0);
		setBlock(world, i + 6, j + 0, k + 7, Blocks.log, 0);
		setBlock(world, i + 6, j + 0, k + 8, Blocks.log, 0);
		setBlock(world, i + 6, j + 0, k + 9, Blocks.log, 0);
		setBlock(world, i + 6, j + 0, k + 10, Blocks.log, 0);
		setBlock(world, i + 6, j + 0, k + 11, Blocks.log, 0);
		setBlock(world, i + 6, j + 1, k + 5, Blocks.log, 0);
		setBlock(world, i + 6, j + 1, k + 6, Blocks.log, 0);
		setBlock(world, i + 6, j + 1, k + 7, Blocks.log, 0);
		setBlock(world, i + 6, j + 1, k + 8, Blocks.log, 0);
		setBlock(world, i + 6, j + 1, k + 9, Blocks.log, 0);
		setBlock(world, i + 6, j + 1, k + 10, Blocks.log, 0);
		setBlock(world, i + 6, j + 1, k + 11, Blocks.log, 0);
		setBlock(world, i + 6, j + 2, k + 5, Blocks.log, 0);
		setBlock(world, i + 6, j + 2, k + 6, Blocks.log, 0);
		setBlock(world, i + 6, j + 2, k + 7, Blocks.log, 0);
		setBlock(world, i + 6, j + 2, k + 8, Blocks.log, 0);
		setBlock(world, i + 6, j + 2, k + 9, Blocks.log, 0);
		setBlock(world, i + 6, j + 2, k + 10, Blocks.log, 0);
		setBlock(world, i + 6, j + 2, k + 11, Blocks.log, 0);
		setBlock(world, i + 6, j + 3, k + 5, Blocks.log, 0);
		setBlock(world, i + 6, j + 3, k + 6, Blocks.log, 0);
		setBlock(world, i + 6, j + 3, k + 7, Blocks.log, 0);
		setBlock(world, i + 6, j + 3, k + 8, Blocks.log, 0);
		setBlock(world, i + 6, j + 3, k + 9, Blocks.log, 0);
		setBlock(world, i + 6, j + 3, k + 10, Blocks.log, 0);
		setBlock(world, i + 6, j + 3, k + 11, Blocks.log, 0);
		setBlock(world, i + 6, j + 4, k + 5, Blocks.log, 0);
		setBlock(world, i + 6, j + 4, k + 6, Blocks.log, 0);
		setBlock(world, i + 6, j + 4, k + 7, Blocks.log, 0);
		setBlock(world, i + 6, j + 4, k + 8, Blocks.log, 0);
		setBlock(world, i + 6, j + 4, k + 9, Blocks.log, 0);
		setBlock(world, i + 6, j + 4, k + 10, Blocks.log, 0);
		setBlock(world, i + 6, j + 4, k + 11, Blocks.log, 0);
		setBlock(world, i + 6, j + 5, k + 5, Blocks.log, 0);
		setBlock(world, i + 6, j + 5, k + 6, Blocks.log, 0);
		setBlock(world, i + 6, j + 5, k + 7, Blocks.log, 0);
		setBlock(world, i + 6, j + 5, k + 8, Blocks.log, 0);
		setBlock(world, i + 6, j + 5, k + 9, Blocks.log, 0);
		setBlock(world, i + 6, j + 5, k + 10, Blocks.log, 0);
		setBlock(world, i + 6, j + 5, k + 11, Blocks.log, 0);
		setBlock(world, i + 6, j + 6, k + 5, Blocks.log, 0);
		setBlock(world, i + 6, j + 6, k + 6, Blocks.log, 0);
		setBlock(world, i + 6, j + 6, k + 7, Blocks.log, 0);
		setBlock(world, i + 6, j + 6, k + 8, Blocks.log, 0);
		setBlock(world, i + 6, j + 6, k + 9, Blocks.log, 0);
		setBlock(world, i + 6, j + 6, k + 10, Blocks.log, 0);
		setBlock(world, i + 6, j + 6, k + 11, Blocks.log, 0);
		setBlock(world, i + 6, j + 7, k + 6, Blocks.log, 0);
		setBlock(world, i + 6, j + 7, k + 7, Blocks.log, 0);
		setBlock(world, i + 6, j + 7, k + 8, Blocks.log, 0);
		setBlock(world, i + 6, j + 7, k + 9, Blocks.log, 0);
		setBlock(world, i + 6, j + 7, k + 10, Blocks.log, 0);
		setBlock(world, i + 6, j + 8, k + 6, Blocks.log, 0);
		setBlock(world, i + 6, j + 8, k + 7, Blocks.log, 0);
		setBlock(world, i + 6, j + 8, k + 8, Blocks.log, 0);
		setBlock(world, i + 6, j + 8, k + 9, Blocks.log, 0);
		setBlock(world, i + 6, j + 8, k + 10, Blocks.log, 0);
		setBlock(world, i + 6, j + 8, k + 11, Blocks.log, 0);
		setBlock(world, i + 6, j + 9, k + 6, Blocks.log, 0);
		setBlock(world, i + 6, j + 9, k + 7, Blocks.log, 0);
		setBlock(world, i + 6, j + 9, k + 8, Blocks.log, 0);
		setBlock(world, i + 6, j + 9, k + 9, Blocks.log, 0);
		setBlock(world, i + 6, j + 9, k + 10, Blocks.log, 0);
		setBlock(world, i + 6, j + 9, k + 11, Blocks.log, 0);
		setBlock(world, i + 6, j + 10, k + 6, Blocks.log, 0);
		setBlock(world, i + 6, j + 10, k + 7, Blocks.log, 0);
		setBlock(world, i + 6, j + 10, k + 8, Blocks.log, 0);
		setBlock(world, i + 6, j + 10, k + 9, Blocks.log, 0);
		setBlock(world, i + 6, j + 10, k + 10, Blocks.log, 0);
		setBlock(world, i + 6, j + 10, k + 11, Blocks.log, 0);
		setBlock(world, i + 6, j + 10, k + 12, Blocks.log, 0);
		setBlock(world, i + 6, j + 11, k + 6, Blocks.log, 0);
		setBlock(world, i + 6, j + 11, k + 7, Blocks.log, 0);
		setBlock(world, i + 6, j + 11, k + 8, Blocks.log, 0);
		setBlock(world, i + 6, j + 11, k + 9, Blocks.log, 0);
		setBlock(world, i + 6, j + 11, k + 10, Blocks.log, 0);
		setBlock(world, i + 6, j + 12, k + 6, Blocks.log, 0);
		setBlock(world, i + 6, j + 12, k + 7, Blocks.log, 0);
		setBlock(world, i + 6, j + 12, k + 8, Blocks.log, 0);
		setBlock(world, i + 6, j + 12, k + 9, Blocks.log, 0);
		setBlock(world, i + 6, j + 12, k + 10, Blocks.log, 0);
		setBlock(world, i + 6, j + 13, k + 6, Blocks.log, 0);
		setBlock(world, i + 6, j + 13, k + 7, Blocks.log, 0);
		setBlock(world, i + 6, j + 13, k + 8, Blocks.log, 0);
		setBlock(world, i + 6, j + 13, k + 9, Blocks.log, 0);
		setBlock(world, i + 6, j + 13, k + 10, Blocks.log, 0);
		setBlock(world, i + 6, j + 14, k + 6, Blocks.log, 0);
		setBlock(world, i + 6, j + 14, k + 7, Blocks.log, 0);
		setBlock(world, i + 6, j + 14, k + 8, Blocks.log, 0);
		setBlock(world, i + 6, j + 14, k + 9, Blocks.log, 0);
		setBlock(world, i + 6, j + 14, k + 10, Blocks.log, 0);
		setBlock(world, i + 6, j + 15, k + 6, Blocks.log, 0);
		setBlock(world, i + 6, j + 15, k + 7, Blocks.log, 0);
		setBlock(world, i + 6, j + 15, k + 8, Blocks.log, 0);
		setBlock(world, i + 6, j + 15, k + 9, Blocks.log, 0);
		setBlock(world, i + 6, j + 15, k + 10, Blocks.log, 0);
		setBlock(world, i + 6, j + 16, k + 7, Blocks.log, 0);
		setBlock(world, i + 6, j + 16, k + 8, Blocks.log, 0);
		setBlock(world, i + 6, j + 16, k + 9, Blocks.log, 0);
		setBlock(world, i + 6, j + 17, k + 7, Blocks.log, 0);
		setBlock(world, i + 6, j + 17, k + 8, Blocks.log, 0);
		setBlock(world, i + 6, j + 17, k + 9, Blocks.log, 0);
		setBlock(world, i + 6, j + 18, k + 7, Blocks.log, 0);
		setBlock(world, i + 6, j + 18, k + 8, Blocks.log, 0);
		setBlock(world, i + 6, j + 18, k + 9, Blocks.log, 0);
		setBlock(world, i + 6, j + 19, k + 7, Blocks.log, 0);
		setBlock(world, i + 6, j + 19, k + 8, Blocks.log, 0);
		setBlock(world, i + 6, j + 19, k + 9, Blocks.log, 0);
		setBlock(world, i + 6, j + 20, k + 7, Blocks.log, 0);
		setBlock(world, i + 6, j + 20, k + 8, Blocks.log, 0);
		setBlock(world, i + 6, j + 20, k + 9, Blocks.log, 0);
		setBlock(world, i + 6, j + 21, k + 7, Blocks.log, 0);
		setBlock(world, i + 6, j + 21, k + 8, Blocks.log, 0);
		setBlock(world, i + 6, j + 21, k + 9, Blocks.log, 0);
		setBlock(world, i + 6, j + 22, k + 7, Blocks.log, 0);
		setBlock(world, i + 6, j + 22, k + 8, Blocks.log, 0);
		setBlock(world, i + 6, j + 22, k + 9, Blocks.log, 0);
		setBlock(world, i + 6, j + 23, k + 8, Blocks.log, 0);
		setBlock(world, i + 6, j + 24, k + 8, Blocks.log, 0);
		setBlock(world, i + 6, j + 24, k + 10, Blocks.log, 0);
		setBlock(world, i + 6, j + 25, k + 8, Blocks.log, 0);
		setBlock(world, i + 6, j + 26, k + 8, Blocks.log, 0);
		setBlock(world, i + 6, j + 27, k + 5, Blocks.log, 0);
		setBlock(world, i + 6, j + 28, k + 5, Blocks.log, 0);
		setBlock(world, i + 6, j + 28, k + 6, Blocks.log, 0);
		setBlock(world, i + 6, j + 29, k + 4, Blocks.log, 0);
		setBlock(world, i + 6, j + 34, k + 7, Blocks.log, 0);
		setBlock(world, i + 6, j + 36, k + 8, Blocks.log, 0);
		setBlock(world, i + 6, j + 37, k + 8, Blocks.log, 0);
		setBlock(world, i + 6, j + 37, k + 10, Blocks.log, 0);
		setBlock(world, i + 6, j + 38, k + 8, Blocks.log, 0);
		setBlock(world, i + 6, j + 39, k + 7, Blocks.log, 0);
		setBlock(world, i + 6, j + 40, k + 2, Blocks.log, 0);
		setBlock(world, i + 6, j + 40, k + 7, Blocks.log, 0);
		setBlock(world, i + 6, j + 41, k + 7, Blocks.log, 0);
		setBlock(world, i + 6, j + 41, k + 12, Blocks.log, 0);
		setBlock(world, i + 6, j + 42, k + 7, Blocks.log, 0);
		setBlock(world, i + 6, j + 42, k + 12, Blocks.log, 0);
		setBlock(world, i + 6, j + 43, k + 12, Blocks.log, 0);
		setBlock(world, i + 6, j + 44, k + 13, Blocks.log, 0);
		setBlock(world, i + 6, j + 45, k + 13, Blocks.log, 0);
		setBlock(world, i + 6, j + 46, k + 13, Blocks.log, 0);
		setBlock(world, i + 6, j + 47, k + 3, Blocks.log, 0);
		setBlock(world, i + 6, j + 47, k + 11, Blocks.log, 0);
		setBlock(world, i + 6, j + 47, k + 13, Blocks.log, 0);
		setBlock(world, i + 7, j + 0, k + 4, Blocks.log, 0);
		setBlock(world, i + 7, j + 0, k + 5, Blocks.log, 0);
		setBlock(world, i + 7, j + 0, k + 6, Blocks.log, 0);
		setBlock(world, i + 7, j + 0, k + 7, Blocks.log, 0);
		setBlock(world, i + 7, j + 0, k + 8, Blocks.log, 0);
		setBlock(world, i + 7, j + 0, k + 9, Blocks.log, 0);
		setBlock(world, i + 7, j + 0, k + 10, Blocks.log, 0);
		setBlock(world, i + 7, j + 0, k + 11, Blocks.log, 0);
		setBlock(world, i + 7, j + 0, k + 12, Blocks.log, 0);
		setBlock(world, i + 7, j + 1, k + 5, Blocks.log, 0);
		setBlock(world, i + 7, j + 1, k + 6, Blocks.log, 0);
		setBlock(world, i + 7, j + 1, k + 7, Blocks.log, 0);
		setBlock(world, i + 7, j + 1, k + 8, Blocks.log, 0);
		setBlock(world, i + 7, j + 1, k + 9, Blocks.log, 0);
		setBlock(world, i + 7, j + 1, k + 10, Blocks.log, 0);
		setBlock(world, i + 7, j + 1, k + 11, Blocks.log, 0);
		setBlock(world, i + 7, j + 2, k + 5, Blocks.log, 0);
		setBlock(world, i + 7, j + 2, k + 6, Blocks.log, 0);
		setBlock(world, i + 7, j + 2, k + 7, Blocks.log, 0);
		setBlock(world, i + 7, j + 2, k + 8, Blocks.log, 0);
		setBlock(world, i + 7, j + 2, k + 9, Blocks.log, 0);
		setBlock(world, i + 7, j + 2, k + 10, Blocks.log, 0);
		setBlock(world, i + 7, j + 2, k + 11, Blocks.log, 0);
		setBlock(world, i + 7, j + 3, k + 5, Blocks.log, 0);
		setBlock(world, i + 7, j + 3, k + 6, Blocks.log, 0);
		setBlock(world, i + 7, j + 3, k + 7, Blocks.log, 0);
		setBlock(world, i + 7, j + 3, k + 8, Blocks.log, 0);
		setBlock(world, i + 7, j + 3, k + 9, Blocks.log, 0);
		setBlock(world, i + 7, j + 3, k + 10, Blocks.log, 0);
		setBlock(world, i + 7, j + 3, k + 11, Blocks.log, 0);
		setBlock(world, i + 7, j + 4, k + 5, Blocks.log, 0);
		setBlock(world, i + 7, j + 4, k + 6, Blocks.log, 0);
		setBlock(world, i + 7, j + 4, k + 7, Blocks.log, 0);
		setBlock(world, i + 7, j + 4, k + 8, Blocks.log, 0);
		setBlock(world, i + 7, j + 4, k + 9, Blocks.log, 0);
		setBlock(world, i + 7, j + 4, k + 10, Blocks.log, 0);
		setBlock(world, i + 7, j + 4, k + 11, Blocks.log, 0);
		setBlock(world, i + 7, j + 4, k + 12, Blocks.log, 0);
		setBlock(world, i + 7, j + 5, k + 5, Blocks.log, 0);
		setBlock(world, i + 7, j + 5, k + 6, Blocks.log, 0);
		setBlock(world, i + 7, j + 5, k + 7, Blocks.log, 0);
		setBlock(world, i + 7, j + 5, k + 8, Blocks.log, 0);
		setBlock(world, i + 7, j + 5, k + 9, Blocks.log, 0);
		setBlock(world, i + 7, j + 5, k + 10, Blocks.log, 0);
		setBlock(world, i + 7, j + 5, k + 11, Blocks.log, 0);
		setBlock(world, i + 7, j + 5, k + 13, Blocks.log, 0);
		setBlock(world, i + 7, j + 6, k + 5, Blocks.log, 0);
		setBlock(world, i + 7, j + 6, k + 6, Blocks.log, 0);
		setBlock(world, i + 7, j + 6, k + 7, Blocks.log, 0);
		setBlock(world, i + 7, j + 6, k + 8, Blocks.log, 0);
		setBlock(world, i + 7, j + 6, k + 9, Blocks.log, 0);
		setBlock(world, i + 7, j + 6, k + 10, Blocks.log, 0);
		setBlock(world, i + 7, j + 6, k + 11, Blocks.log, 0);
		setBlock(world, i + 7, j + 7, k + 5, Blocks.log, 0);
		setBlock(world, i + 7, j + 7, k + 6, Blocks.log, 0);
		setBlock(world, i + 7, j + 7, k + 7, Blocks.log, 0);
		setBlock(world, i + 7, j + 7, k + 8, Blocks.log, 0);
		setBlock(world, i + 7, j + 7, k + 9, Blocks.log, 0);
		setBlock(world, i + 7, j + 7, k + 10, Blocks.log, 0);
		setBlock(world, i + 7, j + 7, k + 11, Blocks.log, 0);
		setBlock(world, i + 7, j + 8, k + 5, Blocks.log, 0);
		setBlock(world, i + 7, j + 8, k + 6, Blocks.log, 0);
		setBlock(world, i + 7, j + 8, k + 7, Blocks.log, 0);
		setBlock(world, i + 7, j + 8, k + 8, Blocks.log, 0);
		setBlock(world, i + 7, j + 8, k + 9, Blocks.log, 0);
		setBlock(world, i + 7, j + 8, k + 10, Blocks.log, 0);
		setBlock(world, i + 7, j + 8, k + 11, Blocks.log, 0);
		setBlock(world, i + 7, j + 9, k + 5, Blocks.log, 0);
		setBlock(world, i + 7, j + 9, k + 6, Blocks.log, 0);
		setBlock(world, i + 7, j + 9, k + 7, Blocks.log, 0);
		setBlock(world, i + 7, j + 9, k + 8, Blocks.log, 0);
		setBlock(world, i + 7, j + 9, k + 9, Blocks.log, 0);
		setBlock(world, i + 7, j + 9, k + 10, Blocks.log, 0);
		setBlock(world, i + 7, j + 9, k + 11, Blocks.log, 0);
		setBlock(world, i + 7, j + 10, k + 5, Blocks.log, 0);
		setBlock(world, i + 7, j + 10, k + 6, Blocks.log, 0);
		setBlock(world, i + 7, j + 10, k + 7, Blocks.log, 0);
		setBlock(world, i + 7, j + 10, k + 8, Blocks.log, 0);
		setBlock(world, i + 7, j + 10, k + 9, Blocks.log, 0);
		setBlock(world, i + 7, j + 10, k + 10, Blocks.log, 0);
		setBlock(world, i + 7, j + 10, k + 11, Blocks.log, 0);
		setBlock(world, i + 7, j + 11, k + 5, Blocks.log, 0);
		setBlock(world, i + 7, j + 11, k + 6, Blocks.log, 0);
		setBlock(world, i + 7, j + 11, k + 7, Blocks.log, 0);
		setBlock(world, i + 7, j + 11, k + 8, Blocks.log, 0);
		setBlock(world, i + 7, j + 11, k + 9, Blocks.log, 0);
		setBlock(world, i + 7, j + 11, k + 10, Blocks.log, 0);
		setBlock(world, i + 7, j + 11, k + 11, Blocks.log, 0);
		setBlock(world, i + 7, j + 12, k + 5, Blocks.log, 0);
		setBlock(world, i + 7, j + 12, k + 6, Blocks.log, 0);
		setBlock(world, i + 7, j + 12, k + 7, Blocks.log, 0);
		setBlock(world, i + 7, j + 12, k + 8, Blocks.log, 0);
		setBlock(world, i + 7, j + 12, k + 9, Blocks.log, 0);
		setBlock(world, i + 7, j + 12, k + 10, Blocks.log, 0);
		setBlock(world, i + 7, j + 12, k + 11, Blocks.log, 0);
		setBlock(world, i + 7, j + 13, k + 6, Blocks.log, 0);
		setBlock(world, i + 7, j + 13, k + 7, Blocks.log, 0);
		setBlock(world, i + 7, j + 13, k + 8, Blocks.log, 0);
		setBlock(world, i + 7, j + 13, k + 9, Blocks.log, 0);
		setBlock(world, i + 7, j + 13, k + 10, Blocks.log, 0);
		setBlock(world, i + 7, j + 14, k + 6, Blocks.log, 0);
		setBlock(world, i + 7, j + 14, k + 7, Blocks.log, 0);
		setBlock(world, i + 7, j + 14, k + 8, Blocks.log, 0);
		setBlock(world, i + 7, j + 14, k + 9, Blocks.log, 0);
		setBlock(world, i + 7, j + 14, k + 10, Blocks.log, 0);
		setBlock(world, i + 7, j + 15, k + 6, Blocks.log, 0);
		setBlock(world, i + 7, j + 15, k + 7, Blocks.log, 0);
		setBlock(world, i + 7, j + 15, k + 8, Blocks.log, 0);
		setBlock(world, i + 7, j + 15, k + 9, Blocks.log, 0);
		setBlock(world, i + 7, j + 15, k + 10, Blocks.log, 0);
		setBlock(world, i + 7, j + 16, k + 6, Blocks.log, 0);
		setBlock(world, i + 7, j + 16, k + 7, Blocks.log, 0);
		setBlock(world, i + 7, j + 16, k + 8, Blocks.log, 0);
		setBlock(world, i + 7, j + 16, k + 9, Blocks.log, 0);
		setBlock(world, i + 7, j + 16, k + 10, Blocks.log, 0);
		setBlock(world, i + 7, j + 17, k + 6, Blocks.log, 0);
		setBlock(world, i + 7, j + 17, k + 7, Blocks.log, 0);
		setBlock(world, i + 7, j + 17, k + 8, Blocks.log, 0);
		setBlock(world, i + 7, j + 17, k + 9, Blocks.log, 0);
		setBlock(world, i + 7, j + 17, k + 10, Blocks.log, 0);
		setBlock(world, i + 7, j + 18, k + 6, Blocks.log, 0);
		setBlock(world, i + 7, j + 18, k + 7, Blocks.log, 0);
		setBlock(world, i + 7, j + 18, k + 8, Blocks.log, 0);
		setBlock(world, i + 7, j + 18, k + 9, Blocks.log, 0);
		setBlock(world, i + 7, j + 18, k + 10, Blocks.log, 0);
		setBlock(world, i + 7, j + 19, k + 6, Blocks.log, 0);
		setBlock(world, i + 7, j + 19, k + 7, Blocks.log, 0);
		setBlock(world, i + 7, j + 19, k + 8, Blocks.log, 0);
		setBlock(world, i + 7, j + 19, k + 9, Blocks.log, 0);
		setBlock(world, i + 7, j + 19, k + 10, Blocks.log, 0);
		setBlock(world, i + 7, j + 20, k + 6, Blocks.log, 0);
		setBlock(world, i + 7, j + 20, k + 7, Blocks.log, 0);
		setBlock(world, i + 7, j + 20, k + 8, Blocks.log, 0);
		setBlock(world, i + 7, j + 20, k + 9, Blocks.log, 0);
		setBlock(world, i + 7, j + 20, k + 10, Blocks.log, 0);
		setBlock(world, i + 7, j + 21, k + 6, Blocks.log, 0);
		setBlock(world, i + 7, j + 21, k + 7, Blocks.log, 0);
		setBlock(world, i + 7, j + 21, k + 8, Blocks.log, 0);
		setBlock(world, i + 7, j + 21, k + 9, Blocks.log, 0);
		setBlock(world, i + 7, j + 21, k + 10, Blocks.log, 0);
		setBlock(world, i + 7, j + 22, k + 6, Blocks.log, 0);
		setBlock(world, i + 7, j + 22, k + 7, Blocks.log, 0);
		setBlock(world, i + 7, j + 22, k + 8, Blocks.log, 0);
		setBlock(world, i + 7, j + 22, k + 9, Blocks.log, 0);
		setBlock(world, i + 7, j + 22, k + 10, Blocks.log, 0);
		setBlock(world, i + 7, j + 23, k + 7, Blocks.log, 0);
		setBlock(world, i + 7, j + 23, k + 8, Blocks.log, 0);
		setBlock(world, i + 7, j + 23, k + 9, Blocks.log, 0);
		setBlock(world, i + 7, j + 23, k + 10, Blocks.log, 0);
		setBlock(world, i + 7, j + 24, k + 7, Blocks.log, 0);
		setBlock(world, i + 7, j + 24, k + 8, Blocks.log, 0);
		setBlock(world, i + 7, j + 24, k + 9, Blocks.log, 0);
		setBlock(world, i + 7, j + 25, k + 7, Blocks.log, 0);
		setBlock(world, i + 7, j + 25, k + 8, Blocks.log, 0);
		setBlock(world, i + 7, j + 25, k + 9, Blocks.log, 0);
		setBlock(world, i + 7, j + 26, k + 7, Blocks.log, 0);
		setBlock(world, i + 7, j + 26, k + 8, Blocks.log, 0);
		setBlock(world, i + 7, j + 26, k + 9, Blocks.log, 0);
		setBlock(world, i + 7, j + 27, k + 6, Blocks.log, 0);
		setBlock(world, i + 7, j + 27, k + 7, Blocks.log, 0);
		setBlock(world, i + 7, j + 27, k + 8, Blocks.log, 0);
		setBlock(world, i + 7, j + 27, k + 9, Blocks.log, 0);
		setBlock(world, i + 7, j + 28, k + 7, Blocks.log, 0);
		setBlock(world, i + 7, j + 28, k + 8, Blocks.log, 0);
		setBlock(world, i + 7, j + 28, k + 9, Blocks.log, 0);
		setBlock(world, i + 7, j + 29, k + 7, Blocks.log, 0);
		setBlock(world, i + 7, j + 29, k + 8, Blocks.log, 0);
		setBlock(world, i + 7, j + 29, k + 9, Blocks.log, 0);
		setBlock(world, i + 7, j + 30, k + 7, Blocks.log, 0);
		setBlock(world, i + 7, j + 30, k + 8, Blocks.log, 0);
		setBlock(world, i + 7, j + 30, k + 9, Blocks.log, 0);
		setBlock(world, i + 7, j + 31, k + 8, Blocks.log, 0);
		setBlock(world, i + 7, j + 32, k + 8, Blocks.log, 0);
		setBlock(world, i + 7, j + 33, k + 8, Blocks.log, 0);
		setBlock(world, i + 7, j + 34, k + 8, Blocks.log, 0);
		setBlock(world, i + 7, j + 35, k + 8, Blocks.log, 0);
		setBlock(world, i + 7, j + 35, k + 9, Blocks.log, 0);
		setBlock(world, i + 7, j + 35, k + 10, Blocks.log, 0);
		setBlock(world, i + 7, j + 36, k + 8, Blocks.log, 0);
		setBlock(world, i + 7, j + 36, k + 9, Blocks.log, 0);
		setBlock(world, i + 7, j + 36, k + 10, Blocks.log, 0);
		setBlock(world, i + 7, j + 37, k + 8, Blocks.log, 0);
		setBlock(world, i + 7, j + 37, k + 9, Blocks.log, 0);
		setBlock(world, i + 7, j + 37, k + 10, Blocks.log, 0);
		setBlock(world, i + 7, j + 38, k + 8, Blocks.log, 0);
		setBlock(world, i + 7, j + 38, k + 9, Blocks.log, 0);
		setBlock(world, i + 7, j + 38, k + 11, Blocks.log, 0);
		setBlock(world, i + 7, j + 39, k + 8, Blocks.log, 0);
		setBlock(world, i + 7, j + 39, k + 11, Blocks.log, 0);
		setBlock(world, i + 7, j + 40, k + 8, Blocks.log, 0);
		setBlock(world, i + 7, j + 40, k + 11, Blocks.log, 0);
		setBlock(world, i + 7, j + 41, k + 8, Blocks.log, 0);
		setBlock(world, i + 7, j + 42, k + 8, Blocks.log, 0);
		setBlock(world, i + 7, j + 43, k + 7, Blocks.log, 0);
		setBlock(world, i + 7, j + 44, k + 7, Blocks.log, 0);
		setBlock(world, i + 7, j + 45, k + 7, Blocks.log, 0);
		setBlock(world, i + 7, j + 46, k + 7, Blocks.log, 0);
		setBlock(world, i + 7, j + 47, k + 6, Blocks.log, 0);
		setBlock(world, i + 8, j + 0, k + 4, Blocks.log, 0);
		setBlock(world, i + 8, j + 0, k + 5, Blocks.log, 0);
		setBlock(world, i + 8, j + 0, k + 6, Blocks.log, 0);
		setBlock(world, i + 8, j + 0, k + 7, Blocks.log, 0);
		setBlock(world, i + 8, j + 0, k + 8, Blocks.log, 0);
		setBlock(world, i + 8, j + 0, k + 9, Blocks.log, 0);
		setBlock(world, i + 8, j + 0, k + 10, Blocks.log, 0);
		setBlock(world, i + 8, j + 0, k + 11, Blocks.log, 0);
		setBlock(world, i + 8, j + 0, k + 12, Blocks.log, 0);
		setBlock(world, i + 8, j + 1, k + 4, Blocks.log, 0);
		setBlock(world, i + 8, j + 1, k + 5, Blocks.log, 0);
		setBlock(world, i + 8, j + 1, k + 6, Blocks.log, 0);
		setBlock(world, i + 8, j + 1, k + 7, Blocks.log, 0);
		setBlock(world, i + 8, j + 1, k + 8, Blocks.log, 0);
		setBlock(world, i + 8, j + 1, k + 9, Blocks.log, 0);
		setBlock(world, i + 8, j + 1, k + 10, Blocks.log, 0);
		setBlock(world, i + 8, j + 1, k + 11, Blocks.log, 0);
		setBlock(world, i + 8, j + 1, k + 12, Blocks.log, 0);
		setBlock(world, i + 8, j + 2, k + 4, Blocks.log, 0);
		setBlock(world, i + 8, j + 2, k + 5, Blocks.log, 0);
		setBlock(world, i + 8, j + 2, k + 6, Blocks.log, 0);
		setBlock(world, i + 8, j + 2, k + 7, Blocks.log, 0);
		setBlock(world, i + 8, j + 2, k + 8, Blocks.log, 0);
		setBlock(world, i + 8, j + 2, k + 9, Blocks.log, 0);
		setBlock(world, i + 8, j + 2, k + 10, Blocks.log, 0);
		setBlock(world, i + 8, j + 2, k + 11, Blocks.log, 0);
		setBlock(world, i + 8, j + 2, k + 12, Blocks.log, 0);
		setBlock(world, i + 8, j + 3, k + 4, Blocks.log, 0);
		setBlock(world, i + 8, j + 3, k + 5, Blocks.log, 0);
		setBlock(world, i + 8, j + 3, k + 6, Blocks.log, 0);
		setBlock(world, i + 8, j + 3, k + 7, Blocks.log, 0);
		setBlock(world, i + 8, j + 3, k + 8, Blocks.log, 0);
		setBlock(world, i + 8, j + 3, k + 9, Blocks.log, 0);
		setBlock(world, i + 8, j + 3, k + 10, Blocks.log, 0);
		setBlock(world, i + 8, j + 3, k + 11, Blocks.log, 0);
		setBlock(world, i + 8, j + 3, k + 12, Blocks.log, 0);
		setBlock(world, i + 8, j + 4, k + 5, Blocks.log, 0);
		setBlock(world, i + 8, j + 4, k + 6, Blocks.log, 0);
		setBlock(world, i + 8, j + 4, k + 7, Blocks.log, 0);
		setBlock(world, i + 8, j + 4, k + 8, Blocks.log, 0);
		setBlock(world, i + 8, j + 4, k + 9, Blocks.log, 0);
		setBlock(world, i + 8, j + 4, k + 10, Blocks.log, 0);
		setBlock(world, i + 8, j + 4, k + 11, Blocks.log, 0);
		setBlock(world, i + 8, j + 5, k + 5, Blocks.log, 0);
		setBlock(world, i + 8, j + 5, k + 6, Blocks.log, 0);
		setBlock(world, i + 8, j + 5, k + 7, Blocks.log, 0);
		setBlock(world, i + 8, j + 5, k + 8, Blocks.log, 0);
		setBlock(world, i + 8, j + 5, k + 9, Blocks.log, 0);
		setBlock(world, i + 8, j + 5, k + 10, Blocks.log, 0);
		setBlock(world, i + 8, j + 5, k + 11, Blocks.log, 0);
		setBlock(world, i + 8, j + 6, k + 5, Blocks.log, 0);
		setBlock(world, i + 8, j + 6, k + 6, Blocks.log, 0);
		setBlock(world, i + 8, j + 6, k + 7, Blocks.log, 0);
		setBlock(world, i + 8, j + 6, k + 8, Blocks.log, 0);
		setBlock(world, i + 8, j + 6, k + 9, Blocks.log, 0);
		setBlock(world, i + 8, j + 6, k + 10, Blocks.log, 0);
		setBlock(world, i + 8, j + 6, k + 11, Blocks.log, 0);
		setBlock(world, i + 8, j + 7, k + 5, Blocks.log, 0);
		setBlock(world, i + 8, j + 7, k + 6, Blocks.log, 0);
		setBlock(world, i + 8, j + 7, k + 7, Blocks.log, 0);
		setBlock(world, i + 8, j + 7, k + 8, Blocks.log, 0);
		setBlock(world, i + 8, j + 7, k + 9, Blocks.log, 0);
		setBlock(world, i + 8, j + 7, k + 10, Blocks.log, 0);
		setBlock(world, i + 8, j + 7, k + 11, Blocks.log, 0);
		setBlock(world, i + 8, j + 7, k + 12, Blocks.log, 0);
		setBlock(world, i + 8, j + 8, k + 5, Blocks.log, 0);
		setBlock(world, i + 8, j + 8, k + 6, Blocks.log, 0);
		setBlock(world, i + 8, j + 8, k + 7, Blocks.log, 0);
		setBlock(world, i + 8, j + 8, k + 8, Blocks.log, 0);
		setBlock(world, i + 8, j + 8, k + 9, Blocks.log, 0);
		setBlock(world, i + 8, j + 8, k + 10, Blocks.log, 0);
		setBlock(world, i + 8, j + 8, k + 11, Blocks.log, 0);
		setBlock(world, i + 8, j + 8, k + 12, Blocks.log, 0);
		setBlock(world, i + 8, j + 9, k + 5, Blocks.log, 0);
		setBlock(world, i + 8, j + 9, k + 6, Blocks.log, 0);
		setBlock(world, i + 8, j + 9, k + 7, Blocks.log, 0);
		setBlock(world, i + 8, j + 9, k + 8, Blocks.log, 0);
		setBlock(world, i + 8, j + 9, k + 9, Blocks.log, 0);
		setBlock(world, i + 8, j + 9, k + 10, Blocks.log, 0);
		setBlock(world, i + 8, j + 9, k + 11, Blocks.log, 0);
		setBlock(world, i + 8, j + 9, k + 12, Blocks.log, 0);
		setBlock(world, i + 8, j + 10, k + 5, Blocks.log, 0);
		setBlock(world, i + 8, j + 10, k + 6, Blocks.log, 0);
		setBlock(world, i + 8, j + 10, k + 7, Blocks.log, 0);
		setBlock(world, i + 8, j + 10, k + 8, Blocks.log, 0);
		setBlock(world, i + 8, j + 10, k + 9, Blocks.log, 0);
		setBlock(world, i + 8, j + 10, k + 10, Blocks.log, 0);
		setBlock(world, i + 8, j + 10, k + 11, Blocks.log, 0);
		setBlock(world, i + 8, j + 11, k + 5, Blocks.log, 0);
		setBlock(world, i + 8, j + 11, k + 6, Blocks.log, 0);
		setBlock(world, i + 8, j + 11, k + 7, Blocks.log, 0);
		setBlock(world, i + 8, j + 11, k + 8, Blocks.log, 0);
		setBlock(world, i + 8, j + 11, k + 9, Blocks.log, 0);
		setBlock(world, i + 8, j + 11, k + 10, Blocks.log, 0);
		setBlock(world, i + 8, j + 11, k + 11, Blocks.log, 0);
		setBlock(world, i + 8, j + 12, k + 5, Blocks.log, 0);
		setBlock(world, i + 8, j + 12, k + 6, Blocks.log, 0);
		setBlock(world, i + 8, j + 12, k + 7, Blocks.log, 0);
		setBlock(world, i + 8, j + 12, k + 8, Blocks.log, 0);
		setBlock(world, i + 8, j + 12, k + 9, Blocks.log, 0);
		setBlock(world, i + 8, j + 12, k + 10, Blocks.log, 0);
		setBlock(world, i + 8, j + 12, k + 11, Blocks.log, 0);
		setBlock(world, i + 8, j + 13, k + 5, Blocks.log, 0);
		setBlock(world, i + 8, j + 13, k + 6, Blocks.log, 0);
		setBlock(world, i + 8, j + 13, k + 7, Blocks.log, 0);
		setBlock(world, i + 8, j + 13, k + 8, Blocks.log, 0);
		setBlock(world, i + 8, j + 13, k + 9, Blocks.log, 0);
		setBlock(world, i + 8, j + 13, k + 10, Blocks.log, 0);
		setBlock(world, i + 8, j + 13, k + 11, Blocks.log, 0);
		setBlock(world, i + 8, j + 14, k + 5, Blocks.log, 0);
		setBlock(world, i + 8, j + 14, k + 6, Blocks.log, 0);
		setBlock(world, i + 8, j + 14, k + 7, Blocks.log, 0);
		setBlock(world, i + 8, j + 14, k + 8, Blocks.log, 0);
		setBlock(world, i + 8, j + 14, k + 9, Blocks.log, 0);
		setBlock(world, i + 8, j + 14, k + 10, Blocks.log, 0);
		setBlock(world, i + 8, j + 14, k + 11, Blocks.log, 0);
		setBlock(world, i + 8, j + 15, k + 5, Blocks.log, 0);
		setBlock(world, i + 8, j + 15, k + 6, Blocks.log, 0);
		setBlock(world, i + 8, j + 15, k + 7, Blocks.log, 0);
		setBlock(world, i + 8, j + 15, k + 8, Blocks.log, 0);
		setBlock(world, i + 8, j + 15, k + 9, Blocks.log, 0);
		setBlock(world, i + 8, j + 15, k + 10, Blocks.log, 0);
		setBlock(world, i + 8, j + 15, k + 11, Blocks.log, 0);
		setBlock(world, i + 8, j + 16, k + 5, Blocks.log, 0);
		setBlock(world, i + 8, j + 16, k + 6, Blocks.log, 0);
		setBlock(world, i + 8, j + 16, k + 7, Blocks.log, 0);
		setBlock(world, i + 8, j + 16, k + 8, Blocks.log, 0);
		setBlock(world, i + 8, j + 16, k + 9, Blocks.log, 0);
		setBlock(world, i + 8, j + 16, k + 10, Blocks.log, 0);
		setBlock(world, i + 8, j + 17, k + 3, Blocks.log, 0);
		setBlock(world, i + 8, j + 17, k + 4, Blocks.log, 0);
		setBlock(world, i + 8, j + 17, k + 6, Blocks.log, 0);
		setBlock(world, i + 8, j + 17, k + 7, Blocks.log, 0);
		setBlock(world, i + 8, j + 17, k + 8, Blocks.log, 0);
		setBlock(world, i + 8, j + 17, k + 9, Blocks.log, 0);
		setBlock(world, i + 8, j + 17, k + 10, Blocks.log, 0);
		setBlock(world, i + 8, j + 18, k + 2, Blocks.log, 0);
		setBlock(world, i + 8, j + 18, k + 6, Blocks.log, 0);
		setBlock(world, i + 8, j + 18, k + 7, Blocks.log, 0);
		setBlock(world, i + 8, j + 18, k + 8, Blocks.log, 0);
		setBlock(world, i + 8, j + 18, k + 9, Blocks.log, 0);
		setBlock(world, i + 8, j + 18, k + 10, Blocks.log, 0);
		setBlock(world, i + 8, j + 19, k + 6, Blocks.log, 0);
		setBlock(world, i + 8, j + 19, k + 7, Blocks.log, 0);
		setBlock(world, i + 8, j + 19, k + 8, Blocks.log, 0);
		setBlock(world, i + 8, j + 19, k + 9, Blocks.log, 0);
		setBlock(world, i + 8, j + 19, k + 10, Blocks.log, 0);
		setBlock(world, i + 8, j + 20, k + 6, Blocks.log, 0);
		setBlock(world, i + 8, j + 20, k + 7, Blocks.log, 0);
		setBlock(world, i + 8, j + 20, k + 8, Blocks.log, 0);
		setBlock(world, i + 8, j + 20, k + 9, Blocks.log, 0);
		setBlock(world, i + 8, j + 20, k + 10, Blocks.log, 0);
		setBlock(world, i + 8, j + 21, k + 6, Blocks.log, 0);
		setBlock(world, i + 8, j + 21, k + 7, Blocks.log, 0);
		setBlock(world, i + 8, j + 21, k + 8, Blocks.log, 0);
		setBlock(world, i + 8, j + 21, k + 9, Blocks.log, 0);
		setBlock(world, i + 8, j + 21, k + 10, Blocks.log, 0);
		setBlock(world, i + 8, j + 22, k + 6, Blocks.log, 0);
		setBlock(world, i + 8, j + 22, k + 7, Blocks.log, 0);
		setBlock(world, i + 8, j + 22, k + 8, Blocks.log, 0);
		setBlock(world, i + 8, j + 22, k + 9, Blocks.log, 0);
		setBlock(world, i + 8, j + 22, k + 10, Blocks.log, 0);
		setBlock(world, i + 8, j + 23, k + 6, Blocks.log, 0);
		setBlock(world, i + 8, j + 23, k + 7, Blocks.log, 0);
		setBlock(world, i + 8, j + 23, k + 8, Blocks.log, 0);
		setBlock(world, i + 8, j + 23, k + 9, Blocks.log, 0);
		setBlock(world, i + 8, j + 23, k + 10, Blocks.log, 0);
		setBlock(world, i + 8, j + 24, k + 6, Blocks.log, 0);
		setBlock(world, i + 8, j + 24, k + 7, Blocks.log, 0);
		setBlock(world, i + 8, j + 24, k + 8, Blocks.log, 0);
		setBlock(world, i + 8, j + 24, k + 9, Blocks.log, 0);
		setBlock(world, i + 8, j + 24, k + 10, Blocks.log, 0);
		setBlock(world, i + 8, j + 25, k + 6, Blocks.log, 0);
		setBlock(world, i + 8, j + 25, k + 7, Blocks.log, 0);
		setBlock(world, i + 8, j + 25, k + 8, Blocks.log, 0);
		setBlock(world, i + 8, j + 25, k + 9, Blocks.log, 0);
		setBlock(world, i + 8, j + 25, k + 10, Blocks.log, 0);
		setBlock(world, i + 8, j + 26, k + 6, Blocks.log, 0);
		setBlock(world, i + 8, j + 26, k + 7, Blocks.log, 0);
		setBlock(world, i + 8, j + 26, k + 8, Blocks.log, 0);
		setBlock(world, i + 8, j + 26, k + 9, Blocks.log, 0);
		setBlock(world, i + 8, j + 26, k + 10, Blocks.log, 0);
		setBlock(world, i + 8, j + 27, k + 7, Blocks.log, 0);
		setBlock(world, i + 8, j + 27, k + 8, Blocks.log, 0);
		setBlock(world, i + 8, j + 27, k + 9, Blocks.log, 0);
		setBlock(world, i + 8, j + 28, k + 7, Blocks.log, 0);
		setBlock(world, i + 8, j + 28, k + 8, Blocks.log, 0);
		setBlock(world, i + 8, j + 28, k + 9, Blocks.log, 0);
		setBlock(world, i + 8, j + 29, k + 7, Blocks.log, 0);
		setBlock(world, i + 8, j + 29, k + 8, Blocks.log, 0);
		setBlock(world, i + 8, j + 29, k + 9, Blocks.log, 0);
		setBlock(world, i + 8, j + 30, k + 7, Blocks.log, 0);
		setBlock(world, i + 8, j + 30, k + 8, Blocks.log, 0);
		setBlock(world, i + 8, j + 30, k + 9, Blocks.log, 0);
		setBlock(world, i + 8, j + 31, k + 7, Blocks.log, 0);
		setBlock(world, i + 8, j + 31, k + 8, Blocks.log, 0);
		setBlock(world, i + 8, j + 31, k + 9, Blocks.log, 0);
		setBlock(world, i + 8, j + 32, k + 7, Blocks.log, 0);
		setBlock(world, i + 8, j + 32, k + 8, Blocks.log, 0);
		setBlock(world, i + 8, j + 32, k + 9, Blocks.log, 0);
		setBlock(world, i + 8, j + 33, k + 7, Blocks.log, 0);
		setBlock(world, i + 8, j + 33, k + 8, Blocks.log, 0);
		setBlock(world, i + 8, j + 33, k + 9, Blocks.log, 0);
		setBlock(world, i + 8, j + 34, k + 0, Blocks.log, 0);
		setBlock(world, i + 8, j + 34, k + 7, Blocks.log, 0);
		setBlock(world, i + 8, j + 34, k + 8, Blocks.log, 0);
		setBlock(world, i + 8, j + 34, k + 9, Blocks.log, 0);
		setBlock(world, i + 8, j + 35, k + 8, Blocks.log, 0);
		setBlock(world, i + 8, j + 35, k + 9, Blocks.log, 0);
		setBlock(world, i + 8, j + 36, k + 8, Blocks.log, 0);
		setBlock(world, i + 8, j + 36, k + 9, Blocks.log, 0);
		setBlock(world, i + 8, j + 37, k + 7, Blocks.log, 0);
		setBlock(world, i + 8, j + 37, k + 8, Blocks.log, 0);
		setBlock(world, i + 8, j + 37, k + 9, Blocks.log, 0);
		setBlock(world, i + 8, j + 37, k + 10, Blocks.log, 0);
		setBlock(world, i + 8, j + 38, k + 7, Blocks.log, 0);
		setBlock(world, i + 8, j + 38, k + 8, Blocks.log, 0);
		setBlock(world, i + 8, j + 38, k + 10, Blocks.log, 0);
		setBlock(world, i + 8, j + 39, k + 7, Blocks.log, 0);
		setBlock(world, i + 8, j + 39, k + 8, Blocks.log, 0);
		setBlock(world, i + 8, j + 39, k + 10, Blocks.log, 0);
		setBlock(world, i + 8, j + 39, k + 11, Blocks.log, 0);
		setBlock(world, i + 8, j + 40, k + 6, Blocks.log, 0);
		setBlock(world, i + 8, j + 40, k + 7, Blocks.log, 0);
		setBlock(world, i + 8, j + 40, k + 8, Blocks.log, 0);
		setBlock(world, i + 8, j + 40, k + 10, Blocks.log, 0);
		setBlock(world, i + 8, j + 41, k + 3, Blocks.log, 0);
		setBlock(world, i + 8, j + 41, k + 6, Blocks.log, 0);
		setBlock(world, i + 8, j + 41, k + 7, Blocks.log, 0);
		setBlock(world, i + 8, j + 41, k + 11, Blocks.log, 0);
		setBlock(world, i + 8, j + 42, k + 5, Blocks.log, 0);
		setBlock(world, i + 8, j + 42, k + 7, Blocks.log, 0);
		setBlock(world, i + 8, j + 42, k + 11, Blocks.log, 0);
		setBlock(world, i + 8, j + 43, k + 5, Blocks.log, 0);
		setBlock(world, i + 8, j + 43, k + 6, Blocks.log, 0);
		setBlock(world, i + 8, j + 43, k + 7, Blocks.log, 0);
		setBlock(world, i + 8, j + 43, k + 11, Blocks.log, 0);
		setBlock(world, i + 8, j + 44, k + 5, Blocks.log, 0);
		setBlock(world, i + 8, j + 44, k + 6, Blocks.log, 0);
		setBlock(world, i + 8, j + 44, k + 7, Blocks.log, 0);
		setBlock(world, i + 8, j + 44, k + 12, Blocks.log, 0);
		setBlock(world, i + 8, j + 45, k + 4, Blocks.log, 0);
		setBlock(world, i + 8, j + 45, k + 6, Blocks.log, 0);
		setBlock(world, i + 8, j + 45, k + 7, Blocks.log, 0);
		setBlock(world, i + 8, j + 45, k + 12, Blocks.log, 0);
		setBlock(world, i + 8, j + 46, k + 4, Blocks.log, 0);
		setBlock(world, i + 8, j + 46, k + 6, Blocks.log, 0);
		setBlock(world, i + 8, j + 46, k + 7, Blocks.log, 0);
		setBlock(world, i + 8, j + 46, k + 12, Blocks.log, 0);
		setBlock(world, i + 8, j + 47, k + 12, Blocks.log, 0);
		setBlock(world, i + 9, j + 0, k + 4, Blocks.log, 0);
		setBlock(world, i + 9, j + 0, k + 5, Blocks.log, 0);
		setBlock(world, i + 9, j + 0, k + 6, Blocks.log, 0);
		setBlock(world, i + 9, j + 0, k + 7, Blocks.log, 0);
		setBlock(world, i + 9, j + 0, k + 8, Blocks.log, 0);
		setBlock(world, i + 9, j + 0, k + 9, Blocks.log, 0);
		setBlock(world, i + 9, j + 0, k + 10, Blocks.log, 0);
		setBlock(world, i + 9, j + 0, k + 11, Blocks.log, 0);
		setBlock(world, i + 9, j + 0, k + 12, Blocks.log, 0);
		setBlock(world, i + 9, j + 1, k + 5, Blocks.log, 0);
		setBlock(world, i + 9, j + 1, k + 6, Blocks.log, 0);
		setBlock(world, i + 9, j + 1, k + 7, Blocks.log, 0);
		setBlock(world, i + 9, j + 1, k + 8, Blocks.log, 0);
		setBlock(world, i + 9, j + 1, k + 9, Blocks.log, 0);
		setBlock(world, i + 9, j + 1, k + 10, Blocks.log, 0);
		setBlock(world, i + 9, j + 1, k + 11, Blocks.log, 0);
		setBlock(world, i + 9, j + 2, k + 5, Blocks.log, 0);
		setBlock(world, i + 9, j + 2, k + 6, Blocks.log, 0);
		setBlock(world, i + 9, j + 2, k + 7, Blocks.log, 0);
		setBlock(world, i + 9, j + 2, k + 8, Blocks.log, 0);
		setBlock(world, i + 9, j + 2, k + 9, Blocks.log, 0);
		setBlock(world, i + 9, j + 2, k + 10, Blocks.log, 0);
		setBlock(world, i + 9, j + 2, k + 11, Blocks.log, 0);
		setBlock(world, i + 9, j + 3, k + 3, Blocks.log, 0);
		setBlock(world, i + 9, j + 3, k + 4, Blocks.log, 0);
		setBlock(world, i + 9, j + 3, k + 5, Blocks.log, 0);
		setBlock(world, i + 9, j + 3, k + 6, Blocks.log, 0);
		setBlock(world, i + 9, j + 3, k + 7, Blocks.log, 0);
		setBlock(world, i + 9, j + 3, k + 8, Blocks.log, 0);
		setBlock(world, i + 9, j + 3, k + 9, Blocks.log, 0);
		setBlock(world, i + 9, j + 3, k + 10, Blocks.log, 0);
		setBlock(world, i + 9, j + 3, k + 11, Blocks.log, 0);
		setBlock(world, i + 9, j + 4, k + 1, Blocks.log, 0);
		setBlock(world, i + 9, j + 4, k + 2, Blocks.log, 0);
		setBlock(world, i + 9, j + 4, k + 5, Blocks.log, 0);
		setBlock(world, i + 9, j + 4, k + 6, Blocks.log, 0);
		setBlock(world, i + 9, j + 4, k + 7, Blocks.log, 0);
		setBlock(world, i + 9, j + 4, k + 8, Blocks.log, 0);
		setBlock(world, i + 9, j + 4, k + 9, Blocks.log, 0);
		setBlock(world, i + 9, j + 4, k + 10, Blocks.log, 0);
		setBlock(world, i + 9, j + 4, k + 11, Blocks.log, 0);
		setBlock(world, i + 9, j + 5, k + 5, Blocks.log, 0);
		setBlock(world, i + 9, j + 5, k + 6, Blocks.log, 0);
		setBlock(world, i + 9, j + 5, k + 7, Blocks.log, 0);
		setBlock(world, i + 9, j + 5, k + 8, Blocks.log, 0);
		setBlock(world, i + 9, j + 5, k + 9, Blocks.log, 0);
		setBlock(world, i + 9, j + 5, k + 10, Blocks.log, 0);
		setBlock(world, i + 9, j + 5, k + 11, Blocks.log, 0);
		setBlock(world, i + 9, j + 5, k + 14, Blocks.log, 0);
		setBlock(world, i + 9, j + 6, k + 5, Blocks.log, 0);
		setBlock(world, i + 9, j + 6, k + 6, Blocks.log, 0);
		setBlock(world, i + 9, j + 6, k + 7, Blocks.log, 0);
		setBlock(world, i + 9, j + 6, k + 8, Blocks.log, 0);
		setBlock(world, i + 9, j + 6, k + 9, Blocks.log, 0);
		setBlock(world, i + 9, j + 6, k + 10, Blocks.log, 0);
		setBlock(world, i + 9, j + 6, k + 11, Blocks.log, 0);
		setBlock(world, i + 9, j + 6, k + 13, Blocks.log, 0);
		setBlock(world, i + 9, j + 6, k + 14, Blocks.log, 0);
		setBlock(world, i + 9, j + 7, k + 5, Blocks.log, 0);
		setBlock(world, i + 9, j + 7, k + 6, Blocks.log, 0);
		setBlock(world, i + 9, j + 7, k + 7, Blocks.log, 0);
		setBlock(world, i + 9, j + 7, k + 8, Blocks.log, 0);
		setBlock(world, i + 9, j + 7, k + 9, Blocks.log, 0);
		setBlock(world, i + 9, j + 7, k + 10, Blocks.log, 0);
		setBlock(world, i + 9, j + 7, k + 11, Blocks.log, 0);
		setBlock(world, i + 9, j + 7, k + 12, Blocks.log, 0);
		setBlock(world, i + 9, j + 7, k + 13, Blocks.log, 0);
		setBlock(world, i + 9, j + 7, k + 14, Blocks.log, 0);
		setBlock(world, i + 9, j + 8, k + 5, Blocks.log, 0);
		setBlock(world, i + 9, j + 8, k + 6, Blocks.log, 0);
		setBlock(world, i + 9, j + 8, k + 7, Blocks.log, 0);
		setBlock(world, i + 9, j + 8, k + 8, Blocks.log, 0);
		setBlock(world, i + 9, j + 8, k + 9, Blocks.log, 0);
		setBlock(world, i + 9, j + 8, k + 10, Blocks.log, 0);
		setBlock(world, i + 9, j + 8, k + 11, Blocks.log, 0);
		setBlock(world, i + 9, j + 8, k + 12, Blocks.log, 0);
		setBlock(world, i + 9, j + 8, k + 13, Blocks.log, 0);
		setBlock(world, i + 9, j + 9, k + 5, Blocks.log, 0);
		setBlock(world, i + 9, j + 9, k + 6, Blocks.log, 0);
		setBlock(world, i + 9, j + 9, k + 7, Blocks.log, 0);
		setBlock(world, i + 9, j + 9, k + 8, Blocks.log, 0);
		setBlock(world, i + 9, j + 9, k + 9, Blocks.log, 0);
		setBlock(world, i + 9, j + 9, k + 10, Blocks.log, 0);
		setBlock(world, i + 9, j + 9, k + 11, Blocks.log, 0);
		setBlock(world, i + 9, j + 9, k + 12, Blocks.log, 0);
		setBlock(world, i + 9, j + 10, k + 5, Blocks.log, 0);
		setBlock(world, i + 9, j + 10, k + 6, Blocks.log, 0);
		setBlock(world, i + 9, j + 10, k + 7, Blocks.log, 0);
		setBlock(world, i + 9, j + 10, k + 8, Blocks.log, 0);
		setBlock(world, i + 9, j + 10, k + 9, Blocks.log, 0);
		setBlock(world, i + 9, j + 10, k + 10, Blocks.log, 0);
		setBlock(world, i + 9, j + 10, k + 11, Blocks.log, 0);
		setBlock(world, i + 9, j + 11, k + 5, Blocks.log, 0);
		setBlock(world, i + 9, j + 11, k + 6, Blocks.log, 0);
		setBlock(world, i + 9, j + 11, k + 7, Blocks.log, 0);
		setBlock(world, i + 9, j + 11, k + 8, Blocks.log, 0);
		setBlock(world, i + 9, j + 11, k + 9, Blocks.log, 0);
		setBlock(world, i + 9, j + 11, k + 10, Blocks.log, 0);
		setBlock(world, i + 9, j + 11, k + 11, Blocks.log, 0);
		setBlock(world, i + 9, j + 12, k + 5, Blocks.log, 0);
		setBlock(world, i + 9, j + 12, k + 6, Blocks.log, 0);
		setBlock(world, i + 9, j + 12, k + 7, Blocks.log, 0);
		setBlock(world, i + 9, j + 12, k + 8, Blocks.log, 0);
		setBlock(world, i + 9, j + 12, k + 9, Blocks.log, 0);
		setBlock(world, i + 9, j + 12, k + 10, Blocks.log, 0);
		setBlock(world, i + 9, j + 12, k + 11, Blocks.log, 0);
		setBlock(world, i + 9, j + 13, k + 6, Blocks.log, 0);
		setBlock(world, i + 9, j + 13, k + 7, Blocks.log, 0);
		setBlock(world, i + 9, j + 13, k + 8, Blocks.log, 0);
		setBlock(world, i + 9, j + 13, k + 9, Blocks.log, 0);
		setBlock(world, i + 9, j + 13, k + 10, Blocks.log, 0);
		setBlock(world, i + 9, j + 14, k + 6, Blocks.log, 0);
		setBlock(world, i + 9, j + 14, k + 7, Blocks.log, 0);
		setBlock(world, i + 9, j + 14, k + 8, Blocks.log, 0);
		setBlock(world, i + 9, j + 14, k + 9, Blocks.log, 0);
		setBlock(world, i + 9, j + 14, k + 10, Blocks.log, 0);
		setBlock(world, i + 9, j + 15, k + 6, Blocks.log, 0);
		setBlock(world, i + 9, j + 15, k + 7, Blocks.log, 0);
		setBlock(world, i + 9, j + 15, k + 8, Blocks.log, 0);
		setBlock(world, i + 9, j + 15, k + 9, Blocks.log, 0);
		setBlock(world, i + 9, j + 15, k + 10, Blocks.log, 0);
		setBlock(world, i + 9, j + 16, k + 6, Blocks.log, 0);
		setBlock(world, i + 9, j + 16, k + 7, Blocks.log, 0);
		setBlock(world, i + 9, j + 16, k + 8, Blocks.log, 0);
		setBlock(world, i + 9, j + 16, k + 9, Blocks.log, 0);
		setBlock(world, i + 9, j + 16, k + 10, Blocks.log, 0);
		setBlock(world, i + 9, j + 17, k + 6, Blocks.log, 0);
		setBlock(world, i + 9, j + 17, k + 7, Blocks.log, 0);
		setBlock(world, i + 9, j + 17, k + 8, Blocks.log, 0);
		setBlock(world, i + 9, j + 17, k + 9, Blocks.log, 0);
		setBlock(world, i + 9, j + 17, k + 10, Blocks.log, 0);
		setBlock(world, i + 9, j + 18, k + 6, Blocks.log, 0);
		setBlock(world, i + 9, j + 18, k + 7, Blocks.log, 0);
		setBlock(world, i + 9, j + 18, k + 8, Blocks.log, 0);
		setBlock(world, i + 9, j + 18, k + 9, Blocks.log, 0);
		setBlock(world, i + 9, j + 18, k + 10, Blocks.log, 0);
		setBlock(world, i + 9, j + 19, k + 6, Blocks.log, 0);
		setBlock(world, i + 9, j + 19, k + 7, Blocks.log, 0);
		setBlock(world, i + 9, j + 19, k + 8, Blocks.log, 0);
		setBlock(world, i + 9, j + 19, k + 9, Blocks.log, 0);
		setBlock(world, i + 9, j + 19, k + 10, Blocks.log, 0);
		setBlock(world, i + 9, j + 20, k + 6, Blocks.log, 0);
		setBlock(world, i + 9, j + 20, k + 7, Blocks.log, 0);
		setBlock(world, i + 9, j + 20, k + 8, Blocks.log, 0);
		setBlock(world, i + 9, j + 20, k + 9, Blocks.log, 0);
		setBlock(world, i + 9, j + 20, k + 10, Blocks.log, 0);
		setBlock(world, i + 9, j + 21, k + 6, Blocks.log, 0);
		setBlock(world, i + 9, j + 21, k + 7, Blocks.log, 0);
		setBlock(world, i + 9, j + 21, k + 8, Blocks.log, 0);
		setBlock(world, i + 9, j + 21, k + 9, Blocks.log, 0);
		setBlock(world, i + 9, j + 21, k + 10, Blocks.log, 0);
		setBlock(world, i + 9, j + 22, k + 6, Blocks.log, 0);
		setBlock(world, i + 9, j + 22, k + 7, Blocks.log, 0);
		setBlock(world, i + 9, j + 22, k + 8, Blocks.log, 0);
		setBlock(world, i + 9, j + 22, k + 9, Blocks.log, 0);
		setBlock(world, i + 9, j + 22, k + 10, Blocks.log, 0);
		setBlock(world, i + 9, j + 23, k + 7, Blocks.log, 0);
		setBlock(world, i + 9, j + 23, k + 8, Blocks.log, 0);
		setBlock(world, i + 9, j + 23, k + 9, Blocks.log, 0);
		setBlock(world, i + 9, j + 24, k + 7, Blocks.log, 0);
		setBlock(world, i + 9, j + 24, k + 8, Blocks.log, 0);
		setBlock(world, i + 9, j + 24, k + 9, Blocks.log, 0);
		setBlock(world, i + 9, j + 25, k + 5, Blocks.log, 0);
		setBlock(world, i + 9, j + 25, k + 7, Blocks.log, 0);
		setBlock(world, i + 9, j + 25, k + 8, Blocks.log, 0);
		setBlock(world, i + 9, j + 25, k + 9, Blocks.log, 0);
		setBlock(world, i + 9, j + 26, k + 5, Blocks.log, 0);
		setBlock(world, i + 9, j + 26, k + 7, Blocks.log, 0);
		setBlock(world, i + 9, j + 26, k + 8, Blocks.log, 0);
		setBlock(world, i + 9, j + 26, k + 9, Blocks.log, 0);
		setBlock(world, i + 9, j + 27, k + 5, Blocks.log, 0);
		setBlock(world, i + 9, j + 27, k + 7, Blocks.log, 0);
		setBlock(world, i + 9, j + 27, k + 8, Blocks.log, 0);
		setBlock(world, i + 9, j + 27, k + 9, Blocks.log, 0);
		setBlock(world, i + 9, j + 28, k + 7, Blocks.log, 0);
		setBlock(world, i + 9, j + 28, k + 8, Blocks.log, 0);
		setBlock(world, i + 9, j + 28, k + 9, Blocks.log, 0);
		setBlock(world, i + 9, j + 29, k + 7, Blocks.log, 0);
		setBlock(world, i + 9, j + 29, k + 8, Blocks.log, 0);
		setBlock(world, i + 9, j + 29, k + 9, Blocks.log, 0);
		setBlock(world, i + 9, j + 30, k + 7, Blocks.log, 0);
		setBlock(world, i + 9, j + 30, k + 8, Blocks.log, 0);
		setBlock(world, i + 9, j + 30, k + 9, Blocks.log, 0);
		setBlock(world, i + 9, j + 31, k + 8, Blocks.log, 0);
		setBlock(world, i + 9, j + 32, k + 8, Blocks.log, 0);
		setBlock(world, i + 9, j + 33, k + 8, Blocks.log, 0);
		setBlock(world, i + 9, j + 34, k + 7, Blocks.log, 0);
		setBlock(world, i + 9, j + 34, k + 8, Blocks.log, 0);
		/* 1000 */setBlock(world, i + 9, j + 35, k + 7, Blocks.log, 0);
		/* 1001 */setBlock(world, i + 9, j + 36, k + 6, Blocks.log, 0);
		/* 1002 */setBlock(world, i + 9, j + 36, k + 7, Blocks.log, 0);
		/* 1003 */setBlock(world, i + 9, j + 37, k + 5, Blocks.log, 0);
		/* 1004 */setBlock(world, i + 9, j + 37, k + 6, Blocks.log, 0);
		/* 1005 */setBlock(world, i + 9, j + 38, k + 5, Blocks.log, 0);
		/* 1006 */setBlock(world, i + 9, j + 38, k + 6, Blocks.log, 0);
		/* 1007 */setBlock(world, i + 9, j + 38, k + 9, Blocks.log, 0);
		/* 1008 */setBlock(world, i + 9, j + 39, k + 7, Blocks.log, 0);
		/* 1009 */setBlock(world, i + 9, j + 39, k + 10, Blocks.log, 0);
		/* 1010 */setBlock(world, i + 9, j + 40, k + 7, Blocks.log, 0);
		/* 1011 */setBlock(world, i + 9, j + 40, k + 10, Blocks.log, 0);
		/* 1012 */setBlock(world, i + 9, j + 40, k + 11, Blocks.log, 0);
		/* 1013 */setBlock(world, i + 9, j + 41, k + 6, Blocks.log, 0);
		/* 1014 */setBlock(world, i + 9, j + 41, k + 11, Blocks.log, 0);
		/* 1015 */setBlock(world, i + 9, j + 42, k + 6, Blocks.log, 0);
		/* 1016 */setBlock(world, i + 9, j + 42, k + 12, Blocks.log, 0);
		/* 1017 */setBlock(world, i + 9, j + 43, k + 6, Blocks.log, 0);
		/* 1018 */setBlock(world, i + 9, j + 43, k + 12, Blocks.log, 0);
		/* 1019 */setBlock(world, i + 9, j + 44, k + 13, Blocks.log, 0);
		/* 1020 */setBlock(world, i + 9, j + 45, k + 13, Blocks.log, 0);
		/* 1021 */setBlock(world, i + 9, j + 47, k + 3, Blocks.log, 0);
		/* 1022 */setBlock(world, i + 9, j + 47, k + 5, Blocks.log, 0);
		/* 1023 */setBlock(world, i + 9, j + 47, k + 6, Blocks.log, 0);
		/* 1024 */setBlock(world, i + 10, j + 0, k + 5, Blocks.log, 0);
		/* 1025 */setBlock(world, i + 10, j + 0, k + 6, Blocks.log, 0);
		/* 1026 */setBlock(world, i + 10, j + 0, k + 7, Blocks.log, 0);
		/* 1027 */setBlock(world, i + 10, j + 0, k + 8, Blocks.log, 0);
		/* 1028 */setBlock(world, i + 10, j + 0, k + 9, Blocks.log, 0);
		/* 1029 */setBlock(world, i + 10, j + 0, k + 10, Blocks.log, 0);
		/* 1030 */setBlock(world, i + 10, j + 0, k + 11, Blocks.log, 0);
		/* 1031 */setBlock(world, i + 10, j + 1, k + 5, Blocks.log, 0);
		/* 1032 */setBlock(world, i + 10, j + 1, k + 6, Blocks.log, 0);
		/* 1033 */setBlock(world, i + 10, j + 1, k + 7, Blocks.log, 0);
		/* 1034 */setBlock(world, i + 10, j + 1, k + 8, Blocks.log, 0);
		/* 1035 */setBlock(world, i + 10, j + 1, k + 9, Blocks.log, 0);
		/* 1036 */setBlock(world, i + 10, j + 1, k + 10, Blocks.log, 0);
		/* 1037 */setBlock(world, i + 10, j + 1, k + 11, Blocks.log, 0);
		/* 1038 */setBlock(world, i + 10, j + 2, k + 5, Blocks.log, 0);
		/* 1039 */setBlock(world, i + 10, j + 2, k + 6, Blocks.log, 0);
		/* 1040 */setBlock(world, i + 10, j + 2, k + 7, Blocks.log, 0);
		/* 1041 */setBlock(world, i + 10, j + 2, k + 8, Blocks.log, 0);
		/* 1042 */setBlock(world, i + 10, j + 2, k + 9, Blocks.log, 0);
		/* 1043 */setBlock(world, i + 10, j + 2, k + 10, Blocks.log, 0);
		/* 1044 */setBlock(world, i + 10, j + 2, k + 11, Blocks.log, 0);
		/* 1045 */setBlock(world, i + 10, j + 3, k + 5, Blocks.log, 0);
		/* 1046 */setBlock(world, i + 10, j + 3, k + 6, Blocks.log, 0);
		/* 1047 */setBlock(world, i + 10, j + 3, k + 7, Blocks.log, 0);
		/* 1048 */setBlock(world, i + 10, j + 3, k + 8, Blocks.log, 0);
		/* 1049 */setBlock(world, i + 10, j + 3, k + 9, Blocks.log, 0);
		/* 1050 */setBlock(world, i + 10, j + 3, k + 10, Blocks.log, 0);
		/* 1051 */setBlock(world, i + 10, j + 3, k + 11, Blocks.log, 0);
		/* 1052 */setBlock(world, i + 10, j + 4, k + 5, Blocks.log, 0);
		/* 1053 */setBlock(world, i + 10, j + 4, k + 6, Blocks.log, 0);
		/* 1054 */setBlock(world, i + 10, j + 4, k + 7, Blocks.log, 0);
		/* 1055 */setBlock(world, i + 10, j + 4, k + 8, Blocks.log, 0);
		/* 1056 */setBlock(world, i + 10, j + 4, k + 9, Blocks.log, 0);
		/* 1057 */setBlock(world, i + 10, j + 4, k + 10, Blocks.log, 0);
		/* 1058 */setBlock(world, i + 10, j + 4, k + 11, Blocks.log, 0);
		/* 1059 */setBlock(world, i + 10, j + 5, k + 0, Blocks.log, 0);
		/* 1060 */setBlock(world, i + 10, j + 5, k + 5, Blocks.log, 0);
		/* 1061 */setBlock(world, i + 10, j + 5, k + 6, Blocks.log, 0);
		/* 1062 */setBlock(world, i + 10, j + 5, k + 7, Blocks.log, 0);
		/* 1063 */setBlock(world, i + 10, j + 5, k + 8, Blocks.log, 0);
		/* 1064 */setBlock(world, i + 10, j + 5, k + 9, Blocks.log, 0);
		/* 1065 */setBlock(world, i + 10, j + 5, k + 10, Blocks.log, 0);
		/* 1066 */setBlock(world, i + 10, j + 5, k + 11, Blocks.log, 0);
		/* 1067 */setBlock(world, i + 10, j + 5, k + 14, Blocks.log, 0);
		/* 1068 */setBlock(world, i + 10, j + 5, k + 15, Blocks.log, 0);
		/* 1069 */setBlock(world, i + 10, j + 6, k + 5, Blocks.log, 0);
		/* 1070 */setBlock(world, i + 10, j + 6, k + 6, Blocks.log, 0);
		/* 1071 */setBlock(world, i + 10, j + 6, k + 7, Blocks.log, 0);
		/* 1072 */setBlock(world, i + 10, j + 6, k + 8, Blocks.log, 0);
		/* 1073 */setBlock(world, i + 10, j + 6, k + 9, Blocks.log, 0);
		/* 1074 */setBlock(world, i + 10, j + 6, k + 10, Blocks.log, 0);
		/* 1075 */setBlock(world, i + 10, j + 6, k + 11, Blocks.log, 0);
		/* 1076 */setBlock(world, i + 10, j + 6, k + 13, Blocks.log, 0);
		/* 1077 */setBlock(world, i + 10, j + 6, k + 14, Blocks.log, 0);
		/* 1078 */setBlock(world, i + 10, j + 6, k + 15, Blocks.log, 0);
		/* 1079 */setBlock(world, i + 10, j + 7, k + 6, Blocks.log, 0);
		/* 1080 */setBlock(world, i + 10, j + 7, k + 7, Blocks.log, 0);
		/* 1081 */setBlock(world, i + 10, j + 7, k + 8, Blocks.log, 0);
		/* 1082 */setBlock(world, i + 10, j + 7, k + 9, Blocks.log, 0);
		/* 1083 */setBlock(world, i + 10, j + 7, k + 10, Blocks.log, 0);
		/* 1084 */setBlock(world, i + 10, j + 7, k + 12, Blocks.log, 0);
		/* 1085 */setBlock(world, i + 10, j + 7, k + 13, Blocks.log, 0);
		/* 1086 */setBlock(world, i + 10, j + 7, k + 14, Blocks.log, 0);
		/* 1087 */setBlock(world, i + 10, j + 7, k + 15, Blocks.log, 0);
		/* 1088 */setBlock(world, i + 10, j + 8, k + 6, Blocks.log, 0);
		/* 1089 */setBlock(world, i + 10, j + 8, k + 7, Blocks.log, 0);
		/* 1090 */setBlock(world, i + 10, j + 8, k + 8, Blocks.log, 0);
		/* 1091 */setBlock(world, i + 10, j + 8, k + 9, Blocks.log, 0);
		/* 1092 */setBlock(world, i + 10, j + 8, k + 10, Blocks.log, 0);
		/* 1093 */setBlock(world, i + 10, j + 8, k + 11, Blocks.log, 0);
		/* 1094 */setBlock(world, i + 10, j + 8, k + 12, Blocks.log, 0);
		/* 1095 */setBlock(world, i + 10, j + 8, k + 13, Blocks.log, 0);
		/* 1096 */setBlock(world, i + 10, j + 9, k + 6, Blocks.log, 0);
		/* 1097 */setBlock(world, i + 10, j + 9, k + 7, Blocks.log, 0);
		/* 1098 */setBlock(world, i + 10, j + 9, k + 8, Blocks.log, 0);
		/* 1099 */setBlock(world, i + 10, j + 9, k + 9, Blocks.log, 0);
		/* 1100 */setBlock(world, i + 10, j + 9, k + 10, Blocks.log, 0);
		/* 1101 */setBlock(world, i + 10, j + 9, k + 11, Blocks.log, 0);
		/* 1102 */setBlock(world, i + 10, j + 9, k + 12, Blocks.log, 0);
		/* 1103 */setBlock(world, i + 10, j + 10, k + 6, Blocks.log, 0);
		/* 1104 */setBlock(world, i + 10, j + 10, k + 7, Blocks.log, 0);
		/* 1105 */setBlock(world, i + 10, j + 10, k + 8, Blocks.log, 0);
		/* 1106 */setBlock(world, i + 10, j + 10, k + 9, Blocks.log, 0);
		/* 1107 */setBlock(world, i + 10, j + 10, k + 10, Blocks.log, 0);
		/* 1108 */setBlock(world, i + 10, j + 10, k + 11, Blocks.log, 0);
		/* 1109 */setBlock(world, i + 10, j + 11, k + 6, Blocks.log, 0);
		/* 1110 */setBlock(world, i + 10, j + 11, k + 7, Blocks.log, 0);
		/* 1111 */setBlock(world, i + 10, j + 11, k + 8, Blocks.log, 0);
		/* 1112 */setBlock(world, i + 10, j + 11, k + 9, Blocks.log, 0);
		/* 1113 */setBlock(world, i + 10, j + 11, k + 10, Blocks.log, 0);
		/* 1114 */setBlock(world, i + 10, j + 12, k + 6, Blocks.log, 0);
		/* 1115 */setBlock(world, i + 10, j + 12, k + 7, Blocks.log, 0);
		/* 1116 */setBlock(world, i + 10, j + 12, k + 8, Blocks.log, 0);
		/* 1117 */setBlock(world, i + 10, j + 12, k + 9, Blocks.log, 0);
		/* 1118 */setBlock(world, i + 10, j + 12, k + 10, Blocks.log, 0);
		/* 1119 */setBlock(world, i + 10, j + 13, k + 6, Blocks.log, 0);
		/* 1120 */setBlock(world, i + 10, j + 13, k + 7, Blocks.log, 0);
		/* 1121 */setBlock(world, i + 10, j + 13, k + 8, Blocks.log, 0);
		/* 1122 */setBlock(world, i + 10, j + 13, k + 9, Blocks.log, 0);
		/* 1123 */setBlock(world, i + 10, j + 13, k + 10, Blocks.log, 0);
		/* 1124 */setBlock(world, i + 10, j + 14, k + 6, Blocks.log, 0);
		/* 1125 */setBlock(world, i + 10, j + 14, k + 7, Blocks.log, 0);
		/* 1126 */setBlock(world, i + 10, j + 14, k + 8, Blocks.log, 0);
		/* 1127 */setBlock(world, i + 10, j + 14, k + 9, Blocks.log, 0);
		/* 1128 */setBlock(world, i + 10, j + 14, k + 10, Blocks.log, 0);
		/* 1129 */setBlock(world, i + 10, j + 15, k + 6, Blocks.log, 0);
		/* 1130 */setBlock(world, i + 10, j + 15, k + 7, Blocks.log, 0);
		/* 1131 */setBlock(world, i + 10, j + 15, k + 8, Blocks.log, 0);
		/* 1132 */setBlock(world, i + 10, j + 15, k + 9, Blocks.log, 0);
		/* 1133 */setBlock(world, i + 10, j + 15, k + 10, Blocks.log, 0);
		/* 1134 */setBlock(world, i + 10, j + 16, k + 7, Blocks.log, 0);
		/* 1135 */setBlock(world, i + 10, j + 16, k + 8, Blocks.log, 0);
		/* 1136 */setBlock(world, i + 10, j + 16, k + 9, Blocks.log, 0);
		/* 1137 */setBlock(world, i + 10, j + 17, k + 7, Blocks.log, 0);
		/* 1138 */setBlock(world, i + 10, j + 17, k + 8, Blocks.log, 0);
		/* 1139 */setBlock(world, i + 10, j + 17, k + 9, Blocks.log, 0);
		/* 1140 */setBlock(world, i + 10, j + 18, k + 7, Blocks.log, 0);
		/* 1141 */setBlock(world, i + 10, j + 18, k + 8, Blocks.log, 0);
		/* 1142 */setBlock(world, i + 10, j + 18, k + 9, Blocks.log, 0);
		/* 1143 */setBlock(world, i + 10, j + 19, k + 7, Blocks.log, 0);
		/* 1144 */setBlock(world, i + 10, j + 19, k + 8, Blocks.log, 0);
		/* 1145 */setBlock(world, i + 10, j + 19, k + 9, Blocks.log, 0);
		/* 1146 */setBlock(world, i + 10, j + 20, k + 7, Blocks.log, 0);
		/* 1147 */setBlock(world, i + 10, j + 20, k + 8, Blocks.log, 0);
		/* 1148 */setBlock(world, i + 10, j + 20, k + 9, Blocks.log, 0);
		/* 1149 */setBlock(world, i + 10, j + 21, k + 7, Blocks.log, 0);
		/* 1150 */setBlock(world, i + 10, j + 21, k + 8, Blocks.log, 0);
		/* 1151 */setBlock(world, i + 10, j + 21, k + 9, Blocks.log, 0);
		/* 1152 */setBlock(world, i + 10, j + 22, k + 7, Blocks.log, 0);
		/* 1153 */setBlock(world, i + 10, j + 22, k + 8, Blocks.log, 0);
		/* 1154 */setBlock(world, i + 10, j + 22, k + 9, Blocks.log, 0);
		/* 1155 */setBlock(world, i + 10, j + 23, k + 8, Blocks.log, 0);
		/* 1156 */setBlock(world, i + 10, j + 24, k + 8, Blocks.log, 0);
		/* 1157 */setBlock(world, i + 10, j + 25, k + 8, Blocks.log, 0);
		/* 1158 */setBlock(world, i + 10, j + 26, k + 4, Blocks.log, 0);
		/* 1159 */setBlock(world, i + 10, j + 26, k + 5, Blocks.log, 0);
		/* 1160 */setBlock(world, i + 10, j + 26, k + 8, Blocks.log, 0);
		/* 1161 */setBlock(world, i + 10, j + 27, k + 4, Blocks.log, 0);
		/* 1162 */setBlock(world, i + 10, j + 27, k + 5, Blocks.log, 0);
		/* 1163 */setBlock(world, i + 10, j + 37, k + 5, Blocks.log, 0);
		/* 1164 */setBlock(world, i + 10, j + 38, k + 5, Blocks.log, 0);
		/* 1165 */setBlock(world, i + 10, j + 41, k + 10, Blocks.log, 0);
		/* 1166 */setBlock(world, i + 10, j + 42, k + 10, Blocks.log, 0);
		/* 1167 */setBlock(world, i + 10, j + 43, k + 11, Blocks.log, 0);
		/* 1168 */setBlock(world, i + 10, j + 44, k + 5, Blocks.log, 0);
		/* 1169 */setBlock(world, i + 10, j + 46, k + 4, Blocks.log, 0);
		/* 1170 */setBlock(world, i + 10, j + 46, k + 5, Blocks.log, 0);
		/* 1171 */setBlock(world, i + 10, j + 46, k + 13, Blocks.log, 0);
		/* 1172 */setBlock(world, i + 11, j + 0, k + 6, Blocks.log, 0);
		/* 1173 */setBlock(world, i + 11, j + 0, k + 7, Blocks.log, 0);
		/* 1174 */setBlock(world, i + 11, j + 0, k + 8, Blocks.log, 0);
		/* 1175 */setBlock(world, i + 11, j + 0, k + 9, Blocks.log, 0);
		/* 1176 */setBlock(world, i + 11, j + 0, k + 10, Blocks.log, 0);
		/* 1177 */setBlock(world, i + 11, j + 1, k + 6, Blocks.log, 0);
		/* 1178 */setBlock(world, i + 11, j + 1, k + 7, Blocks.log, 0);
		/* 1179 */setBlock(world, i + 11, j + 1, k + 8, Blocks.log, 0);
		/* 1180 */setBlock(world, i + 11, j + 1, k + 9, Blocks.log, 0);
		/* 1181 */setBlock(world, i + 11, j + 1, k + 10, Blocks.log, 0);
		/* 1182 */setBlock(world, i + 11, j + 2, k + 6, Blocks.log, 0);
		/* 1183 */setBlock(world, i + 11, j + 2, k + 7, Blocks.log, 0);
		/* 1184 */setBlock(world, i + 11, j + 2, k + 8, Blocks.log, 0);
		/* 1185 */setBlock(world, i + 11, j + 2, k + 9, Blocks.log, 0);
		/* 1186 */setBlock(world, i + 11, j + 2, k + 10, Blocks.log, 0);
		/* 1187 */setBlock(world, i + 11, j + 3, k + 6, Blocks.log, 0);
		/* 1188 */setBlock(world, i + 11, j + 3, k + 7, Blocks.log, 0);
		/* 1189 */setBlock(world, i + 11, j + 3, k + 8, Blocks.log, 0);
		/* 1190 */setBlock(world, i + 11, j + 3, k + 9, Blocks.log, 0);
		/* 1191 */setBlock(world, i + 11, j + 3, k + 10, Blocks.log, 0);
		/* 1192 */setBlock(world, i + 11, j + 4, k + 6, Blocks.log, 0);
		/* 1193 */setBlock(world, i + 11, j + 4, k + 7, Blocks.log, 0);
		/* 1194 */setBlock(world, i + 11, j + 4, k + 8, Blocks.log, 0);
		/* 1195 */setBlock(world, i + 11, j + 4, k + 9, Blocks.log, 0);
		/* 1196 */setBlock(world, i + 11, j + 4, k + 10, Blocks.log, 0);
		/* 1197 */setBlock(world, i + 11, j + 5, k + 6, Blocks.log, 0);
		/* 1198 */setBlock(world, i + 11, j + 5, k + 7, Blocks.log, 0);
		/* 1199 */setBlock(world, i + 11, j + 5, k + 8, Blocks.log, 0);
		/* 1200 */setBlock(world, i + 11, j + 5, k + 9, Blocks.log, 0);
		/* 1201 */setBlock(world, i + 11, j + 5, k + 10, Blocks.log, 0);
		/* 1202 */setBlock(world, i + 11, j + 5, k + 14, Blocks.log, 0);
		/* 1203 */setBlock(world, i + 11, j + 5, k + 15, Blocks.log, 0);
		/* 1204 */setBlock(world, i + 11, j + 6, k + 6, Blocks.log, 0);
		/* 1205 */setBlock(world, i + 11, j + 6, k + 7, Blocks.log, 0);
		/* 1206 */setBlock(world, i + 11, j + 6, k + 8, Blocks.log, 0);
		/* 1207 */setBlock(world, i + 11, j + 6, k + 9, Blocks.log, 0);
		/* 1208 */setBlock(world, i + 11, j + 6, k + 10, Blocks.log, 0);
		/* 1209 */setBlock(world, i + 11, j + 6, k + 13, Blocks.log, 0);
		/* 1210 */setBlock(world, i + 11, j + 6, k + 14, Blocks.log, 0);
		/* 1211 */setBlock(world, i + 11, j + 6, k + 15, Blocks.log, 0);
		/* 1212 */setBlock(world, i + 11, j + 7, k + 7, Blocks.log, 0);
		/* 1213 */setBlock(world, i + 11, j + 7, k + 8, Blocks.log, 0);
		/* 1214 */setBlock(world, i + 11, j + 7, k + 9, Blocks.log, 0);
		/* 1215 */setBlock(world, i + 11, j + 7, k + 10, Blocks.log, 0);
		/* 1216 */setBlock(world, i + 11, j + 7, k + 13, Blocks.log, 0);
		/* 1217 */setBlock(world, i + 11, j + 7, k + 14, Blocks.log, 0);
		/* 1218 */setBlock(world, i + 11, j + 7, k + 15, Blocks.log, 0);
		/* 1219 */setBlock(world, i + 11, j + 8, k + 6, Blocks.log, 0);
		/* 1220 */setBlock(world, i + 11, j + 8, k + 7, Blocks.log, 0);
		/* 1221 */setBlock(world, i + 11, j + 8, k + 8, Blocks.log, 0);
		/* 1222 */setBlock(world, i + 11, j + 8, k + 9, Blocks.log, 0);
		/* 1223 */setBlock(world, i + 11, j + 8, k + 13, Blocks.log, 0);
		/* 1224 */setBlock(world, i + 11, j + 9, k + 6, Blocks.log, 0);
		/* 1225 */setBlock(world, i + 11, j + 9, k + 7, Blocks.log, 0);
		/* 1226 */setBlock(world, i + 11, j + 9, k + 8, Blocks.log, 0);
		/* 1227 */setBlock(world, i + 11, j + 9, k + 9, Blocks.log, 0);
		/* 1228 */setBlock(world, i + 11, j + 10, k + 6, Blocks.log, 0);
		/* 1229 */setBlock(world, i + 11, j + 10, k + 7, Blocks.log, 0);
		/* 1230 */setBlock(world, i + 11, j + 10, k + 8, Blocks.log, 0);
		/* 1231 */setBlock(world, i + 11, j + 10, k + 9, Blocks.log, 0);
		/* 1232 */setBlock(world, i + 11, j + 11, k + 7, Blocks.log, 0);
		/* 1233 */setBlock(world, i + 11, j + 11, k + 8, Blocks.log, 0);
		/* 1234 */setBlock(world, i + 11, j + 11, k + 9, Blocks.log, 0);
		/* 1235 */setBlock(world, i + 11, j + 12, k + 7, Blocks.log, 0);
		/* 1236 */setBlock(world, i + 11, j + 12, k + 8, Blocks.log, 0);
		/* 1237 */setBlock(world, i + 11, j + 12, k + 9, Blocks.log, 0);
		/* 1238 */setBlock(world, i + 11, j + 13, k + 8, Blocks.log, 0);
		/* 1239 */setBlock(world, i + 11, j + 14, k + 8, Blocks.log, 0);
		/* 1240 */setBlock(world, i + 11, j + 15, k + 8, Blocks.log, 0);
		/* 1241 */setBlock(world, i + 11, j + 27, k + 3, Blocks.log, 0);
		/* 1242 */setBlock(world, i + 11, j + 39, k + 5, Blocks.log, 0);
		/* 1243 */setBlock(world, i + 11, j + 40, k + 4, Blocks.log, 0);
		/* 1244 */setBlock(world, i + 11, j + 44, k + 11, Blocks.log, 0);
		/* 1245 */setBlock(world, i + 11, j + 45, k + 11, Blocks.log, 0);
		/* 1246 */setBlock(world, i + 11, j + 46, k + 11, Blocks.log, 0);
		/* 1247 */setBlock(world, i + 12, j + 0, k + 7, Blocks.log, 0);
		/* 1248 */setBlock(world, i + 12, j + 0, k + 8, Blocks.log, 0);
		/* 1249 */setBlock(world, i + 12, j + 0, k + 9, Blocks.log, 0);
		/* 1250 */setBlock(world, i + 12, j + 1, k + 8, Blocks.log, 0);
		/* 1251 */setBlock(world, i + 12, j + 2, k + 8, Blocks.log, 0);
		/* 1252 */setBlock(world, i + 12, j + 3, k + 8, Blocks.log, 0);
		/* 1253 */setBlock(world, i + 12, j + 5, k + 15, Blocks.log, 0);
		/* 1254 */setBlock(world, i + 12, j + 6, k + 15, Blocks.log, 0);
		/* 1255 */setBlock(world, i + 12, j + 7, k + 5, Blocks.log, 0);
		/* 1256 */setBlock(world, i + 12, j + 7, k + 6, Blocks.log, 0);
		/* 1257 */setBlock(world, i + 12, j + 7, k + 7, Blocks.log, 0);
		/* 1258 */setBlock(world, i + 12, j + 7, k + 8, Blocks.log, 0);
		/* 1259 */setBlock(world, i + 12, j + 7, k + 15, Blocks.log, 0);
		/* 1260 */setBlock(world, i + 12, j + 8, k + 5, Blocks.log, 0);
		/* 1261 */setBlock(world, i + 12, j + 8, k + 6, Blocks.log, 0);
		/* 1262 */setBlock(world, i + 12, j + 8, k + 7, Blocks.log, 0);
		/* 1263 */setBlock(world, i + 12, j + 8, k + 8, Blocks.log, 0);
		/* 1264 */setBlock(world, i + 12, j + 8, k + 9, Blocks.log, 0);
		/* 1265 */setBlock(world, i + 12, j + 9, k + 5, Blocks.log, 0);
		/* 1266 */setBlock(world, i + 12, j + 9, k + 6, Blocks.log, 0);
		/* 1267 */setBlock(world, i + 12, j + 9, k + 7, Blocks.log, 0);
		/* 1268 */setBlock(world, i + 12, j + 9, k + 8, Blocks.log, 0);
		/* 1269 */setBlock(world, i + 12, j + 9, k + 9, Blocks.log, 0);
		/* 1270 */setBlock(world, i + 12, j + 10, k + 7, Blocks.log, 0);
		/* 1271 */setBlock(world, i + 12, j + 10, k + 8, Blocks.log, 0);
		/* 1272 */setBlock(world, i + 12, j + 10, k + 9, Blocks.log, 0);
		/* 1273 */setBlock(world, i + 12, j + 39, k + 2, Blocks.log, 0);
		/* 1274 */setBlock(world, i + 12, j + 41, k + 3, Blocks.log, 0);
		/* 1275 */setBlock(world, i + 12, j + 46, k + 11, Blocks.log, 0);
		/* 1276 */setBlock(world, i + 12, j + 47, k + 3, Blocks.log, 0);
		/* 1277 */setBlock(world, i + 12, j + 47, k + 11, Blocks.log, 0);
		/* 1278 */setBlock(world, i + 13, j + 6, k + 5, Blocks.log, 0);
		/* 1279 */setBlock(world, i + 13, j + 6, k + 6, Blocks.log, 0);
		/* 1280 */setBlock(world, i + 13, j + 6, k + 7, Blocks.log, 0);
		/* 1281 */setBlock(world, i + 13, j + 6, k + 8, Blocks.log, 0);
		/* 1282 */setBlock(world, i + 13, j + 7, k + 5, Blocks.log, 0);
		/* 1283 */setBlock(world, i + 13, j + 7, k + 6, Blocks.log, 0);
		/* 1284 */setBlock(world, i + 13, j + 7, k + 7, Blocks.log, 0);
		/* 1285 */setBlock(world, i + 13, j + 7, k + 8, Blocks.log, 0);
		/* 1286 */setBlock(world, i + 13, j + 7, k + 9, Blocks.log, 0);
		/* 1287 */setBlock(world, i + 13, j + 8, k + 5, Blocks.log, 0);
		/* 1288 */setBlock(world, i + 13, j + 8, k + 6, Blocks.log, 0);
		/* 1289 */setBlock(world, i + 13, j + 8, k + 7, Blocks.log, 0);
		/* 1290 */setBlock(world, i + 13, j + 8, k + 8, Blocks.log, 0);
		/* 1291 */setBlock(world, i + 13, j + 8, k + 9, Blocks.log, 0);
		/* 1292 */setBlock(world, i + 13, j + 9, k + 7, Blocks.log, 0);
		/* 1293 */setBlock(world, i + 13, j + 9, k + 8, Blocks.log, 0);
		/* 1294 */setBlock(world, i + 13, j + 9, k + 9, Blocks.log, 0);
		/* 1295 */setBlock(world, i + 13, j + 40, k + 1, Blocks.log, 0);
		/* 1296 */setBlock(world, i + 13, j + 42, k + 2, Blocks.log, 0);
		/* 1297 */setBlock(world, i + 13, j + 46, k + 1, Blocks.log, 0);
		/* 1298 */setBlock(world, i + 13, j + 47, k + 11, Blocks.log, 0);
		/* 1299 */setBlock(world, i + 14, j + 5, k + 4, Blocks.log, 0);
		/* 1300 */setBlock(world, i + 14, j + 5, k + 5, Blocks.log, 0);
		/* 1301 */setBlock(world, i + 14, j + 5, k + 6, Blocks.log, 0);
		/* 1302 */setBlock(world, i + 14, j + 5, k + 7, Blocks.log, 0);
		/* 1303 */setBlock(world, i + 14, j + 5, k + 8, Blocks.log, 0);
		/* 1304 */setBlock(world, i + 14, j + 6, k + 4, Blocks.log, 0);
		/* 1305 */setBlock(world, i + 14, j + 6, k + 5, Blocks.log, 0);
		/* 1306 */setBlock(world, i + 14, j + 6, k + 6, Blocks.log, 0);
		/* 1307 */setBlock(world, i + 14, j + 6, k + 7, Blocks.log, 0);
		/* 1308 */setBlock(world, i + 14, j + 6, k + 8, Blocks.log, 0);
		/* 1309 */setBlock(world, i + 14, j + 6, k + 9, Blocks.log, 0);
		/* 1310 */setBlock(world, i + 14, j + 7, k + 4, Blocks.log, 0);
		/* 1311 */setBlock(world, i + 14, j + 7, k + 5, Blocks.log, 0);
		/* 1312 */setBlock(world, i + 14, j + 7, k + 6, Blocks.log, 0);
		/* 1313 */setBlock(world, i + 14, j + 7, k + 7, Blocks.log, 0);
		/* 1314 */setBlock(world, i + 14, j + 7, k + 8, Blocks.log, 0);
		/* 1315 */setBlock(world, i + 14, j + 7, k + 9, Blocks.log, 0);
		/* 1316 */setBlock(world, i + 14, j + 8, k + 7, Blocks.log, 0);
		/* 1317 */setBlock(world, i + 14, j + 8, k + 8, Blocks.log, 0);
		/* 1318 */setBlock(world, i + 14, j + 8, k + 9, Blocks.log, 0);
		/* 1319 */setBlock(world, i + 14, j + 47, k + 3, Blocks.log, 0);
		/* 1320 */setBlock(world, i + 14, j + 47, k + 10, Blocks.log, 0);
		/* 1321 */setBlock(world, i + 15, j + 4, k + 4, Blocks.log, 0);
		/* 1322 */setBlock(world, i + 15, j + 4, k + 5, Blocks.log, 0);
		/* 1323 */setBlock(world, i + 15, j + 4, k + 6, Blocks.log, 0);
		/* 1324 */setBlock(world, i + 15, j + 4, k + 7, Blocks.log, 0);
		/* 1325 */setBlock(world, i + 15, j + 5, k + 4, Blocks.log, 0);
		/* 1326 */setBlock(world, i + 15, j + 5, k + 5, Blocks.log, 0);
		/* 1327 */setBlock(world, i + 15, j + 5, k + 6, Blocks.log, 0);
		/* 1328 */setBlock(world, i + 15, j + 5, k + 7, Blocks.log, 0);
		/* 1329 */setBlock(world, i + 15, j + 5, k + 8, Blocks.log, 0);
		/* 1330 */setBlock(world, i + 15, j + 5, k + 9, Blocks.log, 0);
		/* 1331 */setBlock(world, i + 15, j + 6, k + 4, Blocks.log, 0);
		/* 1332 */setBlock(world, i + 15, j + 6, k + 5, Blocks.log, 0);
		/* 1333 */setBlock(world, i + 15, j + 6, k + 6, Blocks.log, 0);
		/* 1334 */setBlock(world, i + 15, j + 6, k + 7, Blocks.log, 0);
		/* 1335 */setBlock(world, i + 15, j + 6, k + 8, Blocks.log, 0);
		/* 1336 */setBlock(world, i + 15, j + 6, k + 9, Blocks.log, 0);
		/* 1337 */setBlock(world, i + 15, j + 7, k + 7, Blocks.log, 0);
		/* 1338 */setBlock(world, i + 15, j + 7, k + 8, Blocks.log, 0);
		/* 1339 */setBlock(world, i + 15, j + 7, k + 9, Blocks.log, 0);
		/* 1340 */setBlock(world, i + 0, j + 31, k + 0, Blocks.leaves, 4);
		/* 1341 */world.setBlockMetadataWithNotify(i + 0, j + 31, k + 0, 4, 2);
		/* 1342 */setBlock(world, i + 0, j + 31, k + 1, Blocks.leaves, 4);
		/* 1343 */world.setBlockMetadataWithNotify(i + 0, j + 31, k + 1, 4, 2);
		/* 1344 */setBlock(world, i + 0, j + 32, k + 0, Blocks.leaves, 4);
		/* 1345 */world.setBlockMetadataWithNotify(i + 0, j + 32, k + 0, 4, 2);
		/* 1346 */setBlock(world, i + 0, j + 32, k + 1, Blocks.leaves, 4);
		/* 1347 */world.setBlockMetadataWithNotify(i + 0, j + 32, k + 1, 4, 2);
		/* 1348 */setBlock(world, i + 0, j + 37, k + 2, Blocks.leaves, 4);
		/* 1349 */world.setBlockMetadataWithNotify(i + 0, j + 37, k + 2, 4, 2);
		/* 1350 */setBlock(world, i + 0, j + 38, k + 0, Blocks.leaves, 4);
		/* 1351 */world.setBlockMetadataWithNotify(i + 0, j + 38, k + 0, 4, 2);
		/* 1352 */setBlock(world, i + 0, j + 38, k + 1, Blocks.leaves, 4);
		/* 1353 */world.setBlockMetadataWithNotify(i + 0, j + 38, k + 1, 4, 2);
		/* 1354 */setBlock(world, i + 0, j + 38, k + 2, Blocks.leaves, 4);
		/* 1355 */world.setBlockMetadataWithNotify(i + 0, j + 38, k + 2, 4, 2);
		/* 1356 */setBlock(world, i + 0, j + 38, k + 3, Blocks.leaves, 4);
		/* 1357 */world.setBlockMetadataWithNotify(i + 0, j + 38, k + 3, 4, 2);
		/* 1358 */setBlock(world, i + 0, j + 38, k + 4, Blocks.leaves, 4);
		/* 1359 */world.setBlockMetadataWithNotify(i + 0, j + 38, k + 4, 4, 2);
		/* 1360 */setBlock(world, i + 0, j + 39, k + 0, Blocks.leaves, 4);
		/* 1361 */world.setBlockMetadataWithNotify(i + 0, j + 39, k + 0, 4, 2);
		/* 1362 */setBlock(world, i + 0, j + 39, k + 1, Blocks.leaves, 4);
		/* 1363 */world.setBlockMetadataWithNotify(i + 0, j + 39, k + 1, 4, 2);
		/* 1364 */setBlock(world, i + 0, j + 39, k + 2, Blocks.leaves, 4);
		/* 1365 */world.setBlockMetadataWithNotify(i + 0, j + 39, k + 2, 4, 2);
		/* 1366 */setBlock(world, i + 0, j + 39, k + 3, Blocks.leaves, 4);
		/* 1367 */world.setBlockMetadataWithNotify(i + 0, j + 39, k + 3, 4, 2);
		/* 1368 */setBlock(world, i + 0, j + 39, k + 4, Blocks.leaves, 4);
		/* 1369 */world.setBlockMetadataWithNotify(i + 0, j + 39, k + 4, 4, 2);
		/* 1370 */setBlock(world, i + 0, j + 40, k + 1, Blocks.leaves, 4);
		/* 1371 */world.setBlockMetadataWithNotify(i + 0, j + 40, k + 1, 4, 2);
		/* 1372 */setBlock(world, i + 0, j + 40, k + 2, Blocks.leaves, 4);
		/* 1373 */world.setBlockMetadataWithNotify(i + 0, j + 40, k + 2, 4, 2);
		/* 1374 */setBlock(world, i + 0, j + 40, k + 3, Blocks.leaves, 4);
		/* 1375 */world.setBlockMetadataWithNotify(i + 0, j + 40, k + 3, 4, 2);
		/* 1376 */setBlock(world, i + 0, j + 41, k + 2, Blocks.leaves, 4);
		/* 1377 */world.setBlockMetadataWithNotify(i + 0, j + 41, k + 2, 4, 2);
		/* 1378 */setBlock(world, i + 0, j + 43, k + 0, Blocks.leaves, 4);
		/* 1379 */world.setBlockMetadataWithNotify(i + 0, j + 43, k + 0, 4, 2);
		/* 1380 */setBlock(world, i + 0, j + 44, k + 0, Blocks.leaves, 4);
		/* 1381 */world.setBlockMetadataWithNotify(i + 0, j + 44, k + 0, 4, 2);
		/* 1382 */setBlock(world, i + 0, j + 44, k + 1, Blocks.leaves, 4);
		/* 1383 */world.setBlockMetadataWithNotify(i + 0, j + 44, k + 1, 4, 2);
		/* 1384 */setBlock(world, i + 0, j + 44, k + 2, Blocks.leaves, 4);
		/* 1385 */world.setBlockMetadataWithNotify(i + 0, j + 44, k + 2, 4, 2);
		/* 1386 */setBlock(world, i + 0, j + 44, k + 3, Blocks.leaves, 4);
		/* 1387 */world.setBlockMetadataWithNotify(i + 0, j + 44, k + 3, 4, 2);
		/* 1388 */setBlock(world, i + 0, j + 44, k + 4, Blocks.leaves, 4);
		/* 1389 */world.setBlockMetadataWithNotify(i + 0, j + 44, k + 4, 4, 2);
		/* 1390 */setBlock(world, i + 0, j + 44, k + 5, Blocks.leaves, 4);
		/* 1391 */world.setBlockMetadataWithNotify(i + 0, j + 44, k + 5, 4, 2);
		/* 1392 */setBlock(world, i + 0, j + 45, k + 0, Blocks.leaves, 4);
		/* 1393 */world.setBlockMetadataWithNotify(i + 0, j + 45, k + 0, 4, 2);
		/* 1394 */setBlock(world, i + 0, j + 45, k + 1, Blocks.leaves, 4);
		/* 1395 */world.setBlockMetadataWithNotify(i + 0, j + 45, k + 1, 4, 2);
		/* 1396 */setBlock(world, i + 0, j + 45, k + 2, Blocks.leaves, 4);
		/* 1397 */world.setBlockMetadataWithNotify(i + 0, j + 45, k + 2, 4, 2);
		/* 1398 */setBlock(world, i + 0, j + 45, k + 3, Blocks.leaves, 4);
		/* 1399 */world.setBlockMetadataWithNotify(i + 0, j + 45, k + 3, 4, 2);
		/* 1400 */setBlock(world, i + 0, j + 45, k + 4, Blocks.leaves, 4);
		/* 1401 */world.setBlockMetadataWithNotify(i + 0, j + 45, k + 4, 4, 2);
		/* 1402 */setBlock(world, i + 0, j + 45, k + 5, Blocks.leaves, 4);
		/* 1403 */world.setBlockMetadataWithNotify(i + 0, j + 45, k + 5, 4, 2);
		/* 1404 */setBlock(world, i + 0, j + 46, k + 0, Blocks.leaves, 4);
		/* 1405 */world.setBlockMetadataWithNotify(i + 0, j + 46, k + 0, 4, 2);
		/* 1406 */setBlock(world, i + 0, j + 46, k + 1, Blocks.leaves, 4);
		/* 1407 */world.setBlockMetadataWithNotify(i + 0, j + 46, k + 1, 4, 2);
		/* 1408 */setBlock(world, i + 0, j + 46, k + 2, Blocks.leaves, 4);
		/* 1409 */world.setBlockMetadataWithNotify(i + 0, j + 46, k + 2, 4, 2);
		/* 1410 */setBlock(world, i + 0, j + 46, k + 8, Blocks.leaves, 4);
		/* 1411 */world.setBlockMetadataWithNotify(i + 0, j + 46, k + 8, 4, 2);
		/* 1412 */setBlock(world, i + 0, j + 47, k + 0, Blocks.leaves, 4);
		/* 1413 */world.setBlockMetadataWithNotify(i + 0, j + 47, k + 0, 4, 2);
		/* 1414 */setBlock(world, i + 0, j + 47, k + 1, Blocks.leaves, 4);
		/* 1415 */world.setBlockMetadataWithNotify(i + 0, j + 47, k + 1, 4, 2);
		/* 1416 */setBlock(world, i + 0, j + 47, k + 2, Blocks.leaves, 4);
		/* 1417 */world.setBlockMetadataWithNotify(i + 0, j + 47, k + 2, 4, 2);
		/* 1418 */setBlock(world, i + 0, j + 47, k + 3, Blocks.leaves, 4);
		/* 1419 */world.setBlockMetadataWithNotify(i + 0, j + 47, k + 3, 4, 2);
		/* 1420 */setBlock(world, i + 0, j + 47, k + 4, Blocks.leaves, 4);
		/* 1421 */world.setBlockMetadataWithNotify(i + 0, j + 47, k + 4, 4, 2);
		/* 1422 */setBlock(world, i + 0, j + 47, k + 6, Blocks.leaves, 4);
		/* 1423 */world.setBlockMetadataWithNotify(i + 0, j + 47, k + 6, 4, 2);
		/* 1424 */setBlock(world, i + 0, j + 47, k + 7, Blocks.leaves, 4);
		/* 1425 */world.setBlockMetadataWithNotify(i + 0, j + 47, k + 7, 4, 2);
		/* 1426 */setBlock(world, i + 0, j + 47, k + 8, Blocks.leaves, 4);
		/* 1427 */world.setBlockMetadataWithNotify(i + 0, j + 47, k + 8, 4, 2);
		/* 1428 */setBlock(world, i + 0, j + 47, k + 9, Blocks.leaves, 4);
		/* 1429 */world.setBlockMetadataWithNotify(i + 0, j + 47, k + 9, 4, 2);
		/* 1430 */setBlock(world, i + 0, j + 47, k + 10, Blocks.leaves, 4);
		/* 1431 */world.setBlockMetadataWithNotify(i + 0, j + 47, k + 10, 4, 2);
		/* 1432 */setBlock(world, i + 0, j + 48, k + 2, Blocks.leaves, 4);
		/* 1433 */world.setBlockMetadataWithNotify(i + 0, j + 48, k + 2, 4, 2);
		/* 1434 */setBlock(world, i + 0, j + 48, k + 3, Blocks.leaves, 4);
		/* 1435 */world.setBlockMetadataWithNotify(i + 0, j + 48, k + 3, 4, 2);
		/* 1436 */setBlock(world, i + 0, j + 48, k + 4, Blocks.leaves, 4);
		/* 1437 */world.setBlockMetadataWithNotify(i + 0, j + 48, k + 4, 4, 2);
		/* 1438 */setBlock(world, i + 0, j + 48, k + 5, Blocks.leaves, 4);
		/* 1439 */world.setBlockMetadataWithNotify(i + 0, j + 48, k + 5, 4, 2);
		/* 1440 */setBlock(world, i + 0, j + 48, k + 6, Blocks.leaves, 4);
		/* 1441 */world.setBlockMetadataWithNotify(i + 0, j + 48, k + 6, 4, 2);
		/* 1442 */setBlock(world, i + 0, j + 48, k + 7, Blocks.leaves, 4);
		/* 1443 */world.setBlockMetadataWithNotify(i + 0, j + 48, k + 7, 4, 2);
		/* 1444 */setBlock(world, i + 0, j + 48, k + 8, Blocks.leaves, 4);
		/* 1445 */world.setBlockMetadataWithNotify(i + 0, j + 48, k + 8, 4, 2);
		/* 1446 */setBlock(world, i + 0, j + 48, k + 9, Blocks.leaves, 4);
		/* 1447 */world.setBlockMetadataWithNotify(i + 0, j + 48, k + 9, 4, 2);
		/* 1448 */setBlock(world, i + 0, j + 48, k + 10, Blocks.leaves, 4);
		/* 1449 */world.setBlockMetadataWithNotify(i + 0, j + 48, k + 10, 4, 2);
		/* 1450 */setBlock(world, i + 0, j + 49, k + 4, Blocks.leaves, 4);
		/* 1451 */world.setBlockMetadataWithNotify(i + 0, j + 49, k + 4, 4, 2);
		/* 1452 */setBlock(world, i + 0, j + 49, k + 5, Blocks.leaves, 4);
		/* 1453 */world.setBlockMetadataWithNotify(i + 0, j + 49, k + 5, 4, 2);
		/* 1454 */setBlock(world, i + 0, j + 49, k + 6, Blocks.leaves, 4);
		/* 1455 */world.setBlockMetadataWithNotify(i + 0, j + 49, k + 6, 4, 2);
		/* 1456 */setBlock(world, i + 0, j + 49, k + 7, Blocks.leaves, 4);
		/* 1457 */world.setBlockMetadataWithNotify(i + 0, j + 49, k + 7, 4, 2);
		/* 1458 */setBlock(world, i + 0, j + 49, k + 8, Blocks.leaves, 4);
		/* 1459 */world.setBlockMetadataWithNotify(i + 0, j + 49, k + 8, 4, 2);
		/* 1460 */setBlock(world, i + 0, j + 49, k + 9, Blocks.leaves, 4);
		/* 1461 */world.setBlockMetadataWithNotify(i + 0, j + 49, k + 9, 4, 2);
		/* 1462 */setBlock(world, i + 0, j + 49, k + 10, Blocks.leaves, 4);
		/* 1463 */world.setBlockMetadataWithNotify(i + 0, j + 49, k + 10, 4, 2);
		/* 1464 */setBlock(world, i + 0, j + 50, k + 5, Blocks.leaves, 4);
		/* 1465 */world.setBlockMetadataWithNotify(i + 0, j + 50, k + 5, 4, 2);
		/* 1466 */setBlock(world, i + 0, j + 50, k + 6, Blocks.leaves, 4);
		/* 1467 */world.setBlockMetadataWithNotify(i + 0, j + 50, k + 6, 4, 2);
		/* 1468 */setBlock(world, i + 0, j + 50, k + 7, Blocks.leaves, 4);
		/* 1469 */world.setBlockMetadataWithNotify(i + 0, j + 50, k + 7, 4, 2);
		/* 1470 */setBlock(world, i + 0, j + 50, k + 8, Blocks.leaves, 4);
		/* 1471 */world.setBlockMetadataWithNotify(i + 0, j + 50, k + 8, 4, 2);
		/* 1472 */setBlock(world, i + 0, j + 50, k + 9, Blocks.leaves, 4);
		/* 1473 */world.setBlockMetadataWithNotify(i + 0, j + 50, k + 9, 4, 2);
		/* 1474 */setBlock(world, i + 0, j + 51, k + 6, Blocks.leaves, 4);
		/* 1475 */world.setBlockMetadataWithNotify(i + 0, j + 51, k + 6, 4, 2);
		/* 1476 */setBlock(world, i + 0, j + 51, k + 7, Blocks.leaves, 4);
		/* 1477 */world.setBlockMetadataWithNotify(i + 0, j + 51, k + 7, 4, 2);
		/* 1478 */setBlock(world, i + 0, j + 51, k + 8, Blocks.leaves, 4);
		/* 1479 */world.setBlockMetadataWithNotify(i + 0, j + 51, k + 8, 4, 2);
		/* 1480 */setBlock(world, i + 1, j + 30, k + 0, Blocks.leaves, 4);
		/* 1481 */world.setBlockMetadataWithNotify(i + 1, j + 30, k + 0, 4, 2);
		/* 1482 */setBlock(world, i + 1, j + 31, k + 0, Blocks.leaves, 4);
		/* 1483 */world.setBlockMetadataWithNotify(i + 1, j + 31, k + 0, 4, 2);
		/* 1484 */setBlock(world, i + 1, j + 31, k + 1, Blocks.leaves, 4);
		/* 1485 */world.setBlockMetadataWithNotify(i + 1, j + 31, k + 1, 4, 2);
		/* 1486 */setBlock(world, i + 1, j + 31, k + 2, Blocks.leaves, 4);
		/* 1487 */world.setBlockMetadataWithNotify(i + 1, j + 31, k + 2, 4, 2);
		/* 1488 */setBlock(world, i + 1, j + 32, k + 0, Blocks.leaves, 4);
		/* 1489 */world.setBlockMetadataWithNotify(i + 1, j + 32, k + 0, 4, 2);
		/* 1490 */setBlock(world, i + 1, j + 32, k + 1, Blocks.leaves, 4);
		/* 1491 */world.setBlockMetadataWithNotify(i + 1, j + 32, k + 1, 4, 2);
		/* 1492 */setBlock(world, i + 1, j + 32, k + 2, Blocks.leaves, 4);
		/* 1493 */world.setBlockMetadataWithNotify(i + 1, j + 32, k + 2, 4, 2);
		/* 1494 */setBlock(world, i + 1, j + 33, k + 0, Blocks.leaves, 4);
		/* 1495 */world.setBlockMetadataWithNotify(i + 1, j + 33, k + 0, 4, 2);
		/* 1496 */setBlock(world, i + 1, j + 33, k + 1, Blocks.leaves, 4);
		/* 1497 */world.setBlockMetadataWithNotify(i + 1, j + 33, k + 1, 4, 2);
		/* 1498 */setBlock(world, i + 1, j + 34, k + 0, Blocks.leaves, 4);
		/* 1499 */world.setBlockMetadataWithNotify(i + 1, j + 34, k + 0, 4, 2);
		/* 1500 */setBlock(world, i + 1, j + 37, k + 1, Blocks.leaves, 4);
		/* 1501 */world.setBlockMetadataWithNotify(i + 1, j + 37, k + 1, 4, 2);
		/* 1502 */setBlock(world, i + 1, j + 37, k + 3, Blocks.leaves, 4);
		/* 1503 */world.setBlockMetadataWithNotify(i + 1, j + 37, k + 3, 4, 2);
		/* 1504 */setBlock(world, i + 1, j + 38, k + 0, Blocks.leaves, 4);
		/* 1505 */world.setBlockMetadataWithNotify(i + 1, j + 38, k + 0, 4, 2);
		/* 1506 */setBlock(world, i + 1, j + 38, k + 1, Blocks.leaves, 4);
		/* 1507 */world.setBlockMetadataWithNotify(i + 1, j + 38, k + 1, 4, 2);
		/* 1508 */setBlock(world, i + 1, j + 38, k + 2, Blocks.leaves, 4);
		/* 1509 */world.setBlockMetadataWithNotify(i + 1, j + 38, k + 2, 4, 2);
		/* 1510 */setBlock(world, i + 1, j + 38, k + 3, Blocks.leaves, 4);
		/* 1511 */world.setBlockMetadataWithNotify(i + 1, j + 38, k + 3, 4, 2);
		/* 1512 */setBlock(world, i + 1, j + 38, k + 4, Blocks.leaves, 4);
		/* 1513 */world.setBlockMetadataWithNotify(i + 1, j + 38, k + 4, 4, 2);
		/* 1514 */setBlock(world, i + 1, j + 39, k + 0, Blocks.leaves, 4);
		/* 1515 */world.setBlockMetadataWithNotify(i + 1, j + 39, k + 0, 4, 2);
		/* 1516 */setBlock(world, i + 1, j + 39, k + 1, Blocks.leaves, 4);
		/* 1517 */world.setBlockMetadataWithNotify(i + 1, j + 39, k + 1, 4, 2);
		/* 1518 */setBlock(world, i + 1, j + 39, k + 2, Blocks.leaves, 4);
		/* 1519 */world.setBlockMetadataWithNotify(i + 1, j + 39, k + 2, 4, 2);
		/* 1520 */setBlock(world, i + 1, j + 39, k + 3, Blocks.leaves, 4);
		/* 1521 */world.setBlockMetadataWithNotify(i + 1, j + 39, k + 3, 4, 2);
		/* 1522 */setBlock(world, i + 1, j + 39, k + 4, Blocks.leaves, 4);
		/* 1523 */world.setBlockMetadataWithNotify(i + 1, j + 39, k + 4, 4, 2);
		/* 1524 */setBlock(world, i + 1, j + 40, k + 1, Blocks.leaves, 4);
		/* 1525 */world.setBlockMetadataWithNotify(i + 1, j + 40, k + 1, 4, 2);
		/* 1526 */setBlock(world, i + 1, j + 40, k + 2, Blocks.leaves, 4);
		/* 1527 */world.setBlockMetadataWithNotify(i + 1, j + 40, k + 2, 4, 2);
		/* 1528 */setBlock(world, i + 1, j + 40, k + 3, Blocks.leaves, 4);
		/* 1529 */world.setBlockMetadataWithNotify(i + 1, j + 40, k + 3, 4, 2);
		/* 1530 */setBlock(world, i + 1, j + 41, k + 1, Blocks.leaves, 4);
		/* 1531 */world.setBlockMetadataWithNotify(i + 1, j + 41, k + 1, 4, 2);
		/*      */
		/* 1533 */generate2(world, rand, i, j, k);
		/* 1534 */return true;
		/*      */}

	/*      */
	/*      */public boolean generate2(World world, Random rand, int i, int j, int k)
	/*      */
	{
		/* 1539 */setBlock(world, i + 1, j + 41, k + 2, Blocks.leaves, 4);
		/* 1540 */world.setBlockMetadataWithNotify(i + 1, j + 41, k + 2, 4, 2);
		/* 1541 */setBlock(world, i + 1, j + 41, k + 3, Blocks.leaves, 4);
		/* 1542 */world.setBlockMetadataWithNotify(i + 1, j + 41, k + 3, 4, 2);
		/* 1543 */setBlock(world, i + 1, j + 41, k + 11, Blocks.leaves, 4);
		/* 1544 */world.setBlockMetadataWithNotify(i + 1, j + 41, k + 11, 4, 2);
		/* 1545 */setBlock(world, i + 1, j + 41, k + 12, Blocks.leaves, 4);
		/* 1546 */world.setBlockMetadataWithNotify(i + 1, j + 41, k + 12, 4, 2);
		/* 1547 */setBlock(world, i + 1, j + 41, k + 13, Blocks.leaves, 4);
		/* 1548 */world.setBlockMetadataWithNotify(i + 1, j + 41, k + 13, 4, 2);
		/* 1549 */setBlock(world, i + 1, j + 42, k + 11, Blocks.leaves, 4);
		/* 1550 */world.setBlockMetadataWithNotify(i + 1, j + 42, k + 11, 4, 2);
		/* 1551 */setBlock(world, i + 1, j + 42, k + 12, Blocks.leaves, 4);
		/* 1552 */world.setBlockMetadataWithNotify(i + 1, j + 42, k + 12, 4, 2);
		/* 1553 */setBlock(world, i + 1, j + 42, k + 13, Blocks.leaves, 4);
		/* 1554 */world.setBlockMetadataWithNotify(i + 1, j + 42, k + 13, 4, 2);
		/* 1555 */setBlock(world, i + 1, j + 43, k + 1, Blocks.leaves, 4);
		/* 1556 */world.setBlockMetadataWithNotify(i + 1, j + 43, k + 1, 4, 2);
		/* 1557 */setBlock(world, i + 1, j + 43, k + 4, Blocks.leaves, 4);
		/* 1558 */world.setBlockMetadataWithNotify(i + 1, j + 43, k + 4, 4, 2);
		/* 1559 */setBlock(world, i + 1, j + 43, k + 11, Blocks.leaves, 4);
		/* 1560 */world.setBlockMetadataWithNotify(i + 1, j + 43, k + 11, 4, 2);
		/* 1561 */setBlock(world, i + 1, j + 43, k + 12, Blocks.leaves, 4);
		/* 1562 */world.setBlockMetadataWithNotify(i + 1, j + 43, k + 12, 4, 2);
		/* 1563 */setBlock(world, i + 1, j + 43, k + 13, Blocks.leaves, 4);
		/* 1564 */world.setBlockMetadataWithNotify(i + 1, j + 43, k + 13, 4, 2);
		/* 1565 */setBlock(world, i + 1, j + 44, k + 0, Blocks.leaves, 4);
		/* 1566 */world.setBlockMetadataWithNotify(i + 1, j + 44, k + 0, 4, 2);
		/* 1567 */setBlock(world, i + 1, j + 44, k + 1, Blocks.leaves, 4);
		/* 1568 */world.setBlockMetadataWithNotify(i + 1, j + 44, k + 1, 4, 2);
		/* 1569 */setBlock(world, i + 1, j + 44, k + 2, Blocks.leaves, 4);
		/* 1570 */world.setBlockMetadataWithNotify(i + 1, j + 44, k + 2, 4, 2);
		/* 1571 */setBlock(world, i + 1, j + 44, k + 3, Blocks.leaves, 4);
		/* 1572 */world.setBlockMetadataWithNotify(i + 1, j + 44, k + 3, 4, 2);
		/* 1573 */setBlock(world, i + 1, j + 44, k + 4, Blocks.leaves, 4);
		/* 1574 */world.setBlockMetadataWithNotify(i + 1, j + 44, k + 4, 4, 2);
		/* 1575 */setBlock(world, i + 1, j + 44, k + 5, Blocks.leaves, 4);
		/* 1576 */world.setBlockMetadataWithNotify(i + 1, j + 44, k + 5, 4, 2);
		/* 1577 */setBlock(world, i + 1, j + 44, k + 6, Blocks.leaves, 4);
		/* 1578 */world.setBlockMetadataWithNotify(i + 1, j + 44, k + 6, 4, 2);
		/* 1579 */setBlock(world, i + 1, j + 45, k + 0, Blocks.leaves, 4);
		/* 1580 */world.setBlockMetadataWithNotify(i + 1, j + 45, k + 0, 4, 2);
		/* 1581 */setBlock(world, i + 1, j + 45, k + 1, Blocks.leaves, 4);
		/* 1582 */world.setBlockMetadataWithNotify(i + 1, j + 45, k + 1, 4, 2);
		/* 1583 */setBlock(world, i + 1, j + 45, k + 2, Blocks.leaves, 4);
		/* 1584 */world.setBlockMetadataWithNotify(i + 1, j + 45, k + 2, 4, 2);
		/* 1585 */setBlock(world, i + 1, j + 45, k + 3, Blocks.leaves, 4);
		/* 1586 */world.setBlockMetadataWithNotify(i + 1, j + 45, k + 3, 4, 2);
		/* 1587 */setBlock(world, i + 1, j + 45, k + 4, Blocks.leaves, 4);
		/* 1588 */world.setBlockMetadataWithNotify(i + 1, j + 45, k + 4, 4, 2);
		/* 1589 */setBlock(world, i + 1, j + 45, k + 5, Blocks.leaves, 4);
		/* 1590 */world.setBlockMetadataWithNotify(i + 1, j + 45, k + 5, 4, 2);
		/* 1591 */setBlock(world, i + 1, j + 45, k + 6, Blocks.leaves, 4);
		/* 1592 */world.setBlockMetadataWithNotify(i + 1, j + 45, k + 6, 4, 2);
		/* 1593 */setBlock(world, i + 1, j + 46, k + 0, Blocks.leaves, 4);
		/* 1594 */world.setBlockMetadataWithNotify(i + 1, j + 46, k + 0, 4, 2);
		/* 1595 */setBlock(world, i + 1, j + 46, k + 1, Blocks.leaves, 4);
		/* 1596 */world.setBlockMetadataWithNotify(i + 1, j + 46, k + 1, 4, 2);
		/* 1597 */setBlock(world, i + 1, j + 46, k + 2, Blocks.leaves, 4);
		/* 1598 */world.setBlockMetadataWithNotify(i + 1, j + 46, k + 2, 4, 2);
		/* 1599 */setBlock(world, i + 1, j + 46, k + 3, Blocks.leaves, 4);
		/* 1600 */world.setBlockMetadataWithNotify(i + 1, j + 46, k + 3, 4, 2);
		/* 1601 */setBlock(world, i + 1, j + 46, k + 4, Blocks.leaves, 4);
		/* 1602 */world.setBlockMetadataWithNotify(i + 1, j + 46, k + 4, 4, 2);
		/* 1603 */setBlock(world, i + 1, j + 46, k + 5, Blocks.leaves, 4);
		/* 1604 */world.setBlockMetadataWithNotify(i + 1, j + 46, k + 5, 4, 2);
		/* 1605 */setBlock(world, i + 1, j + 46, k + 7, Blocks.leaves, 4);
		/* 1606 */world.setBlockMetadataWithNotify(i + 1, j + 46, k + 7, 4, 2);
		/* 1607 */setBlock(world, i + 1, j + 46, k + 9, Blocks.leaves, 4);
		/* 1608 */world.setBlockMetadataWithNotify(i + 1, j + 46, k + 9, 4, 2);
		/* 1609 */setBlock(world, i + 1, j + 46, k + 12, Blocks.leaves, 4);
		/* 1610 */world.setBlockMetadataWithNotify(i + 1, j + 46, k + 12, 4, 2);
		/* 1611 */setBlock(world, i + 1, j + 46, k + 13, Blocks.leaves, 4);
		/* 1612 */world.setBlockMetadataWithNotify(i + 1, j + 46, k + 13, 4, 2);
		/* 1613 */setBlock(world, i + 1, j + 46, k + 14, Blocks.leaves, 4);
		/* 1614 */world.setBlockMetadataWithNotify(i + 1, j + 46, k + 14, 4, 2);
		/* 1615 */setBlock(world, i + 1, j + 47, k + 0, Blocks.leaves, 4);
		/* 1616 */world.setBlockMetadataWithNotify(i + 1, j + 47, k + 0, 4, 2);
		/* 1617 */setBlock(world, i + 1, j + 47, k + 1, Blocks.leaves, 4);
		/* 1618 */world.setBlockMetadataWithNotify(i + 1, j + 47, k + 1, 4, 2);
		/* 1619 */setBlock(world, i + 1, j + 47, k + 2, Blocks.leaves, 4);
		/* 1620 */world.setBlockMetadataWithNotify(i + 1, j + 47, k + 2, 4, 2);
		/* 1621 */setBlock(world, i + 1, j + 47, k + 3, Blocks.leaves, 4);
		/* 1622 */world.setBlockMetadataWithNotify(i + 1, j + 47, k + 3, 4, 2);
		/* 1623 */setBlock(world, i + 1, j + 47, k + 4, Blocks.leaves, 4);
		/* 1624 */world.setBlockMetadataWithNotify(i + 1, j + 47, k + 4, 4, 2);
		/* 1625 */setBlock(world, i + 1, j + 47, k + 5, Blocks.leaves, 4);
		/* 1626 */world.setBlockMetadataWithNotify(i + 1, j + 47, k + 5, 4, 2);
		/* 1627 */setBlock(world, i + 1, j + 47, k + 9, Blocks.leaves, 4);
		/* 1628 */world.setBlockMetadataWithNotify(i + 1, j + 47, k + 9, 4, 2);
		/* 1629 */setBlock(world, i + 1, j + 47, k + 10, Blocks.leaves, 4);
		/* 1630 */world.setBlockMetadataWithNotify(i + 1, j + 47, k + 10, 4, 2);
		/* 1631 */setBlock(world, i + 1, j + 47, k + 12, Blocks.leaves, 4);
		/* 1632 */world.setBlockMetadataWithNotify(i + 1, j + 47, k + 12, 4, 2);
		/* 1633 */setBlock(world, i + 1, j + 47, k + 13, Blocks.leaves, 4);
		/* 1634 */world.setBlockMetadataWithNotify(i + 1, j + 47, k + 13, 4, 2);
		/* 1635 */setBlock(world, i + 1, j + 47, k + 14, Blocks.leaves, 4);
		/* 1636 */world.setBlockMetadataWithNotify(i + 1, j + 47, k + 14, 4, 2);
		/* 1637 */setBlock(world, i + 1, j + 48, k + 0, Blocks.leaves, 4);
		/* 1638 */world.setBlockMetadataWithNotify(i + 1, j + 48, k + 0, 4, 2);
		/* 1639 */setBlock(world, i + 1, j + 48, k + 1, Blocks.leaves, 4);
		/* 1640 */world.setBlockMetadataWithNotify(i + 1, j + 48, k + 1, 4, 2);
		/* 1641 */setBlock(world, i + 1, j + 48, k + 2, Blocks.leaves, 4);
		/* 1642 */world.setBlockMetadataWithNotify(i + 1, j + 48, k + 2, 4, 2);
		/* 1643 */setBlock(world, i + 1, j + 48, k + 3, Blocks.leaves, 4);
		/* 1644 */world.setBlockMetadataWithNotify(i + 1, j + 48, k + 3, 4, 2);
		/* 1645 */setBlock(world, i + 1, j + 48, k + 4, Blocks.leaves, 4);
		/* 1646 */world.setBlockMetadataWithNotify(i + 1, j + 48, k + 4, 4, 2);
		/* 1647 */setBlock(world, i + 1, j + 48, k + 5, Blocks.leaves, 4);
		/* 1648 */world.setBlockMetadataWithNotify(i + 1, j + 48, k + 5, 4, 2);
		/* 1649 */setBlock(world, i + 1, j + 48, k + 6, Blocks.leaves, 4);
		/* 1650 */world.setBlockMetadataWithNotify(i + 1, j + 48, k + 6, 4, 2);
		/* 1651 */setBlock(world, i + 1, j + 48, k + 7, Blocks.leaves, 4);
		/* 1652 */world.setBlockMetadataWithNotify(i + 1, j + 48, k + 7, 4, 2);
