package com.parzivail.pswm.world.gen.wookietree;




import com.parzivail.pswm.utils.LootGenUtils;
import com.parzivail.pswm.utils.NPCType;
import com.parzivail.pswm.utils.SpawnUtils;



import cpw.mods.fml.common.IWorldGenerator;



import java.util.Random;



import net.minecraft.block.Block;

import net.minecraft.init.Blocks;

import net.minecraft.tileentity.TileEntityChest;

import net.minecraft.world.World;

import net.minecraft.world.WorldProvider;

import net.minecraft.world.chunk.IChunkProvider;

import net.minecraft.world.gen.feature.WorldGenerator;


public class WT_01
extends WorldGenerator implements IWorldGenerator

{
	protected Block[] getValidSpawnBlocks()
	
	{
		return new Block[0];
		}

	
	public boolean locationIsValidSpawn(World world, int i, int j, int k)
	
	{
		int distanceToAir = 0;
		Block check = world.getBlock(i, j, k);
		
		while (check != Blocks.air)
		{
			if (distanceToAir > 3) { return false;
			}
			
			distanceToAir++;
			check = world.getBlock(i, j + distanceToAir, k);
			}
		
		j += distanceToAir - 1;
		
		Block block = world.getBlock(i, j, k);
		Block blockAbove = world.getBlock(i, j + 1, k);
		Block blockBelow = world.getBlock(i, j - 1, k);
		
		for (Block x : getValidSpawnBlocks())
		{
			if (blockAbove != Blocks.air) { return false;
			}
			if (block == x) return true;
			if ((block == Blocks.snow) && (blockBelow == x)) { return true;
			}
			}
		
		return false;
		}

	
	
	
	public void generate(Random random, int chunkX, int chunkZ, World world, IChunkProvider chunkGenerator, IChunkProvider chunkProvider)
	{
	}

	
	
	public void setBlock(World world, int x, int y, int z, Block block, int metadata)
	
	{
		world.setBlock(x, y, z, block, metadata, 2);
		}

	
	public boolean generate(World world, Random rand, int i, int j, int k)
	
	{
		k -= 10;
		i -= 10;
		
		setBlock(world, i + 7, j + 59, k + 4, Blocks.fence, 0);
		setBlock(world, i + 8, j + 59, k + 4, Blocks.fence, 0);
		setBlock(world, i + 8, j + 59, k + 5, Blocks.fence, 0);
		setBlock(world, i + 8, j + 59, k + 6, Blocks.fence, 0);
		setBlock(world, i + 8, j + 59, k + 7, Blocks.fence, 0);
		setBlock(world, i + 9, j + 59, k + 7, Blocks.fence, 0);
		setBlock(world, i + 9, j + 59, k + 8, Blocks.fence, 0);
		setBlock(world, i + 9, j + 59, k + 9, Blocks.fence, 0);
		setBlock(world, i + 10, j + 56, k + 4, Blocks.fence, 0);
		setBlock(world, i + 10, j + 56, k + 5, Blocks.fence, 0);
		setBlock(world, i + 10, j + 56, k + 6, Blocks.fence, 0);
		setBlock(world, i + 10, j + 59, k + 9, Blocks.fence, 0);
		setBlock(world, i + 10, j + 59, k + 10, Blocks.fence, 0);
		setBlock(world, i + 11, j + 56, k + 6, Blocks.fence, 0);
		setBlock(world, i + 11, j + 56, k + 7, Blocks.fence, 0);
		setBlock(world, i + 11, j + 56, k + 8, Blocks.fence, 0);
		setBlock(world, i + 11, j + 59, k + 10, Blocks.fence, 0);
		setBlock(world, i + 11, j + 59, k + 11, Blocks.fence, 0);
		SpawnUtils.spawnNPC(NPCType.WOOKIETREE, world, i + 12, j + 56, k + 2);
		setBlock(world, i + 14, j + 56, k + 0, Blocks.spruce_stairs, 0);
		setBlock(world, i + 17, j + 56, k + 1, Blocks.crafting_table, 0);
		setBlock(world, i + 18, j + 56, k + 9, Blocks.spruce_stairs, 0);
		SpawnUtils.spawnNPC(NPCType.WOOKIETREE, world, i + 19, j + 56, k + 2);
		setBlock(world, i + 20, j + 56, k + 6, Blocks.fence, 0);
		setBlock(world, i + 20, j + 56, k + 7, Blocks.fence, 0);
		setBlock(world, i + 20, j + 56, k + 8, Blocks.fence, 0);
		setBlock(world, i + 20, j + 59, k + 10, Blocks.fence, 0);
		setBlock(world, i + 20, j + 59, k + 11, Blocks.fence, 0);
		setBlock(world, i + 21, j + 56, k + 3, Blocks.spruce_stairs, 0);
		setBlock(world, i + 21, j + 56, k + 4, Blocks.fence, 0);
		setBlock(world, i + 21, j + 56, k + 5, Blocks.fence, 0);
		setBlock(world, i + 21, j + 56, k + 6, Blocks.fence, 0);
		setBlock(world, i + 21, j + 59, k + 9, Blocks.fence, 0);
		setBlock(world, i + 21, j + 59, k + 10, Blocks.fence, 0);
		setBlock(world, i + 22, j + 59, k + 7, Blocks.fence, 0);
		setBlock(world, i + 22, j + 59, k + 8, Blocks.fence, 0);
		setBlock(world, i + 22, j + 59, k + 9, Blocks.fence, 0);
		setBlock(world, i + 23, j + 59, k + 4, Blocks.fence, 0);
		setBlock(world, i + 23, j + 59, k + 5, Blocks.fence, 0);
		setBlock(world, i + 23, j + 59, k + 6, Blocks.fence, 0);
		setBlock(world, i + 23, j + 59, k + 7, Blocks.fence, 0);
		setBlock(world, i + 24, j + 59, k + 4, Blocks.fence, 0);
		setBlock(world, i + 25, j + 29, k + 2, Blocks.fence, 0);
		setBlock(world, i + 25, j + 29, k + 8, Blocks.fence, 0);
		setBlock(world, i + 26, j + 29, k + 2, Blocks.fence, 0);
		setBlock(world, i + 26, j + 29, k + 8, Blocks.fence, 0);
		setBlock(world, i + 28, j + 27, k + 1, Blocks.fence, 0);
		setBlock(world, i + 28, j + 27, k + 2, Blocks.fence, 0);
		setBlock(world, i + 28, j + 27, k + 8, Blocks.fence, 0);
		setBlock(world, i + 28, j + 27, k + 9, Blocks.fence, 0);
		setBlock(world, i + 29, j + 27, k + 0, Blocks.fence, 0);
		setBlock(world, i + 29, j + 27, k + 1, Blocks.fence, 0);
		setBlock(world, i + 29, j + 27, k + 9, Blocks.fence, 0);
		setBlock(world, i + 29, j + 27, k + 10, Blocks.fence, 0);
		setBlock(world, i + 30, j + 27, k + 0, Blocks.fence, 0);
		setBlock(world, i + 30, j + 27, k + 10, Blocks.fence, 0);
		setBlock(world, i + 30, j + 27, k + 11, Blocks.spruce_stairs, 0);
		setBlock(world, i + 30, j + 29, k + 12, Blocks.fence, 0);
		setBlock(world, i + 30, j + 29, k + 13, Blocks.fence, 0);
		SpawnUtils.spawnNPC(NPCType.WOOKIETREE, world, i + 31, j + 27, k + 3);
		SpawnUtils.spawnNPC(NPCType.WOOKIETREE, world, i + 31, j + 27, k + 7);
		setBlock(world, i + 5, j + 27, k + 0, Blocks.leaves, 7);
		world.setBlockMetadataWithNotify(i + 5, j + 27, k + 0, 7, 2);
		setBlock(world, i + 6, j + 27, k + 0, Blocks.leaves, 7);
		world.setBlockMetadataWithNotify(i + 6, j + 27, k + 0, 7, 2);
		setBlock(world, i + 6, j + 28, k + 0, Blocks.leaves, 7);
		world.setBlockMetadataWithNotify(i + 6, j + 28, k + 0, 7, 2);
		setBlock(world, i + 7, j + 27, k + 0, Blocks.leaves, 7);
		world.setBlockMetadataWithNotify(i + 7, j + 27, k + 0, 7, 2);
		setBlock(world, i + 7, j + 57, k + 3, Blocks.spruce_stairs, 4);
		world.setBlockMetadataWithNotify(i + 7, j + 57, k + 3, 4, 2);
		setBlock(world, i + 7, j + 58, k + 3, Blocks.log, 1);
		world.setBlockMetadataWithNotify(i + 7, j + 58, k + 3, 1, 2);
		setBlock(world, i + 7, j + 59, k + 2, Blocks.spruce_stairs, 6);
		world.setBlockMetadataWithNotify(i + 7, j + 59, k + 2, 6, 2);
		setBlock(world, i + 7, j + 59, k + 3, Blocks.log, 1);
		world.setBlockMetadataWithNotify(i + 7, j + 59, k + 3, 1, 2);
		setBlock(world, i + 7, j + 60, k + 0, Blocks.log, 1);
		world.setBlockMetadataWithNotify(i + 7, j + 60, k + 0, 1, 2);
		setBlock(world, i + 7, j + 60, k + 1, Blocks.log, 1);
		world.setBlockMetadataWithNotify(i + 7, j + 60, k + 1, 1, 2);
		setBlock(world, i + 7, j + 60, k + 2, Blocks.log, 1);
		world.setBlockMetadataWithNotify(i + 7, j + 60, k + 2, 1, 2);
		setBlock(world, i + 7, j + 60, k + 3, Blocks.log, 1);
		world.setBlockMetadataWithNotify(i + 7, j + 60, k + 3, 1, 2);
		setBlock(world, i + 7, j + 60, k + 4, Blocks.log, 1);
		world.setBlockMetadataWithNotify(i + 7, j + 60, k + 4, 1, 2);
		setBlock(world, i + 8, j + 28, k + 4, Blocks.leaves, 7);
		world.setBlockMetadataWithNotify(i + 8, j + 28, k + 4, 7, 2);
		setBlock(world, i + 8, j + 28, k + 5, Blocks.leaves, 7);
		world.setBlockMetadataWithNotify(i + 8, j + 28, k + 5, 7, 2);
		setBlock(world, i + 8, j + 28, k + 6, Blocks.leaves, 7);
		world.setBlockMetadataWithNotify(i + 8, j + 28, k + 6, 7, 2);
		setBlock(world, i + 8, j + 29, k + 1, Blocks.leaves, 7);
		world.setBlockMetadataWithNotify(i + 8, j + 29, k + 1, 7, 2);
		setBlock(world, i + 8, j + 29, k + 2, Blocks.leaves, 7);
		world.setBlockMetadataWithNotify(i + 8, j + 29, k + 2, 7, 2);
		setBlock(world, i + 8, j + 29, k + 3, Blocks.leaves, 7);
		world.setBlockMetadataWithNotify(i + 8, j + 29, k + 3, 7, 2);
		setBlock(world, i + 8, j + 29, k + 5, Blocks.leaves, 7);
		world.setBlockMetadataWithNotify(i + 8, j + 29, k + 5, 7, 2);
		setBlock(world, i + 8, j + 30, k + 2, Blocks.leaves, 7);
		world.setBlockMetadataWithNotify(i + 8, j + 30, k + 2, 7, 2);
		setBlock(world, i + 8, j + 56, k + 3, Blocks.spruce_stairs, 4);
		world.setBlockMetadataWithNotify(i + 8, j + 56, k + 3, 4, 2);
		setBlock(world, i + 8, j + 57, k + 3, Blocks.log, 1);
		world.setBlockMetadataWithNotify(i + 8, j + 57, k + 3, 1, 2);
		setBlock(world, i + 8, j + 58, k + 2, Blocks.torch, 4);
		world.setBlockMetadataWithNotify(i + 8, j + 58, k + 2, 4, 2);
		setBlock(world, i + 8, j + 58, k + 3, Blocks.log, 1);
		world.setBlockMetadataWithNotify(i + 8, j + 58, k + 3, 1, 2);
		setBlock(world, i + 8, j + 60, k + 0, Blocks.log, 1);
		world.setBlockMetadataWithNotify(i + 8, j + 60, k + 0, 1, 2);
		setBlock(world, i + 8, j + 60, k + 1, Blocks.log, 1);
		world.setBlockMetadataWithNotify(i + 8, j + 60, k + 1, 1, 2);
		setBlock(world, i + 8, j + 60, k + 2, Blocks.log, 1);
		world.setBlockMetadataWithNotify(i + 8, j + 60, k + 2, 1, 2);
		setBlock(world, i + 8, j + 60, k + 3, Blocks.log, 1);
		world.setBlockMetadataWithNotify(i + 8, j + 60, k + 3, 1, 2);
		setBlock(world, i + 8, j + 60, k + 4, Blocks.log, 1);
		world.setBlockMetadataWithNotify(i + 8, j + 60, k + 4, 1, 2);
		setBlock(world, i + 8, j + 60, k + 5, Blocks.log, 1);
		world.setBlockMetadataWithNotify(i + 8, j + 60, k + 5, 1, 2);
		setBlock(world, i + 8, j + 60, k + 6, Blocks.log, 1);
		world.setBlockMetadataWithNotify(i + 8, j + 60, k + 6, 1, 2);
		setBlock(world, i + 8, j + 60, k + 7, Blocks.log, 1);
		world.setBlockMetadataWithNotify(i + 8, j + 60, k + 7, 1, 2);
		setBlock(world, i + 8, j + 61, k + 0, Blocks.log, 1);
		world.setBlockMetadataWithNotify(i + 8, j + 61, k + 0, 1, 2);
		setBlock(world, i + 8, j + 61, k + 1, Blocks.log, 1);
		world.setBlockMetadataWithNotify(i + 8, j + 61, k + 1, 1, 2);
		setBlock(world, i + 8, j + 61, k + 2, Blocks.log, 1);
		world.setBlockMetadataWithNotify(i + 8, j + 61, k + 2, 1, 2);
		setBlock(world, i + 8, j + 61, k + 3, Blocks.log, 1);
		world.setBlockMetadataWithNotify(i + 8, j + 61, k + 3, 1, 2);
		setBlock(world, i + 8, j + 61, k + 4, Blocks.log, 1);
		world.setBlockMetadataWithNotify(i + 8, j + 61, k + 4, 1, 2);
		setBlock(world, i + 8, j + 61, k + 5, Blocks.log, 1);
		world.setBlockMetadataWithNotify(i + 8, j + 61, k + 5, 1, 2);
		setBlock(world, i + 9, j + 28, k + 3, Blocks.leaves, 7);
		world.setBlockMetadataWithNotify(i + 9, j + 28, k + 3, 7, 2);
		setBlock(world, i + 9, j + 28, k + 4, Blocks.leaves, 7);
		world.setBlockMetadataWithNotify(i + 9, j + 28, k + 4, 7, 2);
		setBlock(world, i + 9, j + 28, k + 5, Blocks.leaves, 7);
		world.setBlockMetadataWithNotify(i + 9, j + 28, k + 5, 7, 2);
		setBlock(world, i + 9, j + 28, k + 6, Blocks.leaves, 7);
		world.setBlockMetadataWithNotify(i + 9, j + 28, k + 6, 7, 2);
		setBlock(world, i + 9, j + 28, k + 7, Blocks.leaves, 7);
		world.setBlockMetadataWithNotify(i + 9, j + 28, k + 7, 7, 2);
		setBlock(world, i + 9, j + 29, k + 0, Blocks.leaves, 7);
		world.setBlockMetadataWithNotify(i + 9, j + 29, k + 0, 7, 2);
		setBlock(world, i + 9, j + 29, k + 1, Blocks.leaves, 7);
		world.setBlockMetadataWithNotify(i + 9, j + 29, k + 1, 7, 2);
		setBlock(world, i + 9, j + 29, k + 2, Blocks.leaves, 7);
		world.setBlockMetadataWithNotify(i + 9, j + 29, k + 2, 7, 2);
		setBlock(world, i + 9, j + 29, k + 3, Blocks.leaves, 7);
		world.setBlockMetadataWithNotify(i + 9, j + 29, k + 3, 7, 2);
		setBlock(world, i + 9, j + 29, k + 4, Blocks.leaves, 7);
		world.setBlockMetadataWithNotify(i + 9, j + 29, k + 4, 7, 2);
		setBlock(world, i + 9, j + 29, k + 5, Blocks.leaves, 7);
		world.setBlockMetadataWithNotify(i + 9, j + 29, k + 5, 7, 2);
		setBlock(world, i + 9, j + 29, k + 6, Blocks.leaves, 7);
		world.setBlockMetadataWithNotify(i + 9, j + 29, k + 6, 7, 2);
		setBlock(world, i + 9, j + 30, k + 1, Blocks.leaves, 7);
		world.setBlockMetadataWithNotify(i + 9, j + 30, k + 1, 7, 2);
		setBlock(world, i + 9, j + 30, k + 2, Blocks.leaves, 7);
		world.setBlockMetadataWithNotify(i + 9, j + 30, k + 2, 7, 2);
		setBlock(world, i + 9, j + 30, k + 3, Blocks.leaves, 7);
		world.setBlockMetadataWithNotify(i + 9, j + 30, k + 3, 7, 2);
		setBlock(world, i + 9, j + 30, k + 5, Blocks.leaves, 7);
		world.setBlockMetadataWithNotify(i + 9, j + 30, k + 5, 7, 2);
		setBlock(world, i + 9, j + 31, k + 2, Blocks.leaves, 7);
		world.setBlockMetadataWithNotify(i + 9, j + 31, k + 2, 7, 2);
		setBlock(world, i + 9, j + 54, k + 0, Blocks.log, 1);
		world.setBlockMetadataWithNotify(i + 9, j + 54, k + 0, 1, 2);
		setBlock(world, i + 9, j + 54, k + 1, Blocks.log, 1);
		world.setBlockMetadataWithNotify(i + 9, j + 54, k + 1, 1, 2);
		setBlock(world, i + 9, j + 54, k + 2, Blocks.log, 1);
		world.setBlockMetadataWithNotify(i + 9, j + 54, k + 2, 1, 2);
		
		generate92(world, rand, i, j, k);
		return true;
		}

	
	public boolean generate92(World world, Random rand, int i, int j, int k)
	
	{
		setBlock(world, i + 9, j + 55, k + 0, Blocks.log, 1);
		world.setBlockMetadataWithNotify(i + 9, j + 55, k + 0, 1, 2);
		setBlock(world, i + 9, j + 55, k + 1, Blocks.log, 1);
		world.setBlockMetadataWithNotify(i + 9, j + 55, k + 1, 1, 2);
		setBlock(world, i + 9, j + 55, k + 2, Blocks.log, 1);
		world.setBlockMetadataWithNotify(i + 9, j + 55, k + 2, 1, 2);
		setBlock(world, i + 9, j + 55, k + 3, Blocks.log, 1);
		world.setBlockMetadataWithNotify(i + 9, j + 55, k + 3, 1, 2);
		setBlock(world, i + 9, j + 56, k + 3, Blocks.log, 1);
		world.setBlockMetadataWithNotify(i + 9, j + 56, k + 3, 1, 2);
		setBlock(world, i + 9, j + 57, k + 3, Blocks.log, 1);
		world.setBlockMetadataWithNotify(i + 9, j + 57, k + 3, 1, 2);
		setBlock(world, i + 9, j + 60, k + 0, Blocks.log, 1);
		world.setBlockMetadataWithNotify(i + 9, j + 60, k + 0, 1, 2);
		setBlock(world, i + 9, j + 60, k + 1, Blocks.log, 1);
		world.setBlockMetadataWithNotify(i + 9, j + 60, k + 1, 1, 2);
		setBlock(world, i + 9, j + 60, k + 2, Blocks.log, 1);
		world.setBlockMetadataWithNotify(i + 9, j + 60, k + 2, 1, 2);
		setBlock(world, i + 9, j + 60, k + 3, Blocks.log, 1);
		world.setBlockMetadataWithNotify(i + 9, j + 60, k + 3, 1, 2);
		setBlock(world, i + 9, j + 60, k + 4, Blocks.log, 1);
		world.setBlockMetadataWithNotify(i + 9, j + 60, k + 4, 1, 2);
		setBlock(world, i + 9, j + 60, k + 5, Blocks.log, 1);
		world.setBlockMetadataWithNotify(i + 9, j + 60, k + 5, 1, 2);
		setBlock(world, i + 9, j + 60, k + 6, Blocks.log, 1);
		world.setBlockMetadataWithNotify(i + 9, j + 60, k + 6, 1, 2);
		setBlock(world, i + 9, j + 60, k + 7, Blocks.log, 1);
		world.setBlockMetadataWithNotify(i + 9, j + 60, k + 7, 1, 2);
		setBlock(world, i + 9, j + 60, k + 8, Blocks.log, 1);
		world.setBlockMetadataWithNotify(i + 9, j + 60, k + 8, 1, 2);
		setBlock(world, i + 9, j + 60, k + 9, Blocks.log, 1);
		world.setBlockMetadataWithNotify(i + 9, j + 60, k + 9, 1, 2);
		setBlock(world, i + 9, j + 61, k + 0, Blocks.log, 1);
		world.setBlockMetadataWithNotify(i + 9, j + 61, k + 0, 1, 2);
		setBlock(world, i + 9, j + 61, k + 1, Blocks.log, 1);
		world.setBlockMetadataWithNotify(i + 9, j + 61, k + 1, 1, 2);
		setBlock(world, i + 9, j + 61, k + 2, Blocks.log, 1);
		world.setBlockMetadataWithNotify(i + 9, j + 61, k + 2, 1, 2);
		setBlock(world, i + 9, j + 61, k + 3, Blocks.log, 1);
		world.setBlockMetadataWithNotify(i + 9, j + 61, k + 3, 1, 2);
		setBlock(world, i + 9, j + 61, k + 4, Blocks.log, 1);
		world.setBlockMetadataWithNotify(i + 9, j + 61, k + 4, 1, 2);
		setBlock(world, i + 9, j + 61, k + 5, Blocks.log, 1);
		world.setBlockMetadataWithNotify(i + 9, j + 61, k + 5, 1, 2);
		setBlock(world, i + 9, j + 61, k + 6, Blocks.log, 1);
		world.setBlockMetadataWithNotify(i + 9, j + 61, k + 6, 1, 2);
		setBlock(world, i + 9, j + 61, k + 7, Blocks.log, 1);
		world.setBlockMetadataWithNotify(i + 9, j + 61, k + 7, 1, 2);
		setBlock(world, i + 9, j + 62, k + 0, Blocks.log, 1);
		world.setBlockMetadataWithNotify(i + 9, j + 62, k + 0, 1, 2);
		setBlock(world, i + 9, j + 62, k + 1, Blocks.log, 1);
		world.setBlockMetadataWithNotify(i + 9, j + 62, k + 1, 1, 2);
		setBlock(world, i + 9, j + 62, k + 2, Blocks.log, 1);
		world.setBlockMetadataWithNotify(i + 9, j + 62, k + 2, 1, 2);
		setBlock(world, i + 9, j + 62, k + 3, Blocks.log, 1);
		world.setBlockMetadataWithNotify(i + 9, j + 62, k + 3, 1, 2);
		setBlock(world, i + 10, j + 27, k + 4, Blocks.log, 3);
		world.setBlockMetadataWithNotify(i + 10, j + 27, k + 4, 3, 2);
		setBlock(world, i + 10, j + 28, k + 3, Blocks.leaves, 7);
		world.setBlockMetadataWithNotify(i + 10, j + 28, k + 3, 7, 2);
		setBlock(world, i + 10, j + 28, k + 4, Blocks.leaves, 7);
		world.setBlockMetadataWithNotify(i + 10, j + 28, k + 4, 7, 2);
		setBlock(world, i + 10, j + 28, k + 5, Blocks.log, 3);
		world.setBlockMetadataWithNotify(i + 10, j + 28, k + 5, 3, 2);
		setBlock(world, i + 10, j + 28, k + 6, Blocks.leaves, 7);
		world.setBlockMetadataWithNotify(i + 10, j + 28, k + 6, 7, 2);
		setBlock(world, i + 10, j + 28, k + 7, Blocks.leaves, 7);
		world.setBlockMetadataWithNotify(i + 10, j + 28, k + 7, 7, 2);
		setBlock(world, i + 10, j + 29, k + 0, Blocks.leaves, 7);
		world.setBlockMetadataWithNotify(i + 10, j + 29, k + 0, 7, 2);
		setBlock(world, i + 10, j + 29, k + 1, Blocks.leaves, 7);
		world.setBlockMetadataWithNotify(i + 10, j + 29, k + 1, 7, 2);
		setBlock(world, i + 10, j + 29, k + 2, Blocks.log, 3);
		world.setBlockMetadataWithNotify(i + 10, j + 29, k + 2, 3, 2);
		setBlock(world, i + 10, j + 29, k + 3, Blocks.leaves, 7);
		world.setBlockMetadataWithNotify(i + 10, j + 29, k + 3, 7, 2);
		setBlock(world, i + 10, j + 29, k + 4, Blocks.leaves, 7);
		world.setBlockMetadataWithNotify(i + 10, j + 29, k + 4, 7, 2);
		setBlock(world, i + 10, j + 29, k + 5, Blocks.leaves, 7);
		world.setBlockMetadataWithNotify(i + 10, j + 29, k + 5, 7, 2);
		setBlock(world, i + 10, j + 29, k + 6, Blocks.leaves, 7);
		world.setBlockMetadataWithNotify(i + 10, j + 29, k + 6, 7, 2);
		setBlock(world, i + 10, j + 29, k + 7, Blocks.leaves, 7);
		world.setBlockMetadataWithNotify(i + 10, j + 29, k + 7, 7, 2);
		setBlock(world, i + 10, j + 30, k + 0, Blocks.leaves, 7);
		world.setBlockMetadataWithNotify(i + 10, j + 30, k + 0, 7, 2);
		setBlock(world, i + 10, j + 30, k + 1, Blocks.leaves, 7);
		world.setBlockMetadataWithNotify(i + 10, j + 30, k + 1, 7, 2);
		setBlock(world, i + 10, j + 30, k + 2, Blocks.leaves, 7);
		world.setBlockMetadataWithNotify(i + 10, j + 30, k + 2, 7, 2);
		setBlock(world, i + 10, j + 30, k + 3, Blocks.leaves, 7);
		world.setBlockMetadataWithNotify(i + 10, j + 30, k + 3, 7, 2);
		setBlock(world, i + 10, j + 30, k + 4, Blocks.leaves, 7);
		world.setBlockMetadataWithNotify(i + 10, j + 30, k + 4, 7, 2);
		setBlock(world, i + 10, j + 30, k + 5, Blocks.leaves, 7);
		world.setBlockMetadataWithNotify(i + 10, j + 30, k + 5, 7, 2);
		setBlock(world, i + 10, j + 30, k + 6, Blocks.leaves, 7);
		world.setBlockMetadataWithNotify(i + 10, j + 30, k + 6, 7, 2);
		setBlock(world, i + 10, j + 31, k + 1, Blocks.leaves, 7);
		world.setBlockMetadataWithNotify(i + 10, j + 31, k + 1, 7, 2);
		setBlock(world, i + 10, j + 31, k + 2, Blocks.leaves, 7);
		world.setBlockMetadataWithNotify(i + 10, j + 31, k + 2, 7, 2);
		setBlock(world, i + 10, j + 31, k + 3, Blocks.leaves, 7);
		world.setBlockMetadataWithNotify(i + 10, j + 31, k + 3, 7, 2);
		setBlock(world, i + 10, j + 31, k + 5, Blocks.leaves, 7);
		world.setBlockMetadataWithNotify(i + 10, j + 31, k + 5, 7, 2);
		setBlock(world, i + 10, j + 32, k + 2, Blocks.leaves, 7);
		world.setBlockMetadataWithNotify(i + 10, j + 32, k + 2, 7, 2);
		setBlock(world, i + 10, j + 52, k + 2, Blocks.log, 1);
		world.setBlockMetadataWithNotify(i + 10, j + 52, k + 2, 1, 2);
		setBlock(world, i + 10, j + 52, k + 3, Blocks.log, 1);
		world.setBlockMetadataWithNotify(i + 10, j + 52, k + 3, 1, 2);
		setBlock(world, i + 10, j + 53, k + 1, Blocks.log, 1);
		world.setBlockMetadataWithNotify(i + 10, j + 53, k + 1, 1, 2);
		setBlock(world, i + 10, j + 53, k + 2, Blocks.log, 1);
		world.setBlockMetadataWithNotify(i + 10, j + 53, k + 2, 1, 2);
		setBlock(world, i + 10, j + 53, k + 3, Blocks.log, 1);
		world.setBlockMetadataWithNotify(i + 10, j + 53, k + 3, 1, 2);
		setBlock(world, i + 10, j + 53, k + 4, Blocks.log, 1);
		world.setBlockMetadataWithNotify(i + 10, j + 53, k + 4, 1, 2);
		setBlock(world, i + 10, j + 54, k + 0, Blocks.log, 1);
		world.setBlockMetadataWithNotify(i + 10, j + 54, k + 0, 1, 2);
		setBlock(world, i + 10, j + 54, k + 1, Blocks.log, 1);
		world.setBlockMetadataWithNotify(i + 10, j + 54, k + 1, 1, 2);
		setBlock(world, i + 10, j + 54, k + 2, Blocks.log, 1);
		world.setBlockMetadataWithNotify(i + 10, j + 54, k + 2, 1, 2);
		setBlock(world, i + 10, j + 54, k + 3, Blocks.log, 1);
		world.setBlockMetadataWithNotify(i + 10, j + 54, k + 3, 1, 2);
		setBlock(world, i + 10, j + 55, k + 0, Blocks.planks, 5);
		world.setBlockMetadataWithNotify(i + 10, j + 55, k + 0, 5, 2);
		setBlock(world, i + 10, j + 55, k + 1, Blocks.log, 1);
		world.setBlockMetadataWithNotify(i + 10, j + 55, k + 1, 1, 2);
		setBlock(world, i + 10, j + 55, k + 2, Blocks.log, 1);
		world.setBlockMetadataWithNotify(i + 10, j + 55, k + 2, 1, 2);
		setBlock(world, i + 10, j + 55, k + 3, Blocks.log, 1);
		world.setBlockMetadataWithNotify(i + 10, j + 55, k + 3, 1, 2);
		setBlock(world, i + 10, j + 55, k + 4, Blocks.log, 1);
		world.setBlockMetadataWithNotify(i + 10, j + 55, k + 4, 1, 2);
		setBlock(world, i + 10, j + 55, k + 5, Blocks.log, 1);
		world.setBlockMetadataWithNotify(i + 10, j + 55, k + 5, 1, 2);
		setBlock(world, i + 10, j + 55, k + 6, Blocks.log, 1);
		world.setBlockMetadataWithNotify(i + 10, j + 55, k + 6, 1, 2);
		setBlock(world, i + 10, j + 56, k + 3, Blocks.spruce_stairs, 1);
		world.setBlockMetadataWithNotify(i + 10, j + 56, k + 3, 1, 2);
		setBlock(world, i + 10, j + 57, k + 4, Blocks.torch, 5);
		world.setBlockMetadataWithNotify(i + 10, j + 57, k + 4, 5, 2);
		setBlock(world, i + 10, j + 60, k + 0, Blocks.log, 1);
		world.setBlockMetadataWithNotify(i + 10, j + 60, k + 0, 1, 2);
		setBlock(world, i + 10, j + 60, k + 1, Blocks.log, 1);
		world.setBlockMetadataWithNotify(i + 10, j + 60, k + 1, 1, 2);
		setBlock(world, i + 10, j + 60, k + 2, Blocks.log, 1);
		world.setBlockMetadataWithNotify(i + 10, j + 60, k + 2, 1, 2);
		setBlock(world, i + 10, j + 60, k + 3, Blocks.log, 1);
		world.setBlockMetadataWithNotify(i + 10, j + 60, k + 3, 1, 2);
		setBlock(world, i + 10, j + 60, k + 4, Blocks.log, 1);
		world.setBlockMetadataWithNotify(i + 10, j + 60, k + 4, 1, 2);
		setBlock(world, i + 10, j + 60, k + 5, Blocks.log, 1);
		world.setBlockMetadataWithNotify(i + 10, j + 60, k + 5, 1, 2);
		setBlock(world, i + 10, j + 60, k + 6, Blocks.log, 1);
		world.setBlockMetadataWithNotify(i + 10, j + 60, k + 6, 1, 2);
		setBlock(world, i + 10, j + 60, k + 7, Blocks.log, 1);
		world.setBlockMetadataWithNotify(i + 10, j + 60, k + 7, 1, 2);
		setBlock(world, i + 10, j + 60, k + 8, Blocks.log, 1);
		world.setBlockMetadataWithNotify(i + 10, j + 60, k + 8, 1, 2);
		setBlock(world, i + 10, j + 60, k + 9, Blocks.log, 1);
		world.setBlockMetadataWithNotify(i + 10, j + 60, k + 9, 1, 2);
		setBlock(world, i + 10, j + 60, k + 10, Blocks.log, 1);
		world.setBlockMetadataWithNotify(i + 10, j + 60, k + 10, 1, 2);
		setBlock(world, i + 10, j + 61, k + 0, Blocks.log, 1);
		world.setBlockMetadataWithNotify(i + 10, j + 61, k + 0, 1, 2);
		setBlock(world, i + 10, j + 61, k + 1, Blocks.log, 1);
		world.setBlockMetadataWithNotify(i + 10, j + 61, k + 1, 1, 2);
		setBlock(world, i + 10, j + 61, k + 2, Blocks.log, 1);
		world.setBlockMetadataWithNotify(i + 10, j + 61, k + 2, 1, 2);
		setBlock(world, i + 10, j + 61, k + 3, Blocks.log, 1);
		world.setBlockMetadataWithNotify(i + 10, j + 61, k + 3, 1, 2);
		setBlock(world, i + 10, j + 61, k + 4, Blocks.log, 1);
		world.setBlockMetadataWithNotify(i + 10, j + 61, k + 4, 1, 2);
		setBlock(world, i + 10, j + 61, k + 5, Blocks.log, 1);
		world.setBlockMetadataWithNotify(i + 10, j + 61, k + 5, 1, 2);
		setBlock(world, i + 10, j + 61, k + 6, Blocks.log, 1);
		world.setBlockMetadataWithNotify(i + 10, j + 61, k + 6, 1, 2);
		setBlock(world, i + 10, j + 61, k + 7, Blocks.log, 1);
		world.setBlockMetadataWithNotify(i + 10, j + 61, k + 7, 1, 2);
		setBlock(world, i + 10, j + 61, k + 8, Blocks.log, 1);
		world.setBlockMetadataWithNotify(i + 10, j + 61, k + 8, 1, 2);
		setBlock(world, i + 10, j + 61, k + 9, Blocks.log, 1);
		world.setBlockMetadataWithNotify(i + 10, j + 61, k + 9, 1, 2);
		setBlock(world, i + 10, j + 62, k + 0, Blocks.log, 1);
		world.setBlockMetadataWithNotify(i + 10, j + 62, k + 0, 1, 2);
		setBlock(world, i + 10, j + 62, k + 1, Blocks.log, 1);
		world.setBlockMetadataWithNotify(i + 10, j + 62, k + 1, 1, 2);
		setBlock(world, i + 10, j + 62, k + 2, Blocks.log, 1);
		world.setBlockMetadataWithNotify(i + 10, j + 62, k + 2, 1, 2);
		setBlock(world, i + 10, j + 62, k + 3, Blocks.log, 1);
		world.setBlockMetadataWithNotify(i + 10, j + 62, k + 3, 1, 2);
		setBlock(world, i + 10, j + 62, k + 4, Blocks.log, 1);
		world.setBlockMetadataWithNotify(i + 10, j + 62, k + 4, 1, 2);
		setBlock(world, i + 10, j + 62, k + 5, Blocks.log, 1);
		world.setBlockMetadataWithNotify(i + 10, j + 62, k + 5, 1, 2);
		setBlock(world, i + 10, j + 62, k + 6, Blocks.log, 1);
		world.setBlockMetadataWithNotify(i + 10, j + 62, k + 6, 1, 2);
		setBlock(world, i + 11, j + 21, k + 26, Blocks.leaves, 7);
		world.setBlockMetadataWithNotify(i + 11, j + 21, k + 26, 7, 2);
		setBlock(world, i + 11, j + 21, k + 27, Blocks.leaves, 7);
		world.setBlockMetadataWithNotify(i + 11, j + 21, k + 27, 7, 2);
		setBlock(world, i + 11, j + 21, k + 28, Blocks.leaves, 7);
		world.setBlockMetadataWithNotify(i + 11, j + 21, k + 28, 7, 2);
		setBlock(world, i + 11, j + 22, k + 27, Blocks.leaves, 7);
		world.setBlockMetadataWithNotify(i + 11, j + 22, k + 27, 7, 2);
		setBlock(world, i + 11, j + 23, k + 17, Blocks.leaves, 7);
		world.setBlockMetadataWithNotify(i + 11, j + 23, k + 17, 7, 2);
		setBlock(world, i + 11, j + 23, k + 18, Blocks.leaves, 7);
		world.setBlockMetadataWithNotify(i + 11, j + 23, k + 18, 7, 2);
		setBlock(world, i + 11, j + 23, k + 19, Blocks.leaves, 7);
		world.setBlockMetadataWithNotify(i + 11, j + 23, k + 19, 7, 2);
		setBlock(world, i + 11, j + 24, k + 18, Blocks.leaves, 7);
		world.setBlockMetadataWithNotify(i + 11, j + 24, k + 18, 7, 2);
		setBlock(world, i + 11, j + 27, k + 3, Blocks.log, 3);
		world.setBlockMetadataWithNotify(i + 11, j + 27, k + 3, 3, 2);
		setBlock(world, i + 11, j + 28, k + 2, Blocks.log, 3);
		world.setBlockMetadataWithNotify(i + 11, j + 28, k + 2, 3, 2);
		setBlock(world, i + 11, j + 28, k + 3, Blocks.leaves, 7);
		world.setBlockMetadataWithNotify(i + 11, j + 28, k + 3, 7, 2);
		setBlock(world, i + 11, j + 28, k + 4, Blocks.leaves, 7);
		world.setBlockMetadataWithNotify(i + 11, j + 28, k + 4, 7, 2);
		setBlock(world, i + 11, j + 28, k + 5, Blocks.leaves, 7);
		world.setBlockMetadataWithNotify(i + 11, j + 28, k + 5, 7, 2);
		setBlock(world, i + 11, j + 28, k + 6, Blocks.leaves, 7);
		world.setBlockMetadataWithNotify(i + 11, j + 28, k + 6, 7, 2);
		setBlock(world, i + 11, j + 28, k + 7, Blocks.leaves, 7);
		world.setBlockMetadataWithNotify(i + 11, j + 28, k + 7, 7, 2);
		setBlock(world, i + 11, j + 29, k + 0, Blocks.leaves, 7);
		world.setBlockMetadataWithNotify(i + 11, j + 29, k + 0, 7, 2);
		setBlock(world, i + 11, j + 29, k + 1, Blocks.leaves, 7);
		world.setBlockMetadataWithNotify(i + 11, j + 29, k + 1, 7, 2);
		setBlock(world, i + 11, j + 29, k + 2, Blocks.leaves, 7);
		world.setBlockMetadataWithNotify(i + 11, j + 29, k + 2, 7, 2);
		setBlock(world, i + 11, j + 29, k + 3, Blocks.leaves, 7);
		world.setBlockMetadataWithNotify(i + 11, j + 29, k + 3, 7, 2);
		setBlock(world, i + 11, j + 29, k + 4, Blocks.leaves, 7);
		world.setBlockMetadataWithNotify(i + 11, j + 29, k + 4, 7, 2);
		setBlock(world, i + 11, j + 29, k + 5, Blocks.leaves, 7);
		world.setBlockMetadataWithNotify(i + 11, j + 29, k + 5, 7, 2);
		setBlock(world, i + 11, j + 29, k + 6, Blocks.leaves, 7);
		world.setBlockMetadataWithNotify(i + 11, j + 29, k + 6, 7, 2);
		setBlock(world, i + 11, j + 30, k + 1, Blocks.leaves, 7);
		world.setBlockMetadataWithNotify(i + 11, j + 30, k + 1, 7, 2);
		setBlock(world, i + 11, j + 30, k + 2, Blocks.leaves, 7);
		world.setBlockMetadataWithNotify(i + 11, j + 30, k + 2, 7, 2);
		setBlock(world, i + 11, j + 30, k + 3, Blocks.leaves, 7);
		world.setBlockMetadataWithNotify(i + 11, j + 30, k + 3, 7, 2);
		setBlock(world, i + 11, j + 30, k + 5, Blocks.leaves, 7);
		world.setBlockMetadataWithNotify(i + 11, j + 30, k + 5, 7, 2);
		setBlock(world, i + 11, j + 31, k + 2, Blocks.leaves, 7);
		world.setBlockMetadataWithNotify(i + 11, j + 31, k + 2, 7, 2);
		setBlock(world, i + 11, j + 37, k + 1, Blocks.leaves, 7);
		world.setBlockMetadataWithNotify(i + 11, j + 37, k + 1, 7, 2);
		setBlock(world, i + 11, j + 37, k + 2, Blocks.leaves, 7);
		world.setBlockMetadataWithNotify(i + 11, j + 37, k + 2, 7, 2);
		setBlock(world, i + 11, j + 37, k + 3, Blocks.leaves, 7);
		world.setBlockMetadataWithNotify(i + 11, j + 37, k + 3, 7, 2);
		setBlock(world, i + 11, j + 38, k + 2, Blocks.leaves, 7);
		world.setBlockMetadataWithNotify(i + 11, j + 38, k + 2, 7, 2);
		setBlock(world, i + 11, j + 52, k + 1, Blocks.log, 1);
		world.setBlockMetadataWithNotify(i + 11, j + 52, k + 1, 1, 2);
		setBlock(world, i + 11, j + 52, k + 2, Blocks.log, 1);
		world.setBlockMetadataWithNotify(i + 11, j + 52, k + 2, 1, 2);
		setBlock(world, i + 11, j + 52, k + 3, Blocks.log, 1);
		world.setBlockMetadataWithNotify(i + 11, j + 52, k + 3, 1, 2);
		setBlock(world, i + 11, j + 52, k + 4, Blocks.log, 1);
		world.setBlockMetadataWithNotify(i + 11, j + 52, k + 4, 1, 2);
		setBlock(world, i + 11, j + 53, k + 0, Blocks.log, 1);
		world.setBlockMetadataWithNotify(i + 11, j + 53, k + 0, 1, 2);
		setBlock(world, i + 11, j + 53, k + 1, Blocks.log, 1);
		world.setBlockMetadataWithNotify(i + 11, j + 53, k + 1, 1, 2);
		setBlock(world, i + 11, j + 53, k + 2, Blocks.log, 1);
		world.setBlockMetadataWithNotify(i + 11, j + 53, k + 2, 1, 2);
		setBlock(world, i + 11, j + 53, k + 3, Blocks.log, 1);
		world.setBlockMetadataWithNotify(i + 11, j + 53, k + 3, 1, 2);
		setBlock(world, i + 11, j + 53, k + 4, Blocks.log, 1);
		world.setBlockMetadataWithNotify(i + 11, j + 53, k + 4, 1, 2);
		setBlock(world, i + 11, j + 53, k + 5, Blocks.log, 1);
		world.setBlockMetadataWithNotify(i + 11, j + 53, k + 5, 1, 2);
		setBlock(world, i + 11, j + 54, k + 0, Blocks.log, 1);
		world.setBlockMetadataWithNotify(i + 11, j + 54, k + 0, 1, 2);
		setBlock(world, i + 11, j + 54, k + 1, Blocks.log, 1);
		world.setBlockMetadataWithNotify(i + 11, j + 54, k + 1, 1, 2);
		setBlock(world, i + 11, j + 54, k + 2, Blocks.log, 1);
		world.setBlockMetadataWithNotify(i + 11, j + 54, k + 2, 1, 2);
		setBlock(world, i + 11, j + 54, k + 3, Blocks.log, 1);
		world.setBlockMetadataWithNotify(i + 11, j + 54, k + 3, 1, 2);
		setBlock(world, i + 11, j + 54, k + 4, Blocks.log, 1);
		world.setBlockMetadataWithNotify(i + 11, j + 54, k + 4, 1, 2);
		setBlock(world, i + 11, j + 54, k + 5, Blocks.log, 1);
		world.setBlockMetadataWithNotify(i + 11, j + 54, k + 5, 1, 2);
		setBlock(world, i + 11, j + 55, k + 0, Blocks.planks, 5);
		world.setBlockMetadataWithNotify(i + 11, j + 55, k + 0, 5, 2);
		setBlock(world, i + 11, j + 55, k + 1, Blocks.planks, 5);
		world.setBlockMetadataWithNotify(i + 11, j + 55, k + 1, 5, 2);
		setBlock(world, i + 11, j + 55, k + 2, Blocks.planks, 5);
		world.setBlockMetadataWithNotify(i + 11, j + 55, k + 2, 5, 2);
		setBlock(world, i + 11, j + 55, k + 3, Blocks.log, 1);
		world.setBlockMetadataWithNotify(i + 11, j + 55, k + 3, 1, 2);
		setBlock(world, i + 11, j + 55, k + 4, Blocks.log, 1);
		world.setBlockMetadataWithNotify(i + 11, j + 55, k + 4, 1, 2);
		setBlock(world, i + 11, j + 55, k + 5, Blocks.log, 1);
		world.setBlockMetadataWithNotify(i + 11, j + 55, k + 5, 1, 2);
		setBlock(world, i + 11, j + 55, k + 6, Blocks.log, 1);
		world.setBlockMetadataWithNotify(i + 11, j + 55, k + 6, 1, 2);
		setBlock(world, i + 11, j + 55, k + 7, Blocks.log, 1);
		world.setBlockMetadataWithNotify(i + 11, j + 55, k + 7, 1, 2);
		setBlock(world, i + 11, j + 55, k + 8, Blocks.log, 1);
		world.setBlockMetadataWithNotify(i + 11, j + 55, k + 8, 1, 2);
		setBlock(world, i + 11, j + 57, k + 8, Blocks.torch, 5);
		world.setBlockMetadataWithNotify(i + 11, j + 57, k + 8, 5, 2);
		setBlock(world, i + 11, j + 60, k + 4, Blocks.torch, 1);
		world.setBlockMetadataWithNotify(i + 11, j + 60, k + 4, 1, 2);
		setBlock(world, i + 11, j + 60, k + 5, Blocks.log, 1);
		world.setBlockMetadataWithNotify(i + 11, j + 60, k + 5, 1, 2);
		setBlock(world, i + 11, j + 60, k + 6, Blocks.log, 1);
		world.setBlockMetadataWithNotify(i + 11, j + 60, k + 6, 1, 2);
		setBlock(world, i + 11, j + 60, k + 7, Blocks.log, 1);
		world.setBlockMetadataWithNotify(i + 11, j + 60, k + 7, 1, 2);
		setBlock(world, i + 11, j + 60, k + 8, Blocks.log, 1);
		world.setBlockMetadataWithNotify(i + 11, j + 60, k + 8, 1, 2);
		setBlock(world, i + 11, j + 60, k + 9, Blocks.log, 1);
		world.setBlockMetadataWithNotify(i + 11, j + 60, k + 9, 1, 2);
		setBlock(world, i + 11, j + 60, k + 10, Blocks.log, 1);
		world.setBlockMetadataWithNotify(i + 11, j + 60, k + 10, 1, 2);
		setBlock(world, i + 11, j + 60, k + 11, Blocks.log, 1);
		world.setBlockMetadataWithNotify(i + 11, j + 60, k + 11, 1, 2);
		setBlock(world, i + 11, j + 61, k + 0, Blocks.log, 1);
		world.setBlockMetadataWithNotify(i + 11, j + 61, k + 0, 1, 2);
		setBlock(world, i + 11, j + 61, k + 1, Blocks.log, 1);
		world.setBlockMetadataWithNotify(i + 11, j + 61, k + 1, 1, 2);
		setBlock(world, i + 11, j + 61, k + 2, Blocks.log, 1);
		world.setBlockMetadataWithNotify(i + 11, j + 61, k + 2, 1, 2);
		setBlock(world, i + 11, j + 61, k + 3, Blocks.log, 1);
		world.setBlockMetadataWithNotify(i + 11, j + 61, k + 3, 1, 2);
		setBlock(world, i + 11, j + 61, k + 4, Blocks.log, 1);
		world.setBlockMetadataWithNotify(i + 11, j + 61, k + 4, 1, 2);
		setBlock(world, i + 11, j + 61, k + 5, Blocks.log, 1);
		world.setBlockMetadataWithNotify(i + 11, j + 61, k + 5, 1, 2);
		setBlock(world, i + 11, j + 61, k + 6, Blocks.log, 1);
		world.setBlockMetadataWithNotify(i + 11, j + 61, k + 6, 1, 2);
		setBlock(world, i + 11, j + 61, k + 7, Blocks.log, 1);
		world.setBlockMetadataWithNotify(i + 11, j + 61, k + 7, 1, 2);
		setBlock(world, i + 11, j + 61, k + 8, Blocks.log, 1);
		world.setBlockMetadataWithNotify(i + 11, j + 61, k + 8, 1, 2);
		setBlock(world, i + 11, j + 61, k + 9, Blocks.log, 1);
		world.setBlockMetadataWithNotify(i + 11, j + 61, k + 9, 1, 2);
		setBlock(world, i + 11, j + 61, k + 10, Blocks.log, 1);
		world.setBlockMetadataWithNotify(i + 11, j + 61, k + 10, 1, 2);
		setBlock(world, i + 11, j + 62, k + 0, Blocks.log, 1);
		world.setBlockMetadataWithNotify(i + 11, j + 62, k + 0, 1, 2);
		setBlock(world, i + 11, j + 62, k + 1, Blocks.log, 1);
		world.setBlockMetadataWithNotify(i + 11, j + 62, k + 1, 1, 2);
		setBlock(world, i + 11, j + 62, k + 2, Blocks.log, 1);
		world.setBlockMetadataWithNotify(i + 11, j + 62, k + 2, 1, 2);
		setBlock(world, i + 11, j + 62, k + 3, Blocks.log, 1);
		world.setBlockMetadataWithNotify(i + 11, j + 62, k + 3, 1, 2);
		setBlock(world, i + 11, j + 62, k + 4, Blocks.log, 1);
		world.setBlockMetadataWithNotify(i + 11, j + 62, k + 4, 1, 2);
		setBlock(world, i + 11, j + 62, k + 5, Blocks.log, 1);
		world.setBlockMetadataWithNotify(i + 11, j + 62, k + 5, 1, 2);
		setBlock(world, i + 11, j + 62, k + 6, Blocks.log, 1);
		world.setBlockMetadataWithNotify(i + 11, j + 62, k + 6, 1, 2);
		setBlock(world, i + 11, j + 62, k + 7, Blocks.log, 1);
		world.setBlockMetadataWithNotify(i + 11, j + 62, k + 7, 1, 2);
		setBlock(world, i + 12, j + 21, k + 25, Blocks.leaves, 7);
		world.setBlockMetadataWithNotify(i + 12, j + 21, k + 25, 7, 2);
		setBlock(world, i + 12, j + 21, k + 26, Blocks.leaves, 7);
		world.setBlockMetadataWithNotify(i + 12, j + 21, k + 26, 7, 2);
		setBlock(world, i + 12, j + 21, k + 27, Blocks.leaves, 7);
		world.setBlockMetadataWithNotify(i + 12, j + 21, k + 27, 7, 2);
		setBlock(world, i + 12, j + 21, k + 28, Blocks.leaves, 7);
		world.setBlockMetadataWithNotify(i + 12, j + 21, k + 28, 7, 2);
		setBlock(world, i + 12, j + 21, k + 29, Blocks.leaves, 7);
		world.setBlockMetadataWithNotify(i + 12, j + 21, k + 29, 7, 2);
		setBlock(world, i + 12, j + 22, k + 26, Blocks.leaves, 7);
		world.setBlockMetadataWithNotify(i + 12, j + 22, k + 26, 7, 2);
		setBlock(world, i + 12, j + 22, k + 27, Blocks.leaves, 7);
		world.setBlockMetadataWithNotify(i + 12, j + 22, k + 27, 7, 2);
		setBlock(world, i + 12, j + 22, k + 28, Blocks.leaves, 7);
		world.setBlockMetadataWithNotify(i + 12, j + 22, k + 28, 7, 2);
		setBlock(world, i + 12, j + 23, k + 16, Blocks.leaves, 7);
		world.setBlockMetadataWithNotify(i + 12, j + 23, k + 16, 7, 2);
		setBlock(world, i + 12, j + 23, k + 17, Blocks.leaves, 7);
		world.setBlockMetadataWithNotify(i + 12, j + 23, k + 17, 7, 2);
		setBlock(world, i + 12, j + 23, k + 18, Blocks.leaves, 7);
		world.setBlockMetadataWithNotify(i + 12, j + 23, k + 18, 7, 2);
		setBlock(world, i + 12, j + 23, k + 19, Blocks.leaves, 7);
		world.setBlockMetadataWithNotify(i + 12, j + 23, k + 19, 7, 2);
		setBlock(world, i + 12, j + 23, k + 20, Blocks.leaves, 7);
		world.setBlockMetadataWithNotify(i + 12, j + 23, k + 20, 7, 2);
		setBlock(world, i + 12, j + 23, k + 27, Blocks.leaves, 7);
		world.setBlockMetadataWithNotify(i + 12, j + 23, k + 27, 7, 2);
		setBlock(world, i + 12, j + 24, k + 17, Blocks.leaves, 7);
		world.setBlockMetadataWithNotify(i + 12, j + 24, k + 17, 7, 2);
		setBlock(world, i + 12, j + 24, k + 18, Blocks.leaves, 7);
		world.setBlockMetadataWithNotify(i + 12, j + 24, k + 18, 7, 2);
		setBlock(world, i + 12, j + 24, k + 19, Blocks.leaves, 7);
		world.setBlockMetadataWithNotify(i + 12, j + 24, k + 19, 7, 2);
		setBlock(world, i + 12, j + 25, k + 18, Blocks.leaves, 7);
		world.setBlockMetadataWithNotify(i + 12, j + 25, k + 18, 7, 2);
		setBlock(world, i + 12, j + 27, k + 2, Blocks.log, 3);
		world.setBlockMetadataWithNotify(i + 12, j + 27, k + 2, 3, 2);
		setBlock(world, i + 12, j + 28, k + 1, Blocks.log, 3);
		world.setBlockMetadataWithNotify(i + 12, j + 28, k + 1, 3, 2);
		setBlock(world, i + 12, j + 28, k + 4, Blocks.leaves, 7);
		world.setBlockMetadataWithNotify(i + 12, j + 28, k + 4, 7, 2);
		setBlock(world, i + 12, j + 28, k + 5, Blocks.leaves, 7);
		world.setBlockMetadataWithNotify(i + 12, j + 28, k + 5, 7, 2);
		setBlock(world, i + 12, j + 28, k + 6, Blocks.leaves, 7);
		world.setBlockMetadataWithNotify(i + 12, j + 28, k + 6, 7, 2);
		setBlock(world, i + 12, j + 29, k + 1, Blocks.leaves, 7);
		world.setBlockMetadataWithNotify(i + 12, j + 29, k + 1, 7, 2);
		setBlock(world, i + 12, j + 29, k + 2, Blocks.leaves, 7);
		world.setBlockMetadataWithNotify(i + 12, j + 29, k + 2, 7, 2);
		setBlock(world, i + 12, j + 29, k + 3, Blocks.leaves, 7);
		world.setBlockMetadataWithNotify(i + 12, j + 29, k + 3, 7, 2);
		setBlock(world, i + 12, j + 29, k + 5, Blocks.leaves, 7);
		world.setBlockMetadataWithNotify(i + 12, j + 29, k + 5, 7, 2);
		setBlock(world, i + 12, j + 29, k + 31, Blocks.leaves, 7);
		world.setBlockMetadataWithNotify(i + 12, j + 29, k + 31, 7, 2);
		setBlock(world, i + 12, j + 30, k + 2, Blocks.leaves, 7);
		world.setBlockMetadataWithNotify(i + 12, j + 30, k + 2, 7, 2);
		setBlock(world, i + 12, j + 37, k + 0, Blocks.leaves, 7);
		world.setBlockMetadataWithNotify(i + 12, j + 37, k + 0, 7, 2);
		setBlock(world, i + 12, j + 37, k + 1, Blocks.leaves, 7);
		world.setBlockMetadataWithNotify(i + 12, j + 37, k + 1, 7, 2);
		setBlock(world, i + 12, j + 37, k + 2, Blocks.leaves, 7);
		world.setBlockMetadataWithNotify(i + 12, j + 37, k + 2, 7, 2);
		setBlock(world, i + 12, j + 37, k + 3, Blocks.leaves, 7);
		world.setBlockMetadataWithNotify(i + 12, j + 37, k + 3, 7, 2);
		setBlock(world, i + 12, j + 37, k + 4, Blocks.leaves, 7);
		world.setBlockMetadataWithNotify(i + 12, j + 37, k + 4, 7, 2);
		setBlock(world, i + 12, j + 38, k + 1, Blocks.leaves, 7);
		world.setBlockMetadataWithNotify(i + 12, j + 38, k + 1, 7, 2);
		setBlock(world, i + 12, j + 38, k + 2, Blocks.leaves, 7);
		world.setBlockMetadataWithNotify(i + 12, j + 38, k + 2, 7, 2);
		setBlock(world, i + 12, j + 38, k + 3, Blocks.leaves, 7);
		world.setBlockMetadataWithNotify(i + 12, j + 38, k + 3, 7, 2);
		setBlock(world, i + 12, j + 39, k + 2, Blocks.leaves, 7);
		world.setBlockMetadataWithNotify(i + 12, j + 39, k + 2, 7, 2);
		setBlock(world, i + 12, j + 46, k + 0, Blocks.log, 1);
		world.setBlockMetadataWithNotify(i + 12, j + 46, k + 0, 1, 2);
		setBlock(world, i + 12, j + 47, k + 0, Blocks.log, 1);
		world.setBlockMetadataWithNotify(i + 12, j + 47, k + 0, 1, 2);
		setBlock(world, i + 12, j + 47, k + 1, Blocks.log, 1);
		world.setBlockMetadataWithNotify(i + 12, j + 47, k + 1, 1, 2);
		setBlock(world, i + 12, j + 48, k + 0, Blocks.log, 1);
		world.setBlockMetadataWithNotify(i + 12, j + 48, k + 0, 1, 2);
		setBlock(world, i + 12, j + 50, k + 0, Blocks.log, 1);
		world.setBlockMetadataWithNotify(i + 12, j + 50, k + 0, 1, 2);
		setBlock(world, i + 12, j + 50, k + 1, Blocks.log, 1);
		world.setBlockMetadataWithNotify(i + 12, j + 50, k + 1, 1, 2);
		setBlock(world, i + 12, j + 50, k + 2, Blocks.log, 1);
		world.setBlockMetadataWithNotify(i + 12, j + 50, k + 2, 1, 2);
		setBlock(world, i + 12, j + 51, k + 0, Blocks.log, 1);
		world.setBlockMetadataWithNotify(i + 12, j + 51, k + 0, 1, 2);
		setBlock(world, i + 12, j + 51, k + 1, Blocks.log, 1);
		world.setBlockMetadataWithNotify(i + 12, j + 51, k + 1, 1, 2);
		setBlock(world, i + 12, j + 51, k + 2, Blocks.log, 1);
		world.setBlockMetadataWithNotify(i + 12, j + 51, k + 2, 1, 2);
		setBlock(world, i + 12, j + 51, k + 3, Blocks.log, 1);
		world.setBlockMetadataWithNotify(i + 12, j + 51, k + 3, 1, 2);
		setBlock(world, i + 12, j + 52, k + 0, Blocks.log, 1);
		world.setBlockMetadataWithNotify(i + 12, j + 52, k + 0, 1, 2);
		setBlock(world, i + 12, j + 52, k + 1, Blocks.log, 1);
		world.setBlockMetadataWithNotify(i + 12, j + 52, k + 1, 1, 2);
		setBlock(world, i + 12, j + 52, k + 2, Blocks.log, 1);
		world.setBlockMetadataWithNotify(i + 12, j + 52, k + 2, 1, 2);
		setBlock(world, i + 12, j + 52, k + 3, Blocks.log, 1);
		world.setBlockMetadataWithNotify(i + 12, j + 52, k + 3, 1, 2);
		setBlock(world, i + 12, j + 52, k + 4, Blocks.log, 1);
		world.setBlockMetadataWithNotify(i + 12, j + 52, k + 4, 1, 2);
		setBlock(world, i + 12, j + 52, k + 5, Blocks.log, 1);
		world.setBlockMetadataWithNotify(i + 12, j + 52, k + 5, 1, 2);
		setBlock(world, i + 12, j + 53, k + 0, Blocks.log, 1);
		world.setBlockMetadataWithNotify(i + 12, j + 53, k + 0, 1, 2);
		setBlock(world, i + 12, j + 53, k + 1, Blocks.log, 1);
		world.setBlockMetadataWithNotify(i + 12, j + 53, k + 1, 1, 2);
		setBlock(world, i + 12, j + 53, k + 2, Blocks.log, 1);
		world.setBlockMetadataWithNotify(i + 12, j + 53, k + 2, 1, 2);
		setBlock(world, i + 12, j + 53, k + 3, Blocks.log, 1);
		world.setBlockMetadataWithNotify(i + 12, j + 53, k + 3, 1, 2);
		setBlock(world, i + 12, j + 53, k + 4, Blocks.log, 1);
		world.setBlockMetadataWithNotify(i + 12, j + 53, k + 4, 1, 2);
		setBlock(world, i + 12, j + 53, k + 5, Blocks.log, 1);
		world.setBlockMetadataWithNotify(i + 12, j + 53, k + 5, 1, 2);
		setBlock(world, i + 12, j + 53, k + 6, Blocks.log, 1);
		world.setBlockMetadataWithNotify(i + 12, j + 53, k + 6, 1, 2);
		setBlock(world, i + 12, j + 54, k + 0, Blocks.log, 1);
		world.setBlockMetadataWithNotify(i + 12, j + 54, k + 0, 1, 2);
		setBlock(world, i + 12, j + 54, k + 1, Blocks.log, 1);
		world.setBlockMetadataWithNotify(i + 12, j + 54, k + 1, 1, 2);
		setBlock(world, i + 12, j + 54, k + 2, Blocks.log, 1);
		world.setBlockMetadataWithNotify(i + 12, j + 54, k + 2, 1, 2);
		setBlock(world, i + 12, j + 54, k + 3, Blocks.log, 1);
		world.setBlockMetadataWithNotify(i + 12, j + 54, k + 3, 1, 2);
		setBlock(world, i + 12, j + 54, k + 4, Blocks.log, 1);
		world.setBlockMetadataWithNotify(i + 12, j + 54, k + 4, 1, 2);
		setBlock(world, i + 12, j + 54, k + 5, Blocks.log, 1);
		world.setBlockMetadataWithNotify(i + 12, j + 54, k + 5, 1, 2);
		setBlock(world, i + 12, j + 54, k + 6, Blocks.log, 1);
		world.setBlockMetadataWithNotify(i + 12, j + 54, k + 6, 1, 2);
		setBlock(world, i + 12, j + 54, k + 7, Blocks.log, 1);
		world.setBlockMetadataWithNotify(i + 12, j + 54, k + 7, 1, 2);
		setBlock(world, i + 12, j + 55, k + 0, Blocks.planks, 5);
		world.setBlockMetadataWithNotify(i + 12, j + 55, k + 0, 5, 2);
		setBlock(world, i + 12, j + 55, k + 1, Blocks.log, 1);
		world.setBlockMetadataWithNotify(i + 12, j + 55, k + 1, 1, 2);
		setBlock(world, i + 12, j + 55, k + 2, Blocks.log, 1);
		world.setBlockMetadataWithNotify(i + 12, j + 55, k + 2, 1, 2);
		setBlock(world, i + 12, j + 55, k + 3, Blocks.planks, 5);
		world.setBlockMetadataWithNotify(i + 12, j + 55, k + 3, 5, 2);
		setBlock(world, i + 12, j + 55, k + 4, Blocks.log, 1);
		world.setBlockMetadataWithNotify(i + 12, j + 55, k + 4, 1, 2);
		setBlock(world, i + 12, j + 55, k + 5, Blocks.log, 1);
		world.setBlockMetadataWithNotify(i + 12, j + 55, k + 5, 1, 2);
		setBlock(world, i + 12, j + 55, k + 6, Blocks.log, 1);
		world.setBlockMetadataWithNotify(i + 12, j + 55, k + 6, 1, 2);
		setBlock(world, i + 12, j + 55, k + 7, Blocks.log, 1);
		world.setBlockMetadataWithNotify(i + 12, j + 55, k + 7, 1, 2);
		setBlock(world, i + 12, j + 55, k + 8, Blocks.log, 1);
		world.setBlockMetadataWithNotify(i + 12, j + 55, k + 8, 1, 2);
		setBlock(world, i + 12, j + 55, k + 9, Blocks.log, 1);
		world.setBlockMetadataWithNotify(i + 12, j + 55, k + 9, 1, 2);
		setBlock(world, i + 12, j + 56, k + 8, Blocks.spruce_stairs, 2);
		world.setBlockMetadataWithNotify(i + 12, j + 56, k + 8, 2, 2);
		setBlock(world, i + 12, j + 56, k + 9, Blocks.log, 1);
		world.setBlockMetadataWithNotify(i + 12, j + 56, k + 9, 1, 2);
		setBlock(world, i + 12, j + 56, k + 10, Blocks.spruce_stairs, 7);
		world.setBlockMetadataWithNotify(i + 12, j + 56, k + 10, 7, 2);
		setBlock(world, i + 12, j + 57, k + 9, Blocks.log, 1);
		world.setBlockMetadataWithNotify(i + 12, j + 57, k + 9, 1, 2);
		setBlock(world, i + 12, j + 57, k + 10, Blocks.log, 1);
		world.setBlockMetadataWithNotify(i + 12, j + 57, k + 10, 1, 2);
		setBlock(world, i + 12, j + 57, k + 11, Blocks.spruce_stairs, 7);
		world.setBlockMetadataWithNotify(i + 12, j + 57, k + 11, 7, 2);
		setBlock(world, i + 12, j + 58, k + 10, Blocks.log, 1);
		world.setBlockMetadataWithNotify(i + 12, j + 58, k + 10, 1, 2);
		setBlock(world, i + 12, j + 58, k + 11, Blocks.log, 1);
		world.setBlockMetadataWithNotify(i + 12, j + 58, k + 11, 1, 2);
		setBlock(world, i + 12, j + 59, k + 11, Blocks.log, 1);
		world.setBlockMetadataWithNotify(i + 12, j + 59, k + 11, 1, 2);
		setBlock(world, i + 12, j + 60, k + 6, Blocks.log, 1);
		world.setBlockMetadataWithNotify(i + 12, j + 60, k + 6, 1, 2);
		setBlock(world, i + 12, j + 60, k + 7, Blocks.log, 1);
		world.setBlockMetadataWithNotify(i + 12, j + 60, k + 7, 1, 2);
		setBlock(world, i + 12, j + 60, k + 8, Blocks.log, 1);
		world.setBlockMetadataWithNotify(i + 12, j + 60, k + 8, 1, 2);
		setBlock(world, i + 12, j + 60, k + 9, Blocks.log, 1);
		world.setBlockMetadataWithNotify(i + 12, j + 60, k + 9, 1, 2);
		setBlock(world, i + 12, j + 60, k + 10, Blocks.log, 1);
		world.setBlockMetadataWithNotify(i + 12, j + 60, k + 10, 1, 2);
		setBlock(world, i + 12, j + 60, k + 11, Blocks.log, 1);
		world.setBlockMetadataWithNotify(i + 12, j + 60, k + 11, 1, 2);
		setBlock(world, i + 12, j + 60, k + 12, Blocks.log, 1);
		world.setBlockMetadataWithNotify(i + 12, j + 60, k + 12, 1, 2);
		setBlock(world, i + 12, j + 61, k + 5, Blocks.log, 1);
		world.setBlockMetadataWithNotify(i + 12, j + 61, k + 5, 1, 2);
		setBlock(world, i + 12, j + 61, k + 6, Blocks.log, 1);
		world.setBlockMetadataWithNotify(i + 12, j + 61, k + 6, 1, 2);
		setBlock(world, i + 12, j + 61, k + 7, Blocks.log, 1);
		world.setBlockMetadataWithNotify(i + 12, j + 61, k + 7, 1, 2);
		setBlock(world, i + 12, j + 61, k + 8, Blocks.log, 1);
		world.setBlockMetadataWithNotify(i + 12, j + 61, k + 8, 1, 2);
		setBlock(world, i + 12, j + 61, k + 9, Blocks.log, 1);
		world.setBlockMetadataWithNotify(i + 12, j + 61, k + 9, 1, 2);
		setBlock(world, i + 12, j + 61, k + 10, Blocks.log, 1);
		world.setBlockMetadataWithNotify(i + 12, j + 61, k + 10, 1, 2);
		setBlock(world, i + 12, j + 61, k + 11, Blocks.log, 1);
		world.setBlockMetadataWithNotify(i + 12, j + 61, k + 11, 1, 2);
		setBlock(world, i + 12, j + 62, k + 0, Blocks.log, 1);
		world.setBlockMetadataWithNotify(i + 12, j + 62, k + 0, 1, 2);
		setBlock(world, i + 12, j + 62, k + 1, Blocks.log, 1);
		world.setBlockMetadataWithNotify(i + 12, j + 62, k + 1, 1, 2);
		setBlock(world, i + 12, j + 62, k + 2, Blocks.log, 1);
		world.setBlockMetadataWithNotify(i + 12, j + 62, k + 2, 1, 2);
		setBlock(world, i + 12, j + 62, k + 3, Blocks.log, 1);
		world.setBlockMetadataWithNotify(i + 12, j + 62, k + 3, 1, 2);
		setBlock(world, i + 12, j + 62, k + 4, Blocks.log, 1);
		world.setBlockMetadataWithNotify(i + 12, j + 62, k + 4, 1, 2);
		setBlock(world, i + 12, j + 62, k + 5, Blocks.log, 1);
		world.setBlockMetadataWithNotify(i + 12, j + 62, k + 5, 1, 2);
		setBlock(world, i + 12, j + 62, k + 6, Blocks.log, 1);
		world.setBlockMetadataWithNotify(i + 12, j + 62, k + 6, 1, 2);
		setBlock(world, i + 12, j + 62, k + 7, Blocks.log, 1);
		world.setBlockMetadataWithNotify(i + 12, j + 62, k + 7, 1, 2);
		setBlock(world, i + 12, j + 62, k + 8, Blocks.log, 1);
		world.setBlockMetadataWithNotify(i + 12, j + 62, k + 8, 1, 2);
		setBlock(world, i + 12, j + 63, k + 0, Blocks.log, 1);
		world.setBlockMetadataWithNotify(i + 12, j + 63, k + 0, 1, 2);
		setBlock(world, i + 12, j + 63, k + 1, Blocks.log, 1);
		world.setBlockMetadataWithNotify(i + 12, j + 63, k + 1, 1, 2);
		setBlock(world, i + 12, j + 63, k + 2, Blocks.log, 1);
		world.setBlockMetadataWithNotify(i + 12, j + 63, k + 2, 1, 2);
		setBlock(world, i + 12, j + 63, k + 3, Blocks.log, 1);
		world.setBlockMetadataWithNotify(i + 12, j + 63, k + 3, 1, 2);
		setBlock(world, i + 13, j + 20, k + 28, Blocks.log, 3);
		world.setBlockMetadataWithNotify(i + 13, j + 20, k + 28, 3, 2);
		setBlock(world, i + 13, j + 21, k + 25, Blocks.leaves, 7);
		world.setBlockMetadataWithNotify(i + 13, j + 21, k + 25, 7, 2);
		setBlock(world, i + 13, j + 21, k + 26, Blocks.leaves, 7);
		world.setBlockMetadataWithNotify(i + 13, j + 21, k + 26, 7, 2);
		setBlock(world, i + 13, j + 21, k + 27, Blocks.log, 3);
		world.setBlockMetadataWithNotify(i + 13, j + 21, k + 27, 3, 2);
		setBlock(world, i + 13, j + 21, k + 28, Blocks.leaves, 7);
		world.setBlockMetadataWithNotify(i + 13, j + 21, k + 28, 7, 2);
		setBlock(world, i + 13, j + 21, k + 29, Blocks.leaves, 7);
		world.setBlockMetadataWithNotify(i + 13, j + 21, k + 29, 7, 2);
		setBlock(world, i + 13, j + 22, k + 19, Blocks.log, 3);
		world.setBlockMetadataWithNotify(i + 13, j + 22, k + 19, 3, 2);
		setBlock(world, i + 13, j + 22, k + 25, Blocks.leaves, 7);
		world.setBlockMetadataWithNotify(i + 13, j + 22, k + 25, 7, 2);
		setBlock(world, i + 13, j + 22, k + 26, Blocks.leaves, 7);
		world.setBlockMetadataWithNotify(i + 13, j + 22, k + 26, 7, 2);
		setBlock(world, i + 13, j + 22, k + 27, Blocks.leaves, 7);
		world.setBlockMetadataWithNotify(i + 13, j + 22, k + 27, 7, 2);
		setBlock(world, i + 13, j + 22, k + 28, Blocks.leaves, 7);
		world.setBlockMetadataWithNotify(i + 13, j + 22, k + 28, 7, 2);
		setBlock(world, i + 13, j + 22, k + 29, Blocks.leaves, 7);
		world.setBlockMetadataWithNotify(i + 13, j + 22, k + 29, 7, 2);
		setBlock(world, i + 13, j + 23, k + 16, Blocks.leaves, 7);
		world.setBlockMetadataWithNotify(i + 13, j + 23, k + 16, 7, 2);
		setBlock(world, i + 13, j + 23, k + 17, Blocks.leaves, 7);
		world.setBlockMetadataWithNotify(i + 13, j + 23, k + 17, 7, 2);
		setBlock(world, i + 13, j + 23, k + 18, Blocks.log, 3);
		world.setBlockMetadataWithNotify(i + 13, j + 23, k + 18, 3, 2);
		setBlock(world, i + 13, j + 23, k + 19, Blocks.leaves, 7);
		world.setBlockMetadataWithNotify(i + 13, j + 23, k + 19, 7, 2);
		setBlock(world, i + 13, j + 23, k + 20, Blocks.leaves, 7);
		world.setBlockMetadataWithNotify(i + 13, j + 23, k + 20, 7, 2);
		setBlock(world, i + 13, j + 23, k + 26, Blocks.leaves, 7);
		world.setBlockMetadataWithNotify(i + 13, j + 23, k + 26, 7, 2);
		setBlock(world, i + 13, j + 23, k + 27, Blocks.leaves, 7);
		world.setBlockMetadataWithNotify(i + 13, j + 23, k + 27, 7, 2);
		setBlock(world, i + 13, j + 23, k + 28, Blocks.leaves, 7);
		world.setBlockMetadataWithNotify(i + 13, j + 23, k + 28, 7, 2);
		setBlock(world, i + 13, j + 24, k + 16, Blocks.leaves, 7);
		world.setBlockMetadataWithNotify(i + 13, j + 24, k + 16, 7, 2);
		setBlock(world, i + 13, j + 24, k + 17, Blocks.leaves, 7);
		world.setBlockMetadataWithNotify(i + 13, j + 24, k + 17, 7, 2);
		setBlock(world, i + 13, j + 24, k + 18, Blocks.leaves, 7);
		world.setBlockMetadataWithNotify(i + 13, j + 24, k + 18, 7, 2);
		setBlock(world, i + 13, j + 24, k + 19, Blocks.leaves, 7);
		world.setBlockMetadataWithNotify(i + 13, j + 24, k + 19, 7, 2);
		setBlock(world, i + 13, j + 24, k + 20, Blocks.leaves, 7);
		world.setBlockMetadataWithNotify(i + 13, j + 24, k + 20, 7, 2);
		setBlock(world, i + 13, j + 24, k + 27, Blocks.leaves, 7);
		world.setBlockMetadataWithNotify(i + 13, j + 24, k + 27, 7, 2);
		setBlock(world, i + 13, j + 25, k + 17, Blocks.leaves, 7);
		world.setBlockMetadataWithNotify(i + 13, j + 25, k + 17, 7, 2);
		setBlock(world, i + 13, j + 25, k + 18, Blocks.leaves, 7);
		world.setBlockMetadataWithNotify(i + 13, j + 25, k + 18, 7, 2);
		setBlock(world, i + 13, j + 25, k + 19, Blocks.leaves, 7);
		world.setBlockMetadataWithNotify(i + 13, j + 25, k + 19, 7, 2);
		setBlock(world, i + 13, j + 26, k + 18, Blocks.leaves, 7);
		world.setBlockMetadataWithNotify(i + 13, j + 26, k + 18, 7, 2);
		setBlock(world, i + 13, j + 27, k + 1, Blocks.log, 3);
		world.setBlockMetadataWithNotify(i + 13, j + 27, k + 1, 3, 2);
		setBlock(world, i + 13, j + 28, k + 0, Blocks.log, 3);
		world.setBlockMetadataWithNotify(i + 13, j + 28, k + 0, 3, 2);
		setBlock(world, i + 13, j + 29, k + 31, Blocks.leaves, 7);
		world.setBlockMetadataWithNotify(i + 13, j + 29, k + 31, 7, 2);
		setBlock(world, i + 13, j + 30, k + 31, Blocks.leaves, 7);
		world.setBlockMetadataWithNotify(i + 13, j + 30, k + 31, 7, 2);
		setBlock(world, i + 13, j + 37, k + 0, Blocks.leaves, 7);
		world.setBlockMetadataWithNotify(i + 13, j + 37, k + 0, 7, 2);
		setBlock(world, i + 13, j + 37, k + 1, Blocks.leaves, 7);
		world.setBlockMetadataWithNotify(i + 13, j + 37, k + 1, 7, 2);
		setBlock(world, i + 13, j + 37, k + 2, Blocks.log, 3);
		world.setBlockMetadataWithNotify(i + 13, j + 37, k + 2, 3, 2);
		setBlock(world, i + 13, j + 37, k + 3, Blocks.leaves, 7);
		world.setBlockMetadataWithNotify(i + 13, j + 37, k + 3, 7, 2);
		setBlock(world, i + 13, j + 37, k + 4, Blocks.leaves, 7);
		world.setBlockMetadataWithNotify(i + 13, j + 37, k + 4, 7, 2);
		setBlock(world, i + 13, j + 38, k + 0, Blocks.leaves, 7);
		world.setBlockMetadataWithNotify(i + 13, j + 38, k + 0, 7, 2);
		setBlock(world, i + 13, j + 38, k + 1, Blocks.leaves, 7);
		world.setBlockMetadataWithNotify(i + 13, j + 38, k + 1, 7, 2);
		setBlock(world, i + 13, j + 38, k + 2, Blocks.leaves, 7);
		world.setBlockMetadataWithNotify(i + 13, j + 38, k + 2, 7, 2);
		setBlock(world, i + 13, j + 38, k + 3, Blocks.leaves, 7);
		world.setBlockMetadataWithNotify(i + 13, j + 38, k + 3, 7, 2);
		setBlock(world, i + 13, j + 38, k + 4, Blocks.leaves, 7);
		world.setBlockMetadataWithNotify(i + 13, j + 38, k + 4, 7, 2);
		setBlock(world, i + 13, j + 38, k + 30, Blocks.leaves, 7);
		world.setBlockMetadataWithNotify(i + 13, j + 38, k + 30, 7, 2);
		setBlock(world, i + 13, j + 38, k + 31, Blocks.leaves, 7);
		world.setBlockMetadataWithNotify(i + 13, j + 38, k + 31, 7, 2);
		setBlock(world, i + 13, j + 39, k + 1, Blocks.leaves, 7);
		world.setBlockMetadataWithNotify(i + 13, j + 39, k + 1, 7, 2);
		setBlock(world, i + 13, j + 39, k + 2, Blocks.leaves, 7);
		world.setBlockMetadataWithNotify(i + 13, j + 39, k + 2, 7, 2);
		setBlock(world, i + 13, j + 39, k + 3, Blocks.leaves, 7);
		world.setBlockMetadataWithNotify(i + 13, j + 39, k + 3, 7, 2);
		setBlock(world, i + 13, j + 39, k + 31, Blocks.leaves, 7);
		world.setBlockMetadataWithNotify(i + 13, j + 39, k + 31, 7, 2);
		setBlock(world, i + 13, j + 40, k + 2, Blocks.leaves, 7);
		world.setBlockMetadataWithNotify(i + 13, j + 40, k + 2, 7, 2);
		setBlock(world, i + 13, j + 46, k + 0, Blocks.log, 1);
		world.setBlockMetadataWithNotify(i + 13, j + 46, k + 0, 1, 2);
		setBlock(world, i + 13, j + 46, k + 1, Blocks.log, 1);
		world.setBlockMetadataWithNotify(i + 13, j + 46, k + 1, 1, 2);
		setBlock(world, i + 13, j + 47, k + 0, Blocks.log, 1);
		world.setBlockMetadataWithNotify(i + 13, j + 47, k + 0, 1, 2);
		setBlock(world, i + 13, j + 47, k + 1, Blocks.log, 1);
		world.setBlockMetadataWithNotify(i + 13, j + 47, k + 1, 1, 2);
		setBlock(world, i + 13, j + 48, k + 0, Blocks.log, 1);
		world.setBlockMetadataWithNotify(i + 13, j + 48, k + 0, 1, 2);
		setBlock(world, i + 13, j + 48, k + 1, Blocks.log, 1);
		world.setBlockMetadataWithNotify(i + 13, j + 48, k + 1, 1, 2);
		setBlock(world, i + 13, j + 49, k + 0, Blocks.log, 1);
		world.setBlockMetadataWithNotify(i + 13, j + 49, k + 0, 1, 2);
		setBlock(world, i + 13, j + 49, k + 1, Blocks.log, 1);
		world.setBlockMetadataWithNotify(i + 13, j + 49, k + 1, 1, 2);
		setBlock(world, i + 13, j + 49, k + 2, Blocks.log, 1);
		world.setBlockMetadataWithNotify(i + 13, j + 49, k + 2, 1, 2);
		setBlock(world, i + 13, j + 50, k + 0, Blocks.log, 1);
		world.setBlockMetadataWithNotify(i + 13, j + 50, k + 0, 1, 2);
		setBlock(world, i + 13, j + 50, k + 1, Blocks.log, 1);
		world.setBlockMetadataWithNotify(i + 13, j + 50, k + 1, 1, 2);
		setBlock(world, i + 13, j + 50, k + 2, Blocks.log, 1);
		world.setBlockMetadataWithNotify(i + 13, j + 50, k + 2, 1, 2);
		setBlock(world, i + 13, j + 50, k + 3, Blocks.log, 1);
		world.setBlockMetadataWithNotify(i + 13, j + 50, k + 3, 1, 2);
		setBlock(world, i + 13, j + 51, k + 0, Blocks.log, 1);
		world.setBlockMetadataWithNotify(i + 13, j + 51, k + 0, 1, 2);
		setBlock(world, i + 13, j + 51, k + 1, Blocks.log, 1);
		world.setBlockMetadataWithNotify(i + 13, j + 51, k + 1, 1, 2);
		setBlock(world, i + 13, j + 51, k + 2, Blocks.log, 1);
		world.setBlockMetadataWithNotify(i + 13, j + 51, k + 2, 1, 2);
		setBlock(world, i + 13, j + 51, k + 3, Blocks.log, 1);
		world.setBlockMetadataWithNotify(i + 13, j + 51, k + 3, 1, 2);
		setBlock(world, i + 13, j + 52, k + 0, Blocks.log, 1);
		world.setBlockMetadataWithNotify(i + 13, j + 52, k + 0, 1, 2);
		setBlock(world, i + 13, j + 52, k + 1, Blocks.log, 1);
		world.setBlockMetadataWithNotify(i + 13, j + 52, k + 1, 1, 2);
		setBlock(world, i + 13, j + 52, k + 2, Blocks.log, 1);
		world.setBlockMetadataWithNotify(i + 13, j + 52, k + 2, 1, 2);
		setBlock(world, i + 13, j + 52, k + 3, Blocks.log, 1);
		world.setBlockMetadataWithNotify(i + 13, j + 52, k + 3, 1, 2);
		setBlock(world, i + 13, j + 52, k + 4, Blocks.log, 1);
		world.setBlockMetadataWithNotify(i + 13, j + 52, k + 4, 1, 2);
		setBlock(world, i + 13, j + 52, k + 5, Blocks.log, 1);
		world.setBlockMetadataWithNotify(i + 13, j + 52, k + 5, 1, 2);
		setBlock(world, i + 13, j + 52, k + 6, Blocks.log, 1);
		world.setBlockMetadataWithNotify(i + 13, j + 52, k + 6, 1, 2);
		setBlock(world, i + 13, j + 53, k + 0, Blocks.log, 1);
		world.setBlockMetadataWithNotify(i + 13, j + 53, k + 0, 1, 2);
		setBlock(world, i + 13, j + 53, k + 1, Blocks.log, 1);
		world.setBlockMetadataWithNotify(i + 13, j + 53, k + 1, 1, 2);
		setBlock(world, i + 13, j + 53, k + 2, Blocks.log, 1);
		world.setBlockMetadataWithNotify(i + 13, j + 53, k + 2, 1, 2);
		setBlock(world, i + 13, j + 53, k + 3, Blocks.log, 1);
		world.setBlockMetadataWithNotify(i + 13, j + 53, k + 3, 1, 2);
		setBlock(world, i + 13, j + 53, k + 4, Blocks.log, 1);
		world.setBlockMetadataWithNotify(i + 13, j + 53, k + 4, 1, 2);
		setBlock(world, i + 13, j + 53, k + 5, Blocks.log, 1);
		world.setBlockMetadataWithNotify(i + 13, j + 53, k + 5, 1, 2);
		setBlock(world, i + 13, j + 53, k + 6, Blocks.log, 1);
		world.setBlockMetadataWithNotify(i + 13, j + 53, k + 6, 1, 2);
		setBlock(world, i + 13, j + 53, k + 7, Blocks.log, 1);
		world.setBlockMetadataWithNotify(i + 13, j + 53, k + 7, 1, 2);
		setBlock(world, i + 13, j + 54, k + 0, Blocks.log, 1);
		world.setBlockMetadataWithNotify(i + 13, j + 54, k + 0, 1, 2);
		setBlock(world, i + 13, j + 54, k + 1, Blocks.log, 1);
		world.setBlockMetadataWithNotify(i + 13, j + 54, k + 1, 1, 2);
		setBlock(world, i + 13, j + 54, k + 2, Blocks.log, 1);
		world.setBlockMetadataWithNotify(i + 13, j + 54, k + 2, 1, 2);
		setBlock(world, i + 13, j + 54, k + 3, Blocks.log, 1);
		world.setBlockMetadataWithNotify(i + 13, j + 54, k + 3, 1, 2);
		setBlock(world, i + 13, j + 54, k + 4, Blocks.log, 1);
		world.setBlockMetadataWithNotify(i + 13, j + 54, k + 4, 1, 2);
		setBlock(world, i + 13, j + 54, k + 5, Blocks.log, 1);
		world.setBlockMetadataWithNotify(i + 13, j + 54, k + 5, 1, 2);
		setBlock(world, i + 13, j + 54, k + 6, Blocks.log, 1);
		world.setBlockMetadataWithNotify(i + 13, j + 54, k + 6, 1, 2);
		setBlock(world, i + 13, j + 54, k + 7, Blocks.log, 1);
		world.setBlockMetadataWithNotify(i + 13, j + 54, k + 7, 1, 2);
		setBlock(world, i + 13, j + 54, k + 8, Blocks.log, 1);
		world.setBlockMetadataWithNotify(i + 13, j + 54, k + 8, 1, 2);
		setBlock(world, i + 13, j + 55, k + 0, Blocks.planks, 5);
		world.setBlockMetadataWithNotify(i + 13, j + 55, k + 0, 5, 2);
		setBlock(world, i + 13, j + 55, k + 1, Blocks.planks, 5);
		world.setBlockMetadataWithNotify(i + 13, j + 55, k + 1, 5, 2);
		setBlock(world, i + 13, j + 55, k + 2, Blocks.log, 1);
		world.setBlockMetadataWithNotify(i + 13, j + 55, k + 2, 1, 2);
		setBlock(world, i + 13, j + 55, k + 3, Blocks.log, 1);
		world.setBlockMetadataWithNotify(i + 13, j + 55, k + 3, 1, 2);
		setBlock(world, i + 13, j + 55, k + 4, Blocks.planks, 5);
		world.setBlockMetadataWithNotify(i + 13, j + 55, k + 4, 5, 2);
		setBlock(world, i + 13, j + 55, k + 5, Blocks.log, 1);
		world.setBlockMetadataWithNotify(i + 13, j + 55, k + 5, 1, 2);
		setBlock(world, i + 13, j + 55, k + 6, Blocks.log, 1);
		world.setBlockMetadataWithNotify(i + 13, j + 55, k + 6, 1, 2);
		setBlock(world, i + 13, j + 55, k + 7, Blocks.log, 1);
		world.setBlockMetadataWithNotify(i + 13, j + 55, k + 7, 1, 2);
		setBlock(world, i + 13, j + 55, k + 8, Blocks.log, 1);
		world.setBlockMetadataWithNotify(i + 13, j + 55, k + 8, 1, 2);
		setBlock(world, i + 13, j + 55, k + 9, Blocks.log, 1);
		world.setBlockMetadataWithNotify(i + 13, j + 55, k + 9, 1, 2);
		setBlock(world, i + 13, j + 55, k + 10, Blocks.log, 1);
		world.setBlockMetadataWithNotify(i + 13, j + 55, k + 10, 1, 2);
		setBlock(world, i + 13, j + 55, k + 11, Blocks.planks, 5);
		world.setBlockMetadataWithNotify(i + 13, j + 55, k + 11, 5, 2);
		setBlock(world, i + 13, j + 55, k + 12, Blocks.planks, 5);
		world.setBlockMetadataWithNotify(i + 13, j + 55, k + 12, 5, 2);
		setBlock(world, i + 13, j + 55, k + 13, Blocks.planks, 5);
		world.setBlockMetadataWithNotify(i + 13, j + 55, k + 13, 5, 2);
		setBlock(world, i + 13, j + 55, k + 14, Blocks.planks, 5);
		world.setBlockMetadataWithNotify(i + 13, j + 55, k + 14, 5, 2);
		setBlock(world, i + 13, j + 55, k + 15, Blocks.planks, 5);
		world.setBlockMetadataWithNotify(i + 13, j + 55, k + 15, 5, 2);
		setBlock(world, i + 13, j + 55, k + 16, Blocks.planks, 5);
		world.setBlockMetadataWithNotify(i + 13, j + 55, k + 16, 5, 2);
		setBlock(world, i + 13, j + 55, k + 17, Blocks.planks, 5);
		world.setBlockMetadataWithNotify(i + 13, j + 55, k + 17, 5, 2);
		setBlock(world, i + 13, j + 56, k + 9, Blocks.spruce_stairs, 1);
		world.setBlockMetadataWithNotify(i + 13, j + 56, k + 9, 1, 2);
		setBlock(world, i + 13, j + 56, k + 14, Blocks.torch, 5);
		world.setBlockMetadataWithNotify(i + 13, j + 56, k + 14, 5, 2);
		setBlock(world, i + 13, j + 56, k + 17, Blocks.torch, 5);
		world.setBlockMetadataWithNotify(i + 13, j + 56, k + 17, 5, 2);
		setBlock(world, i + 13, j + 58, k + 10, Blocks.torch, 1);
		world.setBlockMetadataWithNotify(i + 13, j + 58, k + 10, 1, 2);
		setBlock(world, i + 13, j + 59, k + 11, Blocks.spruce_stairs, 5);
		world.setBlockMetadataWithNotify(i + 13, j + 59, k + 11, 5, 2);
		setBlock(world, i + 13, j + 60, k + 6, Blocks.torch, 4);
		world.setBlockMetadataWithNotify(i + 13, j + 60, k + 6, 4, 2);
		setBlock(world, i + 13, j + 60, k + 7, Blocks.log, 1);
		world.setBlockMetadataWithNotify(i + 13, j + 60, k + 7, 1, 2);
		setBlock(world, i + 13, j + 60, k + 8, Blocks.log, 1);
		world.setBlockMetadataWithNotify(i + 13, j + 60, k + 8, 1, 2);
		setBlock(world, i + 13, j + 60, k + 9, Blocks.log, 1);
		world.setBlockMetadataWithNotify(i + 13, j + 60, k + 9, 1, 2);
		setBlock(world, i + 13, j + 60, k + 10, Blocks.log, 1);
		world.setBlockMetadataWithNotify(i + 13, j + 60, k + 10, 1, 2);
		setBlock(world, i + 13, j + 60, k + 11, Blocks.log, 1);
		world.setBlockMetadataWithNotify(i + 13, j + 60, k + 11, 1, 2);
		setBlock(world, i + 13, j + 60, k + 12, Blocks.log, 1);
		world.setBlockMetadataWithNotify(i + 13, j + 60, k + 12, 1, 2);
		setBlock(world, i + 13, j + 61, k + 6, Blocks.log, 1);
		world.setBlockMetadataWithNotify(i + 13, j + 61, k + 6, 1, 2);
		setBlock(world, i + 13, j + 61, k + 7, Blocks.log, 1);
		world.setBlockMetadataWithNotify(i + 13, j + 61, k + 7, 1, 2);
		setBlock(world, i + 13, j + 61, k + 8, Blocks.log, 1);
		world.setBlockMetadataWithNotify(i + 13, j + 61, k + 8, 1, 2);
		setBlock(world, i + 13, j + 61, k + 9, Blocks.log, 1);
		world.setBlockMetadataWithNotify(i + 13, j + 61, k + 9, 1, 2);
		setBlock(world, i + 13, j + 61, k + 10, Blocks.log, 1);
		world.setBlockMetadataWithNotify(i + 13, j + 61, k + 10, 1, 2);
		setBlock(world, i + 13, j + 61, k + 11, Blocks.log, 1);
		world.setBlockMetadataWithNotify(i + 13, j + 61, k + 11, 1, 2);
		setBlock(world, i + 13, j + 62, k + 1, Blocks.torch, 2);
		world.setBlockMetadataWithNotify(i + 13, j + 62, k + 1, 2, 2);
		setBlock(world, i + 13, j + 62, k + 4, Blocks.torch, 4);
		world.setBlockMetadataWithNotify(i + 13, j + 62, k + 4, 4, 2);
		setBlock(world, i + 13, j + 62, k + 5, Blocks.log, 1);
		world.setBlockMetadataWithNotify(i + 13, j + 62, k + 5, 1, 2);
		setBlock(world, i + 13, j + 62, k + 6, Blocks.log, 1);
		world.setBlockMetadataWithNotify(i + 13, j + 62, k + 6, 1, 2);
		setBlock(world, i + 13, j + 62, k + 7, Blocks.log, 1);
		world.setBlockMetadataWithNotify(i + 13, j + 62, k + 7, 1, 2);
		setBlock(world, i + 13, j + 62, k + 8, Blocks.log, 1);
		world.setBlockMetadataWithNotify(i + 13, j + 62, k + 8, 1, 2);
		setBlock(world, i + 13, j + 62, k + 9, Blocks.log, 1);
		world.setBlockMetadataWithNotify(i + 13, j + 62, k + 9, 1, 2);
		setBlock(world, i + 13, j + 63, k + 0, Blocks.log, 1);
		world.setBlockMetadataWithNotify(i + 13, j + 63, k + 0, 1, 2);
		setBlock(world, i + 13, j + 63, k + 1, Blocks.log, 1);
		world.setBlockMetadataWithNotify(i + 13, j + 63, k + 1, 1, 2);
		setBlock(world, i + 13, j + 63, k + 2, Blocks.log, 1);
		world.setBlockMetadataWithNotify(i + 13, j + 63, k + 2, 1, 2);
		setBlock(world, i + 13, j + 63, k + 3, Blocks.log, 1);
		world.setBlockMetadataWithNotify(i + 13, j + 63, k + 3, 1, 2);
		setBlock(world, i + 13, j + 63, k + 4, Blocks.log, 1);
		world.setBlockMetadataWithNotify(i + 13, j + 63, k + 4, 1, 2);
		setBlock(world, i + 13, j + 63, k + 5, Blocks.log, 1);
		world.setBlockMetadataWithNotify(i + 13, j + 63, k + 5, 1, 2);
		setBlock(world, i + 14, j + 20, k + 29, Blocks.log, 3);
		world.setBlockMetadataWithNotify(i + 14, j + 20, k + 29, 3, 2);
		setBlock(world, i + 14, j + 21, k + 25, Blocks.leaves, 7);
		world.setBlockMetadataWithNotify(i + 14, j + 21, k + 25, 7, 2);
		setBlock(world, i + 14, j + 21, k + 26, Blocks.leaves, 7);
		world.setBlockMetadataWithNotify(i + 14, j + 21, k + 26, 7, 2);
		setBlock(world, i + 14, j + 21, k + 27, Blocks.leaves, 7);
		world.setBlockMetadataWithNotify(i + 14, j + 21, k + 27, 7, 2);
		setBlock(world, i + 14, j + 21, k + 28, Blocks.leaves, 7);
		world.setBlockMetadataWithNotify(i + 14, j + 21, k + 28, 7, 2);
		setBlock(world, i + 14, j + 21, k + 29, Blocks.leaves, 7);
		world.setBlockMetadataWithNotify(i + 14, j + 21, k + 29, 7, 2);
		setBlock(world, i + 14, j + 22, k + 20, Blocks.log, 3);
		world.setBlockMetadataWithNotify(i + 14, j + 22, k + 20, 3, 2);
		setBlock(world, i + 14, j + 22, k + 21, Blocks.log, 3);
		world.setBlockMetadataWithNotify(i + 14, j + 22, k + 21, 3, 2);
		setBlock(world, i + 14, j + 22, k + 26, Blocks.leaves, 7);
		world.setBlockMetadataWithNotify(i + 14, j + 22, k + 26, 7, 2);
		setBlock(world, i + 14, j + 22, k + 27, Blocks.leaves, 7);
		world.setBlockMetadataWithNotify(i + 14, j + 22, k + 27, 7, 2);
		setBlock(world, i + 14, j + 22, k + 28, Blocks.leaves, 7);
		
		generate93(world, rand, i, j, k);
		return true;
		}

	
	public boolean generate93(World world, Random rand, int i, int j, int k)
	
	{
		world.setBlockMetadataWithNotify(i + 14, j + 22, k + 28, 7, 2);
		setBlock(world, i + 14, j + 23, k + 16, Blocks.leaves, 7);
		world.setBlockMetadataWithNotify(i + 14, j + 23, k + 16, 7, 2);
		setBlock(world, i + 14, j + 23, k + 17, Blocks.leaves, 7);
		world.setBlockMetadataWithNotify(i + 14, j + 23, k + 17, 7, 2);
		setBlock(world, i + 14, j + 23, k + 18, Blocks.leaves, 7);
		world.setBlockMetadataWithNotify(i + 14, j + 23, k + 18, 7, 2);
		setBlock(world, i + 14, j + 23, k + 19, Blocks.leaves, 7);
		world.setBlockMetadataWithNotify(i + 14, j + 23, k + 19, 7, 2);
		setBlock(world, i + 14, j + 23, k + 20, Blocks.leaves, 7);
		world.setBlockMetadataWithNotify(i + 14, j + 23, k + 20, 7, 2);
		setBlock(world, i + 14, j + 23, k + 27, Blocks.leaves, 7);
		world.setBlockMetadataWithNotify(i + 14, j + 23, k + 27, 7, 2);
		setBlock(world, i + 14, j + 24, k + 17, Blocks.leaves, 7);
		world.setBlockMetadataWithNotify(i + 14, j + 24, k + 17, 7, 2);
		setBlock(world, i + 14, j + 24, k + 18, Blocks.leaves, 7);
		world.setBlockMetadataWithNotify(i + 14, j + 24, k + 18, 7, 2);
		setBlock(world, i + 14, j + 24, k + 19, Blocks.leaves, 7);
		world.setBlockMetadataWithNotify(i + 14, j + 24, k + 19, 7, 2);
		setBlock(world, i + 14, j + 25, k + 18, Blocks.leaves, 7);
		world.setBlockMetadataWithNotify(i + 14, j + 25, k + 18, 7, 2);
		setBlock(world, i + 14, j + 26, k + 0, Blocks.log, 3);
		world.setBlockMetadataWithNotify(i + 14, j + 26, k + 0, 3, 2);
		setBlock(world, i + 14, j + 28, k + 0, Blocks.log, 3);
		world.setBlockMetadataWithNotify(i + 14, j + 28, k + 0, 3, 2);
		setBlock(world, i + 14, j + 29, k + 31, Blocks.leaves, 7);
		world.setBlockMetadataWithNotify(i + 14, j + 29, k + 31, 7, 2);
		setBlock(world, i + 14, j + 36, k + 2, Blocks.log, 3);
		world.setBlockMetadataWithNotify(i + 14, j + 36, k + 2, 3, 2);
		setBlock(world, i + 14, j + 37, k + 0, Blocks.leaves, 7);
		world.setBlockMetadataWithNotify(i + 14, j + 37, k + 0, 7, 2);
		setBlock(world, i + 14, j + 37, k + 1, Blocks.leaves, 7);
		world.setBlockMetadataWithNotify(i + 14, j + 37, k + 1, 7, 2);
		setBlock(world, i + 14, j + 37, k + 2, Blocks.leaves, 7);
		world.setBlockMetadataWithNotify(i + 14, j + 37, k + 2, 7, 2);
		setBlock(world, i + 14, j + 37, k + 3, Blocks.leaves, 7);
		world.setBlockMetadataWithNotify(i + 14, j + 37, k + 3, 7, 2);
		setBlock(world, i + 14, j + 37, k + 4, Blocks.leaves, 7);
		world.setBlockMetadataWithNotify(i + 14, j + 37, k + 4, 7, 2);
		setBlock(world, i + 14, j + 38, k + 1, Blocks.leaves, 7);
		world.setBlockMetadataWithNotify(i + 14, j + 38, k + 1, 7, 2);
		setBlock(world, i + 14, j + 38, k + 2, Blocks.leaves, 7);
		world.setBlockMetadataWithNotify(i + 14, j + 38, k + 2, 7, 2);
		setBlock(world, i + 14, j + 38, k + 3, Blocks.leaves, 7);
		world.setBlockMetadataWithNotify(i + 14, j + 38, k + 3, 7, 2);
		setBlock(world, i + 14, j + 38, k + 29, Blocks.leaves, 7);
		world.setBlockMetadataWithNotify(i + 14, j + 38, k + 29, 7, 2);
		setBlock(world, i + 14, j + 38, k + 30, Blocks.leaves, 7);
		world.setBlockMetadataWithNotify(i + 14, j + 38, k + 30, 7, 2);
		setBlock(world, i + 14, j + 38, k + 31, Blocks.leaves, 7);
		world.setBlockMetadataWithNotify(i + 14, j + 38, k + 31, 7, 2);
		setBlock(world, i + 14, j + 39, k + 2, Blocks.leaves, 7);
		world.setBlockMetadataWithNotify(i + 14, j + 39, k + 2, 7, 2);
		setBlock(world, i + 14, j + 39, k + 30, Blocks.leaves, 7);
		world.setBlockMetadataWithNotify(i + 14, j + 39, k + 30, 7, 2);
		setBlock(world, i + 14, j + 39, k + 31, Blocks.leaves, 7);
		world.setBlockMetadataWithNotify(i + 14, j + 39, k + 31, 7, 2);
		setBlock(world, i + 14, j + 40, k + 31, Blocks.leaves, 7);
		world.setBlockMetadataWithNotify(i + 14, j + 40, k + 31, 7, 2);
		setBlock(world, i + 14, j + 46, k + 0, Blocks.log, 1);
		world.setBlockMetadataWithNotify(i + 14, j + 46, k + 0, 1, 2);
		setBlock(world, i + 14, j + 46, k + 31, Blocks.leaves, 7);
		world.setBlockMetadataWithNotify(i + 14, j + 46, k + 31, 7, 2);
		setBlock(world, i + 14, j + 47, k + 0, Blocks.log, 1);
		world.setBlockMetadataWithNotify(i + 14, j + 47, k + 0, 1, 2);
		setBlock(world, i + 14, j + 47, k + 1, Blocks.log, 1);
		world.setBlockMetadataWithNotify(i + 14, j + 47, k + 1, 1, 2);
		setBlock(world, i + 14, j + 48, k + 0, Blocks.log, 1);
		world.setBlockMetadataWithNotify(i + 14, j + 48, k + 0, 1, 2);
		setBlock(world, i + 14, j + 49, k + 0, Blocks.log, 1);
		world.setBlockMetadataWithNotify(i + 14, j + 49, k + 0, 1, 2);
		setBlock(world, i + 14, j + 49, k + 1, Blocks.log, 1);
		world.setBlockMetadataWithNotify(i + 14, j + 49, k + 1, 1, 2);
		setBlock(world, i + 14, j + 49, k + 2, Blocks.log, 1);
		world.setBlockMetadataWithNotify(i + 14, j + 49, k + 2, 1, 2);
		setBlock(world, i + 14, j + 49, k + 3, Blocks.log, 1);
		world.setBlockMetadataWithNotify(i + 14, j + 49, k + 3, 1, 2);
		setBlock(world, i + 14, j + 50, k + 0, Blocks.log, 1);
		world.setBlockMetadataWithNotify(i + 14, j + 50, k + 0, 1, 2);
		setBlock(world, i + 14, j + 50, k + 1, Blocks.log, 1);
		world.setBlockMetadataWithNotify(i + 14, j + 50, k + 1, 1, 2);
		setBlock(world, i + 14, j + 50, k + 2, Blocks.log, 1);
		world.setBlockMetadataWithNotify(i + 14, j + 50, k + 2, 1, 2);
		setBlock(world, i + 14, j + 50, k + 3, Blocks.log, 1);
		world.setBlockMetadataWithNotify(i + 14, j + 50, k + 3, 1, 2);
		setBlock(world, i + 14, j + 51, k + 0, Blocks.log, 1);
		world.setBlockMetadataWithNotify(i + 14, j + 51, k + 0, 1, 2);
		setBlock(world, i + 14, j + 51, k + 1, Blocks.log, 1);
		world.setBlockMetadataWithNotify(i + 14, j + 51, k + 1, 1, 2);
		setBlock(world, i + 14, j + 51, k + 2, Blocks.log, 1);
		world.setBlockMetadataWithNotify(i + 14, j + 51, k + 2, 1, 2);
		setBlock(world, i + 14, j + 51, k + 3, Blocks.log, 1);
		world.setBlockMetadataWithNotify(i + 14, j + 51, k + 3, 1, 2);
		setBlock(world, i + 14, j + 52, k + 0, Blocks.log, 1);
		world.setBlockMetadataWithNotify(i + 14, j + 52, k + 0, 1, 2);
		setBlock(world, i + 14, j + 52, k + 1, Blocks.log, 1);
		world.setBlockMetadataWithNotify(i + 14, j + 52, k + 1, 1, 2);
		setBlock(world, i + 14, j + 52, k + 2, Blocks.log, 1);
		world.setBlockMetadataWithNotify(i + 14, j + 52, k + 2, 1, 2);
		setBlock(world, i + 14, j + 52, k + 3, Blocks.log, 1);
		world.setBlockMetadataWithNotify(i + 14, j + 52, k + 3, 1, 2);
		setBlock(world, i + 14, j + 52, k + 5, Blocks.log, 1);
		world.setBlockMetadataWithNotify(i + 14, j + 52, k + 5, 1, 2);
		setBlock(world, i + 14, j + 53, k + 0, Blocks.log, 1);
		world.setBlockMetadataWithNotify(i + 14, j + 53, k + 0, 1, 2);
		setBlock(world, i + 14, j + 53, k + 1, Blocks.log, 1);
		world.setBlockMetadataWithNotify(i + 14, j + 53, k + 1, 1, 2);
		setBlock(world, i + 14, j + 53, k + 2, Blocks.log, 1);
		world.setBlockMetadataWithNotify(i + 14, j + 53, k + 2, 1, 2);
		setBlock(world, i + 14, j + 53, k + 3, Blocks.log, 1);
		world.setBlockMetadataWithNotify(i + 14, j + 53, k + 3, 1, 2);
		setBlock(world, i + 14, j + 53, k + 4, Blocks.log, 1);
		world.setBlockMetadataWithNotify(i + 14, j + 53, k + 4, 1, 2);
		setBlock(world, i + 14, j + 53, k + 5, Blocks.log, 1);
		world.setBlockMetadataWithNotify(i + 14, j + 53, k + 5, 1, 2);
		setBlock(world, i + 14, j + 53, k + 6, Blocks.log, 1);
		world.setBlockMetadataWithNotify(i + 14, j + 53, k + 6, 1, 2);
		setBlock(world, i + 14, j + 53, k + 7, Blocks.log, 1);
		world.setBlockMetadataWithNotify(i + 14, j + 53, k + 7, 1, 2);
		setBlock(world, i + 14, j + 53, k + 8, Blocks.log, 1);
		world.setBlockMetadataWithNotify(i + 14, j + 53, k + 8, 1, 2);
		setBlock(world, i + 14, j + 54, k + 0, Blocks.log, 1);
		world.setBlockMetadataWithNotify(i + 14, j + 54, k + 0, 1, 2);
		setBlock(world, i + 14, j + 54, k + 1, Blocks.log, 1);
		world.setBlockMetadataWithNotify(i + 14, j + 54, k + 1, 1, 2);
		setBlock(world, i + 14, j + 54, k + 2, Blocks.log, 1);
		world.setBlockMetadataWithNotify(i + 14, j + 54, k + 2, 1, 2);
		setBlock(world, i + 14, j + 54, k + 3, Blocks.log, 1);
		world.setBlockMetadataWithNotify(i + 14, j + 54, k + 3, 1, 2);
		setBlock(world, i + 14, j + 54, k + 4, Blocks.log, 1);
		world.setBlockMetadataWithNotify(i + 14, j + 54, k + 4, 1, 2);
		setBlock(world, i + 14, j + 54, k + 5, Blocks.log, 1);
		world.setBlockMetadataWithNotify(i + 14, j + 54, k + 5, 1, 2);
		setBlock(world, i + 14, j + 54, k + 6, Blocks.log, 1);
		world.setBlockMetadataWithNotify(i + 14, j + 54, k + 6, 1, 2);
		setBlock(world, i + 14, j + 54, k + 7, Blocks.log, 1);
		world.setBlockMetadataWithNotify(i + 14, j + 54, k + 7, 1, 2);
		setBlock(world, i + 14, j + 54, k + 8, Blocks.log, 1);
		world.setBlockMetadataWithNotify(i + 14, j + 54, k + 8, 1, 2);
		setBlock(world, i + 14, j + 55, k + 0, Blocks.log, 1);
		world.setBlockMetadataWithNotify(i + 14, j + 55, k + 0, 1, 2);
		setBlock(world, i + 14, j + 55, k + 1, Blocks.planks, 5);
		world.setBlockMetadataWithNotify(i + 14, j + 55, k + 1, 5, 2);
		setBlock(world, i + 14, j + 55, k + 2, Blocks.planks, 5);
		world.setBlockMetadataWithNotify(i + 14, j + 55, k + 2, 5, 2);
		setBlock(world, i + 14, j + 55, k + 3, Blocks.log, 1);
		world.setBlockMetadataWithNotify(i + 14, j + 55, k + 3, 1, 2);
		setBlock(world, i + 14, j + 55, k + 4, Blocks.log, 1);
		world.setBlockMetadataWithNotify(i + 14, j + 55, k + 4, 1, 2);
		setBlock(world, i + 14, j + 55, k + 5, Blocks.planks, 5);
		world.setBlockMetadataWithNotify(i + 14, j + 55, k + 5, 5, 2);
		setBlock(world, i + 14, j + 55, k + 6, Blocks.log, 1);
		world.setBlockMetadataWithNotify(i + 14, j + 55, k + 6, 1, 2);
		setBlock(world, i + 14, j + 55, k + 7, Blocks.log, 1);
		world.setBlockMetadataWithNotify(i + 14, j + 55, k + 7, 1, 2);
		setBlock(world, i + 14, j + 55, k + 8, Blocks.log, 1);
		world.setBlockMetadataWithNotify(i + 14, j + 55, k + 8, 1, 2);
		setBlock(world, i + 14, j + 55, k + 9, Blocks.log, 1);
		world.setBlockMetadataWithNotify(i + 14, j + 55, k + 9, 1, 2);
		setBlock(world, i + 14, j + 55, k + 10, Blocks.log, 1);
		world.setBlockMetadataWithNotify(i + 14, j + 55, k + 10, 1, 2);
		setBlock(world, i + 14, j + 55, k + 11, Blocks.log, 1);
		world.setBlockMetadataWithNotify(i + 14, j + 55, k + 11, 1, 2);
		setBlock(world, i + 14, j + 55, k + 12, Blocks.planks, 5);
		world.setBlockMetadataWithNotify(i + 14, j + 55, k + 12, 5, 2);
		setBlock(world, i + 14, j + 55, k + 13, Blocks.planks, 5);
		world.setBlockMetadataWithNotify(i + 14, j + 55, k + 13, 5, 2);
		setBlock(world, i + 14, j + 55, k + 14, Blocks.planks, 5);
		world.setBlockMetadataWithNotify(i + 14, j + 55, k + 14, 5, 2);
		setBlock(world, i + 14, j + 55, k + 15, Blocks.planks, 5);
		world.setBlockMetadataWithNotify(i + 14, j + 55, k + 15, 5, 2);
		setBlock(world, i + 14, j + 55, k + 16, Blocks.planks, 5);
		world.setBlockMetadataWithNotify(i + 14, j + 55, k + 16, 5, 2);
		setBlock(world, i + 14, j + 55, k + 17, Blocks.planks, 5);
		world.setBlockMetadataWithNotify(i + 14, j + 55, k + 17, 5, 2);
		setBlock(world, i + 14, j + 56, k + 1, Blocks.chest, 4);
		LootGenUtils.fillLootChest(world.provider.dimensionId, world.rand, (TileEntityChest)world.getTileEntity(i + 14, j + 56, k + 1));
		world.setBlockMetadataWithNotify(i + 14, j + 56, k + 1, 4, 2);
		setBlock(world, i + 14, j + 58, k + 0, Blocks.torch, 2);
		world.setBlockMetadataWithNotify(i + 14, j + 58, k + 0, 2, 2);
		setBlock(world, i + 14, j + 60, k + 8, Blocks.log, 1);
		world.setBlockMetadataWithNotify(i + 14, j + 60, k + 8, 1, 2);
		setBlock(world, i + 14, j + 60, k + 9, Blocks.log, 1);
		world.setBlockMetadataWithNotify(i + 14, j + 60, k + 9, 1, 2);
		setBlock(world, i + 14, j + 60, k + 10, Blocks.log, 1);
		world.setBlockMetadataWithNotify(i + 14, j + 60, k + 10, 1, 2);
		setBlock(world, i + 14, j + 60, k + 11, Blocks.log, 1);
		world.setBlockMetadataWithNotify(i + 14, j + 60, k + 11, 1, 2);
		setBlock(world, i + 14, j + 60, k + 12, Blocks.log, 1);
		world.setBlockMetadataWithNotify(i + 14, j + 60, k + 12, 1, 2);
		setBlock(world, i + 14, j + 60, k + 13, Blocks.log, 1);
		world.setBlockMetadataWithNotify(i + 14, j + 60, k + 13, 1, 2);
		setBlock(world, i + 14, j + 61, k + 7, Blocks.log, 1);
		world.setBlockMetadataWithNotify(i + 14, j + 61, k + 7, 1, 2);
		setBlock(world, i + 14, j + 61, k + 8, Blocks.log, 1);
		world.setBlockMetadataWithNotify(i + 14, j + 61, k + 8, 1, 2);
		setBlock(world, i + 14, j + 61, k + 9, Blocks.log, 1);
		world.setBlockMetadataWithNotify(i + 14, j + 61, k + 9, 1, 2);
		setBlock(world, i + 14, j + 61, k + 10, Blocks.log, 1);
		world.setBlockMetadataWithNotify(i + 14, j + 61, k + 10, 1, 2);
		setBlock(world, i + 14, j + 61, k + 11, Blocks.log, 1);
		world.setBlockMetadataWithNotify(i + 14, j + 61, k + 11, 1, 2);
		setBlock(world, i + 14, j + 61, k + 12, Blocks.log, 1);
		world.setBlockMetadataWithNotify(i + 14, j + 61, k + 12, 1, 2);
		setBlock(world, i + 14, j + 62, k + 0, Blocks.log, 1);
		world.setBlockMetadataWithNotify(i + 14, j + 62, k + 0, 1, 2);
		setBlock(world, i + 14, j + 62, k + 1, Blocks.log, 1);
		world.setBlockMetadataWithNotify(i + 14, j + 62, k + 1, 1, 2);
		setBlock(world, i + 14, j + 62, k + 2, Blocks.torch, 3);
		world.setBlockMetadataWithNotify(i + 14, j + 62, k + 2, 3, 2);
		setBlock(world, i + 14, j + 62, k + 6, Blocks.log, 1);
		world.setBlockMetadataWithNotify(i + 14, j + 62, k + 6, 1, 2);
		setBlock(world, i + 14, j + 62, k + 7, Blocks.log, 1);
		world.setBlockMetadataWithNotify(i + 14, j + 62, k + 7, 1, 2);
		setBlock(world, i + 14, j + 62, k + 8, Blocks.log, 1);
		world.setBlockMetadataWithNotify(i + 14, j + 62, k + 8, 1, 2);
		setBlock(world, i + 14, j + 62, k + 9, Blocks.log, 1);
		world.setBlockMetadataWithNotify(i + 14, j + 62, k + 9, 1, 2);
		setBlock(world, i + 14, j + 62, k + 10, Blocks.log, 1);
		world.setBlockMetadataWithNotify(i + 14, j + 62, k + 10, 1, 2);
		setBlock(world, i + 14, j + 63, k + 0, Blocks.log, 1);
		world.setBlockMetadataWithNotify(i + 14, j + 63, k + 0, 1, 2);
		setBlock(world, i + 14, j + 63, k + 1, Blocks.log, 1);
		world.setBlockMetadataWithNotify(i + 14, j + 63, k + 1, 1, 2);
		setBlock(world, i + 14, j + 63, k + 2, Blocks.log, 1);
		world.setBlockMetadataWithNotify(i + 14, j + 63, k + 2, 1, 2);
		setBlock(world, i + 14, j + 63, k + 3, Blocks.log, 1);
		world.setBlockMetadataWithNotify(i + 14, j + 63, k + 3, 1, 2);
		setBlock(world, i + 14, j + 63, k + 4, Blocks.log, 1);
		world.setBlockMetadataWithNotify(i + 14, j + 63, k + 4, 1, 2);
		setBlock(world, i + 14, j + 63, k + 5, Blocks.log, 1);
		world.setBlockMetadataWithNotify(i + 14, j + 63, k + 5, 1, 2);
		setBlock(world, i + 15, j + 20, k + 30, Blocks.log, 3);
		world.setBlockMetadataWithNotify(i + 15, j + 20, k + 30, 3, 2);
		setBlock(world, i + 15, j + 20, k + 31, Blocks.log, 3);
		world.setBlockMetadataWithNotify(i + 15, j + 20, k + 31, 3, 2);
		setBlock(world, i + 15, j + 21, k + 26, Blocks.leaves, 7);
		world.setBlockMetadataWithNotify(i + 15, j + 21, k + 26, 7, 2);
		setBlock(world, i + 15, j + 21, k + 27, Blocks.leaves, 7);
		world.setBlockMetadataWithNotify(i + 15, j + 21, k + 27, 7, 2);
		setBlock(world, i + 15, j + 21, k + 28, Blocks.leaves, 7);
		world.setBlockMetadataWithNotify(i + 15, j + 21, k + 28, 7, 2);
		setBlock(world, i + 15, j + 22, k + 22, Blocks.log, 3);
		world.setBlockMetadataWithNotify(i + 15, j + 22, k + 22, 3, 2);
		setBlock(world, i + 15, j + 22, k + 27, Blocks.leaves, 7);
		world.setBlockMetadataWithNotify(i + 15, j + 22, k + 27, 7, 2);
		setBlock(world, i + 15, j + 23, k + 17, Blocks.leaves, 7);
		world.setBlockMetadataWithNotify(i + 15, j + 23, k + 17, 7, 2);
		setBlock(world, i + 15, j + 23, k + 18, Blocks.leaves, 7);
		world.setBlockMetadataWithNotify(i + 15, j + 23, k + 18, 7, 2);
		setBlock(world, i + 15, j + 23, k + 19, Blocks.leaves, 7);
		world.setBlockMetadataWithNotify(i + 15, j + 23, k + 19, 7, 2);
		setBlock(world, i + 15, j + 24, k + 18, Blocks.leaves, 7);
		world.setBlockMetadataWithNotify(i + 15, j + 24, k + 18, 7, 2);
		setBlock(world, i + 15, j + 30, k + 1, Blocks.leaves, 7);
		world.setBlockMetadataWithNotify(i + 15, j + 30, k + 1, 7, 2);
		setBlock(world, i + 15, j + 30, k + 2, Blocks.leaves, 7);
		world.setBlockMetadataWithNotify(i + 15, j + 30, k + 2, 7, 2);
		setBlock(world, i + 15, j + 30, k + 3, Blocks.leaves, 7);
		world.setBlockMetadataWithNotify(i + 15, j + 30, k + 3, 7, 2);
		setBlock(world, i + 15, j + 31, k + 2, Blocks.leaves, 7);
		world.setBlockMetadataWithNotify(i + 15, j + 31, k + 2, 7, 2);
		setBlock(world, i + 15, j + 36, k + 1, Blocks.log, 3);
		world.setBlockMetadataWithNotify(i + 15, j + 36, k + 1, 3, 2);
		setBlock(world, i + 15, j + 37, k + 1, Blocks.leaves, 7);
		world.setBlockMetadataWithNotify(i + 15, j + 37, k + 1, 7, 2);
		setBlock(world, i + 15, j + 37, k + 2, Blocks.leaves, 7);
		world.setBlockMetadataWithNotify(i + 15, j + 37, k + 2, 7, 2);
		setBlock(world, i + 15, j + 37, k + 3, Blocks.leaves, 7);
		world.setBlockMetadataWithNotify(i + 15, j + 37, k + 3, 7, 2);
		setBlock(world, i + 15, j + 37, k + 24, Blocks.leaves, 7);
		world.setBlockMetadataWithNotify(i + 15, j + 37, k + 24, 7, 2);
		setBlock(world, i + 15, j + 37, k + 25, Blocks.leaves, 7);
		world.setBlockMetadataWithNotify(i + 15, j + 37, k + 25, 7, 2);
		setBlock(world, i + 15, j + 37, k + 26, Blocks.leaves, 7);
		world.setBlockMetadataWithNotify(i + 15, j + 37, k + 26, 7, 2);
		setBlock(world, i + 15, j + 38, k + 2, Blocks.leaves, 7);
		world.setBlockMetadataWithNotify(i + 15, j + 38, k + 2, 7, 2);
		setBlock(world, i + 15, j + 38, k + 25, Blocks.leaves, 7);
		world.setBlockMetadataWithNotify(i + 15, j + 38, k + 25, 7, 2);
		setBlock(world, i + 15, j + 38, k + 29, Blocks.leaves, 7);
		world.setBlockMetadataWithNotify(i + 15, j + 38, k + 29, 7, 2);
		setBlock(world, i + 15, j + 38, k + 30, Blocks.leaves, 7);
		world.setBlockMetadataWithNotify(i + 15, j + 38, k + 30, 7, 2);
		setBlock(world, i + 15, j + 38, k + 31, Blocks.log, 3);
		world.setBlockMetadataWithNotify(i + 15, j + 38, k + 31, 3, 2);
		setBlock(world, i + 15, j + 39, k + 29, Blocks.leaves, 7);
		world.setBlockMetadataWithNotify(i + 15, j + 39, k + 29, 7, 2);
		setBlock(world, i + 15, j + 39, k + 30, Blocks.leaves, 7);
		world.setBlockMetadataWithNotify(i + 15, j + 39, k + 30, 7, 2);
		setBlock(world, i + 15, j + 39, k + 31, Blocks.leaves, 7);
		world.setBlockMetadataWithNotify(i + 15, j + 39, k + 31, 7, 2);
		setBlock(world, i + 15, j + 40, k + 30, Blocks.leaves, 7);
		world.setBlockMetadataWithNotify(i + 15, j + 40, k + 30, 7, 2);
		setBlock(world, i + 15, j + 40, k + 31, Blocks.leaves, 7);
		world.setBlockMetadataWithNotify(i + 15, j + 40, k + 31, 7, 2);
		setBlock(world, i + 15, j + 41, k + 31, Blocks.leaves, 7);
		world.setBlockMetadataWithNotify(i + 15, j + 41, k + 31, 7, 2);
		setBlock(world, i + 15, j + 42, k + 25, Blocks.leaves, 7);
		world.setBlockMetadataWithNotify(i + 15, j + 42, k + 25, 7, 2);
		setBlock(world, i + 15, j + 42, k + 26, Blocks.leaves, 7);
		world.setBlockMetadataWithNotify(i + 15, j + 42, k + 26, 7, 2);
		setBlock(world, i + 15, j + 42, k + 27, Blocks.leaves, 7);
		world.setBlockMetadataWithNotify(i + 15, j + 42, k + 27, 7, 2);
		setBlock(world, i + 15, j + 43, k + 4, Blocks.leaves, 7);
		world.setBlockMetadataWithNotify(i + 15, j + 43, k + 4, 7, 2);
		setBlock(world, i + 15, j + 43, k + 5, Blocks.leaves, 7);
		world.setBlockMetadataWithNotify(i + 15, j + 43, k + 5, 7, 2);
		setBlock(world, i + 15, j + 43, k + 6, Blocks.leaves, 7);
		world.setBlockMetadataWithNotify(i + 15, j + 43, k + 6, 7, 2);
		setBlock(world, i + 15, j + 43, k + 26, Blocks.leaves, 7);
		world.setBlockMetadataWithNotify(i + 15, j + 43, k + 26, 7, 2);
		setBlock(world, i + 15, j + 44, k + 5, Blocks.leaves, 7);
		world.setBlockMetadataWithNotify(i + 15, j + 44, k + 5, 7, 2);
		setBlock(world, i + 15, j + 46, k + 0, Blocks.leaves, 7);
		world.setBlockMetadataWithNotify(i + 15, j + 46, k + 0, 7, 2);
		setBlock(world, i + 15, j + 46, k + 30, Blocks.leaves, 7);
		world.setBlockMetadataWithNotify(i + 15, j + 46, k + 30, 7, 2);
		setBlock(world, i + 15, j + 46, k + 31, Blocks.leaves, 7);
		world.setBlockMetadataWithNotify(i + 15, j + 46, k + 31, 7, 2);
		setBlock(world, i + 15, j + 47, k + 0, Blocks.leaves, 7);
		world.setBlockMetadataWithNotify(i + 15, j + 47, k + 0, 7, 2);
		setBlock(world, i + 15, j + 47, k + 1, Blocks.leaves, 7);
		world.setBlockMetadataWithNotify(i + 15, j + 47, k + 1, 7, 2);
		setBlock(world, i + 15, j + 47, k + 31, Blocks.leaves, 7);
		world.setBlockMetadataWithNotify(i + 15, j + 47, k + 31, 7, 2);
		setBlock(world, i + 15, j + 48, k + 0, Blocks.log, 1);
		world.setBlockMetadataWithNotify(i + 15, j + 48, k + 0, 1, 2);
		setBlock(world, i + 15, j + 48, k + 1, Blocks.log, 1);
		world.setBlockMetadataWithNotify(i + 15, j + 48, k + 1, 1, 2);
		setBlock(world, i + 15, j + 49, k + 0, Blocks.log, 1);
		world.setBlockMetadataWithNotify(i + 15, j + 49, k + 0, 1, 2);
		setBlock(world, i + 15, j + 49, k + 1, Blocks.log, 1);
		world.setBlockMetadataWithNotify(i + 15, j + 49, k + 1, 1, 2);
		setBlock(world, i + 15, j + 49, k + 2, Blocks.log, 1);
		world.setBlockMetadataWithNotify(i + 15, j + 49, k + 2, 1, 2);
		setBlock(world, i + 15, j + 50, k + 0, Blocks.log, 1);
		world.setBlockMetadataWithNotify(i + 15, j + 50, k + 0, 1, 2);
		setBlock(world, i + 15, j + 50, k + 1, Blocks.log, 1);
		world.setBlockMetadataWithNotify(i + 15, j + 50, k + 1, 1, 2);
		setBlock(world, i + 15, j + 50, k + 2, Blocks.log, 1);
		world.setBlockMetadataWithNotify(i + 15, j + 50, k + 2, 1, 2);
		setBlock(world, i + 15, j + 50, k + 3, Blocks.log, 1);
		world.setBlockMetadataWithNotify(i + 15, j + 50, k + 3, 1, 2);
		setBlock(world, i + 15, j + 51, k + 0, Blocks.log, 1);
		world.setBlockMetadataWithNotify(i + 15, j + 51, k + 0, 1, 2);
		setBlock(world, i + 15, j + 51, k + 1, Blocks.log, 1);
		world.setBlockMetadataWithNotify(i + 15, j + 51, k + 1, 1, 2);
		setBlock(world, i + 15, j + 51, k + 2, Blocks.log, 1);
		world.setBlockMetadataWithNotify(i + 15, j + 51, k + 2, 1, 2);
		setBlock(world, i + 15, j + 51, k + 3, Blocks.log, 1);
		world.setBlockMetadataWithNotify(i + 15, j + 51, k + 3, 1, 2);
		setBlock(world, i + 15, j + 52, k + 0, Blocks.log, 1);
		world.setBlockMetadataWithNotify(i + 15, j + 52, k + 0, 1, 2);
		setBlock(world, i + 15, j + 52, k + 1, Blocks.log, 1);
		world.setBlockMetadataWithNotify(i + 15, j + 52, k + 1, 1, 2);
		setBlock(world, i + 15, j + 52, k + 2, Blocks.log, 1);
		world.setBlockMetadataWithNotify(i + 15, j + 52, k + 2, 1, 2);
		setBlock(world, i + 15, j + 52, k + 3, Blocks.log, 1);
		world.setBlockMetadataWithNotify(i + 15, j + 52, k + 3, 1, 2);
		setBlock(world, i + 15, j + 52, k + 4, Blocks.log, 1);
		world.setBlockMetadataWithNotify(i + 15, j + 52, k + 4, 1, 2);
		setBlock(world, i + 15, j + 52, k + 5, Blocks.log, 1);
		world.setBlockMetadataWithNotify(i + 15, j + 52, k + 5, 1, 2);
		setBlock(world, i + 15, j + 52, k + 6, Blocks.log, 1);
		world.setBlockMetadataWithNotify(i + 15, j + 52, k + 6, 1, 2);
		setBlock(world, i + 15, j + 53, k + 0, Blocks.log, 1);
		world.setBlockMetadataWithNotify(i + 15, j + 53, k + 0, 1, 2);
		setBlock(world, i + 15, j + 53, k + 1, Blocks.log, 1);
		world.setBlockMetadataWithNotify(i + 15, j + 53, k + 1, 1, 2);
		setBlock(world, i + 15, j + 53, k + 2, Blocks.log, 1);
		world.setBlockMetadataWithNotify(i + 15, j + 53, k + 2, 1, 2);
		setBlock(world, i + 15, j + 53, k + 3, Blocks.log, 1);
		world.setBlockMetadataWithNotify(i + 15, j + 53, k + 3, 1, 2);
		setBlock(world, i + 15, j + 53, k + 4, Blocks.log, 1);
		world.setBlockMetadataWithNotify(i + 15, j + 53, k + 4, 1, 2);
		setBlock(world, i + 15, j + 53, k + 5, Blocks.log, 1);
		world.setBlockMetadataWithNotify(i + 15, j + 53, k + 5, 1, 2);
		setBlock(world, i + 15, j + 53, k + 6, Blocks.log, 1);
		world.setBlockMetadataWithNotify(i + 15, j + 53, k + 6, 1, 2);
		setBlock(world, i + 15, j + 53, k + 7, Blocks.log, 1);
		world.setBlockMetadataWithNotify(i + 15, j + 53, k + 7, 1, 2);
		setBlock(world, i + 15, j + 53, k + 8, Blocks.log, 1);
		world.setBlockMetadataWithNotify(i + 15, j + 53, k + 8, 1, 2);
		setBlock(world, i + 15, j + 54, k + 0, Blocks.log, 1);
		world.setBlockMetadataWithNotify(i + 15, j + 54, k + 0, 1, 2);
		setBlock(world, i + 15, j + 54, k + 1, Blocks.log, 1);
		world.setBlockMetadataWithNotify(i + 15, j + 54, k + 1, 1, 2);
		setBlock(world, i + 15, j + 54, k + 2, Blocks.log, 1);
		world.setBlockMetadataWithNotify(i + 15, j + 54, k + 2, 1, 2);
		setBlock(world, i + 15, j + 54, k + 3, Blocks.log, 1);
		world.setBlockMetadataWithNotify(i + 15, j + 54, k + 3, 1, 2);
		setBlock(world, i + 15, j + 54, k + 4, Blocks.log, 1);
		world.setBlockMetadataWithNotify(i + 15, j + 54, k + 4, 1, 2);
		setBlock(world, i + 15, j + 54, k + 5, Blocks.log, 1);
		world.setBlockMetadataWithNotify(i + 15, j + 54, k + 5, 1, 2);
		setBlock(world, i + 15, j + 54, k + 6, Blocks.log, 1);
		world.setBlockMetadataWithNotify(i + 15, j + 54, k + 6, 1, 2);
		setBlock(world, i + 15, j + 54, k + 7, Blocks.log, 1);
		world.setBlockMetadataWithNotify(i + 15, j + 54, k + 7, 1, 2);
		setBlock(world, i + 15, j + 54, k + 8, Blocks.log, 1);
		world.setBlockMetadataWithNotify(i + 15, j + 54, k + 8, 1, 2);
		setBlock(world, i + 15, j + 55, k + 0, Blocks.log, 1);
		world.setBlockMetadataWithNotify(i + 15, j + 55, k + 0, 1, 2);
		setBlock(world, i + 15, j + 55, k + 1, Blocks.log, 1);
		world.setBlockMetadataWithNotify(i + 15, j + 55, k + 1, 1, 2);
		setBlock(world, i + 15, j + 55, k + 2, Blocks.planks, 5);
		world.setBlockMetadataWithNotify(i + 15, j + 55, k + 2, 5, 2);
		setBlock(world, i + 15, j + 55, k + 3, Blocks.log, 1);
		world.setBlockMetadataWithNotify(i + 15, j + 55, k + 3, 1, 2);
		setBlock(world, i + 15, j + 55, k + 4, Blocks.planks, 5);
		world.setBlockMetadataWithNotify(i + 15, j + 55, k + 4, 5, 2);
		setBlock(world, i + 15, j + 55, k + 5, Blocks.planks, 5);
		world.setBlockMetadataWithNotify(i + 15, j + 55, k + 5, 5, 2);
		setBlock(world, i + 15, j + 55, k + 6, Blocks.planks, 5);
		world.setBlockMetadataWithNotify(i + 15, j + 55, k + 6, 5, 2);
		setBlock(world, i + 15, j + 55, k + 7, Blocks.planks, 5);
		world.setBlockMetadataWithNotify(i + 15, j + 55, k + 7, 5, 2);
		setBlock(world, i + 15, j + 55, k + 8, Blocks.planks, 5);
		world.setBlockMetadataWithNotify(i + 15, j + 55, k + 8, 5, 2);
		setBlock(world, i + 15, j + 55, k + 9, Blocks.planks, 5);
		world.setBlockMetadataWithNotify(i + 15, j + 55, k + 9, 5, 2);
		setBlock(world, i + 15, j + 55, k + 10, Blocks.log, 1);
		world.setBlockMetadataWithNotify(i + 15, j + 55, k + 10, 1, 2);
		setBlock(world, i + 15, j + 55, k + 11, Blocks.log, 1);
		world.setBlockMetadataWithNotify(i + 15, j + 55, k + 11, 1, 2);
		setBlock(world, i + 15, j + 55, k + 12, Blocks.planks, 5);
		world.setBlockMetadataWithNotify(i + 15, j + 55, k + 12, 5, 2);
		setBlock(world, i + 15, j + 55, k + 13, Blocks.planks, 5);
		world.setBlockMetadataWithNotify(i + 15, j + 55, k + 13, 5, 2);
		setBlock(world, i + 15, j + 55, k + 14, Blocks.planks, 5);
		world.setBlockMetadataWithNotify(i + 15, j + 55, k + 14, 5, 2);
		setBlock(world, i + 15, j + 55, k + 15, Blocks.planks, 5);
		world.setBlockMetadataWithNotify(i + 15, j + 55, k + 15, 5, 2);
		setBlock(world, i + 15, j + 55, k + 16, Blocks.planks, 5);
		world.setBlockMetadataWithNotify(i + 15, j + 55, k + 16, 5, 2);
		setBlock(world, i + 15, j + 55, k + 17, Blocks.planks, 5);
		world.setBlockMetadataWithNotify(i + 15, j + 55, k + 17, 5, 2);
		setBlock(world, i + 15, j + 56, k + 0, Blocks.log, 1);
		world.setBlockMetadataWithNotify(i + 15, j + 56, k + 0, 1, 2);
		setBlock(world, i + 15, j + 56, k + 1, Blocks.spruce_stairs, 3);
		world.setBlockMetadataWithNotify(i + 15, j + 56, k + 1, 3, 2);
		setBlock(world, i + 15, j + 57, k + 0, Blocks.log, 1);
		world.setBlockMetadataWithNotify(i + 15, j + 57, k + 0, 1, 2);
		setBlock(world, i + 15, j + 58, k + 0, Blocks.log, 1);
		world.setBlockMetadataWithNotify(i + 15, j + 58, k + 0, 1, 2);
		setBlock(world, i + 15, j + 59, k + 0, Blocks.log, 1);
		world.setBlockMetadataWithNotify(i + 15, j + 59, k + 0, 1, 2);
		setBlock(world, i + 15, j + 59, k + 1, Blocks.torch, 3);
		world.setBlockMetadataWithNotify(i + 15, j + 59, k + 1, 3, 2);
		setBlock(world, i + 15, j + 60, k + 0, Blocks.log, 1);
		world.setBlockMetadataWithNotify(i + 15, j + 60, k + 0, 1, 2);
		setBlock(world, i + 15, j + 60, k + 9, Blocks.log, 1);
		world.setBlockMetadataWithNotify(i + 15, j + 60, k + 9, 1, 2);
		setBlock(world, i + 15, j + 60, k + 10, Blocks.log, 1);
		world.setBlockMetadataWithNotify(i + 15, j + 60, k + 10, 1, 2);
		setBlock(world, i + 15, j + 60, k + 11, Blocks.log, 1);
		world.setBlockMetadataWithNotify(i + 15, j + 60, k + 11, 1, 2);
		setBlock(world, i + 15, j + 60, k + 12, Blocks.log, 1);
		world.setBlockMetadataWithNotify(i + 15, j + 60, k + 12, 1, 2);
		setBlock(world, i + 15, j + 60, k + 13, Blocks.log, 1);
		world.setBlockMetadataWithNotify(i + 15, j + 60, k + 13, 1, 2);
		setBlock(world, i + 15, j + 61, k + 0, Blocks.log, 1);
		world.setBlockMetadataWithNotify(i + 15, j + 61, k + 0, 1, 2);
		setBlock(world, i + 15, j + 61, k + 8, Blocks.log, 1);
		world.setBlockMetadataWithNotify(i + 15, j + 61, k + 8, 1, 2);
		setBlock(world, i + 15, j + 61, k + 9, Blocks.log, 1);
		world.setBlockMetadataWithNotify(i + 15, j + 61, k + 9, 1, 2);
		setBlock(world, i + 15, j + 61, k + 10, Blocks.log, 1);
		world.setBlockMetadataWithNotify(i + 15, j + 61, k + 10, 1, 2);
		setBlock(world, i + 15, j + 61, k + 11, Blocks.log, 1);
		world.setBlockMetadataWithNotify(i + 15, j + 61, k + 11, 1, 2);
		setBlock(world, i + 15, j + 61, k + 12, Blocks.log, 1);
		world.setBlockMetadataWithNotify(i + 15, j + 61, k + 12, 1, 2);
		setBlock(world, i + 15, j + 62, k + 0, Blocks.log, 1);
		world.setBlockMetadataWithNotify(i + 15, j + 62, k + 0, 1, 2);
		setBlock(world, i + 15, j + 62, k + 1, Blocks.log, 1);
		world.setBlockMetadataWithNotify(i + 15, j + 62, k + 1, 1, 2);
		setBlock(world, i + 15, j + 62, k + 7, Blocks.log, 1);
		world.setBlockMetadataWithNotify(i + 15, j + 62, k + 7, 1, 2);
		setBlock(world, i + 15, j + 62, k + 8, Blocks.log, 1);
		world.setBlockMetadataWithNotify(i + 15, j + 62, k + 8, 1, 2);
		setBlock(world, i + 15, j + 62, k + 9, Blocks.log, 1);
		world.setBlockMetadataWithNotify(i + 15, j + 62, k + 9, 1, 2);
		setBlock(world, i + 15, j + 62, k + 10, Blocks.log, 1);
		world.setBlockMetadataWithNotify(i + 15, j + 62, k + 10, 1, 2);
		setBlock(world, i + 15, j + 63, k + 0, Blocks.log, 1);
		world.setBlockMetadataWithNotify(i + 15, j + 63, k + 0, 1, 2);
		setBlock(world, i + 15, j + 63, k + 1, Blocks.log, 1);
		world.setBlockMetadataWithNotify(i + 15, j + 63, k + 1, 1, 2);
		setBlock(world, i + 15, j + 63, k + 2, Blocks.log, 1);
		world.setBlockMetadataWithNotify(i + 15, j + 63, k + 2, 1, 2);
		setBlock(world, i + 15, j + 63, k + 3, Blocks.log, 1);
		world.setBlockMetadataWithNotify(i + 15, j + 63, k + 3, 1, 2);
		setBlock(world, i + 15, j + 63, k + 4, Blocks.log, 1);
		world.setBlockMetadataWithNotify(i + 15, j + 63, k + 4, 1, 2);
		setBlock(world, i + 15, j + 63, k + 5, Blocks.log, 1);
		world.setBlockMetadataWithNotify(i + 15, j + 63, k + 5, 1, 2);
		setBlock(world, i + 15, j + 63, k + 6, Blocks.log, 1);
		world.setBlockMetadataWithNotify(i + 15, j + 63, k + 6, 1, 2);
		setBlock(world, i + 16, j + 21, k + 24, Blocks.log, 3);
