package com.parzivail.pswm.world.gen.wookietree;




import com.parzivail.pswm.utils.LootGenUtils;
import com.parzivail.pswm.utils.NPCType;
import com.parzivail.pswm.utils.SpawnUtils;



import cpw.mods.fml.common.IWorldGenerator;



import java.util.Random;



import net.minecraft.block.Block;

import net.minecraft.init.Blocks;

import net.minecraft.tileentity.TileEntityChest;

import net.minecraft.world.World;

import net.minecraft.world.WorldProvider;

import net.minecraft.world.chunk.IChunkProvider;

import net.minecraft.world.gen.feature.WorldGenerator;


public class WT_00
extends WorldGenerator implements IWorldGenerator

{
	protected Block[] getValidSpawnBlocks()
	
	{
		return new Block[0];
		}

	
	public boolean locationIsValidSpawn(World world, int i, int j, int k)
	
	{
		int distanceToAir = 0;
		Block check = world.getBlock(i, j, k);
		
		while (check != Blocks.air)
		{
			if (distanceToAir > 3) { return false;
			}
			
			distanceToAir++;
			check = world.getBlock(i, j + distanceToAir, k);
			}
		
		j += distanceToAir - 1;
		
		Block block = world.getBlock(i, j, k);
		Block blockAbove = world.getBlock(i, j + 1, k);
		Block blockBelow = world.getBlock(i, j - 1, k);
		
		for (Block x : getValidSpawnBlocks())
		{
			if (blockAbove != Blocks.air) { return false;
			}
			if (block == x) return true;
			if ((block == Blocks.snow) && (blockBelow == x)) { return true;
			}
			}
		
		return false;
		}

	
	
	
	public void generate(Random random, int chunkX, int chunkZ, World world, IChunkProvider chunkGenerator, IChunkProvider chunkProvider)
	{
	}

	
	
	public void setBlock(World world, int x, int y, int z, Block block, int metadata)
	
	{
		world.setBlock(x, y, z, block, metadata, 2);
		}

	
	public boolean generate(World world, Random rand, int i, int j, int k)
	
	{
		k -= 10;
		i -= 10;
		
		setBlock(world, i + 7, j + 59, k + 27, Blocks.fence, 0);
		setBlock(world, i + 8, j + 59, k + 24, Blocks.fence, 0);
		setBlock(world, i + 8, j + 59, k + 25, Blocks.fence, 0);
		setBlock(world, i + 8, j + 59, k + 26, Blocks.fence, 0);
		setBlock(world, i + 8, j + 59, k + 27, Blocks.fence, 0);
		setBlock(world, i + 9, j + 59, k + 22, Blocks.fence, 0);
		setBlock(world, i + 9, j + 59, k + 23, Blocks.fence, 0);
		setBlock(world, i + 9, j + 59, k + 24, Blocks.fence, 0);
		setBlock(world, i + 10, j + 56, k + 25, Blocks.fence, 0);
		setBlock(world, i + 10, j + 56, k + 26, Blocks.fence, 0);
		setBlock(world, i + 10, j + 56, k + 27, Blocks.fence, 0);
		setBlock(world, i + 10, j + 59, k + 21, Blocks.fence, 0);
		setBlock(world, i + 10, j + 59, k + 22, Blocks.fence, 0);
		setBlock(world, i + 11, j + 56, k + 23, Blocks.fence, 0);
		setBlock(world, i + 11, j + 56, k + 24, Blocks.fence, 0);
		setBlock(world, i + 11, j + 56, k + 25, Blocks.fence, 0);
		setBlock(world, i + 11, j + 59, k + 20, Blocks.fence, 0);
		setBlock(world, i + 11, j + 59, k + 21, Blocks.fence, 0);
		SpawnUtils.spawnNPC(NPCType.WOOKIETREE, world, i + 12, j + 56, k + 29);
		setBlock(world, i + 14, j + 56, k + 31, Blocks.spruce_stairs, 0);
		setBlock(world, i + 18, j + 56, k + 22, Blocks.spruce_stairs, 0);
		SpawnUtils.spawnNPC(NPCType.WOOKIETREE, world, i + 19, j + 56, k + 29);
		setBlock(world, i + 20, j + 56, k + 23, Blocks.fence, 0);
		setBlock(world, i + 20, j + 56, k + 24, Blocks.fence, 0);
		setBlock(world, i + 20, j + 56, k + 25, Blocks.fence, 0);
		setBlock(world, i + 20, j + 59, k + 20, Blocks.fence, 0);
		setBlock(world, i + 20, j + 59, k + 21, Blocks.fence, 0);
		setBlock(world, i + 21, j + 56, k + 25, Blocks.fence, 0);
		setBlock(world, i + 21, j + 56, k + 26, Blocks.fence, 0);
		setBlock(world, i + 21, j + 56, k + 27, Blocks.fence, 0);
		setBlock(world, i + 21, j + 56, k + 28, Blocks.spruce_stairs, 0);
		setBlock(world, i + 21, j + 59, k + 21, Blocks.fence, 0);
		setBlock(world, i + 21, j + 59, k + 22, Blocks.fence, 0);
		setBlock(world, i + 22, j + 59, k + 22, Blocks.fence, 0);
		setBlock(world, i + 22, j + 59, k + 23, Blocks.fence, 0);
		setBlock(world, i + 22, j + 59, k + 24, Blocks.fence, 0);
		setBlock(world, i + 23, j + 59, k + 24, Blocks.fence, 0);
		setBlock(world, i + 23, j + 59, k + 25, Blocks.fence, 0);
		setBlock(world, i + 23, j + 59, k + 26, Blocks.fence, 0);
		setBlock(world, i + 23, j + 59, k + 27, Blocks.fence, 0);
		setBlock(world, i + 24, j + 59, k + 27, Blocks.fence, 0);
		setBlock(world, i + 30, j + 27, k + 31, Blocks.spruce_stairs, 0);
		setBlock(world, i + 30, j + 29, k + 29, Blocks.fence, 0);
		setBlock(world, i + 30, j + 29, k + 30, Blocks.fence, 0);
		setBlock(world, i + 4, j + 27, k + 29, Blocks.leaves, 7);
		world.setBlockMetadataWithNotify(i + 4, j + 27, k + 29, 7, 2);
		setBlock(world, i + 4, j + 27, k + 30, Blocks.leaves, 7);
		world.setBlockMetadataWithNotify(i + 4, j + 27, k + 30, 7, 2);
		setBlock(world, i + 4, j + 27, k + 31, Blocks.leaves, 7);
		world.setBlockMetadataWithNotify(i + 4, j + 27, k + 31, 7, 2);
		setBlock(world, i + 4, j + 28, k + 30, Blocks.leaves, 7);
		world.setBlockMetadataWithNotify(i + 4, j + 28, k + 30, 7, 2);
		setBlock(world, i + 4, j + 34, k + 14, Blocks.leaves, 7);
		world.setBlockMetadataWithNotify(i + 4, j + 34, k + 14, 7, 2);
		setBlock(world, i + 4, j + 34, k + 15, Blocks.leaves, 7);
		world.setBlockMetadataWithNotify(i + 4, j + 34, k + 15, 7, 2);
		setBlock(world, i + 4, j + 34, k + 16, Blocks.leaves, 7);
		world.setBlockMetadataWithNotify(i + 4, j + 34, k + 16, 7, 2);
		setBlock(world, i + 4, j + 35, k + 15, Blocks.leaves, 7);
		world.setBlockMetadataWithNotify(i + 4, j + 35, k + 15, 7, 2);
		setBlock(world, i + 5, j + 24, k + 23, Blocks.leaves, 7);
		world.setBlockMetadataWithNotify(i + 5, j + 24, k + 23, 7, 2);
		setBlock(world, i + 5, j + 24, k + 24, Blocks.leaves, 7);
		world.setBlockMetadataWithNotify(i + 5, j + 24, k + 24, 7, 2);
		setBlock(world, i + 5, j + 24, k + 25, Blocks.leaves, 7);
		world.setBlockMetadataWithNotify(i + 5, j + 24, k + 25, 7, 2);
		setBlock(world, i + 5, j + 25, k + 24, Blocks.leaves, 7);
		world.setBlockMetadataWithNotify(i + 5, j + 25, k + 24, 7, 2);
		setBlock(world, i + 5, j + 27, k + 28, Blocks.leaves, 7);
		world.setBlockMetadataWithNotify(i + 5, j + 27, k + 28, 7, 2);
		setBlock(world, i + 5, j + 27, k + 29, Blocks.leaves, 7);
		world.setBlockMetadataWithNotify(i + 5, j + 27, k + 29, 7, 2);
		setBlock(world, i + 5, j + 27, k + 30, Blocks.leaves, 7);
		world.setBlockMetadataWithNotify(i + 5, j + 27, k + 30, 7, 2);
		setBlock(world, i + 5, j + 27, k + 31, Blocks.leaves, 7);
		world.setBlockMetadataWithNotify(i + 5, j + 27, k + 31, 7, 2);
		setBlock(world, i + 5, j + 28, k + 29, Blocks.leaves, 7);
		world.setBlockMetadataWithNotify(i + 5, j + 28, k + 29, 7, 2);
		setBlock(world, i + 5, j + 28, k + 30, Blocks.leaves, 7);
		world.setBlockMetadataWithNotify(i + 5, j + 28, k + 30, 7, 2);
		setBlock(world, i + 5, j + 28, k + 31, Blocks.leaves, 7);
		world.setBlockMetadataWithNotify(i + 5, j + 28, k + 31, 7, 2);
		setBlock(world, i + 5, j + 29, k + 30, Blocks.leaves, 7);
		world.setBlockMetadataWithNotify(i + 5, j + 29, k + 30, 7, 2);
		setBlock(world, i + 5, j + 34, k + 13, Blocks.leaves, 7);
		world.setBlockMetadataWithNotify(i + 5, j + 34, k + 13, 7, 2);
		setBlock(world, i + 5, j + 34, k + 14, Blocks.leaves, 7);
		world.setBlockMetadataWithNotify(i + 5, j + 34, k + 14, 7, 2);
		setBlock(world, i + 5, j + 34, k + 15, Blocks.leaves, 7);
		world.setBlockMetadataWithNotify(i + 5, j + 34, k + 15, 7, 2);
		setBlock(world, i + 5, j + 34, k + 16, Blocks.leaves, 7);
		world.setBlockMetadataWithNotify(i + 5, j + 34, k + 16, 7, 2);
		setBlock(world, i + 5, j + 34, k + 17, Blocks.leaves, 7);
		world.setBlockMetadataWithNotify(i + 5, j + 34, k + 17, 7, 2);
		setBlock(world, i + 5, j + 35, k + 14, Blocks.leaves, 7);
		world.setBlockMetadataWithNotify(i + 5, j + 35, k + 14, 7, 2);
		setBlock(world, i + 5, j + 35, k + 15, Blocks.leaves, 7);
		world.setBlockMetadataWithNotify(i + 5, j + 35, k + 15, 7, 2);
		setBlock(world, i + 5, j + 35, k + 16, Blocks.leaves, 7);
		world.setBlockMetadataWithNotify(i + 5, j + 35, k + 16, 7, 2);
		setBlock(world, i + 5, j + 35, k + 22, Blocks.leaves, 7);
		world.setBlockMetadataWithNotify(i + 5, j + 35, k + 22, 7, 2);
		setBlock(world, i + 5, j + 35, k + 23, Blocks.leaves, 7);
		world.setBlockMetadataWithNotify(i + 5, j + 35, k + 23, 7, 2);
		setBlock(world, i + 5, j + 35, k + 24, Blocks.leaves, 7);
		world.setBlockMetadataWithNotify(i + 5, j + 35, k + 24, 7, 2);
		setBlock(world, i + 5, j + 36, k + 14, Blocks.leaves, 7);
		world.setBlockMetadataWithNotify(i + 5, j + 36, k + 14, 7, 2);
		setBlock(world, i + 5, j + 36, k + 15, Blocks.leaves, 7);
		world.setBlockMetadataWithNotify(i + 5, j + 36, k + 15, 7, 2);
		setBlock(world, i + 5, j + 36, k + 16, Blocks.leaves, 7);
		world.setBlockMetadataWithNotify(i + 5, j + 36, k + 16, 7, 2);
		setBlock(world, i + 5, j + 36, k + 23, Blocks.leaves, 7);
		world.setBlockMetadataWithNotify(i + 5, j + 36, k + 23, 7, 2);
		setBlock(world, i + 5, j + 37, k + 15, Blocks.leaves, 7);
		world.setBlockMetadataWithNotify(i + 5, j + 37, k + 15, 7, 2);
		setBlock(world, i + 6, j + 24, k + 22, Blocks.leaves, 7);
		world.setBlockMetadataWithNotify(i + 6, j + 24, k + 22, 7, 2);
		setBlock(world, i + 6, j + 24, k + 23, Blocks.leaves, 7);
		world.setBlockMetadataWithNotify(i + 6, j + 24, k + 23, 7, 2);
		setBlock(world, i + 6, j + 24, k + 24, Blocks.leaves, 7);
		world.setBlockMetadataWithNotify(i + 6, j + 24, k + 24, 7, 2);
		setBlock(world, i + 6, j + 24, k + 25, Blocks.leaves, 7);
		world.setBlockMetadataWithNotify(i + 6, j + 24, k + 25, 7, 2);
		setBlock(world, i + 6, j + 24, k + 26, Blocks.leaves, 7);
		world.setBlockMetadataWithNotify(i + 6, j + 24, k + 26, 7, 2);
		setBlock(world, i + 6, j + 25, k + 23, Blocks.leaves, 7);
		world.setBlockMetadataWithNotify(i + 6, j + 25, k + 23, 7, 2);
		setBlock(world, i + 6, j + 25, k + 24, Blocks.leaves, 7);
		world.setBlockMetadataWithNotify(i + 6, j + 25, k + 24, 7, 2);
		setBlock(world, i + 6, j + 25, k + 25, Blocks.leaves, 7);
		world.setBlockMetadataWithNotify(i + 6, j + 25, k + 25, 7, 2);
		setBlock(world, i + 6, j + 26, k + 24, Blocks.leaves, 7);
		world.setBlockMetadataWithNotify(i + 6, j + 26, k + 24, 7, 2);
		setBlock(world, i + 6, j + 27, k + 28, Blocks.leaves, 7);
		world.setBlockMetadataWithNotify(i + 6, j + 27, k + 28, 7, 2);
		setBlock(world, i + 6, j + 27, k + 29, Blocks.leaves, 7);
		world.setBlockMetadataWithNotify(i + 6, j + 27, k + 29, 7, 2);
		setBlock(world, i + 6, j + 27, k + 30, Blocks.log, 3);
		world.setBlockMetadataWithNotify(i + 6, j + 27, k + 30, 3, 2);
		setBlock(world, i + 6, j + 27, k + 31, Blocks.leaves, 7);
		world.setBlockMetadataWithNotify(i + 6, j + 27, k + 31, 7, 2);
		setBlock(world, i + 6, j + 28, k + 28, Blocks.leaves, 7);
		world.setBlockMetadataWithNotify(i + 6, j + 28, k + 28, 7, 2);
		setBlock(world, i + 6, j + 28, k + 29, Blocks.leaves, 7);
		world.setBlockMetadataWithNotify(i + 6, j + 28, k + 29, 7, 2);
		setBlock(world, i + 6, j + 28, k + 30, Blocks.leaves, 7);
		world.setBlockMetadataWithNotify(i + 6, j + 28, k + 30, 7, 2);
		setBlock(world, i + 6, j + 28, k + 31, Blocks.leaves, 7);
		world.setBlockMetadataWithNotify(i + 6, j + 28, k + 31, 7, 2);
		setBlock(world, i + 6, j + 29, k + 29, Blocks.leaves, 7);
		world.setBlockMetadataWithNotify(i + 6, j + 29, k + 29, 7, 2);
		setBlock(world, i + 6, j + 29, k + 30, Blocks.leaves, 7);
		world.setBlockMetadataWithNotify(i + 6, j + 29, k + 30, 7, 2);
		setBlock(world, i + 6, j + 29, k + 31, Blocks.leaves, 7);
		world.setBlockMetadataWithNotify(i + 6, j + 29, k + 31, 7, 2);
		setBlock(world, i + 6, j + 30, k + 30, Blocks.leaves, 7);
		world.setBlockMetadataWithNotify(i + 6, j + 30, k + 30, 7, 2);
		setBlock(world, i + 6, j + 34, k + 13, Blocks.leaves, 7);
		world.setBlockMetadataWithNotify(i + 6, j + 34, k + 13, 7, 2);
		setBlock(world, i + 6, j + 34, k + 14, Blocks.leaves, 7);
		world.setBlockMetadataWithNotify(i + 6, j + 34, k + 14, 7, 2);
		setBlock(world, i + 6, j + 34, k + 15, Blocks.log, 3);
		world.setBlockMetadataWithNotify(i + 6, j + 34, k + 15, 3, 2);
		setBlock(world, i + 6, j + 34, k + 16, Blocks.leaves, 7);
		world.setBlockMetadataWithNotify(i + 6, j + 34, k + 16, 7, 2);
		setBlock(world, i + 6, j + 34, k + 17, Blocks.leaves, 7);
		world.setBlockMetadataWithNotify(i + 6, j + 34, k + 17, 7, 2);
		setBlock(world, i + 6, j + 35, k + 13, Blocks.leaves, 7);
		world.setBlockMetadataWithNotify(i + 6, j + 35, k + 13, 7, 2);
		setBlock(world, i + 6, j + 35, k + 14, Blocks.leaves, 7);
		world.setBlockMetadataWithNotify(i + 6, j + 35, k + 14, 7, 2);
		setBlock(world, i + 6, j + 35, k + 15, Blocks.leaves, 7);
		world.setBlockMetadataWithNotify(i + 6, j + 35, k + 15, 7, 2);
		setBlock(world, i + 6, j + 35, k + 16, Blocks.leaves, 7);
		world.setBlockMetadataWithNotify(i + 6, j + 35, k + 16, 7, 2);
		setBlock(world, i + 6, j + 35, k + 17, Blocks.leaves, 7);
		world.setBlockMetadataWithNotify(i + 6, j + 35, k + 17, 7, 2);
		setBlock(world, i + 6, j + 35, k + 21, Blocks.leaves, 7);
		world.setBlockMetadataWithNotify(i + 6, j + 35, k + 21, 7, 2);
		setBlock(world, i + 6, j + 35, k + 22, Blocks.leaves, 7);
		world.setBlockMetadataWithNotify(i + 6, j + 35, k + 22, 7, 2);
		setBlock(world, i + 6, j + 35, k + 23, Blocks.leaves, 7);
		world.setBlockMetadataWithNotify(i + 6, j + 35, k + 23, 7, 2);
		setBlock(world, i + 6, j + 35, k + 24, Blocks.leaves, 7);
		world.setBlockMetadataWithNotify(i + 6, j + 35, k + 24, 7, 2);
		setBlock(world, i + 6, j + 35, k + 25, Blocks.leaves, 7);
		world.setBlockMetadataWithNotify(i + 6, j + 35, k + 25, 7, 2);
		setBlock(world, i + 6, j + 35, k + 27, Blocks.leaves, 7);
		world.setBlockMetadataWithNotify(i + 6, j + 35, k + 27, 7, 2);
		setBlock(world, i + 6, j + 35, k + 28, Blocks.leaves, 7);
		world.setBlockMetadataWithNotify(i + 6, j + 35, k + 28, 7, 2);
		setBlock(world, i + 6, j + 35, k + 29, Blocks.leaves, 7);
		world.setBlockMetadataWithNotify(i + 6, j + 35, k + 29, 7, 2);
		setBlock(world, i + 6, j + 36, k + 13, Blocks.leaves, 7);
		world.setBlockMetadataWithNotify(i + 6, j + 36, k + 13, 7, 2);
		setBlock(world, i + 6, j + 36, k + 14, Blocks.leaves, 7);
		world.setBlockMetadataWithNotify(i + 6, j + 36, k + 14, 7, 2);
		setBlock(world, i + 6, j + 36, k + 15, Blocks.leaves, 7);
		world.setBlockMetadataWithNotify(i + 6, j + 36, k + 15, 7, 2);
		setBlock(world, i + 6, j + 36, k + 16, Blocks.leaves, 7);
		world.setBlockMetadataWithNotify(i + 6, j + 36, k + 16, 7, 2);
		setBlock(world, i + 6, j + 36, k + 17, Blocks.leaves, 7);
		world.setBlockMetadataWithNotify(i + 6, j + 36, k + 17, 7, 2);
		setBlock(world, i + 6, j + 36, k + 22, Blocks.leaves, 7);
		world.setBlockMetadataWithNotify(i + 6, j + 36, k + 22, 7, 2);
		setBlock(world, i + 6, j + 36, k + 23, Blocks.leaves, 7);
		world.setBlockMetadataWithNotify(i + 6, j + 36, k + 23, 7, 2);
		setBlock(world, i + 6, j + 36, k + 24, Blocks.leaves, 7);
		world.setBlockMetadataWithNotify(i + 6, j + 36, k + 24, 7, 2);
		setBlock(world, i + 6, j + 36, k + 28, Blocks.leaves, 7);
		world.setBlockMetadataWithNotify(i + 6, j + 36, k + 28, 7, 2);
		setBlock(world, i + 6, j + 37, k + 14, Blocks.leaves, 7);
		world.setBlockMetadataWithNotify(i + 6, j + 37, k + 14, 7, 2);
		setBlock(world, i + 6, j + 37, k + 15, Blocks.leaves, 7);
		world.setBlockMetadataWithNotify(i + 6, j + 37, k + 15, 7, 2);
		setBlock(world, i + 6, j + 37, k + 16, Blocks.leaves, 7);
		world.setBlockMetadataWithNotify(i + 6, j + 37, k + 16, 7, 2);
		setBlock(world, i + 6, j + 37, k + 23, Blocks.leaves, 7);
		world.setBlockMetadataWithNotify(i + 6, j + 37, k + 23, 7, 2);
		setBlock(world, i + 6, j + 38, k + 15, Blocks.leaves, 7);
		world.setBlockMetadataWithNotify(i + 6, j + 38, k + 15, 7, 2);
		setBlock(world, i + 6, j + 41, k + 25, Blocks.leaves, 7);
		world.setBlockMetadataWithNotify(i + 6, j + 41, k + 25, 7, 2);
		setBlock(world, i + 6, j + 41, k + 26, Blocks.leaves, 7);
		world.setBlockMetadataWithNotify(i + 6, j + 41, k + 26, 7, 2);
		setBlock(world, i + 6, j + 41, k + 27, Blocks.leaves, 7);
		world.setBlockMetadataWithNotify(i + 6, j + 41, k + 27, 7, 2);
		setBlock(world, i + 6, j + 42, k + 26, Blocks.leaves, 7);
		world.setBlockMetadataWithNotify(i + 6, j + 42, k + 26, 7, 2);
		setBlock(world, i + 7, j + 24, k + 22, Blocks.leaves, 7);
		world.setBlockMetadataWithNotify(i + 7, j + 24, k + 22, 7, 2);
		setBlock(world, i + 7, j + 24, k + 23, Blocks.leaves, 7);
		world.setBlockMetadataWithNotify(i + 7, j + 24, k + 23, 7, 2);
		setBlock(world, i + 7, j + 24, k + 24, Blocks.log, 3);
		world.setBlockMetadataWithNotify(i + 7, j + 24, k + 24, 3, 2);
		setBlock(world, i + 7, j + 24, k + 25, Blocks.leaves, 7);
		world.setBlockMetadataWithNotify(i + 7, j + 24, k + 25, 7, 2);
		setBlock(world, i + 7, j + 24, k + 26, Blocks.leaves, 7);
		world.setBlockMetadataWithNotify(i + 7, j + 24, k + 26, 7, 2);
		setBlock(world, i + 7, j + 25, k + 22, Blocks.leaves, 7);
		world.setBlockMetadataWithNotify(i + 7, j + 25, k + 22, 7, 2);
		setBlock(world, i + 7, j + 25, k + 23, Blocks.leaves, 7);
		world.setBlockMetadataWithNotify(i + 7, j + 25, k + 23, 7, 2);
		setBlock(world, i + 7, j + 25, k + 24, Blocks.leaves, 7);
		world.setBlockMetadataWithNotify(i + 7, j + 25, k + 24, 7, 2);
		setBlock(world, i + 7, j + 25, k + 25, Blocks.leaves, 7);
		world.setBlockMetadataWithNotify(i + 7, j + 25, k + 25, 7, 2);
		setBlock(world, i + 7, j + 25, k + 26, Blocks.leaves, 7);
		world.setBlockMetadataWithNotify(i + 7, j + 25, k + 26, 7, 2);
		setBlock(world, i + 7, j + 26, k + 23, Blocks.leaves, 7);
		world.setBlockMetadataWithNotify(i + 7, j + 26, k + 23, 7, 2);
		setBlock(world, i + 7, j + 26, k + 24, Blocks.leaves, 7);
		world.setBlockMetadataWithNotify(i + 7, j + 26, k + 24, 7, 2);
		setBlock(world, i + 7, j + 26, k + 25, Blocks.leaves, 7);
		world.setBlockMetadataWithNotify(i + 7, j + 26, k + 25, 7, 2);
		setBlock(world, i + 7, j + 26, k + 30, Blocks.log, 3);
		world.setBlockMetadataWithNotify(i + 7, j + 26, k + 30, 3, 2);
		setBlock(world, i + 7, j + 27, k + 24, Blocks.leaves, 7);
		world.setBlockMetadataWithNotify(i + 7, j + 27, k + 24, 7, 2);
		setBlock(world, i + 7, j + 27, k + 28, Blocks.leaves, 7);
		world.setBlockMetadataWithNotify(i + 7, j + 27, k + 28, 7, 2);
		setBlock(world, i + 7, j + 27, k + 29, Blocks.leaves, 7);
		world.setBlockMetadataWithNotify(i + 7, j + 27, k + 29, 7, 2);
		setBlock(world, i + 7, j + 27, k + 30, Blocks.leaves, 7);
		world.setBlockMetadataWithNotify(i + 7, j + 27, k + 30, 7, 2);
		setBlock(world, i + 7, j + 27, k + 31, Blocks.leaves, 7);
		world.setBlockMetadataWithNotify(i + 7, j + 27, k + 31, 7, 2);
		setBlock(world, i + 7, j + 28, k + 29, Blocks.leaves, 7);
		world.setBlockMetadataWithNotify(i + 7, j + 28, k + 29, 7, 2);
		setBlock(world, i + 7, j + 28, k + 30, Blocks.leaves, 7);
		world.setBlockMetadataWithNotify(i + 7, j + 28, k + 30, 7, 2);
		setBlock(world, i + 7, j + 28, k + 31, Blocks.leaves, 7);
		world.setBlockMetadataWithNotify(i + 7, j + 28, k + 31, 7, 2);
		setBlock(world, i + 7, j + 29, k + 30, Blocks.leaves, 7);
		world.setBlockMetadataWithNotify(i + 7, j + 29, k + 30, 7, 2);
		setBlock(world, i + 7, j + 33, k + 16, Blocks.log, 3);
		world.setBlockMetadataWithNotify(i + 7, j + 33, k + 16, 3, 2);
		setBlock(world, i + 7, j + 34, k + 13, Blocks.leaves, 7);
		world.setBlockMetadataWithNotify(i + 7, j + 34, k + 13, 7, 2);
		setBlock(world, i + 7, j + 34, k + 14, Blocks.leaves, 7);
		world.setBlockMetadataWithNotify(i + 7, j + 34, k + 14, 7, 2);
		setBlock(world, i + 7, j + 34, k + 15, Blocks.leaves, 7);
		world.setBlockMetadataWithNotify(i + 7, j + 34, k + 15, 7, 2);
		setBlock(world, i + 7, j + 34, k + 16, Blocks.leaves, 7);
		world.setBlockMetadataWithNotify(i + 7, j + 34, k + 16, 7, 2);
		setBlock(world, i + 7, j + 34, k + 17, Blocks.leaves, 7);
		world.setBlockMetadataWithNotify(i + 7, j + 34, k + 17, 7, 2);
		setBlock(world, i + 7, j + 35, k + 14, Blocks.leaves, 7);
		world.setBlockMetadataWithNotify(i + 7, j + 35, k + 14, 7, 2);
		setBlock(world, i + 7, j + 35, k + 15, Blocks.leaves, 7);
		world.setBlockMetadataWithNotify(i + 7, j + 35, k + 15, 7, 2);
		setBlock(world, i + 7, j + 35, k + 16, Blocks.leaves, 7);
		world.setBlockMetadataWithNotify(i + 7, j + 35, k + 16, 7, 2);
		setBlock(world, i + 7, j + 35, k + 21, Blocks.leaves, 7);
		world.setBlockMetadataWithNotify(i + 7, j + 35, k + 21, 7, 2);
		setBlock(world, i + 7, j + 35, k + 22, Blocks.leaves, 7);
		world.setBlockMetadataWithNotify(i + 7, j + 35, k + 22, 7, 2);
		setBlock(world, i + 7, j + 35, k + 23, Blocks.log, 3);
		world.setBlockMetadataWithNotify(i + 7, j + 35, k + 23, 3, 2);
		setBlock(world, i + 7, j + 35, k + 24, Blocks.leaves, 7);
		world.setBlockMetadataWithNotify(i + 7, j + 35, k + 24, 7, 2);
		setBlock(world, i + 7, j + 35, k + 25, Blocks.leaves, 7);
		world.setBlockMetadataWithNotify(i + 7, j + 35, k + 25, 7, 2);
		setBlock(world, i + 7, j + 35, k + 26, Blocks.leaves, 7);
		world.setBlockMetadataWithNotify(i + 7, j + 35, k + 26, 7, 2);
		setBlock(world, i + 7, j + 35, k + 27, Blocks.leaves, 7);
		world.setBlockMetadataWithNotify(i + 7, j + 35, k + 27, 7, 2);
		setBlock(world, i + 7, j + 35, k + 28, Blocks.leaves, 7);
		world.setBlockMetadataWithNotify(i + 7, j + 35, k + 28, 7, 2);
		setBlock(world, i + 7, j + 35, k + 29, Blocks.leaves, 7);
		world.setBlockMetadataWithNotify(i + 7, j + 35, k + 29, 7, 2);
		setBlock(world, i + 7, j + 35, k + 30, Blocks.leaves, 7);
		world.setBlockMetadataWithNotify(i + 7, j + 35, k + 30, 7, 2);
		setBlock(world, i + 7, j + 36, k + 13, Blocks.leaves, 7);
		world.setBlockMetadataWithNotify(i + 7, j + 36, k + 13, 7, 2);
		setBlock(world, i + 7, j + 36, k + 14, Blocks.leaves, 7);
		world.setBlockMetadataWithNotify(i + 7, j + 36, k + 14, 7, 2);
		setBlock(world, i + 7, j + 36, k + 15, Blocks.log, 3);
		world.setBlockMetadataWithNotify(i + 7, j + 36, k + 15, 3, 2);
		setBlock(world, i + 7, j + 36, k + 16, Blocks.leaves, 7);
		world.setBlockMetadataWithNotify(i + 7, j + 36, k + 16, 7, 2);
		setBlock(world, i + 7, j + 36, k + 17, Blocks.leaves, 7);
		world.setBlockMetadataWithNotify(i + 7, j + 36, k + 17, 7, 2);
		setBlock(world, i + 7, j + 36, k + 18, Blocks.leaves, 7);
		world.setBlockMetadataWithNotify(i + 7, j + 36, k + 18, 7, 2);
		setBlock(world, i + 7, j + 36, k + 19, Blocks.leaves, 7);
		world.setBlockMetadataWithNotify(i + 7, j + 36, k + 19, 7, 2);
		setBlock(world, i + 7, j + 36, k + 21, Blocks.leaves, 7);
		world.setBlockMetadataWithNotify(i + 7, j + 36, k + 21, 7, 2);
		setBlock(world, i + 7, j + 36, k + 22, Blocks.leaves, 7);
		world.setBlockMetadataWithNotify(i + 7, j + 36, k + 22, 7, 2);
		setBlock(world, i + 7, j + 36, k + 23, Blocks.leaves, 7);
		world.setBlockMetadataWithNotify(i + 7, j + 36, k + 23, 7, 2);
		setBlock(world, i + 7, j + 36, k + 24, Blocks.leaves, 7);
		world.setBlockMetadataWithNotify(i + 7, j + 36, k + 24, 7, 2);
		setBlock(world, i + 7, j + 36, k + 25, Blocks.leaves, 7);
		world.setBlockMetadataWithNotify(i + 7, j + 36, k + 25, 7, 2);
		setBlock(world, i + 7, j + 36, k + 27, Blocks.leaves, 7);
		world.setBlockMetadataWithNotify(i + 7, j + 36, k + 27, 7, 2);
		setBlock(world, i + 7, j + 36, k + 28, Blocks.leaves, 7);
		world.setBlockMetadataWithNotify(i + 7, j + 36, k + 28, 7, 2);
		setBlock(world, i + 7, j + 36, k + 29, Blocks.leaves, 7);
		world.setBlockMetadataWithNotify(i + 7, j + 36, k + 29, 7, 2);
		setBlock(world, i + 7, j + 37, k + 13, Blocks.leaves, 7);
		world.setBlockMetadataWithNotify(i + 7, j + 37, k + 13, 7, 2);
		setBlock(world, i + 7, j + 37, k + 14, Blocks.leaves, 7);
		world.setBlockMetadataWithNotify(i + 7, j + 37, k + 14, 7, 2);
		setBlock(world, i + 7, j + 37, k + 15, Blocks.leaves, 7);
		world.setBlockMetadataWithNotify(i + 7, j + 37, k + 15, 7, 2);
		setBlock(world, i + 7, j + 37, k + 16, Blocks.leaves, 7);
		world.setBlockMetadataWithNotify(i + 7, j + 37, k + 16, 7, 2);
		setBlock(world, i + 7, j + 37, k + 17, Blocks.leaves, 7);
		world.setBlockMetadataWithNotify(i + 7, j + 37, k + 17, 7, 2);
		setBlock(world, i + 7, j + 37, k + 18, Blocks.leaves, 7);
		world.setBlockMetadataWithNotify(i + 7, j + 37, k + 18, 7, 2);
		setBlock(world, i + 7, j + 37, k + 22, Blocks.leaves, 7);
		world.setBlockMetadataWithNotify(i + 7, j + 37, k + 22, 7, 2);
		setBlock(world, i + 7, j + 37, k + 23, Blocks.leaves, 7);
		world.setBlockMetadataWithNotify(i + 7, j + 37, k + 23, 7, 2);
		setBlock(world, i + 7, j + 37, k + 24, Blocks.leaves, 7);
		world.setBlockMetadataWithNotify(i + 7, j + 37, k + 24, 7, 2);
		setBlock(world, i + 7, j + 37, k + 28, Blocks.leaves, 7);
		world.setBlockMetadataWithNotify(i + 7, j + 37, k + 28, 7, 2);
		setBlock(world, i + 7, j + 38, k + 14, Blocks.leaves, 7);
		world.setBlockMetadataWithNotify(i + 7, j + 38, k + 14, 7, 2);
		setBlock(world, i + 7, j + 38, k + 15, Blocks.leaves, 7);
		world.setBlockMetadataWithNotify(i + 7, j + 38, k + 15, 7, 2);
		setBlock(world, i + 7, j + 38, k + 16, Blocks.leaves, 7);
		world.setBlockMetadataWithNotify(i + 7, j + 38, k + 16, 7, 2);
		setBlock(world, i + 7, j + 38, k + 23, Blocks.leaves, 7);
		world.setBlockMetadataWithNotify(i + 7, j + 38, k + 23, 7, 2);
		setBlock(world, i + 7, j + 39, k + 15, Blocks.leaves, 7);
		world.setBlockMetadataWithNotify(i + 7, j + 39, k + 15, 7, 2);
		setBlock(world, i + 7, j + 41, k + 24, Blocks.leaves, 7);
		world.setBlockMetadataWithNotify(i + 7, j + 41, k + 24, 7, 2);
		setBlock(world, i + 7, j + 41, k + 25, Blocks.leaves, 7);
		world.setBlockMetadataWithNotify(i + 7, j + 41, k + 25, 7, 2);
		setBlock(world, i + 7, j + 41, k + 26, Blocks.leaves, 7);
		world.setBlockMetadataWithNotify(i + 7, j + 41, k + 26, 7, 2);
		setBlock(world, i + 7, j + 41, k + 27, Blocks.leaves, 7);
		world.setBlockMetadataWithNotify(i + 7, j + 41, k + 27, 7, 2);
		setBlock(world, i + 7, j + 41, k + 28, Blocks.leaves, 7);
		world.setBlockMetadataWithNotify(i + 7, j + 41, k + 28, 7, 2);
		setBlock(world, i + 7, j + 42, k + 25, Blocks.leaves, 7);
		world.setBlockMetadataWithNotify(i + 7, j + 42, k + 25, 7, 2);
		setBlock(world, i + 7, j + 42, k + 26, Blocks.leaves, 7);
		world.setBlockMetadataWithNotify(i + 7, j + 42, k + 26, 7, 2);
		setBlock(world, i + 7, j + 42, k + 27, Blocks.leaves, 7);
		world.setBlockMetadataWithNotify(i + 7, j + 42, k + 27, 7, 2);
		setBlock(world, i + 7, j + 43, k + 26, Blocks.leaves, 7);
		world.setBlockMetadataWithNotify(i + 7, j + 43, k + 26, 7, 2);
		setBlock(world, i + 7, j + 57, k + 28, Blocks.spruce_stairs, 4);
		world.setBlockMetadataWithNotify(i + 7, j + 57, k + 28, 4, 2);
		setBlock(world, i + 7, j + 58, k + 28, Blocks.log, 1);
		world.setBlockMetadataWithNotify(i + 7, j + 58, k + 28, 1, 2);
		setBlock(world, i + 7, j + 59, k + 28, Blocks.log, 1);
		world.setBlockMetadataWithNotify(i + 7, j + 59, k + 28, 1, 2);
		setBlock(world, i + 7, j + 59, k + 29, Blocks.spruce_stairs, 7);
		world.setBlockMetadataWithNotify(i + 7, j + 59, k + 29, 7, 2);
		setBlock(world, i + 7, j + 60, k + 27, Blocks.log, 1);
		world.setBlockMetadataWithNotify(i + 7, j + 60, k + 27, 1, 2);
		setBlock(world, i + 7, j + 60, k + 28, Blocks.log, 1);
		world.setBlockMetadataWithNotify(i + 7, j + 60, k + 28, 1, 2);
		setBlock(world, i + 7, j + 60, k + 29, Blocks.log, 1);
		world.setBlockMetadataWithNotify(i + 7, j + 60, k + 29, 1, 2);
		setBlock(world, i + 7, j + 60, k + 30, Blocks.log, 1);
		world.setBlockMetadataWithNotify(i + 7, j + 60, k + 30, 1, 2);
		setBlock(world, i + 7, j + 60, k + 31, Blocks.log, 1);
		world.setBlockMetadataWithNotify(i + 7, j + 60, k + 31, 1, 2);
		setBlock(world, i + 8, j + 23, k + 25, Blocks.log, 3);
		world.setBlockMetadataWithNotify(i + 8, j + 23, k + 25, 3, 2);
		setBlock(world, i + 8, j + 24, k + 22, Blocks.leaves, 7);
		world.setBlockMetadataWithNotify(i + 8, j + 24, k + 22, 7, 2);
		setBlock(world, i + 8, j + 24, k + 23, Blocks.leaves, 7);
		world.setBlockMetadataWithNotify(i + 8, j + 24, k + 23, 7, 2);
		setBlock(world, i + 8, j + 24, k + 24, Blocks.leaves, 7);
		world.setBlockMetadataWithNotify(i + 8, j + 24, k + 24, 7, 2);
		setBlock(world, i + 8, j + 24, k + 25, Blocks.leaves, 7);
		world.setBlockMetadataWithNotify(i + 8, j + 24, k + 25, 7, 2);
		setBlock(world, i + 8, j + 24, k + 26, Blocks.leaves, 7);
		world.setBlockMetadataWithNotify(i + 8, j + 24, k + 26, 7, 2);
		setBlock(world, i + 8, j + 25, k + 23, Blocks.leaves, 7);
		world.setBlockMetadataWithNotify(i + 8, j + 25, k + 23, 7, 2);
		setBlock(world, i + 8, j + 25, k + 24, Blocks.leaves, 7);
		world.setBlockMetadataWithNotify(i + 8, j + 25, k + 24, 7, 2);
		setBlock(world, i + 8, j + 25, k + 25, Blocks.leaves, 7);
		world.setBlockMetadataWithNotify(i + 8, j + 25, k + 25, 7, 2);
		setBlock(world, i + 8, j + 26, k + 24, Blocks.leaves, 7);
		world.setBlockMetadataWithNotify(i + 8, j + 26, k + 24, 7, 2);
		setBlock(world, i + 8, j + 26, k + 30, Blocks.log, 3);
		world.setBlockMetadataWithNotify(i + 8, j + 26, k + 30, 3, 2);
		setBlock(world, i + 8, j + 27, k + 29, Blocks.leaves, 7);
		world.setBlockMetadataWithNotify(i + 8, j + 27, k + 29, 7, 2);
		setBlock(world, i + 8, j + 27, k + 30, Blocks.leaves, 7);
		world.setBlockMetadataWithNotify(i + 8, j + 27, k + 30, 7, 2);
		setBlock(world, i + 8, j + 27, k + 31, Blocks.leaves, 7);
		world.setBlockMetadataWithNotify(i + 8, j + 27, k + 31, 7, 2);
		setBlock(world, i + 8, j + 28, k + 30, Blocks.leaves, 7);
		world.setBlockMetadataWithNotify(i + 8, j + 28, k + 30, 7, 2);
		setBlock(world, i + 8, j + 31, k + 23, Blocks.leaves, 7);
		world.setBlockMetadataWithNotify(i + 8, j + 31, k + 23, 7, 2);
		setBlock(world, i + 8, j + 31, k + 24, Blocks.leaves, 7);
		world.setBlockMetadataWithNotify(i + 8, j + 31, k + 24, 7, 2);
		setBlock(world, i + 8, j + 31, k + 25, Blocks.leaves, 7);
		world.setBlockMetadataWithNotify(i + 8, j + 31, k + 25, 7, 2);
		setBlock(world, i + 8, j + 32, k + 24, Blocks.leaves, 7);
		world.setBlockMetadataWithNotify(i + 8, j + 32, k + 24, 7, 2);
		setBlock(world, i + 8, j + 33, k + 17, Blocks.log, 3);
		world.setBlockMetadataWithNotify(i + 8, j + 33, k + 17, 3, 2);
		setBlock(world, i + 8, j + 34, k + 14, Blocks.leaves, 7);
		world.setBlockMetadataWithNotify(i + 8, j + 34, k + 14, 7, 2);
		setBlock(world, i + 8, j + 34, k + 15, Blocks.leaves, 7);
		world.setBlockMetadataWithNotify(i + 8, j + 34, k + 15, 7, 2);
		setBlock(world, i + 8, j + 34, k + 16, Blocks.leaves, 7);
		world.setBlockMetadataWithNotify(i + 8, j + 34, k + 16, 7, 2);
		setBlock(world, i + 8, j + 34, k + 24, Blocks.log, 3);
		world.setBlockMetadataWithNotify(i + 8, j + 34, k + 24, 3, 2);
		setBlock(world, i + 8, j + 35, k + 15, Blocks.leaves, 7);
		world.setBlockMetadataWithNotify(i + 8, j + 35, k + 15, 7, 2);
		setBlock(world, i + 8, j + 35, k + 16, Blocks.log, 3);
		world.setBlockMetadataWithNotify(i + 8, j + 35, k + 16, 3, 2);
		setBlock(world, i + 8, j + 35, k + 21, Blocks.leaves, 7);
		world.setBlockMetadataWithNotify(i + 8, j + 35, k + 21, 7, 2);
		setBlock(world, i + 8, j + 35, k + 22, Blocks.leaves, 7);
		world.setBlockMetadataWithNotify(i + 8, j + 35, k + 22, 7, 2);
		setBlock(world, i + 8, j + 35, k + 23, Blocks.leaves, 7);
		world.setBlockMetadataWithNotify(i + 8, j + 35, k + 23, 7, 2);
		setBlock(world, i + 8, j + 35, k + 24, Blocks.leaves, 7);
		world.setBlockMetadataWithNotify(i + 8, j + 35, k + 24, 7, 2);
		setBlock(world, i + 8, j + 35, k + 25, Blocks.leaves, 7);
		world.setBlockMetadataWithNotify(i + 8, j + 35, k + 25, 7, 2);
		setBlock(world, i + 8, j + 35, k + 26, Blocks.leaves, 7);
		world.setBlockMetadataWithNotify(i + 8, j + 35, k + 26, 7, 2);
		setBlock(world, i + 8, j + 35, k + 27, Blocks.leaves, 7);
		world.setBlockMetadataWithNotify(i + 8, j + 35, k + 27, 7, 2);
		setBlock(world, i + 8, j + 35, k + 28, Blocks.log, 3);
		world.setBlockMetadataWithNotify(i + 8, j + 35, k + 28, 3, 2);
		setBlock(world, i + 8, j + 35, k + 29, Blocks.leaves, 7);
		world.setBlockMetadataWithNotify(i + 8, j + 35, k + 29, 7, 2);
		setBlock(world, i + 8, j + 35, k + 30, Blocks.leaves, 7);
		world.setBlockMetadataWithNotify(i + 8, j + 35, k + 30, 7, 2);
		setBlock(world, i + 8, j + 36, k + 13, Blocks.leaves, 7);
		world.setBlockMetadataWithNotify(i + 8, j + 36, k + 13, 7, 2);
		setBlock(world, i + 8, j + 36, k + 14, Blocks.leaves, 7);
		world.setBlockMetadataWithNotify(i + 8, j + 36, k + 14, 7, 2);
		setBlock(world, i + 8, j + 36, k + 15, Blocks.leaves, 7);
		world.setBlockMetadataWithNotify(i + 8, j + 36, k + 15, 7, 2);
		setBlock(world, i + 8, j + 36, k + 16, Blocks.leaves, 7);
		world.setBlockMetadataWithNotify(i + 8, j + 36, k + 16, 7, 2);
		setBlock(world, i + 8, j + 36, k + 17, Blocks.leaves, 7);
		world.setBlockMetadataWithNotify(i + 8, j + 36, k + 17, 7, 2);
		setBlock(world, i + 8, j + 36, k + 18, Blocks.leaves, 7);
		world.setBlockMetadataWithNotify(i + 8, j + 36, k + 18, 7, 2);
		setBlock(world, i + 8, j + 36, k + 19, Blocks.leaves, 7);
		world.setBlockMetadataWithNotify(i + 8, j + 36, k + 19, 7, 2);
		setBlock(world, i + 8, j + 36, k + 20, Blocks.leaves, 7);
		world.setBlockMetadataWithNotify(i + 8, j + 36, k + 20, 7, 2);
		setBlock(world, i + 8, j + 36, k + 22, Blocks.leaves, 7);
		world.setBlockMetadataWithNotify(i + 8, j + 36, k + 22, 7, 2);
		setBlock(world, i + 8, j + 36, k + 23, Blocks.leaves, 7);
		world.setBlockMetadataWithNotify(i + 8, j + 36, k + 23, 7, 2);
		setBlock(world, i + 8, j + 36, k + 24, Blocks.leaves, 7);
		world.setBlockMetadataWithNotify(i + 8, j + 36, k + 24, 7, 2);
		setBlock(world, i + 8, j + 36, k + 26, Blocks.leaves, 7);
		world.setBlockMetadataWithNotify(i + 8, j + 36, k + 26, 7, 2);
		setBlock(world, i + 8, j + 36, k + 27, Blocks.leaves, 7);
		world.setBlockMetadataWithNotify(i + 8, j + 36, k + 27, 7, 2);
		setBlock(world, i + 8, j + 36, k + 28, Blocks.leaves, 7);
		world.setBlockMetadataWithNotify(i + 8, j + 36, k + 28, 7, 2);
		setBlock(world, i + 8, j + 36, k + 29, Blocks.leaves, 7);
		world.setBlockMetadataWithNotify(i + 8, j + 36, k + 29, 7, 2);
		setBlock(world, i + 8, j + 36, k + 30, Blocks.leaves, 7);
		world.setBlockMetadataWithNotify(i + 8, j + 36, k + 30, 7, 2);
		setBlock(world, i + 8, j + 37, k + 14, Blocks.leaves, 7);
		world.setBlockMetadataWithNotify(i + 8, j + 37, k + 14, 7, 2);
		setBlock(world, i + 8, j + 37, k + 15, Blocks.leaves, 7);
		world.setBlockMetadataWithNotify(i + 8, j + 37, k + 15, 7, 2);
		setBlock(world, i + 8, j + 37, k + 16, Blocks.leaves, 7);
		world.setBlockMetadataWithNotify(i + 8, j + 37, k + 16, 7, 2);
		setBlock(world, i + 8, j + 37, k + 17, Blocks.leaves, 7);
		world.setBlockMetadataWithNotify(i + 8, j + 37, k + 17, 7, 2);
		setBlock(world, i + 8, j + 37, k + 18, Blocks.leaves, 7);
		world.setBlockMetadataWithNotify(i + 8, j + 37, k + 18, 7, 2);
		setBlock(world, i + 8, j + 37, k + 19, Blocks.leaves, 7);
		world.setBlockMetadataWithNotify(i + 8, j + 37, k + 19, 7, 2);
		setBlock(world, i + 8, j + 37, k + 23, Blocks.leaves, 7);
		world.setBlockMetadataWithNotify(i + 8, j + 37, k + 23, 7, 2);
		setBlock(world, i + 8, j + 37, k + 24, Blocks.leaves, 7);
		world.setBlockMetadataWithNotify(i + 8, j + 37, k + 24, 7, 2);
		setBlock(world, i + 8, j + 37, k + 25, Blocks.leaves, 7);
		world.setBlockMetadataWithNotify(i + 8, j + 37, k + 25, 7, 2);
		setBlock(world, i + 8, j + 37, k + 26, Blocks.leaves, 7);
		world.setBlockMetadataWithNotify(i + 8, j + 37, k + 26, 7, 2);
		setBlock(world, i + 8, j + 37, k + 27, Blocks.leaves, 7);
		world.setBlockMetadataWithNotify(i + 8, j + 37, k + 27, 7, 2);
		setBlock(world, i + 8, j + 37, k + 28, Blocks.leaves, 7);
		world.setBlockMetadataWithNotify(i + 8, j + 37, k + 28, 7, 2);
		setBlock(world, i + 8, j + 37, k + 29, Blocks.leaves, 7);
		world.setBlockMetadataWithNotify(i + 8, j + 37, k + 29, 7, 2);
		setBlock(world, i + 8, j + 38, k + 15, Blocks.leaves, 7);
		world.setBlockMetadataWithNotify(i + 8, j + 38, k + 15, 7, 2);
		setBlock(world, i + 8, j + 38, k + 18, Blocks.leaves, 7);
		world.setBlockMetadataWithNotify(i + 8, j + 38, k + 18, 7, 2);
		setBlock(world, i + 8, j + 38, k + 25, Blocks.leaves, 7);
		world.setBlockMetadataWithNotify(i + 8, j + 38, k + 25, 7, 2);
		setBlock(world, i + 8, j + 38, k + 28, Blocks.leaves, 7);
		world.setBlockMetadataWithNotify(i + 8, j + 38, k + 28, 7, 2);
		setBlock(world, i + 8, j + 41, k + 24, Blocks.leaves, 7);
		world.setBlockMetadataWithNotify(i + 8, j + 41, k + 24, 7, 2);
		setBlock(world, i + 8, j + 41, k + 25, Blocks.leaves, 7);
		world.setBlockMetadataWithNotify(i + 8, j + 41, k + 25, 7, 2);
		setBlock(world, i + 8, j + 41, k + 26, Blocks.log, 3);
		world.setBlockMetadataWithNotify(i + 8, j + 41, k + 26, 3, 2);
		setBlock(world, i + 8, j + 41, k + 27, Blocks.leaves, 7);
		world.setBlockMetadataWithNotify(i + 8, j + 41, k + 27, 7, 2);
		setBlock(world, i + 8, j + 41, k + 28, Blocks.leaves, 7);
		world.setBlockMetadataWithNotify(i + 8, j + 41, k + 28, 7, 2);
		setBlock(world, i + 8, j + 42, k + 24, Blocks.leaves, 7);
		world.setBlockMetadataWithNotify(i + 8, j + 42, k + 24, 7, 2);
		setBlock(world, i + 8, j + 42, k + 25, Blocks.leaves, 7);
		world.setBlockMetadataWithNotify(i + 8, j + 42, k + 25, 7, 2);
		setBlock(world, i + 8, j + 42, k + 26, Blocks.leaves, 7);
		world.setBlockMetadataWithNotify(i + 8, j + 42, k + 26, 7, 2);
		setBlock(world, i + 8, j + 42, k + 27, Blocks.leaves, 7);
		world.setBlockMetadataWithNotify(i + 8, j + 42, k + 27, 7, 2);
		setBlock(world, i + 8, j + 42, k + 28, Blocks.leaves, 7);
		world.setBlockMetadataWithNotify(i + 8, j + 42, k + 28, 7, 2);
		setBlock(world, i + 8, j + 43, k + 25, Blocks.leaves, 7);
		world.setBlockMetadataWithNotify(i + 8, j + 43, k + 25, 7, 2);
		setBlock(world, i + 8, j + 43, k + 26, Blocks.leaves, 7);
		world.setBlockMetadataWithNotify(i + 8, j + 43, k + 26, 7, 2);
		setBlock(world, i + 8, j + 43, k + 27, Blocks.leaves, 7);
		world.setBlockMetadataWithNotify(i + 8, j + 43, k + 27, 7, 2);
		setBlock(world, i + 8, j + 44, k + 26, Blocks.leaves, 7);
		world.setBlockMetadataWithNotify(i + 8, j + 44, k + 26, 7, 2);
		setBlock(world, i + 8, j + 56, k + 28, Blocks.spruce_stairs, 4);
		world.setBlockMetadataWithNotify(i + 8, j + 56, k + 28, 4, 2);
		setBlock(world, i + 8, j + 57, k + 28, Blocks.log, 1);
		world.setBlockMetadataWithNotify(i + 8, j + 57, k + 28, 1, 2);
		setBlock(world, i + 8, j + 58, k + 28, Blocks.log, 1);
		world.setBlockMetadataWithNotify(i + 8, j + 58, k + 28, 1, 2);
		setBlock(world, i + 8, j + 58, k + 29, Blocks.torch, 3);
		world.setBlockMetadataWithNotify(i + 8, j + 58, k + 29, 3, 2);
		setBlock(world, i + 8, j + 60, k + 24, Blocks.log, 1);
		world.setBlockMetadataWithNotify(i + 8, j + 60, k + 24, 1, 2);
		setBlock(world, i + 8, j + 60, k + 25, Blocks.log, 1);
		world.setBlockMetadataWithNotify(i + 8, j + 60, k + 25, 1, 2);
		setBlock(world, i + 8, j + 60, k + 26, Blocks.log, 1);
		world.setBlockMetadataWithNotify(i + 8, j + 60, k + 26, 1, 2);
		setBlock(world, i + 8, j + 60, k + 27, Blocks.log, 1);
		world.setBlockMetadataWithNotify(i + 8, j + 60, k + 27, 1, 2);
		setBlock(world, i + 8, j + 60, k + 28, Blocks.log, 1);
		world.setBlockMetadataWithNotify(i + 8, j + 60, k + 28, 1, 2);
		setBlock(world, i + 8, j + 60, k + 29, Blocks.log, 1);
		world.setBlockMetadataWithNotify(i + 8, j + 60, k + 29, 1, 2);
		setBlock(world, i + 8, j + 60, k + 30, Blocks.log, 1);
		world.setBlockMetadataWithNotify(i + 8, j + 60, k + 30, 1, 2);
		setBlock(world, i + 8, j + 60, k + 31, Blocks.log, 1);
		world.setBlockMetadataWithNotify(i + 8, j + 60, k + 31, 1, 2);
		setBlock(world, i + 8, j + 61, k + 26, Blocks.log, 1);
		world.setBlockMetadataWithNotify(i + 8, j + 61, k + 26, 1, 2);
		setBlock(world, i + 8, j + 61, k + 27, Blocks.log, 1);
		world.setBlockMetadataWithNotify(i + 8, j + 61, k + 27, 1, 2);
		setBlock(world, i + 8, j + 61, k + 28, Blocks.log, 1);
		world.setBlockMetadataWithNotify(i + 8, j + 61, k + 28, 1, 2);
		setBlock(world, i + 8, j + 61, k + 29, Blocks.log, 1);
		world.setBlockMetadataWithNotify(i + 8, j + 61, k + 29, 1, 2);
		setBlock(world, i + 8, j + 61, k + 30, Blocks.log, 1);
		world.setBlockMetadataWithNotify(i + 8, j + 61, k + 30, 1, 2);
		setBlock(world, i + 8, j + 61, k + 31, Blocks.log, 1);
		world.setBlockMetadataWithNotify(i + 8, j + 61, k + 31, 1, 2);
		setBlock(world, i + 9, j + 23, k + 25, Blocks.log, 3);
		world.setBlockMetadataWithNotify(i + 9, j + 23, k + 25, 3, 2);
		setBlock(world, i + 9, j + 24, k + 23, Blocks.leaves, 7);
		world.setBlockMetadataWithNotify(i + 9, j + 24, k + 23, 7, 2);
		setBlock(world, i + 9, j + 24, k + 24, Blocks.leaves, 7);
		world.setBlockMetadataWithNotify(i + 9, j + 24, k + 24, 7, 2);
		setBlock(world, i + 9, j + 24, k + 25, Blocks.leaves, 7);
		world.setBlockMetadataWithNotify(i + 9, j + 24, k + 25, 7, 2);
		setBlock(world, i + 9, j + 25, k + 23, Blocks.leaves, 7);
		world.setBlockMetadataWithNotify(i + 9, j + 25, k + 23, 7, 2);
		setBlock(world, i + 9, j + 25, k + 24, Blocks.leaves, 7);
		world.setBlockMetadataWithNotify(i + 9, j + 25, k + 24, 7, 2);
		setBlock(world, i + 9, j + 25, k + 25, Blocks.leaves, 7);
		world.setBlockMetadataWithNotify(i + 9, j + 25, k + 25, 7, 2);
		setBlock(world, i + 9, j + 26, k + 24, Blocks.leaves, 7);
		world.setBlockMetadataWithNotify(i + 9, j + 26, k + 24, 7, 2);
		setBlock(world, i + 9, j + 26, k + 30, Blocks.log, 3);
		world.setBlockMetadataWithNotify(i + 9, j + 26, k + 30, 3, 2);
		setBlock(world, i + 9, j + 31, k + 22, Blocks.leaves, 7);
		world.setBlockMetadataWithNotify(i + 9, j + 31, k + 22, 7, 2);
		setBlock(world, i + 9, j + 31, k + 23, Blocks.leaves, 7);
		world.setBlockMetadataWithNotify(i + 9, j + 31, k + 23, 7, 2);
		setBlock(world, i + 9, j + 31, k + 24, Blocks.leaves, 7);
		world.setBlockMetadataWithNotify(i + 9, j + 31, k + 24, 7, 2);
		setBlock(world, i + 9, j + 31, k + 25, Blocks.leaves, 7);
		world.setBlockMetadataWithNotify(i + 9, j + 31, k + 25, 7, 2);
		setBlock(world, i + 9, j + 31, k + 26, Blocks.leaves, 7);
		world.setBlockMetadataWithNotify(i + 9, j + 31, k + 26, 7, 2);
		setBlock(world, i + 9, j + 32, k + 23, Blocks.leaves, 7);
		world.setBlockMetadataWithNotify(i + 9, j + 32, k + 23, 7, 2);
		setBlock(world, i + 9, j + 32, k + 24, Blocks.leaves, 7);
		world.setBlockMetadataWithNotify(i + 9, j + 32, k + 24, 7, 2);
		setBlock(world, i + 9, j + 32, k + 25, Blocks.leaves, 7);
		world.setBlockMetadataWithNotify(i + 9, j + 32, k + 25, 7, 2);
		setBlock(world, i + 9, j + 33, k + 17, Blocks.log, 3);
		world.setBlockMetadataWithNotify(i + 9, j + 33, k + 17, 3, 2);
		setBlock(world, i + 9, j + 33, k + 24, Blocks.leaves, 7);
		world.setBlockMetadataWithNotify(i + 9, j + 33, k + 24, 7, 2);
		setBlock(world, i + 9, j + 34, k + 24, Blocks.log, 3);
		world.setBlockMetadataWithNotify(i + 9, j + 34, k + 24, 3, 2);
		setBlock(world, i + 9, j + 34, k + 28, Blocks.log, 3);
		world.setBlockMetadataWithNotify(i + 9, j + 34, k + 28, 3, 2);
		setBlock(world, i + 9, j + 35, k + 17, Blocks.log, 3);
		world.setBlockMetadataWithNotify(i + 9, j + 35, k + 17, 3, 2);
		setBlock(world, i + 9, j + 35, k + 22, Blocks.leaves, 7);
		world.setBlockMetadataWithNotify(i + 9, j + 35, k + 22, 7, 2);
		setBlock(world, i + 9, j + 35, k + 23, Blocks.leaves, 7);
		world.setBlockMetadataWithNotify(i + 9, j + 35, k + 23, 7, 2);
		setBlock(world, i + 9, j + 35, k + 24, Blocks.leaves, 7);
		world.setBlockMetadataWithNotify(i + 9, j + 35, k + 24, 7, 2);
		setBlock(world, i + 9, j + 35, k + 26, Blocks.leaves, 7);
		world.setBlockMetadataWithNotify(i + 9, j + 35, k + 26, 7, 2);
		setBlock(world, i + 9, j + 35, k + 27, Blocks.leaves, 7);
		world.setBlockMetadataWithNotify(i + 9, j + 35, k + 27, 7, 2);
		setBlock(world, i + 9, j + 35, k + 28, Blocks.leaves, 7);
		world.setBlockMetadataWithNotify(i + 9, j + 35, k + 28, 7, 2);
		setBlock(world, i + 9, j + 35, k + 29, Blocks.leaves, 7);
		world.setBlockMetadataWithNotify(i + 9, j + 35, k + 29, 7, 2);
		setBlock(world, i + 9, j + 35, k + 30, Blocks.leaves, 7);
		world.setBlockMetadataWithNotify(i + 9, j + 35, k + 30, 7, 2);
		setBlock(world, i + 9, j + 36, k + 14, Blocks.leaves, 7);
		world.setBlockMetadataWithNotify(i + 9, j + 36, k + 14, 7, 2);
		setBlock(world, i + 9, j + 36, k + 15, Blocks.leaves, 7);
		world.setBlockMetadataWithNotify(i + 9, j + 36, k + 15, 7, 2);
		setBlock(world, i + 9, j + 36, k + 16, Blocks.leaves, 7);
		world.setBlockMetadataWithNotify(i + 9, j + 36, k + 16, 7, 2);
		setBlock(world, i + 9, j + 36, k + 17, Blocks.leaves, 7);
		world.setBlockMetadataWithNotify(i + 9, j + 36, k + 17, 7, 2);
		setBlock(world, i + 9, j + 36, k + 18, Blocks.log, 3);
		world.setBlockMetadataWithNotify(i + 9, j + 36, k + 18, 3, 2);
		setBlock(world, i + 9, j + 36, k + 19, Blocks.leaves, 7);
		world.setBlockMetadataWithNotify(i + 9, j + 36, k + 19, 7, 2);
		setBlock(world, i + 9, j + 36, k + 20, Blocks.leaves, 7);
		world.setBlockMetadataWithNotify(i + 9, j + 36, k + 20, 7, 2);
		setBlock(world, i + 9, j + 36, k + 23, Blocks.leaves, 7);
		world.setBlockMetadataWithNotify(i + 9, j + 36, k + 23, 7, 2);
		setBlock(world, i + 9, j + 36, k + 27, Blocks.leaves, 7);
		world.setBlockMetadataWithNotify(i + 9, j + 36, k + 27, 7, 2);
		setBlock(world, i + 9, j + 36, k + 28, Blocks.leaves, 7);
		world.setBlockMetadataWithNotify(i + 9, j + 36, k + 28, 7, 2);
		setBlock(world, i + 9, j + 36, k + 29, Blocks.leaves, 7);
		world.setBlockMetadataWithNotify(i + 9, j + 36, k + 29, 7, 2);
		setBlock(world, i + 9, j + 37, k + 15, Blocks.leaves, 7);
		world.setBlockMetadataWithNotify(i + 9, j + 37, k + 15, 7, 2);
		setBlock(world, i + 9, j + 37, k + 16, Blocks.leaves, 7);
		world.setBlockMetadataWithNotify(i + 9, j + 37, k + 16, 7, 2);
		setBlock(world, i + 9, j + 37, k + 17, Blocks.leaves, 7);
		world.setBlockMetadataWithNotify(i + 9, j + 37, k + 17, 7, 2);
		setBlock(world, i + 9, j + 37, k + 18, Blocks.leaves, 7);
		world.setBlockMetadataWithNotify(i + 9, j + 37, k + 18, 7, 2);
		setBlock(world, i + 9, j + 37, k + 19, Blocks.leaves, 7);
		world.setBlockMetadataWithNotify(i + 9, j + 37, k + 19, 7, 2);
		setBlock(world, i + 9, j + 37, k + 20, Blocks.leaves, 7);
		world.setBlockMetadataWithNotify(i + 9, j + 37, k + 20, 7, 2);
		setBlock(world, i + 9, j + 37, k + 23, Blocks.leaves, 7);
		world.setBlockMetadataWithNotify(i + 9, j + 37, k + 23, 7, 2);
		setBlock(world, i + 9, j + 37, k + 24, Blocks.leaves, 7);
		world.setBlockMetadataWithNotify(i + 9, j + 37, k + 24, 7, 2);
		setBlock(world, i + 9, j + 37, k + 25, Blocks.leaves, 7);
		world.setBlockMetadataWithNotify(i + 9, j + 37, k + 25, 7, 2);
		setBlock(world, i + 9, j + 37, k + 26, Blocks.leaves, 7);
		world.setBlockMetadataWithNotify(i + 9, j + 37, k + 26, 7, 2);
		setBlock(world, i + 9, j + 37, k + 27, Blocks.leaves, 7);
		world.setBlockMetadataWithNotify(i + 9, j + 37, k + 27, 7, 2);
		setBlock(world, i + 9, j + 37, k + 28, Blocks.leaves, 7);
		world.setBlockMetadataWithNotify(i + 9, j + 37, k + 28, 7, 2);
		setBlock(world, i + 9, j + 38, k + 17, Blocks.leaves, 7);
		world.setBlockMetadataWithNotify(i + 9, j + 38, k + 17, 7, 2);
		setBlock(world, i + 9, j + 38, k + 18, Blocks.leaves, 7);
		world.setBlockMetadataWithNotify(i + 9, j + 38, k + 18, 7, 2);
		setBlock(world, i + 9, j + 38, k + 19, Blocks.leaves, 7);
		world.setBlockMetadataWithNotify(i + 9, j + 38, k + 19, 7, 2);
		setBlock(world, i + 9, j + 38, k + 24, Blocks.leaves, 7);
		world.setBlockMetadataWithNotify(i + 9, j + 38, k + 24, 7, 2);
		setBlock(world, i + 9, j + 38, k + 25, Blocks.leaves, 7);
		world.setBlockMetadataWithNotify(i + 9, j + 38, k + 25, 7, 2);
		setBlock(world, i + 9, j + 38, k + 26, Blocks.leaves, 7);
		world.setBlockMetadataWithNotify(i + 9, j + 38, k + 26, 7, 2);
		setBlock(world, i + 9, j + 39, k + 18, Blocks.leaves, 7);
		world.setBlockMetadataWithNotify(i + 9, j + 39, k + 18, 7, 2);
		setBlock(world, i + 9, j + 39, k + 25, Blocks.leaves, 7);
		world.setBlockMetadataWithNotify(i + 9, j + 39, k + 25, 7, 2);
		setBlock(world, i + 9, j + 41, k + 24, Blocks.leaves, 7);
		world.setBlockMetadataWithNotify(i + 9, j + 41, k + 24, 7, 2);
		setBlock(world, i + 9, j + 41, k + 25, Blocks.leaves, 7);
		world.setBlockMetadataWithNotify(i + 9, j + 41, k + 25, 7, 2);
		setBlock(world, i + 9, j + 41, k + 26, Blocks.leaves, 7);
		world.setBlockMetadataWithNotify(i + 9, j + 41, k + 26, 7, 2);
		setBlock(world, i + 9, j + 41, k + 27, Blocks.leaves, 7);
		world.setBlockMetadataWithNotify(i + 9, j + 41, k + 27, 7, 2);
		setBlock(world, i + 9, j + 41, k + 28, Blocks.leaves, 7);
		world.setBlockMetadataWithNotify(i + 9, j + 41, k + 28, 7, 2);
		setBlock(world, i + 9, j + 42, k + 25, Blocks.leaves, 7);
		world.setBlockMetadataWithNotify(i + 9, j + 42, k + 25, 7, 2);
		setBlock(world, i + 9, j + 42, k + 26, Blocks.leaves, 7);
		world.setBlockMetadataWithNotify(i + 9, j + 42, k + 26, 7, 2);
		setBlock(world, i + 9, j + 42, k + 27, Blocks.leaves, 7);
		world.setBlockMetadataWithNotify(i + 9, j + 42, k + 27, 7, 2);
		setBlock(world, i + 9, j + 43, k + 26, Blocks.leaves, 7);
		world.setBlockMetadataWithNotify(i + 9, j + 43, k + 26, 7, 2);
		setBlock(world, i + 9, j + 54, k + 31, Blocks.log, 1);
		world.setBlockMetadataWithNotify(i + 9, j + 54, k + 31, 1, 2);
		setBlock(world, i + 9, j + 55, k + 28, Blocks.log, 1);
		world.setBlockMetadataWithNotify(i + 9, j + 55, k + 28, 1, 2);
		setBlock(world, i + 9, j + 55, k + 29, Blocks.log, 1);
		world.setBlockMetadataWithNotify(i + 9, j + 55, k + 29, 1, 2);
		setBlock(world, i + 9, j + 55, k + 30, Blocks.log, 1);
		world.setBlockMetadataWithNotify(i + 9, j + 55, k + 30, 1, 2);
		setBlock(world, i + 9, j + 55, k + 31, Blocks.log, 1);
		world.setBlockMetadataWithNotify(i + 9, j + 55, k + 31, 1, 2);
		setBlock(world, i + 9, j + 56, k + 28, Blocks.log, 1);
		world.setBlockMetadataWithNotify(i + 9, j + 56, k + 28, 1, 2);
		setBlock(world, i + 9, j + 56, k + 29, Blocks.spruce_stairs, 3);
		world.setBlockMetadataWithNotify(i + 9, j + 56, k + 29, 3, 2);
		setBlock(world, i + 9, j + 57, k + 28, Blocks.log, 1);
		world.setBlockMetadataWithNotify(i + 9, j + 57, k + 28, 1, 2);
		setBlock(world, i + 9, j + 60, k + 22, Blocks.log, 1);
		world.setBlockMetadataWithNotify(i + 9, j + 60, k + 22, 1, 2);
		setBlock(world, i + 9, j + 60, k + 23, Blocks.log, 1);
		world.setBlockMetadataWithNotify(i + 9, j + 60, k + 23, 1, 2);
		setBlock(world, i + 9, j + 60, k + 24, Blocks.log, 1);
		world.setBlockMetadataWithNotify(i + 9, j + 60, k + 24, 1, 2);
		setBlock(world, i + 9, j + 60, k + 25, Blocks.log, 1);
		world.setBlockMetadataWithNotify(i + 9, j + 60, k + 25, 1, 2);
		setBlock(world, i + 9, j + 60, k + 26, Blocks.log, 1);
		world.setBlockMetadataWithNotify(i + 9, j + 60, k + 26, 1, 2);
		setBlock(world, i + 9, j + 60, k + 27, Blocks.log, 1);
		world.setBlockMetadataWithNotify(i + 9, j + 60, k + 27, 1, 2);
		setBlock(world, i + 9, j + 60, k + 28, Blocks.log, 1);
		world.setBlockMetadataWithNotify(i + 9, j + 60, k + 28, 1, 2);
		setBlock(world, i + 9, j + 60, k + 29, Blocks.log, 1);
		world.setBlockMetadataWithNotify(i + 9, j + 60, k + 29, 1, 2);
		setBlock(world, i + 9, j + 60, k + 30, Blocks.log, 1);
		world.setBlockMetadataWithNotify(i + 9, j + 60, k + 30, 1, 2);
		setBlock(world, i + 9, j + 60, k + 31, Blocks.log, 1);
		world.setBlockMetadataWithNotify(i + 9, j + 60, k + 31, 1, 2);
		setBlock(world, i + 9, j + 61, k + 24, Blocks.log, 1);
		world.setBlockMetadataWithNotify(i + 9, j + 61, k + 24, 1, 2);
		setBlock(world, i + 9, j + 61, k + 25, Blocks.log, 1);
		world.setBlockMetadataWithNotify(i + 9, j + 61, k + 25, 1, 2);
		setBlock(world, i + 9, j + 61, k + 26, Blocks.log, 1);
		world.setBlockMetadataWithNotify(i + 9, j + 61, k + 26, 1, 2);
		setBlock(world, i + 9, j + 61, k + 27, Blocks.log, 1);
		world.setBlockMetadataWithNotify(i + 9, j + 61, k + 27, 1, 2);
		setBlock(world, i + 9, j + 61, k + 28, Blocks.log, 1);
		world.setBlockMetadataWithNotify(i + 9, j + 61, k + 28, 1, 2);
		setBlock(world, i + 9, j + 61, k + 29, Blocks.log, 1);
		world.setBlockMetadataWithNotify(i + 9, j + 61, k + 29, 1, 2);
		setBlock(world, i + 9, j + 61, k + 30, Blocks.log, 1);
		world.setBlockMetadataWithNotify(i + 9, j + 61, k + 30, 1, 2);
		setBlock(world, i + 9, j + 61, k + 31, Blocks.log, 1);
		world.setBlockMetadataWithNotify(i + 9, j + 61, k + 31, 1, 2);
		setBlock(world, i + 9, j + 62, k + 28, Blocks.log, 1);
		world.setBlockMetadataWithNotify(i + 9, j + 62, k + 28, 1, 2);
		setBlock(world, i + 9, j + 62, k + 29, Blocks.log, 1);
		world.setBlockMetadataWithNotify(i + 9, j + 62, k + 29, 1, 2);
		setBlock(world, i + 9, j + 62, k + 30, Blocks.log, 1);
		world.setBlockMetadataWithNotify(i + 9, j + 62, k + 30, 1, 2);
		setBlock(world, i + 9, j + 62, k + 31, Blocks.log, 1);
		world.setBlockMetadataWithNotify(i + 9, j + 62, k + 31, 1, 2);
		setBlock(world, i + 10, j + 23, k + 25, Blocks.log, 3);
		world.setBlockMetadataWithNotify(i + 10, j + 23, k + 25, 3, 2);
		setBlock(world, i + 10, j + 25, k + 22, Blocks.leaves, 7);
		world.setBlockMetadataWithNotify(i + 10, j + 25, k + 22, 7, 2);
		setBlock(world, i + 10, j + 25, k + 23, Blocks.leaves, 7);
		world.setBlockMetadataWithNotify(i + 10, j + 25, k + 23, 7, 2);
		setBlock(world, i + 10, j + 25, k + 24, Blocks.leaves, 7);
		world.setBlockMetadataWithNotify(i + 10, j + 25, k + 24, 7, 2);
		setBlock(world, i + 10, j + 25, k + 25, Blocks.leaves, 7);
		world.setBlockMetadataWithNotify(i + 10, j + 25, k + 25, 7, 2);
		setBlock(world, i + 10, j + 25, k + 26, Blocks.leaves, 7);
		world.setBlockMetadataWithNotify(i + 10, j + 25, k + 26, 7, 2);
		setBlock(world, i + 10, j + 26, k + 23, Blocks.leaves, 7);
		world.setBlockMetadataWithNotify(i + 10, j + 26, k + 23, 7, 2);
		setBlock(world, i + 10, j + 26, k + 24, Blocks.leaves, 7);
		world.setBlockMetadataWithNotify(i + 10, j + 26, k + 24, 7, 2);
		setBlock(world, i + 10, j + 26, k + 25, Blocks.leaves, 7);
		world.setBlockMetadataWithNotify(i + 10, j + 26, k + 25, 7, 2);
		setBlock(world, i + 10, j + 26, k + 30, Blocks.log, 3);
		world.setBlockMetadataWithNotify(i + 10, j + 26, k + 30, 3, 2);
		setBlock(world, i + 10, j + 27, k + 24, Blocks.leaves, 7);
		world.setBlockMetadataWithNotify(i + 10, j + 27, k + 24, 7, 2);
		setBlock(world, i + 10, j + 31, k + 22, Blocks.leaves, 7);
		world.setBlockMetadataWithNotify(i + 10, j + 31, k + 22, 7, 2);
		setBlock(world, i + 10, j + 31, k + 23, Blocks.leaves, 7);
		world.setBlockMetadataWithNotify(i + 10, j + 31, k + 23, 7, 2);
		setBlock(world, i + 10, j + 31, k + 24, Blocks.log, 3);
		world.setBlockMetadataWithNotify(i + 10, j + 31, k + 24, 3, 2);
		setBlock(world, i + 10, j + 31, k + 25, Blocks.leaves, 7);
		world.setBlockMetadataWithNotify(i + 10, j + 31, k + 25, 7, 2);
		setBlock(world, i + 10, j + 31, k + 26, Blocks.leaves, 7);
		world.setBlockMetadataWithNotify(i + 10, j + 31, k + 26, 7, 2);
		setBlock(world, i + 10, j + 32, k + 22, Blocks.leaves, 7);
		world.setBlockMetadataWithNotify(i + 10, j + 32, k + 22, 7, 2);
		setBlock(world, i + 10, j + 32, k + 23, Blocks.leaves, 7);
		world.setBlockMetadataWithNotify(i + 10, j + 32, k + 23, 7, 2);
		setBlock(world, i + 10, j + 32, k + 24, Blocks.leaves, 7);
		world.setBlockMetadataWithNotify(i + 10, j + 32, k + 24, 7, 2);
		setBlock(world, i + 10, j + 32, k + 25, Blocks.leaves, 7);
		world.setBlockMetadataWithNotify(i + 10, j + 32, k + 25, 7, 2);
		setBlock(world, i + 10, j + 32, k + 26, Blocks.leaves, 7);
		world.setBlockMetadataWithNotify(i + 10, j + 32, k + 26, 7, 2);
		setBlock(world, i + 10, j + 33, k + 18, Blocks.log, 3);
		world.setBlockMetadataWithNotify(i + 10, j + 33, k + 18, 3, 2);
		setBlock(world, i + 10, j + 33, k + 23, Blocks.leaves, 7);
		world.setBlockMetadataWithNotify(i + 10, j + 33, k + 23, 7, 2);
		setBlock(world, i + 10, j + 33, k + 24, Blocks.leaves, 7);
		world.setBlockMetadataWithNotify(i + 10, j + 33, k + 24, 7, 2);
		setBlock(world, i + 10, j + 33, k + 25, Blocks.leaves, 7);
		world.setBlockMetadataWithNotify(i + 10, j + 33, k + 25, 7, 2);
		setBlock(world, i + 10, j + 34, k + 24, Blocks.log, 3);
		world.setBlockMetadataWithNotify(i + 10, j + 34, k + 24, 3, 2);
		setBlock(world, i + 10, j + 34, k + 28, Blocks.log, 3);
		world.setBlockMetadataWithNotify(i + 10, j + 34, k + 28, 3, 2);
		setBlock(world, i + 10, j + 35, k + 17, Blocks.log, 3);
		world.setBlockMetadataWithNotify(i + 10, j + 35, k + 17, 3, 2);
		setBlock(world, i + 10, j + 35, k + 19, Blocks.log, 3);
		world.setBlockMetadataWithNotify(i + 10, j + 35, k + 19, 3, 2);
		setBlock(world, i + 10, j + 35, k + 27, Blocks.leaves, 7);
		world.setBlockMetadataWithNotify(i + 10, j + 35, k + 27, 7, 2);
		setBlock(world, i + 10, j + 35, k + 28, Blocks.leaves, 7);
		world.setBlockMetadataWithNotify(i + 10, j + 35, k + 28, 7, 2);
		setBlock(world, i + 10, j + 35, k + 29, Blocks.leaves, 7);
		world.setBlockMetadataWithNotify(i + 10, j + 35, k + 29, 7, 2);
		setBlock(world, i + 10, j + 36, k + 16, Blocks.leaves, 7);
		world.setBlockMetadataWithNotify(i + 10, j + 36, k + 16, 7, 2);
		setBlock(world, i + 10, j + 36, k + 17, Blocks.leaves, 7);
		world.setBlockMetadataWithNotify(i + 10, j + 36, k + 17, 7, 2);
		setBlock(world, i + 10, j + 36, k + 18, Blocks.leaves, 7);
		world.setBlockMetadataWithNotify(i + 10, j + 36, k + 18, 7, 2);
		setBlock(world, i + 10, j + 36, k + 19, Blocks.leaves, 7);
		world.setBlockMetadataWithNotify(i + 10, j + 36, k + 19, 7, 2);
		setBlock(world, i + 10, j + 36, k + 20, Blocks.leaves, 7);
		world.setBlockMetadataWithNotify(i + 10, j + 36, k + 20, 7, 2);
		setBlock(world, i + 10, j + 36, k + 28, Blocks.leaves, 7);
		world.setBlockMetadataWithNotify(i + 10, j + 36, k + 28, 7, 2);
		setBlock(world, i + 10, j + 37, k + 17, Blocks.leaves, 7);
		world.setBlockMetadataWithNotify(i + 10, j + 37, k + 17, 7, 2);
		setBlock(world, i + 10, j + 37, k + 18, Blocks.leaves, 7);
		world.setBlockMetadataWithNotify(i + 10, j + 37, k + 18, 7, 2);
		setBlock(world, i + 10, j + 37, k + 19, Blocks.leaves, 7);
		world.setBlockMetadataWithNotify(i + 10, j + 37, k + 19, 7, 2);
		setBlock(world, i + 10, j + 37, k + 23, Blocks.leaves, 7);
		world.setBlockMetadataWithNotify(i + 10, j + 37, k + 23, 7, 2);
		setBlock(world, i + 10, j + 37, k + 24, Blocks.leaves, 7);
		world.setBlockMetadataWithNotify(i + 10, j + 37, k + 24, 7, 2);
		setBlock(world, i + 10, j + 37, k + 25, Blocks.log, 3);
		world.setBlockMetadataWithNotify(i + 10, j + 37, k + 25, 3, 2);
		setBlock(world, i + 10, j + 37, k + 26, Blocks.leaves, 7);
		world.setBlockMetadataWithNotify(i + 10, j + 37, k + 26, 7, 2);
		setBlock(world, i + 10, j + 37, k + 27, Blocks.leaves, 7);
		world.setBlockMetadataWithNotify(i + 10, j + 37, k + 27, 7, 2);
		setBlock(world, i + 10, j + 38, k + 18, Blocks.leaves, 7);
		world.setBlockMetadataWithNotify(i + 10, j + 38, k + 18, 7, 2);
		setBlock(world, i + 10, j + 38, k + 23, Blocks.leaves, 7);
		world.setBlockMetadataWithNotify(i + 10, j + 38, k + 23, 7, 2);
		setBlock(world, i + 10, j + 38, k + 24, Blocks.leaves, 7);
		world.setBlockMetadataWithNotify(i + 10, j + 38, k + 24, 7, 2);
		setBlock(world, i + 10, j + 38, k + 25, Blocks.leaves, 7);
		world.setBlockMetadataWithNotify(i + 10, j + 38, k + 25, 7, 2);
		setBlock(world, i + 10, j + 38, k + 26, Blocks.leaves, 7);
		world.setBlockMetadataWithNotify(i + 10, j + 38, k + 26, 7, 2);
		setBlock(world, i + 10, j + 38, k + 27, Blocks.leaves, 7);
		world.setBlockMetadataWithNotify(i + 10, j + 38, k + 27, 7, 2);
		setBlock(world, i + 10, j + 39, k + 24, Blocks.leaves, 7);
		world.setBlockMetadataWithNotify(i + 10, j + 39, k + 24, 7, 2);
		setBlock(world, i + 10, j + 39, k + 25, Blocks.leaves, 7);
		world.setBlockMetadataWithNotify(i + 10, j + 39, k + 25, 7, 2);
		setBlock(world, i + 10, j + 39, k + 26, Blocks.leaves, 7);
		world.setBlockMetadataWithNotify(i + 10, j + 39, k + 26, 7, 2);
		setBlock(world, i + 10, j + 40, k + 25, Blocks.leaves, 7);
		world.setBlockMetadataWithNotify(i + 10, j + 40, k + 25, 7, 2);
		setBlock(world, i + 10, j + 41, k + 25, Blocks.leaves, 7);
		world.setBlockMetadataWithNotify(i + 10, j + 41, k + 25, 7, 2);
		setBlock(world, i + 10, j + 41, k + 26, Blocks.leaves, 7);
		world.setBlockMetadataWithNotify(i + 10, j + 41, k + 26, 7, 2);
		setBlock(world, i + 10, j + 41, k + 27, Blocks.leaves, 7);
		world.setBlockMetadataWithNotify(i + 10, j + 41, k + 27, 7, 2);
		setBlock(world, i + 10, j + 42, k + 26, Blocks.leaves, 7);
		world.setBlockMetadataWithNotify(i + 10, j + 42, k + 26, 7, 2);
		setBlock(world, i + 10, j + 43, k + 23, Blocks.log, 1);
		world.setBlockMetadataWithNotify(i + 10, j + 43, k + 23, 1, 2);
		setBlock(world, i + 10, j + 44, k + 22, Blocks.log, 1);
		world.setBlockMetadataWithNotify(i + 10, j + 44, k + 22, 1, 2);
		setBlock(world, i + 10, j + 44, k + 23, Blocks.log, 1);
		world.setBlockMetadataWithNotify(i + 10, j + 44, k + 23, 1, 2);
		setBlock(world, i + 10, j + 44, k + 24, Blocks.log, 1);
		world.setBlockMetadataWithNotify(i + 10, j + 44, k + 24, 1, 2);
		setBlock(world, i + 10, j + 44, k + 25, Blocks.leaves, 7);
		world.setBlockMetadataWithNotify(i + 10, j + 44, k + 25, 7, 2);
		setBlock(world, i + 10, j + 44, k + 26, Blocks.leaves, 7);
		world.setBlockMetadataWithNotify(i + 10, j + 44, k + 26, 7, 2);
		setBlock(world, i + 10, j + 44, k + 27, Blocks.leaves, 7);
		world.setBlockMetadataWithNotify(i + 10, j + 44, k + 27, 7, 2);
		setBlock(world, i + 10, j + 45, k + 23, Blocks.log, 1);
		world.setBlockMetadataWithNotify(i + 10, j + 45, k + 23, 1, 2);
		setBlock(world, i + 10, j + 45, k + 24, Blocks.log, 1);
		world.setBlockMetadataWithNotify(i + 10, j + 45, k + 24, 1, 2);
		setBlock(world, i + 10, j + 45, k + 25, Blocks.log, 1);
		world.setBlockMetadataWithNotify(i + 10, j + 45, k + 25, 1, 2);
		setBlock(world, i + 10, j + 45, k + 26, Blocks.leaves, 7);
		world.setBlockMetadataWithNotify(i + 10, j + 45, k + 26, 7, 2);
		setBlock(world, i + 10, j + 46, k + 24, Blocks.log, 1);
		world.setBlockMetadataWithNotify(i + 10, j + 46, k + 24, 1, 2);
		setBlock(world, i + 10, j + 52, k + 28, Blocks.log, 1);
		world.setBlockMetadataWithNotify(i + 10, j + 52, k + 28, 1, 2);
		setBlock(world, i + 10, j + 53, k + 27, Blocks.log, 1);
		world.setBlockMetadataWithNotify(i + 10, j + 53, k + 27, 1, 2);
		setBlock(world, i + 10, j + 53, k + 29, Blocks.log, 1);
		world.setBlockMetadataWithNotify(i + 10, j + 53, k + 29, 1, 2);
		setBlock(world, i + 10, j + 54, k + 28, Blocks.log, 1);
		world.setBlockMetadataWithNotify(i + 10, j + 54, k + 28, 1, 2);
		setBlock(world, i + 10, j + 54, k + 29, Blocks.log, 1);
		world.setBlockMetadataWithNotify(i + 10, j + 54, k + 29, 1, 2);
		setBlock(world, i + 10, j + 54, k + 30, Blocks.log, 1);
		world.setBlockMetadataWithNotify(i + 10, j + 54, k + 30, 1, 2);
		setBlock(world, i + 10, j + 54, k + 31, Blocks.log, 1);
		world.setBlockMetadataWithNotify(i + 10, j + 54, k + 31, 1, 2);
		setBlock(world, i + 10, j + 55, k + 25, Blocks.log, 1);
		world.setBlockMetadataWithNotify(i + 10, j + 55, k + 25, 1, 2);
		setBlock(world, i + 10, j + 55, k + 26, Blocks.log, 1);
		world.setBlockMetadataWithNotify(i + 10, j + 55, k + 26, 1, 2);
		setBlock(world, i + 10, j + 55, k + 27, Blocks.log, 1);
		world.setBlockMetadataWithNotify(i + 10, j + 55, k + 27, 1, 2);
		setBlock(world, i + 10, j + 55, k + 28, Blocks.log, 1);
		world.setBlockMetadataWithNotify(i + 10, j + 55, k + 28, 1, 2);
		setBlock(world, i + 10, j + 55, k + 29, Blocks.log, 1);
		world.setBlockMetadataWithNotify(i + 10, j + 55, k + 29, 1, 2);
		setBlock(world, i + 10, j + 55, k + 30, Blocks.log, 1);
		world.setBlockMetadataWithNotify(i + 10, j + 55, k + 30, 1, 2);
		setBlock(world, i + 10, j + 55, k + 31, Blocks.planks, 5);
		world.setBlockMetadataWithNotify(i + 10, j + 55, k + 31, 5, 2);
		setBlock(world, i + 10, j + 56, k + 28, Blocks.spruce_stairs, 1);
		world.setBlockMetadataWithNotify(i + 10, j + 56, k + 28, 1, 2);
		setBlock(world, i + 10, j + 57, k + 27, Blocks.torch, 5);
		world.setBlockMetadataWithNotify(i + 10, j + 57, k + 27, 5, 2);
		setBlock(world, i + 10, j + 60, k + 21, Blocks.log, 1);
		world.setBlockMetadataWithNotify(i + 10, j + 60, k + 21, 1, 2);
		setBlock(world, i + 10, j + 60, k + 22, Blocks.log, 1);
		world.setBlockMetadataWithNotify(i + 10, j + 60, k + 22, 1, 2);
		setBlock(world, i + 10, j + 60, k + 23, Blocks.log, 1);
		world.setBlockMetadataWithNotify(i + 10, j + 60, k + 23, 1, 2);
		setBlock(world, i + 10, j + 60, k + 24, Blocks.log, 1);
		world.setBlockMetadataWithNotify(i + 10, j + 60, k + 24, 1, 2);
		setBlock(world, i + 10, j + 60, k + 25, Blocks.log, 1);
		world.setBlockMetadataWithNotify(i + 10, j + 60, k + 25, 1, 2);
		setBlock(world, i + 10, j + 60, k + 26, Blocks.log, 1);
		world.setBlockMetadataWithNotify(i + 10, j + 60, k + 26, 1, 2);
		setBlock(world, i + 10, j + 60, k + 27, Blocks.log, 1);
		world.setBlockMetadataWithNotify(i + 10, j + 60, k + 27, 1, 2);
		setBlock(world, i + 10, j + 60, k + 28, Blocks.log, 1);
		world.setBlockMetadataWithNotify(i + 10, j + 60, k + 28, 1, 2);
		setBlock(world, i + 10, j + 60, k + 29, Blocks.log, 1);
		world.setBlockMetadataWithNotify(i + 10, j + 60, k + 29, 1, 2);
		setBlock(world, i + 10, j + 60, k + 30, Blocks.log, 1);
		world.setBlockMetadataWithNotify(i + 10, j + 60, k + 30, 1, 2);
		setBlock(world, i + 10, j + 60, k + 31, Blocks.log, 1);
		world.setBlockMetadataWithNotify(i + 10, j + 60, k + 31, 1, 2);
		setBlock(world, i + 10, j + 61, k + 22, Blocks.log, 1);
		world.setBlockMetadataWithNotify(i + 10, j + 61, k + 22, 1, 2);
		setBlock(world, i + 10, j + 61, k + 23, Blocks.log, 1);
		world.setBlockMetadataWithNotify(i + 10, j + 61, k + 23, 1, 2);
		setBlock(world, i + 10, j + 61, k + 24, Blocks.log, 1);
		world.setBlockMetadataWithNotify(i + 10, j + 61, k + 24, 1, 2);
		setBlock(world, i + 10, j + 61, k + 25, Blocks.log, 1);
		world.setBlockMetadataWithNotify(i + 10, j + 61, k + 25, 1, 2);
		setBlock(world, i + 10, j + 61, k + 26, Blocks.log, 1);
		world.setBlockMetadataWithNotify(i + 10, j + 61, k + 26, 1, 2);
		setBlock(world, i + 10, j + 61, k + 27, Blocks.log, 1);
		world.setBlockMetadataWithNotify(i + 10, j + 61, k + 27, 1, 2);
		setBlock(world, i + 10, j + 61, k + 28, Blocks.log, 1);
		world.setBlockMetadataWithNotify(i + 10, j + 61, k + 28, 1, 2);
		setBlock(world, i + 10, j + 61, k + 29, Blocks.log, 1);
		world.setBlockMetadataWithNotify(i + 10, j + 61, k + 29, 1, 2);
		setBlock(world, i + 10, j + 61, k + 30, Blocks.log, 1);
		world.setBlockMetadataWithNotify(i + 10, j + 61, k + 30, 1, 2);
		setBlock(world, i + 10, j + 61, k + 31, Blocks.log, 1);
		world.setBlockMetadataWithNotify(i + 10, j + 61, k + 31, 1, 2);
		setBlock(world, i + 10, j + 62, k + 25, Blocks.log, 1);
		world.setBlockMetadataWithNotify(i + 10, j + 62, k + 25, 1, 2);
		setBlock(world, i + 10, j + 62, k + 26, Blocks.log, 1);
		world.setBlockMetadataWithNotify(i + 10, j + 62, k + 26, 1, 2);
		setBlock(world, i + 10, j + 62, k + 27, Blocks.log, 1);
		world.setBlockMetadataWithNotify(i + 10, j + 62, k + 27, 1, 2);
		setBlock(world, i + 10, j + 62, k + 28, Blocks.log, 1);
		world.setBlockMetadataWithNotify(i + 10, j + 62, k + 28, 1, 2);
		setBlock(world, i + 10, j + 62, k + 29, Blocks.log, 1);
		world.setBlockMetadataWithNotify(i + 10, j + 62, k + 29, 1, 2);
		setBlock(world, i + 10, j + 62, k + 30, Blocks.log, 1);
		world.setBlockMetadataWithNotify(i + 10, j + 62, k + 30, 1, 2);
		setBlock(world, i + 10, j + 62, k + 31, Blocks.log, 1);
		world.setBlockMetadataWithNotify(i + 10, j + 62, k + 31, 1, 2);
		setBlock(world, i + 11, j + 23, k + 25, Blocks.log, 3);
		world.setBlockMetadataWithNotify(i + 11, j + 23, k + 25, 3, 2);
		setBlock(world, i + 11, j + 25, k + 22, Blocks.leaves, 7);
		world.setBlockMetadataWithNotify(i + 11, j + 25, k + 22, 7, 2);
		setBlock(world, i + 11, j + 25, k + 23, Blocks.leaves, 7);
		world.setBlockMetadataWithNotify(i + 11, j + 25, k + 23, 7, 2);
		setBlock(world, i + 11, j + 25, k + 24, Blocks.log, 3);
		world.setBlockMetadataWithNotify(i + 11, j + 25, k + 24, 3, 2);
		setBlock(world, i + 11, j + 25, k + 25, Blocks.leaves, 7);
		world.setBlockMetadataWithNotify(i + 11, j + 25, k + 25, 7, 2);
		setBlock(world, i + 11, j + 25, k + 26, Blocks.leaves, 7);
		world.setBlockMetadataWithNotify(i + 11, j + 25, k + 26, 7, 2);
		setBlock(world, i + 11, j + 25, k + 29, Blocks.log, 3);
		world.setBlockMetadataWithNotify(i + 11, j + 25, k + 29, 3, 2);
		setBlock(world, i + 11, j + 26, k + 22, Blocks.leaves, 7);
		world.setBlockMetadataWithNotify(i + 11, j + 26, k + 22, 7, 2);
		setBlock(world, i + 11, j + 26, k + 23, Blocks.leaves, 7);
		world.setBlockMetadataWithNotify(i + 11, j + 26, k + 23, 7, 2);
		setBlock(world, i + 11, j + 26, k + 24, Blocks.leaves, 7);
		world.setBlockMetadataWithNotify(i + 11, j + 26, k + 24, 7, 2);
		setBlock(world, i + 11, j + 26, k + 25, Blocks.leaves, 7);
		world.setBlockMetadataWithNotify(i + 11, j + 26, k + 25, 7, 2);
		setBlock(world, i + 11, j + 26, k + 26, Blocks.leaves, 7);
		world.setBlockMetadataWithNotify(i + 11, j + 26, k + 26, 7, 2);
		setBlock(world, i + 11, j + 27, k + 23, Blocks.leaves, 7);
		world.setBlockMetadataWithNotify(i + 11, j + 27, k + 23, 7, 2);
		setBlock(world, i + 11, j + 27, k + 24, Blocks.leaves, 7);
		world.setBlockMetadataWithNotify(i + 11, j + 27, k + 24, 7, 2);
		setBlock(world, i + 11, j + 27, k + 25, Blocks.leaves, 7);
		world.setBlockMetadataWithNotify(i + 11, j + 27, k + 25, 7, 2);
		setBlock(world, i + 11, j + 28, k + 24, Blocks.leaves, 7);
		world.setBlockMetadataWithNotify(i + 11, j + 28, k + 24, 7, 2);
		setBlock(world, i + 11, j + 30, k + 25, Blocks.log, 3);
		world.setBlockMetadataWithNotify(i + 11, j + 30, k + 25, 3, 2);
		setBlock(world, i + 11, j + 31, k + 22, Blocks.leaves, 7);
		world.setBlockMetadataWithNotify(i + 11, j + 31, k + 22, 7, 2);
		setBlock(world, i + 11, j + 31, k + 23, Blocks.leaves, 7);
		world.setBlockMetadataWithNotify(i + 11, j + 31, k + 23, 7, 2);
		setBlock(world, i + 11, j + 31, k + 24, Blocks.leaves, 7);
		world.setBlockMetadataWithNotify(i + 11, j + 31, k + 24, 7, 2);
		setBlock(world, i + 11, j + 31, k + 25, Blocks.leaves, 7);
		world.setBlockMetadataWithNotify(i + 11, j + 31, k + 25, 7, 2);
		setBlock(world, i + 11, j + 31, k + 26, Blocks.leaves, 7);
		world.setBlockMetadataWithNotify(i + 11, j + 31, k + 26, 7, 2);
		setBlock(world, i + 11, j + 32, k + 18, Blocks.log, 3);
		world.setBlockMetadataWithNotify(i + 11, j + 32, k + 18, 3, 2);
		setBlock(world, i + 11, j + 32, k + 23, Blocks.leaves, 7);
		world.setBlockMetadataWithNotify(i + 11, j + 32, k + 23, 7, 2);
		setBlock(world, i + 11, j + 32, k + 24, Blocks.leaves, 7);
		world.setBlockMetadataWithNotify(i + 11, j + 32, k + 24, 7, 2);
		setBlock(world, i + 11, j + 32, k + 25, Blocks.leaves, 7);
		world.setBlockMetadataWithNotify(i + 11, j + 32, k + 25, 7, 2);
		setBlock(world, i + 11, j + 33, k + 24, Blocks.leaves, 7);
		world.setBlockMetadataWithNotify(i + 11, j + 33, k + 24, 7, 2);
		setBlock(world, i + 11, j + 34, k + 24, Blocks.log, 3);
		world.setBlockMetadataWithNotify(i + 11, j + 34, k + 24, 3, 2);
		setBlock(world, i + 11, j + 34, k + 28, Blocks.log, 3);
		world.setBlockMetadataWithNotify(i + 11, j + 34, k + 28, 3, 2);
		setBlock(world, i + 11, j + 35, k + 18, Blocks.log, 3);
		world.setBlockMetadataWithNotify(i + 11, j + 35, k + 18, 3, 2);
		setBlock(world, i + 11, j + 35, k + 19, Blocks.log, 3);
		world.setBlockMetadataWithNotify(i + 11, j + 35, k + 19, 3, 2);
		setBlock(world, i + 11, j + 36, k + 17, Blocks.leaves, 7);
		world.setBlockMetadataWithNotify(i + 11, j + 36, k + 17, 7, 2);
		setBlock(world, i + 11, j + 36, k + 18, Blocks.leaves, 7);
		world.setBlockMetadataWithNotify(i + 11, j + 36, k + 18, 7, 2);
		setBlock(world, i + 11, j + 36, k + 19, Blocks.leaves, 7);
		world.setBlockMetadataWithNotify(i + 11, j + 36, k + 19, 7, 2);
		setBlock(world, i + 11, j + 36, k + 25, Blocks.log, 3);
		world.setBlockMetadataWithNotify(i + 11, j + 36, k + 25, 3, 2);
		setBlock(world, i + 11, j + 37, k + 18, Blocks.leaves, 7);
		world.setBlockMetadataWithNotify(i + 11, j + 37, k + 18, 7, 2);
		setBlock(world, i + 11, j + 37, k + 23, Blocks.leaves, 7);
		world.setBlockMetadataWithNotify(i + 11, j + 37, k + 23, 7, 2);
		setBlock(world, i + 11, j + 37, k + 24, Blocks.leaves, 7);
		world.setBlockMetadataWithNotify(i + 11, j + 37, k + 24, 7, 2);
		setBlock(world, i + 11, j + 37, k + 25, Blocks.leaves, 7);
		world.setBlockMetadataWithNotify(i + 11, j + 37, k + 25, 7, 2);
		setBlock(world, i + 11, j + 37, k + 26, Blocks.leaves, 7);
		world.setBlockMetadataWithNotify(i + 11, j + 37, k + 26, 7, 2);
		setBlock(world, i + 11, j + 37, k + 27, Blocks.leaves, 7);
		world.setBlockMetadataWithNotify(i + 11, j + 37, k + 27, 7, 2);
		setBlock(world, i + 11, j + 38, k + 24, Blocks.leaves, 7);
		world.setBlockMetadataWithNotify(i + 11, j + 38, k + 24, 7, 2);
		setBlock(world, i + 11, j + 38, k + 25, Blocks.leaves, 7);
		world.setBlockMetadataWithNotify(i + 11, j + 38, k + 25, 7, 2);
		setBlock(world, i + 11, j + 38, k + 26, Blocks.leaves, 7);
		world.setBlockMetadataWithNotify(i + 11, j + 38, k + 26, 7, 2);
		setBlock(world, i + 11, j + 39, k + 25, Blocks.leaves, 7);
		world.setBlockMetadataWithNotify(i + 11, j + 39, k + 25, 7, 2);
		setBlock(world, i + 11, j + 43, k + 22, Blocks.log, 1);
		world.setBlockMetadataWithNotify(i + 11, j + 43, k + 22, 1, 2);
		setBlock(world, i + 11, j + 43, k + 23, Blocks.log, 1);
		world.setBlockMetadataWithNotify(i + 11, j + 43, k + 23, 1, 2);
		setBlock(world, i + 11, j + 44, k + 22, Blocks.log, 1);
		world.setBlockMetadataWithNotify(i + 11, j + 44, k + 22, 1, 2);
		setBlock(world, i + 11, j + 44, k + 23, Blocks.log, 1);
		world.setBlockMetadataWithNotify(i + 11, j + 44, k + 23, 1, 2);
		setBlock(world, i + 11, j + 44, k + 24, Blocks.log, 1);
		world.setBlockMetadataWithNotify(i + 11, j + 44, k + 24, 1, 2);
		setBlock(world, i + 11, j + 44, k + 25, Blocks.leaves, 7);
		world.setBlockMetadataWithNotify(i + 11, j + 44, k + 25, 7, 2);
		setBlock(world, i + 11, j + 44, k + 26, Blocks.leaves, 7);
		world.setBlockMetadataWithNotify(i + 11, j + 44, k + 26, 7, 2);
		setBlock(world, i + 11, j + 44, k + 27, Blocks.leaves, 7);
		world.setBlockMetadataWithNotify(i + 11, j + 44, k + 27, 7, 2);
		setBlock(world, i + 11, j + 44, k + 28, Blocks.leaves, 7);
		world.setBlockMetadataWithNotify(i + 11, j + 44, k + 28, 7, 2);
		setBlock(world, i + 11, j + 45, k + 22, Blocks.log, 1);
		world.setBlockMetadataWithNotify(i + 11, j + 45, k + 22, 1, 2);
		setBlock(world, i + 11, j + 45, k + 23, Blocks.log, 1);
		world.setBlockMetadataWithNotify(i + 11, j + 45, k + 23, 1, 2);
		setBlock(world, i + 11, j + 45, k + 24, Blocks.log, 1);
		world.setBlockMetadataWithNotify(i + 11, j + 45, k + 24, 1, 2);
		setBlock(world, i + 11, j + 45, k + 25, Blocks.log, 1);
		world.setBlockMetadataWithNotify(i + 11, j + 45, k + 25, 1, 2);
		setBlock(world, i + 11, j + 45, k + 26, Blocks.leaves, 7);
		world.setBlockMetadataWithNotify(i + 11, j + 45, k + 26, 7, 2);
		setBlock(world, i + 11, j + 45, k + 27, Blocks.leaves, 7);
		world.setBlockMetadataWithNotify(i + 11, j + 45, k + 27, 7, 2);
		setBlock(world, i + 11, j + 46, k + 23, Blocks.log, 1);
		world.setBlockMetadataWithNotify(i + 11, j + 46, k + 23, 1, 2);
		setBlock(world, i + 11, j + 46, k + 24, Blocks.log, 1);
		world.setBlockMetadataWithNotify(i + 11, j + 46, k + 24, 1, 2);
		setBlock(world, i + 11, j + 46, k + 25, Blocks.log, 1);
		world.setBlockMetadataWithNotify(i + 11, j + 46, k + 25, 1, 2);
		setBlock(world, i + 11, j + 46, k + 26, Blocks.leaves, 7);
		world.setBlockMetadataWithNotify(i + 11, j + 46, k + 26, 7, 2);
		setBlock(world, i + 11, j + 50, k + 29, Blocks.log, 1);
		world.setBlockMetadataWithNotify(i + 11, j + 50, k + 29, 1, 2);
		setBlock(world, i + 11, j + 51, k + 28, Blocks.log, 1);
		world.setBlockMetadataWithNotify(i + 11, j + 51, k + 28, 1, 2);
		setBlock(world, i + 11, j + 51, k + 29, Blocks.log, 1);
		world.setBlockMetadataWithNotify(i + 11, j + 51, k + 29, 1, 2);
		setBlock(world, i + 11, j + 51, k + 30, Blocks.log, 1);
		world.setBlockMetadataWithNotify(i + 11, j + 51, k + 30, 1, 2);
		setBlock(world, i + 11, j + 52, k + 27, Blocks.log, 1);
		world.setBlockMetadataWithNotify(i + 11, j + 52, k + 27, 1, 2);
		setBlock(world, i + 11, j + 52, k + 28, Blocks.log, 1);
		world.setBlockMetadataWithNotify(i + 11, j + 52, k + 28, 1, 2);
		setBlock(world, i + 11, j + 52, k + 29, Blocks.log, 1);
		world.setBlockMetadataWithNotify(i + 11, j + 52, k + 29, 1, 2);
		setBlock(world, i + 11, j + 53, k + 25, Blocks.log, 1);
		world.setBlockMetadataWithNotify(i + 11, j + 53, k + 25, 1, 2);
		setBlock(world, i + 11, j + 53, k + 26, Blocks.log, 1);
		world.setBlockMetadataWithNotify(i + 11, j + 53, k + 26, 1, 2);
		setBlock(world, i + 11, j + 53, k + 27, Blocks.log, 1);
		world.setBlockMetadataWithNotify(i + 11, j + 53, k + 27, 1, 2);
		setBlock(world, i + 11, j + 53, k + 28, Blocks.log, 1);
		world.setBlockMetadataWithNotify(i + 11, j + 53, k + 28, 1, 2);
		setBlock(world, i + 11, j + 53, k + 29, Blocks.log, 1);
		world.setBlockMetadataWithNotify(i + 11, j + 53, k + 29, 1, 2);
		setBlock(world, i + 11, j + 54, k + 24, Blocks.log, 1);
		world.setBlockMetadataWithNotify(i + 11, j + 54, k + 24, 1, 2);
		setBlock(world, i + 11, j + 54, k + 25, Blocks.log, 1);
		world.setBlockMetadataWithNotify(i + 11, j + 54, k + 25, 1, 2);
		setBlock(world, i + 11, j + 54, k + 26, Blocks.log, 1);
		world.setBlockMetadataWithNotify(i + 11, j + 54, k + 26, 1, 2);
		setBlock(world, i + 11, j + 54, k + 27, Blocks.log, 1);
		world.setBlockMetadataWithNotify(i + 11, j + 54, k + 27, 1, 2);
		setBlock(world, i + 11, j + 54, k + 28, Blocks.log, 1);
		world.setBlockMetadataWithNotify(i + 11, j + 54, k + 28, 1, 2);
		setBlock(world, i + 11, j + 54, k + 29, Blocks.log, 1);
		world.setBlockMetadataWithNotify(i + 11, j + 54, k + 29, 1, 2);
		setBlock(world, i + 11, j + 54, k + 30, Blocks.log, 1);
		world.setBlockMetadataWithNotify(i + 11, j + 54, k + 30, 1, 2);
		setBlock(world, i + 11, j + 54, k + 31, Blocks.log, 1);
		world.setBlockMetadataWithNotify(i + 11, j + 54, k + 31, 1, 2);
		setBlock(world, i + 11, j + 55, k + 23, Blocks.log, 1);
		world.setBlockMetadataWithNotify(i + 11, j + 55, k + 23, 1, 2);
		setBlock(world, i + 11, j + 55, k + 24, Blocks.log, 1);
		world.setBlockMetadataWithNotify(i + 11, j + 55, k + 24, 1, 2);
		setBlock(world, i + 11, j + 55, k + 25, Blocks.log, 1);
		world.setBlockMetadataWithNotify(i + 11, j + 55, k + 25, 1, 2);
		setBlock(world, i + 11, j + 55, k + 26, Blocks.log, 1);
		world.setBlockMetadataWithNotify(i + 11, j + 55, k + 26, 1, 2);
		setBlock(world, i + 11, j + 55, k + 27, Blocks.log, 1);
		world.setBlockMetadataWithNotify(i + 11, j + 55, k + 27, 1, 2);
		setBlock(world, i + 11, j + 55, k + 28, Blocks.log, 1);
		world.setBlockMetadataWithNotify(i + 11, j + 55, k + 28, 1, 2);
		setBlock(world, i + 11, j + 55, k + 29, Blocks.planks, 5);
		world.setBlockMetadataWithNotify(i + 11, j + 55, k + 29, 5, 2);
		setBlock(world, i + 11, j + 55, k + 30, Blocks.planks, 5);
		world.setBlockMetadataWithNotify(i + 11, j + 55, k + 30, 5, 2);
		setBlock(world, i + 11, j + 55, k + 31, Blocks.planks, 5);
		world.setBlockMetadataWithNotify(i + 11, j + 55, k + 31, 5, 2);
		setBlock(world, i + 11, j + 57, k + 23, Blocks.torch, 5);
		world.setBlockMetadataWithNotify(i + 11, j + 57, k + 23, 5, 2);
		setBlock(world, i + 11, j + 60, k + 20, Blocks.log, 1);
		world.setBlockMetadataWithNotify(i + 11, j + 60, k + 20, 1, 2);
		setBlock(world, i + 11, j + 60, k + 21, Blocks.log, 1);
		world.setBlockMetadataWithNotify(i + 11, j + 60, k + 21, 1, 2);
		setBlock(world, i + 11, j + 60, k + 22, Blocks.log, 1);
		world.setBlockMetadataWithNotify(i + 11, j + 60, k + 22, 1, 2);
		setBlock(world, i + 11, j + 60, k + 23, Blocks.log, 1);
		world.setBlockMetadataWithNotify(i + 11, j + 60, k + 23, 1, 2);
		setBlock(world, i + 11, j + 60, k + 24, Blocks.log, 1);
		world.setBlockMetadataWithNotify(i + 11, j + 60, k + 24, 1, 2);
		setBlock(world, i + 11, j + 60, k + 25, Blocks.log, 1);
		world.setBlockMetadataWithNotify(i + 11, j + 60, k + 25, 1, 2);
		setBlock(world, i + 11, j + 60, k + 26, Blocks.log, 1);
		world.setBlockMetadataWithNotify(i + 11, j + 60, k + 26, 1, 2);
		setBlock(world, i + 11, j + 60, k + 27, Blocks.torch, 1);
		world.setBlockMetadataWithNotify(i + 11, j + 60, k + 27, 1, 2);
		setBlock(world, i + 11, j + 61, k + 21, Blocks.log, 1);
		world.setBlockMetadataWithNotify(i + 11, j + 61, k + 21, 1, 2);
		setBlock(world, i + 11, j + 61, k + 22, Blocks.log, 1);
		world.setBlockMetadataWithNotify(i + 11, j + 61, k + 22, 1, 2);
		setBlock(world, i + 11, j + 61, k + 23, Blocks.log, 1);
		world.setBlockMetadataWithNotify(i + 11, j + 61, k + 23, 1, 2);
		setBlock(world, i + 11, j + 61, k + 24, Blocks.log, 1);
		world.setBlockMetadataWithNotify(i + 11, j + 61, k + 24, 1, 2);
		setBlock(world, i + 11, j + 61, k + 25, Blocks.log, 1);
		world.setBlockMetadataWithNotify(i + 11, j + 61, k + 25, 1, 2);
		setBlock(world, i + 11, j + 61, k + 26, Blocks.log, 1);
		world.setBlockMetadataWithNotify(i + 11, j + 61, k + 26, 1, 2);
		setBlock(world, i + 11, j + 61, k + 27, Blocks.log, 1);
		world.setBlockMetadataWithNotify(i + 11, j + 61, k + 27, 1, 2);
		setBlock(world, i + 11, j + 61, k + 28, Blocks.log, 1);
		world.setBlockMetadataWithNotify(i + 11, j + 61, k + 28, 1, 2);
		setBlock(world, i + 11, j + 61, k + 29, Blocks.log, 1);
		world.setBlockMetadataWithNotify(i + 11, j + 61, k + 29, 1, 2);
		setBlock(world, i + 11, j + 61, k + 30, Blocks.log, 1);
		world.setBlockMetadataWithNotify(i + 11, j + 61, k + 30, 1, 2);
		setBlock(world, i + 11, j + 61, k + 31, Blocks.log, 1);
		world.setBlockMetadataWithNotify(i + 11, j + 61, k + 31, 1, 2);
		setBlock(world, i + 11, j + 62, k + 24, Blocks.log, 1);
		world.setBlockMetadataWithNotify(i + 11, j + 62, k + 24, 1, 2);
		setBlock(world, i + 11, j + 62, k + 25, Blocks.log, 1);
		world.setBlockMetadataWithNotify(i + 11, j + 62, k + 25, 1, 2);
		setBlock(world, i + 11, j + 62, k + 26, Blocks.log, 1);
		world.setBlockMetadataWithNotify(i + 11, j + 62, k + 26, 1, 2);
		setBlock(world, i + 11, j + 62, k + 27, Blocks.log, 1);
		world.setBlockMetadataWithNotify(i + 11, j + 62, k + 27, 1, 2);
		setBlock(world, i + 11, j + 62, k + 28, Blocks.log, 1);
		world.setBlockMetadataWithNotify(i + 11, j + 62, k + 28, 1, 2);
		setBlock(world, i + 11, j + 62, k + 29, Blocks.log, 1);
		world.setBlockMetadataWithNotify(i + 11, j + 62, k + 29, 1, 2);
		setBlock(world, i + 11, j + 62, k + 30, Blocks.log, 1);
		world.setBlockMetadataWithNotify(i + 11, j + 62, k + 30, 1, 2);
		setBlock(world, i + 11, j + 62, k + 31, Blocks.log, 1);
		world.setBlockMetadataWithNotify(i + 11, j + 62, k + 31, 1, 2);
		setBlock(world, i + 12, j + 22, k + 25, Blocks.log, 3);
		world.setBlockMetadataWithNotify(i + 12, j + 22, k + 25, 3, 2);
		setBlock(world, i + 12, j + 24, k + 24, Blocks.log, 3);
		world.setBlockMetadataWithNotify(i + 12, j + 24, k + 24, 3, 2);
		setBlock(world, i + 12, j + 25, k + 22, Blocks.leaves, 7);
		world.setBlockMetadataWithNotify(i + 12, j + 25, k + 22, 7, 2);
		setBlock(world, i + 12, j + 25, k + 23, Blocks.leaves, 7);
		world.setBlockMetadataWithNotify(i + 12, j + 25, k + 23, 7, 2);
		setBlock(world, i + 12, j + 25, k + 24, Blocks.leaves, 7);
		world.setBlockMetadataWithNotify(i + 12, j + 25, k + 24, 7, 2);
		setBlock(world, i + 12, j + 25, k + 25, Blocks.leaves, 7);
		world.setBlockMetadataWithNotify(i + 12, j + 25, k + 25, 7, 2);
		setBlock(world, i + 12, j + 25, k + 26, Blocks.leaves, 7);
		world.setBlockMetadataWithNotify(i + 12, j + 25, k + 26, 7, 2);
		setBlock(world, i + 12, j + 25, k + 29, Blocks.log, 3);
		world.setBlockMetadataWithNotify(i + 12, j + 25, k + 29, 3, 2);
		setBlock(world, i + 12, j + 26, k + 23, Blocks.leaves, 7);
		world.setBlockMetadataWithNotify(i + 12, j + 26, k + 23, 7, 2);
		setBlock(world, i + 12, j + 26, k + 24, Blocks.leaves, 7);
		world.setBlockMetadataWithNotify(i + 12, j + 26, k + 24, 7, 2);
		setBlock(world, i + 12, j + 26, k + 25, Blocks.leaves, 7);
		world.setBlockMetadataWithNotify(i + 12, j + 26, k + 25, 7, 2);
		setBlock(world, i + 12, j + 27, k + 24, Blocks.leaves, 7);
		world.setBlockMetadataWithNotify(i + 12, j + 27, k + 24, 7, 2);
		setBlock(world, i + 12, j + 30, k + 25, Blocks.log, 3);
		world.setBlockMetadataWithNotify(i + 12, j + 30, k + 25, 3, 2);
		setBlock(world, i + 12, j + 31, k + 23, Blocks.leaves, 7);
		world.setBlockMetadataWithNotify(i + 12, j + 31, k + 23, 7, 2);
		setBlock(world, i + 12, j + 31, k + 24, Blocks.leaves, 7);
		world.setBlockMetadataWithNotify(i + 12, j + 31, k + 24, 7, 2);
		setBlock(world, i + 12, j + 31, k + 25, Blocks.leaves, 7);
		world.setBlockMetadataWithNotify(i + 12, j + 31, k + 25, 7, 2);
		setBlock(world, i + 12, j + 32, k + 19, Blocks.log, 3);
		world.setBlockMetadataWithNotify(i + 12, j + 32, k + 19, 3, 2);
		setBlock(world, i + 12, j + 32, k + 24, Blocks.leaves, 7);
		world.setBlockMetadataWithNotify(i + 12, j + 32, k + 24, 7, 2);
		setBlock(world, i + 12, j + 33, k + 24, Blocks.log, 3);
		world.setBlockMetadataWithNotify(i + 12, j + 33, k + 24, 3, 2);
		setBlock(world, i + 12, j + 34, k + 27, Blocks.log, 3);
		world.setBlockMetadataWithNotify(i + 12, j + 34, k + 27, 3, 2);
		setBlock(world, i + 12, j + 35, k + 18, Blocks.log, 3);
		world.setBlockMetadataWithNotify(i + 12, j + 35, k + 18, 3, 2);
		setBlock(world, i + 12, j + 35, k + 20, Blocks.log, 3);
		world.setBlockMetadataWithNotify(i + 12, j + 35, k + 20, 3, 2);
		setBlock(world, i + 12, j + 36, k + 25, Blocks.log, 3);
		world.setBlockMetadataWithNotify(i + 12, j + 36, k + 25, 3, 2);
		setBlock(world, i + 12, j + 37, k + 24, Blocks.leaves, 7);
		world.setBlockMetadataWithNotify(i + 12, j + 37, k + 24, 7, 2);
		setBlock(world, i + 12, j + 37, k + 25, Blocks.leaves, 7);
		world.setBlockMetadataWithNotify(i + 12, j + 37, k + 25, 7, 2);
		setBlock(world, i + 12, j + 37, k + 26, Blocks.leaves, 7);
		world.setBlockMetadataWithNotify(i + 12, j + 37, k + 26, 7, 2);
		setBlock(world, i + 12, j + 38, k + 25, Blocks.leaves, 7);
		world.setBlockMetadataWithNotify(i + 12, j + 38, k + 25, 7, 2);
		setBlock(world, i + 12, j + 43, k + 23, Blocks.log, 1);
		world.setBlockMetadataWithNotify(i + 12, j + 43, k + 23, 1, 2);
		setBlock(world, i + 12, j + 44, k + 22, Blocks.log, 1);
		world.setBlockMetadataWithNotify(i + 12, j + 44, k + 22, 1, 2);
		setBlock(world, i + 12, j + 44, k + 23, Blocks.log, 1);
		world.setBlockMetadataWithNotify(i + 12, j + 44, k + 23, 1, 2);
		setBlock(world, i + 12, j + 44, k + 24, Blocks.log, 1);
		world.setBlockMetadataWithNotify(i + 12, j + 44, k + 24, 1, 2);
		setBlock(world, i + 12, j + 44, k + 25, Blocks.leaves, 7);
		world.setBlockMetadataWithNotify(i + 12, j + 44, k + 25, 7, 2);
		setBlock(world, i + 12, j + 44, k + 26, Blocks.log, 3);
		world.setBlockMetadataWithNotify(i + 12, j + 44, k + 26, 3, 2);
		setBlock(world, i + 12, j + 44, k + 27, Blocks.leaves, 7);
		world.setBlockMetadataWithNotify(i + 12, j + 44, k + 27, 7, 2);
		setBlock(world, i + 12, j + 44, k + 28, Blocks.leaves, 7);
		world.setBlockMetadataWithNotify(i + 12, j + 44, k + 28, 7, 2);
		setBlock(world, i + 12, j + 45, k + 22, Blocks.log, 1);
		world.setBlockMetadataWithNotify(i + 12, j + 45, k + 22, 1, 2);
		setBlock(world, i + 12, j + 45, k + 23, Blocks.log, 1);
		world.setBlockMetadataWithNotify(i + 12, j + 45, k + 23, 1, 2);
		setBlock(world, i + 12, j + 45, k + 24, Blocks.log, 1);
		world.setBlockMetadataWithNotify(i + 12, j + 45, k + 24, 1, 2);
		setBlock(world, i + 12, j + 45, k + 25, Blocks.log, 1);
		world.setBlockMetadataWithNotify(i + 12, j + 45, k + 25, 1, 2);
		setBlock(world, i + 12, j + 45, k + 26, Blocks.leaves, 7);
		world.setBlockMetadataWithNotify(i + 12, j + 45, k + 26, 7, 2);
		setBlock(world, i + 12, j + 45, k + 27, Blocks.leaves, 7);
		world.setBlockMetadataWithNotify(i + 12, j + 45, k + 27, 7, 2);
		setBlock(world, i + 12, j + 45, k + 28, Blocks.leaves, 7);
		world.setBlockMetadataWithNotify(i + 12, j + 45, k + 28, 7, 2);
		setBlock(world, i + 12, j + 46, k + 23, Blocks.log, 1);
		world.setBlockMetadataWithNotify(i + 12, j + 46, k + 23, 1, 2);
		setBlock(world, i + 12, j + 46, k + 24, Blocks.log, 1);
		world.setBlockMetadataWithNotify(i + 12, j + 46, k + 24, 1, 2);
		setBlock(world, i + 12, j + 46, k + 25, Blocks.leaves, 7);
		world.setBlockMetadataWithNotify(i + 12, j + 46, k + 25, 7, 2);
		setBlock(world, i + 12, j + 46, k + 26, Blocks.leaves, 7);
		world.setBlockMetadataWithNotify(i + 12, j + 46, k + 26, 7, 2);
		setBlock(world, i + 12, j + 46, k + 27, Blocks.leaves, 7);
		world.setBlockMetadataWithNotify(i + 12, j + 46, k + 27, 7, 2);
		setBlock(world, i + 12, j + 47, k + 22, Blocks.log, 1);
		world.setBlockMetadataWithNotify(i + 12, j + 47, k + 22, 1, 2);
		setBlock(world, i + 12, j + 47, k + 24, Blocks.leaves, 7);
		world.setBlockMetadataWithNotify(i + 12, j + 47, k + 24, 7, 2);
		setBlock(world, i + 12, j + 47, k + 26, Blocks.leaves, 7);
		world.setBlockMetadataWithNotify(i + 12, j + 47, k + 26, 7, 2);
		setBlock(world, i + 12, j + 47, k + 31, Blocks.log, 1);
		world.setBlockMetadataWithNotify(i + 12, j + 47, k + 31, 1, 2);
		setBlock(world, i + 12, j + 48, k + 21, Blocks.log, 1);
		world.setBlockMetadataWithNotify(i + 12, j + 48, k + 21, 1, 2);
		setBlock(world, i + 12, j + 48, k + 22, Blocks.log, 1);
		world.setBlockMetadataWithNotify(i + 12, j + 48, k + 22, 1, 2);
		setBlock(world, i + 12, j + 48, k + 23, Blocks.log, 1);
		world.setBlockMetadataWithNotify(i + 12, j + 48, k + 23, 1, 2);
		setBlock(world, i + 12, j + 48, k + 30, Blocks.log, 1);
		world.setBlockMetadataWithNotify(i + 12, j + 48, k + 30, 1, 2);
		setBlock(world, i + 12, j + 48, k + 31, Blocks.log, 1);
		world.setBlockMetadataWithNotify(i + 12, j + 48, k + 31, 1, 2);
		setBlock(world, i + 12, j + 49, k + 20, Blocks.log, 1);
		world.setBlockMetadataWithNotify(i + 12, j + 49, k + 20, 1, 2);
		setBlock(world, i + 12, j + 49, k + 21, Blocks.log, 1);
		world.setBlockMetadataWithNotify(i + 12, j + 49, k + 21, 1, 2);
		setBlock(world, i + 12, j + 49, k + 22, Blocks.log, 1);
		world.setBlockMetadataWithNotify(i + 12, j + 49, k + 22, 1, 2);
		setBlock(world, i + 12, j + 49, k + 31, Blocks.log, 1);
		world.setBlockMetadataWithNotify(i + 12, j + 49, k + 31, 1, 2);
		setBlock(world, i + 12, j + 50, k + 21, Blocks.log, 1);
		world.setBlockMetadataWithNotify(i + 12, j + 50, k + 21, 1, 2);
		setBlock(world, i + 12, j + 50, k + 28, Blocks.log, 1);
		world.setBlockMetadataWithNotify(i + 12, j + 50, k + 28, 1, 2);
		setBlock(world, i + 12, j + 50, k + 29, Blocks.log, 1);
		world.setBlockMetadataWithNotify(i + 12, j + 50, k + 29, 1, 2);
		setBlock(world, i + 12, j + 50, k + 30, Blocks.log, 1);
		world.setBlockMetadataWithNotify(i + 12, j + 50, k + 30, 1, 2);
		setBlock(world, i + 12, j + 51, k + 27, Blocks.log, 1);
		world.setBlockMetadataWithNotify(i + 12, j + 51, k + 27, 1, 2);
		setBlock(world, i + 12, j + 51, k + 28, Blocks.log, 1);
		world.setBlockMetadataWithNotify(i + 12, j + 51, k + 28, 1, 2);
		setBlock(world, i + 12, j + 51, k + 29, Blocks.log, 1);
		world.setBlockMetadataWithNotify(i + 12, j + 51, k + 29, 1, 2);
		setBlock(world, i + 12, j + 51, k + 30, Blocks.log, 1);
		world.setBlockMetadataWithNotify(i + 12, j + 51, k + 30, 1, 2);
		setBlock(world, i + 12, j + 51, k + 31, Blocks.log, 1);
		world.setBlockMetadataWithNotify(i + 12, j + 51, k + 31, 1, 2);
		setBlock(world, i + 12, j + 52, k + 26, Blocks.log, 1);
		world.setBlockMetadataWithNotify(i + 12, j + 52, k + 26, 1, 2);
		setBlock(world, i + 12, j + 52, k + 27, Blocks.log, 1);
		world.setBlockMetadataWithNotify(i + 12, j + 52, k + 27, 1, 2);
		setBlock(world, i + 12, j + 52, k + 28, Blocks.log, 1);
		world.setBlockMetadataWithNotify(i + 12, j + 52, k + 28, 1, 2);
		setBlock(world, i + 12, j + 52, k + 29, Blocks.log, 1);
		world.setBlockMetadataWithNotify(i + 12, j + 52, k + 29, 1, 2);
		setBlock(world, i + 12, j + 52, k + 30, Blocks.log, 1);
		world.setBlockMetadataWithNotify(i + 12, j + 52, k + 30, 1, 2);
		setBlock(world, i + 12, j + 52, k + 31, Blocks.log, 1);
		world.setBlockMetadataWithNotify(i + 12, j + 52, k + 31, 1, 2);
		setBlock(world, i + 12, j + 53, k + 23, Blocks.log, 1);
		world.setBlockMetadataWithNotify(i + 12, j + 53, k + 23, 1, 2);
		setBlock(world, i + 12, j + 53, k + 24, Blocks.log, 1);
		world.setBlockMetadataWithNotify(i + 12, j + 53, k + 24, 1, 2);
		setBlock(world, i + 12, j + 53, k + 25, Blocks.log, 1);
		world.setBlockMetadataWithNotify(i + 12, j + 53, k + 25, 1, 2);
		setBlock(world, i + 12, j + 53, k + 26, Blocks.log, 1);
		world.setBlockMetadataWithNotify(i + 12, j + 53, k + 26, 1, 2);
		setBlock(world, i + 12, j + 53, k + 27, Blocks.log, 1);
		world.setBlockMetadataWithNotify(i + 12, j + 53, k + 27, 1, 2);
		setBlock(world, i + 12, j + 53, k + 28, Blocks.log, 1);
		world.setBlockMetadataWithNotify(i + 12, j + 53, k + 28, 1, 2);
		setBlock(world, i + 12, j + 53, k + 29, Blocks.log, 1);
		world.setBlockMetadataWithNotify(i + 12, j + 53, k + 29, 1, 2);
		setBlock(world, i + 12, j + 53, k + 30, Blocks.log, 1);
		world.setBlockMetadataWithNotify(i + 12, j + 53, k + 30, 1, 2);
		setBlock(world, i + 12, j + 53, k + 31, Blocks.log, 1);
		world.setBlockMetadataWithNotify(i + 12, j + 53, k + 31, 1, 2);
		setBlock(world, i + 12, j + 54, k + 22, Blocks.log, 1);
		world.setBlockMetadataWithNotify(i + 12, j + 54, k + 22, 1, 2);
		setBlock(world, i + 12, j + 54, k + 23, Blocks.log, 1);
		world.setBlockMetadataWithNotify(i + 12, j + 54, k + 23, 1, 2);
		setBlock(world, i + 12, j + 54, k + 24, Blocks.log, 1);
		world.setBlockMetadataWithNotify(i + 12, j + 54, k + 24, 1, 2);
		setBlock(world, i + 12, j + 54, k + 25, Blocks.log, 1);
		world.setBlockMetadataWithNotify(i + 12, j + 54, k + 25, 1, 2);
		setBlock(world, i + 12, j + 54, k + 26, Blocks.log, 1);
		world.setBlockMetadataWithNotify(i + 12, j + 54, k + 26, 1, 2);
		setBlock(world, i + 12, j + 54, k + 27, Blocks.log, 1);
		world.setBlockMetadataWithNotify(i + 12, j + 54, k + 27, 1, 2);
		setBlock(world, i + 12, j + 54, k + 28, Blocks.log, 1);
		world.setBlockMetadataWithNotify(i + 12, j + 54, k + 28, 1, 2);
		setBlock(world, i + 12, j + 54, k + 29, Blocks.log, 1);
		world.setBlockMetadataWithNotify(i + 12, j + 54, k + 29, 1, 2);
		setBlock(world, i + 12, j + 54, k + 30, Blocks.log, 1);
		world.setBlockMetadataWithNotify(i + 12, j + 54, k + 30, 1, 2);
		setBlock(world, i + 12, j + 54, k + 31, Blocks.log, 1);
		world.setBlockMetadataWithNotify(i + 12, j + 54, k + 31, 1, 2);
		setBlock(world, i + 12, j + 55, k + 22, Blocks.log, 1);
		world.setBlockMetadataWithNotify(i + 12, j + 55, k + 22, 1, 2);
		setBlock(world, i + 12, j + 55, k + 23, Blocks.log, 1);
		world.setBlockMetadataWithNotify(i + 12, j + 55, k + 23, 1, 2);
		setBlock(world, i + 12, j + 55, k + 24, Blocks.log, 1);
		world.setBlockMetadataWithNotify(i + 12, j + 55, k + 24, 1, 2);
		setBlock(world, i + 12, j + 55, k + 25, Blocks.log, 1);
		world.setBlockMetadataWithNotify(i + 12, j + 55, k + 25, 1, 2);
		setBlock(world, i + 12, j + 55, k + 26, Blocks.log, 1);
		world.setBlockMetadataWithNotify(i + 12, j + 55, k + 26, 1, 2);
		setBlock(world, i + 12, j + 55, k + 27, Blocks.log, 1);
		world.setBlockMetadataWithNotify(i + 12, j + 55, k + 27, 1, 2);
		setBlock(world, i + 12, j + 55, k + 28, Blocks.planks, 5);
		world.setBlockMetadataWithNotify(i + 12, j + 55, k + 28, 5, 2);
		setBlock(world, i + 12, j + 55, k + 29, Blocks.log, 1);
		world.setBlockMetadataWithNotify(i + 12, j + 55, k + 29, 1, 2);
		setBlock(world, i + 12, j + 55, k + 30, Blocks.log, 1);
		world.setBlockMetadataWithNotify(i + 12, j + 55, k + 30, 1, 2);
		setBlock(world, i + 12, j + 55, k + 31, Blocks.planks, 5);
		world.setBlockMetadataWithNotify(i + 12, j + 55, k + 31, 5, 2);
		setBlock(world, i + 12, j + 56, k + 21, Blocks.spruce_stairs, 6);
		world.setBlockMetadataWithNotify(i + 12, j + 56, k + 21, 6, 2);
		setBlock(world, i + 12, j + 56, k + 22, Blocks.log, 1);
		world.setBlockMetadataWithNotify(i + 12, j + 56, k + 22, 1, 2);
		setBlock(world, i + 12, j + 56, k + 23, Blocks.spruce_stairs, 3);
		world.setBlockMetadataWithNotify(i + 12, j + 56, k + 23, 3, 2);
		
		generate2(world, rand, i, j, k);
		return true;
		}

	
	public boolean generate2(World world, Random rand, int i, int j, int k)
	{
		setBlock(world, i + 12, j + 57, k + 20, Blocks.spruce_stairs, 6);
		world.setBlockMetadataWithNotify(i + 12, j + 57, k + 20, 6, 2);
		setBlock(world, i + 12, j + 57, k + 21, Blocks.log, 1);
		world.setBlockMetadataWithNotify(i + 12, j + 57, k + 21, 1, 2);
		setBlock(world, i + 12, j + 57, k + 22, Blocks.log, 1);
		world.setBlockMetadataWithNotify(i + 12, j + 57, k + 22, 1, 2);
		setBlock(world, i + 12, j + 58, k + 20, Blocks.log, 1);
		world.setBlockMetadataWithNotify(i + 12, j + 58, k + 20, 1, 2);
		setBlock(world, i + 12, j + 58, k + 21, Blocks.log, 1);
		world.setBlockMetadataWithNotify(i + 12, j + 58, k + 21, 1, 2);
		setBlock(world, i + 12, j + 59, k + 20, Blocks.log, 1);
		world.setBlockMetadataWithNotify(i + 12, j + 59, k + 20, 1, 2);
		setBlock(world, i + 12, j + 60, k + 19, Blocks.log, 1);
		world.setBlockMetadataWithNotify(i + 12, j + 60, k + 19, 1, 2);
		setBlock(world, i + 12, j + 60, k + 20, Blocks.log, 1);
		world.setBlockMetadataWithNotify(i + 12, j + 60, k + 20, 1, 2);
		setBlock(world, i + 12, j + 60, k + 21, Blocks.log, 1);
		world.setBlockMetadataWithNotify(i + 12, j + 60, k + 21, 1, 2);
		setBlock(world, i + 12, j + 60, k + 22, Blocks.log, 1);
		world.setBlockMetadataWithNotify(i + 12, j + 60, k + 22, 1, 2);
		setBlock(world, i + 12, j + 60, k + 23, Blocks.log, 1);
		world.setBlockMetadataWithNotify(i + 12, j + 60, k + 23, 1, 2);
		setBlock(world, i + 12, j + 60, k + 24, Blocks.log, 1);
		world.setBlockMetadataWithNotify(i + 12, j + 60, k + 24, 1, 2);
		setBlock(world, i + 12, j + 60, k + 25, Blocks.log, 1);
		world.setBlockMetadataWithNotify(i + 12, j + 60, k + 25, 1, 2);
		setBlock(world, i + 12, j + 61, k + 20, Blocks.log, 1);
		world.setBlockMetadataWithNotify(i + 12, j + 61, k + 20, 1, 2);
		setBlock(world, i + 12, j + 61, k + 21, Blocks.log, 1);
		world.setBlockMetadataWithNotify(i + 12, j + 61, k + 21, 1, 2);
		setBlock(world, i + 12, j + 61, k + 22, Blocks.log, 1);
		world.setBlockMetadataWithNotify(i + 12, j + 61, k + 22, 1, 2);
		setBlock(world, i + 12, j + 61, k + 23, Blocks.log, 1);
		world.setBlockMetadataWithNotify(i + 12, j + 61, k + 23, 1, 2);
		setBlock(world, i + 12, j + 61, k + 24, Blocks.log, 1);
		world.setBlockMetadataWithNotify(i + 12, j + 61, k + 24, 1, 2);
		setBlock(world, i + 12, j + 61, k + 25, Blocks.log, 1);
		world.setBlockMetadataWithNotify(i + 12, j + 61, k + 25, 1, 2);
		setBlock(world, i + 12, j + 61, k + 26, Blocks.log, 1);
		world.setBlockMetadataWithNotify(i + 12, j + 61, k + 26, 1, 2);
		setBlock(world, i + 12, j + 62, k + 23, Blocks.log, 1);
		world.setBlockMetadataWithNotify(i + 12, j + 62, k + 23, 1, 2);
		setBlock(world, i + 12, j + 62, k + 24, Blocks.log, 1);
		world.setBlockMetadataWithNotify(i + 12, j + 62, k + 24, 1, 2);
		setBlock(world, i + 12, j + 62, k + 25, Blocks.log, 1);
		world.setBlockMetadataWithNotify(i + 12, j + 62, k + 25, 1, 2);
		setBlock(world, i + 12, j + 62, k + 26, Blocks.log, 1);
		world.setBlockMetadataWithNotify(i + 12, j + 62, k + 26, 1, 2);
		setBlock(world, i + 12, j + 62, k + 27, Blocks.log, 1);
		world.setBlockMetadataWithNotify(i + 12, j + 62, k + 27, 1, 2);
		setBlock(world, i + 12, j + 62, k + 28, Blocks.log, 1);
		world.setBlockMetadataWithNotify(i + 12, j + 62, k + 28, 1, 2);
		setBlock(world, i + 12, j + 62, k + 29, Blocks.log, 1);
		world.setBlockMetadataWithNotify(i + 12, j + 62, k + 29, 1, 2);
		setBlock(world, i + 12, j + 62, k + 30, Blocks.log, 1);
		world.setBlockMetadataWithNotify(i + 12, j + 62, k + 30, 1, 2);
		setBlock(world, i + 12, j + 62, k + 31, Blocks.log, 1);
		world.setBlockMetadataWithNotify(i + 12, j + 62, k + 31, 1, 2);
		setBlock(world, i + 12, j + 63, k + 28, Blocks.log, 1);
		world.setBlockMetadataWithNotify(i + 12, j + 63, k + 28, 1, 2);
		setBlock(world, i + 12, j + 63, k + 29, Blocks.log, 1);
		world.setBlockMetadataWithNotify(i + 12, j + 63, k + 29, 1, 2);
		setBlock(world, i + 12, j + 63, k + 30, Blocks.log, 1);
		world.setBlockMetadataWithNotify(i + 12, j + 63, k + 30, 1, 2);
		setBlock(world, i + 12, j + 63, k + 31, Blocks.log, 1);
		world.setBlockMetadataWithNotify(i + 12, j + 63, k + 31, 1, 2);
		setBlock(world, i + 13, j + 22, k + 26, Blocks.log, 3);
		world.setBlockMetadataWithNotify(i + 13, j + 22, k + 26, 3, 2);
		setBlock(world, i + 13, j + 23, k + 1, Blocks.leaves, 7);
		world.setBlockMetadataWithNotify(i + 13, j + 23, k + 1, 7, 2);
		setBlock(world, i + 13, j + 23, k + 2, Blocks.leaves, 7);
