/*      */package com.parzivail.pswm.world.gen.wookietree;

/*      */
/*      *//*      */
/*      */
import com.parzivail.pswm.utils.LootGenUtils;
import com.parzivail.pswm.utils.NPCType;
import com.parzivail.pswm.utils.SpawnUtils;


/*      */
import cpw.mods.fml.common.IWorldGenerator;


/*      */
import java.util.Random;


/*      */
import net.minecraft.block.Block;
/*      */
import net.minecraft.init.Blocks;
/*      */
import net.minecraft.tileentity.TileEntityChest;
/*      */
import net.minecraft.world.World;
/*      */
import net.minecraft.world.WorldProvider;
/*      */
import net.minecraft.world.chunk.IChunkProvider;
/*      */
import net.minecraft.world.gen.feature.WorldGenerator;

/*      */
/*      */public class WT_01
/*      */extends WorldGenerator implements IWorldGenerator
/*      */
{
	/*      */protected Block[] getValidSpawnBlocks()
	/*      */
	{
		return new Block[0];
		/*      */}

	/*      */
	/*      */public boolean locationIsValidSpawn(World world, int i, int j, int k)
	/*      */
	{
		int distanceToAir = 0;
		Block check = world.getBlock(i, j, k);
		/*      */
		while (check != Blocks.air)
		{
			if (distanceToAir > 3) { return false;
			/*      */}
			/*      */
			distanceToAir++;
			check = world.getBlock(i, j + distanceToAir, k);
			/*      */}
		/*      */
		j += distanceToAir - 1;
		/*      */
		Block block = world.getBlock(i, j, k);
		Block blockAbove = world.getBlock(i, j + 1, k);
		Block blockBelow = world.getBlock(i, j - 1, k);
		/*      */
		for (Block x : getValidSpawnBlocks())
		{
			if (blockAbove != Blocks.air) { return false;
			/*      */}
			if (block == x) return true;
			if ((block == Blocks.snow) && (blockBelow == x)) { return true;
			/*      */}
			/*      */}
		/*      */
		return false;
		/*      */}

	/*      */
	/*      */
	/*      */
	/*      */public void generate(Random random, int chunkX, int chunkZ, World world, IChunkProvider chunkGenerator, IChunkProvider chunkProvider)
	{
	}

	/*      */
	/*      */
	/*      */public void setBlock(World world, int x, int y, int z, Block block, int metadata)
	/*      */
	{
		world.setBlock(x, y, z, block, metadata, 2);
		/*      */}

	/*      */
	/*      */public boolean generate(World world, Random rand, int i, int j, int k)
	/*      */
	{
		k -= 10;
		i -= 10;
		/*      */
		setBlock(world, i + 7, j + 59, k + 4, Blocks.fence, 0);
		setBlock(world, i + 8, j + 59, k + 4, Blocks.fence, 0);
		setBlock(world, i + 8, j + 59, k + 5, Blocks.fence, 0);
		setBlock(world, i + 8, j + 59, k + 6, Blocks.fence, 0);
		setBlock(world, i + 8, j + 59, k + 7, Blocks.fence, 0);
		setBlock(world, i + 9, j + 59, k + 7, Blocks.fence, 0);
		setBlock(world, i + 9, j + 59, k + 8, Blocks.fence, 0);
		setBlock(world, i + 9, j + 59, k + 9, Blocks.fence, 0);
		setBlock(world, i + 10, j + 56, k + 4, Blocks.fence, 0);
		setBlock(world, i + 10, j + 56, k + 5, Blocks.fence, 0);
		setBlock(world, i + 10, j + 56, k + 6, Blocks.fence, 0);
		setBlock(world, i + 10, j + 59, k + 9, Blocks.fence, 0);
		setBlock(world, i + 10, j + 59, k + 10, Blocks.fence, 0);
		setBlock(world, i + 11, j + 56, k + 6, Blocks.fence, 0);
		setBlock(world, i + 11, j + 56, k + 7, Blocks.fence, 0);
		setBlock(world, i + 11, j + 56, k + 8, Blocks.fence, 0);
		setBlock(world, i + 11, j + 59, k + 10, Blocks.fence, 0);
		setBlock(world, i + 11, j + 59, k + 11, Blocks.fence, 0);
		SpawnUtils.spawnNPC(NPCType.WOOKIETREE, world, i + 12, j + 56, k + 2);
		setBlock(world, i + 14, j + 56, k + 0, Blocks.spruce_stairs, 0);
		setBlock(world, i + 17, j + 56, k + 1, Blocks.crafting_table, 0);
		setBlock(world, i + 18, j + 56, k + 9, Blocks.spruce_stairs, 0);
		SpawnUtils.spawnNPC(NPCType.WOOKIETREE, world, i + 19, j + 56, k + 2);
		setBlock(world, i + 20, j + 56, k + 6, Blocks.fence, 0);
		setBlock(world, i + 20, j + 56, k + 7, Blocks.fence, 0);
		setBlock(world, i + 20, j + 56, k + 8, Blocks.fence, 0);
		setBlock(world, i + 20, j + 59, k + 10, Blocks.fence, 0);
		setBlock(world, i + 20, j + 59, k + 11, Blocks.fence, 0);
		setBlock(world, i + 21, j + 56, k + 3, Blocks.spruce_stairs, 0);
		setBlock(world, i + 21, j + 56, k + 4, Blocks.fence, 0);
		setBlock(world, i + 21, j + 56, k + 5, Blocks.fence, 0);
		setBlock(world, i + 21, j + 56, k + 6, Blocks.fence, 0);
		setBlock(world, i + 21, j + 59, k + 9, Blocks.fence, 0);
		setBlock(world, i + 21, j + 59, k + 10, Blocks.fence, 0);
		setBlock(world, i + 22, j + 59, k + 7, Blocks.fence, 0);
		setBlock(world, i + 22, j + 59, k + 8, Blocks.fence, 0);
		setBlock(world, i + 22, j + 59, k + 9, Blocks.fence, 0);
		setBlock(world, i + 23, j + 59, k + 4, Blocks.fence, 0);
		setBlock(world, i + 23, j + 59, k + 5, Blocks.fence, 0);
		setBlock(world, i + 23, j + 59, k + 6, Blocks.fence, 0);
		setBlock(world, i + 23, j + 59, k + 7, Blocks.fence, 0);
		setBlock(world, i + 24, j + 59, k + 4, Blocks.fence, 0);
		setBlock(world, i + 25, j + 29, k + 2, Blocks.fence, 0);
		setBlock(world, i + 25, j + 29, k + 8, Blocks.fence, 0);
		setBlock(world, i + 26, j + 29, k + 2, Blocks.fence, 0);
		setBlock(world, i + 26, j + 29, k + 8, Blocks.fence, 0);
		setBlock(world, i + 28, j + 27, k + 1, Blocks.fence, 0);
		setBlock(world, i + 28, j + 27, k + 2, Blocks.fence, 0);
		setBlock(world, i + 28, j + 27, k + 8, Blocks.fence, 0);
		setBlock(world, i + 28, j + 27, k + 9, Blocks.fence, 0);
		setBlock(world, i + 29, j + 27, k + 0, Blocks.fence, 0);
		setBlock(world, i + 29, j + 27, k + 1, Blocks.fence, 0);
		setBlock(world, i + 29, j + 27, k + 9, Blocks.fence, 0);
		setBlock(world, i + 29, j + 27, k + 10, Blocks.fence, 0);
		setBlock(world, i + 30, j + 27, k + 0, Blocks.fence, 0);
		setBlock(world, i + 30, j + 27, k + 10, Blocks.fence, 0);
		setBlock(world, i + 30, j + 27, k + 11, Blocks.spruce_stairs, 0);
		setBlock(world, i + 30, j + 29, k + 12, Blocks.fence, 0);
		setBlock(world, i + 30, j + 29, k + 13, Blocks.fence, 0);
		SpawnUtils.spawnNPC(NPCType.WOOKIETREE, world, i + 31, j + 27, k + 3);
		SpawnUtils.spawnNPC(NPCType.WOOKIETREE, world, i + 31, j + 27, k + 7);
		setBlock(world, i + 5, j + 27, k + 0, Blocks.leaves, 7);
		world.setBlockMetadataWithNotify(i + 5, j + 27, k + 0, 7, 2);
		setBlock(world, i + 6, j + 27, k + 0, Blocks.leaves, 7);
		world.setBlockMetadataWithNotify(i + 6, j + 27, k + 0, 7, 2);
		setBlock(world, i + 6, j + 28, k + 0, Blocks.leaves, 7);
		world.setBlockMetadataWithNotify(i + 6, j + 28, k + 0, 7, 2);
		setBlock(world, i + 7, j + 27, k + 0, Blocks.leaves, 7);
		world.setBlockMetadataWithNotify(i + 7, j + 27, k + 0, 7, 2);
		setBlock(world, i + 7, j + 57, k + 3, Blocks.spruce_stairs, 4);
		world.setBlockMetadataWithNotify(i + 7, j + 57, k + 3, 4, 2);
		setBlock(world, i + 7, j + 58, k + 3, Blocks.log, 1);
		world.setBlockMetadataWithNotify(i + 7, j + 58, k + 3, 1, 2);
		setBlock(world, i + 7, j + 59, k + 2, Blocks.spruce_stairs, 6);
		world.setBlockMetadataWithNotify(i + 7, j + 59, k + 2, 6, 2);
		setBlock(world, i + 7, j + 59, k + 3, Blocks.log, 1);
		world.setBlockMetadataWithNotify(i + 7, j + 59, k + 3, 1, 2);
		setBlock(world, i + 7, j + 60, k + 0, Blocks.log, 1);
		world.setBlockMetadataWithNotify(i + 7, j + 60, k + 0, 1, 2);
		setBlock(world, i + 7, j + 60, k + 1, Blocks.log, 1);
		world.setBlockMetadataWithNotify(i + 7, j + 60, k + 1, 1, 2);
		setBlock(world, i + 7, j + 60, k + 2, Blocks.log, 1);
		world.setBlockMetadataWithNotify(i + 7, j + 60, k + 2, 1, 2);
		setBlock(world, i + 7, j + 60, k + 3, Blocks.log, 1);
		world.setBlockMetadataWithNotify(i + 7, j + 60, k + 3, 1, 2);
		setBlock(world, i + 7, j + 60, k + 4, Blocks.log, 1);
		world.setBlockMetadataWithNotify(i + 7, j + 60, k + 4, 1, 2);
		setBlock(world, i + 8, j + 28, k + 4, Blocks.leaves, 7);
		world.setBlockMetadataWithNotify(i + 8, j + 28, k + 4, 7, 2);
		setBlock(world, i + 8, j + 28, k + 5, Blocks.leaves, 7);
		world.setBlockMetadataWithNotify(i + 8, j + 28, k + 5, 7, 2);
		setBlock(world, i + 8, j + 28, k + 6, Blocks.leaves, 7);
		world.setBlockMetadataWithNotify(i + 8, j + 28, k + 6, 7, 2);
		setBlock(world, i + 8, j + 29, k + 1, Blocks.leaves, 7);
		world.setBlockMetadataWithNotify(i + 8, j + 29, k + 1, 7, 2);
		setBlock(world, i + 8, j + 29, k + 2, Blocks.leaves, 7);
		world.setBlockMetadataWithNotify(i + 8, j + 29, k + 2, 7, 2);
		setBlock(world, i + 8, j + 29, k + 3, Blocks.leaves, 7);
		world.setBlockMetadataWithNotify(i + 8, j + 29, k + 3, 7, 2);
		setBlock(world, i + 8, j + 29, k + 5, Blocks.leaves, 7);
		world.setBlockMetadataWithNotify(i + 8, j + 29, k + 5, 7, 2);
		setBlock(world, i + 8, j + 30, k + 2, Blocks.leaves, 7);
		world.setBlockMetadataWithNotify(i + 8, j + 30, k + 2, 7, 2);
		setBlock(world, i + 8, j + 56, k + 3, Blocks.spruce_stairs, 4);
		world.setBlockMetadataWithNotify(i + 8, j + 56, k + 3, 4, 2);
		setBlock(world, i + 8, j + 57, k + 3, Blocks.log, 1);
		world.setBlockMetadataWithNotify(i + 8, j + 57, k + 3, 1, 2);
		setBlock(world, i + 8, j + 58, k + 2, Blocks.torch, 4);
		world.setBlockMetadataWithNotify(i + 8, j + 58, k + 2, 4, 2);
		setBlock(world, i + 8, j + 58, k + 3, Blocks.log, 1);
		world.setBlockMetadataWithNotify(i + 8, j + 58, k + 3, 1, 2);
		setBlock(world, i + 8, j + 60, k + 0, Blocks.log, 1);
		world.setBlockMetadataWithNotify(i + 8, j + 60, k + 0, 1, 2);
		setBlock(world, i + 8, j + 60, k + 1, Blocks.log, 1);
		world.setBlockMetadataWithNotify(i + 8, j + 60, k + 1, 1, 2);
		setBlock(world, i + 8, j + 60, k + 2, Blocks.log, 1);
		world.setBlockMetadataWithNotify(i + 8, j + 60, k + 2, 1, 2);
		setBlock(world, i + 8, j + 60, k + 3, Blocks.log, 1);
		world.setBlockMetadataWithNotify(i + 8, j + 60, k + 3, 1, 2);
		setBlock(world, i + 8, j + 60, k + 4, Blocks.log, 1);
		world.setBlockMetadataWithNotify(i + 8, j + 60, k + 4, 1, 2);
		setBlock(world, i + 8, j + 60, k + 5, Blocks.log, 1);
		world.setBlockMetadataWithNotify(i + 8, j + 60, k + 5, 1, 2);
		setBlock(world, i + 8, j + 60, k + 6, Blocks.log, 1);
		world.setBlockMetadataWithNotify(i + 8, j + 60, k + 6, 1, 2);
		setBlock(world, i + 8, j + 60, k + 7, Blocks.log, 1);
		world.setBlockMetadataWithNotify(i + 8, j + 60, k + 7, 1, 2);
		setBlock(world, i + 8, j + 61, k + 0, Blocks.log, 1);
		world.setBlockMetadataWithNotify(i + 8, j + 61, k + 0, 1, 2);
		setBlock(world, i + 8, j + 61, k + 1, Blocks.log, 1);
		world.setBlockMetadataWithNotify(i + 8, j + 61, k + 1, 1, 2);
		setBlock(world, i + 8, j + 61, k + 2, Blocks.log, 1);
		world.setBlockMetadataWithNotify(i + 8, j + 61, k + 2, 1, 2);
		setBlock(world, i + 8, j + 61, k + 3, Blocks.log, 1);
		world.setBlockMetadataWithNotify(i + 8, j + 61, k + 3, 1, 2);
		setBlock(world, i + 8, j + 61, k + 4, Blocks.log, 1);
		world.setBlockMetadataWithNotify(i + 8, j + 61, k + 4, 1, 2);
		setBlock(world, i + 8, j + 61, k + 5, Blocks.log, 1);
		world.setBlockMetadataWithNotify(i + 8, j + 61, k + 5, 1, 2);
		setBlock(world, i + 9, j + 28, k + 3, Blocks.leaves, 7);
		world.setBlockMetadataWithNotify(i + 9, j + 28, k + 3, 7, 2);
		setBlock(world, i + 9, j + 28, k + 4, Blocks.leaves, 7);
		world.setBlockMetadataWithNotify(i + 9, j + 28, k + 4, 7, 2);
		setBlock(world, i + 9, j + 28, k + 5, Blocks.leaves, 7);
		world.setBlockMetadataWithNotify(i + 9, j + 28, k + 5, 7, 2);
		setBlock(world, i + 9, j + 28, k + 6, Blocks.leaves, 7);
		world.setBlockMetadataWithNotify(i + 9, j + 28, k + 6, 7, 2);
		setBlock(world, i + 9, j + 28, k + 7, Blocks.leaves, 7);
		world.setBlockMetadataWithNotify(i + 9, j + 28, k + 7, 7, 2);
		setBlock(world, i + 9, j + 29, k + 0, Blocks.leaves, 7);
		world.setBlockMetadataWithNotify(i + 9, j + 29, k + 0, 7, 2);
		setBlock(world, i + 9, j + 29, k + 1, Blocks.leaves, 7);
		world.setBlockMetadataWithNotify(i + 9, j + 29, k + 1, 7, 2);
		setBlock(world, i + 9, j + 29, k + 2, Blocks.leaves, 7);
		world.setBlockMetadataWithNotify(i + 9, j + 29, k + 2, 7, 2);
		setBlock(world, i + 9, j + 29, k + 3, Blocks.leaves, 7);
		world.setBlockMetadataWithNotify(i + 9, j + 29, k + 3, 7, 2);
		setBlock(world, i + 9, j + 29, k + 4, Blocks.leaves, 7);
		world.setBlockMetadataWithNotify(i + 9, j + 29, k + 4, 7, 2);
		setBlock(world, i + 9, j + 29, k + 5, Blocks.leaves, 7);
		world.setBlockMetadataWithNotify(i + 9, j + 29, k + 5, 7, 2);
		setBlock(world, i + 9, j + 29, k + 6, Blocks.leaves, 7);
		world.setBlockMetadataWithNotify(i + 9, j + 29, k + 6, 7, 2);
		setBlock(world, i + 9, j + 30, k + 1, Blocks.leaves, 7);
		world.setBlockMetadataWithNotify(i + 9, j + 30, k + 1, 7, 2);
		setBlock(world, i + 9, j + 30, k + 2, Blocks.leaves, 7);
		world.setBlockMetadataWithNotify(i + 9, j + 30, k + 2, 7, 2);
		setBlock(world, i + 9, j + 30, k + 3, Blocks.leaves, 7);
		world.setBlockMetadataWithNotify(i + 9, j + 30, k + 3, 7, 2);
		setBlock(world, i + 9, j + 30, k + 5, Blocks.leaves, 7);
		world.setBlockMetadataWithNotify(i + 9, j + 30, k + 5, 7, 2);
		setBlock(world, i + 9, j + 31, k + 2, Blocks.leaves, 7);
		world.setBlockMetadataWithNotify(i + 9, j + 31, k + 2, 7, 2);
		setBlock(world, i + 9, j + 54, k + 0, Blocks.log, 1);
		world.setBlockMetadataWithNotify(i + 9, j + 54, k + 0, 1, 2);
		setBlock(world, i + 9, j + 54, k + 1, Blocks.log, 1);
		world.setBlockMetadataWithNotify(i + 9, j + 54, k + 1, 1, 2);
		setBlock(world, i + 9, j + 54, k + 2, Blocks.log, 1);
		world.setBlockMetadataWithNotify(i + 9, j + 54, k + 2, 1, 2);
		/*      */
		generate92(world, rand, i, j, k);
		return true;
		/*      */}

	/*      */
	/*      */public boolean generate92(World world, Random rand, int i, int j, int k)
	/*      */
	{
		setBlock(world, i + 9, j + 55, k + 0, Blocks.log, 1);
		world.setBlockMetadataWithNotify(i + 9, j + 55, k + 0, 1, 2);
		setBlock(world, i + 9, j + 55, k + 1, Blocks.log, 1);
		world.setBlockMetadataWithNotify(i + 9, j + 55, k + 1, 1, 2);
		setBlock(world, i + 9, j + 55, k + 2, Blocks.log, 1);
		world.setBlockMetadataWithNotify(i + 9, j + 55, k + 2, 1, 2);
		setBlock(world, i + 9, j + 55, k + 3, Blocks.log, 1);
		world.setBlockMetadataWithNotify(i + 9, j + 55, k + 3, 1, 2);
		setBlock(world, i + 9, j + 56, k + 3, Blocks.log, 1);
		world.setBlockMetadataWithNotify(i + 9, j + 56, k + 3, 1, 2);
		setBlock(world, i + 9, j + 57, k + 3, Blocks.log, 1);
		world.setBlockMetadataWithNotify(i + 9, j + 57, k + 3, 1, 2);
		setBlock(world, i + 9, j + 60, k + 0, Blocks.log, 1);
		world.setBlockMetadataWithNotify(i + 9, j + 60, k + 0, 1, 2);
		setBlock(world, i + 9, j + 60, k + 1, Blocks.log, 1);
		world.setBlockMetadataWithNotify(i + 9, j + 60, k + 1, 1, 2);
		setBlock(world, i + 9, j + 60, k + 2, Blocks.log, 1);
		world.setBlockMetadataWithNotify(i + 9, j + 60, k + 2, 1, 2);
		setBlock(world, i + 9, j + 60, k + 3, Blocks.log, 1);
		world.setBlockMetadataWithNotify(i + 9, j + 60, k + 3, 1, 2);
		setBlock(world, i + 9, j + 60, k + 4, Blocks.log, 1);
		world.setBlockMetadataWithNotify(i + 9, j + 60, k + 4, 1, 2);
		setBlock(world, i + 9, j + 60, k + 5, Blocks.log, 1);
		world.setBlockMetadataWithNotify(i + 9, j + 60, k + 5, 1, 2);
		setBlock(world, i + 9, j + 60, k + 6, Blocks.log, 1);
		world.setBlockMetadataWithNotify(i + 9, j + 60, k + 6, 1, 2);
		setBlock(world, i + 9, j + 60, k + 7, Blocks.log, 1);
		world.setBlockMetadataWithNotify(i + 9, j + 60, k + 7, 1, 2);
		setBlock(world, i + 9, j + 60, k + 8, Blocks.log, 1);
		world.setBlockMetadataWithNotify(i + 9, j + 60, k + 8, 1, 2);
		setBlock(world, i + 9, j + 60, k + 9, Blocks.log, 1);
		world.setBlockMetadataWithNotify(i + 9, j + 60, k + 9, 1, 2);
		setBlock(world, i + 9, j + 61, k + 0, Blocks.log, 1);
		world.setBlockMetadataWithNotify(i + 9, j + 61, k + 0, 1, 2);
		setBlock(world, i + 9, j + 61, k + 1, Blocks.log, 1);
		world.setBlockMetadataWithNotify(i + 9, j + 61, k + 1, 1, 2);
		setBlock(world, i + 9, j + 61, k + 2, Blocks.log, 1);
		world.setBlockMetadataWithNotify(i + 9, j + 61, k + 2, 1, 2);
		setBlock(world, i + 9, j + 61, k + 3, Blocks.log, 1);
		world.setBlockMetadataWithNotify(i + 9, j + 61, k + 3, 1, 2);
		setBlock(world, i + 9, j + 61, k + 4, Blocks.log, 1);
		world.setBlockMetadataWithNotify(i + 9, j + 61, k + 4, 1, 2);
		setBlock(world, i + 9, j + 61, k + 5, Blocks.log, 1);
		world.setBlockMetadataWithNotify(i + 9, j + 61, k + 5, 1, 2);
		setBlock(world, i + 9, j + 61, k + 6, Blocks.log, 1);
		world.setBlockMetadataWithNotify(i + 9, j + 61, k + 6, 1, 2);
		setBlock(world, i + 9, j + 61, k + 7, Blocks.log, 1);
		world.setBlockMetadataWithNotify(i + 9, j + 61, k + 7, 1, 2);
		setBlock(world, i + 9, j + 62, k + 0, Blocks.log, 1);
		world.setBlockMetadataWithNotify(i + 9, j + 62, k + 0, 1, 2);
		setBlock(world, i + 9, j + 62, k + 1, Blocks.log, 1);
		world.setBlockMetadataWithNotify(i + 9, j + 62, k + 1, 1, 2);
		setBlock(world, i + 9, j + 62, k + 2, Blocks.log, 1);
		world.setBlockMetadataWithNotify(i + 9, j + 62, k + 2, 1, 2);
		setBlock(world, i + 9, j + 62, k + 3, Blocks.log, 1);
		world.setBlockMetadataWithNotify(i + 9, j + 62, k + 3, 1, 2);
		setBlock(world, i + 10, j + 27, k + 4, Blocks.log, 3);
		world.setBlockMetadataWithNotify(i + 10, j + 27, k + 4, 3, 2);
		setBlock(world, i + 10, j + 28, k + 3, Blocks.leaves, 7);
		world.setBlockMetadataWithNotify(i + 10, j + 28, k + 3, 7, 2);
		setBlock(world, i + 10, j + 28, k + 4, Blocks.leaves, 7);
		world.setBlockMetadataWithNotify(i + 10, j + 28, k + 4, 7, 2);
		setBlock(world, i + 10, j + 28, k + 5, Blocks.log, 3);
		world.setBlockMetadataWithNotify(i + 10, j + 28, k + 5, 3, 2);
		setBlock(world, i + 10, j + 28, k + 6, Blocks.leaves, 7);
		world.setBlockMetadataWithNotify(i + 10, j + 28, k + 6, 7, 2);
		setBlock(world, i + 10, j + 28, k + 7, Blocks.leaves, 7);
		world.setBlockMetadataWithNotify(i + 10, j + 28, k + 7, 7, 2);
		setBlock(world, i + 10, j + 29, k + 0, Blocks.leaves, 7);
		world.setBlockMetadataWithNotify(i + 10, j + 29, k + 0, 7, 2);
		setBlock(world, i + 10, j + 29, k + 1, Blocks.leaves, 7);
		world.setBlockMetadataWithNotify(i + 10, j + 29, k + 1, 7, 2);
		setBlock(world, i + 10, j + 29, k + 2, Blocks.log, 3);
		world.setBlockMetadataWithNotify(i + 10, j + 29, k + 2, 3, 2);
		setBlock(world, i + 10, j + 29, k + 3, Blocks.leaves, 7);
		world.setBlockMetadataWithNotify(i + 10, j + 29, k + 3, 7, 2);
		setBlock(world, i + 10, j + 29, k + 4, Blocks.leaves, 7);
		world.setBlockMetadataWithNotify(i + 10, j + 29, k + 4, 7, 2);
		setBlock(world, i + 10, j + 29, k + 5, Blocks.leaves, 7);
		world.setBlockMetadataWithNotify(i + 10, j + 29, k + 5, 7, 2);
		setBlock(world, i + 10, j + 29, k + 6, Blocks.leaves, 7);
		world.setBlockMetadataWithNotify(i + 10, j + 29, k + 6, 7, 2);
		setBlock(world, i + 10, j + 29, k + 7, Blocks.leaves, 7);
		world.setBlockMetadataWithNotify(i + 10, j + 29, k + 7, 7, 2);
		setBlock(world, i + 10, j + 30, k + 0, Blocks.leaves, 7);
		world.setBlockMetadataWithNotify(i + 10, j + 30, k + 0, 7, 2);
		setBlock(world, i + 10, j + 30, k + 1, Blocks.leaves, 7);
		world.setBlockMetadataWithNotify(i + 10, j + 30, k + 1, 7, 2);
		setBlock(world, i + 10, j + 30, k + 2, Blocks.leaves, 7);
		world.setBlockMetadataWithNotify(i + 10, j + 30, k + 2, 7, 2);
		setBlock(world, i + 10, j + 30, k + 3, Blocks.leaves, 7);
		world.setBlockMetadataWithNotify(i + 10, j + 30, k + 3, 7, 2);
		setBlock(world, i + 10, j + 30, k + 4, Blocks.leaves, 7);
		world.setBlockMetadataWithNotify(i + 10, j + 30, k + 4, 7, 2);
		setBlock(world, i + 10, j + 30, k + 5, Blocks.leaves, 7);
		world.setBlockMetadataWithNotify(i + 10, j + 30, k + 5, 7, 2);
		setBlock(world, i + 10, j + 30, k + 6, Blocks.leaves, 7);
		world.setBlockMetadataWithNotify(i + 10, j + 30, k + 6, 7, 2);
		setBlock(world, i + 10, j + 31, k + 1, Blocks.leaves, 7);
		world.setBlockMetadataWithNotify(i + 10, j + 31, k + 1, 7, 2);
		setBlock(world, i + 10, j + 31, k + 2, Blocks.leaves, 7);
		world.setBlockMetadataWithNotify(i + 10, j + 31, k + 2, 7, 2);
		setBlock(world, i + 10, j + 31, k + 3, Blocks.leaves, 7);
		world.setBlockMetadataWithNotify(i + 10, j + 31, k + 3, 7, 2);
		setBlock(world, i + 10, j + 31, k + 5, Blocks.leaves, 7);
		world.setBlockMetadataWithNotify(i + 10, j + 31, k + 5, 7, 2);
		setBlock(world, i + 10, j + 32, k + 2, Blocks.leaves, 7);
		world.setBlockMetadataWithNotify(i + 10, j + 32, k + 2, 7, 2);
		setBlock(world, i + 10, j + 52, k + 2, Blocks.log, 1);
		world.setBlockMetadataWithNotify(i + 10, j + 52, k + 2, 1, 2);
		setBlock(world, i + 10, j + 52, k + 3, Blocks.log, 1);
		world.setBlockMetadataWithNotify(i + 10, j + 52, k + 3, 1, 2);
		setBlock(world, i + 10, j + 53, k + 1, Blocks.log, 1);
		world.setBlockMetadataWithNotify(i + 10, j + 53, k + 1, 1, 2);
		setBlock(world, i + 10, j + 53, k + 2, Blocks.log, 1);
		world.setBlockMetadataWithNotify(i + 10, j + 53, k + 2, 1, 2);
		setBlock(world, i + 10, j + 53, k + 3, Blocks.log, 1);
		world.setBlockMetadataWithNotify(i + 10, j + 53, k + 3, 1, 2);
		setBlock(world, i + 10, j + 53, k + 4, Blocks.log, 1);
		world.setBlockMetadataWithNotify(i + 10, j + 53, k + 4, 1, 2);
		setBlock(world, i + 10, j + 54, k + 0, Blocks.log, 1);
		world.setBlockMetadataWithNotify(i + 10, j + 54, k + 0, 1, 2);
		setBlock(world, i + 10, j + 54, k + 1, Blocks.log, 1);
		world.setBlockMetadataWithNotify(i + 10, j + 54, k + 1, 1, 2);
		setBlock(world, i + 10, j + 54, k + 2, Blocks.log, 1);
		world.setBlockMetadataWithNotify(i + 10, j + 54, k + 2, 1, 2);
		setBlock(world, i + 10, j + 54, k + 3, Blocks.log, 1);
		world.setBlockMetadataWithNotify(i + 10, j + 54, k + 3, 1, 2);
		setBlock(world, i + 10, j + 55, k + 0, Blocks.planks, 5);
		world.setBlockMetadataWithNotify(i + 10, j + 55, k + 0, 5, 2);
		setBlock(world, i + 10, j + 55, k + 1, Blocks.log, 1);
		world.setBlockMetadataWithNotify(i + 10, j + 55, k + 1, 1, 2);
		setBlock(world, i + 10, j + 55, k + 2, Blocks.log, 1);
		world.setBlockMetadataWithNotify(i + 10, j + 55, k + 2, 1, 2);
		setBlock(world, i + 10, j + 55, k + 3, Blocks.log, 1);
		world.setBlockMetadataWithNotify(i + 10, j + 55, k + 3, 1, 2);
		setBlock(world, i + 10, j + 55, k + 4, Blocks.log, 1);
		world.setBlockMetadataWithNotify(i + 10, j + 55, k + 4, 1, 2);
		setBlock(world, i + 10, j + 55, k + 5, Blocks.log, 1);
		world.setBlockMetadataWithNotify(i + 10, j + 55, k + 5, 1, 2);
		setBlock(world, i + 10, j + 55, k + 6, Blocks.log, 1);
		world.setBlockMetadataWithNotify(i + 10, j + 55, k + 6, 1, 2);
		setBlock(world, i + 10, j + 56, k + 3, Blocks.spruce_stairs, 1);
		world.setBlockMetadataWithNotify(i + 10, j + 56, k + 3, 1, 2);
		setBlock(world, i + 10, j + 57, k + 4, Blocks.torch, 5);
		world.setBlockMetadataWithNotify(i + 10, j + 57, k + 4, 5, 2);
		setBlock(world, i + 10, j + 60, k + 0, Blocks.log, 1);
		world.setBlockMetadataWithNotify(i + 10, j + 60, k + 0, 1, 2);
		setBlock(world, i + 10, j + 60, k + 1, Blocks.log, 1);
		world.setBlockMetadataWithNotify(i + 10, j + 60, k + 1, 1, 2);
		setBlock(world, i + 10, j + 60, k + 2, Blocks.log, 1);
		world.setBlockMetadataWithNotify(i + 10, j + 60, k + 2, 1, 2);
		setBlock(world, i + 10, j + 60, k + 3, Blocks.log, 1);
		world.setBlockMetadataWithNotify(i + 10, j + 60, k + 3, 1, 2);
		setBlock(world, i + 10, j + 60, k + 4, Blocks.log, 1);
		world.setBlockMetadataWithNotify(i + 10, j + 60, k + 4, 1, 2);
		setBlock(world, i + 10, j + 60, k + 5, Blocks.log, 1);
		world.setBlockMetadataWithNotify(i + 10, j + 60, k + 5, 1, 2);
		setBlock(world, i + 10, j + 60, k + 6, Blocks.log, 1);
		world.setBlockMetadataWithNotify(i + 10, j + 60, k + 6, 1, 2);
		setBlock(world, i + 10, j + 60, k + 7, Blocks.log, 1);
		world.setBlockMetadataWithNotify(i + 10, j + 60, k + 7, 1, 2);
		setBlock(world, i + 10, j + 60, k + 8, Blocks.log, 1);
		world.setBlockMetadataWithNotify(i + 10, j + 60, k + 8, 1, 2);
		setBlock(world, i + 10, j + 60, k + 9, Blocks.log, 1);
		world.setBlockMetadataWithNotify(i + 10, j + 60, k + 9, 1, 2);
		setBlock(world, i + 10, j + 60, k + 10, Blocks.log, 1);
		world.setBlockMetadataWithNotify(i + 10, j + 60, k + 10, 1, 2);
		setBlock(world, i + 10, j + 61, k + 0, Blocks.log, 1);
		world.setBlockMetadataWithNotify(i + 10, j + 61, k + 0, 1, 2);
		setBlock(world, i + 10, j + 61, k + 1, Blocks.log, 1);
		world.setBlockMetadataWithNotify(i + 10, j + 61, k + 1, 1, 2);
		setBlock(world, i + 10, j + 61, k + 2, Blocks.log, 1);
		world.setBlockMetadataWithNotify(i + 10, j + 61, k + 2, 1, 2);
		setBlock(world, i + 10, j + 61, k + 3, Blocks.log, 1);
		world.setBlockMetadataWithNotify(i + 10, j + 61, k + 3, 1, 2);
		setBlock(world, i + 10, j + 61, k + 4, Blocks.log, 1);
		world.setBlockMetadataWithNotify(i + 10, j + 61, k + 4, 1, 2);
		setBlock(world, i + 10, j + 61, k + 5, Blocks.log, 1);
		world.setBlockMetadataWithNotify(i + 10, j + 61, k + 5, 1, 2);
		setBlock(world, i + 10, j + 61, k + 6, Blocks.log, 1);
		world.setBlockMetadataWithNotify(i + 10, j + 61, k + 6, 1, 2);
		setBlock(world, i + 10, j + 61, k + 7, Blocks.log, 1);
		world.setBlockMetadataWithNotify(i + 10, j + 61, k + 7, 1, 2);
		setBlock(world, i + 10, j + 61, k + 8, Blocks.log, 1);
		world.setBlockMetadataWithNotify(i + 10, j + 61, k + 8, 1, 2);
		setBlock(world, i + 10, j + 61, k + 9, Blocks.log, 1);
		world.setBlockMetadataWithNotify(i + 10, j + 61, k + 9, 1, 2);
		setBlock(world, i + 10, j + 62, k + 0, Blocks.log, 1);
		world.setBlockMetadataWithNotify(i + 10, j + 62, k + 0, 1, 2);
		setBlock(world, i + 10, j + 62, k + 1, Blocks.log, 1);
		world.setBlockMetadataWithNotify(i + 10, j + 62, k + 1, 1, 2);
		setBlock(world, i + 10, j + 62, k + 2, Blocks.log, 1);
		world.setBlockMetadataWithNotify(i + 10, j + 62, k + 2, 1, 2);
		setBlock(world, i + 10, j + 62, k + 3, Blocks.log, 1);
		world.setBlockMetadataWithNotify(i + 10, j + 62, k + 3, 1, 2);
		setBlock(world, i + 10, j + 62, k + 4, Blocks.log, 1);
		world.setBlockMetadataWithNotify(i + 10, j + 62, k + 4, 1, 2);
		setBlock(world, i + 10, j + 62, k + 5, Blocks.log, 1);
		world.setBlockMetadataWithNotify(i + 10, j + 62, k + 5, 1, 2);
		setBlock(world, i + 10, j + 62, k + 6, Blocks.log, 1);
		world.setBlockMetadataWithNotify(i + 10, j + 62, k + 6, 1, 2);
		setBlock(world, i + 11, j + 21, k + 26, Blocks.leaves, 7);
		world.setBlockMetadataWithNotify(i + 11, j + 21, k + 26, 7, 2);
		setBlock(world, i + 11, j + 21, k + 27, Blocks.leaves, 7);
		world.setBlockMetadataWithNotify(i + 11, j + 21, k + 27, 7, 2);
		setBlock(world, i + 11, j + 21, k + 28, Blocks.leaves, 7);
		world.setBlockMetadataWithNotify(i + 11, j + 21, k + 28, 7, 2);
		setBlock(world, i + 11, j + 22, k + 27, Blocks.leaves, 7);
		world.setBlockMetadataWithNotify(i + 11, j + 22, k + 27, 7, 2);
		setBlock(world, i + 11, j + 23, k + 17, Blocks.leaves, 7);
		world.setBlockMetadataWithNotify(i + 11, j + 23, k + 17, 7, 2);
		setBlock(world, i + 11, j + 23, k + 18, Blocks.leaves, 7);
		world.setBlockMetadataWithNotify(i + 11, j + 23, k + 18, 7, 2);
		setBlock(world, i + 11, j + 23, k + 19, Blocks.leaves, 7);
		world.setBlockMetadataWithNotify(i + 11, j + 23, k + 19, 7, 2);
		setBlock(world, i + 11, j + 24, k + 18, Blocks.leaves, 7);
		world.setBlockMetadataWithNotify(i + 11, j + 24, k + 18, 7, 2);
		setBlock(world, i + 11, j + 27, k + 3, Blocks.log, 3);
		world.setBlockMetadataWithNotify(i + 11, j + 27, k + 3, 3, 2);
		setBlock(world, i + 11, j + 28, k + 2, Blocks.log, 3);
		world.setBlockMetadataWithNotify(i + 11, j + 28, k + 2, 3, 2);
		setBlock(world, i + 11, j + 28, k + 3, Blocks.leaves, 7);
		world.setBlockMetadataWithNotify(i + 11, j + 28, k + 3, 7, 2);
		setBlock(world, i + 11, j + 28, k + 4, Blocks.leaves, 7);
		world.setBlockMetadataWithNotify(i + 11, j + 28, k + 4, 7, 2);
		setBlock(world, i + 11, j + 28, k + 5, Blocks.leaves, 7);
		world.setBlockMetadataWithNotify(i + 11, j + 28, k + 5, 7, 2);
		setBlock(world, i + 11, j + 28, k + 6, Blocks.leaves, 7);
		world.setBlockMetadataWithNotify(i + 11, j + 28, k + 6, 7, 2);
		setBlock(world, i + 11, j + 28, k + 7, Blocks.leaves, 7);
		world.setBlockMetadataWithNotify(i + 11, j + 28, k + 7, 7, 2);
		setBlock(world, i + 11, j + 29, k + 0, Blocks.leaves, 7);
		world.setBlockMetadataWithNotify(i + 11, j + 29, k + 0, 7, 2);
		setBlock(world, i + 11, j + 29, k + 1, Blocks.leaves, 7);
		world.setBlockMetadataWithNotify(i + 11, j + 29, k + 1, 7, 2);
		setBlock(world, i + 11, j + 29, k + 2, Blocks.leaves, 7);
		world.setBlockMetadataWithNotify(i + 11, j + 29, k + 2, 7, 2);
		setBlock(world, i + 11, j + 29, k + 3, Blocks.leaves, 7);
		world.setBlockMetadataWithNotify(i + 11, j + 29, k + 3, 7, 2);
		setBlock(world, i + 11, j + 29, k + 4, Blocks.leaves, 7);
		world.setBlockMetadataWithNotify(i + 11, j + 29, k + 4, 7, 2);
		setBlock(world, i + 11, j + 29, k + 5, Blocks.leaves, 7);
		world.setBlockMetadataWithNotify(i + 11, j + 29, k + 5, 7, 2);
		setBlock(world, i + 11, j + 29, k + 6, Blocks.leaves, 7);
		world.setBlockMetadataWithNotify(i + 11, j + 29, k + 6, 7, 2);
		setBlock(world, i + 11, j + 30, k + 1, Blocks.leaves, 7);
		world.setBlockMetadataWithNotify(i + 11, j + 30, k + 1, 7, 2);
		setBlock(world, i + 11, j + 30, k + 2, Blocks.leaves, 7);
		world.setBlockMetadataWithNotify(i + 11, j + 30, k + 2, 7, 2);
		setBlock(world, i + 11, j + 30, k + 3, Blocks.leaves, 7);
		world.setBlockMetadataWithNotify(i + 11, j + 30, k + 3, 7, 2);
		setBlock(world, i + 11, j + 30, k + 5, Blocks.leaves, 7);
		world.setBlockMetadataWithNotify(i + 11, j + 30, k + 5, 7, 2);
		setBlock(world, i + 11, j + 31, k + 2, Blocks.leaves, 7);
		world.setBlockMetadataWithNotify(i + 11, j + 31, k + 2, 7, 2);
		setBlock(world, i + 11, j + 37, k + 1, Blocks.leaves, 7);
		world.setBlockMetadataWithNotify(i + 11, j + 37, k + 1, 7, 2);
		setBlock(world, i + 11, j + 37, k + 2, Blocks.leaves, 7);
		world.setBlockMetadataWithNotify(i + 11, j + 37, k + 2, 7, 2);
		setBlock(world, i + 11, j + 37, k + 3, Blocks.leaves, 7);
		world.setBlockMetadataWithNotify(i + 11, j + 37, k + 3, 7, 2);
		setBlock(world, i + 11, j + 38, k + 2, Blocks.leaves, 7);
		world.setBlockMetadataWithNotify(i + 11, j + 38, k + 2, 7, 2);
		setBlock(world, i + 11, j + 52, k + 1, Blocks.log, 1);
		world.setBlockMetadataWithNotify(i + 11, j + 52, k + 1, 1, 2);
		setBlock(world, i + 11, j + 52, k + 2, Blocks.log, 1);
		world.setBlockMetadataWithNotify(i + 11, j + 52, k + 2, 1, 2);
		setBlock(world, i + 11, j + 52, k + 3, Blocks.log, 1);
		world.setBlockMetadataWithNotify(i + 11, j + 52, k + 3, 1, 2);
		setBlock(world, i + 11, j + 52, k + 4, Blocks.log, 1);
		world.setBlockMetadataWithNotify(i + 11, j + 52, k + 4, 1, 2);
		setBlock(world, i + 11, j + 53, k + 0, Blocks.log, 1);
		world.setBlockMetadataWithNotify(i + 11, j + 53, k + 0, 1, 2);
		setBlock(world, i + 11, j + 53, k + 1, Blocks.log, 1);
		world.setBlockMetadataWithNotify(i + 11, j + 53, k + 1, 1, 2);
		setBlock(world, i + 11, j + 53, k + 2, Blocks.log, 1);
		world.setBlockMetadataWithNotify(i + 11, j + 53, k + 2, 1, 2);
		setBlock(world, i + 11, j + 53, k + 3, Blocks.log, 1);
		world.setBlockMetadataWithNotify(i + 11, j + 53, k + 3, 1, 2);
		setBlock(world, i + 11, j + 53, k + 4, Blocks.log, 1);
		world.setBlockMetadataWithNotify(i + 11, j + 53, k + 4, 1, 2);
		setBlock(world, i + 11, j + 53, k + 5, Blocks.log, 1);
		world.setBlockMetadataWithNotify(i + 11, j + 53, k + 5, 1, 2);
		setBlock(world, i + 11, j + 54, k + 0, Blocks.log, 1);
		world.setBlockMetadataWithNotify(i + 11, j + 54, k + 0, 1, 2);
		setBlock(world, i + 11, j + 54, k + 1, Blocks.log, 1);
		world.setBlockMetadataWithNotify(i + 11, j + 54, k + 1, 1, 2);
		setBlock(world, i + 11, j + 54, k + 2, Blocks.log, 1);
		world.setBlockMetadataWithNotify(i + 11, j + 54, k + 2, 1, 2);
		setBlock(world, i + 11, j + 54, k + 3, Blocks.log, 1);
		world.setBlockMetadataWithNotify(i + 11, j + 54, k + 3, 1, 2);
		setBlock(world, i + 11, j + 54, k + 4, Blocks.log, 1);
		world.setBlockMetadataWithNotify(i + 11, j + 54, k + 4, 1, 2);
		setBlock(world, i + 11, j + 54, k + 5, Blocks.log, 1);
		world.setBlockMetadataWithNotify(i + 11, j + 54, k + 5, 1, 2);
		setBlock(world, i + 11, j + 55, k + 0, Blocks.planks, 5);
		world.setBlockMetadataWithNotify(i + 11, j + 55, k + 0, 5, 2);
		setBlock(world, i + 11, j + 55, k + 1, Blocks.planks, 5);
		world.setBlockMetadataWithNotify(i + 11, j + 55, k + 1, 5, 2);
		setBlock(world, i + 11, j + 55, k + 2, Blocks.planks, 5);
		world.setBlockMetadataWithNotify(i + 11, j + 55, k + 2, 5, 2);
		setBlock(world, i + 11, j + 55, k + 3, Blocks.log, 1);
		world.setBlockMetadataWithNotify(i + 11, j + 55, k + 3, 1, 2);
		setBlock(world, i + 11, j + 55, k + 4, Blocks.log, 1);
		world.setBlockMetadataWithNotify(i + 11, j + 55, k + 4, 1, 2);
		setBlock(world, i + 11, j + 55, k + 5, Blocks.log, 1);
		world.setBlockMetadataWithNotify(i + 11, j + 55, k + 5, 1, 2);
		setBlock(world, i + 11, j + 55, k + 6, Blocks.log, 1);
		world.setBlockMetadataWithNotify(i + 11, j + 55, k + 6, 1, 2);
		setBlock(world, i + 11, j + 55, k + 7, Blocks.log, 1);
		world.setBlockMetadataWithNotify(i + 11, j + 55, k + 7, 1, 2);
		setBlock(world, i + 11, j + 55, k + 8, Blocks.log, 1);
		world.setBlockMetadataWithNotify(i + 11, j + 55, k + 8, 1, 2);
		setBlock(world, i + 11, j + 57, k + 8, Blocks.torch, 5);
		world.setBlockMetadataWithNotify(i + 11, j + 57, k + 8, 5, 2);
		setBlock(world, i + 11, j + 60, k + 4, Blocks.torch, 1);
		world.setBlockMetadataWithNotify(i + 11, j + 60, k + 4, 1, 2);
		setBlock(world, i + 11, j + 60, k + 5, Blocks.log, 1);
		world.setBlockMetadataWithNotify(i + 11, j + 60, k + 5, 1, 2);
		setBlock(world, i + 11, j + 60, k + 6, Blocks.log, 1);
		world.setBlockMetadataWithNotify(i + 11, j + 60, k + 6, 1, 2);
		setBlock(world, i + 11, j + 60, k + 7, Blocks.log, 1);
		world.setBlockMetadataWithNotify(i + 11, j + 60, k + 7, 1, 2);
		setBlock(world, i + 11, j + 60, k + 8, Blocks.log, 1);
		world.setBlockMetadataWithNotify(i + 11, j + 60, k + 8, 1, 2);
		setBlock(world, i + 11, j + 60, k + 9, Blocks.log, 1);
		world.setBlockMetadataWithNotify(i + 11, j + 60, k + 9, 1, 2);
		setBlock(world, i + 11, j + 60, k + 10, Blocks.log, 1);
		world.setBlockMetadataWithNotify(i + 11, j + 60, k + 10, 1, 2);
		setBlock(world, i + 11, j + 60, k + 11, Blocks.log, 1);
		world.setBlockMetadataWithNotify(i + 11, j + 60, k + 11, 1, 2);
		setBlock(world, i + 11, j + 61, k + 0, Blocks.log, 1);
		world.setBlockMetadataWithNotify(i + 11, j + 61, k + 0, 1, 2);
		setBlock(world, i + 11, j + 61, k + 1, Blocks.log, 1);
		world.setBlockMetadataWithNotify(i + 11, j + 61, k + 1, 1, 2);
		setBlock(world, i + 11, j + 61, k + 2, Blocks.log, 1);
		world.setBlockMetadataWithNotify(i + 11, j + 61, k + 2, 1, 2);
		setBlock(world, i + 11, j + 61, k + 3, Blocks.log, 1);
		world.setBlockMetadataWithNotify(i + 11, j + 61, k + 3, 1, 2);
		setBlock(world, i + 11, j + 61, k + 4, Blocks.log, 1);
		world.setBlockMetadataWithNotify(i + 11, j + 61, k + 4, 1, 2);
		setBlock(world, i + 11, j + 61, k + 5, Blocks.log, 1);
		world.setBlockMetadataWithNotify(i + 11, j + 61, k + 5, 1, 2);
		setBlock(world, i + 11, j + 61, k + 6, Blocks.log, 1);
		world.setBlockMetadataWithNotify(i + 11, j + 61, k + 6, 1, 2);
		setBlock(world, i + 11, j + 61, k + 7, Blocks.log, 1);
		world.setBlockMetadataWithNotify(i + 11, j + 61, k + 7, 1, 2);
		setBlock(world, i + 11, j + 61, k + 8, Blocks.log, 1);
		world.setBlockMetadataWithNotify(i + 11, j + 61, k + 8, 1, 2);
		setBlock(world, i + 11, j + 61, k + 9, Blocks.log, 1);
		world.setBlockMetadataWithNotify(i + 11, j + 61, k + 9, 1, 2);
		setBlock(world, i + 11, j + 61, k + 10, Blocks.log, 1);
		world.setBlockMetadataWithNotify(i + 11, j + 61, k + 10, 1, 2);
		setBlock(world, i + 11, j + 62, k + 0, Blocks.log, 1);
		world.setBlockMetadataWithNotify(i + 11, j + 62, k + 0, 1, 2);
		setBlock(world, i + 11, j + 62, k + 1, Blocks.log, 1);
		world.setBlockMetadataWithNotify(i + 11, j + 62, k + 1, 1, 2);
		setBlock(world, i + 11, j + 62, k + 2, Blocks.log, 1);
		world.setBlockMetadataWithNotify(i + 11, j + 62, k + 2, 1, 2);
		setBlock(world, i + 11, j + 62, k + 3, Blocks.log, 1);
		world.setBlockMetadataWithNotify(i + 11, j + 62, k + 3, 1, 2);
		setBlock(world, i + 11, j + 62, k + 4, Blocks.log, 1);
		world.setBlockMetadataWithNotify(i + 11, j + 62, k + 4, 1, 2);
		setBlock(world, i + 11, j + 62, k + 5, Blocks.log, 1);
		world.setBlockMetadataWithNotify(i + 11, j + 62, k + 5, 1, 2);
		setBlock(world, i + 11, j + 62, k + 6, Blocks.log, 1);
		world.setBlockMetadataWithNotify(i + 11, j + 62, k + 6, 1, 2);
		setBlock(world, i + 11, j + 62, k + 7, Blocks.log, 1);
		world.setBlockMetadataWithNotify(i + 11, j + 62, k + 7, 1, 2);
		setBlock(world, i + 12, j + 21, k + 25, Blocks.leaves, 7);
		world.setBlockMetadataWithNotify(i + 12, j + 21, k + 25, 7, 2);
		setBlock(world, i + 12, j + 21, k + 26, Blocks.leaves, 7);
		world.setBlockMetadataWithNotify(i + 12, j + 21, k + 26, 7, 2);
		setBlock(world, i + 12, j + 21, k + 27, Blocks.leaves, 7);
		world.setBlockMetadataWithNotify(i + 12, j + 21, k + 27, 7, 2);
		setBlock(world, i + 12, j + 21, k + 28, Blocks.leaves, 7);
		world.setBlockMetadataWithNotify(i + 12, j + 21, k + 28, 7, 2);
		setBlock(world, i + 12, j + 21, k + 29, Blocks.leaves, 7);
		world.setBlockMetadataWithNotify(i + 12, j + 21, k + 29, 7, 2);
		setBlock(world, i + 12, j + 22, k + 26, Blocks.leaves, 7);
		world.setBlockMetadataWithNotify(i + 12, j + 22, k + 26, 7, 2);
		setBlock(world, i + 12, j + 22, k + 27, Blocks.leaves, 7);
		world.setBlockMetadataWithNotify(i + 12, j + 22, k + 27, 7, 2);
		setBlock(world, i + 12, j + 22, k + 28, Blocks.leaves, 7);
		world.setBlockMetadataWithNotify(i + 12, j + 22, k + 28, 7, 2);
		setBlock(world, i + 12, j + 23, k + 16, Blocks.leaves, 7);
		world.setBlockMetadataWithNotify(i + 12, j + 23, k + 16, 7, 2);
		setBlock(world, i + 12, j + 23, k + 17, Blocks.leaves, 7);
		world.setBlockMetadataWithNotify(i + 12, j + 23, k + 17, 7, 2);
		setBlock(world, i + 12, j + 23, k + 18, Blocks.leaves, 7);
		world.setBlockMetadataWithNotify(i + 12, j + 23, k + 18, 7, 2);
		setBlock(world, i + 12, j + 23, k + 19, Blocks.leaves, 7);
		world.setBlockMetadataWithNotify(i + 12, j + 23, k + 19, 7, 2);
		setBlock(world, i + 12, j + 23, k + 20, Blocks.leaves, 7);
		world.setBlockMetadataWithNotify(i + 12, j + 23, k + 20, 7, 2);
		setBlock(world, i + 12, j + 23, k + 27, Blocks.leaves, 7);
		world.setBlockMetadataWithNotify(i + 12, j + 23, k + 27, 7, 2);
		setBlock(world, i + 12, j + 24, k + 17, Blocks.leaves, 7);
		world.setBlockMetadataWithNotify(i + 12, j + 24, k + 17, 7, 2);
		setBlock(world, i + 12, j + 24, k + 18, Blocks.leaves, 7);
		world.setBlockMetadataWithNotify(i + 12, j + 24, k + 18, 7, 2);
		setBlock(world, i + 12, j + 24, k + 19, Blocks.leaves, 7);
		world.setBlockMetadataWithNotify(i + 12, j + 24, k + 19, 7, 2);
		setBlock(world, i + 12, j + 25, k + 18, Blocks.leaves, 7);
		world.setBlockMetadataWithNotify(i + 12, j + 25, k + 18, 7, 2);
		setBlock(world, i + 12, j + 27, k + 2, Blocks.log, 3);
		world.setBlockMetadataWithNotify(i + 12, j + 27, k + 2, 3, 2);
		setBlock(world, i + 12, j + 28, k + 1, Blocks.log, 3);
		world.setBlockMetadataWithNotify(i + 12, j + 28, k + 1, 3, 2);
		setBlock(world, i + 12, j + 28, k + 4, Blocks.leaves, 7);
		world.setBlockMetadataWithNotify(i + 12, j + 28, k + 4, 7, 2);
		setBlock(world, i + 12, j + 28, k + 5, Blocks.leaves, 7);
		world.setBlockMetadataWithNotify(i + 12, j + 28, k + 5, 7, 2);
		setBlock(world, i + 12, j + 28, k + 6, Blocks.leaves, 7);
		world.setBlockMetadataWithNotify(i + 12, j + 28, k + 6, 7, 2);
		setBlock(world, i + 12, j + 29, k + 1, Blocks.leaves, 7);
		world.setBlockMetadataWithNotify(i + 12, j + 29, k + 1, 7, 2);
		setBlock(world, i + 12, j + 29, k + 2, Blocks.leaves, 7);
		world.setBlockMetadataWithNotify(i + 12, j + 29, k + 2, 7, 2);
		setBlock(world, i + 12, j + 29, k + 3, Blocks.leaves, 7);
		world.setBlockMetadataWithNotify(i + 12, j + 29, k + 3, 7, 2);
		setBlock(world, i + 12, j + 29, k + 5, Blocks.leaves, 7);
		world.setBlockMetadataWithNotify(i + 12, j + 29, k + 5, 7, 2);
		setBlock(world, i + 12, j + 29, k + 31, Blocks.leaves, 7);
		world.setBlockMetadataWithNotify(i + 12, j + 29, k + 31, 7, 2);
		setBlock(world, i + 12, j + 30, k + 2, Blocks.leaves, 7);
		world.setBlockMetadataWithNotify(i + 12, j + 30, k + 2, 7, 2);
		setBlock(world, i + 12, j + 37, k + 0, Blocks.leaves, 7);
		world.setBlockMetadataWithNotify(i + 12, j + 37, k + 0, 7, 2);
		setBlock(world, i + 12, j + 37, k + 1, Blocks.leaves, 7);
		world.setBlockMetadataWithNotify(i + 12, j + 37, k + 1, 7, 2);
		setBlock(world, i + 12, j + 37, k + 2, Blocks.leaves, 7);
		world.setBlockMetadataWithNotify(i + 12, j + 37, k + 2, 7, 2);
		setBlock(world, i + 12, j + 37, k + 3, Blocks.leaves, 7);
		world.setBlockMetadataWithNotify(i + 12, j + 37, k + 3, 7, 2);
		setBlock(world, i + 12, j + 37, k + 4, Blocks.leaves, 7);
		world.setBlockMetadataWithNotify(i + 12, j + 37, k + 4, 7, 2);
		setBlock(world, i + 12, j + 38, k + 1, Blocks.leaves, 7);
		world.setBlockMetadataWithNotify(i + 12, j + 38, k + 1, 7, 2);
		setBlock(world, i + 12, j + 38, k + 2, Blocks.leaves, 7);
		world.setBlockMetadataWithNotify(i + 12, j + 38, k + 2, 7, 2);
		setBlock(world, i + 12, j + 38, k + 3, Blocks.leaves, 7);
		world.setBlockMetadataWithNotify(i + 12, j + 38, k + 3, 7, 2);
		setBlock(world, i + 12, j + 39, k + 2, Blocks.leaves, 7);
		world.setBlockMetadataWithNotify(i + 12, j + 39, k + 2, 7, 2);
		setBlock(world, i + 12, j + 46, k + 0, Blocks.log, 1);
		world.setBlockMetadataWithNotify(i + 12, j + 46, k + 0, 1, 2);
		setBlock(world, i + 12, j + 47, k + 0, Blocks.log, 1);
		world.setBlockMetadataWithNotify(i + 12, j + 47, k + 0, 1, 2);
		setBlock(world, i + 12, j + 47, k + 1, Blocks.log, 1);
		world.setBlockMetadataWithNotify(i + 12, j + 47, k + 1, 1, 2);
		setBlock(world, i + 12, j + 48, k + 0, Blocks.log, 1);
		world.setBlockMetadataWithNotify(i + 12, j + 48, k + 0, 1, 2);
		setBlock(world, i + 12, j + 50, k + 0, Blocks.log, 1);
		world.setBlockMetadataWithNotify(i + 12, j + 50, k + 0, 1, 2);
		setBlock(world, i + 12, j + 50, k + 1, Blocks.log, 1);
		world.setBlockMetadataWithNotify(i + 12, j + 50, k + 1, 1, 2);
		setBlock(world, i + 12, j + 50, k + 2, Blocks.log, 1);
		world.setBlockMetadataWithNotify(i + 12, j + 50, k + 2, 1, 2);
		setBlock(world, i + 12, j + 51, k + 0, Blocks.log, 1);
		world.setBlockMetadataWithNotify(i + 12, j + 51, k + 0, 1, 2);
		setBlock(world, i + 12, j + 51, k + 1, Blocks.log, 1);
		world.setBlockMetadataWithNotify(i + 12, j + 51, k + 1, 1, 2);
		setBlock(world, i + 12, j + 51, k + 2, Blocks.log, 1);
		world.setBlockMetadataWithNotify(i + 12, j + 51, k + 2, 1, 2);
		setBlock(world, i + 12, j + 51, k + 3, Blocks.log, 1);
		world.setBlockMetadataWithNotify(i + 12, j + 51, k + 3, 1, 2);
		setBlock(world, i + 12, j + 52, k + 0, Blocks.log, 1);
		world.setBlockMetadataWithNotify(i + 12, j + 52, k + 0, 1, 2);
		setBlock(world, i + 12, j + 52, k + 1, Blocks.log, 1);
		world.setBlockMetadataWithNotify(i + 12, j + 52, k + 1, 1, 2);
		setBlock(world, i + 12, j + 52, k + 2, Blocks.log, 1);
		world.setBlockMetadataWithNotify(i + 12, j + 52, k + 2, 1, 2);
		setBlock(world, i + 12, j + 52, k + 3, Blocks.log, 1);
		world.setBlockMetadataWithNotify(i + 12, j + 52, k + 3, 1, 2);
		setBlock(world, i + 12, j + 52, k + 4, Blocks.log, 1);
		world.setBlockMetadataWithNotify(i + 12, j + 52, k + 4, 1, 2);
		setBlock(world, i + 12, j + 52, k + 5, Blocks.log, 1);
		world.setBlockMetadataWithNotify(i + 12, j + 52, k + 5, 1, 2);
		setBlock(world, i + 12, j + 53, k + 0, Blocks.log, 1);
		world.setBlockMetadataWithNotify(i + 12, j + 53, k + 0, 1, 2);
		setBlock(world, i + 12, j + 53, k + 1, Blocks.log, 1);
		world.setBlockMetadataWithNotify(i + 12, j + 53, k + 1, 1, 2);
		setBlock(world, i + 12, j + 53, k + 2, Blocks.log, 1);
		world.setBlockMetadataWithNotify(i + 12, j + 53, k + 2, 1, 2);
		setBlock(world, i + 12, j + 53, k + 3, Blocks.log, 1);
		world.setBlockMetadataWithNotify(i + 12, j + 53, k + 3, 1, 2);
		setBlock(world, i + 12, j + 53, k + 4, Blocks.log, 1);
		world.setBlockMetadataWithNotify(i + 12, j + 53, k + 4, 1, 2);
		setBlock(world, i + 12, j + 53, k + 5, Blocks.log, 1);
		world.setBlockMetadataWithNotify(i + 12, j + 53, k + 5, 1, 2);
		setBlock(world, i + 12, j + 53, k + 6, Blocks.log, 1);
		world.setBlockMetadataWithNotify(i + 12, j + 53, k + 6, 1, 2);
		setBlock(world, i + 12, j + 54, k + 0, Blocks.log, 1);
		world.setBlockMetadataWithNotify(i + 12, j + 54, k + 0, 1, 2);
		setBlock(world, i + 12, j + 54, k + 1, Blocks.log, 1);
		world.setBlockMetadataWithNotify(i + 12, j + 54, k + 1, 1, 2);
		setBlock(world, i + 12, j + 54, k + 2, Blocks.log, 1);
		world.setBlockMetadataWithNotify(i + 12, j + 54, k + 2, 1, 2);
		setBlock(world, i + 12, j + 54, k + 3, Blocks.log, 1);
		world.setBlockMetadataWithNotify(i + 12, j + 54, k + 3, 1, 2);
		setBlock(world, i + 12, j + 54, k + 4, Blocks.log, 1);
		world.setBlockMetadataWithNotify(i + 12, j + 54, k + 4, 1, 2);
		setBlock(world, i + 12, j + 54, k + 5, Blocks.log, 1);
		world.setBlockMetadataWithNotify(i + 12, j + 54, k + 5, 1, 2);
		setBlock(world, i + 12, j + 54, k + 6, Blocks.log, 1);
		world.setBlockMetadataWithNotify(i + 12, j + 54, k + 6, 1, 2);
		setBlock(world, i + 12, j + 54, k + 7, Blocks.log, 1);
		world.setBlockMetadataWithNotify(i + 12, j + 54, k + 7, 1, 2);
		setBlock(world, i + 12, j + 55, k + 0, Blocks.planks, 5);
		world.setBlockMetadataWithNotify(i + 12, j + 55, k + 0, 5, 2);
		setBlock(world, i + 12, j + 55, k + 1, Blocks.log, 1);
		world.setBlockMetadataWithNotify(i + 12, j + 55, k + 1, 1, 2);
		setBlock(world, i + 12, j + 55, k + 2, Blocks.log, 1);
		world.setBlockMetadataWithNotify(i + 12, j + 55, k + 2, 1, 2);
		setBlock(world, i + 12, j + 55, k + 3, Blocks.planks, 5);
		world.setBlockMetadataWithNotify(i + 12, j + 55, k + 3, 5, 2);
		setBlock(world, i + 12, j + 55, k + 4, Blocks.log, 1);
		world.setBlockMetadataWithNotify(i + 12, j + 55, k + 4, 1, 2);
		setBlock(world, i + 12, j + 55, k + 5, Blocks.log, 1);
		world.setBlockMetadataWithNotify(i + 12, j + 55, k + 5, 1, 2);
		setBlock(world, i + 12, j + 55, k + 6, Blocks.log, 1);
		world.setBlockMetadataWithNotify(i + 12, j + 55, k + 6, 1, 2);
		setBlock(world, i + 12, j + 55, k + 7, Blocks.log, 1);
		world.setBlockMetadataWithNotify(i + 12, j + 55, k + 7, 1, 2);
		setBlock(world, i + 12, j + 55, k + 8, Blocks.log, 1);
		world.setBlockMetadataWithNotify(i + 12, j + 55, k + 8, 1, 2);
		setBlock(world, i + 12, j + 55, k + 9, Blocks.log, 1);
		world.setBlockMetadataWithNotify(i + 12, j + 55, k + 9, 1, 2);
		setBlock(world, i + 12, j + 56, k + 8, Blocks.spruce_stairs, 2);
		world.setBlockMetadataWithNotify(i + 12, j + 56, k + 8, 2, 2);
		setBlock(world, i + 12, j + 56, k + 9, Blocks.log, 1);
		world.setBlockMetadataWithNotify(i + 12, j + 56, k + 9, 1, 2);
		setBlock(world, i + 12, j + 56, k + 10, Blocks.spruce_stairs, 7);
		world.setBlockMetadataWithNotify(i + 12, j + 56, k + 10, 7, 2);
		setBlock(world, i + 12, j + 57, k + 9, Blocks.log, 1);
		world.setBlockMetadataWithNotify(i + 12, j + 57, k + 9, 1, 2);
		setBlock(world, i + 12, j + 57, k + 10, Blocks.log, 1);
		world.setBlockMetadataWithNotify(i + 12, j + 57, k + 10, 1, 2);
		setBlock(world, i + 12, j + 57, k + 11, Blocks.spruce_stairs, 7);
		world.setBlockMetadataWithNotify(i + 12, j + 57, k + 11, 7, 2);
		setBlock(world, i + 12, j + 58, k + 10, Blocks.log, 1);
		world.setBlockMetadataWithNotify(i + 12, j + 58, k + 10, 1, 2);
		setBlock(world, i + 12, j + 58, k + 11, Blocks.log, 1);
		world.setBlockMetadataWithNotify(i + 12, j + 58, k + 11, 1, 2);
		setBlock(world, i + 12, j + 59, k + 11, Blocks.log, 1);
		world.setBlockMetadataWithNotify(i + 12, j + 59, k + 11, 1, 2);
		setBlock(world, i + 12, j + 60, k + 6, Blocks.log, 1);
		world.setBlockMetadataWithNotify(i + 12, j + 60, k + 6, 1, 2);
		setBlock(world, i + 12, j + 60, k + 7, Blocks.log, 1);
		world.setBlockMetadataWithNotify(i + 12, j + 60, k + 7, 1, 2);
		setBlock(world, i + 12, j + 60, k + 8, Blocks.log, 1);
		world.setBlockMetadataWithNotify(i + 12, j + 60, k + 8, 1, 2);
		setBlock(world, i + 12, j + 60, k + 9, Blocks.log, 1);
		world.setBlockMetadataWithNotify(i + 12, j + 60, k + 9, 1, 2);
		setBlock(world, i + 12, j + 60, k + 10, Blocks.log, 1);
		world.setBlockMetadataWithNotify(i + 12, j + 60, k + 10, 1, 2);
		setBlock(world, i + 12, j + 60, k + 11, Blocks.log, 1);
		world.setBlockMetadataWithNotify(i + 12, j + 60, k + 11, 1, 2);
		setBlock(world, i + 12, j + 60, k + 12, Blocks.log, 1);
		world.setBlockMetadataWithNotify(i + 12, j + 60, k + 12, 1, 2);
		setBlock(world, i + 12, j + 61, k + 5, Blocks.log, 1);
		world.setBlockMetadataWithNotify(i + 12, j + 61, k + 5, 1, 2);
		setBlock(world, i + 12, j + 61, k + 6, Blocks.log, 1);
		world.setBlockMetadataWithNotify(i + 12, j + 61, k + 6, 1, 2);
		setBlock(world, i + 12, j + 61, k + 7, Blocks.log, 1);
		world.setBlockMetadataWithNotify(i + 12, j + 61, k + 7, 1, 2);
		setBlock(world, i + 12, j + 61, k + 8, Blocks.log, 1);
		world.setBlockMetadataWithNotify(i + 12, j + 61, k + 8, 1, 2);
		setBlock(world, i + 12, j + 61, k + 9, Blocks.log, 1);
		world.setBlockMetadataWithNotify(i + 12, j + 61, k + 9, 1, 2);
		setBlock(world, i + 12, j + 61, k + 10, Blocks.log, 1);
		world.setBlockMetadataWithNotify(i + 12, j + 61, k + 10, 1, 2);
		setBlock(world, i + 12, j + 61, k + 11, Blocks.log, 1);
		world.setBlockMetadataWithNotify(i + 12, j + 61, k + 11, 1, 2);
		setBlock(world, i + 12, j + 62, k + 0, Blocks.log, 1);
		world.setBlockMetadataWithNotify(i + 12, j + 62, k + 0, 1, 2);
		setBlock(world, i + 12, j + 62, k + 1, Blocks.log, 1);
		world.setBlockMetadataWithNotify(i + 12, j + 62, k + 1, 1, 2);
		setBlock(world, i + 12, j + 62, k + 2, Blocks.log, 1);
		world.setBlockMetadataWithNotify(i + 12, j + 62, k + 2, 1, 2);
		setBlock(world, i + 12, j + 62, k + 3, Blocks.log, 1);
		world.setBlockMetadataWithNotify(i + 12, j + 62, k + 3, 1, 2);
		setBlock(world, i + 12, j + 62, k + 4, Blocks.log, 1);
		world.setBlockMetadataWithNotify(i + 12, j + 62, k + 4, 1, 2);
		setBlock(world, i + 12, j + 62, k + 5, Blocks.log, 1);
		world.setBlockMetadataWithNotify(i + 12, j + 62, k + 5, 1, 2);
		setBlock(world, i + 12, j + 62, k + 6, Blocks.log, 1);
		world.setBlockMetadataWithNotify(i + 12, j + 62, k + 6, 1, 2);
		setBlock(world, i + 12, j + 62, k + 7, Blocks.log, 1);
		world.setBlockMetadataWithNotify(i + 12, j + 62, k + 7, 1, 2);
		setBlock(world, i + 12, j + 62, k + 8, Blocks.log, 1);
		world.setBlockMetadataWithNotify(i + 12, j + 62, k + 8, 1, 2);
		setBlock(world, i + 12, j + 63, k + 0, Blocks.log, 1);
		world.setBlockMetadataWithNotify(i + 12, j + 63, k + 0, 1, 2);
		setBlock(world, i + 12, j + 63, k + 1, Blocks.log, 1);
		world.setBlockMetadataWithNotify(i + 12, j + 63, k + 1, 1, 2);
		setBlock(world, i + 12, j + 63, k + 2, Blocks.log, 1);
		world.setBlockMetadataWithNotify(i + 12, j + 63, k + 2, 1, 2);
		setBlock(world, i + 12, j + 63, k + 3, Blocks.log, 1);
		world.setBlockMetadataWithNotify(i + 12, j + 63, k + 3, 1, 2);
		setBlock(world, i + 13, j + 20, k + 28, Blocks.log, 3);
		world.setBlockMetadataWithNotify(i + 13, j + 20, k + 28, 3, 2);
		setBlock(world, i + 13, j + 21, k + 25, Blocks.leaves, 7);
		world.setBlockMetadataWithNotify(i + 13, j + 21, k + 25, 7, 2);
		setBlock(world, i + 13, j + 21, k + 26, Blocks.leaves, 7);
		world.setBlockMetadataWithNotify(i + 13, j + 21, k + 26, 7, 2);
		setBlock(world, i + 13, j + 21, k + 27, Blocks.log, 3);
		world.setBlockMetadataWithNotify(i + 13, j + 21, k + 27, 3, 2);
		setBlock(world, i + 13, j + 21, k + 28, Blocks.leaves, 7);
		world.setBlockMetadataWithNotify(i + 13, j + 21, k + 28, 7, 2);
		setBlock(world, i + 13, j + 21, k + 29, Blocks.leaves, 7);
		world.setBlockMetadataWithNotify(i + 13, j + 21, k + 29, 7, 2);
		setBlock(world, i + 13, j + 22, k + 19, Blocks.log, 3);
		world.setBlockMetadataWithNotify(i + 13, j + 22, k + 19, 3, 2);
		setBlock(world, i + 13, j + 22, k + 25, Blocks.leaves, 7);
		world.setBlockMetadataWithNotify(i + 13, j + 22, k + 25, 7, 2);
		setBlock(world, i + 13, j + 22, k + 26, Blocks.leaves, 7);
		world.setBlockMetadataWithNotify(i + 13, j + 22, k + 26, 7, 2);
		setBlock(world, i + 13, j + 22, k + 27, Blocks.leaves, 7);
		world.setBlockMetadataWithNotify(i + 13, j + 22, k + 27, 7, 2);
		setBlock(world, i + 13, j + 22, k + 28, Blocks.leaves, 7);
		world.setBlockMetadataWithNotify(i + 13, j + 22, k + 28, 7, 2);
		setBlock(world, i + 13, j + 22, k + 29, Blocks.leaves, 7);
		world.setBlockMetadataWithNotify(i + 13, j + 22, k + 29, 7, 2);
		setBlock(world, i + 13, j + 23, k + 16, Blocks.leaves, 7);
		world.setBlockMetadataWithNotify(i + 13, j + 23, k + 16, 7, 2);
		setBlock(world, i + 13, j + 23, k + 17, Blocks.leaves, 7);
		world.setBlockMetadataWithNotify(i + 13, j + 23, k + 17, 7, 2);
		setBlock(world, i + 13, j + 23, k + 18, Blocks.log, 3);
		world.setBlockMetadataWithNotify(i + 13, j + 23, k + 18, 3, 2);
		setBlock(world, i + 13, j + 23, k + 19, Blocks.leaves, 7);
		world.setBlockMetadataWithNotify(i + 13, j + 23, k + 19, 7, 2);
		setBlock(world, i + 13, j + 23, k + 20, Blocks.leaves, 7);
		world.setBlockMetadataWithNotify(i + 13, j + 23, k + 20, 7, 2);
		setBlock(world, i + 13, j + 23, k + 26, Blocks.leaves, 7);
		world.setBlockMetadataWithNotify(i + 13, j + 23, k + 26, 7, 2);
		setBlock(world, i + 13, j + 23, k + 27, Blocks.leaves, 7);
		world.setBlockMetadataWithNotify(i + 13, j + 23, k + 27, 7, 2);
		setBlock(world, i + 13, j + 23, k + 28, Blocks.leaves, 7);
		world.setBlockMetadataWithNotify(i + 13, j + 23, k + 28, 7, 2);
		setBlock(world, i + 13, j + 24, k + 16, Blocks.leaves, 7);
		world.setBlockMetadataWithNotify(i + 13, j + 24, k + 16, 7, 2);
		setBlock(world, i + 13, j + 24, k + 17, Blocks.leaves, 7);
		world.setBlockMetadataWithNotify(i + 13, j + 24, k + 17, 7, 2);
		setBlock(world, i + 13, j + 24, k + 18, Blocks.leaves, 7);
		world.setBlockMetadataWithNotify(i + 13, j + 24, k + 18, 7, 2);
		setBlock(world, i + 13, j + 24, k + 19, Blocks.leaves, 7);
		world.setBlockMetadataWithNotify(i + 13, j + 24, k + 19, 7, 2);
		setBlock(world, i + 13, j + 24, k + 20, Blocks.leaves, 7);
		world.setBlockMetadataWithNotify(i + 13, j + 24, k + 20, 7, 2);
		setBlock(world, i + 13, j + 24, k + 27, Blocks.leaves, 7);
		world.setBlockMetadataWithNotify(i + 13, j + 24, k + 27, 7, 2);
		setBlock(world, i + 13, j + 25, k + 17, Blocks.leaves, 7);
		world.setBlockMetadataWithNotify(i + 13, j + 25, k + 17, 7, 2);
		setBlock(world, i + 13, j + 25, k + 18, Blocks.leaves, 7);
		world.setBlockMetadataWithNotify(i + 13, j + 25, k + 18, 7, 2);
		setBlock(world, i + 13, j + 25, k + 19, Blocks.leaves, 7);
		world.setBlockMetadataWithNotify(i + 13, j + 25, k + 19, 7, 2);
		setBlock(world, i + 13, j + 26, k + 18, Blocks.leaves, 7);
		world.setBlockMetadataWithNotify(i + 13, j + 26, k + 18, 7, 2);
		setBlock(world, i + 13, j + 27, k + 1, Blocks.log, 3);
		world.setBlockMetadataWithNotify(i + 13, j + 27, k + 1, 3, 2);
		setBlock(world, i + 13, j + 28, k + 0, Blocks.log, 3);
		world.setBlockMetadataWithNotify(i + 13, j + 28, k + 0, 3, 2);
		setBlock(world, i + 13, j + 29, k + 31, Blocks.leaves, 7);
		world.setBlockMetadataWithNotify(i + 13, j + 29, k + 31, 7, 2);
		setBlock(world, i + 13, j + 30, k + 31, Blocks.leaves, 7);
		world.setBlockMetadataWithNotify(i + 13, j + 30, k + 31, 7, 2);
		setBlock(world, i + 13, j + 37, k + 0, Blocks.leaves, 7);
		world.setBlockMetadataWithNotify(i + 13, j + 37, k + 0, 7, 2);
		setBlock(world, i + 13, j + 37, k + 1, Blocks.leaves, 7);
		world.setBlockMetadataWithNotify(i + 13, j + 37, k + 1, 7, 2);
		setBlock(world, i + 13, j + 37, k + 2, Blocks.log, 3);
		world.setBlockMetadataWithNotify(i + 13, j + 37, k + 2, 3, 2);
		setBlock(world, i + 13, j + 37, k + 3, Blocks.leaves, 7);
		world.setBlockMetadataWithNotify(i + 13, j + 37, k + 3, 7, 2);
		setBlock(world, i + 13, j + 37, k + 4, Blocks.leaves, 7);
		world.setBlockMetadataWithNotify(i + 13, j + 37, k + 4, 7, 2);
		setBlock(world, i + 13, j + 38, k + 0, Blocks.leaves, 7);
		world.setBlockMetadataWithNotify(i + 13, j + 38, k + 0, 7, 2);
		setBlock(world, i + 13, j + 38, k + 1, Blocks.leaves, 7);
		world.setBlockMetadataWithNotify(i + 13, j + 38, k + 1, 7, 2);
		setBlock(world, i + 13, j + 38, k + 2, Blocks.leaves, 7);
		world.setBlockMetadataWithNotify(i + 13, j + 38, k + 2, 7, 2);
		setBlock(world, i + 13, j + 38, k + 3, Blocks.leaves, 7);
		world.setBlockMetadataWithNotify(i + 13, j + 38, k + 3, 7, 2);
		setBlock(world, i + 13, j + 38, k + 4, Blocks.leaves, 7);
		world.setBlockMetadataWithNotify(i + 13, j + 38, k + 4, 7, 2);
		setBlock(world, i + 13, j + 38, k + 30, Blocks.leaves, 7);
		world.setBlockMetadataWithNotify(i + 13, j + 38, k + 30, 7, 2);
		setBlock(world, i + 13, j + 38, k + 31, Blocks.leaves, 7);
		world.setBlockMetadataWithNotify(i + 13, j + 38, k + 31, 7, 2);
		setBlock(world, i + 13, j + 39, k + 1, Blocks.leaves, 7);
		world.setBlockMetadataWithNotify(i + 13, j + 39, k + 1, 7, 2);
		setBlock(world, i + 13, j + 39, k + 2, Blocks.leaves, 7);
		world.setBlockMetadataWithNotify(i + 13, j + 39, k + 2, 7, 2);
		setBlock(world, i + 13, j + 39, k + 3, Blocks.leaves, 7);
		world.setBlockMetadataWithNotify(i + 13, j + 39, k + 3, 7, 2);
		setBlock(world, i + 13, j + 39, k + 31, Blocks.leaves, 7);
		world.setBlockMetadataWithNotify(i + 13, j + 39, k + 31, 7, 2);
		setBlock(world, i + 13, j + 40, k + 2, Blocks.leaves, 7);
		world.setBlockMetadataWithNotify(i + 13, j + 40, k + 2, 7, 2);
		setBlock(world, i + 13, j + 46, k + 0, Blocks.log, 1);
		world.setBlockMetadataWithNotify(i + 13, j + 46, k + 0, 1, 2);
		setBlock(world, i + 13, j + 46, k + 1, Blocks.log, 1);
		world.setBlockMetadataWithNotify(i + 13, j + 46, k + 1, 1, 2);
		setBlock(world, i + 13, j + 47, k + 0, Blocks.log, 1);
		world.setBlockMetadataWithNotify(i + 13, j + 47, k + 0, 1, 2);
		setBlock(world, i + 13, j + 47, k + 1, Blocks.log, 1);
		world.setBlockMetadataWithNotify(i + 13, j + 47, k + 1, 1, 2);
		setBlock(world, i + 13, j + 48, k + 0, Blocks.log, 1);
		world.setBlockMetadataWithNotify(i + 13, j + 48, k + 0, 1, 2);
		setBlock(world, i + 13, j + 48, k + 1, Blocks.log, 1);
		world.setBlockMetadataWithNotify(i + 13, j + 48, k + 1, 1, 2);
		setBlock(world, i + 13, j + 49, k + 0, Blocks.log, 1);
		world.setBlockMetadataWithNotify(i + 13, j + 49, k + 0, 1, 2);
		setBlock(world, i + 13, j + 49, k + 1, Blocks.log, 1);
		world.setBlockMetadataWithNotify(i + 13, j + 49, k + 1, 1, 2);
		setBlock(world, i + 13, j + 49, k + 2, Blocks.log, 1);
		world.setBlockMetadataWithNotify(i + 13, j + 49, k + 2, 1, 2);
		setBlock(world, i + 13, j + 50, k + 0, Blocks.log, 1);
		world.setBlockMetadataWithNotify(i + 13, j + 50, k + 0, 1, 2);
		setBlock(world, i + 13, j + 50, k + 1, Blocks.log, 1);
		world.setBlockMetadataWithNotify(i + 13, j + 50, k + 1, 1, 2);
		setBlock(world, i + 13, j + 50, k + 2, Blocks.log, 1);
		world.setBlockMetadataWithNotify(i + 13, j + 50, k + 2, 1, 2);
		setBlock(world, i + 13, j + 50, k + 3, Blocks.log, 1);
		world.setBlockMetadataWithNotify(i + 13, j + 50, k + 3, 1, 2);
		setBlock(world, i + 13, j + 51, k + 0, Blocks.log, 1);
		world.setBlockMetadataWithNotify(i + 13, j + 51, k + 0, 1, 2);
		setBlock(world, i + 13, j + 51, k + 1, Blocks.log, 1);
		world.setBlockMetadataWithNotify(i + 13, j + 51, k + 1, 1, 2);
		setBlock(world, i + 13, j + 51, k + 2, Blocks.log, 1);
		world.setBlockMetadataWithNotify(i + 13, j + 51, k + 2, 1, 2);
		setBlock(world, i + 13, j + 51, k + 3, Blocks.log, 1);
		world.setBlockMetadataWithNotify(i + 13, j + 51, k + 3, 1, 2);
		setBlock(world, i + 13, j + 52, k + 0, Blocks.log, 1);
		world.setBlockMetadataWithNotify(i + 13, j + 52, k + 0, 1, 2);
		setBlock(world, i + 13, j + 52, k + 1, Blocks.log, 1);
		/* 1000 */world.setBlockMetadataWithNotify(i + 13, j + 52, k + 1, 1, 2);
		/* 1001 */setBlock(world, i + 13, j + 52, k + 2, Blocks.log, 1);
		/* 1002 */world.setBlockMetadataWithNotify(i + 13, j + 52, k + 2, 1, 2);
		/* 1003 */setBlock(world, i + 13, j + 52, k + 3, Blocks.log, 1);
		/* 1004 */world.setBlockMetadataWithNotify(i + 13, j + 52, k + 3, 1, 2);
		/* 1005 */setBlock(world, i + 13, j + 52, k + 4, Blocks.log, 1);
		/* 1006 */world.setBlockMetadataWithNotify(i + 13, j + 52, k + 4, 1, 2);
		/* 1007 */setBlock(world, i + 13, j + 52, k + 5, Blocks.log, 1);
		/* 1008 */world.setBlockMetadataWithNotify(i + 13, j + 52, k + 5, 1, 2);
		/* 1009 */setBlock(world, i + 13, j + 52, k + 6, Blocks.log, 1);
		/* 1010 */world.setBlockMetadataWithNotify(i + 13, j + 52, k + 6, 1, 2);
		/* 1011 */setBlock(world, i + 13, j + 53, k + 0, Blocks.log, 1);
		/* 1012 */world.setBlockMetadataWithNotify(i + 13, j + 53, k + 0, 1, 2);
		/* 1013 */setBlock(world, i + 13, j + 53, k + 1, Blocks.log, 1);
		/* 1014 */world.setBlockMetadataWithNotify(i + 13, j + 53, k + 1, 1, 2);
		/* 1015 */setBlock(world, i + 13, j + 53, k + 2, Blocks.log, 1);
		/* 1016 */world.setBlockMetadataWithNotify(i + 13, j + 53, k + 2, 1, 2);
		/* 1017 */setBlock(world, i + 13, j + 53, k + 3, Blocks.log, 1);
		/* 1018 */world.setBlockMetadataWithNotify(i + 13, j + 53, k + 3, 1, 2);
		/* 1019 */setBlock(world, i + 13, j + 53, k + 4, Blocks.log, 1);
		/* 1020 */world.setBlockMetadataWithNotify(i + 13, j + 53, k + 4, 1, 2);
		/* 1021 */setBlock(world, i + 13, j + 53, k + 5, Blocks.log, 1);
		/* 1022 */world.setBlockMetadataWithNotify(i + 13, j + 53, k + 5, 1, 2);
		/* 1023 */setBlock(world, i + 13, j + 53, k + 6, Blocks.log, 1);
		/* 1024 */world.setBlockMetadataWithNotify(i + 13, j + 53, k + 6, 1, 2);
		/* 1025 */setBlock(world, i + 13, j + 53, k + 7, Blocks.log, 1);
		/* 1026 */world.setBlockMetadataWithNotify(i + 13, j + 53, k + 7, 1, 2);
		/* 1027 */setBlock(world, i + 13, j + 54, k + 0, Blocks.log, 1);
		/* 1028 */world.setBlockMetadataWithNotify(i + 13, j + 54, k + 0, 1, 2);
		/* 1029 */setBlock(world, i + 13, j + 54, k + 1, Blocks.log, 1);
		/* 1030 */world.setBlockMetadataWithNotify(i + 13, j + 54, k + 1, 1, 2);
		/* 1031 */setBlock(world, i + 13, j + 54, k + 2, Blocks.log, 1);
		/* 1032 */world.setBlockMetadataWithNotify(i + 13, j + 54, k + 2, 1, 2);
		/* 1033 */setBlock(world, i + 13, j + 54, k + 3, Blocks.log, 1);
		/* 1034 */world.setBlockMetadataWithNotify(i + 13, j + 54, k + 3, 1, 2);
		/* 1035 */setBlock(world, i + 13, j + 54, k + 4, Blocks.log, 1);
		/* 1036 */world.setBlockMetadataWithNotify(i + 13, j + 54, k + 4, 1, 2);
		/* 1037 */setBlock(world, i + 13, j + 54, k + 5, Blocks.log, 1);
		/* 1038 */world.setBlockMetadataWithNotify(i + 13, j + 54, k + 5, 1, 2);
		/* 1039 */setBlock(world, i + 13, j + 54, k + 6, Blocks.log, 1);
		/* 1040 */world.setBlockMetadataWithNotify(i + 13, j + 54, k + 6, 1, 2);
		/* 1041 */setBlock(world, i + 13, j + 54, k + 7, Blocks.log, 1);
		/* 1042 */world.setBlockMetadataWithNotify(i + 13, j + 54, k + 7, 1, 2);
		/* 1043 */setBlock(world, i + 13, j + 54, k + 8, Blocks.log, 1);
		/* 1044 */world.setBlockMetadataWithNotify(i + 13, j + 54, k + 8, 1, 2);
		/* 1045 */setBlock(world, i + 13, j + 55, k + 0, Blocks.planks, 5);
		/* 1046 */world.setBlockMetadataWithNotify(i + 13, j + 55, k + 0, 5, 2);
		/* 1047 */setBlock(world, i + 13, j + 55, k + 1, Blocks.planks, 5);
		/* 1048 */world.setBlockMetadataWithNotify(i + 13, j + 55, k + 1, 5, 2);
		/* 1049 */setBlock(world, i + 13, j + 55, k + 2, Blocks.log, 1);
		/* 1050 */world.setBlockMetadataWithNotify(i + 13, j + 55, k + 2, 1, 2);
		/* 1051 */setBlock(world, i + 13, j + 55, k + 3, Blocks.log, 1);
		/* 1052 */world.setBlockMetadataWithNotify(i + 13, j + 55, k + 3, 1, 2);
		/* 1053 */setBlock(world, i + 13, j + 55, k + 4, Blocks.planks, 5);
		/* 1054 */world.setBlockMetadataWithNotify(i + 13, j + 55, k + 4, 5, 2);
		/* 1055 */setBlock(world, i + 13, j + 55, k + 5, Blocks.log, 1);
		/* 1056 */world.setBlockMetadataWithNotify(i + 13, j + 55, k + 5, 1, 2);
		/* 1057 */setBlock(world, i + 13, j + 55, k + 6, Blocks.log, 1);
		/* 1058 */world.setBlockMetadataWithNotify(i + 13, j + 55, k + 6, 1, 2);
		/* 1059 */setBlock(world, i + 13, j + 55, k + 7, Blocks.log, 1);
		/* 1060 */world.setBlockMetadataWithNotify(i + 13, j + 55, k + 7, 1, 2);
		/* 1061 */setBlock(world, i + 13, j + 55, k + 8, Blocks.log, 1);
		/* 1062 */world.setBlockMetadataWithNotify(i + 13, j + 55, k + 8, 1, 2);
		/* 1063 */setBlock(world, i + 13, j + 55, k + 9, Blocks.log, 1);
		/* 1064 */world.setBlockMetadataWithNotify(i + 13, j + 55, k + 9, 1, 2);
		/* 1065 */setBlock(world, i + 13, j + 55, k + 10, Blocks.log, 1);
		/* 1066 */world.setBlockMetadataWithNotify(i + 13, j + 55, k + 10, 1, 2);
		/* 1067 */setBlock(world, i + 13, j + 55, k + 11, Blocks.planks, 5);
		/* 1068 */world.setBlockMetadataWithNotify(i + 13, j + 55, k + 11, 5, 2);
		/* 1069 */setBlock(world, i + 13, j + 55, k + 12, Blocks.planks, 5);
		/* 1070 */world.setBlockMetadataWithNotify(i + 13, j + 55, k + 12, 5, 2);
		/* 1071 */setBlock(world, i + 13, j + 55, k + 13, Blocks.planks, 5);
		/* 1072 */world.setBlockMetadataWithNotify(i + 13, j + 55, k + 13, 5, 2);
		/* 1073 */setBlock(world, i + 13, j + 55, k + 14, Blocks.planks, 5);
		/* 1074 */world.setBlockMetadataWithNotify(i + 13, j + 55, k + 14, 5, 2);
		/* 1075 */setBlock(world, i + 13, j + 55, k + 15, Blocks.planks, 5);
		/* 1076 */world.setBlockMetadataWithNotify(i + 13, j + 55, k + 15, 5, 2);
		/* 1077 */setBlock(world, i + 13, j + 55, k + 16, Blocks.planks, 5);
		/* 1078 */world.setBlockMetadataWithNotify(i + 13, j + 55, k + 16, 5, 2);
		/* 1079 */setBlock(world, i + 13, j + 55, k + 17, Blocks.planks, 5);
		/* 1080 */world.setBlockMetadataWithNotify(i + 13, j + 55, k + 17, 5, 2);
		/* 1081 */setBlock(world, i + 13, j + 56, k + 9, Blocks.spruce_stairs, 1);
		/* 1082 */world.setBlockMetadataWithNotify(i + 13, j + 56, k + 9, 1, 2);
		/* 1083 */setBlock(world, i + 13, j + 56, k + 14, Blocks.torch, 5);
		/* 1084 */world.setBlockMetadataWithNotify(i + 13, j + 56, k + 14, 5, 2);
		/* 1085 */setBlock(world, i + 13, j + 56, k + 17, Blocks.torch, 5);
		/* 1086 */world.setBlockMetadataWithNotify(i + 13, j + 56, k + 17, 5, 2);
		/* 1087 */setBlock(world, i + 13, j + 58, k + 10, Blocks.torch, 1);
		/* 1088 */world.setBlockMetadataWithNotify(i + 13, j + 58, k + 10, 1, 2);
		/* 1089 */setBlock(world, i + 13, j + 59, k + 11, Blocks.spruce_stairs, 5);
		/* 1090 */world.setBlockMetadataWithNotify(i + 13, j + 59, k + 11, 5, 2);
		/* 1091 */setBlock(world, i + 13, j + 60, k + 6, Blocks.torch, 4);
		/* 1092 */world.setBlockMetadataWithNotify(i + 13, j + 60, k + 6, 4, 2);
		/* 1093 */setBlock(world, i + 13, j + 60, k + 7, Blocks.log, 1);
		/* 1094 */world.setBlockMetadataWithNotify(i + 13, j + 60, k + 7, 1, 2);
		/* 1095 */setBlock(world, i + 13, j + 60, k + 8, Blocks.log, 1);
		/* 1096 */world.setBlockMetadataWithNotify(i + 13, j + 60, k + 8, 1, 2);
		/* 1097 */setBlock(world, i + 13, j + 60, k + 9, Blocks.log, 1);
		/* 1098 */world.setBlockMetadataWithNotify(i + 13, j + 60, k + 9, 1, 2);
		/* 1099 */setBlock(world, i + 13, j + 60, k + 10, Blocks.log, 1);
		/* 1100 */world.setBlockMetadataWithNotify(i + 13, j + 60, k + 10, 1, 2);
		/* 1101 */setBlock(world, i + 13, j + 60, k + 11, Blocks.log, 1);
		/* 1102 */world.setBlockMetadataWithNotify(i + 13, j + 60, k + 11, 1, 2);
		/* 1103 */setBlock(world, i + 13, j + 60, k + 12, Blocks.log, 1);
		/* 1104 */world.setBlockMetadataWithNotify(i + 13, j + 60, k + 12, 1, 2);
		/* 1105 */setBlock(world, i + 13, j + 61, k + 6, Blocks.log, 1);
		/* 1106 */world.setBlockMetadataWithNotify(i + 13, j + 61, k + 6, 1, 2);
		/* 1107 */setBlock(world, i + 13, j + 61, k + 7, Blocks.log, 1);
		/* 1108 */world.setBlockMetadataWithNotify(i + 13, j + 61, k + 7, 1, 2);
		/* 1109 */setBlock(world, i + 13, j + 61, k + 8, Blocks.log, 1);
		/* 1110 */world.setBlockMetadataWithNotify(i + 13, j + 61, k + 8, 1, 2);
		/* 1111 */setBlock(world, i + 13, j + 61, k + 9, Blocks.log, 1);
		/* 1112 */world.setBlockMetadataWithNotify(i + 13, j + 61, k + 9, 1, 2);
		/* 1113 */setBlock(world, i + 13, j + 61, k + 10, Blocks.log, 1);
		/* 1114 */world.setBlockMetadataWithNotify(i + 13, j + 61, k + 10, 1, 2);
		/* 1115 */setBlock(world, i + 13, j + 61, k + 11, Blocks.log, 1);
		/* 1116 */world.setBlockMetadataWithNotify(i + 13, j + 61, k + 11, 1, 2);
		/* 1117 */setBlock(world, i + 13, j + 62, k + 1, Blocks.torch, 2);
		/* 1118 */world.setBlockMetadataWithNotify(i + 13, j + 62, k + 1, 2, 2);
		/* 1119 */setBlock(world, i + 13, j + 62, k + 4, Blocks.torch, 4);
		/* 1120 */world.setBlockMetadataWithNotify(i + 13, j + 62, k + 4, 4, 2);
		/* 1121 */setBlock(world, i + 13, j + 62, k + 5, Blocks.log, 1);
		/* 1122 */world.setBlockMetadataWithNotify(i + 13, j + 62, k + 5, 1, 2);
		/* 1123 */setBlock(world, i + 13, j + 62, k + 6, Blocks.log, 1);
		/* 1124 */world.setBlockMetadataWithNotify(i + 13, j + 62, k + 6, 1, 2);
		/* 1125 */setBlock(world, i + 13, j + 62, k + 7, Blocks.log, 1);
		/* 1126 */world.setBlockMetadataWithNotify(i + 13, j + 62, k + 7, 1, 2);
		/* 1127 */setBlock(world, i + 13, j + 62, k + 8, Blocks.log, 1);
		/* 1128 */world.setBlockMetadataWithNotify(i + 13, j + 62, k + 8, 1, 2);
		/* 1129 */setBlock(world, i + 13, j + 62, k + 9, Blocks.log, 1);
		/* 1130 */world.setBlockMetadataWithNotify(i + 13, j + 62, k + 9, 1, 2);
		/* 1131 */setBlock(world, i + 13, j + 63, k + 0, Blocks.log, 1);
		/* 1132 */world.setBlockMetadataWithNotify(i + 13, j + 63, k + 0, 1, 2);
		/* 1133 */setBlock(world, i + 13, j + 63, k + 1, Blocks.log, 1);
		/* 1134 */world.setBlockMetadataWithNotify(i + 13, j + 63, k + 1, 1, 2);
		/* 1135 */setBlock(world, i + 13, j + 63, k + 2, Blocks.log, 1);
		/* 1136 */world.setBlockMetadataWithNotify(i + 13, j + 63, k + 2, 1, 2);
		/* 1137 */setBlock(world, i + 13, j + 63, k + 3, Blocks.log, 1);
		/* 1138 */world.setBlockMetadataWithNotify(i + 13, j + 63, k + 3, 1, 2);
		/* 1139 */setBlock(world, i + 13, j + 63, k + 4, Blocks.log, 1);
		/* 1140 */world.setBlockMetadataWithNotify(i + 13, j + 63, k + 4, 1, 2);
		/* 1141 */setBlock(world, i + 13, j + 63, k + 5, Blocks.log, 1);
		/* 1142 */world.setBlockMetadataWithNotify(i + 13, j + 63, k + 5, 1, 2);
		/* 1143 */setBlock(world, i + 14, j + 20, k + 29, Blocks.log, 3);
		/* 1144 */world.setBlockMetadataWithNotify(i + 14, j + 20, k + 29, 3, 2);
		/* 1145 */setBlock(world, i + 14, j + 21, k + 25, Blocks.leaves, 7);
		/* 1146 */world.setBlockMetadataWithNotify(i + 14, j + 21, k + 25, 7, 2);
		/* 1147 */setBlock(world, i + 14, j + 21, k + 26, Blocks.leaves, 7);
		/* 1148 */world.setBlockMetadataWithNotify(i + 14, j + 21, k + 26, 7, 2);
		/* 1149 */setBlock(world, i + 14, j + 21, k + 27, Blocks.leaves, 7);
		/* 1150 */world.setBlockMetadataWithNotify(i + 14, j + 21, k + 27, 7, 2);
		/* 1151 */setBlock(world, i + 14, j + 21, k + 28, Blocks.leaves, 7);
		/* 1152 */world.setBlockMetadataWithNotify(i + 14, j + 21, k + 28, 7, 2);
		/* 1153 */setBlock(world, i + 14, j + 21, k + 29, Blocks.leaves, 7);
		/* 1154 */world.setBlockMetadataWithNotify(i + 14, j + 21, k + 29, 7, 2);
		/* 1155 */setBlock(world, i + 14, j + 22, k + 20, Blocks.log, 3);
		/* 1156 */world.setBlockMetadataWithNotify(i + 14, j + 22, k + 20, 3, 2);
		/* 1157 */setBlock(world, i + 14, j + 22, k + 21, Blocks.log, 3);
		/* 1158 */world.setBlockMetadataWithNotify(i + 14, j + 22, k + 21, 3, 2);
		/* 1159 */setBlock(world, i + 14, j + 22, k + 26, Blocks.leaves, 7);
		/* 1160 */world.setBlockMetadataWithNotify(i + 14, j + 22, k + 26, 7, 2);
		/* 1161 */setBlock(world, i + 14, j + 22, k + 27, Blocks.leaves, 7);
		/* 1162 */world.setBlockMetadataWithNotify(i + 14, j + 22, k + 27, 7, 2);
		/* 1163 */setBlock(world, i + 14, j + 22, k + 28, Blocks.leaves, 7);
		/*      */
		/* 1165 */generate93(world, rand, i, j, k);
		/* 1166 */return true;
		/*      */}

	/*      */
	/*      */public boolean generate93(World world, Random rand, int i, int j, int k)
	/*      */
	{
		/* 1171 */world.setBlockMetadataWithNotify(i + 14, j + 22, k + 28, 7, 2);
		/* 1172 */setBlock(world, i + 14, j + 23, k + 16, Blocks.leaves, 7);
		/* 1173 */world.setBlockMetadataWithNotify(i + 14, j + 23, k + 16, 7, 2);
		/* 1174 */setBlock(world, i + 14, j + 23, k + 17, Blocks.leaves, 7);
		/* 1175 */world.setBlockMetadataWithNotify(i + 14, j + 23, k + 17, 7, 2);
		/* 1176 */setBlock(world, i + 14, j + 23, k + 18, Blocks.leaves, 7);
		/* 1177 */world.setBlockMetadataWithNotify(i + 14, j + 23, k + 18, 7, 2);
		/* 1178 */setBlock(world, i + 14, j + 23, k + 19, Blocks.leaves, 7);
		/* 1179 */world.setBlockMetadataWithNotify(i + 14, j + 23, k + 19, 7, 2);
		/* 1180 */setBlock(world, i + 14, j + 23, k + 20, Blocks.leaves, 7);
		/* 1181 */world.setBlockMetadataWithNotify(i + 14, j + 23, k + 20, 7, 2);
		/* 1182 */setBlock(world, i + 14, j + 23, k + 27, Blocks.leaves, 7);
		/* 1183 */world.setBlockMetadataWithNotify(i + 14, j + 23, k + 27, 7, 2);
		/* 1184 */setBlock(world, i + 14, j + 24, k + 17, Blocks.leaves, 7);
		/* 1185 */world.setBlockMetadataWithNotify(i + 14, j + 24, k + 17, 7, 2);
		/* 1186 */setBlock(world, i + 14, j + 24, k + 18, Blocks.leaves, 7);
		/* 1187 */world.setBlockMetadataWithNotify(i + 14, j + 24, k + 18, 7, 2);
		/* 1188 */setBlock(world, i + 14, j + 24, k + 19, Blocks.leaves, 7);
		/* 1189 */world.setBlockMetadataWithNotify(i + 14, j + 24, k + 19, 7, 2);
		/* 1190 */setBlock(world, i + 14, j + 25, k + 18, Blocks.leaves, 7);
		/* 1191 */world.setBlockMetadataWithNotify(i + 14, j + 25, k + 18, 7, 2);
		/* 1192 */setBlock(world, i + 14, j + 26, k + 0, Blocks.log, 3);
		/* 1193 */world.setBlockMetadataWithNotify(i + 14, j + 26, k + 0, 3, 2);
		/* 1194 */setBlock(world, i + 14, j + 28, k + 0, Blocks.log, 3);
		/* 1195 */world.setBlockMetadataWithNotify(i + 14, j + 28, k + 0, 3, 2);
		/* 1196 */setBlock(world, i + 14, j + 29, k + 31, Blocks.leaves, 7);
		/* 1197 */world.setBlockMetadataWithNotify(i + 14, j + 29, k + 31, 7, 2);
		/* 1198 */setBlock(world, i + 14, j + 36, k + 2, Blocks.log, 3);
		/* 1199 */world.setBlockMetadataWithNotify(i + 14, j + 36, k + 2, 3, 2);
		/* 1200 */setBlock(world, i + 14, j + 37, k + 0, Blocks.leaves, 7);
		/* 1201 */world.setBlockMetadataWithNotify(i + 14, j + 37, k + 0, 7, 2);
		/* 1202 */setBlock(world, i + 14, j + 37, k + 1, Blocks.leaves, 7);
		/* 1203 */world.setBlockMetadataWithNotify(i + 14, j + 37, k + 1, 7, 2);
		/* 1204 */setBlock(world, i + 14, j + 37, k + 2, Blocks.leaves, 7);
		/* 1205 */world.setBlockMetadataWithNotify(i + 14, j + 37, k + 2, 7, 2);
		/* 1206 */setBlock(world, i + 14, j + 37, k + 3, Blocks.leaves, 7);
		/* 1207 */world.setBlockMetadataWithNotify(i + 14, j + 37, k + 3, 7, 2);
		/* 1208 */setBlock(world, i + 14, j + 37, k + 4, Blocks.leaves, 7);
		/* 1209 */world.setBlockMetadataWithNotify(i + 14, j + 37, k + 4, 7, 2);
		/* 1210 */setBlock(world, i + 14, j + 38, k + 1, Blocks.leaves, 7);
		/* 1211 */world.setBlockMetadataWithNotify(i + 14, j + 38, k + 1, 7, 2);
		/* 1212 */setBlock(world, i + 14, j + 38, k + 2, Blocks.leaves, 7);
		/* 1213 */world.setBlockMetadataWithNotify(i + 14, j + 38, k + 2, 7, 2);
		/* 1214 */setBlock(world, i + 14, j + 38, k + 3, Blocks.leaves, 7);
		/* 1215 */world.setBlockMetadataWithNotify(i + 14, j + 38, k + 3, 7, 2);
		/* 1216 */setBlock(world, i + 14, j + 38, k + 29, Blocks.leaves, 7);
		/* 1217 */world.setBlockMetadataWithNotify(i + 14, j + 38, k + 29, 7, 2);
		/* 1218 */setBlock(world, i + 14, j + 38, k + 30, Blocks.leaves, 7);
		/* 1219 */world.setBlockMetadataWithNotify(i + 14, j + 38, k + 30, 7, 2);
		/* 1220 */setBlock(world, i + 14, j + 38, k + 31, Blocks.leaves, 7);
		/* 1221 */world.setBlockMetadataWithNotify(i + 14, j + 38, k + 31, 7, 2);
		/* 1222 */setBlock(world, i + 14, j + 39, k + 2, Blocks.leaves, 7);
		/* 1223 */world.setBlockMetadataWithNotify(i + 14, j + 39, k + 2, 7, 2);
		/* 1224 */setBlock(world, i + 14, j + 39, k + 30, Blocks.leaves, 7);
		/* 1225 */world.setBlockMetadataWithNotify(i + 14, j + 39, k + 30, 7, 2);
		/* 1226 */setBlock(world, i + 14, j + 39, k + 31, Blocks.leaves, 7);
		/* 1227 */world.setBlockMetadataWithNotify(i + 14, j + 39, k + 31, 7, 2);
		/* 1228 */setBlock(world, i + 14, j + 40, k + 31, Blocks.leaves, 7);
		/* 1229 */world.setBlockMetadataWithNotify(i + 14, j + 40, k + 31, 7, 2);
		/* 1230 */setBlock(world, i + 14, j + 46, k + 0, Blocks.log, 1);
		/* 1231 */world.setBlockMetadataWithNotify(i + 14, j + 46, k + 0, 1, 2);
		/* 1232 */setBlock(world, i + 14, j + 46, k + 31, Blocks.leaves, 7);
		/* 1233 */world.setBlockMetadataWithNotify(i + 14, j + 46, k + 31, 7, 2);
		/* 1234 */setBlock(world, i + 14, j + 47, k + 0, Blocks.log, 1);
		/* 1235 */world.setBlockMetadataWithNotify(i + 14, j + 47, k + 0, 1, 2);
		/* 1236 */setBlock(world, i + 14, j + 47, k + 1, Blocks.log, 1);
		/* 1237 */world.setBlockMetadataWithNotify(i + 14, j + 47, k + 1, 1, 2);
		/* 1238 */setBlock(world, i + 14, j + 48, k + 0, Blocks.log, 1);
		/* 1239 */world.setBlockMetadataWithNotify(i + 14, j + 48, k + 0, 1, 2);
		/* 1240 */setBlock(world, i + 14, j + 49, k + 0, Blocks.log, 1);
		/* 1241 */world.setBlockMetadataWithNotify(i + 14, j + 49, k + 0, 1, 2);
		/* 1242 */setBlock(world, i + 14, j + 49, k + 1, Blocks.log, 1);
		/* 1243 */world.setBlockMetadataWithNotify(i + 14, j + 49, k + 1, 1, 2);
		/* 1244 */setBlock(world, i + 14, j + 49, k + 2, Blocks.log, 1);
		/* 1245 */world.setBlockMetadataWithNotify(i + 14, j + 49, k + 2, 1, 2);
		/* 1246 */setBlock(world, i + 14, j + 49, k + 3, Blocks.log, 1);
		/* 1247 */world.setBlockMetadataWithNotify(i + 14, j + 49, k + 3, 1, 2);
		/* 1248 */setBlock(world, i + 14, j + 50, k + 0, Blocks.log, 1);
		/* 1249 */world.setBlockMetadataWithNotify(i + 14, j + 50, k + 0, 1, 2);
		/* 1250 */setBlock(world, i + 14, j + 50, k + 1, Blocks.log, 1);
		/* 1251 */world.setBlockMetadataWithNotify(i + 14, j + 50, k + 1, 1, 2);
		/* 1252 */setBlock(world, i + 14, j + 50, k + 2, Blocks.log, 1);
		/* 1253 */world.setBlockMetadataWithNotify(i + 14, j + 50, k + 2, 1, 2);
		/* 1254 */setBlock(world, i + 14, j + 50, k + 3, Blocks.log, 1);
		/* 1255 */world.setBlockMetadataWithNotify(i + 14, j + 50, k + 3, 1, 2);
		/* 1256 */setBlock(world, i + 14, j + 51, k + 0, Blocks.log, 1);
		/* 1257 */world.setBlockMetadataWithNotify(i + 14, j + 51, k + 0, 1, 2);
		/* 1258 */setBlock(world, i + 14, j + 51, k + 1, Blocks.log, 1);
		/* 1259 */world.setBlockMetadataWithNotify(i + 14, j + 51, k + 1, 1, 2);
		/* 1260 */setBlock(world, i + 14, j + 51, k + 2, Blocks.log, 1);
		/* 1261 */world.setBlockMetadataWithNotify(i + 14, j + 51, k + 2, 1, 2);
		/* 1262 */setBlock(world, i + 14, j + 51, k + 3, Blocks.log, 1);
		/* 1263 */world.setBlockMetadataWithNotify(i + 14, j + 51, k + 3, 1, 2);
		/* 1264 */setBlock(world, i + 14, j + 52, k + 0, Blocks.log, 1);
		/* 1265 */world.setBlockMetadataWithNotify(i + 14, j + 52, k + 0, 1, 2);
		/* 1266 */setBlock(world, i + 14, j + 52, k + 1, Blocks.log, 1);
		/* 1267 */world.setBlockMetadataWithNotify(i + 14, j + 52, k + 1, 1, 2);
		/* 1268 */setBlock(world, i + 14, j + 52, k + 2, Blocks.log, 1);
		/* 1269 */world.setBlockMetadataWithNotify(i + 14, j + 52, k + 2, 1, 2);
		/* 1270 */setBlock(world, i + 14, j + 52, k + 3, Blocks.log, 1);
		/* 1271 */world.setBlockMetadataWithNotify(i + 14, j + 52, k + 3, 1, 2);
		/* 1272 */setBlock(world, i + 14, j + 52, k + 5, Blocks.log, 1);
		/* 1273 */world.setBlockMetadataWithNotify(i + 14, j + 52, k + 5, 1, 2);
		/* 1274 */setBlock(world, i + 14, j + 53, k + 0, Blocks.log, 1);
		/* 1275 */world.setBlockMetadataWithNotify(i + 14, j + 53, k + 0, 1, 2);
		/* 1276 */setBlock(world, i + 14, j + 53, k + 1, Blocks.log, 1);
		/* 1277 */world.setBlockMetadataWithNotify(i + 14, j + 53, k + 1, 1, 2);
		/* 1278 */setBlock(world, i + 14, j + 53, k + 2, Blocks.log, 1);
		/* 1279 */world.setBlockMetadataWithNotify(i + 14, j + 53, k + 2, 1, 2);
		/* 1280 */setBlock(world, i + 14, j + 53, k + 3, Blocks.log, 1);
		/* 1281 */world.setBlockMetadataWithNotify(i + 14, j + 53, k + 3, 1, 2);
		/* 1282 */setBlock(world, i + 14, j + 53, k + 4, Blocks.log, 1);
		/* 1283 */world.setBlockMetadataWithNotify(i + 14, j + 53, k + 4, 1, 2);
		/* 1284 */setBlock(world, i + 14, j + 53, k + 5, Blocks.log, 1);
		/* 1285 */world.setBlockMetadataWithNotify(i + 14, j + 53, k + 5, 1, 2);
		/* 1286 */setBlock(world, i + 14, j + 53, k + 6, Blocks.log, 1);
		/* 1287 */world.setBlockMetadataWithNotify(i + 14, j + 53, k + 6, 1, 2);
		/* 1288 */setBlock(world, i + 14, j + 53, k + 7, Blocks.log, 1);
		/* 1289 */world.setBlockMetadataWithNotify(i + 14, j + 53, k + 7, 1, 2);
		/* 1290 */setBlock(world, i + 14, j + 53, k + 8, Blocks.log, 1);
		/* 1291 */world.setBlockMetadataWithNotify(i + 14, j + 53, k + 8, 1, 2);
		/* 1292 */setBlock(world, i + 14, j + 54, k + 0, Blocks.log, 1);
		/* 1293 */world.setBlockMetadataWithNotify(i + 14, j + 54, k + 0, 1, 2);
		/* 1294 */setBlock(world, i + 14, j + 54, k + 1, Blocks.log, 1);
		/* 1295 */world.setBlockMetadataWithNotify(i + 14, j + 54, k + 1, 1, 2);
		/* 1296 */setBlock(world, i + 14, j + 54, k + 2, Blocks.log, 1);
		/* 1297 */world.setBlockMetadataWithNotify(i + 14, j + 54, k + 2, 1, 2);
		/* 1298 */setBlock(world, i + 14, j + 54, k + 3, Blocks.log, 1);
		/* 1299 */world.setBlockMetadataWithNotify(i + 14, j + 54, k + 3, 1, 2);
		/* 1300 */setBlock(world, i + 14, j + 54, k + 4, Blocks.log, 1);
		/* 1301 */world.setBlockMetadataWithNotify(i + 14, j + 54, k + 4, 1, 2);
		/* 1302 */setBlock(world, i + 14, j + 54, k + 5, Blocks.log, 1);
		/* 1303 */world.setBlockMetadataWithNotify(i + 14, j + 54, k + 5, 1, 2);
		/* 1304 */setBlock(world, i + 14, j + 54, k + 6, Blocks.log, 1);
		/* 1305 */world.setBlockMetadataWithNotify(i + 14, j + 54, k + 6, 1, 2);
		/* 1306 */setBlock(world, i + 14, j + 54, k + 7, Blocks.log, 1);
		/* 1307 */world.setBlockMetadataWithNotify(i + 14, j + 54, k + 7, 1, 2);
		/* 1308 */setBlock(world, i + 14, j + 54, k + 8, Blocks.log, 1);
		/* 1309 */world.setBlockMetadataWithNotify(i + 14, j + 54, k + 8, 1, 2);
		/* 1310 */setBlock(world, i + 14, j + 55, k + 0, Blocks.log, 1);
		/* 1311 */world.setBlockMetadataWithNotify(i + 14, j + 55, k + 0, 1, 2);
		/* 1312 */setBlock(world, i + 14, j + 55, k + 1, Blocks.planks, 5);
		/* 1313 */world.setBlockMetadataWithNotify(i + 14, j + 55, k + 1, 5, 2);
		/* 1314 */setBlock(world, i + 14, j + 55, k + 2, Blocks.planks, 5);
		/* 1315 */world.setBlockMetadataWithNotify(i + 14, j + 55, k + 2, 5, 2);
		/* 1316 */setBlock(world, i + 14, j + 55, k + 3, Blocks.log, 1);
		/* 1317 */world.setBlockMetadataWithNotify(i + 14, j + 55, k + 3, 1, 2);
		/* 1318 */setBlock(world, i + 14, j + 55, k + 4, Blocks.log, 1);
		/* 1319 */world.setBlockMetadataWithNotify(i + 14, j + 55, k + 4, 1, 2);
		/* 1320 */setBlock(world, i + 14, j + 55, k + 5, Blocks.planks, 5);
		/* 1321 */world.setBlockMetadataWithNotify(i + 14, j + 55, k + 5, 5, 2);
		/* 1322 */setBlock(world, i + 14, j + 55, k + 6, Blocks.log, 1);
		/* 1323 */world.setBlockMetadataWithNotify(i + 14, j + 55, k + 6, 1, 2);
		/* 1324 */setBlock(world, i + 14, j + 55, k + 7, Blocks.log, 1);
		/* 1325 */world.setBlockMetadataWithNotify(i + 14, j + 55, k + 7, 1, 2);
		/* 1326 */setBlock(world, i + 14, j + 55, k + 8, Blocks.log, 1);
		/* 1327 */world.setBlockMetadataWithNotify(i + 14, j + 55, k + 8, 1, 2);
		/* 1328 */setBlock(world, i + 14, j + 55, k + 9, Blocks.log, 1);
		/* 1329 */world.setBlockMetadataWithNotify(i + 14, j + 55, k + 9, 1, 2);
		/* 1330 */setBlock(world, i + 14, j + 55, k + 10, Blocks.log, 1);
		/* 1331 */world.setBlockMetadataWithNotify(i + 14, j + 55, k + 10, 1, 2);
		/* 1332 */setBlock(world, i + 14, j + 55, k + 11, Blocks.log, 1);
		/* 1333 */world.setBlockMetadataWithNotify(i + 14, j + 55, k + 11, 1, 2);
		/* 1334 */setBlock(world, i + 14, j + 55, k + 12, Blocks.planks, 5);
		/* 1335 */world.setBlockMetadataWithNotify(i + 14, j + 55, k + 12, 5, 2);
		/* 1336 */setBlock(world, i + 14, j + 55, k + 13, Blocks.planks, 5);
		/* 1337 */world.setBlockMetadataWithNotify(i + 14, j + 55, k + 13, 5, 2);
		/* 1338 */setBlock(world, i + 14, j + 55, k + 14, Blocks.planks, 5);
		/* 1339 */world.setBlockMetadataWithNotify(i + 14, j + 55, k + 14, 5, 2);
		/* 1340 */setBlock(world, i + 14, j + 55, k + 15, Blocks.planks, 5);
		/* 1341 */world.setBlockMetadataWithNotify(i + 14, j + 55, k + 15, 5, 2);
		/* 1342 */setBlock(world, i + 14, j + 55, k + 16, Blocks.planks, 5);
		/* 1343 */world.setBlockMetadataWithNotify(i + 14, j + 55, k + 16, 5, 2);
		/* 1344 */setBlock(world, i + 14, j + 55, k + 17, Blocks.planks, 5);
		/* 1345 */world.setBlockMetadataWithNotify(i + 14, j + 55, k + 17, 5, 2);
		/* 1346 */setBlock(world, i + 14, j + 56, k + 1, Blocks.chest, 4);
		/* 1347 */LootGenUtils.fillLootChest(world.provider.dimensionId, world.rand, (TileEntityChest)world.getTileEntity(i + 14, j + 56, k + 1));
		/* 1348 */world.setBlockMetadataWithNotify(i + 14, j + 56, k + 1, 4, 2);
		/* 1349 */setBlock(world, i + 14, j + 58, k + 0, Blocks.torch, 2);
		/* 1350 */world.setBlockMetadataWithNotify(i + 14, j + 58, k + 0, 2, 2);
		/* 1351 */setBlock(world, i + 14, j + 60, k + 8, Blocks.log, 1);
		/* 1352 */world.setBlockMetadataWithNotify(i + 14, j + 60, k + 8, 1, 2);
		/* 1353 */setBlock(world, i + 14, j + 60, k + 9, Blocks.log, 1);
		/* 1354 */world.setBlockMetadataWithNotify(i + 14, j + 60, k + 9, 1, 2);
		/* 1355 */setBlock(world, i + 14, j + 60, k + 10, Blocks.log, 1);
		/* 1356 */world.setBlockMetadataWithNotify(i + 14, j + 60, k + 10, 1, 2);
		/* 1357 */setBlock(world, i + 14, j + 60, k + 11, Blocks.log, 1);
		/* 1358 */world.setBlockMetadataWithNotify(i + 14, j + 60, k + 11, 1, 2);
		/* 1359 */setBlock(world, i + 14, j + 60, k + 12, Blocks.log, 1);
		/* 1360 */world.setBlockMetadataWithNotify(i + 14, j + 60, k + 12, 1, 2);
		/* 1361 */setBlock(world, i + 14, j + 60, k + 13, Blocks.log, 1);
		/* 1362 */world.setBlockMetadataWithNotify(i + 14, j + 60, k + 13, 1, 2);
		/* 1363 */setBlock(world, i + 14, j + 61, k + 7, Blocks.log, 1);
		/* 1364 */world.setBlockMetadataWithNotify(i + 14, j + 61, k + 7, 1, 2);
		/* 1365 */setBlock(world, i + 14, j + 61, k + 8, Blocks.log, 1);
		/* 1366 */world.setBlockMetadataWithNotify(i + 14, j + 61, k + 8, 1, 2);
		/* 1367 */setBlock(world, i + 14, j + 61, k + 9, Blocks.log, 1);
		/* 1368 */world.setBlockMetadataWithNotify(i + 14, j + 61, k + 9, 1, 2);
		/* 1369 */setBlock(world, i + 14, j + 61, k + 10, Blocks.log, 1);
		/* 1370 */world.setBlockMetadataWithNotify(i + 14, j + 61, k + 10, 1, 2);
		/* 1371 */setBlock(world, i + 14, j + 61, k + 11, Blocks.log, 1);
		/* 1372 */world.setBlockMetadataWithNotify(i + 14, j + 61, k + 11, 1, 2);
		/* 1373 */setBlock(world, i + 14, j + 61, k + 12, Blocks.log, 1);
		/* 1374 */world.setBlockMetadataWithNotify(i + 14, j + 61, k + 12, 1, 2);
		/* 1375 */setBlock(world, i + 14, j + 62, k + 0, Blocks.log, 1);
		/* 1376 */world.setBlockMetadataWithNotify(i + 14, j + 62, k + 0, 1, 2);
		/* 1377 */setBlock(world, i + 14, j + 62, k + 1, Blocks.log, 1);
		/* 1378 */world.setBlockMetadataWithNotify(i + 14, j + 62, k + 1, 1, 2);
		/* 1379 */setBlock(world, i + 14, j + 62, k + 2, Blocks.torch, 3);
		/* 1380 */world.setBlockMetadataWithNotify(i + 14, j + 62, k + 2, 3, 2);
		/* 1381 */setBlock(world, i + 14, j + 62, k + 6, Blocks.log, 1);
		/* 1382 */world.setBlockMetadataWithNotify(i + 14, j + 62, k + 6, 1, 2);
		/* 1383 */setBlock(world, i + 14, j + 62, k + 7, Blocks.log, 1);
		/* 1384 */world.setBlockMetadataWithNotify(i + 14, j + 62, k + 7, 1, 2);
		/* 1385 */setBlock(world, i + 14, j + 62, k + 8, Blocks.log, 1);
		/* 1386 */world.setBlockMetadataWithNotify(i + 14, j + 62, k + 8, 1, 2);
		/* 1387 */setBlock(world, i + 14, j + 62, k + 9, Blocks.log, 1);
		/* 1388 */world.setBlockMetadataWithNotify(i + 14, j + 62, k + 9, 1, 2);
		/* 1389 */setBlock(world, i + 14, j + 62, k + 10, Blocks.log, 1);
		/* 1390 */world.setBlockMetadataWithNotify(i + 14, j + 62, k + 10, 1, 2);
		/* 1391 */setBlock(world, i + 14, j + 63, k + 0, Blocks.log, 1);
		/* 1392 */world.setBlockMetadataWithNotify(i + 14, j + 63, k + 0, 1, 2);
		/* 1393 */setBlock(world, i + 14, j + 63, k + 1, Blocks.log, 1);
		/* 1394 */world.setBlockMetadataWithNotify(i + 14, j + 63, k + 1, 1, 2);
		/* 1395 */setBlock(world, i + 14, j + 63, k + 2, Blocks.log, 1);
		/* 1396 */world.setBlockMetadataWithNotify(i + 14, j + 63, k + 2, 1, 2);
		/* 1397 */setBlock(world, i + 14, j + 63, k + 3, Blocks.log, 1);
		/* 1398 */world.setBlockMetadataWithNotify(i + 14, j + 63, k + 3, 1, 2);
		/* 1399 */setBlock(world, i + 14, j + 63, k + 4, Blocks.log, 1);
		/* 1400 */world.setBlockMetadataWithNotify(i + 14, j + 63, k + 4, 1, 2);
		/* 1401 */setBlock(world, i + 14, j + 63, k + 5, Blocks.log, 1);
		/* 1402 */world.setBlockMetadataWithNotify(i + 14, j + 63, k + 5, 1, 2);
		/* 1403 */setBlock(world, i + 15, j + 20, k + 30, Blocks.log, 3);
		/* 1404 */world.setBlockMetadataWithNotify(i + 15, j + 20, k + 30, 3, 2);
		/* 1405 */setBlock(world, i + 15, j + 20, k + 31, Blocks.log, 3);
		/* 1406 */world.setBlockMetadataWithNotify(i + 15, j + 20, k + 31, 3, 2);
		/* 1407 */setBlock(world, i + 15, j + 21, k + 26, Blocks.leaves, 7);
		/* 1408 */world.setBlockMetadataWithNotify(i + 15, j + 21, k + 26, 7, 2);
		/* 1409 */setBlock(world, i + 15, j + 21, k + 27, Blocks.leaves, 7);
		/* 1410 */world.setBlockMetadataWithNotify(i + 15, j + 21, k + 27, 7, 2);
		/* 1411 */setBlock(world, i + 15, j + 21, k + 28, Blocks.leaves, 7);
		/* 1412 */world.setBlockMetadataWithNotify(i + 15, j + 21, k + 28, 7, 2);
		/* 1413 */setBlock(world, i + 15, j + 22, k + 22, Blocks.log, 3);
		/* 1414 */world.setBlockMetadataWithNotify(i + 15, j + 22, k + 22, 3, 2);
		/* 1415 */setBlock(world, i + 15, j + 22, k + 27, Blocks.leaves, 7);
		/* 1416 */world.setBlockMetadataWithNotify(i + 15, j + 22, k + 27, 7, 2);
		/* 1417 */setBlock(world, i + 15, j + 23, k + 17, Blocks.leaves, 7);
		/* 1418 */world.setBlockMetadataWithNotify(i + 15, j + 23, k + 17, 7, 2);
		/* 1419 */setBlock(world, i + 15, j + 23, k + 18, Blocks.leaves, 7);
		/* 1420 */world.setBlockMetadataWithNotify(i + 15, j + 23, k + 18, 7, 2);
		/* 1421 */setBlock(world, i + 15, j + 23, k + 19, Blocks.leaves, 7);
		/* 1422 */world.setBlockMetadataWithNotify(i + 15, j + 23, k + 19, 7, 2);
		/* 1423 */setBlock(world, i + 15, j + 24, k + 18, Blocks.leaves, 7);
		/* 1424 */world.setBlockMetadataWithNotify(i + 15, j + 24, k + 18, 7, 2);
		/* 1425 */setBlock(world, i + 15, j + 30, k + 1, Blocks.leaves, 7);
		/* 1426 */world.setBlockMetadataWithNotify(i + 15, j + 30, k + 1, 7, 2);
		/* 1427 */setBlock(world, i + 15, j + 30, k + 2, Blocks.leaves, 7);
		/* 1428 */world.setBlockMetadataWithNotify(i + 15, j + 30, k + 2, 7, 2);
		/* 1429 */setBlock(world, i + 15, j + 30, k + 3, Blocks.leaves, 7);
		/* 1430 */world.setBlockMetadataWithNotify(i + 15, j + 30, k + 3, 7, 2);
		/* 1431 */setBlock(world, i + 15, j + 31, k + 2, Blocks.leaves, 7);
		/* 1432 */world.setBlockMetadataWithNotify(i + 15, j + 31, k + 2, 7, 2);
		/* 1433 */setBlock(world, i + 15, j + 36, k + 1, Blocks.log, 3);
		/* 1434 */world.setBlockMetadataWithNotify(i + 15, j + 36, k + 1, 3, 2);
		/* 1435 */setBlock(world, i + 15, j + 37, k + 1, Blocks.leaves, 7);
		/* 1436 */world.setBlockMetadataWithNotify(i + 15, j + 37, k + 1, 7, 2);
		/* 1437 */setBlock(world, i + 15, j + 37, k + 2, Blocks.leaves, 7);
		/* 1438 */world.setBlockMetadataWithNotify(i + 15, j + 37, k + 2, 7, 2);
		/* 1439 */setBlock(world, i + 15, j + 37, k + 3, Blocks.leaves, 7);
		/* 1440 */world.setBlockMetadataWithNotify(i + 15, j + 37, k + 3, 7, 2);
		/* 1441 */setBlock(world, i + 15, j + 37, k + 24, Blocks.leaves, 7);
		/* 1442 */world.setBlockMetadataWithNotify(i + 15, j + 37, k + 24, 7, 2);
		/* 1443 */setBlock(world, i + 15, j + 37, k + 25, Blocks.leaves, 7);
		/* 1444 */world.setBlockMetadataWithNotify(i + 15, j + 37, k + 25, 7, 2);
		/* 1445 */setBlock(world, i + 15, j + 37, k + 26, Blocks.leaves, 7);
		/* 1446 */world.setBlockMetadataWithNotify(i + 15, j + 37, k + 26, 7, 2);
		/* 1447 */setBlock(world, i + 15, j + 38, k + 2, Blocks.leaves, 7);
		/* 1448 */world.setBlockMetadataWithNotify(i + 15, j + 38, k + 2, 7, 2);
		/* 1449 */setBlock(world, i + 15, j + 38, k + 25, Blocks.leaves, 7);
		/* 1450 */world.setBlockMetadataWithNotify(i + 15, j + 38, k + 25, 7, 2);
		/* 1451 */setBlock(world, i + 15, j + 38, k + 29, Blocks.leaves, 7);
		/* 1452 */world.setBlockMetadataWithNotify(i + 15, j + 38, k + 29, 7, 2);
		/* 1453 */setBlock(world, i + 15, j + 38, k + 30, Blocks.leaves, 7);
		/* 1454 */world.setBlockMetadataWithNotify(i + 15, j + 38, k + 30, 7, 2);
		/* 1455 */setBlock(world, i + 15, j + 38, k + 31, Blocks.log, 3);
		/* 1456 */world.setBlockMetadataWithNotify(i + 15, j + 38, k + 31, 3, 2);
		/* 1457 */setBlock(world, i + 15, j + 39, k + 29, Blocks.leaves, 7);
		/* 1458 */world.setBlockMetadataWithNotify(i + 15, j + 39, k + 29, 7, 2);
		/* 1459 */setBlock(world, i + 15, j + 39, k + 30, Blocks.leaves, 7);
		/* 1460 */world.setBlockMetadataWithNotify(i + 15, j + 39, k + 30, 7, 2);
		/* 1461 */setBlock(world, i + 15, j + 39, k + 31, Blocks.leaves, 7);
		/* 1462 */world.setBlockMetadataWithNotify(i + 15, j + 39, k + 31, 7, 2);
		/* 1463 */setBlock(world, i + 15, j + 40, k + 30, Blocks.leaves, 7);
		/* 1464 */world.setBlockMetadataWithNotify(i + 15, j + 40, k + 30, 7, 2);
		/* 1465 */setBlock(world, i + 15, j + 40, k + 31, Blocks.leaves, 7);
		/* 1466 */world.setBlockMetadataWithNotify(i + 15, j + 40, k + 31, 7, 2);
		/* 1467 */setBlock(world, i + 15, j + 41, k + 31, Blocks.leaves, 7);
		/* 1468 */world.setBlockMetadataWithNotify(i + 15, j + 41, k + 31, 7, 2);
		/* 1469 */setBlock(world, i + 15, j + 42, k + 25, Blocks.leaves, 7);
		/* 1470 */world.setBlockMetadataWithNotify(i + 15, j + 42, k + 25, 7, 2);
		/* 1471 */setBlock(world, i + 15, j + 42, k + 26, Blocks.leaves, 7);
		/* 1472 */world.setBlockMetadataWithNotify(i + 15, j + 42, k + 26, 7, 2);
		/* 1473 */setBlock(world, i + 15, j + 42, k + 27, Blocks.leaves, 7);
		/* 1474 */world.setBlockMetadataWithNotify(i + 15, j + 42, k + 27, 7, 2);
		/* 1475 */setBlock(world, i + 15, j + 43, k + 4, Blocks.leaves, 7);
		/* 1476 */world.setBlockMetadataWithNotify(i + 15, j + 43, k + 4, 7, 2);
		/* 1477 */setBlock(world, i + 15, j + 43, k + 5, Blocks.leaves, 7);
		/* 1478 */world.setBlockMetadataWithNotify(i + 15, j + 43, k + 5, 7, 2);
		/* 1479 */setBlock(world, i + 15, j + 43, k + 6, Blocks.leaves, 7);
		/* 1480 */world.setBlockMetadataWithNotify(i + 15, j + 43, k + 6, 7, 2);
		/* 1481 */setBlock(world, i + 15, j + 43, k + 26, Blocks.leaves, 7);
		/* 1482 */world.setBlockMetadataWithNotify(i + 15, j + 43, k + 26, 7, 2);
		/* 1483 */setBlock(world, i + 15, j + 44, k + 5, Blocks.leaves, 7);
		/* 1484 */world.setBlockMetadataWithNotify(i + 15, j + 44, k + 5, 7, 2);
		/* 1485 */setBlock(world, i + 15, j + 46, k + 0, Blocks.leaves, 7);
		/* 1486 */world.setBlockMetadataWithNotify(i + 15, j + 46, k + 0, 7, 2);
		/* 1487 */setBlock(world, i + 15, j + 46, k + 30, Blocks.leaves, 7);
		/* 1488 */world.setBlockMetadataWithNotify(i + 15, j + 46, k + 30, 7, 2);
		/* 1489 */setBlock(world, i + 15, j + 46, k + 31, Blocks.leaves, 7);
		/* 1490 */world.setBlockMetadataWithNotify(i + 15, j + 46, k + 31, 7, 2);
		/* 1491 */setBlock(world, i + 15, j + 47, k + 0, Blocks.leaves, 7);
		/* 1492 */world.setBlockMetadataWithNotify(i + 15, j + 47, k + 0, 7, 2);
		/* 1493 */setBlock(world, i + 15, j + 47, k + 1, Blocks.leaves, 7);
		/* 1494 */world.setBlockMetadataWithNotify(i + 15, j + 47, k + 1, 7, 2);
		/* 1495 */setBlock(world, i + 15, j + 47, k + 31, Blocks.leaves, 7);
		/* 1496 */world.setBlockMetadataWithNotify(i + 15, j + 47, k + 31, 7, 2);
		/* 1497 */setBlock(world, i + 15, j + 48, k + 0, Blocks.log, 1);
		/* 1498 */world.setBlockMetadataWithNotify(i + 15, j + 48, k + 0, 1, 2);
		/* 1499 */setBlock(world, i + 15, j + 48, k + 1, Blocks.log, 1);
		/* 1500 */world.setBlockMetadataWithNotify(i + 15, j + 48, k + 1, 1, 2);
		/* 1501 */setBlock(world, i + 15, j + 49, k + 0, Blocks.log, 1);
		/* 1502 */world.setBlockMetadataWithNotify(i + 15, j + 49, k + 0, 1, 2);
		/* 1503 */setBlock(world, i + 15, j + 49, k + 1, Blocks.log, 1);
		/* 1504 */world.setBlockMetadataWithNotify(i + 15, j + 49, k + 1, 1, 2);
		/* 1505 */setBlock(world, i + 15, j + 49, k + 2, Blocks.log, 1);
		/* 1506 */world.setBlockMetadataWithNotify(i + 15, j + 49, k + 2, 1, 2);
		/* 1507 */setBlock(world, i + 15, j + 50, k + 0, Blocks.log, 1);
		/* 1508 */world.setBlockMetadataWithNotify(i + 15, j + 50, k + 0, 1, 2);
		/* 1509 */setBlock(world, i + 15, j + 50, k + 1, Blocks.log, 1);
		/* 1510 */world.setBlockMetadataWithNotify(i + 15, j + 50, k + 1, 1, 2);
		/* 1511 */setBlock(world, i + 15, j + 50, k + 2, Blocks.log, 1);
		/* 1512 */world.setBlockMetadataWithNotify(i + 15, j + 50, k + 2, 1, 2);
		/* 1513 */setBlock(world, i + 15, j + 50, k + 3, Blocks.log, 1);
		/* 1514 */world.setBlockMetadataWithNotify(i + 15, j + 50, k + 3, 1, 2);
		/* 1515 */setBlock(world, i + 15, j + 51, k + 0, Blocks.log, 1);
		/* 1516 */world.setBlockMetadataWithNotify(i + 15, j + 51, k + 0, 1, 2);
		/* 1517 */setBlock(world, i + 15, j + 51, k + 1, Blocks.log, 1);
		/* 1518 */world.setBlockMetadataWithNotify(i + 15, j + 51, k + 1, 1, 2);
		/* 1519 */setBlock(world, i + 15, j + 51, k + 2, Blocks.log, 1);
		/* 1520 */world.setBlockMetadataWithNotify(i + 15, j + 51, k + 2, 1, 2);
		/* 1521 */setBlock(world, i + 15, j + 51, k + 3, Blocks.log, 1);
		/* 1522 */world.setBlockMetadataWithNotify(i + 15, j + 51, k + 3, 1, 2);
		/* 1523 */setBlock(world, i + 15, j + 52, k + 0, Blocks.log, 1);
		/* 1524 */world.setBlockMetadataWithNotify(i + 15, j + 52, k + 0, 1, 2);
		/* 1525 */setBlock(world, i + 15, j + 52, k + 1, Blocks.log, 1);
		/* 1526 */world.setBlockMetadataWithNotify(i + 15, j + 52, k + 1, 1, 2);
		/* 1527 */setBlock(world, i + 15, j + 52, k + 2, Blocks.log, 1);
		/* 1528 */world.setBlockMetadataWithNotify(i + 15, j + 52, k + 2, 1, 2);
		/* 1529 */setBlock(world, i + 15, j + 52, k + 3, Blocks.log, 1);
		/* 1530 */world.setBlockMetadataWithNotify(i + 15, j + 52, k + 3, 1, 2);
		/* 1531 */setBlock(world, i + 15, j + 52, k + 4, Blocks.log, 1);
		/* 1532 */world.setBlockMetadataWithNotify(i + 15, j + 52, k + 4, 1, 2);
		/* 1533 */setBlock(world, i + 15, j + 52, k + 5, Blocks.log, 1);
		/* 1534 */world.setBlockMetadataWithNotify(i + 15, j + 52, k + 5, 1, 2);
		/* 1535 */setBlock(world, i + 15, j + 52, k + 6, Blocks.log, 1);
		/* 1536 */world.setBlockMetadataWithNotify(i + 15, j + 52, k + 6, 1, 2);
		/* 1537 */setBlock(world, i + 15, j + 53, k + 0, Blocks.log, 1);
		/* 1538 */world.setBlockMetadataWithNotify(i + 15, j + 53, k + 0, 1, 2);
		/* 1539 */setBlock(world, i + 15, j + 53, k + 1, Blocks.log, 1);
		/* 1540 */world.setBlockMetadataWithNotify(i + 15, j + 53, k + 1, 1, 2);
		/* 1541 */setBlock(world, i + 15, j + 53, k + 2, Blocks.log, 1);
		/* 1542 */world.setBlockMetadataWithNotify(i + 15, j + 53, k + 2, 1, 2);
		/* 1543 */setBlock(world, i + 15, j + 53, k + 3, Blocks.log, 1);
		/* 1544 */world.setBlockMetadataWithNotify(i + 15, j + 53, k + 3, 1, 2);
		/* 1545 */setBlock(world, i + 15, j + 53, k + 4, Blocks.log, 1);
		/* 1546 */world.setBlockMetadataWithNotify(i + 15, j + 53, k + 4, 1, 2);
		/* 1547 */setBlock(world, i + 15, j + 53, k + 5, Blocks.log, 1);
		/* 1548 */world.setBlockMetadataWithNotify(i + 15, j + 53, k + 5, 1, 2);
		/* 1549 */setBlock(world, i + 15, j + 53, k + 6, Blocks.log, 1);
		/* 1550 */world.setBlockMetadataWithNotify(i + 15, j + 53, k + 6, 1, 2);
		/* 1551 */setBlock(world, i + 15, j + 53, k + 7, Blocks.log, 1);
		/* 1552 */world.setBlockMetadataWithNotify(i + 15, j + 53, k + 7, 1, 2);
		/* 1553 */setBlock(world, i + 15, j + 53, k + 8, Blocks.log, 1);
		/* 1554 */world.setBlockMetadataWithNotify(i + 15, j + 53, k + 8, 1, 2);
		/* 1555 */setBlock(world, i + 15, j + 54, k + 0, Blocks.log, 1);
		/* 1556 */world.setBlockMetadataWithNotify(i + 15, j + 54, k + 0, 1, 2);
		/* 1557 */setBlock(world, i + 15, j + 54, k + 1, Blocks.log, 1);
		/* 1558 */world.setBlockMetadataWithNotify(i + 15, j + 54, k + 1, 1, 2);
		/* 1559 */setBlock(world, i + 15, j + 54, k + 2, Blocks.log, 1);
		/* 1560 */world.setBlockMetadataWithNotify(i + 15, j + 54, k + 2, 1, 2);
		/* 1561 */setBlock(world, i + 15, j + 54, k + 3, Blocks.log, 1);
		/* 1562 */world.setBlockMetadataWithNotify(i + 15, j + 54, k + 3, 1, 2);
		/* 1563 */setBlock(world, i + 15, j + 54, k + 4, Blocks.log, 1);
		/* 1564 */world.setBlockMetadataWithNotify(i + 15, j + 54, k + 4, 1, 2);
		/* 1565 */setBlock(world, i + 15, j + 54, k + 5, Blocks.log, 1);
		/* 1566 */world.setBlockMetadataWithNotify(i + 15, j + 54, k + 5, 1, 2);
		/* 1567 */setBlock(world, i + 15, j + 54, k + 6, Blocks.log, 1);
		/* 1568 */world.setBlockMetadataWithNotify(i + 15, j + 54, k + 6, 1, 2);
		/* 1569 */setBlock(world, i + 15, j + 54, k + 7, Blocks.log, 1);
		/* 1570 */world.setBlockMetadataWithNotify(i + 15, j + 54, k + 7, 1, 2);
