package com.parzivail.pswm.world.gen.wookietree;


import cpw.mods.fml.common.IWorldGenerator;

import java.util.Random;

import net.minecraft.block.Block;

import net.minecraft.init.Blocks;

import net.minecraft.world.World;

import net.minecraft.world.chunk.IChunkProvider;

import net.minecraft.world.gen.feature.WorldGenerator;


public class WT_13 extends WorldGenerator implements IWorldGenerator

{
	protected Block[] getValidSpawnBlocks()
	
	{
		return new Block[0];
		}

	
	public boolean locationIsValidSpawn(World world, int i, int j, int k)
	
	{
		int distanceToAir = 0;
		Block check = world.getBlock(i, j, k);
		
		while (check != Blocks.air)
		{
			if (distanceToAir > 3) { return false;
			}
			
			distanceToAir++;
			check = world.getBlock(i, j + distanceToAir, k);
			}
		
		j += distanceToAir - 1;
		
		Block block = world.getBlock(i, j, k);
		Block blockAbove = world.getBlock(i, j + 1, k);
		Block blockBelow = world.getBlock(i, j - 1, k);
		
		for (Block x : getValidSpawnBlocks())
		{
			if (blockAbove != Blocks.air) { return false;
			}
			if (block == x) return true;
			if ((block == Blocks.snow) && (blockBelow == x)) { return true;
			}
			}
		
		return false;
		}

	
	
	
	public void generate(Random random, int chunkX, int chunkZ, World world, IChunkProvider chunkGenerator, IChunkProvider chunkProvider)
	{
	}

	
	
	public void setBlock(World world, int x, int y, int z, Block block, int metadata)
	
	{
		world.setBlock(x, y, z, block, metadata, 2);
		}

	
	public boolean generate(World world, Random rand, int i, int j, int k)
	
	{
		k -= 10;
		i -= 10;
		
		setBlock(world, i + 0, j + 38, k + 19, Blocks.fence, 0);
		setBlock(world, i + 0, j + 38, k + 20, Blocks.fence, 0);
		setBlock(world, i + 0, j + 38, k + 29, Blocks.fence, 0);
		setBlock(world, i + 0, j + 38, k + 30, Blocks.fence, 0);
		setBlock(world, i + 0, j + 41, k + 17, Blocks.fence, 0);
		setBlock(world, i + 1, j + 38, k + 20, Blocks.fence, 0);
		setBlock(world, i + 1, j + 38, k + 29, Blocks.fence, 0);
		setBlock(world, i + 1, j + 41, k + 17, Blocks.fence, 0);
		setBlock(world, i + 1, j + 41, k + 18, Blocks.fence, 0);
		setBlock(world, i + 1, j + 41, k + 31, Blocks.fence, 0);
		setBlock(world, i + 2, j + 38, k + 20, Blocks.fence, 0);
		setBlock(world, i + 2, j + 38, k + 21, Blocks.spruce_stairs, 0);
		setBlock(world, i + 2, j + 38, k + 28, Blocks.spruce_stairs, 0);
		setBlock(world, i + 2, j + 38, k + 29, Blocks.fence, 0);
		setBlock(world, i + 2, j + 41, k + 18, Blocks.fence, 0);
		setBlock(world, i + 2, j + 41, k + 31, Blocks.fence, 0);
		setBlock(world, i + 3, j + 41, k + 18, Blocks.fence, 0);
		setBlock(world, i + 3, j + 41, k + 19, Blocks.fence, 0);
		setBlock(world, i + 3, j + 41, k + 30, Blocks.fence, 0);
		setBlock(world, i + 3, j + 41, k + 31, Blocks.fence, 0);
		setBlock(world, i + 4, j + 41, k + 19, Blocks.fence, 0);
		setBlock(world, i + 4, j + 41, k + 20, Blocks.fence, 0);
		setBlock(world, i + 4, j + 41, k + 29, Blocks.fence, 0);
		setBlock(world, i + 4, j + 41, k + 30, Blocks.fence, 0);
		setBlock(world, i + 5, j + 41, k + 20, Blocks.fence, 0);
		setBlock(world, i + 5, j + 41, k + 29, Blocks.fence, 0);
		setBlock(world, i + 0, j + 35, k + 27, Blocks.log, 1);
		world.setBlockMetadataWithNotify(i + 0, j + 35, k + 27, 1, 2);
		setBlock(world, i + 0, j + 35, k + 28, Blocks.log, 1);
		world.setBlockMetadataWithNotify(i + 0, j + 35, k + 28, 1, 2);
		setBlock(world, i + 0, j + 35, k + 29, Blocks.log, 1);
		world.setBlockMetadataWithNotify(i + 0, j + 35, k + 29, 1, 2);
		setBlock(world, i + 0, j + 36, k + 26, Blocks.log, 1);
		world.setBlockMetadataWithNotify(i + 0, j + 36, k + 26, 1, 2);
		setBlock(world, i + 0, j + 36, k + 27, Blocks.log, 1);
		world.setBlockMetadataWithNotify(i + 0, j + 36, k + 27, 1, 2);
		setBlock(world, i + 0, j + 36, k + 28, Blocks.log, 1);
		world.setBlockMetadataWithNotify(i + 0, j + 36, k + 28, 1, 2);
		setBlock(world, i + 0, j + 36, k + 29, Blocks.log, 1);
		world.setBlockMetadataWithNotify(i + 0, j + 36, k + 29, 1, 2);
		setBlock(world, i + 0, j + 37, k + 19, Blocks.log, 1);
		world.setBlockMetadataWithNotify(i + 0, j + 37, k + 19, 1, 2);
		setBlock(world, i + 0, j + 37, k + 20, Blocks.log, 1);
		world.setBlockMetadataWithNotify(i + 0, j + 37, k + 20, 1, 2);
		setBlock(world, i + 0, j + 37, k + 21, Blocks.log, 1);
		world.setBlockMetadataWithNotify(i + 0, j + 37, k + 21, 1, 2);
		setBlock(world, i + 0, j + 37, k + 22, Blocks.log, 1);
		world.setBlockMetadataWithNotify(i + 0, j + 37, k + 22, 1, 2);
		setBlock(world, i + 0, j + 37, k + 23, Blocks.log, 1);
		world.setBlockMetadataWithNotify(i + 0, j + 37, k + 23, 1, 2);
		setBlock(world, i + 0, j + 37, k + 24, Blocks.planks, 5);
		world.setBlockMetadataWithNotify(i + 0, j + 37, k + 24, 5, 2);
		setBlock(world, i + 0, j + 37, k + 25, Blocks.planks, 5);
		world.setBlockMetadataWithNotify(i + 0, j + 37, k + 25, 5, 2);
		setBlock(world, i + 0, j + 37, k + 26, Blocks.log, 1);
		world.setBlockMetadataWithNotify(i + 0, j + 37, k + 26, 1, 2);
		setBlock(world, i + 0, j + 37, k + 27, Blocks.log, 1);
		world.setBlockMetadataWithNotify(i + 0, j + 37, k + 27, 1, 2);
		setBlock(world, i + 0, j + 37, k + 28, Blocks.log, 1);
		world.setBlockMetadataWithNotify(i + 0, j + 37, k + 28, 1, 2);
		setBlock(world, i + 0, j + 37, k + 29, Blocks.log, 1);
		world.setBlockMetadataWithNotify(i + 0, j + 37, k + 29, 1, 2);
		setBlock(world, i + 0, j + 37, k + 30, Blocks.log, 1);
		world.setBlockMetadataWithNotify(i + 0, j + 37, k + 30, 1, 2);
		setBlock(world, i + 0, j + 42, k + 17, Blocks.log, 1);
		world.setBlockMetadataWithNotify(i + 0, j + 42, k + 17, 1, 2);
		setBlock(world, i + 0, j + 42, k + 18, Blocks.log, 1);
		world.setBlockMetadataWithNotify(i + 0, j + 42, k + 18, 1, 2);
		setBlock(world, i + 0, j + 42, k + 19, Blocks.log, 1);
		world.setBlockMetadataWithNotify(i + 0, j + 42, k + 19, 1, 2);
		setBlock(world, i + 0, j + 42, k + 20, Blocks.log, 1);
		world.setBlockMetadataWithNotify(i + 0, j + 42, k + 20, 1, 2);
		setBlock(world, i + 0, j + 42, k + 21, Blocks.log, 1);
		world.setBlockMetadataWithNotify(i + 0, j + 42, k + 21, 1, 2);
		setBlock(world, i + 0, j + 42, k + 22, Blocks.torch, 2);
		world.setBlockMetadataWithNotify(i + 0, j + 42, k + 22, 2, 2);
		setBlock(world, i + 0, j + 42, k + 27, Blocks.torch, 2);
		world.setBlockMetadataWithNotify(i + 0, j + 42, k + 27, 2, 2);
		setBlock(world, i + 0, j + 42, k + 28, Blocks.log, 1);
		world.setBlockMetadataWithNotify(i + 0, j + 42, k + 28, 1, 2);
		setBlock(world, i + 0, j + 42, k + 29, Blocks.log, 1);
		world.setBlockMetadataWithNotify(i + 0, j + 42, k + 29, 1, 2);
		setBlock(world, i + 0, j + 42, k + 30, Blocks.log, 1);
		world.setBlockMetadataWithNotify(i + 0, j + 42, k + 30, 1, 2);
		setBlock(world, i + 0, j + 42, k + 31, Blocks.log, 1);
		world.setBlockMetadataWithNotify(i + 0, j + 42, k + 31, 1, 2);
		setBlock(world, i + 0, j + 43, k + 18, Blocks.log, 1);
		world.setBlockMetadataWithNotify(i + 0, j + 43, k + 18, 1, 2);
		setBlock(world, i + 0, j + 43, k + 19, Blocks.log, 1);
		world.setBlockMetadataWithNotify(i + 0, j + 43, k + 19, 1, 2);
		setBlock(world, i + 0, j + 43, k + 20, Blocks.log, 1);
		world.setBlockMetadataWithNotify(i + 0, j + 43, k + 20, 1, 2);
		setBlock(world, i + 0, j + 43, k + 21, Blocks.log, 1);
		world.setBlockMetadataWithNotify(i + 0, j + 43, k + 21, 1, 2);
		setBlock(world, i + 0, j + 43, k + 22, Blocks.log, 1);
		world.setBlockMetadataWithNotify(i + 0, j + 43, k + 22, 1, 2);
		setBlock(world, i + 0, j + 43, k + 27, Blocks.log, 1);
		world.setBlockMetadataWithNotify(i + 0, j + 43, k + 27, 1, 2);
		setBlock(world, i + 0, j + 43, k + 28, Blocks.log, 1);
		world.setBlockMetadataWithNotify(i + 0, j + 43, k + 28, 1, 2);
		setBlock(world, i + 0, j + 43, k + 29, Blocks.log, 1);
		world.setBlockMetadataWithNotify(i + 0, j + 43, k + 29, 1, 2);
		setBlock(world, i + 0, j + 43, k + 30, Blocks.log, 1);
		world.setBlockMetadataWithNotify(i + 0, j + 43, k + 30, 1, 2);
		setBlock(world, i + 0, j + 43, k + 31, Blocks.log, 1);
		world.setBlockMetadataWithNotify(i + 0, j + 43, k + 31, 1, 2);
		setBlock(world, i + 0, j + 44, k + 19, Blocks.log, 1);
		world.setBlockMetadataWithNotify(i + 0, j + 44, k + 19, 1, 2);
		setBlock(world, i + 0, j + 44, k + 20, Blocks.log, 1);
		world.setBlockMetadataWithNotify(i + 0, j + 44, k + 20, 1, 2);
		setBlock(world, i + 0, j + 44, k + 21, Blocks.log, 1);
		world.setBlockMetadataWithNotify(i + 0, j + 44, k + 21, 1, 2);
		setBlock(world, i + 0, j + 44, k + 22, Blocks.log, 1);
		world.setBlockMetadataWithNotify(i + 0, j + 44, k + 22, 1, 2);
		setBlock(world, i + 0, j + 44, k + 23, Blocks.log, 1);
		world.setBlockMetadataWithNotify(i + 0, j + 44, k + 23, 1, 2);
		setBlock(world, i + 0, j + 44, k + 26, Blocks.log, 1);
		world.setBlockMetadataWithNotify(i + 0, j + 44, k + 26, 1, 2);
		setBlock(world, i + 0, j + 44, k + 27, Blocks.log, 1);
		world.setBlockMetadataWithNotify(i + 0, j + 44, k + 27, 1, 2);
		setBlock(world, i + 0, j + 44, k + 28, Blocks.log, 1);
		world.setBlockMetadataWithNotify(i + 0, j + 44, k + 28, 1, 2);
		setBlock(world, i + 0, j + 44, k + 29, Blocks.log, 1);
		world.setBlockMetadataWithNotify(i + 0, j + 44, k + 29, 1, 2);
		setBlock(world, i + 0, j + 44, k + 30, Blocks.log, 1);
		world.setBlockMetadataWithNotify(i + 0, j + 44, k + 30, 1, 2);
		setBlock(world, i + 0, j + 45, k + 24, Blocks.log, 1);
		world.setBlockMetadataWithNotify(i + 0, j + 45, k + 24, 1, 2);
		setBlock(world, i + 0, j + 45, k + 25, Blocks.log, 1);
		world.setBlockMetadataWithNotify(i + 0, j + 45, k + 25, 1, 2);
		setBlock(world, i + 1, j + 35, k + 27, Blocks.log, 1);
		world.setBlockMetadataWithNotify(i + 1, j + 35, k + 27, 1, 2);
		setBlock(world, i + 1, j + 35, k + 28, Blocks.log, 1);
		world.setBlockMetadataWithNotify(i + 1, j + 35, k + 28, 1, 2);
		setBlock(world, i + 1, j + 35, k + 29, Blocks.log, 1);
		world.setBlockMetadataWithNotify(i + 1, j + 35, k + 29, 1, 2);
		setBlock(world, i + 1, j + 36, k + 26, Blocks.log, 1);
		world.setBlockMetadataWithNotify(i + 1, j + 36, k + 26, 1, 2);
		setBlock(world, i + 1, j + 36, k + 27, Blocks.log, 1);
		world.setBlockMetadataWithNotify(i + 1, j + 36, k + 27, 1, 2);
		setBlock(world, i + 1, j + 36, k + 28, Blocks.log, 1);
		world.setBlockMetadataWithNotify(i + 1, j + 36, k + 28, 1, 2);
		setBlock(world, i + 1, j + 36, k + 29, Blocks.log, 1);
		world.setBlockMetadataWithNotify(i + 1, j + 36, k + 29, 1, 2);
		setBlock(world, i + 1, j + 37, k + 20, Blocks.log, 1);
		world.setBlockMetadataWithNotify(i + 1, j + 37, k + 20, 1, 2);
		setBlock(world, i + 1, j + 37, k + 21, Blocks.log, 1);
		world.setBlockMetadataWithNotify(i + 1, j + 37, k + 21, 1, 2);
		setBlock(world, i + 1, j + 37, k + 22, Blocks.log, 1);
		world.setBlockMetadataWithNotify(i + 1, j + 37, k + 22, 1, 2);
		setBlock(world, i + 1, j + 37, k + 23, Blocks.log, 1);
		world.setBlockMetadataWithNotify(i + 1, j + 37, k + 23, 1, 2);
		setBlock(world, i + 1, j + 37, k + 24, Blocks.planks, 5);
		world.setBlockMetadataWithNotify(i + 1, j + 37, k + 24, 5, 2);
		setBlock(world, i + 1, j + 37, k + 25, Blocks.planks, 5);
		world.setBlockMetadataWithNotify(i + 1, j + 37, k + 25, 5, 2);
		setBlock(world, i + 1, j + 37, k + 26, Blocks.log, 1);
		world.setBlockMetadataWithNotify(i + 1, j + 37, k + 26, 1, 2);
		setBlock(world, i + 1, j + 37, k + 27, Blocks.log, 1);
		world.setBlockMetadataWithNotify(i + 1, j + 37, k + 27, 1, 2);
		setBlock(world, i + 1, j + 37, k + 28, Blocks.log, 1);
		world.setBlockMetadataWithNotify(i + 1, j + 37, k + 28, 1, 2);
		setBlock(world, i + 1, j + 37, k + 29, Blocks.log, 1);
		world.setBlockMetadataWithNotify(i + 1, j + 37, k + 29, 1, 2);
		setBlock(world, i + 1, j + 42, k + 17, Blocks.log, 1);
		world.setBlockMetadataWithNotify(i + 1, j + 42, k + 17, 1, 2);
		setBlock(world, i + 1, j + 42, k + 18, Blocks.log, 1);
		world.setBlockMetadataWithNotify(i + 1, j + 42, k + 18, 1, 2);
		setBlock(world, i + 1, j + 42, k + 19, Blocks.log, 1);
		world.setBlockMetadataWithNotify(i + 1, j + 42, k + 19, 1, 2);
		setBlock(world, i + 1, j + 42, k + 20, Blocks.log, 1);
		world.setBlockMetadataWithNotify(i + 1, j + 42, k + 20, 1, 2);
		setBlock(world, i + 1, j + 42, k + 21, Blocks.log, 1);
		world.setBlockMetadataWithNotify(i + 1, j + 42, k + 21, 1, 2);
		setBlock(world, i + 1, j + 42, k + 22, Blocks.log, 1);
		world.setBlockMetadataWithNotify(i + 1, j + 42, k + 22, 1, 2);
		setBlock(world, i + 1, j + 42, k + 27, Blocks.log, 1);
		world.setBlockMetadataWithNotify(i + 1, j + 42, k + 27, 1, 2);
		setBlock(world, i + 1, j + 42, k + 28, Blocks.log, 1);
		world.setBlockMetadataWithNotify(i + 1, j + 42, k + 28, 1, 2);
		setBlock(world, i + 1, j + 42, k + 29, Blocks.log, 1);
		world.setBlockMetadataWithNotify(i + 1, j + 42, k + 29, 1, 2);
		setBlock(world, i + 1, j + 42, k + 30, Blocks.log, 1);
		world.setBlockMetadataWithNotify(i + 1, j + 42, k + 30, 1, 2);
		setBlock(world, i + 1, j + 42, k + 31, Blocks.log, 1);
		world.setBlockMetadataWithNotify(i + 1, j + 42, k + 31, 1, 2);
		setBlock(world, i + 1, j + 43, k + 18, Blocks.log, 1);
		world.setBlockMetadataWithNotify(i + 1, j + 43, k + 18, 1, 2);
		setBlock(world, i + 1, j + 43, k + 19, Blocks.log, 1);
		world.setBlockMetadataWithNotify(i + 1, j + 43, k + 19, 1, 2);
		setBlock(world, i + 1, j + 43, k + 20, Blocks.log, 1);
		world.setBlockMetadataWithNotify(i + 1, j + 43, k + 20, 1, 2);
		setBlock(world, i + 1, j + 43, k + 21, Blocks.log, 1);
		world.setBlockMetadataWithNotify(i + 1, j + 43, k + 21, 1, 2);
		setBlock(world, i + 1, j + 43, k + 22, Blocks.log, 1);
		world.setBlockMetadataWithNotify(i + 1, j + 43, k + 22, 1, 2);
		setBlock(world, i + 1, j + 43, k + 23, Blocks.log, 1);
		world.setBlockMetadataWithNotify(i + 1, j + 43, k + 23, 1, 2);
		setBlock(world, i + 1, j + 43, k + 26, Blocks.log, 1);
		world.setBlockMetadataWithNotify(i + 1, j + 43, k + 26, 1, 2);
		setBlock(world, i + 1, j + 43, k + 27, Blocks.log, 1);
		world.setBlockMetadataWithNotify(i + 1, j + 43, k + 27, 1, 2);
		setBlock(world, i + 1, j + 43, k + 28, Blocks.log, 1);
		world.setBlockMetadataWithNotify(i + 1, j + 43, k + 28, 1, 2);
		setBlock(world, i + 1, j + 43, k + 29, Blocks.log, 1);
		world.setBlockMetadataWithNotify(i + 1, j + 43, k + 29, 1, 2);
		setBlock(world, i + 1, j + 43, k + 30, Blocks.log, 1);
		world.setBlockMetadataWithNotify(i + 1, j + 43, k + 30, 1, 2);
		setBlock(world, i + 1, j + 43, k + 31, Blocks.log, 1);
		world.setBlockMetadataWithNotify(i + 1, j + 43, k + 31, 1, 2);
		setBlock(world, i + 1, j + 44, k + 20, Blocks.log, 1);
		world.setBlockMetadataWithNotify(i + 1, j + 44, k + 20, 1, 2);
		setBlock(world, i + 1, j + 44, k + 21, Blocks.log, 1);
		world.setBlockMetadataWithNotify(i + 1, j + 44, k + 21, 1, 2);
		setBlock(world, i + 1, j + 44, k + 22, Blocks.log, 1);
		world.setBlockMetadataWithNotify(i + 1, j + 44, k + 22, 1, 2);
		setBlock(world, i + 1, j + 44, k + 23, Blocks.log, 1);
		world.setBlockMetadataWithNotify(i + 1, j + 44, k + 23, 1, 2);
		setBlock(world, i + 1, j + 44, k + 24, Blocks.log, 1);
		world.setBlockMetadataWithNotify(i + 1, j + 44, k + 24, 1, 2);
		setBlock(world, i + 1, j + 44, k + 25, Blocks.log, 1);
		world.setBlockMetadataWithNotify(i + 1, j + 44, k + 25, 1, 2);
		setBlock(world, i + 1, j + 44, k + 26, Blocks.log, 1);
		world.setBlockMetadataWithNotify(i + 1, j + 44, k + 26, 1, 2);
		setBlock(world, i + 1, j + 44, k + 27, Blocks.log, 1);
		world.setBlockMetadataWithNotify(i + 1, j + 44, k + 27, 1, 2);
		setBlock(world, i + 1, j + 44, k + 28, Blocks.log, 1);
		world.setBlockMetadataWithNotify(i + 1, j + 44, k + 28, 1, 2);
		setBlock(world, i + 1, j + 44, k + 29, Blocks.log, 1);
		world.setBlockMetadataWithNotify(i + 1, j + 44, k + 29, 1, 2);
		setBlock(world, i + 2, j + 35, k + 28, Blocks.log, 1);
		world.setBlockMetadataWithNotify(i + 2, j + 35, k + 28, 1, 2);
		setBlock(world, i + 2, j + 36, k + 27, Blocks.log, 1);
		world.setBlockMetadataWithNotify(i + 2, j + 36, k + 27, 1, 2);
		setBlock(world, i + 2, j + 36, k + 28, Blocks.log, 1);
		world.setBlockMetadataWithNotify(i + 2, j + 36, k + 28, 1, 2);
		setBlock(world, i + 2, j + 37, k + 20, Blocks.log, 1);
		world.setBlockMetadataWithNotify(i + 2, j + 37, k + 20, 1, 2);
		setBlock(world, i + 2, j + 37, k + 21, Blocks.log, 1);
		world.setBlockMetadataWithNotify(i + 2, j + 37, k + 21, 1, 2);
		setBlock(world, i + 2, j + 37, k + 22, Blocks.log, 1);
		world.setBlockMetadataWithNotify(i + 2, j + 37, k + 22, 1, 2);
		setBlock(world, i + 2, j + 37, k + 23, Blocks.log, 1);
		world.setBlockMetadataWithNotify(i + 2, j + 37, k + 23, 1, 2);
		setBlock(world, i + 2, j + 37, k + 24, Blocks.planks, 5);
		world.setBlockMetadataWithNotify(i + 2, j + 37, k + 24, 5, 2);
		setBlock(world, i + 2, j + 37, k + 25, Blocks.planks, 5);
		world.setBlockMetadataWithNotify(i + 2, j + 37, k + 25, 5, 2);
		setBlock(world, i + 2, j + 37, k + 26, Blocks.log, 1);
		world.setBlockMetadataWithNotify(i + 2, j + 37, k + 26, 1, 2);
		setBlock(world, i + 2, j + 37, k + 27, Blocks.log, 1);
		world.setBlockMetadataWithNotify(i + 2, j + 37, k + 27, 1, 2);
		setBlock(world, i + 2, j + 37, k + 28, Blocks.log, 1);
		world.setBlockMetadataWithNotify(i + 2, j + 37, k + 28, 1, 2);
		setBlock(world, i + 2, j + 37, k + 29, Blocks.log, 1);
		world.setBlockMetadataWithNotify(i + 2, j + 37, k + 29, 1, 2);
		setBlock(world, i + 2, j + 39, k + 20, Blocks.torch, 5);
		world.setBlockMetadataWithNotify(i + 2, j + 39, k + 20, 5, 2);
		setBlock(world, i + 2, j + 39, k + 29, Blocks.torch, 5);
		world.setBlockMetadataWithNotify(i + 2, j + 39, k + 29, 5, 2);
		setBlock(world, i + 2, j + 42, k + 18, Blocks.log, 1);
		world.setBlockMetadataWithNotify(i + 2, j + 42, k + 18, 1, 2);
		setBlock(world, i + 2, j + 42, k + 19, Blocks.log, 1);
		world.setBlockMetadataWithNotify(i + 2, j + 42, k + 19, 1, 2);
		setBlock(world, i + 2, j + 42, k + 20, Blocks.log, 1);
		world.setBlockMetadataWithNotify(i + 2, j + 42, k + 20, 1, 2);
		setBlock(world, i + 2, j + 42, k + 21, Blocks.log, 1);
		world.setBlockMetadataWithNotify(i + 2, j + 42, k + 21, 1, 2);
		setBlock(world, i + 2, j + 42, k + 22, Blocks.log, 1);
		world.setBlockMetadataWithNotify(i + 2, j + 42, k + 22, 1, 2);
		setBlock(world, i + 2, j + 42, k + 23, Blocks.log, 1);
		world.setBlockMetadataWithNotify(i + 2, j + 42, k + 23, 1, 2);
		setBlock(world, i + 2, j + 42, k + 26, Blocks.log, 1);
		world.setBlockMetadataWithNotify(i + 2, j + 42, k + 26, 1, 2);
		setBlock(world, i + 2, j + 42, k + 27, Blocks.log, 1);
		world.setBlockMetadataWithNotify(i + 2, j + 42, k + 27, 1, 2);
		setBlock(world, i + 2, j + 42, k + 28, Blocks.log, 1);
		world.setBlockMetadataWithNotify(i + 2, j + 42, k + 28, 1, 2);
		setBlock(world, i + 2, j + 42, k + 29, Blocks.log, 1);
		world.setBlockMetadataWithNotify(i + 2, j + 42, k + 29, 1, 2);
		setBlock(world, i + 2, j + 42, k + 30, Blocks.log, 1);
		world.setBlockMetadataWithNotify(i + 2, j + 42, k + 30, 1, 2);
		setBlock(world, i + 2, j + 42, k + 31, Blocks.log, 1);
		world.setBlockMetadataWithNotify(i + 2, j + 42, k + 31, 1, 2);
		setBlock(world, i + 2, j + 43, k + 19, Blocks.log, 1);
		world.setBlockMetadataWithNotify(i + 2, j + 43, k + 19, 1, 2);
		setBlock(world, i + 2, j + 43, k + 20, Blocks.log, 1);
		world.setBlockMetadataWithNotify(i + 2, j + 43, k + 20, 1, 2);
		setBlock(world, i + 2, j + 43, k + 21, Blocks.log, 1);
		world.setBlockMetadataWithNotify(i + 2, j + 43, k + 21, 1, 2);
		setBlock(world, i + 2, j + 43, k + 22, Blocks.log, 1);
		world.setBlockMetadataWithNotify(i + 2, j + 43, k + 22, 1, 2);
		setBlock(world, i + 2, j + 43, k + 23, Blocks.log, 1);
		world.setBlockMetadataWithNotify(i + 2, j + 43, k + 23, 1, 2);
		setBlock(world, i + 2, j + 43, k + 24, Blocks.log, 1);
		world.setBlockMetadataWithNotify(i + 2, j + 43, k + 24, 1, 2);
		setBlock(world, i + 2, j + 43, k + 25, Blocks.log, 1);
		world.setBlockMetadataWithNotify(i + 2, j + 43, k + 25, 1, 2);
		setBlock(world, i + 2, j + 43, k + 26, Blocks.log, 1);
		world.setBlockMetadataWithNotify(i + 2, j + 43, k + 26, 1, 2);
		setBlock(world, i + 2, j + 43, k + 27, Blocks.log, 1);
		world.setBlockMetadataWithNotify(i + 2, j + 43, k + 27, 1, 2);
		setBlock(world, i + 2, j + 43, k + 28, Blocks.log, 1);
		world.setBlockMetadataWithNotify(i + 2, j + 43, k + 28, 1, 2);
		setBlock(world, i + 2, j + 43, k + 29, Blocks.log, 1);
		world.setBlockMetadataWithNotify(i + 2, j + 43, k + 29, 1, 2);
		setBlock(world, i + 2, j + 43, k + 30, Blocks.log, 1);
		world.setBlockMetadataWithNotify(i + 2, j + 43, k + 30, 1, 2);
		setBlock(world, i + 2, j + 44, k + 21, Blocks.log, 1);
		world.setBlockMetadataWithNotify(i + 2, j + 44, k + 21, 1, 2);
		setBlock(world, i + 2, j + 44, k + 22, Blocks.log, 1);
		world.setBlockMetadataWithNotify(i + 2, j + 44, k + 22, 1, 2);
		setBlock(world, i + 2, j + 44, k + 23, Blocks.log, 1);
		world.setBlockMetadataWithNotify(i + 2, j + 44, k + 23, 1, 2);
		setBlock(world, i + 2, j + 44, k + 24, Blocks.log, 1);
		world.setBlockMetadataWithNotify(i + 2, j + 44, k + 24, 1, 2);
		setBlock(world, i + 2, j + 44, k + 25, Blocks.log, 1);
		world.setBlockMetadataWithNotify(i + 2, j + 44, k + 25, 1, 2);
		setBlock(world, i + 2, j + 44, k + 26, Blocks.log, 1);
		world.setBlockMetadataWithNotify(i + 2, j + 44, k + 26, 1, 2);
		setBlock(world, i + 2, j + 44, k + 27, Blocks.log, 1);
		world.setBlockMetadataWithNotify(i + 2, j + 44, k + 27, 1, 2);
		setBlock(world, i + 2, j + 44, k + 28, Blocks.log, 1);
		world.setBlockMetadataWithNotify(i + 2, j + 44, k + 28, 1, 2);
		setBlock(world, i + 3, j + 37, k + 21, Blocks.log, 1);
		world.setBlockMetadataWithNotify(i + 3, j + 37, k + 21, 1, 2);
		setBlock(world, i + 3, j + 37, k + 22, Blocks.log, 1);
		world.setBlockMetadataWithNotify(i + 3, j + 37, k + 22, 1, 2);
		setBlock(world, i + 3, j + 37, k + 23, Blocks.log, 1);
		world.setBlockMetadataWithNotify(i + 3, j + 37, k + 23, 1, 2);
		setBlock(world, i + 3, j + 37, k + 24, Blocks.planks, 5);
		world.setBlockMetadataWithNotify(i + 3, j + 37, k + 24, 5, 2);
		setBlock(world, i + 3, j + 37, k + 25, Blocks.planks, 5);
		world.setBlockMetadataWithNotify(i + 3, j + 37, k + 25, 5, 2);
		setBlock(world, i + 3, j + 37, k + 26, Blocks.log, 1);
		world.setBlockMetadataWithNotify(i + 3, j + 37, k + 26, 1, 2);
		setBlock(world, i + 3, j + 37, k + 27, Blocks.log, 1);
		world.setBlockMetadataWithNotify(i + 3, j + 37, k + 27, 1, 2);
		setBlock(world, i + 3, j + 37, k + 28, Blocks.log, 1);
		world.setBlockMetadataWithNotify(i + 3, j + 37, k + 28, 1, 2);
		setBlock(world, i + 3, j + 38, k + 21, Blocks.log, 1);
		world.setBlockMetadataWithNotify(i + 3, j + 38, k + 21, 1, 2);
		setBlock(world, i + 3, j + 38, k + 22, Blocks.spruce_stairs, 3);
		world.setBlockMetadataWithNotify(i + 3, j + 38, k + 22, 3, 2);
		setBlock(world, i + 3, j + 38, k + 27, Blocks.spruce_stairs, 2);
		world.setBlockMetadataWithNotify(i + 3, j + 38, k + 27, 2, 2);
		setBlock(world, i + 3, j + 38, k + 28, Blocks.log, 1);
		world.setBlockMetadataWithNotify(i + 3, j + 38, k + 28, 1, 2);
		setBlock(world, i + 3, j + 39, k + 21, Blocks.log, 1);
		world.setBlockMetadataWithNotify(i + 3, j + 39, k + 21, 1, 2);
		setBlock(world, i + 3, j + 39, k + 28, Blocks.log, 1);
		world.setBlockMetadataWithNotify(i + 3, j + 39, k + 28, 1, 2);
		setBlock(world, i + 3, j + 42, k + 18, Blocks.log, 1);
		world.setBlockMetadataWithNotify(i + 3, j + 42, k + 18, 1, 2);
		setBlock(world, i + 3, j + 42, k + 19, Blocks.log, 1);
		world.setBlockMetadataWithNotify(i + 3, j + 42, k + 19, 1, 2);
		setBlock(world, i + 3, j + 42, k + 20, Blocks.log, 1);
		world.setBlockMetadataWithNotify(i + 3, j + 42, k + 20, 1, 2);
		setBlock(world, i + 3, j + 42, k + 21, Blocks.log, 1);
		world.setBlockMetadataWithNotify(i + 3, j + 42, k + 21, 1, 2);
		setBlock(world, i + 3, j + 42, k + 22, Blocks.log, 1);
		world.setBlockMetadataWithNotify(i + 3, j + 42, k + 22, 1, 2);
		setBlock(world, i + 3, j + 42, k + 23, Blocks.log, 1);
		world.setBlockMetadataWithNotify(i + 3, j + 42, k + 23, 1, 2);
		setBlock(world, i + 3, j + 42, k + 24, Blocks.log, 1);
		world.setBlockMetadataWithNotify(i + 3, j + 42, k + 24, 1, 2);
		setBlock(world, i + 3, j + 42, k + 25, Blocks.log, 1);
		world.setBlockMetadataWithNotify(i + 3, j + 42, k + 25, 1, 2);
		setBlock(world, i + 3, j + 42, k + 26, Blocks.log, 1);
		world.setBlockMetadataWithNotify(i + 3, j + 42, k + 26, 1, 2);
		setBlock(world, i + 3, j + 42, k + 27, Blocks.log, 1);
		world.setBlockMetadataWithNotify(i + 3, j + 42, k + 27, 1, 2);
		setBlock(world, i + 3, j + 42, k + 28, Blocks.log, 1);
		world.setBlockMetadataWithNotify(i + 3, j + 42, k + 28, 1, 2);
		setBlock(world, i + 3, j + 42, k + 29, Blocks.log, 1);
		world.setBlockMetadataWithNotify(i + 3, j + 42, k + 29, 1, 2);
		setBlock(world, i + 3, j + 42, k + 30, Blocks.log, 1);
		world.setBlockMetadataWithNotify(i + 3, j + 42, k + 30, 1, 2);
		setBlock(world, i + 3, j + 42, k + 31, Blocks.log, 1);
		world.setBlockMetadataWithNotify(i + 3, j + 42, k + 31, 1, 2);
		setBlock(world, i + 3, j + 43, k + 19, Blocks.log, 1);
		world.setBlockMetadataWithNotify(i + 3, j + 43, k + 19, 1, 2);
		setBlock(world, i + 3, j + 43, k + 20, Blocks.log, 1);
		world.setBlockMetadataWithNotify(i + 3, j + 43, k + 20, 1, 2);
		setBlock(world, i + 3, j + 43, k + 21, Blocks.log, 1);
		world.setBlockMetadataWithNotify(i + 3, j + 43, k + 21, 1, 2);
		setBlock(world, i + 3, j + 43, k + 22, Blocks.log, 1);
		world.setBlockMetadataWithNotify(i + 3, j + 43, k + 22, 1, 2);
		setBlock(world, i + 3, j + 43, k + 23, Blocks.log, 1);
		world.setBlockMetadataWithNotify(i + 3, j + 43, k + 23, 1, 2);
		setBlock(world, i + 3, j + 43, k + 24, Blocks.log, 1);
		world.setBlockMetadataWithNotify(i + 3, j + 43, k + 24, 1, 2);
		setBlock(world, i + 3, j + 43, k + 25, Blocks.log, 1);
		world.setBlockMetadataWithNotify(i + 3, j + 43, k + 25, 1, 2);
		setBlock(world, i + 3, j + 43, k + 26, Blocks.log, 1);
		world.setBlockMetadataWithNotify(i + 3, j + 43, k + 26, 1, 2);
		setBlock(world, i + 3, j + 43, k + 27, Blocks.log, 1);
		world.setBlockMetadataWithNotify(i + 3, j + 43, k + 27, 1, 2);
		setBlock(world, i + 3, j + 43, k + 28, Blocks.log, 1);
		world.setBlockMetadataWithNotify(i + 3, j + 43, k + 28, 1, 2);
		setBlock(world, i + 3, j + 43, k + 29, Blocks.log, 1);
		world.setBlockMetadataWithNotify(i + 3, j + 43, k + 29, 1, 2);
		setBlock(world, i + 3, j + 43, k + 30, Blocks.log, 1);
		world.setBlockMetadataWithNotify(i + 3, j + 43, k + 30, 1, 2);
		setBlock(world, i + 3, j + 44, k + 22, Blocks.log, 1);
		world.setBlockMetadataWithNotify(i + 3, j + 44, k + 22, 1, 2);
		setBlock(world, i + 3, j + 44, k + 23, Blocks.log, 1);
		world.setBlockMetadataWithNotify(i + 3, j + 44, k + 23, 1, 2);
		setBlock(world, i + 3, j + 44, k + 24, Blocks.log, 1);
		world.setBlockMetadataWithNotify(i + 3, j + 44, k + 24, 1, 2);
		setBlock(world, i + 3, j + 44, k + 25, Blocks.log, 1);
		world.setBlockMetadataWithNotify(i + 3, j + 44, k + 25, 1, 2);
		setBlock(world, i + 3, j + 44, k + 26, Blocks.log, 1);
		world.setBlockMetadataWithNotify(i + 3, j + 44, k + 26, 1, 2);
		setBlock(world, i + 3, j + 44, k + 27, Blocks.log, 1);
		world.setBlockMetadataWithNotify(i + 3, j + 44, k + 27, 1, 2);
		setBlock(world, i + 4, j + 26, k + 31, Blocks.leaves, 7);
		world.setBlockMetadataWithNotify(i + 4, j + 26, k + 31, 7, 2);
		setBlock(world, i + 4, j + 37, k + 22, Blocks.log, 1);
		world.setBlockMetadataWithNotify(i + 4, j + 37, k + 22, 1, 2);
		setBlock(world, i + 4, j + 37, k + 23, Blocks.log, 1);
		world.setBlockMetadataWithNotify(i + 4, j + 37, k + 23, 1, 2);
		setBlock(world, i + 4, j + 37, k + 24, Blocks.log, 1);
		world.setBlockMetadataWithNotify(i + 4, j + 37, k + 24, 1, 2);
		setBlock(world, i + 4, j + 37, k + 25, Blocks.log, 1);
		world.setBlockMetadataWithNotify(i + 4, j + 37, k + 25, 1, 2);
		setBlock(world, i + 4, j + 37, k + 26, Blocks.log, 1);
		world.setBlockMetadataWithNotify(i + 4, j + 37, k + 26, 1, 2);
		setBlock(world, i + 4, j + 37, k + 27, Blocks.log, 1);
		world.setBlockMetadataWithNotify(i + 4, j + 37, k + 27, 1, 2);
		setBlock(world, i + 4, j + 38, k + 21, Blocks.spruce_stairs, 5);
		world.setBlockMetadataWithNotify(i + 4, j + 38, k + 21, 5, 2);
		setBlock(world, i + 4, j + 38, k + 28, Blocks.spruce_stairs, 5);
		world.setBlockMetadataWithNotify(i + 4, j + 38, k + 28, 5, 2);
		setBlock(world, i + 4, j + 39, k + 21, Blocks.log, 1);
		world.setBlockMetadataWithNotify(i + 4, j + 39, k + 21, 1, 2);
		setBlock(world, i + 4, j + 39, k + 28, Blocks.log, 1);
		world.setBlockMetadataWithNotify(i + 4, j + 39, k + 28, 1, 2);
		setBlock(world, i + 4, j + 40, k + 21, Blocks.log, 1);
		world.setBlockMetadataWithNotify(i + 4, j + 40, k + 21, 1, 2);
		setBlock(world, i + 4, j + 40, k + 22, Blocks.torch, 3);
		world.setBlockMetadataWithNotify(i + 4, j + 40, k + 22, 3, 2);
		setBlock(world, i + 4, j + 40, k + 27, Blocks.torch, 4);
		world.setBlockMetadataWithNotify(i + 4, j + 40, k + 27, 4, 2);
		setBlock(world, i + 4, j + 40, k + 28, Blocks.log, 1);
		world.setBlockMetadataWithNotify(i + 4, j + 40, k + 28, 1, 2);
		setBlock(world, i + 4, j + 42, k + 19, Blocks.log, 1);
		world.setBlockMetadataWithNotify(i + 4, j + 42, k + 19, 1, 2);
		setBlock(world, i + 4, j + 42, k + 20, Blocks.log, 1);
		world.setBlockMetadataWithNotify(i + 4, j + 42, k + 20, 1, 2);
		setBlock(world, i + 4, j + 42, k + 21, Blocks.log, 1);
		world.setBlockMetadataWithNotify(i + 4, j + 42, k + 21, 1, 2);
		setBlock(world, i + 4, j + 42, k + 22, Blocks.log, 1);
		world.setBlockMetadataWithNotify(i + 4, j + 42, k + 22, 1, 2);
		setBlock(world, i + 4, j + 42, k + 23, Blocks.log, 1);
		world.setBlockMetadataWithNotify(i + 4, j + 42, k + 23, 1, 2);
		setBlock(world, i + 4, j + 42, k + 24, Blocks.log, 1);
		world.setBlockMetadataWithNotify(i + 4, j + 42, k + 24, 1, 2);
		setBlock(world, i + 4, j + 42, k + 25, Blocks.log, 1);
		world.setBlockMetadataWithNotify(i + 4, j + 42, k + 25, 1, 2);
		setBlock(world, i + 4, j + 42, k + 26, Blocks.log, 1);
		world.setBlockMetadataWithNotify(i + 4, j + 42, k + 26, 1, 2);
		setBlock(world, i + 4, j + 42, k + 27, Blocks.log, 1);
		world.setBlockMetadataWithNotify(i + 4, j + 42, k + 27, 1, 2);
		setBlock(world, i + 4, j + 42, k + 28, Blocks.log, 1);
		world.setBlockMetadataWithNotify(i + 4, j + 42, k + 28, 1, 2);
		setBlock(world, i + 4, j + 42, k + 29, Blocks.log, 1);
		world.setBlockMetadataWithNotify(i + 4, j + 42, k + 29, 1, 2);
		setBlock(world, i + 4, j + 42, k + 30, Blocks.log, 1);
		world.setBlockMetadataWithNotify(i + 4, j + 42, k + 30, 1, 2);
		setBlock(world, i + 4, j + 43, k + 20, Blocks.log, 1);
		world.setBlockMetadataWithNotify(i + 4, j + 43, k + 20, 1, 2);
		setBlock(world, i + 4, j + 43, k + 21, Blocks.log, 1);
		world.setBlockMetadataWithNotify(i + 4, j + 43, k + 21, 1, 2);
		setBlock(world, i + 4, j + 43, k + 22, Blocks.log, 1);
		world.setBlockMetadataWithNotify(i + 4, j + 43, k + 22, 1, 2);
		setBlock(world, i + 4, j + 43, k + 23, Blocks.log, 1);
		world.setBlockMetadataWithNotify(i + 4, j + 43, k + 23, 1, 2);
		setBlock(world, i + 4, j + 43, k + 24, Blocks.log, 1);
		world.setBlockMetadataWithNotify(i + 4, j + 43, k + 24, 1, 2);
		setBlock(world, i + 4, j + 43, k + 25, Blocks.log, 1);
		world.setBlockMetadataWithNotify(i + 4, j + 43, k + 25, 1, 2);
		setBlock(world, i + 4, j + 43, k + 26, Blocks.log, 1);
		world.setBlockMetadataWithNotify(i + 4, j + 43, k + 26, 1, 2);
		setBlock(world, i + 4, j + 43, k + 27, Blocks.log, 1);
		world.setBlockMetadataWithNotify(i + 4, j + 43, k + 27, 1, 2);
		setBlock(world, i + 4, j + 43, k + 28, Blocks.log, 1);
		world.setBlockMetadataWithNotify(i + 4, j + 43, k + 28, 1, 2);
		setBlock(world, i + 4, j + 43, k + 29, Blocks.log, 1);
		world.setBlockMetadataWithNotify(i + 4, j + 43, k + 29, 1, 2);
		setBlock(world, i + 4, j + 44, k + 23, Blocks.log, 1);
		world.setBlockMetadataWithNotify(i + 4, j + 44, k + 23, 1, 2);
		setBlock(world, i + 4, j + 44, k + 24, Blocks.log, 1);
		world.setBlockMetadataWithNotify(i + 4, j + 44, k + 24, 1, 2);
		setBlock(world, i + 4, j + 44, k + 25, Blocks.log, 1);
		world.setBlockMetadataWithNotify(i + 4, j + 44, k + 25, 1, 2);
		setBlock(world, i + 4, j + 44, k + 26, Blocks.log, 1);
		world.setBlockMetadataWithNotify(i + 4, j + 44, k + 26, 1, 2);
		setBlock(world, i + 5, j + 26, k + 30, Blocks.leaves, 7);
		world.setBlockMetadataWithNotify(i + 5, j + 26, k + 30, 7, 2);
		setBlock(world, i + 5, j + 26, k + 31, Blocks.leaves, 7);
		world.setBlockMetadataWithNotify(i + 5, j + 26, k + 31, 7, 2);
		setBlock(world, i + 5, j + 27, k + 31, Blocks.leaves, 7);
		world.setBlockMetadataWithNotify(i + 5, j + 27, k + 31, 7, 2);
		setBlock(world, i + 5, j + 37, k + 23, Blocks.log, 1);
		world.setBlockMetadataWithNotify(i + 5, j + 37, k + 23, 1, 2);
		setBlock(world, i + 5, j + 37, k + 24, Blocks.log, 1);
		world.setBlockMetadataWithNotify(i + 5, j + 37, k + 24, 1, 2);
		setBlock(world, i + 5, j + 37, k + 25, Blocks.log, 1);
		world.setBlockMetadataWithNotify(i + 5, j + 37, k + 25, 1, 2);
		setBlock(world, i + 5, j + 37, k + 26, Blocks.log, 1);
		world.setBlockMetadataWithNotify(i + 5, j + 37, k + 26, 1, 2);
		setBlock(world, i + 5, j + 39, k + 21, Blocks.spruce_stairs, 5);
		world.setBlockMetadataWithNotify(i + 5, j + 39, k + 21, 5, 2);
		setBlock(world, i + 5, j + 39, k + 28, Blocks.spruce_stairs, 5);
		world.setBlockMetadataWithNotify(i + 5, j + 39, k + 28, 5, 2);
		setBlock(world, i + 5, j + 40, k + 21, Blocks.log, 1);
		world.setBlockMetadataWithNotify(i + 5, j + 40, k + 21, 1, 2);
		setBlock(world, i + 5, j + 40, k + 28, Blocks.log, 1);
		world.setBlockMetadataWithNotify(i + 5, j + 40, k + 28, 1, 2);
		setBlock(world, i + 5, j + 41, k + 21, Blocks.log, 1);
		world.setBlockMetadataWithNotify(i + 5, j + 41, k + 21, 1, 2);
		setBlock(world, i + 5, j + 41, k + 22, Blocks.spruce_stairs, 7);
		world.setBlockMetadataWithNotify(i + 5, j + 41, k + 22, 7, 2);
		setBlock(world, i + 5, j + 41, k + 27, Blocks.spruce_stairs, 6);
		world.setBlockMetadataWithNotify(i + 5, j + 41, k + 27, 6, 2);
		setBlock(world, i + 5, j + 41, k + 28, Blocks.log, 1);
		world.setBlockMetadataWithNotify(i + 5, j + 41, k + 28, 1, 2);
		setBlock(world, i + 5, j + 42, k + 20, Blocks.log, 1);
		world.setBlockMetadataWithNotify(i + 5, j + 42, k + 20, 1, 2);
		setBlock(world, i + 5, j + 42, k + 21, Blocks.log, 1);
		world.setBlockMetadataWithNotify(i + 5, j + 42, k + 21, 1, 2);
		setBlock(world, i + 5, j + 42, k + 22, Blocks.log, 1);
		world.setBlockMetadataWithNotify(i + 5, j + 42, k + 22, 1, 2);
		setBlock(world, i + 5, j + 42, k + 23, Blocks.log, 1);
		world.setBlockMetadataWithNotify(i + 5, j + 42, k + 23, 1, 2);
		setBlock(world, i + 5, j + 42, k + 24, Blocks.log, 1);
		world.setBlockMetadataWithNotify(i + 5, j + 42, k + 24, 1, 2);
		setBlock(world, i + 5, j + 42, k + 25, Blocks.log, 1);
		world.setBlockMetadataWithNotify(i + 5, j + 42, k + 25, 1, 2);
		setBlock(world, i + 5, j + 42, k + 26, Blocks.log, 1);
		world.setBlockMetadataWithNotify(i + 5, j + 42, k + 26, 1, 2);
		setBlock(world, i + 5, j + 42, k + 27, Blocks.log, 1);
		world.setBlockMetadataWithNotify(i + 5, j + 42, k + 27, 1, 2);
		setBlock(world, i + 5, j + 42, k + 28, Blocks.log, 1);
		world.setBlockMetadataWithNotify(i + 5, j + 42, k + 28, 1, 2);
		setBlock(world, i + 5, j + 42, k + 29, Blocks.log, 1);
		world.setBlockMetadataWithNotify(i + 5, j + 42, k + 29, 1, 2);
		setBlock(world, i + 5, j + 43, k + 21, Blocks.log, 1);
		world.setBlockMetadataWithNotify(i + 5, j + 43, k + 21, 1, 2);
		setBlock(world, i + 5, j + 43, k + 22, Blocks.log, 1);
		world.setBlockMetadataWithNotify(i + 5, j + 43, k + 22, 1, 2);
		setBlock(world, i + 5, j + 43, k + 23, Blocks.log, 1);
		world.setBlockMetadataWithNotify(i + 5, j + 43, k + 23, 1, 2);
		setBlock(world, i + 5, j + 43, k + 24, Blocks.log, 1);
		world.setBlockMetadataWithNotify(i + 5, j + 43, k + 24, 1, 2);
		setBlock(world, i + 5, j + 43, k + 25, Blocks.log, 1);
		world.setBlockMetadataWithNotify(i + 5, j + 43, k + 25, 1, 2);
		setBlock(world, i + 5, j + 43, k + 26, Blocks.log, 1);
		world.setBlockMetadataWithNotify(i + 5, j + 43, k + 26, 1, 2);
		setBlock(world, i + 5, j + 43, k + 27, Blocks.log, 1);
		world.setBlockMetadataWithNotify(i + 5, j + 43, k + 27, 1, 2);
		setBlock(world, i + 5, j + 43, k + 28, Blocks.log, 1);
		world.setBlockMetadataWithNotify(i + 5, j + 43, k + 28, 1, 2);
		setBlock(world, i + 6, j + 26, k + 30, Blocks.leaves, 7);
		world.setBlockMetadataWithNotify(i + 6, j + 26, k + 30, 7, 2);
		setBlock(world, i + 6, j + 26, k + 31, Blocks.leaves, 7);
		world.setBlockMetadataWithNotify(i + 6, j + 26, k + 31, 7, 2);
		setBlock(world, i + 6, j + 27, k + 30, Blocks.leaves, 7);
		world.setBlockMetadataWithNotify(i + 6, j + 27, k + 30, 7, 2);
		setBlock(world, i + 6, j + 27, k + 31, Blocks.leaves, 7);
		world.setBlockMetadataWithNotify(i + 6, j + 27, k + 31, 7, 2);
		setBlock(world, i + 6, j + 28, k + 31, Blocks.leaves, 7);
		world.setBlockMetadataWithNotify(i + 6, j + 28, k + 31, 7, 2);
		setBlock(world, i + 6, j + 42, k + 21, Blocks.log, 1);
		world.setBlockMetadataWithNotify(i + 6, j + 42, k + 21, 1, 2);
		setBlock(world, i + 6, j + 42, k + 22, Blocks.log, 1);
		world.setBlockMetadataWithNotify(i + 6, j + 42, k + 22, 1, 2);
		setBlock(world, i + 6, j + 42, k + 23, Blocks.log, 1);
		world.setBlockMetadataWithNotify(i + 6, j + 42, k + 23, 1, 2);
		setBlock(world, i + 6, j + 42, k + 24, Blocks.log, 1);
		world.setBlockMetadataWithNotify(i + 6, j + 42, k + 24, 1, 2);
		setBlock(world, i + 6, j + 42, k + 25, Blocks.log, 1);
		world.setBlockMetadataWithNotify(i + 6, j + 42, k + 25, 1, 2);
		setBlock(world, i + 6, j + 42, k + 26, Blocks.log, 1);
		world.setBlockMetadataWithNotify(i + 6, j + 42, k + 26, 1, 2);
		setBlock(world, i + 6, j + 42, k + 27, Blocks.log, 1);
		world.setBlockMetadataWithNotify(i + 6, j + 42, k + 27, 1, 2);
		setBlock(world, i + 6, j + 42, k + 28, Blocks.log, 1);
		world.setBlockMetadataWithNotify(i + 6, j + 42, k + 28, 1, 2);
		setBlock(world, i + 6, j + 43, k + 23, Blocks.log, 1);
		world.setBlockMetadataWithNotify(i + 6, j + 43, k + 23, 1, 2);
		setBlock(world, i + 6, j + 43, k + 24, Blocks.log, 1);
		world.setBlockMetadataWithNotify(i + 6, j + 43, k + 24, 1, 2);
		setBlock(world, i + 6, j + 43, k + 25, Blocks.log, 1);
		world.setBlockMetadataWithNotify(i + 6, j + 43, k + 25, 1, 2);
		setBlock(world, i + 6, j + 43, k + 26, Blocks.log, 1);
		world.setBlockMetadataWithNotify(i + 6, j + 43, k + 26, 1, 2);
		setBlock(world, i + 7, j + 26, k + 30, Blocks.leaves, 7);
		world.setBlockMetadataWithNotify(i + 7, j + 26, k + 30, 7, 2);
		setBlock(world, i + 7, j + 26, k + 31, Blocks.leaves, 7);
		world.setBlockMetadataWithNotify(i + 7, j + 26, k + 31, 7, 2);
		setBlock(world, i + 7, j + 27, k + 31, Blocks.leaves, 7);
		world.setBlockMetadataWithNotify(i + 7, j + 27, k + 31, 7, 2);
		setBlock(world, i + 7, j + 42, k + 23, Blocks.log, 1);
		world.setBlockMetadataWithNotify(i + 7, j + 42, k + 23, 1, 2);
		setBlock(world, i + 7, j + 42, k + 24, Blocks.log, 1);
		world.setBlockMetadataWithNotify(i + 7, j + 42, k + 24, 1, 2);
		setBlock(world, i + 7, j + 42, k + 25, Blocks.log, 1);
		world.setBlockMetadataWithNotify(i + 7, j + 42, k + 25, 1, 2);
		setBlock(world, i + 7, j + 42, k + 26, Blocks.log, 1);
		world.setBlockMetadataWithNotify(i + 7, j + 42, k + 26, 1, 2);
		setBlock(world, i + 8, j + 26, k + 24, Blocks.leaves, 7);
		world.setBlockMetadataWithNotify(i + 8, j + 26, k + 24, 7, 2);
		setBlock(world, i + 8, j + 26, k + 25, Blocks.leaves, 7);
		world.setBlockMetadataWithNotify(i + 8, j + 26, k + 25, 7, 2);
		setBlock(world, i + 8, j + 26, k + 26, Blocks.leaves, 7);
		world.setBlockMetadataWithNotify(i + 8, j + 26, k + 26, 7, 2);
		setBlock(world, i + 8, j + 26, k + 31, Blocks.leaves, 7);
		world.setBlockMetadataWithNotify(i + 8, j + 26, k + 31, 7, 2);
		setBlock(world, i + 8, j + 27, k + 25, Blocks.leaves, 7);
		world.setBlockMetadataWithNotify(i + 8, j + 27, k + 25, 7, 2);
		setBlock(world, i + 9, j + 26, k + 23, Blocks.leaves, 7);
		world.setBlockMetadataWithNotify(i + 9, j + 26, k + 23, 7, 2);
		setBlock(world, i + 9, j + 26, k + 24, Blocks.leaves, 7);
		world.setBlockMetadataWithNotify(i + 9, j + 26, k + 24, 7, 2);
		setBlock(world, i + 9, j + 26, k + 25, Blocks.leaves, 7);
		world.setBlockMetadataWithNotify(i + 9, j + 26, k + 25, 7, 2);
		setBlock(world, i + 9, j + 26, k + 26, Blocks.leaves, 7);
		world.setBlockMetadataWithNotify(i + 9, j + 26, k + 26, 7, 2);
		setBlock(world, i + 9, j + 26, k + 27, Blocks.leaves, 7);
		world.setBlockMetadataWithNotify(i + 9, j + 26, k + 27, 7, 2);
		setBlock(world, i + 9, j + 27, k + 24, Blocks.leaves, 7);
		world.setBlockMetadataWithNotify(i + 9, j + 27, k + 24, 7, 2);
		setBlock(world, i + 9, j + 27, k + 25, Blocks.leaves, 7);
		world.setBlockMetadataWithNotify(i + 9, j + 27, k + 25, 7, 2);
		setBlock(world, i + 9, j + 27, k + 26, Blocks.leaves, 7);
		world.setBlockMetadataWithNotify(i + 9, j + 27, k + 26, 7, 2);
		setBlock(world, i + 9, j + 28, k + 25, Blocks.leaves, 7);
		world.setBlockMetadataWithNotify(i + 9, j + 28, k + 25, 7, 2);
		setBlock(world, i + 9, j + 35, k + 31, Blocks.leaves, 7);
		world.setBlockMetadataWithNotify(i + 9, j + 35, k + 31, 7, 2);
		setBlock(world, i + 9, j + 38, k + 31, Blocks.leaves, 7);
		world.setBlockMetadataWithNotify(i + 9, j + 38, k + 31, 7, 2);
		setBlock(world, i + 10, j + 26, k + 23, Blocks.leaves, 7);
		world.setBlockMetadataWithNotify(i + 10, j + 26, k + 23, 7, 2);
		setBlock(world, i + 10, j + 26, k + 24, Blocks.leaves, 7);
		world.setBlockMetadataWithNotify(i + 10, j + 26, k + 24, 7, 2);
		setBlock(world, i + 10, j + 26, k + 25, Blocks.log, 3);
		world.setBlockMetadataWithNotify(i + 10, j + 26, k + 25, 3, 2);
		setBlock(world, i + 10, j + 26, k + 26, Blocks.leaves, 7);
		world.setBlockMetadataWithNotify(i + 10, j + 26, k + 26, 7, 2);
		setBlock(world, i + 10, j + 26, k + 27, Blocks.leaves, 7);
		world.setBlockMetadataWithNotify(i + 10, j + 26, k + 27, 7, 2);
		setBlock(world, i + 10, j + 27, k + 23, Blocks.leaves, 7);
		world.setBlockMetadataWithNotify(i + 10, j + 27, k + 23, 7, 2);
		setBlock(world, i + 10, j + 27, k + 24, Blocks.leaves, 7);
		world.setBlockMetadataWithNotify(i + 10, j + 27, k + 24, 7, 2);
		setBlock(world, i + 10, j + 27, k + 25, Blocks.leaves, 7);
		world.setBlockMetadataWithNotify(i + 10, j + 27, k + 25, 7, 2);
		setBlock(world, i + 10, j + 27, k + 26, Blocks.leaves, 7);
		world.setBlockMetadataWithNotify(i + 10, j + 27, k + 26, 7, 2);
		setBlock(world, i + 10, j + 27, k + 27, Blocks.leaves, 7);
		world.setBlockMetadataWithNotify(i + 10, j + 27, k + 27, 7, 2);
		setBlock(world, i + 10, j + 28, k + 24, Blocks.leaves, 7);
		world.setBlockMetadataWithNotify(i + 10, j + 28, k + 24, 7, 2);
		setBlock(world, i + 10, j + 28, k + 25, Blocks.leaves, 7);
		world.setBlockMetadataWithNotify(i + 10, j + 28, k + 25, 7, 2);
		setBlock(world, i + 10, j + 28, k + 26, Blocks.leaves, 7);
		world.setBlockMetadataWithNotify(i + 10, j + 28, k + 26, 7, 2);
		setBlock(world, i + 10, j + 29, k + 25, Blocks.leaves, 7);
		world.setBlockMetadataWithNotify(i + 10, j + 29, k + 25, 7, 2);
		setBlock(world, i + 10, j + 35, k + 30, Blocks.leaves, 7);
		world.setBlockMetadataWithNotify(i + 10, j + 35, k + 30, 7, 2);
		setBlock(world, i + 10, j + 35, k + 31, Blocks.leaves, 7);
		world.setBlockMetadataWithNotify(i + 10, j + 35, k + 31, 7, 2);
		setBlock(world, i + 10, j + 36, k + 31, Blocks.leaves, 7);
		world.setBlockMetadataWithNotify(i + 10, j + 36, k + 31, 7, 2);
		setBlock(world, i + 10, j + 38, k + 31, Blocks.leaves, 7);
		world.setBlockMetadataWithNotify(i + 10, j + 38, k + 31, 7, 2);
		setBlock(world, i + 10, j + 39, k + 31, Blocks.leaves, 7);
		world.setBlockMetadataWithNotify(i + 10, j + 39, k + 31, 7, 2);
		setBlock(world, i + 11, j + 25, k + 26, Blocks.log, 3);
		world.setBlockMetadataWithNotify(i + 11, j + 25, k + 26, 3, 2);
		setBlock(world, i + 11, j + 26, k + 23, Blocks.leaves, 7);
		world.setBlockMetadataWithNotify(i + 11, j + 26, k + 23, 7, 2);
		setBlock(world, i + 11, j + 26, k + 24, Blocks.leaves, 7);
		world.setBlockMetadataWithNotify(i + 11, j + 26, k + 24, 7, 2);
		setBlock(world, i + 11, j + 26, k + 25, Blocks.leaves, 7);
		world.setBlockMetadataWithNotify(i + 11, j + 26, k + 25, 7, 2);
		setBlock(world, i + 11, j + 26, k + 26, Blocks.leaves, 7);
		world.setBlockMetadataWithNotify(i + 11, j + 26, k + 26, 7, 2);
		setBlock(world, i + 11, j + 26, k + 27, Blocks.leaves, 7);
		world.setBlockMetadataWithNotify(i + 11, j + 26, k + 27, 7, 2);
		setBlock(world, i + 11, j + 27, k + 24, Blocks.leaves, 7);
		world.setBlockMetadataWithNotify(i + 11, j + 27, k + 24, 7, 2);
		setBlock(world, i + 11, j + 27, k + 25, Blocks.leaves, 7);
		world.setBlockMetadataWithNotify(i + 11, j + 27, k + 25, 7, 2);
		setBlock(world, i + 11, j + 27, k + 26, Blocks.leaves, 7);
		world.setBlockMetadataWithNotify(i + 11, j + 27, k + 26, 7, 2);
		setBlock(world, i + 11, j + 28, k + 25, Blocks.leaves, 7);
		world.setBlockMetadataWithNotify(i + 11, j + 28, k + 25, 7, 2);
		setBlock(world, i + 11, j + 35, k + 30, Blocks.leaves, 7);
		world.setBlockMetadataWithNotify(i + 11, j + 35, k + 30, 7, 2);
		setBlock(world, i + 11, j + 35, k + 31, Blocks.leaves, 7);
		world.setBlockMetadataWithNotify(i + 11, j + 35, k + 31, 7, 2);
		setBlock(world, i + 11, j + 36, k + 30, Blocks.leaves, 7);
		world.setBlockMetadataWithNotify(i + 11, j + 36, k + 30, 7, 2);
		setBlock(world, i + 11, j + 36, k + 31, Blocks.leaves, 7);
		world.setBlockMetadataWithNotify(i + 11, j + 36, k + 31, 7, 2);
		setBlock(world, i + 11, j + 37, k + 31, Blocks.leaves, 7);
		world.setBlockMetadataWithNotify(i + 11, j + 37, k + 31, 7, 2);
		setBlock(world, i + 11, j + 38, k + 31, Blocks.leaves, 7);
		world.setBlockMetadataWithNotify(i + 11, j + 38, k + 31, 7, 2);
		setBlock(world, i + 12, j + 25, k + 27, Blocks.log, 3);
		world.setBlockMetadataWithNotify(i + 12, j + 25, k + 27, 3, 2);
		setBlock(world, i + 12, j + 26, k + 24, Blocks.leaves, 7);
		world.setBlockMetadataWithNotify(i + 12, j + 26, k + 24, 7, 2);
		setBlock(world, i + 12, j + 26, k + 25, Blocks.leaves, 7);
		world.setBlockMetadataWithNotify(i + 12, j + 26, k + 25, 7, 2);
		setBlock(world, i + 12, j + 26, k + 26, Blocks.leaves, 7);
		world.setBlockMetadataWithNotify(i + 12, j + 26, k + 26, 7, 2);
		setBlock(world, i + 12, j + 27, k + 25, Blocks.leaves, 7);
		world.setBlockMetadataWithNotify(i + 12, j + 27, k + 25, 7, 2);
		setBlock(world, i + 12, j + 35, k + 30, Blocks.leaves, 7);
		world.setBlockMetadataWithNotify(i + 12, j + 35, k + 30, 7, 2);
		setBlock(world, i + 12, j + 35, k + 31, Blocks.leaves, 7);
		world.setBlockMetadataWithNotify(i + 12, j + 35, k + 31, 7, 2);
		setBlock(world, i + 12, j + 36, k + 31, Blocks.leaves, 7);
		world.setBlockMetadataWithNotify(i + 12, j + 36, k + 31, 7, 2);
		setBlock(world, i + 13, j + 25, k + 28, Blocks.log, 3);
		world.setBlockMetadataWithNotify(i + 13, j + 25, k + 28, 3, 2);
		setBlock(world, i + 13, j + 35, k + 31, Blocks.leaves, 7);
		world.setBlockMetadataWithNotify(i + 13, j + 35, k + 31, 7, 2);
		setBlock(world, i + 14, j + 25, k + 29, Blocks.log, 3);
		world.setBlockMetadataWithNotify(i + 14, j + 25, k + 29, 3, 2);
		setBlock(world, i + 15, j + 25, k + 30, Blocks.log, 3);
		world.setBlockMetadataWithNotify(i + 15, j + 25, k + 30, 3, 2);
		setBlock(world, i + 15, j + 46, k + 30, Blocks.leaves, 7);
		world.setBlockMetadataWithNotify(i + 15, j + 46, k + 30, 7, 2);
		setBlock(world, i + 15, j + 46, k + 31, Blocks.leaves, 7);
		world.setBlockMetadataWithNotify(i + 15, j + 46, k + 31, 7, 2);
		setBlock(world, i + 15, j + 47, k + 31, Blocks.leaves, 7);
		world.setBlockMetadataWithNotify(i + 15, j + 47, k + 31, 7, 2);
		setBlock(world, i + 16, j + 24, k + 31, Blocks.log, 3);
		world.setBlockMetadataWithNotify(i + 16, j + 24, k + 31, 3, 2);
		setBlock(world, i + 16, j + 41, k + 31, Blocks.leaves, 7);
		world.setBlockMetadataWithNotify(i + 16, j + 41, k + 31, 7, 2);
		setBlock(world, i + 16, j + 46, k + 29, Blocks.leaves, 7);
		world.setBlockMetadataWithNotify(i + 16, j + 46, k + 29, 7, 2);
		setBlock(world, i + 16, j + 46, k + 30, Blocks.leaves, 7);
		world.setBlockMetadataWithNotify(i + 16, j + 46, k + 30, 7, 2);
		setBlock(world, i + 16, j + 46, k + 31, Blocks.leaves, 7);
		world.setBlockMetadataWithNotify(i + 16, j + 46, k + 31, 7, 2);
		setBlock(world, i + 16, j + 47, k + 30, Blocks.leaves, 7);
		world.setBlockMetadataWithNotify(i + 16, j + 47, k + 30, 7, 2);
		setBlock(world, i + 16, j + 47, k + 31, Blocks.leaves, 7);
		world.setBlockMetadataWithNotify(i + 16, j + 47, k + 31, 7, 2);
		setBlock(world, i + 16, j + 48, k + 31, Blocks.leaves, 7);
		world.setBlockMetadataWithNotify(i + 16, j + 48, k + 31, 7, 2);
		setBlock(world, i + 17, j + 22, k + 19, Blocks.leaves, 7);
		world.setBlockMetadataWithNotify(i + 17, j + 22, k + 19, 7, 2);
		setBlock(world, i + 17, j + 22, k + 20, Blocks.leaves, 7);
		world.setBlockMetadataWithNotify(i + 17, j + 22, k + 20, 7, 2);
		setBlock(world, i + 17, j + 22, k + 21, Blocks.leaves, 7);
		world.setBlockMetadataWithNotify(i + 17, j + 22, k + 21, 7, 2);
		setBlock(world, i + 17, j + 23, k + 20, Blocks.leaves, 7);
		world.setBlockMetadataWithNotify(i + 17, j + 23, k + 20, 7, 2);
		setBlock(world, i + 17, j + 24, k + 31, Blocks.log, 3);
		world.setBlockMetadataWithNotify(i + 17, j + 24, k + 31, 3, 2);
		setBlock(world, i + 17, j + 41, k + 31, Blocks.leaves, 7);
		world.setBlockMetadataWithNotify(i + 17, j + 41, k + 31, 7, 2);
		setBlock(world, i + 17, j + 42, k + 31, Blocks.leaves, 7);
		world.setBlockMetadataWithNotify(i + 17, j + 42, k + 31, 7, 2);
		setBlock(world, i + 17, j + 46, k + 29, Blocks.leaves, 7);
		world.setBlockMetadataWithNotify(i + 17, j + 46, k + 29, 7, 2);
		setBlock(world, i + 17, j + 46, k + 30, Blocks.leaves, 7);
		world.setBlockMetadataWithNotify(i + 17, j + 46, k + 30, 7, 2);
		setBlock(world, i + 17, j + 46, k + 31, Blocks.log, 3);
		world.setBlockMetadataWithNotify(i + 17, j + 46, k + 31, 3, 2);
		setBlock(world, i + 17, j + 47, k + 29, Blocks.leaves, 7);
		world.setBlockMetadataWithNotify(i + 17, j + 47, k + 29, 7, 2);
		setBlock(world, i + 17, j + 47, k + 30, Blocks.leaves, 7);
		world.setBlockMetadataWithNotify(i + 17, j + 47, k + 30, 7, 2);
		setBlock(world, i + 17, j + 47, k + 31, Blocks.leaves, 7);
		world.setBlockMetadataWithNotify(i + 17, j + 47, k + 31, 7, 2);
		setBlock(world, i + 17, j + 48, k + 30, Blocks.leaves, 7);
		world.setBlockMetadataWithNotify(i + 17, j + 48, k + 30, 7, 2);
		setBlock(world, i + 17, j + 48, k + 31, Blocks.leaves, 7);
		world.setBlockMetadataWithNotify(i + 17, j + 48, k + 31, 7, 2);
		setBlock(world, i + 17, j + 49, k + 31, Blocks.leaves, 7);
		world.setBlockMetadataWithNotify(i + 17, j + 49, k + 31, 7, 2);
		setBlock(world, i + 18, j + 22, k + 18, Blocks.leaves, 7);
		world.setBlockMetadataWithNotify(i + 18, j + 22, k + 18, 7, 2);
		setBlock(world, i + 18, j + 22, k + 19, Blocks.leaves, 7);
		world.setBlockMetadataWithNotify(i + 18, j + 22, k + 19, 7, 2);
		setBlock(world, i + 18, j + 22, k + 20, Blocks.leaves, 7);
		world.setBlockMetadataWithNotify(i + 18, j + 22, k + 20, 7, 2);
		setBlock(world, i + 18, j + 22, k + 21, Blocks.leaves, 7);
		world.setBlockMetadataWithNotify(i + 18, j + 22, k + 21, 7, 2);
		setBlock(world, i + 18, j + 22, k + 22, Blocks.leaves, 7);
		world.setBlockMetadataWithNotify(i + 18, j + 22, k + 22, 7, 2);
		setBlock(world, i + 18, j + 23, k + 19, Blocks.leaves, 7);
		world.setBlockMetadataWithNotify(i + 18, j + 23, k + 19, 7, 2);
		setBlock(world, i + 18, j + 23, k + 20, Blocks.leaves, 7);
		world.setBlockMetadataWithNotify(i + 18, j + 23, k + 20, 7, 2);
		setBlock(world, i + 18, j + 23, k + 21, Blocks.leaves, 7);
		world.setBlockMetadataWithNotify(i + 18, j + 23, k + 21, 7, 2);
		setBlock(world, i + 18, j + 24, k + 20, Blocks.leaves, 7);
		world.setBlockMetadataWithNotify(i + 18, j + 24, k + 20, 7, 2);
		setBlock(world, i + 18, j + 24, k + 29, Blocks.leaves, 7);
		world.setBlockMetadataWithNotify(i + 18, j + 24, k + 29, 7, 2);
		setBlock(world, i + 18, j + 24, k + 30, Blocks.leaves, 7);
		world.setBlockMetadataWithNotify(i + 18, j + 24, k + 30, 7, 2);
		setBlock(world, i + 18, j + 24, k + 31, Blocks.leaves, 7);
		world.setBlockMetadataWithNotify(i + 18, j + 24, k + 31, 7, 2);
		setBlock(world, i + 18, j + 25, k + 30, Blocks.leaves, 7);
		world.setBlockMetadataWithNotify(i + 18, j + 25, k + 30, 7, 2);
		setBlock(world, i + 18, j + 41, k + 31, Blocks.leaves, 7);
		world.setBlockMetadataWithNotify(i + 18, j + 41, k + 31, 7, 2);
		setBlock(world, i + 18, j + 46, k + 29, Blocks.leaves, 7);
		world.setBlockMetadataWithNotify(i + 18, j + 46, k + 29, 7, 2);
		setBlock(world, i + 18, j + 46, k + 30, Blocks.leaves, 7);
		world.setBlockMetadataWithNotify(i + 18, j + 46, k + 30, 7, 2);
		setBlock(world, i + 18, j + 46, k + 31, Blocks.leaves, 7);
		world.setBlockMetadataWithNotify(i + 18, j + 46, k + 31, 7, 2);
		setBlock(world, i + 18, j + 47, k + 30, Blocks.leaves, 7);
		world.setBlockMetadataWithNotify(i + 18, j + 47, k + 30, 7, 2);
		setBlock(world, i + 18, j + 47, k + 31, Blocks.leaves, 7);
		world.setBlockMetadataWithNotify(i + 18, j + 47, k + 31, 7, 2);
		setBlock(world, i + 18, j + 48, k + 31, Blocks.leaves, 7);
		world.setBlockMetadataWithNotify(i + 18, j + 48, k + 31, 7, 2);
		setBlock(world, i + 19, j + 21, k + 21, Blocks.log, 3);
		world.setBlockMetadataWithNotify(i + 19, j + 21, k + 21, 3, 2);
		setBlock(world, i + 19, j + 21, k + 22, Blocks.log, 3);
		world.setBlockMetadataWithNotify(i + 19, j + 21, k + 22, 3, 2);
		setBlock(world, i + 19, j + 22, k + 18, Blocks.leaves, 7);
		world.setBlockMetadataWithNotify(i + 19, j + 22, k + 18, 7, 2);
		setBlock(world, i + 19, j + 22, k + 19, Blocks.leaves, 7);
		world.setBlockMetadataWithNotify(i + 19, j + 22, k + 19, 7, 2);
		setBlock(world, i + 19, j + 22, k + 20, Blocks.log, 3);
		world.setBlockMetadataWithNotify(i + 19, j + 22, k + 20, 3, 2);
		setBlock(world, i + 19, j + 22, k + 21, Blocks.leaves, 7);
		world.setBlockMetadataWithNotify(i + 19, j + 22, k + 21, 7, 2);
		setBlock(world, i + 19, j + 22, k + 22, Blocks.leaves, 7);
		world.setBlockMetadataWithNotify(i + 19, j + 22, k + 22, 7, 2);
		setBlock(world, i + 19, j + 23, k + 18, Blocks.leaves, 7);
		world.setBlockMetadataWithNotify(i + 19, j + 23, k + 18, 7, 2);
		setBlock(world, i + 19, j + 23, k + 19, Blocks.leaves, 7);
		world.setBlockMetadataWithNotify(i + 19, j + 23, k + 19, 7, 2);
		setBlock(world, i + 19, j + 23, k + 20, Blocks.leaves, 7);
		world.setBlockMetadataWithNotify(i + 19, j + 23, k + 20, 7, 2);
		setBlock(world, i + 19, j + 23, k + 21, Blocks.leaves, 7);
		world.setBlockMetadataWithNotify(i + 19, j + 23, k + 21, 7, 2);
		setBlock(world, i + 19, j + 23, k + 22, Blocks.leaves, 7);
		world.setBlockMetadataWithNotify(i + 19, j + 23, k + 22, 7, 2);
		setBlock(world, i + 19, j + 24, k + 19, Blocks.leaves, 7);
		world.setBlockMetadataWithNotify(i + 19, j + 24, k + 19, 7, 2);
		setBlock(world, i + 19, j + 24, k + 20, Blocks.leaves, 7);
		world.setBlockMetadataWithNotify(i + 19, j + 24, k + 20, 7, 2);
		setBlock(world, i + 19, j + 24, k + 21, Blocks.leaves, 7);
		world.setBlockMetadataWithNotify(i + 19, j + 24, k + 21, 7, 2);
		setBlock(world, i + 19, j + 24, k + 28, Blocks.leaves, 7);
		world.setBlockMetadataWithNotify(i + 19, j + 24, k + 28, 7, 2);
		setBlock(world, i + 19, j + 24, k + 29, Blocks.leaves, 7);
		world.setBlockMetadataWithNotify(i + 19, j + 24, k + 29, 7, 2);
		setBlock(world, i + 19, j + 24, k + 30, Blocks.leaves, 7);
		world.setBlockMetadataWithNotify(i + 19, j + 24, k + 30, 7, 2);
		setBlock(world, i + 19, j + 24, k + 31, Blocks.leaves, 7);
		world.setBlockMetadataWithNotify(i + 19, j + 24, k + 31, 7, 2);
		setBlock(world, i + 19, j + 25, k + 20, Blocks.leaves, 7);
		world.setBlockMetadataWithNotify(i + 19, j + 25, k + 20, 7, 2);
		setBlock(world, i + 19, j + 25, k + 29, Blocks.leaves, 7);
		world.setBlockMetadataWithNotify(i + 19, j + 25, k + 29, 7, 2);
		setBlock(world, i + 19, j + 25, k + 30, Blocks.leaves, 7);
		world.setBlockMetadataWithNotify(i + 19, j + 25, k + 30, 7, 2);
		setBlock(world, i + 19, j + 25, k + 31, Blocks.leaves, 7);
		world.setBlockMetadataWithNotify(i + 19, j + 25, k + 31, 7, 2);
		setBlock(world, i + 19, j + 26, k + 30, Blocks.leaves, 7);
		world.setBlockMetadataWithNotify(i + 19, j + 26, k + 30, 7, 2);
		setBlock(world, i + 19, j + 46, k + 30, Blocks.leaves, 7);
		world.setBlockMetadataWithNotify(i + 19, j + 46, k + 30, 7, 2);
		setBlock(world, i + 19, j + 46, k + 31, Blocks.leaves, 7);
		world.setBlockMetadataWithNotify(i + 19, j + 46, k + 31, 7, 2);
		setBlock(world, i + 19, j + 47, k + 31, Blocks.leaves, 7);
		world.setBlockMetadataWithNotify(i + 19, j + 47, k + 31, 7, 2);
		setBlock(world, i + 20, j + 20, k + 28, Blocks.log, 3);
		world.setBlockMetadataWithNotify(i + 20, j + 20, k + 28, 3, 2);
		setBlock(world, i + 20, j + 21, k + 23, Blocks.log, 3);
		world.setBlockMetadataWithNotify(i + 20, j + 21, k + 23, 3, 2);
		setBlock(world, i + 20, j + 21, k + 24, Blocks.log, 3);
		world.setBlockMetadataWithNotify(i + 20, j + 21, k + 24, 3, 2);
		setBlock(world, i + 20, j + 21, k + 25, Blocks.log, 3);
		world.setBlockMetadataWithNotify(i + 20, j + 21, k + 25, 3, 2);
		setBlock(world, i + 20, j + 22, k + 18, Blocks.leaves, 7);
		world.setBlockMetadataWithNotify(i + 20, j + 22, k + 18, 7, 2);
		setBlock(world, i + 20, j + 22, k + 19, Blocks.leaves, 7);
		world.setBlockMetadataWithNotify(i + 20, j + 22, k + 19, 7, 2);
		setBlock(world, i + 20, j + 22, k + 20, Blocks.leaves, 7);
		world.setBlockMetadataWithNotify(i + 20, j + 22, k + 20, 7, 2);
		setBlock(world, i + 20, j + 22, k + 21, Blocks.leaves, 7);
		world.setBlockMetadataWithNotify(i + 20, j + 22, k + 21, 7, 2);
		setBlock(world, i + 20, j + 22, k + 22, Blocks.leaves, 7);
		world.setBlockMetadataWithNotify(i + 20, j + 22, k + 22, 7, 2);
		setBlock(world, i + 20, j + 23, k + 19, Blocks.leaves, 7);
		world.setBlockMetadataWithNotify(i + 20, j + 23, k + 19, 7, 2);
		setBlock(world, i + 20, j + 23, k + 20, Blocks.leaves, 7);
		world.setBlockMetadataWithNotify(i + 20, j + 23, k + 20, 7, 2);
		setBlock(world, i + 20, j + 23, k + 21, Blocks.leaves, 7);
		world.setBlockMetadataWithNotify(i + 20, j + 23, k + 21, 7, 2);
		setBlock(world, i + 20, j + 23, k + 31, Blocks.log, 3);
		world.setBlockMetadataWithNotify(i + 20, j + 23, k + 31, 3, 2);
		setBlock(world, i + 20, j + 24, k + 20, Blocks.leaves, 7);
		world.setBlockMetadataWithNotify(i + 20, j + 24, k + 20, 7, 2);
		setBlock(world, i + 20, j + 24, k + 28, Blocks.leaves, 7);
		world.setBlockMetadataWithNotify(i + 20, j + 24, k + 28, 7, 2);
		setBlock(world, i + 20, j + 24, k + 29, Blocks.leaves, 7);
		world.setBlockMetadataWithNotify(i + 20, j + 24, k + 29, 7, 2);
		setBlock(world, i + 20, j + 24, k + 30, Blocks.log, 3);
		world.setBlockMetadataWithNotify(i + 20, j + 24, k + 30, 3, 2);
		setBlock(world, i + 20, j + 24, k + 31, Blocks.leaves, 7);
		world.setBlockMetadataWithNotify(i + 20, j + 24, k + 31, 7, 2);
		setBlock(world, i + 20, j + 25, k + 28, Blocks.leaves, 7);
		world.setBlockMetadataWithNotify(i + 20, j + 25, k + 28, 7, 2);
		setBlock(world, i + 20, j + 25, k + 29, Blocks.leaves, 7);
		world.setBlockMetadataWithNotify(i + 20, j + 25, k + 29, 7, 2);
		setBlock(world, i + 20, j + 25, k + 30, Blocks.leaves, 7);
		world.setBlockMetadataWithNotify(i + 20, j + 25, k + 30, 7, 2);
		setBlock(world, i + 20, j + 25, k + 31, Blocks.leaves, 7);
		world.setBlockMetadataWithNotify(i + 20, j + 25, k + 31, 7, 2);
		setBlock(world, i + 20, j + 26, k + 29, Blocks.leaves, 7);
		world.setBlockMetadataWithNotify(i + 20, j + 26, k + 29, 7, 2);
		setBlock(world, i + 20, j + 26, k + 30, Blocks.leaves, 7);
		world.setBlockMetadataWithNotify(i + 20, j + 26, k + 30, 7, 2);
		setBlock(world, i + 20, j + 26, k + 31, Blocks.leaves, 7);
		world.setBlockMetadataWithNotify(i + 20, j + 26, k + 31, 7, 2);
		setBlock(world, i + 20, j + 27, k + 30, Blocks.leaves, 7);
		world.setBlockMetadataWithNotify(i + 20, j + 27, k + 30, 7, 2);
		setBlock(world, i + 21, j + 19, k + 28, Blocks.log, 3);
		world.setBlockMetadataWithNotify(i + 21, j + 19, k + 28, 3, 2);
		setBlock(world, i + 21, j + 20, k + 28, Blocks.log, 3);
		world.setBlockMetadataWithNotify(i + 21, j + 20, k + 28, 3, 2);
		setBlock(world, i + 21, j + 20, k + 29, Blocks.log, 3);
		world.setBlockMetadataWithNotify(i + 21, j + 20, k + 29, 3, 2);
		setBlock(world, i + 21, j + 20, k + 30, Blocks.log, 3);
		world.setBlockMetadataWithNotify(i + 21, j + 20, k + 30, 3, 2);
		setBlock(world, i + 21, j + 21, k + 26, Blocks.log, 3);
		world.setBlockMetadataWithNotify(i + 21, j + 21, k + 26, 3, 2);
		setBlock(world, i + 21, j + 21, k + 27, Blocks.log, 3);
		world.setBlockMetadataWithNotify(i + 21, j + 21, k + 27, 3, 2);
		setBlock(world, i + 21, j + 21, k + 28, Blocks.log, 3);
		world.setBlockMetadataWithNotify(i + 21, j + 21, k + 28, 3, 2);
		setBlock(world, i + 21, j + 22, k + 19, Blocks.leaves, 7);
		world.setBlockMetadataWithNotify(i + 21, j + 22, k + 19, 7, 2);
		setBlock(world, i + 21, j + 22, k + 20, Blocks.leaves, 7);
		world.setBlockMetadataWithNotify(i + 21, j + 22, k + 20, 7, 2);
		setBlock(world, i + 21, j + 22, k + 21, Blocks.leaves, 7);
		world.setBlockMetadataWithNotify(i + 21, j + 22, k + 21, 7, 2);
		setBlock(world, i + 21, j + 23, k + 20, Blocks.leaves, 7);
		world.setBlockMetadataWithNotify(i + 21, j + 23, k + 20, 7, 2);
		setBlock(world, i + 21, j + 24, k + 28, Blocks.leaves, 7);
		world.setBlockMetadataWithNotify(i + 21, j + 24, k + 28, 7, 2);
		setBlock(world, i + 21, j + 24, k + 29, Blocks.leaves, 7);
		world.setBlockMetadataWithNotify(i + 21, j + 24, k + 29, 7, 2);
		setBlock(world, i + 21, j + 24, k + 30, Blocks.leaves, 7);
		world.setBlockMetadataWithNotify(i + 21, j + 24, k + 30, 7, 2);
		setBlock(world, i + 21, j + 24, k + 31, Blocks.leaves, 7);
		world.setBlockMetadataWithNotify(i + 21, j + 24, k + 31, 7, 2);
		setBlock(world, i + 21, j + 25, k + 29, Blocks.leaves, 7);
		world.setBlockMetadataWithNotify(i + 21, j + 25, k + 29, 7, 2);
		setBlock(world, i + 21, j + 25, k + 30, Blocks.leaves, 7);
		world.setBlockMetadataWithNotify(i + 21, j + 25, k + 30, 7, 2);
		setBlock(world, i + 21, j + 25, k + 31, Blocks.leaves, 7);
		world.setBlockMetadataWithNotify(i + 21, j + 25, k + 31, 7, 2);
		setBlock(world, i + 21, j + 26, k + 30, Blocks.leaves, 7);
		world.setBlockMetadataWithNotify(i + 21, j + 26, k + 30, 7, 2);
		setBlock(world, i + 21, j + 53, k + 29, Blocks.leaves, 7);
		world.setBlockMetadataWithNotify(i + 21, j + 53, k + 29, 7, 2);
		setBlock(world, i + 21, j + 53, k + 30, Blocks.leaves, 7);
		world.setBlockMetadataWithNotify(i + 21, j + 53, k + 30, 7, 2);
		setBlock(world, i + 21, j + 53, k + 31, Blocks.leaves, 7);
		world.setBlockMetadataWithNotify(i + 21, j + 53, k + 31, 7, 2);
		setBlock(world, i + 21, j + 54, k + 30, Blocks.leaves, 7);
		world.setBlockMetadataWithNotify(i + 21, j + 54, k + 30, 7, 2);
		setBlock(world, i + 22, j + 19, k + 29, Blocks.log, 3);
		world.setBlockMetadataWithNotify(i + 22, j + 19, k + 29, 3, 2);
		setBlock(world, i + 22, j + 19, k + 30, Blocks.log, 3);
		world.setBlockMetadataWithNotify(i + 22, j + 19, k + 30, 3, 2);
		setBlock(world, i + 22, j + 20, k + 28, Blocks.log, 3);
		world.setBlockMetadataWithNotify(i + 22, j + 20, k + 28, 3, 2);
		setBlock(world, i + 22, j + 20, k + 29, Blocks.log, 3);
		world.setBlockMetadataWithNotify(i + 22, j + 20, k + 29, 3, 2);
		setBlock(world, i + 22, j + 20, k + 30, Blocks.log, 3);
		world.setBlockMetadataWithNotify(i + 22, j + 20, k + 30, 3, 2);
		setBlock(world, i + 22, j + 20, k + 31, Blocks.log, 3);
		world.setBlockMetadataWithNotify(i + 22, j + 20, k + 31, 3, 2);
		setBlock(world, i + 22, j + 21, k + 29, Blocks.log, 3);
		world.setBlockMetadataWithNotify(i + 22, j + 21, k + 29, 3, 2);
		setBlock(world, i + 22, j + 21, k + 30, Blocks.log, 3);
		world.setBlockMetadataWithNotify(i + 22, j + 21, k + 30, 3, 2);
		setBlock(world, i + 22, j + 24, k + 29, Blocks.leaves, 7);
		world.setBlockMetadataWithNotify(i + 22, j + 24, k + 29, 7, 2);
		setBlock(world, i + 22, j + 24, k + 30, Blocks.leaves, 7);
		world.setBlockMetadataWithNotify(i + 22, j + 24, k + 30, 7, 2);
		setBlock(world, i + 22, j + 24, k + 31, Blocks.leaves, 7);
		world.setBlockMetadataWithNotify(i + 22, j + 24, k + 31, 7, 2);
		setBlock(world, i + 22, j + 25, k + 30, Blocks.leaves, 7);
		world.setBlockMetadataWithNotify(i + 22, j + 25, k + 30, 7, 2);
		setBlock(world, i + 22, j + 30, k + 26, Blocks.leaves, 7);
		world.setBlockMetadataWithNotify(i + 22, j + 30, k + 26, 7, 2);
		setBlock(world, i + 22, j + 30, k + 27, Blocks.leaves, 7);
		world.setBlockMetadataWithNotify(i + 22, j + 30, k + 27, 7, 2);
		setBlock(world, i + 22, j + 30, k + 28, Blocks.leaves, 7);
		world.setBlockMetadataWithNotify(i + 22, j + 30, k + 28, 7, 2);
		setBlock(world, i + 22, j + 31, k + 27, Blocks.leaves, 7);
		world.setBlockMetadataWithNotify(i + 22, j + 31, k + 27, 7, 2);
		setBlock(world, i + 22, j + 33, k + 20, Blocks.leaves, 7);
		world.setBlockMetadataWithNotify(i + 22, j + 33, k + 20, 7, 2);
		setBlock(world, i + 22, j + 33, k + 21, Blocks.leaves, 7);
		world.setBlockMetadataWithNotify(i + 22, j + 33, k + 21, 7, 2);
		setBlock(world, i + 22, j + 33, k + 22, Blocks.leaves, 7);
		world.setBlockMetadataWithNotify(i + 22, j + 33, k + 22, 7, 2);
		setBlock(world, i + 22, j + 34, k + 21, Blocks.leaves, 7);
		world.setBlockMetadataWithNotify(i + 22, j + 34, k + 21, 7, 2);
		setBlock(world, i + 22, j + 34, k + 31, Blocks.leaves, 7);
		world.setBlockMetadataWithNotify(i + 22, j + 34, k + 31, 7, 2);
		setBlock(world, i + 22, j + 53, k + 28, Blocks.leaves, 7);
		world.setBlockMetadataWithNotify(i + 22, j + 53, k + 28, 7, 2);
		setBlock(world, i + 22, j + 53, k + 29, Blocks.leaves, 7);
		world.setBlockMetadataWithNotify(i + 22, j + 53, k + 29, 7, 2);
		setBlock(world, i + 22, j + 53, k + 30, Blocks.leaves, 7);
		world.setBlockMetadataWithNotify(i + 22, j + 53, k + 30, 7, 2);
		setBlock(world, i + 22, j + 53, k + 31, Blocks.leaves, 7);
		world.setBlockMetadataWithNotify(i + 22, j + 53, k + 31, 7, 2);
		setBlock(world, i + 22, j + 54, k + 29, Blocks.leaves, 7);
		world.setBlockMetadataWithNotify(i + 22, j + 54, k + 29, 7, 2);
		setBlock(world, i + 22, j + 54, k + 30, Blocks.leaves, 7);
		world.setBlockMetadataWithNotify(i + 22, j + 54, k + 30, 7, 2);
		setBlock(world, i + 22, j + 54, k + 31, Blocks.leaves, 7);
		world.setBlockMetadataWithNotify(i + 22, j + 54, k + 31, 7, 2);
		setBlock(world, i + 22, j + 55, k + 30, Blocks.leaves, 7);
		world.setBlockMetadataWithNotify(i + 22, j + 55, k + 30, 7, 2);
		setBlock(world, i + 23, j + 19, k + 31, Blocks.log, 3);
		world.setBlockMetadataWithNotify(i + 23, j + 19, k + 31, 3, 2);
		setBlock(world, i + 23, j + 20, k + 29, Blocks.log, 3);
		world.setBlockMetadataWithNotify(i + 23, j + 20, k + 29, 3, 2);
		setBlock(world, i + 23, j + 20, k + 30, Blocks.log, 3);
		world.setBlockMetadataWithNotify(i + 23, j + 20, k + 30, 3, 2);
		setBlock(world, i + 23, j + 20, k + 31, Blocks.log, 3);
		world.setBlockMetadataWithNotify(i + 23, j + 20, k + 31, 3, 2);
		setBlock(world, i + 23, j + 21, k + 31, Blocks.log, 3);
		world.setBlockMetadataWithNotify(i + 23, j + 21, k + 31, 3, 2);
		setBlock(world, i + 23, j + 30, k + 25, Blocks.leaves, 7);
		world.setBlockMetadataWithNotify(i + 23, j + 30, k + 25, 7, 2);
		setBlock(world, i + 23, j + 30, k + 26, Blocks.leaves, 7);
		world.setBlockMetadataWithNotify(i + 23, j + 30, k + 26, 7, 2);
		setBlock(world, i + 23, j + 30, k + 27, Blocks.leaves, 7);
		world.setBlockMetadataWithNotify(i + 23, j + 30, k + 27, 7, 2);
		setBlock(world, i + 23, j + 30, k + 28, Blocks.leaves, 7);
		world.setBlockMetadataWithNotify(i + 23, j + 30, k + 28, 7, 2);
		setBlock(world, i + 23, j + 30, k + 29, Blocks.leaves, 7);
		world.setBlockMetadataWithNotify(i + 23, j + 30, k + 29, 7, 2);
		setBlock(world, i + 23, j + 31, k + 26, Blocks.leaves, 7);
		world.setBlockMetadataWithNotify(i + 23, j + 31, k + 26, 7, 2);
		setBlock(world, i + 23, j + 31, k + 27, Blocks.leaves, 7);
		world.setBlockMetadataWithNotify(i + 23, j + 31, k + 27, 7, 2);
		setBlock(world, i + 23, j + 31, k + 28, Blocks.leaves, 7);
		world.setBlockMetadataWithNotify(i + 23, j + 31, k + 28, 7, 2);
		setBlock(world, i + 23, j + 32, k + 27, Blocks.leaves, 7);
		world.setBlockMetadataWithNotify(i + 23, j + 32, k + 27, 7, 2);
		setBlock(world, i + 23, j + 33, k + 19, Blocks.leaves, 7);
		world.setBlockMetadataWithNotify(i + 23, j + 33, k + 19, 7, 2);
		setBlock(world, i + 23, j + 33, k + 20, Blocks.leaves, 7);
		world.setBlockMetadataWithNotify(i + 23, j + 33, k + 20, 7, 2);
		setBlock(world, i + 23, j + 33, k + 21, Blocks.leaves, 7);
		world.setBlockMetadataWithNotify(i + 23, j + 33, k + 21, 7, 2);
		setBlock(world, i + 23, j + 33, k + 22, Blocks.leaves, 7);
		world.setBlockMetadataWithNotify(i + 23, j + 33, k + 22, 7, 2);
		setBlock(world, i + 23, j + 33, k + 23, Blocks.leaves, 7);
		world.setBlockMetadataWithNotify(i + 23, j + 33, k + 23, 7, 2);
		setBlock(world, i + 23, j + 34, k + 20, Blocks.leaves, 7);
		world.setBlockMetadataWithNotify(i + 23, j + 34, k + 20, 7, 2);
		setBlock(world, i + 23, j + 34, k + 21, Blocks.leaves, 7);
		world.setBlockMetadataWithNotify(i + 23, j + 34, k + 21, 7, 2);
		setBlock(world, i + 23, j + 34, k + 22, Blocks.leaves, 7);
		world.setBlockMetadataWithNotify(i + 23, j + 34, k + 22, 7, 2);
		setBlock(world, i + 23, j + 34, k + 31, Blocks.leaves, 7);
		world.setBlockMetadataWithNotify(i + 23, j + 34, k + 31, 7, 2);
		setBlock(world, i + 23, j + 35, k + 21, Blocks.leaves, 7);
		world.setBlockMetadataWithNotify(i + 23, j + 35, k + 21, 7, 2);
		setBlock(world, i + 23, j + 35, k + 31, Blocks.leaves, 7);
		world.setBlockMetadataWithNotify(i + 23, j + 35, k + 31, 7, 2);
		setBlock(world, i + 23, j + 37, k + 23, Blocks.leaves, 7);
		world.setBlockMetadataWithNotify(i + 23, j + 37, k + 23, 7, 2);
		setBlock(world, i + 23, j + 37, k + 24, Blocks.leaves, 7);
		world.setBlockMetadataWithNotify(i + 23, j + 37, k + 24, 7, 2);
		setBlock(world, i + 23, j + 37, k + 25, Blocks.leaves, 7);
		world.setBlockMetadataWithNotify(i + 23, j + 37, k + 25, 7, 2);
		setBlock(world, i + 23, j + 38, k + 24, Blocks.leaves, 7);
		world.setBlockMetadataWithNotify(i + 23, j + 38, k + 24, 7, 2);
		setBlock(world, i + 23, j + 45, k + 31, Blocks.leaves, 7);
		world.setBlockMetadataWithNotify(i + 23, j + 45, k + 31, 7, 2);
		setBlock(world, i + 23, j + 52, k + 31, Blocks.log, 3);
		world.setBlockMetadataWithNotify(i + 23, j + 52, k + 31, 3, 2);
		setBlock(world, i + 23, j + 53, k + 28, Blocks.leaves, 7);
		world.setBlockMetadataWithNotify(i + 23, j + 53, k + 28, 7, 2);
		setBlock(world, i + 23, j + 53, k + 29, Blocks.leaves, 7);
		world.setBlockMetadataWithNotify(i + 23, j + 53, k + 29, 7, 2);
		setBlock(world, i + 23, j + 53, k + 30, Blocks.log, 3);
		world.setBlockMetadataWithNotify(i + 23, j + 53, k + 30, 3, 2);
		setBlock(world, i + 23, j + 53, k + 31, Blocks.leaves, 7);
		world.setBlockMetadataWithNotify(i + 23, j + 53, k + 31, 7, 2);
		setBlock(world, i + 23, j + 54, k + 28, Blocks.leaves, 7);
		world.setBlockMetadataWithNotify(i + 23, j + 54, k + 28, 7, 2);
		setBlock(world, i + 23, j + 54, k + 29, Blocks.leaves, 7);
		world.setBlockMetadataWithNotify(i + 23, j + 54, k + 29, 7, 2);
		setBlock(world, i + 23, j + 54, k + 30, Blocks.leaves, 7);
		world.setBlockMetadataWithNotify(i + 23, j + 54, k + 30, 7, 2);
		setBlock(world, i + 23, j + 54, k + 31, Blocks.leaves, 7);
		world.setBlockMetadataWithNotify(i + 23, j + 54, k + 31, 7, 2);
		setBlock(world, i + 23, j + 55, k + 29, Blocks.leaves, 7);
		world.setBlockMetadataWithNotify(i + 23, j + 55, k + 29, 7, 2);
		setBlock(world, i + 23, j + 55, k + 30, Blocks.leaves, 7);
		world.setBlockMetadataWithNotify(i + 23, j + 55, k + 30, 7, 2);
		setBlock(world, i + 23, j + 55, k + 31, Blocks.leaves, 7);
		world.setBlockMetadataWithNotify(i + 23, j + 55, k + 31, 7, 2);
		setBlock(world, i + 23, j + 56, k + 30, Blocks.leaves, 7);
		world.setBlockMetadataWithNotify(i + 23, j + 56, k + 30, 7, 2);
		setBlock(world, i + 23, j + 57, k + 31, Blocks.leaves, 7);
		world.setBlockMetadataWithNotify(i + 23, j + 57, k + 31, 7, 2);
		setBlock(world, i + 24, j + 12, k + 28, Blocks.leaves, 7);
		world.setBlockMetadataWithNotify(i + 24, j + 12, k + 28, 7, 2);
		setBlock(world, i + 24, j + 12, k + 29, Blocks.leaves, 7);
		world.setBlockMetadataWithNotify(i + 24, j + 12, k + 29, 7, 2);
		setBlock(world, i + 24, j + 12, k + 30, Blocks.leaves, 7);
		world.setBlockMetadataWithNotify(i + 24, j + 12, k + 30, 7, 2);
		setBlock(world, i + 24, j + 13, k + 29, Blocks.leaves, 7);
		world.setBlockMetadataWithNotify(i + 24, j + 13, k + 29, 7, 2);
		setBlock(world, i + 24, j + 20, k + 31, Blocks.log, 3);
		world.setBlockMetadataWithNotify(i + 24, j + 20, k + 31, 3, 2);
		setBlock(world, i + 24, j + 29, k + 28, Blocks.log, 3);
		world.setBlockMetadataWithNotify(i + 24, j + 29, k + 28, 3, 2);
		setBlock(world, i + 24, j + 29, k + 29, Blocks.log, 3);
		world.setBlockMetadataWithNotify(i + 24, j + 29, k + 29, 3, 2);
		setBlock(world, i + 24, j + 29, k + 30, Blocks.log, 3);
		world.setBlockMetadataWithNotify(i + 24, j + 29, k + 30, 3, 2);
		setBlock(world, i + 24, j + 29, k + 31, Blocks.log, 3);
		world.setBlockMetadataWithNotify(i + 24, j + 29, k + 31, 3, 2);
		setBlock(world, i + 24, j + 30, k + 25, Blocks.leaves, 7);
		world.setBlockMetadataWithNotify(i + 24, j + 30, k + 25, 7, 2);
		setBlock(world, i + 24, j + 30, k + 26, Blocks.leaves, 7);
		world.setBlockMetadataWithNotify(i + 24, j + 30, k + 26, 7, 2);
		setBlock(world, i + 24, j + 30, k + 27, Blocks.log, 3);
		world.setBlockMetadataWithNotify(i + 24, j + 30, k + 27, 3, 2);
		setBlock(world, i + 24, j + 30, k + 28, Blocks.leaves, 7);
		world.setBlockMetadataWithNotify(i + 24, j + 30, k + 28, 7, 2);
		setBlock(world, i + 24, j + 30, k + 29, Blocks.leaves, 7);
		world.setBlockMetadataWithNotify(i + 24, j + 30, k + 29, 7, 2);
		setBlock(world, i + 24, j + 31, k + 25, Blocks.leaves, 7);
		world.setBlockMetadataWithNotify(i + 24, j + 31, k + 25, 7, 2);
		setBlock(world, i + 24, j + 31, k + 26, Blocks.leaves, 7);
		world.setBlockMetadataWithNotify(i + 24, j + 31, k + 26, 7, 2);
		setBlock(world, i + 24, j + 31, k + 27, Blocks.leaves, 7);
		world.setBlockMetadataWithNotify(i + 24, j + 31, k + 27, 7, 2);
		setBlock(world, i + 24, j + 31, k + 28, Blocks.leaves, 7);
		world.setBlockMetadataWithNotify(i + 24, j + 31, k + 28, 7, 2);
		setBlock(world, i + 24, j + 31, k + 29, Blocks.leaves, 7);
		world.setBlockMetadataWithNotify(i + 24, j + 31, k + 29, 7, 2);
		setBlock(world, i + 24, j + 32, k + 26, Blocks.leaves, 7);
		world.setBlockMetadataWithNotify(i + 24, j + 32, k + 26, 7, 2);
		setBlock(world, i + 24, j + 32, k + 27, Blocks.leaves, 7);
		world.setBlockMetadataWithNotify(i + 24, j + 32, k + 27, 7, 2);
		setBlock(world, i + 24, j + 32, k + 28, Blocks.leaves, 7);
		world.setBlockMetadataWithNotify(i + 24, j + 32, k + 28, 7, 2);
		setBlock(world, i + 24, j + 33, k + 19, Blocks.leaves, 7);
		world.setBlockMetadataWithNotify(i + 24, j + 33, k + 19, 7, 2);
		setBlock(world, i + 24, j + 33, k + 20, Blocks.leaves, 7);
		world.setBlockMetadataWithNotify(i + 24, j + 33, k + 20, 7, 2);
		setBlock(world, i + 24, j + 33, k + 21, Blocks.log, 3);
		world.setBlockMetadataWithNotify(i + 24, j + 33, k + 21, 3, 2);
		setBlock(world, i + 24, j + 33, k + 22, Blocks.leaves, 7);
		world.setBlockMetadataWithNotify(i + 24, j + 33, k + 22, 7, 2);
		setBlock(world, i + 24, j + 33, k + 23, Blocks.leaves, 7);
		world.setBlockMetadataWithNotify(i + 24, j + 33, k + 23, 7, 2);
		setBlock(world, i + 24, j + 33, k + 27, Blocks.leaves, 7);
		world.setBlockMetadataWithNotify(i + 24, j + 33, k + 27, 7, 2);
		setBlock(world, i + 24, j + 34, k + 19, Blocks.leaves, 7);
		world.setBlockMetadataWithNotify(i + 24, j + 34, k + 19, 7, 2);
		setBlock(world, i + 24, j + 34, k + 20, Blocks.leaves, 7);
		world.setBlockMetadataWithNotify(i + 24, j + 34, k + 20, 7, 2);
		setBlock(world, i + 24, j + 34, k + 21, Blocks.leaves, 7);
		world.setBlockMetadataWithNotify(i + 24, j + 34, k + 21, 7, 2);
		setBlock(world, i + 24, j + 34, k + 22, Blocks.leaves, 7);
		world.setBlockMetadataWithNotify(i + 24, j + 34, k + 22, 7, 2);
		setBlock(world, i + 24, j + 34, k + 23, Blocks.leaves, 7);
		world.setBlockMetadataWithNotify(i + 24, j + 34, k + 23, 7, 2);
		setBlock(world, i + 24, j + 34, k + 31, Blocks.leaves, 7);
		world.setBlockMetadataWithNotify(i + 24, j + 34, k + 31, 7, 2);
		setBlock(world, i + 24, j + 35, k + 20, Blocks.leaves, 7);
		world.setBlockMetadataWithNotify(i + 24, j + 35, k + 20, 7, 2);
		setBlock(world, i + 24, j + 35, k + 21, Blocks.leaves, 7);
		world.setBlockMetadataWithNotify(i + 24, j + 35, k + 21, 7, 2);
		setBlock(world, i + 24, j + 35, k + 22, Blocks.leaves, 7);
		world.setBlockMetadataWithNotify(i + 24, j + 35, k + 22, 7, 2);
		setBlock(world, i + 24, j + 35, k + 28, Blocks.log, 3);
		world.setBlockMetadataWithNotify(i + 24, j + 35, k + 28, 3, 2);
		setBlock(world, i + 24, j + 35, k + 29, Blocks.log, 3);
		world.setBlockMetadataWithNotify(i + 24, j + 35, k + 29, 3, 2);
		setBlock(world, i + 24, j + 35, k + 30, Blocks.log, 3);
		world.setBlockMetadataWithNotify(i + 24, j + 35, k + 30, 3, 2);
		setBlock(world, i + 24, j + 35, k + 31, Blocks.log, 3);
		world.setBlockMetadataWithNotify(i + 24, j + 35, k + 31, 3, 2);
		setBlock(world, i + 24, j + 36, k + 21, Blocks.leaves, 7);
		world.setBlockMetadataWithNotify(i + 24, j + 36, k + 21, 7, 2);
		setBlock(world, i + 24, j + 36, k + 25, Blocks.log, 3);
		world.setBlockMetadataWithNotify(i + 24, j + 36, k + 25, 3, 2);
		setBlock(world, i + 24, j + 36, k + 26, Blocks.log, 3);
		world.setBlockMetadataWithNotify(i + 24, j + 36, k + 26, 3, 2);
		setBlock(world, i + 24, j + 36, k + 27, Blocks.log, 3);
		world.setBlockMetadataWithNotify(i + 24, j + 36, k + 27, 3, 2);
		setBlock(world, i + 24, j + 37, k + 22, Blocks.leaves, 7);
		world.setBlockMetadataWithNotify(i + 24, j + 37, k + 22, 7, 2);
		setBlock(world, i + 24, j + 37, k + 23, Blocks.leaves, 7);
		world.setBlockMetadataWithNotify(i + 24, j + 37, k + 23, 7, 2);
		setBlock(world, i + 24, j + 37, k + 24, Blocks.leaves, 7);
		world.setBlockMetadataWithNotify(i + 24, j + 37, k + 24, 7, 2);
		setBlock(world, i + 24, j + 37, k + 25, Blocks.leaves, 7);
		world.setBlockMetadataWithNotify(i + 24, j + 37, k + 25, 7, 2);
		setBlock(world, i + 24, j + 37, k + 26, Blocks.leaves, 7);
		world.setBlockMetadataWithNotify(i + 24, j + 37, k + 26, 7, 2);
		setBlock(world, i + 24, j + 38, k + 23, Blocks.leaves, 7);
		world.setBlockMetadataWithNotify(i + 24, j + 38, k + 23, 7, 2);
		setBlock(world, i + 24, j + 38, k + 24, Blocks.leaves, 7);
		world.setBlockMetadataWithNotify(i + 24, j + 38, k + 24, 7, 2);
		setBlock(world, i + 24, j + 38, k + 25, Blocks.leaves, 7);
		world.setBlockMetadataWithNotify(i + 24, j + 38, k + 25, 7, 2);
		setBlock(world, i + 24, j + 39, k + 24, Blocks.leaves, 7);
		world.setBlockMetadataWithNotify(i + 24, j + 39, k + 24, 7, 2);
		setBlock(world, i + 24, j + 45, k + 31, Blocks.leaves, 7);
		world.setBlockMetadataWithNotify(i + 24, j + 45, k + 31, 7, 2);
		setBlock(world, i + 24, j + 46, k + 31, Blocks.leaves, 7);
		world.setBlockMetadataWithNotify(i + 24, j + 46, k + 31, 7, 2);
		setBlock(world, i + 24, j + 53, k + 28, Blocks.leaves, 7);
		world.setBlockMetadataWithNotify(i + 24, j + 53, k + 28, 7, 2);
		setBlock(world, i + 24, j + 53, k + 29, Blocks.leaves, 7);
		world.setBlockMetadataWithNotify(i + 24, j + 53, k + 29, 7, 2);
		setBlock(world, i + 24, j + 53, k + 30, Blocks.leaves, 7);
		world.setBlockMetadataWithNotify(i + 24, j + 53, k + 30, 7, 2);
		setBlock(world, i + 24, j + 53, k + 31, Blocks.leaves, 7);
		world.setBlockMetadataWithNotify(i + 24, j + 53, k + 31, 7, 2);
		setBlock(world, i + 24, j + 54, k + 29, Blocks.leaves, 7);
		world.setBlockMetadataWithNotify(i + 24, j + 54, k + 29, 7, 2);
		setBlock(world, i + 24, j + 54, k + 30, Blocks.leaves, 7);
		world.setBlockMetadataWithNotify(i + 24, j + 54, k + 30, 7, 2);
		setBlock(world, i + 24, j + 54, k + 31, Blocks.leaves, 7);
		world.setBlockMetadataWithNotify(i + 24, j + 54, k + 31, 7, 2);
		setBlock(world, i + 24, j + 55, k + 30, Blocks.leaves, 7);
		world.setBlockMetadataWithNotify(i + 24, j + 55, k + 30, 7, 2);
		setBlock(world, i + 24, j + 57, k + 31, Blocks.leaves, 7);
		world.setBlockMetadataWithNotify(i + 24, j + 57, k + 31, 7, 2);
		setBlock(world, i + 24, j + 58, k + 31, Blocks.leaves, 7);
		world.setBlockMetadataWithNotify(i + 24, j + 58, k + 31, 7, 2);
		setBlock(world, i + 25, j + 11, k + 30, Blocks.log, 3);
		world.setBlockMetadataWithNotify(i + 25, j + 11, k + 30, 3, 2);
		setBlock(world, i + 25, j + 11, k + 31, Blocks.log, 3);
		world.setBlockMetadataWithNotify(i + 25, j + 11, k + 31, 3, 2);
		setBlock(world, i + 25, j + 12, k + 27, Blocks.leaves, 7);
		world.setBlockMetadataWithNotify(i + 25, j + 12, k + 27, 7, 2);
		setBlock(world, i + 25, j + 12, k + 28, Blocks.leaves, 7);
		world.setBlockMetadataWithNotify(i + 25, j + 12, k + 28, 7, 2);
		setBlock(world, i + 25, j + 12, k + 29, Blocks.leaves, 7);
		world.setBlockMetadataWithNotify(i + 25, j + 12, k + 29, 7, 2);
		setBlock(world, i + 25, j + 12, k + 30, Blocks.leaves, 7);
		world.setBlockMetadataWithNotify(i + 25, j + 12, k + 30, 7, 2);
		setBlock(world, i + 25, j + 12, k + 31, Blocks.leaves, 7);
		world.setBlockMetadataWithNotify(i + 25, j + 12, k + 31, 7, 2);
		setBlock(world, i + 25, j + 13, k + 28, Blocks.leaves, 7);
		world.setBlockMetadataWithNotify(i + 25, j + 13, k + 28, 7, 2);
		setBlock(world, i + 25, j + 13, k + 29, Blocks.leaves, 7);
		world.setBlockMetadataWithNotify(i + 25, j + 13, k + 29, 7, 2);
		setBlock(world, i + 25, j + 13, k + 30, Blocks.leaves, 7);
		world.setBlockMetadataWithNotify(i + 25, j + 13, k + 30, 7, 2);
		setBlock(world, i + 25, j + 14, k + 29, Blocks.leaves, 7);
		world.setBlockMetadataWithNotify(i + 25, j + 14, k + 29, 7, 2);
		setBlock(world, i + 25, j + 21, k + 31, Blocks.log, 3);
		world.setBlockMetadataWithNotify(i + 25, j + 21, k + 31, 3, 2);
		setBlock(world, i + 25, j + 22, k + 29, Blocks.log, 3);
		world.setBlockMetadataWithNotify(i + 25, j + 22, k + 29, 3, 2);
		setBlock(world, i + 25, j + 22, k + 30, Blocks.log, 3);
		world.setBlockMetadataWithNotify(i + 25, j + 22, k + 30, 3, 2);
		setBlock(world, i + 25, j + 22, k + 31, Blocks.log, 3);
		world.setBlockMetadataWithNotify(i + 25, j + 22, k + 31, 3, 2);
		setBlock(world, i + 25, j + 23, k + 31, Blocks.log, 3);
		world.setBlockMetadataWithNotify(i + 25, j + 23, k + 31, 3, 2);
		setBlock(world, i + 25, j + 30, k + 25, Blocks.leaves, 7);
		world.setBlockMetadataWithNotify(i + 25, j + 30, k + 25, 7, 2);
		setBlock(world, i + 25, j + 30, k + 26, Blocks.leaves, 7);
		world.setBlockMetadataWithNotify(i + 25, j + 30, k + 26, 7, 2);
		setBlock(world, i + 25, j + 30, k + 27, Blocks.leaves, 7);
		world.setBlockMetadataWithNotify(i + 25, j + 30, k + 27, 7, 2);
		setBlock(world, i + 25, j + 30, k + 28, Blocks.leaves, 7);
		world.setBlockMetadataWithNotify(i + 25, j + 30, k + 28, 7, 2);
		setBlock(world, i + 25, j + 30, k + 29, Blocks.leaves, 7);
		world.setBlockMetadataWithNotify(i + 25, j + 30, k + 29, 7, 2);
		setBlock(world, i + 25, j + 31, k + 26, Blocks.leaves, 7);
		world.setBlockMetadataWithNotify(i + 25, j + 31, k + 26, 7, 2);
		setBlock(world, i + 25, j + 31, k + 27, Blocks.leaves, 7);
		world.setBlockMetadataWithNotify(i + 25, j + 31, k + 27, 7, 2);
		setBlock(world, i + 25, j + 31, k + 28, Blocks.leaves, 7);
		world.setBlockMetadataWithNotify(i + 25, j + 31, k + 28, 7, 2);
		setBlock(world, i + 25, j + 32, k + 27, Blocks.leaves, 7);
		world.setBlockMetadataWithNotify(i + 25, j + 32, k + 27, 7, 2);
		setBlock(world, i + 25, j + 33, k + 19, Blocks.leaves, 7);
		world.setBlockMetadataWithNotify(i + 25, j + 33, k + 19, 7, 2);
		setBlock(world, i + 25, j + 33, k + 20, Blocks.leaves, 7);
		world.setBlockMetadataWithNotify(i + 25, j + 33, k + 20, 7, 2);
		setBlock(world, i + 25, j + 33, k + 21, Blocks.leaves, 7);
		world.setBlockMetadataWithNotify(i + 25, j + 33, k + 21, 7, 2);
		setBlock(world, i + 25, j + 33, k + 22, Blocks.leaves, 7);
		world.setBlockMetadataWithNotify(i + 25, j + 33, k + 22, 7, 2);
		setBlock(world, i + 25, j + 33, k + 23, Blocks.leaves, 7);
		world.setBlockMetadataWithNotify(i + 25, j + 33, k + 23, 7, 2);
		setBlock(world, i + 25, j + 34, k + 20, Blocks.leaves, 7);
		world.setBlockMetadataWithNotify(i + 25, j + 34, k + 20, 7, 2);
		setBlock(world, i + 25, j + 34, k + 21, Blocks.leaves, 7);
		world.setBlockMetadataWithNotify(i + 25, j + 34, k + 21, 7, 2);
		setBlock(world, i + 25, j + 34, k + 22, Blocks.leaves, 7);
		world.setBlockMetadataWithNotify(i + 25, j + 34, k + 22, 7, 2);
		setBlock(world, i + 25, j + 35, k + 21, Blocks.leaves, 7);
		world.setBlockMetadataWithNotify(i + 25, j + 35, k + 21, 7, 2);
		setBlock(world, i + 25, j + 37, k + 22, Blocks.leaves, 7);
		world.setBlockMetadataWithNotify(i + 25, j + 37, k + 22, 7, 2);
		setBlock(world, i + 25, j + 37, k + 23, Blocks.leaves, 7);
		world.setBlockMetadataWithNotify(i + 25, j + 37, k + 23, 7, 2);
		setBlock(world, i + 25, j + 37, k + 24, Blocks.log, 3);
		world.setBlockMetadataWithNotify(i + 25, j + 37, k + 24, 3, 2);
		setBlock(world, i + 25, j + 37, k + 25, Blocks.leaves, 7);
		world.setBlockMetadataWithNotify(i + 25, j + 37, k + 25, 7, 2);
		setBlock(world, i + 25, j + 37, k + 26, Blocks.leaves, 7);
		world.setBlockMetadataWithNotify(i + 25, j + 37, k + 26, 7, 2);
		setBlock(world, i + 25, j + 37, k + 28, Blocks.leaves, 7);
		world.setBlockMetadataWithNotify(i + 25, j + 37, k + 28, 7, 2);
		setBlock(world, i + 25, j + 37, k + 29, Blocks.leaves, 7);
		world.setBlockMetadataWithNotify(i + 25, j + 37, k + 29, 7, 2);
		setBlock(world, i + 25, j + 37, k + 30, Blocks.leaves, 7);
		world.setBlockMetadataWithNotify(i + 25, j + 37, k + 30, 7, 2);
		setBlock(world, i + 25, j + 38, k + 22, Blocks.leaves, 7);
		world.setBlockMetadataWithNotify(i + 25, j + 38, k + 22, 7, 2);
		setBlock(world, i + 25, j + 38, k + 23, Blocks.leaves, 7);
		world.setBlockMetadataWithNotify(i + 25, j + 38, k + 23, 7, 2);
		setBlock(world, i + 25, j + 38, k + 24, Blocks.leaves, 7);
		world.setBlockMetadataWithNotify(i + 25, j + 38, k + 24, 7, 2);
		setBlock(world, i + 25, j + 38, k + 25, Blocks.leaves, 7);
		world.setBlockMetadataWithNotify(i + 25, j + 38, k + 25, 7, 2);
		setBlock(world, i + 25, j + 38, k + 26, Blocks.leaves, 7);
		world.setBlockMetadataWithNotify(i + 25, j + 38, k + 26, 7, 2);
		setBlock(world, i + 25, j + 38, k + 29, Blocks.leaves, 7);
		world.setBlockMetadataWithNotify(i + 25, j + 38, k + 29, 7, 2);
		setBlock(world, i + 25, j + 39, k + 23, Blocks.leaves, 7);
		world.setBlockMetadataWithNotify(i + 25, j + 39, k + 23, 7, 2);
		setBlock(world, i + 25, j + 39, k + 24, Blocks.leaves, 7);
		world.setBlockMetadataWithNotify(i + 25, j + 39, k + 24, 7, 2);
		setBlock(world, i + 25, j + 39, k + 25, Blocks.leaves, 7);
		world.setBlockMetadataWithNotify(i + 25, j + 39, k + 25, 7, 2);
		setBlock(world, i + 25, j + 40, k + 24, Blocks.leaves, 7);
		world.setBlockMetadataWithNotify(i + 25, j + 40, k + 24, 7, 2);
		setBlock(world, i + 25, j + 45, k + 31, Blocks.leaves, 7);
		world.setBlockMetadataWithNotify(i + 25, j + 45, k + 31, 7, 2);
		setBlock(world, i + 25, j + 53, k + 29, Blocks.leaves, 7);
		world.setBlockMetadataWithNotify(i + 25, j + 53, k + 29, 7, 2);
		setBlock(world, i + 25, j + 53, k + 30, Blocks.leaves, 7);
		world.setBlockMetadataWithNotify(i + 25, j + 53, k + 30, 7, 2);
		setBlock(world, i + 25, j + 53, k + 31, Blocks.leaves, 7);
		world.setBlockMetadataWithNotify(i + 25, j + 53, k + 31, 7, 2);
		setBlock(world, i + 25, j + 54, k + 30, Blocks.leaves, 7);
		world.setBlockMetadataWithNotify(i + 25, j + 54, k + 30, 7, 2);
		setBlock(world, i + 25, j + 57, k + 31, Blocks.leaves, 7);
		world.setBlockMetadataWithNotify(i + 25, j + 57, k + 31, 7, 2);
		setBlock(world, i + 26, j + 12, k + 27, Blocks.leaves, 7);
		world.setBlockMetadataWithNotify(i + 26, j + 12, k + 27, 7, 2);
		setBlock(world, i + 26, j + 12, k + 28, Blocks.leaves, 7);
		world.setBlockMetadataWithNotify(i + 26, j + 12, k + 28, 7, 2);
		setBlock(world, i + 26, j + 12, k + 29, Blocks.log, 3);
		world.setBlockMetadataWithNotify(i + 26, j + 12, k + 29, 3, 2);
		setBlock(world, i + 26, j + 12, k + 30, Blocks.leaves, 7);
		world.setBlockMetadataWithNotify(i + 26, j + 12, k + 30, 7, 2);
		setBlock(world, i + 26, j + 12, k + 31, Blocks.leaves, 7);
		world.setBlockMetadataWithNotify(i + 26, j + 12, k + 31, 7, 2);
		setBlock(world, i + 26, j + 13, k + 27, Blocks.leaves, 7);
		world.setBlockMetadataWithNotify(i + 26, j + 13, k + 27, 7, 2);
		setBlock(world, i + 26, j + 13, k + 28, Blocks.leaves, 7);
		world.setBlockMetadataWithNotify(i + 26, j + 13, k + 28, 7, 2);
		setBlock(world, i + 26, j + 13, k + 29, Blocks.leaves, 7);
		world.setBlockMetadataWithNotify(i + 26, j + 13, k + 29, 7, 2);
		setBlock(world, i + 26, j + 13, k + 30, Blocks.leaves, 7);
		world.setBlockMetadataWithNotify(i + 26, j + 13, k + 30, 7, 2);
		setBlock(world, i + 26, j + 13, k + 31, Blocks.leaves, 7);
		world.setBlockMetadataWithNotify(i + 26, j + 13, k + 31, 7, 2);
		setBlock(world, i + 26, j + 14, k + 28, Blocks.leaves, 7);
		world.setBlockMetadataWithNotify(i + 26, j + 14, k + 28, 7, 2);
		setBlock(world, i + 26, j + 14, k + 29, Blocks.leaves, 7);
		world.setBlockMetadataWithNotify(i + 26, j + 14, k + 29, 7, 2);
		setBlock(world, i + 26, j + 14, k + 30, Blocks.leaves, 7);
		world.setBlockMetadataWithNotify(i + 26, j + 14, k + 30, 7, 2);
		setBlock(world, i + 26, j + 15, k + 29, Blocks.leaves, 7);
		world.setBlockMetadataWithNotify(i + 26, j + 15, k + 29, 7, 2);
		setBlock(world, i + 26, j + 21, k + 29, Blocks.log, 3);
		world.setBlockMetadataWithNotify(i + 26, j + 21, k + 29, 3, 2);
		setBlock(world, i + 26, j + 21, k + 30, Blocks.log, 3);
		world.setBlockMetadataWithNotify(i + 26, j + 21, k + 30, 3, 2);
		setBlock(world, i + 26, j + 21, k + 31, Blocks.log, 3);
		world.setBlockMetadataWithNotify(i + 26, j + 21, k + 31, 3, 2);
		setBlock(world, i + 26, j + 22, k + 29, Blocks.log, 3);
		world.setBlockMetadataWithNotify(i + 26, j + 22, k + 29, 3, 2);
		setBlock(world, i + 26, j + 22, k + 30, Blocks.log, 3);
		world.setBlockMetadataWithNotify(i + 26, j + 22, k + 30, 3, 2);
		setBlock(world, i + 26, j + 22, k + 31, Blocks.log, 3);
		world.setBlockMetadataWithNotify(i + 26, j + 22, k + 31, 3, 2);
		setBlock(world, i + 26, j + 23, k + 25, Blocks.log, 3);
		world.setBlockMetadataWithNotify(i + 26, j + 23, k + 25, 3, 2);
		setBlock(world, i + 26, j + 23, k + 26, Blocks.log, 3);
		world.setBlockMetadataWithNotify(i + 26, j + 23, k + 26, 3, 2);
		setBlock(world, i + 26, j + 23, k + 27, Blocks.log, 3);
		world.setBlockMetadataWithNotify(i + 26, j + 23, k + 27, 3, 2);
		setBlock(world, i + 26, j + 23, k + 28, Blocks.log, 3);
		world.setBlockMetadataWithNotify(i + 26, j + 23, k + 28, 3, 2);
		setBlock(world, i + 26, j + 23, k + 29, Blocks.log, 3);
		world.setBlockMetadataWithNotify(i + 26, j + 23, k + 29, 3, 2);
		setBlock(world, i + 26, j + 23, k + 30, Blocks.log, 3);
		world.setBlockMetadataWithNotify(i + 26, j + 23, k + 30, 3, 2);
		setBlock(world, i + 26, j + 23, k + 31, Blocks.log, 3);
		world.setBlockMetadataWithNotify(i + 26, j + 23, k + 31, 3, 2);
		setBlock(world, i + 26, j + 30, k + 26, Blocks.leaves, 7);
		world.setBlockMetadataWithNotify(i + 26, j + 30, k + 26, 7, 2);
		setBlock(world, i + 26, j + 30, k + 27, Blocks.leaves, 7);
		world.setBlockMetadataWithNotify(i + 26, j + 30, k + 27, 7, 2);
		setBlock(world, i + 26, j + 30, k + 28, Blocks.leaves, 7);
		world.setBlockMetadataWithNotify(i + 26, j + 30, k + 28, 7, 2);
		setBlock(world, i + 26, j + 31, k + 27, Blocks.leaves, 7);
		world.setBlockMetadataWithNotify(i + 26, j + 31, k + 27, 7, 2);
		setBlock(world, i + 26, j + 31, k + 28, Blocks.leaves, 7);
		world.setBlockMetadataWithNotify(i + 26, j + 31, k + 28, 7, 2);
		setBlock(world, i + 26, j + 31, k + 29, Blocks.leaves, 7);
		world.setBlockMetadataWithNotify(i + 26, j + 31, k + 29, 7, 2);
		setBlock(world, i + 26, j + 31, k + 30, Blocks.leaves, 7);
		world.setBlockMetadataWithNotify(i + 26, j + 31, k + 30, 7, 2);
		setBlock(world, i + 26, j + 32, k + 29, Blocks.leaves, 7);
		world.setBlockMetadataWithNotify(i + 26, j + 32, k + 29, 7, 2);
		setBlock(world, i + 26, j + 33, k + 20, Blocks.leaves, 7);
		world.setBlockMetadataWithNotify(i + 26, j + 33, k + 20, 7, 2);
		setBlock(world, i + 26, j + 33, k + 21, Blocks.leaves, 7);
		world.setBlockMetadataWithNotify(i + 26, j + 33, k + 21, 7, 2);
		setBlock(world, i + 26, j + 33, k + 22, Blocks.leaves, 7);
		world.setBlockMetadataWithNotify(i + 26, j + 33, k + 22, 7, 2);
		setBlock(world, i + 26, j + 34, k + 21, Blocks.leaves, 7);
		world.setBlockMetadataWithNotify(i + 26, j + 34, k + 21, 7, 2);
		setBlock(world, i + 26, j + 36, k + 30, Blocks.log, 3);
		world.setBlockMetadataWithNotify(i + 26, j + 36, k + 30, 3, 2);
		setBlock(world, i + 26, j + 36, k + 31, Blocks.log, 3);
		world.setBlockMetadataWithNotify(i + 26, j + 36, k + 31, 3, 2);
		setBlock(world, i + 26, j + 37, k + 22, Blocks.leaves, 7);
		world.setBlockMetadataWithNotify(i + 26, j + 37, k + 22, 7, 2);
		setBlock(world, i + 26, j + 37, k + 23, Blocks.leaves, 7);
		world.setBlockMetadataWithNotify(i + 26, j + 37, k + 23, 7, 2);
		setBlock(world, i + 26, j + 37, k + 24, Blocks.leaves, 7);
		world.setBlockMetadataWithNotify(i + 26, j + 37, k + 24, 7, 2);
		setBlock(world, i + 26, j + 37, k + 25, Blocks.leaves, 7);
		world.setBlockMetadataWithNotify(i + 26, j + 37, k + 25, 7, 2);
		setBlock(world, i + 26, j + 37, k + 26, Blocks.leaves, 7);
		world.setBlockMetadataWithNotify(i + 26, j + 37, k + 26, 7, 2);
		setBlock(world, i + 26, j + 37, k + 27, Blocks.leaves, 7);
		world.setBlockMetadataWithNotify(i + 26, j + 37, k + 27, 7, 2);
		setBlock(world, i + 26, j + 37, k + 28, Blocks.leaves, 7);
		world.setBlockMetadataWithNotify(i + 26, j + 37, k + 28, 7, 2);
		setBlock(world, i + 26, j + 37, k + 29, Blocks.leaves, 7);
		world.setBlockMetadataWithNotify(i + 26, j + 37, k + 29, 7, 2);
		setBlock(world, i + 26, j + 37, k + 30, Blocks.leaves, 7);
		world.setBlockMetadataWithNotify(i + 26, j + 37, k + 30, 7, 2);
		setBlock(world, i + 26, j + 37, k + 31, Blocks.leaves, 7);
		world.setBlockMetadataWithNotify(i + 26, j + 37, k + 31, 7, 2);
		setBlock(world, i + 26, j + 38, k + 23, Blocks.leaves, 7);
		world.setBlockMetadataWithNotify(i + 26, j + 38, k + 23, 7, 2);
		setBlock(world, i + 26, j + 38, k + 24, Blocks.leaves, 7);
		world.setBlockMetadataWithNotify(i + 26, j + 38, k + 24, 7, 2);
		setBlock(world, i + 26, j + 38, k + 25, Blocks.leaves, 7);
		world.setBlockMetadataWithNotify(i + 26, j + 38, k + 25, 7, 2);
		setBlock(world, i + 26, j + 38, k + 28, Blocks.leaves, 7);
		world.setBlockMetadataWithNotify(i + 26, j + 38, k + 28, 7, 2);
		setBlock(world, i + 26, j + 38, k + 29, Blocks.leaves, 7);
		world.setBlockMetadataWithNotify(i + 26, j + 38, k + 29, 7, 2);
		setBlock(world, i + 26, j + 38, k + 30, Blocks.leaves, 7);
		world.setBlockMetadataWithNotify(i + 26, j + 38, k + 30, 7, 2);
		setBlock(world, i + 26, j + 39, k + 24, Blocks.leaves, 7);
		world.setBlockMetadataWithNotify(i + 26, j + 39, k + 24, 7, 2);
		setBlock(world, i + 26, j + 39, k + 29, Blocks.leaves, 7);
		world.setBlockMetadataWithNotify(i + 26, j + 39, k + 29, 7, 2);
		setBlock(world, i + 26, j + 51, k + 30, Blocks.leaves, 7);
		world.setBlockMetadataWithNotify(i + 26, j + 51, k + 30, 7, 2);
		setBlock(world, i + 26, j + 51, k + 31, Blocks.leaves, 7);
		world.setBlockMetadataWithNotify(i + 26, j + 51, k + 31, 7, 2);
		
		generate2(world, rand, i, j, k);
		return true;
		}

	
	public boolean generate2(World world, Random rand, int i, int j, int k)
	{
		setBlock(world, i + 26, j + 52, k + 31, Blocks.leaves, 7);
		world.setBlockMetadataWithNotify(i + 26, j + 52, k + 31, 7, 2);
		setBlock(world, i + 27, j + 12, k + 27, Blocks.leaves, 7);
		world.setBlockMetadataWithNotify(i + 27, j + 12, k + 27, 7, 2);
		setBlock(world, i + 27, j + 12, k + 28, Blocks.leaves, 7);
		world.setBlockMetadataWithNotify(i + 27, j + 12, k + 28, 7, 2);
		setBlock(world, i + 27, j + 12, k + 29, Blocks.leaves, 7);
		world.setBlockMetadataWithNotify(i + 27, j + 12, k + 29, 7, 2);
		setBlock(world, i + 27, j + 12, k + 30, Blocks.leaves, 7);
		world.setBlockMetadataWithNotify(i + 27, j + 12, k + 30, 7, 2);
		setBlock(world, i + 27, j + 12, k + 31, Blocks.leaves, 7);
		world.setBlockMetadataWithNotify(i + 27, j + 12, k + 31, 7, 2);
		setBlock(world, i + 27, j + 13, k + 28, Blocks.leaves, 7);
		world.setBlockMetadataWithNotify(i + 27, j + 13, k + 28, 7, 2);
		setBlock(world, i + 27, j + 13, k + 29, Blocks.leaves, 7);
		world.setBlockMetadataWithNotify(i + 27, j + 13, k + 29, 7, 2);
		setBlock(world, i + 27, j + 13, k + 30, Blocks.leaves, 7);
		world.setBlockMetadataWithNotify(i + 27, j + 13, k + 30, 7, 2);
		setBlock(world, i + 27, j + 14, k + 29, Blocks.leaves, 7);
		world.setBlockMetadataWithNotify(i + 27, j + 14, k + 29, 7, 2);
		setBlock(world, i + 27, j + 20, k + 31, Blocks.log, 3);
		world.setBlockMetadataWithNotify(i + 27, j + 20, k + 31, 3, 2);
		setBlock(world, i + 27, j + 21, k + 31, Blocks.log, 3);
		world.setBlockMetadataWithNotify(i + 27, j + 21, k + 31, 3, 2);
		setBlock(world, i + 27, j + 22, k + 25, Blocks.log, 3);
		world.setBlockMetadataWithNotify(i + 27, j + 22, k + 25, 3, 2);
		setBlock(world, i + 27, j + 22, k + 26, Blocks.log, 3);
		world.setBlockMetadataWithNotify(i + 27, j + 22, k + 26, 3, 2);
		setBlock(world, i + 27, j + 22, k + 27, Blocks.log, 3);
		world.setBlockMetadataWithNotify(i + 27, j + 22, k + 27, 3, 2);
		setBlock(world, i + 27, j + 22, k + 28, Blocks.log, 3);
		world.setBlockMetadataWithNotify(i + 27, j + 22, k + 28, 3, 2);
		setBlock(world, i + 27, j + 22, k + 29, Blocks.log, 3);
		world.setBlockMetadataWithNotify(i + 27, j + 22, k + 29, 3, 2);
		setBlock(world, i + 27, j + 22, k + 30, Blocks.log, 3);
		world.setBlockMetadataWithNotify(i + 27, j + 22, k + 30, 3, 2);
		setBlock(world, i + 27, j + 22, k + 31, Blocks.log, 3);
		world.setBlockMetadataWithNotify(i + 27, j + 22, k + 31, 3, 2);
		setBlock(world, i + 27, j + 23, k + 24, Blocks.log, 3);
		world.setBlockMetadataWithNotify(i + 27, j + 23, k + 24, 3, 2);
		setBlock(world, i + 27, j + 23, k + 25, Blocks.log, 3);
		world.setBlockMetadataWithNotify(i + 27, j + 23, k + 25, 3, 2);
		setBlock(world, i + 27, j + 23, k + 26, Blocks.log, 3);
		world.setBlockMetadataWithNotify(i + 27, j + 23, k + 26, 3, 2);
		setBlock(world, i + 27, j + 23, k + 27, Blocks.log, 3);
		world.setBlockMetadataWithNotify(i + 27, j + 23, k + 27, 3, 2);
		setBlock(world, i + 27, j + 23, k + 28, Blocks.log, 3);
		world.setBlockMetadataWithNotify(i + 27, j + 23, k + 28, 3, 2);
		setBlock(world, i + 27, j + 23, k + 31, Blocks.log, 3);
		world.setBlockMetadataWithNotify(i + 27, j + 23, k + 31, 3, 2);
		setBlock(world, i + 27, j + 24, k + 25, Blocks.log, 3);
		world.setBlockMetadataWithNotify(i + 27, j + 24, k + 25, 3, 2);
		setBlock(world, i + 27, j + 24, k + 26, Blocks.log, 3);
		world.setBlockMetadataWithNotify(i + 27, j + 24, k + 26, 3, 2);
		setBlock(world, i + 27, j + 24, k + 27, Blocks.log, 3);
		world.setBlockMetadataWithNotify(i + 27, j + 24, k + 27, 3, 2);
		setBlock(world, i + 27, j + 24, k + 28, Blocks.log, 3);
		world.setBlockMetadataWithNotify(i + 27, j + 24, k + 28, 3, 2);
		setBlock(world, i + 27, j + 30, k + 30, Blocks.log, 3);
		world.setBlockMetadataWithNotify(i + 27, j + 30, k + 30, 3, 2);
		setBlock(world, i + 27, j + 30, k + 31, Blocks.log, 3);
		world.setBlockMetadataWithNotify(i + 27, j + 30, k + 31, 3, 2);
		setBlock(world, i + 27, j + 31, k + 27, Blocks.leaves, 7);
		world.setBlockMetadataWithNotify(i + 27, j + 31, k + 27, 7, 2);
		setBlock(world, i + 27, j + 31, k + 28, Blocks.leaves, 7);
		world.setBlockMetadataWithNotify(i + 27, j + 31, k + 28, 7, 2);
		setBlock(world, i + 27, j + 31, k + 29, Blocks.leaves, 7);
		world.setBlockMetadataWithNotify(i + 27, j + 31, k + 29, 7, 2);
		setBlock(world, i + 27, j + 31, k + 30, Blocks.leaves, 7);
		world.setBlockMetadataWithNotify(i + 27, j + 31, k + 30, 7, 2);
		setBlock(world, i + 27, j + 31, k + 31, Blocks.leaves, 7);
		world.setBlockMetadataWithNotify(i + 27, j + 31, k + 31, 7, 2);
		setBlock(world, i + 27, j + 32, k + 28, Blocks.leaves, 7);
		world.setBlockMetadataWithNotify(i + 27, j + 32, k + 28, 7, 2);
		setBlock(world, i + 27, j + 32, k + 29, Blocks.leaves, 7);
