package com.parzivail.pswm.world.gen.wookietree;


import cpw.mods.fml.common.IWorldGenerator;

import java.util.Random;

import net.minecraft.block.Block;

import net.minecraft.init.Blocks;

import net.minecraft.world.World;

import net.minecraft.world.chunk.IChunkProvider;

import net.minecraft.world.gen.feature.WorldGenerator;


public class WT_10 extends WorldGenerator implements IWorldGenerator

{
	protected Block[] getValidSpawnBlocks()
	
	{
		return new Block[0];
		}

	
	public boolean locationIsValidSpawn(World world, int i, int j, int k)
	
	{
		int distanceToAir = 0;
		Block check = world.getBlock(i, j, k);
		
		while (check != Blocks.air)
		{
			if (distanceToAir > 3) { return false;
			}
			
			distanceToAir++;
			check = world.getBlock(i, j + distanceToAir, k);
			}
		
		j += distanceToAir - 1;
		
		Block block = world.getBlock(i, j, k);
		Block blockAbove = world.getBlock(i, j + 1, k);
		Block blockBelow = world.getBlock(i, j - 1, k);
		
		for (Block x : getValidSpawnBlocks())
		{
			if (blockAbove != Blocks.air) { return false;
			}
			if (block == x) return true;
			if ((block == Blocks.snow) && (blockBelow == x)) { return true;
			}
			}
		
		return false;
		}

	
	
	
	public void generate(Random random, int chunkX, int chunkZ, World world, IChunkProvider chunkGenerator, IChunkProvider chunkProvider)
	{
	}

	
	
	public void setBlock(World world, int x, int y, int z, Block block, int metadata)
	
	{
		world.setBlock(x, y, z, block, metadata, 2);
		}

	
	public boolean generate(World world, Random rand, int i, int j, int k)
	
	{
		k -= 10;
		i -= 10;
		
		setBlock(world, i + 4, j + 29, k + 29, Blocks.fence, 0);
		setBlock(world, i + 4, j + 29, k + 30, Blocks.fence, 0);
		setBlock(world, i + 0, j + 21, k + 2, Blocks.log, 3);
		world.setBlockMetadataWithNotify(i + 0, j + 21, k + 2, 3, 2);
		setBlock(world, i + 0, j + 21, k + 3, Blocks.log, 3);
		world.setBlockMetadataWithNotify(i + 0, j + 21, k + 3, 3, 2);
		setBlock(world, i + 0, j + 22, k + 0, Blocks.leaves, 7);
		world.setBlockMetadataWithNotify(i + 0, j + 22, k + 0, 7, 2);
		setBlock(world, i + 0, j + 22, k + 1, Blocks.leaves, 7);
		world.setBlockMetadataWithNotify(i + 0, j + 22, k + 1, 7, 2);
		setBlock(world, i + 0, j + 22, k + 2, Blocks.leaves, 7);
		world.setBlockMetadataWithNotify(i + 0, j + 22, k + 2, 7, 2);
		setBlock(world, i + 0, j + 22, k + 3, Blocks.leaves, 7);
		world.setBlockMetadataWithNotify(i + 0, j + 22, k + 3, 7, 2);
		setBlock(world, i + 0, j + 23, k + 0, Blocks.leaves, 7);
		world.setBlockMetadataWithNotify(i + 0, j + 23, k + 0, 7, 2);
		setBlock(world, i + 0, j + 23, k + 1, Blocks.leaves, 7);
		world.setBlockMetadataWithNotify(i + 0, j + 23, k + 1, 7, 2);
		setBlock(world, i + 0, j + 23, k + 2, Blocks.leaves, 7);
		world.setBlockMetadataWithNotify(i + 0, j + 23, k + 2, 7, 2);
		setBlock(world, i + 0, j + 23, k + 22, Blocks.log, 3);
		world.setBlockMetadataWithNotify(i + 0, j + 23, k + 22, 3, 2);
		setBlock(world, i + 0, j + 24, k + 1, Blocks.leaves, 7);
		world.setBlockMetadataWithNotify(i + 0, j + 24, k + 1, 7, 2);
		setBlock(world, i + 0, j + 24, k + 20, Blocks.log, 3);
		world.setBlockMetadataWithNotify(i + 0, j + 24, k + 20, 3, 2);
		setBlock(world, i + 0, j + 24, k + 21, Blocks.log, 3);
		world.setBlockMetadataWithNotify(i + 0, j + 24, k + 21, 3, 2);
		setBlock(world, i + 0, j + 24, k + 22, Blocks.log, 3);
		world.setBlockMetadataWithNotify(i + 0, j + 24, k + 22, 3, 2);
		setBlock(world, i + 0, j + 24, k + 23, Blocks.log, 3);
		world.setBlockMetadataWithNotify(i + 0, j + 24, k + 23, 3, 2);
		setBlock(world, i + 0, j + 25, k + 22, Blocks.log, 3);
		world.setBlockMetadataWithNotify(i + 0, j + 25, k + 22, 3, 2);
		setBlock(world, i + 0, j + 26, k + 24, Blocks.log, 3);
		world.setBlockMetadataWithNotify(i + 0, j + 26, k + 24, 3, 2);
		setBlock(world, i + 0, j + 26, k + 31, Blocks.log, 1);
		world.setBlockMetadataWithNotify(i + 0, j + 26, k + 31, 1, 2);
		setBlock(world, i + 0, j + 27, k + 11, Blocks.leaves, 7);
		world.setBlockMetadataWithNotify(i + 0, j + 27, k + 11, 7, 2);
		setBlock(world, i + 0, j + 27, k + 12, Blocks.leaves, 7);
		world.setBlockMetadataWithNotify(i + 0, j + 27, k + 12, 7, 2);
		setBlock(world, i + 0, j + 27, k + 13, Blocks.log, 3);
		world.setBlockMetadataWithNotify(i + 0, j + 27, k + 13, 3, 2);
		setBlock(world, i + 0, j + 27, k + 14, Blocks.leaves, 7);
		world.setBlockMetadataWithNotify(i + 0, j + 27, k + 14, 7, 2);
		setBlock(world, i + 0, j + 27, k + 15, Blocks.leaves, 7);
		world.setBlockMetadataWithNotify(i + 0, j + 27, k + 15, 7, 2);
		setBlock(world, i + 0, j + 28, k + 11, Blocks.leaves, 7);
		world.setBlockMetadataWithNotify(i + 0, j + 28, k + 11, 7, 2);
		setBlock(world, i + 0, j + 28, k + 12, Blocks.leaves, 7);
		world.setBlockMetadataWithNotify(i + 0, j + 28, k + 12, 7, 2);
		setBlock(world, i + 0, j + 28, k + 13, Blocks.leaves, 7);
		world.setBlockMetadataWithNotify(i + 0, j + 28, k + 13, 7, 2);
		setBlock(world, i + 0, j + 28, k + 14, Blocks.leaves, 7);
		world.setBlockMetadataWithNotify(i + 0, j + 28, k + 14, 7, 2);
		setBlock(world, i + 0, j + 28, k + 15, Blocks.leaves, 7);
		world.setBlockMetadataWithNotify(i + 0, j + 28, k + 15, 7, 2);
		setBlock(world, i + 0, j + 28, k + 16, Blocks.log, 3);
		world.setBlockMetadataWithNotify(i + 0, j + 28, k + 16, 3, 2);
		setBlock(world, i + 0, j + 28, k + 17, Blocks.leaves, 7);
		world.setBlockMetadataWithNotify(i + 0, j + 28, k + 17, 7, 2);
		setBlock(world, i + 0, j + 28, k + 18, Blocks.log, 3);
		world.setBlockMetadataWithNotify(i + 0, j + 28, k + 18, 3, 2);
		setBlock(world, i + 0, j + 29, k + 12, Blocks.leaves, 7);
		world.setBlockMetadataWithNotify(i + 0, j + 29, k + 12, 7, 2);
		setBlock(world, i + 0, j + 29, k + 13, Blocks.leaves, 7);
		world.setBlockMetadataWithNotify(i + 0, j + 29, k + 13, 7, 2);
		setBlock(world, i + 0, j + 29, k + 14, Blocks.leaves, 7);
		world.setBlockMetadataWithNotify(i + 0, j + 29, k + 14, 7, 2);
		setBlock(world, i + 0, j + 29, k + 15, Blocks.leaves, 7);
		world.setBlockMetadataWithNotify(i + 0, j + 29, k + 15, 7, 2);
		setBlock(world, i + 0, j + 29, k + 16, Blocks.leaves, 7);
		world.setBlockMetadataWithNotify(i + 0, j + 29, k + 16, 7, 2);
		setBlock(world, i + 0, j + 29, k + 17, Blocks.leaves, 7);
		world.setBlockMetadataWithNotify(i + 0, j + 29, k + 17, 7, 2);
		setBlock(world, i + 0, j + 29, k + 18, Blocks.leaves, 7);
		world.setBlockMetadataWithNotify(i + 0, j + 29, k + 18, 7, 2);
		setBlock(world, i + 0, j + 29, k + 29, Blocks.torch, 1);
		world.setBlockMetadataWithNotify(i + 0, j + 29, k + 29, 1, 2);
		setBlock(world, i + 0, j + 30, k + 13, Blocks.leaves, 7);
		world.setBlockMetadataWithNotify(i + 0, j + 30, k + 13, 7, 2);
		setBlock(world, i + 0, j + 30, k + 15, Blocks.leaves, 7);
		world.setBlockMetadataWithNotify(i + 0, j + 30, k + 15, 7, 2);
		setBlock(world, i + 0, j + 30, k + 16, Blocks.leaves, 7);
		world.setBlockMetadataWithNotify(i + 0, j + 30, k + 16, 7, 2);
		setBlock(world, i + 0, j + 30, k + 17, Blocks.log, 3);
		world.setBlockMetadataWithNotify(i + 0, j + 30, k + 17, 3, 2);
		setBlock(world, i + 0, j + 30, k + 27, Blocks.leaves, 7);
		world.setBlockMetadataWithNotify(i + 0, j + 30, k + 27, 7, 2);
		setBlock(world, i + 0, j + 30, k + 28, Blocks.log, 1);
		world.setBlockMetadataWithNotify(i + 0, j + 30, k + 28, 1, 2);
		setBlock(world, i + 0, j + 30, k + 29, Blocks.log, 1);
		world.setBlockMetadataWithNotify(i + 0, j + 30, k + 29, 1, 2);
		setBlock(world, i + 0, j + 30, k + 30, Blocks.log, 1);
		world.setBlockMetadataWithNotify(i + 0, j + 30, k + 30, 1, 2);
		setBlock(world, i + 0, j + 30, k + 31, Blocks.log, 1);
		world.setBlockMetadataWithNotify(i + 0, j + 30, k + 31, 1, 2);
		setBlock(world, i + 0, j + 31, k + 16, Blocks.leaves, 7);
		world.setBlockMetadataWithNotify(i + 0, j + 31, k + 16, 7, 2);
		setBlock(world, i + 0, j + 31, k + 21, Blocks.log, 3);
		world.setBlockMetadataWithNotify(i + 0, j + 31, k + 21, 3, 2);
		setBlock(world, i + 0, j + 31, k + 28, Blocks.log, 3);
		world.setBlockMetadataWithNotify(i + 0, j + 31, k + 28, 3, 2);
		setBlock(world, i + 0, j + 31, k + 29, Blocks.log, 1);
		world.setBlockMetadataWithNotify(i + 0, j + 31, k + 29, 1, 2);
		setBlock(world, i + 0, j + 31, k + 30, Blocks.log, 1);
		world.setBlockMetadataWithNotify(i + 0, j + 31, k + 30, 1, 2);
		setBlock(world, i + 0, j + 31, k + 31, Blocks.log, 1);
		world.setBlockMetadataWithNotify(i + 0, j + 31, k + 31, 1, 2);
		setBlock(world, i + 0, j + 32, k + 29, Blocks.log, 1);
		world.setBlockMetadataWithNotify(i + 0, j + 32, k + 29, 1, 2);
		setBlock(world, i + 0, j + 32, k + 30, Blocks.log, 1);
		world.setBlockMetadataWithNotify(i + 0, j + 32, k + 30, 1, 2);
		setBlock(world, i + 0, j + 32, k + 31, Blocks.log, 1);
		world.setBlockMetadataWithNotify(i + 0, j + 32, k + 31, 1, 2);
		setBlock(world, i + 0, j + 33, k + 30, Blocks.log, 1);
		world.setBlockMetadataWithNotify(i + 0, j + 33, k + 30, 1, 2);
		setBlock(world, i + 0, j + 33, k + 31, Blocks.log, 1);
		world.setBlockMetadataWithNotify(i + 0, j + 33, k + 31, 1, 2);
		setBlock(world, i + 0, j + 34, k + 19, Blocks.log, 3);
		world.setBlockMetadataWithNotify(i + 0, j + 34, k + 19, 3, 2);
		setBlock(world, i + 0, j + 34, k + 31, Blocks.log, 1);
		world.setBlockMetadataWithNotify(i + 0, j + 34, k + 31, 1, 2);
		setBlock(world, i + 0, j + 37, k + 19, Blocks.log, 3);
		world.setBlockMetadataWithNotify(i + 0, j + 37, k + 19, 3, 2);
		setBlock(world, i + 0, j + 38, k + 16, Blocks.leaves, 7);
		world.setBlockMetadataWithNotify(i + 0, j + 38, k + 16, 7, 2);
		setBlock(world, i + 0, j + 38, k + 17, Blocks.leaves, 7);
		world.setBlockMetadataWithNotify(i + 0, j + 38, k + 17, 7, 2);
		setBlock(world, i + 0, j + 38, k + 18, Blocks.log, 3);
		world.setBlockMetadataWithNotify(i + 0, j + 38, k + 18, 3, 2);
		setBlock(world, i + 0, j + 38, k + 19, Blocks.leaves, 7);
		world.setBlockMetadataWithNotify(i + 0, j + 38, k + 19, 7, 2);
		setBlock(world, i + 0, j + 38, k + 20, Blocks.leaves, 7);
		world.setBlockMetadataWithNotify(i + 0, j + 38, k + 20, 7, 2);
		setBlock(world, i + 0, j + 38, k + 26, Blocks.log, 3);
		world.setBlockMetadataWithNotify(i + 0, j + 38, k + 26, 3, 2);
		setBlock(world, i + 0, j + 39, k + 15, Blocks.leaves, 7);
		world.setBlockMetadataWithNotify(i + 0, j + 39, k + 15, 7, 2);
		setBlock(world, i + 0, j + 39, k + 16, Blocks.leaves, 7);
		world.setBlockMetadataWithNotify(i + 0, j + 39, k + 16, 7, 2);
		setBlock(world, i + 0, j + 39, k + 17, Blocks.leaves, 7);
		world.setBlockMetadataWithNotify(i + 0, j + 39, k + 17, 7, 2);
		setBlock(world, i + 0, j + 39, k + 18, Blocks.leaves, 7);
		world.setBlockMetadataWithNotify(i + 0, j + 39, k + 18, 7, 2);
		setBlock(world, i + 0, j + 39, k + 19, Blocks.leaves, 7);
		world.setBlockMetadataWithNotify(i + 0, j + 39, k + 19, 7, 2);
		setBlock(world, i + 0, j + 39, k + 24, Blocks.leaves, 7);
		world.setBlockMetadataWithNotify(i + 0, j + 39, k + 24, 7, 2);
		setBlock(world, i + 0, j + 39, k + 25, Blocks.leaves, 7);
		world.setBlockMetadataWithNotify(i + 0, j + 39, k + 25, 7, 2);
		setBlock(world, i + 0, j + 39, k + 26, Blocks.leaves, 7);
		world.setBlockMetadataWithNotify(i + 0, j + 39, k + 26, 7, 2);
		setBlock(world, i + 0, j + 39, k + 27, Blocks.leaves, 7);
		world.setBlockMetadataWithNotify(i + 0, j + 39, k + 27, 7, 2);
		setBlock(world, i + 0, j + 39, k + 28, Blocks.leaves, 7);
		world.setBlockMetadataWithNotify(i + 0, j + 39, k + 28, 7, 2);
		setBlock(world, i + 0, j + 40, k + 16, Blocks.leaves, 7);
		world.setBlockMetadataWithNotify(i + 0, j + 40, k + 16, 7, 2);
		setBlock(world, i + 0, j + 40, k + 18, Blocks.leaves, 7);
		world.setBlockMetadataWithNotify(i + 0, j + 40, k + 18, 7, 2);
		setBlock(world, i + 0, j + 40, k + 25, Blocks.leaves, 7);
		world.setBlockMetadataWithNotify(i + 0, j + 40, k + 25, 7, 2);
		setBlock(world, i + 0, j + 40, k + 26, Blocks.leaves, 7);
		world.setBlockMetadataWithNotify(i + 0, j + 40, k + 26, 7, 2);
		setBlock(world, i + 0, j + 40, k + 27, Blocks.leaves, 7);
		world.setBlockMetadataWithNotify(i + 0, j + 40, k + 27, 7, 2);
		setBlock(world, i + 0, j + 41, k + 23, Blocks.log, 3);
		world.setBlockMetadataWithNotify(i + 0, j + 41, k + 23, 3, 2);
		setBlock(world, i + 0, j + 41, k + 26, Blocks.leaves, 7);
		world.setBlockMetadataWithNotify(i + 0, j + 41, k + 26, 7, 2);
		setBlock(world, i + 0, j + 42, k + 20, Blocks.leaves, 7);
		world.setBlockMetadataWithNotify(i + 0, j + 42, k + 20, 7, 2);
		setBlock(world, i + 0, j + 42, k + 21, Blocks.leaves, 7);
		world.setBlockMetadataWithNotify(i + 0, j + 42, k + 21, 7, 2);
		setBlock(world, i + 0, j + 42, k + 22, Blocks.leaves, 7);
		world.setBlockMetadataWithNotify(i + 0, j + 42, k + 22, 7, 2);
		setBlock(world, i + 0, j + 42, k + 23, Blocks.leaves, 7);
		world.setBlockMetadataWithNotify(i + 0, j + 42, k + 23, 7, 2);
		setBlock(world, i + 0, j + 42, k + 24, Blocks.leaves, 7);
		world.setBlockMetadataWithNotify(i + 0, j + 42, k + 24, 7, 2);
		setBlock(world, i + 0, j + 43, k + 14, Blocks.leaves, 7);
		world.setBlockMetadataWithNotify(i + 0, j + 43, k + 14, 7, 2);
		setBlock(world, i + 0, j + 43, k + 15, Blocks.leaves, 7);
		world.setBlockMetadataWithNotify(i + 0, j + 43, k + 15, 7, 2);
		setBlock(world, i + 0, j + 43, k + 16, Blocks.leaves, 7);
		world.setBlockMetadataWithNotify(i + 0, j + 43, k + 16, 7, 2);
		setBlock(world, i + 0, j + 43, k + 17, Blocks.leaves, 7);
		world.setBlockMetadataWithNotify(i + 0, j + 43, k + 17, 7, 2);
		setBlock(world, i + 0, j + 43, k + 18, Blocks.leaves, 7);
		world.setBlockMetadataWithNotify(i + 0, j + 43, k + 18, 7, 2);
		setBlock(world, i + 0, j + 43, k + 21, Blocks.leaves, 7);
		world.setBlockMetadataWithNotify(i + 0, j + 43, k + 21, 7, 2);
		setBlock(world, i + 0, j + 43, k + 22, Blocks.leaves, 7);
		world.setBlockMetadataWithNotify(i + 0, j + 43, k + 22, 7, 2);
		setBlock(world, i + 0, j + 43, k + 23, Blocks.leaves, 7);
		world.setBlockMetadataWithNotify(i + 0, j + 43, k + 23, 7, 2);
		setBlock(world, i + 0, j + 44, k + 15, Blocks.leaves, 7);
		world.setBlockMetadataWithNotify(i + 0, j + 44, k + 15, 7, 2);
		setBlock(world, i + 0, j + 44, k + 16, Blocks.leaves, 7);
		world.setBlockMetadataWithNotify(i + 0, j + 44, k + 16, 7, 2);
		setBlock(world, i + 0, j + 44, k + 17, Blocks.leaves, 7);
		world.setBlockMetadataWithNotify(i + 0, j + 44, k + 17, 7, 2);
		setBlock(world, i + 0, j + 44, k + 22, Blocks.leaves, 7);
		world.setBlockMetadataWithNotify(i + 0, j + 44, k + 22, 7, 2);
		setBlock(world, i + 0, j + 45, k + 16, Blocks.leaves, 7);
		world.setBlockMetadataWithNotify(i + 0, j + 45, k + 16, 7, 2);
		setBlock(world, i + 0, j + 48, k + 27, Blocks.leaves, 7);
		world.setBlockMetadataWithNotify(i + 0, j + 48, k + 27, 7, 2);
		setBlock(world, i + 0, j + 48, k + 28, Blocks.leaves, 7);
		world.setBlockMetadataWithNotify(i + 0, j + 48, k + 28, 7, 2);
		setBlock(world, i + 0, j + 48, k + 29, Blocks.leaves, 7);
		world.setBlockMetadataWithNotify(i + 0, j + 48, k + 29, 7, 2);
		setBlock(world, i + 0, j + 48, k + 30, Blocks.leaves, 7);
		world.setBlockMetadataWithNotify(i + 0, j + 48, k + 30, 7, 2);
		setBlock(world, i + 0, j + 48, k + 31, Blocks.leaves, 7);
		world.setBlockMetadataWithNotify(i + 0, j + 48, k + 31, 7, 2);
		setBlock(world, i + 0, j + 49, k + 26, Blocks.leaves, 7);
		world.setBlockMetadataWithNotify(i + 0, j + 49, k + 26, 7, 2);
		setBlock(world, i + 0, j + 49, k + 27, Blocks.leaves, 7);
		world.setBlockMetadataWithNotify(i + 0, j + 49, k + 27, 7, 2);
		setBlock(world, i + 0, j + 49, k + 28, Blocks.leaves, 7);
		world.setBlockMetadataWithNotify(i + 0, j + 49, k + 28, 7, 2);
		setBlock(world, i + 0, j + 49, k + 29, Blocks.leaves, 7);
		world.setBlockMetadataWithNotify(i + 0, j + 49, k + 29, 7, 2);
		setBlock(world, i + 0, j + 49, k + 30, Blocks.leaves, 7);
		world.setBlockMetadataWithNotify(i + 0, j + 49, k + 30, 7, 2);
		setBlock(world, i + 0, j + 50, k + 19, Blocks.leaves, 7);
		world.setBlockMetadataWithNotify(i + 0, j + 50, k + 19, 7, 2);
		setBlock(world, i + 0, j + 50, k + 20, Blocks.leaves, 7);
		world.setBlockMetadataWithNotify(i + 0, j + 50, k + 20, 7, 2);
		setBlock(world, i + 0, j + 50, k + 21, Blocks.leaves, 7);
		world.setBlockMetadataWithNotify(i + 0, j + 50, k + 21, 7, 2);
		setBlock(world, i + 0, j + 50, k + 22, Blocks.leaves, 7);
		world.setBlockMetadataWithNotify(i + 0, j + 50, k + 22, 7, 2);
		setBlock(world, i + 0, j + 50, k + 23, Blocks.leaves, 7);
		world.setBlockMetadataWithNotify(i + 0, j + 50, k + 23, 7, 2);
		setBlock(world, i + 0, j + 50, k + 26, Blocks.leaves, 7);
		world.setBlockMetadataWithNotify(i + 0, j + 50, k + 26, 7, 2);
		setBlock(world, i + 0, j + 50, k + 27, Blocks.leaves, 7);
		world.setBlockMetadataWithNotify(i + 0, j + 50, k + 27, 7, 2);
		setBlock(world, i + 0, j + 50, k + 28, Blocks.leaves, 7);
		world.setBlockMetadataWithNotify(i + 0, j + 50, k + 28, 7, 2);
		setBlock(world, i + 0, j + 50, k + 29, Blocks.leaves, 7);
		world.setBlockMetadataWithNotify(i + 0, j + 50, k + 29, 7, 2);
		setBlock(world, i + 0, j + 50, k + 30, Blocks.leaves, 7);
		world.setBlockMetadataWithNotify(i + 0, j + 50, k + 30, 7, 2);
		setBlock(world, i + 0, j + 51, k + 20, Blocks.leaves, 7);
		world.setBlockMetadataWithNotify(i + 0, j + 51, k + 20, 7, 2);
		setBlock(world, i + 0, j + 51, k + 21, Blocks.leaves, 7);
		world.setBlockMetadataWithNotify(i + 0, j + 51, k + 21, 7, 2);
		setBlock(world, i + 0, j + 51, k + 22, Blocks.leaves, 7);
		world.setBlockMetadataWithNotify(i + 0, j + 51, k + 22, 7, 2);
		setBlock(world, i + 0, j + 51, k + 27, Blocks.leaves, 7);
		world.setBlockMetadataWithNotify(i + 0, j + 51, k + 27, 7, 2);
		setBlock(world, i + 0, j + 51, k + 28, Blocks.leaves, 7);
		world.setBlockMetadataWithNotify(i + 0, j + 51, k + 28, 7, 2);
		setBlock(world, i + 0, j + 51, k + 29, Blocks.leaves, 7);
		world.setBlockMetadataWithNotify(i + 0, j + 51, k + 29, 7, 2);
		setBlock(world, i + 0, j + 52, k + 21, Blocks.leaves, 7);
		world.setBlockMetadataWithNotify(i + 0, j + 52, k + 21, 7, 2);
		setBlock(world, i + 0, j + 52, k + 28, Blocks.leaves, 7);
		world.setBlockMetadataWithNotify(i + 0, j + 52, k + 28, 7, 2);
		setBlock(world, i + 0, j + 54, k + 23, Blocks.leaves, 7);
		world.setBlockMetadataWithNotify(i + 0, j + 54, k + 23, 7, 2);
		setBlock(world, i + 0, j + 54, k + 24, Blocks.leaves, 7);
		world.setBlockMetadataWithNotify(i + 0, j + 54, k + 24, 7, 2);
		setBlock(world, i + 0, j + 54, k + 25, Blocks.leaves, 7);
		world.setBlockMetadataWithNotify(i + 0, j + 54, k + 25, 7, 2);
		setBlock(world, i + 0, j + 55, k + 24, Blocks.leaves, 7);
		world.setBlockMetadataWithNotify(i + 0, j + 55, k + 24, 7, 2);
		setBlock(world, i + 0, j + 57, k + 20, Blocks.leaves, 7);
		world.setBlockMetadataWithNotify(i + 0, j + 57, k + 20, 7, 2);
		setBlock(world, i + 0, j + 57, k + 21, Blocks.leaves, 7);
		world.setBlockMetadataWithNotify(i + 0, j + 57, k + 21, 7, 2);
		setBlock(world, i + 0, j + 57, k + 22, Blocks.leaves, 7);
		world.setBlockMetadataWithNotify(i + 0, j + 57, k + 22, 7, 2);
		setBlock(world, i + 0, j + 58, k + 21, Blocks.leaves, 7);
		world.setBlockMetadataWithNotify(i + 0, j + 58, k + 21, 7, 2);
		setBlock(world, i + 1, j + 22, k + 0, Blocks.leaves, 7);
		world.setBlockMetadataWithNotify(i + 1, j + 22, k + 0, 7, 2);
		setBlock(world, i + 1, j + 22, k + 1, Blocks.log, 3);
		world.setBlockMetadataWithNotify(i + 1, j + 22, k + 1, 3, 2);
		setBlock(world, i + 1, j + 22, k + 2, Blocks.leaves, 7);
		world.setBlockMetadataWithNotify(i + 1, j + 22, k + 2, 7, 2);
		setBlock(world, i + 1, j + 22, k + 3, Blocks.leaves, 7);
		world.setBlockMetadataWithNotify(i + 1, j + 22, k + 3, 7, 2);
		setBlock(world, i + 1, j + 23, k + 0, Blocks.leaves, 7);
		world.setBlockMetadataWithNotify(i + 1, j + 23, k + 0, 7, 2);
		setBlock(world, i + 1, j + 23, k + 1, Blocks.leaves, 7);
		world.setBlockMetadataWithNotify(i + 1, j + 23, k + 1, 7, 2);
		setBlock(world, i + 1, j + 23, k + 2, Blocks.leaves, 7);
		world.setBlockMetadataWithNotify(i + 1, j + 23, k + 2, 7, 2);
		setBlock(world, i + 1, j + 23, k + 3, Blocks.leaves, 7);
		world.setBlockMetadataWithNotify(i + 1, j + 23, k + 3, 7, 2);
		setBlock(world, i + 1, j + 23, k + 22, Blocks.log, 3);
		world.setBlockMetadataWithNotify(i + 1, j + 23, k + 22, 3, 2);
		setBlock(world, i + 1, j + 24, k + 0, Blocks.leaves, 7);
		world.setBlockMetadataWithNotify(i + 1, j + 24, k + 0, 7, 2);
		setBlock(world, i + 1, j + 24, k + 1, Blocks.leaves, 7);
		world.setBlockMetadataWithNotify(i + 1, j + 24, k + 1, 7, 2);
		setBlock(world, i + 1, j + 24, k + 2, Blocks.leaves, 7);
		world.setBlockMetadataWithNotify(i + 1, j + 24, k + 2, 7, 2);
		setBlock(world, i + 1, j + 24, k + 19, Blocks.log, 3);
		world.setBlockMetadataWithNotify(i + 1, j + 24, k + 19, 3, 2);
		setBlock(world, i + 1, j + 24, k + 21, Blocks.log, 3);
		world.setBlockMetadataWithNotify(i + 1, j + 24, k + 21, 3, 2);
		setBlock(world, i + 1, j + 24, k + 22, Blocks.log, 3);
		world.setBlockMetadataWithNotify(i + 1, j + 24, k + 22, 3, 2);
		setBlock(world, i + 1, j + 24, k + 23, Blocks.log, 3);
		world.setBlockMetadataWithNotify(i + 1, j + 24, k + 23, 3, 2);
		setBlock(world, i + 1, j + 25, k + 1, Blocks.leaves, 7);
		world.setBlockMetadataWithNotify(i + 1, j + 25, k + 1, 7, 2);
		setBlock(world, i + 1, j + 25, k + 22, Blocks.log, 3);
		world.setBlockMetadataWithNotify(i + 1, j + 25, k + 22, 3, 2);
		setBlock(world, i + 1, j + 26, k + 24, Blocks.log, 3);
		world.setBlockMetadataWithNotify(i + 1, j + 26, k + 24, 3, 2);
		setBlock(world, i + 1, j + 26, k + 31, Blocks.log, 1);
		world.setBlockMetadataWithNotify(i + 1, j + 26, k + 31, 1, 2);
		setBlock(world, i + 1, j + 27, k + 11, Blocks.leaves, 7);
		world.setBlockMetadataWithNotify(i + 1, j + 27, k + 11, 7, 2);
		setBlock(world, i + 1, j + 27, k + 12, Blocks.leaves, 7);
		world.setBlockMetadataWithNotify(i + 1, j + 27, k + 12, 7, 2);
		setBlock(world, i + 1, j + 27, k + 13, Blocks.leaves, 7);
		world.setBlockMetadataWithNotify(i + 1, j + 27, k + 13, 7, 2);
		setBlock(world, i + 1, j + 27, k + 14, Blocks.leaves, 7);
		world.setBlockMetadataWithNotify(i + 1, j + 27, k + 14, 7, 2);
		setBlock(world, i + 1, j + 27, k + 15, Blocks.leaves, 7);
		world.setBlockMetadataWithNotify(i + 1, j + 27, k + 15, 7, 2);
		setBlock(world, i + 1, j + 28, k + 12, Blocks.leaves, 7);
		world.setBlockMetadataWithNotify(i + 1, j + 28, k + 12, 7, 2);
		setBlock(world, i + 1, j + 28, k + 13, Blocks.leaves, 7);
		world.setBlockMetadataWithNotify(i + 1, j + 28, k + 13, 7, 2);
		setBlock(world, i + 1, j + 28, k + 14, Blocks.leaves, 7);
		world.setBlockMetadataWithNotify(i + 1, j + 28, k + 14, 7, 2);
		setBlock(world, i + 1, j + 28, k + 15, Blocks.leaves, 7);
		world.setBlockMetadataWithNotify(i + 1, j + 28, k + 15, 7, 2);
		setBlock(world, i + 1, j + 28, k + 16, Blocks.leaves, 7);
		world.setBlockMetadataWithNotify(i + 1, j + 28, k + 16, 7, 2);
		setBlock(world, i + 1, j + 28, k + 17, Blocks.log, 3);
		world.setBlockMetadataWithNotify(i + 1, j + 28, k + 17, 3, 2);
		setBlock(world, i + 1, j + 28, k + 18, Blocks.leaves, 7);
		world.setBlockMetadataWithNotify(i + 1, j + 28, k + 18, 7, 2);
		setBlock(world, i + 1, j + 29, k + 13, Blocks.leaves, 7);
		world.setBlockMetadataWithNotify(i + 1, j + 29, k + 13, 7, 2);
		setBlock(world, i + 1, j + 29, k + 14, Blocks.leaves, 7);
		world.setBlockMetadataWithNotify(i + 1, j + 29, k + 14, 7, 2);
		setBlock(world, i + 1, j + 29, k + 15, Blocks.leaves, 7);
		world.setBlockMetadataWithNotify(i + 1, j + 29, k + 15, 7, 2);
		setBlock(world, i + 1, j + 29, k + 16, Blocks.leaves, 7);
		world.setBlockMetadataWithNotify(i + 1, j + 29, k + 16, 7, 2);
		setBlock(world, i + 1, j + 29, k + 17, Blocks.leaves, 7);
		world.setBlockMetadataWithNotify(i + 1, j + 29, k + 17, 7, 2);
		setBlock(world, i + 1, j + 30, k + 15, Blocks.leaves, 7);
		world.setBlockMetadataWithNotify(i + 1, j + 30, k + 15, 7, 2);
		setBlock(world, i + 1, j + 30, k + 16, Blocks.log, 3);
		world.setBlockMetadataWithNotify(i + 1, j + 30, k + 16, 3, 2);
		setBlock(world, i + 1, j + 30, k + 27, Blocks.leaves, 15);
		world.setBlockMetadataWithNotify(i + 1, j + 30, k + 27, 15, 2);
		setBlock(world, i + 1, j + 30, k + 28, Blocks.log, 1);
		world.setBlockMetadataWithNotify(i + 1, j + 30, k + 28, 1, 2);
		setBlock(world, i + 1, j + 30, k + 29, Blocks.log, 1);
		world.setBlockMetadataWithNotify(i + 1, j + 30, k + 29, 1, 2);
		setBlock(world, i + 1, j + 30, k + 30, Blocks.log, 1);
		world.setBlockMetadataWithNotify(i + 1, j + 30, k + 30, 1, 2);
		setBlock(world, i + 1, j + 30, k + 31, Blocks.log, 1);
		world.setBlockMetadataWithNotify(i + 1, j + 30, k + 31, 1, 2);
		setBlock(world, i + 1, j + 31, k + 20, Blocks.log, 3);
		world.setBlockMetadataWithNotify(i + 1, j + 31, k + 20, 3, 2);
		setBlock(world, i + 1, j + 31, k + 27, Blocks.leaves, 15);
		world.setBlockMetadataWithNotify(i + 1, j + 31, k + 27, 15, 2);
		setBlock(world, i + 1, j + 31, k + 28, Blocks.log, 3);
		world.setBlockMetadataWithNotify(i + 1, j + 31, k + 28, 3, 2);
		setBlock(world, i + 1, j + 31, k + 29, Blocks.log, 1);
		world.setBlockMetadataWithNotify(i + 1, j + 31, k + 29, 1, 2);
		setBlock(world, i + 1, j + 31, k + 30, Blocks.log, 1);
		world.setBlockMetadataWithNotify(i + 1, j + 31, k + 30, 1, 2);
		setBlock(world, i + 1, j + 31, k + 31, Blocks.log, 1);
		world.setBlockMetadataWithNotify(i + 1, j + 31, k + 31, 1, 2);
		setBlock(world, i + 1, j + 32, k + 18, Blocks.leaves, 7);
		world.setBlockMetadataWithNotify(i + 1, j + 32, k + 18, 7, 2);
		setBlock(world, i + 1, j + 32, k + 19, Blocks.leaves, 7);
		world.setBlockMetadataWithNotify(i + 1, j + 32, k + 19, 7, 2);
		setBlock(world, i + 1, j + 32, k + 20, Blocks.leaves, 7);
		world.setBlockMetadataWithNotify(i + 1, j + 32, k + 20, 7, 2);
		setBlock(world, i + 1, j + 32, k + 28, Blocks.leaves, 15);
		world.setBlockMetadataWithNotify(i + 1, j + 32, k + 28, 15, 2);
		setBlock(world, i + 1, j + 32, k + 29, Blocks.log, 1);
		world.setBlockMetadataWithNotify(i + 1, j + 32, k + 29, 1, 2);
		setBlock(world, i + 1, j + 32, k + 30, Blocks.log, 1);
		world.setBlockMetadataWithNotify(i + 1, j + 32, k + 30, 1, 2);
		setBlock(world, i + 1, j + 32, k + 31, Blocks.log, 1);
		world.setBlockMetadataWithNotify(i + 1, j + 32, k + 31, 1, 2);
		setBlock(world, i + 1, j + 33, k + 19, Blocks.leaves, 7);
		world.setBlockMetadataWithNotify(i + 1, j + 33, k + 19, 7, 2);
		setBlock(world, i + 1, j + 33, k + 29, Blocks.leaves, 15);
		world.setBlockMetadataWithNotify(i + 1, j + 33, k + 29, 15, 2);
		setBlock(world, i + 1, j + 33, k + 30, Blocks.log, 1);
		world.setBlockMetadataWithNotify(i + 1, j + 33, k + 30, 1, 2);
		setBlock(world, i + 1, j + 33, k + 31, Blocks.log, 1);
		world.setBlockMetadataWithNotify(i + 1, j + 33, k + 31, 1, 2);
		setBlock(world, i + 1, j + 34, k + 18, Blocks.log, 3);
		world.setBlockMetadataWithNotify(i + 1, j + 34, k + 18, 3, 2);
		setBlock(world, i + 1, j + 34, k + 31, Blocks.log, 1);
		world.setBlockMetadataWithNotify(i + 1, j + 34, k + 31, 1, 2);
		setBlock(world, i + 1, j + 38, k + 16, Blocks.leaves, 7);
		world.setBlockMetadataWithNotify(i + 1, j + 38, k + 16, 7, 2);
		setBlock(world, i + 1, j + 38, k + 17, Blocks.log, 3);
		world.setBlockMetadataWithNotify(i + 1, j + 38, k + 17, 3, 2);
		setBlock(world, i + 1, j + 38, k + 18, Blocks.log, 3);
		world.setBlockMetadataWithNotify(i + 1, j + 38, k + 18, 3, 2);
		setBlock(world, i + 1, j + 38, k + 19, Blocks.leaves, 7);
		world.setBlockMetadataWithNotify(i + 1, j + 38, k + 19, 7, 2);
		setBlock(world, i + 1, j + 38, k + 20, Blocks.leaves, 7);
		world.setBlockMetadataWithNotify(i + 1, j + 38, k + 20, 7, 2);
		setBlock(world, i + 1, j + 39, k + 14, Blocks.leaves, 7);
		world.setBlockMetadataWithNotify(i + 1, j + 39, k + 14, 7, 2);
		setBlock(world, i + 1, j + 39, k + 15, Blocks.leaves, 7);
		world.setBlockMetadataWithNotify(i + 1, j + 39, k + 15, 7, 2);
		setBlock(world, i + 1, j + 39, k + 16, Blocks.leaves, 7);
		world.setBlockMetadataWithNotify(i + 1, j + 39, k + 16, 7, 2);
		setBlock(world, i + 1, j + 39, k + 17, Blocks.leaves, 7);
		world.setBlockMetadataWithNotify(i + 1, j + 39, k + 17, 7, 2);
		setBlock(world, i + 1, j + 39, k + 18, Blocks.leaves, 7);
		world.setBlockMetadataWithNotify(i + 1, j + 39, k + 18, 7, 2);
		setBlock(world, i + 1, j + 39, k + 19, Blocks.leaves, 7);
		world.setBlockMetadataWithNotify(i + 1, j + 39, k + 19, 7, 2);
		setBlock(world, i + 1, j + 39, k + 20, Blocks.leaves, 7);
		world.setBlockMetadataWithNotify(i + 1, j + 39, k + 20, 7, 2);
		setBlock(world, i + 1, j + 39, k + 24, Blocks.leaves, 7);
		world.setBlockMetadataWithNotify(i + 1, j + 39, k + 24, 7, 2);
		setBlock(world, i + 1, j + 39, k + 25, Blocks.leaves, 7);
		world.setBlockMetadataWithNotify(i + 1, j + 39, k + 25, 7, 2);
		setBlock(world, i + 1, j + 39, k + 26, Blocks.log, 3);
		world.setBlockMetadataWithNotify(i + 1, j + 39, k + 26, 3, 2);
		setBlock(world, i + 1, j + 39, k + 27, Blocks.leaves, 7);
		world.setBlockMetadataWithNotify(i + 1, j + 39, k + 27, 7, 2);
		setBlock(world, i + 1, j + 39, k + 28, Blocks.leaves, 7);
		world.setBlockMetadataWithNotify(i + 1, j + 39, k + 28, 7, 2);
		setBlock(world, i + 1, j + 40, k + 15, Blocks.leaves, 7);
		world.setBlockMetadataWithNotify(i + 1, j + 40, k + 15, 7, 2);
		setBlock(world, i + 1, j + 40, k + 16, Blocks.leaves, 7);
		world.setBlockMetadataWithNotify(i + 1, j + 40, k + 16, 7, 2);
		setBlock(world, i + 1, j + 40, k + 17, Blocks.leaves, 7);
		world.setBlockMetadataWithNotify(i + 1, j + 40, k + 17, 7, 2);
		setBlock(world, i + 1, j + 40, k + 18, Blocks.leaves, 7);
		world.setBlockMetadataWithNotify(i + 1, j + 40, k + 18, 7, 2);
		setBlock(world, i + 1, j + 40, k + 19, Blocks.leaves, 7);
		world.setBlockMetadataWithNotify(i + 1, j + 40, k + 19, 7, 2);
		setBlock(world, i + 1, j + 40, k + 24, Blocks.leaves, 7);
		world.setBlockMetadataWithNotify(i + 1, j + 40, k + 24, 7, 2);
		setBlock(world, i + 1, j + 40, k + 25, Blocks.leaves, 7);
		world.setBlockMetadataWithNotify(i + 1, j + 40, k + 25, 7, 2);
		setBlock(world, i + 1, j + 40, k + 26, Blocks.leaves, 7);
		world.setBlockMetadataWithNotify(i + 1, j + 40, k + 26, 7, 2);
		setBlock(world, i + 1, j + 40, k + 27, Blocks.leaves, 7);
		world.setBlockMetadataWithNotify(i + 1, j + 40, k + 27, 7, 2);
		setBlock(world, i + 1, j + 40, k + 28, Blocks.leaves, 7);
		world.setBlockMetadataWithNotify(i + 1, j + 40, k + 28, 7, 2);
		setBlock(world, i + 1, j + 41, k + 16, Blocks.leaves, 7);
		world.setBlockMetadataWithNotify(i + 1, j + 41, k + 16, 7, 2);
		setBlock(world, i + 1, j + 41, k + 18, Blocks.leaves, 7);
		world.setBlockMetadataWithNotify(i + 1, j + 41, k + 18, 7, 2);
		setBlock(world, i + 1, j + 41, k + 25, Blocks.leaves, 7);
		world.setBlockMetadataWithNotify(i + 1, j + 41, k + 25, 7, 2);
		setBlock(world, i + 1, j + 41, k + 26, Blocks.leaves, 7);
		world.setBlockMetadataWithNotify(i + 1, j + 41, k + 26, 7, 2);
		setBlock(world, i + 1, j + 41, k + 27, Blocks.leaves, 7);
		world.setBlockMetadataWithNotify(i + 1, j + 41, k + 27, 7, 2);
		setBlock(world, i + 1, j + 42, k + 20, Blocks.leaves, 7);
		world.setBlockMetadataWithNotify(i + 1, j + 42, k + 20, 7, 2);
		setBlock(world, i + 1, j + 42, k + 21, Blocks.leaves, 7);
		world.setBlockMetadataWithNotify(i + 1, j + 42, k + 21, 7, 2);
		setBlock(world, i + 1, j + 42, k + 22, Blocks.log, 3);
		world.setBlockMetadataWithNotify(i + 1, j + 42, k + 22, 3, 2);
		setBlock(world, i + 1, j + 42, k + 23, Blocks.leaves, 7);
		world.setBlockMetadataWithNotify(i + 1, j + 42, k + 23, 7, 2);
		setBlock(world, i + 1, j + 42, k + 24, Blocks.leaves, 7);
		world.setBlockMetadataWithNotify(i + 1, j + 42, k + 24, 7, 2);
		setBlock(world, i + 1, j + 42, k + 26, Blocks.leaves, 7);
		world.setBlockMetadataWithNotify(i + 1, j + 42, k + 26, 7, 2);
		setBlock(world, i + 1, j + 43, k + 15, Blocks.leaves, 7);
		world.setBlockMetadataWithNotify(i + 1, j + 43, k + 15, 7, 2);
		setBlock(world, i + 1, j + 43, k + 16, Blocks.leaves, 7);
		world.setBlockMetadataWithNotify(i + 1, j + 43, k + 16, 7, 2);
		setBlock(world, i + 1, j + 43, k + 17, Blocks.leaves, 7);
		world.setBlockMetadataWithNotify(i + 1, j + 43, k + 17, 7, 2);
		setBlock(world, i + 1, j + 43, k + 20, Blocks.leaves, 7);
		world.setBlockMetadataWithNotify(i + 1, j + 43, k + 20, 7, 2);
		setBlock(world, i + 1, j + 43, k + 21, Blocks.leaves, 7);
		world.setBlockMetadataWithNotify(i + 1, j + 43, k + 21, 7, 2);
		setBlock(world, i + 1, j + 43, k + 22, Blocks.leaves, 7);
		world.setBlockMetadataWithNotify(i + 1, j + 43, k + 22, 7, 2);
		setBlock(world, i + 1, j + 43, k + 23, Blocks.leaves, 7);
		world.setBlockMetadataWithNotify(i + 1, j + 43, k + 23, 7, 2);
		setBlock(world, i + 1, j + 43, k + 24, Blocks.leaves, 7);
		world.setBlockMetadataWithNotify(i + 1, j + 43, k + 24, 7, 2);
		setBlock(world, i + 1, j + 44, k + 16, Blocks.leaves, 7);
		world.setBlockMetadataWithNotify(i + 1, j + 44, k + 16, 7, 2);
		setBlock(world, i + 1, j + 44, k + 21, Blocks.leaves, 7);
		world.setBlockMetadataWithNotify(i + 1, j + 44, k + 21, 7, 2);
		setBlock(world, i + 1, j + 44, k + 22, Blocks.leaves, 7);
		world.setBlockMetadataWithNotify(i + 1, j + 44, k + 22, 7, 2);
		setBlock(world, i + 1, j + 44, k + 23, Blocks.leaves, 7);
		world.setBlockMetadataWithNotify(i + 1, j + 44, k + 23, 7, 2);
		setBlock(world, i + 1, j + 45, k + 22, Blocks.leaves, 7);
		world.setBlockMetadataWithNotify(i + 1, j + 45, k + 22, 7, 2);
		setBlock(world, i + 1, j + 48, k + 28, Blocks.leaves, 7);
		world.setBlockMetadataWithNotify(i + 1, j + 48, k + 28, 7, 2);
		setBlock(world, i + 1, j + 48, k + 29, Blocks.leaves, 7);
		world.setBlockMetadataWithNotify(i + 1, j + 48, k + 29, 7, 2);
		setBlock(world, i + 1, j + 48, k + 30, Blocks.leaves, 7);
		world.setBlockMetadataWithNotify(i + 1, j + 48, k + 30, 7, 2);
		setBlock(world, i + 1, j + 49, k + 25, Blocks.leaves, 7);
		world.setBlockMetadataWithNotify(i + 1, j + 49, k + 25, 7, 2);
		setBlock(world, i + 1, j + 49, k + 26, Blocks.leaves, 7);
		world.setBlockMetadataWithNotify(i + 1, j + 49, k + 26, 7, 2);
		setBlock(world, i + 1, j + 49, k + 27, Blocks.leaves, 7);
		world.setBlockMetadataWithNotify(i + 1, j + 49, k + 27, 7, 2);
		setBlock(world, i + 1, j + 49, k + 28, Blocks.leaves, 7);
		world.setBlockMetadataWithNotify(i + 1, j + 49, k + 28, 7, 2);
		setBlock(world, i + 1, j + 49, k + 29, Blocks.leaves, 7);
		world.setBlockMetadataWithNotify(i + 1, j + 49, k + 29, 7, 2);
		setBlock(world, i + 1, j + 50, k + 19, Blocks.leaves, 7);
		world.setBlockMetadataWithNotify(i + 1, j + 50, k + 19, 7, 2);
		setBlock(world, i + 1, j + 50, k + 20, Blocks.leaves, 7);
		world.setBlockMetadataWithNotify(i + 1, j + 50, k + 20, 7, 2);
		setBlock(world, i + 1, j + 50, k + 21, Blocks.log, 3);
		world.setBlockMetadataWithNotify(i + 1, j + 50, k + 21, 3, 2);
		setBlock(world, i + 1, j + 50, k + 22, Blocks.leaves, 7);
		world.setBlockMetadataWithNotify(i + 1, j + 50, k + 22, 7, 2);
		setBlock(world, i + 1, j + 50, k + 23, Blocks.leaves, 7);
		world.setBlockMetadataWithNotify(i + 1, j + 50, k + 23, 7, 2);
		setBlock(world, i + 1, j + 50, k + 26, Blocks.leaves, 7);
		world.setBlockMetadataWithNotify(i + 1, j + 50, k + 26, 7, 2);
		setBlock(world, i + 1, j + 50, k + 27, Blocks.leaves, 7);
		world.setBlockMetadataWithNotify(i + 1, j + 50, k + 27, 7, 2);
		setBlock(world, i + 1, j + 50, k + 28, Blocks.leaves, 7);
		world.setBlockMetadataWithNotify(i + 1, j + 50, k + 28, 7, 2);
		setBlock(world, i + 1, j + 50, k + 29, Blocks.leaves, 7);
		world.setBlockMetadataWithNotify(i + 1, j + 50, k + 29, 7, 2);
		setBlock(world, i + 1, j + 51, k + 19, Blocks.leaves, 7);
		world.setBlockMetadataWithNotify(i + 1, j + 51, k + 19, 7, 2);
		setBlock(world, i + 1, j + 51, k + 20, Blocks.leaves, 7);
		world.setBlockMetadataWithNotify(i + 1, j + 51, k + 20, 7, 2);
		setBlock(world, i + 1, j + 51, k + 21, Blocks.leaves, 7);
		world.setBlockMetadataWithNotify(i + 1, j + 51, k + 21, 7, 2);
		setBlock(world, i + 1, j + 51, k + 22, Blocks.leaves, 7);
		world.setBlockMetadataWithNotify(i + 1, j + 51, k + 22, 7, 2);
		setBlock(world, i + 1, j + 51, k + 23, Blocks.leaves, 7);
		world.setBlockMetadataWithNotify(i + 1, j + 51, k + 23, 7, 2);
		setBlock(world, i + 1, j + 51, k + 27, Blocks.leaves, 7);
		world.setBlockMetadataWithNotify(i + 1, j + 51, k + 27, 7, 2);
		setBlock(world, i + 1, j + 51, k + 28, Blocks.leaves, 7);
		world.setBlockMetadataWithNotify(i + 1, j + 51, k + 28, 7, 2);
		setBlock(world, i + 1, j + 52, k + 20, Blocks.leaves, 7);
		world.setBlockMetadataWithNotify(i + 1, j + 52, k + 20, 7, 2);
		setBlock(world, i + 1, j + 52, k + 21, Blocks.leaves, 7);
		world.setBlockMetadataWithNotify(i + 1, j + 52, k + 21, 7, 2);
		setBlock(world, i + 1, j + 52, k + 22, Blocks.leaves, 7);
		world.setBlockMetadataWithNotify(i + 1, j + 52, k + 22, 7, 2);
		setBlock(world, i + 1, j + 53, k + 21, Blocks.leaves, 7);
		world.setBlockMetadataWithNotify(i + 1, j + 53, k + 21, 7, 2);
		setBlock(world, i + 2, j + 22, k + 0, Blocks.leaves, 7);
		world.setBlockMetadataWithNotify(i + 2, j + 22, k + 0, 7, 2);
		setBlock(world, i + 2, j + 22, k + 1, Blocks.leaves, 7);
		world.setBlockMetadataWithNotify(i + 2, j + 22, k + 1, 7, 2);
		setBlock(world, i + 2, j + 22, k + 2, Blocks.leaves, 7);
		world.setBlockMetadataWithNotify(i + 2, j + 22, k + 2, 7, 2);
		setBlock(world, i + 2, j + 22, k + 3, Blocks.leaves, 7);
		world.setBlockMetadataWithNotify(i + 2, j + 22, k + 3, 7, 2);
		setBlock(world, i + 2, j + 23, k + 0, Blocks.leaves, 7);
		world.setBlockMetadataWithNotify(i + 2, j + 23, k + 0, 7, 2);
		setBlock(world, i + 2, j + 23, k + 1, Blocks.leaves, 7);
		world.setBlockMetadataWithNotify(i + 2, j + 23, k + 1, 7, 2);
		setBlock(world, i + 2, j + 23, k + 2, Blocks.leaves, 7);
		world.setBlockMetadataWithNotify(i + 2, j + 23, k + 2, 7, 2);
		setBlock(world, i + 2, j + 23, k + 22, Blocks.log, 3);
		world.setBlockMetadataWithNotify(i + 2, j + 23, k + 22, 3, 2);
		setBlock(world, i + 2, j + 24, k + 1, Blocks.leaves, 7);
		world.setBlockMetadataWithNotify(i + 2, j + 24, k + 1, 7, 2);
		setBlock(world, i + 2, j + 24, k + 19, Blocks.log, 3);
		world.setBlockMetadataWithNotify(i + 2, j + 24, k + 19, 3, 2);
		setBlock(world, i + 2, j + 24, k + 21, Blocks.log, 3);
		world.setBlockMetadataWithNotify(i + 2, j + 24, k + 21, 3, 2);
		setBlock(world, i + 2, j + 24, k + 22, Blocks.log, 3);
		world.setBlockMetadataWithNotify(i + 2, j + 24, k + 22, 3, 2);
		setBlock(world, i + 2, j + 24, k + 23, Blocks.log, 3);
		world.setBlockMetadataWithNotify(i + 2, j + 24, k + 23, 3, 2);
		setBlock(world, i + 2, j + 25, k + 22, Blocks.log, 3);
		world.setBlockMetadataWithNotify(i + 2, j + 25, k + 22, 3, 2);
		setBlock(world, i + 2, j + 26, k + 24, Blocks.log, 3);
		world.setBlockMetadataWithNotify(i + 2, j + 26, k + 24, 3, 2);
		setBlock(world, i + 2, j + 26, k + 31, Blocks.log, 1);
		world.setBlockMetadataWithNotify(i + 2, j + 26, k + 31, 1, 2);
		setBlock(world, i + 2, j + 27, k + 12, Blocks.leaves, 7);
		world.setBlockMetadataWithNotify(i + 2, j + 27, k + 12, 7, 2);
		setBlock(world, i + 2, j + 27, k + 13, Blocks.leaves, 7);
		world.setBlockMetadataWithNotify(i + 2, j + 27, k + 13, 7, 2);
		setBlock(world, i + 2, j + 27, k + 14, Blocks.leaves, 7);
		world.setBlockMetadataWithNotify(i + 2, j + 27, k + 14, 7, 2);
		setBlock(world, i + 2, j + 28, k + 13, Blocks.leaves, 7);
		world.setBlockMetadataWithNotify(i + 2, j + 28, k + 13, 7, 2);
		setBlock(world, i + 2, j + 28, k + 15, Blocks.leaves, 7);
		world.setBlockMetadataWithNotify(i + 2, j + 28, k + 15, 7, 2);
		setBlock(world, i + 2, j + 28, k + 16, Blocks.log, 3);
		world.setBlockMetadataWithNotify(i + 2, j + 28, k + 16, 3, 2);
		setBlock(world, i + 2, j + 28, k + 17, Blocks.leaves, 7);
		world.setBlockMetadataWithNotify(i + 2, j + 28, k + 17, 7, 2);
		setBlock(world, i + 2, j + 29, k + 13, Blocks.leaves, 7);
		world.setBlockMetadataWithNotify(i + 2, j + 29, k + 13, 7, 2);
		setBlock(world, i + 2, j + 29, k + 14, Blocks.leaves, 7);
		world.setBlockMetadataWithNotify(i + 2, j + 29, k + 14, 7, 2);
		setBlock(world, i + 2, j + 29, k + 15, Blocks.leaves, 7);
		world.setBlockMetadataWithNotify(i + 2, j + 29, k + 15, 7, 2);
		setBlock(world, i + 2, j + 29, k + 16, Blocks.leaves, 7);
		world.setBlockMetadataWithNotify(i + 2, j + 29, k + 16, 7, 2);
		setBlock(world, i + 2, j + 29, k + 17, Blocks.leaves, 7);
		world.setBlockMetadataWithNotify(i + 2, j + 29, k + 17, 7, 2);
		setBlock(world, i + 2, j + 29, k + 29, Blocks.torch, 2);
		world.setBlockMetadataWithNotify(i + 2, j + 29, k + 29, 2, 2);
		setBlock(world, i + 2, j + 30, k + 14, Blocks.leaves, 7);
		world.setBlockMetadataWithNotify(i + 2, j + 30, k + 14, 7, 2);
		setBlock(world, i + 2, j + 30, k + 15, Blocks.log, 3);
		world.setBlockMetadataWithNotify(i + 2, j + 30, k + 15, 3, 2);
		setBlock(world, i + 2, j + 30, k + 16, Blocks.leaves, 7);
		world.setBlockMetadataWithNotify(i + 2, j + 30, k + 16, 7, 2);
		setBlock(world, i + 2, j + 30, k + 27, Blocks.leaves, 15);
		world.setBlockMetadataWithNotify(i + 2, j + 30, k + 27, 15, 2);
		setBlock(world, i + 2, j + 30, k + 28, Blocks.log, 1);
		world.setBlockMetadataWithNotify(i + 2, j + 30, k + 28, 1, 2);
		setBlock(world, i + 2, j + 30, k + 29, Blocks.log, 1);
		world.setBlockMetadataWithNotify(i + 2, j + 30, k + 29, 1, 2);
		setBlock(world, i + 2, j + 30, k + 30, Blocks.log, 1);
		world.setBlockMetadataWithNotify(i + 2, j + 30, k + 30, 1, 2);
		setBlock(world, i + 2, j + 30, k + 31, Blocks.log, 1);
		world.setBlockMetadataWithNotify(i + 2, j + 30, k + 31, 1, 2);
		setBlock(world, i + 2, j + 31, k + 12, Blocks.leaves, 7);
		world.setBlockMetadataWithNotify(i + 2, j + 31, k + 12, 7, 2);
		setBlock(world, i + 2, j + 31, k + 13, Blocks.leaves, 7);
		world.setBlockMetadataWithNotify(i + 2, j + 31, k + 13, 7, 2);
		setBlock(world, i + 2, j + 31, k + 14, Blocks.leaves, 7);
		world.setBlockMetadataWithNotify(i + 2, j + 31, k + 14, 7, 2);
		setBlock(world, i + 2, j + 31, k + 15, Blocks.leaves, 7);
		world.setBlockMetadataWithNotify(i + 2, j + 31, k + 15, 7, 2);
		setBlock(world, i + 2, j + 31, k + 20, Blocks.log, 3);
		world.setBlockMetadataWithNotify(i + 2, j + 31, k + 20, 3, 2);
		setBlock(world, i + 2, j + 31, k + 28, Blocks.leaves, 15);
		world.setBlockMetadataWithNotify(i + 2, j + 31, k + 28, 15, 2);
		setBlock(world, i + 2, j + 31, k + 29, Blocks.log, 1);
		world.setBlockMetadataWithNotify(i + 2, j + 31, k + 29, 1, 2);
		setBlock(world, i + 2, j + 31, k + 30, Blocks.log, 1);
		world.setBlockMetadataWithNotify(i + 2, j + 31, k + 30, 1, 2);
		setBlock(world, i + 2, j + 31, k + 31, Blocks.log, 1);
		world.setBlockMetadataWithNotify(i + 2, j + 31, k + 31, 1, 2);
		setBlock(world, i + 2, j + 32, k + 13, Blocks.leaves, 7);
		world.setBlockMetadataWithNotify(i + 2, j + 32, k + 13, 7, 2);
		setBlock(world, i + 2, j + 32, k + 17, Blocks.leaves, 7);
		world.setBlockMetadataWithNotify(i + 2, j + 32, k + 17, 7, 2);
		setBlock(world, i + 2, j + 32, k + 18, Blocks.leaves, 7);
		world.setBlockMetadataWithNotify(i + 2, j + 32, k + 18, 7, 2);
		setBlock(world, i + 2, j + 32, k + 19, Blocks.leaves, 7);
		world.setBlockMetadataWithNotify(i + 2, j + 32, k + 19, 7, 2);
		setBlock(world, i + 2, j + 32, k + 20, Blocks.leaves, 7);
		world.setBlockMetadataWithNotify(i + 2, j + 32, k + 20, 7, 2);
		setBlock(world, i + 2, j + 32, k + 21, Blocks.leaves, 7);
		world.setBlockMetadataWithNotify(i + 2, j + 32, k + 21, 7, 2);
		setBlock(world, i + 2, j + 32, k + 29, Blocks.log, 1);
		world.setBlockMetadataWithNotify(i + 2, j + 32, k + 29, 1, 2);
		setBlock(world, i + 2, j + 32, k + 30, Blocks.log, 1);
		world.setBlockMetadataWithNotify(i + 2, j + 32, k + 30, 1, 2);
		setBlock(world, i + 2, j + 32, k + 31, Blocks.log, 1);
		world.setBlockMetadataWithNotify(i + 2, j + 32, k + 31, 1, 2);
		setBlock(world, i + 2, j + 33, k + 18, Blocks.leaves, 7);
		world.setBlockMetadataWithNotify(i + 2, j + 33, k + 18, 7, 2);
		setBlock(world, i + 2, j + 33, k + 19, Blocks.leaves, 7);
		world.setBlockMetadataWithNotify(i + 2, j + 33, k + 19, 7, 2);
		setBlock(world, i + 2, j + 33, k + 20, Blocks.leaves, 7);
		world.setBlockMetadataWithNotify(i + 2, j + 33, k + 20, 7, 2);
		setBlock(world, i + 2, j + 33, k + 30, Blocks.log, 1);
		world.setBlockMetadataWithNotify(i + 2, j + 33, k + 30, 1, 2);
		setBlock(world, i + 2, j + 33, k + 31, Blocks.log, 1);
		world.setBlockMetadataWithNotify(i + 2, j + 33, k + 31, 1, 2);
		setBlock(world, i + 2, j + 34, k + 17, Blocks.log, 3);
		world.setBlockMetadataWithNotify(i + 2, j + 34, k + 17, 3, 2);
		setBlock(world, i + 2, j + 34, k + 19, Blocks.leaves, 7);
		world.setBlockMetadataWithNotify(i + 2, j + 34, k + 19, 7, 2);
		setBlock(world, i + 2, j + 34, k + 31, Blocks.log, 1);
		world.setBlockMetadataWithNotify(i + 2, j + 34, k + 31, 1, 2);
		setBlock(world, i + 2, j + 38, k + 16, Blocks.leaves, 7);
		world.setBlockMetadataWithNotify(i + 2, j + 38, k + 16, 7, 2);
		setBlock(world, i + 2, j + 38, k + 17, Blocks.leaves, 7);
		world.setBlockMetadataWithNotify(i + 2, j + 38, k + 17, 7, 2);
		setBlock(world, i + 2, j + 38, k + 18, Blocks.leaves, 7);
		world.setBlockMetadataWithNotify(i + 2, j + 38, k + 18, 7, 2);
		setBlock(world, i + 2, j + 38, k + 19, Blocks.leaves, 7);
		world.setBlockMetadataWithNotify(i + 2, j + 38, k + 19, 7, 2);
		setBlock(world, i + 2, j + 38, k + 20, Blocks.leaves, 7);
		world.setBlockMetadataWithNotify(i + 2, j + 38, k + 20, 7, 2);
		setBlock(world, i + 2, j + 39, k + 14, Blocks.leaves, 7);
		world.setBlockMetadataWithNotify(i + 2, j + 39, k + 14, 7, 2);
		setBlock(world, i + 2, j + 39, k + 15, Blocks.leaves, 7);
		world.setBlockMetadataWithNotify(i + 2, j + 39, k + 15, 7, 2);
		setBlock(world, i + 2, j + 39, k + 16, Blocks.log, 3);
		world.setBlockMetadataWithNotify(i + 2, j + 39, k + 16, 3, 2);
		setBlock(world, i + 2, j + 39, k + 17, Blocks.leaves, 7);
		world.setBlockMetadataWithNotify(i + 2, j + 39, k + 17, 7, 2);
		setBlock(world, i + 2, j + 39, k + 18, Blocks.leaves, 7);
		world.setBlockMetadataWithNotify(i + 2, j + 39, k + 18, 7, 2);
		setBlock(world, i + 2, j + 39, k + 19, Blocks.leaves, 7);
		world.setBlockMetadataWithNotify(i + 2, j + 39, k + 19, 7, 2);
		setBlock(world, i + 2, j + 39, k + 24, Blocks.leaves, 7);
		world.setBlockMetadataWithNotify(i + 2, j + 39, k + 24, 7, 2);
		setBlock(world, i + 2, j + 39, k + 25, Blocks.leaves, 7);
		world.setBlockMetadataWithNotify(i + 2, j + 39, k + 25, 7, 2);
		setBlock(world, i + 2, j + 39, k + 26, Blocks.leaves, 7);
		world.setBlockMetadataWithNotify(i + 2, j + 39, k + 26, 7, 2);
		setBlock(world, i + 2, j + 39, k + 27, Blocks.leaves, 7);
		world.setBlockMetadataWithNotify(i + 2, j + 39, k + 27, 7, 2);
		setBlock(world, i + 2, j + 39, k + 28, Blocks.leaves, 7);
		world.setBlockMetadataWithNotify(i + 2, j + 39, k + 28, 7, 2);
		setBlock(world, i + 2, j + 40, k + 14, Blocks.leaves, 7);
		world.setBlockMetadataWithNotify(i + 2, j + 40, k + 14, 7, 2);
		setBlock(world, i + 2, j + 40, k + 15, Blocks.leaves, 7);
		world.setBlockMetadataWithNotify(i + 2, j + 40, k + 15, 7, 2);
		setBlock(world, i + 2, j + 40, k + 16, Blocks.leaves, 7);
		world.setBlockMetadataWithNotify(i + 2, j + 40, k + 16, 7, 2);
		setBlock(world, i + 2, j + 40, k + 17, Blocks.leaves, 7);
		world.setBlockMetadataWithNotify(i + 2, j + 40, k + 17, 7, 2);
		setBlock(world, i + 2, j + 40, k + 18, Blocks.leaves, 7);
		world.setBlockMetadataWithNotify(i + 2, j + 40, k + 18, 7, 2);
		setBlock(world, i + 2, j + 40, k + 25, Blocks.leaves, 7);
		world.setBlockMetadataWithNotify(i + 2, j + 40, k + 25, 7, 2);
		setBlock(world, i + 2, j + 40, k + 26, Blocks.leaves, 7);
		world.setBlockMetadataWithNotify(i + 2, j + 40, k + 26, 7, 2);
		setBlock(world, i + 2, j + 40, k + 27, Blocks.leaves, 7);
		world.setBlockMetadataWithNotify(i + 2, j + 40, k + 27, 7, 2);
		setBlock(world, i + 2, j + 41, k + 15, Blocks.leaves, 7);
		world.setBlockMetadataWithNotify(i + 2, j + 41, k + 15, 7, 2);
		setBlock(world, i + 2, j + 41, k + 16, Blocks.leaves, 7);
		world.setBlockMetadataWithNotify(i + 2, j + 41, k + 16, 7, 2);
		setBlock(world, i + 2, j + 41, k + 17, Blocks.leaves, 7);
		world.setBlockMetadataWithNotify(i + 2, j + 41, k + 17, 7, 2);
		setBlock(world, i + 2, j + 41, k + 26, Blocks.leaves, 7);
		world.setBlockMetadataWithNotify(i + 2, j + 41, k + 26, 7, 2);
		setBlock(world, i + 2, j + 42, k + 16, Blocks.leaves, 7);
		world.setBlockMetadataWithNotify(i + 2, j + 42, k + 16, 7, 2);
		setBlock(world, i + 2, j + 42, k + 20, Blocks.leaves, 7);
		world.setBlockMetadataWithNotify(i + 2, j + 42, k + 20, 7, 2);
		setBlock(world, i + 2, j + 42, k + 21, Blocks.leaves, 7);
		world.setBlockMetadataWithNotify(i + 2, j + 42, k + 21, 7, 2);
		setBlock(world, i + 2, j + 42, k + 22, Blocks.leaves, 7);
		world.setBlockMetadataWithNotify(i + 2, j + 42, k + 22, 7, 2);
		setBlock(world, i + 2, j + 42, k + 23, Blocks.leaves, 7);
		world.setBlockMetadataWithNotify(i + 2, j + 42, k + 23, 7, 2);
		setBlock(world, i + 2, j + 42, k + 24, Blocks.leaves, 7);
		world.setBlockMetadataWithNotify(i + 2, j + 42, k + 24, 7, 2);
		setBlock(world, i + 2, j + 43, k + 21, Blocks.leaves, 7);
		world.setBlockMetadataWithNotify(i + 2, j + 43, k + 21, 7, 2);
		setBlock(world, i + 2, j + 43, k + 22, Blocks.leaves, 7);
		world.setBlockMetadataWithNotify(i + 2, j + 43, k + 22, 7, 2);
		setBlock(world, i + 2, j + 43, k + 23, Blocks.leaves, 7);
		world.setBlockMetadataWithNotify(i + 2, j + 43, k + 23, 7, 2);
		setBlock(world, i + 2, j + 44, k + 22, Blocks.leaves, 7);
		world.setBlockMetadataWithNotify(i + 2, j + 44, k + 22, 7, 2);
		setBlock(world, i + 2, j + 49, k + 25, Blocks.leaves, 7);
		world.setBlockMetadataWithNotify(i + 2, j + 49, k + 25, 7, 2);
		setBlock(world, i + 2, j + 49, k + 26, Blocks.leaves, 7);
		world.setBlockMetadataWithNotify(i + 2, j + 49, k + 26, 7, 2);
		setBlock(world, i + 2, j + 49, k + 27, Blocks.log, 3);
		world.setBlockMetadataWithNotify(i + 2, j + 49, k + 27, 3, 2);
		setBlock(world, i + 2, j + 49, k + 28, Blocks.leaves, 7);
		world.setBlockMetadataWithNotify(i + 2, j + 49, k + 28, 7, 2);
		setBlock(world, i + 2, j + 49, k + 29, Blocks.leaves, 7);
		world.setBlockMetadataWithNotify(i + 2, j + 49, k + 29, 7, 2);
		setBlock(world, i + 2, j + 50, k + 19, Blocks.leaves, 7);
		world.setBlockMetadataWithNotify(i + 2, j + 50, k + 19, 7, 2);
		setBlock(world, i + 2, j + 50, k + 20, Blocks.leaves, 7);
		world.setBlockMetadataWithNotify(i + 2, j + 50, k + 20, 7, 2);
		setBlock(world, i + 2, j + 50, k + 21, Blocks.leaves, 7);
		world.setBlockMetadataWithNotify(i + 2, j + 50, k + 21, 7, 2);
		setBlock(world, i + 2, j + 50, k + 22, Blocks.leaves, 7);
		world.setBlockMetadataWithNotify(i + 2, j + 50, k + 22, 7, 2);
		setBlock(world, i + 2, j + 50, k + 23, Blocks.leaves, 7);
		world.setBlockMetadataWithNotify(i + 2, j + 50, k + 23, 7, 2);
		setBlock(world, i + 2, j + 50, k + 25, Blocks.leaves, 7);
		world.setBlockMetadataWithNotify(i + 2, j + 50, k + 25, 7, 2);
		setBlock(world, i + 2, j + 50, k + 26, Blocks.leaves, 7);
		world.setBlockMetadataWithNotify(i + 2, j + 50, k + 26, 7, 2);
		setBlock(world, i + 2, j + 50, k + 27, Blocks.leaves, 7);
		world.setBlockMetadataWithNotify(i + 2, j + 50, k + 27, 7, 2);
		setBlock(world, i + 2, j + 50, k + 28, Blocks.leaves, 7);
		world.setBlockMetadataWithNotify(i + 2, j + 50, k + 28, 7, 2);
		setBlock(world, i + 2, j + 50, k + 29, Blocks.leaves, 7);
		world.setBlockMetadataWithNotify(i + 2, j + 50, k + 29, 7, 2);
		setBlock(world, i + 2, j + 51, k + 20, Blocks.leaves, 7);
		world.setBlockMetadataWithNotify(i + 2, j + 51, k + 20, 7, 2);
		setBlock(world, i + 2, j + 51, k + 21, Blocks.leaves, 7);
		world.setBlockMetadataWithNotify(i + 2, j + 51, k + 21, 7, 2);
		setBlock(world, i + 2, j + 51, k + 22, Blocks.leaves, 7);
		world.setBlockMetadataWithNotify(i + 2, j + 51, k + 22, 7, 2);
		setBlock(world, i + 2, j + 51, k + 26, Blocks.leaves, 7);
		world.setBlockMetadataWithNotify(i + 2, j + 51, k + 26, 7, 2);
		setBlock(world, i + 2, j + 51, k + 27, Blocks.leaves, 7);
		world.setBlockMetadataWithNotify(i + 2, j + 51, k + 27, 7, 2);
		setBlock(world, i + 2, j + 51, k + 28, Blocks.leaves, 7);
		world.setBlockMetadataWithNotify(i + 2, j + 51, k + 28, 7, 2);
		setBlock(world, i + 2, j + 52, k + 21, Blocks.leaves, 7);
		world.setBlockMetadataWithNotify(i + 2, j + 52, k + 21, 7, 2);
		setBlock(world, i + 2, j + 52, k + 27, Blocks.leaves, 7);
		world.setBlockMetadataWithNotify(i + 2, j + 52, k + 27, 7, 2);
		setBlock(world, i + 3, j + 22, k + 0, Blocks.leaves, 7);
		world.setBlockMetadataWithNotify(i + 3, j + 22, k + 0, 7, 2);
		setBlock(world, i + 3, j + 22, k + 1, Blocks.leaves, 7);
		world.setBlockMetadataWithNotify(i + 3, j + 22, k + 1, 7, 2);
		setBlock(world, i + 3, j + 22, k + 2, Blocks.leaves, 7);
		world.setBlockMetadataWithNotify(i + 3, j + 22, k + 2, 7, 2);
		setBlock(world, i + 3, j + 23, k + 1, Blocks.leaves, 7);
		world.setBlockMetadataWithNotify(i + 3, j + 23, k + 1, 7, 2);
		setBlock(world, i + 3, j + 23, k + 21, Blocks.log, 3);
		world.setBlockMetadataWithNotify(i + 3, j + 23, k + 21, 3, 2);
		setBlock(world, i + 3, j + 24, k + 18, Blocks.log, 3);
		world.setBlockMetadataWithNotify(i + 3, j + 24, k + 18, 3, 2);
		setBlock(world, i + 3, j + 24, k + 20, Blocks.log, 3);
		world.setBlockMetadataWithNotify(i + 3, j + 24, k + 20, 3, 2);
		setBlock(world, i + 3, j + 24, k + 21, Blocks.log, 3);
		world.setBlockMetadataWithNotify(i + 3, j + 24, k + 21, 3, 2);
		setBlock(world, i + 3, j + 24, k + 22, Blocks.log, 3);
		world.setBlockMetadataWithNotify(i + 3, j + 24, k + 22, 3, 2);
		setBlock(world, i + 3, j + 25, k + 21, Blocks.log, 3);
		world.setBlockMetadataWithNotify(i + 3, j + 25, k + 21, 3, 2);
		setBlock(world, i + 3, j + 26, k + 31, Blocks.log, 1);
		world.setBlockMetadataWithNotify(i + 3, j + 26, k + 31, 1, 2);
		setBlock(world, i + 3, j + 27, k + 24, Blocks.log, 3);
		world.setBlockMetadataWithNotify(i + 3, j + 27, k + 24, 3, 2);
		setBlock(world, i + 3, j + 27, k + 30, Blocks.spruce_stairs, 6);
		world.setBlockMetadataWithNotify(i + 3, j + 27, k + 30, 6, 2);
		setBlock(world, i + 3, j + 27, k + 31, Blocks.log, 1);
		world.setBlockMetadataWithNotify(i + 3, j + 27, k + 31, 1, 2);
		setBlock(world, i + 3, j + 28, k + 29, Blocks.spruce_stairs, 6);
		world.setBlockMetadataWithNotify(i + 3, j + 28, k + 29, 6, 2);
		setBlock(world, i + 3, j + 28, k + 30, Blocks.log, 1);
		world.setBlockMetadataWithNotify(i + 3, j + 28, k + 30, 1, 2);
		setBlock(world, i + 3, j + 28, k + 31, Blocks.log, 1);
		world.setBlockMetadataWithNotify(i + 3, j + 28, k + 31, 1, 2);
		setBlock(world, i + 3, j + 29, k + 13, Blocks.leaves, 7);
		world.setBlockMetadataWithNotify(i + 3, j + 29, k + 13, 7, 2);
		setBlock(world, i + 3, j + 29, k + 14, Blocks.leaves, 7);
		world.setBlockMetadataWithNotify(i + 3, j + 29, k + 14, 7, 2);
		setBlock(world, i + 3, j + 29, k + 15, Blocks.log, 3);
		world.setBlockMetadataWithNotify(i + 3, j + 29, k + 15, 3, 2);
		setBlock(world, i + 3, j + 29, k + 16, Blocks.leaves, 7);
		world.setBlockMetadataWithNotify(i + 3, j + 29, k + 16, 7, 2);
		setBlock(world, i + 3, j + 29, k + 17, Blocks.leaves, 7);
		world.setBlockMetadataWithNotify(i + 3, j + 29, k + 17, 7, 2);
		setBlock(world, i + 3, j + 29, k + 29, Blocks.log, 1);
		world.setBlockMetadataWithNotify(i + 3, j + 29, k + 29, 1, 2);
		setBlock(world, i + 3, j + 29, k + 30, Blocks.log, 1);
		world.setBlockMetadataWithNotify(i + 3, j + 29, k + 30, 1, 2);
		setBlock(world, i + 3, j + 30, k + 13, Blocks.leaves, 7);
		world.setBlockMetadataWithNotify(i + 3, j + 30, k + 13, 7, 2);
		setBlock(world, i + 3, j + 30, k + 14, Blocks.log, 3);
		world.setBlockMetadataWithNotify(i + 3, j + 30, k + 14, 3, 2);
		setBlock(world, i + 3, j + 30, k + 15, Blocks.leaves, 7);
		world.setBlockMetadataWithNotify(i + 3, j + 30, k + 15, 7, 2);
		setBlock(world, i + 3, j + 30, k + 16, Blocks.leaves, 7);
		world.setBlockMetadataWithNotify(i + 3, j + 30, k + 16, 7, 2);
		setBlock(world, i + 3, j + 30, k + 17, Blocks.leaves, 7);
		world.setBlockMetadataWithNotify(i + 3, j + 30, k + 17, 7, 2);
		setBlock(world, i + 3, j + 30, k + 28, Blocks.log, 1);
		world.setBlockMetadataWithNotify(i + 3, j + 30, k + 28, 1, 2);
		setBlock(world, i + 3, j + 30, k + 29, Blocks.log, 1);
		world.setBlockMetadataWithNotify(i + 3, j + 30, k + 29, 1, 2);
		setBlock(world, i + 3, j + 30, k + 30, Blocks.log, 1);
		world.setBlockMetadataWithNotify(i + 3, j + 30, k + 30, 1, 2);
		setBlock(world, i + 3, j + 30, k + 31, Blocks.log, 1);
		world.setBlockMetadataWithNotify(i + 3, j + 30, k + 31, 1, 2);
		setBlock(world, i + 3, j + 31, k + 11, Blocks.leaves, 7);
		world.setBlockMetadataWithNotify(i + 3, j + 31, k + 11, 7, 2);
		setBlock(world, i + 3, j + 31, k + 12, Blocks.leaves, 7);
		world.setBlockMetadataWithNotify(i + 3, j + 31, k + 12, 7, 2);
		setBlock(world, i + 3, j + 31, k + 13, Blocks.leaves, 7);
		world.setBlockMetadataWithNotify(i + 3, j + 31, k + 13, 7, 2);
		setBlock(world, i + 3, j + 31, k + 14, Blocks.leaves, 7);
		world.setBlockMetadataWithNotify(i + 3, j + 31, k + 14, 7, 2);
		setBlock(world, i + 3, j + 31, k + 15, Blocks.leaves, 7);
		world.setBlockMetadataWithNotify(i + 3, j + 31, k + 15, 7, 2);
		setBlock(world, i + 3, j + 31, k + 16, Blocks.leaves, 7);
		world.setBlockMetadataWithNotify(i + 3, j + 31, k + 16, 7, 2);
		setBlock(world, i + 3, j + 31, k + 29, Blocks.log, 1);
		world.setBlockMetadataWithNotify(i + 3, j + 31, k + 29, 1, 2);
		setBlock(world, i + 3, j + 31, k + 30, Blocks.log, 1);
		world.setBlockMetadataWithNotify(i + 3, j + 31, k + 30, 1, 2);
		setBlock(world, i + 3, j + 31, k + 31, Blocks.log, 1);
		world.setBlockMetadataWithNotify(i + 3, j + 31, k + 31, 1, 2);
		setBlock(world, i + 3, j + 32, k + 12, Blocks.leaves, 7);
		world.setBlockMetadataWithNotify(i + 3, j + 32, k + 12, 7, 2);
		setBlock(world, i + 3, j + 32, k + 13, Blocks.leaves, 7);
		world.setBlockMetadataWithNotify(i + 3, j + 32, k + 13, 7, 2);
		setBlock(world, i + 3, j + 32, k + 14, Blocks.leaves, 7);
		world.setBlockMetadataWithNotify(i + 3, j + 32, k + 14, 7, 2);
		setBlock(world, i + 3, j + 32, k + 15, Blocks.leaves, 7);
		world.setBlockMetadataWithNotify(i + 3, j + 32, k + 15, 7, 2);
		setBlock(world, i + 3, j + 32, k + 17, Blocks.leaves, 7);
		world.setBlockMetadataWithNotify(i + 3, j + 32, k + 17, 7, 2);
		setBlock(world, i + 3, j + 32, k + 18, Blocks.leaves, 7);
		world.setBlockMetadataWithNotify(i + 3, j + 32, k + 18, 7, 2);
		setBlock(world, i + 3, j + 32, k + 19, Blocks.log, 3);
		world.setBlockMetadataWithNotify(i + 3, j + 32, k + 19, 3, 2);
		setBlock(world, i + 3, j + 32, k + 20, Blocks.leaves, 7);
		world.setBlockMetadataWithNotify(i + 3, j + 32, k + 20, 7, 2);
		setBlock(world, i + 3, j + 32, k + 21, Blocks.leaves, 7);
		world.setBlockMetadataWithNotify(i + 3, j + 32, k + 21, 7, 2);
		setBlock(world, i + 3, j + 32, k + 29, Blocks.log, 1);
		world.setBlockMetadataWithNotify(i + 3, j + 32, k + 29, 1, 2);
		setBlock(world, i + 3, j + 32, k + 30, Blocks.log, 1);
		world.setBlockMetadataWithNotify(i + 3, j + 32, k + 30, 1, 2);
		setBlock(world, i + 3, j + 32, k + 31, Blocks.log, 1);
		world.setBlockMetadataWithNotify(i + 3, j + 32, k + 31, 1, 2);
		setBlock(world, i + 3, j + 33, k + 13, Blocks.leaves, 7);
		world.setBlockMetadataWithNotify(i + 3, j + 33, k + 13, 7, 2);
		setBlock(world, i + 3, j + 33, k + 17, Blocks.leaves, 7);
		world.setBlockMetadataWithNotify(i + 3, j + 33, k + 17, 7, 2);
		setBlock(world, i + 3, j + 33, k + 18, Blocks.leaves, 7);
		world.setBlockMetadataWithNotify(i + 3, j + 33, k + 18, 7, 2);
		setBlock(world, i + 3, j + 33, k + 19, Blocks.leaves, 7);
		world.setBlockMetadataWithNotify(i + 3, j + 33, k + 19, 7, 2);
		setBlock(world, i + 3, j + 33, k + 20, Blocks.leaves, 7);
		world.setBlockMetadataWithNotify(i + 3, j + 33, k + 20, 7, 2);
		setBlock(world, i + 3, j + 33, k + 21, Blocks.leaves, 7);
		world.setBlockMetadataWithNotify(i + 3, j + 33, k + 21, 7, 2);
		setBlock(world, i + 3, j + 33, k + 30, Blocks.log, 1);
		world.setBlockMetadataWithNotify(i + 3, j + 33, k + 30, 1, 2);
		setBlock(world, i + 3, j + 33, k + 31, Blocks.log, 1);
		world.setBlockMetadataWithNotify(i + 3, j + 33, k + 31, 1, 2);
		setBlock(world, i + 3, j + 34, k + 17, Blocks.log, 3);
		world.setBlockMetadataWithNotify(i + 3, j + 34, k + 17, 3, 2);
		setBlock(world, i + 3, j + 34, k + 18, Blocks.leaves, 7);
		world.setBlockMetadataWithNotify(i + 3, j + 34, k + 18, 7, 2);
		setBlock(world, i + 3, j + 34, k + 19, Blocks.leaves, 7);
		world.setBlockMetadataWithNotify(i + 3, j + 34, k + 19, 7, 2);
		setBlock(world, i + 3, j + 34, k + 20, Blocks.leaves, 7);
		world.setBlockMetadataWithNotify(i + 3, j + 34, k + 20, 7, 2);
		setBlock(world, i + 3, j + 34, k + 31, Blocks.log, 1);
		world.setBlockMetadataWithNotify(i + 3, j + 34, k + 31, 1, 2);
		setBlock(world, i + 3, j + 35, k + 19, Blocks.leaves, 7);
		world.setBlockMetadataWithNotify(i + 3, j + 35, k + 19, 7, 2);
		setBlock(world, i + 3, j + 38, k + 17, Blocks.leaves, 7);
		world.setBlockMetadataWithNotify(i + 3, j + 38, k + 17, 7, 2);
		setBlock(world, i + 3, j + 38, k + 18, Blocks.leaves, 7);
		world.setBlockMetadataWithNotify(i + 3, j + 38, k + 18, 7, 2);
		setBlock(world, i + 3, j + 38, k + 19, Blocks.leaves, 7);
		world.setBlockMetadataWithNotify(i + 3, j + 38, k + 19, 7, 2);
		setBlock(world, i + 3, j + 39, k + 14, Blocks.leaves, 7);
		world.setBlockMetadataWithNotify(i + 3, j + 39, k + 14, 7, 2);
		setBlock(world, i + 3, j + 39, k + 15, Blocks.leaves, 7);
		world.setBlockMetadataWithNotify(i + 3, j + 39, k + 15, 7, 2);
		setBlock(world, i + 3, j + 39, k + 16, Blocks.leaves, 7);
		world.setBlockMetadataWithNotify(i + 3, j + 39, k + 16, 7, 2);
		setBlock(world, i + 3, j + 39, k + 17, Blocks.leaves, 7);
		world.setBlockMetadataWithNotify(i + 3, j + 39, k + 17, 7, 2);
		setBlock(world, i + 3, j + 39, k + 18, Blocks.leaves, 7);
		world.setBlockMetadataWithNotify(i + 3, j + 39, k + 18, 7, 2);
		setBlock(world, i + 3, j + 39, k + 25, Blocks.leaves, 7);
		world.setBlockMetadataWithNotify(i + 3, j + 39, k + 25, 7, 2);
		setBlock(world, i + 3, j + 39, k + 26, Blocks.leaves, 7);
		world.setBlockMetadataWithNotify(i + 3, j + 39, k + 26, 7, 2);
		setBlock(world, i + 3, j + 39, k + 27, Blocks.leaves, 7);
		world.setBlockMetadataWithNotify(i + 3, j + 39, k + 27, 7, 2);
		setBlock(world, i + 3, j + 40, k + 15, Blocks.leaves, 7);
		world.setBlockMetadataWithNotify(i + 3, j + 40, k + 15, 7, 2);
		setBlock(world, i + 3, j + 40, k + 16, Blocks.leaves, 7);
		world.setBlockMetadataWithNotify(i + 3, j + 40, k + 16, 7, 2);
		setBlock(world, i + 3, j + 40, k + 17, Blocks.leaves, 7);
		world.setBlockMetadataWithNotify(i + 3, j + 40, k + 17, 7, 2);
		setBlock(world, i + 3, j + 40, k + 26, Blocks.leaves, 7);
		world.setBlockMetadataWithNotify(i + 3, j + 40, k + 26, 7, 2);
		setBlock(world, i + 3, j + 41, k + 16, Blocks.leaves, 7);
		world.setBlockMetadataWithNotify(i + 3, j + 41, k + 16, 7, 2);
		setBlock(world, i + 3, j + 42, k + 21, Blocks.leaves, 7);
		world.setBlockMetadataWithNotify(i + 3, j + 42, k + 21, 7, 2);
		setBlock(world, i + 3, j + 42, k + 22, Blocks.leaves, 7);
		world.setBlockMetadataWithNotify(i + 3, j + 42, k + 22, 7, 2);
		setBlock(world, i + 3, j + 42, k + 23, Blocks.leaves, 7);
		world.setBlockMetadataWithNotify(i + 3, j + 42, k + 23, 7, 2);
		setBlock(world, i + 3, j + 43, k + 22, Blocks.leaves, 7);
		world.setBlockMetadataWithNotify(i + 3, j + 43, k + 22, 7, 2);
		setBlock(world, i + 3, j + 49, k + 25, Blocks.leaves, 7);
		world.setBlockMetadataWithNotify(i + 3, j + 49, k + 25, 7, 2);
		setBlock(world, i + 3, j + 49, k + 26, Blocks.leaves, 7);
		world.setBlockMetadataWithNotify(i + 3, j + 49, k + 26, 7, 2);
		setBlock(world, i + 3, j + 49, k + 27, Blocks.leaves, 7);
		world.setBlockMetadataWithNotify(i + 3, j + 49, k + 27, 7, 2);
		setBlock(world, i + 3, j + 49, k + 28, Blocks.leaves, 7);
		world.setBlockMetadataWithNotify(i + 3, j + 49, k + 28, 7, 2);
		setBlock(world, i + 3, j + 49, k + 29, Blocks.leaves, 7);
		world.setBlockMetadataWithNotify(i + 3, j + 49, k + 29, 7, 2);
		setBlock(world, i + 3, j + 50, k + 20, Blocks.leaves, 7);
		world.setBlockMetadataWithNotify(i + 3, j + 50, k + 20, 7, 2);
		setBlock(world, i + 3, j + 50, k + 21, Blocks.leaves, 7);
		world.setBlockMetadataWithNotify(i + 3, j + 50, k + 21, 7, 2);
		setBlock(world, i + 3, j + 50, k + 22, Blocks.leaves, 7);
		world.setBlockMetadataWithNotify(i + 3, j + 50, k + 22, 7, 2);
		setBlock(world, i + 3, j + 50, k + 26, Blocks.leaves, 7);
		world.setBlockMetadataWithNotify(i + 3, j + 50, k + 26, 7, 2);
		setBlock(world, i + 3, j + 50, k + 27, Blocks.leaves, 7);
		world.setBlockMetadataWithNotify(i + 3, j + 50, k + 27, 7, 2);
		setBlock(world, i + 3, j + 50, k + 28, Blocks.leaves, 7);
		world.setBlockMetadataWithNotify(i + 3, j + 50, k + 28, 7, 2);
		setBlock(world, i + 3, j + 51, k + 21, Blocks.leaves, 7);
		world.setBlockMetadataWithNotify(i + 3, j + 51, k + 21, 7, 2);
		setBlock(world, i + 3, j + 51, k + 27, Blocks.leaves, 7);
		world.setBlockMetadataWithNotify(i + 3, j + 51, k + 27, 7, 2);
		setBlock(world, i + 4, j + 24, k + 18, Blocks.log, 3);
		world.setBlockMetadataWithNotify(i + 4, j + 24, k + 18, 3, 2);
		setBlock(world, i + 4, j + 24, k + 21, Blocks.log, 3);
		world.setBlockMetadataWithNotify(i + 4, j + 24, k + 21, 3, 2);
		setBlock(world, i + 4, j + 27, k + 23, Blocks.log, 3);
		world.setBlockMetadataWithNotify(i + 4, j + 27, k + 23, 3, 2);
		setBlock(world, i + 4, j + 27, k + 31, Blocks.spruce_stairs, 1);
		world.setBlockMetadataWithNotify(i + 4, j + 27, k + 31, 1, 2);
		setBlock(world, i + 4, j + 29, k + 13, Blocks.leaves, 7);
		world.setBlockMetadataWithNotify(i + 4, j + 29, k + 13, 7, 2);
		setBlock(world, i + 4, j + 29, k + 14, Blocks.leaves, 7);
		world.setBlockMetadataWithNotify(i + 4, j + 29, k + 14, 7, 2);
		setBlock(world, i + 4, j + 29, k + 15, Blocks.leaves, 7);
		world.setBlockMetadataWithNotify(i + 4, j + 29, k + 15, 7, 2);
		setBlock(world, i + 4, j + 29, k + 16, Blocks.leaves, 7);
		world.setBlockMetadataWithNotify(i + 4, j + 29, k + 16, 7, 2);
		setBlock(world, i + 4, j + 29, k + 17, Blocks.leaves, 7);
		world.setBlockMetadataWithNotify(i + 4, j + 29, k + 17, 7, 2);
		setBlock(world, i + 4, j + 30, k + 14, Blocks.leaves, 7);
		world.setBlockMetadataWithNotify(i + 4, j + 30, k + 14, 7, 2);
		setBlock(world, i + 4, j + 30, k + 15, Blocks.leaves, 7);
		world.setBlockMetadataWithNotify(i + 4, j + 30, k + 15, 7, 2);
		setBlock(world, i + 4, j + 30, k + 16, Blocks.leaves, 7);
		world.setBlockMetadataWithNotify(i + 4, j + 30, k + 16, 7, 2);
		setBlock(world, i + 4, j + 30, k + 28, Blocks.log, 1);
		world.setBlockMetadataWithNotify(i + 4, j + 30, k + 28, 1, 2);
		setBlock(world, i + 4, j + 30, k + 29, Blocks.log, 1);
		world.setBlockMetadataWithNotify(i + 4, j + 30, k + 29, 1, 2);
		setBlock(world, i + 4, j + 30, k + 30, Blocks.log, 1);
		world.setBlockMetadataWithNotify(i + 4, j + 30, k + 30, 1, 2);
		setBlock(world, i + 4, j + 30, k + 31, Blocks.log, 1);
		world.setBlockMetadataWithNotify(i + 4, j + 30, k + 31, 1, 2);
		setBlock(world, i + 4, j + 31, k + 11, Blocks.leaves, 7);
		world.setBlockMetadataWithNotify(i + 4, j + 31, k + 11, 7, 2);
		setBlock(world, i + 4, j + 31, k + 12, Blocks.leaves, 7);
		world.setBlockMetadataWithNotify(i + 4, j + 31, k + 12, 7, 2);
		setBlock(world, i + 4, j + 31, k + 13, Blocks.log, 3);
		world.setBlockMetadataWithNotify(i + 4, j + 31, k + 13, 3, 2);
		setBlock(world, i + 4, j + 31, k + 14, Blocks.leaves, 7);
		world.setBlockMetadataWithNotify(i + 4, j + 31, k + 14, 7, 2);
		setBlock(world, i + 4, j + 31, k + 15, Blocks.leaves, 7);
		world.setBlockMetadataWithNotify(i + 4, j + 31, k + 15, 7, 2);
		setBlock(world, i + 4, j + 31, k + 30, Blocks.log, 1);
		world.setBlockMetadataWithNotify(i + 4, j + 31, k + 30, 1, 2);
		setBlock(world, i + 4, j + 31, k + 31, Blocks.log, 1);
		world.setBlockMetadataWithNotify(i + 4, j + 31, k + 31, 1, 2);
		setBlock(world, i + 4, j + 32, k + 11, Blocks.leaves, 7);
		world.setBlockMetadataWithNotify(i + 4, j + 32, k + 11, 7, 2);
		setBlock(world, i + 4, j + 32, k + 12, Blocks.leaves, 7);
		world.setBlockMetadataWithNotify(i + 4, j + 32, k + 12, 7, 2);
		setBlock(world, i + 4, j + 32, k + 13, Blocks.leaves, 7);
		world.setBlockMetadataWithNotify(i + 4, j + 32, k + 13, 7, 2);
		setBlock(world, i + 4, j + 32, k + 14, Blocks.leaves, 7);
		world.setBlockMetadataWithNotify(i + 4, j + 32, k + 14, 7, 2);
		setBlock(world, i + 4, j + 32, k + 15, Blocks.leaves, 7);
		world.setBlockMetadataWithNotify(i + 4, j + 32, k + 15, 7, 2);
		setBlock(world, i + 4, j + 32, k + 17, Blocks.leaves, 7);
		world.setBlockMetadataWithNotify(i + 4, j + 32, k + 17, 7, 2);
		setBlock(world, i + 4, j + 32, k + 18, Blocks.leaves, 7);
		world.setBlockMetadataWithNotify(i + 4, j + 32, k + 18, 7, 2);
		setBlock(world, i + 4, j + 32, k + 19, Blocks.leaves, 7);
		world.setBlockMetadataWithNotify(i + 4, j + 32, k + 19, 7, 2);
		setBlock(world, i + 4, j + 32, k + 20, Blocks.leaves, 7);
		world.setBlockMetadataWithNotify(i + 4, j + 32, k + 20, 7, 2);
		setBlock(world, i + 4, j + 32, k + 21, Blocks.leaves, 7);
		world.setBlockMetadataWithNotify(i + 4, j + 32, k + 21, 7, 2);
		setBlock(world, i + 4, j + 32, k + 29, Blocks.log, 3);
		world.setBlockMetadataWithNotify(i + 4, j + 32, k + 29, 3, 2);
		setBlock(world, i + 4, j + 32, k + 30, Blocks.log, 1);
		world.setBlockMetadataWithNotify(i + 4, j + 32, k + 30, 1, 2);
		setBlock(world, i + 4, j + 32, k + 31, Blocks.log, 1);
		world.setBlockMetadataWithNotify(i + 4, j + 32, k + 31, 1, 2);
		setBlock(world, i + 4, j + 33, k + 12, Blocks.leaves, 7);
		world.setBlockMetadataWithNotify(i + 4, j + 33, k + 12, 7, 2);
		setBlock(world, i + 4, j + 33, k + 13, Blocks.leaves, 7);
		world.setBlockMetadataWithNotify(i + 4, j + 33, k + 13, 7, 2);
		setBlock(world, i + 4, j + 33, k + 14, Blocks.leaves, 7);
		world.setBlockMetadataWithNotify(i + 4, j + 33, k + 14, 7, 2);
		setBlock(world, i + 4, j + 33, k + 18, Blocks.leaves, 7);
		world.setBlockMetadataWithNotify(i + 4, j + 33, k + 18, 7, 2);
		setBlock(world, i + 4, j + 33, k + 19, Blocks.leaves, 7);
		world.setBlockMetadataWithNotify(i + 4, j + 33, k + 19, 7, 2);
		setBlock(world, i + 4, j + 33, k + 20, Blocks.leaves, 7);
		world.setBlockMetadataWithNotify(i + 4, j + 33, k + 20, 7, 2);
		setBlock(world, i + 4, j + 33, k + 31, Blocks.log, 1);
		world.setBlockMetadataWithNotify(i + 4, j + 33, k + 31, 1, 2);
		setBlock(world, i + 4, j + 34, k + 13, Blocks.leaves, 7);
		world.setBlockMetadataWithNotify(i + 4, j + 34, k + 13, 7, 2);
		setBlock(world, i + 4, j + 34, k + 19, Blocks.leaves, 7);
		world.setBlockMetadataWithNotify(i + 4, j + 34, k + 19, 7, 2);
		setBlock(world, i + 4, j + 35, k + 16, Blocks.log, 3);
		world.setBlockMetadataWithNotify(i + 4, j + 35, k + 16, 3, 2);
		setBlock(world, i + 4, j + 39, k + 15, Blocks.leaves, 7);
		world.setBlockMetadataWithNotify(i + 4, j + 39, k + 15, 7, 2);
		setBlock(world, i + 4, j + 39, k + 16, Blocks.leaves, 7);
		world.setBlockMetadataWithNotify(i + 4, j + 39, k + 16, 7, 2);
		setBlock(world, i + 4, j + 39, k + 17, Blocks.leaves, 7);
		world.setBlockMetadataWithNotify(i + 4, j + 39, k + 17, 7, 2);
		setBlock(world, i + 4, j + 40, k + 16, Blocks.leaves, 7);
		world.setBlockMetadataWithNotify(i + 4, j + 40, k + 16, 7, 2);
		setBlock(world, i + 4, j + 45, k + 22, Blocks.leaves, 7);
		world.setBlockMetadataWithNotify(i + 4, j + 45, k + 22, 7, 2);
		setBlock(world, i + 4, j + 45, k + 23, Blocks.leaves, 7);
		world.setBlockMetadataWithNotify(i + 4, j + 45, k + 23, 7, 2);
		setBlock(world, i + 4, j + 45, k + 24, Blocks.leaves, 7);
		world.setBlockMetadataWithNotify(i + 4, j + 45, k + 24, 7, 2);
		setBlock(world, i + 4, j + 46, k + 23, Blocks.leaves, 7);
		world.setBlockMetadataWithNotify(i + 4, j + 46, k + 23, 7, 2);
		setBlock(world, i + 4, j + 49, k + 26, Blocks.leaves, 7);
		world.setBlockMetadataWithNotify(i + 4, j + 49, k + 26, 7, 2);
		setBlock(world, i + 4, j + 49, k + 27, Blocks.leaves, 7);
		world.setBlockMetadataWithNotify(i + 4, j + 49, k + 27, 7, 2);
		setBlock(world, i + 4, j + 49, k + 28, Blocks.leaves, 7);
		world.setBlockMetadataWithNotify(i + 4, j + 49, k + 28, 7, 2);
		setBlock(world, i + 4, j + 50, k + 27, Blocks.leaves, 7);
		world.setBlockMetadataWithNotify(i + 4, j + 50, k + 27, 7, 2);
		setBlock(world, i + 5, j + 24, k + 21, Blocks.log, 3);
		world.setBlockMetadataWithNotify(i + 5, j + 24, k + 21, 3, 2);
		setBlock(world, i + 5, j + 25, k + 17, Blocks.log, 3);
		world.setBlockMetadataWithNotify(i + 5, j + 25, k + 17, 3, 2);
		setBlock(world, i + 5, j + 27, k + 23, Blocks.log, 3);
		world.setBlockMetadataWithNotify(i + 5, j + 27, k + 23, 3, 2);
		setBlock(world, i + 5, j + 28, k + 21, Blocks.leaves, 7);
		world.setBlockMetadataWithNotify(i + 5, j + 28, k + 21, 7, 2);
		setBlock(world, i + 5, j + 28, k + 22, Blocks.leaves, 7);
		world.setBlockMetadataWithNotify(i + 5, j + 28, k + 22, 7, 2);
		setBlock(world, i + 5, j + 28, k + 23, Blocks.leaves, 7);
		world.setBlockMetadataWithNotify(i + 5, j + 28, k + 23, 7, 2);
		setBlock(world, i + 5, j + 29, k + 14, Blocks.leaves, 7);
		world.setBlockMetadataWithNotify(i + 5, j + 29, k + 14, 7, 2);
		setBlock(world, i + 5, j + 29, k + 15, Blocks.leaves, 7);
		world.setBlockMetadataWithNotify(i + 5, j + 29, k + 15, 7, 2);
		setBlock(world, i + 5, j + 29, k + 16, Blocks.leaves, 7);
		world.setBlockMetadataWithNotify(i + 5, j + 29, k + 16, 7, 2);
		setBlock(world, i + 5, j + 29, k + 22, Blocks.leaves, 7);
		world.setBlockMetadataWithNotify(i + 5, j + 29, k + 22, 7, 2);
		setBlock(world, i + 5, j + 30, k + 15, Blocks.leaves, 7);
		world.setBlockMetadataWithNotify(i + 5, j + 30, k + 15, 7, 2);
		setBlock(world, i + 5, j + 30, k + 29, Blocks.log, 1);
		world.setBlockMetadataWithNotify(i + 5, j + 30, k + 29, 1, 2);
		setBlock(world, i + 5, j + 30, k + 30, Blocks.log, 1);
		world.setBlockMetadataWithNotify(i + 5, j + 30, k + 30, 1, 2);
		setBlock(world, i + 5, j + 30, k + 31, Blocks.log, 1);
		world.setBlockMetadataWithNotify(i + 5, j + 30, k + 31, 1, 2);
		setBlock(world, i + 5, j + 31, k + 11, Blocks.leaves, 7);
		world.setBlockMetadataWithNotify(i + 5, j + 31, k + 11, 7, 2);
		setBlock(world, i + 5, j + 31, k + 12, Blocks.leaves, 7);
		world.setBlockMetadataWithNotify(i + 5, j + 31, k + 12, 7, 2);
		setBlock(world, i + 5, j + 31, k + 13, Blocks.leaves, 7);
		world.setBlockMetadataWithNotify(i + 5, j + 31, k + 13, 7, 2);
		setBlock(world, i + 5, j + 31, k + 14, Blocks.leaves, 7);
		world.setBlockMetadataWithNotify(i + 5, j + 31, k + 14, 7, 2);
		setBlock(world, i + 5, j + 31, k + 15, Blocks.leaves, 7);
		world.setBlockMetadataWithNotify(i + 5, j + 31, k + 15, 7, 2);
		setBlock(world, i + 5, j + 31, k + 30, Blocks.log, 1);
		world.setBlockMetadataWithNotify(i + 5, j + 31, k + 30, 1, 2);
		setBlock(world, i + 5, j + 31, k + 31, Blocks.log, 1);
		world.setBlockMetadataWithNotify(i + 5, j + 31, k + 31, 1, 2);
		setBlock(world, i + 5, j + 32, k + 12, Blocks.leaves, 7);
		world.setBlockMetadataWithNotify(i + 5, j + 32, k + 12, 7, 2);
		setBlock(world, i + 5, j + 32, k + 13, Blocks.leaves, 7);
		world.setBlockMetadataWithNotify(i + 5, j + 32, k + 13, 7, 2);
		setBlock(world, i + 5, j + 32, k + 14, Blocks.leaves, 7);
		world.setBlockMetadataWithNotify(i + 5, j + 32, k + 14, 7, 2);
		setBlock(world, i + 5, j + 32, k + 18, Blocks.leaves, 7);
		world.setBlockMetadataWithNotify(i + 5, j + 32, k + 18, 7, 2);
		setBlock(world, i + 5, j + 32, k + 19, Blocks.leaves, 7);
		world.setBlockMetadataWithNotify(i + 5, j + 32, k + 19, 7, 2);
		setBlock(world, i + 5, j + 32, k + 20, Blocks.leaves, 7);
		world.setBlockMetadataWithNotify(i + 5, j + 32, k + 20, 7, 2);
		setBlock(world, i + 5, j + 32, k + 30, Blocks.log, 1);
		world.setBlockMetadataWithNotify(i + 5, j + 32, k + 30, 1, 2);
		setBlock(world, i + 5, j + 32, k + 31, Blocks.log, 1);
		world.setBlockMetadataWithNotify(i + 5, j + 32, k + 31, 1, 2);
		setBlock(world, i + 5, j + 33, k + 13, Blocks.leaves, 7);
		world.setBlockMetadataWithNotify(i + 5, j + 33, k + 13, 7, 2);
		setBlock(world, i + 5, j + 33, k + 19, Blocks.leaves, 7);
		world.setBlockMetadataWithNotify(i + 5, j + 33, k + 19, 7, 2);
		setBlock(world, i + 5, j + 33, k + 31, Blocks.log, 1);
		world.setBlockMetadataWithNotify(i + 5, j + 33, k + 31, 1, 2);
		setBlock(world, i + 5, j + 35, k + 15, Blocks.log, 3);
		world.setBlockMetadataWithNotify(i + 5, j + 35, k + 15, 3, 2);
		setBlock(world, i + 5, j + 36, k + 12, Blocks.leaves, 7);
		world.setBlockMetadataWithNotify(i + 5, j + 36, k + 12, 7, 2);
		setBlock(world, i + 5, j + 36, k + 13, Blocks.leaves, 7);
		world.setBlockMetadataWithNotify(i + 5, j + 36, k + 13, 7, 2);
		setBlock(world, i + 5, j + 36, k + 14, Blocks.leaves, 7);
		world.setBlockMetadataWithNotify(i + 5, j + 36, k + 14, 7, 2);
		setBlock(world, i + 5, j + 37, k + 13, Blocks.leaves, 7);
		world.setBlockMetadataWithNotify(i + 5, j + 37, k + 13, 7, 2);
		setBlock(world, i + 5, j + 45, k + 21, Blocks.leaves, 7);
		world.setBlockMetadataWithNotify(i + 5, j + 45, k + 21, 7, 2);
		setBlock(world, i + 5, j + 45, k + 22, Blocks.leaves, 7);
		world.setBlockMetadataWithNotify(i + 5, j + 45, k + 22, 7, 2);
		setBlock(world, i + 5, j + 45, k + 23, Blocks.leaves, 7);
		world.setBlockMetadataWithNotify(i + 5, j + 45, k + 23, 7, 2);
		setBlock(world, i + 5, j + 45, k + 24, Blocks.leaves, 7);
		world.setBlockMetadataWithNotify(i + 5, j + 45, k + 24, 7, 2);
		setBlock(world, i + 5, j + 45, k + 25, Blocks.leaves, 7);
		world.setBlockMetadataWithNotify(i + 5, j + 45, k + 25, 7, 2);
		setBlock(world, i + 5, j + 46, k + 22, Blocks.leaves, 7);
		world.setBlockMetadataWithNotify(i + 5, j + 46, k + 22, 7, 2);
		setBlock(world, i + 5, j + 46, k + 23, Blocks.leaves, 7);
		world.setBlockMetadataWithNotify(i + 5, j + 46, k + 23, 7, 2);
		setBlock(world, i + 5, j + 46, k + 24, Blocks.leaves, 7);
		world.setBlockMetadataWithNotify(i + 5, j + 46, k + 24, 7, 2);
		setBlock(world, i + 5, j + 47, k + 23, Blocks.leaves, 7);
		world.setBlockMetadataWithNotify(i + 5, j + 47, k + 23, 7, 2);
		setBlock(world, i + 6, j + 25, k + 17, Blocks.log, 3);
		world.setBlockMetadataWithNotify(i + 6, j + 25, k + 17, 3, 2);
		setBlock(world, i + 6, j + 25, k + 20, Blocks.log, 3);
		world.setBlockMetadataWithNotify(i + 6, j + 25, k + 20, 3, 2);
		setBlock(world, i + 6, j + 27, k + 23, Blocks.log, 3);
		world.setBlockMetadataWithNotify(i + 6, j + 27, k + 23, 3, 2);
		setBlock(world, i + 6, j + 28, k + 20, Blocks.leaves, 7);
		world.setBlockMetadataWithNotify(i + 6, j + 28, k + 20, 7, 2);
		setBlock(world, i + 6, j + 28, k + 21, Blocks.leaves, 7);
		world.setBlockMetadataWithNotify(i + 6, j + 28, k + 21, 7, 2);
		setBlock(world, i + 6, j + 28, k + 22, Blocks.leaves, 7);
		world.setBlockMetadataWithNotify(i + 6, j + 28, k + 22, 7, 2);
		setBlock(world, i + 6, j + 28, k + 23, Blocks.leaves, 7);
		world.setBlockMetadataWithNotify(i + 6, j + 28, k + 23, 7, 2);
		setBlock(world, i + 6, j + 28, k + 24, Blocks.leaves, 7);
		world.setBlockMetadataWithNotify(i + 6, j + 28, k + 24, 7, 2);
		setBlock(world, i + 6, j + 29, k + 21, Blocks.leaves, 7);
		world.setBlockMetadataWithNotify(i + 6, j + 29, k + 21, 7, 2);
		setBlock(world, i + 6, j + 29, k + 22, Blocks.leaves, 7);
		world.setBlockMetadataWithNotify(i + 6, j + 29, k + 22, 7, 2);
		setBlock(world, i + 6, j + 29, k + 23, Blocks.leaves, 7);
		world.setBlockMetadataWithNotify(i + 6, j + 29, k + 23, 7, 2);
		setBlock(world, i + 6, j + 30, k + 22, Blocks.leaves, 7);
		world.setBlockMetadataWithNotify(i + 6, j + 30, k + 22, 7, 2);
		setBlock(world, i + 6, j + 30, k + 29, Blocks.log, 1);
		world.setBlockMetadataWithNotify(i + 6, j + 30, k + 29, 1, 2);
		setBlock(world, i + 6, j + 30, k + 30, Blocks.log, 1);
		world.setBlockMetadataWithNotify(i + 6, j + 30, k + 30, 1, 2);
		setBlock(world, i + 6, j + 30, k + 31, Blocks.log, 1);
		world.setBlockMetadataWithNotify(i + 6, j + 30, k + 31, 1, 2);
		setBlock(world, i + 6, j + 31, k + 12, Blocks.leaves, 7);
		world.setBlockMetadataWithNotify(i + 6, j + 31, k + 12, 7, 2);
		setBlock(world, i + 6, j + 31, k + 13, Blocks.leaves, 7);
		world.setBlockMetadataWithNotify(i + 6, j + 31, k + 13, 7, 2);
		setBlock(world, i + 6, j + 31, k + 14, Blocks.leaves, 7);
		world.setBlockMetadataWithNotify(i + 6, j + 31, k + 14, 7, 2);
		setBlock(world, i + 6, j + 31, k + 31, Blocks.log, 1);
		world.setBlockMetadataWithNotify(i + 6, j + 31, k + 31, 1, 2);
		setBlock(world, i + 6, j + 32, k + 13, Blocks.leaves, 7);
		world.setBlockMetadataWithNotify(i + 6, j + 32, k + 13, 7, 2);
		setBlock(world, i + 6, j + 32, k + 31, Blocks.log, 1);
		world.setBlockMetadataWithNotify(i + 6, j + 32, k + 31, 1, 2);
		setBlock(world, i + 6, j + 35, k + 14, Blocks.log, 3);
		world.setBlockMetadataWithNotify(i + 6, j + 35, k + 14, 3, 2);
		setBlock(world, i + 6, j + 36, k + 11, Blocks.leaves, 7);
		world.setBlockMetadataWithNotify(i + 6, j + 36, k + 11, 7, 2);
		setBlock(world, i + 6, j + 36, k + 12, Blocks.leaves, 7);
		world.setBlockMetadataWithNotify(i + 6, j + 36, k + 12, 7, 2);
		setBlock(world, i + 6, j + 36, k + 13, Blocks.leaves, 7);
		world.setBlockMetadataWithNotify(i + 6, j + 36, k + 13, 7, 2);
		setBlock(world, i + 6, j + 36, k + 14, Blocks.leaves, 7);
		world.setBlockMetadataWithNotify(i + 6, j + 36, k + 14, 7, 2);
		setBlock(world, i + 6, j + 36, k + 15, Blocks.leaves, 7);
		world.setBlockMetadataWithNotify(i + 6, j + 36, k + 15, 7, 2);
		setBlock(world, i + 6, j + 37, k + 12, Blocks.leaves, 7);
		world.setBlockMetadataWithNotify(i + 6, j + 37, k + 12, 7, 2);
		setBlock(world, i + 6, j + 37, k + 13, Blocks.leaves, 7);
		world.setBlockMetadataWithNotify(i + 6, j + 37, k + 13, 7, 2);
		setBlock(world, i + 6, j + 37, k + 14, Blocks.leaves, 7);
		world.setBlockMetadataWithNotify(i + 6, j + 37, k + 14, 7, 2);
		setBlock(world, i + 6, j + 38, k + 13, Blocks.leaves, 7);
		world.setBlockMetadataWithNotify(i + 6, j + 38, k + 13, 7, 2);
		setBlock(world, i + 6, j + 45, k + 21, Blocks.leaves, 7);
		world.setBlockMetadataWithNotify(i + 6, j + 45, k + 21, 7, 2);
		setBlock(world, i + 6, j + 45, k + 22, Blocks.leaves, 7);
		world.setBlockMetadataWithNotify(i + 6, j + 45, k + 22, 7, 2);
		setBlock(world, i + 6, j + 45, k + 23, Blocks.log, 3);
		world.setBlockMetadataWithNotify(i + 6, j + 45, k + 23, 3, 2);
		setBlock(world, i + 6, j + 45, k + 24, Blocks.leaves, 7);
		world.setBlockMetadataWithNotify(i + 6, j + 45, k + 24, 7, 2);
		setBlock(world, i + 6, j + 45, k + 25, Blocks.leaves, 7);
		world.setBlockMetadataWithNotify(i + 6, j + 45, k + 25, 7, 2);
		setBlock(world, i + 6, j + 46, k + 21, Blocks.leaves, 7);
		world.setBlockMetadataWithNotify(i + 6, j + 46, k + 21, 7, 2);
		setBlock(world, i + 6, j + 46, k + 22, Blocks.leaves, 7);
		world.setBlockMetadataWithNotify(i + 6, j + 46, k + 22, 7, 2);
		setBlock(world, i + 6, j + 46, k + 23, Blocks.leaves, 7);
		world.setBlockMetadataWithNotify(i + 6, j + 46, k + 23, 7, 2);
		setBlock(world, i + 6, j + 46, k + 24, Blocks.leaves, 7);
		world.setBlockMetadataWithNotify(i + 6, j + 46, k + 24, 7, 2);
		setBlock(world, i + 6, j + 46, k + 25, Blocks.leaves, 7);
		world.setBlockMetadataWithNotify(i + 6, j + 46, k + 25, 7, 2);
		setBlock(world, i + 6, j + 47, k + 22, Blocks.leaves, 7);
		world.setBlockMetadataWithNotify(i + 6, j + 47, k + 22, 7, 2);
		setBlock(world, i + 6, j + 47, k + 23, Blocks.leaves, 7);
		world.setBlockMetadataWithNotify(i + 6, j + 47, k + 23, 7, 2);
		setBlock(world, i + 6, j + 47, k + 24, Blocks.leaves, 7);
		world.setBlockMetadataWithNotify(i + 6, j + 47, k + 24, 7, 2);
		setBlock(world, i + 6, j + 48, k + 23, Blocks.leaves, 7);
		world.setBlockMetadataWithNotify(i + 6, j + 48, k + 23, 7, 2);
		setBlock(world, i + 7, j + 25, k + 16, Blocks.log, 3);
		world.setBlockMetadataWithNotify(i + 7, j + 25, k + 16, 3, 2);
		setBlock(world, i + 7, j + 25, k + 20, Blocks.log, 3);
		world.setBlockMetadataWithNotify(i + 7, j + 25, k + 20, 3, 2);
		setBlock(world, i + 7, j + 28, k + 20, Blocks.leaves, 7);
		world.setBlockMetadataWithNotify(i + 7, j + 28, k + 20, 7, 2);
		setBlock(world, i + 7, j + 28, k + 21, Blocks.leaves, 7);
		world.setBlockMetadataWithNotify(i + 7, j + 28, k + 21, 7, 2);
		setBlock(world, i + 7, j + 28, k + 22, Blocks.log, 3);
		world.setBlockMetadataWithNotify(i + 7, j + 28, k + 22, 3, 2);
		setBlock(world, i + 7, j + 28, k + 23, Blocks.leaves, 7);
		world.setBlockMetadataWithNotify(i + 7, j + 28, k + 23, 7, 2);
		setBlock(world, i + 7, j + 28, k + 24, Blocks.leaves, 7);
		world.setBlockMetadataWithNotify(i + 7, j + 28, k + 24, 7, 2);
		setBlock(world, i + 7, j + 29, k + 20, Blocks.leaves, 7);
		world.setBlockMetadataWithNotify(i + 7, j + 29, k + 20, 7, 2);
		setBlock(world, i + 7, j + 29, k + 21, Blocks.leaves, 7);
		world.setBlockMetadataWithNotify(i + 7, j + 29, k + 21, 7, 2);
		setBlock(world, i + 7, j + 29, k + 22, Blocks.leaves, 7);
		world.setBlockMetadataWithNotify(i + 7, j + 29, k + 22, 7, 2);
		setBlock(world, i + 7, j + 29, k + 23, Blocks.leaves, 7);
		world.setBlockMetadataWithNotify(i + 7, j + 29, k + 23, 7, 2);
		setBlock(world, i + 7, j + 29, k + 24, Blocks.leaves, 7);
		world.setBlockMetadataWithNotify(i + 7, j + 29, k + 24, 7, 2);
		setBlock(world, i + 7, j + 30, k + 21, Blocks.leaves, 7);
		world.setBlockMetadataWithNotify(i + 7, j + 30, k + 21, 7, 2);
		setBlock(world, i + 7, j + 30, k + 22, Blocks.leaves, 7);
		world.setBlockMetadataWithNotify(i + 7, j + 30, k + 22, 7, 2);
		setBlock(world, i + 7, j + 30, k + 23, Blocks.leaves, 7);
		world.setBlockMetadataWithNotify(i + 7, j + 30, k + 23, 7, 2);
		setBlock(world, i + 7, j + 30, k + 30, Blocks.log, 1);
		world.setBlockMetadataWithNotify(i + 7, j + 30, k + 30, 1, 2);
		setBlock(world, i + 7, j + 30, k + 31, Blocks.log, 1);
		world.setBlockMetadataWithNotify(i + 7, j + 30, k + 31, 1, 2);
		setBlock(world, i + 7, j + 31, k + 22, Blocks.leaves, 7);
		world.setBlockMetadataWithNotify(i + 7, j + 31, k + 22, 7, 2);
		setBlock(world, i + 7, j + 31, k + 31, Blocks.log, 1);
		world.setBlockMetadataWithNotify(i + 7, j + 31, k + 31, 1, 2);
		setBlock(world, i + 7, j + 36, k + 11, Blocks.leaves, 7);
		world.setBlockMetadataWithNotify(i + 7, j + 36, k + 11, 7, 2);
		setBlock(world, i + 7, j + 36, k + 12, Blocks.leaves, 7);
		world.setBlockMetadataWithNotify(i + 7, j + 36, k + 12, 7, 2);
		setBlock(world, i + 7, j + 36, k + 13, Blocks.log, 3);
		world.setBlockMetadataWithNotify(i + 7, j + 36, k + 13, 3, 2);
		setBlock(world, i + 7, j + 36, k + 14, Blocks.leaves, 7);
		world.setBlockMetadataWithNotify(i + 7, j + 36, k + 14, 7, 2);
		setBlock(world, i + 7, j + 36, k + 15, Blocks.leaves, 7);
		world.setBlockMetadataWithNotify(i + 7, j + 36, k + 15, 7, 2);
		setBlock(world, i + 7, j + 37, k + 11, Blocks.leaves, 7);
		world.setBlockMetadataWithNotify(i + 7, j + 37, k + 11, 7, 2);
		setBlock(world, i + 7, j + 37, k + 12, Blocks.leaves, 7);
		world.setBlockMetadataWithNotify(i + 7, j + 37, k + 12, 7, 2);
		setBlock(world, i + 7, j + 37, k + 13, Blocks.leaves, 7);
		world.setBlockMetadataWithNotify(i + 7, j + 37, k + 13, 7, 2);
		setBlock(world, i + 7, j + 37, k + 14, Blocks.leaves, 7);
		world.setBlockMetadataWithNotify(i + 7, j + 37, k + 14, 7, 2);
		setBlock(world, i + 7, j + 37, k + 15, Blocks.leaves, 7);
		world.setBlockMetadataWithNotify(i + 7, j + 37, k + 15, 7, 2);
		setBlock(world, i + 7, j + 38, k + 12, Blocks.leaves, 7);
		world.setBlockMetadataWithNotify(i + 7, j + 38, k + 12, 7, 2);
		setBlock(world, i + 7, j + 38, k + 13, Blocks.leaves, 7);
		world.setBlockMetadataWithNotify(i + 7, j + 38, k + 13, 7, 2);
		setBlock(world, i + 7, j + 38, k + 14, Blocks.leaves, 7);
		world.setBlockMetadataWithNotify(i + 7, j + 38, k + 14, 7, 2);
		setBlock(world, i + 7, j + 39, k + 13, Blocks.leaves, 7);
		world.setBlockMetadataWithNotify(i + 7, j + 39, k + 13, 7, 2);
		setBlock(world, i + 7, j + 45, k + 21, Blocks.leaves, 7);
		world.setBlockMetadataWithNotify(i + 7, j + 45, k + 21, 7, 2);
		setBlock(world, i + 7, j + 45, k + 22, Blocks.leaves, 7);
		world.setBlockMetadataWithNotify(i + 7, j + 45, k + 22, 7, 2);
		setBlock(world, i + 7, j + 45, k + 23, Blocks.leaves, 7);
		world.setBlockMetadataWithNotify(i + 7, j + 45, k + 23, 7, 2);
		setBlock(world, i + 7, j + 45, k + 24, Blocks.leaves, 7);
		world.setBlockMetadataWithNotify(i + 7, j + 45, k + 24, 7, 2);
		setBlock(world, i + 7, j + 45, k + 25, Blocks.leaves, 7);
		world.setBlockMetadataWithNotify(i + 7, j + 45, k + 25, 7, 2);
		setBlock(world, i + 7, j + 46, k + 22, Blocks.leaves, 7);
		world.setBlockMetadataWithNotify(i + 7, j + 46, k + 22, 7, 2);
		setBlock(world, i + 7, j + 46, k + 23, Blocks.leaves, 7);
		world.setBlockMetadataWithNotify(i + 7, j + 46, k + 23, 7, 2);
		setBlock(world, i + 7, j + 46, k + 24, Blocks.leaves, 7);
		world.setBlockMetadataWithNotify(i + 7, j + 46, k + 24, 7, 2);
		setBlock(world, i + 7, j + 47, k + 23, Blocks.leaves, 7);
		world.setBlockMetadataWithNotify(i + 7, j + 47, k + 23, 7, 2);
		setBlock(world, i + 8, j + 25, k + 16, Blocks.log, 3);
		world.setBlockMetadataWithNotify(i + 8, j + 25, k + 16, 3, 2);
		setBlock(world, i + 8, j + 25, k + 20, Blocks.log, 3);
		world.setBlockMetadataWithNotify(i + 8, j + 25, k + 20, 3, 2);
		setBlock(world, i + 8, j + 28, k + 20, Blocks.leaves, 7);
		world.setBlockMetadataWithNotify(i + 8, j + 28, k + 20, 7, 2);
		setBlock(world, i + 8, j + 28, k + 21, Blocks.leaves, 7);
		world.setBlockMetadataWithNotify(i + 8, j + 28, k + 21, 7, 2);
		setBlock(world, i + 8, j + 28, k + 22, Blocks.leaves, 7);
		world.setBlockMetadataWithNotify(i + 8, j + 28, k + 22, 7, 2);
		setBlock(world, i + 8, j + 28, k + 23, Blocks.leaves, 7);
		world.setBlockMetadataWithNotify(i + 8, j + 28, k + 23, 7, 2);
		setBlock(world, i + 8, j + 28, k + 24, Blocks.leaves, 7);
		world.setBlockMetadataWithNotify(i + 8, j + 28, k + 24, 7, 2);
		setBlock(world, i + 8, j + 29, k + 21, Blocks.leaves, 7);
		world.setBlockMetadataWithNotify(i + 8, j + 29, k + 21, 7, 2);
		setBlock(world, i + 8, j + 29, k + 22, Blocks.leaves, 7);
		world.setBlockMetadataWithNotify(i + 8, j + 29, k + 22, 7, 2);
		setBlock(world, i + 8, j + 29, k + 23, Blocks.leaves, 7);
		world.setBlockMetadataWithNotify(i + 8, j + 29, k + 23, 7, 2);
		setBlock(world, i + 8, j + 30, k + 22, Blocks.leaves, 7);
		world.setBlockMetadataWithNotify(i + 8, j + 30, k + 22, 7, 2);
		setBlock(world, i + 8, j + 30, k + 31, Blocks.log, 1);
		world.setBlockMetadataWithNotify(i + 8, j + 30, k + 31, 1, 2);
		setBlock(world, i + 8, j + 36, k + 11, Blocks.leaves, 7);
		world.setBlockMetadataWithNotify(i + 8, j + 36, k + 11, 7, 2);
		setBlock(world, i + 8, j + 36, k + 12, Blocks.leaves, 7);
		world.setBlockMetadataWithNotify(i + 8, j + 36, k + 12, 7, 2);
		setBlock(world, i + 8, j + 36, k + 13, Blocks.leaves, 7);
		world.setBlockMetadataWithNotify(i + 8, j + 36, k + 13, 7, 2);
		setBlock(world, i + 8, j + 36, k + 14, Blocks.leaves, 7);
		world.setBlockMetadataWithNotify(i + 8, j + 36, k + 14, 7, 2);
		setBlock(world, i + 8, j + 36, k + 15, Blocks.leaves, 7);
		world.setBlockMetadataWithNotify(i + 8, j + 36, k + 15, 7, 2);
		setBlock(world, i + 8, j + 37, k + 12, Blocks.leaves, 7);
		world.setBlockMetadataWithNotify(i + 8, j + 37, k + 12, 7, 2);
		setBlock(world, i + 8, j + 37, k + 13, Blocks.leaves, 7);
		world.setBlockMetadataWithNotify(i + 8, j + 37, k + 13, 7, 2);
		setBlock(world, i + 8, j + 37, k + 14, Blocks.leaves, 7);
		world.setBlockMetadataWithNotify(i + 8, j + 37, k + 14, 7, 2);
		setBlock(world, i + 8, j + 38, k + 13, Blocks.leaves, 7);
		world.setBlockMetadataWithNotify(i + 8, j + 38, k + 13, 7, 2);
		setBlock(world, i + 8, j + 45, k + 22, Blocks.leaves, 7);
		world.setBlockMetadataWithNotify(i + 8, j + 45, k + 22, 7, 2);
		setBlock(world, i + 8, j + 45, k + 23, Blocks.leaves, 7);
		world.setBlockMetadataWithNotify(i + 8, j + 45, k + 23, 7, 2);
		setBlock(world, i + 8, j + 45, k + 24, Blocks.leaves, 7);
		world.setBlockMetadataWithNotify(i + 8, j + 45, k + 24, 7, 2);
		setBlock(world, i + 8, j + 46, k + 23, Blocks.leaves, 7);
		world.setBlockMetadataWithNotify(i + 8, j + 46, k + 23, 7, 2);
		setBlock(world, i + 9, j + 25, k + 15, Blocks.log, 3);
		world.setBlockMetadataWithNotify(i + 9, j + 25, k + 15, 3, 2);
		setBlock(world, i + 9, j + 25, k + 19, Blocks.log, 3);
		world.setBlockMetadataWithNotify(i + 9, j + 25, k + 19, 3, 2);
		setBlock(world, i + 9, j + 28, k + 21, Blocks.leaves, 7);
		world.setBlockMetadataWithNotify(i + 9, j + 28, k + 21, 7, 2);
		setBlock(world, i + 9, j + 28, k + 22, Blocks.leaves, 7);
		world.setBlockMetadataWithNotify(i + 9, j + 28, k + 22, 7, 2);
		setBlock(world, i + 9, j + 28, k + 23, Blocks.leaves, 7);
		world.setBlockMetadataWithNotify(i + 9, j + 28, k + 23, 7, 2);
		setBlock(world, i + 9, j + 29, k + 22, Blocks.leaves, 7);
		world.setBlockMetadataWithNotify(i + 9, j + 29, k + 22, 7, 2);
		setBlock(world, i + 9, j + 36, k + 12, Blocks.leaves, 7);
		world.setBlockMetadataWithNotify(i + 9, j + 36, k + 12, 7, 2);
		setBlock(world, i + 9, j + 36, k + 13, Blocks.leaves, 7);
		world.setBlockMetadataWithNotify(i + 9, j + 36, k + 13, 7, 2);
		setBlock(world, i + 9, j + 36, k + 14, Blocks.leaves, 7);
		world.setBlockMetadataWithNotify(i + 9, j + 36, k + 14, 7, 2);
		setBlock(world, i + 9, j + 37, k + 13, Blocks.leaves, 7);
		world.setBlockMetadataWithNotify(i + 9, j + 37, k + 13, 7, 2);
		setBlock(world, i + 10, j + 25, k + 15, Blocks.log, 3);
		world.setBlockMetadataWithNotify(i + 10, j + 25, k + 15, 3, 2);
		setBlock(world, i + 10, j + 25, k + 19, Blocks.log, 3);
		world.setBlockMetadataWithNotify(i + 10, j + 25, k + 19, 3, 2);
		setBlock(world, i + 10, j + 26, k + 12, Blocks.leaves, 7);
		world.setBlockMetadataWithNotify(i + 10, j + 26, k + 12, 7, 2);
		setBlock(world, i + 10, j + 26, k + 13, Blocks.leaves, 7);
		world.setBlockMetadataWithNotify(i + 10, j + 26, k + 13, 7, 2);
		setBlock(world, i + 10, j + 26, k + 14, Blocks.leaves, 7);
		world.setBlockMetadataWithNotify(i + 10, j + 26, k + 14, 7, 2);
		setBlock(world, i + 10, j + 26, k + 17, Blocks.leaves, 7);
		world.setBlockMetadataWithNotify(i + 10, j + 26, k + 17, 7, 2);
		setBlock(world, i + 10, j + 26, k + 18, Blocks.leaves, 7);
		world.setBlockMetadataWithNotify(i + 10, j + 26, k + 18, 7, 2);
		setBlock(world, i + 10, j + 26, k + 19, Blocks.leaves, 7);
		world.setBlockMetadataWithNotify(i + 10, j + 26, k + 19, 7, 2);
		setBlock(world, i + 10, j + 27, k + 13, Blocks.leaves, 7);
		world.setBlockMetadataWithNotify(i + 10, j + 27, k + 13, 7, 2);
		setBlock(world, i + 10, j + 27, k + 18, Blocks.leaves, 7);
		world.setBlockMetadataWithNotify(i + 10, j + 27, k + 18, 7, 2);
		setBlock(world, i + 11, j + 25, k + 14, Blocks.log, 3);
		world.setBlockMetadataWithNotify(i + 11, j + 25, k + 14, 3, 2);
		setBlock(world, i + 11, j + 25, k + 19, Blocks.log, 3);
		world.setBlockMetadataWithNotify(i + 11, j + 25, k + 19, 3, 2);
		setBlock(world, i + 11, j + 26, k + 11, Blocks.leaves, 7);
		world.setBlockMetadataWithNotify(i + 11, j + 26, k + 11, 7, 2);
		setBlock(world, i + 11, j + 26, k + 12, Blocks.leaves, 7);
		world.setBlockMetadataWithNotify(i + 11, j + 26, k + 12, 7, 2);
		setBlock(world, i + 11, j + 26, k + 13, Blocks.leaves, 7);
		world.setBlockMetadataWithNotify(i + 11, j + 26, k + 13, 7, 2);
		setBlock(world, i + 11, j + 26, k + 14, Blocks.leaves, 7);
		world.setBlockMetadataWithNotify(i + 11, j + 26, k + 14, 7, 2);
		setBlock(world, i + 11, j + 26, k + 15, Blocks.leaves, 7);
		world.setBlockMetadataWithNotify(i + 11, j + 26, k + 15, 7, 2);
		
		generate2(world, rand, i, j, k);
		return true;
		}

	
	public boolean generate2(World world, Random rand, int i, int j, int k)
	{
		setBlock(world, i + 11, j + 26, k + 16, Blocks.leaves, 7);
		world.setBlockMetadataWithNotify(i + 11, j + 26, k + 16, 7, 2);
		setBlock(world, i + 11, j + 26, k + 17, Blocks.leaves, 7);
		world.setBlockMetadataWithNotify(i + 11, j + 26, k + 17, 7, 2);
		setBlock(world, i + 11, j + 26, k + 18, Blocks.leaves, 7);
		world.setBlockMetadataWithNotify(i + 11, j + 26, k + 18, 7, 2);
		setBlock(world, i + 11, j + 26, k + 19, Blocks.leaves, 7);
		world.setBlockMetadataWithNotify(i + 11, j + 26, k + 19, 7, 2);
		setBlock(world, i + 11, j + 26, k + 20, Blocks.leaves, 7);
		world.setBlockMetadataWithNotify(i + 11, j + 26, k + 20, 7, 2);
		setBlock(world, i + 11, j + 27, k + 12, Blocks.leaves, 7);
		world.setBlockMetadataWithNotify(i + 11, j + 27, k + 12, 7, 2);
		setBlock(world, i + 11, j + 27, k + 13, Blocks.leaves, 7);
		world.setBlockMetadataWithNotify(i + 11, j + 27, k + 13, 7, 2);
		setBlock(world, i + 11, j + 27, k + 14, Blocks.leaves, 7);
		world.setBlockMetadataWithNotify(i + 11, j + 27, k + 14, 7, 2);
		setBlock(world, i + 11, j + 27, k + 17, Blocks.leaves, 7);
		world.setBlockMetadataWithNotify(i + 11, j + 27, k + 17, 7, 2);
		setBlock(world, i + 11, j + 27, k + 18, Blocks.leaves, 7);
		world.setBlockMetadataWithNotify(i + 11, j + 27, k + 18, 7, 2);
		setBlock(world, i + 11, j + 27, k + 19, Blocks.leaves, 7);
		world.setBlockMetadataWithNotify(i + 11, j + 27, k + 19, 7, 2);
		setBlock(world, i + 11, j + 28, k + 13, Blocks.leaves, 7);
		world.setBlockMetadataWithNotify(i + 11, j + 28, k + 13, 7, 2);
		setBlock(world, i + 11, j + 28, k + 18, Blocks.leaves, 7);
		world.setBlockMetadataWithNotify(i + 11, j + 28, k + 18, 7, 2);
		setBlock(world, i + 12, j + 26, k + 11, Blocks.leaves, 7);
		world.setBlockMetadataWithNotify(i + 12, j + 26, k + 11, 7, 2);
		setBlock(world, i + 12, j + 26, k + 12, Blocks.leaves, 7);
		world.setBlockMetadataWithNotify(i + 12, j + 26, k + 12, 7, 2);
		setBlock(world, i + 12, j + 26, k + 13, Blocks.log, 3);
		world.setBlockMetadataWithNotify(i + 12, j + 26, k + 13, 3, 2);
		setBlock(world, i + 12, j + 26, k + 14, Blocks.leaves, 7);
		world.setBlockMetadataWithNotify(i + 12, j + 26, k + 14, 7, 2);
		setBlock(world, i + 12, j + 26, k + 15, Blocks.leaves, 7);
		world.setBlockMetadataWithNotify(i + 12, j + 26, k + 15, 7, 2);
		setBlock(world, i + 12, j + 26, k + 16, Blocks.leaves, 7);
		world.setBlockMetadataWithNotify(i + 12, j + 26, k + 16, 7, 2);
		setBlock(world, i + 12, j + 26, k + 17, Blocks.leaves, 7);
		world.setBlockMetadataWithNotify(i + 12, j + 26, k + 17, 7, 2);
		setBlock(world, i + 12, j + 26, k + 18, Blocks.log, 3);
		world.setBlockMetadataWithNotify(i + 12, j + 26, k + 18, 3, 2);
		setBlock(world, i + 12, j + 26, k + 19, Blocks.leaves, 7);
		world.setBlockMetadataWithNotify(i + 12, j + 26, k + 19, 7, 2);
		setBlock(world, i + 12, j + 26, k + 20, Blocks.leaves, 7);
		world.setBlockMetadataWithNotify(i + 12, j + 26, k + 20, 7, 2);
		setBlock(world, i + 12, j + 27, k + 11, Blocks.leaves, 7);
		world.setBlockMetadataWithNotify(i + 12, j + 27, k + 11, 7, 2);
		setBlock(world, i + 12, j + 27, k + 12, Blocks.leaves, 7);
		world.setBlockMetadataWithNotify(i + 12, j + 27, k + 12, 7, 2);
		setBlock(world, i + 12, j + 27, k + 13, Blocks.leaves, 7);
		world.setBlockMetadataWithNotify(i + 12, j + 27, k + 13, 7, 2);
		setBlock(world, i + 12, j + 27, k + 14, Blocks.leaves, 7);
		world.setBlockMetadataWithNotify(i + 12, j + 27, k + 14, 7, 2);
		setBlock(world, i + 12, j + 27, k + 15, Blocks.leaves, 7);
		world.setBlockMetadataWithNotify(i + 12, j + 27, k + 15, 7, 2);
		setBlock(world, i + 12, j + 27, k + 16, Blocks.leaves, 7);
		world.setBlockMetadataWithNotify(i + 12, j + 27, k + 16, 7, 2);
		setBlock(world, i + 12, j + 27, k + 17, Blocks.leaves, 7);
		world.setBlockMetadataWithNotify(i + 12, j + 27, k + 17, 7, 2);
		setBlock(world, i + 12, j + 27, k + 18, Blocks.leaves, 7);
		world.setBlockMetadataWithNotify(i + 12, j + 27, k + 18, 7, 2);
		setBlock(world, i + 12, j + 27, k + 19, Blocks.leaves, 7);
		world.setBlockMetadataWithNotify(i + 12, j + 27, k + 19, 7, 2);
		setBlock(world, i + 12, j + 27, k + 20, Blocks.leaves, 7);
		world.setBlockMetadataWithNotify(i + 12, j + 27, k + 20, 7, 2);
		setBlock(world, i + 12, j + 28, k + 12, Blocks.leaves, 7);
		world.setBlockMetadataWithNotify(i + 12, j + 28, k + 12, 7, 2);
		setBlock(world, i + 12, j + 28, k + 13, Blocks.leaves, 7);
		world.setBlockMetadataWithNotify(i + 12, j + 28, k + 13, 7, 2);
		setBlock(world, i + 12, j + 28, k + 14, Blocks.leaves, 7);
		world.setBlockMetadataWithNotify(i + 12, j + 28, k + 14, 7, 2);
		setBlock(world, i + 12, j + 28, k + 17, Blocks.leaves, 7);
		world.setBlockMetadataWithNotify(i + 12, j + 28, k + 17, 7, 2);
		setBlock(world, i + 12, j + 28, k + 18, Blocks.leaves, 7);
		world.setBlockMetadataWithNotify(i + 12, j + 28, k + 18, 7, 2);
		setBlock(world, i + 12, j + 28, k + 19, Blocks.leaves, 7);
		world.setBlockMetadataWithNotify(i + 12, j + 28, k + 19, 7, 2);
		setBlock(world, i + 12, j + 29, k + 13, Blocks.leaves, 7);
