/*       */package com.parzivail.pswm.world.gen.wookietree;

/*       */
/*       *//*       */
/*       */
import com.parzivail.pswm.utils.LootGenUtils;
import com.parzivail.pswm.utils.NPCType;
import com.parzivail.pswm.utils.SpawnUtils;


/*       */
import cpw.mods.fml.common.IWorldGenerator;


/*       */
import java.util.Random;


/*       */
import net.minecraft.block.Block;
/*       */
import net.minecraft.init.Blocks;
/*       */
import net.minecraft.tileentity.TileEntityChest;
/*       */
import net.minecraft.world.World;
/*       */
import net.minecraft.world.WorldProvider;
/*       */
import net.minecraft.world.chunk.IChunkProvider;
/*       */
import net.minecraft.world.gen.feature.WorldGenerator;

/*       */
/*       */public class WT_12
/*       */extends WorldGenerator implements IWorldGenerator
/*       */
{
	/*       */protected Block[] getValidSpawnBlocks()
	/*       */
	{
		return new Block[0];
		/*       */}

	/*       */
	/*       */public boolean locationIsValidSpawn(World world, int i, int j, int k)
	/*       */
	{
		int distanceToAir = 0;
		Block check = world.getBlock(i, j, k);
		/*       */
		while (check != Blocks.air)
		{
			if (distanceToAir > 3) { return false;
			/*       */}
			/*       */
			distanceToAir++;
			check = world.getBlock(i, j + distanceToAir, k);
			/*       */}
		/*       */
		j += distanceToAir - 1;
		/*       */
		Block block = world.getBlock(i, j, k);
		Block blockAbove = world.getBlock(i, j + 1, k);
		Block blockBelow = world.getBlock(i, j - 1, k);
		/*       */
		for (Block x : getValidSpawnBlocks())
		{
			if (blockAbove != Blocks.air) { return false;
			/*       */}
			if (block == x) return true;
			if ((block == Blocks.snow) && (blockBelow == x)) { return true;
			/*       */}
			/*       */}
		/*       */
		return false;
		/*       */}

	/*       */
	/*       */
	/*       */
	/*       */public void generate(Random random, int chunkX, int chunkZ, World world, IChunkProvider chunkGenerator, IChunkProvider chunkProvider)
	{
	}

	/*       */
	/*       */
	/*       */public void setBlock(World world, int x, int y, int z, Block block, int metadata)
	/*       */
	{
		world.setBlock(x, y, z, block, metadata, 2);
		/*       */}

	/*       */
	/*       */public boolean generate(World world, Random rand, int i, int j, int k)
	/*       */
	{
		k -= 10;
		i -= 10;
		/*       */
		setBlock(world, i + 14, j + 41, k + 20, Blocks.fence, 0);
		setBlock(world, i + 14, j + 41, k + 29, Blocks.fence, 0);
		setBlock(world, i + 15, j + 41, k + 19, Blocks.fence, 0);
		setBlock(world, i + 15, j + 41, k + 20, Blocks.fence, 0);
		setBlock(world, i + 15, j + 41, k + 29, Blocks.fence, 0);
		setBlock(world, i + 15, j + 41, k + 30, Blocks.fence, 0);
		setBlock(world, i + 16, j + 41, k + 18, Blocks.fence, 0);
		setBlock(world, i + 16, j + 41, k + 19, Blocks.fence, 0);
		setBlock(world, i + 16, j + 41, k + 30, Blocks.fence, 0);
		setBlock(world, i + 16, j + 41, k + 31, Blocks.fence, 0);
		setBlock(world, i + 17, j + 38, k + 20, Blocks.fence, 0);
		setBlock(world, i + 17, j + 38, k + 29, Blocks.fence, 0);
		setBlock(world, i + 17, j + 41, k + 18, Blocks.fence, 0);
		setBlock(world, i + 17, j + 41, k + 31, Blocks.fence, 0);
		setBlock(world, i + 18, j + 38, k + 20, Blocks.fence, 0);
		SpawnUtils.spawnNPC(NPCType.WOOKIETREE, world, i + 18, j + 38, k + 25);
		setBlock(world, i + 18, j + 38, k + 29, Blocks.fence, 0);
		setBlock(world, i + 18, j + 41, k + 17, Blocks.fence, 0);
		setBlock(world, i + 18, j + 41, k + 18, Blocks.fence, 0);
		setBlock(world, i + 18, j + 41, k + 31, Blocks.fence, 0);
		setBlock(world, i + 19, j + 38, k + 19, Blocks.fence, 0);
		setBlock(world, i + 19, j + 38, k + 20, Blocks.fence, 0);
		setBlock(world, i + 19, j + 38, k + 29, Blocks.fence, 0);
		setBlock(world, i + 19, j + 38, k + 30, Blocks.fence, 0);
		setBlock(world, i + 19, j + 41, k + 17, Blocks.fence, 0);
		setBlock(world, i + 20, j + 38, k + 19, Blocks.fence, 0);
		setBlock(world, i + 20, j + 38, k + 30, Blocks.fence, 0);
		setBlock(world, i + 20, j + 41, k + 17, Blocks.fence, 0);
		setBlock(world, i + 21, j + 38, k + 19, Blocks.fence, 0);
		setBlock(world, i + 21, j + 38, k + 30, Blocks.fence, 0);
		setBlock(world, i + 21, j + 41, k + 16, Blocks.fence, 0);
		setBlock(world, i + 21, j + 41, k + 17, Blocks.fence, 0);
		setBlock(world, i + 24, j + 38, k + 24, Blocks.spruce_stairs, 0);
		setBlock(world, i + 24, j + 38, k + 25, Blocks.spruce_stairs, 0);
		setBlock(world, i + 24, j + 38, k + 26, Blocks.crafting_table, 0);
		SpawnUtils.spawnNPC(NPCType.WOOKIETREE, world, i + 25, j + 38, k + 29);
		SpawnUtils.spawnNPC(NPCType.WOOKIETREE, world, i + 26, j + 38, k + 20);
		setBlock(world, i + 28, j + 38, k + 18, Blocks.spruce_stairs, 0);
		setBlock(world, i + 28, j + 38, k + 31, Blocks.spruce_stairs, 0);
		setBlock(world, i + 30, j + 38, k + 19, Blocks.fence, 0);
		setBlock(world, i + 30, j + 38, k + 30, Blocks.fence, 0);
		setBlock(world, i + 30, j + 41, k + 16, Blocks.fence, 0);
		setBlock(world, i + 30, j + 41, k + 17, Blocks.fence, 0);
		setBlock(world, i + 31, j + 38, k + 19, Blocks.fence, 0);
		SpawnUtils.spawnNPC(NPCType.WOOKIETREE, world, i + 31, j + 38, k + 24);
		setBlock(world, i + 31, j + 38, k + 30, Blocks.fence, 0);
		setBlock(world, i + 31, j + 41, k + 17, Blocks.fence, 0);
		setBlock(world, i + 0, j + 0, k + 21, Blocks.log, 3);
		world.setBlockMetadataWithNotify(i + 0, j + 0, k + 21, 3, 2);
		setBlock(world, i + 0, j + 0, k + 22, Blocks.log, 3);
		world.setBlockMetadataWithNotify(i + 0, j + 0, k + 22, 3, 2);
		setBlock(world, i + 0, j + 0, k + 23, Blocks.log, 3);
		world.setBlockMetadataWithNotify(i + 0, j + 0, k + 23, 3, 2);
		setBlock(world, i + 0, j + 0, k + 24, Blocks.log, 3);
		world.setBlockMetadataWithNotify(i + 0, j + 0, k + 24, 3, 2);
		setBlock(world, i + 0, j + 0, k + 25, Blocks.log, 3);
		world.setBlockMetadataWithNotify(i + 0, j + 0, k + 25, 3, 2);
		setBlock(world, i + 0, j + 1, k + 23, Blocks.log, 3);
		world.setBlockMetadataWithNotify(i + 0, j + 1, k + 23, 3, 2);
		setBlock(world, i + 0, j + 18, k + 24, Blocks.log, 3);
		world.setBlockMetadataWithNotify(i + 0, j + 18, k + 24, 3, 2);
		setBlock(world, i + 0, j + 18, k + 27, Blocks.log, 1);
		world.setBlockMetadataWithNotify(i + 0, j + 18, k + 27, 1, 2);
		setBlock(world, i + 0, j + 18, k + 28, Blocks.log, 1);
		world.setBlockMetadataWithNotify(i + 0, j + 18, k + 28, 1, 2);
		setBlock(world, i + 0, j + 18, k + 29, Blocks.log, 1);
		world.setBlockMetadataWithNotify(i + 0, j + 18, k + 29, 1, 2);
		setBlock(world, i + 0, j + 19, k + 20, Blocks.log, 1);
		world.setBlockMetadataWithNotify(i + 0, j + 19, k + 20, 1, 2);
		setBlock(world, i + 0, j + 19, k + 23, Blocks.log, 3);
		world.setBlockMetadataWithNotify(i + 0, j + 19, k + 23, 3, 2);
		setBlock(world, i + 0, j + 19, k + 24, Blocks.log, 3);
		world.setBlockMetadataWithNotify(i + 0, j + 19, k + 24, 3, 2);
		setBlock(world, i + 0, j + 19, k + 25, Blocks.log, 3);
		world.setBlockMetadataWithNotify(i + 0, j + 19, k + 25, 3, 2);
		setBlock(world, i + 0, j + 19, k + 27, Blocks.log, 1);
		world.setBlockMetadataWithNotify(i + 0, j + 19, k + 27, 1, 2);
		setBlock(world, i + 0, j + 19, k + 28, Blocks.log, 1);
		world.setBlockMetadataWithNotify(i + 0, j + 19, k + 28, 1, 2);
		setBlock(world, i + 0, j + 19, k + 29, Blocks.log, 1);
		world.setBlockMetadataWithNotify(i + 0, j + 19, k + 29, 1, 2);
		setBlock(world, i + 0, j + 19, k + 30, Blocks.log, 1);
		world.setBlockMetadataWithNotify(i + 0, j + 19, k + 30, 1, 2);
		setBlock(world, i + 0, j + 20, k + 17, Blocks.log, 3);
		world.setBlockMetadataWithNotify(i + 0, j + 20, k + 17, 3, 2);
		setBlock(world, i + 0, j + 20, k + 18, Blocks.log, 3);
		world.setBlockMetadataWithNotify(i + 0, j + 20, k + 18, 3, 2);
		setBlock(world, i + 0, j + 20, k + 19, Blocks.log, 1);
		world.setBlockMetadataWithNotify(i + 0, j + 20, k + 19, 1, 2);
		setBlock(world, i + 0, j + 20, k + 20, Blocks.log, 1);
		world.setBlockMetadataWithNotify(i + 0, j + 20, k + 20, 1, 2);
		setBlock(world, i + 0, j + 20, k + 21, Blocks.log, 1);
		world.setBlockMetadataWithNotify(i + 0, j + 20, k + 21, 1, 2);
		setBlock(world, i + 0, j + 20, k + 24, Blocks.log, 1);
		world.setBlockMetadataWithNotify(i + 0, j + 20, k + 24, 1, 2);
		setBlock(world, i + 0, j + 20, k + 25, Blocks.log, 1);
		world.setBlockMetadataWithNotify(i + 0, j + 20, k + 25, 1, 2);
		setBlock(world, i + 0, j + 20, k + 26, Blocks.log, 1);
		world.setBlockMetadataWithNotify(i + 0, j + 20, k + 26, 1, 2);
		setBlock(world, i + 0, j + 20, k + 27, Blocks.log, 1);
		world.setBlockMetadataWithNotify(i + 0, j + 20, k + 27, 1, 2);
		setBlock(world, i + 0, j + 20, k + 28, Blocks.log, 1);
		world.setBlockMetadataWithNotify(i + 0, j + 20, k + 28, 1, 2);
		setBlock(world, i + 0, j + 20, k + 29, Blocks.log, 1);
		world.setBlockMetadataWithNotify(i + 0, j + 20, k + 29, 1, 2);
		setBlock(world, i + 0, j + 20, k + 30, Blocks.log, 1);
		world.setBlockMetadataWithNotify(i + 0, j + 20, k + 30, 1, 2);
		setBlock(world, i + 0, j + 21, k + 17, Blocks.log, 3);
		world.setBlockMetadataWithNotify(i + 0, j + 21, k + 17, 3, 2);
		setBlock(world, i + 0, j + 21, k + 18, Blocks.log, 3);
		world.setBlockMetadataWithNotify(i + 0, j + 21, k + 18, 3, 2);
		setBlock(world, i + 0, j + 21, k + 19, Blocks.log, 1);
		world.setBlockMetadataWithNotify(i + 0, j + 21, k + 19, 1, 2);
		setBlock(world, i + 0, j + 21, k + 20, Blocks.log, 1);
		world.setBlockMetadataWithNotify(i + 0, j + 21, k + 20, 1, 2);
		setBlock(world, i + 0, j + 21, k + 25, Blocks.log, 1);
		world.setBlockMetadataWithNotify(i + 0, j + 21, k + 25, 1, 2);
		setBlock(world, i + 0, j + 21, k + 27, Blocks.log, 3);
		world.setBlockMetadataWithNotify(i + 0, j + 21, k + 27, 3, 2);
		setBlock(world, i + 0, j + 21, k + 28, Blocks.log, 1);
		world.setBlockMetadataWithNotify(i + 0, j + 21, k + 28, 1, 2);
		setBlock(world, i + 0, j + 21, k + 29, Blocks.log, 1);
		world.setBlockMetadataWithNotify(i + 0, j + 21, k + 29, 1, 2);
		setBlock(world, i + 0, j + 21, k + 30, Blocks.log, 1);
		world.setBlockMetadataWithNotify(i + 0, j + 21, k + 30, 1, 2);
		setBlock(world, i + 0, j + 21, k + 31, Blocks.log, 1);
		world.setBlockMetadataWithNotify(i + 0, j + 21, k + 31, 1, 2);
		setBlock(world, i + 0, j + 22, k + 17, Blocks.log, 3);
		world.setBlockMetadataWithNotify(i + 0, j + 22, k + 17, 3, 2);
		setBlock(world, i + 0, j + 22, k + 18, Blocks.log, 3);
		world.setBlockMetadataWithNotify(i + 0, j + 22, k + 18, 3, 2);
		setBlock(world, i + 0, j + 22, k + 19, Blocks.log, 3);
		world.setBlockMetadataWithNotify(i + 0, j + 22, k + 19, 3, 2);
		setBlock(world, i + 0, j + 22, k + 27, Blocks.log, 3);
		world.setBlockMetadataWithNotify(i + 0, j + 22, k + 27, 3, 2);
		setBlock(world, i + 0, j + 22, k + 30, Blocks.log, 1);
		world.setBlockMetadataWithNotify(i + 0, j + 22, k + 30, 1, 2);
		setBlock(world, i + 0, j + 27, k + 28, Blocks.leaves, 15);
		world.setBlockMetadataWithNotify(i + 0, j + 27, k + 28, 15, 2);
		setBlock(world, i + 0, j + 27, k + 29, Blocks.leaves, 15);
		world.setBlockMetadataWithNotify(i + 0, j + 27, k + 29, 15, 2);
		setBlock(world, i + 0, j + 27, k + 30, Blocks.log, 3);
		world.setBlockMetadataWithNotify(i + 0, j + 27, k + 30, 3, 2);
		setBlock(world, i + 0, j + 27, k + 31, Blocks.leaves, 15);
		world.setBlockMetadataWithNotify(i + 0, j + 27, k + 31, 15, 2);
		setBlock(world, i + 0, j + 28, k + 28, Blocks.leaves, 15);
		world.setBlockMetadataWithNotify(i + 0, j + 28, k + 28, 15, 2);
		setBlock(world, i + 0, j + 28, k + 29, Blocks.leaves, 15);
		world.setBlockMetadataWithNotify(i + 0, j + 28, k + 29, 15, 2);
		setBlock(world, i + 0, j + 28, k + 30, Blocks.leaves, 15);
		world.setBlockMetadataWithNotify(i + 0, j + 28, k + 30, 15, 2);
		setBlock(world, i + 0, j + 28, k + 31, Blocks.leaves, 15);
		world.setBlockMetadataWithNotify(i + 0, j + 28, k + 31, 15, 2);
		setBlock(world, i + 0, j + 29, k + 8, Blocks.leaves, 7);
		world.setBlockMetadataWithNotify(i + 0, j + 29, k + 8, 7, 2);
		setBlock(world, i + 0, j + 29, k + 9, Blocks.leaves, 7);
		world.setBlockMetadataWithNotify(i + 0, j + 29, k + 9, 7, 2);
		setBlock(world, i + 0, j + 29, k + 10, Blocks.leaves, 7);
		world.setBlockMetadataWithNotify(i + 0, j + 29, k + 10, 7, 2);
		setBlock(world, i + 0, j + 29, k + 11, Blocks.leaves, 7);
		world.setBlockMetadataWithNotify(i + 0, j + 29, k + 11, 7, 2);
		setBlock(world, i + 0, j + 29, k + 12, Blocks.leaves, 7);
		world.setBlockMetadataWithNotify(i + 0, j + 29, k + 12, 7, 2);
		setBlock(world, i + 0, j + 29, k + 29, Blocks.log, 3);
		world.setBlockMetadataWithNotify(i + 0, j + 29, k + 29, 3, 2);
		setBlock(world, i + 0, j + 29, k + 30, Blocks.leaves, 15);
		world.setBlockMetadataWithNotify(i + 0, j + 29, k + 30, 15, 2);
		setBlock(world, i + 0, j + 29, k + 31, Blocks.leaves, 15);
		world.setBlockMetadataWithNotify(i + 0, j + 29, k + 31, 15, 2);
		setBlock(world, i + 0, j + 30, k + 9, Blocks.leaves, 7);
		world.setBlockMetadataWithNotify(i + 0, j + 30, k + 9, 7, 2);
		setBlock(world, i + 0, j + 30, k + 10, Blocks.leaves, 7);
		world.setBlockMetadataWithNotify(i + 0, j + 30, k + 10, 7, 2);
		setBlock(world, i + 0, j + 30, k + 11, Blocks.leaves, 7);
		world.setBlockMetadataWithNotify(i + 0, j + 30, k + 11, 7, 2);
		setBlock(world, i + 0, j + 30, k + 30, Blocks.leaves, 15);
		world.setBlockMetadataWithNotify(i + 0, j + 30, k + 30, 15, 2);
		setBlock(world, i + 0, j + 31, k + 10, Blocks.leaves, 7);
		world.setBlockMetadataWithNotify(i + 0, j + 31, k + 10, 7, 2);
		setBlock(world, i + 0, j + 31, k + 18, Blocks.log, 3);
		world.setBlockMetadataWithNotify(i + 0, j + 31, k + 18, 3, 2);
		setBlock(world, i + 0, j + 32, k + 21, Blocks.leaves, 7);
		world.setBlockMetadataWithNotify(i + 0, j + 32, k + 21, 7, 2);
		setBlock(world, i + 0, j + 32, k + 22, Blocks.leaves, 7);
		world.setBlockMetadataWithNotify(i + 0, j + 32, k + 22, 7, 2);
		setBlock(world, i + 0, j + 32, k + 23, Blocks.leaves, 7);
		world.setBlockMetadataWithNotify(i + 0, j + 32, k + 23, 7, 2);
		setBlock(world, i + 0, j + 33, k + 17, Blocks.log, 3);
		world.setBlockMetadataWithNotify(i + 0, j + 33, k + 17, 3, 2);
		setBlock(world, i + 0, j + 33, k + 22, Blocks.leaves, 7);
		world.setBlockMetadataWithNotify(i + 0, j + 33, k + 22, 7, 2);
		setBlock(world, i + 0, j + 34, k + 24, Blocks.log, 3);
		world.setBlockMetadataWithNotify(i + 0, j + 34, k + 24, 3, 2);
		setBlock(world, i + 0, j + 35, k + 20, Blocks.log, 3);
		world.setBlockMetadataWithNotify(i + 0, j + 35, k + 20, 3, 2);
		setBlock(world, i + 0, j + 35, k + 21, Blocks.leaves, 7);
		world.setBlockMetadataWithNotify(i + 0, j + 35, k + 21, 7, 2);
		setBlock(world, i + 0, j + 35, k + 22, Blocks.leaves, 7);
		world.setBlockMetadataWithNotify(i + 0, j + 35, k + 22, 7, 2);
		setBlock(world, i + 0, j + 35, k + 23, Blocks.leaves, 7);
		world.setBlockMetadataWithNotify(i + 0, j + 35, k + 23, 7, 2);
		setBlock(world, i + 0, j + 35, k + 24, Blocks.leaves, 7);
		world.setBlockMetadataWithNotify(i + 0, j + 35, k + 24, 7, 2);
		setBlock(world, i + 0, j + 35, k + 25, Blocks.leaves, 7);
		world.setBlockMetadataWithNotify(i + 0, j + 35, k + 25, 7, 2);
		setBlock(world, i + 0, j + 36, k + 22, Blocks.log, 3);
		world.setBlockMetadataWithNotify(i + 0, j + 36, k + 22, 3, 2);
		setBlock(world, i + 0, j + 36, k + 23, Blocks.leaves, 7);
		world.setBlockMetadataWithNotify(i + 0, j + 36, k + 23, 7, 2);
		setBlock(world, i + 0, j + 36, k + 24, Blocks.leaves, 7);
		world.setBlockMetadataWithNotify(i + 0, j + 36, k + 24, 7, 2);
		setBlock(world, i + 0, j + 37, k + 19, Blocks.log, 3);
		world.setBlockMetadataWithNotify(i + 0, j + 37, k + 19, 3, 2);
		setBlock(world, i + 0, j + 37, k + 23, Blocks.leaves, 7);
		world.setBlockMetadataWithNotify(i + 0, j + 37, k + 23, 7, 2);
		setBlock(world, i + 0, j + 38, k + 15, Blocks.leaves, 7);
		world.setBlockMetadataWithNotify(i + 0, j + 38, k + 15, 7, 2);
		setBlock(world, i + 0, j + 38, k + 16, Blocks.leaves, 7);
		world.setBlockMetadataWithNotify(i + 0, j + 38, k + 16, 7, 2);
		setBlock(world, i + 0, j + 38, k + 17, Blocks.log, 3);
		world.setBlockMetadataWithNotify(i + 0, j + 38, k + 17, 3, 2);
		setBlock(world, i + 0, j + 38, k + 18, Blocks.leaves, 7);
		world.setBlockMetadataWithNotify(i + 0, j + 38, k + 18, 7, 2);
		setBlock(world, i + 0, j + 38, k + 19, Blocks.leaves, 7);
		world.setBlockMetadataWithNotify(i + 0, j + 38, k + 19, 7, 2);
		setBlock(world, i + 0, j + 38, k + 25, Blocks.leaves, 7);
		world.setBlockMetadataWithNotify(i + 0, j + 38, k + 25, 7, 2);
		setBlock(world, i + 0, j + 38, k + 26, Blocks.leaves, 7);
		world.setBlockMetadataWithNotify(i + 0, j + 38, k + 26, 7, 2);
		setBlock(world, i + 0, j + 38, k + 27, Blocks.log, 3);
		world.setBlockMetadataWithNotify(i + 0, j + 38, k + 27, 3, 2);
		setBlock(world, i + 0, j + 38, k + 28, Blocks.leaves, 7);
		world.setBlockMetadataWithNotify(i + 0, j + 38, k + 28, 7, 2);
		setBlock(world, i + 0, j + 38, k + 29, Blocks.leaves, 7);
		world.setBlockMetadataWithNotify(i + 0, j + 38, k + 29, 7, 2);
		setBlock(world, i + 0, j + 39, k + 15, Blocks.leaves, 7);
		world.setBlockMetadataWithNotify(i + 0, j + 39, k + 15, 7, 2);
		setBlock(world, i + 0, j + 39, k + 16, Blocks.leaves, 7);
		world.setBlockMetadataWithNotify(i + 0, j + 39, k + 16, 7, 2);
		setBlock(world, i + 0, j + 39, k + 17, Blocks.leaves, 7);
		world.setBlockMetadataWithNotify(i + 0, j + 39, k + 17, 7, 2);
		setBlock(world, i + 0, j + 39, k + 18, Blocks.leaves, 7);
		world.setBlockMetadataWithNotify(i + 0, j + 39, k + 18, 7, 2);
		setBlock(world, i + 0, j + 39, k + 19, Blocks.leaves, 7);
		world.setBlockMetadataWithNotify(i + 0, j + 39, k + 19, 7, 2);
		setBlock(world, i + 0, j + 39, k + 25, Blocks.leaves, 7);
		world.setBlockMetadataWithNotify(i + 0, j + 39, k + 25, 7, 2);
		setBlock(world, i + 0, j + 39, k + 26, Blocks.leaves, 7);
		world.setBlockMetadataWithNotify(i + 0, j + 39, k + 26, 7, 2);
		setBlock(world, i + 0, j + 39, k + 27, Blocks.leaves, 7);
		world.setBlockMetadataWithNotify(i + 0, j + 39, k + 27, 7, 2);
		setBlock(world, i + 0, j + 39, k + 28, Blocks.leaves, 7);
		world.setBlockMetadataWithNotify(i + 0, j + 39, k + 28, 7, 2);
		setBlock(world, i + 0, j + 39, k + 29, Blocks.leaves, 7);
		world.setBlockMetadataWithNotify(i + 0, j + 39, k + 29, 7, 2);
		setBlock(world, i + 0, j + 40, k + 16, Blocks.leaves, 7);
		world.setBlockMetadataWithNotify(i + 0, j + 40, k + 16, 7, 2);
		setBlock(world, i + 0, j + 40, k + 17, Blocks.leaves, 7);
		world.setBlockMetadataWithNotify(i + 0, j + 40, k + 17, 7, 2);
		setBlock(world, i + 0, j + 40, k + 18, Blocks.leaves, 7);
		world.setBlockMetadataWithNotify(i + 0, j + 40, k + 18, 7, 2);
		setBlock(world, i + 0, j + 40, k + 19, Blocks.log, 3);
		world.setBlockMetadataWithNotify(i + 0, j + 40, k + 19, 3, 2);
		setBlock(world, i + 0, j + 40, k + 26, Blocks.leaves, 7);
		world.setBlockMetadataWithNotify(i + 0, j + 40, k + 26, 7, 2);
		setBlock(world, i + 0, j + 40, k + 27, Blocks.log, 3);
		world.setBlockMetadataWithNotify(i + 0, j + 40, k + 27, 3, 2);
		setBlock(world, i + 0, j + 40, k + 28, Blocks.leaves, 7);
		world.setBlockMetadataWithNotify(i + 0, j + 40, k + 28, 7, 2);
		setBlock(world, i + 0, j + 41, k + 14, Blocks.leaves, 7);
		world.setBlockMetadataWithNotify(i + 0, j + 41, k + 14, 7, 2);
		setBlock(world, i + 0, j + 41, k + 15, Blocks.leaves, 7);
		world.setBlockMetadataWithNotify(i + 0, j + 41, k + 15, 7, 2);
		setBlock(world, i + 0, j + 41, k + 16, Blocks.leaves, 7);
		world.setBlockMetadataWithNotify(i + 0, j + 41, k + 16, 7, 2);
		setBlock(world, i + 0, j + 41, k + 17, Blocks.leaves, 7);
		world.setBlockMetadataWithNotify(i + 0, j + 41, k + 17, 7, 2);
		setBlock(world, i + 0, j + 41, k + 27, Blocks.leaves, 7);
		world.setBlockMetadataWithNotify(i + 0, j + 41, k + 27, 7, 2);
		setBlock(world, i + 0, j + 42, k + 15, Blocks.leaves, 7);
		world.setBlockMetadataWithNotify(i + 0, j + 42, k + 15, 7, 2);
		setBlock(world, i + 0, j + 43, k + 30, Blocks.leaves, 7);
		world.setBlockMetadataWithNotify(i + 0, j + 43, k + 30, 7, 2);
		setBlock(world, i + 0, j + 43, k + 31, Blocks.leaves, 7);
		world.setBlockMetadataWithNotify(i + 0, j + 43, k + 31, 7, 2);
		setBlock(world, i + 0, j + 44, k + 31, Blocks.leaves, 7);
		world.setBlockMetadataWithNotify(i + 0, j + 44, k + 31, 7, 2);
		setBlock(world, i + 0, j + 46, k + 13, Blocks.leaves, 7);
		world.setBlockMetadataWithNotify(i + 0, j + 46, k + 13, 7, 2);
		setBlock(world, i + 0, j + 46, k + 14, Blocks.leaves, 7);
		world.setBlockMetadataWithNotify(i + 0, j + 46, k + 14, 7, 2);
		setBlock(world, i + 0, j + 46, k + 15, Blocks.leaves, 7);
		world.setBlockMetadataWithNotify(i + 0, j + 46, k + 15, 7, 2);
		setBlock(world, i + 0, j + 46, k + 26, Blocks.log, 3);
		world.setBlockMetadataWithNotify(i + 0, j + 46, k + 26, 3, 2);
		setBlock(world, i + 0, j + 47, k + 14, Blocks.leaves, 7);
		world.setBlockMetadataWithNotify(i + 0, j + 47, k + 14, 7, 2);
		setBlock(world, i + 0, j + 47, k + 20, Blocks.log, 3);
		world.setBlockMetadataWithNotify(i + 0, j + 47, k + 20, 3, 2);
		setBlock(world, i + 0, j + 47, k + 22, Blocks.leaves, 7);
		world.setBlockMetadataWithNotify(i + 0, j + 47, k + 22, 7, 2);
		setBlock(world, i + 0, j + 47, k + 23, Blocks.leaves, 7);
		world.setBlockMetadataWithNotify(i + 0, j + 47, k + 23, 7, 2);
		setBlock(world, i + 0, j + 47, k + 24, Blocks.leaves, 7);
		world.setBlockMetadataWithNotify(i + 0, j + 47, k + 24, 7, 2);
		setBlock(world, i + 0, j + 47, k + 25, Blocks.leaves, 7);
		world.setBlockMetadataWithNotify(i + 0, j + 47, k + 25, 7, 2);
		setBlock(world, i + 0, j + 47, k + 26, Blocks.leaves, 7);
		world.setBlockMetadataWithNotify(i + 0, j + 47, k + 26, 7, 2);
		setBlock(world, i + 0, j + 48, k + 23, Blocks.leaves, 7);
		world.setBlockMetadataWithNotify(i + 0, j + 48, k + 23, 7, 2);
		setBlock(world, i + 0, j + 48, k + 24, Blocks.leaves, 7);
		world.setBlockMetadataWithNotify(i + 0, j + 48, k + 24, 7, 2);
		setBlock(world, i + 0, j + 48, k + 25, Blocks.leaves, 7);
		world.setBlockMetadataWithNotify(i + 0, j + 48, k + 25, 7, 2);
		setBlock(world, i + 0, j + 49, k + 14, Blocks.leaves, 7);
		world.setBlockMetadataWithNotify(i + 0, j + 49, k + 14, 7, 2);
		setBlock(world, i + 0, j + 49, k + 15, Blocks.leaves, 7);
		world.setBlockMetadataWithNotify(i + 0, j + 49, k + 15, 7, 2);
		setBlock(world, i + 0, j + 49, k + 16, Blocks.leaves, 7);
		world.setBlockMetadataWithNotify(i + 0, j + 49, k + 16, 7, 2);
		setBlock(world, i + 0, j + 49, k + 17, Blocks.leaves, 7);
		world.setBlockMetadataWithNotify(i + 0, j + 49, k + 17, 7, 2);
		setBlock(world, i + 0, j + 49, k + 18, Blocks.leaves, 7);
		world.setBlockMetadataWithNotify(i + 0, j + 49, k + 18, 7, 2);
		setBlock(world, i + 0, j + 49, k + 24, Blocks.leaves, 7);
		world.setBlockMetadataWithNotify(i + 0, j + 49, k + 24, 7, 2);
		setBlock(world, i + 0, j + 49, k + 29, Blocks.leaves, 7);
		world.setBlockMetadataWithNotify(i + 0, j + 49, k + 29, 7, 2);
		setBlock(world, i + 0, j + 49, k + 30, Blocks.leaves, 7);
		world.setBlockMetadataWithNotify(i + 0, j + 49, k + 30, 7, 2);
		setBlock(world, i + 0, j + 49, k + 31, Blocks.leaves, 7);
		world.setBlockMetadataWithNotify(i + 0, j + 49, k + 31, 7, 2);
		setBlock(world, i + 0, j + 50, k + 15, Blocks.leaves, 7);
		world.setBlockMetadataWithNotify(i + 0, j + 50, k + 15, 7, 2);
		setBlock(world, i + 0, j + 50, k + 16, Blocks.leaves, 7);
		world.setBlockMetadataWithNotify(i + 0, j + 50, k + 16, 7, 2);
		setBlock(world, i + 0, j + 50, k + 17, Blocks.leaves, 7);
		world.setBlockMetadataWithNotify(i + 0, j + 50, k + 17, 7, 2);
		setBlock(world, i + 0, j + 50, k + 30, Blocks.leaves, 7);
		world.setBlockMetadataWithNotify(i + 0, j + 50, k + 30, 7, 2);
		setBlock(world, i + 0, j + 51, k + 16, Blocks.leaves, 7);
		world.setBlockMetadataWithNotify(i + 0, j + 51, k + 16, 7, 2);
		setBlock(world, i + 0, j + 52, k + 23, Blocks.leaves, 7);
		world.setBlockMetadataWithNotify(i + 0, j + 52, k + 23, 7, 2);
		setBlock(world, i + 0, j + 52, k + 24, Blocks.leaves, 7);
		world.setBlockMetadataWithNotify(i + 0, j + 52, k + 24, 7, 2);
		setBlock(world, i + 0, j + 52, k + 25, Blocks.leaves, 7);
		world.setBlockMetadataWithNotify(i + 0, j + 52, k + 25, 7, 2);
		setBlock(world, i + 0, j + 52, k + 26, Blocks.leaves, 7);
		world.setBlockMetadataWithNotify(i + 0, j + 52, k + 26, 7, 2);
		setBlock(world, i + 0, j + 52, k + 27, Blocks.leaves, 7);
		world.setBlockMetadataWithNotify(i + 0, j + 52, k + 27, 7, 2);
		setBlock(world, i + 0, j + 53, k + 24, Blocks.leaves, 7);
		world.setBlockMetadataWithNotify(i + 0, j + 53, k + 24, 7, 2);
		setBlock(world, i + 0, j + 53, k + 25, Blocks.leaves, 7);
		world.setBlockMetadataWithNotify(i + 0, j + 53, k + 25, 7, 2);
		setBlock(world, i + 0, j + 53, k + 26, Blocks.leaves, 7);
		world.setBlockMetadataWithNotify(i + 0, j + 53, k + 26, 7, 2);
		setBlock(world, i + 0, j + 54, k + 18, Blocks.leaves, 7);
		world.setBlockMetadataWithNotify(i + 0, j + 54, k + 18, 7, 2);
		setBlock(world, i + 0, j + 54, k + 19, Blocks.leaves, 7);
		world.setBlockMetadataWithNotify(i + 0, j + 54, k + 19, 7, 2);
		setBlock(world, i + 0, j + 54, k + 20, Blocks.leaves, 7);
		world.setBlockMetadataWithNotify(i + 0, j + 54, k + 20, 7, 2);
		setBlock(world, i + 0, j + 54, k + 21, Blocks.leaves, 7);
		world.setBlockMetadataWithNotify(i + 0, j + 54, k + 21, 7, 2);
		setBlock(world, i + 0, j + 54, k + 22, Blocks.leaves, 7);
		world.setBlockMetadataWithNotify(i + 0, j + 54, k + 22, 7, 2);
		setBlock(world, i + 0, j + 54, k + 24, Blocks.leaves, 7);
		world.setBlockMetadataWithNotify(i + 0, j + 54, k + 24, 7, 2);
		setBlock(world, i + 0, j + 54, k + 25, Blocks.leaves, 7);
		world.setBlockMetadataWithNotify(i + 0, j + 54, k + 25, 7, 2);
		setBlock(world, i + 0, j + 54, k + 26, Blocks.leaves, 7);
		world.setBlockMetadataWithNotify(i + 0, j + 54, k + 26, 7, 2);
		setBlock(world, i + 0, j + 55, k + 19, Blocks.leaves, 7);
		world.setBlockMetadataWithNotify(i + 0, j + 55, k + 19, 7, 2);
		setBlock(world, i + 0, j + 55, k + 20, Blocks.leaves, 7);
		world.setBlockMetadataWithNotify(i + 0, j + 55, k + 20, 7, 2);
		setBlock(world, i + 0, j + 55, k + 21, Blocks.leaves, 7);
		world.setBlockMetadataWithNotify(i + 0, j + 55, k + 21, 7, 2);
		setBlock(world, i + 0, j + 55, k + 25, Blocks.leaves, 7);
		world.setBlockMetadataWithNotify(i + 0, j + 55, k + 25, 7, 2);
		setBlock(world, i + 0, j + 55, k + 27, Blocks.leaves, 7);
		world.setBlockMetadataWithNotify(i + 0, j + 55, k + 27, 7, 2);
		setBlock(world, i + 0, j + 55, k + 28, Blocks.leaves, 7);
		world.setBlockMetadataWithNotify(i + 0, j + 55, k + 28, 7, 2);
		setBlock(world, i + 0, j + 55, k + 29, Blocks.leaves, 7);
		world.setBlockMetadataWithNotify(i + 0, j + 55, k + 29, 7, 2);
		setBlock(world, i + 0, j + 55, k + 30, Blocks.leaves, 7);
		world.setBlockMetadataWithNotify(i + 0, j + 55, k + 30, 7, 2);
		setBlock(world, i + 0, j + 55, k + 31, Blocks.leaves, 7);
		world.setBlockMetadataWithNotify(i + 0, j + 55, k + 31, 7, 2);
		setBlock(world, i + 0, j + 56, k + 20, Blocks.leaves, 7);
		world.setBlockMetadataWithNotify(i + 0, j + 56, k + 20, 7, 2);
		setBlock(world, i + 0, j + 56, k + 28, Blocks.leaves, 7);
		world.setBlockMetadataWithNotify(i + 0, j + 56, k + 28, 7, 2);
		setBlock(world, i + 0, j + 56, k + 29, Blocks.leaves, 7);
		world.setBlockMetadataWithNotify(i + 0, j + 56, k + 29, 7, 2);
		setBlock(world, i + 0, j + 56, k + 30, Blocks.leaves, 7);
		world.setBlockMetadataWithNotify(i + 0, j + 56, k + 30, 7, 2);
		setBlock(world, i + 0, j + 57, k + 29, Blocks.leaves, 7);
		world.setBlockMetadataWithNotify(i + 0, j + 57, k + 29, 7, 2);
		setBlock(world, i + 1, j + 0, k + 20, Blocks.log, 3);
		world.setBlockMetadataWithNotify(i + 1, j + 0, k + 20, 3, 2);
		setBlock(world, i + 1, j + 0, k + 21, Blocks.log, 3);
		world.setBlockMetadataWithNotify(i + 1, j + 0, k + 21, 3, 2);
		setBlock(world, i + 1, j + 0, k + 22, Blocks.log, 3);
		world.setBlockMetadataWithNotify(i + 1, j + 0, k + 22, 3, 2);
		setBlock(world, i + 1, j + 0, k + 23, Blocks.log, 3);
		world.setBlockMetadataWithNotify(i + 1, j + 0, k + 23, 3, 2);
		setBlock(world, i + 1, j + 0, k + 24, Blocks.log, 3);
		world.setBlockMetadataWithNotify(i + 1, j + 0, k + 24, 3, 2);
		setBlock(world, i + 1, j + 0, k + 25, Blocks.log, 3);
		world.setBlockMetadataWithNotify(i + 1, j + 0, k + 25, 3, 2);
		setBlock(world, i + 1, j + 0, k + 26, Blocks.log, 3);
		world.setBlockMetadataWithNotify(i + 1, j + 0, k + 26, 3, 2);
		setBlock(world, i + 1, j + 0, k + 27, Blocks.log, 3);
		world.setBlockMetadataWithNotify(i + 1, j + 0, k + 27, 3, 2);
		setBlock(world, i + 1, j + 1, k + 21, Blocks.log, 3);
		world.setBlockMetadataWithNotify(i + 1, j + 1, k + 21, 3, 2);
		setBlock(world, i + 1, j + 1, k + 22, Blocks.log, 3);
		world.setBlockMetadataWithNotify(i + 1, j + 1, k + 22, 3, 2);
		setBlock(world, i + 1, j + 1, k + 23, Blocks.log, 3);
		world.setBlockMetadataWithNotify(i + 1, j + 1, k + 23, 3, 2);
		setBlock(world, i + 1, j + 1, k + 24, Blocks.log, 3);
		world.setBlockMetadataWithNotify(i + 1, j + 1, k + 24, 3, 2);
		setBlock(world, i + 1, j + 1, k + 25, Blocks.log, 3);
		world.setBlockMetadataWithNotify(i + 1, j + 1, k + 25, 3, 2);
		setBlock(world, i + 1, j + 18, k + 24, Blocks.log, 3);
		world.setBlockMetadataWithNotify(i + 1, j + 18, k + 24, 3, 2);
		setBlock(world, i + 1, j + 18, k + 28, Blocks.log, 1);
		world.setBlockMetadataWithNotify(i + 1, j + 18, k + 28, 1, 2);
		setBlock(world, i + 1, j + 18, k + 29, Blocks.log, 1);
		world.setBlockMetadataWithNotify(i + 1, j + 18, k + 29, 1, 2);
		setBlock(world, i + 1, j + 19, k + 20, Blocks.log, 1);
		world.setBlockMetadataWithNotify(i + 1, j + 19, k + 20, 1, 2);
		setBlock(world, i + 1, j + 19, k + 23, Blocks.log, 3);
		world.setBlockMetadataWithNotify(i + 1, j + 19, k + 23, 3, 2);
		setBlock(world, i + 1, j + 19, k + 24, Blocks.log, 3);
		world.setBlockMetadataWithNotify(i + 1, j + 19, k + 24, 3, 2);
		setBlock(world, i + 1, j + 19, k + 25, Blocks.log, 3);
		world.setBlockMetadataWithNotify(i + 1, j + 19, k + 25, 3, 2);
		setBlock(world, i + 1, j + 19, k + 27, Blocks.log, 1);
		world.setBlockMetadataWithNotify(i + 1, j + 19, k + 27, 1, 2);
		setBlock(world, i + 1, j + 19, k + 28, Blocks.log, 1);
		world.setBlockMetadataWithNotify(i + 1, j + 19, k + 28, 1, 2);
		setBlock(world, i + 1, j + 19, k + 29, Blocks.log, 1);
		world.setBlockMetadataWithNotify(i + 1, j + 19, k + 29, 1, 2);
		setBlock(world, i + 1, j + 20, k + 18, Blocks.log, 3);
		world.setBlockMetadataWithNotify(i + 1, j + 20, k + 18, 3, 2);
		setBlock(world, i + 1, j + 20, k + 19, Blocks.log, 1);
		world.setBlockMetadataWithNotify(i + 1, j + 20, k + 19, 1, 2);
		setBlock(world, i + 1, j + 20, k + 20, Blocks.log, 1);
		world.setBlockMetadataWithNotify(i + 1, j + 20, k + 20, 1, 2);
		setBlock(world, i + 1, j + 20, k + 21, Blocks.log, 1);
		world.setBlockMetadataWithNotify(i + 1, j + 20, k + 21, 1, 2);
		setBlock(world, i + 1, j + 20, k + 24, Blocks.log, 3);
		world.setBlockMetadataWithNotify(i + 1, j + 20, k + 24, 3, 2);
		setBlock(world, i + 1, j + 20, k + 26, Blocks.log, 3);
		world.setBlockMetadataWithNotify(i + 1, j + 20, k + 26, 3, 2);
		setBlock(world, i + 1, j + 20, k + 27, Blocks.log, 1);
		world.setBlockMetadataWithNotify(i + 1, j + 20, k + 27, 1, 2);
		setBlock(world, i + 1, j + 20, k + 28, Blocks.log, 1);
		world.setBlockMetadataWithNotify(i + 1, j + 20, k + 28, 1, 2);
		setBlock(world, i + 1, j + 20, k + 29, Blocks.log, 1);
		world.setBlockMetadataWithNotify(i + 1, j + 20, k + 29, 1, 2);
		setBlock(world, i + 1, j + 20, k + 30, Blocks.log, 1);
		world.setBlockMetadataWithNotify(i + 1, j + 20, k + 30, 1, 2);
		setBlock(world, i + 1, j + 21, k + 18, Blocks.log, 3);
		world.setBlockMetadataWithNotify(i + 1, j + 21, k + 18, 3, 2);
		setBlock(world, i + 1, j + 21, k + 19, Blocks.log, 3);
		world.setBlockMetadataWithNotify(i + 1, j + 21, k + 19, 3, 2);
		setBlock(world, i + 1, j + 21, k + 20, Blocks.log, 3);
		world.setBlockMetadataWithNotify(i + 1, j + 21, k + 20, 3, 2);
		setBlock(world, i + 1, j + 21, k + 22, Blocks.log, 1);
		world.setBlockMetadataWithNotify(i + 1, j + 21, k + 22, 1, 2);
		setBlock(world, i + 1, j + 21, k + 27, Blocks.log, 3);
		world.setBlockMetadataWithNotify(i + 1, j + 21, k + 27, 3, 2);
		setBlock(world, i + 1, j + 21, k + 28, Blocks.log, 3);
		world.setBlockMetadataWithNotify(i + 1, j + 21, k + 28, 3, 2);
		setBlock(world, i + 1, j + 21, k + 29, Blocks.log, 1);
		world.setBlockMetadataWithNotify(i + 1, j + 21, k + 29, 1, 2);
		setBlock(world, i + 1, j + 21, k + 30, Blocks.log, 1);
		world.setBlockMetadataWithNotify(i + 1, j + 21, k + 30, 1, 2);
		setBlock(world, i + 1, j + 21, k + 31, Blocks.log, 1);
		world.setBlockMetadataWithNotify(i + 1, j + 21, k + 31, 1, 2);
		setBlock(world, i + 1, j + 22, k + 18, Blocks.log, 3);
		world.setBlockMetadataWithNotify(i + 1, j + 22, k + 18, 3, 2);
		setBlock(world, i + 1, j + 22, k + 19, Blocks.log, 3);
		world.setBlockMetadataWithNotify(i + 1, j + 22, k + 19, 3, 2);
		setBlock(world, i + 1, j + 22, k + 20, Blocks.log, 3);
		world.setBlockMetadataWithNotify(i + 1, j + 22, k + 20, 3, 2);
		setBlock(world, i + 1, j + 22, k + 21, Blocks.log, 1);
		world.setBlockMetadataWithNotify(i + 1, j + 22, k + 21, 1, 2);
		setBlock(world, i + 1, j + 22, k + 22, Blocks.log, 1);
		world.setBlockMetadataWithNotify(i + 1, j + 22, k + 22, 1, 2);
		setBlock(world, i + 1, j + 22, k + 23, Blocks.log, 1);
		world.setBlockMetadataWithNotify(i + 1, j + 22, k + 23, 1, 2);
		setBlock(world, i + 1, j + 22, k + 30, Blocks.log, 1);
		world.setBlockMetadataWithNotify(i + 1, j + 22, k + 30, 1, 2);
		setBlock(world, i + 1, j + 22, k + 31, Blocks.log, 1);
		world.setBlockMetadataWithNotify(i + 1, j + 22, k + 31, 1, 2);
		setBlock(world, i + 1, j + 23, k + 22, Blocks.log, 1);
		world.setBlockMetadataWithNotify(i + 1, j + 23, k + 22, 1, 2);
		setBlock(world, i + 1, j + 26, k + 30, Blocks.log, 3);
		world.setBlockMetadataWithNotify(i + 1, j + 26, k + 30, 3, 2);
		setBlock(world, i + 1, j + 27, k + 28, Blocks.leaves, 15);
		world.setBlockMetadataWithNotify(i + 1, j + 27, k + 28, 15, 2);
		setBlock(world, i + 1, j + 27, k + 29, Blocks.leaves, 15);
		world.setBlockMetadataWithNotify(i + 1, j + 27, k + 29, 15, 2);
		setBlock(world, i + 1, j + 27, k + 30, Blocks.leaves, 15);
		world.setBlockMetadataWithNotify(i + 1, j + 27, k + 30, 15, 2);
		setBlock(world, i + 1, j + 27, k + 31, Blocks.leaves, 15);
		world.setBlockMetadataWithNotify(i + 1, j + 27, k + 31, 15, 2);
		setBlock(world, i + 1, j + 28, k + 11, Blocks.log, 3);
		world.setBlockMetadataWithNotify(i + 1, j + 28, k + 11, 3, 2);
		setBlock(world, i + 1, j + 28, k + 12, Blocks.log, 3);
		world.setBlockMetadataWithNotify(i + 1, j + 28, k + 12, 3, 2);
		setBlock(world, i + 1, j + 28, k + 29, Blocks.leaves, 15);
		world.setBlockMetadataWithNotify(i + 1, j + 28, k + 29, 15, 2);
		setBlock(world, i + 1, j + 28, k + 30, Blocks.leaves, 15);
		world.setBlockMetadataWithNotify(i + 1, j + 28, k + 30, 15, 2);
		setBlock(world, i + 1, j + 28, k + 31, Blocks.leaves, 15);
		world.setBlockMetadataWithNotify(i + 1, j + 28, k + 31, 15, 2);
		setBlock(world, i + 1, j + 29, k + 8, Blocks.leaves, 7);
		world.setBlockMetadataWithNotify(i + 1, j + 29, k + 8, 7, 2);
		setBlock(world, i + 1, j + 29, k + 9, Blocks.leaves, 7);
		world.setBlockMetadataWithNotify(i + 1, j + 29, k + 9, 7, 2);
		setBlock(world, i + 1, j + 29, k + 10, Blocks.log, 3);
		world.setBlockMetadataWithNotify(i + 1, j + 29, k + 10, 3, 2);
		setBlock(world, i + 1, j + 29, k + 11, Blocks.leaves, 7);
		world.setBlockMetadataWithNotify(i + 1, j + 29, k + 11, 7, 2);
		setBlock(world, i + 1, j + 29, k + 12, Blocks.leaves, 7);
		world.setBlockMetadataWithNotify(i + 1, j + 29, k + 12, 7, 2);
		setBlock(world, i + 1, j + 29, k + 29, Blocks.log, 3);
		world.setBlockMetadataWithNotify(i + 1, j + 29, k + 29, 3, 2);
		setBlock(world, i + 1, j + 29, k + 30, Blocks.leaves, 15);
		world.setBlockMetadataWithNotify(i + 1, j + 29, k + 30, 15, 2);
		setBlock(world, i + 1, j + 30, k + 8, Blocks.leaves, 7);
		world.setBlockMetadataWithNotify(i + 1, j + 30, k + 8, 7, 2);
		setBlock(world, i + 1, j + 30, k + 9, Blocks.leaves, 7);
		world.setBlockMetadataWithNotify(i + 1, j + 30, k + 9, 7, 2);
		setBlock(world, i + 1, j + 30, k + 10, Blocks.leaves, 7);
		world.setBlockMetadataWithNotify(i + 1, j + 30, k + 10, 7, 2);
		setBlock(world, i + 1, j + 30, k + 11, Blocks.leaves, 7);
		world.setBlockMetadataWithNotify(i + 1, j + 30, k + 11, 7, 2);
		setBlock(world, i + 1, j + 30, k + 12, Blocks.leaves, 7);
		world.setBlockMetadataWithNotify(i + 1, j + 30, k + 12, 7, 2);
		setBlock(world, i + 1, j + 30, k + 15, Blocks.leaves, 7);
		world.setBlockMetadataWithNotify(i + 1, j + 30, k + 15, 7, 2);
		setBlock(world, i + 1, j + 30, k + 16, Blocks.leaves, 7);
		world.setBlockMetadataWithNotify(i + 1, j + 30, k + 16, 7, 2);
		setBlock(world, i + 1, j + 30, k + 17, Blocks.leaves, 7);
		world.setBlockMetadataWithNotify(i + 1, j + 30, k + 17, 7, 2);
		setBlock(world, i + 1, j + 31, k + 9, Blocks.leaves, 7);
		world.setBlockMetadataWithNotify(i + 1, j + 31, k + 9, 7, 2);
		setBlock(world, i + 1, j + 31, k + 10, Blocks.leaves, 7);
		world.setBlockMetadataWithNotify(i + 1, j + 31, k + 10, 7, 2);
		setBlock(world, i + 1, j + 31, k + 11, Blocks.leaves, 7);
		world.setBlockMetadataWithNotify(i + 1, j + 31, k + 11, 7, 2);
		setBlock(world, i + 1, j + 31, k + 16, Blocks.leaves, 7);
		world.setBlockMetadataWithNotify(i + 1, j + 31, k + 16, 7, 2);
		setBlock(world, i + 1, j + 31, k + 19, Blocks.log, 3);
		world.setBlockMetadataWithNotify(i + 1, j + 31, k + 19, 3, 2);
		setBlock(world, i + 1, j + 32, k + 10, Blocks.leaves, 7);
		world.setBlockMetadataWithNotify(i + 1, j + 32, k + 10, 7, 2);
		setBlock(world, i + 1, j + 32, k + 20, Blocks.leaves, 7);
		world.setBlockMetadataWithNotify(i + 1, j + 32, k + 20, 7, 2);
		setBlock(world, i + 1, j + 32, k + 21, Blocks.leaves, 7);
		world.setBlockMetadataWithNotify(i + 1, j + 32, k + 21, 7, 2);
		setBlock(world, i + 1, j + 32, k + 22, Blocks.leaves, 7);
		world.setBlockMetadataWithNotify(i + 1, j + 32, k + 22, 7, 2);
		setBlock(world, i + 1, j + 32, k + 23, Blocks.leaves, 7);
		world.setBlockMetadataWithNotify(i + 1, j + 32, k + 23, 7, 2);
		setBlock(world, i + 1, j + 32, k + 24, Blocks.leaves, 7);
		world.setBlockMetadataWithNotify(i + 1, j + 32, k + 24, 7, 2);
		setBlock(world, i + 1, j + 33, k + 18, Blocks.log, 3);
		world.setBlockMetadataWithNotify(i + 1, j + 33, k + 18, 3, 2);
		setBlock(world, i + 1, j + 33, k + 21, Blocks.leaves, 7);
		world.setBlockMetadataWithNotify(i + 1, j + 33, k + 21, 7, 2);
		setBlock(world, i + 1, j + 33, k + 22, Blocks.leaves, 7);
		world.setBlockMetadataWithNotify(i + 1, j + 33, k + 22, 7, 2);
		setBlock(world, i + 1, j + 33, k + 23, Blocks.leaves, 7);
		world.setBlockMetadataWithNotify(i + 1, j + 33, k + 23, 7, 2);
		setBlock(world, i + 1, j + 34, k + 22, Blocks.leaves, 7);
		world.setBlockMetadataWithNotify(i + 1, j + 34, k + 22, 7, 2);
		setBlock(world, i + 1, j + 34, k + 24, Blocks.log, 3);
		world.setBlockMetadataWithNotify(i + 1, j + 34, k + 24, 3, 2);
		setBlock(world, i + 1, j + 35, k + 21, Blocks.log, 3);
		world.setBlockMetadataWithNotify(i + 1, j + 35, k + 21, 3, 2);
		setBlock(world, i + 1, j + 35, k + 22, Blocks.leaves, 7);
		world.setBlockMetadataWithNotify(i + 1, j + 35, k + 22, 7, 2);
		setBlock(world, i + 1, j + 35, k + 23, Blocks.leaves, 7);
		world.setBlockMetadataWithNotify(i + 1, j + 35, k + 23, 7, 2);
		setBlock(world, i + 1, j + 35, k + 24, Blocks.leaves, 7);
		world.setBlockMetadataWithNotify(i + 1, j + 35, k + 24, 7, 2);
		setBlock(world, i + 1, j + 36, k + 23, Blocks.log, 3);
		world.setBlockMetadataWithNotify(i + 1, j + 36, k + 23, 3, 2);
		setBlock(world, i + 1, j + 37, k + 18, Blocks.log, 3);
		world.setBlockMetadataWithNotify(i + 1, j + 37, k + 18, 3, 2);
		setBlock(world, i + 1, j + 37, k + 19, Blocks.log, 3);
		world.setBlockMetadataWithNotify(i + 1, j + 37, k + 19, 3, 2);
		setBlock(world, i + 1, j + 37, k + 27, Blocks.log, 3);
		world.setBlockMetadataWithNotify(i + 1, j + 37, k + 27, 3, 2);
		setBlock(world, i + 1, j + 38, k + 15, Blocks.leaves, 7);
		world.setBlockMetadataWithNotify(i + 1, j + 38, k + 15, 7, 2);
		setBlock(world, i + 1, j + 38, k + 16, Blocks.leaves, 7);
		world.setBlockMetadataWithNotify(i + 1, j + 38, k + 16, 7, 2);
		setBlock(world, i + 1, j + 38, k + 17, Blocks.leaves, 7);
		world.setBlockMetadataWithNotify(i + 1, j + 38, k + 17, 7, 2);
		setBlock(world, i + 1, j + 38, k + 18, Blocks.leaves, 7);
		world.setBlockMetadataWithNotify(i + 1, j + 38, k + 18, 7, 2);
		setBlock(world, i + 1, j + 38, k + 19, Blocks.leaves, 7);
		world.setBlockMetadataWithNotify(i + 1, j + 38, k + 19, 7, 2);
		setBlock(world, i + 1, j + 38, k + 25, Blocks.leaves, 7);
		world.setBlockMetadataWithNotify(i + 1, j + 38, k + 25, 7, 2);
		setBlock(world, i + 1, j + 38, k + 26, Blocks.leaves, 7);
		world.setBlockMetadataWithNotify(i + 1, j + 38, k + 26, 7, 2);
		setBlock(world, i + 1, j + 38, k + 27, Blocks.log, 3);
		world.setBlockMetadataWithNotify(i + 1, j + 38, k + 27, 3, 2);
		setBlock(world, i + 1, j + 38, k + 28, Blocks.leaves, 7);
		world.setBlockMetadataWithNotify(i + 1, j + 38, k + 28, 7, 2);
		setBlock(world, i + 1, j + 38, k + 29, Blocks.leaves, 7);
		world.setBlockMetadataWithNotify(i + 1, j + 38, k + 29, 7, 2);
		setBlock(world, i + 1, j + 38, k + 30, Blocks.leaves, 7);
		world.setBlockMetadataWithNotify(i + 1, j + 38, k + 30, 7, 2);
		setBlock(world, i + 1, j + 38, k + 31, Blocks.leaves, 7);
		world.setBlockMetadataWithNotify(i + 1, j + 38, k + 31, 7, 2);
		setBlock(world, i + 1, j + 39, k + 16, Blocks.leaves, 7);
		world.setBlockMetadataWithNotify(i + 1, j + 39, k + 16, 7, 2);
		setBlock(world, i + 1, j + 39, k + 17, Blocks.leaves, 7);
		world.setBlockMetadataWithNotify(i + 1, j + 39, k + 17, 7, 2);
		setBlock(world, i + 1, j + 39, k + 18, Blocks.leaves, 7);
		world.setBlockMetadataWithNotify(i + 1, j + 39, k + 18, 7, 2);
		setBlock(world, i + 1, j + 39, k + 26, Blocks.leaves, 7);
		world.setBlockMetadataWithNotify(i + 1, j + 39, k + 26, 7, 2);
		setBlock(world, i + 1, j + 39, k + 27, Blocks.leaves, 7);
		world.setBlockMetadataWithNotify(i + 1, j + 39, k + 27, 7, 2);
		setBlock(world, i + 1, j + 39, k + 28, Blocks.leaves, 7);
		world.setBlockMetadataWithNotify(i + 1, j + 39, k + 28, 7, 2);
		setBlock(world, i + 1, j + 39, k + 31, Blocks.leaves, 7);
		world.setBlockMetadataWithNotify(i + 1, j + 39, k + 31, 7, 2);
		setBlock(world, i + 1, j + 40, k + 17, Blocks.leaves, 7);
		world.setBlockMetadataWithNotify(i + 1, j + 40, k + 17, 7, 2);
		setBlock(world, i + 1, j + 40, k + 20, Blocks.log, 3);
		world.setBlockMetadataWithNotify(i + 1, j + 40, k + 20, 3, 2);
		setBlock(world, i + 1, j + 40, k + 27, Blocks.log, 3);
		world.setBlockMetadataWithNotify(i + 1, j + 40, k + 27, 3, 2);
		setBlock(world, i + 1, j + 41, k + 13, Blocks.leaves, 7);
		world.setBlockMetadataWithNotify(i + 1, j + 41, k + 13, 7, 2);
		setBlock(world, i + 1, j + 41, k + 14, Blocks.leaves, 7);
		world.setBlockMetadataWithNotify(i + 1, j + 41, k + 14, 7, 2);
		setBlock(world, i + 1, j + 41, k + 15, Blocks.leaves, 7);
		world.setBlockMetadataWithNotify(i + 1, j + 41, k + 15, 7, 2);
		setBlock(world, i + 1, j + 41, k + 16, Blocks.leaves, 7);
		world.setBlockMetadataWithNotify(i + 1, j + 41, k + 16, 7, 2);
		setBlock(world, i + 1, j + 41, k + 17, Blocks.leaves, 7);
		world.setBlockMetadataWithNotify(i + 1, j + 41, k + 17, 7, 2);
		setBlock(world, i + 1, j + 41, k + 31, Blocks.leaves, 7);
		world.setBlockMetadataWithNotify(i + 1, j + 41, k + 31, 7, 2);
		setBlock(world, i + 1, j + 42, k + 14, Blocks.leaves, 7);
		world.setBlockMetadataWithNotify(i + 1, j + 42, k + 14, 7, 2);
		setBlock(world, i + 1, j + 42, k + 15, Blocks.leaves, 7);
		world.setBlockMetadataWithNotify(i + 1, j + 42, k + 15, 7, 2);
		setBlock(world, i + 1, j + 42, k + 16, Blocks.leaves, 7);
		world.setBlockMetadataWithNotify(i + 1, j + 42, k + 16, 7, 2);
		setBlock(world, i + 1, j + 42, k + 31, Blocks.log, 3);
		world.setBlockMetadataWithNotify(i + 1, j + 42, k + 31, 3, 2);
		setBlock(world, i + 1, j + 43, k + 15, Blocks.leaves, 7);
		world.setBlockMetadataWithNotify(i + 1, j + 43, k + 15, 7, 2);
		setBlock(world, i + 1, j + 43, k + 30, Blocks.leaves, 7);
		world.setBlockMetadataWithNotify(i + 1, j + 43, k + 30, 7, 2);
		setBlock(world, i + 1, j + 43, k + 31, Blocks.leaves, 7);
		world.setBlockMetadataWithNotify(i + 1, j + 43, k + 31, 7, 2);
		setBlock(world, i + 1, j + 44, k + 13, Blocks.leaves, 7);
		world.setBlockMetadataWithNotify(i + 1, j + 44, k + 13, 7, 2);
		setBlock(world, i + 1, j + 44, k + 14, Blocks.leaves, 7);
		world.setBlockMetadataWithNotify(i + 1, j + 44, k + 14, 7, 2);
		setBlock(world, i + 1, j + 44, k + 15, Blocks.leaves, 7);
		world.setBlockMetadataWithNotify(i + 1, j + 44, k + 15, 7, 2);
		setBlock(world, i + 1, j + 44, k + 30, Blocks.leaves, 7);
		world.setBlockMetadataWithNotify(i + 1, j + 44, k + 30, 7, 2);
		setBlock(world, i + 1, j + 44, k + 31, Blocks.leaves, 7);
		world.setBlockMetadataWithNotify(i + 1, j + 44, k + 31, 7, 2);
		setBlock(world, i + 1, j + 45, k + 14, Blocks.leaves, 7);
		world.setBlockMetadataWithNotify(i + 1, j + 45, k + 14, 7, 2);
		setBlock(world, i + 1, j + 45, k + 31, Blocks.leaves, 7);
		world.setBlockMetadataWithNotify(i + 1, j + 45, k + 31, 7, 2);
		setBlock(world, i + 1, j + 46, k + 13, Blocks.leaves, 7);
		world.setBlockMetadataWithNotify(i + 1, j + 46, k + 13, 7, 2);
		setBlock(world, i + 1, j + 46, k + 14, Blocks.leaves, 7);
		world.setBlockMetadataWithNotify(i + 1, j + 46, k + 14, 7, 2);
		setBlock(world, i + 1, j + 46, k + 15, Blocks.leaves, 7);
		world.setBlockMetadataWithNotify(i + 1, j + 46, k + 15, 7, 2);
		setBlock(world, i + 1, j + 46, k + 26, Blocks.log, 3);
		world.setBlockMetadataWithNotify(i + 1, j + 46, k + 26, 3, 2);
		setBlock(world, i + 1, j + 47, k + 14, Blocks.leaves, 7);
		world.setBlockMetadataWithNotify(i + 1, j + 47, k + 14, 7, 2);
		setBlock(world, i + 1, j + 47, k + 19, Blocks.leaves, 7);
		world.setBlockMetadataWithNotify(i + 1, j + 47, k + 19, 7, 2);
		setBlock(world, i + 1, j + 47, k + 20, Blocks.log, 3);
		world.setBlockMetadataWithNotify(i + 1, j + 47, k + 20, 3, 2);
		setBlock(world, i + 1, j + 47, k + 21, Blocks.leaves, 7);
		world.setBlockMetadataWithNotify(i + 1, j + 47, k + 21, 7, 2);
		setBlock(world, i + 1, j + 47, k + 23, Blocks.leaves, 7);
		world.setBlockMetadataWithNotify(i + 1, j + 47, k + 23, 7, 2);
		setBlock(world, i + 1, j + 47, k + 24, Blocks.leaves, 7);
		world.setBlockMetadataWithNotify(i + 1, j + 47, k + 24, 7, 2);
		setBlock(world, i + 1, j + 47, k + 25, Blocks.leaves, 7);
		world.setBlockMetadataWithNotify(i + 1, j + 47, k + 25, 7, 2);
		setBlock(world, i + 1, j + 48, k + 20, Blocks.leaves, 7);
		world.setBlockMetadataWithNotify(i + 1, j + 48, k + 20, 7, 2);
		setBlock(world, i + 1, j + 48, k + 24, Blocks.leaves, 7);
		world.setBlockMetadataWithNotify(i + 1, j + 48, k + 24, 7, 2);
		setBlock(world, i + 1, j + 49, k + 15, Blocks.leaves, 7);
		world.setBlockMetadataWithNotify(i + 1, j + 49, k + 15, 7, 2);
		setBlock(world, i + 1, j + 49, k + 16, Blocks.leaves, 7);
		world.setBlockMetadataWithNotify(i + 1, j + 49, k + 16, 7, 2);
		setBlock(world, i + 1, j + 49, k + 17, Blocks.leaves, 7);
		world.setBlockMetadataWithNotify(i + 1, j + 49, k + 17, 7, 2);
		setBlock(world, i + 1, j + 49, k + 28, Blocks.leaves, 7);
		world.setBlockMetadataWithNotify(i + 1, j + 49, k + 28, 7, 2);
		setBlock(world, i + 1, j + 49, k + 29, Blocks.leaves, 7);
		world.setBlockMetadataWithNotify(i + 1, j + 49, k + 29, 7, 2);
		setBlock(world, i + 1, j + 49, k + 30, Blocks.leaves, 7);
		world.setBlockMetadataWithNotify(i + 1, j + 49, k + 30, 7, 2);
		setBlock(world, i + 1, j + 49, k + 31, Blocks.leaves, 7);
		world.setBlockMetadataWithNotify(i + 1, j + 49, k + 31, 7, 2);
		setBlock(world, i + 1, j + 50, k + 16, Blocks.leaves, 7);
		world.setBlockMetadataWithNotify(i + 1, j + 50, k + 16, 7, 2);
		setBlock(world, i + 1, j + 50, k + 29, Blocks.leaves, 7);
		world.setBlockMetadataWithNotify(i + 1, j + 50, k + 29, 7, 2);
		setBlock(world, i + 1, j + 50, k + 30, Blocks.leaves, 7);
		world.setBlockMetadataWithNotify(i + 1, j + 50, k + 30, 7, 2);
		setBlock(world, i + 1, j + 50, k + 31, Blocks.leaves, 7);
		world.setBlockMetadataWithNotify(i + 1, j + 50, k + 31, 7, 2);
		setBlock(world, i + 1, j + 51, k + 30, Blocks.leaves, 7);
		world.setBlockMetadataWithNotify(i + 1, j + 51, k + 30, 7, 2);
		setBlock(world, i + 1, j + 52, k + 23, Blocks.leaves, 7);
		world.setBlockMetadataWithNotify(i + 1, j + 52, k + 23, 7, 2);
		setBlock(world, i + 1, j + 52, k + 24, Blocks.leaves, 7);
		world.setBlockMetadataWithNotify(i + 1, j + 52, k + 24, 7, 2);
		setBlock(world, i + 1, j + 52, k + 25, Blocks.log, 3);
		world.setBlockMetadataWithNotify(i + 1, j + 52, k + 25, 3, 2);
		setBlock(world, i + 1, j + 52, k + 26, Blocks.leaves, 7);
		world.setBlockMetadataWithNotify(i + 1, j + 52, k + 26, 7, 2);
		setBlock(world, i + 1, j + 52, k + 27, Blocks.leaves, 7);
		world.setBlockMetadataWithNotify(i + 1, j + 52, k + 27, 7, 2);
		setBlock(world, i + 1, j + 53, k + 23, Blocks.leaves, 7);
		world.setBlockMetadataWithNotify(i + 1, j + 53, k + 23, 7, 2);
		setBlock(world, i + 1, j + 53, k + 24, Blocks.leaves, 7);
		world.setBlockMetadataWithNotify(i + 1, j + 53, k + 24, 7, 2);
		setBlock(world, i + 1, j + 53, k + 25, Blocks.leaves, 7);
		world.setBlockMetadataWithNotify(i + 1, j + 53, k + 25, 7, 2);
		setBlock(world, i + 1, j + 53, k + 26, Blocks.leaves, 7);
		world.setBlockMetadataWithNotify(i + 1, j + 53, k + 26, 7, 2);
		setBlock(world, i + 1, j + 53, k + 27, Blocks.leaves, 7);
		world.setBlockMetadataWithNotify(i + 1, j + 53, k + 27, 7, 2);
		setBlock(world, i + 1, j + 53, k + 29, Blocks.leaves, 7);
		world.setBlockMetadataWithNotify(i + 1, j + 53, k + 29, 7, 2);
		setBlock(world, i + 1, j + 53, k + 30, Blocks.leaves, 7);
		world.setBlockMetadataWithNotify(i + 1, j + 53, k + 30, 7, 2);
		setBlock(world, i + 1, j + 53, k + 31, Blocks.leaves, 7);
		world.setBlockMetadataWithNotify(i + 1, j + 53, k + 31, 7, 2);
		setBlock(world, i + 1, j + 54, k + 18, Blocks.leaves, 7);
		world.setBlockMetadataWithNotify(i + 1, j + 54, k + 18, 7, 2);
		setBlock(world, i + 1, j + 54, k + 19, Blocks.leaves, 7);
		world.setBlockMetadataWithNotify(i + 1, j + 54, k + 19, 7, 2);
		setBlock(world, i + 1, j + 54, k + 20, Blocks.log, 3);
		world.setBlockMetadataWithNotify(i + 1, j + 54, k + 20, 3, 2);
		setBlock(world, i + 1, j + 54, k + 21, Blocks.leaves, 7);
		world.setBlockMetadataWithNotify(i + 1, j + 54, k + 21, 7, 2);
		setBlock(world, i + 1, j + 54, k + 22, Blocks.leaves, 7);
		world.setBlockMetadataWithNotify(i + 1, j + 54, k + 22, 7, 2);
		setBlock(world, i + 1, j + 54, k + 24, Blocks.leaves, 7);
		world.setBlockMetadataWithNotify(i + 1, j + 54, k + 24, 7, 2);
		setBlock(world, i + 1, j + 54, k + 25, Blocks.leaves, 7);
		world.setBlockMetadataWithNotify(i + 1, j + 54, k + 25, 7, 2);
		setBlock(world, i + 1, j + 54, k + 26, Blocks.leaves, 7);
		world.setBlockMetadataWithNotify(i + 1, j + 54, k + 26, 7, 2);
		setBlock(world, i + 1, j + 54, k + 30, Blocks.leaves, 7);
		world.setBlockMetadataWithNotify(i + 1, j + 54, k + 30, 7, 2);
		setBlock(world, i + 1, j + 55, k + 18, Blocks.leaves, 7);
		world.setBlockMetadataWithNotify(i + 1, j + 55, k + 18, 7, 2);
		setBlock(world, i + 1, j + 55, k + 19, Blocks.leaves, 7);
		world.setBlockMetadataWithNotify(i + 1, j + 55, k + 19, 7, 2);
		setBlock(world, i + 1, j + 55, k + 20, Blocks.leaves, 7);
		world.setBlockMetadataWithNotify(i + 1, j + 55, k + 20, 7, 2);
		setBlock(world, i + 1, j + 55, k + 21, Blocks.leaves, 7);
		world.setBlockMetadataWithNotify(i + 1, j + 55, k + 21, 7, 2);
		setBlock(world, i + 1, j + 55, k + 22, Blocks.leaves, 7);
		world.setBlockMetadataWithNotify(i + 1, j + 55, k + 22, 7, 2);
		setBlock(world, i + 1, j + 55, k + 25, Blocks.leaves, 7);
		world.setBlockMetadataWithNotify(i + 1, j + 55, k + 25, 7, 2);
		setBlock(world, i + 1, j + 55, k + 27, Blocks.leaves, 7);
		world.setBlockMetadataWithNotify(i + 1, j + 55, k + 27, 7, 2);
		setBlock(world, i + 1, j + 55, k + 28, Blocks.leaves, 7);
		world.setBlockMetadataWithNotify(i + 1, j + 55, k + 28, 7, 2);
		setBlock(world, i + 1, j + 55, k + 29, Blocks.log, 3);
		world.setBlockMetadataWithNotify(i + 1, j + 55, k + 29, 3, 2);
		setBlock(world, i + 1, j + 55, k + 30, Blocks.leaves, 7);
		world.setBlockMetadataWithNotify(i + 1, j + 55, k + 30, 7, 2);
		setBlock(world, i + 1, j + 55, k + 31, Blocks.leaves, 7);
		world.setBlockMetadataWithNotify(i + 1, j + 55, k + 31, 7, 2);
		setBlock(world, i + 1, j + 56, k + 19, Blocks.leaves, 7);
		world.setBlockMetadataWithNotify(i + 1, j + 56, k + 19, 7, 2);
		setBlock(world, i + 1, j + 56, k + 20, Blocks.leaves, 7);
		world.setBlockMetadataWithNotify(i + 1, j + 56, k + 20, 7, 2);
		setBlock(world, i + 1, j + 56, k + 21, Blocks.leaves, 7);
		world.setBlockMetadataWithNotify(i + 1, j + 56, k + 21, 7, 2);
		setBlock(world, i + 1, j + 56, k + 27, Blocks.leaves, 7);
		world.setBlockMetadataWithNotify(i + 1, j + 56, k + 27, 7, 2);
		setBlock(world, i + 1, j + 56, k + 28, Blocks.leaves, 7);
		world.setBlockMetadataWithNotify(i + 1, j + 56, k + 28, 7, 2);
		setBlock(world, i + 1, j + 56, k + 29, Blocks.leaves, 7);
		world.setBlockMetadataWithNotify(i + 1, j + 56, k + 29, 7, 2);
		setBlock(world, i + 1, j + 56, k + 30, Blocks.leaves, 7);
		world.setBlockMetadataWithNotify(i + 1, j + 56, k + 30, 7, 2);
		setBlock(world, i + 1, j + 56, k + 31, Blocks.leaves, 7);
		world.setBlockMetadataWithNotify(i + 1, j + 56, k + 31, 7, 2);
		setBlock(world, i + 1, j + 57, k + 20, Blocks.leaves, 7);
		world.setBlockMetadataWithNotify(i + 1, j + 57, k + 20, 7, 2);
		setBlock(world, i + 1, j + 57, k + 28, Blocks.leaves, 7);
		world.setBlockMetadataWithNotify(i + 1, j + 57, k + 28, 7, 2);
		setBlock(world, i + 1, j + 57, k + 29, Blocks.leaves, 7);
		world.setBlockMetadataWithNotify(i + 1, j + 57, k + 29, 7, 2);
		setBlock(world, i + 1, j + 57, k + 30, Blocks.leaves, 7);
		world.setBlockMetadataWithNotify(i + 1, j + 57, k + 30, 7, 2);
		setBlock(world, i + 1, j + 58, k + 19, Blocks.leaves, 7);
		world.setBlockMetadataWithNotify(i + 1, j + 58, k + 19, 7, 2);
		setBlock(world, i + 1, j + 58, k + 20, Blocks.leaves, 7);
		world.setBlockMetadataWithNotify(i + 1, j + 58, k + 20, 7, 2);
		setBlock(world, i + 1, j + 58, k + 21, Blocks.leaves, 7);
		world.setBlockMetadataWithNotify(i + 1, j + 58, k + 21, 7, 2);
		setBlock(world, i + 1, j + 58, k + 29, Blocks.leaves, 7);
		world.setBlockMetadataWithNotify(i + 1, j + 58, k + 29, 7, 2);
		setBlock(world, i + 1, j + 59, k + 20, Blocks.leaves, 7);
		world.setBlockMetadataWithNotify(i + 1, j + 59, k + 20, 7, 2);
		setBlock(world, i + 1, j + 63, k + 26, Blocks.leaves, 7);
		world.setBlockMetadataWithNotify(i + 1, j + 63, k + 26, 7, 2);
		setBlock(world, i + 1, j + 63, k + 27, Blocks.leaves, 7);
		world.setBlockMetadataWithNotify(i + 1, j + 63, k + 27, 7, 2);
		setBlock(world, i + 1, j + 63, k + 28, Blocks.leaves, 7);
		world.setBlockMetadataWithNotify(i + 1, j + 63, k + 28, 7, 2);
		setBlock(world, i + 1, j + 64, k + 27, Blocks.leaves, 7);
		world.setBlockMetadataWithNotify(i + 1, j + 64, k + 27, 7, 2);
		setBlock(world, i + 2, j + 0, k + 19, Blocks.log, 3);
		world.setBlockMetadataWithNotify(i + 2, j + 0, k + 19, 3, 2);
		setBlock(world, i + 2, j + 0, k + 20, Blocks.log, 3);
		world.setBlockMetadataWithNotify(i + 2, j + 0, k + 20, 3, 2);
		setBlock(world, i + 2, j + 0, k + 21, Blocks.log, 3);
		world.setBlockMetadataWithNotify(i + 2, j + 0, k + 21, 3, 2);
		setBlock(world, i + 2, j + 0, k + 22, Blocks.log, 3);
		world.setBlockMetadataWithNotify(i + 2, j + 0, k + 22, 3, 2);
		setBlock(world, i + 2, j + 0, k + 23, Blocks.log, 3);
		world.setBlockMetadataWithNotify(i + 2, j + 0, k + 23, 3, 2);
		setBlock(world, i + 2, j + 0, k + 24, Blocks.log, 3);
		world.setBlockMetadataWithNotify(i + 2, j + 0, k + 24, 3, 2);
		setBlock(world, i + 2, j + 0, k + 25, Blocks.log, 3);
		world.setBlockMetadataWithNotify(i + 2, j + 0, k + 25, 3, 2);
		setBlock(world, i + 2, j + 0, k + 26, Blocks.log, 3);
		world.setBlockMetadataWithNotify(i + 2, j + 0, k + 26, 3, 2);
		setBlock(world, i + 2, j + 0, k + 27, Blocks.log, 3);
		world.setBlockMetadataWithNotify(i + 2, j + 0, k + 27, 3, 2);
		setBlock(world, i + 2, j + 0, k + 28, Blocks.log, 3);
		world.setBlockMetadataWithNotify(i + 2, j + 0, k + 28, 3, 2);
		setBlock(world, i + 2, j + 0, k + 29, Blocks.log, 3);
		world.setBlockMetadataWithNotify(i + 2, j + 0, k + 29, 3, 2);
		setBlock(world, i + 2, j + 1, k + 20, Blocks.log, 3);
		world.setBlockMetadataWithNotify(i + 2, j + 1, k + 20, 3, 2);
		setBlock(world, i + 2, j + 1, k + 21, Blocks.log, 3);
		world.setBlockMetadataWithNotify(i + 2, j + 1, k + 21, 3, 2);
		setBlock(world, i + 2, j + 1, k + 22, Blocks.log, 3);
		world.setBlockMetadataWithNotify(i + 2, j + 1, k + 22, 3, 2);
		setBlock(world, i + 2, j + 1, k + 23, Blocks.log, 3);
		world.setBlockMetadataWithNotify(i + 2, j + 1, k + 23, 3, 2);
		setBlock(world, i + 2, j + 1, k + 24, Blocks.log, 3);
		world.setBlockMetadataWithNotify(i + 2, j + 1, k + 24, 3, 2);
		setBlock(world, i + 2, j + 1, k + 25, Blocks.log, 3);
		world.setBlockMetadataWithNotify(i + 2, j + 1, k + 25, 3, 2);
		setBlock(world, i + 2, j + 1, k + 26, Blocks.log, 3);
		world.setBlockMetadataWithNotify(i + 2, j + 1, k + 26, 3, 2);
		setBlock(world, i + 2, j + 1, k + 27, Blocks.log, 3);
		world.setBlockMetadataWithNotify(i + 2, j + 1, k + 27, 3, 2);
		setBlock(world, i + 2, j + 2, k + 23, Blocks.log, 3);
		world.setBlockMetadataWithNotify(i + 2, j + 2, k + 23, 3, 2);
		setBlock(world, i + 2, j + 2, k + 24, Blocks.log, 3);
		world.setBlockMetadataWithNotify(i + 2, j + 2, k + 24, 3, 2);
		setBlock(world, i + 2, j + 2, k + 25, Blocks.log, 3);
		world.setBlockMetadataWithNotify(i + 2, j + 2, k + 25, 3, 2);
		setBlock(world, i + 2, j + 18, k + 24, Blocks.log, 3);
		world.setBlockMetadataWithNotify(i + 2, j + 18, k + 24, 3, 2);
		setBlock(world, i + 2, j + 18, k + 28, Blocks.log, 1);
		world.setBlockMetadataWithNotify(i + 2, j + 18, k + 28, 1, 2);
		setBlock(world, i + 2, j + 19, k + 23, Blocks.log, 3);
		world.setBlockMetadataWithNotify(i + 2, j + 19, k + 23, 3, 2);
		setBlock(world, i + 2, j + 19, k + 24, Blocks.log, 3);
		world.setBlockMetadataWithNotify(i + 2, j + 19, k + 24, 3, 2);
		setBlock(world, i + 2, j + 19, k + 25, Blocks.log, 3);
		world.setBlockMetadataWithNotify(i + 2, j + 19, k + 25, 3, 2);
		setBlock(world, i + 2, j + 19, k + 27, Blocks.log, 1);
		world.setBlockMetadataWithNotify(i + 2, j + 19, k + 27, 1, 2);
		setBlock(world, i + 2, j + 19, k + 28, Blocks.log, 1);
		world.setBlockMetadataWithNotify(i + 2, j + 19, k + 28, 1, 2);
		setBlock(world, i + 2, j + 19, k + 29, Blocks.log, 1);
		world.setBlockMetadataWithNotify(i + 2, j + 19, k + 29, 1, 2);
		setBlock(world, i + 2, j + 20, k + 19, Blocks.log, 3);
		world.setBlockMetadataWithNotify(i + 2, j + 20, k + 19, 3, 2);
		setBlock(world, i + 2, j + 20, k + 20, Blocks.log, 3);
		world.setBlockMetadataWithNotify(i + 2, j + 20, k + 20, 3, 2);
		setBlock(world, i + 2, j + 20, k + 21, Blocks.log, 3);
		world.setBlockMetadataWithNotify(i + 2, j + 20, k + 21, 3, 2);
		setBlock(world, i + 2, j + 20, k + 24, Blocks.log, 3);
		world.setBlockMetadataWithNotify(i + 2, j + 20, k + 24, 3, 2);
		setBlock(world, i + 2, j + 20, k + 26, Blocks.log, 3);
		world.setBlockMetadataWithNotify(i + 2, j + 20, k + 26, 3, 2);
		setBlock(world, i + 2, j + 20, k + 27, Blocks.log, 3);
		world.setBlockMetadataWithNotify(i + 2, j + 20, k + 27, 3, 2);
		setBlock(world, i + 2, j + 20, k + 28, Blocks.log, 1);
		world.setBlockMetadataWithNotify(i + 2, j + 20, k + 28, 1, 2);
		setBlock(world, i + 2, j + 20, k + 30, Blocks.log, 1);
		world.setBlockMetadataWithNotify(i + 2, j + 20, k + 30, 1, 2);
		setBlock(world, i + 2, j + 21, k + 19, Blocks.log, 3);
		world.setBlockMetadataWithNotify(i + 2, j + 21, k + 19, 3, 2);
		setBlock(world, i + 2, j + 21, k + 20, Blocks.log, 3);
		world.setBlockMetadataWithNotify(i + 2, j + 21, k + 20, 3, 2);
		/* 1000 */setBlock(world, i + 2, j + 21, k + 21, Blocks.log, 1);
		/* 1001 */world.setBlockMetadataWithNotify(i + 2, j + 21, k + 21, 1, 2);
		/* 1002 */setBlock(world, i + 2, j + 21, k + 22, Blocks.log, 1);
		/* 1003 */world.setBlockMetadataWithNotify(i + 2, j + 21, k + 22, 1, 2);
		/* 1004 */setBlock(world, i + 2, j + 21, k + 26, Blocks.log, 3);
		/* 1005 */world.setBlockMetadataWithNotify(i + 2, j + 21, k + 26, 3, 2);
		/* 1006 */setBlock(world, i + 2, j + 21, k + 27, Blocks.log, 3);
		/* 1007 */world.setBlockMetadataWithNotify(i + 2, j + 21, k + 27, 3, 2);
		/* 1008 */setBlock(world, i + 2, j + 21, k + 28, Blocks.log, 3);
		/* 1009 */world.setBlockMetadataWithNotify(i + 2, j + 21, k + 28, 3, 2);
		/* 1010 */setBlock(world, i + 2, j + 21, k + 31, Blocks.log, 1);
		/* 1011 */world.setBlockMetadataWithNotify(i + 2, j + 21, k + 31, 1, 2);
		/* 1012 */setBlock(world, i + 2, j + 22, k + 19, Blocks.log, 3);
		/* 1013 */world.setBlockMetadataWithNotify(i + 2, j + 22, k + 19, 3, 2);
		/* 1014 */setBlock(world, i + 2, j + 22, k + 20, Blocks.log, 3);
		/* 1015 */world.setBlockMetadataWithNotify(i + 2, j + 22, k + 20, 3, 2);
		/* 1016 */setBlock(world, i + 2, j + 22, k + 21, Blocks.log, 1);
		/* 1017 */world.setBlockMetadataWithNotify(i + 2, j + 22, k + 21, 1, 2);
		/* 1018 */setBlock(world, i + 2, j + 22, k + 22, Blocks.log, 1);
		/* 1019 */world.setBlockMetadataWithNotify(i + 2, j + 22, k + 22, 1, 2);
		/* 1020 */setBlock(world, i + 2, j + 22, k + 23, Blocks.log, 1);
		/* 1021 */world.setBlockMetadataWithNotify(i + 2, j + 22, k + 23, 1, 2);
		/* 1022 */setBlock(world, i + 2, j + 22, k + 27, Blocks.log, 3);
		/* 1023 */world.setBlockMetadataWithNotify(i + 2, j + 22, k + 27, 3, 2);
		/* 1024 */setBlock(world, i + 2, j + 22, k + 30, Blocks.log, 1);
		/* 1025 */world.setBlockMetadataWithNotify(i + 2, j + 22, k + 30, 1, 2);
		/* 1026 */setBlock(world, i + 2, j + 23, k + 21, Blocks.log, 1);
		/* 1027 */world.setBlockMetadataWithNotify(i + 2, j + 23, k + 21, 1, 2);
		/* 1028 */setBlock(world, i + 2, j + 23, k + 22, Blocks.log, 1);
		/* 1029 */world.setBlockMetadataWithNotify(i + 2, j + 23, k + 22, 1, 2);
		/* 1030 */setBlock(world, i + 2, j + 23, k + 23, Blocks.log, 1);
		/* 1031 */world.setBlockMetadataWithNotify(i + 2, j + 23, k + 23, 1, 2);
		/* 1032 */setBlock(world, i + 2, j + 26, k + 29, Blocks.log, 3);
		/* 1033 */world.setBlockMetadataWithNotify(i + 2, j + 26, k + 29, 3, 2);
		/* 1034 */setBlock(world, i + 2, j + 27, k + 29, Blocks.leaves, 15);
		/* 1035 */world.setBlockMetadataWithNotify(i + 2, j + 27, k + 29, 15, 2);
		/* 1036 */setBlock(world, i + 2, j + 27, k + 30, Blocks.leaves, 15);
		/* 1037 */world.setBlockMetadataWithNotify(i + 2, j + 27, k + 30, 15, 2);
		/* 1038 */setBlock(world, i + 2, j + 27, k + 31, Blocks.leaves, 15);
		/* 1039 */world.setBlockMetadataWithNotify(i + 2, j + 27, k + 31, 15, 2);
		/* 1040 */setBlock(world, i + 2, j + 28, k + 13, Blocks.log, 3);
		/* 1041 */world.setBlockMetadataWithNotify(i + 2, j + 28, k + 13, 3, 2);
		/* 1042 */setBlock(world, i + 2, j + 28, k + 14, Blocks.log, 3);
		/* 1043 */world.setBlockMetadataWithNotify(i + 2, j + 28, k + 14, 3, 2);
		/* 1044 */setBlock(world, i + 2, j + 28, k + 30, Blocks.leaves, 15);
		/* 1045 */world.setBlockMetadataWithNotify(i + 2, j + 28, k + 30, 15, 2);
		/* 1046 */setBlock(world, i + 2, j + 29, k + 8, Blocks.leaves, 7);
		/* 1047 */world.setBlockMetadataWithNotify(i + 2, j + 29, k + 8, 7, 2);
		/* 1048 */setBlock(world, i + 2, j + 29, k + 9, Blocks.leaves, 7);
		/* 1049 */world.setBlockMetadataWithNotify(i + 2, j + 29, k + 9, 7, 2);
		/* 1050 */setBlock(world, i + 2, j + 29, k + 10, Blocks.leaves, 7);
		/* 1051 */world.setBlockMetadataWithNotify(i + 2, j + 29, k + 10, 7, 2);
		/* 1052 */setBlock(world, i + 2, j + 29, k + 11, Blocks.leaves, 7);
		/* 1053 */world.setBlockMetadataWithNotify(i + 2, j + 29, k + 11, 7, 2);
		/* 1054 */setBlock(world, i + 2, j + 29, k + 12, Blocks.leaves, 7);
		/* 1055 */world.setBlockMetadataWithNotify(i + 2, j + 29, k + 12, 7, 2);
		/* 1056 */setBlock(world, i + 2, j + 29, k + 28, Blocks.log, 3);
		/* 1057 */world.setBlockMetadataWithNotify(i + 2, j + 29, k + 28, 3, 2);
		/* 1058 */setBlock(world, i + 2, j + 30, k + 9, Blocks.leaves, 7);
		/* 1059 */world.setBlockMetadataWithNotify(i + 2, j + 30, k + 9, 7, 2);
		/* 1060 */setBlock(world, i + 2, j + 30, k + 10, Blocks.leaves, 7);
		/* 1061 */world.setBlockMetadataWithNotify(i + 2, j + 30, k + 10, 7, 2);
		/* 1062 */setBlock(world, i + 2, j + 30, k + 11, Blocks.leaves, 7);
		/* 1063 */world.setBlockMetadataWithNotify(i + 2, j + 30, k + 11, 7, 2);
		/* 1064 */setBlock(world, i + 2, j + 30, k + 14, Blocks.leaves, 7);
		/* 1065 */world.setBlockMetadataWithNotify(i + 2, j + 30, k + 14, 7, 2);
		/* 1066 */setBlock(world, i + 2, j + 30, k + 15, Blocks.leaves, 7);
		/* 1067 */world.setBlockMetadataWithNotify(i + 2, j + 30, k + 15, 7, 2);
		/* 1068 */setBlock(world, i + 2, j + 30, k + 16, Blocks.leaves, 7);
		/* 1069 */world.setBlockMetadataWithNotify(i + 2, j + 30, k + 16, 7, 2);
		/* 1070 */setBlock(world, i + 2, j + 30, k + 17, Blocks.leaves, 7);
		/* 1071 */world.setBlockMetadataWithNotify(i + 2, j + 30, k + 17, 7, 2);
		/* 1072 */setBlock(world, i + 2, j + 30, k + 18, Blocks.leaves, 7);
		/* 1073 */world.setBlockMetadataWithNotify(i + 2, j + 30, k + 18, 7, 2);
		/* 1074 */setBlock(world, i + 2, j + 31, k + 10, Blocks.leaves, 7);
		/* 1075 */world.setBlockMetadataWithNotify(i + 2, j + 31, k + 10, 7, 2);
		/* 1076 */setBlock(world, i + 2, j + 31, k + 15, Blocks.leaves, 7);
		/* 1077 */world.setBlockMetadataWithNotify(i + 2, j + 31, k + 15, 7, 2);
		/* 1078 */setBlock(world, i + 2, j + 31, k + 16, Blocks.leaves, 7);
		/* 1079 */world.setBlockMetadataWithNotify(i + 2, j + 31, k + 16, 7, 2);
		/* 1080 */setBlock(world, i + 2, j + 31, k + 17, Blocks.leaves, 7);
		/* 1081 */world.setBlockMetadataWithNotify(i + 2, j + 31, k + 17, 7, 2);
		/* 1082 */setBlock(world, i + 2, j + 31, k + 20, Blocks.log, 3);
		/* 1083 */world.setBlockMetadataWithNotify(i + 2, j + 31, k + 20, 3, 2);
		/* 1084 */setBlock(world, i + 2, j + 32, k + 16, Blocks.leaves, 7);
		/* 1085 */world.setBlockMetadataWithNotify(i + 2, j + 32, k + 16, 7, 2);
		/* 1086 */setBlock(world, i + 2, j + 32, k + 20, Blocks.leaves, 7);
		/* 1087 */world.setBlockMetadataWithNotify(i + 2, j + 32, k + 20, 7, 2);
		/* 1088 */setBlock(world, i + 2, j + 32, k + 21, Blocks.leaves, 7);
		/* 1089 */world.setBlockMetadataWithNotify(i + 2, j + 32, k + 21, 7, 2);
		/* 1090 */setBlock(world, i + 2, j + 32, k + 22, Blocks.log, 3);
		/* 1091 */world.setBlockMetadataWithNotify(i + 2, j + 32, k + 22, 3, 2);
		/* 1092 */setBlock(world, i + 2, j + 32, k + 23, Blocks.leaves, 7);
		/* 1093 */world.setBlockMetadataWithNotify(i + 2, j + 32, k + 23, 7, 2);
		/* 1094 */setBlock(world, i + 2, j + 32, k + 24, Blocks.leaves, 7);
		/* 1095 */world.setBlockMetadataWithNotify(i + 2, j + 32, k + 24, 7, 2);
		/* 1096 */setBlock(world, i + 2, j + 33, k + 19, Blocks.log, 3);
		/* 1097 */world.setBlockMetadataWithNotify(i + 2, j + 33, k + 19, 3, 2);
		/* 1098 */setBlock(world, i + 2, j + 33, k + 20, Blocks.leaves, 7);
		/* 1099 */world.setBlockMetadataWithNotify(i + 2, j + 33, k + 20, 7, 2);
		/* 1100 */setBlock(world, i + 2, j + 33, k + 21, Blocks.leaves, 7);
		/* 1101 */world.setBlockMetadataWithNotify(i + 2, j + 33, k + 21, 7, 2);
		/* 1102 */setBlock(world, i + 2, j + 33, k + 22, Blocks.leaves, 7);
		/* 1103 */world.setBlockMetadataWithNotify(i + 2, j + 33, k + 22, 7, 2);
		/* 1104 */setBlock(world, i + 2, j + 33, k + 23, Blocks.leaves, 7);
		/* 1105 */world.setBlockMetadataWithNotify(i + 2, j + 33, k + 23, 7, 2);
		/* 1106 */setBlock(world, i + 2, j + 33, k + 24, Blocks.leaves, 7);
		/* 1107 */world.setBlockMetadataWithNotify(i + 2, j + 33, k + 24, 7, 2);
		/* 1108 */setBlock(world, i + 2, j + 34, k + 21, Blocks.leaves, 7);
		/* 1109 */world.setBlockMetadataWithNotify(i + 2, j + 34, k + 21, 7, 2);
		/* 1110 */setBlock(world, i + 2, j + 34, k + 22, Blocks.leaves, 7);
		/* 1111 */world.setBlockMetadataWithNotify(i + 2, j + 34, k + 22, 7, 2);
		/* 1112 */setBlock(world, i + 2, j + 34, k + 23, Blocks.leaves, 7);
		/* 1113 */world.setBlockMetadataWithNotify(i + 2, j + 34, k + 23, 7, 2);
		/* 1114 */setBlock(world, i + 2, j + 34, k + 24, Blocks.log, 3);
		/* 1115 */world.setBlockMetadataWithNotify(i + 2, j + 34, k + 24, 3, 2);
		/* 1116 */setBlock(world, i + 2, j + 35, k + 21, Blocks.log, 3);
		/* 1117 */world.setBlockMetadataWithNotify(i + 2, j + 35, k + 21, 3, 2);
		/* 1118 */setBlock(world, i + 2, j + 35, k + 22, Blocks.leaves, 7);
		/* 1119 */world.setBlockMetadataWithNotify(i + 2, j + 35, k + 22, 7, 2);
		/* 1120 */setBlock(world, i + 2, j + 36, k + 23, Blocks.log, 3);
		/* 1121 */world.setBlockMetadataWithNotify(i + 2, j + 36, k + 23, 3, 2);
		/* 1122 */setBlock(world, i + 2, j + 37, k + 19, Blocks.log, 3);
		/* 1123 */world.setBlockMetadataWithNotify(i + 2, j + 37, k + 19, 3, 2);
		/* 1124 */setBlock(world, i + 2, j + 37, k + 20, Blocks.log, 3);
		/* 1125 */world.setBlockMetadataWithNotify(i + 2, j + 37, k + 20, 3, 2);
		/* 1126 */setBlock(world, i + 2, j + 37, k + 27, Blocks.log, 3);
		/* 1127 */world.setBlockMetadataWithNotify(i + 2, j + 37, k + 27, 3, 2);
		/* 1128 */setBlock(world, i + 2, j + 38, k + 16, Blocks.leaves, 7);
		/* 1129 */world.setBlockMetadataWithNotify(i + 2, j + 38, k + 16, 7, 2);
		/* 1130 */setBlock(world, i + 2, j + 38, k + 17, Blocks.leaves, 7);
		/* 1131 */world.setBlockMetadataWithNotify(i + 2, j + 38, k + 17, 7, 2);
		/* 1132 */setBlock(world, i + 2, j + 38, k + 18, Blocks.leaves, 7);
		/* 1133 */world.setBlockMetadataWithNotify(i + 2, j + 38, k + 18, 7, 2);
		/* 1134 */setBlock(world, i + 2, j + 38, k + 26, Blocks.log, 3);
		/* 1135 */world.setBlockMetadataWithNotify(i + 2, j + 38, k + 26, 3, 2);
		/* 1136 */setBlock(world, i + 2, j + 38, k + 27, Blocks.leaves, 7);
		/* 1137 */world.setBlockMetadataWithNotify(i + 2, j + 38, k + 27, 7, 2);
		/* 1138 */setBlock(world, i + 2, j + 38, k + 28, Blocks.leaves, 7);
		/* 1139 */world.setBlockMetadataWithNotify(i + 2, j + 38, k + 28, 7, 2);
		/* 1140 */setBlock(world, i + 2, j + 38, k + 29, Blocks.leaves, 7);
		/* 1141 */world.setBlockMetadataWithNotify(i + 2, j + 38, k + 29, 7, 2);
		/* 1142 */setBlock(world, i + 2, j + 38, k + 30, Blocks.leaves, 7);
		/* 1143 */world.setBlockMetadataWithNotify(i + 2, j + 38, k + 30, 7, 2);
		/* 1144 */setBlock(world, i + 2, j + 38, k + 31, Blocks.leaves, 7);
		/* 1145 */world.setBlockMetadataWithNotify(i + 2, j + 38, k + 31, 7, 2);
		/* 1146 */setBlock(world, i + 2, j + 39, k + 17, Blocks.leaves, 7);
		/* 1147 */world.setBlockMetadataWithNotify(i + 2, j + 39, k + 17, 7, 2);
		/* 1148 */setBlock(world, i + 2, j + 39, k + 27, Blocks.leaves, 7);
		/* 1149 */world.setBlockMetadataWithNotify(i + 2, j + 39, k + 27, 7, 2);
		/* 1150 */setBlock(world, i + 2, j + 39, k + 30, Blocks.leaves, 7);
		/* 1151 */world.setBlockMetadataWithNotify(i + 2, j + 39, k + 30, 7, 2);
		/* 1152 */setBlock(world, i + 2, j + 39, k + 31, Blocks.leaves, 7);
		/* 1153 */world.setBlockMetadataWithNotify(i + 2, j + 39, k + 31, 7, 2);
		/* 1154 */setBlock(world, i + 2, j + 40, k + 16, Blocks.log, 3);
		/* 1155 */world.setBlockMetadataWithNotify(i + 2, j + 40, k + 16, 3, 2);
		/* 1156 */setBlock(world, i + 2, j + 40, k + 20, Blocks.log, 3);
		/* 1157 */world.setBlockMetadataWithNotify(i + 2, j + 40, k + 20, 3, 2);
		/* 1158 */setBlock(world, i + 2, j + 40, k + 26, Blocks.log, 3);
		/* 1159 */world.setBlockMetadataWithNotify(i + 2, j + 40, k + 26, 3, 2);
		/* 1160 */setBlock(world, i + 2, j + 40, k + 31, Blocks.leaves, 7);
		/* 1161 */world.setBlockMetadataWithNotify(i + 2, j + 40, k + 31, 7, 2);
		/* 1162 */setBlock(world, i + 2, j + 41, k + 13, Blocks.leaves, 7);
		/* 1163 */world.setBlockMetadataWithNotify(i + 2, j + 41, k + 13, 7, 2);
		/* 1164 */setBlock(world, i + 2, j + 41, k + 14, Blocks.leaves, 7);
		/* 1165 */world.setBlockMetadataWithNotify(i + 2, j + 41, k + 14, 7, 2);
		/* 1166 */setBlock(world, i + 2, j + 41, k + 15, Blocks.log, 3);
		/* 1167 */world.setBlockMetadataWithNotify(i + 2, j + 41, k + 15, 3, 2);
		/* 1168 */setBlock(world, i + 2, j + 41, k + 16, Blocks.leaves, 7);
		/* 1169 */world.setBlockMetadataWithNotify(i + 2, j + 41, k + 16, 7, 2);
		/* 1170 */setBlock(world, i + 2, j + 41, k + 17, Blocks.leaves, 7);
		/* 1171 */world.setBlockMetadataWithNotify(i + 2, j + 41, k + 17, 7, 2);
		/* 1172 */setBlock(world, i + 2, j + 41, k + 30, Blocks.leaves, 7);
		/* 1173 */world.setBlockMetadataWithNotify(i + 2, j + 41, k + 30, 7, 2);
		/* 1174 */setBlock(world, i + 2, j + 41, k + 31, Blocks.leaves, 7);
		/* 1175 */world.setBlockMetadataWithNotify(i + 2, j + 41, k + 31, 7, 2);
		/* 1176 */setBlock(world, i + 2, j + 42, k + 13, Blocks.leaves, 7);
		/* 1177 */world.setBlockMetadataWithNotify(i + 2, j + 42, k + 13, 7, 2);
		/* 1178 */setBlock(world, i + 2, j + 42, k + 14, Blocks.leaves, 7);
		/* 1179 */world.setBlockMetadataWithNotify(i + 2, j + 42, k + 14, 7, 2);
		/* 1180 */setBlock(world, i + 2, j + 42, k + 15, Blocks.leaves, 7);
		/* 1181 */world.setBlockMetadataWithNotify(i + 2, j + 42, k + 15, 7, 2);
		/* 1182 */setBlock(world, i + 2, j + 42, k + 16, Blocks.leaves, 7);
		/* 1183 */world.setBlockMetadataWithNotify(i + 2, j + 42, k + 16, 7, 2);
		/* 1184 */setBlock(world, i + 2, j + 42, k + 17, Blocks.leaves, 7);
		/* 1185 */world.setBlockMetadataWithNotify(i + 2, j + 42, k + 17, 7, 2);
		/* 1186 */setBlock(world, i + 2, j + 42, k + 30, Blocks.log, 3);
		/* 1187 */world.setBlockMetadataWithNotify(i + 2, j + 42, k + 30, 3, 2);
		/* 1188 */setBlock(world, i + 2, j + 42, k + 31, Blocks.leaves, 7);
		/* 1189 */world.setBlockMetadataWithNotify(i + 2, j + 42, k + 31, 7, 2);
		/* 1190 */setBlock(world, i + 2, j + 43, k + 14, Blocks.leaves, 7);
		/* 1191 */world.setBlockMetadataWithNotify(i + 2, j + 43, k + 14, 7, 2);
		/* 1192 */setBlock(world, i + 2, j + 43, k + 15, Blocks.leaves, 7);
		/* 1193 */world.setBlockMetadataWithNotify(i + 2, j + 43, k + 15, 7, 2);
		/* 1194 */setBlock(world, i + 2, j + 43, k + 16, Blocks.leaves, 7);
		/* 1195 */world.setBlockMetadataWithNotify(i + 2, j + 43, k + 16, 7, 2);
		/* 1196 */setBlock(world, i + 2, j + 43, k + 30, Blocks.leaves, 7);
		/* 1197 */world.setBlockMetadataWithNotify(i + 2, j + 43, k + 30, 7, 2);
		/* 1198 */setBlock(world, i + 2, j + 43, k + 31, Blocks.leaves, 7);
		/* 1199 */world.setBlockMetadataWithNotify(i + 2, j + 43, k + 31, 7, 2);
		/* 1200 */setBlock(world, i + 2, j + 44, k + 12, Blocks.leaves, 7);
		/* 1201 */world.setBlockMetadataWithNotify(i + 2, j + 44, k + 12, 7, 2);
		/* 1202 */setBlock(world, i + 2, j + 44, k + 13, Blocks.leaves, 7);
		/* 1203 */world.setBlockMetadataWithNotify(i + 2, j + 44, k + 13, 7, 2);
		/* 1204 */setBlock(world, i + 2, j + 44, k + 14, Blocks.leaves, 7);
		/* 1205 */world.setBlockMetadataWithNotify(i + 2, j + 44, k + 14, 7, 2);
		/* 1206 */setBlock(world, i + 2, j + 44, k + 15, Blocks.leaves, 7);
		/* 1207 */world.setBlockMetadataWithNotify(i + 2, j + 44, k + 15, 7, 2);
		/* 1208 */setBlock(world, i + 2, j + 44, k + 16, Blocks.leaves, 7);
		/* 1209 */world.setBlockMetadataWithNotify(i + 2, j + 44, k + 16, 7, 2);
		/* 1210 */setBlock(world, i + 2, j + 44, k + 31, Blocks.leaves, 7);
		/* 1211 */world.setBlockMetadataWithNotify(i + 2, j + 44, k + 31, 7, 2);
		/* 1212 */setBlock(world, i + 2, j + 45, k + 13, Blocks.leaves, 7);
		/* 1213 */world.setBlockMetadataWithNotify(i + 2, j + 45, k + 13, 7, 2);
		/* 1214 */setBlock(world, i + 2, j + 45, k + 14, Blocks.leaves, 7);
		/* 1215 */world.setBlockMetadataWithNotify(i + 2, j + 45, k + 14, 7, 2);
		/* 1216 */setBlock(world, i + 2, j + 45, k + 15, Blocks.leaves, 7);
		/* 1217 */world.setBlockMetadataWithNotify(i + 2, j + 45, k + 15, 7, 2);
		/* 1218 */setBlock(world, i + 2, j + 45, k + 25, Blocks.log, 3);
		/* 1219 */world.setBlockMetadataWithNotify(i + 2, j + 45, k + 25, 3, 2);
		/* 1220 */setBlock(world, i + 2, j + 46, k + 12, Blocks.leaves, 7);
		/* 1221 */world.setBlockMetadataWithNotify(i + 2, j + 46, k + 12, 7, 2);
		/* 1222 */setBlock(world, i + 2, j + 46, k + 13, Blocks.leaves, 7);
		/* 1223 */world.setBlockMetadataWithNotify(i + 2, j + 46, k + 13, 7, 2);
		/* 1224 */setBlock(world, i + 2, j + 46, k + 14, Blocks.leaves, 7);
		/* 1225 */world.setBlockMetadataWithNotify(i + 2, j + 46, k + 14, 7, 2);
		/* 1226 */setBlock(world, i + 2, j + 46, k + 15, Blocks.leaves, 7);
		/* 1227 */world.setBlockMetadataWithNotify(i + 2, j + 46, k + 15, 7, 2);
		/* 1228 */setBlock(world, i + 2, j + 46, k + 16, Blocks.leaves, 7);
		/* 1229 */world.setBlockMetadataWithNotify(i + 2, j + 46, k + 16, 7, 2);
		/* 1230 */setBlock(world, i + 2, j + 47, k + 13, Blocks.leaves, 7);
		/* 1231 */world.setBlockMetadataWithNotify(i + 2, j + 47, k + 13, 7, 2);
		/* 1232 */setBlock(world, i + 2, j + 47, k + 14, Blocks.leaves, 7);
		/* 1233 */world.setBlockMetadataWithNotify(i + 2, j + 47, k + 14, 7, 2);
		/* 1234 */setBlock(world, i + 2, j + 47, k + 15, Blocks.leaves, 7);
		/* 1235 */world.setBlockMetadataWithNotify(i + 2, j + 47, k + 15, 7, 2);
		/* 1236 */setBlock(world, i + 2, j + 47, k + 18, Blocks.leaves, 7);
		/* 1237 */world.setBlockMetadataWithNotify(i + 2, j + 47, k + 18, 7, 2);
		/* 1238 */setBlock(world, i + 2, j + 47, k + 19, Blocks.leaves, 7);
		/* 1239 */world.setBlockMetadataWithNotify(i + 2, j + 47, k + 19, 7, 2);
		/* 1240 */setBlock(world, i + 2, j + 47, k + 20, Blocks.leaves, 7);
		/* 1241 */world.setBlockMetadataWithNotify(i + 2, j + 47, k + 20, 7, 2);
		/* 1242 */setBlock(world, i + 2, j + 47, k + 21, Blocks.log, 3);
		/* 1243 */world.setBlockMetadataWithNotify(i + 2, j + 47, k + 21, 3, 2);
		/* 1244 */setBlock(world, i + 2, j + 47, k + 22, Blocks.leaves, 7);
		/* 1245 */world.setBlockMetadataWithNotify(i + 2, j + 47, k + 22, 7, 2);
		/* 1246 */setBlock(world, i + 2, j + 48, k + 14, Blocks.leaves, 7);
		/* 1247 */world.setBlockMetadataWithNotify(i + 2, j + 48, k + 14, 7, 2);
		/* 1248 */setBlock(world, i + 2, j + 48, k + 19, Blocks.leaves, 7);
		/* 1249 */world.setBlockMetadataWithNotify(i + 2, j + 48, k + 19, 7, 2);
		/* 1250 */setBlock(world, i + 2, j + 48, k + 20, Blocks.leaves, 7);
		/* 1251 */world.setBlockMetadataWithNotify(i + 2, j + 48, k + 20, 7, 2);
		/* 1252 */setBlock(world, i + 2, j + 48, k + 21, Blocks.leaves, 7);
		/* 1253 */world.setBlockMetadataWithNotify(i + 2, j + 48, k + 21, 7, 2);
		/* 1254 */setBlock(world, i + 2, j + 49, k + 20, Blocks.leaves, 7);
		/* 1255 */world.setBlockMetadataWithNotify(i + 2, j + 49, k + 20, 7, 2);
		/* 1256 */setBlock(world, i + 2, j + 49, k + 28, Blocks.leaves, 7);
		/* 1257 */world.setBlockMetadataWithNotify(i + 2, j + 49, k + 28, 7, 2);
		/* 1258 */setBlock(world, i + 2, j + 49, k + 29, Blocks.leaves, 7);
		/* 1259 */world.setBlockMetadataWithNotify(i + 2, j + 49, k + 29, 7, 2);
		/* 1260 */setBlock(world, i + 2, j + 49, k + 30, Blocks.log, 3);
		/* 1261 */world.setBlockMetadataWithNotify(i + 2, j + 49, k + 30, 3, 2);
		/* 1262 */setBlock(world, i + 2, j + 49, k + 31, Blocks.leaves, 7);
		/* 1263 */world.setBlockMetadataWithNotify(i + 2, j + 49, k + 31, 7, 2);
		/* 1264 */setBlock(world, i + 2, j + 50, k + 28, Blocks.leaves, 7);
		/* 1265 */world.setBlockMetadataWithNotify(i + 2, j + 50, k + 28, 7, 2);
		/* 1266 */setBlock(world, i + 2, j + 50, k + 29, Blocks.leaves, 7);
		/* 1267 */world.setBlockMetadataWithNotify(i + 2, j + 50, k + 29, 7, 2);
		/* 1268 */setBlock(world, i + 2, j + 50, k + 30, Blocks.leaves, 7);
		/* 1269 */world.setBlockMetadataWithNotify(i + 2, j + 50, k + 30, 7, 2);
		/* 1270 */setBlock(world, i + 2, j + 50, k + 31, Blocks.leaves, 7);
		/* 1271 */world.setBlockMetadataWithNotify(i + 2, j + 50, k + 31, 7, 2);
		/* 1272 */setBlock(world, i + 2, j + 51, k + 17, Blocks.leaves, 7);
		/* 1273 */world.setBlockMetadataWithNotify(i + 2, j + 51, k + 17, 7, 2);
		/* 1274 */setBlock(world, i + 2, j + 51, k + 18, Blocks.leaves, 7);
		/* 1275 */world.setBlockMetadataWithNotify(i + 2, j + 51, k + 18, 7, 2);
		/* 1276 */setBlock(world, i + 2, j + 51, k + 19, Blocks.leaves, 7);
		/* 1277 */world.setBlockMetadataWithNotify(i + 2, j + 51, k + 19, 7, 2);
		/* 1278 */setBlock(world, i + 2, j + 51, k + 29, Blocks.leaves, 7);
		/* 1279 */world.setBlockMetadataWithNotify(i + 2, j + 51, k + 29, 7, 2);
		/* 1280 */setBlock(world, i + 2, j + 51, k + 30, Blocks.leaves, 7);
		/* 1281 */world.setBlockMetadataWithNotify(i + 2, j + 51, k + 30, 7, 2);
		/* 1282 */setBlock(world, i + 2, j + 51, k + 31, Blocks.leaves, 7);
		/* 1283 */world.setBlockMetadataWithNotify(i + 2, j + 51, k + 31, 7, 2);
		/* 1284 */setBlock(world, i + 2, j + 52, k + 18, Blocks.leaves, 7);
		/* 1285 */world.setBlockMetadataWithNotify(i + 2, j + 52, k + 18, 7, 2);
		/* 1286 */setBlock(world, i + 2, j + 52, k + 23, Blocks.leaves, 7);
		/* 1287 */world.setBlockMetadataWithNotify(i + 2, j + 52, k + 23, 7, 2);
		/* 1288 */setBlock(world, i + 2, j + 52, k + 24, Blocks.leaves, 7);
		/* 1289 */world.setBlockMetadataWithNotify(i + 2, j + 52, k + 24, 7, 2);
		/* 1290 */setBlock(world, i + 2, j + 52, k + 25, Blocks.leaves, 7);
		/* 1291 */world.setBlockMetadataWithNotify(i + 2, j + 52, k + 25, 7, 2);
		/* 1292 */setBlock(world, i + 2, j + 52, k + 26, Blocks.leaves, 7);
		/* 1293 */world.setBlockMetadataWithNotify(i + 2, j + 52, k + 26, 7, 2);
		/* 1294 */setBlock(world, i + 2, j + 52, k + 27, Blocks.leaves, 7);
		/* 1295 */world.setBlockMetadataWithNotify(i + 2, j + 52, k + 27, 7, 2);
		/* 1296 */setBlock(world, i + 2, j + 52, k + 30, Blocks.leaves, 7);
		/* 1297 */world.setBlockMetadataWithNotify(i + 2, j + 52, k + 30, 7, 2);
		/* 1298 */setBlock(world, i + 2, j + 53, k + 24, Blocks.leaves, 7);
		/* 1299 */world.setBlockMetadataWithNotify(i + 2, j + 53, k + 24, 7, 2);
		/* 1300 */setBlock(world, i + 2, j + 53, k + 25, Blocks.leaves, 7);
		/* 1301 */world.setBlockMetadataWithNotify(i + 2, j + 53, k + 25, 7, 2);
		/* 1302 */setBlock(world, i + 2, j + 53, k + 26, Blocks.leaves, 7);
		/* 1303 */world.setBlockMetadataWithNotify(i + 2, j + 53, k + 26, 7, 2);
		/* 1304 */setBlock(world, i + 2, j + 53, k + 27, Blocks.leaves, 7);
		/* 1305 */world.setBlockMetadataWithNotify(i + 2, j + 53, k + 27, 7, 2);
		/* 1306 */setBlock(world, i + 2, j + 53, k + 28, Blocks.leaves, 7);
		/* 1307 */world.setBlockMetadataWithNotify(i + 2, j + 53, k + 28, 7, 2);
		/* 1308 */setBlock(world, i + 2, j + 53, k + 29, Blocks.leaves, 7);
		/* 1309 */world.setBlockMetadataWithNotify(i + 2, j + 53, k + 29, 7, 2);
		/* 1310 */setBlock(world, i + 2, j + 53, k + 30, Blocks.leaves, 7);
		/* 1311 */world.setBlockMetadataWithNotify(i + 2, j + 53, k + 30, 7, 2);
		/* 1312 */setBlock(world, i + 2, j + 53, k + 31, Blocks.leaves, 7);
		/* 1313 */world.setBlockMetadataWithNotify(i + 2, j + 53, k + 31, 7, 2);
		/* 1314 */setBlock(world, i + 2, j + 54, k + 18, Blocks.leaves, 7);
		/* 1315 */world.setBlockMetadataWithNotify(i + 2, j + 54, k + 18, 7, 2);
		/* 1316 */setBlock(world, i + 2, j + 54, k + 19, Blocks.leaves, 7);
		/* 1317 */world.setBlockMetadataWithNotify(i + 2, j + 54, k + 19, 7, 2);
		/* 1318 */setBlock(world, i + 2, j + 54, k + 20, Blocks.leaves, 7);
		/* 1319 */world.setBlockMetadataWithNotify(i + 2, j + 54, k + 20, 7, 2);
		/* 1320 */setBlock(world, i + 2, j + 54, k + 21, Blocks.leaves, 7);
		/* 1321 */world.setBlockMetadataWithNotify(i + 2, j + 54, k + 21, 7, 2);
		/* 1322 */setBlock(world, i + 2, j + 54, k + 22, Blocks.leaves, 7);
		/* 1323 */world.setBlockMetadataWithNotify(i + 2, j + 54, k + 22, 7, 2);
		/* 1324 */setBlock(world, i + 2, j + 54, k + 25, Blocks.leaves, 7);
		/* 1325 */world.setBlockMetadataWithNotify(i + 2, j + 54, k + 25, 7, 2);
		/* 1326 */setBlock(world, i + 2, j + 54, k + 26, Blocks.leaves, 7);
		/* 1327 */world.setBlockMetadataWithNotify(i + 2, j + 54, k + 26, 7, 2);
		/* 1328 */setBlock(world, i + 2, j + 54, k + 27, Blocks.leaves, 7);
		/* 1329 */world.setBlockMetadataWithNotify(i + 2, j + 54, k + 27, 7, 2);
		/* 1330 */setBlock(world, i + 2, j + 54, k + 28, Blocks.leaves, 7);
		/* 1331 */world.setBlockMetadataWithNotify(i + 2, j + 54, k + 28, 7, 2);
		/* 1332 */setBlock(world, i + 2, j + 54, k + 29, Blocks.log, 3);
		/* 1333 */world.setBlockMetadataWithNotify(i + 2, j + 54, k + 29, 3, 2);
		/* 1334 */setBlock(world, i + 2, j + 54, k + 30, Blocks.leaves, 7);
		/* 1335 */world.setBlockMetadataWithNotify(i + 2, j + 54, k + 30, 7, 2);
		/* 1336 */setBlock(world, i + 2, j + 54, k + 31, Blocks.leaves, 7);
		/* 1337 */world.setBlockMetadataWithNotify(i + 2, j + 54, k + 31, 7, 2);
		/* 1338 */setBlock(world, i + 2, j + 55, k + 19, Blocks.leaves, 7);
		/* 1339 */world.setBlockMetadataWithNotify(i + 2, j + 55, k + 19, 7, 2);
		/* 1340 */setBlock(world, i + 2, j + 55, k + 20, Blocks.leaves, 7);
		/* 1341 */world.setBlockMetadataWithNotify(i + 2, j + 55, k + 20, 7, 2);
		/* 1342 */setBlock(world, i + 2, j + 55, k + 21, Blocks.leaves, 7);
		/* 1343 */world.setBlockMetadataWithNotify(i + 2, j + 55, k + 21, 7, 2);
		/* 1344 */setBlock(world, i + 2, j + 55, k + 26, Blocks.leaves, 7);
		/* 1345 */world.setBlockMetadataWithNotify(i + 2, j + 55, k + 26, 7, 2);
		/* 1346 */setBlock(world, i + 2, j + 55, k + 27, Blocks.leaves, 7);
		/* 1347 */world.setBlockMetadataWithNotify(i + 2, j + 55, k + 27, 7, 2);
		/* 1348 */setBlock(world, i + 2, j + 55, k + 28, Blocks.leaves, 7);
		/* 1349 */world.setBlockMetadataWithNotify(i + 2, j + 55, k + 28, 7, 2);
		/* 1350 */setBlock(world, i + 2, j + 55, k + 29, Blocks.leaves, 7);
		/* 1351 */world.setBlockMetadataWithNotify(i + 2, j + 55, k + 29, 7, 2);
		/* 1352 */setBlock(world, i + 2, j + 55, k + 30, Blocks.leaves, 7);
		/* 1353 */world.setBlockMetadataWithNotify(i + 2, j + 55, k + 30, 7, 2);
		/* 1354 */setBlock(world, i + 2, j + 55, k + 31, Blocks.leaves, 7);
		/* 1355 */world.setBlockMetadataWithNotify(i + 2, j + 55, k + 31, 7, 2);
		/* 1356 */setBlock(world, i + 2, j + 56, k + 20, Blocks.leaves, 7);
		/* 1357 */world.setBlockMetadataWithNotify(i + 2, j + 56, k + 20, 7, 2);
		/* 1358 */setBlock(world, i + 2, j + 56, k + 21, Blocks.leaves, 7);
		/* 1359 */world.setBlockMetadataWithNotify(i + 2, j + 56, k + 21, 7, 2);
		/* 1360 */setBlock(world, i + 2, j + 56, k + 22, Blocks.leaves, 7);
		/* 1361 */world.setBlockMetadataWithNotify(i + 2, j + 56, k + 22, 7, 2);
		/* 1362 */setBlock(world, i + 2, j + 56, k + 28, Blocks.leaves, 7);
		/* 1363 */world.setBlockMetadataWithNotify(i + 2, j + 56, k + 28, 7, 2);
		/* 1364 */setBlock(world, i + 2, j + 56, k + 29, Blocks.leaves, 7);
		/* 1365 */world.setBlockMetadataWithNotify(i + 2, j + 56, k + 29, 7, 2);
		/* 1366 */setBlock(world, i + 2, j + 56, k + 30, Blocks.leaves, 7);
		/* 1367 */world.setBlockMetadataWithNotify(i + 2, j + 56, k + 30, 7, 2);
		/* 1368 */setBlock(world, i + 2, j + 57, k + 21, Blocks.leaves, 7);
		/* 1369 */world.setBlockMetadataWithNotify(i + 2, j + 57, k + 21, 7, 2);
		/* 1370 */setBlock(world, i + 2, j + 57, k + 29, Blocks.leaves, 7);
		/* 1371 */world.setBlockMetadataWithNotify(i + 2, j + 57, k + 29, 7, 2);
		/* 1372 */setBlock(world, i + 2, j + 58, k + 18, Blocks.leaves, 7);
		/* 1373 */world.setBlockMetadataWithNotify(i + 2, j + 58, k + 18, 7, 2);
		/* 1374 */setBlock(world, i + 2, j + 58, k + 19, Blocks.leaves, 7);
		/* 1375 */world.setBlockMetadataWithNotify(i + 2, j + 58, k + 19, 7, 2);
		/* 1376 */setBlock(world, i + 2, j + 58, k + 20, Blocks.leaves, 7);
		/* 1377 */world.setBlockMetadataWithNotify(i + 2, j + 58, k + 20, 7, 2);
		/* 1378 */setBlock(world, i + 2, j + 58, k + 21, Blocks.leaves, 7);
		/* 1379 */world.setBlockMetadataWithNotify(i + 2, j + 58, k + 21, 7, 2);
		/* 1380 */setBlock(world, i + 2, j + 58, k + 22, Blocks.leaves, 7);
		/* 1381 */world.setBlockMetadataWithNotify(i + 2, j + 58, k + 22, 7, 2);
		/* 1382 */setBlock(world, i + 2, j + 59, k + 19, Blocks.leaves, 7);
		/* 1383 */world.setBlockMetadataWithNotify(i + 2, j + 59, k + 19, 7, 2);
		/* 1384 */setBlock(world, i + 2, j + 59, k + 20, Blocks.leaves, 7);
		/* 1385 */world.setBlockMetadataWithNotify(i + 2, j + 59, k + 20, 7, 2);
		/* 1386 */setBlock(world, i + 2, j + 59, k + 21, Blocks.leaves, 7);
		/* 1387 */world.setBlockMetadataWithNotify(i + 2, j + 59, k + 21, 7, 2);
		/* 1388 */setBlock(world, i + 2, j + 59, k + 26, Blocks.leaves, 7);
		/* 1389 */world.setBlockMetadataWithNotify(i + 2, j + 59, k + 26, 7, 2);
		/* 1390 */setBlock(world, i + 2, j + 59, k + 27, Blocks.leaves, 7);
		/* 1391 */world.setBlockMetadataWithNotify(i + 2, j + 59, k + 27, 7, 2);
		/* 1392 */setBlock(world, i + 2, j + 59, k + 28, Blocks.leaves, 7);
		/* 1393 */world.setBlockMetadataWithNotify(i + 2, j + 59, k + 28, 7, 2);
		/* 1394 */setBlock(world, i + 2, j + 60, k + 20, Blocks.leaves, 7);
		/* 1395 */world.setBlockMetadataWithNotify(i + 2, j + 60, k + 20, 7, 2);
		/* 1396 */setBlock(world, i + 2, j + 60, k + 27, Blocks.leaves, 7);
		/* 1397 */world.setBlockMetadataWithNotify(i + 2, j + 60, k + 27, 7, 2);
		/* 1398 */setBlock(world, i + 2, j + 61, k + 18, Blocks.leaves, 7);
		/* 1399 */world.setBlockMetadataWithNotify(i + 2, j + 61, k + 18, 7, 2);
		/* 1400 */setBlock(world, i + 2, j + 61, k + 19, Blocks.leaves, 7);
		/* 1401 */world.setBlockMetadataWithNotify(i + 2, j + 61, k + 19, 7, 2);
		/* 1402 */setBlock(world, i + 2, j + 61, k + 20, Blocks.leaves, 7);
		/* 1403 */world.setBlockMetadataWithNotify(i + 2, j + 61, k + 20, 7, 2);
		/* 1404 */setBlock(world, i + 2, j + 62, k + 19, Blocks.leaves, 7);
		/* 1405 */world.setBlockMetadataWithNotify(i + 2, j + 62, k + 19, 7, 2);
		/* 1406 */setBlock(world, i + 2, j + 63, k + 25, Blocks.leaves, 7);
		/* 1407 */world.setBlockMetadataWithNotify(i + 2, j + 63, k + 25, 7, 2);
		/* 1408 */setBlock(world, i + 2, j + 63, k + 26, Blocks.leaves, 7);
		/* 1409 */world.setBlockMetadataWithNotify(i + 2, j + 63, k + 26, 7, 2);
		/* 1410 */setBlock(world, i + 2, j + 63, k + 27, Blocks.leaves, 7);
		/* 1411 */world.setBlockMetadataWithNotify(i + 2, j + 63, k + 27, 7, 2);
		/* 1412 */setBlock(world, i + 2, j + 63, k + 28, Blocks.leaves, 7);
		/* 1413 */world.setBlockMetadataWithNotify(i + 2, j + 63, k + 28, 7, 2);
		/* 1414 */setBlock(world, i + 2, j + 63, k + 29, Blocks.leaves, 7);
		/* 1415 */world.setBlockMetadataWithNotify(i + 2, j + 63, k + 29, 7, 2);
		/* 1416 */setBlock(world, i + 2, j + 64, k + 26, Blocks.leaves, 7);
		/* 1417 */world.setBlockMetadataWithNotify(i + 2, j + 64, k + 26, 7, 2);
		/* 1418 */setBlock(world, i + 2, j + 64, k + 27, Blocks.leaves, 7);
		/* 1419 */world.setBlockMetadataWithNotify(i + 2, j + 64, k + 27, 7, 2);
		/* 1420 */setBlock(world, i + 2, j + 64, k + 28, Blocks.leaves, 7);
		/* 1421 */world.setBlockMetadataWithNotify(i + 2, j + 64, k + 28, 7, 2);
		/* 1422 */setBlock(world, i + 2, j + 65, k + 27, Blocks.leaves, 7);
		/* 1423 */world.setBlockMetadataWithNotify(i + 2, j + 65, k + 27, 7, 2);
		/* 1424 */setBlock(world, i + 3, j + 0, k + 19, Blocks.log, 3);
		/* 1425 */world.setBlockMetadataWithNotify(i + 3, j + 0, k + 19, 3, 2);
		/* 1426 */setBlock(world, i + 3, j + 0, k + 20, Blocks.log, 3);
		/* 1427 */world.setBlockMetadataWithNotify(i + 3, j + 0, k + 20, 3, 2);
		/* 1428 */setBlock(world, i + 3, j + 0, k + 21, Blocks.log, 3);
		/* 1429 */world.setBlockMetadataWithNotify(i + 3, j + 0, k + 21, 3, 2);
		/* 1430 */setBlock(world, i + 3, j + 0, k + 22, Blocks.log, 3);
		/* 1431 */world.setBlockMetadataWithNotify(i + 3, j + 0, k + 22, 3, 2);
		/* 1432 */setBlock(world, i + 3, j + 0, k + 23, Blocks.log, 3);
		/* 1433 */world.setBlockMetadataWithNotify(i + 3, j + 0, k + 23, 3, 2);
		/* 1434 */setBlock(world, i + 3, j + 0, k + 24, Blocks.log, 3);
		/* 1435 */world.setBlockMetadataWithNotify(i + 3, j + 0, k + 24, 3, 2);
		/* 1436 */setBlock(world, i + 3, j + 0, k + 25, Blocks.log, 3);
		/* 1437 */world.setBlockMetadataWithNotify(i + 3, j + 0, k + 25, 3, 2);
		/* 1438 */setBlock(world, i + 3, j + 0, k + 26, Blocks.log, 3);
		/* 1439 */world.setBlockMetadataWithNotify(i + 3, j + 0, k + 26, 3, 2);
		/* 1440 */setBlock(world, i + 3, j + 0, k + 27, Blocks.log, 3);
		/* 1441 */world.setBlockMetadataWithNotify(i + 3, j + 0, k + 27, 3, 2);
		/* 1442 */setBlock(world, i + 3, j + 0, k + 28, Blocks.log, 3);
		/* 1443 */world.setBlockMetadataWithNotify(i + 3, j + 0, k + 28, 3, 2);
		/* 1444 */setBlock(world, i + 3, j + 0, k + 29, Blocks.log, 3);
		/* 1445 */world.setBlockMetadataWithNotify(i + 3, j + 0, k + 29, 3, 2);
		/* 1446 */setBlock(world, i + 3, j + 0, k + 30, Blocks.log, 3);
		/* 1447 */world.setBlockMetadataWithNotify(i + 3, j + 0, k + 30, 3, 2);
		/* 1448 */setBlock(world, i + 3, j + 1, k + 19, Blocks.log, 3);
		/* 1449 */world.setBlockMetadataWithNotify(i + 3, j + 1, k + 19, 3, 2);
		/* 1450 */setBlock(world, i + 3, j + 1, k + 20, Blocks.log, 3);
		/* 1451 */world.setBlockMetadataWithNotify(i + 3, j + 1, k + 20, 3, 2);
		/* 1452 */setBlock(world, i + 3, j + 1, k + 21, Blocks.log, 3);
		/* 1453 */world.setBlockMetadataWithNotify(i + 3, j + 1, k + 21, 3, 2);
		/* 1454 */setBlock(world, i + 3, j + 1, k + 22, Blocks.log, 3);
		/* 1455 */world.setBlockMetadataWithNotify(i + 3, j + 1, k + 22, 3, 2);
		/* 1456 */setBlock(world, i + 3, j + 1, k + 23, Blocks.log, 3);
		/* 1457 */world.setBlockMetadataWithNotify(i + 3, j + 1, k + 23, 3, 2);
		/* 1458 */setBlock(world, i + 3, j + 1, k + 24, Blocks.log, 3);
		/* 1459 */world.setBlockMetadataWithNotify(i + 3, j + 1, k + 24, 3, 2);
		/* 1460 */setBlock(world, i + 3, j + 1, k + 25, Blocks.log, 3);
		/* 1461 */world.setBlockMetadataWithNotify(i + 3, j + 1, k + 25, 3, 2);
		/* 1462 */setBlock(world, i + 3, j + 1, k + 26, Blocks.log, 3);
		/* 1463 */world.setBlockMetadataWithNotify(i + 3, j + 1, k + 26, 3, 2);
		/* 1464 */setBlock(world, i + 3, j + 1, k + 27, Blocks.log, 3);
		/* 1465 */world.setBlockMetadataWithNotify(i + 3, j + 1, k + 27, 3, 2);
		/* 1466 */setBlock(world, i + 3, j + 1, k + 28, Blocks.log, 3);
		/* 1467 */world.setBlockMetadataWithNotify(i + 3, j + 1, k + 28, 3, 2);
		/* 1468 */setBlock(world, i + 3, j + 1, k + 29, Blocks.log, 3);
		/* 1469 */world.setBlockMetadataWithNotify(i + 3, j + 1, k + 29, 3, 2);
		/* 1470 */setBlock(world, i + 3, j + 2, k + 21, Blocks.log, 3);
		/* 1471 */world.setBlockMetadataWithNotify(i + 3, j + 2, k + 21, 3, 2);
		/* 1472 */setBlock(world, i + 3, j + 2, k + 22, Blocks.log, 3);
		/* 1473 */world.setBlockMetadataWithNotify(i + 3, j + 2, k + 22, 3, 2);
		/* 1474 */setBlock(world, i + 3, j + 2, k + 23, Blocks.log, 3);
		/* 1475 */world.setBlockMetadataWithNotify(i + 3, j + 2, k + 23, 3, 2);
		/* 1476 */setBlock(world, i + 3, j + 2, k + 24, Blocks.log, 3);
		/* 1477 */world.setBlockMetadataWithNotify(i + 3, j + 2, k + 24, 3, 2);
		/* 1478 */setBlock(world, i + 3, j + 2, k + 25, Blocks.log, 3);
		/* 1479 */world.setBlockMetadataWithNotify(i + 3, j + 2, k + 25, 3, 2);
		/* 1480 */setBlock(world, i + 3, j + 2, k + 26, Blocks.log, 3);
		/* 1481 */world.setBlockMetadataWithNotify(i + 3, j + 2, k + 26, 3, 2);
		/* 1482 */setBlock(world, i + 3, j + 2, k + 27, Blocks.log, 3);
		/* 1483 */world.setBlockMetadataWithNotify(i + 3, j + 2, k + 27, 3, 2);
		/* 1484 */setBlock(world, i + 3, j + 3, k + 22, Blocks.log, 3);
		/* 1485 */world.setBlockMetadataWithNotify(i + 3, j + 3, k + 22, 3, 2);
		/* 1486 */setBlock(world, i + 3, j + 3, k + 23, Blocks.log, 3);
		/* 1487 */world.setBlockMetadataWithNotify(i + 3, j + 3, k + 23, 3, 2);
		/* 1488 */setBlock(world, i + 3, j + 3, k + 24, Blocks.log, 3);
		/* 1489 */world.setBlockMetadataWithNotify(i + 3, j + 3, k + 24, 3, 2);
		/* 1490 */setBlock(world, i + 3, j + 3, k + 25, Blocks.log, 3);
		/* 1491 */world.setBlockMetadataWithNotify(i + 3, j + 3, k + 25, 3, 2);
		/* 1492 */setBlock(world, i + 3, j + 3, k + 26, Blocks.log, 3);
		/* 1493 */world.setBlockMetadataWithNotify(i + 3, j + 3, k + 26, 3, 2);
		/* 1494 */setBlock(world, i + 3, j + 4, k + 22, Blocks.log, 3);
		/* 1495 */world.setBlockMetadataWithNotify(i + 3, j + 4, k + 22, 3, 2);
		/* 1496 */setBlock(world, i + 3, j + 4, k + 23, Blocks.log, 3);
		/* 1497 */world.setBlockMetadataWithNotify(i + 3, j + 4, k + 23, 3, 2);
		/* 1498 */setBlock(world, i + 3, j + 4, k + 24, Blocks.log, 3);
		/* 1499 */world.setBlockMetadataWithNotify(i + 3, j + 4, k + 24, 3, 2);
		/* 1500 */setBlock(world, i + 3, j + 4, k + 25, Blocks.log, 3);
		/* 1501 */world.setBlockMetadataWithNotify(i + 3, j + 4, k + 25, 3, 2);
		/* 1502 */setBlock(world, i + 3, j + 4, k + 26, Blocks.log, 3);
		/* 1503 */world.setBlockMetadataWithNotify(i + 3, j + 4, k + 26, 3, 2);
		/* 1504 */setBlock(world, i + 3, j + 5, k + 23, Blocks.log, 3);
		/* 1505 */world.setBlockMetadataWithNotify(i + 3, j + 5, k + 23, 3, 2);
		/* 1506 */setBlock(world, i + 3, j + 5, k + 24, Blocks.log, 3);
		/* 1507 */world.setBlockMetadataWithNotify(i + 3, j + 5, k + 24, 3, 2);
		/* 1508 */setBlock(world, i + 3, j + 5, k + 25, Blocks.log, 3);
		/* 1509 */world.setBlockMetadataWithNotify(i + 3, j + 5, k + 25, 3, 2);
		/* 1510 */setBlock(world, i + 3, j + 6, k + 23, Blocks.log, 3);
		/* 1511 */world.setBlockMetadataWithNotify(i + 3, j + 6, k + 23, 3, 2);
		/* 1512 */setBlock(world, i + 3, j + 6, k + 24, Blocks.log, 3);
		/* 1513 */world.setBlockMetadataWithNotify(i + 3, j + 6, k + 24, 3, 2);
		/* 1514 */setBlock(world, i + 3, j + 6, k + 25, Blocks.log, 3);
		/* 1515 */world.setBlockMetadataWithNotify(i + 3, j + 6, k + 25, 3, 2);
		/* 1516 */setBlock(world, i + 3, j + 7, k + 23, Blocks.log, 3);
		/* 1517 */world.setBlockMetadataWithNotify(i + 3, j + 7, k + 23, 3, 2);
		/* 1518 */setBlock(world, i + 3, j + 7, k + 24, Blocks.log, 3);
		/* 1519 */world.setBlockMetadataWithNotify(i + 3, j + 7, k + 24, 3, 2);
		/* 1520 */setBlock(world, i + 3, j + 7, k + 25, Blocks.log, 3);
		/* 1521 */world.setBlockMetadataWithNotify(i + 3, j + 7, k + 25, 3, 2);
		/* 1522 */setBlock(world, i + 3, j + 8, k + 24, Blocks.log, 3);
		/* 1523 */world.setBlockMetadataWithNotify(i + 3, j + 8, k + 24, 3, 2);
		/* 1524 */setBlock(world, i + 3, j + 18, k + 24, Blocks.log, 3);
		/* 1525 */world.setBlockMetadataWithNotify(i + 3, j + 18, k + 24, 3, 2);
		/* 1526 */setBlock(world, i + 3, j + 18, k + 25, Blocks.log, 1);
		/* 1527 */world.setBlockMetadataWithNotify(i + 3, j + 18, k + 25, 1, 2);
		/* 1528 */setBlock(world, i + 3, j + 18, k + 26, Blocks.log, 1);
		/* 1529 */world.setBlockMetadataWithNotify(i + 3, j + 18, k + 26, 1, 2);
		/* 1530 */setBlock(world, i + 3, j + 18, k + 27, Blocks.log, 1);
		/* 1531 */world.setBlockMetadataWithNotify(i + 3, j + 18, k + 27, 1, 2);
		/* 1532 */setBlock(world, i + 3, j + 19, k + 23, Blocks.log, 3);
		/* 1533 */world.setBlockMetadataWithNotify(i + 3, j + 19, k + 23, 3, 2);
		/* 1534 */setBlock(world, i + 3, j + 19, k + 24, Blocks.log, 3);
		/* 1535 */world.setBlockMetadataWithNotify(i + 3, j + 19, k + 24, 3, 2);
		/* 1536 */setBlock(world, i + 3, j + 19, k + 25, Blocks.log, 3);
		/* 1537 */world.setBlockMetadataWithNotify(i + 3, j + 19, k + 25, 3, 2);
		/* 1538 */setBlock(world, i + 3, j + 19, k + 26, Blocks.log, 1);
		/* 1539 */world.setBlockMetadataWithNotify(i + 3, j + 19, k + 26, 1, 2);
		/* 1540 */setBlock(world, i + 3, j + 19, k + 27, Blocks.log, 3);
		/* 1541 */world.setBlockMetadataWithNotify(i + 3, j + 19, k + 27, 3, 2);
		/* 1542 */setBlock(world, i + 3, j + 20, k + 19, Blocks.log, 3);
		/* 1543 */world.setBlockMetadataWithNotify(i + 3, j + 20, k + 19, 3, 2);
		/* 1544 */setBlock(world, i + 3, j + 20, k + 20, Blocks.log, 3);
		/* 1545 */world.setBlockMetadataWithNotify(i + 3, j + 20, k + 20, 3, 2);
		/* 1546 */setBlock(world, i + 3, j + 20, k + 21, Blocks.log, 3);
		/* 1547 */world.setBlockMetadataWithNotify(i + 3, j + 20, k + 21, 3, 2);
		/* 1548 */setBlock(world, i + 3, j + 20, k + 24, Blocks.log, 3);
		/* 1549 */world.setBlockMetadataWithNotify(i + 3, j + 20, k + 24, 3, 2);
		/* 1550 */setBlock(world, i + 3, j + 20, k + 26, Blocks.log, 3);
		/* 1551 */world.setBlockMetadataWithNotify(i + 3, j + 20, k + 26, 3, 2);
		/* 1552 */setBlock(world, i + 3, j + 20, k + 27, Blocks.log, 3);
		/* 1553 */world.setBlockMetadataWithNotify(i + 3, j + 20, k + 27, 3, 2);
		/* 1554 */setBlock(world, i + 3, j + 20, k + 28, Blocks.log, 3);
		/* 1555 */world.setBlockMetadataWithNotify(i + 3, j + 20, k + 28, 3, 2);
		/* 1556 */setBlock(world, i + 3, j + 21, k + 19, Blocks.log, 3);
		/* 1557 */world.setBlockMetadataWithNotify(i + 3, j + 21, k + 19, 3, 2);
		/* 1558 */setBlock(world, i + 3, j + 21, k + 20, Blocks.log, 3);
		/* 1559 */world.setBlockMetadataWithNotify(i + 3, j + 21, k + 20, 3, 2);
		/* 1560 */setBlock(world, i + 3, j + 21, k + 21, Blocks.log, 3);
