package com.parzivail.pswm.world.gen.wookietree;




import com.parzivail.pswm.utils.LootGenUtils;
import com.parzivail.pswm.utils.NPCType;
import com.parzivail.pswm.utils.SpawnUtils;



import cpw.mods.fml.common.IWorldGenerator;



import java.util.Random;



import net.minecraft.block.Block;

import net.minecraft.init.Blocks;

import net.minecraft.tileentity.TileEntityChest;

import net.minecraft.world.World;

import net.minecraft.world.WorldProvider;

import net.minecraft.world.chunk.IChunkProvider;

import net.minecraft.world.gen.feature.WorldGenerator;


public class WT_11
extends WorldGenerator implements IWorldGenerator

{
	protected Block[] getValidSpawnBlocks()
	
	{
		return new Block[0];
		}

	
	public boolean locationIsValidSpawn(World world, int i, int j, int k)
	
	{
		int distanceToAir = 0;
		Block check = world.getBlock(i, j, k);
		
		while (check != Blocks.air)
		{
			if (distanceToAir > 3) { return false;
			}
			
			distanceToAir++;
			check = world.getBlock(i, j + distanceToAir, k);
			}
		
		j += distanceToAir - 1;
		
		Block block = world.getBlock(i, j, k);
		Block blockAbove = world.getBlock(i, j + 1, k);
		Block blockBelow = world.getBlock(i, j - 1, k);
		
		for (Block x : getValidSpawnBlocks())
		{
			if (blockAbove != Blocks.air) { return false;
			}
			if (block == x) return true;
			if ((block == Blocks.snow) && (blockBelow == x)) { return true;
			}
			}
		
		return false;
		}

	
	
	
	public void generate(Random random, int chunkX, int chunkZ, World world, IChunkProvider chunkGenerator, IChunkProvider chunkProvider)
	{
	}

	
	
	public void setBlock(World world, int x, int y, int z, Block block, int metadata)
	
	{
		world.setBlock(x, y, z, block, metadata, 2);
		}

	
	public boolean generate(World world, Random rand, int i, int j, int k)
	
	{
		k -= 10;
		i -= 10;
		
		setBlock(world, i + 0, j + 5, k + 9, Blocks.spruce_stairs, 0);
		setBlock(world, i + 0, j + 5, k + 10, Blocks.spruce_stairs, 0);
		setBlock(world, i + 0, j + 13, k + 9, Blocks.spruce_stairs, 0);
		setBlock(world, i + 0, j + 13, k + 10, Blocks.spruce_stairs, 0);
		setBlock(world, i + 0, j + 27, k + 5, Blocks.spruce_stairs, 0);
		setBlock(world, i + 0, j + 27, k + 6, Blocks.crafting_table, 0);
		setBlock(world, i + 1, j + 6, k + 9, Blocks.spruce_stairs, 0);
		setBlock(world, i + 1, j + 6, k + 10, Blocks.spruce_stairs, 0);
		setBlock(world, i + 1, j + 14, k + 9, Blocks.spruce_stairs, 0);
		setBlock(world, i + 1, j + 14, k + 10, Blocks.spruce_stairs, 0);
		SpawnUtils.spawnNPC(NPCType.WOOKIETREE, world, i + 3, j + 27, k + 3);
		SpawnUtils.spawnNPC(NPCType.WOOKIETREE, world, i + 3, j + 27, k + 7);
		setBlock(world, i + 4, j + 27, k + 0, Blocks.fence, 0);
		setBlock(world, i + 4, j + 27, k + 10, Blocks.fence, 0);
		setBlock(world, i + 4, j + 29, k + 12, Blocks.fence, 0);
		setBlock(world, i + 4, j + 29, k + 13, Blocks.fence, 0);
		setBlock(world, i + 5, j + 15, k + 9, Blocks.spruce_stairs, 0);
		setBlock(world, i + 5, j + 15, k + 10, Blocks.spruce_stairs, 0);
		setBlock(world, i + 5, j + 15, k + 11, Blocks.spruce_stairs, 0);
		setBlock(world, i + 5, j + 15, k + 12, Blocks.spruce_stairs, 0);
		setBlock(world, i + 5, j + 15, k + 13, Blocks.spruce_stairs, 0);
		setBlock(world, i + 5, j + 27, k + 0, Blocks.fence, 0);
		setBlock(world, i + 5, j + 27, k + 1, Blocks.fence, 0);
		setBlock(world, i + 5, j + 27, k + 9, Blocks.fence, 0);
		setBlock(world, i + 5, j + 27, k + 10, Blocks.fence, 0);
		setBlock(world, i + 6, j + 16, k + 9, Blocks.spruce_stairs, 0);
		setBlock(world, i + 6, j + 16, k + 10, Blocks.spruce_stairs, 0);
		setBlock(world, i + 6, j + 16, k + 11, Blocks.spruce_stairs, 0);
		setBlock(world, i + 6, j + 16, k + 12, Blocks.spruce_stairs, 0);
		setBlock(world, i + 6, j + 16, k + 13, Blocks.spruce_stairs, 0);
		setBlock(world, i + 6, j + 27, k + 1, Blocks.fence, 0);
		setBlock(world, i + 6, j + 27, k + 2, Blocks.fence, 0);
		setBlock(world, i + 6, j + 27, k + 3, Blocks.spruce_stairs, 0);
		setBlock(world, i + 6, j + 27, k + 7, Blocks.spruce_stairs, 0);
		setBlock(world, i + 6, j + 27, k + 8, Blocks.fence, 0);
		setBlock(world, i + 6, j + 27, k + 9, Blocks.fence, 0);
		setBlock(world, i + 7, j + 17, k + 9, Blocks.spruce_stairs, 0);
		setBlock(world, i + 7, j + 17, k + 10, Blocks.spruce_stairs, 0);
		setBlock(world, i + 7, j + 17, k + 11, Blocks.spruce_stairs, 0);
		setBlock(world, i + 7, j + 17, k + 12, Blocks.spruce_stairs, 0);
		setBlock(world, i + 7, j + 17, k + 13, Blocks.spruce_stairs, 0);
		setBlock(world, i + 8, j + 29, k + 2, Blocks.fence, 0);
		setBlock(world, i + 8, j + 29, k + 8, Blocks.fence, 0);
		setBlock(world, i + 9, j + 29, k + 2, Blocks.fence, 0);
		setBlock(world, i + 9, j + 29, k + 8, Blocks.fence, 0);
		setBlock(world, i + 10, j + 18, k + 9, Blocks.spruce_stairs, 0);
		setBlock(world, i + 10, j + 18, k + 10, Blocks.spruce_stairs, 0);
		setBlock(world, i + 10, j + 18, k + 11, Blocks.spruce_stairs, 0);
		setBlock(world, i + 10, j + 18, k + 12, Blocks.spruce_stairs, 0);
		setBlock(world, i + 10, j + 18, k + 13, Blocks.spruce_stairs, 0);
		setBlock(world, i + 11, j + 19, k + 9, Blocks.spruce_stairs, 0);
		setBlock(world, i + 11, j + 19, k + 10, Blocks.spruce_stairs, 0);
		setBlock(world, i + 11, j + 19, k + 11, Blocks.spruce_stairs, 0);
		setBlock(world, i + 11, j + 19, k + 12, Blocks.spruce_stairs, 0);
		setBlock(world, i + 11, j + 19, k + 13, Blocks.spruce_stairs, 0);
		setBlock(world, i + 12, j + 20, k + 9, Blocks.spruce_stairs, 0);
		setBlock(world, i + 12, j + 20, k + 10, Blocks.spruce_stairs, 0);
		setBlock(world, i + 12, j + 20, k + 11, Blocks.spruce_stairs, 0);
		setBlock(world, i + 12, j + 20, k + 12, Blocks.spruce_stairs, 0);
		setBlock(world, i + 12, j + 20, k + 13, Blocks.spruce_stairs, 0);
		setBlock(world, i + 13, j + 21, k + 9, Blocks.spruce_stairs, 0);
		setBlock(world, i + 13, j + 21, k + 10, Blocks.spruce_stairs, 0);
		setBlock(world, i + 13, j + 21, k + 11, Blocks.spruce_stairs, 0);
		setBlock(world, i + 13, j + 21, k + 12, Blocks.spruce_stairs, 0);
		setBlock(world, i + 13, j + 21, k + 13, Blocks.spruce_stairs, 0);
		setBlock(world, i + 13, j + 25, k + 26, Blocks.fence, 0);
		setBlock(world, i + 14, j + 22, k + 9, Blocks.spruce_stairs, 0);
		setBlock(world, i + 14, j + 22, k + 10, Blocks.spruce_stairs, 0);
		setBlock(world, i + 14, j + 22, k + 11, Blocks.spruce_stairs, 0);
		setBlock(world, i + 14, j + 22, k + 12, Blocks.spruce_stairs, 0);
		setBlock(world, i + 14, j + 22, k + 13, Blocks.spruce_stairs, 0);
		setBlock(world, i + 14, j + 25, k + 26, Blocks.fence, 0);
		setBlock(world, i + 15, j + 23, k + 9, Blocks.spruce_stairs, 0);
		setBlock(world, i + 15, j + 23, k + 10, Blocks.spruce_stairs, 0);
		setBlock(world, i + 15, j + 23, k + 11, Blocks.spruce_stairs, 0);
		setBlock(world, i + 15, j + 23, k + 12, Blocks.spruce_stairs, 0);
		setBlock(world, i + 15, j + 23, k + 13, Blocks.spruce_stairs, 0);
		setBlock(world, i + 16, j + 23, k + 25, Blocks.fence, 0);
		setBlock(world, i + 16, j + 23, k + 26, Blocks.fence, 0);
		setBlock(world, i + 16, j + 24, k + 9, Blocks.spruce_stairs, 0);
		setBlock(world, i + 16, j + 24, k + 10, Blocks.spruce_stairs, 0);
		setBlock(world, i + 16, j + 24, k + 11, Blocks.spruce_stairs, 0);
		setBlock(world, i + 16, j + 24, k + 12, Blocks.spruce_stairs, 0);
		setBlock(world, i + 16, j + 24, k + 13, Blocks.spruce_stairs, 0);
		setBlock(world, i + 17, j + 23, k + 24, Blocks.fence, 0);
		setBlock(world, i + 17, j + 23, k + 25, Blocks.fence, 0);
		setBlock(world, i + 18, j + 23, k + 23, Blocks.spruce_stairs, 0);
		setBlock(world, i + 18, j + 23, k + 24, Blocks.fence, 0);
		setBlock(world, i + 18, j + 25, k + 21, Blocks.fence, 0);
		setBlock(world, i + 18, j + 25, k + 22, Blocks.fence, 0);
		SpawnUtils.spawnNPC(NPCType.WOOKIETREE, world, i + 19, j + 23, k + 27);
		SpawnUtils.spawnNPC(NPCType.WOOKIETREE, world, i + 19, j + 23, k + 31);
		setBlock(world, i + 20, j + 23, k + 29, Blocks.spruce_stairs, 0);
		setBlock(world, i + 22, j + 23, k + 28, Blocks.crafting_table, 0);
		SpawnUtils.spawnNPC(NPCType.WOOKIETREE, world, i + 23, j + 23, k + 27);
		SpawnUtils.spawnNPC(NPCType.WOOKIETREE, world, i + 23, j + 23, k + 31);
		setBlock(world, i + 24, j + 23, k + 24, Blocks.fence, 0);
		setBlock(world, i + 24, j + 25, k + 21, Blocks.fence, 0);
		setBlock(world, i + 24, j + 25, k + 22, Blocks.fence, 0);
		setBlock(world, i + 25, j + 23, k + 24, Blocks.fence, 0);
		setBlock(world, i + 25, j + 23, k + 25, Blocks.fence, 0);
		setBlock(world, i + 26, j + 23, k + 25, Blocks.fence, 0);
		setBlock(world, i + 26, j + 23, k + 26, Blocks.fence, 0);
		setBlock(world, i + 26, j + 23, k + 27, Blocks.spruce_stairs, 0);
		setBlock(world, i + 26, j + 23, k + 31, Blocks.spruce_stairs, 0);
		setBlock(world, i + 28, j + 25, k + 26, Blocks.fence, 0);
		setBlock(world, i + 29, j + 25, k + 26, Blocks.fence, 0);
		setBlock(world, i + 0, j + 0, k + 4, Blocks.planks, 5);
		world.setBlockMetadataWithNotify(i + 0, j + 0, k + 4, 5, 2);
		setBlock(world, i + 0, j + 0, k + 5, Blocks.planks, 5);
		world.setBlockMetadataWithNotify(i + 0, j + 0, k + 5, 5, 2);
		setBlock(world, i + 0, j + 0, k + 6, Blocks.log, 1);
		world.setBlockMetadataWithNotify(i + 0, j + 0, k + 6, 1, 2);
		setBlock(world, i + 0, j + 1, k + 4, Blocks.planks, 5);
		world.setBlockMetadataWithNotify(i + 0, j + 1, k + 4, 5, 2);
		setBlock(world, i + 0, j + 1, k + 5, Blocks.planks, 5);
		world.setBlockMetadataWithNotify(i + 0, j + 1, k + 5, 5, 2);
		setBlock(world, i + 0, j + 1, k + 6, Blocks.log, 1);
		world.setBlockMetadataWithNotify(i + 0, j + 1, k + 6, 1, 2);
		setBlock(world, i + 0, j + 1, k + 7, Blocks.log, 1);
		world.setBlockMetadataWithNotify(i + 0, j + 1, k + 7, 1, 2);
		setBlock(world, i + 0, j + 2, k + 4, Blocks.spruce_stairs, 1);
		world.setBlockMetadataWithNotify(i + 0, j + 2, k + 4, 1, 2);
		setBlock(world, i + 0, j + 2, k + 5, Blocks.spruce_stairs, 1);
		world.setBlockMetadataWithNotify(i + 0, j + 2, k + 5, 1, 2);
		setBlock(world, i + 0, j + 2, k + 6, Blocks.log, 1);
		world.setBlockMetadataWithNotify(i + 0, j + 2, k + 6, 1, 2);
		setBlock(world, i + 0, j + 2, k + 7, Blocks.log, 1);
		world.setBlockMetadataWithNotify(i + 0, j + 2, k + 7, 1, 2);
		setBlock(world, i + 0, j + 2, k + 8, Blocks.log, 1);
		world.setBlockMetadataWithNotify(i + 0, j + 2, k + 8, 1, 2);
		setBlock(world, i + 0, j + 3, k + 6, Blocks.log, 1);
		world.setBlockMetadataWithNotify(i + 0, j + 3, k + 6, 1, 2);
		setBlock(world, i + 0, j + 3, k + 7, Blocks.log, 1);
		world.setBlockMetadataWithNotify(i + 0, j + 3, k + 7, 1, 2);
		setBlock(world, i + 0, j + 3, k + 8, Blocks.log, 1);
		world.setBlockMetadataWithNotify(i + 0, j + 3, k + 8, 1, 2);
		setBlock(world, i + 0, j + 4, k + 6, Blocks.log, 1);
		world.setBlockMetadataWithNotify(i + 0, j + 4, k + 6, 1, 2);
		setBlock(world, i + 0, j + 4, k + 7, Blocks.log, 1);
		world.setBlockMetadataWithNotify(i + 0, j + 4, k + 7, 1, 2);
		setBlock(world, i + 0, j + 4, k + 8, Blocks.log, 1);
		world.setBlockMetadataWithNotify(i + 0, j + 4, k + 8, 1, 2);
		setBlock(world, i + 0, j + 4, k + 9, Blocks.planks, 5);
		world.setBlockMetadataWithNotify(i + 0, j + 4, k + 9, 5, 2);
		setBlock(world, i + 0, j + 4, k + 10, Blocks.planks, 5);
		world.setBlockMetadataWithNotify(i + 0, j + 4, k + 10, 5, 2);
		setBlock(world, i + 0, j + 5, k + 5, Blocks.torch, 4);
		world.setBlockMetadataWithNotify(i + 0, j + 5, k + 5, 4, 2);
		setBlock(world, i + 0, j + 5, k + 6, Blocks.log, 1);
		world.setBlockMetadataWithNotify(i + 0, j + 5, k + 6, 1, 2);
		setBlock(world, i + 0, j + 5, k + 7, Blocks.log, 1);
		world.setBlockMetadataWithNotify(i + 0, j + 5, k + 7, 1, 2);
		setBlock(world, i + 0, j + 5, k + 8, Blocks.log, 1);
		world.setBlockMetadataWithNotify(i + 0, j + 5, k + 8, 1, 2);
		setBlock(world, i + 0, j + 6, k + 6, Blocks.log, 1);
		world.setBlockMetadataWithNotify(i + 0, j + 6, k + 6, 1, 2);
		setBlock(world, i + 0, j + 6, k + 7, Blocks.log, 1);
		world.setBlockMetadataWithNotify(i + 0, j + 6, k + 7, 1, 2);
		setBlock(world, i + 0, j + 6, k + 8, Blocks.log, 1);
		world.setBlockMetadataWithNotify(i + 0, j + 6, k + 8, 1, 2);
		setBlock(world, i + 0, j + 7, k + 7, Blocks.log, 1);
		world.setBlockMetadataWithNotify(i + 0, j + 7, k + 7, 1, 2);
		setBlock(world, i + 0, j + 7, k + 8, Blocks.log, 1);
		world.setBlockMetadataWithNotify(i + 0, j + 7, k + 8, 1, 2);
		setBlock(world, i + 0, j + 8, k + 8, Blocks.log, 1);
		world.setBlockMetadataWithNotify(i + 0, j + 8, k + 8, 1, 2);
		setBlock(world, i + 0, j + 9, k + 4, Blocks.planks, 5);
		world.setBlockMetadataWithNotify(i + 0, j + 9, k + 4, 5, 2);
		setBlock(world, i + 0, j + 9, k + 5, Blocks.planks, 5);
		world.setBlockMetadataWithNotify(i + 0, j + 9, k + 5, 5, 2);
		setBlock(world, i + 0, j + 9, k + 6, Blocks.log, 1);
		world.setBlockMetadataWithNotify(i + 0, j + 9, k + 6, 1, 2);
		setBlock(world, i + 0, j + 9, k + 7, Blocks.log, 1);
		world.setBlockMetadataWithNotify(i + 0, j + 9, k + 7, 1, 2);
		setBlock(world, i + 0, j + 10, k + 4, Blocks.planks, 5);
		world.setBlockMetadataWithNotify(i + 0, j + 10, k + 4, 5, 2);
		setBlock(world, i + 0, j + 10, k + 5, Blocks.planks, 5);
		world.setBlockMetadataWithNotify(i + 0, j + 10, k + 5, 5, 2);
		setBlock(world, i + 0, j + 10, k + 6, Blocks.log, 1);
		world.setBlockMetadataWithNotify(i + 0, j + 10, k + 6, 1, 2);
		setBlock(world, i + 0, j + 10, k + 7, Blocks.log, 1);
		world.setBlockMetadataWithNotify(i + 0, j + 10, k + 7, 1, 2);
		setBlock(world, i + 0, j + 11, k + 6, Blocks.log, 1);
		world.setBlockMetadataWithNotify(i + 0, j + 11, k + 6, 1, 2);
		setBlock(world, i + 0, j + 11, k + 7, Blocks.log, 1);
		world.setBlockMetadataWithNotify(i + 0, j + 11, k + 7, 1, 2);
		setBlock(world, i + 0, j + 11, k + 8, Blocks.log, 1);
		world.setBlockMetadataWithNotify(i + 0, j + 11, k + 8, 1, 2);
		setBlock(world, i + 0, j + 12, k + 6, Blocks.log, 1);
		world.setBlockMetadataWithNotify(i + 0, j + 12, k + 6, 1, 2);
		setBlock(world, i + 0, j + 12, k + 7, Blocks.log, 1);
		world.setBlockMetadataWithNotify(i + 0, j + 12, k + 7, 1, 2);
		setBlock(world, i + 0, j + 12, k + 8, Blocks.log, 1);
		world.setBlockMetadataWithNotify(i + 0, j + 12, k + 8, 1, 2);
		setBlock(world, i + 0, j + 12, k + 9, Blocks.planks, 5);
		world.setBlockMetadataWithNotify(i + 0, j + 12, k + 9, 5, 2);
		setBlock(world, i + 0, j + 12, k + 10, Blocks.planks, 5);
		world.setBlockMetadataWithNotify(i + 0, j + 12, k + 10, 5, 2);
		setBlock(world, i + 0, j + 13, k + 5, Blocks.torch, 4);
		world.setBlockMetadataWithNotify(i + 0, j + 13, k + 5, 4, 2);
		setBlock(world, i + 0, j + 13, k + 6, Blocks.log, 1);
		world.setBlockMetadataWithNotify(i + 0, j + 13, k + 6, 1, 2);
		setBlock(world, i + 0, j + 13, k + 7, Blocks.log, 1);
		world.setBlockMetadataWithNotify(i + 0, j + 13, k + 7, 1, 2);
		setBlock(world, i + 0, j + 13, k + 8, Blocks.log, 1);
		world.setBlockMetadataWithNotify(i + 0, j + 13, k + 8, 1, 2);
		setBlock(world, i + 0, j + 14, k + 6, Blocks.log, 1);
		world.setBlockMetadataWithNotify(i + 0, j + 14, k + 6, 1, 2);
		setBlock(world, i + 0, j + 14, k + 7, Blocks.log, 1);
		world.setBlockMetadataWithNotify(i + 0, j + 14, k + 7, 1, 2);
		setBlock(world, i + 0, j + 15, k + 7, Blocks.log, 1);
		world.setBlockMetadataWithNotify(i + 0, j + 15, k + 7, 1, 2);
		setBlock(world, i + 0, j + 15, k + 8, Blocks.log, 1);
		world.setBlockMetadataWithNotify(i + 0, j + 15, k + 8, 1, 2);
		setBlock(world, i + 0, j + 16, k + 7, Blocks.log, 1);
		world.setBlockMetadataWithNotify(i + 0, j + 16, k + 7, 1, 2);
		setBlock(world, i + 0, j + 16, k + 8, Blocks.log, 1);
		world.setBlockMetadataWithNotify(i + 0, j + 16, k + 8, 1, 2);
		setBlock(world, i + 0, j + 17, k + 6, Blocks.log, 1);
		world.setBlockMetadataWithNotify(i + 0, j + 17, k + 6, 1, 2);
		setBlock(world, i + 0, j + 17, k + 7, Blocks.log, 1);
		world.setBlockMetadataWithNotify(i + 0, j + 17, k + 7, 1, 2);
		setBlock(world, i + 0, j + 17, k + 8, Blocks.log, 1);
		world.setBlockMetadataWithNotify(i + 0, j + 17, k + 8, 1, 2);
		setBlock(world, i + 0, j + 18, k + 2, Blocks.vine, 14);
		world.setBlockMetadataWithNotify(i + 0, j + 18, k + 2, 14, 2);
		setBlock(world, i + 0, j + 18, k + 6, Blocks.log, 1);
		world.setBlockMetadataWithNotify(i + 0, j + 18, k + 6, 1, 2);
		setBlock(world, i + 0, j + 18, k + 7, Blocks.log, 1);
		world.setBlockMetadataWithNotify(i + 0, j + 18, k + 7, 1, 2);
		setBlock(world, i + 0, j + 18, k + 8, Blocks.log, 1);
		world.setBlockMetadataWithNotify(i + 0, j + 18, k + 8, 1, 2);
		setBlock(world, i + 0, j + 19, k + 2, Blocks.vine, 14);
		world.setBlockMetadataWithNotify(i + 0, j + 19, k + 2, 14, 2);
		setBlock(world, i + 0, j + 19, k + 3, Blocks.vine, 15);
		world.setBlockMetadataWithNotify(i + 0, j + 19, k + 3, 15, 2);
		setBlock(world, i + 0, j + 19, k + 6, Blocks.log, 1);
		world.setBlockMetadataWithNotify(i + 0, j + 19, k + 6, 1, 2);
		setBlock(world, i + 0, j + 19, k + 7, Blocks.log, 1);
		world.setBlockMetadataWithNotify(i + 0, j + 19, k + 7, 1, 2);
		setBlock(world, i + 0, j + 19, k + 8, Blocks.log, 1);
		world.setBlockMetadataWithNotify(i + 0, j + 19, k + 8, 1, 2);
		setBlock(world, i + 0, j + 20, k + 1, Blocks.vine, 11);
		world.setBlockMetadataWithNotify(i + 0, j + 20, k + 1, 11, 2);
		setBlock(world, i + 0, j + 20, k + 2, Blocks.vine, 15);
		world.setBlockMetadataWithNotify(i + 0, j + 20, k + 2, 15, 2);
		setBlock(world, i + 0, j + 20, k + 3, Blocks.vine, 15);
		world.setBlockMetadataWithNotify(i + 0, j + 20, k + 3, 15, 2);
		setBlock(world, i + 0, j + 20, k + 4, Blocks.log, 1);
		world.setBlockMetadataWithNotify(i + 0, j + 20, k + 4, 1, 2);
		setBlock(world, i + 0, j + 20, k + 5, Blocks.log, 1);
		world.setBlockMetadataWithNotify(i + 0, j + 20, k + 5, 1, 2);
		setBlock(world, i + 0, j + 20, k + 6, Blocks.log, 1);
		world.setBlockMetadataWithNotify(i + 0, j + 20, k + 6, 1, 2);
		setBlock(world, i + 0, j + 20, k + 7, Blocks.log, 1);
		world.setBlockMetadataWithNotify(i + 0, j + 20, k + 7, 1, 2);
		setBlock(world, i + 0, j + 20, k + 8, Blocks.log, 1);
		world.setBlockMetadataWithNotify(i + 0, j + 20, k + 8, 1, 2);
		setBlock(world, i + 0, j + 21, k + 1, Blocks.vine, 15);
		world.setBlockMetadataWithNotify(i + 0, j + 21, k + 1, 15, 2);
		setBlock(world, i + 0, j + 21, k + 2, Blocks.vine, 15);
		world.setBlockMetadataWithNotify(i + 0, j + 21, k + 2, 15, 2);
		setBlock(world, i + 0, j + 21, k + 3, Blocks.log, 1);
		world.setBlockMetadataWithNotify(i + 0, j + 21, k + 3, 1, 2);
		setBlock(world, i + 0, j + 21, k + 4, Blocks.log, 1);
		world.setBlockMetadataWithNotify(i + 0, j + 21, k + 4, 1, 2);
		setBlock(world, i + 0, j + 21, k + 5, Blocks.log, 1);
		world.setBlockMetadataWithNotify(i + 0, j + 21, k + 5, 1, 2);
		setBlock(world, i + 0, j + 21, k + 6, Blocks.log, 1);
		world.setBlockMetadataWithNotify(i + 0, j + 21, k + 6, 1, 2);
		setBlock(world, i + 0, j + 21, k + 7, Blocks.log, 1);
		world.setBlockMetadataWithNotify(i + 0, j + 21, k + 7, 1, 2);
		setBlock(world, i + 0, j + 21, k + 8, Blocks.log, 1);
		world.setBlockMetadataWithNotify(i + 0, j + 21, k + 8, 1, 2);
		setBlock(world, i + 0, j + 22, k + 0, Blocks.vine, 15);
		world.setBlockMetadataWithNotify(i + 0, j + 22, k + 0, 15, 2);
		setBlock(world, i + 0, j + 22, k + 1, Blocks.vine, 15);
		world.setBlockMetadataWithNotify(i + 0, j + 22, k + 1, 15, 2);
		setBlock(world, i + 0, j + 22, k + 2, Blocks.vine, 15);
		world.setBlockMetadataWithNotify(i + 0, j + 22, k + 2, 15, 2);
		setBlock(world, i + 0, j + 22, k + 3, Blocks.log, 1);
		world.setBlockMetadataWithNotify(i + 0, j + 22, k + 3, 1, 2);
		setBlock(world, i + 0, j + 22, k + 4, Blocks.log, 1);
		world.setBlockMetadataWithNotify(i + 0, j + 22, k + 4, 1, 2);
		setBlock(world, i + 0, j + 22, k + 5, Blocks.log, 1);
		world.setBlockMetadataWithNotify(i + 0, j + 22, k + 5, 1, 2);
		setBlock(world, i + 0, j + 22, k + 6, Blocks.log, 1);
		world.setBlockMetadataWithNotify(i + 0, j + 22, k + 6, 1, 2);
		setBlock(world, i + 0, j + 22, k + 7, Blocks.log, 1);
		world.setBlockMetadataWithNotify(i + 0, j + 22, k + 7, 1, 2);
		setBlock(world, i + 0, j + 22, k + 8, Blocks.log, 1);
		world.setBlockMetadataWithNotify(i + 0, j + 22, k + 8, 1, 2);
		setBlock(world, i + 0, j + 22, k + 31, Blocks.log, 3);
		world.setBlockMetadataWithNotify(i + 0, j + 22, k + 31, 3, 2);
		setBlock(world, i + 0, j + 23, k + 0, Blocks.vine, 15);
		world.setBlockMetadataWithNotify(i + 0, j + 23, k + 0, 15, 2);
		setBlock(world, i + 0, j + 23, k + 1, Blocks.vine, 15);
		world.setBlockMetadataWithNotify(i + 0, j + 23, k + 1, 15, 2);
		setBlock(world, i + 0, j + 23, k + 3, Blocks.log, 1);
		world.setBlockMetadataWithNotify(i + 0, j + 23, k + 3, 1, 2);
		setBlock(world, i + 0, j + 23, k + 4, Blocks.log, 1);
		world.setBlockMetadataWithNotify(i + 0, j + 23, k + 4, 1, 2);
		setBlock(world, i + 0, j + 23, k + 5, Blocks.log, 1);
		world.setBlockMetadataWithNotify(i + 0, j + 23, k + 5, 1, 2);
		setBlock(world, i + 0, j + 23, k + 6, Blocks.leaves, 15);
		world.setBlockMetadataWithNotify(i + 0, j + 23, k + 6, 15, 2);
		setBlock(world, i + 0, j + 24, k + 3, Blocks.log, 1);
		world.setBlockMetadataWithNotify(i + 0, j + 24, k + 3, 1, 2);
		setBlock(world, i + 0, j + 24, k + 4, Blocks.log, 1);
		world.setBlockMetadataWithNotify(i + 0, j + 24, k + 4, 1, 2);
		setBlock(world, i + 0, j + 24, k + 5, Blocks.log, 1);
		world.setBlockMetadataWithNotify(i + 0, j + 24, k + 5, 1, 2);
		setBlock(world, i + 0, j + 24, k + 6, Blocks.log, 1);
		world.setBlockMetadataWithNotify(i + 0, j + 24, k + 6, 1, 2);
		setBlock(world, i + 0, j + 24, k + 7, Blocks.log, 1);
		world.setBlockMetadataWithNotify(i + 0, j + 24, k + 7, 1, 2);
		setBlock(world, i + 0, j + 24, k + 8, Blocks.log, 1);
		world.setBlockMetadataWithNotify(i + 0, j + 24, k + 8, 1, 2);
		setBlock(world, i + 0, j + 24, k + 9, Blocks.log, 1);
		world.setBlockMetadataWithNotify(i + 0, j + 24, k + 9, 1, 2);
		setBlock(world, i + 0, j + 24, k + 10, Blocks.log, 1);
		world.setBlockMetadataWithNotify(i + 0, j + 24, k + 10, 1, 2);
		setBlock(world, i + 0, j + 24, k + 11, Blocks.log, 1);
		world.setBlockMetadataWithNotify(i + 0, j + 24, k + 11, 1, 2);
		setBlock(world, i + 0, j + 24, k + 12, Blocks.log, 1);
		world.setBlockMetadataWithNotify(i + 0, j + 24, k + 12, 1, 2);
		setBlock(world, i + 0, j + 25, k + 5, Blocks.log, 1);
		world.setBlockMetadataWithNotify(i + 0, j + 25, k + 5, 1, 2);
		setBlock(world, i + 0, j + 25, k + 6, Blocks.log, 1);
		world.setBlockMetadataWithNotify(i + 0, j + 25, k + 6, 1, 2);
		setBlock(world, i + 0, j + 25, k + 7, Blocks.log, 1);
		world.setBlockMetadataWithNotify(i + 0, j + 25, k + 7, 1, 2);
		setBlock(world, i + 0, j + 25, k + 8, Blocks.log, 1);
		world.setBlockMetadataWithNotify(i + 0, j + 25, k + 8, 1, 2);
		setBlock(world, i + 0, j + 25, k + 9, Blocks.log, 1);
		world.setBlockMetadataWithNotify(i + 0, j + 25, k + 9, 1, 2);
		setBlock(world, i + 0, j + 25, k + 10, Blocks.log, 1);
		world.setBlockMetadataWithNotify(i + 0, j + 25, k + 10, 1, 2);
		setBlock(world, i + 0, j + 25, k + 11, Blocks.log, 1);
		world.setBlockMetadataWithNotify(i + 0, j + 25, k + 11, 1, 2);
		setBlock(world, i + 0, j + 26, k + 0, Blocks.planks, 5);
		world.setBlockMetadataWithNotify(i + 0, j + 26, k + 0, 5, 2);
		setBlock(world, i + 0, j + 26, k + 1, Blocks.planks, 5);
		world.setBlockMetadataWithNotify(i + 0, j + 26, k + 1, 5, 2);
		setBlock(world, i + 0, j + 26, k + 2, Blocks.log, 1);
		world.setBlockMetadataWithNotify(i + 0, j + 26, k + 2, 1, 2);
		setBlock(world, i + 0, j + 26, k + 3, Blocks.planks, 5);
		world.setBlockMetadataWithNotify(i + 0, j + 26, k + 3, 5, 2);
		setBlock(world, i + 0, j + 26, k + 4, Blocks.planks, 5);
		world.setBlockMetadataWithNotify(i + 0, j + 26, k + 4, 5, 2);
		setBlock(world, i + 0, j + 26, k + 5, Blocks.log, 1);
		world.setBlockMetadataWithNotify(i + 0, j + 26, k + 5, 1, 2);
		setBlock(world, i + 0, j + 26, k + 6, Blocks.planks, 5);
		world.setBlockMetadataWithNotify(i + 0, j + 26, k + 6, 5, 2);
		setBlock(world, i + 0, j + 26, k + 7, Blocks.planks, 5);
		world.setBlockMetadataWithNotify(i + 0, j + 26, k + 7, 5, 2);
		setBlock(world, i + 0, j + 26, k + 8, Blocks.log, 1);
		world.setBlockMetadataWithNotify(i + 0, j + 26, k + 8, 1, 2);
		setBlock(world, i + 0, j + 26, k + 9, Blocks.planks, 5);
		world.setBlockMetadataWithNotify(i + 0, j + 26, k + 9, 5, 2);
		setBlock(world, i + 0, j + 26, k + 10, Blocks.planks, 5);
		world.setBlockMetadataWithNotify(i + 0, j + 26, k + 10, 5, 2);
		setBlock(world, i + 0, j + 26, k + 11, Blocks.log, 1);
		world.setBlockMetadataWithNotify(i + 0, j + 26, k + 11, 1, 2);
		setBlock(world, i + 0, j + 26, k + 12, Blocks.planks, 5);
		world.setBlockMetadataWithNotify(i + 0, j + 26, k + 12, 5, 2);
		setBlock(world, i + 0, j + 26, k + 13, Blocks.planks, 5);
		world.setBlockMetadataWithNotify(i + 0, j + 26, k + 13, 5, 2);
		setBlock(world, i + 0, j + 26, k + 14, Blocks.planks, 5);
		world.setBlockMetadataWithNotify(i + 0, j + 26, k + 14, 5, 2);
		setBlock(world, i + 0, j + 26, k + 15, Blocks.planks, 5);
		world.setBlockMetadataWithNotify(i + 0, j + 26, k + 15, 5, 2);
		setBlock(world, i + 0, j + 27, k + 4, Blocks.chest, 2);
		LootGenUtils.fillLootChest(world.provider.dimensionId, world.rand, (TileEntityChest)world.getTileEntity(i + 0, j + 27, k + 4));
		world.setBlockMetadataWithNotify(i + 0, j + 27, k + 4, 2, 2);
		setBlock(world, i + 0, j + 29, k + 5, Blocks.torch, 2);
		world.setBlockMetadataWithNotify(i + 0, j + 29, k + 5, 2, 2);
		setBlock(world, i + 0, j + 29, k + 13, Blocks.torch, 1);
		world.setBlockMetadataWithNotify(i + 0, j + 29, k + 13, 1, 2);
		setBlock(world, i + 0, j + 30, k + 0, Blocks.log, 1);
		world.setBlockMetadataWithNotify(i + 0, j + 30, k + 0, 1, 2);
		setBlock(world, i + 0, j + 30, k + 10, Blocks.log, 1);
		world.setBlockMetadataWithNotify(i + 0, j + 30, k + 10, 1, 2);
		setBlock(world, i + 0, j + 30, k + 11, Blocks.log, 1);
		world.setBlockMetadataWithNotify(i + 0, j + 30, k + 11, 1, 2);
		setBlock(world, i + 0, j + 30, k + 12, Blocks.log, 1);
		world.setBlockMetadataWithNotify(i + 0, j + 30, k + 12, 1, 2);
		setBlock(world, i + 0, j + 30, k + 13, Blocks.log, 1);
		world.setBlockMetadataWithNotify(i + 0, j + 30, k + 13, 1, 2);
		setBlock(world, i + 0, j + 30, k + 14, Blocks.log, 1);
		world.setBlockMetadataWithNotify(i + 0, j + 30, k + 14, 1, 2);
		setBlock(world, i + 0, j + 31, k + 0, Blocks.log, 1);
		world.setBlockMetadataWithNotify(i + 0, j + 31, k + 0, 1, 2);
		setBlock(world, i + 0, j + 31, k + 1, Blocks.log, 1);
		world.setBlockMetadataWithNotify(i + 0, j + 31, k + 1, 1, 2);
		setBlock(world, i + 0, j + 31, k + 9, Blocks.log, 1);
		world.setBlockMetadataWithNotify(i + 0, j + 31, k + 9, 1, 2);
		setBlock(world, i + 0, j + 31, k + 10, Blocks.log, 1);
		world.setBlockMetadataWithNotify(i + 0, j + 31, k + 10, 1, 2);
		setBlock(world, i + 0, j + 31, k + 11, Blocks.log, 1);
		world.setBlockMetadataWithNotify(i + 0, j + 31, k + 11, 1, 2);
		setBlock(world, i + 0, j + 31, k + 12, Blocks.log, 1);
		world.setBlockMetadataWithNotify(i + 0, j + 31, k + 12, 1, 2);
		setBlock(world, i + 0, j + 31, k + 13, Blocks.log, 1);
		world.setBlockMetadataWithNotify(i + 0, j + 31, k + 13, 1, 2);
		setBlock(world, i + 0, j + 32, k + 0, Blocks.log, 1);
		world.setBlockMetadataWithNotify(i + 0, j + 32, k + 0, 1, 2);
		setBlock(world, i + 0, j + 32, k + 1, Blocks.log, 1);
		world.setBlockMetadataWithNotify(i + 0, j + 32, k + 1, 1, 2);
		setBlock(world, i + 0, j + 32, k + 2, Blocks.log, 1);
		world.setBlockMetadataWithNotify(i + 0, j + 32, k + 2, 1, 2);
		setBlock(world, i + 0, j + 32, k + 4, Blocks.log, 1);
		world.setBlockMetadataWithNotify(i + 0, j + 32, k + 4, 1, 2);
		setBlock(world, i + 0, j + 32, k + 5, Blocks.log, 1);
		world.setBlockMetadataWithNotify(i + 0, j + 32, k + 5, 1, 2);
		setBlock(world, i + 0, j + 32, k + 6, Blocks.log, 1);
		world.setBlockMetadataWithNotify(i + 0, j + 32, k + 6, 1, 2);
		setBlock(world, i + 0, j + 32, k + 8, Blocks.log, 1);
		world.setBlockMetadataWithNotify(i + 0, j + 32, k + 8, 1, 2);
		setBlock(world, i + 0, j + 32, k + 9, Blocks.log, 1);
		world.setBlockMetadataWithNotify(i + 0, j + 32, k + 9, 1, 2);
		setBlock(world, i + 0, j + 32, k + 10, Blocks.log, 1);
		world.setBlockMetadataWithNotify(i + 0, j + 32, k + 10, 1, 2);
		setBlock(world, i + 0, j + 32, k + 11, Blocks.log, 1);
		world.setBlockMetadataWithNotify(i + 0, j + 32, k + 11, 1, 2);
		setBlock(world, i + 0, j + 32, k + 12, Blocks.log, 1);
		world.setBlockMetadataWithNotify(i + 0, j + 32, k + 12, 1, 2);
		setBlock(world, i + 0, j + 32, k + 13, Blocks.log, 1);
		world.setBlockMetadataWithNotify(i + 0, j + 32, k + 13, 1, 2);
		setBlock(world, i + 0, j + 33, k + 0, Blocks.log, 1);
		world.setBlockMetadataWithNotify(i + 0, j + 33, k + 0, 1, 2);
		setBlock(world, i + 0, j + 33, k + 1, Blocks.log, 1);
		world.setBlockMetadataWithNotify(i + 0, j + 33, k + 1, 1, 2);
		setBlock(world, i + 0, j + 33, k + 2, Blocks.log, 1);
		world.setBlockMetadataWithNotify(i + 0, j + 33, k + 2, 1, 2);
		setBlock(world, i + 0, j + 33, k + 3, Blocks.log, 1);
		world.setBlockMetadataWithNotify(i + 0, j + 33, k + 3, 1, 2);
		setBlock(world, i + 0, j + 33, k + 4, Blocks.log, 1);
		world.setBlockMetadataWithNotify(i + 0, j + 33, k + 4, 1, 2);
		setBlock(world, i + 0, j + 33, k + 5, Blocks.log, 1);
		world.setBlockMetadataWithNotify(i + 0, j + 33, k + 5, 1, 2);
		setBlock(world, i + 0, j + 33, k + 6, Blocks.log, 1);
		world.setBlockMetadataWithNotify(i + 0, j + 33, k + 6, 1, 2);
		setBlock(world, i + 0, j + 33, k + 7, Blocks.log, 1);
		world.setBlockMetadataWithNotify(i + 0, j + 33, k + 7, 1, 2);
		setBlock(world, i + 0, j + 33, k + 8, Blocks.log, 1);
		world.setBlockMetadataWithNotify(i + 0, j + 33, k + 8, 1, 2);
		setBlock(world, i + 0, j + 33, k + 9, Blocks.log, 1);
		world.setBlockMetadataWithNotify(i + 0, j + 33, k + 9, 1, 2);
		setBlock(world, i + 0, j + 33, k + 10, Blocks.log, 1);
		world.setBlockMetadataWithNotify(i + 0, j + 33, k + 10, 1, 2);
		setBlock(world, i + 0, j + 33, k + 11, Blocks.log, 1);
		world.setBlockMetadataWithNotify(i + 0, j + 33, k + 11, 1, 2);
		setBlock(world, i + 0, j + 33, k + 12, Blocks.log, 1);
		world.setBlockMetadataWithNotify(i + 0, j + 33, k + 12, 1, 2);
		setBlock(world, i + 0, j + 34, k + 0, Blocks.log, 1);
		world.setBlockMetadataWithNotify(i + 0, j + 34, k + 0, 1, 2);
		setBlock(world, i + 0, j + 34, k + 1, Blocks.log, 1);
		world.setBlockMetadataWithNotify(i + 0, j + 34, k + 1, 1, 2);
		setBlock(world, i + 0, j + 34, k + 2, Blocks.log, 1);
		world.setBlockMetadataWithNotify(i + 0, j + 34, k + 2, 1, 2);
		setBlock(world, i + 0, j + 34, k + 3, Blocks.log, 1);
		world.setBlockMetadataWithNotify(i + 0, j + 34, k + 3, 1, 2);
		setBlock(world, i + 0, j + 34, k + 4, Blocks.log, 1);
		world.setBlockMetadataWithNotify(i + 0, j + 34, k + 4, 1, 2);
		setBlock(world, i + 0, j + 34, k + 5, Blocks.log, 1);
		world.setBlockMetadataWithNotify(i + 0, j + 34, k + 5, 1, 2);
		setBlock(world, i + 0, j + 34, k + 6, Blocks.log, 1);
		world.setBlockMetadataWithNotify(i + 0, j + 34, k + 6, 1, 2);
		setBlock(world, i + 0, j + 34, k + 7, Blocks.log, 1);
		world.setBlockMetadataWithNotify(i + 0, j + 34, k + 7, 1, 2);
		setBlock(world, i + 0, j + 34, k + 8, Blocks.log, 1);
		world.setBlockMetadataWithNotify(i + 0, j + 34, k + 8, 1, 2);
		setBlock(world, i + 0, j + 34, k + 9, Blocks.log, 1);
		world.setBlockMetadataWithNotify(i + 0, j + 34, k + 9, 1, 2);
		setBlock(world, i + 0, j + 34, k + 10, Blocks.log, 1);
		world.setBlockMetadataWithNotify(i + 0, j + 34, k + 10, 1, 2);
		setBlock(world, i + 0, j + 34, k + 11, Blocks.log, 1);
		world.setBlockMetadataWithNotify(i + 0, j + 34, k + 11, 1, 2);
		setBlock(world, i + 0, j + 35, k + 2, Blocks.log, 1);
		world.setBlockMetadataWithNotify(i + 0, j + 35, k + 2, 1, 2);
		setBlock(world, i + 0, j + 35, k + 3, Blocks.log, 1);
		world.setBlockMetadataWithNotify(i + 0, j + 35, k + 3, 1, 2);
		setBlock(world, i + 0, j + 35, k + 4, Blocks.log, 1);
		world.setBlockMetadataWithNotify(i + 0, j + 35, k + 4, 1, 2);
		setBlock(world, i + 0, j + 35, k + 5, Blocks.log, 1);
		world.setBlockMetadataWithNotify(i + 0, j + 35, k + 5, 1, 2);
		setBlock(world, i + 0, j + 35, k + 6, Blocks.log, 1);
		world.setBlockMetadataWithNotify(i + 0, j + 35, k + 6, 1, 2);
		setBlock(world, i + 0, j + 35, k + 7, Blocks.log, 1);
		world.setBlockMetadataWithNotify(i + 0, j + 35, k + 7, 1, 2);
		setBlock(world, i + 0, j + 35, k + 8, Blocks.log, 1);
		world.setBlockMetadataWithNotify(i + 0, j + 35, k + 8, 1, 2);
		setBlock(world, i + 0, j + 40, k + 27, Blocks.planks, 5);
		world.setBlockMetadataWithNotify(i + 0, j + 40, k + 27, 5, 2);
		setBlock(world, i + 0, j + 40, k + 28, Blocks.planks, 5);
		world.setBlockMetadataWithNotify(i + 0, j + 40, k + 28, 5, 2);
		setBlock(world, i + 0, j + 40, k + 29, Blocks.planks, 5);
		world.setBlockMetadataWithNotify(i + 0, j + 40, k + 29, 5, 2);
		setBlock(world, i + 0, j + 40, k + 30, Blocks.planks, 5);
		world.setBlockMetadataWithNotify(i + 0, j + 40, k + 30, 5, 2);
		setBlock(world, i + 0, j + 40, k + 31, Blocks.planks, 5);
		world.setBlockMetadataWithNotify(i + 0, j + 40, k + 31, 5, 2);
		setBlock(world, i + 0, j + 41, k + 26, Blocks.planks, 5);
		world.setBlockMetadataWithNotify(i + 0, j + 41, k + 26, 5, 2);
		setBlock(world, i + 0, j + 41, k + 27, Blocks.planks, 5);
		world.setBlockMetadataWithNotify(i + 0, j + 41, k + 27, 5, 2);
		setBlock(world, i + 0, j + 41, k + 28, Blocks.spruce_stairs, 3);
		world.setBlockMetadataWithNotify(i + 0, j + 41, k + 28, 3, 2);
		setBlock(world, i + 0, j + 42, k + 25, Blocks.planks, 5);
		world.setBlockMetadataWithNotify(i + 0, j + 42, k + 25, 5, 2);
		setBlock(world, i + 0, j + 42, k + 26, Blocks.planks, 5);
		world.setBlockMetadataWithNotify(i + 0, j + 42, k + 26, 5, 2);
		setBlock(world, i + 0, j + 42, k + 27, Blocks.spruce_stairs, 3);
		world.setBlockMetadataWithNotify(i + 0, j + 42, k + 27, 3, 2);
		setBlock(world, i + 0, j + 43, k + 24, Blocks.planks, 5);
		world.setBlockMetadataWithNotify(i + 0, j + 43, k + 24, 5, 2);
		setBlock(world, i + 0, j + 43, k + 25, Blocks.planks, 5);
		world.setBlockMetadataWithNotify(i + 0, j + 43, k + 25, 5, 2);
		setBlock(world, i + 0, j + 43, k + 26, Blocks.spruce_stairs, 3);
		world.setBlockMetadataWithNotify(i + 0, j + 43, k + 26, 3, 2);
		setBlock(world, i + 0, j + 44, k + 23, Blocks.planks, 5);
		world.setBlockMetadataWithNotify(i + 0, j + 44, k + 23, 5, 2);
		setBlock(world, i + 0, j + 44, k + 24, Blocks.planks, 5);
		world.setBlockMetadataWithNotify(i + 0, j + 44, k + 24, 5, 2);
		setBlock(world, i + 0, j + 44, k + 25, Blocks.spruce_stairs, 3);
		world.setBlockMetadataWithNotify(i + 0, j + 44, k + 25, 3, 2);
		setBlock(world, i + 0, j + 45, k + 22, Blocks.planks, 5);
		world.setBlockMetadataWithNotify(i + 0, j + 45, k + 22, 5, 2);
		setBlock(world, i + 0, j + 45, k + 23, Blocks.planks, 5);
		world.setBlockMetadataWithNotify(i + 0, j + 45, k + 23, 5, 2);
		setBlock(world, i + 0, j + 45, k + 24, Blocks.spruce_stairs, 3);
		world.setBlockMetadataWithNotify(i + 0, j + 45, k + 24, 3, 2);
		setBlock(world, i + 0, j + 46, k + 21, Blocks.planks, 5);
		world.setBlockMetadataWithNotify(i + 0, j + 46, k + 21, 5, 2);
		setBlock(world, i + 0, j + 46, k + 22, Blocks.planks, 5);
		world.setBlockMetadataWithNotify(i + 0, j + 46, k + 22, 5, 2);
		setBlock(world, i + 0, j + 46, k + 23, Blocks.spruce_stairs, 3);
		world.setBlockMetadataWithNotify(i + 0, j + 46, k + 23, 3, 2);
		setBlock(world, i + 0, j + 47, k + 20, Blocks.planks, 5);
		world.setBlockMetadataWithNotify(i + 0, j + 47, k + 20, 5, 2);
		setBlock(world, i + 0, j + 47, k + 21, Blocks.planks, 5);
		world.setBlockMetadataWithNotify(i + 0, j + 47, k + 21, 5, 2);
		setBlock(world, i + 0, j + 47, k + 22, Blocks.spruce_stairs, 3);
		world.setBlockMetadataWithNotify(i + 0, j + 47, k + 22, 3, 2);
		setBlock(world, i + 0, j + 48, k + 19, Blocks.planks, 5);
		world.setBlockMetadataWithNotify(i + 0, j + 48, k + 19, 5, 2);
		setBlock(world, i + 0, j + 48, k + 20, Blocks.planks, 5);
		world.setBlockMetadataWithNotify(i + 0, j + 48, k + 20, 5, 2);
		setBlock(world, i + 0, j + 48, k + 21, Blocks.spruce_stairs, 3);
		world.setBlockMetadataWithNotify(i + 0, j + 48, k + 21, 3, 2);
		setBlock(world, i + 0, j + 49, k + 18, Blocks.planks, 5);
		world.setBlockMetadataWithNotify(i + 0, j + 49, k + 18, 5, 2);
		setBlock(world, i + 0, j + 49, k + 19, Blocks.planks, 5);
		world.setBlockMetadataWithNotify(i + 0, j + 49, k + 19, 5, 2);
		setBlock(world, i + 0, j + 49, k + 20, Blocks.spruce_stairs, 3);
		world.setBlockMetadataWithNotify(i + 0, j + 49, k + 20, 3, 2);
		setBlock(world, i + 0, j + 50, k + 17, Blocks.planks, 5);
		world.setBlockMetadataWithNotify(i + 0, j + 50, k + 17, 5, 2);
		setBlock(world, i + 0, j + 50, k + 18, Blocks.planks, 5);
		world.setBlockMetadataWithNotify(i + 0, j + 50, k + 18, 5, 2);
		setBlock(world, i + 0, j + 50, k + 19, Blocks.spruce_stairs, 3);
		world.setBlockMetadataWithNotify(i + 0, j + 50, k + 19, 3, 2);
		setBlock(world, i + 0, j + 50, k + 31, Blocks.leaves, 15);
		world.setBlockMetadataWithNotify(i + 0, j + 50, k + 31, 15, 2);
		setBlock(world, i + 1, j + 0, k + 4, Blocks.planks, 5);
		world.setBlockMetadataWithNotify(i + 1, j + 0, k + 4, 5, 2);
		setBlock(world, i + 1, j + 0, k + 5, Blocks.planks, 5);
		world.setBlockMetadataWithNotify(i + 1, j + 0, k + 5, 5, 2);
		setBlock(world, i + 1, j + 0, k + 6, Blocks.log, 1);
		world.setBlockMetadataWithNotify(i + 1, j + 0, k + 6, 1, 2);
		setBlock(world, i + 1, j + 0, k + 7, Blocks.log, 1);
		world.setBlockMetadataWithNotify(i + 1, j + 0, k + 7, 1, 2);
		setBlock(world, i + 1, j + 0, k + 8, Blocks.log, 1);
		world.setBlockMetadataWithNotify(i + 1, j + 0, k + 8, 1, 2);
		setBlock(world, i + 1, j + 1, k + 4, Blocks.spruce_stairs, 1);
		world.setBlockMetadataWithNotify(i + 1, j + 1, k + 4, 1, 2);
		setBlock(world, i + 1, j + 1, k + 5, Blocks.spruce_stairs, 1);
		world.setBlockMetadataWithNotify(i + 1, j + 1, k + 5, 1, 2);
		setBlock(world, i + 1, j + 1, k + 6, Blocks.log, 1);
		world.setBlockMetadataWithNotify(i + 1, j + 1, k + 6, 1, 2);
		setBlock(world, i + 1, j + 1, k + 7, Blocks.log, 1);
		world.setBlockMetadataWithNotify(i + 1, j + 1, k + 7, 1, 2);
		setBlock(world, i + 1, j + 1, k + 8, Blocks.log, 1);
		world.setBlockMetadataWithNotify(i + 1, j + 1, k + 8, 1, 2);
		setBlock(world, i + 1, j + 2, k + 6, Blocks.log, 1);
		world.setBlockMetadataWithNotify(i + 1, j + 2, k + 6, 1, 2);
		setBlock(world, i + 1, j + 2, k + 7, Blocks.log, 1);
		world.setBlockMetadataWithNotify(i + 1, j + 2, k + 7, 1, 2);
		setBlock(world, i + 1, j + 3, k + 6, Blocks.log, 1);
		world.setBlockMetadataWithNotify(i + 1, j + 3, k + 6, 1, 2);
		setBlock(world, i + 1, j + 3, k + 7, Blocks.log, 1);
		world.setBlockMetadataWithNotify(i + 1, j + 3, k + 7, 1, 2);
		setBlock(world, i + 1, j + 3, k + 8, Blocks.log, 1);
		world.setBlockMetadataWithNotify(i + 1, j + 3, k + 8, 1, 2);
		setBlock(world, i + 1, j + 4, k + 7, Blocks.log, 1);
		world.setBlockMetadataWithNotify(i + 1, j + 4, k + 7, 1, 2);
		setBlock(world, i + 1, j + 4, k + 8, Blocks.log, 1);
		world.setBlockMetadataWithNotify(i + 1, j + 4, k + 8, 1, 2);
		setBlock(world, i + 1, j + 4, k + 9, Blocks.planks, 5);
		world.setBlockMetadataWithNotify(i + 1, j + 4, k + 9, 5, 2);
		setBlock(world, i + 1, j + 4, k + 10, Blocks.planks, 5);
		world.setBlockMetadataWithNotify(i + 1, j + 4, k + 10, 5, 2);
		setBlock(world, i + 1, j + 5, k + 7, Blocks.log, 1);
		world.setBlockMetadataWithNotify(i + 1, j + 5, k + 7, 1, 2);
		setBlock(world, i + 1, j + 5, k + 8, Blocks.log, 1);
		world.setBlockMetadataWithNotify(i + 1, j + 5, k + 8, 1, 2);
		setBlock(world, i + 1, j + 5, k + 9, Blocks.planks, 5);
		world.setBlockMetadataWithNotify(i + 1, j + 5, k + 9, 5, 2);
		setBlock(world, i + 1, j + 5, k + 10, Blocks.planks, 5);
		world.setBlockMetadataWithNotify(i + 1, j + 5, k + 10, 5, 2);
		setBlock(world, i + 1, j + 6, k + 6, Blocks.log, 1);
		world.setBlockMetadataWithNotify(i + 1, j + 6, k + 6, 1, 2);
		setBlock(world, i + 1, j + 6, k + 7, Blocks.log, 1);
		world.setBlockMetadataWithNotify(i + 1, j + 6, k + 7, 1, 2);
		setBlock(world, i + 1, j + 6, k + 8, Blocks.log, 1);
		world.setBlockMetadataWithNotify(i + 1, j + 6, k + 8, 1, 2);
		setBlock(world, i + 1, j + 7, k + 6, Blocks.log, 1);
		world.setBlockMetadataWithNotify(i + 1, j + 7, k + 6, 1, 2);
		setBlock(world, i + 1, j + 7, k + 7, Blocks.log, 1);
		world.setBlockMetadataWithNotify(i + 1, j + 7, k + 7, 1, 2);
		setBlock(world, i + 1, j + 7, k + 8, Blocks.log, 1);
		world.setBlockMetadataWithNotify(i + 1, j + 7, k + 8, 1, 2);
		setBlock(world, i + 1, j + 8, k + 4, Blocks.planks, 5);
		world.setBlockMetadataWithNotify(i + 1, j + 8, k + 4, 5, 2);
		setBlock(world, i + 1, j + 8, k + 5, Blocks.planks, 5);
		world.setBlockMetadataWithNotify(i + 1, j + 8, k + 5, 5, 2);
		setBlock(world, i + 1, j + 8, k + 6, Blocks.log, 1);
		world.setBlockMetadataWithNotify(i + 1, j + 8, k + 6, 1, 2);
		setBlock(world, i + 1, j + 8, k + 7, Blocks.log, 1);
		world.setBlockMetadataWithNotify(i + 1, j + 8, k + 7, 1, 2);
		setBlock(world, i + 1, j + 8, k + 8, Blocks.log, 1);
		world.setBlockMetadataWithNotify(i + 1, j + 8, k + 8, 1, 2);
		setBlock(world, i + 1, j + 9, k + 4, Blocks.planks, 5);
		world.setBlockMetadataWithNotify(i + 1, j + 9, k + 4, 5, 2);
		setBlock(world, i + 1, j + 9, k + 5, Blocks.planks, 5);
		world.setBlockMetadataWithNotify(i + 1, j + 9, k + 5, 5, 2);
		setBlock(world, i + 1, j + 9, k + 6, Blocks.log, 1);
		world.setBlockMetadataWithNotify(i + 1, j + 9, k + 6, 1, 2);
		setBlock(world, i + 1, j + 9, k + 7, Blocks.log, 1);
		world.setBlockMetadataWithNotify(i + 1, j + 9, k + 7, 1, 2);
		setBlock(world, i + 1, j + 10, k + 4, Blocks.spruce_stairs, 1);
		world.setBlockMetadataWithNotify(i + 1, j + 10, k + 4, 1, 2);
		setBlock(world, i + 1, j + 10, k + 5, Blocks.spruce_stairs, 1);
		world.setBlockMetadataWithNotify(i + 1, j + 10, k + 5, 1, 2);
		setBlock(world, i + 1, j + 10, k + 6, Blocks.log, 1);
		world.setBlockMetadataWithNotify(i + 1, j + 10, k + 6, 1, 2);
		setBlock(world, i + 1, j + 10, k + 7, Blocks.log, 1);
		world.setBlockMetadataWithNotify(i + 1, j + 10, k + 7, 1, 2);
		setBlock(world, i + 1, j + 10, k + 8, Blocks.log, 1);
		world.setBlockMetadataWithNotify(i + 1, j + 10, k + 8, 1, 2);
		setBlock(world, i + 1, j + 11, k + 6, Blocks.log, 1);
		world.setBlockMetadataWithNotify(i + 1, j + 11, k + 6, 1, 2);
		setBlock(world, i + 1, j + 11, k + 7, Blocks.log, 1);
		world.setBlockMetadataWithNotify(i + 1, j + 11, k + 7, 1, 2);
		setBlock(world, i + 1, j + 11, k + 8, Blocks.log, 1);
		world.setBlockMetadataWithNotify(i + 1, j + 11, k + 8, 1, 2);
		setBlock(world, i + 1, j + 12, k + 6, Blocks.log, 1);
		world.setBlockMetadataWithNotify(i + 1, j + 12, k + 6, 1, 2);
		setBlock(world, i + 1, j + 12, k + 7, Blocks.log, 1);
		world.setBlockMetadataWithNotify(i + 1, j + 12, k + 7, 1, 2);
		setBlock(world, i + 1, j + 12, k + 8, Blocks.log, 1);
		world.setBlockMetadataWithNotify(i + 1, j + 12, k + 8, 1, 2);
		setBlock(world, i + 1, j + 12, k + 9, Blocks.planks, 5);
		world.setBlockMetadataWithNotify(i + 1, j + 12, k + 9, 5, 2);
		setBlock(world, i + 1, j + 12, k + 10, Blocks.planks, 5);
		world.setBlockMetadataWithNotify(i + 1, j + 12, k + 10, 5, 2);
		setBlock(world, i + 1, j + 13, k + 6, Blocks.log, 1);
		world.setBlockMetadataWithNotify(i + 1, j + 13, k + 6, 1, 2);
		setBlock(world, i + 1, j + 13, k + 7, Blocks.log, 1);
		world.setBlockMetadataWithNotify(i + 1, j + 13, k + 7, 1, 2);
		setBlock(world, i + 1, j + 13, k + 8, Blocks.log, 1);
		world.setBlockMetadataWithNotify(i + 1, j + 13, k + 8, 1, 2);
		setBlock(world, i + 1, j + 13, k + 9, Blocks.planks, 5);
		world.setBlockMetadataWithNotify(i + 1, j + 13, k + 9, 5, 2);
		setBlock(world, i + 1, j + 13, k + 10, Blocks.planks, 5);
		world.setBlockMetadataWithNotify(i + 1, j + 13, k + 10, 5, 2);
		setBlock(world, i + 1, j + 14, k + 6, Blocks.log, 1);
		world.setBlockMetadataWithNotify(i + 1, j + 14, k + 6, 1, 2);
		setBlock(world, i + 1, j + 14, k + 7, Blocks.log, 1);
		world.setBlockMetadataWithNotify(i + 1, j + 14, k + 7, 1, 2);
		setBlock(world, i + 1, j + 14, k + 8, Blocks.log, 1);
		world.setBlockMetadataWithNotify(i + 1, j + 14, k + 8, 1, 2);
		setBlock(world, i + 1, j + 15, k + 6, Blocks.log, 1);
		world.setBlockMetadataWithNotify(i + 1, j + 15, k + 6, 1, 2);
		setBlock(world, i + 1, j + 15, k + 7, Blocks.log, 1);
		world.setBlockMetadataWithNotify(i + 1, j + 15, k + 7, 1, 2);
		setBlock(world, i + 1, j + 15, k + 8, Blocks.log, 1);
		world.setBlockMetadataWithNotify(i + 1, j + 15, k + 8, 1, 2);
		setBlock(world, i + 1, j + 16, k + 6, Blocks.log, 1);
		world.setBlockMetadataWithNotify(i + 1, j + 16, k + 6, 1, 2);
		setBlock(world, i + 1, j + 16, k + 7, Blocks.log, 1);
		world.setBlockMetadataWithNotify(i + 1, j + 16, k + 7, 1, 2);
		setBlock(world, i + 1, j + 16, k + 8, Blocks.log, 1);
		world.setBlockMetadataWithNotify(i + 1, j + 16, k + 8, 1, 2);
		setBlock(world, i + 1, j + 17, k + 6, Blocks.log, 1);
		world.setBlockMetadataWithNotify(i + 1, j + 17, k + 6, 1, 2);
		setBlock(world, i + 1, j + 17, k + 7, Blocks.log, 1);
		world.setBlockMetadataWithNotify(i + 1, j + 17, k + 7, 1, 2);
		setBlock(world, i + 1, j + 17, k + 8, Blocks.log, 1);
		world.setBlockMetadataWithNotify(i + 1, j + 17, k + 8, 1, 2);
		setBlock(world, i + 1, j + 18, k + 1, Blocks.vine, 10);
		world.setBlockMetadataWithNotify(i + 1, j + 18, k + 1, 10, 2);
		setBlock(world, i + 1, j + 18, k + 3, Blocks.vine, 14);
		world.setBlockMetadataWithNotify(i + 1, j + 18, k + 3, 14, 2);
		setBlock(world, i + 1, j + 18, k + 6, Blocks.log, 1);
		world.setBlockMetadataWithNotify(i + 1, j + 18, k + 6, 1, 2);
		setBlock(world, i + 1, j + 18, k + 7, Blocks.log, 1);
		world.setBlockMetadataWithNotify(i + 1, j + 18, k + 7, 1, 2);
		setBlock(world, i + 1, j + 18, k + 8, Blocks.log, 1);
		world.setBlockMetadataWithNotify(i + 1, j + 18, k + 8, 1, 2);
		setBlock(world, i + 1, j + 19, k + 1, Blocks.vine, 14);
		world.setBlockMetadataWithNotify(i + 1, j + 19, k + 1, 14, 2);
		setBlock(world, i + 1, j + 19, k + 3, Blocks.vine, 14);
		world.setBlockMetadataWithNotify(i + 1, j + 19, k + 3, 14, 2);
		setBlock(world, i + 1, j + 19, k + 4, Blocks.vine, 8);
		world.setBlockMetadataWithNotify(i + 1, j + 19, k + 4, 8, 2);
		setBlock(world, i + 1, j + 19, k + 6, Blocks.log, 1);
		world.setBlockMetadataWithNotify(i + 1, j + 19, k + 6, 1, 2);
		setBlock(world, i + 1, j + 19, k + 7, Blocks.log, 1);
		world.setBlockMetadataWithNotify(i + 1, j + 19, k + 7, 1, 2);
		setBlock(world, i + 1, j + 19, k + 8, Blocks.log, 1);
		world.setBlockMetadataWithNotify(i + 1, j + 19, k + 8, 1, 2);
		setBlock(world, i + 1, j + 20, k + 1, Blocks.vine, 15);
		world.setBlockMetadataWithNotify(i + 1, j + 20, k + 1, 15, 2);
		setBlock(world, i + 1, j + 20, k + 2, Blocks.vine, 6);
		world.setBlockMetadataWithNotify(i + 1, j + 20, k + 2, 6, 2);
		setBlock(world, i + 1, j + 20, k + 3, Blocks.vine, 15);
		world.setBlockMetadataWithNotify(i + 1, j + 20, k + 3, 15, 2);
		setBlock(world, i + 1, j + 20, k + 4, Blocks.vine, 15);
		world.setBlockMetadataWithNotify(i + 1, j + 20, k + 4, 15, 2);
		setBlock(world, i + 1, j + 20, k + 5, Blocks.log, 1);
		world.setBlockMetadataWithNotify(i + 1, j + 20, k + 5, 1, 2);
		setBlock(world, i + 1, j + 20, k + 6, Blocks.log, 1);
		world.setBlockMetadataWithNotify(i + 1, j + 20, k + 6, 1, 2);
		setBlock(world, i + 1, j + 20, k + 7, Blocks.log, 1);
		world.setBlockMetadataWithNotify(i + 1, j + 20, k + 7, 1, 2);
		setBlock(world, i + 1, j + 20, k + 8, Blocks.log, 1);
		world.setBlockMetadataWithNotify(i + 1, j + 20, k + 8, 1, 2);
		setBlock(world, i + 1, j + 21, k + 0, Blocks.vine, 11);
		world.setBlockMetadataWithNotify(i + 1, j + 21, k + 0, 11, 2);
		setBlock(world, i + 1, j + 21, k + 1, Blocks.vine, 15);
		world.setBlockMetadataWithNotify(i + 1, j + 21, k + 1, 15, 2);
		setBlock(world, i + 1, j + 21, k + 2, Blocks.vine, 15);
		world.setBlockMetadataWithNotify(i + 1, j + 21, k + 2, 15, 2);
		setBlock(world, i + 1, j + 21, k + 3, Blocks.vine, 15);
		world.setBlockMetadataWithNotify(i + 1, j + 21, k + 3, 15, 2);
		setBlock(world, i + 1, j + 21, k + 4, Blocks.log, 1);
		world.setBlockMetadataWithNotify(i + 1, j + 21, k + 4, 1, 2);
		setBlock(world, i + 1, j + 21, k + 5, Blocks.log, 1);
		world.setBlockMetadataWithNotify(i + 1, j + 21, k + 5, 1, 2);
		setBlock(world, i + 1, j + 21, k + 6, Blocks.log, 1);
		world.setBlockMetadataWithNotify(i + 1, j + 21, k + 6, 1, 2);
		setBlock(world, i + 1, j + 21, k + 7, Blocks.log, 1);
		world.setBlockMetadataWithNotify(i + 1, j + 21, k + 7, 1, 2);
		setBlock(world, i + 1, j + 21, k + 8, Blocks.log, 1);
		world.setBlockMetadataWithNotify(i + 1, j + 21, k + 8, 1, 2);
		setBlock(world, i + 1, j + 22, k + 0, Blocks.vine, 15);
		world.setBlockMetadataWithNotify(i + 1, j + 22, k + 0, 15, 2);
		setBlock(world, i + 1, j + 22, k + 1, Blocks.vine, 15);
		world.setBlockMetadataWithNotify(i + 1, j + 22, k + 1, 15, 2);
		setBlock(world, i + 1, j + 22, k + 2, Blocks.log, 1);
		world.setBlockMetadataWithNotify(i + 1, j + 22, k + 2, 1, 2);
		setBlock(world, i + 1, j + 22, k + 3, Blocks.log, 1);
		world.setBlockMetadataWithNotify(i + 1, j + 22, k + 3, 1, 2);
		setBlock(world, i + 1, j + 22, k + 4, Blocks.log, 1);
		world.setBlockMetadataWithNotify(i + 1, j + 22, k + 4, 1, 2);
		setBlock(world, i + 1, j + 22, k + 5, Blocks.log, 1);
		world.setBlockMetadataWithNotify(i + 1, j + 22, k + 5, 1, 2);
		setBlock(world, i + 1, j + 22, k + 6, Blocks.log, 1);
		world.setBlockMetadataWithNotify(i + 1, j + 22, k + 6, 1, 2);
		setBlock(world, i + 1, j + 22, k + 7, Blocks.log, 1);
		world.setBlockMetadataWithNotify(i + 1, j + 22, k + 7, 1, 2);
		setBlock(world, i + 1, j + 22, k + 8, Blocks.log, 1);
		world.setBlockMetadataWithNotify(i + 1, j + 22, k + 8, 1, 2);
		setBlock(world, i + 1, j + 22, k + 30, Blocks.log, 3);
		world.setBlockMetadataWithNotify(i + 1, j + 22, k + 30, 3, 2);
		setBlock(world, i + 1, j + 23, k + 0, Blocks.vine, 15);
		world.setBlockMetadataWithNotify(i + 1, j + 23, k + 0, 15, 2);
		setBlock(world, i + 1, j + 23, k + 1, Blocks.log, 1);
		world.setBlockMetadataWithNotify(i + 1, j + 23, k + 1, 1, 2);
		setBlock(world, i + 1, j + 23, k + 2, Blocks.log, 1);
		world.setBlockMetadataWithNotify(i + 1, j + 23, k + 2, 1, 2);
		setBlock(world, i + 1, j + 23, k + 3, Blocks.log, 1);
		world.setBlockMetadataWithNotify(i + 1, j + 23, k + 3, 1, 2);
		setBlock(world, i + 1, j + 23, k + 4, Blocks.log, 1);
		world.setBlockMetadataWithNotify(i + 1, j + 23, k + 4, 1, 2);
		setBlock(world, i + 1, j + 23, k + 5, Blocks.log, 1);
		world.setBlockMetadataWithNotify(i + 1, j + 23, k + 5, 1, 2);
		setBlock(world, i + 1, j + 23, k + 6, Blocks.log, 1);
		world.setBlockMetadataWithNotify(i + 1, j + 23, k + 6, 1, 2);
		setBlock(world, i + 1, j + 23, k + 7, Blocks.log, 1);
		world.setBlockMetadataWithNotify(i + 1, j + 23, k + 7, 1, 2);
		setBlock(world, i + 1, j + 23, k + 8, Blocks.log, 1);
		world.setBlockMetadataWithNotify(i + 1, j + 23, k + 8, 1, 2);
		setBlock(world, i + 1, j + 23, k + 9, Blocks.vine, 15);
		world.setBlockMetadataWithNotify(i + 1, j + 23, k + 9, 15, 2);
		setBlock(world, i + 1, j + 23, k + 27, Blocks.leaves, 15);
		world.setBlockMetadataWithNotify(i + 1, j + 23, k + 27, 15, 2);
		setBlock(world, i + 1, j + 23, k + 28, Blocks.leaves, 15);
		world.setBlockMetadataWithNotify(i + 1, j + 23, k + 28, 15, 2);
		setBlock(world, i + 1, j + 23, k + 29, Blocks.leaves, 15);
		world.setBlockMetadataWithNotify(i + 1, j + 23, k + 29, 15, 2);
		setBlock(world, i + 1, j + 24, k + 2, Blocks.log, 1);
		world.setBlockMetadataWithNotify(i + 1, j + 24, k + 2, 1, 2);
		setBlock(world, i + 1, j + 24, k + 3, Blocks.log, 1);
		world.setBlockMetadataWithNotify(i + 1, j + 24, k + 3, 1, 2);
		setBlock(world, i + 1, j + 24, k + 4, Blocks.log, 1);
		world.setBlockMetadataWithNotify(i + 1, j + 24, k + 4, 1, 2);
		setBlock(world, i + 1, j + 24, k + 5, Blocks.log, 1);
		world.setBlockMetadataWithNotify(i + 1, j + 24, k + 5, 1, 2);
		setBlock(world, i + 1, j + 24, k + 6, Blocks.log, 1);
		world.setBlockMetadataWithNotify(i + 1, j + 24, k + 6, 1, 2);
		setBlock(world, i + 1, j + 24, k + 7, Blocks.log, 1);
		world.setBlockMetadataWithNotify(i + 1, j + 24, k + 7, 1, 2);
		setBlock(world, i + 1, j + 24, k + 8, Blocks.log, 1);
		world.setBlockMetadataWithNotify(i + 1, j + 24, k + 8, 1, 2);
		setBlock(world, i + 1, j + 24, k + 9, Blocks.log, 1);
		world.setBlockMetadataWithNotify(i + 1, j + 24, k + 9, 1, 2);
		setBlock(world, i + 1, j + 24, k + 10, Blocks.log, 1);
		world.setBlockMetadataWithNotify(i + 1, j + 24, k + 10, 1, 2);
		setBlock(world, i + 1, j + 24, k + 11, Blocks.log, 1);
		world.setBlockMetadataWithNotify(i + 1, j + 24, k + 11, 1, 2);
		setBlock(world, i + 1, j + 24, k + 12, Blocks.log, 1);
		world.setBlockMetadataWithNotify(i + 1, j + 24, k + 12, 1, 2);
		setBlock(world, i + 1, j + 24, k + 28, Blocks.leaves, 15);
		world.setBlockMetadataWithNotify(i + 1, j + 24, k + 28, 15, 2);
		setBlock(world, i + 1, j + 25, k + 3, Blocks.log, 1);
		world.setBlockMetadataWithNotify(i + 1, j + 25, k + 3, 1, 2);
		setBlock(world, i + 1, j + 25, k + 5, Blocks.log, 1);
		world.setBlockMetadataWithNotify(i + 1, j + 25, k + 5, 1, 2);
		setBlock(world, i + 1, j + 25, k + 6, Blocks.log, 1);
		world.setBlockMetadataWithNotify(i + 1, j + 25, k + 6, 1, 2);
		setBlock(world, i + 1, j + 25, k + 7, Blocks.log, 1);
		world.setBlockMetadataWithNotify(i + 1, j + 25, k + 7, 1, 2);
		setBlock(world, i + 1, j + 25, k + 8, Blocks.log, 1);
		world.setBlockMetadataWithNotify(i + 1, j + 25, k + 8, 1, 2);
		setBlock(world, i + 1, j + 25, k + 9, Blocks.log, 1);
		world.setBlockMetadataWithNotify(i + 1, j + 25, k + 9, 1, 2);
		setBlock(world, i + 1, j + 25, k + 10, Blocks.log, 1);
		world.setBlockMetadataWithNotify(i + 1, j + 25, k + 10, 1, 2);
		setBlock(world, i + 1, j + 25, k + 11, Blocks.log, 1);
		world.setBlockMetadataWithNotify(i + 1, j + 25, k + 11, 1, 2);
		setBlock(world, i + 1, j + 26, k + 0, Blocks.log, 1);
		world.setBlockMetadataWithNotify(i + 1, j + 26, k + 0, 1, 2);
		setBlock(world, i + 1, j + 26, k + 1, Blocks.planks, 5);
		world.setBlockMetadataWithNotify(i + 1, j + 26, k + 1, 5, 2);
		setBlock(world, i + 1, j + 26, k + 2, Blocks.log, 1);
		world.setBlockMetadataWithNotify(i + 1, j + 26, k + 2, 1, 2);
		setBlock(world, i + 1, j + 26, k + 3, Blocks.planks, 5);
		world.setBlockMetadataWithNotify(i + 1, j + 26, k + 3, 5, 2);
		setBlock(world, i + 1, j + 26, k + 4, Blocks.log, 1);
		world.setBlockMetadataWithNotify(i + 1, j + 26, k + 4, 1, 2);
		setBlock(world, i + 1, j + 26, k + 5, Blocks.log, 1);
		world.setBlockMetadataWithNotify(i + 1, j + 26, k + 5, 1, 2);
		setBlock(world, i + 1, j + 26, k + 6, Blocks.log, 1);
		world.setBlockMetadataWithNotify(i + 1, j + 26, k + 6, 1, 2);
		setBlock(world, i + 1, j + 26, k + 7, Blocks.planks, 5);
		world.setBlockMetadataWithNotify(i + 1, j + 26, k + 7, 5, 2);
		setBlock(world, i + 1, j + 26, k + 8, Blocks.log, 1);
		world.setBlockMetadataWithNotify(i + 1, j + 26, k + 8, 1, 2);
		setBlock(world, i + 1, j + 26, k + 9, Blocks.planks, 5);
		world.setBlockMetadataWithNotify(i + 1, j + 26, k + 9, 5, 2);
		setBlock(world, i + 1, j + 26, k + 10, Blocks.log, 1);
		world.setBlockMetadataWithNotify(i + 1, j + 26, k + 10, 1, 2);
		setBlock(world, i + 1, j + 26, k + 11, Blocks.log, 1);
		world.setBlockMetadataWithNotify(i + 1, j + 26, k + 11, 1, 2);
		setBlock(world, i + 1, j + 26, k + 12, Blocks.planks, 5);
		world.setBlockMetadataWithNotify(i + 1, j + 26, k + 12, 5, 2);
		setBlock(world, i + 1, j + 26, k + 13, Blocks.planks, 5);
		world.setBlockMetadataWithNotify(i + 1, j + 26, k + 13, 5, 2);
		setBlock(world, i + 1, j + 26, k + 14, Blocks.planks, 5);
		world.setBlockMetadataWithNotify(i + 1, j + 26, k + 14, 5, 2);
		setBlock(world, i + 1, j + 26, k + 15, Blocks.planks, 5);
		world.setBlockMetadataWithNotify(i + 1, j + 26, k + 15, 5, 2);
		setBlock(world, i + 1, j + 26, k + 16, Blocks.planks, 5);
		world.setBlockMetadataWithNotify(i + 1, j + 26, k + 16, 5, 2);
		setBlock(world, i + 1, j + 27, k + 4, Blocks.spruce_stairs, 2);
		world.setBlockMetadataWithNotify(i + 1, j + 27, k + 4, 2, 2);
		setBlock(world, i + 1, j + 27, k + 5, Blocks.log, 1);
		world.setBlockMetadataWithNotify(i + 1, j + 27, k + 5, 1, 2);
		setBlock(world, i + 1, j + 27, k + 6, Blocks.spruce_stairs, 3);
		world.setBlockMetadataWithNotify(i + 1, j + 27, k + 6, 3, 2);
		setBlock(world, i + 1, j + 27, k + 16, Blocks.torch, 5);
		world.setBlockMetadataWithNotify(i + 1, j + 27, k + 16, 5, 2);
		setBlock(world, i + 1, j + 28, k + 5, Blocks.log, 1);
		world.setBlockMetadataWithNotify(i + 1, j + 28, k + 5, 1, 2);
		setBlock(world, i + 1, j + 29, k + 5, Blocks.log, 1);
		world.setBlockMetadataWithNotify(i + 1, j + 29, k + 5, 1, 2);
		setBlock(world, i + 1, j + 30, k + 0, Blocks.log, 1);
		world.setBlockMetadataWithNotify(i + 1, j + 30, k + 0, 1, 2);
		setBlock(world, i + 1, j + 30, k + 4, Blocks.torch, 4);
		world.setBlockMetadataWithNotify(i + 1, j + 30, k + 4, 4, 2);
		setBlock(world, i + 1, j + 30, k + 5, Blocks.log, 1);
		world.setBlockMetadataWithNotify(i + 1, j + 30, k + 5, 1, 2);
		setBlock(world, i + 1, j + 30, k + 6, Blocks.torch, 3);
		world.setBlockMetadataWithNotify(i + 1, j + 30, k + 6, 3, 2);
		setBlock(world, i + 1, j + 30, k + 10, Blocks.log, 1);
		world.setBlockMetadataWithNotify(i + 1, j + 30, k + 10, 1, 2);
		setBlock(world, i + 1, j + 30, k + 11, Blocks.log, 1);
		world.setBlockMetadataWithNotify(i + 1, j + 30, k + 11, 1, 2);
		setBlock(world, i + 1, j + 30, k + 12, Blocks.log, 1);
		world.setBlockMetadataWithNotify(i + 1, j + 30, k + 12, 1, 2);
		setBlock(world, i + 1, j + 30, k + 13, Blocks.log, 1);
		world.setBlockMetadataWithNotify(i + 1, j + 30, k + 13, 1, 2);
		setBlock(world, i + 1, j + 30, k + 14, Blocks.log, 1);
		world.setBlockMetadataWithNotify(i + 1, j + 30, k + 14, 1, 2);
		setBlock(world, i + 1, j + 31, k + 0, Blocks.log, 1);
		world.setBlockMetadataWithNotify(i + 1, j + 31, k + 0, 1, 2);
		setBlock(world, i + 1, j + 31, k + 1, Blocks.log, 1);
		world.setBlockMetadataWithNotify(i + 1, j + 31, k + 1, 1, 2);
		setBlock(world, i + 1, j + 31, k + 5, Blocks.log, 1);
		world.setBlockMetadataWithNotify(i + 1, j + 31, k + 5, 1, 2);
		setBlock(world, i + 1, j + 31, k + 9, Blocks.log, 1);
		world.setBlockMetadataWithNotify(i + 1, j + 31, k + 9, 1, 2);
		setBlock(world, i + 1, j + 31, k + 10, Blocks.log, 1);
		world.setBlockMetadataWithNotify(i + 1, j + 31, k + 10, 1, 2);
		setBlock(world, i + 1, j + 31, k + 11, Blocks.log, 1);
		world.setBlockMetadataWithNotify(i + 1, j + 31, k + 11, 1, 2);
		setBlock(world, i + 1, j + 31, k + 12, Blocks.log, 1);
		world.setBlockMetadataWithNotify(i + 1, j + 31, k + 12, 1, 2);
		setBlock(world, i + 1, j + 31, k + 13, Blocks.log, 1);
		world.setBlockMetadataWithNotify(i + 1, j + 31, k + 13, 1, 2);
		setBlock(world, i + 1, j + 32, k + 0, Blocks.log, 1);
		world.setBlockMetadataWithNotify(i + 1, j + 32, k + 0, 1, 2);
		setBlock(world, i + 1, j + 32, k + 1, Blocks.log, 1);
		world.setBlockMetadataWithNotify(i + 1, j + 32, k + 1, 1, 2);
		setBlock(world, i + 1, j + 32, k + 2, Blocks.log, 1);
		world.setBlockMetadataWithNotify(i + 1, j + 32, k + 2, 1, 2);
		setBlock(world, i + 1, j + 32, k + 4, Blocks.log, 1);
		world.setBlockMetadataWithNotify(i + 1, j + 32, k + 4, 1, 2);
		setBlock(world, i + 1, j + 32, k + 5, Blocks.log, 1);
		world.setBlockMetadataWithNotify(i + 1, j + 32, k + 5, 1, 2);
		setBlock(world, i + 1, j + 32, k + 6, Blocks.log, 1);
		world.setBlockMetadataWithNotify(i + 1, j + 32, k + 6, 1, 2);
		setBlock(world, i + 1, j + 32, k + 8, Blocks.log, 1);
		world.setBlockMetadataWithNotify(i + 1, j + 32, k + 8, 1, 2);
		setBlock(world, i + 1, j + 32, k + 9, Blocks.log, 1);
		world.setBlockMetadataWithNotify(i + 1, j + 32, k + 9, 1, 2);
		setBlock(world, i + 1, j + 32, k + 10, Blocks.log, 1);
		world.setBlockMetadataWithNotify(i + 1, j + 32, k + 10, 1, 2);
		setBlock(world, i + 1, j + 32, k + 11, Blocks.log, 1);
		world.setBlockMetadataWithNotify(i + 1, j + 32, k + 11, 1, 2);
		setBlock(world, i + 1, j + 32, k + 12, Blocks.log, 1);
		world.setBlockMetadataWithNotify(i + 1, j + 32, k + 12, 1, 2);
		setBlock(world, i + 1, j + 32, k + 13, Blocks.log, 1);
		world.setBlockMetadataWithNotify(i + 1, j + 32, k + 13, 1, 2);
		setBlock(world, i + 1, j + 33, k + 0, Blocks.log, 1);
		world.setBlockMetadataWithNotify(i + 1, j + 33, k + 0, 1, 2);
		setBlock(world, i + 1, j + 33, k + 1, Blocks.log, 1);
		world.setBlockMetadataWithNotify(i + 1, j + 33, k + 1, 1, 2);
		setBlock(world, i + 1, j + 33, k + 2, Blocks.log, 1);
		world.setBlockMetadataWithNotify(i + 1, j + 33, k + 2, 1, 2);
		setBlock(world, i + 1, j + 33, k + 3, Blocks.log, 1);
		world.setBlockMetadataWithNotify(i + 1, j + 33, k + 3, 1, 2);
		setBlock(world, i + 1, j + 33, k + 4, Blocks.log, 1);
		world.setBlockMetadataWithNotify(i + 1, j + 33, k + 4, 1, 2);
		setBlock(world, i + 1, j + 33, k + 5, Blocks.log, 1);
		world.setBlockMetadataWithNotify(i + 1, j + 33, k + 5, 1, 2);
		setBlock(world, i + 1, j + 33, k + 6, Blocks.log, 1);
		world.setBlockMetadataWithNotify(i + 1, j + 33, k + 6, 1, 2);
		setBlock(world, i + 1, j + 33, k + 7, Blocks.log, 1);
		world.setBlockMetadataWithNotify(i + 1, j + 33, k + 7, 1, 2);
		setBlock(world, i + 1, j + 33, k + 8, Blocks.log, 1);
		
		generate9(world, rand, i, j, k);
		return true;
		}

	
	public boolean generate9(World world, Random rand, int i, int j, int k)
	
	{
		world.setBlockMetadataWithNotify(i + 1, j + 33, k + 8, 1, 2);
		setBlock(world, i + 1, j + 33, k + 9, Blocks.log, 1);
		world.setBlockMetadataWithNotify(i + 1, j + 33, k + 9, 1, 2);
		setBlock(world, i + 1, j + 33, k + 10, Blocks.log, 1);
		world.setBlockMetadataWithNotify(i + 1, j + 33, k + 10, 1, 2);
		setBlock(world, i + 1, j + 33, k + 11, Blocks.log, 1);
		world.setBlockMetadataWithNotify(i + 1, j + 33, k + 11, 1, 2);
		setBlock(world, i + 1, j + 33, k + 12, Blocks.log, 1);
		world.setBlockMetadataWithNotify(i + 1, j + 33, k + 12, 1, 2);
		setBlock(world, i + 1, j + 34, k + 0, Blocks.log, 1);
		world.setBlockMetadataWithNotify(i + 1, j + 34, k + 0, 1, 2);
		setBlock(world, i + 1, j + 34, k + 1, Blocks.log, 1);
		world.setBlockMetadataWithNotify(i + 1, j + 34, k + 1, 1, 2);
		setBlock(world, i + 1, j + 34, k + 2, Blocks.log, 1);
		world.setBlockMetadataWithNotify(i + 1, j + 34, k + 2, 1, 2);
		setBlock(world, i + 1, j + 34, k + 3, Blocks.log, 1);
		world.setBlockMetadataWithNotify(i + 1, j + 34, k + 3, 1, 2);
		setBlock(world, i + 1, j + 34, k + 4, Blocks.log, 1);
		world.setBlockMetadataWithNotify(i + 1, j + 34, k + 4, 1, 2);
		setBlock(world, i + 1, j + 34, k + 5, Blocks.log, 1);
		world.setBlockMetadataWithNotify(i + 1, j + 34, k + 5, 1, 2);
		setBlock(world, i + 1, j + 34, k + 6, Blocks.log, 1);
		world.setBlockMetadataWithNotify(i + 1, j + 34, k + 6, 1, 2);
		setBlock(world, i + 1, j + 34, k + 7, Blocks.log, 1);
		world.setBlockMetadataWithNotify(i + 1, j + 34, k + 7, 1, 2);
		setBlock(world, i + 1, j + 34, k + 8, Blocks.log, 1);
		world.setBlockMetadataWithNotify(i + 1, j + 34, k + 8, 1, 2);
		setBlock(world, i + 1, j + 34, k + 9, Blocks.log, 1);
		world.setBlockMetadataWithNotify(i + 1, j + 34, k + 9, 1, 2);
		setBlock(world, i + 1, j + 34, k + 10, Blocks.log, 1);
		world.setBlockMetadataWithNotify(i + 1, j + 34, k + 10, 1, 2);
		setBlock(world, i + 1, j + 34, k + 11, Blocks.log, 1);
		world.setBlockMetadataWithNotify(i + 1, j + 34, k + 11, 1, 2);
		setBlock(world, i + 1, j + 35, k + 2, Blocks.log, 1);
		world.setBlockMetadataWithNotify(i + 1, j + 35, k + 2, 1, 2);
		setBlock(world, i + 1, j + 35, k + 3, Blocks.log, 1);
		world.setBlockMetadataWithNotify(i + 1, j + 35, k + 3, 1, 2);
		setBlock(world, i + 1, j + 35, k + 4, Blocks.log, 1);
		world.setBlockMetadataWithNotify(i + 1, j + 35, k + 4, 1, 2);
		setBlock(world, i + 1, j + 35, k + 5, Blocks.log, 1);
		world.setBlockMetadataWithNotify(i + 1, j + 35, k + 5, 1, 2);
		setBlock(world, i + 1, j + 35, k + 6, Blocks.log, 1);
		world.setBlockMetadataWithNotify(i + 1, j + 35, k + 6, 1, 2);
		setBlock(world, i + 1, j + 35, k + 7, Blocks.log, 1);
		world.setBlockMetadataWithNotify(i + 1, j + 35, k + 7, 1, 2);
		setBlock(world, i + 1, j + 35, k + 8, Blocks.log, 1);
		world.setBlockMetadataWithNotify(i + 1, j + 35, k + 8, 1, 2);
		setBlock(world, i + 1, j + 40, k + 30, Blocks.planks, 5);
		world.setBlockMetadataWithNotify(i + 1, j + 40, k + 30, 5, 2);
		setBlock(world, i + 1, j + 40, k + 31, Blocks.planks, 5);
		world.setBlockMetadataWithNotify(i + 1, j + 40, k + 31, 5, 2);
		setBlock(world, i + 1, j + 50, k + 31, Blocks.leaves, 15);
		world.setBlockMetadataWithNotify(i + 1, j + 50, k + 31, 15, 2);
		setBlock(world, i + 1, j + 51, k + 31, Blocks.leaves, 7);
		world.setBlockMetadataWithNotify(i + 1, j + 51, k + 31, 7, 2);
		setBlock(world, i + 2, j + 0, k + 4, Blocks.spruce_stairs, 1);
		world.setBlockMetadataWithNotify(i + 2, j + 0, k + 4, 1, 2);
		setBlock(world, i + 2, j + 0, k + 5, Blocks.spruce_stairs, 1);
		world.setBlockMetadataWithNotify(i + 2, j + 0, k + 5, 1, 2);
		setBlock(world, i + 2, j + 0, k + 6, Blocks.log, 1);
		world.setBlockMetadataWithNotify(i + 2, j + 0, k + 6, 1, 2);
		setBlock(world, i + 2, j + 0, k + 7, Blocks.log, 1);
		world.setBlockMetadataWithNotify(i + 2, j + 0, k + 7, 1, 2);
		setBlock(world, i + 2, j + 0, k + 8, Blocks.log, 1);
		world.setBlockMetadataWithNotify(i + 2, j + 0, k + 8, 1, 2);
		setBlock(world, i + 2, j + 1, k + 6, Blocks.log, 1);
		world.setBlockMetadataWithNotify(i + 2, j + 1, k + 6, 1, 2);
		setBlock(world, i + 2, j + 2, k + 6, Blocks.log, 1);
		world.setBlockMetadataWithNotify(i + 2, j + 2, k + 6, 1, 2);
		setBlock(world, i + 2, j + 2, k + 7, Blocks.log, 1);
		world.setBlockMetadataWithNotify(i + 2, j + 2, k + 7, 1, 2);
		setBlock(world, i + 2, j + 3, k + 7, Blocks.log, 1);
		world.setBlockMetadataWithNotify(i + 2, j + 3, k + 7, 1, 2);
		setBlock(world, i + 2, j + 4, k + 7, Blocks.log, 1);
		world.setBlockMetadataWithNotify(i + 2, j + 4, k + 7, 1, 2);
		setBlock(world, i + 2, j + 4, k + 8, Blocks.log, 1);
		world.setBlockMetadataWithNotify(i + 2, j + 4, k + 8, 1, 2);
		setBlock(world, i + 2, j + 5, k + 7, Blocks.log, 1);
		world.setBlockMetadataWithNotify(i + 2, j + 5, k + 7, 1, 2);
		setBlock(world, i + 2, j + 5, k + 8, Blocks.log, 1);
		world.setBlockMetadataWithNotify(i + 2, j + 5, k + 8, 1, 2);
		setBlock(world, i + 2, j + 5, k + 9, Blocks.planks, 5);
		world.setBlockMetadataWithNotify(i + 2, j + 5, k + 9, 5, 2);
		setBlock(world, i + 2, j + 5, k + 10, Blocks.planks, 5);
		world.setBlockMetadataWithNotify(i + 2, j + 5, k + 10, 5, 2);
		setBlock(world, i + 2, j + 6, k + 7, Blocks.log, 1);
		world.setBlockMetadataWithNotify(i + 2, j + 6, k + 7, 1, 2);
		setBlock(world, i + 2, j + 6, k + 8, Blocks.log, 1);
		world.setBlockMetadataWithNotify(i + 2, j + 6, k + 8, 1, 2);
		setBlock(world, i + 2, j + 6, k + 9, Blocks.planks, 5);
		world.setBlockMetadataWithNotify(i + 2, j + 6, k + 9, 5, 2);
		setBlock(world, i + 2, j + 6, k + 10, Blocks.planks, 5);
		world.setBlockMetadataWithNotify(i + 2, j + 6, k + 10, 5, 2);
		setBlock(world, i + 2, j + 7, k + 6, Blocks.log, 1);
		world.setBlockMetadataWithNotify(i + 2, j + 7, k + 6, 1, 2);
		setBlock(world, i + 2, j + 7, k + 7, Blocks.log, 1);
		world.setBlockMetadataWithNotify(i + 2, j + 7, k + 7, 1, 2);
		setBlock(world, i + 2, j + 7, k + 8, Blocks.log, 1);
		world.setBlockMetadataWithNotify(i + 2, j + 7, k + 8, 1, 2);
		setBlock(world, i + 2, j + 8, k + 4, Blocks.planks, 5);
		world.setBlockMetadataWithNotify(i + 2, j + 8, k + 4, 5, 2);
		setBlock(world, i + 2, j + 8, k + 5, Blocks.planks, 5);
		world.setBlockMetadataWithNotify(i + 2, j + 8, k + 5, 5, 2);
		setBlock(world, i + 2, j + 8, k + 6, Blocks.log, 1);
		world.setBlockMetadataWithNotify(i + 2, j + 8, k + 6, 1, 2);
		setBlock(world, i + 2, j + 8, k + 7, Blocks.log, 1);
		world.setBlockMetadataWithNotify(i + 2, j + 8, k + 7, 1, 2);
		setBlock(world, i + 2, j + 8, k + 8, Blocks.log, 1);
		world.setBlockMetadataWithNotify(i + 2, j + 8, k + 8, 1, 2);
		setBlock(world, i + 2, j + 9, k + 4, Blocks.spruce_stairs, 1);
		world.setBlockMetadataWithNotify(i + 2, j + 9, k + 4, 1, 2);
		setBlock(world, i + 2, j + 9, k + 5, Blocks.spruce_stairs, 1);
		world.setBlockMetadataWithNotify(i + 2, j + 9, k + 5, 1, 2);
		setBlock(world, i + 2, j + 9, k + 7, Blocks.log, 1);
		world.setBlockMetadataWithNotify(i + 2, j + 9, k + 7, 1, 2);
		setBlock(world, i + 2, j + 9, k + 8, Blocks.log, 1);
		world.setBlockMetadataWithNotify(i + 2, j + 9, k + 8, 1, 2);
		setBlock(world, i + 2, j + 9, k + 9, Blocks.torch, 3);
		world.setBlockMetadataWithNotify(i + 2, j + 9, k + 9, 3, 2);
		setBlock(world, i + 2, j + 10, k + 7, Blocks.log, 1);
		world.setBlockMetadataWithNotify(i + 2, j + 10, k + 7, 1, 2);
		setBlock(world, i + 2, j + 11, k + 6, Blocks.log, 1);
		world.setBlockMetadataWithNotify(i + 2, j + 11, k + 6, 1, 2);
		setBlock(world, i + 2, j + 11, k + 7, Blocks.log, 1);
		world.setBlockMetadataWithNotify(i + 2, j + 11, k + 7, 1, 2);
		setBlock(world, i + 2, j + 12, k + 6, Blocks.log, 1);
		world.setBlockMetadataWithNotify(i + 2, j + 12, k + 6, 1, 2);
		setBlock(world, i + 2, j + 12, k + 7, Blocks.log, 1);
		world.setBlockMetadataWithNotify(i + 2, j + 12, k + 7, 1, 2);
		setBlock(world, i + 2, j + 12, k + 8, Blocks.log, 1);
		world.setBlockMetadataWithNotify(i + 2, j + 12, k + 8, 1, 2);
		setBlock(world, i + 2, j + 12, k + 9, Blocks.planks, 5);
		world.setBlockMetadataWithNotify(i + 2, j + 12, k + 9, 5, 2);
		setBlock(world, i + 2, j + 12, k + 10, Blocks.planks, 5);
		world.setBlockMetadataWithNotify(i + 2, j + 12, k + 10, 5, 2);
		setBlock(world, i + 2, j + 13, k + 7, Blocks.log, 1);
		world.setBlockMetadataWithNotify(i + 2, j + 13, k + 7, 1, 2);
		setBlock(world, i + 2, j + 13, k + 8, Blocks.log, 1);
		world.setBlockMetadataWithNotify(i + 2, j + 13, k + 8, 1, 2);
		setBlock(world, i + 2, j + 13, k + 9, Blocks.planks, 5);
		world.setBlockMetadataWithNotify(i + 2, j + 13, k + 9, 5, 2);
		setBlock(world, i + 2, j + 13, k + 10, Blocks.planks, 5);
		world.setBlockMetadataWithNotify(i + 2, j + 13, k + 10, 5, 2);
		setBlock(world, i + 2, j + 13, k + 11, Blocks.planks, 5);
		world.setBlockMetadataWithNotify(i + 2, j + 13, k + 11, 5, 2);
		setBlock(world, i + 2, j + 14, k + 7, Blocks.log, 1);
		world.setBlockMetadataWithNotify(i + 2, j + 14, k + 7, 1, 2);
		setBlock(world, i + 2, j + 14, k + 8, Blocks.log, 1);
		world.setBlockMetadataWithNotify(i + 2, j + 14, k + 8, 1, 2);
		setBlock(world, i + 2, j + 14, k + 9, Blocks.planks, 5);
		world.setBlockMetadataWithNotify(i + 2, j + 14, k + 9, 5, 2);
		setBlock(world, i + 2, j + 14, k + 10, Blocks.planks, 5);
		world.setBlockMetadataWithNotify(i + 2, j + 14, k + 10, 5, 2);
		setBlock(world, i + 2, j + 14, k + 11, Blocks.planks, 5);
		world.setBlockMetadataWithNotify(i + 2, j + 14, k + 11, 5, 2);
		setBlock(world, i + 2, j + 15, k + 6, Blocks.log, 1);
		world.setBlockMetadataWithNotify(i + 2, j + 15, k + 6, 1, 2);
		setBlock(world, i + 2, j + 15, k + 7, Blocks.log, 1);
		world.setBlockMetadataWithNotify(i + 2, j + 15, k + 7, 1, 2);
		setBlock(world, i + 2, j + 15, k + 8, Blocks.log, 1);
		world.setBlockMetadataWithNotify(i + 2, j + 15, k + 8, 1, 2);
		setBlock(world, i + 2, j + 16, k + 7, Blocks.log, 1);
		world.setBlockMetadataWithNotify(i + 2, j + 16, k + 7, 1, 2);
		setBlock(world, i + 2, j + 16, k + 8, Blocks.log, 1);
		world.setBlockMetadataWithNotify(i + 2, j + 16, k + 8, 1, 2);
		setBlock(world, i + 2, j + 17, k + 7, Blocks.log, 1);
		world.setBlockMetadataWithNotify(i + 2, j + 17, k + 7, 1, 2);
		setBlock(world, i + 2, j + 17, k + 8, Blocks.log, 1);
		world.setBlockMetadataWithNotify(i + 2, j + 17, k + 8, 1, 2);
		setBlock(world, i + 2, j + 17, k + 9, Blocks.torch, 3);
		world.setBlockMetadataWithNotify(i + 2, j + 17, k + 9, 3, 2);
		setBlock(world, i + 2, j + 18, k + 3, Blocks.vine, 1);
		world.setBlockMetadataWithNotify(i + 2, j + 18, k + 3, 1, 2);
		setBlock(world, i + 2, j + 18, k + 4, Blocks.vine, 15);
		world.setBlockMetadataWithNotify(i + 2, j + 18, k + 4, 15, 2);
		setBlock(world, i + 2, j + 18, k + 6, Blocks.log, 1);
		world.setBlockMetadataWithNotify(i + 2, j + 18, k + 6, 1, 2);
		setBlock(world, i + 2, j + 18, k + 7, Blocks.log, 1);
		world.setBlockMetadataWithNotify(i + 2, j + 18, k + 7, 1, 2);
		setBlock(world, i + 2, j + 18, k + 8, Blocks.log, 1);
		world.setBlockMetadataWithNotify(i + 2, j + 18, k + 8, 1, 2);
		setBlock(world, i + 2, j + 19, k + 3, Blocks.vine, 15);
		world.setBlockMetadataWithNotify(i + 2, j + 19, k + 3, 15, 2);
		setBlock(world, i + 2, j + 19, k + 4, Blocks.vine, 15);
		world.setBlockMetadataWithNotify(i + 2, j + 19, k + 4, 15, 2);
		setBlock(world, i + 2, j + 19, k + 5, Blocks.vine, 15);
		world.setBlockMetadataWithNotify(i + 2, j + 19, k + 5, 15, 2);
		setBlock(world, i + 2, j + 19, k + 6, Blocks.log, 1);
		world.setBlockMetadataWithNotify(i + 2, j + 19, k + 6, 1, 2);
		setBlock(world, i + 2, j + 19, k + 7, Blocks.log, 1);
		world.setBlockMetadataWithNotify(i + 2, j + 19, k + 7, 1, 2);
		setBlock(world, i + 2, j + 19, k + 8, Blocks.log, 1);
		world.setBlockMetadataWithNotify(i + 2, j + 19, k + 8, 1, 2);
		setBlock(world, i + 2, j + 20, k + 3, Blocks.vine, 15);
		world.setBlockMetadataWithNotify(i + 2, j + 20, k + 3, 15, 2);
		setBlock(world, i + 2, j + 20, k + 4, Blocks.vine, 15);
		world.setBlockMetadataWithNotify(i + 2, j + 20, k + 4, 15, 2);
		setBlock(world, i + 2, j + 20, k + 5, Blocks.vine, 15);
		world.setBlockMetadataWithNotify(i + 2, j + 20, k + 5, 15, 2);
		setBlock(world, i + 2, j + 20, k + 6, Blocks.log, 1);
		world.setBlockMetadataWithNotify(i + 2, j + 20, k + 6, 1, 2);
		setBlock(world, i + 2, j + 20, k + 7, Blocks.log, 1);
		world.setBlockMetadataWithNotify(i + 2, j + 20, k + 7, 1, 2);
		setBlock(world, i + 2, j + 20, k + 8, Blocks.log, 1);
		world.setBlockMetadataWithNotify(i + 2, j + 20, k + 8, 1, 2);
		setBlock(world, i + 2, j + 21, k + 0, Blocks.vine, 13);
		world.setBlockMetadataWithNotify(i + 2, j + 21, k + 0, 13, 2);
		setBlock(world, i + 2, j + 21, k + 1, Blocks.vine, 15);
		world.setBlockMetadataWithNotify(i + 2, j + 21, k + 1, 15, 2);
		setBlock(world, i + 2, j + 21, k + 2, Blocks.vine, 15);
		world.setBlockMetadataWithNotify(i + 2, j + 21, k + 2, 15, 2);
		setBlock(world, i + 2, j + 21, k + 3, Blocks.vine, 15);
		world.setBlockMetadataWithNotify(i + 2, j + 21, k + 3, 15, 2);
		setBlock(world, i + 2, j + 21, k + 4, Blocks.vine, 15);
		world.setBlockMetadataWithNotify(i + 2, j + 21, k + 4, 15, 2);
		setBlock(world, i + 2, j + 21, k + 5, Blocks.log, 1);
		world.setBlockMetadataWithNotify(i + 2, j + 21, k + 5, 1, 2);
		setBlock(world, i + 2, j + 21, k + 6, Blocks.log, 1);
		world.setBlockMetadataWithNotify(i + 2, j + 21, k + 6, 1, 2);
		setBlock(world, i + 2, j + 21, k + 7, Blocks.log, 1);
		world.setBlockMetadataWithNotify(i + 2, j + 21, k + 7, 1, 2);
		setBlock(world, i + 2, j + 21, k + 8, Blocks.log, 1);
		world.setBlockMetadataWithNotify(i + 2, j + 21, k + 8, 1, 2);
		setBlock(world, i + 2, j + 22, k + 0, Blocks.vine, 15);
		world.setBlockMetadataWithNotify(i + 2, j + 22, k + 0, 15, 2);
		setBlock(world, i + 2, j + 22, k + 1, Blocks.log, 1);
		world.setBlockMetadataWithNotify(i + 2, j + 22, k + 1, 1, 2);
		setBlock(world, i + 2, j + 22, k + 2, Blocks.log, 1);
		world.setBlockMetadataWithNotify(i + 2, j + 22, k + 2, 1, 2);
		setBlock(world, i + 2, j + 22, k + 3, Blocks.log, 1);
		world.setBlockMetadataWithNotify(i + 2, j + 22, k + 3, 1, 2);
		setBlock(world, i + 2, j + 22, k + 4, Blocks.log, 1);
		world.setBlockMetadataWithNotify(i + 2, j + 22, k + 4, 1, 2);
		setBlock(world, i + 2, j + 22, k + 5, Blocks.log, 1);
		world.setBlockMetadataWithNotify(i + 2, j + 22, k + 5, 1, 2);
		setBlock(world, i + 2, j + 22, k + 6, Blocks.log, 1);
		world.setBlockMetadataWithNotify(i + 2, j + 22, k + 6, 1, 2);
		setBlock(world, i + 2, j + 22, k + 7, Blocks.log, 1);
		world.setBlockMetadataWithNotify(i + 2, j + 22, k + 7, 1, 2);
		setBlock(world, i + 2, j + 22, k + 8, Blocks.log, 1);
		world.setBlockMetadataWithNotify(i + 2, j + 22, k + 8, 1, 2);
		setBlock(world, i + 2, j + 22, k + 29, Blocks.log, 3);
		world.setBlockMetadataWithNotify(i + 2, j + 22, k + 29, 3, 2);
		setBlock(world, i + 2, j + 23, k + 0, Blocks.vine, 15);
		world.setBlockMetadataWithNotify(i + 2, j + 23, k + 0, 15, 2);
		setBlock(world, i + 2, j + 23, k + 1, Blocks.log, 1);
		world.setBlockMetadataWithNotify(i + 2, j + 23, k + 1, 1, 2);
		setBlock(world, i + 2, j + 23, k + 2, Blocks.log, 1);
		world.setBlockMetadataWithNotify(i + 2, j + 23, k + 2, 1, 2);
		setBlock(world, i + 2, j + 23, k + 3, Blocks.log, 1);
		world.setBlockMetadataWithNotify(i + 2, j + 23, k + 3, 1, 2);
		setBlock(world, i + 2, j + 23, k + 4, Blocks.log, 1);
		world.setBlockMetadataWithNotify(i + 2, j + 23, k + 4, 1, 2);
		setBlock(world, i + 2, j + 23, k + 5, Blocks.log, 1);
		world.setBlockMetadataWithNotify(i + 2, j + 23, k + 5, 1, 2);
		setBlock(world, i + 2, j + 23, k + 6, Blocks.leaves, 15);
		world.setBlockMetadataWithNotify(i + 2, j + 23, k + 6, 15, 2);
		setBlock(world, i + 2, j + 23, k + 7, Blocks.log, 1);
		world.setBlockMetadataWithNotify(i + 2, j + 23, k + 7, 1, 2);
		setBlock(world, i + 2, j + 23, k + 8, Blocks.vine, 15);
		world.setBlockMetadataWithNotify(i + 2, j + 23, k + 8, 15, 2);
		setBlock(world, i + 2, j + 23, k + 9, Blocks.vine, 15);
		world.setBlockMetadataWithNotify(i + 2, j + 23, k + 9, 15, 2);
		setBlock(world, i + 2, j + 23, k + 26, Blocks.leaves, 15);
		world.setBlockMetadataWithNotify(i + 2, j + 23, k + 26, 15, 2);
		setBlock(world, i + 2, j + 23, k + 27, Blocks.leaves, 15);
		world.setBlockMetadataWithNotify(i + 2, j + 23, k + 27, 15, 2);
		setBlock(world, i + 2, j + 23, k + 28, Blocks.leaves, 15);
		world.setBlockMetadataWithNotify(i + 2, j + 23, k + 28, 15, 2);
		setBlock(world, i + 2, j + 23, k + 29, Blocks.leaves, 15);
		world.setBlockMetadataWithNotify(i + 2, j + 23, k + 29, 15, 2);
		setBlock(world, i + 2, j + 23, k + 30, Blocks.leaves, 15);
		world.setBlockMetadataWithNotify(i + 2, j + 23, k + 30, 15, 2);
		setBlock(world, i + 2, j + 24, k + 1, Blocks.log, 1);
		world.setBlockMetadataWithNotify(i + 2, j + 24, k + 1, 1, 2);
		setBlock(world, i + 2, j + 24, k + 2, Blocks.log, 1);
		world.setBlockMetadataWithNotify(i + 2, j + 24, k + 2, 1, 2);
		setBlock(world, i + 2, j + 24, k + 3, Blocks.log, 1);
		world.setBlockMetadataWithNotify(i + 2, j + 24, k + 3, 1, 2);
		setBlock(world, i + 2, j + 24, k + 4, Blocks.log, 1);
		world.setBlockMetadataWithNotify(i + 2, j + 24, k + 4, 1, 2);
		setBlock(world, i + 2, j + 24, k + 5, Blocks.log, 1);
		world.setBlockMetadataWithNotify(i + 2, j + 24, k + 5, 1, 2);
		setBlock(world, i + 2, j + 24, k + 6, Blocks.log, 1);
		world.setBlockMetadataWithNotify(i + 2, j + 24, k + 6, 1, 2);
		setBlock(world, i + 2, j + 24, k + 7, Blocks.log, 1);
		world.setBlockMetadataWithNotify(i + 2, j + 24, k + 7, 1, 2);
		setBlock(world, i + 2, j + 24, k + 8, Blocks.log, 1);
		world.setBlockMetadataWithNotify(i + 2, j + 24, k + 8, 1, 2);
		setBlock(world, i + 2, j + 24, k + 9, Blocks.log, 1);
		world.setBlockMetadataWithNotify(i + 2, j + 24, k + 9, 1, 2);
		setBlock(world, i + 2, j + 24, k + 10, Blocks.log, 1);
		world.setBlockMetadataWithNotify(i + 2, j + 24, k + 10, 1, 2);
		setBlock(world, i + 2, j + 24, k + 11, Blocks.log, 1);
		world.setBlockMetadataWithNotify(i + 2, j + 24, k + 11, 1, 2);
		setBlock(world, i + 2, j + 24, k + 12, Blocks.log, 1);
		world.setBlockMetadataWithNotify(i + 2, j + 24, k + 12, 1, 2);
		setBlock(world, i + 2, j + 24, k + 27, Blocks.leaves, 15);
		world.setBlockMetadataWithNotify(i + 2, j + 24, k + 27, 15, 2);
		setBlock(world, i + 2, j + 24, k + 28, Blocks.leaves, 15);
		world.setBlockMetadataWithNotify(i + 2, j + 24, k + 28, 15, 2);
		setBlock(world, i + 2, j + 24, k + 29, Blocks.leaves, 15);
		world.setBlockMetadataWithNotify(i + 2, j + 24, k + 29, 15, 2);
		setBlock(world, i + 2, j + 25, k + 1, Blocks.log, 1);
		world.setBlockMetadataWithNotify(i + 2, j + 25, k + 1, 1, 2);
		setBlock(world, i + 2, j + 25, k + 2, Blocks.log, 1);
		world.setBlockMetadataWithNotify(i + 2, j + 25, k + 2, 1, 2);
		setBlock(world, i + 2, j + 25, k + 3, Blocks.log, 1);
		world.setBlockMetadataWithNotify(i + 2, j + 25, k + 3, 1, 2);
		setBlock(world, i + 2, j + 25, k + 4, Blocks.log, 1);
		world.setBlockMetadataWithNotify(i + 2, j + 25, k + 4, 1, 2);
		setBlock(world, i + 2, j + 25, k + 5, Blocks.log, 1);
		world.setBlockMetadataWithNotify(i + 2, j + 25, k + 5, 1, 2);
		setBlock(world, i + 2, j + 25, k + 6, Blocks.log, 1);
		world.setBlockMetadataWithNotify(i + 2, j + 25, k + 6, 1, 2);
		setBlock(world, i + 2, j + 25, k + 7, Blocks.log, 1);
		world.setBlockMetadataWithNotify(i + 2, j + 25, k + 7, 1, 2);
		setBlock(world, i + 2, j + 25, k + 8, Blocks.log, 1);
		world.setBlockMetadataWithNotify(i + 2, j + 25, k + 8, 1, 2);
		setBlock(world, i + 2, j + 25, k + 9, Blocks.log, 1);
		world.setBlockMetadataWithNotify(i + 2, j + 25, k + 9, 1, 2);
		setBlock(world, i + 2, j + 25, k + 10, Blocks.log, 1);
		world.setBlockMetadataWithNotify(i + 2, j + 25, k + 10, 1, 2);
		setBlock(world, i + 2, j + 25, k + 11, Blocks.log, 1);
		world.setBlockMetadataWithNotify(i + 2, j + 25, k + 11, 1, 2);
		setBlock(world, i + 2, j + 25, k + 28, Blocks.leaves, 15);
		world.setBlockMetadataWithNotify(i + 2, j + 25, k + 28, 15, 2);
		setBlock(world, i + 2, j + 26, k + 0, Blocks.planks, 5);
		world.setBlockMetadataWithNotify(i + 2, j + 26, k + 0, 5, 2);
		setBlock(world, i + 2, j + 26, k + 1, Blocks.planks, 5);
		world.setBlockMetadataWithNotify(i + 2, j + 26, k + 1, 5, 2);
		setBlock(world, i + 2, j + 26, k + 2, Blocks.log, 1);
		world.setBlockMetadataWithNotify(i + 2, j + 26, k + 2, 1, 2);
		setBlock(world, i + 2, j + 26, k + 3, Blocks.planks, 5);
		world.setBlockMetadataWithNotify(i + 2, j + 26, k + 3, 5, 2);
		setBlock(world, i + 2, j + 26, k + 4, Blocks.planks, 5);
		world.setBlockMetadataWithNotify(i + 2, j + 26, k + 4, 5, 2);
		setBlock(world, i + 2, j + 26, k + 5, Blocks.log, 1);
		world.setBlockMetadataWithNotify(i + 2, j + 26, k + 5, 1, 2);
		setBlock(world, i + 2, j + 26, k + 6, Blocks.planks, 5);
		world.setBlockMetadataWithNotify(i + 2, j + 26, k + 6, 5, 2);
		setBlock(world, i + 2, j + 26, k + 7, Blocks.planks, 5);
		world.setBlockMetadataWithNotify(i + 2, j + 26, k + 7, 5, 2);
		setBlock(world, i + 2, j + 26, k + 8, Blocks.log, 1);
		world.setBlockMetadataWithNotify(i + 2, j + 26, k + 8, 1, 2);
		setBlock(world, i + 2, j + 26, k + 9, Blocks.planks, 5);
		world.setBlockMetadataWithNotify(i + 2, j + 26, k + 9, 5, 2);
		setBlock(world, i + 2, j + 26, k + 10, Blocks.planks, 5);
		world.setBlockMetadataWithNotify(i + 2, j + 26, k + 10, 5, 2);
		setBlock(world, i + 2, j + 26, k + 11, Blocks.log, 1);
		world.setBlockMetadataWithNotify(i + 2, j + 26, k + 11, 1, 2);
		setBlock(world, i + 2, j + 26, k + 12, Blocks.planks, 5);
		world.setBlockMetadataWithNotify(i + 2, j + 26, k + 12, 5, 2);
		setBlock(world, i + 2, j + 26, k + 13, Blocks.planks, 5);
		world.setBlockMetadataWithNotify(i + 2, j + 26, k + 13, 5, 2);
		setBlock(world, i + 2, j + 26, k + 14, Blocks.planks, 5);
		world.setBlockMetadataWithNotify(i + 2, j + 26, k + 14, 5, 2);
		setBlock(world, i + 2, j + 26, k + 15, Blocks.planks, 5);
		world.setBlockMetadataWithNotify(i + 2, j + 26, k + 15, 5, 2);
		setBlock(world, i + 2, j + 26, k + 16, Blocks.planks, 5);
		world.setBlockMetadataWithNotify(i + 2, j + 26, k + 16, 5, 2);
		setBlock(world, i + 2, j + 26, k + 17, Blocks.planks, 5);
		world.setBlockMetadataWithNotify(i + 2, j + 26, k + 17, 5, 2);
		setBlock(world, i + 2, j + 27, k + 4, Blocks.chest, 2);
		LootGenUtils.fillLootChest(world.provider.dimensionId, world.rand, (TileEntityChest)world.getTileEntity(i + 2, j + 27, k + 4));
		world.setBlockMetadataWithNotify(i + 2, j + 27, k + 4, 2, 2);
		setBlock(world, i + 2, j + 27, k + 5, Blocks.spruce_stairs, 1);
		world.setBlockMetadataWithNotify(i + 2, j + 27, k + 5, 1, 2);
		setBlock(world, i + 2, j + 27, k + 6, Blocks.furnace, 3);
		world.setBlockMetadataWithNotify(i + 2, j + 27, k + 6, 3, 2);
		setBlock(world, i + 2, j + 29, k + 5, Blocks.torch, 1);
		world.setBlockMetadataWithNotify(i + 2, j + 29, k + 5, 1, 2);
		setBlock(world, i + 2, j + 29, k + 13, Blocks.torch, 2);
		world.setBlockMetadataWithNotify(i + 2, j + 29, k + 13, 2, 2);
		setBlock(world, i + 2, j + 30, k + 0, Blocks.log, 1);
		world.setBlockMetadataWithNotify(i + 2, j + 30, k + 0, 1, 2);
		setBlock(world, i + 2, j + 30, k + 10, Blocks.log, 1);
		world.setBlockMetadataWithNotify(i + 2, j + 30, k + 10, 1, 2);
		setBlock(world, i + 2, j + 30, k + 11, Blocks.log, 1);
		world.setBlockMetadataWithNotify(i + 2, j + 30, k + 11, 1, 2);
		setBlock(world, i + 2, j + 30, k + 12, Blocks.log, 1);
		world.setBlockMetadataWithNotify(i + 2, j + 30, k + 12, 1, 2);
		setBlock(world, i + 2, j + 30, k + 13, Blocks.log, 1);
		world.setBlockMetadataWithNotify(i + 2, j + 30, k + 13, 1, 2);
		setBlock(world, i + 2, j + 30, k + 14, Blocks.log, 1);
		world.setBlockMetadataWithNotify(i + 2, j + 30, k + 14, 1, 2);
		setBlock(world, i + 2, j + 31, k + 0, Blocks.log, 1);
		world.setBlockMetadataWithNotify(i + 2, j + 31, k + 0, 1, 2);
		setBlock(world, i + 2, j + 31, k + 1, Blocks.log, 1);
		world.setBlockMetadataWithNotify(i + 2, j + 31, k + 1, 1, 2);
		setBlock(world, i + 2, j + 31, k + 9, Blocks.log, 1);
		world.setBlockMetadataWithNotify(i + 2, j + 31, k + 9, 1, 2);
		setBlock(world, i + 2, j + 31, k + 10, Blocks.log, 1);
		world.setBlockMetadataWithNotify(i + 2, j + 31, k + 10, 1, 2);
		setBlock(world, i + 2, j + 31, k + 11, Blocks.log, 1);
		world.setBlockMetadataWithNotify(i + 2, j + 31, k + 11, 1, 2);
		setBlock(world, i + 2, j + 31, k + 12, Blocks.log, 1);
		world.setBlockMetadataWithNotify(i + 2, j + 31, k + 12, 1, 2);
		setBlock(world, i + 2, j + 31, k + 13, Blocks.log, 1);
		world.setBlockMetadataWithNotify(i + 2, j + 31, k + 13, 1, 2);
		setBlock(world, i + 2, j + 32, k + 0, Blocks.log, 1);
		world.setBlockMetadataWithNotify(i + 2, j + 32, k + 0, 1, 2);
		setBlock(world, i + 2, j + 32, k + 1, Blocks.log, 1);
		world.setBlockMetadataWithNotify(i + 2, j + 32, k + 1, 1, 2);
		setBlock(world, i + 2, j + 32, k + 2, Blocks.log, 1);
		world.setBlockMetadataWithNotify(i + 2, j + 32, k + 2, 1, 2);
		setBlock(world, i + 2, j + 32, k + 4, Blocks.log, 1);
		world.setBlockMetadataWithNotify(i + 2, j + 32, k + 4, 1, 2);
		setBlock(world, i + 2, j + 32, k + 5, Blocks.log, 1);
		world.setBlockMetadataWithNotify(i + 2, j + 32, k + 5, 1, 2);
		setBlock(world, i + 2, j + 32, k + 6, Blocks.log, 1);
		world.setBlockMetadataWithNotify(i + 2, j + 32, k + 6, 1, 2);
		setBlock(world, i + 2, j + 32, k + 8, Blocks.log, 1);
		world.setBlockMetadataWithNotify(i + 2, j + 32, k + 8, 1, 2);
		setBlock(world, i + 2, j + 32, k + 9, Blocks.log, 1);
		world.setBlockMetadataWithNotify(i + 2, j + 32, k + 9, 1, 2);
		setBlock(world, i + 2, j + 32, k + 10, Blocks.log, 1);
		world.setBlockMetadataWithNotify(i + 2, j + 32, k + 10, 1, 2);
		setBlock(world, i + 2, j + 32, k + 11, Blocks.log, 1);
		world.setBlockMetadataWithNotify(i + 2, j + 32, k + 11, 1, 2);
		setBlock(world, i + 2, j + 32, k + 12, Blocks.log, 1);
		world.setBlockMetadataWithNotify(i + 2, j + 32, k + 12, 1, 2);
		setBlock(world, i + 2, j + 32, k + 13, Blocks.log, 1);
		world.setBlockMetadataWithNotify(i + 2, j + 32, k + 13, 1, 2);
		setBlock(world, i + 2, j + 33, k + 0, Blocks.log, 1);
		world.setBlockMetadataWithNotify(i + 2, j + 33, k + 0, 1, 2);
		setBlock(world, i + 2, j + 33, k + 1, Blocks.log, 1);
		world.setBlockMetadataWithNotify(i + 2, j + 33, k + 1, 1, 2);
		setBlock(world, i + 2, j + 33, k + 2, Blocks.log, 1);
		world.setBlockMetadataWithNotify(i + 2, j + 33, k + 2, 1, 2);
		setBlock(world, i + 2, j + 33, k + 3, Blocks.log, 1);
		world.setBlockMetadataWithNotify(i + 2, j + 33, k + 3, 1, 2);
		setBlock(world, i + 2, j + 33, k + 4, Blocks.log, 1);
		world.setBlockMetadataWithNotify(i + 2, j + 33, k + 4, 1, 2);
		setBlock(world, i + 2, j + 33, k + 5, Blocks.log, 1);
		world.setBlockMetadataWithNotify(i + 2, j + 33, k + 5, 1, 2);
		setBlock(world, i + 2, j + 33, k + 6, Blocks.log, 1);
		world.setBlockMetadataWithNotify(i + 2, j + 33, k + 6, 1, 2);
		setBlock(world, i + 2, j + 33, k + 7, Blocks.log, 1);
		world.setBlockMetadataWithNotify(i + 2, j + 33, k + 7, 1, 2);
		setBlock(world, i + 2, j + 33, k + 8, Blocks.log, 1);
		world.setBlockMetadataWithNotify(i + 2, j + 33, k + 8, 1, 2);
		setBlock(world, i + 2, j + 33, k + 9, Blocks.log, 1);
		world.setBlockMetadataWithNotify(i + 2, j + 33, k + 9, 1, 2);
		setBlock(world, i + 2, j + 33, k + 10, Blocks.log, 1);
		world.setBlockMetadataWithNotify(i + 2, j + 33, k + 10, 1, 2);
		setBlock(world, i + 2, j + 33, k + 11, Blocks.log, 1);
		world.setBlockMetadataWithNotify(i + 2, j + 33, k + 11, 1, 2);
		setBlock(world, i + 2, j + 33, k + 12, Blocks.log, 1);
		world.setBlockMetadataWithNotify(i + 2, j + 33, k + 12, 1, 2);
		setBlock(world, i + 2, j + 34, k + 0, Blocks.log, 1);
		world.setBlockMetadataWithNotify(i + 2, j + 34, k + 0, 1, 2);
		setBlock(world, i + 2, j + 34, k + 1, Blocks.log, 1);
		world.setBlockMetadataWithNotify(i + 2, j + 34, k + 1, 1, 2);
		setBlock(world, i + 2, j + 34, k + 2, Blocks.log, 1);
		world.setBlockMetadataWithNotify(i + 2, j + 34, k + 2, 1, 2);
		setBlock(world, i + 2, j + 34, k + 3, Blocks.log, 1);
		world.setBlockMetadataWithNotify(i + 2, j + 34, k + 3, 1, 2);
		setBlock(world, i + 2, j + 34, k + 4, Blocks.log, 1);
		world.setBlockMetadataWithNotify(i + 2, j + 34, k + 4, 1, 2);
		setBlock(world, i + 2, j + 34, k + 5, Blocks.log, 1);
		world.setBlockMetadataWithNotify(i + 2, j + 34, k + 5, 1, 2);
		setBlock(world, i + 2, j + 34, k + 6, Blocks.log, 1);
		world.setBlockMetadataWithNotify(i + 2, j + 34, k + 6, 1, 2);
		setBlock(world, i + 2, j + 34, k + 7, Blocks.log, 1);
		world.setBlockMetadataWithNotify(i + 2, j + 34, k + 7, 1, 2);
		setBlock(world, i + 2, j + 34, k + 8, Blocks.log, 1);
		world.setBlockMetadataWithNotify(i + 2, j + 34, k + 8, 1, 2);
		setBlock(world, i + 2, j + 34, k + 9, Blocks.log, 1);
		world.setBlockMetadataWithNotify(i + 2, j + 34, k + 9, 1, 2);
		setBlock(world, i + 2, j + 34, k + 10, Blocks.log, 1);
		world.setBlockMetadataWithNotify(i + 2, j + 34, k + 10, 1, 2);
		setBlock(world, i + 2, j + 34, k + 11, Blocks.log, 1);
		world.setBlockMetadataWithNotify(i + 2, j + 34, k + 11, 1, 2);
		setBlock(world, i + 2, j + 35, k + 2, Blocks.log, 1);
		world.setBlockMetadataWithNotify(i + 2, j + 35, k + 2, 1, 2);
		setBlock(world, i + 2, j + 35, k + 3, Blocks.log, 1);
		world.setBlockMetadataWithNotify(i + 2, j + 35, k + 3, 1, 2);
		setBlock(world, i + 2, j + 35, k + 4, Blocks.log, 1);
		world.setBlockMetadataWithNotify(i + 2, j + 35, k + 4, 1, 2);
		setBlock(world, i + 2, j + 35, k + 5, Blocks.log, 1);
		world.setBlockMetadataWithNotify(i + 2, j + 35, k + 5, 1, 2);
		setBlock(world, i + 2, j + 35, k + 6, Blocks.log, 1);
		world.setBlockMetadataWithNotify(i + 2, j + 35, k + 6, 1, 2);
		setBlock(world, i + 2, j + 35, k + 7, Blocks.log, 1);
		world.setBlockMetadataWithNotify(i + 2, j + 35, k + 7, 1, 2);
		setBlock(world, i + 2, j + 35, k + 8, Blocks.log, 1);
		world.setBlockMetadataWithNotify(i + 2, j + 35, k + 8, 1, 2);
		setBlock(world, i + 2, j + 40, k + 31, Blocks.planks, 5);
		world.setBlockMetadataWithNotify(i + 2, j + 40, k + 31, 5, 2);
		setBlock(world, i + 2, j + 41, k + 31, Blocks.torch, 5);
		world.setBlockMetadataWithNotify(i + 2, j + 41, k + 31, 5, 2);
		setBlock(world, i + 2, j + 50, k + 31, Blocks.leaves, 15);
		world.setBlockMetadataWithNotify(i + 2, j + 50, k + 31, 15, 2);
		setBlock(world, i + 3, j + 2, k + 6, Blocks.torch, 1);
		world.setBlockMetadataWithNotify(i + 3, j + 2, k + 6, 1, 2);
		setBlock(world, i + 3, j + 6, k + 7, Blocks.planks, 5);
		world.setBlockMetadataWithNotify(i + 3, j + 6, k + 7, 5, 2);
		setBlock(world, i + 3, j + 6, k + 8, Blocks.planks, 5);
		world.setBlockMetadataWithNotify(i + 3, j + 6, k + 8, 5, 2);
		setBlock(world, i + 3, j + 6, k + 9, Blocks.planks, 5);
		world.setBlockMetadataWithNotify(i + 3, j + 6, k + 9, 5, 2);
		setBlock(world, i + 3, j + 6, k + 10, Blocks.planks, 5);
		world.setBlockMetadataWithNotify(i + 3, j + 6, k + 10, 5, 2);
		setBlock(world, i + 3, j + 7, k + 6, Blocks.planks, 5);
		world.setBlockMetadataWithNotify(i + 3, j + 7, k + 6, 5, 2);
		setBlock(world, i + 3, j + 7, k + 7, Blocks.planks, 5);
		world.setBlockMetadataWithNotify(i + 3, j + 7, k + 7, 5, 2);
		setBlock(world, i + 3, j + 7, k + 8, Blocks.spruce_stairs, 3);
		world.setBlockMetadataWithNotify(i + 3, j + 7, k + 8, 3, 2);
		setBlock(world, i + 3, j + 8, k + 4, Blocks.planks, 5);
		world.setBlockMetadataWithNotify(i + 3, j + 8, k + 4, 5, 2);
		setBlock(world, i + 3, j + 8, k + 5, Blocks.planks, 5);
		world.setBlockMetadataWithNotify(i + 3, j + 8, k + 5, 5, 2);
		setBlock(world, i + 3, j + 8, k + 6, Blocks.planks, 5);
		world.setBlockMetadataWithNotify(i + 3, j + 8, k + 6, 5, 2);
		setBlock(world, i + 3, j + 8, k + 7, Blocks.spruce_stairs, 3);
		world.setBlockMetadataWithNotify(i + 3, j + 8, k + 7, 3, 2);
		setBlock(world, i + 3, j + 11, k + 6, Blocks.torch, 1);
		world.setBlockMetadataWithNotify(i + 3, j + 11, k + 6, 1, 2);
		setBlock(world, i + 3, j + 12, k + 10, Blocks.planks, 5);
		world.setBlockMetadataWithNotify(i + 3, j + 12, k + 10, 5, 2);
		setBlock(world, i + 3, j + 13, k + 8, Blocks.planks, 5);
		world.setBlockMetadataWithNotify(i + 3, j + 13, k + 8, 5, 2);
		setBlock(world, i + 3, j + 13, k + 9, Blocks.planks, 5);
		world.setBlockMetadataWithNotify(i + 3, j + 13, k + 9, 5, 2);
		setBlock(world, i + 3, j + 13, k + 10, Blocks.planks, 5);
		world.setBlockMetadataWithNotify(i + 3, j + 13, k + 10, 5, 2);
		setBlock(world, i + 3, j + 13, k + 11, Blocks.planks, 5);
		world.setBlockMetadataWithNotify(i + 3, j + 13, k + 11, 5, 2);
		setBlock(world, i + 3, j + 14, k + 7, Blocks.planks, 5);
		world.setBlockMetadataWithNotify(i + 3, j + 14, k + 7, 5, 2);
		setBlock(world, i + 3, j + 14, k + 8, Blocks.planks, 5);
		world.setBlockMetadataWithNotify(i + 3, j + 14, k + 8, 5, 2);
		setBlock(world, i + 3, j + 14, k + 9, Blocks.planks, 5);
		world.setBlockMetadataWithNotify(i + 3, j + 14, k + 9, 5, 2);
		setBlock(world, i + 3, j + 14, k + 10, Blocks.planks, 5);
		world.setBlockMetadataWithNotify(i + 3, j + 14, k + 10, 5, 2);
		setBlock(world, i + 3, j + 14, k + 11, Blocks.planks, 5);
		world.setBlockMetadataWithNotify(i + 3, j + 14, k + 11, 5, 2);
		setBlock(world, i + 3, j + 14, k + 12, Blocks.planks, 5);
		world.setBlockMetadataWithNotify(i + 3, j + 14, k + 12, 5, 2);
		setBlock(world, i + 3, j + 18, k + 4, Blocks.vine, 8);
		world.setBlockMetadataWithNotify(i + 3, j + 18, k + 4, 8, 2);
		setBlock(world, i + 3, j + 18, k + 5, Blocks.vine, 13);
		world.setBlockMetadataWithNotify(i + 3, j + 18, k + 5, 13, 2);
		setBlock(world, i + 3, j + 19, k + 2, Blocks.vine, 10);
		world.setBlockMetadataWithNotify(i + 3, j + 19, k + 2, 10, 2);
		setBlock(world, i + 3, j + 19, k + 3, Blocks.vine, 7);
		world.setBlockMetadataWithNotify(i + 3, j + 19, k + 3, 7, 2);
		setBlock(world, i + 3, j + 19, k + 4, Blocks.vine, 15);
		world.setBlockMetadataWithNotify(i + 3, j + 19, k + 4, 15, 2);
		setBlock(world, i + 3, j + 19, k + 5, Blocks.vine, 15);
		world.setBlockMetadataWithNotify(i + 3, j + 19, k + 5, 15, 2);
		setBlock(world, i + 3, j + 19, k + 6, Blocks.vine, 15);
		world.setBlockMetadataWithNotify(i + 3, j + 19, k + 6, 15, 2);
		setBlock(world, i + 3, j + 20, k + 0, Blocks.vine, 1);
		world.setBlockMetadataWithNotify(i + 3, j + 20, k + 0, 1, 2);
		setBlock(world, i + 3, j + 20, k + 2, Blocks.vine, 11);
		world.setBlockMetadataWithNotify(i + 3, j + 20, k + 2, 11, 2);
		setBlock(world, i + 3, j + 20, k + 3, Blocks.vine, 15);
		world.setBlockMetadataWithNotify(i + 3, j + 20, k + 3, 15, 2);
		setBlock(world, i + 3, j + 20, k + 4, Blocks.vine, 15);
		world.setBlockMetadataWithNotify(i + 3, j + 20, k + 4, 15, 2);
		setBlock(world, i + 3, j + 20, k + 5, Blocks.log, 1);
		world.setBlockMetadataWithNotify(i + 3, j + 20, k + 5, 1, 2);
		setBlock(world, i + 3, j + 20, k + 6, Blocks.log, 1);
		world.setBlockMetadataWithNotify(i + 3, j + 20, k + 6, 1, 2);
		setBlock(world, i + 3, j + 20, k + 7, Blocks.log, 1);
		world.setBlockMetadataWithNotify(i + 3, j + 20, k + 7, 1, 2);
		setBlock(world, i + 3, j + 21, k + 0, Blocks.vine, 15);
		world.setBlockMetadataWithNotify(i + 3, j + 21, k + 0, 15, 2);
		setBlock(world, i + 3, j + 21, k + 1, Blocks.vine, 15);
		world.setBlockMetadataWithNotify(i + 3, j + 21, k + 1, 15, 2);
		setBlock(world, i + 3, j + 21, k + 2, Blocks.vine, 15);
		world.setBlockMetadataWithNotify(i + 3, j + 21, k + 2, 15, 2);
		setBlock(world, i + 3, j + 21, k + 3, Blocks.vine, 15);
		world.setBlockMetadataWithNotify(i + 3, j + 21, k + 3, 15, 2);
		setBlock(world, i + 3, j + 21, k + 4, Blocks.log, 1);
		world.setBlockMetadataWithNotify(i + 3, j + 21, k + 4, 1, 2);
		setBlock(world, i + 3, j + 21, k + 5, Blocks.log, 1);
		world.setBlockMetadataWithNotify(i + 3, j + 21, k + 5, 1, 2);
		setBlock(world, i + 3, j + 21, k + 6, Blocks.log, 1);
		world.setBlockMetadataWithNotify(i + 3, j + 21, k + 6, 1, 2);
		setBlock(world, i + 3, j + 21, k + 7, Blocks.log, 1);
		world.setBlockMetadataWithNotify(i + 3, j + 21, k + 7, 1, 2);
		setBlock(world, i + 3, j + 21, k + 8, Blocks.log, 1);
		world.setBlockMetadataWithNotify(i + 3, j + 21, k + 8, 1, 2);
		setBlock(world, i + 3, j + 22, k + 0, Blocks.vine, 15);
		world.setBlockMetadataWithNotify(i + 3, j + 22, k + 0, 15, 2);
		setBlock(world, i + 3, j + 22, k + 1, Blocks.vine, 15);
		world.setBlockMetadataWithNotify(i + 3, j + 22, k + 1, 15, 2);
		setBlock(world, i + 3, j + 22, k + 2, Blocks.log, 1);
		world.setBlockMetadataWithNotify(i + 3, j + 22, k + 2, 1, 2);
		setBlock(world, i + 3, j + 22, k + 3, Blocks.vine, 15);
		world.setBlockMetadataWithNotify(i + 3, j + 22, k + 3, 15, 2);
		setBlock(world, i + 3, j + 22, k + 4, Blocks.log, 1);
		world.setBlockMetadataWithNotify(i + 3, j + 22, k + 4, 1, 2);
		setBlock(world, i + 3, j + 22, k + 5, Blocks.log, 1);
		world.setBlockMetadataWithNotify(i + 3, j + 22, k + 5, 1, 2);
		setBlock(world, i + 3, j + 22, k + 6, Blocks.log, 1);
		world.setBlockMetadataWithNotify(i + 3, j + 22, k + 6, 1, 2);
		setBlock(world, i + 3, j + 22, k + 7, Blocks.log, 1);
		world.setBlockMetadataWithNotify(i + 3, j + 22, k + 7, 1, 2);
		setBlock(world, i + 3, j + 22, k + 21, Blocks.planks, 5);
		world.setBlockMetadataWithNotify(i + 3, j + 22, k + 21, 5, 2);
		setBlock(world, i + 3, j + 22, k + 22, Blocks.planks, 5);
		world.setBlockMetadataWithNotify(i + 3, j + 22, k + 22, 5, 2);
		setBlock(world, i + 3, j + 22, k + 23, Blocks.planks, 5);
		world.setBlockMetadataWithNotify(i + 3, j + 22, k + 23, 5, 2);
		setBlock(world, i + 3, j + 23, k + 0, Blocks.vine, 15);
		world.setBlockMetadataWithNotify(i + 3, j + 23, k + 0, 15, 2);
		setBlock(world, i + 3, j + 23, k + 1, Blocks.log, 1);
		world.setBlockMetadataWithNotify(i + 3, j + 23, k + 1, 1, 2);
		setBlock(world, i + 3, j + 23, k + 2, Blocks.log, 1);
		world.setBlockMetadataWithNotify(i + 3, j + 23, k + 2, 1, 2);
		setBlock(world, i + 3, j + 23, k + 3, Blocks.log, 1);
		world.setBlockMetadataWithNotify(i + 3, j + 23, k + 3, 1, 2);
		setBlock(world, i + 3, j + 23, k + 4, Blocks.log, 1);
		world.setBlockMetadataWithNotify(i + 3, j + 23, k + 4, 1, 2);
		setBlock(world, i + 3, j + 23, k + 5, Blocks.log, 1);
		world.setBlockMetadataWithNotify(i + 3, j + 23, k + 5, 1, 2);
		setBlock(world, i + 3, j + 23, k + 6, Blocks.vine, 15);
		world.setBlockMetadataWithNotify(i + 3, j + 23, k + 6, 15, 2);
		setBlock(world, i + 3, j + 23, k + 7, Blocks.vine, 15);
		world.setBlockMetadataWithNotify(i + 3, j + 23, k + 7, 15, 2);
		setBlock(world, i + 3, j + 23, k + 8, Blocks.vine, 15);
		world.setBlockMetadataWithNotify(i + 3, j + 23, k + 8, 15, 2);
		setBlock(world, i + 3, j + 23, k + 20, Blocks.planks, 5);
		world.setBlockMetadataWithNotify(i + 3, j + 23, k + 20, 5, 2);
		setBlock(world, i + 3, j + 23, k + 21, Blocks.planks, 5);
		world.setBlockMetadataWithNotify(i + 3, j + 23, k + 21, 5, 2);
		setBlock(world, i + 3, j + 23, k + 22, Blocks.spruce_stairs, 3);
		world.setBlockMetadataWithNotify(i + 3, j + 23, k + 22, 3, 2);
		setBlock(world, i + 3, j + 23, k + 26, Blocks.leaves, 15);
		world.setBlockMetadataWithNotify(i + 3, j + 23, k + 26, 15, 2);
		setBlock(world, i + 3, j + 23, k + 27, Blocks.leaves, 15);
		world.setBlockMetadataWithNotify(i + 3, j + 23, k + 27, 15, 2);
		setBlock(world, i + 3, j + 23, k + 28, Blocks.log, 3);
