/*      */package com.parzivail.pswm.world.gen.wookietree;

/*      */
/*      *//*      */
/*      */
import com.parzivail.pswm.utils.LootGenUtils;
import com.parzivail.pswm.utils.NPCType;
import com.parzivail.pswm.utils.SpawnUtils;


/*      */
import cpw.mods.fml.common.IWorldGenerator;


/*      */
import java.util.Random;


/*      */
import net.minecraft.block.Block;
/*      */
import net.minecraft.init.Blocks;
/*      */
import net.minecraft.tileentity.TileEntityChest;
/*      */
import net.minecraft.world.World;
/*      */
import net.minecraft.world.WorldProvider;
/*      */
import net.minecraft.world.chunk.IChunkProvider;
/*      */
import net.minecraft.world.gen.feature.WorldGenerator;

/*      */
/*      */public class WT_11
/*      */extends WorldGenerator implements IWorldGenerator
/*      */
{
	/*      */protected Block[] getValidSpawnBlocks()
	/*      */
	{
		return new Block[0];
		/*      */}

	/*      */
	/*      */public boolean locationIsValidSpawn(World world, int i, int j, int k)
	/*      */
	{
		int distanceToAir = 0;
		Block check = world.getBlock(i, j, k);
		/*      */
		while (check != Blocks.air)
		{
			if (distanceToAir > 3) { return false;
			/*      */}
			/*      */
			distanceToAir++;
			check = world.getBlock(i, j + distanceToAir, k);
			/*      */}
		/*      */
		j += distanceToAir - 1;
		/*      */
		Block block = world.getBlock(i, j, k);
		Block blockAbove = world.getBlock(i, j + 1, k);
		Block blockBelow = world.getBlock(i, j - 1, k);
		/*      */
		for (Block x : getValidSpawnBlocks())
		{
			if (blockAbove != Blocks.air) { return false;
			/*      */}
			if (block == x) return true;
			if ((block == Blocks.snow) && (blockBelow == x)) { return true;
			/*      */}
			/*      */}
		/*      */
		return false;
		/*      */}

	/*      */
	/*      */
	/*      */
	/*      */public void generate(Random random, int chunkX, int chunkZ, World world, IChunkProvider chunkGenerator, IChunkProvider chunkProvider)
	{
	}

	/*      */
	/*      */
	/*      */public void setBlock(World world, int x, int y, int z, Block block, int metadata)
	/*      */
	{
		world.setBlock(x, y, z, block, metadata, 2);
		/*      */}

	/*      */
	/*      */public boolean generate(World world, Random rand, int i, int j, int k)
	/*      */
	{
		k -= 10;
		i -= 10;
		/*      */
		setBlock(world, i + 0, j + 5, k + 9, Blocks.spruce_stairs, 0);
		setBlock(world, i + 0, j + 5, k + 10, Blocks.spruce_stairs, 0);
		setBlock(world, i + 0, j + 13, k + 9, Blocks.spruce_stairs, 0);
		setBlock(world, i + 0, j + 13, k + 10, Blocks.spruce_stairs, 0);
		setBlock(world, i + 0, j + 27, k + 5, Blocks.spruce_stairs, 0);
		setBlock(world, i + 0, j + 27, k + 6, Blocks.crafting_table, 0);
		setBlock(world, i + 1, j + 6, k + 9, Blocks.spruce_stairs, 0);
		setBlock(world, i + 1, j + 6, k + 10, Blocks.spruce_stairs, 0);
		setBlock(world, i + 1, j + 14, k + 9, Blocks.spruce_stairs, 0);
		setBlock(world, i + 1, j + 14, k + 10, Blocks.spruce_stairs, 0);
		SpawnUtils.spawnNPC(NPCType.WOOKIETREE, world, i + 3, j + 27, k + 3);
		SpawnUtils.spawnNPC(NPCType.WOOKIETREE, world, i + 3, j + 27, k + 7);
		setBlock(world, i + 4, j + 27, k + 0, Blocks.fence, 0);
		setBlock(world, i + 4, j + 27, k + 10, Blocks.fence, 0);
		setBlock(world, i + 4, j + 29, k + 12, Blocks.fence, 0);
		setBlock(world, i + 4, j + 29, k + 13, Blocks.fence, 0);
		setBlock(world, i + 5, j + 15, k + 9, Blocks.spruce_stairs, 0);
		setBlock(world, i + 5, j + 15, k + 10, Blocks.spruce_stairs, 0);
		setBlock(world, i + 5, j + 15, k + 11, Blocks.spruce_stairs, 0);
		setBlock(world, i + 5, j + 15, k + 12, Blocks.spruce_stairs, 0);
		setBlock(world, i + 5, j + 15, k + 13, Blocks.spruce_stairs, 0);
		setBlock(world, i + 5, j + 27, k + 0, Blocks.fence, 0);
		setBlock(world, i + 5, j + 27, k + 1, Blocks.fence, 0);
		setBlock(world, i + 5, j + 27, k + 9, Blocks.fence, 0);
		setBlock(world, i + 5, j + 27, k + 10, Blocks.fence, 0);
		setBlock(world, i + 6, j + 16, k + 9, Blocks.spruce_stairs, 0);
		setBlock(world, i + 6, j + 16, k + 10, Blocks.spruce_stairs, 0);
		setBlock(world, i + 6, j + 16, k + 11, Blocks.spruce_stairs, 0);
		setBlock(world, i + 6, j + 16, k + 12, Blocks.spruce_stairs, 0);
		setBlock(world, i + 6, j + 16, k + 13, Blocks.spruce_stairs, 0);
		setBlock(world, i + 6, j + 27, k + 1, Blocks.fence, 0);
		setBlock(world, i + 6, j + 27, k + 2, Blocks.fence, 0);
		setBlock(world, i + 6, j + 27, k + 3, Blocks.spruce_stairs, 0);
		setBlock(world, i + 6, j + 27, k + 7, Blocks.spruce_stairs, 0);
		setBlock(world, i + 6, j + 27, k + 8, Blocks.fence, 0);
		setBlock(world, i + 6, j + 27, k + 9, Blocks.fence, 0);
		setBlock(world, i + 7, j + 17, k + 9, Blocks.spruce_stairs, 0);
		setBlock(world, i + 7, j + 17, k + 10, Blocks.spruce_stairs, 0);
		setBlock(world, i + 7, j + 17, k + 11, Blocks.spruce_stairs, 0);
		setBlock(world, i + 7, j + 17, k + 12, Blocks.spruce_stairs, 0);
		setBlock(world, i + 7, j + 17, k + 13, Blocks.spruce_stairs, 0);
		setBlock(world, i + 8, j + 29, k + 2, Blocks.fence, 0);
		setBlock(world, i + 8, j + 29, k + 8, Blocks.fence, 0);
		setBlock(world, i + 9, j + 29, k + 2, Blocks.fence, 0);
		setBlock(world, i + 9, j + 29, k + 8, Blocks.fence, 0);
		setBlock(world, i + 10, j + 18, k + 9, Blocks.spruce_stairs, 0);
		setBlock(world, i + 10, j + 18, k + 10, Blocks.spruce_stairs, 0);
		setBlock(world, i + 10, j + 18, k + 11, Blocks.spruce_stairs, 0);
		setBlock(world, i + 10, j + 18, k + 12, Blocks.spruce_stairs, 0);
		setBlock(world, i + 10, j + 18, k + 13, Blocks.spruce_stairs, 0);
		setBlock(world, i + 11, j + 19, k + 9, Blocks.spruce_stairs, 0);
		setBlock(world, i + 11, j + 19, k + 10, Blocks.spruce_stairs, 0);
		setBlock(world, i + 11, j + 19, k + 11, Blocks.spruce_stairs, 0);
		setBlock(world, i + 11, j + 19, k + 12, Blocks.spruce_stairs, 0);
		setBlock(world, i + 11, j + 19, k + 13, Blocks.spruce_stairs, 0);
		setBlock(world, i + 12, j + 20, k + 9, Blocks.spruce_stairs, 0);
		setBlock(world, i + 12, j + 20, k + 10, Blocks.spruce_stairs, 0);
		setBlock(world, i + 12, j + 20, k + 11, Blocks.spruce_stairs, 0);
		setBlock(world, i + 12, j + 20, k + 12, Blocks.spruce_stairs, 0);
		setBlock(world, i + 12, j + 20, k + 13, Blocks.spruce_stairs, 0);
		setBlock(world, i + 13, j + 21, k + 9, Blocks.spruce_stairs, 0);
		setBlock(world, i + 13, j + 21, k + 10, Blocks.spruce_stairs, 0);
		setBlock(world, i + 13, j + 21, k + 11, Blocks.spruce_stairs, 0);
		setBlock(world, i + 13, j + 21, k + 12, Blocks.spruce_stairs, 0);
		setBlock(world, i + 13, j + 21, k + 13, Blocks.spruce_stairs, 0);
		setBlock(world, i + 13, j + 25, k + 26, Blocks.fence, 0);
		setBlock(world, i + 14, j + 22, k + 9, Blocks.spruce_stairs, 0);
		setBlock(world, i + 14, j + 22, k + 10, Blocks.spruce_stairs, 0);
		setBlock(world, i + 14, j + 22, k + 11, Blocks.spruce_stairs, 0);
		setBlock(world, i + 14, j + 22, k + 12, Blocks.spruce_stairs, 0);
		setBlock(world, i + 14, j + 22, k + 13, Blocks.spruce_stairs, 0);
		setBlock(world, i + 14, j + 25, k + 26, Blocks.fence, 0);
		setBlock(world, i + 15, j + 23, k + 9, Blocks.spruce_stairs, 0);
		setBlock(world, i + 15, j + 23, k + 10, Blocks.spruce_stairs, 0);
		setBlock(world, i + 15, j + 23, k + 11, Blocks.spruce_stairs, 0);
		setBlock(world, i + 15, j + 23, k + 12, Blocks.spruce_stairs, 0);
		setBlock(world, i + 15, j + 23, k + 13, Blocks.spruce_stairs, 0);
		setBlock(world, i + 16, j + 23, k + 25, Blocks.fence, 0);
		setBlock(world, i + 16, j + 23, k + 26, Blocks.fence, 0);
		setBlock(world, i + 16, j + 24, k + 9, Blocks.spruce_stairs, 0);
		setBlock(world, i + 16, j + 24, k + 10, Blocks.spruce_stairs, 0);
		setBlock(world, i + 16, j + 24, k + 11, Blocks.spruce_stairs, 0);
		setBlock(world, i + 16, j + 24, k + 12, Blocks.spruce_stairs, 0);
		setBlock(world, i + 16, j + 24, k + 13, Blocks.spruce_stairs, 0);
		setBlock(world, i + 17, j + 23, k + 24, Blocks.fence, 0);
		setBlock(world, i + 17, j + 23, k + 25, Blocks.fence, 0);
		setBlock(world, i + 18, j + 23, k + 23, Blocks.spruce_stairs, 0);
		setBlock(world, i + 18, j + 23, k + 24, Blocks.fence, 0);
		setBlock(world, i + 18, j + 25, k + 21, Blocks.fence, 0);
		setBlock(world, i + 18, j + 25, k + 22, Blocks.fence, 0);
		SpawnUtils.spawnNPC(NPCType.WOOKIETREE, world, i + 19, j + 23, k + 27);
		SpawnUtils.spawnNPC(NPCType.WOOKIETREE, world, i + 19, j + 23, k + 31);
		setBlock(world, i + 20, j + 23, k + 29, Blocks.spruce_stairs, 0);
		setBlock(world, i + 22, j + 23, k + 28, Blocks.crafting_table, 0);
		SpawnUtils.spawnNPC(NPCType.WOOKIETREE, world, i + 23, j + 23, k + 27);
		SpawnUtils.spawnNPC(NPCType.WOOKIETREE, world, i + 23, j + 23, k + 31);
		setBlock(world, i + 24, j + 23, k + 24, Blocks.fence, 0);
		setBlock(world, i + 24, j + 25, k + 21, Blocks.fence, 0);
		setBlock(world, i + 24, j + 25, k + 22, Blocks.fence, 0);
		setBlock(world, i + 25, j + 23, k + 24, Blocks.fence, 0);
		setBlock(world, i + 25, j + 23, k + 25, Blocks.fence, 0);
		setBlock(world, i + 26, j + 23, k + 25, Blocks.fence, 0);
		setBlock(world, i + 26, j + 23, k + 26, Blocks.fence, 0);
		setBlock(world, i + 26, j + 23, k + 27, Blocks.spruce_stairs, 0);
		setBlock(world, i + 26, j + 23, k + 31, Blocks.spruce_stairs, 0);
		setBlock(world, i + 28, j + 25, k + 26, Blocks.fence, 0);
		setBlock(world, i + 29, j + 25, k + 26, Blocks.fence, 0);
		setBlock(world, i + 0, j + 0, k + 4, Blocks.planks, 5);
		world.setBlockMetadataWithNotify(i + 0, j + 0, k + 4, 5, 2);
		setBlock(world, i + 0, j + 0, k + 5, Blocks.planks, 5);
		world.setBlockMetadataWithNotify(i + 0, j + 0, k + 5, 5, 2);
		setBlock(world, i + 0, j + 0, k + 6, Blocks.log, 1);
		world.setBlockMetadataWithNotify(i + 0, j + 0, k + 6, 1, 2);
		setBlock(world, i + 0, j + 1, k + 4, Blocks.planks, 5);
		world.setBlockMetadataWithNotify(i + 0, j + 1, k + 4, 5, 2);
		setBlock(world, i + 0, j + 1, k + 5, Blocks.planks, 5);
		world.setBlockMetadataWithNotify(i + 0, j + 1, k + 5, 5, 2);
		setBlock(world, i + 0, j + 1, k + 6, Blocks.log, 1);
		world.setBlockMetadataWithNotify(i + 0, j + 1, k + 6, 1, 2);
		setBlock(world, i + 0, j + 1, k + 7, Blocks.log, 1);
		world.setBlockMetadataWithNotify(i + 0, j + 1, k + 7, 1, 2);
		setBlock(world, i + 0, j + 2, k + 4, Blocks.spruce_stairs, 1);
		world.setBlockMetadataWithNotify(i + 0, j + 2, k + 4, 1, 2);
		setBlock(world, i + 0, j + 2, k + 5, Blocks.spruce_stairs, 1);
		world.setBlockMetadataWithNotify(i + 0, j + 2, k + 5, 1, 2);
		setBlock(world, i + 0, j + 2, k + 6, Blocks.log, 1);
		world.setBlockMetadataWithNotify(i + 0, j + 2, k + 6, 1, 2);
		setBlock(world, i + 0, j + 2, k + 7, Blocks.log, 1);
		world.setBlockMetadataWithNotify(i + 0, j + 2, k + 7, 1, 2);
		setBlock(world, i + 0, j + 2, k + 8, Blocks.log, 1);
		world.setBlockMetadataWithNotify(i + 0, j + 2, k + 8, 1, 2);
		setBlock(world, i + 0, j + 3, k + 6, Blocks.log, 1);
		world.setBlockMetadataWithNotify(i + 0, j + 3, k + 6, 1, 2);
		setBlock(world, i + 0, j + 3, k + 7, Blocks.log, 1);
		world.setBlockMetadataWithNotify(i + 0, j + 3, k + 7, 1, 2);
		setBlock(world, i + 0, j + 3, k + 8, Blocks.log, 1);
		world.setBlockMetadataWithNotify(i + 0, j + 3, k + 8, 1, 2);
		setBlock(world, i + 0, j + 4, k + 6, Blocks.log, 1);
		world.setBlockMetadataWithNotify(i + 0, j + 4, k + 6, 1, 2);
		setBlock(world, i + 0, j + 4, k + 7, Blocks.log, 1);
		world.setBlockMetadataWithNotify(i + 0, j + 4, k + 7, 1, 2);
		setBlock(world, i + 0, j + 4, k + 8, Blocks.log, 1);
		world.setBlockMetadataWithNotify(i + 0, j + 4, k + 8, 1, 2);
		setBlock(world, i + 0, j + 4, k + 9, Blocks.planks, 5);
		world.setBlockMetadataWithNotify(i + 0, j + 4, k + 9, 5, 2);
		setBlock(world, i + 0, j + 4, k + 10, Blocks.planks, 5);
		world.setBlockMetadataWithNotify(i + 0, j + 4, k + 10, 5, 2);
		setBlock(world, i + 0, j + 5, k + 5, Blocks.torch, 4);
		world.setBlockMetadataWithNotify(i + 0, j + 5, k + 5, 4, 2);
		setBlock(world, i + 0, j + 5, k + 6, Blocks.log, 1);
		world.setBlockMetadataWithNotify(i + 0, j + 5, k + 6, 1, 2);
		setBlock(world, i + 0, j + 5, k + 7, Blocks.log, 1);
		world.setBlockMetadataWithNotify(i + 0, j + 5, k + 7, 1, 2);
		setBlock(world, i + 0, j + 5, k + 8, Blocks.log, 1);
		world.setBlockMetadataWithNotify(i + 0, j + 5, k + 8, 1, 2);
		setBlock(world, i + 0, j + 6, k + 6, Blocks.log, 1);
		world.setBlockMetadataWithNotify(i + 0, j + 6, k + 6, 1, 2);
		setBlock(world, i + 0, j + 6, k + 7, Blocks.log, 1);
		world.setBlockMetadataWithNotify(i + 0, j + 6, k + 7, 1, 2);
		setBlock(world, i + 0, j + 6, k + 8, Blocks.log, 1);
		world.setBlockMetadataWithNotify(i + 0, j + 6, k + 8, 1, 2);
		setBlock(world, i + 0, j + 7, k + 7, Blocks.log, 1);
		world.setBlockMetadataWithNotify(i + 0, j + 7, k + 7, 1, 2);
		setBlock(world, i + 0, j + 7, k + 8, Blocks.log, 1);
		world.setBlockMetadataWithNotify(i + 0, j + 7, k + 8, 1, 2);
		setBlock(world, i + 0, j + 8, k + 8, Blocks.log, 1);
		world.setBlockMetadataWithNotify(i + 0, j + 8, k + 8, 1, 2);
		setBlock(world, i + 0, j + 9, k + 4, Blocks.planks, 5);
		world.setBlockMetadataWithNotify(i + 0, j + 9, k + 4, 5, 2);
		setBlock(world, i + 0, j + 9, k + 5, Blocks.planks, 5);
		world.setBlockMetadataWithNotify(i + 0, j + 9, k + 5, 5, 2);
		setBlock(world, i + 0, j + 9, k + 6, Blocks.log, 1);
		world.setBlockMetadataWithNotify(i + 0, j + 9, k + 6, 1, 2);
		setBlock(world, i + 0, j + 9, k + 7, Blocks.log, 1);
		world.setBlockMetadataWithNotify(i + 0, j + 9, k + 7, 1, 2);
		setBlock(world, i + 0, j + 10, k + 4, Blocks.planks, 5);
		world.setBlockMetadataWithNotify(i + 0, j + 10, k + 4, 5, 2);
		setBlock(world, i + 0, j + 10, k + 5, Blocks.planks, 5);
		world.setBlockMetadataWithNotify(i + 0, j + 10, k + 5, 5, 2);
		setBlock(world, i + 0, j + 10, k + 6, Blocks.log, 1);
		world.setBlockMetadataWithNotify(i + 0, j + 10, k + 6, 1, 2);
		setBlock(world, i + 0, j + 10, k + 7, Blocks.log, 1);
		world.setBlockMetadataWithNotify(i + 0, j + 10, k + 7, 1, 2);
		setBlock(world, i + 0, j + 11, k + 6, Blocks.log, 1);
		world.setBlockMetadataWithNotify(i + 0, j + 11, k + 6, 1, 2);
		setBlock(world, i + 0, j + 11, k + 7, Blocks.log, 1);
		world.setBlockMetadataWithNotify(i + 0, j + 11, k + 7, 1, 2);
		setBlock(world, i + 0, j + 11, k + 8, Blocks.log, 1);
		world.setBlockMetadataWithNotify(i + 0, j + 11, k + 8, 1, 2);
		setBlock(world, i + 0, j + 12, k + 6, Blocks.log, 1);
		world.setBlockMetadataWithNotify(i + 0, j + 12, k + 6, 1, 2);
		setBlock(world, i + 0, j + 12, k + 7, Blocks.log, 1);
		world.setBlockMetadataWithNotify(i + 0, j + 12, k + 7, 1, 2);
		setBlock(world, i + 0, j + 12, k + 8, Blocks.log, 1);
		world.setBlockMetadataWithNotify(i + 0, j + 12, k + 8, 1, 2);
		setBlock(world, i + 0, j + 12, k + 9, Blocks.planks, 5);
		world.setBlockMetadataWithNotify(i + 0, j + 12, k + 9, 5, 2);
		setBlock(world, i + 0, j + 12, k + 10, Blocks.planks, 5);
		world.setBlockMetadataWithNotify(i + 0, j + 12, k + 10, 5, 2);
		setBlock(world, i + 0, j + 13, k + 5, Blocks.torch, 4);
		world.setBlockMetadataWithNotify(i + 0, j + 13, k + 5, 4, 2);
		setBlock(world, i + 0, j + 13, k + 6, Blocks.log, 1);
		world.setBlockMetadataWithNotify(i + 0, j + 13, k + 6, 1, 2);
		setBlock(world, i + 0, j + 13, k + 7, Blocks.log, 1);
		world.setBlockMetadataWithNotify(i + 0, j + 13, k + 7, 1, 2);
		setBlock(world, i + 0, j + 13, k + 8, Blocks.log, 1);
		world.setBlockMetadataWithNotify(i + 0, j + 13, k + 8, 1, 2);
		setBlock(world, i + 0, j + 14, k + 6, Blocks.log, 1);
		world.setBlockMetadataWithNotify(i + 0, j + 14, k + 6, 1, 2);
		setBlock(world, i + 0, j + 14, k + 7, Blocks.log, 1);
		world.setBlockMetadataWithNotify(i + 0, j + 14, k + 7, 1, 2);
		setBlock(world, i + 0, j + 15, k + 7, Blocks.log, 1);
		world.setBlockMetadataWithNotify(i + 0, j + 15, k + 7, 1, 2);
		setBlock(world, i + 0, j + 15, k + 8, Blocks.log, 1);
		world.setBlockMetadataWithNotify(i + 0, j + 15, k + 8, 1, 2);
		setBlock(world, i + 0, j + 16, k + 7, Blocks.log, 1);
		world.setBlockMetadataWithNotify(i + 0, j + 16, k + 7, 1, 2);
		setBlock(world, i + 0, j + 16, k + 8, Blocks.log, 1);
		world.setBlockMetadataWithNotify(i + 0, j + 16, k + 8, 1, 2);
		setBlock(world, i + 0, j + 17, k + 6, Blocks.log, 1);
		world.setBlockMetadataWithNotify(i + 0, j + 17, k + 6, 1, 2);
		setBlock(world, i + 0, j + 17, k + 7, Blocks.log, 1);
		world.setBlockMetadataWithNotify(i + 0, j + 17, k + 7, 1, 2);
		setBlock(world, i + 0, j + 17, k + 8, Blocks.log, 1);
		world.setBlockMetadataWithNotify(i + 0, j + 17, k + 8, 1, 2);
		setBlock(world, i + 0, j + 18, k + 2, Blocks.vine, 14);
		world.setBlockMetadataWithNotify(i + 0, j + 18, k + 2, 14, 2);
		setBlock(world, i + 0, j + 18, k + 6, Blocks.log, 1);
		world.setBlockMetadataWithNotify(i + 0, j + 18, k + 6, 1, 2);
		setBlock(world, i + 0, j + 18, k + 7, Blocks.log, 1);
		world.setBlockMetadataWithNotify(i + 0, j + 18, k + 7, 1, 2);
		setBlock(world, i + 0, j + 18, k + 8, Blocks.log, 1);
		world.setBlockMetadataWithNotify(i + 0, j + 18, k + 8, 1, 2);
		setBlock(world, i + 0, j + 19, k + 2, Blocks.vine, 14);
		world.setBlockMetadataWithNotify(i + 0, j + 19, k + 2, 14, 2);
		setBlock(world, i + 0, j + 19, k + 3, Blocks.vine, 15);
		world.setBlockMetadataWithNotify(i + 0, j + 19, k + 3, 15, 2);
		setBlock(world, i + 0, j + 19, k + 6, Blocks.log, 1);
		world.setBlockMetadataWithNotify(i + 0, j + 19, k + 6, 1, 2);
		setBlock(world, i + 0, j + 19, k + 7, Blocks.log, 1);
		world.setBlockMetadataWithNotify(i + 0, j + 19, k + 7, 1, 2);
		setBlock(world, i + 0, j + 19, k + 8, Blocks.log, 1);
		world.setBlockMetadataWithNotify(i + 0, j + 19, k + 8, 1, 2);
		setBlock(world, i + 0, j + 20, k + 1, Blocks.vine, 11);
		world.setBlockMetadataWithNotify(i + 0, j + 20, k + 1, 11, 2);
		setBlock(world, i + 0, j + 20, k + 2, Blocks.vine, 15);
		world.setBlockMetadataWithNotify(i + 0, j + 20, k + 2, 15, 2);
		setBlock(world, i + 0, j + 20, k + 3, Blocks.vine, 15);
		world.setBlockMetadataWithNotify(i + 0, j + 20, k + 3, 15, 2);
		setBlock(world, i + 0, j + 20, k + 4, Blocks.log, 1);
		world.setBlockMetadataWithNotify(i + 0, j + 20, k + 4, 1, 2);
		setBlock(world, i + 0, j + 20, k + 5, Blocks.log, 1);
		world.setBlockMetadataWithNotify(i + 0, j + 20, k + 5, 1, 2);
		setBlock(world, i + 0, j + 20, k + 6, Blocks.log, 1);
		world.setBlockMetadataWithNotify(i + 0, j + 20, k + 6, 1, 2);
		setBlock(world, i + 0, j + 20, k + 7, Blocks.log, 1);
		world.setBlockMetadataWithNotify(i + 0, j + 20, k + 7, 1, 2);
		setBlock(world, i + 0, j + 20, k + 8, Blocks.log, 1);
		world.setBlockMetadataWithNotify(i + 0, j + 20, k + 8, 1, 2);
		setBlock(world, i + 0, j + 21, k + 1, Blocks.vine, 15);
		world.setBlockMetadataWithNotify(i + 0, j + 21, k + 1, 15, 2);
		setBlock(world, i + 0, j + 21, k + 2, Blocks.vine, 15);
		world.setBlockMetadataWithNotify(i + 0, j + 21, k + 2, 15, 2);
		setBlock(world, i + 0, j + 21, k + 3, Blocks.log, 1);
		world.setBlockMetadataWithNotify(i + 0, j + 21, k + 3, 1, 2);
		setBlock(world, i + 0, j + 21, k + 4, Blocks.log, 1);
		world.setBlockMetadataWithNotify(i + 0, j + 21, k + 4, 1, 2);
		setBlock(world, i + 0, j + 21, k + 5, Blocks.log, 1);
		world.setBlockMetadataWithNotify(i + 0, j + 21, k + 5, 1, 2);
		setBlock(world, i + 0, j + 21, k + 6, Blocks.log, 1);
		world.setBlockMetadataWithNotify(i + 0, j + 21, k + 6, 1, 2);
		setBlock(world, i + 0, j + 21, k + 7, Blocks.log, 1);
		world.setBlockMetadataWithNotify(i + 0, j + 21, k + 7, 1, 2);
		setBlock(world, i + 0, j + 21, k + 8, Blocks.log, 1);
		world.setBlockMetadataWithNotify(i + 0, j + 21, k + 8, 1, 2);
		setBlock(world, i + 0, j + 22, k + 0, Blocks.vine, 15);
		world.setBlockMetadataWithNotify(i + 0, j + 22, k + 0, 15, 2);
		setBlock(world, i + 0, j + 22, k + 1, Blocks.vine, 15);
		world.setBlockMetadataWithNotify(i + 0, j + 22, k + 1, 15, 2);
		setBlock(world, i + 0, j + 22, k + 2, Blocks.vine, 15);
		world.setBlockMetadataWithNotify(i + 0, j + 22, k + 2, 15, 2);
		setBlock(world, i + 0, j + 22, k + 3, Blocks.log, 1);
		world.setBlockMetadataWithNotify(i + 0, j + 22, k + 3, 1, 2);
		setBlock(world, i + 0, j + 22, k + 4, Blocks.log, 1);
		world.setBlockMetadataWithNotify(i + 0, j + 22, k + 4, 1, 2);
		setBlock(world, i + 0, j + 22, k + 5, Blocks.log, 1);
		world.setBlockMetadataWithNotify(i + 0, j + 22, k + 5, 1, 2);
		setBlock(world, i + 0, j + 22, k + 6, Blocks.log, 1);
		world.setBlockMetadataWithNotify(i + 0, j + 22, k + 6, 1, 2);
		setBlock(world, i + 0, j + 22, k + 7, Blocks.log, 1);
		world.setBlockMetadataWithNotify(i + 0, j + 22, k + 7, 1, 2);
		setBlock(world, i + 0, j + 22, k + 8, Blocks.log, 1);
		world.setBlockMetadataWithNotify(i + 0, j + 22, k + 8, 1, 2);
		setBlock(world, i + 0, j + 22, k + 31, Blocks.log, 3);
		world.setBlockMetadataWithNotify(i + 0, j + 22, k + 31, 3, 2);
		setBlock(world, i + 0, j + 23, k + 0, Blocks.vine, 15);
		world.setBlockMetadataWithNotify(i + 0, j + 23, k + 0, 15, 2);
		setBlock(world, i + 0, j + 23, k + 1, Blocks.vine, 15);
		world.setBlockMetadataWithNotify(i + 0, j + 23, k + 1, 15, 2);
		setBlock(world, i + 0, j + 23, k + 3, Blocks.log, 1);
		world.setBlockMetadataWithNotify(i + 0, j + 23, k + 3, 1, 2);
		setBlock(world, i + 0, j + 23, k + 4, Blocks.log, 1);
		world.setBlockMetadataWithNotify(i + 0, j + 23, k + 4, 1, 2);
		setBlock(world, i + 0, j + 23, k + 5, Blocks.log, 1);
		world.setBlockMetadataWithNotify(i + 0, j + 23, k + 5, 1, 2);
		setBlock(world, i + 0, j + 23, k + 6, Blocks.leaves, 15);
		world.setBlockMetadataWithNotify(i + 0, j + 23, k + 6, 15, 2);
		setBlock(world, i + 0, j + 24, k + 3, Blocks.log, 1);
		world.setBlockMetadataWithNotify(i + 0, j + 24, k + 3, 1, 2);
		setBlock(world, i + 0, j + 24, k + 4, Blocks.log, 1);
		world.setBlockMetadataWithNotify(i + 0, j + 24, k + 4, 1, 2);
		setBlock(world, i + 0, j + 24, k + 5, Blocks.log, 1);
		world.setBlockMetadataWithNotify(i + 0, j + 24, k + 5, 1, 2);
		setBlock(world, i + 0, j + 24, k + 6, Blocks.log, 1);
		world.setBlockMetadataWithNotify(i + 0, j + 24, k + 6, 1, 2);
		setBlock(world, i + 0, j + 24, k + 7, Blocks.log, 1);
		world.setBlockMetadataWithNotify(i + 0, j + 24, k + 7, 1, 2);
		setBlock(world, i + 0, j + 24, k + 8, Blocks.log, 1);
		world.setBlockMetadataWithNotify(i + 0, j + 24, k + 8, 1, 2);
		setBlock(world, i + 0, j + 24, k + 9, Blocks.log, 1);
		world.setBlockMetadataWithNotify(i + 0, j + 24, k + 9, 1, 2);
		setBlock(world, i + 0, j + 24, k + 10, Blocks.log, 1);
		world.setBlockMetadataWithNotify(i + 0, j + 24, k + 10, 1, 2);
		setBlock(world, i + 0, j + 24, k + 11, Blocks.log, 1);
		world.setBlockMetadataWithNotify(i + 0, j + 24, k + 11, 1, 2);
		setBlock(world, i + 0, j + 24, k + 12, Blocks.log, 1);
		world.setBlockMetadataWithNotify(i + 0, j + 24, k + 12, 1, 2);
		setBlock(world, i + 0, j + 25, k + 5, Blocks.log, 1);
		world.setBlockMetadataWithNotify(i + 0, j + 25, k + 5, 1, 2);
		setBlock(world, i + 0, j + 25, k + 6, Blocks.log, 1);
		world.setBlockMetadataWithNotify(i + 0, j + 25, k + 6, 1, 2);
		setBlock(world, i + 0, j + 25, k + 7, Blocks.log, 1);
		world.setBlockMetadataWithNotify(i + 0, j + 25, k + 7, 1, 2);
		setBlock(world, i + 0, j + 25, k + 8, Blocks.log, 1);
		world.setBlockMetadataWithNotify(i + 0, j + 25, k + 8, 1, 2);
		setBlock(world, i + 0, j + 25, k + 9, Blocks.log, 1);
		world.setBlockMetadataWithNotify(i + 0, j + 25, k + 9, 1, 2);
		setBlock(world, i + 0, j + 25, k + 10, Blocks.log, 1);
		world.setBlockMetadataWithNotify(i + 0, j + 25, k + 10, 1, 2);
		setBlock(world, i + 0, j + 25, k + 11, Blocks.log, 1);
		world.setBlockMetadataWithNotify(i + 0, j + 25, k + 11, 1, 2);
		setBlock(world, i + 0, j + 26, k + 0, Blocks.planks, 5);
		world.setBlockMetadataWithNotify(i + 0, j + 26, k + 0, 5, 2);
		setBlock(world, i + 0, j + 26, k + 1, Blocks.planks, 5);
		world.setBlockMetadataWithNotify(i + 0, j + 26, k + 1, 5, 2);
		setBlock(world, i + 0, j + 26, k + 2, Blocks.log, 1);
		world.setBlockMetadataWithNotify(i + 0, j + 26, k + 2, 1, 2);
		setBlock(world, i + 0, j + 26, k + 3, Blocks.planks, 5);
		world.setBlockMetadataWithNotify(i + 0, j + 26, k + 3, 5, 2);
		setBlock(world, i + 0, j + 26, k + 4, Blocks.planks, 5);
		world.setBlockMetadataWithNotify(i + 0, j + 26, k + 4, 5, 2);
		setBlock(world, i + 0, j + 26, k + 5, Blocks.log, 1);
		world.setBlockMetadataWithNotify(i + 0, j + 26, k + 5, 1, 2);
		setBlock(world, i + 0, j + 26, k + 6, Blocks.planks, 5);
		world.setBlockMetadataWithNotify(i + 0, j + 26, k + 6, 5, 2);
		setBlock(world, i + 0, j + 26, k + 7, Blocks.planks, 5);
		world.setBlockMetadataWithNotify(i + 0, j + 26, k + 7, 5, 2);
		setBlock(world, i + 0, j + 26, k + 8, Blocks.log, 1);
		world.setBlockMetadataWithNotify(i + 0, j + 26, k + 8, 1, 2);
		setBlock(world, i + 0, j + 26, k + 9, Blocks.planks, 5);
		world.setBlockMetadataWithNotify(i + 0, j + 26, k + 9, 5, 2);
		setBlock(world, i + 0, j + 26, k + 10, Blocks.planks, 5);
		world.setBlockMetadataWithNotify(i + 0, j + 26, k + 10, 5, 2);
		setBlock(world, i + 0, j + 26, k + 11, Blocks.log, 1);
		world.setBlockMetadataWithNotify(i + 0, j + 26, k + 11, 1, 2);
		setBlock(world, i + 0, j + 26, k + 12, Blocks.planks, 5);
		world.setBlockMetadataWithNotify(i + 0, j + 26, k + 12, 5, 2);
		setBlock(world, i + 0, j + 26, k + 13, Blocks.planks, 5);
		world.setBlockMetadataWithNotify(i + 0, j + 26, k + 13, 5, 2);
		setBlock(world, i + 0, j + 26, k + 14, Blocks.planks, 5);
		world.setBlockMetadataWithNotify(i + 0, j + 26, k + 14, 5, 2);
		setBlock(world, i + 0, j + 26, k + 15, Blocks.planks, 5);
		world.setBlockMetadataWithNotify(i + 0, j + 26, k + 15, 5, 2);
		setBlock(world, i + 0, j + 27, k + 4, Blocks.chest, 2);
		LootGenUtils.fillLootChest(world.provider.dimensionId, world.rand, (TileEntityChest)world.getTileEntity(i + 0, j + 27, k + 4));
		world.setBlockMetadataWithNotify(i + 0, j + 27, k + 4, 2, 2);
		setBlock(world, i + 0, j + 29, k + 5, Blocks.torch, 2);
		world.setBlockMetadataWithNotify(i + 0, j + 29, k + 5, 2, 2);
		setBlock(world, i + 0, j + 29, k + 13, Blocks.torch, 1);
		world.setBlockMetadataWithNotify(i + 0, j + 29, k + 13, 1, 2);
		setBlock(world, i + 0, j + 30, k + 0, Blocks.log, 1);
		world.setBlockMetadataWithNotify(i + 0, j + 30, k + 0, 1, 2);
		setBlock(world, i + 0, j + 30, k + 10, Blocks.log, 1);
		world.setBlockMetadataWithNotify(i + 0, j + 30, k + 10, 1, 2);
		setBlock(world, i + 0, j + 30, k + 11, Blocks.log, 1);
		world.setBlockMetadataWithNotify(i + 0, j + 30, k + 11, 1, 2);
		setBlock(world, i + 0, j + 30, k + 12, Blocks.log, 1);
		world.setBlockMetadataWithNotify(i + 0, j + 30, k + 12, 1, 2);
		setBlock(world, i + 0, j + 30, k + 13, Blocks.log, 1);
		world.setBlockMetadataWithNotify(i + 0, j + 30, k + 13, 1, 2);
		setBlock(world, i + 0, j + 30, k + 14, Blocks.log, 1);
		world.setBlockMetadataWithNotify(i + 0, j + 30, k + 14, 1, 2);
		setBlock(world, i + 0, j + 31, k + 0, Blocks.log, 1);
		world.setBlockMetadataWithNotify(i + 0, j + 31, k + 0, 1, 2);
		setBlock(world, i + 0, j + 31, k + 1, Blocks.log, 1);
		world.setBlockMetadataWithNotify(i + 0, j + 31, k + 1, 1, 2);
		setBlock(world, i + 0, j + 31, k + 9, Blocks.log, 1);
		world.setBlockMetadataWithNotify(i + 0, j + 31, k + 9, 1, 2);
		setBlock(world, i + 0, j + 31, k + 10, Blocks.log, 1);
		world.setBlockMetadataWithNotify(i + 0, j + 31, k + 10, 1, 2);
		setBlock(world, i + 0, j + 31, k + 11, Blocks.log, 1);
		world.setBlockMetadataWithNotify(i + 0, j + 31, k + 11, 1, 2);
		setBlock(world, i + 0, j + 31, k + 12, Blocks.log, 1);
		world.setBlockMetadataWithNotify(i + 0, j + 31, k + 12, 1, 2);
		setBlock(world, i + 0, j + 31, k + 13, Blocks.log, 1);
		world.setBlockMetadataWithNotify(i + 0, j + 31, k + 13, 1, 2);
		setBlock(world, i + 0, j + 32, k + 0, Blocks.log, 1);
		world.setBlockMetadataWithNotify(i + 0, j + 32, k + 0, 1, 2);
		setBlock(world, i + 0, j + 32, k + 1, Blocks.log, 1);
		world.setBlockMetadataWithNotify(i + 0, j + 32, k + 1, 1, 2);
		setBlock(world, i + 0, j + 32, k + 2, Blocks.log, 1);
		world.setBlockMetadataWithNotify(i + 0, j + 32, k + 2, 1, 2);
		setBlock(world, i + 0, j + 32, k + 4, Blocks.log, 1);
		world.setBlockMetadataWithNotify(i + 0, j + 32, k + 4, 1, 2);
		setBlock(world, i + 0, j + 32, k + 5, Blocks.log, 1);
		world.setBlockMetadataWithNotify(i + 0, j + 32, k + 5, 1, 2);
		setBlock(world, i + 0, j + 32, k + 6, Blocks.log, 1);
		world.setBlockMetadataWithNotify(i + 0, j + 32, k + 6, 1, 2);
		setBlock(world, i + 0, j + 32, k + 8, Blocks.log, 1);
		world.setBlockMetadataWithNotify(i + 0, j + 32, k + 8, 1, 2);
		setBlock(world, i + 0, j + 32, k + 9, Blocks.log, 1);
		world.setBlockMetadataWithNotify(i + 0, j + 32, k + 9, 1, 2);
		setBlock(world, i + 0, j + 32, k + 10, Blocks.log, 1);
		world.setBlockMetadataWithNotify(i + 0, j + 32, k + 10, 1, 2);
		setBlock(world, i + 0, j + 32, k + 11, Blocks.log, 1);
		world.setBlockMetadataWithNotify(i + 0, j + 32, k + 11, 1, 2);
		setBlock(world, i + 0, j + 32, k + 12, Blocks.log, 1);
		world.setBlockMetadataWithNotify(i + 0, j + 32, k + 12, 1, 2);
		setBlock(world, i + 0, j + 32, k + 13, Blocks.log, 1);
		world.setBlockMetadataWithNotify(i + 0, j + 32, k + 13, 1, 2);
		setBlock(world, i + 0, j + 33, k + 0, Blocks.log, 1);
		world.setBlockMetadataWithNotify(i + 0, j + 33, k + 0, 1, 2);
		setBlock(world, i + 0, j + 33, k + 1, Blocks.log, 1);
		world.setBlockMetadataWithNotify(i + 0, j + 33, k + 1, 1, 2);
		setBlock(world, i + 0, j + 33, k + 2, Blocks.log, 1);
		world.setBlockMetadataWithNotify(i + 0, j + 33, k + 2, 1, 2);
		setBlock(world, i + 0, j + 33, k + 3, Blocks.log, 1);
		world.setBlockMetadataWithNotify(i + 0, j + 33, k + 3, 1, 2);
		setBlock(world, i + 0, j + 33, k + 4, Blocks.log, 1);
		world.setBlockMetadataWithNotify(i + 0, j + 33, k + 4, 1, 2);
		setBlock(world, i + 0, j + 33, k + 5, Blocks.log, 1);
		world.setBlockMetadataWithNotify(i + 0, j + 33, k + 5, 1, 2);
		setBlock(world, i + 0, j + 33, k + 6, Blocks.log, 1);
		world.setBlockMetadataWithNotify(i + 0, j + 33, k + 6, 1, 2);
		setBlock(world, i + 0, j + 33, k + 7, Blocks.log, 1);
		world.setBlockMetadataWithNotify(i + 0, j + 33, k + 7, 1, 2);
		setBlock(world, i + 0, j + 33, k + 8, Blocks.log, 1);
		world.setBlockMetadataWithNotify(i + 0, j + 33, k + 8, 1, 2);
		setBlock(world, i + 0, j + 33, k + 9, Blocks.log, 1);
		world.setBlockMetadataWithNotify(i + 0, j + 33, k + 9, 1, 2);
		setBlock(world, i + 0, j + 33, k + 10, Blocks.log, 1);
		world.setBlockMetadataWithNotify(i + 0, j + 33, k + 10, 1, 2);
		setBlock(world, i + 0, j + 33, k + 11, Blocks.log, 1);
		world.setBlockMetadataWithNotify(i + 0, j + 33, k + 11, 1, 2);
		setBlock(world, i + 0, j + 33, k + 12, Blocks.log, 1);
		world.setBlockMetadataWithNotify(i + 0, j + 33, k + 12, 1, 2);
		setBlock(world, i + 0, j + 34, k + 0, Blocks.log, 1);
		world.setBlockMetadataWithNotify(i + 0, j + 34, k + 0, 1, 2);
		setBlock(world, i + 0, j + 34, k + 1, Blocks.log, 1);
		world.setBlockMetadataWithNotify(i + 0, j + 34, k + 1, 1, 2);
		setBlock(world, i + 0, j + 34, k + 2, Blocks.log, 1);
		world.setBlockMetadataWithNotify(i + 0, j + 34, k + 2, 1, 2);
		setBlock(world, i + 0, j + 34, k + 3, Blocks.log, 1);
		world.setBlockMetadataWithNotify(i + 0, j + 34, k + 3, 1, 2);
		setBlock(world, i + 0, j + 34, k + 4, Blocks.log, 1);
		world.setBlockMetadataWithNotify(i + 0, j + 34, k + 4, 1, 2);
		setBlock(world, i + 0, j + 34, k + 5, Blocks.log, 1);
		world.setBlockMetadataWithNotify(i + 0, j + 34, k + 5, 1, 2);
		setBlock(world, i + 0, j + 34, k + 6, Blocks.log, 1);
		world.setBlockMetadataWithNotify(i + 0, j + 34, k + 6, 1, 2);
		setBlock(world, i + 0, j + 34, k + 7, Blocks.log, 1);
		world.setBlockMetadataWithNotify(i + 0, j + 34, k + 7, 1, 2);
		setBlock(world, i + 0, j + 34, k + 8, Blocks.log, 1);
		world.setBlockMetadataWithNotify(i + 0, j + 34, k + 8, 1, 2);
		setBlock(world, i + 0, j + 34, k + 9, Blocks.log, 1);
		world.setBlockMetadataWithNotify(i + 0, j + 34, k + 9, 1, 2);
		setBlock(world, i + 0, j + 34, k + 10, Blocks.log, 1);
		world.setBlockMetadataWithNotify(i + 0, j + 34, k + 10, 1, 2);
		setBlock(world, i + 0, j + 34, k + 11, Blocks.log, 1);
		world.setBlockMetadataWithNotify(i + 0, j + 34, k + 11, 1, 2);
		setBlock(world, i + 0, j + 35, k + 2, Blocks.log, 1);
		world.setBlockMetadataWithNotify(i + 0, j + 35, k + 2, 1, 2);
		setBlock(world, i + 0, j + 35, k + 3, Blocks.log, 1);
		world.setBlockMetadataWithNotify(i + 0, j + 35, k + 3, 1, 2);
		setBlock(world, i + 0, j + 35, k + 4, Blocks.log, 1);
		world.setBlockMetadataWithNotify(i + 0, j + 35, k + 4, 1, 2);
		setBlock(world, i + 0, j + 35, k + 5, Blocks.log, 1);
		world.setBlockMetadataWithNotify(i + 0, j + 35, k + 5, 1, 2);
		setBlock(world, i + 0, j + 35, k + 6, Blocks.log, 1);
		world.setBlockMetadataWithNotify(i + 0, j + 35, k + 6, 1, 2);
		setBlock(world, i + 0, j + 35, k + 7, Blocks.log, 1);
		world.setBlockMetadataWithNotify(i + 0, j + 35, k + 7, 1, 2);
		setBlock(world, i + 0, j + 35, k + 8, Blocks.log, 1);
		world.setBlockMetadataWithNotify(i + 0, j + 35, k + 8, 1, 2);
		setBlock(world, i + 0, j + 40, k + 27, Blocks.planks, 5);
		world.setBlockMetadataWithNotify(i + 0, j + 40, k + 27, 5, 2);
		setBlock(world, i + 0, j + 40, k + 28, Blocks.planks, 5);
		world.setBlockMetadataWithNotify(i + 0, j + 40, k + 28, 5, 2);
		setBlock(world, i + 0, j + 40, k + 29, Blocks.planks, 5);
		world.setBlockMetadataWithNotify(i + 0, j + 40, k + 29, 5, 2);
		setBlock(world, i + 0, j + 40, k + 30, Blocks.planks, 5);
		world.setBlockMetadataWithNotify(i + 0, j + 40, k + 30, 5, 2);
		setBlock(world, i + 0, j + 40, k + 31, Blocks.planks, 5);
		world.setBlockMetadataWithNotify(i + 0, j + 40, k + 31, 5, 2);
		setBlock(world, i + 0, j + 41, k + 26, Blocks.planks, 5);
		world.setBlockMetadataWithNotify(i + 0, j + 41, k + 26, 5, 2);
		setBlock(world, i + 0, j + 41, k + 27, Blocks.planks, 5);
		world.setBlockMetadataWithNotify(i + 0, j + 41, k + 27, 5, 2);
		setBlock(world, i + 0, j + 41, k + 28, Blocks.spruce_stairs, 3);
		world.setBlockMetadataWithNotify(i + 0, j + 41, k + 28, 3, 2);
		setBlock(world, i + 0, j + 42, k + 25, Blocks.planks, 5);
		world.setBlockMetadataWithNotify(i + 0, j + 42, k + 25, 5, 2);
		setBlock(world, i + 0, j + 42, k + 26, Blocks.planks, 5);
		world.setBlockMetadataWithNotify(i + 0, j + 42, k + 26, 5, 2);
		setBlock(world, i + 0, j + 42, k + 27, Blocks.spruce_stairs, 3);
		world.setBlockMetadataWithNotify(i + 0, j + 42, k + 27, 3, 2);
		setBlock(world, i + 0, j + 43, k + 24, Blocks.planks, 5);
		world.setBlockMetadataWithNotify(i + 0, j + 43, k + 24, 5, 2);
		setBlock(world, i + 0, j + 43, k + 25, Blocks.planks, 5);
		world.setBlockMetadataWithNotify(i + 0, j + 43, k + 25, 5, 2);
		setBlock(world, i + 0, j + 43, k + 26, Blocks.spruce_stairs, 3);
		world.setBlockMetadataWithNotify(i + 0, j + 43, k + 26, 3, 2);
		setBlock(world, i + 0, j + 44, k + 23, Blocks.planks, 5);
		world.setBlockMetadataWithNotify(i + 0, j + 44, k + 23, 5, 2);
		setBlock(world, i + 0, j + 44, k + 24, Blocks.planks, 5);
		world.setBlockMetadataWithNotify(i + 0, j + 44, k + 24, 5, 2);
		setBlock(world, i + 0, j + 44, k + 25, Blocks.spruce_stairs, 3);
		world.setBlockMetadataWithNotify(i + 0, j + 44, k + 25, 3, 2);
		setBlock(world, i + 0, j + 45, k + 22, Blocks.planks, 5);
		world.setBlockMetadataWithNotify(i + 0, j + 45, k + 22, 5, 2);
		setBlock(world, i + 0, j + 45, k + 23, Blocks.planks, 5);
		world.setBlockMetadataWithNotify(i + 0, j + 45, k + 23, 5, 2);
		setBlock(world, i + 0, j + 45, k + 24, Blocks.spruce_stairs, 3);
		world.setBlockMetadataWithNotify(i + 0, j + 45, k + 24, 3, 2);
		setBlock(world, i + 0, j + 46, k + 21, Blocks.planks, 5);
		world.setBlockMetadataWithNotify(i + 0, j + 46, k + 21, 5, 2);
		setBlock(world, i + 0, j + 46, k + 22, Blocks.planks, 5);
		world.setBlockMetadataWithNotify(i + 0, j + 46, k + 22, 5, 2);
		setBlock(world, i + 0, j + 46, k + 23, Blocks.spruce_stairs, 3);
		world.setBlockMetadataWithNotify(i + 0, j + 46, k + 23, 3, 2);
		setBlock(world, i + 0, j + 47, k + 20, Blocks.planks, 5);
		world.setBlockMetadataWithNotify(i + 0, j + 47, k + 20, 5, 2);
		setBlock(world, i + 0, j + 47, k + 21, Blocks.planks, 5);
		world.setBlockMetadataWithNotify(i + 0, j + 47, k + 21, 5, 2);
		setBlock(world, i + 0, j + 47, k + 22, Blocks.spruce_stairs, 3);
		world.setBlockMetadataWithNotify(i + 0, j + 47, k + 22, 3, 2);
		setBlock(world, i + 0, j + 48, k + 19, Blocks.planks, 5);
		world.setBlockMetadataWithNotify(i + 0, j + 48, k + 19, 5, 2);
		setBlock(world, i + 0, j + 48, k + 20, Blocks.planks, 5);
		world.setBlockMetadataWithNotify(i + 0, j + 48, k + 20, 5, 2);
		setBlock(world, i + 0, j + 48, k + 21, Blocks.spruce_stairs, 3);
		world.setBlockMetadataWithNotify(i + 0, j + 48, k + 21, 3, 2);
		setBlock(world, i + 0, j + 49, k + 18, Blocks.planks, 5);
		world.setBlockMetadataWithNotify(i + 0, j + 49, k + 18, 5, 2);
		setBlock(world, i + 0, j + 49, k + 19, Blocks.planks, 5);
		world.setBlockMetadataWithNotify(i + 0, j + 49, k + 19, 5, 2);
		setBlock(world, i + 0, j + 49, k + 20, Blocks.spruce_stairs, 3);
		world.setBlockMetadataWithNotify(i + 0, j + 49, k + 20, 3, 2);
		setBlock(world, i + 0, j + 50, k + 17, Blocks.planks, 5);
		world.setBlockMetadataWithNotify(i + 0, j + 50, k + 17, 5, 2);
		setBlock(world, i + 0, j + 50, k + 18, Blocks.planks, 5);
		world.setBlockMetadataWithNotify(i + 0, j + 50, k + 18, 5, 2);
		setBlock(world, i + 0, j + 50, k + 19, Blocks.spruce_stairs, 3);
		world.setBlockMetadataWithNotify(i + 0, j + 50, k + 19, 3, 2);
		setBlock(world, i + 0, j + 50, k + 31, Blocks.leaves, 15);
		world.setBlockMetadataWithNotify(i + 0, j + 50, k + 31, 15, 2);
		setBlock(world, i + 1, j + 0, k + 4, Blocks.planks, 5);
		world.setBlockMetadataWithNotify(i + 1, j + 0, k + 4, 5, 2);
		setBlock(world, i + 1, j + 0, k + 5, Blocks.planks, 5);
		world.setBlockMetadataWithNotify(i + 1, j + 0, k + 5, 5, 2);
		setBlock(world, i + 1, j + 0, k + 6, Blocks.log, 1);
		world.setBlockMetadataWithNotify(i + 1, j + 0, k + 6, 1, 2);
		setBlock(world, i + 1, j + 0, k + 7, Blocks.log, 1);
		world.setBlockMetadataWithNotify(i + 1, j + 0, k + 7, 1, 2);
		setBlock(world, i + 1, j + 0, k + 8, Blocks.log, 1);
		world.setBlockMetadataWithNotify(i + 1, j + 0, k + 8, 1, 2);
		setBlock(world, i + 1, j + 1, k + 4, Blocks.spruce_stairs, 1);
		world.setBlockMetadataWithNotify(i + 1, j + 1, k + 4, 1, 2);
		setBlock(world, i + 1, j + 1, k + 5, Blocks.spruce_stairs, 1);
		world.setBlockMetadataWithNotify(i + 1, j + 1, k + 5, 1, 2);
		setBlock(world, i + 1, j + 1, k + 6, Blocks.log, 1);
		world.setBlockMetadataWithNotify(i + 1, j + 1, k + 6, 1, 2);
		setBlock(world, i + 1, j + 1, k + 7, Blocks.log, 1);
		world.setBlockMetadataWithNotify(i + 1, j + 1, k + 7, 1, 2);
		setBlock(world, i + 1, j + 1, k + 8, Blocks.log, 1);
		world.setBlockMetadataWithNotify(i + 1, j + 1, k + 8, 1, 2);
		setBlock(world, i + 1, j + 2, k + 6, Blocks.log, 1);
		world.setBlockMetadataWithNotify(i + 1, j + 2, k + 6, 1, 2);
		setBlock(world, i + 1, j + 2, k + 7, Blocks.log, 1);
		world.setBlockMetadataWithNotify(i + 1, j + 2, k + 7, 1, 2);
		setBlock(world, i + 1, j + 3, k + 6, Blocks.log, 1);
		world.setBlockMetadataWithNotify(i + 1, j + 3, k + 6, 1, 2);
		setBlock(world, i + 1, j + 3, k + 7, Blocks.log, 1);
		world.setBlockMetadataWithNotify(i + 1, j + 3, k + 7, 1, 2);
		setBlock(world, i + 1, j + 3, k + 8, Blocks.log, 1);
		world.setBlockMetadataWithNotify(i + 1, j + 3, k + 8, 1, 2);
		setBlock(world, i + 1, j + 4, k + 7, Blocks.log, 1);
		world.setBlockMetadataWithNotify(i + 1, j + 4, k + 7, 1, 2);
		setBlock(world, i + 1, j + 4, k + 8, Blocks.log, 1);
		world.setBlockMetadataWithNotify(i + 1, j + 4, k + 8, 1, 2);
		setBlock(world, i + 1, j + 4, k + 9, Blocks.planks, 5);
		world.setBlockMetadataWithNotify(i + 1, j + 4, k + 9, 5, 2);
		setBlock(world, i + 1, j + 4, k + 10, Blocks.planks, 5);
		world.setBlockMetadataWithNotify(i + 1, j + 4, k + 10, 5, 2);
		setBlock(world, i + 1, j + 5, k + 7, Blocks.log, 1);
		world.setBlockMetadataWithNotify(i + 1, j + 5, k + 7, 1, 2);
		setBlock(world, i + 1, j + 5, k + 8, Blocks.log, 1);
		world.setBlockMetadataWithNotify(i + 1, j + 5, k + 8, 1, 2);
		setBlock(world, i + 1, j + 5, k + 9, Blocks.planks, 5);
		world.setBlockMetadataWithNotify(i + 1, j + 5, k + 9, 5, 2);
		setBlock(world, i + 1, j + 5, k + 10, Blocks.planks, 5);
		world.setBlockMetadataWithNotify(i + 1, j + 5, k + 10, 5, 2);
		setBlock(world, i + 1, j + 6, k + 6, Blocks.log, 1);
		world.setBlockMetadataWithNotify(i + 1, j + 6, k + 6, 1, 2);
		setBlock(world, i + 1, j + 6, k + 7, Blocks.log, 1);
		world.setBlockMetadataWithNotify(i + 1, j + 6, k + 7, 1, 2);
		setBlock(world, i + 1, j + 6, k + 8, Blocks.log, 1);
		world.setBlockMetadataWithNotify(i + 1, j + 6, k + 8, 1, 2);
		setBlock(world, i + 1, j + 7, k + 6, Blocks.log, 1);
		world.setBlockMetadataWithNotify(i + 1, j + 7, k + 6, 1, 2);
		setBlock(world, i + 1, j + 7, k + 7, Blocks.log, 1);
		world.setBlockMetadataWithNotify(i + 1, j + 7, k + 7, 1, 2);
		setBlock(world, i + 1, j + 7, k + 8, Blocks.log, 1);
		world.setBlockMetadataWithNotify(i + 1, j + 7, k + 8, 1, 2);
		setBlock(world, i + 1, j + 8, k + 4, Blocks.planks, 5);
		world.setBlockMetadataWithNotify(i + 1, j + 8, k + 4, 5, 2);
		setBlock(world, i + 1, j + 8, k + 5, Blocks.planks, 5);
		world.setBlockMetadataWithNotify(i + 1, j + 8, k + 5, 5, 2);
		setBlock(world, i + 1, j + 8, k + 6, Blocks.log, 1);
		world.setBlockMetadataWithNotify(i + 1, j + 8, k + 6, 1, 2);
		setBlock(world, i + 1, j + 8, k + 7, Blocks.log, 1);
		world.setBlockMetadataWithNotify(i + 1, j + 8, k + 7, 1, 2);
		setBlock(world, i + 1, j + 8, k + 8, Blocks.log, 1);
		world.setBlockMetadataWithNotify(i + 1, j + 8, k + 8, 1, 2);
		setBlock(world, i + 1, j + 9, k + 4, Blocks.planks, 5);
		world.setBlockMetadataWithNotify(i + 1, j + 9, k + 4, 5, 2);
		setBlock(world, i + 1, j + 9, k + 5, Blocks.planks, 5);
		world.setBlockMetadataWithNotify(i + 1, j + 9, k + 5, 5, 2);
		setBlock(world, i + 1, j + 9, k + 6, Blocks.log, 1);
		world.setBlockMetadataWithNotify(i + 1, j + 9, k + 6, 1, 2);
		setBlock(world, i + 1, j + 9, k + 7, Blocks.log, 1);
		world.setBlockMetadataWithNotify(i + 1, j + 9, k + 7, 1, 2);
		setBlock(world, i + 1, j + 10, k + 4, Blocks.spruce_stairs, 1);
		world.setBlockMetadataWithNotify(i + 1, j + 10, k + 4, 1, 2);
		setBlock(world, i + 1, j + 10, k + 5, Blocks.spruce_stairs, 1);
		world.setBlockMetadataWithNotify(i + 1, j + 10, k + 5, 1, 2);
		setBlock(world, i + 1, j + 10, k + 6, Blocks.log, 1);
		world.setBlockMetadataWithNotify(i + 1, j + 10, k + 6, 1, 2);
		setBlock(world, i + 1, j + 10, k + 7, Blocks.log, 1);
		world.setBlockMetadataWithNotify(i + 1, j + 10, k + 7, 1, 2);
		setBlock(world, i + 1, j + 10, k + 8, Blocks.log, 1);
		world.setBlockMetadataWithNotify(i + 1, j + 10, k + 8, 1, 2);
		setBlock(world, i + 1, j + 11, k + 6, Blocks.log, 1);
		world.setBlockMetadataWithNotify(i + 1, j + 11, k + 6, 1, 2);
		setBlock(world, i + 1, j + 11, k + 7, Blocks.log, 1);
		world.setBlockMetadataWithNotify(i + 1, j + 11, k + 7, 1, 2);
		setBlock(world, i + 1, j + 11, k + 8, Blocks.log, 1);
		world.setBlockMetadataWithNotify(i + 1, j + 11, k + 8, 1, 2);
		setBlock(world, i + 1, j + 12, k + 6, Blocks.log, 1);
		world.setBlockMetadataWithNotify(i + 1, j + 12, k + 6, 1, 2);
		setBlock(world, i + 1, j + 12, k + 7, Blocks.log, 1);
		world.setBlockMetadataWithNotify(i + 1, j + 12, k + 7, 1, 2);
		setBlock(world, i + 1, j + 12, k + 8, Blocks.log, 1);
		world.setBlockMetadataWithNotify(i + 1, j + 12, k + 8, 1, 2);
		setBlock(world, i + 1, j + 12, k + 9, Blocks.planks, 5);
		world.setBlockMetadataWithNotify(i + 1, j + 12, k + 9, 5, 2);
		setBlock(world, i + 1, j + 12, k + 10, Blocks.planks, 5);
		world.setBlockMetadataWithNotify(i + 1, j + 12, k + 10, 5, 2);
		setBlock(world, i + 1, j + 13, k + 6, Blocks.log, 1);
		world.setBlockMetadataWithNotify(i + 1, j + 13, k + 6, 1, 2);
		setBlock(world, i + 1, j + 13, k + 7, Blocks.log, 1);
		world.setBlockMetadataWithNotify(i + 1, j + 13, k + 7, 1, 2);
		setBlock(world, i + 1, j + 13, k + 8, Blocks.log, 1);
		world.setBlockMetadataWithNotify(i + 1, j + 13, k + 8, 1, 2);
		setBlock(world, i + 1, j + 13, k + 9, Blocks.planks, 5);
		world.setBlockMetadataWithNotify(i + 1, j + 13, k + 9, 5, 2);
		setBlock(world, i + 1, j + 13, k + 10, Blocks.planks, 5);
		world.setBlockMetadataWithNotify(i + 1, j + 13, k + 10, 5, 2);
		setBlock(world, i + 1, j + 14, k + 6, Blocks.log, 1);
		world.setBlockMetadataWithNotify(i + 1, j + 14, k + 6, 1, 2);
		setBlock(world, i + 1, j + 14, k + 7, Blocks.log, 1);
		world.setBlockMetadataWithNotify(i + 1, j + 14, k + 7, 1, 2);
		setBlock(world, i + 1, j + 14, k + 8, Blocks.log, 1);
		world.setBlockMetadataWithNotify(i + 1, j + 14, k + 8, 1, 2);
		setBlock(world, i + 1, j + 15, k + 6, Blocks.log, 1);
		world.setBlockMetadataWithNotify(i + 1, j + 15, k + 6, 1, 2);
		setBlock(world, i + 1, j + 15, k + 7, Blocks.log, 1);
		world.setBlockMetadataWithNotify(i + 1, j + 15, k + 7, 1, 2);
		setBlock(world, i + 1, j + 15, k + 8, Blocks.log, 1);
		world.setBlockMetadataWithNotify(i + 1, j + 15, k + 8, 1, 2);
		setBlock(world, i + 1, j + 16, k + 6, Blocks.log, 1);
		world.setBlockMetadataWithNotify(i + 1, j + 16, k + 6, 1, 2);
		setBlock(world, i + 1, j + 16, k + 7, Blocks.log, 1);
		world.setBlockMetadataWithNotify(i + 1, j + 16, k + 7, 1, 2);
		setBlock(world, i + 1, j + 16, k + 8, Blocks.log, 1);
		world.setBlockMetadataWithNotify(i + 1, j + 16, k + 8, 1, 2);
		setBlock(world, i + 1, j + 17, k + 6, Blocks.log, 1);
		world.setBlockMetadataWithNotify(i + 1, j + 17, k + 6, 1, 2);
		setBlock(world, i + 1, j + 17, k + 7, Blocks.log, 1);
		world.setBlockMetadataWithNotify(i + 1, j + 17, k + 7, 1, 2);
		setBlock(world, i + 1, j + 17, k + 8, Blocks.log, 1);
		world.setBlockMetadataWithNotify(i + 1, j + 17, k + 8, 1, 2);
		setBlock(world, i + 1, j + 18, k + 1, Blocks.vine, 10);
		world.setBlockMetadataWithNotify(i + 1, j + 18, k + 1, 10, 2);
		setBlock(world, i + 1, j + 18, k + 3, Blocks.vine, 14);
		world.setBlockMetadataWithNotify(i + 1, j + 18, k + 3, 14, 2);
		setBlock(world, i + 1, j + 18, k + 6, Blocks.log, 1);
		world.setBlockMetadataWithNotify(i + 1, j + 18, k + 6, 1, 2);
		setBlock(world, i + 1, j + 18, k + 7, Blocks.log, 1);
		world.setBlockMetadataWithNotify(i + 1, j + 18, k + 7, 1, 2);
		setBlock(world, i + 1, j + 18, k + 8, Blocks.log, 1);
		world.setBlockMetadataWithNotify(i + 1, j + 18, k + 8, 1, 2);
		setBlock(world, i + 1, j + 19, k + 1, Blocks.vine, 14);
		world.setBlockMetadataWithNotify(i + 1, j + 19, k + 1, 14, 2);
		setBlock(world, i + 1, j + 19, k + 3, Blocks.vine, 14);
		world.setBlockMetadataWithNotify(i + 1, j + 19, k + 3, 14, 2);
		setBlock(world, i + 1, j + 19, k + 4, Blocks.vine, 8);
		world.setBlockMetadataWithNotify(i + 1, j + 19, k + 4, 8, 2);
		setBlock(world, i + 1, j + 19, k + 6, Blocks.log, 1);
		world.setBlockMetadataWithNotify(i + 1, j + 19, k + 6, 1, 2);
		setBlock(world, i + 1, j + 19, k + 7, Blocks.log, 1);
		world.setBlockMetadataWithNotify(i + 1, j + 19, k + 7, 1, 2);
		setBlock(world, i + 1, j + 19, k + 8, Blocks.log, 1);
		world.setBlockMetadataWithNotify(i + 1, j + 19, k + 8, 1, 2);
		setBlock(world, i + 1, j + 20, k + 1, Blocks.vine, 15);
		world.setBlockMetadataWithNotify(i + 1, j + 20, k + 1, 15, 2);
		setBlock(world, i + 1, j + 20, k + 2, Blocks.vine, 6);
		world.setBlockMetadataWithNotify(i + 1, j + 20, k + 2, 6, 2);
		setBlock(world, i + 1, j + 20, k + 3, Blocks.vine, 15);
		world.setBlockMetadataWithNotify(i + 1, j + 20, k + 3, 15, 2);
		setBlock(world, i + 1, j + 20, k + 4, Blocks.vine, 15);
		world.setBlockMetadataWithNotify(i + 1, j + 20, k + 4, 15, 2);
		setBlock(world, i + 1, j + 20, k + 5, Blocks.log, 1);
		world.setBlockMetadataWithNotify(i + 1, j + 20, k + 5, 1, 2);
		setBlock(world, i + 1, j + 20, k + 6, Blocks.log, 1);
		world.setBlockMetadataWithNotify(i + 1, j + 20, k + 6, 1, 2);
		setBlock(world, i + 1, j + 20, k + 7, Blocks.log, 1);
		world.setBlockMetadataWithNotify(i + 1, j + 20, k + 7, 1, 2);
		setBlock(world, i + 1, j + 20, k + 8, Blocks.log, 1);
		world.setBlockMetadataWithNotify(i + 1, j + 20, k + 8, 1, 2);
		setBlock(world, i + 1, j + 21, k + 0, Blocks.vine, 11);
		world.setBlockMetadataWithNotify(i + 1, j + 21, k + 0, 11, 2);
		setBlock(world, i + 1, j + 21, k + 1, Blocks.vine, 15);
		world.setBlockMetadataWithNotify(i + 1, j + 21, k + 1, 15, 2);
		setBlock(world, i + 1, j + 21, k + 2, Blocks.vine, 15);
		world.setBlockMetadataWithNotify(i + 1, j + 21, k + 2, 15, 2);
		setBlock(world, i + 1, j + 21, k + 3, Blocks.vine, 15);
		world.setBlockMetadataWithNotify(i + 1, j + 21, k + 3, 15, 2);
		setBlock(world, i + 1, j + 21, k + 4, Blocks.log, 1);
		world.setBlockMetadataWithNotify(i + 1, j + 21, k + 4, 1, 2);
		setBlock(world, i + 1, j + 21, k + 5, Blocks.log, 1);
		world.setBlockMetadataWithNotify(i + 1, j + 21, k + 5, 1, 2);
		setBlock(world, i + 1, j + 21, k + 6, Blocks.log, 1);
		world.setBlockMetadataWithNotify(i + 1, j + 21, k + 6, 1, 2);
		setBlock(world, i + 1, j + 21, k + 7, Blocks.log, 1);
		world.setBlockMetadataWithNotify(i + 1, j + 21, k + 7, 1, 2);
		setBlock(world, i + 1, j + 21, k + 8, Blocks.log, 1);
		world.setBlockMetadataWithNotify(i + 1, j + 21, k + 8, 1, 2);
		setBlock(world, i + 1, j + 22, k + 0, Blocks.vine, 15);
		world.setBlockMetadataWithNotify(i + 1, j + 22, k + 0, 15, 2);
		setBlock(world, i + 1, j + 22, k + 1, Blocks.vine, 15);
		world.setBlockMetadataWithNotify(i + 1, j + 22, k + 1, 15, 2);
		setBlock(world, i + 1, j + 22, k + 2, Blocks.log, 1);
		world.setBlockMetadataWithNotify(i + 1, j + 22, k + 2, 1, 2);
		setBlock(world, i + 1, j + 22, k + 3, Blocks.log, 1);
		world.setBlockMetadataWithNotify(i + 1, j + 22, k + 3, 1, 2);
		setBlock(world, i + 1, j + 22, k + 4, Blocks.log, 1);
		world.setBlockMetadataWithNotify(i + 1, j + 22, k + 4, 1, 2);
		setBlock(world, i + 1, j + 22, k + 5, Blocks.log, 1);
		world.setBlockMetadataWithNotify(i + 1, j + 22, k + 5, 1, 2);
		setBlock(world, i + 1, j + 22, k + 6, Blocks.log, 1);
		world.setBlockMetadataWithNotify(i + 1, j + 22, k + 6, 1, 2);
		setBlock(world, i + 1, j + 22, k + 7, Blocks.log, 1);
		world.setBlockMetadataWithNotify(i + 1, j + 22, k + 7, 1, 2);
		setBlock(world, i + 1, j + 22, k + 8, Blocks.log, 1);
		world.setBlockMetadataWithNotify(i + 1, j + 22, k + 8, 1, 2);
		setBlock(world, i + 1, j + 22, k + 30, Blocks.log, 3);
		world.setBlockMetadataWithNotify(i + 1, j + 22, k + 30, 3, 2);
		setBlock(world, i + 1, j + 23, k + 0, Blocks.vine, 15);
		world.setBlockMetadataWithNotify(i + 1, j + 23, k + 0, 15, 2);
		setBlock(world, i + 1, j + 23, k + 1, Blocks.log, 1);
		world.setBlockMetadataWithNotify(i + 1, j + 23, k + 1, 1, 2);
		setBlock(world, i + 1, j + 23, k + 2, Blocks.log, 1);
		world.setBlockMetadataWithNotify(i + 1, j + 23, k + 2, 1, 2);
		setBlock(world, i + 1, j + 23, k + 3, Blocks.log, 1);
		world.setBlockMetadataWithNotify(i + 1, j + 23, k + 3, 1, 2);
		setBlock(world, i + 1, j + 23, k + 4, Blocks.log, 1);
		world.setBlockMetadataWithNotify(i + 1, j + 23, k + 4, 1, 2);
		setBlock(world, i + 1, j + 23, k + 5, Blocks.log, 1);
		world.setBlockMetadataWithNotify(i + 1, j + 23, k + 5, 1, 2);
		setBlock(world, i + 1, j + 23, k + 6, Blocks.log, 1);
		world.setBlockMetadataWithNotify(i + 1, j + 23, k + 6, 1, 2);
		setBlock(world, i + 1, j + 23, k + 7, Blocks.log, 1);
		world.setBlockMetadataWithNotify(i + 1, j + 23, k + 7, 1, 2);
		setBlock(world, i + 1, j + 23, k + 8, Blocks.log, 1);
		world.setBlockMetadataWithNotify(i + 1, j + 23, k + 8, 1, 2);
		setBlock(world, i + 1, j + 23, k + 9, Blocks.vine, 15);
		world.setBlockMetadataWithNotify(i + 1, j + 23, k + 9, 15, 2);
		setBlock(world, i + 1, j + 23, k + 27, Blocks.leaves, 15);
		world.setBlockMetadataWithNotify(i + 1, j + 23, k + 27, 15, 2);
		setBlock(world, i + 1, j + 23, k + 28, Blocks.leaves, 15);
		world.setBlockMetadataWithNotify(i + 1, j + 23, k + 28, 15, 2);
		setBlock(world, i + 1, j + 23, k + 29, Blocks.leaves, 15);
		world.setBlockMetadataWithNotify(i + 1, j + 23, k + 29, 15, 2);
		setBlock(world, i + 1, j + 24, k + 2, Blocks.log, 1);
		world.setBlockMetadataWithNotify(i + 1, j + 24, k + 2, 1, 2);
		setBlock(world, i + 1, j + 24, k + 3, Blocks.log, 1);
		world.setBlockMetadataWithNotify(i + 1, j + 24, k + 3, 1, 2);
		setBlock(world, i + 1, j + 24, k + 4, Blocks.log, 1);
		world.setBlockMetadataWithNotify(i + 1, j + 24, k + 4, 1, 2);
		setBlock(world, i + 1, j + 24, k + 5, Blocks.log, 1);
		world.setBlockMetadataWithNotify(i + 1, j + 24, k + 5, 1, 2);
		setBlock(world, i + 1, j + 24, k + 6, Blocks.log, 1);
		world.setBlockMetadataWithNotify(i + 1, j + 24, k + 6, 1, 2);
		setBlock(world, i + 1, j + 24, k + 7, Blocks.log, 1);
		world.setBlockMetadataWithNotify(i + 1, j + 24, k + 7, 1, 2);
		setBlock(world, i + 1, j + 24, k + 8, Blocks.log, 1);
		world.setBlockMetadataWithNotify(i + 1, j + 24, k + 8, 1, 2);
		setBlock(world, i + 1, j + 24, k + 9, Blocks.log, 1);
		world.setBlockMetadataWithNotify(i + 1, j + 24, k + 9, 1, 2);
		setBlock(world, i + 1, j + 24, k + 10, Blocks.log, 1);
		world.setBlockMetadataWithNotify(i + 1, j + 24, k + 10, 1, 2);
		setBlock(world, i + 1, j + 24, k + 11, Blocks.log, 1);
		world.setBlockMetadataWithNotify(i + 1, j + 24, k + 11, 1, 2);
		setBlock(world, i + 1, j + 24, k + 12, Blocks.log, 1);
		world.setBlockMetadataWithNotify(i + 1, j + 24, k + 12, 1, 2);
		setBlock(world, i + 1, j + 24, k + 28, Blocks.leaves, 15);
		world.setBlockMetadataWithNotify(i + 1, j + 24, k + 28, 15, 2);
		setBlock(world, i + 1, j + 25, k + 3, Blocks.log, 1);
		world.setBlockMetadataWithNotify(i + 1, j + 25, k + 3, 1, 2);
		setBlock(world, i + 1, j + 25, k + 5, Blocks.log, 1);
		world.setBlockMetadataWithNotify(i + 1, j + 25, k + 5, 1, 2);
		setBlock(world, i + 1, j + 25, k + 6, Blocks.log, 1);
		world.setBlockMetadataWithNotify(i + 1, j + 25, k + 6, 1, 2);
		setBlock(world, i + 1, j + 25, k + 7, Blocks.log, 1);
		world.setBlockMetadataWithNotify(i + 1, j + 25, k + 7, 1, 2);
		setBlock(world, i + 1, j + 25, k + 8, Blocks.log, 1);
		world.setBlockMetadataWithNotify(i + 1, j + 25, k + 8, 1, 2);
		setBlock(world, i + 1, j + 25, k + 9, Blocks.log, 1);
		world.setBlockMetadataWithNotify(i + 1, j + 25, k + 9, 1, 2);
		setBlock(world, i + 1, j + 25, k + 10, Blocks.log, 1);
		world.setBlockMetadataWithNotify(i + 1, j + 25, k + 10, 1, 2);
		setBlock(world, i + 1, j + 25, k + 11, Blocks.log, 1);
		world.setBlockMetadataWithNotify(i + 1, j + 25, k + 11, 1, 2);
		setBlock(world, i + 1, j + 26, k + 0, Blocks.log, 1);
		world.setBlockMetadataWithNotify(i + 1, j + 26, k + 0, 1, 2);
		setBlock(world, i + 1, j + 26, k + 1, Blocks.planks, 5);
		world.setBlockMetadataWithNotify(i + 1, j + 26, k + 1, 5, 2);
		setBlock(world, i + 1, j + 26, k + 2, Blocks.log, 1);
		world.setBlockMetadataWithNotify(i + 1, j + 26, k + 2, 1, 2);
		setBlock(world, i + 1, j + 26, k + 3, Blocks.planks, 5);
		world.setBlockMetadataWithNotify(i + 1, j + 26, k + 3, 5, 2);
		setBlock(world, i + 1, j + 26, k + 4, Blocks.log, 1);
		world.setBlockMetadataWithNotify(i + 1, j + 26, k + 4, 1, 2);
		setBlock(world, i + 1, j + 26, k + 5, Blocks.log, 1);
		world.setBlockMetadataWithNotify(i + 1, j + 26, k + 5, 1, 2);
		setBlock(world, i + 1, j + 26, k + 6, Blocks.log, 1);
		world.setBlockMetadataWithNotify(i + 1, j + 26, k + 6, 1, 2);
		setBlock(world, i + 1, j + 26, k + 7, Blocks.planks, 5);
		world.setBlockMetadataWithNotify(i + 1, j + 26, k + 7, 5, 2);
		setBlock(world, i + 1, j + 26, k + 8, Blocks.log, 1);
		world.setBlockMetadataWithNotify(i + 1, j + 26, k + 8, 1, 2);
		setBlock(world, i + 1, j + 26, k + 9, Blocks.planks, 5);
		world.setBlockMetadataWithNotify(i + 1, j + 26, k + 9, 5, 2);
		setBlock(world, i + 1, j + 26, k + 10, Blocks.log, 1);
		world.setBlockMetadataWithNotify(i + 1, j + 26, k + 10, 1, 2);
		setBlock(world, i + 1, j + 26, k + 11, Blocks.log, 1);
		world.setBlockMetadataWithNotify(i + 1, j + 26, k + 11, 1, 2);
		setBlock(world, i + 1, j + 26, k + 12, Blocks.planks, 5);
		world.setBlockMetadataWithNotify(i + 1, j + 26, k + 12, 5, 2);
		setBlock(world, i + 1, j + 26, k + 13, Blocks.planks, 5);
		world.setBlockMetadataWithNotify(i + 1, j + 26, k + 13, 5, 2);
		setBlock(world, i + 1, j + 26, k + 14, Blocks.planks, 5);
		world.setBlockMetadataWithNotify(i + 1, j + 26, k + 14, 5, 2);
		setBlock(world, i + 1, j + 26, k + 15, Blocks.planks, 5);
		world.setBlockMetadataWithNotify(i + 1, j + 26, k + 15, 5, 2);
		setBlock(world, i + 1, j + 26, k + 16, Blocks.planks, 5);
		world.setBlockMetadataWithNotify(i + 1, j + 26, k + 16, 5, 2);
		setBlock(world, i + 1, j + 27, k + 4, Blocks.spruce_stairs, 2);
		world.setBlockMetadataWithNotify(i + 1, j + 27, k + 4, 2, 2);
		setBlock(world, i + 1, j + 27, k + 5, Blocks.log, 1);
		world.setBlockMetadataWithNotify(i + 1, j + 27, k + 5, 1, 2);
		setBlock(world, i + 1, j + 27, k + 6, Blocks.spruce_stairs, 3);
		world.setBlockMetadataWithNotify(i + 1, j + 27, k + 6, 3, 2);
		setBlock(world, i + 1, j + 27, k + 16, Blocks.torch, 5);
		world.setBlockMetadataWithNotify(i + 1, j + 27, k + 16, 5, 2);
		setBlock(world, i + 1, j + 28, k + 5, Blocks.log, 1);
		world.setBlockMetadataWithNotify(i + 1, j + 28, k + 5, 1, 2);
		setBlock(world, i + 1, j + 29, k + 5, Blocks.log, 1);
		world.setBlockMetadataWithNotify(i + 1, j + 29, k + 5, 1, 2);
		setBlock(world, i + 1, j + 30, k + 0, Blocks.log, 1);
		world.setBlockMetadataWithNotify(i + 1, j + 30, k + 0, 1, 2);
		setBlock(world, i + 1, j + 30, k + 4, Blocks.torch, 4);
		world.setBlockMetadataWithNotify(i + 1, j + 30, k + 4, 4, 2);
		setBlock(world, i + 1, j + 30, k + 5, Blocks.log, 1);
		world.setBlockMetadataWithNotify(i + 1, j + 30, k + 5, 1, 2);
		setBlock(world, i + 1, j + 30, k + 6, Blocks.torch, 3);
		world.setBlockMetadataWithNotify(i + 1, j + 30, k + 6, 3, 2);
		setBlock(world, i + 1, j + 30, k + 10, Blocks.log, 1);
		world.setBlockMetadataWithNotify(i + 1, j + 30, k + 10, 1, 2);
		setBlock(world, i + 1, j + 30, k + 11, Blocks.log, 1);
		world.setBlockMetadataWithNotify(i + 1, j + 30, k + 11, 1, 2);
		setBlock(world, i + 1, j + 30, k + 12, Blocks.log, 1);
		world.setBlockMetadataWithNotify(i + 1, j + 30, k + 12, 1, 2);
		setBlock(world, i + 1, j + 30, k + 13, Blocks.log, 1);
		world.setBlockMetadataWithNotify(i + 1, j + 30, k + 13, 1, 2);
		setBlock(world, i + 1, j + 30, k + 14, Blocks.log, 1);
		world.setBlockMetadataWithNotify(i + 1, j + 30, k + 14, 1, 2);
		setBlock(world, i + 1, j + 31, k + 0, Blocks.log, 1);
		world.setBlockMetadataWithNotify(i + 1, j + 31, k + 0, 1, 2);
		setBlock(world, i + 1, j + 31, k + 1, Blocks.log, 1);
		world.setBlockMetadataWithNotify(i + 1, j + 31, k + 1, 1, 2);
		setBlock(world, i + 1, j + 31, k + 5, Blocks.log, 1);
		world.setBlockMetadataWithNotify(i + 1, j + 31, k + 5, 1, 2);
		setBlock(world, i + 1, j + 31, k + 9, Blocks.log, 1);
		world.setBlockMetadataWithNotify(i + 1, j + 31, k + 9, 1, 2);
		setBlock(world, i + 1, j + 31, k + 10, Blocks.log, 1);
		world.setBlockMetadataWithNotify(i + 1, j + 31, k + 10, 1, 2);
		setBlock(world, i + 1, j + 31, k + 11, Blocks.log, 1);
		world.setBlockMetadataWithNotify(i + 1, j + 31, k + 11, 1, 2);
		setBlock(world, i + 1, j + 31, k + 12, Blocks.log, 1);
		world.setBlockMetadataWithNotify(i + 1, j + 31, k + 12, 1, 2);
		setBlock(world, i + 1, j + 31, k + 13, Blocks.log, 1);
		world.setBlockMetadataWithNotify(i + 1, j + 31, k + 13, 1, 2);
		setBlock(world, i + 1, j + 32, k + 0, Blocks.log, 1);
		world.setBlockMetadataWithNotify(i + 1, j + 32, k + 0, 1, 2);
		setBlock(world, i + 1, j + 32, k + 1, Blocks.log, 1);
		/* 1000 */world.setBlockMetadataWithNotify(i + 1, j + 32, k + 1, 1, 2);
		/* 1001 */setBlock(world, i + 1, j + 32, k + 2, Blocks.log, 1);
		/* 1002 */world.setBlockMetadataWithNotify(i + 1, j + 32, k + 2, 1, 2);
		/* 1003 */setBlock(world, i + 1, j + 32, k + 4, Blocks.log, 1);
		/* 1004 */world.setBlockMetadataWithNotify(i + 1, j + 32, k + 4, 1, 2);
		/* 1005 */setBlock(world, i + 1, j + 32, k + 5, Blocks.log, 1);
		/* 1006 */world.setBlockMetadataWithNotify(i + 1, j + 32, k + 5, 1, 2);
		/* 1007 */setBlock(world, i + 1, j + 32, k + 6, Blocks.log, 1);
		/* 1008 */world.setBlockMetadataWithNotify(i + 1, j + 32, k + 6, 1, 2);
		/* 1009 */setBlock(world, i + 1, j + 32, k + 8, Blocks.log, 1);
		/* 1010 */world.setBlockMetadataWithNotify(i + 1, j + 32, k + 8, 1, 2);
		/* 1011 */setBlock(world, i + 1, j + 32, k + 9, Blocks.log, 1);
		/* 1012 */world.setBlockMetadataWithNotify(i + 1, j + 32, k + 9, 1, 2);
		/* 1013 */setBlock(world, i + 1, j + 32, k + 10, Blocks.log, 1);
		/* 1014 */world.setBlockMetadataWithNotify(i + 1, j + 32, k + 10, 1, 2);
		/* 1015 */setBlock(world, i + 1, j + 32, k + 11, Blocks.log, 1);
		/* 1016 */world.setBlockMetadataWithNotify(i + 1, j + 32, k + 11, 1, 2);
		/* 1017 */setBlock(world, i + 1, j + 32, k + 12, Blocks.log, 1);
		/* 1018 */world.setBlockMetadataWithNotify(i + 1, j + 32, k + 12, 1, 2);
		/* 1019 */setBlock(world, i + 1, j + 32, k + 13, Blocks.log, 1);
		/* 1020 */world.setBlockMetadataWithNotify(i + 1, j + 32, k + 13, 1, 2);
		/* 1021 */setBlock(world, i + 1, j + 33, k + 0, Blocks.log, 1);
		/* 1022 */world.setBlockMetadataWithNotify(i + 1, j + 33, k + 0, 1, 2);
		/* 1023 */setBlock(world, i + 1, j + 33, k + 1, Blocks.log, 1);
		/* 1024 */world.setBlockMetadataWithNotify(i + 1, j + 33, k + 1, 1, 2);
		/* 1025 */setBlock(world, i + 1, j + 33, k + 2, Blocks.log, 1);
		/* 1026 */world.setBlockMetadataWithNotify(i + 1, j + 33, k + 2, 1, 2);
		/* 1027 */setBlock(world, i + 1, j + 33, k + 3, Blocks.log, 1);
		/* 1028 */world.setBlockMetadataWithNotify(i + 1, j + 33, k + 3, 1, 2);
		/* 1029 */setBlock(world, i + 1, j + 33, k + 4, Blocks.log, 1);
		/* 1030 */world.setBlockMetadataWithNotify(i + 1, j + 33, k + 4, 1, 2);
		/* 1031 */setBlock(world, i + 1, j + 33, k + 5, Blocks.log, 1);
		/* 1032 */world.setBlockMetadataWithNotify(i + 1, j + 33, k + 5, 1, 2);
		/* 1033 */setBlock(world, i + 1, j + 33, k + 6, Blocks.log, 1);
		/* 1034 */world.setBlockMetadataWithNotify(i + 1, j + 33, k + 6, 1, 2);
		/* 1035 */setBlock(world, i + 1, j + 33, k + 7, Blocks.log, 1);
		/* 1036 */world.setBlockMetadataWithNotify(i + 1, j + 33, k + 7, 1, 2);
		/* 1037 */setBlock(world, i + 1, j + 33, k + 8, Blocks.log, 1);
		/*      */
		/* 1039 */generate9(world, rand, i, j, k);
		/* 1040 */return true;
		/*      */}

	/*      */
	/*      */public boolean generate9(World world, Random rand, int i, int j, int k)
	/*      */
	{
		/* 1045 */world.setBlockMetadataWithNotify(i + 1, j + 33, k + 8, 1, 2);
		/* 1046 */setBlock(world, i + 1, j + 33, k + 9, Blocks.log, 1);
		/* 1047 */world.setBlockMetadataWithNotify(i + 1, j + 33, k + 9, 1, 2);
		/* 1048 */setBlock(world, i + 1, j + 33, k + 10, Blocks.log, 1);
		/* 1049 */world.setBlockMetadataWithNotify(i + 1, j + 33, k + 10, 1, 2);
		/* 1050 */setBlock(world, i + 1, j + 33, k + 11, Blocks.log, 1);
		/* 1051 */world.setBlockMetadataWithNotify(i + 1, j + 33, k + 11, 1, 2);
		/* 1052 */setBlock(world, i + 1, j + 33, k + 12, Blocks.log, 1);
		/* 1053 */world.setBlockMetadataWithNotify(i + 1, j + 33, k + 12, 1, 2);
		/* 1054 */setBlock(world, i + 1, j + 34, k + 0, Blocks.log, 1);
		/* 1055 */world.setBlockMetadataWithNotify(i + 1, j + 34, k + 0, 1, 2);
		/* 1056 */setBlock(world, i + 1, j + 34, k + 1, Blocks.log, 1);
		/* 1057 */world.setBlockMetadataWithNotify(i + 1, j + 34, k + 1, 1, 2);
		/* 1058 */setBlock(world, i + 1, j + 34, k + 2, Blocks.log, 1);
		/* 1059 */world.setBlockMetadataWithNotify(i + 1, j + 34, k + 2, 1, 2);
		/* 1060 */setBlock(world, i + 1, j + 34, k + 3, Blocks.log, 1);
		/* 1061 */world.setBlockMetadataWithNotify(i + 1, j + 34, k + 3, 1, 2);
		/* 1062 */setBlock(world, i + 1, j + 34, k + 4, Blocks.log, 1);
		/* 1063 */world.setBlockMetadataWithNotify(i + 1, j + 34, k + 4, 1, 2);
		/* 1064 */setBlock(world, i + 1, j + 34, k + 5, Blocks.log, 1);
		/* 1065 */world.setBlockMetadataWithNotify(i + 1, j + 34, k + 5, 1, 2);
		/* 1066 */setBlock(world, i + 1, j + 34, k + 6, Blocks.log, 1);
		/* 1067 */world.setBlockMetadataWithNotify(i + 1, j + 34, k + 6, 1, 2);
		/* 1068 */setBlock(world, i + 1, j + 34, k + 7, Blocks.log, 1);
		/* 1069 */world.setBlockMetadataWithNotify(i + 1, j + 34, k + 7, 1, 2);
		/* 1070 */setBlock(world, i + 1, j + 34, k + 8, Blocks.log, 1);
		/* 1071 */world.setBlockMetadataWithNotify(i + 1, j + 34, k + 8, 1, 2);
		/* 1072 */setBlock(world, i + 1, j + 34, k + 9, Blocks.log, 1);
		/* 1073 */world.setBlockMetadataWithNotify(i + 1, j + 34, k + 9, 1, 2);
		/* 1074 */setBlock(world, i + 1, j + 34, k + 10, Blocks.log, 1);
		/* 1075 */world.setBlockMetadataWithNotify(i + 1, j + 34, k + 10, 1, 2);
		/* 1076 */setBlock(world, i + 1, j + 34, k + 11, Blocks.log, 1);
		/* 1077 */world.setBlockMetadataWithNotify(i + 1, j + 34, k + 11, 1, 2);
		/* 1078 */setBlock(world, i + 1, j + 35, k + 2, Blocks.log, 1);
		/* 1079 */world.setBlockMetadataWithNotify(i + 1, j + 35, k + 2, 1, 2);
		/* 1080 */setBlock(world, i + 1, j + 35, k + 3, Blocks.log, 1);
		/* 1081 */world.setBlockMetadataWithNotify(i + 1, j + 35, k + 3, 1, 2);
		/* 1082 */setBlock(world, i + 1, j + 35, k + 4, Blocks.log, 1);
		/* 1083 */world.setBlockMetadataWithNotify(i + 1, j + 35, k + 4, 1, 2);
		/* 1084 */setBlock(world, i + 1, j + 35, k + 5, Blocks.log, 1);
		/* 1085 */world.setBlockMetadataWithNotify(i + 1, j + 35, k + 5, 1, 2);
		/* 1086 */setBlock(world, i + 1, j + 35, k + 6, Blocks.log, 1);
		/* 1087 */world.setBlockMetadataWithNotify(i + 1, j + 35, k + 6, 1, 2);
		/* 1088 */setBlock(world, i + 1, j + 35, k + 7, Blocks.log, 1);
		/* 1089 */world.setBlockMetadataWithNotify(i + 1, j + 35, k + 7, 1, 2);
		/* 1090 */setBlock(world, i + 1, j + 35, k + 8, Blocks.log, 1);
		/* 1091 */world.setBlockMetadataWithNotify(i + 1, j + 35, k + 8, 1, 2);
		/* 1092 */setBlock(world, i + 1, j + 40, k + 30, Blocks.planks, 5);
		/* 1093 */world.setBlockMetadataWithNotify(i + 1, j + 40, k + 30, 5, 2);
		/* 1094 */setBlock(world, i + 1, j + 40, k + 31, Blocks.planks, 5);
		/* 1095 */world.setBlockMetadataWithNotify(i + 1, j + 40, k + 31, 5, 2);
		/* 1096 */setBlock(world, i + 1, j + 50, k + 31, Blocks.leaves, 15);
		/* 1097 */world.setBlockMetadataWithNotify(i + 1, j + 50, k + 31, 15, 2);
		/* 1098 */setBlock(world, i + 1, j + 51, k + 31, Blocks.leaves, 7);
		/* 1099 */world.setBlockMetadataWithNotify(i + 1, j + 51, k + 31, 7, 2);
		/* 1100 */setBlock(world, i + 2, j + 0, k + 4, Blocks.spruce_stairs, 1);
		/* 1101 */world.setBlockMetadataWithNotify(i + 2, j + 0, k + 4, 1, 2);
		/* 1102 */setBlock(world, i + 2, j + 0, k + 5, Blocks.spruce_stairs, 1);
		/* 1103 */world.setBlockMetadataWithNotify(i + 2, j + 0, k + 5, 1, 2);
		/* 1104 */setBlock(world, i + 2, j + 0, k + 6, Blocks.log, 1);
		/* 1105 */world.setBlockMetadataWithNotify(i + 2, j + 0, k + 6, 1, 2);
		/* 1106 */setBlock(world, i + 2, j + 0, k + 7, Blocks.log, 1);
		/* 1107 */world.setBlockMetadataWithNotify(i + 2, j + 0, k + 7, 1, 2);
		/* 1108 */setBlock(world, i + 2, j + 0, k + 8, Blocks.log, 1);
		/* 1109 */world.setBlockMetadataWithNotify(i + 2, j + 0, k + 8, 1, 2);
		/* 1110 */setBlock(world, i + 2, j + 1, k + 6, Blocks.log, 1);
		/* 1111 */world.setBlockMetadataWithNotify(i + 2, j + 1, k + 6, 1, 2);
		/* 1112 */setBlock(world, i + 2, j + 2, k + 6, Blocks.log, 1);
		/* 1113 */world.setBlockMetadataWithNotify(i + 2, j + 2, k + 6, 1, 2);
		/* 1114 */setBlock(world, i + 2, j + 2, k + 7, Blocks.log, 1);
		/* 1115 */world.setBlockMetadataWithNotify(i + 2, j + 2, k + 7, 1, 2);
		/* 1116 */setBlock(world, i + 2, j + 3, k + 7, Blocks.log, 1);
		/* 1117 */world.setBlockMetadataWithNotify(i + 2, j + 3, k + 7, 1, 2);
		/* 1118 */setBlock(world, i + 2, j + 4, k + 7, Blocks.log, 1);
		/* 1119 */world.setBlockMetadataWithNotify(i + 2, j + 4, k + 7, 1, 2);
		/* 1120 */setBlock(world, i + 2, j + 4, k + 8, Blocks.log, 1);
		/* 1121 */world.setBlockMetadataWithNotify(i + 2, j + 4, k + 8, 1, 2);
		/* 1122 */setBlock(world, i + 2, j + 5, k + 7, Blocks.log, 1);
		/* 1123 */world.setBlockMetadataWithNotify(i + 2, j + 5, k + 7, 1, 2);
		/* 1124 */setBlock(world, i + 2, j + 5, k + 8, Blocks.log, 1);
		/* 1125 */world.setBlockMetadataWithNotify(i + 2, j + 5, k + 8, 1, 2);
		/* 1126 */setBlock(world, i + 2, j + 5, k + 9, Blocks.planks, 5);
		/* 1127 */world.setBlockMetadataWithNotify(i + 2, j + 5, k + 9, 5, 2);
		/* 1128 */setBlock(world, i + 2, j + 5, k + 10, Blocks.planks, 5);
		/* 1129 */world.setBlockMetadataWithNotify(i + 2, j + 5, k + 10, 5, 2);
		/* 1130 */setBlock(world, i + 2, j + 6, k + 7, Blocks.log, 1);
		/* 1131 */world.setBlockMetadataWithNotify(i + 2, j + 6, k + 7, 1, 2);
		/* 1132 */setBlock(world, i + 2, j + 6, k + 8, Blocks.log, 1);
		/* 1133 */world.setBlockMetadataWithNotify(i + 2, j + 6, k + 8, 1, 2);
		/* 1134 */setBlock(world, i + 2, j + 6, k + 9, Blocks.planks, 5);
		/* 1135 */world.setBlockMetadataWithNotify(i + 2, j + 6, k + 9, 5, 2);
		/* 1136 */setBlock(world, i + 2, j + 6, k + 10, Blocks.planks, 5);
		/* 1137 */world.setBlockMetadataWithNotify(i + 2, j + 6, k + 10, 5, 2);
		/* 1138 */setBlock(world, i + 2, j + 7, k + 6, Blocks.log, 1);
		/* 1139 */world.setBlockMetadataWithNotify(i + 2, j + 7, k + 6, 1, 2);
		/* 1140 */setBlock(world, i + 2, j + 7, k + 7, Blocks.log, 1);
		/* 1141 */world.setBlockMetadataWithNotify(i + 2, j + 7, k + 7, 1, 2);
		/* 1142 */setBlock(world, i + 2, j + 7, k + 8, Blocks.log, 1);
		/* 1143 */world.setBlockMetadataWithNotify(i + 2, j + 7, k + 8, 1, 2);
		/* 1144 */setBlock(world, i + 2, j + 8, k + 4, Blocks.planks, 5);
		/* 1145 */world.setBlockMetadataWithNotify(i + 2, j + 8, k + 4, 5, 2);
		/* 1146 */setBlock(world, i + 2, j + 8, k + 5, Blocks.planks, 5);
		/* 1147 */world.setBlockMetadataWithNotify(i + 2, j + 8, k + 5, 5, 2);
		/* 1148 */setBlock(world, i + 2, j + 8, k + 6, Blocks.log, 1);
		/* 1149 */world.setBlockMetadataWithNotify(i + 2, j + 8, k + 6, 1, 2);
		/* 1150 */setBlock(world, i + 2, j + 8, k + 7, Blocks.log, 1);
		/* 1151 */world.setBlockMetadataWithNotify(i + 2, j + 8, k + 7, 1, 2);
		/* 1152 */setBlock(world, i + 2, j + 8, k + 8, Blocks.log, 1);
		/* 1153 */world.setBlockMetadataWithNotify(i + 2, j + 8, k + 8, 1, 2);
		/* 1154 */setBlock(world, i + 2, j + 9, k + 4, Blocks.spruce_stairs, 1);
		/* 1155 */world.setBlockMetadataWithNotify(i + 2, j + 9, k + 4, 1, 2);
		/* 1156 */setBlock(world, i + 2, j + 9, k + 5, Blocks.spruce_stairs, 1);
		/* 1157 */world.setBlockMetadataWithNotify(i + 2, j + 9, k + 5, 1, 2);
		/* 1158 */setBlock(world, i + 2, j + 9, k + 7, Blocks.log, 1);
		/* 1159 */world.setBlockMetadataWithNotify(i + 2, j + 9, k + 7, 1, 2);
		/* 1160 */setBlock(world, i + 2, j + 9, k + 8, Blocks.log, 1);
		/* 1161 */world.setBlockMetadataWithNotify(i + 2, j + 9, k + 8, 1, 2);
		/* 1162 */setBlock(world, i + 2, j + 9, k + 9, Blocks.torch, 3);
		/* 1163 */world.setBlockMetadataWithNotify(i + 2, j + 9, k + 9, 3, 2);
		/* 1164 */setBlock(world, i + 2, j + 10, k + 7, Blocks.log, 1);
		/* 1165 */world.setBlockMetadataWithNotify(i + 2, j + 10, k + 7, 1, 2);
		/* 1166 */setBlock(world, i + 2, j + 11, k + 6, Blocks.log, 1);
		/* 1167 */world.setBlockMetadataWithNotify(i + 2, j + 11, k + 6, 1, 2);
		/* 1168 */setBlock(world, i + 2, j + 11, k + 7, Blocks.log, 1);
		/* 1169 */world.setBlockMetadataWithNotify(i + 2, j + 11, k + 7, 1, 2);
		/* 1170 */setBlock(world, i + 2, j + 12, k + 6, Blocks.log, 1);
		/* 1171 */world.setBlockMetadataWithNotify(i + 2, j + 12, k + 6, 1, 2);
		/* 1172 */setBlock(world, i + 2, j + 12, k + 7, Blocks.log, 1);
		/* 1173 */world.setBlockMetadataWithNotify(i + 2, j + 12, k + 7, 1, 2);
		/* 1174 */setBlock(world, i + 2, j + 12, k + 8, Blocks.log, 1);
		/* 1175 */world.setBlockMetadataWithNotify(i + 2, j + 12, k + 8, 1, 2);
		/* 1176 */setBlock(world, i + 2, j + 12, k + 9, Blocks.planks, 5);
		/* 1177 */world.setBlockMetadataWithNotify(i + 2, j + 12, k + 9, 5, 2);
		/* 1178 */setBlock(world, i + 2, j + 12, k + 10, Blocks.planks, 5);
		/* 1179 */world.setBlockMetadataWithNotify(i + 2, j + 12, k + 10, 5, 2);
		/* 1180 */setBlock(world, i + 2, j + 13, k + 7, Blocks.log, 1);
		/* 1181 */world.setBlockMetadataWithNotify(i + 2, j + 13, k + 7, 1, 2);
		/* 1182 */setBlock(world, i + 2, j + 13, k + 8, Blocks.log, 1);
		/* 1183 */world.setBlockMetadataWithNotify(i + 2, j + 13, k + 8, 1, 2);
		/* 1184 */setBlock(world, i + 2, j + 13, k + 9, Blocks.planks, 5);
		/* 1185 */world.setBlockMetadataWithNotify(i + 2, j + 13, k + 9, 5, 2);
		/* 1186 */setBlock(world, i + 2, j + 13, k + 10, Blocks.planks, 5);
		/* 1187 */world.setBlockMetadataWithNotify(i + 2, j + 13, k + 10, 5, 2);
		/* 1188 */setBlock(world, i + 2, j + 13, k + 11, Blocks.planks, 5);
		/* 1189 */world.setBlockMetadataWithNotify(i + 2, j + 13, k + 11, 5, 2);
		/* 1190 */setBlock(world, i + 2, j + 14, k + 7, Blocks.log, 1);
		/* 1191 */world.setBlockMetadataWithNotify(i + 2, j + 14, k + 7, 1, 2);
		/* 1192 */setBlock(world, i + 2, j + 14, k + 8, Blocks.log, 1);
		/* 1193 */world.setBlockMetadataWithNotify(i + 2, j + 14, k + 8, 1, 2);
		/* 1194 */setBlock(world, i + 2, j + 14, k + 9, Blocks.planks, 5);
		/* 1195 */world.setBlockMetadataWithNotify(i + 2, j + 14, k + 9, 5, 2);
		/* 1196 */setBlock(world, i + 2, j + 14, k + 10, Blocks.planks, 5);
		/* 1197 */world.setBlockMetadataWithNotify(i + 2, j + 14, k + 10, 5, 2);
		/* 1198 */setBlock(world, i + 2, j + 14, k + 11, Blocks.planks, 5);
		/* 1199 */world.setBlockMetadataWithNotify(i + 2, j + 14, k + 11, 5, 2);
		/* 1200 */setBlock(world, i + 2, j + 15, k + 6, Blocks.log, 1);
		/* 1201 */world.setBlockMetadataWithNotify(i + 2, j + 15, k + 6, 1, 2);
		/* 1202 */setBlock(world, i + 2, j + 15, k + 7, Blocks.log, 1);
		/* 1203 */world.setBlockMetadataWithNotify(i + 2, j + 15, k + 7, 1, 2);
		/* 1204 */setBlock(world, i + 2, j + 15, k + 8, Blocks.log, 1);
		/* 1205 */world.setBlockMetadataWithNotify(i + 2, j + 15, k + 8, 1, 2);
		/* 1206 */setBlock(world, i + 2, j + 16, k + 7, Blocks.log, 1);
		/* 1207 */world.setBlockMetadataWithNotify(i + 2, j + 16, k + 7, 1, 2);
		/* 1208 */setBlock(world, i + 2, j + 16, k + 8, Blocks.log, 1);
		/* 1209 */world.setBlockMetadataWithNotify(i + 2, j + 16, k + 8, 1, 2);
		/* 1210 */setBlock(world, i + 2, j + 17, k + 7, Blocks.log, 1);
		/* 1211 */world.setBlockMetadataWithNotify(i + 2, j + 17, k + 7, 1, 2);
		/* 1212 */setBlock(world, i + 2, j + 17, k + 8, Blocks.log, 1);
		/* 1213 */world.setBlockMetadataWithNotify(i + 2, j + 17, k + 8, 1, 2);
		/* 1214 */setBlock(world, i + 2, j + 17, k + 9, Blocks.torch, 3);
		/* 1215 */world.setBlockMetadataWithNotify(i + 2, j + 17, k + 9, 3, 2);
		/* 1216 */setBlock(world, i + 2, j + 18, k + 3, Blocks.vine, 1);
		/* 1217 */world.setBlockMetadataWithNotify(i + 2, j + 18, k + 3, 1, 2);
		/* 1218 */setBlock(world, i + 2, j + 18, k + 4, Blocks.vine, 15);
		/* 1219 */world.setBlockMetadataWithNotify(i + 2, j + 18, k + 4, 15, 2);
		/* 1220 */setBlock(world, i + 2, j + 18, k + 6, Blocks.log, 1);
		/* 1221 */world.setBlockMetadataWithNotify(i + 2, j + 18, k + 6, 1, 2);
		/* 1222 */setBlock(world, i + 2, j + 18, k + 7, Blocks.log, 1);
		/* 1223 */world.setBlockMetadataWithNotify(i + 2, j + 18, k + 7, 1, 2);
		/* 1224 */setBlock(world, i + 2, j + 18, k + 8, Blocks.log, 1);
		/* 1225 */world.setBlockMetadataWithNotify(i + 2, j + 18, k + 8, 1, 2);
		/* 1226 */setBlock(world, i + 2, j + 19, k + 3, Blocks.vine, 15);
		/* 1227 */world.setBlockMetadataWithNotify(i + 2, j + 19, k + 3, 15, 2);
		/* 1228 */setBlock(world, i + 2, j + 19, k + 4, Blocks.vine, 15);
		/* 1229 */world.setBlockMetadataWithNotify(i + 2, j + 19, k + 4, 15, 2);
		/* 1230 */setBlock(world, i + 2, j + 19, k + 5, Blocks.vine, 15);
		/* 1231 */world.setBlockMetadataWithNotify(i + 2, j + 19, k + 5, 15, 2);
		/* 1232 */setBlock(world, i + 2, j + 19, k + 6, Blocks.log, 1);
		/* 1233 */world.setBlockMetadataWithNotify(i + 2, j + 19, k + 6, 1, 2);
		/* 1234 */setBlock(world, i + 2, j + 19, k + 7, Blocks.log, 1);
		/* 1235 */world.setBlockMetadataWithNotify(i + 2, j + 19, k + 7, 1, 2);
		/* 1236 */setBlock(world, i + 2, j + 19, k + 8, Blocks.log, 1);
		/* 1237 */world.setBlockMetadataWithNotify(i + 2, j + 19, k + 8, 1, 2);
		/* 1238 */setBlock(world, i + 2, j + 20, k + 3, Blocks.vine, 15);
		/* 1239 */world.setBlockMetadataWithNotify(i + 2, j + 20, k + 3, 15, 2);
		/* 1240 */setBlock(world, i + 2, j + 20, k + 4, Blocks.vine, 15);
		/* 1241 */world.setBlockMetadataWithNotify(i + 2, j + 20, k + 4, 15, 2);
		/* 1242 */setBlock(world, i + 2, j + 20, k + 5, Blocks.vine, 15);
		/* 1243 */world.setBlockMetadataWithNotify(i + 2, j + 20, k + 5, 15, 2);
		/* 1244 */setBlock(world, i + 2, j + 20, k + 6, Blocks.log, 1);
		/* 1245 */world.setBlockMetadataWithNotify(i + 2, j + 20, k + 6, 1, 2);
		/* 1246 */setBlock(world, i + 2, j + 20, k + 7, Blocks.log, 1);
		/* 1247 */world.setBlockMetadataWithNotify(i + 2, j + 20, k + 7, 1, 2);
		/* 1248 */setBlock(world, i + 2, j + 20, k + 8, Blocks.log, 1);
		/* 1249 */world.setBlockMetadataWithNotify(i + 2, j + 20, k + 8, 1, 2);
		/* 1250 */setBlock(world, i + 2, j + 21, k + 0, Blocks.vine, 13);
		/* 1251 */world.setBlockMetadataWithNotify(i + 2, j + 21, k + 0, 13, 2);
		/* 1252 */setBlock(world, i + 2, j + 21, k + 1, Blocks.vine, 15);
		/* 1253 */world.setBlockMetadataWithNotify(i + 2, j + 21, k + 1, 15, 2);
		/* 1254 */setBlock(world, i + 2, j + 21, k + 2, Blocks.vine, 15);
		/* 1255 */world.setBlockMetadataWithNotify(i + 2, j + 21, k + 2, 15, 2);
		/* 1256 */setBlock(world, i + 2, j + 21, k + 3, Blocks.vine, 15);
		/* 1257 */world.setBlockMetadataWithNotify(i + 2, j + 21, k + 3, 15, 2);
		/* 1258 */setBlock(world, i + 2, j + 21, k + 4, Blocks.vine, 15);
		/* 1259 */world.setBlockMetadataWithNotify(i + 2, j + 21, k + 4, 15, 2);
		/* 1260 */setBlock(world, i + 2, j + 21, k + 5, Blocks.log, 1);
		/* 1261 */world.setBlockMetadataWithNotify(i + 2, j + 21, k + 5, 1, 2);
		/* 1262 */setBlock(world, i + 2, j + 21, k + 6, Blocks.log, 1);
		/* 1263 */world.setBlockMetadataWithNotify(i + 2, j + 21, k + 6, 1, 2);
		/* 1264 */setBlock(world, i + 2, j + 21, k + 7, Blocks.log, 1);
		/* 1265 */world.setBlockMetadataWithNotify(i + 2, j + 21, k + 7, 1, 2);
		/* 1266 */setBlock(world, i + 2, j + 21, k + 8, Blocks.log, 1);
		/* 1267 */world.setBlockMetadataWithNotify(i + 2, j + 21, k + 8, 1, 2);
		/* 1268 */setBlock(world, i + 2, j + 22, k + 0, Blocks.vine, 15);
		/* 1269 */world.setBlockMetadataWithNotify(i + 2, j + 22, k + 0, 15, 2);
		/* 1270 */setBlock(world, i + 2, j + 22, k + 1, Blocks.log, 1);
		/* 1271 */world.setBlockMetadataWithNotify(i + 2, j + 22, k + 1, 1, 2);
		/* 1272 */setBlock(world, i + 2, j + 22, k + 2, Blocks.log, 1);
		/* 1273 */world.setBlockMetadataWithNotify(i + 2, j + 22, k + 2, 1, 2);
		/* 1274 */setBlock(world, i + 2, j + 22, k + 3, Blocks.log, 1);
		/* 1275 */world.setBlockMetadataWithNotify(i + 2, j + 22, k + 3, 1, 2);
		/* 1276 */setBlock(world, i + 2, j + 22, k + 4, Blocks.log, 1);
		/* 1277 */world.setBlockMetadataWithNotify(i + 2, j + 22, k + 4, 1, 2);
		/* 1278 */setBlock(world, i + 2, j + 22, k + 5, Blocks.log, 1);
		/* 1279 */world.setBlockMetadataWithNotify(i + 2, j + 22, k + 5, 1, 2);
		/* 1280 */setBlock(world, i + 2, j + 22, k + 6, Blocks.log, 1);
		/* 1281 */world.setBlockMetadataWithNotify(i + 2, j + 22, k + 6, 1, 2);
		/* 1282 */setBlock(world, i + 2, j + 22, k + 7, Blocks.log, 1);
		/* 1283 */world.setBlockMetadataWithNotify(i + 2, j + 22, k + 7, 1, 2);
		/* 1284 */setBlock(world, i + 2, j + 22, k + 8, Blocks.log, 1);
		/* 1285 */world.setBlockMetadataWithNotify(i + 2, j + 22, k + 8, 1, 2);
		/* 1286 */setBlock(world, i + 2, j + 22, k + 29, Blocks.log, 3);
		/* 1287 */world.setBlockMetadataWithNotify(i + 2, j + 22, k + 29, 3, 2);
		/* 1288 */setBlock(world, i + 2, j + 23, k + 0, Blocks.vine, 15);
		/* 1289 */world.setBlockMetadataWithNotify(i + 2, j + 23, k + 0, 15, 2);
		/* 1290 */setBlock(world, i + 2, j + 23, k + 1, Blocks.log, 1);
		/* 1291 */world.setBlockMetadataWithNotify(i + 2, j + 23, k + 1, 1, 2);
		/* 1292 */setBlock(world, i + 2, j + 23, k + 2, Blocks.log, 1);
		/* 1293 */world.setBlockMetadataWithNotify(i + 2, j + 23, k + 2, 1, 2);
		/* 1294 */setBlock(world, i + 2, j + 23, k + 3, Blocks.log, 1);
		/* 1295 */world.setBlockMetadataWithNotify(i + 2, j + 23, k + 3, 1, 2);
		/* 1296 */setBlock(world, i + 2, j + 23, k + 4, Blocks.log, 1);
		/* 1297 */world.setBlockMetadataWithNotify(i + 2, j + 23, k + 4, 1, 2);
		/* 1298 */setBlock(world, i + 2, j + 23, k + 5, Blocks.log, 1);
		/* 1299 */world.setBlockMetadataWithNotify(i + 2, j + 23, k + 5, 1, 2);
		/* 1300 */setBlock(world, i + 2, j + 23, k + 6, Blocks.leaves, 15);
		/* 1301 */world.setBlockMetadataWithNotify(i + 2, j + 23, k + 6, 15, 2);
		/* 1302 */setBlock(world, i + 2, j + 23, k + 7, Blocks.log, 1);
		/* 1303 */world.setBlockMetadataWithNotify(i + 2, j + 23, k + 7, 1, 2);
		/* 1304 */setBlock(world, i + 2, j + 23, k + 8, Blocks.vine, 15);
		/* 1305 */world.setBlockMetadataWithNotify(i + 2, j + 23, k + 8, 15, 2);
		/* 1306 */setBlock(world, i + 2, j + 23, k + 9, Blocks.vine, 15);
		/* 1307 */world.setBlockMetadataWithNotify(i + 2, j + 23, k + 9, 15, 2);
		/* 1308 */setBlock(world, i + 2, j + 23, k + 26, Blocks.leaves, 15);
		/* 1309 */world.setBlockMetadataWithNotify(i + 2, j + 23, k + 26, 15, 2);
		/* 1310 */setBlock(world, i + 2, j + 23, k + 27, Blocks.leaves, 15);
		/* 1311 */world.setBlockMetadataWithNotify(i + 2, j + 23, k + 27, 15, 2);
		/* 1312 */setBlock(world, i + 2, j + 23, k + 28, Blocks.leaves, 15);
		/* 1313 */world.setBlockMetadataWithNotify(i + 2, j + 23, k + 28, 15, 2);
		/* 1314 */setBlock(world, i + 2, j + 23, k + 29, Blocks.leaves, 15);
		/* 1315 */world.setBlockMetadataWithNotify(i + 2, j + 23, k + 29, 15, 2);
		/* 1316 */setBlock(world, i + 2, j + 23, k + 30, Blocks.leaves, 15);
		/* 1317 */world.setBlockMetadataWithNotify(i + 2, j + 23, k + 30, 15, 2);
		/* 1318 */setBlock(world, i + 2, j + 24, k + 1, Blocks.log, 1);
		/* 1319 */world.setBlockMetadataWithNotify(i + 2, j + 24, k + 1, 1, 2);
		/* 1320 */setBlock(world, i + 2, j + 24, k + 2, Blocks.log, 1);
		/* 1321 */world.setBlockMetadataWithNotify(i + 2, j + 24, k + 2, 1, 2);
		/* 1322 */setBlock(world, i + 2, j + 24, k + 3, Blocks.log, 1);
		/* 1323 */world.setBlockMetadataWithNotify(i + 2, j + 24, k + 3, 1, 2);
		/* 1324 */setBlock(world, i + 2, j + 24, k + 4, Blocks.log, 1);
		/* 1325 */world.setBlockMetadataWithNotify(i + 2, j + 24, k + 4, 1, 2);
		/* 1326 */setBlock(world, i + 2, j + 24, k + 5, Blocks.log, 1);
		/* 1327 */world.setBlockMetadataWithNotify(i + 2, j + 24, k + 5, 1, 2);
		/* 1328 */setBlock(world, i + 2, j + 24, k + 6, Blocks.log, 1);
		/* 1329 */world.setBlockMetadataWithNotify(i + 2, j + 24, k + 6, 1, 2);
		/* 1330 */setBlock(world, i + 2, j + 24, k + 7, Blocks.log, 1);
		/* 1331 */world.setBlockMetadataWithNotify(i + 2, j + 24, k + 7, 1, 2);
		/* 1332 */setBlock(world, i + 2, j + 24, k + 8, Blocks.log, 1);
		/* 1333 */world.setBlockMetadataWithNotify(i + 2, j + 24, k + 8, 1, 2);
		/* 1334 */setBlock(world, i + 2, j + 24, k + 9, Blocks.log, 1);
		/* 1335 */world.setBlockMetadataWithNotify(i + 2, j + 24, k + 9, 1, 2);
		/* 1336 */setBlock(world, i + 2, j + 24, k + 10, Blocks.log, 1);
		/* 1337 */world.setBlockMetadataWithNotify(i + 2, j + 24, k + 10, 1, 2);
		/* 1338 */setBlock(world, i + 2, j + 24, k + 11, Blocks.log, 1);
		/* 1339 */world.setBlockMetadataWithNotify(i + 2, j + 24, k + 11, 1, 2);
		/* 1340 */setBlock(world, i + 2, j + 24, k + 12, Blocks.log, 1);
		/* 1341 */world.setBlockMetadataWithNotify(i + 2, j + 24, k + 12, 1, 2);
		/* 1342 */setBlock(world, i + 2, j + 24, k + 27, Blocks.leaves, 15);
		/* 1343 */world.setBlockMetadataWithNotify(i + 2, j + 24, k + 27, 15, 2);
		/* 1344 */setBlock(world, i + 2, j + 24, k + 28, Blocks.leaves, 15);
		/* 1345 */world.setBlockMetadataWithNotify(i + 2, j + 24, k + 28, 15, 2);
		/* 1346 */setBlock(world, i + 2, j + 24, k + 29, Blocks.leaves, 15);
		/* 1347 */world.setBlockMetadataWithNotify(i + 2, j + 24, k + 29, 15, 2);
		/* 1348 */setBlock(world, i + 2, j + 25, k + 1, Blocks.log, 1);
		/* 1349 */world.setBlockMetadataWithNotify(i + 2, j + 25, k + 1, 1, 2);
		/* 1350 */setBlock(world, i + 2, j + 25, k + 2, Blocks.log, 1);
		/* 1351 */world.setBlockMetadataWithNotify(i + 2, j + 25, k + 2, 1, 2);
		/* 1352 */setBlock(world, i + 2, j + 25, k + 3, Blocks.log, 1);
		/* 1353 */world.setBlockMetadataWithNotify(i + 2, j + 25, k + 3, 1, 2);
		/* 1354 */setBlock(world, i + 2, j + 25, k + 4, Blocks.log, 1);
		/* 1355 */world.setBlockMetadataWithNotify(i + 2, j + 25, k + 4, 1, 2);
		/* 1356 */setBlock(world, i + 2, j + 25, k + 5, Blocks.log, 1);
		/* 1357 */world.setBlockMetadataWithNotify(i + 2, j + 25, k + 5, 1, 2);
		/* 1358 */setBlock(world, i + 2, j + 25, k + 6, Blocks.log, 1);
		/* 1359 */world.setBlockMetadataWithNotify(i + 2, j + 25, k + 6, 1, 2);
		/* 1360 */setBlock(world, i + 2, j + 25, k + 7, Blocks.log, 1);
		/* 1361 */world.setBlockMetadataWithNotify(i + 2, j + 25, k + 7, 1, 2);
		/* 1362 */setBlock(world, i + 2, j + 25, k + 8, Blocks.log, 1);
		/* 1363 */world.setBlockMetadataWithNotify(i + 2, j + 25, k + 8, 1, 2);
		/* 1364 */setBlock(world, i + 2, j + 25, k + 9, Blocks.log, 1);
		/* 1365 */world.setBlockMetadataWithNotify(i + 2, j + 25, k + 9, 1, 2);
		/* 1366 */setBlock(world, i + 2, j + 25, k + 10, Blocks.log, 1);
		/* 1367 */world.setBlockMetadataWithNotify(i + 2, j + 25, k + 10, 1, 2);
		/* 1368 */setBlock(world, i + 2, j + 25, k + 11, Blocks.log, 1);
		/* 1369 */world.setBlockMetadataWithNotify(i + 2, j + 25, k + 11, 1, 2);
		/* 1370 */setBlock(world, i + 2, j + 25, k + 28, Blocks.leaves, 15);
		/* 1371 */world.setBlockMetadataWithNotify(i + 2, j + 25, k + 28, 15, 2);
		/* 1372 */setBlock(world, i + 2, j + 26, k + 0, Blocks.planks, 5);
		/* 1373 */world.setBlockMetadataWithNotify(i + 2, j + 26, k + 0, 5, 2);
		/* 1374 */setBlock(world, i + 2, j + 26, k + 1, Blocks.planks, 5);
		/* 1375 */world.setBlockMetadataWithNotify(i + 2, j + 26, k + 1, 5, 2);
		/* 1376 */setBlock(world, i + 2, j + 26, k + 2, Blocks.log, 1);
		/* 1377 */world.setBlockMetadataWithNotify(i + 2, j + 26, k + 2, 1, 2);
		/* 1378 */setBlock(world, i + 2, j + 26, k + 3, Blocks.planks, 5);
		/* 1379 */world.setBlockMetadataWithNotify(i + 2, j + 26, k + 3, 5, 2);
		/* 1380 */setBlock(world, i + 2, j + 26, k + 4, Blocks.planks, 5);
		/* 1381 */world.setBlockMetadataWithNotify(i + 2, j + 26, k + 4, 5, 2);
		/* 1382 */setBlock(world, i + 2, j + 26, k + 5, Blocks.log, 1);
		/* 1383 */world.setBlockMetadataWithNotify(i + 2, j + 26, k + 5, 1, 2);
		/* 1384 */setBlock(world, i + 2, j + 26, k + 6, Blocks.planks, 5);
		/* 1385 */world.setBlockMetadataWithNotify(i + 2, j + 26, k + 6, 5, 2);
		/* 1386 */setBlock(world, i + 2, j + 26, k + 7, Blocks.planks, 5);
		/* 1387 */world.setBlockMetadataWithNotify(i + 2, j + 26, k + 7, 5, 2);
		/* 1388 */setBlock(world, i + 2, j + 26, k + 8, Blocks.log, 1);
		/* 1389 */world.setBlockMetadataWithNotify(i + 2, j + 26, k + 8, 1, 2);
		/* 1390 */setBlock(world, i + 2, j + 26, k + 9, Blocks.planks, 5);
		/* 1391 */world.setBlockMetadataWithNotify(i + 2, j + 26, k + 9, 5, 2);
		/* 1392 */setBlock(world, i + 2, j + 26, k + 10, Blocks.planks, 5);
		/* 1393 */world.setBlockMetadataWithNotify(i + 2, j + 26, k + 10, 5, 2);
		/* 1394 */setBlock(world, i + 2, j + 26, k + 11, Blocks.log, 1);
		/* 1395 */world.setBlockMetadataWithNotify(i + 2, j + 26, k + 11, 1, 2);
		/* 1396 */setBlock(world, i + 2, j + 26, k + 12, Blocks.planks, 5);
		/* 1397 */world.setBlockMetadataWithNotify(i + 2, j + 26, k + 12, 5, 2);
		/* 1398 */setBlock(world, i + 2, j + 26, k + 13, Blocks.planks, 5);
		/* 1399 */world.setBlockMetadataWithNotify(i + 2, j + 26, k + 13, 5, 2);
		/* 1400 */setBlock(world, i + 2, j + 26, k + 14, Blocks.planks, 5);
		/* 1401 */world.setBlockMetadataWithNotify(i + 2, j + 26, k + 14, 5, 2);
		/* 1402 */setBlock(world, i + 2, j + 26, k + 15, Blocks.planks, 5);
		/* 1403 */world.setBlockMetadataWithNotify(i + 2, j + 26, k + 15, 5, 2);
		/* 1404 */setBlock(world, i + 2, j + 26, k + 16, Blocks.planks, 5);
		/* 1405 */world.setBlockMetadataWithNotify(i + 2, j + 26, k + 16, 5, 2);
		/* 1406 */setBlock(world, i + 2, j + 26, k + 17, Blocks.planks, 5);
		/* 1407 */world.setBlockMetadataWithNotify(i + 2, j + 26, k + 17, 5, 2);
		/* 1408 */setBlock(world, i + 2, j + 27, k + 4, Blocks.chest, 2);
		/* 1409 */LootGenUtils.fillLootChest(world.provider.dimensionId, world.rand, (TileEntityChest)world.getTileEntity(i + 2, j + 27, k + 4));
		/* 1410 */world.setBlockMetadataWithNotify(i + 2, j + 27, k + 4, 2, 2);
		/* 1411 */setBlock(world, i + 2, j + 27, k + 5, Blocks.spruce_stairs, 1);
		/* 1412 */world.setBlockMetadataWithNotify(i + 2, j + 27, k + 5, 1, 2);
		/* 1413 */setBlock(world, i + 2, j + 27, k + 6, Blocks.furnace, 3);
		/* 1414 */world.setBlockMetadataWithNotify(i + 2, j + 27, k + 6, 3, 2);
		/* 1415 */setBlock(world, i + 2, j + 29, k + 5, Blocks.torch, 1);
		/* 1416 */world.setBlockMetadataWithNotify(i + 2, j + 29, k + 5, 1, 2);
		/* 1417 */setBlock(world, i + 2, j + 29, k + 13, Blocks.torch, 2);
		/* 1418 */world.setBlockMetadataWithNotify(i + 2, j + 29, k + 13, 2, 2);
		/* 1419 */setBlock(world, i + 2, j + 30, k + 0, Blocks.log, 1);
		/* 1420 */world.setBlockMetadataWithNotify(i + 2, j + 30, k + 0, 1, 2);
		/* 1421 */setBlock(world, i + 2, j + 30, k + 10, Blocks.log, 1);
		/* 1422 */world.setBlockMetadataWithNotify(i + 2, j + 30, k + 10, 1, 2);
		/* 1423 */setBlock(world, i + 2, j + 30, k + 11, Blocks.log, 1);
		/* 1424 */world.setBlockMetadataWithNotify(i + 2, j + 30, k + 11, 1, 2);
		/* 1425 */setBlock(world, i + 2, j + 30, k + 12, Blocks.log, 1);
		/* 1426 */world.setBlockMetadataWithNotify(i + 2, j + 30, k + 12, 1, 2);
		/* 1427 */setBlock(world, i + 2, j + 30, k + 13, Blocks.log, 1);
		/* 1428 */world.setBlockMetadataWithNotify(i + 2, j + 30, k + 13, 1, 2);
		/* 1429 */setBlock(world, i + 2, j + 30, k + 14, Blocks.log, 1);
		/* 1430 */world.setBlockMetadataWithNotify(i + 2, j + 30, k + 14, 1, 2);
		/* 1431 */setBlock(world, i + 2, j + 31, k + 0, Blocks.log, 1);
		/* 1432 */world.setBlockMetadataWithNotify(i + 2, j + 31, k + 0, 1, 2);
		/* 1433 */setBlock(world, i + 2, j + 31, k + 1, Blocks.log, 1);
		/* 1434 */world.setBlockMetadataWithNotify(i + 2, j + 31, k + 1, 1, 2);
		/* 1435 */setBlock(world, i + 2, j + 31, k + 9, Blocks.log, 1);
		/* 1436 */world.setBlockMetadataWithNotify(i + 2, j + 31, k + 9, 1, 2);
		/* 1437 */setBlock(world, i + 2, j + 31, k + 10, Blocks.log, 1);
		/* 1438 */world.setBlockMetadataWithNotify(i + 2, j + 31, k + 10, 1, 2);
		/* 1439 */setBlock(world, i + 2, j + 31, k + 11, Blocks.log, 1);
		/* 1440 */world.setBlockMetadataWithNotify(i + 2, j + 31, k + 11, 1, 2);
		/* 1441 */setBlock(world, i + 2, j + 31, k + 12, Blocks.log, 1);
		/* 1442 */world.setBlockMetadataWithNotify(i + 2, j + 31, k + 12, 1, 2);
		/* 1443 */setBlock(world, i + 2, j + 31, k + 13, Blocks.log, 1);
		/* 1444 */world.setBlockMetadataWithNotify(i + 2, j + 31, k + 13, 1, 2);
		/* 1445 */setBlock(world, i + 2, j + 32, k + 0, Blocks.log, 1);
		/* 1446 */world.setBlockMetadataWithNotify(i + 2, j + 32, k + 0, 1, 2);
		/* 1447 */setBlock(world, i + 2, j + 32, k + 1, Blocks.log, 1);
		/* 1448 */world.setBlockMetadataWithNotify(i + 2, j + 32, k + 1, 1, 2);
		/* 1449 */setBlock(world, i + 2, j + 32, k + 2, Blocks.log, 1);
		/* 1450 */world.setBlockMetadataWithNotify(i + 2, j + 32, k + 2, 1, 2);
		/* 1451 */setBlock(world, i + 2, j + 32, k + 4, Blocks.log, 1);
		/* 1452 */world.setBlockMetadataWithNotify(i + 2, j + 32, k + 4, 1, 2);
		/* 1453 */setBlock(world, i + 2, j + 32, k + 5, Blocks.log, 1);
		/* 1454 */world.setBlockMetadataWithNotify(i + 2, j + 32, k + 5, 1, 2);
		/* 1455 */setBlock(world, i + 2, j + 32, k + 6, Blocks.log, 1);
		/* 1456 */world.setBlockMetadataWithNotify(i + 2, j + 32, k + 6, 1, 2);
		/* 1457 */setBlock(world, i + 2, j + 32, k + 8, Blocks.log, 1);
		/* 1458 */world.setBlockMetadataWithNotify(i + 2, j + 32, k + 8, 1, 2);
		/* 1459 */setBlock(world, i + 2, j + 32, k + 9, Blocks.log, 1);
		/* 1460 */world.setBlockMetadataWithNotify(i + 2, j + 32, k + 9, 1, 2);
		/* 1461 */setBlock(world, i + 2, j + 32, k + 10, Blocks.log, 1);
		/* 1462 */world.setBlockMetadataWithNotify(i + 2, j + 32, k + 10, 1, 2);
		/* 1463 */setBlock(world, i + 2, j + 32, k + 11, Blocks.log, 1);
		/* 1464 */world.setBlockMetadataWithNotify(i + 2, j + 32, k + 11, 1, 2);
		/* 1465 */setBlock(world, i + 2, j + 32, k + 12, Blocks.log, 1);
		/* 1466 */world.setBlockMetadataWithNotify(i + 2, j + 32, k + 12, 1, 2);
		/* 1467 */setBlock(world, i + 2, j + 32, k + 13, Blocks.log, 1);
		/* 1468 */world.setBlockMetadataWithNotify(i + 2, j + 32, k + 13, 1, 2);
		/* 1469 */setBlock(world, i + 2, j + 33, k + 0, Blocks.log, 1);
		/* 1470 */world.setBlockMetadataWithNotify(i + 2, j + 33, k + 0, 1, 2);
		/* 1471 */setBlock(world, i + 2, j + 33, k + 1, Blocks.log, 1);
		/* 1472 */world.setBlockMetadataWithNotify(i + 2, j + 33, k + 1, 1, 2);
		/* 1473 */setBlock(world, i + 2, j + 33, k + 2, Blocks.log, 1);
		/* 1474 */world.setBlockMetadataWithNotify(i + 2, j + 33, k + 2, 1, 2);
		/* 1475 */setBlock(world, i + 2, j + 33, k + 3, Blocks.log, 1);
		/* 1476 */world.setBlockMetadataWithNotify(i + 2, j + 33, k + 3, 1, 2);
		/* 1477 */setBlock(world, i + 2, j + 33, k + 4, Blocks.log, 1);
		/* 1478 */world.setBlockMetadataWithNotify(i + 2, j + 33, k + 4, 1, 2);
		/* 1479 */setBlock(world, i + 2, j + 33, k + 5, Blocks.log, 1);
		/* 1480 */world.setBlockMetadataWithNotify(i + 2, j + 33, k + 5, 1, 2);
		/* 1481 */setBlock(world, i + 2, j + 33, k + 6, Blocks.log, 1);
		/* 1482 */world.setBlockMetadataWithNotify(i + 2, j + 33, k + 6, 1, 2);
		/* 1483 */setBlock(world, i + 2, j + 33, k + 7, Blocks.log, 1);
		/* 1484 */world.setBlockMetadataWithNotify(i + 2, j + 33, k + 7, 1, 2);
		/* 1485 */setBlock(world, i + 2, j + 33, k + 8, Blocks.log, 1);
		/* 1486 */world.setBlockMetadataWithNotify(i + 2, j + 33, k + 8, 1, 2);
		/* 1487 */setBlock(world, i + 2, j + 33, k + 9, Blocks.log, 1);
		/* 1488 */world.setBlockMetadataWithNotify(i + 2, j + 33, k + 9, 1, 2);
		/* 1489 */setBlock(world, i + 2, j + 33, k + 10, Blocks.log, 1);
		/* 1490 */world.setBlockMetadataWithNotify(i + 2, j + 33, k + 10, 1, 2);
		/* 1491 */setBlock(world, i + 2, j + 33, k + 11, Blocks.log, 1);
		/* 1492 */world.setBlockMetadataWithNotify(i + 2, j + 33, k + 11, 1, 2);
		/* 1493 */setBlock(world, i + 2, j + 33, k + 12, Blocks.log, 1);
		/* 1494 */world.setBlockMetadataWithNotify(i + 2, j + 33, k + 12, 1, 2);
		/* 1495 */setBlock(world, i + 2, j + 34, k + 0, Blocks.log, 1);
		/* 1496 */world.setBlockMetadataWithNotify(i + 2, j + 34, k + 0, 1, 2);
		/* 1497 */setBlock(world, i + 2, j + 34, k + 1, Blocks.log, 1);
		/* 1498 */world.setBlockMetadataWithNotify(i + 2, j + 34, k + 1, 1, 2);
		/* 1499 */setBlock(world, i + 2, j + 34, k + 2, Blocks.log, 1);
		/* 1500 */world.setBlockMetadataWithNotify(i + 2, j + 34, k + 2, 1, 2);
		/* 1501 */setBlock(world, i + 2, j + 34, k + 3, Blocks.log, 1);
		/* 1502 */world.setBlockMetadataWithNotify(i + 2, j + 34, k + 3, 1, 2);
		/* 1503 */setBlock(world, i + 2, j + 34, k + 4, Blocks.log, 1);
		/* 1504 */world.setBlockMetadataWithNotify(i + 2, j + 34, k + 4, 1, 2);
		/* 1505 */setBlock(world, i + 2, j + 34, k + 5, Blocks.log, 1);
		/* 1506 */world.setBlockMetadataWithNotify(i + 2, j + 34, k + 5, 1, 2);
		/* 1507 */setBlock(world, i + 2, j + 34, k + 6, Blocks.log, 1);
		/* 1508 */world.setBlockMetadataWithNotify(i + 2, j + 34, k + 6, 1, 2);
		/* 1509 */setBlock(world, i + 2, j + 34, k + 7, Blocks.log, 1);
		/* 1510 */world.setBlockMetadataWithNotify(i + 2, j + 34, k + 7, 1, 2);
		/* 1511 */setBlock(world, i + 2, j + 34, k + 8, Blocks.log, 1);
		/* 1512 */world.setBlockMetadataWithNotify(i + 2, j + 34, k + 8, 1, 2);
		/* 1513 */setBlock(world, i + 2, j + 34, k + 9, Blocks.log, 1);
		/* 1514 */world.setBlockMetadataWithNotify(i + 2, j + 34, k + 9, 1, 2);
		/* 1515 */setBlock(world, i + 2, j + 34, k + 10, Blocks.log, 1);
		/* 1516 */world.setBlockMetadataWithNotify(i + 2, j + 34, k + 10, 1, 2);
		/* 1517 */setBlock(world, i + 2, j + 34, k + 11, Blocks.log, 1);
		/* 1518 */world.setBlockMetadataWithNotify(i + 2, j + 34, k + 11, 1, 2);
		/* 1519 */setBlock(world, i + 2, j + 35, k + 2, Blocks.log, 1);
		/* 1520 */world.setBlockMetadataWithNotify(i + 2, j + 35, k + 2, 1, 2);
		/* 1521 */setBlock(world, i + 2, j + 35, k + 3, Blocks.log, 1);
		/* 1522 */world.setBlockMetadataWithNotify(i + 2, j + 35, k + 3, 1, 2);
		/* 1523 */setBlock(world, i + 2, j + 35, k + 4, Blocks.log, 1);
		/* 1524 */world.setBlockMetadataWithNotify(i + 2, j + 35, k + 4, 1, 2);
		/* 1525 */setBlock(world, i + 2, j + 35, k + 5, Blocks.log, 1);
		/* 1526 */world.setBlockMetadataWithNotify(i + 2, j + 35, k + 5, 1, 2);
		/* 1527 */setBlock(world, i + 2, j + 35, k + 6, Blocks.log, 1);
		/* 1528 */world.setBlockMetadataWithNotify(i + 2, j + 35, k + 6, 1, 2);
		/* 1529 */setBlock(world, i + 2, j + 35, k + 7, Blocks.log, 1);
		/* 1530 */world.setBlockMetadataWithNotify(i + 2, j + 35, k + 7, 1, 2);
		/* 1531 */setBlock(world, i + 2, j + 35, k + 8, Blocks.log, 1);
		/* 1532 */world.setBlockMetadataWithNotify(i + 2, j + 35, k + 8, 1, 2);
		/* 1533 */setBlock(world, i + 2, j + 40, k + 31, Blocks.planks, 5);
		/* 1534 */world.setBlockMetadataWithNotify(i + 2, j + 40, k + 31, 5, 2);
		/* 1535 */setBlock(world, i + 2, j + 41, k + 31, Blocks.torch, 5);
		/* 1536 */world.setBlockMetadataWithNotify(i + 2, j + 41, k + 31, 5, 2);
		/* 1537 */setBlock(world, i + 2, j + 50, k + 31, Blocks.leaves, 15);
		/* 1538 */world.setBlockMetadataWithNotify(i + 2, j + 50, k + 31, 15, 2);
		/* 1539 */setBlock(world, i + 3, j + 2, k + 6, Blocks.torch, 1);
		/* 1540 */world.setBlockMetadataWithNotify(i + 3, j + 2, k + 6, 1, 2);
		/* 1541 */setBlock(world, i + 3, j + 6, k + 7, Blocks.planks, 5);
		/* 1542 */world.setBlockMetadataWithNotify(i + 3, j + 6, k + 7, 5, 2);
		/* 1543 */setBlock(world, i + 3, j + 6, k + 8, Blocks.planks, 5);
		/* 1544 */world.setBlockMetadataWithNotify(i + 3, j + 6, k + 8, 5, 2);
		/* 1545 */setBlock(world, i + 3, j + 6, k + 9, Blocks.planks, 5);
		/* 1546 */world.setBlockMetadataWithNotify(i + 3, j + 6, k + 9, 5, 2);
		/* 1547 */setBlock(world, i + 3, j + 6, k + 10, Blocks.planks, 5);
		/* 1548 */world.setBlockMetadataWithNotify(i + 3, j + 6, k + 10, 5, 2);
		/* 1549 */setBlock(world, i + 3, j + 7, k + 6, Blocks.planks, 5);
		/* 1550 */world.setBlockMetadataWithNotify(i + 3, j + 7, k + 6, 5, 2);
		/* 1551 */setBlock(world, i + 3, j + 7, k + 7, Blocks.planks, 5);
		/* 1552 */world.setBlockMetadataWithNotify(i + 3, j + 7, k + 7, 5, 2);
		/* 1553 */setBlock(world, i + 3, j + 7, k + 8, Blocks.spruce_stairs, 3);
		/* 1554 */world.setBlockMetadataWithNotify(i + 3, j + 7, k + 8, 3, 2);
		/* 1555 */setBlock(world, i + 3, j + 8, k + 4, Blocks.planks, 5);
		/* 1556 */world.setBlockMetadataWithNotify(i + 3, j + 8, k + 4, 5, 2);
		/* 1557 */setBlock(world, i + 3, j + 8, k + 5, Blocks.planks, 5);
		/* 1558 */world.setBlockMetadataWithNotify(i + 3, j + 8, k + 5, 5, 2);
		/* 1559 */setBlock(world, i + 3, j + 8, k + 6, Blocks.planks, 5);
		/* 1560 */world.setBlockMetadataWithNotify(i + 3, j + 8, k + 6, 5, 2);
		/* 1561 */setBlock(world, i + 3, j + 8, k + 7, Blocks.spruce_stairs, 3);
		/* 1562 */world.setBlockMetadataWithNotify(i + 3, j + 8, k + 7, 3, 2);
		/* 1563 */setBlock(world, i + 3, j + 11, k + 6, Blocks.torch, 1);
		/* 1564 */world.setBlockMetadataWithNotify(i + 3, j + 11, k + 6, 1, 2);
		/* 1565 */setBlock(world, i + 3, j + 12, k + 10, Blocks.planks, 5);
		/* 1566 */world.setBlockMetadataWithNotify(i + 3, j + 12, k + 10, 5, 2);
		/* 1567 */setBlock(world, i + 3, j + 13, k + 8, Blocks.planks, 5);
		/* 1568 */world.setBlockMetadataWithNotify(i + 3, j + 13, k + 8, 5, 2);
		/* 1569 */setBlock(world, i + 3, j + 13, k + 9, Blocks.planks, 5);
		/* 1570 */world.setBlockMetadataWithNotify(i + 3, j + 13, k + 9, 5, 2);
		/* 1571 */setBlock(world, i + 3, j + 13, k + 10, Blocks.planks, 5);
		/* 1572 */world.setBlockMetadataWithNotify(i + 3, j + 13, k + 10, 5, 2);
		/* 1573 */setBlock(world, i + 3, j + 13, k + 11, Blocks.planks, 5);
		/* 1574 */world.setBlockMetadataWithNotify(i + 3, j + 13, k + 11, 5, 2);
		/* 1575 */setBlock(world, i + 3, j + 14, k + 7, Blocks.planks, 5);
		/* 1576 */world.setBlockMetadataWithNotify(i + 3, j + 14, k + 7, 5, 2);
		/* 1577 */setBlock(world, i + 3, j + 14, k + 8, Blocks.planks, 5);
		/* 1578 */world.setBlockMetadataWithNotify(i + 3, j + 14, k + 8, 5, 2);
		/* 1579 */setBlock(world, i + 3, j + 14, k + 9, Blocks.planks, 5);
		/* 1580 */world.setBlockMetadataWithNotify(i + 3, j + 14, k + 9, 5, 2);
