package com.parzivail.pswm.world.gen.wookietree;




import com.parzivail.pswm.utils.LootGenUtils;
import com.parzivail.pswm.utils.NPCType;
import com.parzivail.pswm.utils.SpawnUtils;



import cpw.mods.fml.common.IWorldGenerator;



import java.util.Random;



import net.minecraft.block.Block;

import net.minecraft.init.Blocks;

import net.minecraft.tileentity.TileEntityChest;

import net.minecraft.world.World;

import net.minecraft.world.WorldProvider;

import net.minecraft.world.chunk.IChunkProvider;

import net.minecraft.world.gen.feature.WorldGenerator;


public class WT_12
extends WorldGenerator implements IWorldGenerator

{
	protected Block[] getValidSpawnBlocks()
	
	{
		return new Block[0];
		}

	
	public boolean locationIsValidSpawn(World world, int i, int j, int k)
	
	{
		int distanceToAir = 0;
		Block check = world.getBlock(i, j, k);
		
		while (check != Blocks.air)
		{
			if (distanceToAir > 3) { return false;
			}
			
			distanceToAir++;
			check = world.getBlock(i, j + distanceToAir, k);
			}
		
		j += distanceToAir - 1;
		
		Block block = world.getBlock(i, j, k);
		Block blockAbove = world.getBlock(i, j + 1, k);
		Block blockBelow = world.getBlock(i, j - 1, k);
		
		for (Block x : getValidSpawnBlocks())
		{
			if (blockAbove != Blocks.air) { return false;
			}
			if (block == x) return true;
			if ((block == Blocks.snow) && (blockBelow == x)) { return true;
			}
			}
		
		return false;
		}

	
	
	
	public void generate(Random random, int chunkX, int chunkZ, World world, IChunkProvider chunkGenerator, IChunkProvider chunkProvider)
	{
	}

	
	
	public void setBlock(World world, int x, int y, int z, Block block, int metadata)
	
	{
		world.setBlock(x, y, z, block, metadata, 2);
		}

	
	public boolean generate(World world, Random rand, int i, int j, int k)
	
	{
		k -= 10;
		i -= 10;
		
		setBlock(world, i + 14, j + 41, k + 20, Blocks.fence, 0);
		setBlock(world, i + 14, j + 41, k + 29, Blocks.fence, 0);
		setBlock(world, i + 15, j + 41, k + 19, Blocks.fence, 0);
		setBlock(world, i + 15, j + 41, k + 20, Blocks.fence, 0);
		setBlock(world, i + 15, j + 41, k + 29, Blocks.fence, 0);
		setBlock(world, i + 15, j + 41, k + 30, Blocks.fence, 0);
		setBlock(world, i + 16, j + 41, k + 18, Blocks.fence, 0);
		setBlock(world, i + 16, j + 41, k + 19, Blocks.fence, 0);
		setBlock(world, i + 16, j + 41, k + 30, Blocks.fence, 0);
		setBlock(world, i + 16, j + 41, k + 31, Blocks.fence, 0);
		setBlock(world, i + 17, j + 38, k + 20, Blocks.fence, 0);
		setBlock(world, i + 17, j + 38, k + 29, Blocks.fence, 0);
		setBlock(world, i + 17, j + 41, k + 18, Blocks.fence, 0);
		setBlock(world, i + 17, j + 41, k + 31, Blocks.fence, 0);
		setBlock(world, i + 18, j + 38, k + 20, Blocks.fence, 0);
		SpawnUtils.spawnNPC(NPCType.WOOKIETREE, world, i + 18, j + 38, k + 25);
		setBlock(world, i + 18, j + 38, k + 29, Blocks.fence, 0);
		setBlock(world, i + 18, j + 41, k + 17, Blocks.fence, 0);
		setBlock(world, i + 18, j + 41, k + 18, Blocks.fence, 0);
		setBlock(world, i + 18, j + 41, k + 31, Blocks.fence, 0);
		setBlock(world, i + 19, j + 38, k + 19, Blocks.fence, 0);
		setBlock(world, i + 19, j + 38, k + 20, Blocks.fence, 0);
		setBlock(world, i + 19, j + 38, k + 29, Blocks.fence, 0);
		setBlock(world, i + 19, j + 38, k + 30, Blocks.fence, 0);
		setBlock(world, i + 19, j + 41, k + 17, Blocks.fence, 0);
		setBlock(world, i + 20, j + 38, k + 19, Blocks.fence, 0);
		setBlock(world, i + 20, j + 38, k + 30, Blocks.fence, 0);
		setBlock(world, i + 20, j + 41, k + 17, Blocks.fence, 0);
		setBlock(world, i + 21, j + 38, k + 19, Blocks.fence, 0);
		setBlock(world, i + 21, j + 38, k + 30, Blocks.fence, 0);
		setBlock(world, i + 21, j + 41, k + 16, Blocks.fence, 0);
		setBlock(world, i + 21, j + 41, k + 17, Blocks.fence, 0);
		setBlock(world, i + 24, j + 38, k + 24, Blocks.spruce_stairs, 0);
		setBlock(world, i + 24, j + 38, k + 25, Blocks.spruce_stairs, 0);
		setBlock(world, i + 24, j + 38, k + 26, Blocks.crafting_table, 0);
		SpawnUtils.spawnNPC(NPCType.WOOKIETREE, world, i + 25, j + 38, k + 29);
		SpawnUtils.spawnNPC(NPCType.WOOKIETREE, world, i + 26, j + 38, k + 20);
		setBlock(world, i + 28, j + 38, k + 18, Blocks.spruce_stairs, 0);
		setBlock(world, i + 28, j + 38, k + 31, Blocks.spruce_stairs, 0);
		setBlock(world, i + 30, j + 38, k + 19, Blocks.fence, 0);
		setBlock(world, i + 30, j + 38, k + 30, Blocks.fence, 0);
		setBlock(world, i + 30, j + 41, k + 16, Blocks.fence, 0);
		setBlock(world, i + 30, j + 41, k + 17, Blocks.fence, 0);
		setBlock(world, i + 31, j + 38, k + 19, Blocks.fence, 0);
		SpawnUtils.spawnNPC(NPCType.WOOKIETREE, world, i + 31, j + 38, k + 24);
		setBlock(world, i + 31, j + 38, k + 30, Blocks.fence, 0);
		setBlock(world, i + 31, j + 41, k + 17, Blocks.fence, 0);
		setBlock(world, i + 0, j + 0, k + 21, Blocks.log, 3);
		world.setBlockMetadataWithNotify(i + 0, j + 0, k + 21, 3, 2);
		setBlock(world, i + 0, j + 0, k + 22, Blocks.log, 3);
		world.setBlockMetadataWithNotify(i + 0, j + 0, k + 22, 3, 2);
		setBlock(world, i + 0, j + 0, k + 23, Blocks.log, 3);
		world.setBlockMetadataWithNotify(i + 0, j + 0, k + 23, 3, 2);
		setBlock(world, i + 0, j + 0, k + 24, Blocks.log, 3);
		world.setBlockMetadataWithNotify(i + 0, j + 0, k + 24, 3, 2);
		setBlock(world, i + 0, j + 0, k + 25, Blocks.log, 3);
		world.setBlockMetadataWithNotify(i + 0, j + 0, k + 25, 3, 2);
		setBlock(world, i + 0, j + 1, k + 23, Blocks.log, 3);
		world.setBlockMetadataWithNotify(i + 0, j + 1, k + 23, 3, 2);
		setBlock(world, i + 0, j + 18, k + 24, Blocks.log, 3);
		world.setBlockMetadataWithNotify(i + 0, j + 18, k + 24, 3, 2);
		setBlock(world, i + 0, j + 18, k + 27, Blocks.log, 1);
		world.setBlockMetadataWithNotify(i + 0, j + 18, k + 27, 1, 2);
		setBlock(world, i + 0, j + 18, k + 28, Blocks.log, 1);
		world.setBlockMetadataWithNotify(i + 0, j + 18, k + 28, 1, 2);
		setBlock(world, i + 0, j + 18, k + 29, Blocks.log, 1);
		world.setBlockMetadataWithNotify(i + 0, j + 18, k + 29, 1, 2);
		setBlock(world, i + 0, j + 19, k + 20, Blocks.log, 1);
		world.setBlockMetadataWithNotify(i + 0, j + 19, k + 20, 1, 2);
		setBlock(world, i + 0, j + 19, k + 23, Blocks.log, 3);
		world.setBlockMetadataWithNotify(i + 0, j + 19, k + 23, 3, 2);
		setBlock(world, i + 0, j + 19, k + 24, Blocks.log, 3);
		world.setBlockMetadataWithNotify(i + 0, j + 19, k + 24, 3, 2);
		setBlock(world, i + 0, j + 19, k + 25, Blocks.log, 3);
		world.setBlockMetadataWithNotify(i + 0, j + 19, k + 25, 3, 2);
		setBlock(world, i + 0, j + 19, k + 27, Blocks.log, 1);
		world.setBlockMetadataWithNotify(i + 0, j + 19, k + 27, 1, 2);
		setBlock(world, i + 0, j + 19, k + 28, Blocks.log, 1);
		world.setBlockMetadataWithNotify(i + 0, j + 19, k + 28, 1, 2);
		setBlock(world, i + 0, j + 19, k + 29, Blocks.log, 1);
		world.setBlockMetadataWithNotify(i + 0, j + 19, k + 29, 1, 2);
		setBlock(world, i + 0, j + 19, k + 30, Blocks.log, 1);
		world.setBlockMetadataWithNotify(i + 0, j + 19, k + 30, 1, 2);
		setBlock(world, i + 0, j + 20, k + 17, Blocks.log, 3);
		world.setBlockMetadataWithNotify(i + 0, j + 20, k + 17, 3, 2);
		setBlock(world, i + 0, j + 20, k + 18, Blocks.log, 3);
		world.setBlockMetadataWithNotify(i + 0, j + 20, k + 18, 3, 2);
		setBlock(world, i + 0, j + 20, k + 19, Blocks.log, 1);
		world.setBlockMetadataWithNotify(i + 0, j + 20, k + 19, 1, 2);
		setBlock(world, i + 0, j + 20, k + 20, Blocks.log, 1);
		world.setBlockMetadataWithNotify(i + 0, j + 20, k + 20, 1, 2);
		setBlock(world, i + 0, j + 20, k + 21, Blocks.log, 1);
		world.setBlockMetadataWithNotify(i + 0, j + 20, k + 21, 1, 2);
		setBlock(world, i + 0, j + 20, k + 24, Blocks.log, 1);
		world.setBlockMetadataWithNotify(i + 0, j + 20, k + 24, 1, 2);
		setBlock(world, i + 0, j + 20, k + 25, Blocks.log, 1);
		world.setBlockMetadataWithNotify(i + 0, j + 20, k + 25, 1, 2);
		setBlock(world, i + 0, j + 20, k + 26, Blocks.log, 1);
		world.setBlockMetadataWithNotify(i + 0, j + 20, k + 26, 1, 2);
		setBlock(world, i + 0, j + 20, k + 27, Blocks.log, 1);
		world.setBlockMetadataWithNotify(i + 0, j + 20, k + 27, 1, 2);
		setBlock(world, i + 0, j + 20, k + 28, Blocks.log, 1);
		world.setBlockMetadataWithNotify(i + 0, j + 20, k + 28, 1, 2);
		setBlock(world, i + 0, j + 20, k + 29, Blocks.log, 1);
		world.setBlockMetadataWithNotify(i + 0, j + 20, k + 29, 1, 2);
		setBlock(world, i + 0, j + 20, k + 30, Blocks.log, 1);
		world.setBlockMetadataWithNotify(i + 0, j + 20, k + 30, 1, 2);
		setBlock(world, i + 0, j + 21, k + 17, Blocks.log, 3);
		world.setBlockMetadataWithNotify(i + 0, j + 21, k + 17, 3, 2);
		setBlock(world, i + 0, j + 21, k + 18, Blocks.log, 3);
		world.setBlockMetadataWithNotify(i + 0, j + 21, k + 18, 3, 2);
		setBlock(world, i + 0, j + 21, k + 19, Blocks.log, 1);
		world.setBlockMetadataWithNotify(i + 0, j + 21, k + 19, 1, 2);
		setBlock(world, i + 0, j + 21, k + 20, Blocks.log, 1);
		world.setBlockMetadataWithNotify(i + 0, j + 21, k + 20, 1, 2);
		setBlock(world, i + 0, j + 21, k + 25, Blocks.log, 1);
		world.setBlockMetadataWithNotify(i + 0, j + 21, k + 25, 1, 2);
		setBlock(world, i + 0, j + 21, k + 27, Blocks.log, 3);
		world.setBlockMetadataWithNotify(i + 0, j + 21, k + 27, 3, 2);
		setBlock(world, i + 0, j + 21, k + 28, Blocks.log, 1);
		world.setBlockMetadataWithNotify(i + 0, j + 21, k + 28, 1, 2);
		setBlock(world, i + 0, j + 21, k + 29, Blocks.log, 1);
		world.setBlockMetadataWithNotify(i + 0, j + 21, k + 29, 1, 2);
		setBlock(world, i + 0, j + 21, k + 30, Blocks.log, 1);
		world.setBlockMetadataWithNotify(i + 0, j + 21, k + 30, 1, 2);
		setBlock(world, i + 0, j + 21, k + 31, Blocks.log, 1);
		world.setBlockMetadataWithNotify(i + 0, j + 21, k + 31, 1, 2);
		setBlock(world, i + 0, j + 22, k + 17, Blocks.log, 3);
		world.setBlockMetadataWithNotify(i + 0, j + 22, k + 17, 3, 2);
		setBlock(world, i + 0, j + 22, k + 18, Blocks.log, 3);
		world.setBlockMetadataWithNotify(i + 0, j + 22, k + 18, 3, 2);
		setBlock(world, i + 0, j + 22, k + 19, Blocks.log, 3);
		world.setBlockMetadataWithNotify(i + 0, j + 22, k + 19, 3, 2);
		setBlock(world, i + 0, j + 22, k + 27, Blocks.log, 3);
		world.setBlockMetadataWithNotify(i + 0, j + 22, k + 27, 3, 2);
		setBlock(world, i + 0, j + 22, k + 30, Blocks.log, 1);
		world.setBlockMetadataWithNotify(i + 0, j + 22, k + 30, 1, 2);
		setBlock(world, i + 0, j + 27, k + 28, Blocks.leaves, 15);
		world.setBlockMetadataWithNotify(i + 0, j + 27, k + 28, 15, 2);
		setBlock(world, i + 0, j + 27, k + 29, Blocks.leaves, 15);
		world.setBlockMetadataWithNotify(i + 0, j + 27, k + 29, 15, 2);
		setBlock(world, i + 0, j + 27, k + 30, Blocks.log, 3);
		world.setBlockMetadataWithNotify(i + 0, j + 27, k + 30, 3, 2);
		setBlock(world, i + 0, j + 27, k + 31, Blocks.leaves, 15);
		world.setBlockMetadataWithNotify(i + 0, j + 27, k + 31, 15, 2);
		setBlock(world, i + 0, j + 28, k + 28, Blocks.leaves, 15);
		world.setBlockMetadataWithNotify(i + 0, j + 28, k + 28, 15, 2);
		setBlock(world, i + 0, j + 28, k + 29, Blocks.leaves, 15);
		world.setBlockMetadataWithNotify(i + 0, j + 28, k + 29, 15, 2);
		setBlock(world, i + 0, j + 28, k + 30, Blocks.leaves, 15);
		world.setBlockMetadataWithNotify(i + 0, j + 28, k + 30, 15, 2);
		setBlock(world, i + 0, j + 28, k + 31, Blocks.leaves, 15);
		world.setBlockMetadataWithNotify(i + 0, j + 28, k + 31, 15, 2);
		setBlock(world, i + 0, j + 29, k + 8, Blocks.leaves, 7);
		world.setBlockMetadataWithNotify(i + 0, j + 29, k + 8, 7, 2);
		setBlock(world, i + 0, j + 29, k + 9, Blocks.leaves, 7);
		world.setBlockMetadataWithNotify(i + 0, j + 29, k + 9, 7, 2);
		setBlock(world, i + 0, j + 29, k + 10, Blocks.leaves, 7);
		world.setBlockMetadataWithNotify(i + 0, j + 29, k + 10, 7, 2);
		setBlock(world, i + 0, j + 29, k + 11, Blocks.leaves, 7);
		world.setBlockMetadataWithNotify(i + 0, j + 29, k + 11, 7, 2);
		setBlock(world, i + 0, j + 29, k + 12, Blocks.leaves, 7);
		world.setBlockMetadataWithNotify(i + 0, j + 29, k + 12, 7, 2);
		setBlock(world, i + 0, j + 29, k + 29, Blocks.log, 3);
		world.setBlockMetadataWithNotify(i + 0, j + 29, k + 29, 3, 2);
		setBlock(world, i + 0, j + 29, k + 30, Blocks.leaves, 15);
		world.setBlockMetadataWithNotify(i + 0, j + 29, k + 30, 15, 2);
		setBlock(world, i + 0, j + 29, k + 31, Blocks.leaves, 15);
		world.setBlockMetadataWithNotify(i + 0, j + 29, k + 31, 15, 2);
		setBlock(world, i + 0, j + 30, k + 9, Blocks.leaves, 7);
		world.setBlockMetadataWithNotify(i + 0, j + 30, k + 9, 7, 2);
		setBlock(world, i + 0, j + 30, k + 10, Blocks.leaves, 7);
		world.setBlockMetadataWithNotify(i + 0, j + 30, k + 10, 7, 2);
		setBlock(world, i + 0, j + 30, k + 11, Blocks.leaves, 7);
		world.setBlockMetadataWithNotify(i + 0, j + 30, k + 11, 7, 2);
		setBlock(world, i + 0, j + 30, k + 30, Blocks.leaves, 15);
		world.setBlockMetadataWithNotify(i + 0, j + 30, k + 30, 15, 2);
		setBlock(world, i + 0, j + 31, k + 10, Blocks.leaves, 7);
		world.setBlockMetadataWithNotify(i + 0, j + 31, k + 10, 7, 2);
		setBlock(world, i + 0, j + 31, k + 18, Blocks.log, 3);
		world.setBlockMetadataWithNotify(i + 0, j + 31, k + 18, 3, 2);
		setBlock(world, i + 0, j + 32, k + 21, Blocks.leaves, 7);
		world.setBlockMetadataWithNotify(i + 0, j + 32, k + 21, 7, 2);
		setBlock(world, i + 0, j + 32, k + 22, Blocks.leaves, 7);
		world.setBlockMetadataWithNotify(i + 0, j + 32, k + 22, 7, 2);
		setBlock(world, i + 0, j + 32, k + 23, Blocks.leaves, 7);
		world.setBlockMetadataWithNotify(i + 0, j + 32, k + 23, 7, 2);
		setBlock(world, i + 0, j + 33, k + 17, Blocks.log, 3);
		world.setBlockMetadataWithNotify(i + 0, j + 33, k + 17, 3, 2);
		setBlock(world, i + 0, j + 33, k + 22, Blocks.leaves, 7);
		world.setBlockMetadataWithNotify(i + 0, j + 33, k + 22, 7, 2);
		setBlock(world, i + 0, j + 34, k + 24, Blocks.log, 3);
		world.setBlockMetadataWithNotify(i + 0, j + 34, k + 24, 3, 2);
		setBlock(world, i + 0, j + 35, k + 20, Blocks.log, 3);
		world.setBlockMetadataWithNotify(i + 0, j + 35, k + 20, 3, 2);
		setBlock(world, i + 0, j + 35, k + 21, Blocks.leaves, 7);
		world.setBlockMetadataWithNotify(i + 0, j + 35, k + 21, 7, 2);
		setBlock(world, i + 0, j + 35, k + 22, Blocks.leaves, 7);
		world.setBlockMetadataWithNotify(i + 0, j + 35, k + 22, 7, 2);
		setBlock(world, i + 0, j + 35, k + 23, Blocks.leaves, 7);
		world.setBlockMetadataWithNotify(i + 0, j + 35, k + 23, 7, 2);
		setBlock(world, i + 0, j + 35, k + 24, Blocks.leaves, 7);
		world.setBlockMetadataWithNotify(i + 0, j + 35, k + 24, 7, 2);
		setBlock(world, i + 0, j + 35, k + 25, Blocks.leaves, 7);
		world.setBlockMetadataWithNotify(i + 0, j + 35, k + 25, 7, 2);
		setBlock(world, i + 0, j + 36, k + 22, Blocks.log, 3);
		world.setBlockMetadataWithNotify(i + 0, j + 36, k + 22, 3, 2);
		setBlock(world, i + 0, j + 36, k + 23, Blocks.leaves, 7);
		world.setBlockMetadataWithNotify(i + 0, j + 36, k + 23, 7, 2);
		setBlock(world, i + 0, j + 36, k + 24, Blocks.leaves, 7);
		world.setBlockMetadataWithNotify(i + 0, j + 36, k + 24, 7, 2);
		setBlock(world, i + 0, j + 37, k + 19, Blocks.log, 3);
		world.setBlockMetadataWithNotify(i + 0, j + 37, k + 19, 3, 2);
		setBlock(world, i + 0, j + 37, k + 23, Blocks.leaves, 7);
		world.setBlockMetadataWithNotify(i + 0, j + 37, k + 23, 7, 2);
		setBlock(world, i + 0, j + 38, k + 15, Blocks.leaves, 7);
		world.setBlockMetadataWithNotify(i + 0, j + 38, k + 15, 7, 2);
		setBlock(world, i + 0, j + 38, k + 16, Blocks.leaves, 7);
		world.setBlockMetadataWithNotify(i + 0, j + 38, k + 16, 7, 2);
		setBlock(world, i + 0, j + 38, k + 17, Blocks.log, 3);
		world.setBlockMetadataWithNotify(i + 0, j + 38, k + 17, 3, 2);
		setBlock(world, i + 0, j + 38, k + 18, Blocks.leaves, 7);
		world.setBlockMetadataWithNotify(i + 0, j + 38, k + 18, 7, 2);
		setBlock(world, i + 0, j + 38, k + 19, Blocks.leaves, 7);
		world.setBlockMetadataWithNotify(i + 0, j + 38, k + 19, 7, 2);
		setBlock(world, i + 0, j + 38, k + 25, Blocks.leaves, 7);
		world.setBlockMetadataWithNotify(i + 0, j + 38, k + 25, 7, 2);
		setBlock(world, i + 0, j + 38, k + 26, Blocks.leaves, 7);
		world.setBlockMetadataWithNotify(i + 0, j + 38, k + 26, 7, 2);
		setBlock(world, i + 0, j + 38, k + 27, Blocks.log, 3);
		world.setBlockMetadataWithNotify(i + 0, j + 38, k + 27, 3, 2);
		setBlock(world, i + 0, j + 38, k + 28, Blocks.leaves, 7);
		world.setBlockMetadataWithNotify(i + 0, j + 38, k + 28, 7, 2);
		setBlock(world, i + 0, j + 38, k + 29, Blocks.leaves, 7);
		world.setBlockMetadataWithNotify(i + 0, j + 38, k + 29, 7, 2);
		setBlock(world, i + 0, j + 39, k + 15, Blocks.leaves, 7);
		world.setBlockMetadataWithNotify(i + 0, j + 39, k + 15, 7, 2);
		setBlock(world, i + 0, j + 39, k + 16, Blocks.leaves, 7);
		world.setBlockMetadataWithNotify(i + 0, j + 39, k + 16, 7, 2);
		setBlock(world, i + 0, j + 39, k + 17, Blocks.leaves, 7);
		world.setBlockMetadataWithNotify(i + 0, j + 39, k + 17, 7, 2);
		setBlock(world, i + 0, j + 39, k + 18, Blocks.leaves, 7);
		world.setBlockMetadataWithNotify(i + 0, j + 39, k + 18, 7, 2);
		setBlock(world, i + 0, j + 39, k + 19, Blocks.leaves, 7);
		world.setBlockMetadataWithNotify(i + 0, j + 39, k + 19, 7, 2);
		setBlock(world, i + 0, j + 39, k + 25, Blocks.leaves, 7);
		world.setBlockMetadataWithNotify(i + 0, j + 39, k + 25, 7, 2);
		setBlock(world, i + 0, j + 39, k + 26, Blocks.leaves, 7);
		world.setBlockMetadataWithNotify(i + 0, j + 39, k + 26, 7, 2);
		setBlock(world, i + 0, j + 39, k + 27, Blocks.leaves, 7);
		world.setBlockMetadataWithNotify(i + 0, j + 39, k + 27, 7, 2);
		setBlock(world, i + 0, j + 39, k + 28, Blocks.leaves, 7);
		world.setBlockMetadataWithNotify(i + 0, j + 39, k + 28, 7, 2);
		setBlock(world, i + 0, j + 39, k + 29, Blocks.leaves, 7);
		world.setBlockMetadataWithNotify(i + 0, j + 39, k + 29, 7, 2);
		setBlock(world, i + 0, j + 40, k + 16, Blocks.leaves, 7);
		world.setBlockMetadataWithNotify(i + 0, j + 40, k + 16, 7, 2);
		setBlock(world, i + 0, j + 40, k + 17, Blocks.leaves, 7);
		world.setBlockMetadataWithNotify(i + 0, j + 40, k + 17, 7, 2);
		setBlock(world, i + 0, j + 40, k + 18, Blocks.leaves, 7);
		world.setBlockMetadataWithNotify(i + 0, j + 40, k + 18, 7, 2);
		setBlock(world, i + 0, j + 40, k + 19, Blocks.log, 3);
		world.setBlockMetadataWithNotify(i + 0, j + 40, k + 19, 3, 2);
		setBlock(world, i + 0, j + 40, k + 26, Blocks.leaves, 7);
		world.setBlockMetadataWithNotify(i + 0, j + 40, k + 26, 7, 2);
		setBlock(world, i + 0, j + 40, k + 27, Blocks.log, 3);
		world.setBlockMetadataWithNotify(i + 0, j + 40, k + 27, 3, 2);
		setBlock(world, i + 0, j + 40, k + 28, Blocks.leaves, 7);
		world.setBlockMetadataWithNotify(i + 0, j + 40, k + 28, 7, 2);
		setBlock(world, i + 0, j + 41, k + 14, Blocks.leaves, 7);
		world.setBlockMetadataWithNotify(i + 0, j + 41, k + 14, 7, 2);
		setBlock(world, i + 0, j + 41, k + 15, Blocks.leaves, 7);
		world.setBlockMetadataWithNotify(i + 0, j + 41, k + 15, 7, 2);
		setBlock(world, i + 0, j + 41, k + 16, Blocks.leaves, 7);
		world.setBlockMetadataWithNotify(i + 0, j + 41, k + 16, 7, 2);
		setBlock(world, i + 0, j + 41, k + 17, Blocks.leaves, 7);
		world.setBlockMetadataWithNotify(i + 0, j + 41, k + 17, 7, 2);
		setBlock(world, i + 0, j + 41, k + 27, Blocks.leaves, 7);
		world.setBlockMetadataWithNotify(i + 0, j + 41, k + 27, 7, 2);
		setBlock(world, i + 0, j + 42, k + 15, Blocks.leaves, 7);
		world.setBlockMetadataWithNotify(i + 0, j + 42, k + 15, 7, 2);
		setBlock(world, i + 0, j + 43, k + 30, Blocks.leaves, 7);
		world.setBlockMetadataWithNotify(i + 0, j + 43, k + 30, 7, 2);
		setBlock(world, i + 0, j + 43, k + 31, Blocks.leaves, 7);
		world.setBlockMetadataWithNotify(i + 0, j + 43, k + 31, 7, 2);
		setBlock(world, i + 0, j + 44, k + 31, Blocks.leaves, 7);
		world.setBlockMetadataWithNotify(i + 0, j + 44, k + 31, 7, 2);
		setBlock(world, i + 0, j + 46, k + 13, Blocks.leaves, 7);
		world.setBlockMetadataWithNotify(i + 0, j + 46, k + 13, 7, 2);
		setBlock(world, i + 0, j + 46, k + 14, Blocks.leaves, 7);
		world.setBlockMetadataWithNotify(i + 0, j + 46, k + 14, 7, 2);
		setBlock(world, i + 0, j + 46, k + 15, Blocks.leaves, 7);
		world.setBlockMetadataWithNotify(i + 0, j + 46, k + 15, 7, 2);
		setBlock(world, i + 0, j + 46, k + 26, Blocks.log, 3);
		world.setBlockMetadataWithNotify(i + 0, j + 46, k + 26, 3, 2);
		setBlock(world, i + 0, j + 47, k + 14, Blocks.leaves, 7);
		world.setBlockMetadataWithNotify(i + 0, j + 47, k + 14, 7, 2);
		setBlock(world, i + 0, j + 47, k + 20, Blocks.log, 3);
		world.setBlockMetadataWithNotify(i + 0, j + 47, k + 20, 3, 2);
		setBlock(world, i + 0, j + 47, k + 22, Blocks.leaves, 7);
		world.setBlockMetadataWithNotify(i + 0, j + 47, k + 22, 7, 2);
		setBlock(world, i + 0, j + 47, k + 23, Blocks.leaves, 7);
		world.setBlockMetadataWithNotify(i + 0, j + 47, k + 23, 7, 2);
		setBlock(world, i + 0, j + 47, k + 24, Blocks.leaves, 7);
		world.setBlockMetadataWithNotify(i + 0, j + 47, k + 24, 7, 2);
		setBlock(world, i + 0, j + 47, k + 25, Blocks.leaves, 7);
		world.setBlockMetadataWithNotify(i + 0, j + 47, k + 25, 7, 2);
		setBlock(world, i + 0, j + 47, k + 26, Blocks.leaves, 7);
		world.setBlockMetadataWithNotify(i + 0, j + 47, k + 26, 7, 2);
		setBlock(world, i + 0, j + 48, k + 23, Blocks.leaves, 7);
		world.setBlockMetadataWithNotify(i + 0, j + 48, k + 23, 7, 2);
		setBlock(world, i + 0, j + 48, k + 24, Blocks.leaves, 7);
		world.setBlockMetadataWithNotify(i + 0, j + 48, k + 24, 7, 2);
		setBlock(world, i + 0, j + 48, k + 25, Blocks.leaves, 7);
		world.setBlockMetadataWithNotify(i + 0, j + 48, k + 25, 7, 2);
		setBlock(world, i + 0, j + 49, k + 14, Blocks.leaves, 7);
		world.setBlockMetadataWithNotify(i + 0, j + 49, k + 14, 7, 2);
		setBlock(world, i + 0, j + 49, k + 15, Blocks.leaves, 7);
		world.setBlockMetadataWithNotify(i + 0, j + 49, k + 15, 7, 2);
		setBlock(world, i + 0, j + 49, k + 16, Blocks.leaves, 7);
		world.setBlockMetadataWithNotify(i + 0, j + 49, k + 16, 7, 2);
		setBlock(world, i + 0, j + 49, k + 17, Blocks.leaves, 7);
		world.setBlockMetadataWithNotify(i + 0, j + 49, k + 17, 7, 2);
		setBlock(world, i + 0, j + 49, k + 18, Blocks.leaves, 7);
		world.setBlockMetadataWithNotify(i + 0, j + 49, k + 18, 7, 2);
		setBlock(world, i + 0, j + 49, k + 24, Blocks.leaves, 7);
		world.setBlockMetadataWithNotify(i + 0, j + 49, k + 24, 7, 2);
		setBlock(world, i + 0, j + 49, k + 29, Blocks.leaves, 7);
		world.setBlockMetadataWithNotify(i + 0, j + 49, k + 29, 7, 2);
		setBlock(world, i + 0, j + 49, k + 30, Blocks.leaves, 7);
		world.setBlockMetadataWithNotify(i + 0, j + 49, k + 30, 7, 2);
		setBlock(world, i + 0, j + 49, k + 31, Blocks.leaves, 7);
		world.setBlockMetadataWithNotify(i + 0, j + 49, k + 31, 7, 2);
		setBlock(world, i + 0, j + 50, k + 15, Blocks.leaves, 7);
		world.setBlockMetadataWithNotify(i + 0, j + 50, k + 15, 7, 2);
		setBlock(world, i + 0, j + 50, k + 16, Blocks.leaves, 7);
		world.setBlockMetadataWithNotify(i + 0, j + 50, k + 16, 7, 2);
		setBlock(world, i + 0, j + 50, k + 17, Blocks.leaves, 7);
		world.setBlockMetadataWithNotify(i + 0, j + 50, k + 17, 7, 2);
		setBlock(world, i + 0, j + 50, k + 30, Blocks.leaves, 7);
		world.setBlockMetadataWithNotify(i + 0, j + 50, k + 30, 7, 2);
		setBlock(world, i + 0, j + 51, k + 16, Blocks.leaves, 7);
		world.setBlockMetadataWithNotify(i + 0, j + 51, k + 16, 7, 2);
		setBlock(world, i + 0, j + 52, k + 23, Blocks.leaves, 7);
		world.setBlockMetadataWithNotify(i + 0, j + 52, k + 23, 7, 2);
		setBlock(world, i + 0, j + 52, k + 24, Blocks.leaves, 7);
		world.setBlockMetadataWithNotify(i + 0, j + 52, k + 24, 7, 2);
		setBlock(world, i + 0, j + 52, k + 25, Blocks.leaves, 7);
		world.setBlockMetadataWithNotify(i + 0, j + 52, k + 25, 7, 2);
		setBlock(world, i + 0, j + 52, k + 26, Blocks.leaves, 7);
		world.setBlockMetadataWithNotify(i + 0, j + 52, k + 26, 7, 2);
		setBlock(world, i + 0, j + 52, k + 27, Blocks.leaves, 7);
		world.setBlockMetadataWithNotify(i + 0, j + 52, k + 27, 7, 2);
		setBlock(world, i + 0, j + 53, k + 24, Blocks.leaves, 7);
		world.setBlockMetadataWithNotify(i + 0, j + 53, k + 24, 7, 2);
		setBlock(world, i + 0, j + 53, k + 25, Blocks.leaves, 7);
		world.setBlockMetadataWithNotify(i + 0, j + 53, k + 25, 7, 2);
		setBlock(world, i + 0, j + 53, k + 26, Blocks.leaves, 7);
		world.setBlockMetadataWithNotify(i + 0, j + 53, k + 26, 7, 2);
		setBlock(world, i + 0, j + 54, k + 18, Blocks.leaves, 7);
		world.setBlockMetadataWithNotify(i + 0, j + 54, k + 18, 7, 2);
		setBlock(world, i + 0, j + 54, k + 19, Blocks.leaves, 7);
		world.setBlockMetadataWithNotify(i + 0, j + 54, k + 19, 7, 2);
		setBlock(world, i + 0, j + 54, k + 20, Blocks.leaves, 7);
		world.setBlockMetadataWithNotify(i + 0, j + 54, k + 20, 7, 2);
		setBlock(world, i + 0, j + 54, k + 21, Blocks.leaves, 7);
		world.setBlockMetadataWithNotify(i + 0, j + 54, k + 21, 7, 2);
		setBlock(world, i + 0, j + 54, k + 22, Blocks.leaves, 7);
		world.setBlockMetadataWithNotify(i + 0, j + 54, k + 22, 7, 2);
		setBlock(world, i + 0, j + 54, k + 24, Blocks.leaves, 7);
		world.setBlockMetadataWithNotify(i + 0, j + 54, k + 24, 7, 2);
		setBlock(world, i + 0, j + 54, k + 25, Blocks.leaves, 7);
		world.setBlockMetadataWithNotify(i + 0, j + 54, k + 25, 7, 2);
		setBlock(world, i + 0, j + 54, k + 26, Blocks.leaves, 7);
		world.setBlockMetadataWithNotify(i + 0, j + 54, k + 26, 7, 2);
		setBlock(world, i + 0, j + 55, k + 19, Blocks.leaves, 7);
		world.setBlockMetadataWithNotify(i + 0, j + 55, k + 19, 7, 2);
		setBlock(world, i + 0, j + 55, k + 20, Blocks.leaves, 7);
		world.setBlockMetadataWithNotify(i + 0, j + 55, k + 20, 7, 2);
		setBlock(world, i + 0, j + 55, k + 21, Blocks.leaves, 7);
		world.setBlockMetadataWithNotify(i + 0, j + 55, k + 21, 7, 2);
		setBlock(world, i + 0, j + 55, k + 25, Blocks.leaves, 7);
		world.setBlockMetadataWithNotify(i + 0, j + 55, k + 25, 7, 2);
		setBlock(world, i + 0, j + 55, k + 27, Blocks.leaves, 7);
		world.setBlockMetadataWithNotify(i + 0, j + 55, k + 27, 7, 2);
		setBlock(world, i + 0, j + 55, k + 28, Blocks.leaves, 7);
		world.setBlockMetadataWithNotify(i + 0, j + 55, k + 28, 7, 2);
		setBlock(world, i + 0, j + 55, k + 29, Blocks.leaves, 7);
		world.setBlockMetadataWithNotify(i + 0, j + 55, k + 29, 7, 2);
		setBlock(world, i + 0, j + 55, k + 30, Blocks.leaves, 7);
		world.setBlockMetadataWithNotify(i + 0, j + 55, k + 30, 7, 2);
		setBlock(world, i + 0, j + 55, k + 31, Blocks.leaves, 7);
		world.setBlockMetadataWithNotify(i + 0, j + 55, k + 31, 7, 2);
		setBlock(world, i + 0, j + 56, k + 20, Blocks.leaves, 7);
		world.setBlockMetadataWithNotify(i + 0, j + 56, k + 20, 7, 2);
		setBlock(world, i + 0, j + 56, k + 28, Blocks.leaves, 7);
		world.setBlockMetadataWithNotify(i + 0, j + 56, k + 28, 7, 2);
		setBlock(world, i + 0, j + 56, k + 29, Blocks.leaves, 7);
		world.setBlockMetadataWithNotify(i + 0, j + 56, k + 29, 7, 2);
		setBlock(world, i + 0, j + 56, k + 30, Blocks.leaves, 7);
		world.setBlockMetadataWithNotify(i + 0, j + 56, k + 30, 7, 2);
		setBlock(world, i + 0, j + 57, k + 29, Blocks.leaves, 7);
		world.setBlockMetadataWithNotify(i + 0, j + 57, k + 29, 7, 2);
		setBlock(world, i + 1, j + 0, k + 20, Blocks.log, 3);
		world.setBlockMetadataWithNotify(i + 1, j + 0, k + 20, 3, 2);
		setBlock(world, i + 1, j + 0, k + 21, Blocks.log, 3);
		world.setBlockMetadataWithNotify(i + 1, j + 0, k + 21, 3, 2);
		setBlock(world, i + 1, j + 0, k + 22, Blocks.log, 3);
		world.setBlockMetadataWithNotify(i + 1, j + 0, k + 22, 3, 2);
		setBlock(world, i + 1, j + 0, k + 23, Blocks.log, 3);
		world.setBlockMetadataWithNotify(i + 1, j + 0, k + 23, 3, 2);
		setBlock(world, i + 1, j + 0, k + 24, Blocks.log, 3);
		world.setBlockMetadataWithNotify(i + 1, j + 0, k + 24, 3, 2);
		setBlock(world, i + 1, j + 0, k + 25, Blocks.log, 3);
		world.setBlockMetadataWithNotify(i + 1, j + 0, k + 25, 3, 2);
		setBlock(world, i + 1, j + 0, k + 26, Blocks.log, 3);
		world.setBlockMetadataWithNotify(i + 1, j + 0, k + 26, 3, 2);
		setBlock(world, i + 1, j + 0, k + 27, Blocks.log, 3);
		world.setBlockMetadataWithNotify(i + 1, j + 0, k + 27, 3, 2);
		setBlock(world, i + 1, j + 1, k + 21, Blocks.log, 3);
		world.setBlockMetadataWithNotify(i + 1, j + 1, k + 21, 3, 2);
		setBlock(world, i + 1, j + 1, k + 22, Blocks.log, 3);
		world.setBlockMetadataWithNotify(i + 1, j + 1, k + 22, 3, 2);
		setBlock(world, i + 1, j + 1, k + 23, Blocks.log, 3);
		world.setBlockMetadataWithNotify(i + 1, j + 1, k + 23, 3, 2);
		setBlock(world, i + 1, j + 1, k + 24, Blocks.log, 3);
		world.setBlockMetadataWithNotify(i + 1, j + 1, k + 24, 3, 2);
		setBlock(world, i + 1, j + 1, k + 25, Blocks.log, 3);
		world.setBlockMetadataWithNotify(i + 1, j + 1, k + 25, 3, 2);
		setBlock(world, i + 1, j + 18, k + 24, Blocks.log, 3);
		world.setBlockMetadataWithNotify(i + 1, j + 18, k + 24, 3, 2);
		setBlock(world, i + 1, j + 18, k + 28, Blocks.log, 1);
		world.setBlockMetadataWithNotify(i + 1, j + 18, k + 28, 1, 2);
		setBlock(world, i + 1, j + 18, k + 29, Blocks.log, 1);
		world.setBlockMetadataWithNotify(i + 1, j + 18, k + 29, 1, 2);
		setBlock(world, i + 1, j + 19, k + 20, Blocks.log, 1);
		world.setBlockMetadataWithNotify(i + 1, j + 19, k + 20, 1, 2);
		setBlock(world, i + 1, j + 19, k + 23, Blocks.log, 3);
		world.setBlockMetadataWithNotify(i + 1, j + 19, k + 23, 3, 2);
		setBlock(world, i + 1, j + 19, k + 24, Blocks.log, 3);
		world.setBlockMetadataWithNotify(i + 1, j + 19, k + 24, 3, 2);
		setBlock(world, i + 1, j + 19, k + 25, Blocks.log, 3);
		world.setBlockMetadataWithNotify(i + 1, j + 19, k + 25, 3, 2);
		setBlock(world, i + 1, j + 19, k + 27, Blocks.log, 1);
		world.setBlockMetadataWithNotify(i + 1, j + 19, k + 27, 1, 2);
		setBlock(world, i + 1, j + 19, k + 28, Blocks.log, 1);
		world.setBlockMetadataWithNotify(i + 1, j + 19, k + 28, 1, 2);
		setBlock(world, i + 1, j + 19, k + 29, Blocks.log, 1);
		world.setBlockMetadataWithNotify(i + 1, j + 19, k + 29, 1, 2);
		setBlock(world, i + 1, j + 20, k + 18, Blocks.log, 3);
		world.setBlockMetadataWithNotify(i + 1, j + 20, k + 18, 3, 2);
		setBlock(world, i + 1, j + 20, k + 19, Blocks.log, 1);
		world.setBlockMetadataWithNotify(i + 1, j + 20, k + 19, 1, 2);
		setBlock(world, i + 1, j + 20, k + 20, Blocks.log, 1);
		world.setBlockMetadataWithNotify(i + 1, j + 20, k + 20, 1, 2);
		setBlock(world, i + 1, j + 20, k + 21, Blocks.log, 1);
		world.setBlockMetadataWithNotify(i + 1, j + 20, k + 21, 1, 2);
		setBlock(world, i + 1, j + 20, k + 24, Blocks.log, 3);
		world.setBlockMetadataWithNotify(i + 1, j + 20, k + 24, 3, 2);
		setBlock(world, i + 1, j + 20, k + 26, Blocks.log, 3);
		world.setBlockMetadataWithNotify(i + 1, j + 20, k + 26, 3, 2);
		setBlock(world, i + 1, j + 20, k + 27, Blocks.log, 1);
		world.setBlockMetadataWithNotify(i + 1, j + 20, k + 27, 1, 2);
		setBlock(world, i + 1, j + 20, k + 28, Blocks.log, 1);
		world.setBlockMetadataWithNotify(i + 1, j + 20, k + 28, 1, 2);
		setBlock(world, i + 1, j + 20, k + 29, Blocks.log, 1);
		world.setBlockMetadataWithNotify(i + 1, j + 20, k + 29, 1, 2);
		setBlock(world, i + 1, j + 20, k + 30, Blocks.log, 1);
		world.setBlockMetadataWithNotify(i + 1, j + 20, k + 30, 1, 2);
		setBlock(world, i + 1, j + 21, k + 18, Blocks.log, 3);
		world.setBlockMetadataWithNotify(i + 1, j + 21, k + 18, 3, 2);
		setBlock(world, i + 1, j + 21, k + 19, Blocks.log, 3);
		world.setBlockMetadataWithNotify(i + 1, j + 21, k + 19, 3, 2);
		setBlock(world, i + 1, j + 21, k + 20, Blocks.log, 3);
		world.setBlockMetadataWithNotify(i + 1, j + 21, k + 20, 3, 2);
		setBlock(world, i + 1, j + 21, k + 22, Blocks.log, 1);
		world.setBlockMetadataWithNotify(i + 1, j + 21, k + 22, 1, 2);
		setBlock(world, i + 1, j + 21, k + 27, Blocks.log, 3);
		world.setBlockMetadataWithNotify(i + 1, j + 21, k + 27, 3, 2);
		setBlock(world, i + 1, j + 21, k + 28, Blocks.log, 3);
		world.setBlockMetadataWithNotify(i + 1, j + 21, k + 28, 3, 2);
		setBlock(world, i + 1, j + 21, k + 29, Blocks.log, 1);
		world.setBlockMetadataWithNotify(i + 1, j + 21, k + 29, 1, 2);
		setBlock(world, i + 1, j + 21, k + 30, Blocks.log, 1);
		world.setBlockMetadataWithNotify(i + 1, j + 21, k + 30, 1, 2);
		setBlock(world, i + 1, j + 21, k + 31, Blocks.log, 1);
		world.setBlockMetadataWithNotify(i + 1, j + 21, k + 31, 1, 2);
		setBlock(world, i + 1, j + 22, k + 18, Blocks.log, 3);
		world.setBlockMetadataWithNotify(i + 1, j + 22, k + 18, 3, 2);
		setBlock(world, i + 1, j + 22, k + 19, Blocks.log, 3);
		world.setBlockMetadataWithNotify(i + 1, j + 22, k + 19, 3, 2);
		setBlock(world, i + 1, j + 22, k + 20, Blocks.log, 3);
		world.setBlockMetadataWithNotify(i + 1, j + 22, k + 20, 3, 2);
		setBlock(world, i + 1, j + 22, k + 21, Blocks.log, 1);
		world.setBlockMetadataWithNotify(i + 1, j + 22, k + 21, 1, 2);
		setBlock(world, i + 1, j + 22, k + 22, Blocks.log, 1);
		world.setBlockMetadataWithNotify(i + 1, j + 22, k + 22, 1, 2);
		setBlock(world, i + 1, j + 22, k + 23, Blocks.log, 1);
		world.setBlockMetadataWithNotify(i + 1, j + 22, k + 23, 1, 2);
		setBlock(world, i + 1, j + 22, k + 30, Blocks.log, 1);
		world.setBlockMetadataWithNotify(i + 1, j + 22, k + 30, 1, 2);
		setBlock(world, i + 1, j + 22, k + 31, Blocks.log, 1);
		world.setBlockMetadataWithNotify(i + 1, j + 22, k + 31, 1, 2);
		setBlock(world, i + 1, j + 23, k + 22, Blocks.log, 1);
		world.setBlockMetadataWithNotify(i + 1, j + 23, k + 22, 1, 2);
		setBlock(world, i + 1, j + 26, k + 30, Blocks.log, 3);
		world.setBlockMetadataWithNotify(i + 1, j + 26, k + 30, 3, 2);
		setBlock(world, i + 1, j + 27, k + 28, Blocks.leaves, 15);
		world.setBlockMetadataWithNotify(i + 1, j + 27, k + 28, 15, 2);
		setBlock(world, i + 1, j + 27, k + 29, Blocks.leaves, 15);
		world.setBlockMetadataWithNotify(i + 1, j + 27, k + 29, 15, 2);
		setBlock(world, i + 1, j + 27, k + 30, Blocks.leaves, 15);
		world.setBlockMetadataWithNotify(i + 1, j + 27, k + 30, 15, 2);
		setBlock(world, i + 1, j + 27, k + 31, Blocks.leaves, 15);
		world.setBlockMetadataWithNotify(i + 1, j + 27, k + 31, 15, 2);
		setBlock(world, i + 1, j + 28, k + 11, Blocks.log, 3);
		world.setBlockMetadataWithNotify(i + 1, j + 28, k + 11, 3, 2);
		setBlock(world, i + 1, j + 28, k + 12, Blocks.log, 3);
		world.setBlockMetadataWithNotify(i + 1, j + 28, k + 12, 3, 2);
		setBlock(world, i + 1, j + 28, k + 29, Blocks.leaves, 15);
		world.setBlockMetadataWithNotify(i + 1, j + 28, k + 29, 15, 2);
		setBlock(world, i + 1, j + 28, k + 30, Blocks.leaves, 15);
		world.setBlockMetadataWithNotify(i + 1, j + 28, k + 30, 15, 2);
		setBlock(world, i + 1, j + 28, k + 31, Blocks.leaves, 15);
		world.setBlockMetadataWithNotify(i + 1, j + 28, k + 31, 15, 2);
		setBlock(world, i + 1, j + 29, k + 8, Blocks.leaves, 7);
		world.setBlockMetadataWithNotify(i + 1, j + 29, k + 8, 7, 2);
		setBlock(world, i + 1, j + 29, k + 9, Blocks.leaves, 7);
		world.setBlockMetadataWithNotify(i + 1, j + 29, k + 9, 7, 2);
		setBlock(world, i + 1, j + 29, k + 10, Blocks.log, 3);
		world.setBlockMetadataWithNotify(i + 1, j + 29, k + 10, 3, 2);
		setBlock(world, i + 1, j + 29, k + 11, Blocks.leaves, 7);
		world.setBlockMetadataWithNotify(i + 1, j + 29, k + 11, 7, 2);
		setBlock(world, i + 1, j + 29, k + 12, Blocks.leaves, 7);
		world.setBlockMetadataWithNotify(i + 1, j + 29, k + 12, 7, 2);
		setBlock(world, i + 1, j + 29, k + 29, Blocks.log, 3);
		world.setBlockMetadataWithNotify(i + 1, j + 29, k + 29, 3, 2);
		setBlock(world, i + 1, j + 29, k + 30, Blocks.leaves, 15);
		world.setBlockMetadataWithNotify(i + 1, j + 29, k + 30, 15, 2);
		setBlock(world, i + 1, j + 30, k + 8, Blocks.leaves, 7);
		world.setBlockMetadataWithNotify(i + 1, j + 30, k + 8, 7, 2);
		setBlock(world, i + 1, j + 30, k + 9, Blocks.leaves, 7);
		world.setBlockMetadataWithNotify(i + 1, j + 30, k + 9, 7, 2);
		setBlock(world, i + 1, j + 30, k + 10, Blocks.leaves, 7);
		world.setBlockMetadataWithNotify(i + 1, j + 30, k + 10, 7, 2);
		setBlock(world, i + 1, j + 30, k + 11, Blocks.leaves, 7);
		world.setBlockMetadataWithNotify(i + 1, j + 30, k + 11, 7, 2);
		setBlock(world, i + 1, j + 30, k + 12, Blocks.leaves, 7);
		world.setBlockMetadataWithNotify(i + 1, j + 30, k + 12, 7, 2);
		setBlock(world, i + 1, j + 30, k + 15, Blocks.leaves, 7);
		world.setBlockMetadataWithNotify(i + 1, j + 30, k + 15, 7, 2);
		setBlock(world, i + 1, j + 30, k + 16, Blocks.leaves, 7);
		world.setBlockMetadataWithNotify(i + 1, j + 30, k + 16, 7, 2);
		setBlock(world, i + 1, j + 30, k + 17, Blocks.leaves, 7);
		world.setBlockMetadataWithNotify(i + 1, j + 30, k + 17, 7, 2);
		setBlock(world, i + 1, j + 31, k + 9, Blocks.leaves, 7);
		world.setBlockMetadataWithNotify(i + 1, j + 31, k + 9, 7, 2);
		setBlock(world, i + 1, j + 31, k + 10, Blocks.leaves, 7);
		world.setBlockMetadataWithNotify(i + 1, j + 31, k + 10, 7, 2);
		setBlock(world, i + 1, j + 31, k + 11, Blocks.leaves, 7);
		world.setBlockMetadataWithNotify(i + 1, j + 31, k + 11, 7, 2);
		setBlock(world, i + 1, j + 31, k + 16, Blocks.leaves, 7);
		world.setBlockMetadataWithNotify(i + 1, j + 31, k + 16, 7, 2);
		setBlock(world, i + 1, j + 31, k + 19, Blocks.log, 3);
		world.setBlockMetadataWithNotify(i + 1, j + 31, k + 19, 3, 2);
		setBlock(world, i + 1, j + 32, k + 10, Blocks.leaves, 7);
		world.setBlockMetadataWithNotify(i + 1, j + 32, k + 10, 7, 2);
		setBlock(world, i + 1, j + 32, k + 20, Blocks.leaves, 7);
		world.setBlockMetadataWithNotify(i + 1, j + 32, k + 20, 7, 2);
		setBlock(world, i + 1, j + 32, k + 21, Blocks.leaves, 7);
		world.setBlockMetadataWithNotify(i + 1, j + 32, k + 21, 7, 2);
		setBlock(world, i + 1, j + 32, k + 22, Blocks.leaves, 7);
		world.setBlockMetadataWithNotify(i + 1, j + 32, k + 22, 7, 2);
		setBlock(world, i + 1, j + 32, k + 23, Blocks.leaves, 7);
		world.setBlockMetadataWithNotify(i + 1, j + 32, k + 23, 7, 2);
		setBlock(world, i + 1, j + 32, k + 24, Blocks.leaves, 7);
		world.setBlockMetadataWithNotify(i + 1, j + 32, k + 24, 7, 2);
		setBlock(world, i + 1, j + 33, k + 18, Blocks.log, 3);
		world.setBlockMetadataWithNotify(i + 1, j + 33, k + 18, 3, 2);
		setBlock(world, i + 1, j + 33, k + 21, Blocks.leaves, 7);
		world.setBlockMetadataWithNotify(i + 1, j + 33, k + 21, 7, 2);
		setBlock(world, i + 1, j + 33, k + 22, Blocks.leaves, 7);
		world.setBlockMetadataWithNotify(i + 1, j + 33, k + 22, 7, 2);
		setBlock(world, i + 1, j + 33, k + 23, Blocks.leaves, 7);
		world.setBlockMetadataWithNotify(i + 1, j + 33, k + 23, 7, 2);
		setBlock(world, i + 1, j + 34, k + 22, Blocks.leaves, 7);
		world.setBlockMetadataWithNotify(i + 1, j + 34, k + 22, 7, 2);
		setBlock(world, i + 1, j + 34, k + 24, Blocks.log, 3);
		world.setBlockMetadataWithNotify(i + 1, j + 34, k + 24, 3, 2);
		setBlock(world, i + 1, j + 35, k + 21, Blocks.log, 3);
		world.setBlockMetadataWithNotify(i + 1, j + 35, k + 21, 3, 2);
		setBlock(world, i + 1, j + 35, k + 22, Blocks.leaves, 7);
		world.setBlockMetadataWithNotify(i + 1, j + 35, k + 22, 7, 2);
		setBlock(world, i + 1, j + 35, k + 23, Blocks.leaves, 7);
		world.setBlockMetadataWithNotify(i + 1, j + 35, k + 23, 7, 2);
		setBlock(world, i + 1, j + 35, k + 24, Blocks.leaves, 7);
		world.setBlockMetadataWithNotify(i + 1, j + 35, k + 24, 7, 2);
		setBlock(world, i + 1, j + 36, k + 23, Blocks.log, 3);
		world.setBlockMetadataWithNotify(i + 1, j + 36, k + 23, 3, 2);
		setBlock(world, i + 1, j + 37, k + 18, Blocks.log, 3);
		world.setBlockMetadataWithNotify(i + 1, j + 37, k + 18, 3, 2);
		setBlock(world, i + 1, j + 37, k + 19, Blocks.log, 3);
		world.setBlockMetadataWithNotify(i + 1, j + 37, k + 19, 3, 2);
		setBlock(world, i + 1, j + 37, k + 27, Blocks.log, 3);
		world.setBlockMetadataWithNotify(i + 1, j + 37, k + 27, 3, 2);
		setBlock(world, i + 1, j + 38, k + 15, Blocks.leaves, 7);
		world.setBlockMetadataWithNotify(i + 1, j + 38, k + 15, 7, 2);
		setBlock(world, i + 1, j + 38, k + 16, Blocks.leaves, 7);
		world.setBlockMetadataWithNotify(i + 1, j + 38, k + 16, 7, 2);
		setBlock(world, i + 1, j + 38, k + 17, Blocks.leaves, 7);
		world.setBlockMetadataWithNotify(i + 1, j + 38, k + 17, 7, 2);
		setBlock(world, i + 1, j + 38, k + 18, Blocks.leaves, 7);
		world.setBlockMetadataWithNotify(i + 1, j + 38, k + 18, 7, 2);
		setBlock(world, i + 1, j + 38, k + 19, Blocks.leaves, 7);
		world.setBlockMetadataWithNotify(i + 1, j + 38, k + 19, 7, 2);
		setBlock(world, i + 1, j + 38, k + 25, Blocks.leaves, 7);
		world.setBlockMetadataWithNotify(i + 1, j + 38, k + 25, 7, 2);
		setBlock(world, i + 1, j + 38, k + 26, Blocks.leaves, 7);
		world.setBlockMetadataWithNotify(i + 1, j + 38, k + 26, 7, 2);
		setBlock(world, i + 1, j + 38, k + 27, Blocks.log, 3);
		world.setBlockMetadataWithNotify(i + 1, j + 38, k + 27, 3, 2);
		setBlock(world, i + 1, j + 38, k + 28, Blocks.leaves, 7);
		world.setBlockMetadataWithNotify(i + 1, j + 38, k + 28, 7, 2);
		setBlock(world, i + 1, j + 38, k + 29, Blocks.leaves, 7);
		world.setBlockMetadataWithNotify(i + 1, j + 38, k + 29, 7, 2);
		setBlock(world, i + 1, j + 38, k + 30, Blocks.leaves, 7);
		world.setBlockMetadataWithNotify(i + 1, j + 38, k + 30, 7, 2);
		setBlock(world, i + 1, j + 38, k + 31, Blocks.leaves, 7);
		world.setBlockMetadataWithNotify(i + 1, j + 38, k + 31, 7, 2);
		setBlock(world, i + 1, j + 39, k + 16, Blocks.leaves, 7);
		world.setBlockMetadataWithNotify(i + 1, j + 39, k + 16, 7, 2);
		setBlock(world, i + 1, j + 39, k + 17, Blocks.leaves, 7);
		world.setBlockMetadataWithNotify(i + 1, j + 39, k + 17, 7, 2);
		setBlock(world, i + 1, j + 39, k + 18, Blocks.leaves, 7);
		world.setBlockMetadataWithNotify(i + 1, j + 39, k + 18, 7, 2);
		setBlock(world, i + 1, j + 39, k + 26, Blocks.leaves, 7);
		world.setBlockMetadataWithNotify(i + 1, j + 39, k + 26, 7, 2);
		setBlock(world, i + 1, j + 39, k + 27, Blocks.leaves, 7);
		world.setBlockMetadataWithNotify(i + 1, j + 39, k + 27, 7, 2);
		setBlock(world, i + 1, j + 39, k + 28, Blocks.leaves, 7);
		world.setBlockMetadataWithNotify(i + 1, j + 39, k + 28, 7, 2);
		setBlock(world, i + 1, j + 39, k + 31, Blocks.leaves, 7);
		world.setBlockMetadataWithNotify(i + 1, j + 39, k + 31, 7, 2);
		setBlock(world, i + 1, j + 40, k + 17, Blocks.leaves, 7);
		world.setBlockMetadataWithNotify(i + 1, j + 40, k + 17, 7, 2);
		setBlock(world, i + 1, j + 40, k + 20, Blocks.log, 3);
		world.setBlockMetadataWithNotify(i + 1, j + 40, k + 20, 3, 2);
		setBlock(world, i + 1, j + 40, k + 27, Blocks.log, 3);
		world.setBlockMetadataWithNotify(i + 1, j + 40, k + 27, 3, 2);
		setBlock(world, i + 1, j + 41, k + 13, Blocks.leaves, 7);
		world.setBlockMetadataWithNotify(i + 1, j + 41, k + 13, 7, 2);
		setBlock(world, i + 1, j + 41, k + 14, Blocks.leaves, 7);
		world.setBlockMetadataWithNotify(i + 1, j + 41, k + 14, 7, 2);
		setBlock(world, i + 1, j + 41, k + 15, Blocks.leaves, 7);
		world.setBlockMetadataWithNotify(i + 1, j + 41, k + 15, 7, 2);
		setBlock(world, i + 1, j + 41, k + 16, Blocks.leaves, 7);
		world.setBlockMetadataWithNotify(i + 1, j + 41, k + 16, 7, 2);
		setBlock(world, i + 1, j + 41, k + 17, Blocks.leaves, 7);
		world.setBlockMetadataWithNotify(i + 1, j + 41, k + 17, 7, 2);
		setBlock(world, i + 1, j + 41, k + 31, Blocks.leaves, 7);
		world.setBlockMetadataWithNotify(i + 1, j + 41, k + 31, 7, 2);
		setBlock(world, i + 1, j + 42, k + 14, Blocks.leaves, 7);
		world.setBlockMetadataWithNotify(i + 1, j + 42, k + 14, 7, 2);
		setBlock(world, i + 1, j + 42, k + 15, Blocks.leaves, 7);
		world.setBlockMetadataWithNotify(i + 1, j + 42, k + 15, 7, 2);
		setBlock(world, i + 1, j + 42, k + 16, Blocks.leaves, 7);
		world.setBlockMetadataWithNotify(i + 1, j + 42, k + 16, 7, 2);
		setBlock(world, i + 1, j + 42, k + 31, Blocks.log, 3);
		world.setBlockMetadataWithNotify(i + 1, j + 42, k + 31, 3, 2);
		setBlock(world, i + 1, j + 43, k + 15, Blocks.leaves, 7);
		world.setBlockMetadataWithNotify(i + 1, j + 43, k + 15, 7, 2);
		setBlock(world, i + 1, j + 43, k + 30, Blocks.leaves, 7);
		world.setBlockMetadataWithNotify(i + 1, j + 43, k + 30, 7, 2);
		setBlock(world, i + 1, j + 43, k + 31, Blocks.leaves, 7);
		world.setBlockMetadataWithNotify(i + 1, j + 43, k + 31, 7, 2);
		setBlock(world, i + 1, j + 44, k + 13, Blocks.leaves, 7);
		world.setBlockMetadataWithNotify(i + 1, j + 44, k + 13, 7, 2);
		setBlock(world, i + 1, j + 44, k + 14, Blocks.leaves, 7);
		world.setBlockMetadataWithNotify(i + 1, j + 44, k + 14, 7, 2);
		setBlock(world, i + 1, j + 44, k + 15, Blocks.leaves, 7);
		world.setBlockMetadataWithNotify(i + 1, j + 44, k + 15, 7, 2);
		setBlock(world, i + 1, j + 44, k + 30, Blocks.leaves, 7);
		world.setBlockMetadataWithNotify(i + 1, j + 44, k + 30, 7, 2);
		setBlock(world, i + 1, j + 44, k + 31, Blocks.leaves, 7);
		world.setBlockMetadataWithNotify(i + 1, j + 44, k + 31, 7, 2);
		setBlock(world, i + 1, j + 45, k + 14, Blocks.leaves, 7);
		world.setBlockMetadataWithNotify(i + 1, j + 45, k + 14, 7, 2);
		setBlock(world, i + 1, j + 45, k + 31, Blocks.leaves, 7);
		world.setBlockMetadataWithNotify(i + 1, j + 45, k + 31, 7, 2);
		setBlock(world, i + 1, j + 46, k + 13, Blocks.leaves, 7);
		world.setBlockMetadataWithNotify(i + 1, j + 46, k + 13, 7, 2);
		setBlock(world, i + 1, j + 46, k + 14, Blocks.leaves, 7);
		world.setBlockMetadataWithNotify(i + 1, j + 46, k + 14, 7, 2);
		setBlock(world, i + 1, j + 46, k + 15, Blocks.leaves, 7);
		world.setBlockMetadataWithNotify(i + 1, j + 46, k + 15, 7, 2);
		setBlock(world, i + 1, j + 46, k + 26, Blocks.log, 3);
		world.setBlockMetadataWithNotify(i + 1, j + 46, k + 26, 3, 2);
		setBlock(world, i + 1, j + 47, k + 14, Blocks.leaves, 7);
		world.setBlockMetadataWithNotify(i + 1, j + 47, k + 14, 7, 2);
		setBlock(world, i + 1, j + 47, k + 19, Blocks.leaves, 7);
		world.setBlockMetadataWithNotify(i + 1, j + 47, k + 19, 7, 2);
		setBlock(world, i + 1, j + 47, k + 20, Blocks.log, 3);
		world.setBlockMetadataWithNotify(i + 1, j + 47, k + 20, 3, 2);
		setBlock(world, i + 1, j + 47, k + 21, Blocks.leaves, 7);
		world.setBlockMetadataWithNotify(i + 1, j + 47, k + 21, 7, 2);
		setBlock(world, i + 1, j + 47, k + 23, Blocks.leaves, 7);
		world.setBlockMetadataWithNotify(i + 1, j + 47, k + 23, 7, 2);
		setBlock(world, i + 1, j + 47, k + 24, Blocks.leaves, 7);
		world.setBlockMetadataWithNotify(i + 1, j + 47, k + 24, 7, 2);
		setBlock(world, i + 1, j + 47, k + 25, Blocks.leaves, 7);
		world.setBlockMetadataWithNotify(i + 1, j + 47, k + 25, 7, 2);
		setBlock(world, i + 1, j + 48, k + 20, Blocks.leaves, 7);
		world.setBlockMetadataWithNotify(i + 1, j + 48, k + 20, 7, 2);
		setBlock(world, i + 1, j + 48, k + 24, Blocks.leaves, 7);
		world.setBlockMetadataWithNotify(i + 1, j + 48, k + 24, 7, 2);
		setBlock(world, i + 1, j + 49, k + 15, Blocks.leaves, 7);
		world.setBlockMetadataWithNotify(i + 1, j + 49, k + 15, 7, 2);
		setBlock(world, i + 1, j + 49, k + 16, Blocks.leaves, 7);
		world.setBlockMetadataWithNotify(i + 1, j + 49, k + 16, 7, 2);
		setBlock(world, i + 1, j + 49, k + 17, Blocks.leaves, 7);
		world.setBlockMetadataWithNotify(i + 1, j + 49, k + 17, 7, 2);
		setBlock(world, i + 1, j + 49, k + 28, Blocks.leaves, 7);
		world.setBlockMetadataWithNotify(i + 1, j + 49, k + 28, 7, 2);
		setBlock(world, i + 1, j + 49, k + 29, Blocks.leaves, 7);
		world.setBlockMetadataWithNotify(i + 1, j + 49, k + 29, 7, 2);
		setBlock(world, i + 1, j + 49, k + 30, Blocks.leaves, 7);
		world.setBlockMetadataWithNotify(i + 1, j + 49, k + 30, 7, 2);
		setBlock(world, i + 1, j + 49, k + 31, Blocks.leaves, 7);
		world.setBlockMetadataWithNotify(i + 1, j + 49, k + 31, 7, 2);
		setBlock(world, i + 1, j + 50, k + 16, Blocks.leaves, 7);
		world.setBlockMetadataWithNotify(i + 1, j + 50, k + 16, 7, 2);
		setBlock(world, i + 1, j + 50, k + 29, Blocks.leaves, 7);
		world.setBlockMetadataWithNotify(i + 1, j + 50, k + 29, 7, 2);
		setBlock(world, i + 1, j + 50, k + 30, Blocks.leaves, 7);
		world.setBlockMetadataWithNotify(i + 1, j + 50, k + 30, 7, 2);
		setBlock(world, i + 1, j + 50, k + 31, Blocks.leaves, 7);
		world.setBlockMetadataWithNotify(i + 1, j + 50, k + 31, 7, 2);
		setBlock(world, i + 1, j + 51, k + 30, Blocks.leaves, 7);
		world.setBlockMetadataWithNotify(i + 1, j + 51, k + 30, 7, 2);
		setBlock(world, i + 1, j + 52, k + 23, Blocks.leaves, 7);
		world.setBlockMetadataWithNotify(i + 1, j + 52, k + 23, 7, 2);
		setBlock(world, i + 1, j + 52, k + 24, Blocks.leaves, 7);
		world.setBlockMetadataWithNotify(i + 1, j + 52, k + 24, 7, 2);
		setBlock(world, i + 1, j + 52, k + 25, Blocks.log, 3);
		world.setBlockMetadataWithNotify(i + 1, j + 52, k + 25, 3, 2);
		setBlock(world, i + 1, j + 52, k + 26, Blocks.leaves, 7);
		world.setBlockMetadataWithNotify(i + 1, j + 52, k + 26, 7, 2);
		setBlock(world, i + 1, j + 52, k + 27, Blocks.leaves, 7);
		world.setBlockMetadataWithNotify(i + 1, j + 52, k + 27, 7, 2);
		setBlock(world, i + 1, j + 53, k + 23, Blocks.leaves, 7);
		world.setBlockMetadataWithNotify(i + 1, j + 53, k + 23, 7, 2);
		setBlock(world, i + 1, j + 53, k + 24, Blocks.leaves, 7);
		world.setBlockMetadataWithNotify(i + 1, j + 53, k + 24, 7, 2);
		setBlock(world, i + 1, j + 53, k + 25, Blocks.leaves, 7);
		world.setBlockMetadataWithNotify(i + 1, j + 53, k + 25, 7, 2);
		setBlock(world, i + 1, j + 53, k + 26, Blocks.leaves, 7);
		world.setBlockMetadataWithNotify(i + 1, j + 53, k + 26, 7, 2);
		setBlock(world, i + 1, j + 53, k + 27, Blocks.leaves, 7);
		world.setBlockMetadataWithNotify(i + 1, j + 53, k + 27, 7, 2);
		setBlock(world, i + 1, j + 53, k + 29, Blocks.leaves, 7);
		world.setBlockMetadataWithNotify(i + 1, j + 53, k + 29, 7, 2);
		setBlock(world, i + 1, j + 53, k + 30, Blocks.leaves, 7);
		world.setBlockMetadataWithNotify(i + 1, j + 53, k + 30, 7, 2);
		setBlock(world, i + 1, j + 53, k + 31, Blocks.leaves, 7);
		world.setBlockMetadataWithNotify(i + 1, j + 53, k + 31, 7, 2);
		setBlock(world, i + 1, j + 54, k + 18, Blocks.leaves, 7);
		world.setBlockMetadataWithNotify(i + 1, j + 54, k + 18, 7, 2);
		setBlock(world, i + 1, j + 54, k + 19, Blocks.leaves, 7);
		world.setBlockMetadataWithNotify(i + 1, j + 54, k + 19, 7, 2);
		setBlock(world, i + 1, j + 54, k + 20, Blocks.log, 3);
		world.setBlockMetadataWithNotify(i + 1, j + 54, k + 20, 3, 2);
		setBlock(world, i + 1, j + 54, k + 21, Blocks.leaves, 7);
		world.setBlockMetadataWithNotify(i + 1, j + 54, k + 21, 7, 2);
		setBlock(world, i + 1, j + 54, k + 22, Blocks.leaves, 7);
		world.setBlockMetadataWithNotify(i + 1, j + 54, k + 22, 7, 2);
		setBlock(world, i + 1, j + 54, k + 24, Blocks.leaves, 7);
		world.setBlockMetadataWithNotify(i + 1, j + 54, k + 24, 7, 2);
		setBlock(world, i + 1, j + 54, k + 25, Blocks.leaves, 7);
		world.setBlockMetadataWithNotify(i + 1, j + 54, k + 25, 7, 2);
		setBlock(world, i + 1, j + 54, k + 26, Blocks.leaves, 7);
		world.setBlockMetadataWithNotify(i + 1, j + 54, k + 26, 7, 2);
		setBlock(world, i + 1, j + 54, k + 30, Blocks.leaves, 7);
		world.setBlockMetadataWithNotify(i + 1, j + 54, k + 30, 7, 2);
		setBlock(world, i + 1, j + 55, k + 18, Blocks.leaves, 7);
		world.setBlockMetadataWithNotify(i + 1, j + 55, k + 18, 7, 2);
		setBlock(world, i + 1, j + 55, k + 19, Blocks.leaves, 7);
		world.setBlockMetadataWithNotify(i + 1, j + 55, k + 19, 7, 2);
		setBlock(world, i + 1, j + 55, k + 20, Blocks.leaves, 7);
		world.setBlockMetadataWithNotify(i + 1, j + 55, k + 20, 7, 2);
		setBlock(world, i + 1, j + 55, k + 21, Blocks.leaves, 7);
		world.setBlockMetadataWithNotify(i + 1, j + 55, k + 21, 7, 2);
		setBlock(world, i + 1, j + 55, k + 22, Blocks.leaves, 7);
		world.setBlockMetadataWithNotify(i + 1, j + 55, k + 22, 7, 2);
		setBlock(world, i + 1, j + 55, k + 25, Blocks.leaves, 7);
		world.setBlockMetadataWithNotify(i + 1, j + 55, k + 25, 7, 2);
		setBlock(world, i + 1, j + 55, k + 27, Blocks.leaves, 7);
		world.setBlockMetadataWithNotify(i + 1, j + 55, k + 27, 7, 2);
		setBlock(world, i + 1, j + 55, k + 28, Blocks.leaves, 7);
		world.setBlockMetadataWithNotify(i + 1, j + 55, k + 28, 7, 2);
		setBlock(world, i + 1, j + 55, k + 29, Blocks.log, 3);
		world.setBlockMetadataWithNotify(i + 1, j + 55, k + 29, 3, 2);
		setBlock(world, i + 1, j + 55, k + 30, Blocks.leaves, 7);
		world.setBlockMetadataWithNotify(i + 1, j + 55, k + 30, 7, 2);
		setBlock(world, i + 1, j + 55, k + 31, Blocks.leaves, 7);
		world.setBlockMetadataWithNotify(i + 1, j + 55, k + 31, 7, 2);
		setBlock(world, i + 1, j + 56, k + 19, Blocks.leaves, 7);
		world.setBlockMetadataWithNotify(i + 1, j + 56, k + 19, 7, 2);
		setBlock(world, i + 1, j + 56, k + 20, Blocks.leaves, 7);
		world.setBlockMetadataWithNotify(i + 1, j + 56, k + 20, 7, 2);
		setBlock(world, i + 1, j + 56, k + 21, Blocks.leaves, 7);
		world.setBlockMetadataWithNotify(i + 1, j + 56, k + 21, 7, 2);
		setBlock(world, i + 1, j + 56, k + 27, Blocks.leaves, 7);
		world.setBlockMetadataWithNotify(i + 1, j + 56, k + 27, 7, 2);
		setBlock(world, i + 1, j + 56, k + 28, Blocks.leaves, 7);
		world.setBlockMetadataWithNotify(i + 1, j + 56, k + 28, 7, 2);
		setBlock(world, i + 1, j + 56, k + 29, Blocks.leaves, 7);
		world.setBlockMetadataWithNotify(i + 1, j + 56, k + 29, 7, 2);
		setBlock(world, i + 1, j + 56, k + 30, Blocks.leaves, 7);
		world.setBlockMetadataWithNotify(i + 1, j + 56, k + 30, 7, 2);
		setBlock(world, i + 1, j + 56, k + 31, Blocks.leaves, 7);
		world.setBlockMetadataWithNotify(i + 1, j + 56, k + 31, 7, 2);
		setBlock(world, i + 1, j + 57, k + 20, Blocks.leaves, 7);
		world.setBlockMetadataWithNotify(i + 1, j + 57, k + 20, 7, 2);
		setBlock(world, i + 1, j + 57, k + 28, Blocks.leaves, 7);
		world.setBlockMetadataWithNotify(i + 1, j + 57, k + 28, 7, 2);
		setBlock(world, i + 1, j + 57, k + 29, Blocks.leaves, 7);
		world.setBlockMetadataWithNotify(i + 1, j + 57, k + 29, 7, 2);
		setBlock(world, i + 1, j + 57, k + 30, Blocks.leaves, 7);
		world.setBlockMetadataWithNotify(i + 1, j + 57, k + 30, 7, 2);
		setBlock(world, i + 1, j + 58, k + 19, Blocks.leaves, 7);
		world.setBlockMetadataWithNotify(i + 1, j + 58, k + 19, 7, 2);
		setBlock(world, i + 1, j + 58, k + 20, Blocks.leaves, 7);
		world.setBlockMetadataWithNotify(i + 1, j + 58, k + 20, 7, 2);
		setBlock(world, i + 1, j + 58, k + 21, Blocks.leaves, 7);
		world.setBlockMetadataWithNotify(i + 1, j + 58, k + 21, 7, 2);
		setBlock(world, i + 1, j + 58, k + 29, Blocks.leaves, 7);
		world.setBlockMetadataWithNotify(i + 1, j + 58, k + 29, 7, 2);
		setBlock(world, i + 1, j + 59, k + 20, Blocks.leaves, 7);
		world.setBlockMetadataWithNotify(i + 1, j + 59, k + 20, 7, 2);
		setBlock(world, i + 1, j + 63, k + 26, Blocks.leaves, 7);
		world.setBlockMetadataWithNotify(i + 1, j + 63, k + 26, 7, 2);
		setBlock(world, i + 1, j + 63, k + 27, Blocks.leaves, 7);
		world.setBlockMetadataWithNotify(i + 1, j + 63, k + 27, 7, 2);
		setBlock(world, i + 1, j + 63, k + 28, Blocks.leaves, 7);
		world.setBlockMetadataWithNotify(i + 1, j + 63, k + 28, 7, 2);
		setBlock(world, i + 1, j + 64, k + 27, Blocks.leaves, 7);
		world.setBlockMetadataWithNotify(i + 1, j + 64, k + 27, 7, 2);
		setBlock(world, i + 2, j + 0, k + 19, Blocks.log, 3);
		world.setBlockMetadataWithNotify(i + 2, j + 0, k + 19, 3, 2);
		setBlock(world, i + 2, j + 0, k + 20, Blocks.log, 3);
		world.setBlockMetadataWithNotify(i + 2, j + 0, k + 20, 3, 2);
		setBlock(world, i + 2, j + 0, k + 21, Blocks.log, 3);
		world.setBlockMetadataWithNotify(i + 2, j + 0, k + 21, 3, 2);
		setBlock(world, i + 2, j + 0, k + 22, Blocks.log, 3);
		world.setBlockMetadataWithNotify(i + 2, j + 0, k + 22, 3, 2);
		setBlock(world, i + 2, j + 0, k + 23, Blocks.log, 3);
		world.setBlockMetadataWithNotify(i + 2, j + 0, k + 23, 3, 2);
		setBlock(world, i + 2, j + 0, k + 24, Blocks.log, 3);
		world.setBlockMetadataWithNotify(i + 2, j + 0, k + 24, 3, 2);
		setBlock(world, i + 2, j + 0, k + 25, Blocks.log, 3);
		world.setBlockMetadataWithNotify(i + 2, j + 0, k + 25, 3, 2);
		setBlock(world, i + 2, j + 0, k + 26, Blocks.log, 3);
		world.setBlockMetadataWithNotify(i + 2, j + 0, k + 26, 3, 2);
		setBlock(world, i + 2, j + 0, k + 27, Blocks.log, 3);
		world.setBlockMetadataWithNotify(i + 2, j + 0, k + 27, 3, 2);
		setBlock(world, i + 2, j + 0, k + 28, Blocks.log, 3);
		world.setBlockMetadataWithNotify(i + 2, j + 0, k + 28, 3, 2);
		setBlock(world, i + 2, j + 0, k + 29, Blocks.log, 3);
		world.setBlockMetadataWithNotify(i + 2, j + 0, k + 29, 3, 2);
		setBlock(world, i + 2, j + 1, k + 20, Blocks.log, 3);
		world.setBlockMetadataWithNotify(i + 2, j + 1, k + 20, 3, 2);
		setBlock(world, i + 2, j + 1, k + 21, Blocks.log, 3);
		world.setBlockMetadataWithNotify(i + 2, j + 1, k + 21, 3, 2);
		setBlock(world, i + 2, j + 1, k + 22, Blocks.log, 3);
		world.setBlockMetadataWithNotify(i + 2, j + 1, k + 22, 3, 2);
		setBlock(world, i + 2, j + 1, k + 23, Blocks.log, 3);
		world.setBlockMetadataWithNotify(i + 2, j + 1, k + 23, 3, 2);
		setBlock(world, i + 2, j + 1, k + 24, Blocks.log, 3);
		world.setBlockMetadataWithNotify(i + 2, j + 1, k + 24, 3, 2);
		setBlock(world, i + 2, j + 1, k + 25, Blocks.log, 3);
		world.setBlockMetadataWithNotify(i + 2, j + 1, k + 25, 3, 2);
		setBlock(world, i + 2, j + 1, k + 26, Blocks.log, 3);
		world.setBlockMetadataWithNotify(i + 2, j + 1, k + 26, 3, 2);
		setBlock(world, i + 2, j + 1, k + 27, Blocks.log, 3);
		world.setBlockMetadataWithNotify(i + 2, j + 1, k + 27, 3, 2);
		setBlock(world, i + 2, j + 2, k + 23, Blocks.log, 3);
		world.setBlockMetadataWithNotify(i + 2, j + 2, k + 23, 3, 2);
		setBlock(world, i + 2, j + 2, k + 24, Blocks.log, 3);
		world.setBlockMetadataWithNotify(i + 2, j + 2, k + 24, 3, 2);
		setBlock(world, i + 2, j + 2, k + 25, Blocks.log, 3);
		world.setBlockMetadataWithNotify(i + 2, j + 2, k + 25, 3, 2);
		setBlock(world, i + 2, j + 18, k + 24, Blocks.log, 3);
		world.setBlockMetadataWithNotify(i + 2, j + 18, k + 24, 3, 2);
		setBlock(world, i + 2, j + 18, k + 28, Blocks.log, 1);
		world.setBlockMetadataWithNotify(i + 2, j + 18, k + 28, 1, 2);
		setBlock(world, i + 2, j + 19, k + 23, Blocks.log, 3);
		world.setBlockMetadataWithNotify(i + 2, j + 19, k + 23, 3, 2);
		setBlock(world, i + 2, j + 19, k + 24, Blocks.log, 3);
		world.setBlockMetadataWithNotify(i + 2, j + 19, k + 24, 3, 2);
		setBlock(world, i + 2, j + 19, k + 25, Blocks.log, 3);
		world.setBlockMetadataWithNotify(i + 2, j + 19, k + 25, 3, 2);
		setBlock(world, i + 2, j + 19, k + 27, Blocks.log, 1);
		world.setBlockMetadataWithNotify(i + 2, j + 19, k + 27, 1, 2);
		setBlock(world, i + 2, j + 19, k + 28, Blocks.log, 1);
		world.setBlockMetadataWithNotify(i + 2, j + 19, k + 28, 1, 2);
		setBlock(world, i + 2, j + 19, k + 29, Blocks.log, 1);
		world.setBlockMetadataWithNotify(i + 2, j + 19, k + 29, 1, 2);
		setBlock(world, i + 2, j + 20, k + 19, Blocks.log, 3);
		world.setBlockMetadataWithNotify(i + 2, j + 20, k + 19, 3, 2);
		setBlock(world, i + 2, j + 20, k + 20, Blocks.log, 3);
		world.setBlockMetadataWithNotify(i + 2, j + 20, k + 20, 3, 2);
		setBlock(world, i + 2, j + 20, k + 21, Blocks.log, 3);
		world.setBlockMetadataWithNotify(i + 2, j + 20, k + 21, 3, 2);
		setBlock(world, i + 2, j + 20, k + 24, Blocks.log, 3);
		world.setBlockMetadataWithNotify(i + 2, j + 20, k + 24, 3, 2);
		setBlock(world, i + 2, j + 20, k + 26, Blocks.log, 3);
		world.setBlockMetadataWithNotify(i + 2, j + 20, k + 26, 3, 2);
		setBlock(world, i + 2, j + 20, k + 27, Blocks.log, 3);
		world.setBlockMetadataWithNotify(i + 2, j + 20, k + 27, 3, 2);
		setBlock(world, i + 2, j + 20, k + 28, Blocks.log, 1);
		world.setBlockMetadataWithNotify(i + 2, j + 20, k + 28, 1, 2);
		setBlock(world, i + 2, j + 20, k + 30, Blocks.log, 1);
		world.setBlockMetadataWithNotify(i + 2, j + 20, k + 30, 1, 2);
		setBlock(world, i + 2, j + 21, k + 19, Blocks.log, 3);
		world.setBlockMetadataWithNotify(i + 2, j + 21, k + 19, 3, 2);
		setBlock(world, i + 2, j + 21, k + 20, Blocks.log, 3);
		world.setBlockMetadataWithNotify(i + 2, j + 21, k + 20, 3, 2);
		setBlock(world, i + 2, j + 21, k + 21, Blocks.log, 1);
		world.setBlockMetadataWithNotify(i + 2, j + 21, k + 21, 1, 2);
		setBlock(world, i + 2, j + 21, k + 22, Blocks.log, 1);
		world.setBlockMetadataWithNotify(i + 2, j + 21, k + 22, 1, 2);
		setBlock(world, i + 2, j + 21, k + 26, Blocks.log, 3);
		world.setBlockMetadataWithNotify(i + 2, j + 21, k + 26, 3, 2);
		setBlock(world, i + 2, j + 21, k + 27, Blocks.log, 3);
		world.setBlockMetadataWithNotify(i + 2, j + 21, k + 27, 3, 2);
		setBlock(world, i + 2, j + 21, k + 28, Blocks.log, 3);
		world.setBlockMetadataWithNotify(i + 2, j + 21, k + 28, 3, 2);
		setBlock(world, i + 2, j + 21, k + 31, Blocks.log, 1);
		world.setBlockMetadataWithNotify(i + 2, j + 21, k + 31, 1, 2);
		setBlock(world, i + 2, j + 22, k + 19, Blocks.log, 3);
		world.setBlockMetadataWithNotify(i + 2, j + 22, k + 19, 3, 2);
		setBlock(world, i + 2, j + 22, k + 20, Blocks.log, 3);
		world.setBlockMetadataWithNotify(i + 2, j + 22, k + 20, 3, 2);
		setBlock(world, i + 2, j + 22, k + 21, Blocks.log, 1);
		world.setBlockMetadataWithNotify(i + 2, j + 22, k + 21, 1, 2);
		setBlock(world, i + 2, j + 22, k + 22, Blocks.log, 1);
		world.setBlockMetadataWithNotify(i + 2, j + 22, k + 22, 1, 2);
		setBlock(world, i + 2, j + 22, k + 23, Blocks.log, 1);
		world.setBlockMetadataWithNotify(i + 2, j + 22, k + 23, 1, 2);
		setBlock(world, i + 2, j + 22, k + 27, Blocks.log, 3);
		world.setBlockMetadataWithNotify(i + 2, j + 22, k + 27, 3, 2);
		setBlock(world, i + 2, j + 22, k + 30, Blocks.log, 1);
		world.setBlockMetadataWithNotify(i + 2, j + 22, k + 30, 1, 2);
		setBlock(world, i + 2, j + 23, k + 21, Blocks.log, 1);
		world.setBlockMetadataWithNotify(i + 2, j + 23, k + 21, 1, 2);
		setBlock(world, i + 2, j + 23, k + 22, Blocks.log, 1);
		world.setBlockMetadataWithNotify(i + 2, j + 23, k + 22, 1, 2);
		setBlock(world, i + 2, j + 23, k + 23, Blocks.log, 1);
		world.setBlockMetadataWithNotify(i + 2, j + 23, k + 23, 1, 2);
		setBlock(world, i + 2, j + 26, k + 29, Blocks.log, 3);
		world.setBlockMetadataWithNotify(i + 2, j + 26, k + 29, 3, 2);
		setBlock(world, i + 2, j + 27, k + 29, Blocks.leaves, 15);
		world.setBlockMetadataWithNotify(i + 2, j + 27, k + 29, 15, 2);
		setBlock(world, i + 2, j + 27, k + 30, Blocks.leaves, 15);
		world.setBlockMetadataWithNotify(i + 2, j + 27, k + 30, 15, 2);
		setBlock(world, i + 2, j + 27, k + 31, Blocks.leaves, 15);
		world.setBlockMetadataWithNotify(i + 2, j + 27, k + 31, 15, 2);
		setBlock(world, i + 2, j + 28, k + 13, Blocks.log, 3);
		world.setBlockMetadataWithNotify(i + 2, j + 28, k + 13, 3, 2);
		setBlock(world, i + 2, j + 28, k + 14, Blocks.log, 3);
		world.setBlockMetadataWithNotify(i + 2, j + 28, k + 14, 3, 2);
		setBlock(world, i + 2, j + 28, k + 30, Blocks.leaves, 15);
		world.setBlockMetadataWithNotify(i + 2, j + 28, k + 30, 15, 2);
		setBlock(world, i + 2, j + 29, k + 8, Blocks.leaves, 7);
		world.setBlockMetadataWithNotify(i + 2, j + 29, k + 8, 7, 2);
		setBlock(world, i + 2, j + 29, k + 9, Blocks.leaves, 7);
		world.setBlockMetadataWithNotify(i + 2, j + 29, k + 9, 7, 2);
		setBlock(world, i + 2, j + 29, k + 10, Blocks.leaves, 7);
		world.setBlockMetadataWithNotify(i + 2, j + 29, k + 10, 7, 2);
		setBlock(world, i + 2, j + 29, k + 11, Blocks.leaves, 7);
		world.setBlockMetadataWithNotify(i + 2, j + 29, k + 11, 7, 2);
		setBlock(world, i + 2, j + 29, k + 12, Blocks.leaves, 7);
		world.setBlockMetadataWithNotify(i + 2, j + 29, k + 12, 7, 2);
		setBlock(world, i + 2, j + 29, k + 28, Blocks.log, 3);
		world.setBlockMetadataWithNotify(i + 2, j + 29, k + 28, 3, 2);
		setBlock(world, i + 2, j + 30, k + 9, Blocks.leaves, 7);
		world.setBlockMetadataWithNotify(i + 2, j + 30, k + 9, 7, 2);
		setBlock(world, i + 2, j + 30, k + 10, Blocks.leaves, 7);
		world.setBlockMetadataWithNotify(i + 2, j + 30, k + 10, 7, 2);
		setBlock(world, i + 2, j + 30, k + 11, Blocks.leaves, 7);
		world.setBlockMetadataWithNotify(i + 2, j + 30, k + 11, 7, 2);
		setBlock(world, i + 2, j + 30, k + 14, Blocks.leaves, 7);
		world.setBlockMetadataWithNotify(i + 2, j + 30, k + 14, 7, 2);
		setBlock(world, i + 2, j + 30, k + 15, Blocks.leaves, 7);
		world.setBlockMetadataWithNotify(i + 2, j + 30, k + 15, 7, 2);
		setBlock(world, i + 2, j + 30, k + 16, Blocks.leaves, 7);
		world.setBlockMetadataWithNotify(i + 2, j + 30, k + 16, 7, 2);
		setBlock(world, i + 2, j + 30, k + 17, Blocks.leaves, 7);
		world.setBlockMetadataWithNotify(i + 2, j + 30, k + 17, 7, 2);
		setBlock(world, i + 2, j + 30, k + 18, Blocks.leaves, 7);
		world.setBlockMetadataWithNotify(i + 2, j + 30, k + 18, 7, 2);
		setBlock(world, i + 2, j + 31, k + 10, Blocks.leaves, 7);
		world.setBlockMetadataWithNotify(i + 2, j + 31, k + 10, 7, 2);
		setBlock(world, i + 2, j + 31, k + 15, Blocks.leaves, 7);
		world.setBlockMetadataWithNotify(i + 2, j + 31, k + 15, 7, 2);
		setBlock(world, i + 2, j + 31, k + 16, Blocks.leaves, 7);
		world.setBlockMetadataWithNotify(i + 2, j + 31, k + 16, 7, 2);
		setBlock(world, i + 2, j + 31, k + 17, Blocks.leaves, 7);
		world.setBlockMetadataWithNotify(i + 2, j + 31, k + 17, 7, 2);
		setBlock(world, i + 2, j + 31, k + 20, Blocks.log, 3);
		world.setBlockMetadataWithNotify(i + 2, j + 31, k + 20, 3, 2);
		setBlock(world, i + 2, j + 32, k + 16, Blocks.leaves, 7);
		world.setBlockMetadataWithNotify(i + 2, j + 32, k + 16, 7, 2);
		setBlock(world, i + 2, j + 32, k + 20, Blocks.leaves, 7);
		world.setBlockMetadataWithNotify(i + 2, j + 32, k + 20, 7, 2);
		setBlock(world, i + 2, j + 32, k + 21, Blocks.leaves, 7);
		world.setBlockMetadataWithNotify(i + 2, j + 32, k + 21, 7, 2);
		setBlock(world, i + 2, j + 32, k + 22, Blocks.log, 3);
		world.setBlockMetadataWithNotify(i + 2, j + 32, k + 22, 3, 2);
		setBlock(world, i + 2, j + 32, k + 23, Blocks.leaves, 7);
		world.setBlockMetadataWithNotify(i + 2, j + 32, k + 23, 7, 2);
		setBlock(world, i + 2, j + 32, k + 24, Blocks.leaves, 7);
		world.setBlockMetadataWithNotify(i + 2, j + 32, k + 24, 7, 2);
		setBlock(world, i + 2, j + 33, k + 19, Blocks.log, 3);
		world.setBlockMetadataWithNotify(i + 2, j + 33, k + 19, 3, 2);
		setBlock(world, i + 2, j + 33, k + 20, Blocks.leaves, 7);
		world.setBlockMetadataWithNotify(i + 2, j + 33, k + 20, 7, 2);
		setBlock(world, i + 2, j + 33, k + 21, Blocks.leaves, 7);
		world.setBlockMetadataWithNotify(i + 2, j + 33, k + 21, 7, 2);
		setBlock(world, i + 2, j + 33, k + 22, Blocks.leaves, 7);
		world.setBlockMetadataWithNotify(i + 2, j + 33, k + 22, 7, 2);
		setBlock(world, i + 2, j + 33, k + 23, Blocks.leaves, 7);
		world.setBlockMetadataWithNotify(i + 2, j + 33, k + 23, 7, 2);
		setBlock(world, i + 2, j + 33, k + 24, Blocks.leaves, 7);
		world.setBlockMetadataWithNotify(i + 2, j + 33, k + 24, 7, 2);
		setBlock(world, i + 2, j + 34, k + 21, Blocks.leaves, 7);
		world.setBlockMetadataWithNotify(i + 2, j + 34, k + 21, 7, 2);
		setBlock(world, i + 2, j + 34, k + 22, Blocks.leaves, 7);
		world.setBlockMetadataWithNotify(i + 2, j + 34, k + 22, 7, 2);
		setBlock(world, i + 2, j + 34, k + 23, Blocks.leaves, 7);
		world.setBlockMetadataWithNotify(i + 2, j + 34, k + 23, 7, 2);
		setBlock(world, i + 2, j + 34, k + 24, Blocks.log, 3);
		world.setBlockMetadataWithNotify(i + 2, j + 34, k + 24, 3, 2);
		setBlock(world, i + 2, j + 35, k + 21, Blocks.log, 3);
		world.setBlockMetadataWithNotify(i + 2, j + 35, k + 21, 3, 2);
		setBlock(world, i + 2, j + 35, k + 22, Blocks.leaves, 7);
		world.setBlockMetadataWithNotify(i + 2, j + 35, k + 22, 7, 2);
		setBlock(world, i + 2, j + 36, k + 23, Blocks.log, 3);
		world.setBlockMetadataWithNotify(i + 2, j + 36, k + 23, 3, 2);
		setBlock(world, i + 2, j + 37, k + 19, Blocks.log, 3);
		world.setBlockMetadataWithNotify(i + 2, j + 37, k + 19, 3, 2);
		setBlock(world, i + 2, j + 37, k + 20, Blocks.log, 3);
		world.setBlockMetadataWithNotify(i + 2, j + 37, k + 20, 3, 2);
		setBlock(world, i + 2, j + 37, k + 27, Blocks.log, 3);
		world.setBlockMetadataWithNotify(i + 2, j + 37, k + 27, 3, 2);
		setBlock(world, i + 2, j + 38, k + 16, Blocks.leaves, 7);
		world.setBlockMetadataWithNotify(i + 2, j + 38, k + 16, 7, 2);
		setBlock(world, i + 2, j + 38, k + 17, Blocks.leaves, 7);
		world.setBlockMetadataWithNotify(i + 2, j + 38, k + 17, 7, 2);
		setBlock(world, i + 2, j + 38, k + 18, Blocks.leaves, 7);
		world.setBlockMetadataWithNotify(i + 2, j + 38, k + 18, 7, 2);
		setBlock(world, i + 2, j + 38, k + 26, Blocks.log, 3);
		world.setBlockMetadataWithNotify(i + 2, j + 38, k + 26, 3, 2);
		setBlock(world, i + 2, j + 38, k + 27, Blocks.leaves, 7);
		world.setBlockMetadataWithNotify(i + 2, j + 38, k + 27, 7, 2);
		setBlock(world, i + 2, j + 38, k + 28, Blocks.leaves, 7);
		world.setBlockMetadataWithNotify(i + 2, j + 38, k + 28, 7, 2);
		setBlock(world, i + 2, j + 38, k + 29, Blocks.leaves, 7);
		world.setBlockMetadataWithNotify(i + 2, j + 38, k + 29, 7, 2);
		setBlock(world, i + 2, j + 38, k + 30, Blocks.leaves, 7);
		world.setBlockMetadataWithNotify(i + 2, j + 38, k + 30, 7, 2);
		setBlock(world, i + 2, j + 38, k + 31, Blocks.leaves, 7);
		world.setBlockMetadataWithNotify(i + 2, j + 38, k + 31, 7, 2);
		setBlock(world, i + 2, j + 39, k + 17, Blocks.leaves, 7);
		world.setBlockMetadataWithNotify(i + 2, j + 39, k + 17, 7, 2);
		setBlock(world, i + 2, j + 39, k + 27, Blocks.leaves, 7);
		world.setBlockMetadataWithNotify(i + 2, j + 39, k + 27, 7, 2);
		setBlock(world, i + 2, j + 39, k + 30, Blocks.leaves, 7);
		world.setBlockMetadataWithNotify(i + 2, j + 39, k + 30, 7, 2);
		setBlock(world, i + 2, j + 39, k + 31, Blocks.leaves, 7);
		world.setBlockMetadataWithNotify(i + 2, j + 39, k + 31, 7, 2);
		setBlock(world, i + 2, j + 40, k + 16, Blocks.log, 3);
		world.setBlockMetadataWithNotify(i + 2, j + 40, k + 16, 3, 2);
		setBlock(world, i + 2, j + 40, k + 20, Blocks.log, 3);
		world.setBlockMetadataWithNotify(i + 2, j + 40, k + 20, 3, 2);
		setBlock(world, i + 2, j + 40, k + 26, Blocks.log, 3);
		world.setBlockMetadataWithNotify(i + 2, j + 40, k + 26, 3, 2);
		setBlock(world, i + 2, j + 40, k + 31, Blocks.leaves, 7);
		world.setBlockMetadataWithNotify(i + 2, j + 40, k + 31, 7, 2);
		setBlock(world, i + 2, j + 41, k + 13, Blocks.leaves, 7);
		world.setBlockMetadataWithNotify(i + 2, j + 41, k + 13, 7, 2);
		setBlock(world, i + 2, j + 41, k + 14, Blocks.leaves, 7);
		world.setBlockMetadataWithNotify(i + 2, j + 41, k + 14, 7, 2);
		setBlock(world, i + 2, j + 41, k + 15, Blocks.log, 3);
		world.setBlockMetadataWithNotify(i + 2, j + 41, k + 15, 3, 2);
		setBlock(world, i + 2, j + 41, k + 16, Blocks.leaves, 7);
		world.setBlockMetadataWithNotify(i + 2, j + 41, k + 16, 7, 2);
		setBlock(world, i + 2, j + 41, k + 17, Blocks.leaves, 7);
		world.setBlockMetadataWithNotify(i + 2, j + 41, k + 17, 7, 2);
		setBlock(world, i + 2, j + 41, k + 30, Blocks.leaves, 7);
		world.setBlockMetadataWithNotify(i + 2, j + 41, k + 30, 7, 2);
		setBlock(world, i + 2, j + 41, k + 31, Blocks.leaves, 7);
		world.setBlockMetadataWithNotify(i + 2, j + 41, k + 31, 7, 2);
		setBlock(world, i + 2, j + 42, k + 13, Blocks.leaves, 7);
		world.setBlockMetadataWithNotify(i + 2, j + 42, k + 13, 7, 2);
		setBlock(world, i + 2, j + 42, k + 14, Blocks.leaves, 7);
		world.setBlockMetadataWithNotify(i + 2, j + 42, k + 14, 7, 2);
		setBlock(world, i + 2, j + 42, k + 15, Blocks.leaves, 7);
		world.setBlockMetadataWithNotify(i + 2, j + 42, k + 15, 7, 2);
		setBlock(world, i + 2, j + 42, k + 16, Blocks.leaves, 7);
		world.setBlockMetadataWithNotify(i + 2, j + 42, k + 16, 7, 2);
		setBlock(world, i + 2, j + 42, k + 17, Blocks.leaves, 7);
		world.setBlockMetadataWithNotify(i + 2, j + 42, k + 17, 7, 2);
		setBlock(world, i + 2, j + 42, k + 30, Blocks.log, 3);
		world.setBlockMetadataWithNotify(i + 2, j + 42, k + 30, 3, 2);
		setBlock(world, i + 2, j + 42, k + 31, Blocks.leaves, 7);
		world.setBlockMetadataWithNotify(i + 2, j + 42, k + 31, 7, 2);
		setBlock(world, i + 2, j + 43, k + 14, Blocks.leaves, 7);
		world.setBlockMetadataWithNotify(i + 2, j + 43, k + 14, 7, 2);
		setBlock(world, i + 2, j + 43, k + 15, Blocks.leaves, 7);
		world.setBlockMetadataWithNotify(i + 2, j + 43, k + 15, 7, 2);
		setBlock(world, i + 2, j + 43, k + 16, Blocks.leaves, 7);
		world.setBlockMetadataWithNotify(i + 2, j + 43, k + 16, 7, 2);
		setBlock(world, i + 2, j + 43, k + 30, Blocks.leaves, 7);
		world.setBlockMetadataWithNotify(i + 2, j + 43, k + 30, 7, 2);
		setBlock(world, i + 2, j + 43, k + 31, Blocks.leaves, 7);
		world.setBlockMetadataWithNotify(i + 2, j + 43, k + 31, 7, 2);
		setBlock(world, i + 2, j + 44, k + 12, Blocks.leaves, 7);
		world.setBlockMetadataWithNotify(i + 2, j + 44, k + 12, 7, 2);
		setBlock(world, i + 2, j + 44, k + 13, Blocks.leaves, 7);
		world.setBlockMetadataWithNotify(i + 2, j + 44, k + 13, 7, 2);
		setBlock(world, i + 2, j + 44, k + 14, Blocks.leaves, 7);
		world.setBlockMetadataWithNotify(i + 2, j + 44, k + 14, 7, 2);
		setBlock(world, i + 2, j + 44, k + 15, Blocks.leaves, 7);
		world.setBlockMetadataWithNotify(i + 2, j + 44, k + 15, 7, 2);
		setBlock(world, i + 2, j + 44, k + 16, Blocks.leaves, 7);
		world.setBlockMetadataWithNotify(i + 2, j + 44, k + 16, 7, 2);
		setBlock(world, i + 2, j + 44, k + 31, Blocks.leaves, 7);
		world.setBlockMetadataWithNotify(i + 2, j + 44, k + 31, 7, 2);
		setBlock(world, i + 2, j + 45, k + 13, Blocks.leaves, 7);
		world.setBlockMetadataWithNotify(i + 2, j + 45, k + 13, 7, 2);
		setBlock(world, i + 2, j + 45, k + 14, Blocks.leaves, 7);
		world.setBlockMetadataWithNotify(i + 2, j + 45, k + 14, 7, 2);
		setBlock(world, i + 2, j + 45, k + 15, Blocks.leaves, 7);
		world.setBlockMetadataWithNotify(i + 2, j + 45, k + 15, 7, 2);
		setBlock(world, i + 2, j + 45, k + 25, Blocks.log, 3);
		world.setBlockMetadataWithNotify(i + 2, j + 45, k + 25, 3, 2);
		setBlock(world, i + 2, j + 46, k + 12, Blocks.leaves, 7);
		world.setBlockMetadataWithNotify(i + 2, j + 46, k + 12, 7, 2);
		setBlock(world, i + 2, j + 46, k + 13, Blocks.leaves, 7);
		world.setBlockMetadataWithNotify(i + 2, j + 46, k + 13, 7, 2);
		setBlock(world, i + 2, j + 46, k + 14, Blocks.leaves, 7);
		world.setBlockMetadataWithNotify(i + 2, j + 46, k + 14, 7, 2);
		setBlock(world, i + 2, j + 46, k + 15, Blocks.leaves, 7);
		world.setBlockMetadataWithNotify(i + 2, j + 46, k + 15, 7, 2);
		setBlock(world, i + 2, j + 46, k + 16, Blocks.leaves, 7);
		world.setBlockMetadataWithNotify(i + 2, j + 46, k + 16, 7, 2);
		setBlock(world, i + 2, j + 47, k + 13, Blocks.leaves, 7);
		world.setBlockMetadataWithNotify(i + 2, j + 47, k + 13, 7, 2);
		setBlock(world, i + 2, j + 47, k + 14, Blocks.leaves, 7);
		world.setBlockMetadataWithNotify(i + 2, j + 47, k + 14, 7, 2);
		setBlock(world, i + 2, j + 47, k + 15, Blocks.leaves, 7);
		world.setBlockMetadataWithNotify(i + 2, j + 47, k + 15, 7, 2);
		setBlock(world, i + 2, j + 47, k + 18, Blocks.leaves, 7);
		world.setBlockMetadataWithNotify(i + 2, j + 47, k + 18, 7, 2);
		setBlock(world, i + 2, j + 47, k + 19, Blocks.leaves, 7);
		world.setBlockMetadataWithNotify(i + 2, j + 47, k + 19, 7, 2);
		setBlock(world, i + 2, j + 47, k + 20, Blocks.leaves, 7);
		world.setBlockMetadataWithNotify(i + 2, j + 47, k + 20, 7, 2);
		setBlock(world, i + 2, j + 47, k + 21, Blocks.log, 3);
		world.setBlockMetadataWithNotify(i + 2, j + 47, k + 21, 3, 2);
		setBlock(world, i + 2, j + 47, k + 22, Blocks.leaves, 7);
		world.setBlockMetadataWithNotify(i + 2, j + 47, k + 22, 7, 2);
		setBlock(world, i + 2, j + 48, k + 14, Blocks.leaves, 7);
		world.setBlockMetadataWithNotify(i + 2, j + 48, k + 14, 7, 2);
		setBlock(world, i + 2, j + 48, k + 19, Blocks.leaves, 7);
		world.setBlockMetadataWithNotify(i + 2, j + 48, k + 19, 7, 2);
		setBlock(world, i + 2, j + 48, k + 20, Blocks.leaves, 7);
		world.setBlockMetadataWithNotify(i + 2, j + 48, k + 20, 7, 2);
		setBlock(world, i + 2, j + 48, k + 21, Blocks.leaves, 7);
		world.setBlockMetadataWithNotify(i + 2, j + 48, k + 21, 7, 2);
		setBlock(world, i + 2, j + 49, k + 20, Blocks.leaves, 7);
		world.setBlockMetadataWithNotify(i + 2, j + 49, k + 20, 7, 2);
		setBlock(world, i + 2, j + 49, k + 28, Blocks.leaves, 7);
		world.setBlockMetadataWithNotify(i + 2, j + 49, k + 28, 7, 2);
		setBlock(world, i + 2, j + 49, k + 29, Blocks.leaves, 7);
		world.setBlockMetadataWithNotify(i + 2, j + 49, k + 29, 7, 2);
		setBlock(world, i + 2, j + 49, k + 30, Blocks.log, 3);
		world.setBlockMetadataWithNotify(i + 2, j + 49, k + 30, 3, 2);
		setBlock(world, i + 2, j + 49, k + 31, Blocks.leaves, 7);
		world.setBlockMetadataWithNotify(i + 2, j + 49, k + 31, 7, 2);
		setBlock(world, i + 2, j + 50, k + 28, Blocks.leaves, 7);
		world.setBlockMetadataWithNotify(i + 2, j + 50, k + 28, 7, 2);
		setBlock(world, i + 2, j + 50, k + 29, Blocks.leaves, 7);
		world.setBlockMetadataWithNotify(i + 2, j + 50, k + 29, 7, 2);
		setBlock(world, i + 2, j + 50, k + 30, Blocks.leaves, 7);
		world.setBlockMetadataWithNotify(i + 2, j + 50, k + 30, 7, 2);
		setBlock(world, i + 2, j + 50, k + 31, Blocks.leaves, 7);
		world.setBlockMetadataWithNotify(i + 2, j + 50, k + 31, 7, 2);
		setBlock(world, i + 2, j + 51, k + 17, Blocks.leaves, 7);
		world.setBlockMetadataWithNotify(i + 2, j + 51, k + 17, 7, 2);
		setBlock(world, i + 2, j + 51, k + 18, Blocks.leaves, 7);
		world.setBlockMetadataWithNotify(i + 2, j + 51, k + 18, 7, 2);
		setBlock(world, i + 2, j + 51, k + 19, Blocks.leaves, 7);
		world.setBlockMetadataWithNotify(i + 2, j + 51, k + 19, 7, 2);
		setBlock(world, i + 2, j + 51, k + 29, Blocks.leaves, 7);
		world.setBlockMetadataWithNotify(i + 2, j + 51, k + 29, 7, 2);
		setBlock(world, i + 2, j + 51, k + 30, Blocks.leaves, 7);
		world.setBlockMetadataWithNotify(i + 2, j + 51, k + 30, 7, 2);
		setBlock(world, i + 2, j + 51, k + 31, Blocks.leaves, 7);
		world.setBlockMetadataWithNotify(i + 2, j + 51, k + 31, 7, 2);
		setBlock(world, i + 2, j + 52, k + 18, Blocks.leaves, 7);
		world.setBlockMetadataWithNotify(i + 2, j + 52, k + 18, 7, 2);
		setBlock(world, i + 2, j + 52, k + 23, Blocks.leaves, 7);
		world.setBlockMetadataWithNotify(i + 2, j + 52, k + 23, 7, 2);
		setBlock(world, i + 2, j + 52, k + 24, Blocks.leaves, 7);
		world.setBlockMetadataWithNotify(i + 2, j + 52, k + 24, 7, 2);
		setBlock(world, i + 2, j + 52, k + 25, Blocks.leaves, 7);
		world.setBlockMetadataWithNotify(i + 2, j + 52, k + 25, 7, 2);
		setBlock(world, i + 2, j + 52, k + 26, Blocks.leaves, 7);
		world.setBlockMetadataWithNotify(i + 2, j + 52, k + 26, 7, 2);
		setBlock(world, i + 2, j + 52, k + 27, Blocks.leaves, 7);
		world.setBlockMetadataWithNotify(i + 2, j + 52, k + 27, 7, 2);
		setBlock(world, i + 2, j + 52, k + 30, Blocks.leaves, 7);
		world.setBlockMetadataWithNotify(i + 2, j + 52, k + 30, 7, 2);
		setBlock(world, i + 2, j + 53, k + 24, Blocks.leaves, 7);
		world.setBlockMetadataWithNotify(i + 2, j + 53, k + 24, 7, 2);
		setBlock(world, i + 2, j + 53, k + 25, Blocks.leaves, 7);
		world.setBlockMetadataWithNotify(i + 2, j + 53, k + 25, 7, 2);
		setBlock(world, i + 2, j + 53, k + 26, Blocks.leaves, 7);
		world.setBlockMetadataWithNotify(i + 2, j + 53, k + 26, 7, 2);
		setBlock(world, i + 2, j + 53, k + 27, Blocks.leaves, 7);
		world.setBlockMetadataWithNotify(i + 2, j + 53, k + 27, 7, 2);
		setBlock(world, i + 2, j + 53, k + 28, Blocks.leaves, 7);
		world.setBlockMetadataWithNotify(i + 2, j + 53, k + 28, 7, 2);
		setBlock(world, i + 2, j + 53, k + 29, Blocks.leaves, 7);
		world.setBlockMetadataWithNotify(i + 2, j + 53, k + 29, 7, 2);
		setBlock(world, i + 2, j + 53, k + 30, Blocks.leaves, 7);
		world.setBlockMetadataWithNotify(i + 2, j + 53, k + 30, 7, 2);
		setBlock(world, i + 2, j + 53, k + 31, Blocks.leaves, 7);
		world.setBlockMetadataWithNotify(i + 2, j + 53, k + 31, 7, 2);
		setBlock(world, i + 2, j + 54, k + 18, Blocks.leaves, 7);
		world.setBlockMetadataWithNotify(i + 2, j + 54, k + 18, 7, 2);
		setBlock(world, i + 2, j + 54, k + 19, Blocks.leaves, 7);
		world.setBlockMetadataWithNotify(i + 2, j + 54, k + 19, 7, 2);
		setBlock(world, i + 2, j + 54, k + 20, Blocks.leaves, 7);
		world.setBlockMetadataWithNotify(i + 2, j + 54, k + 20, 7, 2);
		setBlock(world, i + 2, j + 54, k + 21, Blocks.leaves, 7);
		world.setBlockMetadataWithNotify(i + 2, j + 54, k + 21, 7, 2);
		setBlock(world, i + 2, j + 54, k + 22, Blocks.leaves, 7);
		world.setBlockMetadataWithNotify(i + 2, j + 54, k + 22, 7, 2);
		setBlock(world, i + 2, j + 54, k + 25, Blocks.leaves, 7);
		world.setBlockMetadataWithNotify(i + 2, j + 54, k + 25, 7, 2);
		setBlock(world, i + 2, j + 54, k + 26, Blocks.leaves, 7);
		world.setBlockMetadataWithNotify(i + 2, j + 54, k + 26, 7, 2);
		setBlock(world, i + 2, j + 54, k + 27, Blocks.leaves, 7);
		world.setBlockMetadataWithNotify(i + 2, j + 54, k + 27, 7, 2);
		setBlock(world, i + 2, j + 54, k + 28, Blocks.leaves, 7);
		world.setBlockMetadataWithNotify(i + 2, j + 54, k + 28, 7, 2);
		setBlock(world, i + 2, j + 54, k + 29, Blocks.log, 3);
		world.setBlockMetadataWithNotify(i + 2, j + 54, k + 29, 3, 2);
		setBlock(world, i + 2, j + 54, k + 30, Blocks.leaves, 7);
		world.setBlockMetadataWithNotify(i + 2, j + 54, k + 30, 7, 2);
		setBlock(world, i + 2, j + 54, k + 31, Blocks.leaves, 7);
		world.setBlockMetadataWithNotify(i + 2, j + 54, k + 31, 7, 2);
		setBlock(world, i + 2, j + 55, k + 19, Blocks.leaves, 7);
		world.setBlockMetadataWithNotify(i + 2, j + 55, k + 19, 7, 2);
		setBlock(world, i + 2, j + 55, k + 20, Blocks.leaves, 7);
		world.setBlockMetadataWithNotify(i + 2, j + 55, k + 20, 7, 2);
		setBlock(world, i + 2, j + 55, k + 21, Blocks.leaves, 7);
		world.setBlockMetadataWithNotify(i + 2, j + 55, k + 21, 7, 2);
		setBlock(world, i + 2, j + 55, k + 26, Blocks.leaves, 7);
		world.setBlockMetadataWithNotify(i + 2, j + 55, k + 26, 7, 2);
		setBlock(world, i + 2, j + 55, k + 27, Blocks.leaves, 7);
		world.setBlockMetadataWithNotify(i + 2, j + 55, k + 27, 7, 2);
		setBlock(world, i + 2, j + 55, k + 28, Blocks.leaves, 7);
		world.setBlockMetadataWithNotify(i + 2, j + 55, k + 28, 7, 2);
		setBlock(world, i + 2, j + 55, k + 29, Blocks.leaves, 7);
		world.setBlockMetadataWithNotify(i + 2, j + 55, k + 29, 7, 2);
		setBlock(world, i + 2, j + 55, k + 30, Blocks.leaves, 7);
		world.setBlockMetadataWithNotify(i + 2, j + 55, k + 30, 7, 2);
		setBlock(world, i + 2, j + 55, k + 31, Blocks.leaves, 7);
		world.setBlockMetadataWithNotify(i + 2, j + 55, k + 31, 7, 2);
		setBlock(world, i + 2, j + 56, k + 20, Blocks.leaves, 7);
		world.setBlockMetadataWithNotify(i + 2, j + 56, k + 20, 7, 2);
		setBlock(world, i + 2, j + 56, k + 21, Blocks.leaves, 7);
		world.setBlockMetadataWithNotify(i + 2, j + 56, k + 21, 7, 2);
		setBlock(world, i + 2, j + 56, k + 22, Blocks.leaves, 7);
		world.setBlockMetadataWithNotify(i + 2, j + 56, k + 22, 7, 2);
		setBlock(world, i + 2, j + 56, k + 28, Blocks.leaves, 7);
		world.setBlockMetadataWithNotify(i + 2, j + 56, k + 28, 7, 2);
		setBlock(world, i + 2, j + 56, k + 29, Blocks.leaves, 7);
		world.setBlockMetadataWithNotify(i + 2, j + 56, k + 29, 7, 2);
		setBlock(world, i + 2, j + 56, k + 30, Blocks.leaves, 7);
		world.setBlockMetadataWithNotify(i + 2, j + 56, k + 30, 7, 2);
		setBlock(world, i + 2, j + 57, k + 21, Blocks.leaves, 7);
		world.setBlockMetadataWithNotify(i + 2, j + 57, k + 21, 7, 2);
		setBlock(world, i + 2, j + 57, k + 29, Blocks.leaves, 7);
		world.setBlockMetadataWithNotify(i + 2, j + 57, k + 29, 7, 2);
		setBlock(world, i + 2, j + 58, k + 18, Blocks.leaves, 7);
		world.setBlockMetadataWithNotify(i + 2, j + 58, k + 18, 7, 2);
		setBlock(world, i + 2, j + 58, k + 19, Blocks.leaves, 7);
		world.setBlockMetadataWithNotify(i + 2, j + 58, k + 19, 7, 2);
		setBlock(world, i + 2, j + 58, k + 20, Blocks.leaves, 7);
		world.setBlockMetadataWithNotify(i + 2, j + 58, k + 20, 7, 2);
		setBlock(world, i + 2, j + 58, k + 21, Blocks.leaves, 7);
		world.setBlockMetadataWithNotify(i + 2, j + 58, k + 21, 7, 2);
		setBlock(world, i + 2, j + 58, k + 22, Blocks.leaves, 7);
		world.setBlockMetadataWithNotify(i + 2, j + 58, k + 22, 7, 2);
		setBlock(world, i + 2, j + 59, k + 19, Blocks.leaves, 7);
		world.setBlockMetadataWithNotify(i + 2, j + 59, k + 19, 7, 2);
		setBlock(world, i + 2, j + 59, k + 20, Blocks.leaves, 7);
		world.setBlockMetadataWithNotify(i + 2, j + 59, k + 20, 7, 2);
		setBlock(world, i + 2, j + 59, k + 21, Blocks.leaves, 7);
		world.setBlockMetadataWithNotify(i + 2, j + 59, k + 21, 7, 2);
		setBlock(world, i + 2, j + 59, k + 26, Blocks.leaves, 7);
		world.setBlockMetadataWithNotify(i + 2, j + 59, k + 26, 7, 2);
		setBlock(world, i + 2, j + 59, k + 27, Blocks.leaves, 7);
		world.setBlockMetadataWithNotify(i + 2, j + 59, k + 27, 7, 2);
		setBlock(world, i + 2, j + 59, k + 28, Blocks.leaves, 7);
		world.setBlockMetadataWithNotify(i + 2, j + 59, k + 28, 7, 2);
		setBlock(world, i + 2, j + 60, k + 20, Blocks.leaves, 7);
		world.setBlockMetadataWithNotify(i + 2, j + 60, k + 20, 7, 2);
		setBlock(world, i + 2, j + 60, k + 27, Blocks.leaves, 7);
		world.setBlockMetadataWithNotify(i + 2, j + 60, k + 27, 7, 2);
		setBlock(world, i + 2, j + 61, k + 18, Blocks.leaves, 7);
		world.setBlockMetadataWithNotify(i + 2, j + 61, k + 18, 7, 2);
		setBlock(world, i + 2, j + 61, k + 19, Blocks.leaves, 7);
		world.setBlockMetadataWithNotify(i + 2, j + 61, k + 19, 7, 2);
		setBlock(world, i + 2, j + 61, k + 20, Blocks.leaves, 7);
		world.setBlockMetadataWithNotify(i + 2, j + 61, k + 20, 7, 2);
		setBlock(world, i + 2, j + 62, k + 19, Blocks.leaves, 7);
		world.setBlockMetadataWithNotify(i + 2, j + 62, k + 19, 7, 2);
		setBlock(world, i + 2, j + 63, k + 25, Blocks.leaves, 7);
		world.setBlockMetadataWithNotify(i + 2, j + 63, k + 25, 7, 2);
		setBlock(world, i + 2, j + 63, k + 26, Blocks.leaves, 7);
		world.setBlockMetadataWithNotify(i + 2, j + 63, k + 26, 7, 2);
		setBlock(world, i + 2, j + 63, k + 27, Blocks.leaves, 7);
		world.setBlockMetadataWithNotify(i + 2, j + 63, k + 27, 7, 2);
		setBlock(world, i + 2, j + 63, k + 28, Blocks.leaves, 7);
		world.setBlockMetadataWithNotify(i + 2, j + 63, k + 28, 7, 2);
		setBlock(world, i + 2, j + 63, k + 29, Blocks.leaves, 7);
		world.setBlockMetadataWithNotify(i + 2, j + 63, k + 29, 7, 2);
		setBlock(world, i + 2, j + 64, k + 26, Blocks.leaves, 7);
		world.setBlockMetadataWithNotify(i + 2, j + 64, k + 26, 7, 2);
		setBlock(world, i + 2, j + 64, k + 27, Blocks.leaves, 7);
		world.setBlockMetadataWithNotify(i + 2, j + 64, k + 27, 7, 2);
		setBlock(world, i + 2, j + 64, k + 28, Blocks.leaves, 7);
		world.setBlockMetadataWithNotify(i + 2, j + 64, k + 28, 7, 2);
		setBlock(world, i + 2, j + 65, k + 27, Blocks.leaves, 7);
		world.setBlockMetadataWithNotify(i + 2, j + 65, k + 27, 7, 2);
		setBlock(world, i + 3, j + 0, k + 19, Blocks.log, 3);
		world.setBlockMetadataWithNotify(i + 3, j + 0, k + 19, 3, 2);
		setBlock(world, i + 3, j + 0, k + 20, Blocks.log, 3);
		world.setBlockMetadataWithNotify(i + 3, j + 0, k + 20, 3, 2);
		setBlock(world, i + 3, j + 0, k + 21, Blocks.log, 3);
		world.setBlockMetadataWithNotify(i + 3, j + 0, k + 21, 3, 2);
		setBlock(world, i + 3, j + 0, k + 22, Blocks.log, 3);
		world.setBlockMetadataWithNotify(i + 3, j + 0, k + 22, 3, 2);
		setBlock(world, i + 3, j + 0, k + 23, Blocks.log, 3);
		world.setBlockMetadataWithNotify(i + 3, j + 0, k + 23, 3, 2);
		setBlock(world, i + 3, j + 0, k + 24, Blocks.log, 3);
		world.setBlockMetadataWithNotify(i + 3, j + 0, k + 24, 3, 2);
		setBlock(world, i + 3, j + 0, k + 25, Blocks.log, 3);
		world.setBlockMetadataWithNotify(i + 3, j + 0, k + 25, 3, 2);
		setBlock(world, i + 3, j + 0, k + 26, Blocks.log, 3);
		world.setBlockMetadataWithNotify(i + 3, j + 0, k + 26, 3, 2);
		setBlock(world, i + 3, j + 0, k + 27, Blocks.log, 3);
		world.setBlockMetadataWithNotify(i + 3, j + 0, k + 27, 3, 2);
		setBlock(world, i + 3, j + 0, k + 28, Blocks.log, 3);
		world.setBlockMetadataWithNotify(i + 3, j + 0, k + 28, 3, 2);
		setBlock(world, i + 3, j + 0, k + 29, Blocks.log, 3);
		world.setBlockMetadataWithNotify(i + 3, j + 0, k + 29, 3, 2);
		setBlock(world, i + 3, j + 0, k + 30, Blocks.log, 3);
		world.setBlockMetadataWithNotify(i + 3, j + 0, k + 30, 3, 2);
		setBlock(world, i + 3, j + 1, k + 19, Blocks.log, 3);
		world.setBlockMetadataWithNotify(i + 3, j + 1, k + 19, 3, 2);
		setBlock(world, i + 3, j + 1, k + 20, Blocks.log, 3);
		world.setBlockMetadataWithNotify(i + 3, j + 1, k + 20, 3, 2);
		setBlock(world, i + 3, j + 1, k + 21, Blocks.log, 3);
		world.setBlockMetadataWithNotify(i + 3, j + 1, k + 21, 3, 2);
		setBlock(world, i + 3, j + 1, k + 22, Blocks.log, 3);
		world.setBlockMetadataWithNotify(i + 3, j + 1, k + 22, 3, 2);
		setBlock(world, i + 3, j + 1, k + 23, Blocks.log, 3);
		world.setBlockMetadataWithNotify(i + 3, j + 1, k + 23, 3, 2);
		setBlock(world, i + 3, j + 1, k + 24, Blocks.log, 3);
		world.setBlockMetadataWithNotify(i + 3, j + 1, k + 24, 3, 2);
		setBlock(world, i + 3, j + 1, k + 25, Blocks.log, 3);
		world.setBlockMetadataWithNotify(i + 3, j + 1, k + 25, 3, 2);
		setBlock(world, i + 3, j + 1, k + 26, Blocks.log, 3);
		world.setBlockMetadataWithNotify(i + 3, j + 1, k + 26, 3, 2);
		setBlock(world, i + 3, j + 1, k + 27, Blocks.log, 3);
		world.setBlockMetadataWithNotify(i + 3, j + 1, k + 27, 3, 2);
		setBlock(world, i + 3, j + 1, k + 28, Blocks.log, 3);
		world.setBlockMetadataWithNotify(i + 3, j + 1, k + 28, 3, 2);
		setBlock(world, i + 3, j + 1, k + 29, Blocks.log, 3);
		world.setBlockMetadataWithNotify(i + 3, j + 1, k + 29, 3, 2);
		setBlock(world, i + 3, j + 2, k + 21, Blocks.log, 3);
		world.setBlockMetadataWithNotify(i + 3, j + 2, k + 21, 3, 2);
		setBlock(world, i + 3, j + 2, k + 22, Blocks.log, 3);
		world.setBlockMetadataWithNotify(i + 3, j + 2, k + 22, 3, 2);
		setBlock(world, i + 3, j + 2, k + 23, Blocks.log, 3);
		world.setBlockMetadataWithNotify(i + 3, j + 2, k + 23, 3, 2);
		setBlock(world, i + 3, j + 2, k + 24, Blocks.log, 3);
		world.setBlockMetadataWithNotify(i + 3, j + 2, k + 24, 3, 2);
		setBlock(world, i + 3, j + 2, k + 25, Blocks.log, 3);
		world.setBlockMetadataWithNotify(i + 3, j + 2, k + 25, 3, 2);
		setBlock(world, i + 3, j + 2, k + 26, Blocks.log, 3);
		world.setBlockMetadataWithNotify(i + 3, j + 2, k + 26, 3, 2);
		setBlock(world, i + 3, j + 2, k + 27, Blocks.log, 3);
		world.setBlockMetadataWithNotify(i + 3, j + 2, k + 27, 3, 2);
		setBlock(world, i + 3, j + 3, k + 22, Blocks.log, 3);
		world.setBlockMetadataWithNotify(i + 3, j + 3, k + 22, 3, 2);
		setBlock(world, i + 3, j + 3, k + 23, Blocks.log, 3);
		world.setBlockMetadataWithNotify(i + 3, j + 3, k + 23, 3, 2);
		setBlock(world, i + 3, j + 3, k + 24, Blocks.log, 3);
		world.setBlockMetadataWithNotify(i + 3, j + 3, k + 24, 3, 2);
		setBlock(world, i + 3, j + 3, k + 25, Blocks.log, 3);
		world.setBlockMetadataWithNotify(i + 3, j + 3, k + 25, 3, 2);
		setBlock(world, i + 3, j + 3, k + 26, Blocks.log, 3);
		world.setBlockMetadataWithNotify(i + 3, j + 3, k + 26, 3, 2);
		setBlock(world, i + 3, j + 4, k + 22, Blocks.log, 3);
		world.setBlockMetadataWithNotify(i + 3, j + 4, k + 22, 3, 2);
		setBlock(world, i + 3, j + 4, k + 23, Blocks.log, 3);
		world.setBlockMetadataWithNotify(i + 3, j + 4, k + 23, 3, 2);
		setBlock(world, i + 3, j + 4, k + 24, Blocks.log, 3);
		world.setBlockMetadataWithNotify(i + 3, j + 4, k + 24, 3, 2);
		setBlock(world, i + 3, j + 4, k + 25, Blocks.log, 3);
		world.setBlockMetadataWithNotify(i + 3, j + 4, k + 25, 3, 2);
		setBlock(world, i + 3, j + 4, k + 26, Blocks.log, 3);
		world.setBlockMetadataWithNotify(i + 3, j + 4, k + 26, 3, 2);
		setBlock(world, i + 3, j + 5, k + 23, Blocks.log, 3);
		world.setBlockMetadataWithNotify(i + 3, j + 5, k + 23, 3, 2);
		setBlock(world, i + 3, j + 5, k + 24, Blocks.log, 3);
		world.setBlockMetadataWithNotify(i + 3, j + 5, k + 24, 3, 2);
		setBlock(world, i + 3, j + 5, k + 25, Blocks.log, 3);
		world.setBlockMetadataWithNotify(i + 3, j + 5, k + 25, 3, 2);
		setBlock(world, i + 3, j + 6, k + 23, Blocks.log, 3);
		world.setBlockMetadataWithNotify(i + 3, j + 6, k + 23, 3, 2);
		setBlock(world, i + 3, j + 6, k + 24, Blocks.log, 3);
		world.setBlockMetadataWithNotify(i + 3, j + 6, k + 24, 3, 2);
		setBlock(world, i + 3, j + 6, k + 25, Blocks.log, 3);
		world.setBlockMetadataWithNotify(i + 3, j + 6, k + 25, 3, 2);
		setBlock(world, i + 3, j + 7, k + 23, Blocks.log, 3);
		world.setBlockMetadataWithNotify(i + 3, j + 7, k + 23, 3, 2);
		setBlock(world, i + 3, j + 7, k + 24, Blocks.log, 3);
		world.setBlockMetadataWithNotify(i + 3, j + 7, k + 24, 3, 2);
		setBlock(world, i + 3, j + 7, k + 25, Blocks.log, 3);
		world.setBlockMetadataWithNotify(i + 3, j + 7, k + 25, 3, 2);
		setBlock(world, i + 3, j + 8, k + 24, Blocks.log, 3);
		world.setBlockMetadataWithNotify(i + 3, j + 8, k + 24, 3, 2);
		setBlock(world, i + 3, j + 18, k + 24, Blocks.log, 3);
		world.setBlockMetadataWithNotify(i + 3, j + 18, k + 24, 3, 2);
		setBlock(world, i + 3, j + 18, k + 25, Blocks.log, 1);
		world.setBlockMetadataWithNotify(i + 3, j + 18, k + 25, 1, 2);
		setBlock(world, i + 3, j + 18, k + 26, Blocks.log, 1);
		world.setBlockMetadataWithNotify(i + 3, j + 18, k + 26, 1, 2);
		setBlock(world, i + 3, j + 18, k + 27, Blocks.log, 1);
		world.setBlockMetadataWithNotify(i + 3, j + 18, k + 27, 1, 2);
		setBlock(world, i + 3, j + 19, k + 23, Blocks.log, 3);
		world.setBlockMetadataWithNotify(i + 3, j + 19, k + 23, 3, 2);
		setBlock(world, i + 3, j + 19, k + 24, Blocks.log, 3);
		world.setBlockMetadataWithNotify(i + 3, j + 19, k + 24, 3, 2);
		setBlock(world, i + 3, j + 19, k + 25, Blocks.log, 3);
		world.setBlockMetadataWithNotify(i + 3, j + 19, k + 25, 3, 2);
		setBlock(world, i + 3, j + 19, k + 26, Blocks.log, 1);
		world.setBlockMetadataWithNotify(i + 3, j + 19, k + 26, 1, 2);
		setBlock(world, i + 3, j + 19, k + 27, Blocks.log, 3);
		world.setBlockMetadataWithNotify(i + 3, j + 19, k + 27, 3, 2);
		setBlock(world, i + 3, j + 20, k + 19, Blocks.log, 3);
		world.setBlockMetadataWithNotify(i + 3, j + 20, k + 19, 3, 2);
		setBlock(world, i + 3, j + 20, k + 20, Blocks.log, 3);
		world.setBlockMetadataWithNotify(i + 3, j + 20, k + 20, 3, 2);
		setBlock(world, i + 3, j + 20, k + 21, Blocks.log, 3);
		world.setBlockMetadataWithNotify(i + 3, j + 20, k + 21, 3, 2);
		setBlock(world, i + 3, j + 20, k + 24, Blocks.log, 3);
		world.setBlockMetadataWithNotify(i + 3, j + 20, k + 24, 3, 2);
		setBlock(world, i + 3, j + 20, k + 26, Blocks.log, 3);
		world.setBlockMetadataWithNotify(i + 3, j + 20, k + 26, 3, 2);
		setBlock(world, i + 3, j + 20, k + 27, Blocks.log, 3);
		world.setBlockMetadataWithNotify(i + 3, j + 20, k + 27, 3, 2);
		setBlock(world, i + 3, j + 20, k + 28, Blocks.log, 3);
		world.setBlockMetadataWithNotify(i + 3, j + 20, k + 28, 3, 2);
		setBlock(world, i + 3, j + 21, k + 19, Blocks.log, 3);
		world.setBlockMetadataWithNotify(i + 3, j + 21, k + 19, 3, 2);
		setBlock(world, i + 3, j + 21, k + 20, Blocks.log, 3);
		world.setBlockMetadataWithNotify(i + 3, j + 21, k + 20, 3, 2);
		setBlock(world, i + 3, j + 21, k + 21, Blocks.log, 3);
		world.setBlockMetadataWithNotify(i + 3, j + 21, k + 21, 3, 2);
		setBlock(world, i + 3, j + 21, k + 22, Blocks.log, 1);
		world.setBlockMetadataWithNotify(i + 3, j + 21, k + 22, 1, 2);
		setBlock(world, i + 3, j + 21, k + 25, Blocks.log, 3);
		world.setBlockMetadataWithNotify(i + 3, j + 21, k + 25, 3, 2);
		setBlock(world, i + 3, j + 21, k + 26, Blocks.log, 3);
		world.setBlockMetadataWithNotify(i + 3, j + 21, k + 26, 3, 2);
		setBlock(world, i + 3, j + 21, k + 27, Blocks.log, 3);
		world.setBlockMetadataWithNotify(i + 3, j + 21, k + 27, 3, 2);
		setBlock(world, i + 3, j + 21, k + 31, Blocks.log, 1);
		world.setBlockMetadataWithNotify(i + 3, j + 21, k + 31, 1, 2);
		setBlock(world, i + 3, j + 22, k + 0, Blocks.leaves, 7);
		world.setBlockMetadataWithNotify(i + 3, j + 22, k + 0, 7, 2);
		setBlock(world, i + 3, j + 22, k + 1, Blocks.leaves, 7);
		world.setBlockMetadataWithNotify(i + 3, j + 22, k + 1, 7, 2);
		setBlock(world, i + 3, j + 22, k + 2, Blocks.leaves, 7);
		world.setBlockMetadataWithNotify(i + 3, j + 22, k + 2, 7, 2);
		setBlock(world, i + 3, j + 22, k + 19, Blocks.log, 3);
		world.setBlockMetadataWithNotify(i + 3, j + 22, k + 19, 3, 2);
		setBlock(world, i + 3, j + 22, k + 20, Blocks.log, 3);
		world.setBlockMetadataWithNotify(i + 3, j + 22, k + 20, 3, 2);
		setBlock(world, i + 3, j + 22, k + 21, Blocks.log, 1);
		world.setBlockMetadataWithNotify(i + 3, j + 22, k + 21, 1, 2);
		setBlock(world, i + 3, j + 22, k + 22, Blocks.log, 1);
		world.setBlockMetadataWithNotify(i + 3, j + 22, k + 22, 1, 2);
		setBlock(world, i + 3, j + 22, k + 23, Blocks.log, 1);
		world.setBlockMetadataWithNotify(i + 3, j + 22, k + 23, 1, 2);
		setBlock(world, i + 3, j + 22, k + 24, Blocks.log, 1);
		world.setBlockMetadataWithNotify(i + 3, j + 22, k + 24, 1, 2);
		setBlock(world, i + 3, j + 22, k + 26, Blocks.log, 3);
		world.setBlockMetadataWithNotify(i + 3, j + 22, k + 26, 3, 2);
		setBlock(world, i + 3, j + 22, k + 31, Blocks.log, 1);
		world.setBlockMetadataWithNotify(i + 3, j + 22, k + 31, 1, 2);
		setBlock(world, i + 3, j + 23, k + 1, Blocks.leaves, 7);
		world.setBlockMetadataWithNotify(i + 3, j + 23, k + 1, 7, 2);
		setBlock(world, i + 3, j + 23, k + 22, Blocks.log, 1);
		world.setBlockMetadataWithNotify(i + 3, j + 23, k + 22, 1, 2);
		setBlock(world, i + 3, j + 23, k + 23, Blocks.log, 1);
		world.setBlockMetadataWithNotify(i + 3, j + 23, k + 23, 1, 2);
		setBlock(world, i + 3, j + 23, k + 31, Blocks.log, 1);
		world.setBlockMetadataWithNotify(i + 3, j + 23, k + 31, 1, 2);
		setBlock(world, i + 3, j + 26, k + 28, Blocks.log, 3);
		world.setBlockMetadataWithNotify(i + 3, j + 26, k + 28, 3, 2);
		setBlock(world, i + 3, j + 28, k + 15, Blocks.log, 3);
		world.setBlockMetadataWithNotify(i + 3, j + 28, k + 15, 3, 2);
		setBlock(world, i + 3, j + 28, k + 16, Blocks.log, 3);
		world.setBlockMetadataWithNotify(i + 3, j + 28, k + 16, 3, 2);
		setBlock(world, i + 3, j + 29, k + 9, Blocks.leaves, 7);
		world.setBlockMetadataWithNotify(i + 3, j + 29, k + 9, 7, 2);
		setBlock(world, i + 3, j + 29, k + 10, Blocks.leaves, 7);
		world.setBlockMetadataWithNotify(i + 3, j + 29, k + 10, 7, 2);
		setBlock(world, i + 3, j + 29, k + 11, Blocks.leaves, 7);
		world.setBlockMetadataWithNotify(i + 3, j + 29, k + 11, 7, 2);
		setBlock(world, i + 3, j + 29, k + 12, Blocks.leaves, 7);
		world.setBlockMetadataWithNotify(i + 3, j + 29, k + 12, 7, 2);
		setBlock(world, i + 3, j + 29, k + 13, Blocks.leaves, 7);
		world.setBlockMetadataWithNotify(i + 3, j + 29, k + 13, 7, 2);
		setBlock(world, i + 3, j + 29, k + 17, Blocks.log, 3);
		world.setBlockMetadataWithNotify(i + 3, j + 29, k + 17, 3, 2);
		setBlock(world, i + 3, j + 29, k + 28, Blocks.log, 3);
		world.setBlockMetadataWithNotify(i + 3, j + 29, k + 28, 3, 2);
		setBlock(world, i + 3, j + 30, k + 10, Blocks.leaves, 7);
		world.setBlockMetadataWithNotify(i + 3, j + 30, k + 10, 7, 2);
		setBlock(world, i + 3, j + 30, k + 11, Blocks.leaves, 7);
		world.setBlockMetadataWithNotify(i + 3, j + 30, k + 11, 7, 2);
		setBlock(world, i + 3, j + 30, k + 12, Blocks.leaves, 7);
		world.setBlockMetadataWithNotify(i + 3, j + 30, k + 12, 7, 2);
		setBlock(world, i + 3, j + 30, k + 14, Blocks.leaves, 7);
		world.setBlockMetadataWithNotify(i + 3, j + 30, k + 14, 7, 2);
		setBlock(world, i + 3, j + 30, k + 15, Blocks.leaves, 7);
		world.setBlockMetadataWithNotify(i + 3, j + 30, k + 15, 7, 2);
		setBlock(world, i + 3, j + 30, k + 16, Blocks.log, 3);
		world.setBlockMetadataWithNotify(i + 3, j + 30, k + 16, 3, 2);
		setBlock(world, i + 3, j + 30, k + 17, Blocks.leaves, 7);
		world.setBlockMetadataWithNotify(i + 3, j + 30, k + 17, 7, 2);
		setBlock(world, i + 3, j + 30, k + 18, Blocks.leaves, 7);
		world.setBlockMetadataWithNotify(i + 3, j + 30, k + 18, 7, 2);
		setBlock(world, i + 3, j + 30, k + 20, Blocks.log, 3);
		world.setBlockMetadataWithNotify(i + 3, j + 30, k + 20, 3, 2);
		setBlock(world, i + 3, j + 31, k + 11, Blocks.leaves, 7);
		world.setBlockMetadataWithNotify(i + 3, j + 31, k + 11, 7, 2);
		setBlock(world, i + 3, j + 31, k + 14, Blocks.leaves, 7);
		world.setBlockMetadataWithNotify(i + 3, j + 31, k + 14, 7, 2);
		setBlock(world, i + 3, j + 31, k + 15, Blocks.leaves, 7);
		world.setBlockMetadataWithNotify(i + 3, j + 31, k + 15, 7, 2);
		setBlock(world, i + 3, j + 31, k + 16, Blocks.leaves, 7);
		world.setBlockMetadataWithNotify(i + 3, j + 31, k + 16, 7, 2);
		setBlock(world, i + 3, j + 31, k + 17, Blocks.leaves, 7);
		world.setBlockMetadataWithNotify(i + 3, j + 31, k + 17, 7, 2);
		setBlock(world, i + 3, j + 31, k + 18, Blocks.leaves, 7);
		world.setBlockMetadataWithNotify(i + 3, j + 31, k + 18, 7, 2);
		setBlock(world, i + 3, j + 31, k + 23, Blocks.log, 3);
		world.setBlockMetadataWithNotify(i + 3, j + 31, k + 23, 3, 2);
		setBlock(world, i + 3, j + 32, k + 15, Blocks.leaves, 7);
		world.setBlockMetadataWithNotify(i + 3, j + 32, k + 15, 7, 2);
		setBlock(world, i + 3, j + 32, k + 16, Blocks.leaves, 7);
		world.setBlockMetadataWithNotify(i + 3, j + 32, k + 16, 7, 2);
		setBlock(world, i + 3, j + 32, k + 17, Blocks.leaves, 7);
		world.setBlockMetadataWithNotify(i + 3, j + 32, k + 17, 7, 2);
		setBlock(world, i + 3, j + 32, k + 20, Blocks.leaves, 7);
