package com.parzivail.pswm.world.gen.wookietree;




import com.parzivail.pswm.utils.LootGenUtils;
import com.parzivail.pswm.utils.NPCType;
import com.parzivail.pswm.utils.SpawnUtils;



import cpw.mods.fml.common.IWorldGenerator;



import java.util.Random;



import net.minecraft.block.Block;

import net.minecraft.init.Blocks;

import net.minecraft.tileentity.TileEntityChest;

import net.minecraft.world.World;

import net.minecraft.world.WorldProvider;

import net.minecraft.world.chunk.IChunkProvider;

import net.minecraft.world.gen.feature.WorldGenerator;


public class WT_21
extends WorldGenerator implements IWorldGenerator

{
	protected Block[] getValidSpawnBlocks()
	
	{
		return new Block[0];
		}

	
	public boolean locationIsValidSpawn(World world, int i, int j, int k)
	
	{
		int distanceToAir = 0;
		Block check = world.getBlock(i, j, k);
		
		while (check != Blocks.air)
		{
			if (distanceToAir > 3) { return false;
			}
			
			distanceToAir++;
			check = world.getBlock(i, j + distanceToAir, k);
			}
		
		j += distanceToAir - 1;
		
		Block block = world.getBlock(i, j, k);
		Block blockAbove = world.getBlock(i, j + 1, k);
		Block blockBelow = world.getBlock(i, j - 1, k);
		
		for (Block x : getValidSpawnBlocks())
		{
			if (blockAbove != Blocks.air) { return false;
			}
			if (block == x) return true;
			if ((block == Blocks.snow) && (blockBelow == x)) { return true;
			}
			}
		
		return false;
		}

	
	
	
	public void generate(Random random, int chunkX, int chunkZ, World world, IChunkProvider chunkGenerator, IChunkProvider chunkProvider)
	{
	}

	
	
	public void setBlock(World world, int x, int y, int z, Block block, int metadata)
	
	{
		world.setBlock(x, y, z, block, metadata, 2);
		}

	
	public boolean generate(World world, Random rand, int i, int j, int k)
	
	{
		k -= 10;
		i -= 10;
		
		setBlock(world, i + 0, j + 41, k + 18, Blocks.spruce_stairs, 0);
		setBlock(world, i + 0, j + 41, k + 19, Blocks.crafting_table, 0);
		SpawnUtils.spawnNPC(NPCType.WOOKIETREE, world, i + 3, j + 41, k + 16);
		SpawnUtils.spawnNPC(NPCType.WOOKIETREE, world, i + 3, j + 41, k + 20);
		setBlock(world, i + 4, j + 41, k + 13, Blocks.fence, 0);
		setBlock(world, i + 4, j + 41, k + 23, Blocks.fence, 0);
		setBlock(world, i + 4, j + 43, k + 10, Blocks.fence, 0);
		setBlock(world, i + 4, j + 43, k + 11, Blocks.fence, 0);
		setBlock(world, i + 4, j + 43, k + 25, Blocks.fence, 0);
		setBlock(world, i + 4, j + 43, k + 26, Blocks.fence, 0);
		setBlock(world, i + 5, j + 41, k + 13, Blocks.fence, 0);
		setBlock(world, i + 5, j + 41, k + 14, Blocks.fence, 0);
		setBlock(world, i + 5, j + 41, k + 22, Blocks.fence, 0);
		setBlock(world, i + 5, j + 41, k + 23, Blocks.fence, 0);
		setBlock(world, i + 6, j + 41, k + 14, Blocks.fence, 0);
		setBlock(world, i + 6, j + 41, k + 15, Blocks.fence, 0);
		setBlock(world, i + 6, j + 41, k + 16, Blocks.spruce_stairs, 0);
		setBlock(world, i + 6, j + 41, k + 20, Blocks.spruce_stairs, 0);
		setBlock(world, i + 6, j + 41, k + 21, Blocks.fence, 0);
		setBlock(world, i + 6, j + 41, k + 22, Blocks.fence, 0);
		setBlock(world, i + 8, j + 43, k + 15, Blocks.fence, 0);
		setBlock(world, i + 8, j + 43, k + 21, Blocks.fence, 0);
		setBlock(world, i + 9, j + 43, k + 15, Blocks.fence, 0);
		setBlock(world, i + 9, j + 43, k + 21, Blocks.fence, 0);
		setBlock(world, i + 13, j + 25, k + 0, Blocks.fence, 0);
		setBlock(world, i + 14, j + 25, k + 0, Blocks.fence, 0);
		setBlock(world, i + 16, j + 23, k + 0, Blocks.fence, 0);
		setBlock(world, i + 16, j + 23, k + 1, Blocks.fence, 0);
		setBlock(world, i + 17, j + 23, k + 1, Blocks.fence, 0);
		setBlock(world, i + 17, j + 23, k + 2, Blocks.fence, 0);
		setBlock(world, i + 17, j + 23, k + 10, Blocks.spruce_stairs, 0);
		setBlock(world, i + 17, j + 23, k + 11, Blocks.spruce_stairs, 0);
		setBlock(world, i + 17, j + 23, k + 12, Blocks.spruce_stairs, 0);
		setBlock(world, i + 17, j + 23, k + 13, Blocks.spruce_stairs, 0);
		setBlock(world, i + 17, j + 23, k + 14, Blocks.spruce_stairs, 0);
		setBlock(world, i + 18, j + 23, k + 2, Blocks.fence, 0);
		setBlock(world, i + 18, j + 23, k + 3, Blocks.spruce_stairs, 0);
		setBlock(world, i + 18, j + 24, k + 10, Blocks.spruce_stairs, 0);
		setBlock(world, i + 18, j + 24, k + 11, Blocks.spruce_stairs, 0);
		setBlock(world, i + 18, j + 24, k + 12, Blocks.spruce_stairs, 0);
		setBlock(world, i + 18, j + 24, k + 13, Blocks.spruce_stairs, 0);
		setBlock(world, i + 18, j + 24, k + 14, Blocks.spruce_stairs, 0);
		setBlock(world, i + 18, j + 25, k + 4, Blocks.fence, 0);
		setBlock(world, i + 18, j + 25, k + 5, Blocks.fence, 0);
		setBlock(world, i + 19, j + 25, k + 10, Blocks.spruce_stairs, 0);
		setBlock(world, i + 19, j + 25, k + 11, Blocks.spruce_stairs, 0);
		setBlock(world, i + 19, j + 25, k + 12, Blocks.spruce_stairs, 0);
		setBlock(world, i + 19, j + 25, k + 13, Blocks.spruce_stairs, 0);
		setBlock(world, i + 19, j + 25, k + 14, Blocks.spruce_stairs, 0);
		setBlock(world, i + 20, j + 26, k + 10, Blocks.spruce_stairs, 0);
		setBlock(world, i + 20, j + 26, k + 11, Blocks.spruce_stairs, 0);
		setBlock(world, i + 20, j + 26, k + 12, Blocks.spruce_stairs, 0);
		setBlock(world, i + 20, j + 26, k + 13, Blocks.spruce_stairs, 0);
		setBlock(world, i + 20, j + 26, k + 14, Blocks.spruce_stairs, 0);
		setBlock(world, i + 21, j + 27, k + 10, Blocks.spruce_stairs, 0);
		setBlock(world, i + 21, j + 27, k + 11, Blocks.spruce_stairs, 0);
		setBlock(world, i + 21, j + 27, k + 12, Blocks.spruce_stairs, 0);
		setBlock(world, i + 21, j + 27, k + 13, Blocks.spruce_stairs, 0);
		setBlock(world, i + 21, j + 27, k + 14, Blocks.spruce_stairs, 0);
		setBlock(world, i + 22, j + 28, k + 10, Blocks.spruce_stairs, 0);
		setBlock(world, i + 22, j + 28, k + 11, Blocks.spruce_stairs, 0);
		setBlock(world, i + 22, j + 28, k + 12, Blocks.spruce_stairs, 0);
		setBlock(world, i + 22, j + 28, k + 13, Blocks.spruce_stairs, 0);
		setBlock(world, i + 22, j + 28, k + 14, Blocks.spruce_stairs, 0);
		setBlock(world, i + 23, j + 29, k + 10, Blocks.spruce_stairs, 0);
		setBlock(world, i + 23, j + 29, k + 11, Blocks.spruce_stairs, 0);
		setBlock(world, i + 23, j + 29, k + 12, Blocks.spruce_stairs, 0);
		setBlock(world, i + 23, j + 29, k + 13, Blocks.spruce_stairs, 0);
		setBlock(world, i + 23, j + 29, k + 14, Blocks.spruce_stairs, 0);
		setBlock(world, i + 24, j + 23, k + 2, Blocks.fence, 0);
		setBlock(world, i + 24, j + 25, k + 4, Blocks.fence, 0);
		setBlock(world, i + 24, j + 25, k + 5, Blocks.fence, 0);
		setBlock(world, i + 24, j + 30, k + 10, Blocks.spruce_stairs, 0);
		setBlock(world, i + 24, j + 30, k + 11, Blocks.spruce_stairs, 0);
		setBlock(world, i + 24, j + 30, k + 12, Blocks.spruce_stairs, 0);
		setBlock(world, i + 24, j + 30, k + 13, Blocks.spruce_stairs, 0);
		setBlock(world, i + 24, j + 30, k + 14, Blocks.spruce_stairs, 0);
		setBlock(world, i + 25, j + 23, k + 1, Blocks.fence, 0);
		setBlock(world, i + 25, j + 23, k + 2, Blocks.fence, 0);
		setBlock(world, i + 25, j + 31, k + 10, Blocks.spruce_stairs, 0);
		setBlock(world, i + 25, j + 31, k + 11, Blocks.spruce_stairs, 0);
		setBlock(world, i + 25, j + 31, k + 12, Blocks.spruce_stairs, 0);
		setBlock(world, i + 25, j + 31, k + 13, Blocks.spruce_stairs, 0);
		setBlock(world, i + 25, j + 31, k + 14, Blocks.spruce_stairs, 0);
		setBlock(world, i + 26, j + 23, k + 0, Blocks.fence, 0);
		setBlock(world, i + 26, j + 23, k + 1, Blocks.fence, 0);
		setBlock(world, i + 26, j + 32, k + 10, Blocks.spruce_stairs, 0);
		setBlock(world, i + 26, j + 32, k + 11, Blocks.spruce_stairs, 0);
		setBlock(world, i + 26, j + 32, k + 12, Blocks.spruce_stairs, 0);
		setBlock(world, i + 26, j + 32, k + 13, Blocks.spruce_stairs, 0);
		setBlock(world, i + 26, j + 32, k + 14, Blocks.spruce_stairs, 0);
		setBlock(world, i + 26, j + 69, k + 31, Blocks.fence, 0);
		setBlock(world, i + 27, j + 33, k + 10, Blocks.spruce_stairs, 0);
		setBlock(world, i + 27, j + 33, k + 11, Blocks.spruce_stairs, 0);
		setBlock(world, i + 27, j + 33, k + 12, Blocks.spruce_stairs, 0);
		setBlock(world, i + 27, j + 33, k + 13, Blocks.spruce_stairs, 0);
		setBlock(world, i + 27, j + 33, k + 14, Blocks.spruce_stairs, 0);
		setBlock(world, i + 27, j + 69, k + 29, Blocks.fence, 0);
		setBlock(world, i + 27, j + 69, k + 30, Blocks.fence, 0);
		setBlock(world, i + 27, j + 69, k + 31, Blocks.fence, 0);
		setBlock(world, i + 28, j + 25, k + 0, Blocks.fence, 0);
		setBlock(world, i + 28, j + 34, k + 10, Blocks.spruce_stairs, 0);
		setBlock(world, i + 28, j + 34, k + 11, Blocks.spruce_stairs, 0);
		setBlock(world, i + 28, j + 34, k + 12, Blocks.spruce_stairs, 0);
		setBlock(world, i + 28, j + 34, k + 13, Blocks.spruce_stairs, 0);
		setBlock(world, i + 28, j + 34, k + 14, Blocks.spruce_stairs, 0);
		setBlock(world, i + 28, j + 69, k + 28, Blocks.fence, 0);
		setBlock(world, i + 28, j + 69, k + 29, Blocks.fence, 0);
		setBlock(world, i + 29, j + 25, k + 0, Blocks.fence, 0);
		setBlock(world, i + 29, j + 35, k + 10, Blocks.spruce_stairs, 0);
		setBlock(world, i + 29, j + 35, k + 11, Blocks.spruce_stairs, 0);
		setBlock(world, i + 29, j + 35, k + 12, Blocks.spruce_stairs, 0);
		setBlock(world, i + 29, j + 35, k + 13, Blocks.spruce_stairs, 0);
		setBlock(world, i + 29, j + 35, k + 14, Blocks.spruce_stairs, 0);
		setBlock(world, i + 29, j + 66, k + 30, Blocks.fence, 0);
		setBlock(world, i + 29, j + 66, k + 31, Blocks.fence, 0);
		setBlock(world, i + 29, j + 69, k + 27, Blocks.fence, 0);
		setBlock(world, i + 29, j + 69, k + 28, Blocks.fence, 0);
		setBlock(world, i + 30, j + 38, k + 9, Blocks.fence, 0);
		setBlock(world, i + 30, j + 38, k + 15, Blocks.fence, 0);
		setBlock(world, i + 31, j + 38, k + 9, Blocks.fence, 0);
		setBlock(world, i + 31, j + 38, k + 15, Blocks.fence, 0);
		setBlock(world, i + 0, j + 0, k + 6, Blocks.log, 3);
		world.setBlockMetadataWithNotify(i + 0, j + 0, k + 6, 3, 2);
		setBlock(world, i + 0, j + 0, k + 7, Blocks.log, 3);
		world.setBlockMetadataWithNotify(i + 0, j + 0, k + 7, 3, 2);
		setBlock(world, i + 0, j + 0, k + 8, Blocks.log, 3);
		world.setBlockMetadataWithNotify(i + 0, j + 0, k + 8, 3, 2);
		setBlock(world, i + 0, j + 0, k + 9, Blocks.log, 3);
		world.setBlockMetadataWithNotify(i + 0, j + 0, k + 9, 3, 2);
		setBlock(world, i + 0, j + 0, k + 10, Blocks.log, 3);
		world.setBlockMetadataWithNotify(i + 0, j + 0, k + 10, 3, 2);
		setBlock(world, i + 0, j + 0, k + 11, Blocks.log, 3);
		world.setBlockMetadataWithNotify(i + 0, j + 0, k + 11, 3, 2);
		setBlock(world, i + 0, j + 1, k + 9, Blocks.log, 3);
		world.setBlockMetadataWithNotify(i + 0, j + 1, k + 9, 3, 2);
		setBlock(world, i + 0, j + 1, k + 10, Blocks.log, 3);
		world.setBlockMetadataWithNotify(i + 0, j + 1, k + 10, 3, 2);
		setBlock(world, i + 0, j + 1, k + 11, Blocks.log, 3);
		world.setBlockMetadataWithNotify(i + 0, j + 1, k + 11, 3, 2);
		setBlock(world, i + 0, j + 2, k + 8, Blocks.log, 3);
		world.setBlockMetadataWithNotify(i + 0, j + 2, k + 8, 3, 2);
		setBlock(world, i + 0, j + 2, k + 9, Blocks.log, 3);
		world.setBlockMetadataWithNotify(i + 0, j + 2, k + 9, 3, 2);
		setBlock(world, i + 0, j + 2, k + 10, Blocks.log, 3);
		world.setBlockMetadataWithNotify(i + 0, j + 2, k + 10, 3, 2);
		setBlock(world, i + 0, j + 18, k + 3, Blocks.leaves, 7);
		world.setBlockMetadataWithNotify(i + 0, j + 18, k + 3, 7, 2);
		setBlock(world, i + 0, j + 18, k + 4, Blocks.leaves, 7);
		world.setBlockMetadataWithNotify(i + 0, j + 18, k + 4, 7, 2);
		setBlock(world, i + 0, j + 18, k + 5, Blocks.leaves, 7);
		world.setBlockMetadataWithNotify(i + 0, j + 18, k + 5, 7, 2);
		setBlock(world, i + 0, j + 19, k + 4, Blocks.leaves, 7);
		world.setBlockMetadataWithNotify(i + 0, j + 19, k + 4, 7, 2);
		setBlock(world, i + 0, j + 21, k + 5, Blocks.log, 3);
		world.setBlockMetadataWithNotify(i + 0, j + 21, k + 5, 3, 2);
		setBlock(world, i + 0, j + 21, k + 11, Blocks.log, 3);
		world.setBlockMetadataWithNotify(i + 0, j + 21, k + 11, 3, 2);
		setBlock(world, i + 0, j + 22, k + 10, Blocks.log, 3);
		world.setBlockMetadataWithNotify(i + 0, j + 22, k + 10, 3, 2);
		setBlock(world, i + 0, j + 22, k + 11, Blocks.log, 3);
		world.setBlockMetadataWithNotify(i + 0, j + 22, k + 11, 3, 2);
		setBlock(world, i + 0, j + 22, k + 12, Blocks.log, 3);
		world.setBlockMetadataWithNotify(i + 0, j + 22, k + 12, 3, 2);
		setBlock(world, i + 0, j + 23, k + 11, Blocks.log, 3);
		world.setBlockMetadataWithNotify(i + 0, j + 23, k + 11, 3, 2);
		setBlock(world, i + 0, j + 23, k + 15, Blocks.log, 3);
		world.setBlockMetadataWithNotify(i + 0, j + 23, k + 15, 3, 2);
		setBlock(world, i + 0, j + 23, k + 16, Blocks.log, 3);
		world.setBlockMetadataWithNotify(i + 0, j + 23, k + 16, 3, 2);
		setBlock(world, i + 0, j + 23, k + 19, Blocks.log, 3);
		world.setBlockMetadataWithNotify(i + 0, j + 23, k + 19, 3, 2);
		setBlock(world, i + 0, j + 24, k + 4, Blocks.log, 3);
		world.setBlockMetadataWithNotify(i + 0, j + 24, k + 4, 3, 2);
		setBlock(world, i + 0, j + 24, k + 6, Blocks.leaves, 7);
		world.setBlockMetadataWithNotify(i + 0, j + 24, k + 6, 7, 2);
		setBlock(world, i + 0, j + 24, k + 7, Blocks.leaves, 7);
		world.setBlockMetadataWithNotify(i + 0, j + 24, k + 7, 7, 2);
		setBlock(world, i + 0, j + 24, k + 8, Blocks.log, 3);
		world.setBlockMetadataWithNotify(i + 0, j + 24, k + 8, 3, 2);
		setBlock(world, i + 0, j + 24, k + 9, Blocks.leaves, 7);
		world.setBlockMetadataWithNotify(i + 0, j + 24, k + 9, 7, 2);
		setBlock(world, i + 0, j + 24, k + 10, Blocks.leaves, 7);
		world.setBlockMetadataWithNotify(i + 0, j + 24, k + 10, 7, 2);
		setBlock(world, i + 0, j + 24, k + 14, Blocks.log, 3);
		world.setBlockMetadataWithNotify(i + 0, j + 24, k + 14, 3, 2);
		setBlock(world, i + 0, j + 24, k + 15, Blocks.log, 3);
		world.setBlockMetadataWithNotify(i + 0, j + 24, k + 15, 3, 2);
		setBlock(world, i + 0, j + 24, k + 16, Blocks.log, 3);
		world.setBlockMetadataWithNotify(i + 0, j + 24, k + 16, 3, 2);
		setBlock(world, i + 0, j + 24, k + 17, Blocks.log, 3);
		world.setBlockMetadataWithNotify(i + 0, j + 24, k + 17, 3, 2);
		setBlock(world, i + 0, j + 24, k + 18, Blocks.log, 3);
		world.setBlockMetadataWithNotify(i + 0, j + 24, k + 18, 3, 2);
		setBlock(world, i + 0, j + 25, k + 6, Blocks.leaves, 7);
		world.setBlockMetadataWithNotify(i + 0, j + 25, k + 6, 7, 2);
		setBlock(world, i + 0, j + 25, k + 7, Blocks.leaves, 7);
		world.setBlockMetadataWithNotify(i + 0, j + 25, k + 7, 7, 2);
		setBlock(world, i + 0, j + 25, k + 8, Blocks.leaves, 7);
		world.setBlockMetadataWithNotify(i + 0, j + 25, k + 8, 7, 2);
		setBlock(world, i + 0, j + 25, k + 9, Blocks.leaves, 7);
		world.setBlockMetadataWithNotify(i + 0, j + 25, k + 9, 7, 2);
		setBlock(world, i + 0, j + 25, k + 10, Blocks.log, 3);
		world.setBlockMetadataWithNotify(i + 0, j + 25, k + 10, 3, 2);
		setBlock(world, i + 0, j + 25, k + 15, Blocks.log, 3);
		world.setBlockMetadataWithNotify(i + 0, j + 25, k + 15, 3, 2);
		setBlock(world, i + 0, j + 25, k + 16, Blocks.log, 3);
		world.setBlockMetadataWithNotify(i + 0, j + 25, k + 16, 3, 2);
		setBlock(world, i + 0, j + 25, k + 19, Blocks.log, 3);
		world.setBlockMetadataWithNotify(i + 0, j + 25, k + 19, 3, 2);
		setBlock(world, i + 0, j + 26, k + 7, Blocks.leaves, 7);
		world.setBlockMetadataWithNotify(i + 0, j + 26, k + 7, 7, 2);
		setBlock(world, i + 0, j + 26, k + 8, Blocks.leaves, 7);
		world.setBlockMetadataWithNotify(i + 0, j + 26, k + 8, 7, 2);
		setBlock(world, i + 0, j + 26, k + 9, Blocks.leaves, 7);
		world.setBlockMetadataWithNotify(i + 0, j + 26, k + 9, 7, 2);
		setBlock(world, i + 0, j + 27, k + 4, Blocks.log, 3);
		world.setBlockMetadataWithNotify(i + 0, j + 27, k + 4, 3, 2);
		setBlock(world, i + 0, j + 27, k + 8, Blocks.leaves, 7);
		world.setBlockMetadataWithNotify(i + 0, j + 27, k + 8, 7, 2);
		setBlock(world, i + 0, j + 31, k + 7, Blocks.log, 3);
		world.setBlockMetadataWithNotify(i + 0, j + 31, k + 7, 3, 2);
		setBlock(world, i + 0, j + 31, k + 19, Blocks.log, 3);
		world.setBlockMetadataWithNotify(i + 0, j + 31, k + 19, 3, 2);
		setBlock(world, i + 0, j + 32, k + 14, Blocks.log, 3);
		world.setBlockMetadataWithNotify(i + 0, j + 32, k + 14, 3, 2);
		setBlock(world, i + 0, j + 33, k + 13, Blocks.log, 3);
		world.setBlockMetadataWithNotify(i + 0, j + 33, k + 13, 3, 2);
		setBlock(world, i + 0, j + 34, k + 12, Blocks.leaves, 7);
		world.setBlockMetadataWithNotify(i + 0, j + 34, k + 12, 7, 2);
		setBlock(world, i + 0, j + 34, k + 13, Blocks.leaves, 7);
		world.setBlockMetadataWithNotify(i + 0, j + 34, k + 13, 7, 2);
		setBlock(world, i + 0, j + 34, k + 14, Blocks.leaves, 7);
		world.setBlockMetadataWithNotify(i + 0, j + 34, k + 14, 7, 2);
		setBlock(world, i + 0, j + 35, k + 13, Blocks.leaves, 7);
		world.setBlockMetadataWithNotify(i + 0, j + 35, k + 13, 7, 2);
		setBlock(world, i + 0, j + 35, k + 18, Blocks.log, 1);
		world.setBlockMetadataWithNotify(i + 0, j + 35, k + 18, 1, 2);
		setBlock(world, i + 0, j + 35, k + 19, Blocks.log, 1);
		world.setBlockMetadataWithNotify(i + 0, j + 35, k + 19, 1, 2);
		setBlock(world, i + 0, j + 35, k + 20, Blocks.log, 1);
		world.setBlockMetadataWithNotify(i + 0, j + 35, k + 20, 1, 2);
		setBlock(world, i + 0, j + 36, k + 17, Blocks.log, 1);
		world.setBlockMetadataWithNotify(i + 0, j + 36, k + 17, 1, 2);
		setBlock(world, i + 0, j + 36, k + 18, Blocks.log, 1);
		world.setBlockMetadataWithNotify(i + 0, j + 36, k + 18, 1, 2);
		setBlock(world, i + 0, j + 36, k + 19, Blocks.log, 1);
		world.setBlockMetadataWithNotify(i + 0, j + 36, k + 19, 1, 2);
		setBlock(world, i + 0, j + 36, k + 20, Blocks.log, 1);
		world.setBlockMetadataWithNotify(i + 0, j + 36, k + 20, 1, 2);
		setBlock(world, i + 0, j + 36, k + 21, Blocks.log, 1);
		world.setBlockMetadataWithNotify(i + 0, j + 36, k + 21, 1, 2);
		setBlock(world, i + 0, j + 37, k + 17, Blocks.leaves, 15);
		world.setBlockMetadataWithNotify(i + 0, j + 37, k + 17, 15, 2);
		setBlock(world, i + 0, j + 37, k + 18, Blocks.log, 1);
		world.setBlockMetadataWithNotify(i + 0, j + 37, k + 18, 1, 2);
		setBlock(world, i + 0, j + 37, k + 19, Blocks.log, 1);
		world.setBlockMetadataWithNotify(i + 0, j + 37, k + 19, 1, 2);
		setBlock(world, i + 0, j + 37, k + 20, Blocks.log, 1);
		world.setBlockMetadataWithNotify(i + 0, j + 37, k + 20, 1, 2);
		setBlock(world, i + 0, j + 37, k + 27, Blocks.vine, 12);
		world.setBlockMetadataWithNotify(i + 0, j + 37, k + 27, 12, 2);
		setBlock(world, i + 0, j + 37, k + 29, Blocks.vine, 11);
		world.setBlockMetadataWithNotify(i + 0, j + 37, k + 29, 11, 2);
		setBlock(world, i + 0, j + 38, k + 6, Blocks.leaves, 15);
		world.setBlockMetadataWithNotify(i + 0, j + 38, k + 6, 15, 2);
		setBlock(world, i + 0, j + 38, k + 7, Blocks.leaves, 15);
		world.setBlockMetadataWithNotify(i + 0, j + 38, k + 7, 15, 2);
		setBlock(world, i + 0, j + 38, k + 8, Blocks.log, 3);
		world.setBlockMetadataWithNotify(i + 0, j + 38, k + 8, 3, 2);
		setBlock(world, i + 0, j + 38, k + 9, Blocks.leaves, 15);
		world.setBlockMetadataWithNotify(i + 0, j + 38, k + 9, 15, 2);
		setBlock(world, i + 0, j + 38, k + 10, Blocks.log, 3);
		world.setBlockMetadataWithNotify(i + 0, j + 38, k + 10, 3, 2);
		setBlock(world, i + 0, j + 38, k + 15, Blocks.log, 1);
		world.setBlockMetadataWithNotify(i + 0, j + 38, k + 15, 1, 2);
		setBlock(world, i + 0, j + 38, k + 16, Blocks.log, 1);
		world.setBlockMetadataWithNotify(i + 0, j + 38, k + 16, 1, 2);
		setBlock(world, i + 0, j + 38, k + 17, Blocks.log, 1);
		world.setBlockMetadataWithNotify(i + 0, j + 38, k + 17, 1, 2);
		setBlock(world, i + 0, j + 38, k + 18, Blocks.log, 1);
		world.setBlockMetadataWithNotify(i + 0, j + 38, k + 18, 1, 2);
		setBlock(world, i + 0, j + 38, k + 19, Blocks.log, 1);
		world.setBlockMetadataWithNotify(i + 0, j + 38, k + 19, 1, 2);
		setBlock(world, i + 0, j + 38, k + 20, Blocks.log, 1);
		world.setBlockMetadataWithNotify(i + 0, j + 38, k + 20, 1, 2);
		setBlock(world, i + 0, j + 38, k + 21, Blocks.log, 1);
		world.setBlockMetadataWithNotify(i + 0, j + 38, k + 21, 1, 2);
		setBlock(world, i + 0, j + 38, k + 22, Blocks.log, 1);
		world.setBlockMetadataWithNotify(i + 0, j + 38, k + 22, 1, 2);
		setBlock(world, i + 0, j + 38, k + 27, Blocks.vine, 13);
		world.setBlockMetadataWithNotify(i + 0, j + 38, k + 27, 13, 2);
		setBlock(world, i + 0, j + 38, k + 29, Blocks.vine, 15);
		world.setBlockMetadataWithNotify(i + 0, j + 38, k + 29, 15, 2);
		setBlock(world, i + 0, j + 39, k + 2, Blocks.leaves, 15);
		world.setBlockMetadataWithNotify(i + 0, j + 39, k + 2, 15, 2);
		setBlock(world, i + 0, j + 39, k + 3, Blocks.leaves, 15);
		world.setBlockMetadataWithNotify(i + 0, j + 39, k + 3, 15, 2);
		setBlock(world, i + 0, j + 39, k + 15, Blocks.log, 1);
		world.setBlockMetadataWithNotify(i + 0, j + 39, k + 15, 1, 2);
		setBlock(world, i + 0, j + 39, k + 16, Blocks.log, 1);
		world.setBlockMetadataWithNotify(i + 0, j + 39, k + 16, 1, 2);
		setBlock(world, i + 0, j + 39, k + 17, Blocks.log, 1);
		world.setBlockMetadataWithNotify(i + 0, j + 39, k + 17, 1, 2);
		setBlock(world, i + 0, j + 39, k + 18, Blocks.log, 1);
		world.setBlockMetadataWithNotify(i + 0, j + 39, k + 18, 1, 2);
		setBlock(world, i + 0, j + 39, k + 19, Blocks.log, 1);
		world.setBlockMetadataWithNotify(i + 0, j + 39, k + 19, 1, 2);
		setBlock(world, i + 0, j + 39, k + 20, Blocks.log, 1);
		world.setBlockMetadataWithNotify(i + 0, j + 39, k + 20, 1, 2);
		setBlock(world, i + 0, j + 39, k + 21, Blocks.log, 1);
		world.setBlockMetadataWithNotify(i + 0, j + 39, k + 21, 1, 2);
		setBlock(world, i + 0, j + 39, k + 22, Blocks.log, 1);
		world.setBlockMetadataWithNotify(i + 0, j + 39, k + 22, 1, 2);
		setBlock(world, i + 0, j + 39, k + 27, Blocks.vine, 15);
		world.setBlockMetadataWithNotify(i + 0, j + 39, k + 27, 15, 2);
		setBlock(world, i + 0, j + 39, k + 28, Blocks.vine, 15);
		world.setBlockMetadataWithNotify(i + 0, j + 39, k + 28, 15, 2);
		setBlock(world, i + 0, j + 39, k + 29, Blocks.vine, 15);
		world.setBlockMetadataWithNotify(i + 0, j + 39, k + 29, 15, 2);
		setBlock(world, i + 0, j + 39, k + 30, Blocks.vine, 15);
		world.setBlockMetadataWithNotify(i + 0, j + 39, k + 30, 15, 2);
		setBlock(world, i + 0, j + 39, k + 31, Blocks.vine, 15);
		world.setBlockMetadataWithNotify(i + 0, j + 39, k + 31, 15, 2);
		setBlock(world, i + 0, j + 40, k + 0, Blocks.planks, 5);
		world.setBlockMetadataWithNotify(i + 0, j + 40, k + 0, 5, 2);
		setBlock(world, i + 0, j + 40, k + 1, Blocks.planks, 5);
		world.setBlockMetadataWithNotify(i + 0, j + 40, k + 1, 5, 2);
		setBlock(world, i + 0, j + 40, k + 2, Blocks.planks, 5);
		world.setBlockMetadataWithNotify(i + 0, j + 40, k + 2, 5, 2);
		setBlock(world, i + 0, j + 40, k + 3, Blocks.planks, 5);
		world.setBlockMetadataWithNotify(i + 0, j + 40, k + 3, 5, 2);
		setBlock(world, i + 0, j + 40, k + 4, Blocks.planks, 5);
		world.setBlockMetadataWithNotify(i + 0, j + 40, k + 4, 5, 2);
		setBlock(world, i + 0, j + 40, k + 5, Blocks.planks, 5);
		world.setBlockMetadataWithNotify(i + 0, j + 40, k + 5, 5, 2);
		setBlock(world, i + 0, j + 40, k + 6, Blocks.planks, 5);
		world.setBlockMetadataWithNotify(i + 0, j + 40, k + 6, 5, 2);
		setBlock(world, i + 0, j + 40, k + 7, Blocks.planks, 5);
		world.setBlockMetadataWithNotify(i + 0, j + 40, k + 7, 5, 2);
		setBlock(world, i + 0, j + 40, k + 8, Blocks.planks, 5);
		world.setBlockMetadataWithNotify(i + 0, j + 40, k + 8, 5, 2);
		setBlock(world, i + 0, j + 40, k + 9, Blocks.planks, 5);
		world.setBlockMetadataWithNotify(i + 0, j + 40, k + 9, 5, 2);
		setBlock(world, i + 0, j + 40, k + 10, Blocks.planks, 5);
		world.setBlockMetadataWithNotify(i + 0, j + 40, k + 10, 5, 2);
		setBlock(world, i + 0, j + 40, k + 11, Blocks.planks, 5);
		world.setBlockMetadataWithNotify(i + 0, j + 40, k + 11, 5, 2);
		setBlock(world, i + 0, j + 40, k + 12, Blocks.log, 1);
		world.setBlockMetadataWithNotify(i + 0, j + 40, k + 12, 1, 2);
		setBlock(world, i + 0, j + 40, k + 13, Blocks.planks, 5);
		world.setBlockMetadataWithNotify(i + 0, j + 40, k + 13, 5, 2);
		setBlock(world, i + 0, j + 40, k + 14, Blocks.planks, 5);
		world.setBlockMetadataWithNotify(i + 0, j + 40, k + 14, 5, 2);
		setBlock(world, i + 0, j + 40, k + 15, Blocks.log, 1);
		world.setBlockMetadataWithNotify(i + 0, j + 40, k + 15, 1, 2);
		setBlock(world, i + 0, j + 40, k + 16, Blocks.planks, 5);
		world.setBlockMetadataWithNotify(i + 0, j + 40, k + 16, 5, 2);
		setBlock(world, i + 0, j + 40, k + 17, Blocks.planks, 5);
		world.setBlockMetadataWithNotify(i + 0, j + 40, k + 17, 5, 2);
		setBlock(world, i + 0, j + 40, k + 18, Blocks.log, 1);
		world.setBlockMetadataWithNotify(i + 0, j + 40, k + 18, 1, 2);
		setBlock(world, i + 0, j + 40, k + 19, Blocks.planks, 5);
		world.setBlockMetadataWithNotify(i + 0, j + 40, k + 19, 5, 2);
		setBlock(world, i + 0, j + 40, k + 20, Blocks.planks, 5);
		world.setBlockMetadataWithNotify(i + 0, j + 40, k + 20, 5, 2);
		setBlock(world, i + 0, j + 40, k + 21, Blocks.log, 1);
		world.setBlockMetadataWithNotify(i + 0, j + 40, k + 21, 1, 2);
		setBlock(world, i + 0, j + 40, k + 22, Blocks.planks, 5);
		world.setBlockMetadataWithNotify(i + 0, j + 40, k + 22, 5, 2);
		setBlock(world, i + 0, j + 40, k + 23, Blocks.planks, 5);
		world.setBlockMetadataWithNotify(i + 0, j + 40, k + 23, 5, 2);
		setBlock(world, i + 0, j + 40, k + 24, Blocks.log, 1);
		world.setBlockMetadataWithNotify(i + 0, j + 40, k + 24, 1, 2);
		setBlock(world, i + 0, j + 40, k + 25, Blocks.planks, 5);
		world.setBlockMetadataWithNotify(i + 0, j + 40, k + 25, 5, 2);
		setBlock(world, i + 0, j + 40, k + 26, Blocks.planks, 5);
		world.setBlockMetadataWithNotify(i + 0, j + 40, k + 26, 5, 2);
		setBlock(world, i + 0, j + 40, k + 27, Blocks.planks, 5);
		world.setBlockMetadataWithNotify(i + 0, j + 40, k + 27, 5, 2);
		setBlock(world, i + 0, j + 40, k + 28, Blocks.planks, 5);
		world.setBlockMetadataWithNotify(i + 0, j + 40, k + 28, 5, 2);
		setBlock(world, i + 0, j + 40, k + 29, Blocks.planks, 5);
		world.setBlockMetadataWithNotify(i + 0, j + 40, k + 29, 5, 2);
		setBlock(world, i + 0, j + 40, k + 30, Blocks.planks, 5);
		world.setBlockMetadataWithNotify(i + 0, j + 40, k + 30, 5, 2);
		setBlock(world, i + 0, j + 40, k + 31, Blocks.planks, 5);
		world.setBlockMetadataWithNotify(i + 0, j + 40, k + 31, 5, 2);
		setBlock(world, i + 0, j + 41, k + 17, Blocks.chest, 2);
		LootGenUtils.fillLootChest(world.provider.dimensionId, world.rand, (TileEntityChest)world.getTileEntity(i + 0, j + 41, k + 17));
		world.setBlockMetadataWithNotify(i + 0, j + 41, k + 17, 2, 2);
		setBlock(world, i + 0, j + 43, k + 10, Blocks.torch, 1);
		world.setBlockMetadataWithNotify(i + 0, j + 43, k + 10, 1, 2);
		setBlock(world, i + 0, j + 43, k + 18, Blocks.torch, 2);
		world.setBlockMetadataWithNotify(i + 0, j + 43, k + 18, 2, 2);
		setBlock(world, i + 0, j + 43, k + 26, Blocks.torch, 1);
		world.setBlockMetadataWithNotify(i + 0, j + 43, k + 26, 1, 2);
		setBlock(world, i + 0, j + 44, k + 9, Blocks.log, 1);
		world.setBlockMetadataWithNotify(i + 0, j + 44, k + 9, 1, 2);
		setBlock(world, i + 0, j + 44, k + 10, Blocks.log, 1);
		world.setBlockMetadataWithNotify(i + 0, j + 44, k + 10, 1, 2);
		setBlock(world, i + 0, j + 44, k + 11, Blocks.log, 1);
		world.setBlockMetadataWithNotify(i + 0, j + 44, k + 11, 1, 2);
		setBlock(world, i + 0, j + 44, k + 12, Blocks.log, 1);
		world.setBlockMetadataWithNotify(i + 0, j + 44, k + 12, 1, 2);
		setBlock(world, i + 0, j + 44, k + 13, Blocks.log, 1);
		world.setBlockMetadataWithNotify(i + 0, j + 44, k + 13, 1, 2);
		setBlock(world, i + 0, j + 44, k + 23, Blocks.log, 1);
		world.setBlockMetadataWithNotify(i + 0, j + 44, k + 23, 1, 2);
		setBlock(world, i + 0, j + 44, k + 24, Blocks.log, 1);
		world.setBlockMetadataWithNotify(i + 0, j + 44, k + 24, 1, 2);
		setBlock(world, i + 0, j + 44, k + 25, Blocks.log, 1);
		world.setBlockMetadataWithNotify(i + 0, j + 44, k + 25, 1, 2);
		setBlock(world, i + 0, j + 44, k + 26, Blocks.log, 1);
		world.setBlockMetadataWithNotify(i + 0, j + 44, k + 26, 1, 2);
		setBlock(world, i + 0, j + 44, k + 27, Blocks.log, 1);
		world.setBlockMetadataWithNotify(i + 0, j + 44, k + 27, 1, 2);
		setBlock(world, i + 0, j + 45, k + 9, Blocks.log, 3);
		world.setBlockMetadataWithNotify(i + 0, j + 45, k + 9, 3, 2);
		setBlock(world, i + 0, j + 45, k + 10, Blocks.log, 1);
		world.setBlockMetadataWithNotify(i + 0, j + 45, k + 10, 1, 2);
		setBlock(world, i + 0, j + 45, k + 11, Blocks.log, 1);
		world.setBlockMetadataWithNotify(i + 0, j + 45, k + 11, 1, 2);
		setBlock(world, i + 0, j + 45, k + 12, Blocks.log, 1);
		world.setBlockMetadataWithNotify(i + 0, j + 45, k + 12, 1, 2);
		setBlock(world, i + 0, j + 45, k + 13, Blocks.log, 1);
		world.setBlockMetadataWithNotify(i + 0, j + 45, k + 13, 1, 2);
		setBlock(world, i + 0, j + 45, k + 14, Blocks.log, 1);
		world.setBlockMetadataWithNotify(i + 0, j + 45, k + 14, 1, 2);
		setBlock(world, i + 0, j + 45, k + 22, Blocks.log, 1);
		world.setBlockMetadataWithNotify(i + 0, j + 45, k + 22, 1, 2);
		setBlock(world, i + 0, j + 45, k + 23, Blocks.log, 1);
		world.setBlockMetadataWithNotify(i + 0, j + 45, k + 23, 1, 2);
		setBlock(world, i + 0, j + 45, k + 24, Blocks.log, 1);
		world.setBlockMetadataWithNotify(i + 0, j + 45, k + 24, 1, 2);
		setBlock(world, i + 0, j + 45, k + 25, Blocks.log, 1);
		world.setBlockMetadataWithNotify(i + 0, j + 45, k + 25, 1, 2);
		setBlock(world, i + 0, j + 45, k + 26, Blocks.log, 1);
		world.setBlockMetadataWithNotify(i + 0, j + 45, k + 26, 1, 2);
		setBlock(world, i + 0, j + 46, k + 9, Blocks.leaves, 15);
		world.setBlockMetadataWithNotify(i + 0, j + 46, k + 9, 15, 2);
		setBlock(world, i + 0, j + 46, k + 10, Blocks.log, 1);
		world.setBlockMetadataWithNotify(i + 0, j + 46, k + 10, 1, 2);
		setBlock(world, i + 0, j + 46, k + 11, Blocks.log, 1);
		world.setBlockMetadataWithNotify(i + 0, j + 46, k + 11, 1, 2);
		setBlock(world, i + 0, j + 46, k + 12, Blocks.log, 1);
		world.setBlockMetadataWithNotify(i + 0, j + 46, k + 12, 1, 2);
		setBlock(world, i + 0, j + 46, k + 13, Blocks.log, 1);
		world.setBlockMetadataWithNotify(i + 0, j + 46, k + 13, 1, 2);
		setBlock(world, i + 0, j + 46, k + 14, Blocks.log, 1);
		world.setBlockMetadataWithNotify(i + 0, j + 46, k + 14, 1, 2);
		setBlock(world, i + 0, j + 46, k + 15, Blocks.log, 1);
		world.setBlockMetadataWithNotify(i + 0, j + 46, k + 15, 1, 2);
		setBlock(world, i + 0, j + 46, k + 17, Blocks.log, 1);
		world.setBlockMetadataWithNotify(i + 0, j + 46, k + 17, 1, 2);
		setBlock(world, i + 0, j + 46, k + 18, Blocks.log, 1);
		world.setBlockMetadataWithNotify(i + 0, j + 46, k + 18, 1, 2);
		setBlock(world, i + 0, j + 46, k + 19, Blocks.log, 1);
		world.setBlockMetadataWithNotify(i + 0, j + 46, k + 19, 1, 2);
		setBlock(world, i + 0, j + 46, k + 21, Blocks.log, 1);
		world.setBlockMetadataWithNotify(i + 0, j + 46, k + 21, 1, 2);
		setBlock(world, i + 0, j + 46, k + 22, Blocks.log, 1);
		world.setBlockMetadataWithNotify(i + 0, j + 46, k + 22, 1, 2);
		setBlock(world, i + 0, j + 46, k + 23, Blocks.log, 1);
		world.setBlockMetadataWithNotify(i + 0, j + 46, k + 23, 1, 2);
		setBlock(world, i + 0, j + 46, k + 24, Blocks.log, 1);
		world.setBlockMetadataWithNotify(i + 0, j + 46, k + 24, 1, 2);
		setBlock(world, i + 0, j + 46, k + 25, Blocks.log, 1);
		world.setBlockMetadataWithNotify(i + 0, j + 46, k + 25, 1, 2);
		setBlock(world, i + 0, j + 46, k + 26, Blocks.log, 1);
		world.setBlockMetadataWithNotify(i + 0, j + 46, k + 26, 1, 2);
		setBlock(world, i + 0, j + 47, k + 7, Blocks.leaves, 15);
		world.setBlockMetadataWithNotify(i + 0, j + 47, k + 7, 15, 2);
		setBlock(world, i + 0, j + 47, k + 8, Blocks.leaves, 15);
		world.setBlockMetadataWithNotify(i + 0, j + 47, k + 8, 15, 2);
		setBlock(world, i + 0, j + 47, k + 9, Blocks.log, 3);
		world.setBlockMetadataWithNotify(i + 0, j + 47, k + 9, 3, 2);
		setBlock(world, i + 0, j + 47, k + 10, Blocks.leaves, 15);
		world.setBlockMetadataWithNotify(i + 0, j + 47, k + 10, 15, 2);
		setBlock(world, i + 0, j + 47, k + 11, Blocks.log, 1);
		world.setBlockMetadataWithNotify(i + 0, j + 47, k + 11, 1, 2);
		setBlock(world, i + 0, j + 47, k + 12, Blocks.log, 1);
		world.setBlockMetadataWithNotify(i + 0, j + 47, k + 12, 1, 2);
		setBlock(world, i + 0, j + 47, k + 13, Blocks.log, 1);
		world.setBlockMetadataWithNotify(i + 0, j + 47, k + 13, 1, 2);
		setBlock(world, i + 0, j + 47, k + 14, Blocks.log, 1);
		world.setBlockMetadataWithNotify(i + 0, j + 47, k + 14, 1, 2);
		setBlock(world, i + 0, j + 47, k + 15, Blocks.log, 1);
		world.setBlockMetadataWithNotify(i + 0, j + 47, k + 15, 1, 2);
		setBlock(world, i + 0, j + 47, k + 16, Blocks.log, 1);
		world.setBlockMetadataWithNotify(i + 0, j + 47, k + 16, 1, 2);
		setBlock(world, i + 0, j + 47, k + 17, Blocks.log, 1);
		world.setBlockMetadataWithNotify(i + 0, j + 47, k + 17, 1, 2);
		setBlock(world, i + 0, j + 47, k + 18, Blocks.log, 1);
		world.setBlockMetadataWithNotify(i + 0, j + 47, k + 18, 1, 2);
		setBlock(world, i + 0, j + 47, k + 19, Blocks.log, 1);
		world.setBlockMetadataWithNotify(i + 0, j + 47, k + 19, 1, 2);
		setBlock(world, i + 0, j + 47, k + 20, Blocks.log, 1);
		world.setBlockMetadataWithNotify(i + 0, j + 47, k + 20, 1, 2);
		setBlock(world, i + 0, j + 47, k + 21, Blocks.log, 1);
		world.setBlockMetadataWithNotify(i + 0, j + 47, k + 21, 1, 2);
		setBlock(world, i + 0, j + 47, k + 22, Blocks.log, 1);
		world.setBlockMetadataWithNotify(i + 0, j + 47, k + 22, 1, 2);
		setBlock(world, i + 0, j + 47, k + 23, Blocks.log, 1);
		world.setBlockMetadataWithNotify(i + 0, j + 47, k + 23, 1, 2);
		setBlock(world, i + 0, j + 47, k + 24, Blocks.log, 1);
		world.setBlockMetadataWithNotify(i + 0, j + 47, k + 24, 1, 2);
		setBlock(world, i + 0, j + 47, k + 25, Blocks.log, 1);
		world.setBlockMetadataWithNotify(i + 0, j + 47, k + 25, 1, 2);
		setBlock(world, i + 0, j + 48, k + 7, Blocks.leaves, 15);
		world.setBlockMetadataWithNotify(i + 0, j + 48, k + 7, 15, 2);
		setBlock(world, i + 0, j + 48, k + 8, Blocks.leaves, 15);
		world.setBlockMetadataWithNotify(i + 0, j + 48, k + 8, 15, 2);
		setBlock(world, i + 0, j + 48, k + 9, Blocks.leaves, 15);
		world.setBlockMetadataWithNotify(i + 0, j + 48, k + 9, 15, 2);
		setBlock(world, i + 0, j + 48, k + 10, Blocks.log, 3);
		world.setBlockMetadataWithNotify(i + 0, j + 48, k + 10, 3, 2);
		setBlock(world, i + 0, j + 48, k + 11, Blocks.leaves, 7);
		world.setBlockMetadataWithNotify(i + 0, j + 48, k + 11, 7, 2);
		setBlock(world, i + 0, j + 48, k + 12, Blocks.log, 1);
		world.setBlockMetadataWithNotify(i + 0, j + 48, k + 12, 1, 2);
		setBlock(world, i + 0, j + 48, k + 13, Blocks.log, 1);
		world.setBlockMetadataWithNotify(i + 0, j + 48, k + 13, 1, 2);
		setBlock(world, i + 0, j + 48, k + 14, Blocks.log, 1);
		world.setBlockMetadataWithNotify(i + 0, j + 48, k + 14, 1, 2);
		setBlock(world, i + 0, j + 48, k + 15, Blocks.log, 1);
		world.setBlockMetadataWithNotify(i + 0, j + 48, k + 15, 1, 2);
		setBlock(world, i + 0, j + 48, k + 16, Blocks.log, 1);
		world.setBlockMetadataWithNotify(i + 0, j + 48, k + 16, 1, 2);
		setBlock(world, i + 0, j + 48, k + 17, Blocks.log, 1);
		world.setBlockMetadataWithNotify(i + 0, j + 48, k + 17, 1, 2);
		setBlock(world, i + 0, j + 48, k + 18, Blocks.log, 1);
		world.setBlockMetadataWithNotify(i + 0, j + 48, k + 18, 1, 2);
		setBlock(world, i + 0, j + 48, k + 19, Blocks.log, 1);
		world.setBlockMetadataWithNotify(i + 0, j + 48, k + 19, 1, 2);
		setBlock(world, i + 0, j + 48, k + 20, Blocks.log, 1);
		world.setBlockMetadataWithNotify(i + 0, j + 48, k + 20, 1, 2);
		setBlock(world, i + 0, j + 48, k + 21, Blocks.log, 1);
		world.setBlockMetadataWithNotify(i + 0, j + 48, k + 21, 1, 2);
		setBlock(world, i + 0, j + 48, k + 22, Blocks.log, 1);
		world.setBlockMetadataWithNotify(i + 0, j + 48, k + 22, 1, 2);
		setBlock(world, i + 0, j + 48, k + 23, Blocks.log, 1);
		world.setBlockMetadataWithNotify(i + 0, j + 48, k + 23, 1, 2);
		setBlock(world, i + 0, j + 48, k + 24, Blocks.log, 1);
		world.setBlockMetadataWithNotify(i + 0, j + 48, k + 24, 1, 2);
		setBlock(world, i + 0, j + 49, k + 1, Blocks.leaves, 15);
		world.setBlockMetadataWithNotify(i + 0, j + 49, k + 1, 15, 2);
		setBlock(world, i + 0, j + 49, k + 2, Blocks.leaves, 7);
		world.setBlockMetadataWithNotify(i + 0, j + 49, k + 2, 7, 2);
		setBlock(world, i + 0, j + 49, k + 8, Blocks.leaves, 7);
		world.setBlockMetadataWithNotify(i + 0, j + 49, k + 8, 7, 2);
		setBlock(world, i + 0, j + 49, k + 9, Blocks.leaves, 7);
		world.setBlockMetadataWithNotify(i + 0, j + 49, k + 9, 7, 2);
		setBlock(world, i + 0, j + 49, k + 10, Blocks.leaves, 7);
		world.setBlockMetadataWithNotify(i + 0, j + 49, k + 10, 7, 2);
		setBlock(world, i + 0, j + 49, k + 11, Blocks.leaves, 7);
		world.setBlockMetadataWithNotify(i + 0, j + 49, k + 11, 7, 2);
		setBlock(world, i + 0, j + 49, k + 12, Blocks.log, 3);
		world.setBlockMetadataWithNotify(i + 0, j + 49, k + 12, 3, 2);
		setBlock(world, i + 0, j + 49, k + 13, Blocks.leaves, 7);
		world.setBlockMetadataWithNotify(i + 0, j + 49, k + 13, 7, 2);
		setBlock(world, i + 0, j + 49, k + 14, Blocks.leaves, 7);
		world.setBlockMetadataWithNotify(i + 0, j + 49, k + 14, 7, 2);
		setBlock(world, i + 0, j + 49, k + 15, Blocks.log, 1);
		world.setBlockMetadataWithNotify(i + 0, j + 49, k + 15, 1, 2);
		setBlock(world, i + 0, j + 49, k + 16, Blocks.log, 1);
		world.setBlockMetadataWithNotify(i + 0, j + 49, k + 16, 1, 2);
		setBlock(world, i + 0, j + 49, k + 17, Blocks.log, 1);
		world.setBlockMetadataWithNotify(i + 0, j + 49, k + 17, 1, 2);
		setBlock(world, i + 0, j + 49, k + 18, Blocks.log, 1);
		world.setBlockMetadataWithNotify(i + 0, j + 49, k + 18, 1, 2);
		setBlock(world, i + 0, j + 49, k + 19, Blocks.log, 1);
		world.setBlockMetadataWithNotify(i + 0, j + 49, k + 19, 1, 2);
		setBlock(world, i + 0, j + 49, k + 20, Blocks.log, 1);
		world.setBlockMetadataWithNotify(i + 0, j + 49, k + 20, 1, 2);
		setBlock(world, i + 0, j + 49, k + 21, Blocks.log, 1);
		world.setBlockMetadataWithNotify(i + 0, j + 49, k + 21, 1, 2);
		setBlock(world, i + 0, j + 50, k + 0, Blocks.leaves, 15);
		world.setBlockMetadataWithNotify(i + 0, j + 50, k + 0, 15, 2);
		setBlock(world, i + 0, j + 50, k + 1, Blocks.leaves, 15);
		world.setBlockMetadataWithNotify(i + 0, j + 50, k + 1, 15, 2);
		setBlock(world, i + 0, j + 50, k + 2, Blocks.leaves, 7);
		world.setBlockMetadataWithNotify(i + 0, j + 50, k + 2, 7, 2);
		setBlock(world, i + 0, j + 50, k + 3, Blocks.leaves, 7);
		world.setBlockMetadataWithNotify(i + 0, j + 50, k + 3, 7, 2);
		setBlock(world, i + 0, j + 50, k + 4, Blocks.leaves, 7);
		world.setBlockMetadataWithNotify(i + 0, j + 50, k + 4, 7, 2);
		setBlock(world, i + 0, j + 50, k + 5, Blocks.leaves, 7);
		world.setBlockMetadataWithNotify(i + 0, j + 50, k + 5, 7, 2);
		setBlock(world, i + 0, j + 50, k + 6, Blocks.leaves, 7);
		world.setBlockMetadataWithNotify(i + 0, j + 50, k + 6, 7, 2);
		setBlock(world, i + 0, j + 50, k + 9, Blocks.leaves, 7);
		world.setBlockMetadataWithNotify(i + 0, j + 50, k + 9, 7, 2);
		setBlock(world, i + 0, j + 50, k + 10, Blocks.leaves, 7);
		world.setBlockMetadataWithNotify(i + 0, j + 50, k + 10, 7, 2);
		setBlock(world, i + 0, j + 50, k + 11, Blocks.leaves, 7);
		world.setBlockMetadataWithNotify(i + 0, j + 50, k + 11, 7, 2);
		setBlock(world, i + 0, j + 50, k + 12, Blocks.leaves, 7);
		world.setBlockMetadataWithNotify(i + 0, j + 50, k + 12, 7, 2);
		setBlock(world, i + 0, j + 50, k + 13, Blocks.leaves, 7);
		world.setBlockMetadataWithNotify(i + 0, j + 50, k + 13, 7, 2);
		setBlock(world, i + 0, j + 50, k + 14, Blocks.leaves, 7);
		world.setBlockMetadataWithNotify(i + 0, j + 50, k + 14, 7, 2);
		setBlock(world, i + 0, j + 51, k + 0, Blocks.leaves, 7);
		world.setBlockMetadataWithNotify(i + 0, j + 51, k + 0, 7, 2);
		setBlock(world, i + 0, j + 51, k + 1, Blocks.leaves, 7);
		world.setBlockMetadataWithNotify(i + 0, j + 51, k + 1, 7, 2);
		setBlock(world, i + 0, j + 51, k + 2, Blocks.leaves, 7);
		world.setBlockMetadataWithNotify(i + 0, j + 51, k + 2, 7, 2);
		setBlock(world, i + 0, j + 51, k + 3, Blocks.leaves, 7);
		world.setBlockMetadataWithNotify(i + 0, j + 51, k + 3, 7, 2);
		setBlock(world, i + 0, j + 51, k + 4, Blocks.leaves, 7);
		world.setBlockMetadataWithNotify(i + 0, j + 51, k + 4, 7, 2);
		setBlock(world, i + 0, j + 51, k + 5, Blocks.leaves, 7);
		world.setBlockMetadataWithNotify(i + 0, j + 51, k + 5, 7, 2);
		setBlock(world, i + 0, j + 51, k + 10, Blocks.leaves, 7);
		world.setBlockMetadataWithNotify(i + 0, j + 51, k + 10, 7, 2);
		setBlock(world, i + 0, j + 51, k + 11, Blocks.leaves, 7);
		world.setBlockMetadataWithNotify(i + 0, j + 51, k + 11, 7, 2);
		setBlock(world, i + 0, j + 51, k + 12, Blocks.leaves, 7);
		world.setBlockMetadataWithNotify(i + 0, j + 51, k + 12, 7, 2);
		setBlock(world, i + 0, j + 51, k + 13, Blocks.leaves, 7);
		world.setBlockMetadataWithNotify(i + 0, j + 51, k + 13, 7, 2);
		setBlock(world, i + 0, j + 52, k + 1, Blocks.leaves, 7);
		world.setBlockMetadataWithNotify(i + 0, j + 52, k + 1, 7, 2);
		setBlock(world, i + 0, j + 52, k + 2, Blocks.leaves, 7);
		world.setBlockMetadataWithNotify(i + 0, j + 52, k + 2, 7, 2);
		setBlock(world, i + 0, j + 52, k + 3, Blocks.leaves, 7);
		world.setBlockMetadataWithNotify(i + 0, j + 52, k + 3, 7, 2);
		setBlock(world, i + 0, j + 52, k + 4, Blocks.leaves, 7);
		world.setBlockMetadataWithNotify(i + 0, j + 52, k + 4, 7, 2);
		setBlock(world, i + 0, j + 52, k + 12, Blocks.leaves, 7);
		world.setBlockMetadataWithNotify(i + 0, j + 52, k + 12, 7, 2);
		setBlock(world, i + 0, j + 53, k + 3, Blocks.leaves, 7);
		world.setBlockMetadataWithNotify(i + 0, j + 53, k + 3, 7, 2);
		setBlock(world, i + 0, j + 54, k + 1, Blocks.leaves, 7);
		world.setBlockMetadataWithNotify(i + 0, j + 54, k + 1, 7, 2);
		setBlock(world, i + 0, j + 54, k + 2, Blocks.leaves, 7);
		world.setBlockMetadataWithNotify(i + 0, j + 54, k + 2, 7, 2);
		setBlock(world, i + 0, j + 54, k + 3, Blocks.leaves, 7);
		world.setBlockMetadataWithNotify(i + 0, j + 54, k + 3, 7, 2);
		setBlock(world, i + 0, j + 54, k + 4, Blocks.leaves, 7);
		world.setBlockMetadataWithNotify(i + 0, j + 54, k + 4, 7, 2);
		setBlock(world, i + 0, j + 54, k + 5, Blocks.leaves, 7);
		world.setBlockMetadataWithNotify(i + 0, j + 54, k + 5, 7, 2);
		setBlock(world, i + 0, j + 55, k + 2, Blocks.leaves, 7);
		world.setBlockMetadataWithNotify(i + 0, j + 55, k + 2, 7, 2);
		setBlock(world, i + 0, j + 55, k + 3, Blocks.leaves, 7);
		world.setBlockMetadataWithNotify(i + 0, j + 55, k + 3, 7, 2);
		setBlock(world, i + 0, j + 55, k + 4, Blocks.leaves, 7);
		world.setBlockMetadataWithNotify(i + 0, j + 55, k + 4, 7, 2);
		setBlock(world, i + 0, j + 56, k + 3, Blocks.leaves, 7);
		world.setBlockMetadataWithNotify(i + 0, j + 56, k + 3, 7, 2);
		setBlock(world, i + 0, j + 57, k + 8, Blocks.leaves, 7);
		world.setBlockMetadataWithNotify(i + 0, j + 57, k + 8, 7, 2);
		setBlock(world, i + 0, j + 57, k + 9, Blocks.leaves, 7);
		world.setBlockMetadataWithNotify(i + 0, j + 57, k + 9, 7, 2);
		setBlock(world, i + 0, j + 57, k + 10, Blocks.log, 3);
		world.setBlockMetadataWithNotify(i + 0, j + 57, k + 10, 3, 2);
		setBlock(world, i + 0, j + 57, k + 11, Blocks.leaves, 7);
		world.setBlockMetadataWithNotify(i + 0, j + 57, k + 11, 7, 2);
		setBlock(world, i + 0, j + 57, k + 12, Blocks.leaves, 7);
		world.setBlockMetadataWithNotify(i + 0, j + 57, k + 12, 7, 2);
		setBlock(world, i + 0, j + 58, k + 8, Blocks.leaves, 7);
		world.setBlockMetadataWithNotify(i + 0, j + 58, k + 8, 7, 2);
		setBlock(world, i + 0, j + 58, k + 9, Blocks.leaves, 7);
		world.setBlockMetadataWithNotify(i + 0, j + 58, k + 9, 7, 2);
		setBlock(world, i + 0, j + 58, k + 10, Blocks.leaves, 7);
		world.setBlockMetadataWithNotify(i + 0, j + 58, k + 10, 7, 2);
		setBlock(world, i + 0, j + 58, k + 11, Blocks.leaves, 7);
		world.setBlockMetadataWithNotify(i + 0, j + 58, k + 11, 7, 2);
		setBlock(world, i + 0, j + 58, k + 12, Blocks.leaves, 7);
		world.setBlockMetadataWithNotify(i + 0, j + 58, k + 12, 7, 2);
		setBlock(world, i + 0, j + 59, k + 5, Blocks.leaves, 7);
		world.setBlockMetadataWithNotify(i + 0, j + 59, k + 5, 7, 2);
		setBlock(world, i + 0, j + 59, k + 6, Blocks.leaves, 7);
		world.setBlockMetadataWithNotify(i + 0, j + 59, k + 6, 7, 2);
		setBlock(world, i + 0, j + 59, k + 7, Blocks.leaves, 7);
		world.setBlockMetadataWithNotify(i + 0, j + 59, k + 7, 7, 2);
		setBlock(world, i + 0, j + 59, k + 9, Blocks.leaves, 7);
		world.setBlockMetadataWithNotify(i + 0, j + 59, k + 9, 7, 2);
		setBlock(world, i + 0, j + 59, k + 10, Blocks.leaves, 7);
		world.setBlockMetadataWithNotify(i + 0, j + 59, k + 10, 7, 2);
		setBlock(world, i + 0, j + 59, k + 11, Blocks.leaves, 7);
		world.setBlockMetadataWithNotify(i + 0, j + 59, k + 11, 7, 2);
		setBlock(world, i + 0, j + 60, k + 6, Blocks.leaves, 7);
		world.setBlockMetadataWithNotify(i + 0, j + 60, k + 6, 7, 2);
		setBlock(world, i + 0, j + 60, k + 10, Blocks.leaves, 7);
		world.setBlockMetadataWithNotify(i + 0, j + 60, k + 10, 7, 2);
		setBlock(world, i + 1, j + 0, k + 8, Blocks.log, 3);
		world.setBlockMetadataWithNotify(i + 1, j + 0, k + 8, 3, 2);
		setBlock(world, i + 1, j + 22, k + 4, Blocks.log, 3);
		world.setBlockMetadataWithNotify(i + 1, j + 22, k + 4, 3, 2);
		setBlock(world, i + 1, j + 22, k + 12, Blocks.log, 3);
		world.setBlockMetadataWithNotify(i + 1, j + 22, k + 12, 3, 2);
		setBlock(world, i + 1, j + 23, k + 17, Blocks.log, 3);
		world.setBlockMetadataWithNotify(i + 1, j + 23, k + 17, 3, 2);
		setBlock(world, i + 1, j + 23, k + 20, Blocks.log, 3);
		world.setBlockMetadataWithNotify(i + 1, j + 23, k + 20, 3, 2);
		setBlock(world, i + 1, j + 24, k + 4, Blocks.log, 3);
		world.setBlockMetadataWithNotify(i + 1, j + 24, k + 4, 3, 2);
		setBlock(world, i + 1, j + 24, k + 6, Blocks.leaves, 7);
		world.setBlockMetadataWithNotify(i + 1, j + 24, k + 6, 7, 2);
		setBlock(world, i + 1, j + 24, k + 7, Blocks.leaves, 7);
		world.setBlockMetadataWithNotify(i + 1, j + 24, k + 7, 7, 2);
		setBlock(world, i + 1, j + 24, k + 8, Blocks.leaves, 7);
		world.setBlockMetadataWithNotify(i + 1, j + 24, k + 8, 7, 2);
		setBlock(world, i + 1, j + 24, k + 9, Blocks.leaves, 7);
		world.setBlockMetadataWithNotify(i + 1, j + 24, k + 9, 7, 2);
		setBlock(world, i + 1, j + 24, k + 10, Blocks.leaves, 7);
		world.setBlockMetadataWithNotify(i + 1, j + 24, k + 10, 7, 2);
		setBlock(world, i + 1, j + 24, k + 15, Blocks.log, 3);
		world.setBlockMetadataWithNotify(i + 1, j + 24, k + 15, 3, 2);
		setBlock(world, i + 1, j + 24, k + 16, Blocks.log, 3);
		world.setBlockMetadataWithNotify(i + 1, j + 24, k + 16, 3, 2);
		setBlock(world, i + 1, j + 24, k + 17, Blocks.log, 3);
		world.setBlockMetadataWithNotify(i + 1, j + 24, k + 17, 3, 2);
		setBlock(world, i + 1, j + 24, k + 21, Blocks.leaves, 7);
		world.setBlockMetadataWithNotify(i + 1, j + 24, k + 21, 7, 2);
		setBlock(world, i + 1, j + 24, k + 22, Blocks.leaves, 7);
		world.setBlockMetadataWithNotify(i + 1, j + 24, k + 22, 7, 2);
		setBlock(world, i + 1, j + 24, k + 23, Blocks.leaves, 7);
		world.setBlockMetadataWithNotify(i + 1, j + 24, k + 23, 7, 2);
		setBlock(world, i + 1, j + 25, k + 7, Blocks.leaves, 7);
		world.setBlockMetadataWithNotify(i + 1, j + 25, k + 7, 7, 2);
		setBlock(world, i + 1, j + 25, k + 8, Blocks.leaves, 7);
		world.setBlockMetadataWithNotify(i + 1, j + 25, k + 8, 7, 2);
		setBlock(world, i + 1, j + 25, k + 9, Blocks.leaves, 7);
		world.setBlockMetadataWithNotify(i + 1, j + 25, k + 9, 7, 2);
		setBlock(world, i + 1, j + 25, k + 11, Blocks.log, 3);
		world.setBlockMetadataWithNotify(i + 1, j + 25, k + 11, 3, 2);
		setBlock(world, i + 1, j + 25, k + 17, Blocks.log, 3);
		world.setBlockMetadataWithNotify(i + 1, j + 25, k + 17, 3, 2);
		setBlock(world, i + 1, j + 25, k + 20, Blocks.log, 3);
		world.setBlockMetadataWithNotify(i + 1, j + 25, k + 20, 3, 2);
		setBlock(world, i + 1, j + 25, k + 22, Blocks.leaves, 7);
		world.setBlockMetadataWithNotify(i + 1, j + 25, k + 22, 7, 2);
		setBlock(world, i + 1, j + 26, k + 8, Blocks.leaves, 7);
		world.setBlockMetadataWithNotify(i + 1, j + 26, k + 8, 7, 2);
		setBlock(world, i + 1, j + 27, k + 3, Blocks.log, 3);
		world.setBlockMetadataWithNotify(i + 1, j + 27, k + 3, 3, 2);
		setBlock(world, i + 1, j + 31, k + 7, Blocks.log, 3);
		world.setBlockMetadataWithNotify(i + 1, j + 31, k + 7, 3, 2);
		setBlock(world, i + 1, j + 31, k + 20, Blocks.log, 3);
		world.setBlockMetadataWithNotify(i + 1, j + 31, k + 20, 3, 2);
		setBlock(world, i + 1, j + 32, k + 15, Blocks.log, 3);
		world.setBlockMetadataWithNotify(i + 1, j + 32, k + 15, 3, 2);
		setBlock(world, i + 1, j + 32, k + 21, Blocks.leaves, 7);
		world.setBlockMetadataWithNotify(i + 1, j + 32, k + 21, 7, 2);
		setBlock(world, i + 1, j + 32, k + 22, Blocks.log, 1);
		world.setBlockMetadataWithNotify(i + 1, j + 32, k + 22, 1, 2);
		setBlock(world, i + 1, j + 32, k + 23, Blocks.leaves, 7);
		world.setBlockMetadataWithNotify(i + 1, j + 32, k + 23, 7, 2);
		setBlock(world, i + 1, j + 33, k + 13, Blocks.log, 3);
		world.setBlockMetadataWithNotify(i + 1, j + 33, k + 13, 3, 2);
		setBlock(world, i + 1, j + 33, k + 15, Blocks.leaves, 7);
		world.setBlockMetadataWithNotify(i + 1, j + 33, k + 15, 7, 2);
		setBlock(world, i + 1, j + 33, k + 16, Blocks.leaves, 7);
		world.setBlockMetadataWithNotify(i + 1, j + 33, k + 16, 7, 2);
		setBlock(world, i + 1, j + 33, k + 17, Blocks.leaves, 7);
		world.setBlockMetadataWithNotify(i + 1, j + 33, k + 17, 7, 2);
		setBlock(world, i + 1, j + 33, k + 21, Blocks.log, 1);
		world.setBlockMetadataWithNotify(i + 1, j + 33, k + 21, 1, 2);
		setBlock(world, i + 1, j + 33, k + 22, Blocks.log, 1);
		world.setBlockMetadataWithNotify(i + 1, j + 33, k + 22, 1, 2);
		setBlock(world, i + 1, j + 33, k + 23, Blocks.log, 1);
		world.setBlockMetadataWithNotify(i + 1, j + 33, k + 23, 1, 2);
		setBlock(world, i + 1, j + 34, k + 11, Blocks.leaves, 7);
		world.setBlockMetadataWithNotify(i + 1, j + 34, k + 11, 7, 2);
		setBlock(world, i + 1, j + 34, k + 12, Blocks.leaves, 7);
		world.setBlockMetadataWithNotify(i + 1, j + 34, k + 12, 7, 2);
		setBlock(world, i + 1, j + 34, k + 13, Blocks.leaves, 7);
		world.setBlockMetadataWithNotify(i + 1, j + 34, k + 13, 7, 2);
		setBlock(world, i + 1, j + 34, k + 14, Blocks.leaves, 7);
		world.setBlockMetadataWithNotify(i + 1, j + 34, k + 14, 7, 2);
		setBlock(world, i + 1, j + 34, k + 15, Blocks.leaves, 7);
		world.setBlockMetadataWithNotify(i + 1, j + 34, k + 15, 7, 2);
		setBlock(world, i + 1, j + 34, k + 16, Blocks.leaves, 7);
		world.setBlockMetadataWithNotify(i + 1, j + 34, k + 16, 7, 2);
		setBlock(world, i + 1, j + 35, k + 12, Blocks.leaves, 7);
		world.setBlockMetadataWithNotify(i + 1, j + 35, k + 12, 7, 2);
		setBlock(world, i + 1, j + 35, k + 13, Blocks.leaves, 7);
		world.setBlockMetadataWithNotify(i + 1, j + 35, k + 13, 7, 2);
		setBlock(world, i + 1, j + 35, k + 14, Blocks.leaves, 7);
		world.setBlockMetadataWithNotify(i + 1, j + 35, k + 14, 7, 2);
		setBlock(world, i + 1, j + 35, k + 18, Blocks.log, 1);
		world.setBlockMetadataWithNotify(i + 1, j + 35, k + 18, 1, 2);
		setBlock(world, i + 1, j + 35, k + 19, Blocks.log, 1);
		world.setBlockMetadataWithNotify(i + 1, j + 35, k + 19, 1, 2);
		setBlock(world, i + 1, j + 35, k + 20, Blocks.log, 1);
		world.setBlockMetadataWithNotify(i + 1, j + 35, k + 20, 1, 2);
		setBlock(world, i + 1, j + 35, k + 21, Blocks.log, 1);
		world.setBlockMetadataWithNotify(i + 1, j + 35, k + 21, 1, 2);
		setBlock(world, i + 1, j + 36, k + 13, Blocks.leaves, 15);
		world.setBlockMetadataWithNotify(i + 1, j + 36, k + 13, 15, 2);
		setBlock(world, i + 1, j + 36, k + 18, Blocks.log, 1);
		world.setBlockMetadataWithNotify(i + 1, j + 36, k + 18, 1, 2);
		setBlock(world, i + 1, j + 36, k + 19, Blocks.log, 1);
		world.setBlockMetadataWithNotify(i + 1, j + 36, k + 19, 1, 2);
		setBlock(world, i + 1, j + 36, k + 20, Blocks.log, 1);
		world.setBlockMetadataWithNotify(i + 1, j + 36, k + 20, 1, 2);
		setBlock(world, i + 1, j + 36, k + 21, Blocks.log, 1);
		world.setBlockMetadataWithNotify(i + 1, j + 36, k + 21, 1, 2);
		setBlock(world, i + 1, j + 37, k + 16, Blocks.leaves, 15);
		world.setBlockMetadataWithNotify(i + 1, j + 37, k + 16, 15, 2);
		setBlock(world, i + 1, j + 37, k + 17, Blocks.log, 1);
		world.setBlockMetadataWithNotify(i + 1, j + 37, k + 17, 1, 2);
		setBlock(world, i + 1, j + 37, k + 18, Blocks.log, 1);
		world.setBlockMetadataWithNotify(i + 1, j + 37, k + 18, 1, 2);
		setBlock(world, i + 1, j + 37, k + 19, Blocks.log, 1);
		world.setBlockMetadataWithNotify(i + 1, j + 37, k + 19, 1, 2);
		setBlock(world, i + 1, j + 37, k + 20, Blocks.log, 1);
		world.setBlockMetadataWithNotify(i + 1, j + 37, k + 20, 1, 2);
		setBlock(world, i + 1, j + 37, k + 21, Blocks.log, 1);
		world.setBlockMetadataWithNotify(i + 1, j + 37, k + 21, 1, 2);
		setBlock(world, i + 1, j + 37, k + 29, Blocks.vine, 4);
		world.setBlockMetadataWithNotify(i + 1, j + 37, k + 29, 4, 2);
		setBlock(world, i + 1, j + 38, k + 6, Blocks.leaves, 15);
		world.setBlockMetadataWithNotify(i + 1, j + 38, k + 6, 15, 2);
		setBlock(world, i + 1, j + 38, k + 8, Blocks.leaves, 15);
		world.setBlockMetadataWithNotify(i + 1, j + 38, k + 8, 15, 2);
		setBlock(world, i + 1, j + 38, k + 9, Blocks.leaves, 15);
		world.setBlockMetadataWithNotify(i + 1, j + 38, k + 9, 15, 2);
		setBlock(world, i + 1, j + 38, k + 10, Blocks.log, 3);
		world.setBlockMetadataWithNotify(i + 1, j + 38, k + 10, 3, 2);
		setBlock(world, i + 1, j + 38, k + 17, Blocks.log, 1);
		world.setBlockMetadataWithNotify(i + 1, j + 38, k + 17, 1, 2);
		setBlock(world, i + 1, j + 38, k + 18, Blocks.log, 1);
		world.setBlockMetadataWithNotify(i + 1, j + 38, k + 18, 1, 2);
		setBlock(world, i + 1, j + 38, k + 19, Blocks.log, 1);
		world.setBlockMetadataWithNotify(i + 1, j + 38, k + 19, 1, 2);
		setBlock(world, i + 1, j + 38, k + 20, Blocks.log, 1);
		world.setBlockMetadataWithNotify(i + 1, j + 38, k + 20, 1, 2);
		setBlock(world, i + 1, j + 38, k + 21, Blocks.log, 1);
		world.setBlockMetadataWithNotify(i + 1, j + 38, k + 21, 1, 2);
		setBlock(world, i + 1, j + 38, k + 22, Blocks.log, 1);
		world.setBlockMetadataWithNotify(i + 1, j + 38, k + 22, 1, 2);
		setBlock(world, i + 1, j + 38, k + 24, Blocks.vine, 2);
		world.setBlockMetadataWithNotify(i + 1, j + 38, k + 24, 2, 2);
		setBlock(world, i + 1, j + 38, k + 25, Blocks.vine, 7);
		world.setBlockMetadataWithNotify(i + 1, j + 38, k + 25, 7, 2);
		setBlock(world, i + 1, j + 38, k + 26, Blocks.vine, 15);
		world.setBlockMetadataWithNotify(i + 1, j + 38, k + 26, 15, 2);
		setBlock(world, i + 1, j + 38, k + 27, Blocks.vine, 15);
		world.setBlockMetadataWithNotify(i + 1, j + 38, k + 27, 15, 2);
		setBlock(world, i + 1, j + 38, k + 28, Blocks.vine, 9);
		world.setBlockMetadataWithNotify(i + 1, j + 38, k + 28, 9, 2);
		setBlock(world, i + 1, j + 38, k + 29, Blocks.vine, 6);
		world.setBlockMetadataWithNotify(i + 1, j + 38, k + 29, 6, 2);
		setBlock(world, i + 1, j + 38, k + 30, Blocks.vine, 15);
		world.setBlockMetadataWithNotify(i + 1, j + 38, k + 30, 15, 2);
		setBlock(world, i + 1, j + 38, k + 31, Blocks.vine, 7);
		world.setBlockMetadataWithNotify(i + 1, j + 38, k + 31, 7, 2);
		setBlock(world, i + 1, j + 39, k + 16, Blocks.log, 1);
		world.setBlockMetadataWithNotify(i + 1, j + 39, k + 16, 1, 2);
		setBlock(world, i + 1, j + 39, k + 17, Blocks.log, 1);
		world.setBlockMetadataWithNotify(i + 1, j + 39, k + 17, 1, 2);
		setBlock(world, i + 1, j + 39, k + 18, Blocks.log, 1);
		world.setBlockMetadataWithNotify(i + 1, j + 39, k + 18, 1, 2);
		setBlock(world, i + 1, j + 39, k + 19, Blocks.log, 1);
		world.setBlockMetadataWithNotify(i + 1, j + 39, k + 19, 1, 2);
		setBlock(world, i + 1, j + 39, k + 20, Blocks.log, 1);
		world.setBlockMetadataWithNotify(i + 1, j + 39, k + 20, 1, 2);
		setBlock(world, i + 1, j + 39, k + 21, Blocks.log, 1);
		world.setBlockMetadataWithNotify(i + 1, j + 39, k + 21, 1, 2);
		setBlock(world, i + 1, j + 39, k + 22, Blocks.log, 1);
		world.setBlockMetadataWithNotify(i + 1, j + 39, k + 22, 1, 2);
		setBlock(world, i + 1, j + 39, k + 23, Blocks.vine, 15);
		world.setBlockMetadataWithNotify(i + 1, j + 39, k + 23, 15, 2);
		setBlock(world, i + 1, j + 39, k + 24, Blocks.vine, 15);
		world.setBlockMetadataWithNotify(i + 1, j + 39, k + 24, 15, 2);
		setBlock(world, i + 1, j + 39, k + 25, Blocks.vine, 15);
		world.setBlockMetadataWithNotify(i + 1, j + 39, k + 25, 15, 2);
		setBlock(world, i + 1, j + 39, k + 26, Blocks.vine, 15);
		world.setBlockMetadataWithNotify(i + 1, j + 39, k + 26, 15, 2);
		setBlock(world, i + 1, j + 39, k + 27, Blocks.vine, 15);
		world.setBlockMetadataWithNotify(i + 1, j + 39, k + 27, 15, 2);
		setBlock(world, i + 1, j + 39, k + 28, Blocks.vine, 15);
		world.setBlockMetadataWithNotify(i + 1, j + 39, k + 28, 15, 2);
		setBlock(world, i + 1, j + 39, k + 29, Blocks.vine, 15);
		world.setBlockMetadataWithNotify(i + 1, j + 39, k + 29, 15, 2);
		setBlock(world, i + 1, j + 39, k + 30, Blocks.vine, 15);
		world.setBlockMetadataWithNotify(i + 1, j + 39, k + 30, 15, 2);
		setBlock(world, i + 1, j + 39, k + 31, Blocks.vine, 15);
		world.setBlockMetadataWithNotify(i + 1, j + 39, k + 31, 15, 2);
		setBlock(world, i + 1, j + 40, k + 0, Blocks.planks, 5);
		world.setBlockMetadataWithNotify(i + 1, j + 40, k + 0, 5, 2);
		setBlock(world, i + 1, j + 40, k + 1, Blocks.planks, 5);
		world.setBlockMetadataWithNotify(i + 1, j + 40, k + 1, 5, 2);
		setBlock(world, i + 1, j + 40, k + 2, Blocks.planks, 5);
		world.setBlockMetadataWithNotify(i + 1, j + 40, k + 2, 5, 2);
		setBlock(world, i + 1, j + 40, k + 3, Blocks.planks, 5);
		world.setBlockMetadataWithNotify(i + 1, j + 40, k + 3, 5, 2);
		setBlock(world, i + 1, j + 40, k + 4, Blocks.planks, 5);
		world.setBlockMetadataWithNotify(i + 1, j + 40, k + 4, 5, 2);
		setBlock(world, i + 1, j + 40, k + 5, Blocks.planks, 5);
		world.setBlockMetadataWithNotify(i + 1, j + 40, k + 5, 5, 2);
		setBlock(world, i + 1, j + 40, k + 6, Blocks.planks, 5);
		world.setBlockMetadataWithNotify(i + 1, j + 40, k + 6, 5, 2);
		setBlock(world, i + 1, j + 40, k + 7, Blocks.planks, 5);
		world.setBlockMetadataWithNotify(i + 1, j + 40, k + 7, 5, 2);
		setBlock(world, i + 1, j + 40, k + 8, Blocks.planks, 5);
		world.setBlockMetadataWithNotify(i + 1, j + 40, k + 8, 5, 2);
		setBlock(world, i + 1, j + 40, k + 9, Blocks.planks, 5);
		world.setBlockMetadataWithNotify(i + 1, j + 40, k + 9, 5, 2);
		setBlock(world, i + 1, j + 40, k + 10, Blocks.planks, 5);
		world.setBlockMetadataWithNotify(i + 1, j + 40, k + 10, 5, 2);
		setBlock(world, i + 1, j + 40, k + 11, Blocks.planks, 5);
		world.setBlockMetadataWithNotify(i + 1, j + 40, k + 11, 5, 2);
		setBlock(world, i + 1, j + 40, k + 12, Blocks.log, 1);
		world.setBlockMetadataWithNotify(i + 1, j + 40, k + 12, 1, 2);
		setBlock(world, i + 1, j + 40, k + 13, Blocks.log, 1);
		world.setBlockMetadataWithNotify(i + 1, j + 40, k + 13, 1, 2);
		setBlock(world, i + 1, j + 40, k + 14, Blocks.planks, 5);
		world.setBlockMetadataWithNotify(i + 1, j + 40, k + 14, 5, 2);
		setBlock(world, i + 1, j + 40, k + 15, Blocks.log, 1);
		world.setBlockMetadataWithNotify(i + 1, j + 40, k + 15, 1, 2);
		setBlock(world, i + 1, j + 40, k + 16, Blocks.planks, 5);
		world.setBlockMetadataWithNotify(i + 1, j + 40, k + 16, 5, 2);
		setBlock(world, i + 1, j + 40, k + 17, Blocks.log, 1);
		world.setBlockMetadataWithNotify(i + 1, j + 40, k + 17, 1, 2);
		setBlock(world, i + 1, j + 40, k + 18, Blocks.log, 1);
		world.setBlockMetadataWithNotify(i + 1, j + 40, k + 18, 1, 2);
		setBlock(world, i + 1, j + 40, k + 19, Blocks.log, 1);
		world.setBlockMetadataWithNotify(i + 1, j + 40, k + 19, 1, 2);
		setBlock(world, i + 1, j + 40, k + 20, Blocks.planks, 5);
		world.setBlockMetadataWithNotify(i + 1, j + 40, k + 20, 5, 2);
		setBlock(world, i + 1, j + 40, k + 21, Blocks.log, 1);
		world.setBlockMetadataWithNotify(i + 1, j + 40, k + 21, 1, 2);
		setBlock(world, i + 1, j + 40, k + 22, Blocks.planks, 5);
		world.setBlockMetadataWithNotify(i + 1, j + 40, k + 22, 5, 2);
		setBlock(world, i + 1, j + 40, k + 23, Blocks.log, 1);
		world.setBlockMetadataWithNotify(i + 1, j + 40, k + 23, 1, 2);
		setBlock(world, i + 1, j + 40, k + 24, Blocks.log, 1);
		world.setBlockMetadataWithNotify(i + 1, j + 40, k + 24, 1, 2);
		setBlock(world, i + 1, j + 40, k + 25, Blocks.planks, 5);
		world.setBlockMetadataWithNotify(i + 1, j + 40, k + 25, 5, 2);
		setBlock(world, i + 1, j + 40, k + 26, Blocks.planks, 5);
		world.setBlockMetadataWithNotify(i + 1, j + 40, k + 26, 5, 2);
		setBlock(world, i + 1, j + 40, k + 27, Blocks.planks, 5);
		world.setBlockMetadataWithNotify(i + 1, j + 40, k + 27, 5, 2);
		setBlock(world, i + 1, j + 40, k + 28, Blocks.planks, 5);
		world.setBlockMetadataWithNotify(i + 1, j + 40, k + 28, 5, 2);
		setBlock(world, i + 1, j + 40, k + 29, Blocks.planks, 5);
		world.setBlockMetadataWithNotify(i + 1, j + 40, k + 29, 5, 2);
		setBlock(world, i + 1, j + 40, k + 30, Blocks.planks, 5);
		world.setBlockMetadataWithNotify(i + 1, j + 40, k + 30, 5, 2);
		setBlock(world, i + 1, j + 40, k + 31, Blocks.planks, 5);
		world.setBlockMetadataWithNotify(i + 1, j + 40, k + 31, 5, 2);
		setBlock(world, i + 1, j + 41, k + 17, Blocks.spruce_stairs, 2);
		world.setBlockMetadataWithNotify(i + 1, j + 41, k + 17, 2, 2);
		setBlock(world, i + 1, j + 41, k + 18, Blocks.log, 1);
		world.setBlockMetadataWithNotify(i + 1, j + 41, k + 18, 1, 2);
		setBlock(world, i + 1, j + 41, k + 19, Blocks.spruce_stairs, 3);
		world.setBlockMetadataWithNotify(i + 1, j + 41, k + 19, 3, 2);
		setBlock(world, i + 1, j + 42, k + 18, Blocks.log, 1);
		world.setBlockMetadataWithNotify(i + 1, j + 42, k + 18, 1, 2);
		setBlock(world, i + 1, j + 43, k + 18, Blocks.log, 1);
		world.setBlockMetadataWithNotify(i + 1, j + 43, k + 18, 1, 2);
		setBlock(world, i + 1, j + 44, k + 9, Blocks.log, 1);
		world.setBlockMetadataWithNotify(i + 1, j + 44, k + 9, 1, 2);
		setBlock(world, i + 1, j + 44, k + 10, Blocks.log, 1);
		world.setBlockMetadataWithNotify(i + 1, j + 44, k + 10, 1, 2);
		setBlock(world, i + 1, j + 44, k + 11, Blocks.log, 1);
		world.setBlockMetadataWithNotify(i + 1, j + 44, k + 11, 1, 2);
		setBlock(world, i + 1, j + 44, k + 12, Blocks.log, 1);
		world.setBlockMetadataWithNotify(i + 1, j + 44, k + 12, 1, 2);
		setBlock(world, i + 1, j + 44, k + 13, Blocks.log, 1);
		world.setBlockMetadataWithNotify(i + 1, j + 44, k + 13, 1, 2);
		setBlock(world, i + 1, j + 44, k + 17, Blocks.torch, 4);
		world.setBlockMetadataWithNotify(i + 1, j + 44, k + 17, 4, 2);
		setBlock(world, i + 1, j + 44, k + 18, Blocks.log, 1);
		world.setBlockMetadataWithNotify(i + 1, j + 44, k + 18, 1, 2);
		setBlock(world, i + 1, j + 44, k + 19, Blocks.torch, 3);
		world.setBlockMetadataWithNotify(i + 1, j + 44, k + 19, 3, 2);
		setBlock(world, i + 1, j + 44, k + 23, Blocks.log, 1);
		world.setBlockMetadataWithNotify(i + 1, j + 44, k + 23, 1, 2);
		setBlock(world, i + 1, j + 44, k + 24, Blocks.log, 1);
		world.setBlockMetadataWithNotify(i + 1, j + 44, k + 24, 1, 2);
		setBlock(world, i + 1, j + 44, k + 25, Blocks.log, 1);
		world.setBlockMetadataWithNotify(i + 1, j + 44, k + 25, 1, 2);
		setBlock(world, i + 1, j + 44, k + 26, Blocks.log, 1);
		world.setBlockMetadataWithNotify(i + 1, j + 44, k + 26, 1, 2);
		setBlock(world, i + 1, j + 44, k + 27, Blocks.log, 1);
		world.setBlockMetadataWithNotify(i + 1, j + 44, k + 27, 1, 2);
		setBlock(world, i + 1, j + 45, k + 9, Blocks.log, 3);
		world.setBlockMetadataWithNotify(i + 1, j + 45, k + 9, 3, 2);
		setBlock(world, i + 1, j + 45, k + 10, Blocks.log, 1);
		world.setBlockMetadataWithNotify(i + 1, j + 45, k + 10, 1, 2);
		setBlock(world, i + 1, j + 45, k + 11, Blocks.log, 1);
		world.setBlockMetadataWithNotify(i + 1, j + 45, k + 11, 1, 2);
		setBlock(world, i + 1, j + 45, k + 12, Blocks.log, 1);
		world.setBlockMetadataWithNotify(i + 1, j + 45, k + 12, 1, 2);
		setBlock(world, i + 1, j + 45, k + 13, Blocks.log, 1);
		world.setBlockMetadataWithNotify(i + 1, j + 45, k + 13, 1, 2);
		setBlock(world, i + 1, j + 45, k + 14, Blocks.log, 1);
		world.setBlockMetadataWithNotify(i + 1, j + 45, k + 14, 1, 2);
		setBlock(world, i + 1, j + 45, k + 18, Blocks.log, 1);
		world.setBlockMetadataWithNotify(i + 1, j + 45, k + 18, 1, 2);
		setBlock(world, i + 1, j + 45, k + 22, Blocks.log, 1);
		world.setBlockMetadataWithNotify(i + 1, j + 45, k + 22, 1, 2);
		setBlock(world, i + 1, j + 45, k + 23, Blocks.log, 1);
		world.setBlockMetadataWithNotify(i + 1, j + 45, k + 23, 1, 2);
		setBlock(world, i + 1, j + 45, k + 24, Blocks.log, 1);
		world.setBlockMetadataWithNotify(i + 1, j + 45, k + 24, 1, 2);
		setBlock(world, i + 1, j + 45, k + 25, Blocks.log, 1);
		world.setBlockMetadataWithNotify(i + 1, j + 45, k + 25, 1, 2);
		setBlock(world, i + 1, j + 45, k + 26, Blocks.log, 1);
		world.setBlockMetadataWithNotify(i + 1, j + 45, k + 26, 1, 2);
		setBlock(world, i + 1, j + 46, k + 8, Blocks.leaves, 15);
		world.setBlockMetadataWithNotify(i + 1, j + 46, k + 8, 15, 2);
		setBlock(world, i + 1, j + 46, k + 9, Blocks.leaves, 15);
		world.setBlockMetadataWithNotify(i + 1, j + 46, k + 9, 15, 2);
		setBlock(world, i + 1, j + 46, k + 10, Blocks.log, 1);
		world.setBlockMetadataWithNotify(i + 1, j + 46, k + 10, 1, 2);
		setBlock(world, i + 1, j + 46, k + 11, Blocks.log, 1);
		world.setBlockMetadataWithNotify(i + 1, j + 46, k + 11, 1, 2);
		setBlock(world, i + 1, j + 46, k + 12, Blocks.log, 1);
		world.setBlockMetadataWithNotify(i + 1, j + 46, k + 12, 1, 2);
		setBlock(world, i + 1, j + 46, k + 13, Blocks.log, 1);
		world.setBlockMetadataWithNotify(i + 1, j + 46, k + 13, 1, 2);
		setBlock(world, i + 1, j + 46, k + 14, Blocks.log, 1);
		world.setBlockMetadataWithNotify(i + 1, j + 46, k + 14, 1, 2);
		setBlock(world, i + 1, j + 46, k + 15, Blocks.log, 1);
		world.setBlockMetadataWithNotify(i + 1, j + 46, k + 15, 1, 2);
		setBlock(world, i + 1, j + 46, k + 17, Blocks.log, 1);
		world.setBlockMetadataWithNotify(i + 1, j + 46, k + 17, 1, 2);
		setBlock(world, i + 1, j + 46, k + 18, Blocks.log, 1);
		world.setBlockMetadataWithNotify(i + 1, j + 46, k + 18, 1, 2);
		setBlock(world, i + 1, j + 46, k + 19, Blocks.log, 1);
		world.setBlockMetadataWithNotify(i + 1, j + 46, k + 19, 1, 2);
		setBlock(world, i + 1, j + 46, k + 21, Blocks.log, 1);
		world.setBlockMetadataWithNotify(i + 1, j + 46, k + 21, 1, 2);
		setBlock(world, i + 1, j + 46, k + 22, Blocks.log, 1);
		world.setBlockMetadataWithNotify(i + 1, j + 46, k + 22, 1, 2);
		setBlock(world, i + 1, j + 46, k + 23, Blocks.log, 1);
		world.setBlockMetadataWithNotify(i + 1, j + 46, k + 23, 1, 2);
		setBlock(world, i + 1, j + 46, k + 24, Blocks.log, 1);
		world.setBlockMetadataWithNotify(i + 1, j + 46, k + 24, 1, 2);
		setBlock(world, i + 1, j + 46, k + 25, Blocks.log, 1);
		world.setBlockMetadataWithNotify(i + 1, j + 46, k + 25, 1, 2);
		setBlock(world, i + 1, j + 46, k + 26, Blocks.log, 1);
		world.setBlockMetadataWithNotify(i + 1, j + 46, k + 26, 1, 2);
		setBlock(world, i + 1, j + 47, k + 7, Blocks.leaves, 15);
		world.setBlockMetadataWithNotify(i + 1, j + 47, k + 7, 15, 2);
		setBlock(world, i + 1, j + 47, k + 8, Blocks.leaves, 15);
		world.setBlockMetadataWithNotify(i + 1, j + 47, k + 8, 15, 2);
		setBlock(world, i + 1, j + 47, k + 9, Blocks.leaves, 15);
		world.setBlockMetadataWithNotify(i + 1, j + 47, k + 9, 15, 2);
		setBlock(world, i + 1, j + 47, k + 10, Blocks.leaves, 15);
		world.setBlockMetadataWithNotify(i + 1, j + 47, k + 10, 15, 2);
		setBlock(world, i + 1, j + 47, k + 11, Blocks.log, 1);
		world.setBlockMetadataWithNotify(i + 1, j + 47, k + 11, 1, 2);
		setBlock(world, i + 1, j + 47, k + 12, Blocks.log, 1);
		world.setBlockMetadataWithNotify(i + 1, j + 47, k + 12, 1, 2);
		setBlock(world, i + 1, j + 47, k + 13, Blocks.log, 1);
		world.setBlockMetadataWithNotify(i + 1, j + 47, k + 13, 1, 2);
		setBlock(world, i + 1, j + 47, k + 14, Blocks.log, 1);
		world.setBlockMetadataWithNotify(i + 1, j + 47, k + 14, 1, 2);
		setBlock(world, i + 1, j + 47, k + 15, Blocks.log, 1);
		world.setBlockMetadataWithNotify(i + 1, j + 47, k + 15, 1, 2);
		setBlock(world, i + 1, j + 47, k + 16, Blocks.log, 1);
		world.setBlockMetadataWithNotify(i + 1, j + 47, k + 16, 1, 2);
		setBlock(world, i + 1, j + 47, k + 17, Blocks.log, 1);
		world.setBlockMetadataWithNotify(i + 1, j + 47, k + 17, 1, 2);
		setBlock(world, i + 1, j + 47, k + 18, Blocks.log, 1);
		world.setBlockMetadataWithNotify(i + 1, j + 47, k + 18, 1, 2);
		setBlock(world, i + 1, j + 47, k + 19, Blocks.log, 1);
		world.setBlockMetadataWithNotify(i + 1, j + 47, k + 19, 1, 2);
		setBlock(world, i + 1, j + 47, k + 20, Blocks.log, 1);
		world.setBlockMetadataWithNotify(i + 1, j + 47, k + 20, 1, 2);
		setBlock(world, i + 1, j + 47, k + 21, Blocks.log, 1);
		world.setBlockMetadataWithNotify(i + 1, j + 47, k + 21, 1, 2);
		setBlock(world, i + 1, j + 47, k + 22, Blocks.log, 1);
		world.setBlockMetadataWithNotify(i + 1, j + 47, k + 22, 1, 2);
		setBlock(world, i + 1, j + 47, k + 23, Blocks.log, 1);
		world.setBlockMetadataWithNotify(i + 1, j + 47, k + 23, 1, 2);
		setBlock(world, i + 1, j + 47, k + 24, Blocks.log, 1);
		world.setBlockMetadataWithNotify(i + 1, j + 47, k + 24, 1, 2);
		setBlock(world, i + 1, j + 47, k + 25, Blocks.log, 1);
		world.setBlockMetadataWithNotify(i + 1, j + 47, k + 25, 1, 2);
		setBlock(world, i + 1, j + 48, k + 8, Blocks.leaves, 15);
		world.setBlockMetadataWithNotify(i + 1, j + 48, k + 8, 15, 2);
		setBlock(world, i + 1, j + 48, k + 9, Blocks.leaves, 15);
		world.setBlockMetadataWithNotify(i + 1, j + 48, k + 9, 15, 2);
		setBlock(world, i + 1, j + 48, k + 10, Blocks.leaves, 15);
		world.setBlockMetadataWithNotify(i + 1, j + 48, k + 10, 15, 2);
		setBlock(world, i + 1, j + 48, k + 11, Blocks.leaves, 7);
		world.setBlockMetadataWithNotify(i + 1, j + 48, k + 11, 7, 2);
		setBlock(world, i + 1, j + 48, k + 12, Blocks.log, 1);
		world.setBlockMetadataWithNotify(i + 1, j + 48, k + 12, 1, 2);
		setBlock(world, i + 1, j + 48, k + 13, Blocks.log, 1);
		world.setBlockMetadataWithNotify(i + 1, j + 48, k + 13, 1, 2);
		setBlock(world, i + 1, j + 48, k + 14, Blocks.log, 1);
		world.setBlockMetadataWithNotify(i + 1, j + 48, k + 14, 1, 2);
		setBlock(world, i + 1, j + 48, k + 15, Blocks.log, 1);
		world.setBlockMetadataWithNotify(i + 1, j + 48, k + 15, 1, 2);
		setBlock(world, i + 1, j + 48, k + 16, Blocks.log, 1);
		world.setBlockMetadataWithNotify(i + 1, j + 48, k + 16, 1, 2);
		setBlock(world, i + 1, j + 48, k + 17, Blocks.log, 1);
		world.setBlockMetadataWithNotify(i + 1, j + 48, k + 17, 1, 2);
		setBlock(world, i + 1, j + 48, k + 18, Blocks.log, 1);
		world.setBlockMetadataWithNotify(i + 1, j + 48, k + 18, 1, 2);
		setBlock(world, i + 1, j + 48, k + 19, Blocks.log, 1);
		world.setBlockMetadataWithNotify(i + 1, j + 48, k + 19, 1, 2);
		setBlock(world, i + 1, j + 48, k + 20, Blocks.log, 1);
		world.setBlockMetadataWithNotify(i + 1, j + 48, k + 20, 1, 2);
		setBlock(world, i + 1, j + 48, k + 21, Blocks.log, 1);
		world.setBlockMetadataWithNotify(i + 1, j + 48, k + 21, 1, 2);
		setBlock(world, i + 1, j + 48, k + 22, Blocks.log, 1);
		world.setBlockMetadataWithNotify(i + 1, j + 48, k + 22, 1, 2);
		setBlock(world, i + 1, j + 48, k + 23, Blocks.log, 1);
		world.setBlockMetadataWithNotify(i + 1, j + 48, k + 23, 1, 2);
		setBlock(world, i + 1, j + 48, k + 24, Blocks.log, 1);
		world.setBlockMetadataWithNotify(i + 1, j + 48, k + 24, 1, 2);
		setBlock(world, i + 1, j + 49, k + 1, Blocks.leaves, 15);
		world.setBlockMetadataWithNotify(i + 1, j + 49, k + 1, 15, 2);
		setBlock(world, i + 1, j + 49, k + 2, Blocks.leaves, 7);
		world.setBlockMetadataWithNotify(i + 1, j + 49, k + 2, 7, 2);
		setBlock(world, i + 1, j + 49, k + 3, Blocks.leaves, 7);
		world.setBlockMetadataWithNotify(i + 1, j + 49, k + 3, 7, 2);
		setBlock(world, i + 1, j + 49, k + 9, Blocks.leaves, 7);
		world.setBlockMetadataWithNotify(i + 1, j + 49, k + 9, 7, 2);
		setBlock(world, i + 1, j + 49, k + 10, Blocks.leaves, 7);
		world.setBlockMetadataWithNotify(i + 1, j + 49, k + 10, 7, 2);
		setBlock(world, i + 1, j + 49, k + 11, Blocks.leaves, 7);
		world.setBlockMetadataWithNotify(i + 1, j + 49, k + 11, 7, 2);
		setBlock(world, i + 1, j + 49, k + 12, Blocks.leaves, 7);
		world.setBlockMetadataWithNotify(i + 1, j + 49, k + 12, 7, 2);
		setBlock(world, i + 1, j + 49, k + 13, Blocks.leaves, 7);
		world.setBlockMetadataWithNotify(i + 1, j + 49, k + 13, 7, 2);
		setBlock(world, i + 1, j + 49, k + 14, Blocks.leaves, 7);
		world.setBlockMetadataWithNotify(i + 1, j + 49, k + 14, 7, 2);
		setBlock(world, i + 1, j + 49, k + 15, Blocks.log, 1);
		world.setBlockMetadataWithNotify(i + 1, j + 49, k + 15, 1, 2);
		setBlock(world, i + 1, j + 49, k + 16, Blocks.log, 1);
		world.setBlockMetadataWithNotify(i + 1, j + 49, k + 16, 1, 2);
		setBlock(world, i + 1, j + 49, k + 17, Blocks.log, 1);
		world.setBlockMetadataWithNotify(i + 1, j + 49, k + 17, 1, 2);
		setBlock(world, i + 1, j + 49, k + 18, Blocks.log, 1);
		world.setBlockMetadataWithNotify(i + 1, j + 49, k + 18, 1, 2);
		setBlock(world, i + 1, j + 49, k + 19, Blocks.log, 1);
		world.setBlockMetadataWithNotify(i + 1, j + 49, k + 19, 1, 2);
		setBlock(world, i + 1, j + 49, k + 20, Blocks.log, 1);
		world.setBlockMetadataWithNotify(i + 1, j + 49, k + 20, 1, 2);
		setBlock(world, i + 1, j + 49, k + 21, Blocks.log, 1);
		world.setBlockMetadataWithNotify(i + 1, j + 49, k + 21, 1, 2);
		setBlock(world, i + 1, j + 50, k + 0, Blocks.leaves, 15);
		world.setBlockMetadataWithNotify(i + 1, j + 50, k + 0, 15, 2);
		setBlock(world, i + 1, j + 50, k + 1, Blocks.log, 3);
		world.setBlockMetadataWithNotify(i + 1, j + 50, k + 1, 3, 2);
		setBlock(world, i + 1, j + 50, k + 2, Blocks.leaves, 7);
		world.setBlockMetadataWithNotify(i + 1, j + 50, k + 2, 7, 2);
		setBlock(world, i + 1, j + 50, k + 3, Blocks.leaves, 7);
		world.setBlockMetadataWithNotify(i + 1, j + 50, k + 3, 7, 2);
		setBlock(world, i + 1, j + 50, k + 10, Blocks.leaves, 7);
		world.setBlockMetadataWithNotify(i + 1, j + 50, k + 10, 7, 2);
		setBlock(world, i + 1, j + 50, k + 11, Blocks.leaves, 7);
		world.setBlockMetadataWithNotify(i + 1, j + 50, k + 11, 7, 2);
		setBlock(world, i + 1, j + 50, k + 12, Blocks.leaves, 7);
		world.setBlockMetadataWithNotify(i + 1, j + 50, k + 12, 7, 2);
		setBlock(world, i + 1, j + 50, k + 13, Blocks.leaves, 7);
		world.setBlockMetadataWithNotify(i + 1, j + 50, k + 13, 7, 2);
		setBlock(world, i + 1, j + 51, k + 0, Blocks.leaves, 7);
		world.setBlockMetadataWithNotify(i + 1, j + 51, k + 0, 7, 2);
		setBlock(world, i + 1, j + 51, k + 1, Blocks.leaves, 7);
		world.setBlockMetadataWithNotify(i + 1, j + 51, k + 1, 7, 2);
		setBlock(world, i + 1, j + 51, k + 2, Blocks.leaves, 7);
		world.setBlockMetadataWithNotify(i + 1, j + 51, k + 2, 7, 2);
		setBlock(world, i + 1, j + 51, k + 3, Blocks.leaves, 7);
		world.setBlockMetadataWithNotify(i + 1, j + 51, k + 3, 7, 2);
		setBlock(world, i + 1, j + 51, k + 4, Blocks.leaves, 7);
		world.setBlockMetadataWithNotify(i + 1, j + 51, k + 4, 7, 2);
		setBlock(world, i + 1, j + 51, k + 12, Blocks.leaves, 7);
		world.setBlockMetadataWithNotify(i + 1, j + 51, k + 12, 7, 2);
		setBlock(world, i + 1, j + 52, k + 0, Blocks.leaves, 7);
		world.setBlockMetadataWithNotify(i + 1, j + 52, k + 0, 7, 2);
		setBlock(world, i + 1, j + 52, k + 1, Blocks.leaves, 7);
		world.setBlockMetadataWithNotify(i + 1, j + 52, k + 1, 7, 2);
		setBlock(world, i + 1, j + 52, k + 2, Blocks.leaves, 7);
		world.setBlockMetadataWithNotify(i + 1, j + 52, k + 2, 7, 2);
		setBlock(world, i + 1, j + 52, k + 3, Blocks.leaves, 7);
		world.setBlockMetadataWithNotify(i + 1, j + 52, k + 3, 7, 2);
		setBlock(world, i + 1, j + 53, k + 1, Blocks.leaves, 7);
		world.setBlockMetadataWithNotify(i + 1, j + 53, k + 1, 7, 2);
		setBlock(world, i + 1, j + 54, k + 2, Blocks.leaves, 7);
		world.setBlockMetadataWithNotify(i + 1, j + 54, k + 2, 7, 2);
		setBlock(world, i + 1, j + 54, k + 3, Blocks.leaves, 7);
		world.setBlockMetadataWithNotify(i + 1, j + 54, k + 3, 7, 2);
		setBlock(world, i + 1, j + 54, k + 4, Blocks.leaves, 7);
		world.setBlockMetadataWithNotify(i + 1, j + 54, k + 4, 7, 2);
		setBlock(world, i + 1, j + 55, k + 3, Blocks.leaves, 7);
		world.setBlockMetadataWithNotify(i + 1, j + 55, k + 3, 7, 2);
		setBlock(world, i + 1, j + 57, k + 8, Blocks.leaves, 7);
		world.setBlockMetadataWithNotify(i + 1, j + 57, k + 8, 7, 2);
		setBlock(world, i + 1, j + 57, k + 9, Blocks.leaves, 7);
		world.setBlockMetadataWithNotify(i + 1, j + 57, k + 9, 7, 2);
		setBlock(world, i + 1, j + 57, k + 10, Blocks.leaves, 7);
		world.setBlockMetadataWithNotify(i + 1, j + 57, k + 10, 7, 2);
		setBlock(world, i + 1, j + 57, k + 11, Blocks.leaves, 7);
		world.setBlockMetadataWithNotify(i + 1, j + 57, k + 11, 7, 2);
		setBlock(world, i + 1, j + 57, k + 12, Blocks.leaves, 7);
		world.setBlockMetadataWithNotify(i + 1, j + 57, k + 12, 7, 2);
		setBlock(world, i + 1, j + 58, k + 9, Blocks.leaves, 7);
		world.setBlockMetadataWithNotify(i + 1, j + 58, k + 9, 7, 2);
		setBlock(world, i + 1, j + 58, k + 10, Blocks.leaves, 7);
		world.setBlockMetadataWithNotify(i + 1, j + 58, k + 10, 7, 2);
		setBlock(world, i + 1, j + 58, k + 11, Blocks.leaves, 7);
		world.setBlockMetadataWithNotify(i + 1, j + 58, k + 11, 7, 2);
		setBlock(world, i + 1, j + 59, k + 10, Blocks.leaves, 7);
		world.setBlockMetadataWithNotify(i + 1, j + 59, k + 10, 7, 2);
		setBlock(world, i + 2, j + 22, k + 4, Blocks.log, 3);
		world.setBlockMetadataWithNotify(i + 2, j + 22, k + 4, 3, 2);
		setBlock(world, i + 2, j + 23, k + 12, Blocks.log, 3);
		world.setBlockMetadataWithNotify(i + 2, j + 23, k + 12, 3, 2);
		setBlock(world, i + 2, j + 23, k + 21, Blocks.log, 3);
		world.setBlockMetadataWithNotify(i + 2, j + 23, k + 21, 3, 2);
		setBlock(world, i + 2, j + 24, k + 3, Blocks.log, 3);
		world.setBlockMetadataWithNotify(i + 2, j + 24, k + 3, 3, 2);
		setBlock(world, i + 2, j + 24, k + 7, Blocks.leaves, 7);
		world.setBlockMetadataWithNotify(i + 2, j + 24, k + 7, 7, 2);
		setBlock(world, i + 2, j + 24, k + 8, Blocks.leaves, 7);
		world.setBlockMetadataWithNotify(i + 2, j + 24, k + 8, 7, 2);
		setBlock(world, i + 2, j + 24, k + 9, Blocks.leaves, 7);
		world.setBlockMetadataWithNotify(i + 2, j + 24, k + 9, 7, 2);
		setBlock(world, i + 2, j + 24, k + 16, Blocks.log, 3);
		world.setBlockMetadataWithNotify(i + 2, j + 24, k + 16, 3, 2);
		setBlock(world, i + 2, j + 24, k + 17, Blocks.log, 3);
		world.setBlockMetadataWithNotify(i + 2, j + 24, k + 17, 3, 2);
		setBlock(world, i + 2, j + 24, k + 18, Blocks.log, 3);
		world.setBlockMetadataWithNotify(i + 2, j + 24, k + 18, 3, 2);
		setBlock(world, i + 2, j + 24, k + 20, Blocks.leaves, 7);
		world.setBlockMetadataWithNotify(i + 2, j + 24, k + 20, 7, 2);
		setBlock(world, i + 2, j + 24, k + 21, Blocks.leaves, 7);
		world.setBlockMetadataWithNotify(i + 2, j + 24, k + 21, 7, 2);
		setBlock(world, i + 2, j + 24, k + 22, Blocks.leaves, 7);
		world.setBlockMetadataWithNotify(i + 2, j + 24, k + 22, 7, 2);
		setBlock(world, i + 2, j + 24, k + 23, Blocks.leaves, 7);
		world.setBlockMetadataWithNotify(i + 2, j + 24, k + 23, 7, 2);
		setBlock(world, i + 2, j + 24, k + 24, Blocks.leaves, 7);
		world.setBlockMetadataWithNotify(i + 2, j + 24, k + 24, 7, 2);
		setBlock(world, i + 2, j + 25, k + 8, Blocks.leaves, 7);
		world.setBlockMetadataWithNotify(i + 2, j + 25, k + 8, 7, 2);
		setBlock(world, i + 2, j + 25, k + 11, Blocks.log, 3);
		world.setBlockMetadataWithNotify(i + 2, j + 25, k + 11, 3, 2);
		setBlock(world, i + 2, j + 25, k + 21, Blocks.log, 3);
		world.setBlockMetadataWithNotify(i + 2, j + 25, k + 21, 3, 2);
		setBlock(world, i + 2, j + 25, k + 22, Blocks.leaves, 7);
		world.setBlockMetadataWithNotify(i + 2, j + 25, k + 22, 7, 2);
		setBlock(world, i + 2, j + 25, k + 23, Blocks.leaves, 7);
		world.setBlockMetadataWithNotify(i + 2, j + 25, k + 23, 7, 2);
		setBlock(world, i + 2, j + 26, k + 22, Blocks.leaves, 7);
		world.setBlockMetadataWithNotify(i + 2, j + 26, k + 22, 7, 2);
		setBlock(world, i + 2, j + 28, k + 2, Blocks.log, 3);
		world.setBlockMetadataWithNotify(i + 2, j + 28, k + 2, 3, 2);
		setBlock(world, i + 2, j + 31, k + 21, Blocks.log, 3);
		world.setBlockMetadataWithNotify(i + 2, j + 31, k + 21, 3, 2);
		setBlock(world, i + 2, j + 32, k + 7, Blocks.log, 3);
		world.setBlockMetadataWithNotify(i + 2, j + 32, k + 7, 3, 2);
		setBlock(world, i + 2, j + 32, k + 16, Blocks.log, 3);
		world.setBlockMetadataWithNotify(i + 2, j + 32, k + 16, 3, 2);
		setBlock(world, i + 2, j + 32, k + 20, Blocks.leaves, 7);
		world.setBlockMetadataWithNotify(i + 2, j + 32, k + 20, 7, 2);
		setBlock(world, i + 2, j + 32, k + 21, Blocks.log, 1);
		world.setBlockMetadataWithNotify(i + 2, j + 32, k + 21, 1, 2);
		setBlock(world, i + 2, j + 32, k + 22, Blocks.log, 1);
		world.setBlockMetadataWithNotify(i + 2, j + 32, k + 22, 1, 2);
		setBlock(world, i + 2, j + 32, k + 23, Blocks.leaves, 7);
		world.setBlockMetadataWithNotify(i + 2, j + 32, k + 23, 7, 2);
		setBlock(world, i + 2, j + 32, k + 24, Blocks.leaves, 7);
		world.setBlockMetadataWithNotify(i + 2, j + 32, k + 24, 7, 2);
		setBlock(world, i + 2, j + 33, k + 14, Blocks.leaves, 7);
		world.setBlockMetadataWithNotify(i + 2, j + 33, k + 14, 7, 2);
		setBlock(world, i + 2, j + 33, k + 15, Blocks.leaves, 7);
		world.setBlockMetadataWithNotify(i + 2, j + 33, k + 15, 7, 2);
		setBlock(world, i + 2, j + 33, k + 16, Blocks.leaves, 7);
		world.setBlockMetadataWithNotify(i + 2, j + 33, k + 16, 7, 2);
		setBlock(world, i + 2, j + 33, k + 17, Blocks.leaves, 7);
		world.setBlockMetadataWithNotify(i + 2, j + 33, k + 17, 7, 2);
		setBlock(world, i + 2, j + 33, k + 18, Blocks.leaves, 7);
		world.setBlockMetadataWithNotify(i + 2, j + 33, k + 18, 7, 2);
		setBlock(world, i + 2, j + 33, k + 21, Blocks.log, 1);
		world.setBlockMetadataWithNotify(i + 2, j + 33, k + 21, 1, 2);
		setBlock(world, i + 2, j + 33, k + 22, Blocks.log, 1);
		world.setBlockMetadataWithNotify(i + 2, j + 33, k + 22, 1, 2);
		setBlock(world, i + 2, j + 33, k + 23, Blocks.log, 1);
		world.setBlockMetadataWithNotify(i + 2, j + 33, k + 23, 1, 2);
		setBlock(world, i + 2, j + 34, k + 11, Blocks.leaves, 7);
		world.setBlockMetadataWithNotify(i + 2, j + 34, k + 11, 7, 2);
		setBlock(world, i + 2, j + 34, k + 12, Blocks.leaves, 7);
		world.setBlockMetadataWithNotify(i + 2, j + 34, k + 12, 7, 2);
		setBlock(world, i + 2, j + 34, k + 13, Blocks.log, 3);
		world.setBlockMetadataWithNotify(i + 2, j + 34, k + 13, 3, 2);
		setBlock(world, i + 2, j + 34, k + 14, Blocks.leaves, 7);
		world.setBlockMetadataWithNotify(i + 2, j + 34, k + 14, 7, 2);
		setBlock(world, i + 2, j + 34, k + 15, Blocks.leaves, 7);
		world.setBlockMetadataWithNotify(i + 2, j + 34, k + 15, 7, 2);
		setBlock(world, i + 2, j + 34, k + 16, Blocks.leaves, 7);
		world.setBlockMetadataWithNotify(i + 2, j + 34, k + 16, 7, 2);
		setBlock(world, i + 2, j + 34, k + 17, Blocks.leaves, 7);
		world.setBlockMetadataWithNotify(i + 2, j + 34, k + 17, 7, 2);
		setBlock(world, i + 2, j + 34, k + 21, Blocks.log, 1);
		world.setBlockMetadataWithNotify(i + 2, j + 34, k + 21, 1, 2);
		setBlock(world, i + 2, j + 34, k + 22, Blocks.log, 1);
		world.setBlockMetadataWithNotify(i + 2, j + 34, k + 22, 1, 2);
		setBlock(world, i + 2, j + 34, k + 23, Blocks.log, 1);
		world.setBlockMetadataWithNotify(i + 2, j + 34, k + 23, 1, 2);
		setBlock(world, i + 2, j + 35, k + 11, Blocks.leaves, 7);
		world.setBlockMetadataWithNotify(i + 2, j + 35, k + 11, 7, 2);
		setBlock(world, i + 2, j + 35, k + 12, Blocks.leaves, 7);
		world.setBlockMetadataWithNotify(i + 2, j + 35, k + 12, 7, 2);
		setBlock(world, i + 2, j + 35, k + 13, Blocks.leaves, 7);
		world.setBlockMetadataWithNotify(i + 2, j + 35, k + 13, 7, 2);
		setBlock(world, i + 2, j + 35, k + 14, Blocks.leaves, 7);
		world.setBlockMetadataWithNotify(i + 2, j + 35, k + 14, 7, 2);
		setBlock(world, i + 2, j + 35, k + 15, Blocks.leaves, 7);
		world.setBlockMetadataWithNotify(i + 2, j + 35, k + 15, 7, 2);
		setBlock(world, i + 2, j + 35, k + 16, Blocks.leaves, 7);
		world.setBlockMetadataWithNotify(i + 2, j + 35, k + 16, 7, 2);
		setBlock(world, i + 2, j + 35, k + 18, Blocks.log, 1);
		world.setBlockMetadataWithNotify(i + 2, j + 35, k + 18, 1, 2);
		setBlock(world, i + 2, j + 35, k + 19, Blocks.log, 1);
		world.setBlockMetadataWithNotify(i + 2, j + 35, k + 19, 1, 2);
		setBlock(world, i + 2, j + 35, k + 20, Blocks.log, 1);
		world.setBlockMetadataWithNotify(i + 2, j + 35, k + 20, 1, 2);
		setBlock(world, i + 2, j + 35, k + 21, Blocks.log, 1);
		world.setBlockMetadataWithNotify(i + 2, j + 35, k + 21, 1, 2);
		setBlock(world, i + 2, j + 35, k + 22, Blocks.log, 1);
		world.setBlockMetadataWithNotify(i + 2, j + 35, k + 22, 1, 2);
		setBlock(world, i + 2, j + 36, k + 12, Blocks.leaves, 15);
		world.setBlockMetadataWithNotify(i + 2, j + 36, k + 12, 15, 2);
		setBlock(world, i + 2, j + 36, k + 13, Blocks.leaves, 15);
		world.setBlockMetadataWithNotify(i + 2, j + 36, k + 13, 15, 2);
		setBlock(world, i + 2, j + 36, k + 14, Blocks.leaves, 15);
		world.setBlockMetadataWithNotify(i + 2, j + 36, k + 14, 15, 2);
		setBlock(world, i + 2, j + 36, k + 18, Blocks.log, 1);
		world.setBlockMetadataWithNotify(i + 2, j + 36, k + 18, 1, 2);
		setBlock(world, i + 2, j + 36, k + 19, Blocks.log, 1);
		world.setBlockMetadataWithNotify(i + 2, j + 36, k + 19, 1, 2);
		setBlock(world, i + 2, j + 36, k + 20, Blocks.log, 1);
		world.setBlockMetadataWithNotify(i + 2, j + 36, k + 20, 1, 2);
		setBlock(world, i + 2, j + 36, k + 21, Blocks.log, 1);
		world.setBlockMetadataWithNotify(i + 2, j + 36, k + 21, 1, 2);
		setBlock(world, i + 2, j + 36, k + 28, Blocks.vine, 5);
		world.setBlockMetadataWithNotify(i + 2, j + 36, k + 28, 5, 2);
		setBlock(world, i + 2, j + 37, k + 13, Blocks.leaves, 15);
		world.setBlockMetadataWithNotify(i + 2, j + 37, k + 13, 15, 2);
		setBlock(world, i + 2, j + 37, k + 16, Blocks.leaves, 15);
		world.setBlockMetadataWithNotify(i + 2, j + 37, k + 16, 15, 2);
		setBlock(world, i + 2, j + 37, k + 17, Blocks.leaves, 15);
		world.setBlockMetadataWithNotify(i + 2, j + 37, k + 17, 15, 2);
		setBlock(world, i + 2, j + 37, k + 18, Blocks.log, 1);
		world.setBlockMetadataWithNotify(i + 2, j + 37, k + 18, 1, 2);
		setBlock(world, i + 2, j + 37, k + 19, Blocks.log, 1);
		world.setBlockMetadataWithNotify(i + 2, j + 37, k + 19, 1, 2);
		setBlock(world, i + 2, j + 37, k + 20, Blocks.log, 1);
		world.setBlockMetadataWithNotify(i + 2, j + 37, k + 20, 1, 2);
		setBlock(world, i + 2, j + 37, k + 21, Blocks.log, 1);
		world.setBlockMetadataWithNotify(i + 2, j + 37, k + 21, 1, 2);
		setBlock(world, i + 2, j + 37, k + 28, Blocks.vine, 13);
		world.setBlockMetadataWithNotify(i + 2, j + 37, k + 28, 13, 2);
		setBlock(world, i + 2, j + 38, k + 7, Blocks.leaves, 15);
		world.setBlockMetadataWithNotify(i + 2, j + 38, k + 7, 15, 2);
		setBlock(world, i + 2, j + 38, k + 8, Blocks.leaves, 15);
		world.setBlockMetadataWithNotify(i + 2, j + 38, k + 8, 15, 2);
		setBlock(world, i + 2, j + 38, k + 9, Blocks.leaves, 15);
		world.setBlockMetadataWithNotify(i + 2, j + 38, k + 9, 15, 2);
		setBlock(world, i + 2, j + 38, k + 10, Blocks.log, 3);
		world.setBlockMetadataWithNotify(i + 2, j + 38, k + 10, 3, 2);
		setBlock(world, i + 2, j + 38, k + 16, Blocks.leaves, 15);
		world.setBlockMetadataWithNotify(i + 2, j + 38, k + 16, 15, 2);
		setBlock(world, i + 2, j + 38, k + 17, Blocks.log, 1);
		world.setBlockMetadataWithNotify(i + 2, j + 38, k + 17, 1, 2);
		setBlock(world, i + 2, j + 38, k + 18, Blocks.log, 1);
		world.setBlockMetadataWithNotify(i + 2, j + 38, k + 18, 1, 2);
		setBlock(world, i + 2, j + 38, k + 19, Blocks.log, 1);
		world.setBlockMetadataWithNotify(i + 2, j + 38, k + 19, 1, 2);
		setBlock(world, i + 2, j + 38, k + 20, Blocks.log, 1);
		world.setBlockMetadataWithNotify(i + 2, j + 38, k + 20, 1, 2);
		setBlock(world, i + 2, j + 38, k + 21, Blocks.log, 1);
		world.setBlockMetadataWithNotify(i + 2, j + 38, k + 21, 1, 2);
		setBlock(world, i + 2, j + 38, k + 22, Blocks.log, 1);
		world.setBlockMetadataWithNotify(i + 2, j + 38, k + 22, 1, 2);
		setBlock(world, i + 2, j + 38, k + 23, Blocks.vine, 13);
		world.setBlockMetadataWithNotify(i + 2, j + 38, k + 23, 13, 2);
		setBlock(world, i + 2, j + 38, k + 24, Blocks.vine, 13);
		world.setBlockMetadataWithNotify(i + 2, j + 38, k + 24, 13, 2);
		setBlock(world, i + 2, j + 38, k + 25, Blocks.vine, 5);
		world.setBlockMetadataWithNotify(i + 2, j + 38, k + 25, 5, 2);
		setBlock(world, i + 2, j + 38, k + 28, Blocks.vine, 15);
		world.setBlockMetadataWithNotify(i + 2, j + 38, k + 28, 15, 2);
		setBlock(world, i + 2, j + 39, k + 17, Blocks.leaves, 15);
		world.setBlockMetadataWithNotify(i + 2, j + 39, k + 17, 15, 2);
		setBlock(world, i + 2, j + 39, k + 18, Blocks.log, 1);
		world.setBlockMetadataWithNotify(i + 2, j + 39, k + 18, 1, 2);
		setBlock(world, i + 2, j + 39, k + 19, Blocks.log, 1);
		world.setBlockMetadataWithNotify(i + 2, j + 39, k + 19, 1, 2);
		setBlock(world, i + 2, j + 39, k + 20, Blocks.log, 1);
		world.setBlockMetadataWithNotify(i + 2, j + 39, k + 20, 1, 2);
		setBlock(world, i + 2, j + 39, k + 21, Blocks.log, 1);
		world.setBlockMetadataWithNotify(i + 2, j + 39, k + 21, 1, 2);
		setBlock(world, i + 2, j + 39, k + 22, Blocks.log, 1);
		world.setBlockMetadataWithNotify(i + 2, j + 39, k + 22, 1, 2);
		setBlock(world, i + 2, j + 39, k + 23, Blocks.vine, 15);
		world.setBlockMetadataWithNotify(i + 2, j + 39, k + 23, 15, 2);
		setBlock(world, i + 2, j + 39, k + 24, Blocks.vine, 15);
		world.setBlockMetadataWithNotify(i + 2, j + 39, k + 24, 15, 2);
		setBlock(world, i + 2, j + 39, k + 25, Blocks.vine, 15);
		world.setBlockMetadataWithNotify(i + 2, j + 39, k + 25, 15, 2);
		setBlock(world, i + 2, j + 39, k + 26, Blocks.vine, 15);
		world.setBlockMetadataWithNotify(i + 2, j + 39, k + 26, 15, 2);
		setBlock(world, i + 2, j + 39, k + 27, Blocks.vine, 15);
		world.setBlockMetadataWithNotify(i + 2, j + 39, k + 27, 15, 2);
		setBlock(world, i + 2, j + 39, k + 28, Blocks.vine, 15);
		world.setBlockMetadataWithNotify(i + 2, j + 39, k + 28, 15, 2);
		setBlock(world, i + 2, j + 40, k + 0, Blocks.planks, 5);
		world.setBlockMetadataWithNotify(i + 2, j + 40, k + 0, 5, 2);
		setBlock(world, i + 2, j + 40, k + 1, Blocks.planks, 5);
		world.setBlockMetadataWithNotify(i + 2, j + 40, k + 1, 5, 2);
		setBlock(world, i + 2, j + 40, k + 2, Blocks.planks, 5);
		world.setBlockMetadataWithNotify(i + 2, j + 40, k + 2, 5, 2);
		setBlock(world, i + 2, j + 40, k + 3, Blocks.planks, 5);
		world.setBlockMetadataWithNotify(i + 2, j + 40, k + 3, 5, 2);
		setBlock(world, i + 2, j + 40, k + 4, Blocks.planks, 5);
		world.setBlockMetadataWithNotify(i + 2, j + 40, k + 4, 5, 2);
		setBlock(world, i + 2, j + 40, k + 5, Blocks.planks, 5);
		world.setBlockMetadataWithNotify(i + 2, j + 40, k + 5, 5, 2);
		setBlock(world, i + 2, j + 40, k + 6, Blocks.planks, 5);
		world.setBlockMetadataWithNotify(i + 2, j + 40, k + 6, 5, 2);
		setBlock(world, i + 2, j + 40, k + 7, Blocks.planks, 5);
		world.setBlockMetadataWithNotify(i + 2, j + 40, k + 7, 5, 2);
		setBlock(world, i + 2, j + 40, k + 8, Blocks.planks, 5);
		world.setBlockMetadataWithNotify(i + 2, j + 40, k + 8, 5, 2);
		setBlock(world, i + 2, j + 40, k + 9, Blocks.planks, 5);
		world.setBlockMetadataWithNotify(i + 2, j + 40, k + 9, 5, 2);
		setBlock(world, i + 2, j + 40, k + 10, Blocks.planks, 5);
		world.setBlockMetadataWithNotify(i + 2, j + 40, k + 10, 5, 2);
		setBlock(world, i + 2, j + 40, k + 11, Blocks.planks, 5);
		world.setBlockMetadataWithNotify(i + 2, j + 40, k + 11, 5, 2);
		setBlock(world, i + 2, j + 40, k + 12, Blocks.log, 1);
		world.setBlockMetadataWithNotify(i + 2, j + 40, k + 12, 1, 2);
		setBlock(world, i + 2, j + 40, k + 13, Blocks.planks, 5);
		world.setBlockMetadataWithNotify(i + 2, j + 40, k + 13, 5, 2);
		setBlock(world, i + 2, j + 40, k + 14, Blocks.planks, 5);
		world.setBlockMetadataWithNotify(i + 2, j + 40, k + 14, 5, 2);
		setBlock(world, i + 2, j + 40, k + 15, Blocks.log, 1);
		world.setBlockMetadataWithNotify(i + 2, j + 40, k + 15, 1, 2);
		setBlock(world, i + 2, j + 40, k + 16, Blocks.planks, 5);
		world.setBlockMetadataWithNotify(i + 2, j + 40, k + 16, 5, 2);
		setBlock(world, i + 2, j + 40, k + 17, Blocks.planks, 5);
		world.setBlockMetadataWithNotify(i + 2, j + 40, k + 17, 5, 2);
		setBlock(world, i + 2, j + 40, k + 18, Blocks.log, 1);
		world.setBlockMetadataWithNotify(i + 2, j + 40, k + 18, 1, 2);
		setBlock(world, i + 2, j + 40, k + 19, Blocks.planks, 5);
		world.setBlockMetadataWithNotify(i + 2, j + 40, k + 19, 5, 2);
		setBlock(world, i + 2, j + 40, k + 20, Blocks.planks, 5);
		world.setBlockMetadataWithNotify(i + 2, j + 40, k + 20, 5, 2);
		setBlock(world, i + 2, j + 40, k + 21, Blocks.log, 1);
		world.setBlockMetadataWithNotify(i + 2, j + 40, k + 21, 1, 2);
		setBlock(world, i + 2, j + 40, k + 22, Blocks.planks, 5);
		world.setBlockMetadataWithNotify(i + 2, j + 40, k + 22, 5, 2);
		setBlock(world, i + 2, j + 40, k + 23, Blocks.planks, 5);
		world.setBlockMetadataWithNotify(i + 2, j + 40, k + 23, 5, 2);
		setBlock(world, i + 2, j + 40, k + 24, Blocks.log, 1);
		world.setBlockMetadataWithNotify(i + 2, j + 40, k + 24, 1, 2);
		setBlock(world, i + 2, j + 40, k + 25, Blocks.planks, 5);
		world.setBlockMetadataWithNotify(i + 2, j + 40, k + 25, 5, 2);
		setBlock(world, i + 2, j + 40, k + 26, Blocks.planks, 5);
		world.setBlockMetadataWithNotify(i + 2, j + 40, k + 26, 5, 2);
		setBlock(world, i + 2, j + 40, k + 27, Blocks.planks, 5);
		world.setBlockMetadataWithNotify(i + 2, j + 40, k + 27, 5, 2);
		setBlock(world, i + 2, j + 40, k + 28, Blocks.planks, 5);
		world.setBlockMetadataWithNotify(i + 2, j + 40, k + 28, 5, 2);
		setBlock(world, i + 2, j + 40, k + 29, Blocks.planks, 5);
		world.setBlockMetadataWithNotify(i + 2, j + 40, k + 29, 5, 2);
		setBlock(world, i + 2, j + 40, k + 30, Blocks.planks, 5);
		world.setBlockMetadataWithNotify(i + 2, j + 40, k + 30, 5, 2);
		setBlock(world, i + 2, j + 40, k + 31, Blocks.planks, 5);
		world.setBlockMetadataWithNotify(i + 2, j + 40, k + 31, 5, 2);
		setBlock(world, i + 2, j + 41, k + 17, Blocks.chest, 2);
		LootGenUtils.fillLootChest(world.provider.dimensionId, world.rand, (TileEntityChest)world.getTileEntity(i + 2, j + 41, k + 17));
		world.setBlockMetadataWithNotify(i + 2, j + 41, k + 17, 2, 2);
		setBlock(world, i + 2, j + 41, k + 18, Blocks.spruce_stairs, 1);
		world.setBlockMetadataWithNotify(i + 2, j + 41, k + 18, 1, 2);
		setBlock(world, i + 2, j + 41, k + 19, Blocks.furnace, 3);
		world.setBlockMetadataWithNotify(i + 2, j + 41, k + 19, 3, 2);
		setBlock(world, i + 2, j + 43, k + 10, Blocks.torch, 2);
		world.setBlockMetadataWithNotify(i + 2, j + 43, k + 10, 2, 2);
		setBlock(world, i + 2, j + 43, k + 18, Blocks.torch, 1);
		world.setBlockMetadataWithNotify(i + 2, j + 43, k + 18, 1, 2);
		setBlock(world, i + 2, j + 43, k + 26, Blocks.torch, 2);
		world.setBlockMetadataWithNotify(i + 2, j + 43, k + 26, 2, 2);
		setBlock(world, i + 2, j + 44, k + 9, Blocks.log, 1);
		world.setBlockMetadataWithNotify(i + 2, j + 44, k + 9, 1, 2);
		setBlock(world, i + 2, j + 44, k + 10, Blocks.log, 1);
		world.setBlockMetadataWithNotify(i + 2, j + 44, k + 10, 1, 2);
		setBlock(world, i + 2, j + 44, k + 11, Blocks.log, 1);
		world.setBlockMetadataWithNotify(i + 2, j + 44, k + 11, 1, 2);
		setBlock(world, i + 2, j + 44, k + 12, Blocks.log, 1);
		world.setBlockMetadataWithNotify(i + 2, j + 44, k + 12, 1, 2);
		setBlock(world, i + 2, j + 44, k + 13, Blocks.log, 1);
		world.setBlockMetadataWithNotify(i + 2, j + 44, k + 13, 1, 2);
		
		generate2(world, rand, i, j, k);
		return true;
		}

	
	public boolean generate2(World world, Random rand, int i, int j, int k)
	{
		setBlock(world, i + 2, j + 44, k + 23, Blocks.log, 1);
		world.setBlockMetadataWithNotify(i + 2, j + 44, k + 23, 1, 2);
		setBlock(world, i + 2, j + 44, k + 24, Blocks.log, 1);
		world.setBlockMetadataWithNotify(i + 2, j + 44, k + 24, 1, 2);
		setBlock(world, i + 2, j + 44, k + 25, Blocks.log, 1);
		world.setBlockMetadataWithNotify(i + 2, j + 44, k + 25, 1, 2);
		setBlock(world, i + 2, j + 44, k + 26, Blocks.log, 1);
		world.setBlockMetadataWithNotify(i + 2, j + 44, k + 26, 1, 2);
		setBlock(world, i + 2, j + 44, k + 27, Blocks.log, 1);
		world.setBlockMetadataWithNotify(i + 2, j + 44, k + 27, 1, 2);
		setBlock(world, i + 2, j + 45, k + 9, Blocks.log, 3);
		world.setBlockMetadataWithNotify(i + 2, j + 45, k + 9, 3, 2);
		setBlock(world, i + 2, j + 45, k + 10, Blocks.log, 1);
		world.setBlockMetadataWithNotify(i + 2, j + 45, k + 10, 1, 2);
		setBlock(world, i + 2, j + 45, k + 11, Blocks.log, 1);
		world.setBlockMetadataWithNotify(i + 2, j + 45, k + 11, 1, 2);
		setBlock(world, i + 2, j + 45, k + 12, Blocks.log, 1);
		world.setBlockMetadataWithNotify(i + 2, j + 45, k + 12, 1, 2);
		setBlock(world, i + 2, j + 45, k + 13, Blocks.log, 1);
		world.setBlockMetadataWithNotify(i + 2, j + 45, k + 13, 1, 2);
		setBlock(world, i + 2, j + 45, k + 14, Blocks.log, 1);
		world.setBlockMetadataWithNotify(i + 2, j + 45, k + 14, 1, 2);
		setBlock(world, i + 2, j + 45, k + 22, Blocks.log, 1);
		world.setBlockMetadataWithNotify(i + 2, j + 45, k + 22, 1, 2);
		setBlock(world, i + 2, j + 45, k + 23, Blocks.log, 1);
		world.setBlockMetadataWithNotify(i + 2, j + 45, k + 23, 1, 2);
		setBlock(world, i + 2, j + 45, k + 24, Blocks.log, 1);
		world.setBlockMetadataWithNotify(i + 2, j + 45, k + 24, 1, 2);
		setBlock(world, i + 2, j + 45, k + 25, Blocks.log, 1);
		world.setBlockMetadataWithNotify(i + 2, j + 45, k + 25, 1, 2);
		setBlock(world, i + 2, j + 45, k + 26, Blocks.log, 1);
		world.setBlockMetadataWithNotify(i + 2, j + 45, k + 26, 1, 2);
		setBlock(world, i + 2, j + 46, k + 8, Blocks.leaves, 15);
		world.setBlockMetadataWithNotify(i + 2, j + 46, k + 8, 15, 2);
		setBlock(world, i + 2, j + 46, k + 9, Blocks.leaves, 15);
		world.setBlockMetadataWithNotify(i + 2, j + 46, k + 9, 15, 2);
		setBlock(world, i + 2, j + 46, k + 10, Blocks.log, 1);
		world.setBlockMetadataWithNotify(i + 2, j + 46, k + 10, 1, 2);
		setBlock(world, i + 2, j + 46, k + 11, Blocks.log, 1);
		world.setBlockMetadataWithNotify(i + 2, j + 46, k + 11, 1, 2);
		setBlock(world, i + 2, j + 46, k + 12, Blocks.log, 1);
		world.setBlockMetadataWithNotify(i + 2, j + 46, k + 12, 1, 2);
		setBlock(world, i + 2, j + 46, k + 13, Blocks.log, 1);
		world.setBlockMetadataWithNotify(i + 2, j + 46, k + 13, 1, 2);
		setBlock(world, i + 2, j + 46, k + 14, Blocks.log, 1);
		world.setBlockMetadataWithNotify(i + 2, j + 46, k + 14, 1, 2);
		setBlock(world, i + 2, j + 46, k + 15, Blocks.log, 1);
		world.setBlockMetadataWithNotify(i + 2, j + 46, k + 15, 1, 2);
		setBlock(world, i + 2, j + 46, k + 17, Blocks.log, 1);
		world.setBlockMetadataWithNotify(i + 2, j + 46, k + 17, 1, 2);
		setBlock(world, i + 2, j + 46, k + 18, Blocks.log, 1);
		world.setBlockMetadataWithNotify(i + 2, j + 46, k + 18, 1, 2);
		setBlock(world, i + 2, j + 46, k + 19, Blocks.log, 1);
		world.setBlockMetadataWithNotify(i + 2, j + 46, k + 19, 1, 2);
		setBlock(world, i + 2, j + 46, k + 21, Blocks.log, 1);
		world.setBlockMetadataWithNotify(i + 2, j + 46, k + 21, 1, 2);
		setBlock(world, i + 2, j + 46, k + 22, Blocks.log, 1);
		world.setBlockMetadataWithNotify(i + 2, j + 46, k + 22, 1, 2);
		setBlock(world, i + 2, j + 46, k + 23, Blocks.log, 1);
		world.setBlockMetadataWithNotify(i + 2, j + 46, k + 23, 1, 2);
		setBlock(world, i + 2, j + 46, k + 24, Blocks.log, 1);
		world.setBlockMetadataWithNotify(i + 2, j + 46, k + 24, 1, 2);
		setBlock(world, i + 2, j + 46, k + 25, Blocks.log, 1);
		world.setBlockMetadataWithNotify(i + 2, j + 46, k + 25, 1, 2);
		setBlock(world, i + 2, j + 46, k + 26, Blocks.log, 1);
		world.setBlockMetadataWithNotify(i + 2, j + 46, k + 26, 1, 2);
		setBlock(world, i + 2, j + 47, k + 8, Blocks.leaves, 15);
		world.setBlockMetadataWithNotify(i + 2, j + 47, k + 8, 15, 2);
		setBlock(world, i + 2, j + 47, k + 9, Blocks.leaves, 15);
		world.setBlockMetadataWithNotify(i + 2, j + 47, k + 9, 15, 2);
		setBlock(world, i + 2, j + 47, k + 10, Blocks.leaves, 15);
		world.setBlockMetadataWithNotify(i + 2, j + 47, k + 10, 15, 2);
		setBlock(world, i + 2, j + 47, k + 11, Blocks.log, 1);
		world.setBlockMetadataWithNotify(i + 2, j + 47, k + 11, 1, 2);
		setBlock(world, i + 2, j + 47, k + 12, Blocks.log, 1);
		world.setBlockMetadataWithNotify(i + 2, j + 47, k + 12, 1, 2);
		setBlock(world, i + 2, j + 47, k + 13, Blocks.log, 1);
		world.setBlockMetadataWithNotify(i + 2, j + 47, k + 13, 1, 2);
		setBlock(world, i + 2, j + 47, k + 14, Blocks.log, 1);
		world.setBlockMetadataWithNotify(i + 2, j + 47, k + 14, 1, 2);
		setBlock(world, i + 2, j + 47, k + 15, Blocks.log, 1);
		world.setBlockMetadataWithNotify(i + 2, j + 47, k + 15, 1, 2);
		setBlock(world, i + 2, j + 47, k + 16, Blocks.log, 1);
