/*      */package com.parzivail.pswm.world.gen.wookietree;

/*      */
/*      *//*      */
/*      */
import com.parzivail.pswm.utils.LootGenUtils;
import com.parzivail.pswm.utils.NPCType;
import com.parzivail.pswm.utils.SpawnUtils;


/*      */
import cpw.mods.fml.common.IWorldGenerator;


/*      */
import java.util.Random;


/*      */
import net.minecraft.block.Block;
/*      */
import net.minecraft.init.Blocks;
/*      */
import net.minecraft.tileentity.TileEntityChest;
/*      */
import net.minecraft.world.World;
/*      */
import net.minecraft.world.WorldProvider;
/*      */
import net.minecraft.world.chunk.IChunkProvider;
/*      */
import net.minecraft.world.gen.feature.WorldGenerator;

/*      */
/*      */public class WT_21
/*      */extends WorldGenerator implements IWorldGenerator
/*      */
{
	/*      */protected Block[] getValidSpawnBlocks()
	/*      */
	{
		return new Block[0];
		/*      */}

	/*      */
	/*      */public boolean locationIsValidSpawn(World world, int i, int j, int k)
	/*      */
	{
		int distanceToAir = 0;
		Block check = world.getBlock(i, j, k);
		/*      */
		while (check != Blocks.air)
		{
			if (distanceToAir > 3) { return false;
			/*      */}
			/*      */
			distanceToAir++;
			check = world.getBlock(i, j + distanceToAir, k);
			/*      */}
		/*      */
		j += distanceToAir - 1;
		/*      */
		Block block = world.getBlock(i, j, k);
		Block blockAbove = world.getBlock(i, j + 1, k);
		Block blockBelow = world.getBlock(i, j - 1, k);
		/*      */
		for (Block x : getValidSpawnBlocks())
		{
			if (blockAbove != Blocks.air) { return false;
			/*      */}
			if (block == x) return true;
			if ((block == Blocks.snow) && (blockBelow == x)) { return true;
			/*      */}
			/*      */}
		/*      */
		return false;
		/*      */}

	/*      */
	/*      */
	/*      */
	/*      */public void generate(Random random, int chunkX, int chunkZ, World world, IChunkProvider chunkGenerator, IChunkProvider chunkProvider)
	{
	}

	/*      */
	/*      */
	/*      */public void setBlock(World world, int x, int y, int z, Block block, int metadata)
	/*      */
	{
		world.setBlock(x, y, z, block, metadata, 2);
		/*      */}

	/*      */
	/*      */public boolean generate(World world, Random rand, int i, int j, int k)
	/*      */
	{
		k -= 10;
		i -= 10;
		/*      */
		setBlock(world, i + 0, j + 41, k + 18, Blocks.spruce_stairs, 0);
		setBlock(world, i + 0, j + 41, k + 19, Blocks.crafting_table, 0);
		SpawnUtils.spawnNPC(NPCType.WOOKIETREE, world, i + 3, j + 41, k + 16);
		SpawnUtils.spawnNPC(NPCType.WOOKIETREE, world, i + 3, j + 41, k + 20);
		setBlock(world, i + 4, j + 41, k + 13, Blocks.fence, 0);
		setBlock(world, i + 4, j + 41, k + 23, Blocks.fence, 0);
		setBlock(world, i + 4, j + 43, k + 10, Blocks.fence, 0);
		setBlock(world, i + 4, j + 43, k + 11, Blocks.fence, 0);
		setBlock(world, i + 4, j + 43, k + 25, Blocks.fence, 0);
		setBlock(world, i + 4, j + 43, k + 26, Blocks.fence, 0);
		setBlock(world, i + 5, j + 41, k + 13, Blocks.fence, 0);
		setBlock(world, i + 5, j + 41, k + 14, Blocks.fence, 0);
		setBlock(world, i + 5, j + 41, k + 22, Blocks.fence, 0);
		setBlock(world, i + 5, j + 41, k + 23, Blocks.fence, 0);
		setBlock(world, i + 6, j + 41, k + 14, Blocks.fence, 0);
		setBlock(world, i + 6, j + 41, k + 15, Blocks.fence, 0);
		setBlock(world, i + 6, j + 41, k + 16, Blocks.spruce_stairs, 0);
		setBlock(world, i + 6, j + 41, k + 20, Blocks.spruce_stairs, 0);
		setBlock(world, i + 6, j + 41, k + 21, Blocks.fence, 0);
		setBlock(world, i + 6, j + 41, k + 22, Blocks.fence, 0);
		setBlock(world, i + 8, j + 43, k + 15, Blocks.fence, 0);
		setBlock(world, i + 8, j + 43, k + 21, Blocks.fence, 0);
		setBlock(world, i + 9, j + 43, k + 15, Blocks.fence, 0);
		setBlock(world, i + 9, j + 43, k + 21, Blocks.fence, 0);
		setBlock(world, i + 13, j + 25, k + 0, Blocks.fence, 0);
		setBlock(world, i + 14, j + 25, k + 0, Blocks.fence, 0);
		setBlock(world, i + 16, j + 23, k + 0, Blocks.fence, 0);
		setBlock(world, i + 16, j + 23, k + 1, Blocks.fence, 0);
		setBlock(world, i + 17, j + 23, k + 1, Blocks.fence, 0);
		setBlock(world, i + 17, j + 23, k + 2, Blocks.fence, 0);
		setBlock(world, i + 17, j + 23, k + 10, Blocks.spruce_stairs, 0);
		setBlock(world, i + 17, j + 23, k + 11, Blocks.spruce_stairs, 0);
		setBlock(world, i + 17, j + 23, k + 12, Blocks.spruce_stairs, 0);
		setBlock(world, i + 17, j + 23, k + 13, Blocks.spruce_stairs, 0);
		setBlock(world, i + 17, j + 23, k + 14, Blocks.spruce_stairs, 0);
		setBlock(world, i + 18, j + 23, k + 2, Blocks.fence, 0);
		setBlock(world, i + 18, j + 23, k + 3, Blocks.spruce_stairs, 0);
		setBlock(world, i + 18, j + 24, k + 10, Blocks.spruce_stairs, 0);
		setBlock(world, i + 18, j + 24, k + 11, Blocks.spruce_stairs, 0);
		setBlock(world, i + 18, j + 24, k + 12, Blocks.spruce_stairs, 0);
		setBlock(world, i + 18, j + 24, k + 13, Blocks.spruce_stairs, 0);
		setBlock(world, i + 18, j + 24, k + 14, Blocks.spruce_stairs, 0);
		setBlock(world, i + 18, j + 25, k + 4, Blocks.fence, 0);
		setBlock(world, i + 18, j + 25, k + 5, Blocks.fence, 0);
		setBlock(world, i + 19, j + 25, k + 10, Blocks.spruce_stairs, 0);
		setBlock(world, i + 19, j + 25, k + 11, Blocks.spruce_stairs, 0);
		setBlock(world, i + 19, j + 25, k + 12, Blocks.spruce_stairs, 0);
		setBlock(world, i + 19, j + 25, k + 13, Blocks.spruce_stairs, 0);
		setBlock(world, i + 19, j + 25, k + 14, Blocks.spruce_stairs, 0);
		setBlock(world, i + 20, j + 26, k + 10, Blocks.spruce_stairs, 0);
		setBlock(world, i + 20, j + 26, k + 11, Blocks.spruce_stairs, 0);
		setBlock(world, i + 20, j + 26, k + 12, Blocks.spruce_stairs, 0);
		setBlock(world, i + 20, j + 26, k + 13, Blocks.spruce_stairs, 0);
		setBlock(world, i + 20, j + 26, k + 14, Blocks.spruce_stairs, 0);
		setBlock(world, i + 21, j + 27, k + 10, Blocks.spruce_stairs, 0);
		setBlock(world, i + 21, j + 27, k + 11, Blocks.spruce_stairs, 0);
		setBlock(world, i + 21, j + 27, k + 12, Blocks.spruce_stairs, 0);
		setBlock(world, i + 21, j + 27, k + 13, Blocks.spruce_stairs, 0);
		setBlock(world, i + 21, j + 27, k + 14, Blocks.spruce_stairs, 0);
		setBlock(world, i + 22, j + 28, k + 10, Blocks.spruce_stairs, 0);
		setBlock(world, i + 22, j + 28, k + 11, Blocks.spruce_stairs, 0);
		setBlock(world, i + 22, j + 28, k + 12, Blocks.spruce_stairs, 0);
		setBlock(world, i + 22, j + 28, k + 13, Blocks.spruce_stairs, 0);
		setBlock(world, i + 22, j + 28, k + 14, Blocks.spruce_stairs, 0);
		setBlock(world, i + 23, j + 29, k + 10, Blocks.spruce_stairs, 0);
		setBlock(world, i + 23, j + 29, k + 11, Blocks.spruce_stairs, 0);
		setBlock(world, i + 23, j + 29, k + 12, Blocks.spruce_stairs, 0);
		setBlock(world, i + 23, j + 29, k + 13, Blocks.spruce_stairs, 0);
		setBlock(world, i + 23, j + 29, k + 14, Blocks.spruce_stairs, 0);
		setBlock(world, i + 24, j + 23, k + 2, Blocks.fence, 0);
		setBlock(world, i + 24, j + 25, k + 4, Blocks.fence, 0);
		setBlock(world, i + 24, j + 25, k + 5, Blocks.fence, 0);
		setBlock(world, i + 24, j + 30, k + 10, Blocks.spruce_stairs, 0);
		setBlock(world, i + 24, j + 30, k + 11, Blocks.spruce_stairs, 0);
		setBlock(world, i + 24, j + 30, k + 12, Blocks.spruce_stairs, 0);
		setBlock(world, i + 24, j + 30, k + 13, Blocks.spruce_stairs, 0);
		setBlock(world, i + 24, j + 30, k + 14, Blocks.spruce_stairs, 0);
		setBlock(world, i + 25, j + 23, k + 1, Blocks.fence, 0);
		setBlock(world, i + 25, j + 23, k + 2, Blocks.fence, 0);
		setBlock(world, i + 25, j + 31, k + 10, Blocks.spruce_stairs, 0);
		setBlock(world, i + 25, j + 31, k + 11, Blocks.spruce_stairs, 0);
		setBlock(world, i + 25, j + 31, k + 12, Blocks.spruce_stairs, 0);
		setBlock(world, i + 25, j + 31, k + 13, Blocks.spruce_stairs, 0);
		setBlock(world, i + 25, j + 31, k + 14, Blocks.spruce_stairs, 0);
		setBlock(world, i + 26, j + 23, k + 0, Blocks.fence, 0);
		setBlock(world, i + 26, j + 23, k + 1, Blocks.fence, 0);
		setBlock(world, i + 26, j + 32, k + 10, Blocks.spruce_stairs, 0);
		setBlock(world, i + 26, j + 32, k + 11, Blocks.spruce_stairs, 0);
		setBlock(world, i + 26, j + 32, k + 12, Blocks.spruce_stairs, 0);
		setBlock(world, i + 26, j + 32, k + 13, Blocks.spruce_stairs, 0);
		setBlock(world, i + 26, j + 32, k + 14, Blocks.spruce_stairs, 0);
		setBlock(world, i + 26, j + 69, k + 31, Blocks.fence, 0);
		setBlock(world, i + 27, j + 33, k + 10, Blocks.spruce_stairs, 0);
		setBlock(world, i + 27, j + 33, k + 11, Blocks.spruce_stairs, 0);
		setBlock(world, i + 27, j + 33, k + 12, Blocks.spruce_stairs, 0);
		setBlock(world, i + 27, j + 33, k + 13, Blocks.spruce_stairs, 0);
		setBlock(world, i + 27, j + 33, k + 14, Blocks.spruce_stairs, 0);
		setBlock(world, i + 27, j + 69, k + 29, Blocks.fence, 0);
		setBlock(world, i + 27, j + 69, k + 30, Blocks.fence, 0);
		setBlock(world, i + 27, j + 69, k + 31, Blocks.fence, 0);
		setBlock(world, i + 28, j + 25, k + 0, Blocks.fence, 0);
		setBlock(world, i + 28, j + 34, k + 10, Blocks.spruce_stairs, 0);
		setBlock(world, i + 28, j + 34, k + 11, Blocks.spruce_stairs, 0);
		setBlock(world, i + 28, j + 34, k + 12, Blocks.spruce_stairs, 0);
		setBlock(world, i + 28, j + 34, k + 13, Blocks.spruce_stairs, 0);
		setBlock(world, i + 28, j + 34, k + 14, Blocks.spruce_stairs, 0);
		setBlock(world, i + 28, j + 69, k + 28, Blocks.fence, 0);
		setBlock(world, i + 28, j + 69, k + 29, Blocks.fence, 0);
		setBlock(world, i + 29, j + 25, k + 0, Blocks.fence, 0);
		setBlock(world, i + 29, j + 35, k + 10, Blocks.spruce_stairs, 0);
		setBlock(world, i + 29, j + 35, k + 11, Blocks.spruce_stairs, 0);
		setBlock(world, i + 29, j + 35, k + 12, Blocks.spruce_stairs, 0);
		setBlock(world, i + 29, j + 35, k + 13, Blocks.spruce_stairs, 0);
		setBlock(world, i + 29, j + 35, k + 14, Blocks.spruce_stairs, 0);
		setBlock(world, i + 29, j + 66, k + 30, Blocks.fence, 0);
		setBlock(world, i + 29, j + 66, k + 31, Blocks.fence, 0);
		setBlock(world, i + 29, j + 69, k + 27, Blocks.fence, 0);
		setBlock(world, i + 29, j + 69, k + 28, Blocks.fence, 0);
		setBlock(world, i + 30, j + 38, k + 9, Blocks.fence, 0);
		setBlock(world, i + 30, j + 38, k + 15, Blocks.fence, 0);
		setBlock(world, i + 31, j + 38, k + 9, Blocks.fence, 0);
		setBlock(world, i + 31, j + 38, k + 15, Blocks.fence, 0);
		setBlock(world, i + 0, j + 0, k + 6, Blocks.log, 3);
		world.setBlockMetadataWithNotify(i + 0, j + 0, k + 6, 3, 2);
		setBlock(world, i + 0, j + 0, k + 7, Blocks.log, 3);
		world.setBlockMetadataWithNotify(i + 0, j + 0, k + 7, 3, 2);
		setBlock(world, i + 0, j + 0, k + 8, Blocks.log, 3);
		world.setBlockMetadataWithNotify(i + 0, j + 0, k + 8, 3, 2);
		setBlock(world, i + 0, j + 0, k + 9, Blocks.log, 3);
		world.setBlockMetadataWithNotify(i + 0, j + 0, k + 9, 3, 2);
		setBlock(world, i + 0, j + 0, k + 10, Blocks.log, 3);
		world.setBlockMetadataWithNotify(i + 0, j + 0, k + 10, 3, 2);
		setBlock(world, i + 0, j + 0, k + 11, Blocks.log, 3);
		world.setBlockMetadataWithNotify(i + 0, j + 0, k + 11, 3, 2);
		setBlock(world, i + 0, j + 1, k + 9, Blocks.log, 3);
		world.setBlockMetadataWithNotify(i + 0, j + 1, k + 9, 3, 2);
		setBlock(world, i + 0, j + 1, k + 10, Blocks.log, 3);
		world.setBlockMetadataWithNotify(i + 0, j + 1, k + 10, 3, 2);
		setBlock(world, i + 0, j + 1, k + 11, Blocks.log, 3);
		world.setBlockMetadataWithNotify(i + 0, j + 1, k + 11, 3, 2);
		setBlock(world, i + 0, j + 2, k + 8, Blocks.log, 3);
		world.setBlockMetadataWithNotify(i + 0, j + 2, k + 8, 3, 2);
		setBlock(world, i + 0, j + 2, k + 9, Blocks.log, 3);
		world.setBlockMetadataWithNotify(i + 0, j + 2, k + 9, 3, 2);
		setBlock(world, i + 0, j + 2, k + 10, Blocks.log, 3);
		world.setBlockMetadataWithNotify(i + 0, j + 2, k + 10, 3, 2);
		setBlock(world, i + 0, j + 18, k + 3, Blocks.leaves, 7);
		world.setBlockMetadataWithNotify(i + 0, j + 18, k + 3, 7, 2);
		setBlock(world, i + 0, j + 18, k + 4, Blocks.leaves, 7);
		world.setBlockMetadataWithNotify(i + 0, j + 18, k + 4, 7, 2);
		setBlock(world, i + 0, j + 18, k + 5, Blocks.leaves, 7);
		world.setBlockMetadataWithNotify(i + 0, j + 18, k + 5, 7, 2);
		setBlock(world, i + 0, j + 19, k + 4, Blocks.leaves, 7);
		world.setBlockMetadataWithNotify(i + 0, j + 19, k + 4, 7, 2);
		setBlock(world, i + 0, j + 21, k + 5, Blocks.log, 3);
		world.setBlockMetadataWithNotify(i + 0, j + 21, k + 5, 3, 2);
		setBlock(world, i + 0, j + 21, k + 11, Blocks.log, 3);
		world.setBlockMetadataWithNotify(i + 0, j + 21, k + 11, 3, 2);
		setBlock(world, i + 0, j + 22, k + 10, Blocks.log, 3);
		world.setBlockMetadataWithNotify(i + 0, j + 22, k + 10, 3, 2);
		setBlock(world, i + 0, j + 22, k + 11, Blocks.log, 3);
		world.setBlockMetadataWithNotify(i + 0, j + 22, k + 11, 3, 2);
		setBlock(world, i + 0, j + 22, k + 12, Blocks.log, 3);
		world.setBlockMetadataWithNotify(i + 0, j + 22, k + 12, 3, 2);
		setBlock(world, i + 0, j + 23, k + 11, Blocks.log, 3);
		world.setBlockMetadataWithNotify(i + 0, j + 23, k + 11, 3, 2);
		setBlock(world, i + 0, j + 23, k + 15, Blocks.log, 3);
		world.setBlockMetadataWithNotify(i + 0, j + 23, k + 15, 3, 2);
		setBlock(world, i + 0, j + 23, k + 16, Blocks.log, 3);
		world.setBlockMetadataWithNotify(i + 0, j + 23, k + 16, 3, 2);
		setBlock(world, i + 0, j + 23, k + 19, Blocks.log, 3);
		world.setBlockMetadataWithNotify(i + 0, j + 23, k + 19, 3, 2);
		setBlock(world, i + 0, j + 24, k + 4, Blocks.log, 3);
		world.setBlockMetadataWithNotify(i + 0, j + 24, k + 4, 3, 2);
		setBlock(world, i + 0, j + 24, k + 6, Blocks.leaves, 7);
		world.setBlockMetadataWithNotify(i + 0, j + 24, k + 6, 7, 2);
		setBlock(world, i + 0, j + 24, k + 7, Blocks.leaves, 7);
		world.setBlockMetadataWithNotify(i + 0, j + 24, k + 7, 7, 2);
		setBlock(world, i + 0, j + 24, k + 8, Blocks.log, 3);
		world.setBlockMetadataWithNotify(i + 0, j + 24, k + 8, 3, 2);
		setBlock(world, i + 0, j + 24, k + 9, Blocks.leaves, 7);
		world.setBlockMetadataWithNotify(i + 0, j + 24, k + 9, 7, 2);
		setBlock(world, i + 0, j + 24, k + 10, Blocks.leaves, 7);
		world.setBlockMetadataWithNotify(i + 0, j + 24, k + 10, 7, 2);
		setBlock(world, i + 0, j + 24, k + 14, Blocks.log, 3);
		world.setBlockMetadataWithNotify(i + 0, j + 24, k + 14, 3, 2);
		setBlock(world, i + 0, j + 24, k + 15, Blocks.log, 3);
		world.setBlockMetadataWithNotify(i + 0, j + 24, k + 15, 3, 2);
		setBlock(world, i + 0, j + 24, k + 16, Blocks.log, 3);
		world.setBlockMetadataWithNotify(i + 0, j + 24, k + 16, 3, 2);
		setBlock(world, i + 0, j + 24, k + 17, Blocks.log, 3);
		world.setBlockMetadataWithNotify(i + 0, j + 24, k + 17, 3, 2);
		setBlock(world, i + 0, j + 24, k + 18, Blocks.log, 3);
		world.setBlockMetadataWithNotify(i + 0, j + 24, k + 18, 3, 2);
		setBlock(world, i + 0, j + 25, k + 6, Blocks.leaves, 7);
		world.setBlockMetadataWithNotify(i + 0, j + 25, k + 6, 7, 2);
		setBlock(world, i + 0, j + 25, k + 7, Blocks.leaves, 7);
		world.setBlockMetadataWithNotify(i + 0, j + 25, k + 7, 7, 2);
		setBlock(world, i + 0, j + 25, k + 8, Blocks.leaves, 7);
		world.setBlockMetadataWithNotify(i + 0, j + 25, k + 8, 7, 2);
		setBlock(world, i + 0, j + 25, k + 9, Blocks.leaves, 7);
		world.setBlockMetadataWithNotify(i + 0, j + 25, k + 9, 7, 2);
		setBlock(world, i + 0, j + 25, k + 10, Blocks.log, 3);
		world.setBlockMetadataWithNotify(i + 0, j + 25, k + 10, 3, 2);
		setBlock(world, i + 0, j + 25, k + 15, Blocks.log, 3);
		world.setBlockMetadataWithNotify(i + 0, j + 25, k + 15, 3, 2);
		setBlock(world, i + 0, j + 25, k + 16, Blocks.log, 3);
		world.setBlockMetadataWithNotify(i + 0, j + 25, k + 16, 3, 2);
		setBlock(world, i + 0, j + 25, k + 19, Blocks.log, 3);
		world.setBlockMetadataWithNotify(i + 0, j + 25, k + 19, 3, 2);
		setBlock(world, i + 0, j + 26, k + 7, Blocks.leaves, 7);
		world.setBlockMetadataWithNotify(i + 0, j + 26, k + 7, 7, 2);
		setBlock(world, i + 0, j + 26, k + 8, Blocks.leaves, 7);
		world.setBlockMetadataWithNotify(i + 0, j + 26, k + 8, 7, 2);
		setBlock(world, i + 0, j + 26, k + 9, Blocks.leaves, 7);
		world.setBlockMetadataWithNotify(i + 0, j + 26, k + 9, 7, 2);
		setBlock(world, i + 0, j + 27, k + 4, Blocks.log, 3);
		world.setBlockMetadataWithNotify(i + 0, j + 27, k + 4, 3, 2);
		setBlock(world, i + 0, j + 27, k + 8, Blocks.leaves, 7);
		world.setBlockMetadataWithNotify(i + 0, j + 27, k + 8, 7, 2);
		setBlock(world, i + 0, j + 31, k + 7, Blocks.log, 3);
		world.setBlockMetadataWithNotify(i + 0, j + 31, k + 7, 3, 2);
		setBlock(world, i + 0, j + 31, k + 19, Blocks.log, 3);
		world.setBlockMetadataWithNotify(i + 0, j + 31, k + 19, 3, 2);
		setBlock(world, i + 0, j + 32, k + 14, Blocks.log, 3);
		world.setBlockMetadataWithNotify(i + 0, j + 32, k + 14, 3, 2);
		setBlock(world, i + 0, j + 33, k + 13, Blocks.log, 3);
		world.setBlockMetadataWithNotify(i + 0, j + 33, k + 13, 3, 2);
		setBlock(world, i + 0, j + 34, k + 12, Blocks.leaves, 7);
		world.setBlockMetadataWithNotify(i + 0, j + 34, k + 12, 7, 2);
		setBlock(world, i + 0, j + 34, k + 13, Blocks.leaves, 7);
		world.setBlockMetadataWithNotify(i + 0, j + 34, k + 13, 7, 2);
		setBlock(world, i + 0, j + 34, k + 14, Blocks.leaves, 7);
		world.setBlockMetadataWithNotify(i + 0, j + 34, k + 14, 7, 2);
		setBlock(world, i + 0, j + 35, k + 13, Blocks.leaves, 7);
		world.setBlockMetadataWithNotify(i + 0, j + 35, k + 13, 7, 2);
		setBlock(world, i + 0, j + 35, k + 18, Blocks.log, 1);
		world.setBlockMetadataWithNotify(i + 0, j + 35, k + 18, 1, 2);
		setBlock(world, i + 0, j + 35, k + 19, Blocks.log, 1);
		world.setBlockMetadataWithNotify(i + 0, j + 35, k + 19, 1, 2);
		setBlock(world, i + 0, j + 35, k + 20, Blocks.log, 1);
		world.setBlockMetadataWithNotify(i + 0, j + 35, k + 20, 1, 2);
		setBlock(world, i + 0, j + 36, k + 17, Blocks.log, 1);
		world.setBlockMetadataWithNotify(i + 0, j + 36, k + 17, 1, 2);
		setBlock(world, i + 0, j + 36, k + 18, Blocks.log, 1);
		world.setBlockMetadataWithNotify(i + 0, j + 36, k + 18, 1, 2);
		setBlock(world, i + 0, j + 36, k + 19, Blocks.log, 1);
		world.setBlockMetadataWithNotify(i + 0, j + 36, k + 19, 1, 2);
		setBlock(world, i + 0, j + 36, k + 20, Blocks.log, 1);
		world.setBlockMetadataWithNotify(i + 0, j + 36, k + 20, 1, 2);
		setBlock(world, i + 0, j + 36, k + 21, Blocks.log, 1);
		world.setBlockMetadataWithNotify(i + 0, j + 36, k + 21, 1, 2);
		setBlock(world, i + 0, j + 37, k + 17, Blocks.leaves, 15);
		world.setBlockMetadataWithNotify(i + 0, j + 37, k + 17, 15, 2);
		setBlock(world, i + 0, j + 37, k + 18, Blocks.log, 1);
		world.setBlockMetadataWithNotify(i + 0, j + 37, k + 18, 1, 2);
		setBlock(world, i + 0, j + 37, k + 19, Blocks.log, 1);
		world.setBlockMetadataWithNotify(i + 0, j + 37, k + 19, 1, 2);
		setBlock(world, i + 0, j + 37, k + 20, Blocks.log, 1);
		world.setBlockMetadataWithNotify(i + 0, j + 37, k + 20, 1, 2);
		setBlock(world, i + 0, j + 37, k + 27, Blocks.vine, 12);
		world.setBlockMetadataWithNotify(i + 0, j + 37, k + 27, 12, 2);
		setBlock(world, i + 0, j + 37, k + 29, Blocks.vine, 11);
		world.setBlockMetadataWithNotify(i + 0, j + 37, k + 29, 11, 2);
		setBlock(world, i + 0, j + 38, k + 6, Blocks.leaves, 15);
		world.setBlockMetadataWithNotify(i + 0, j + 38, k + 6, 15, 2);
		setBlock(world, i + 0, j + 38, k + 7, Blocks.leaves, 15);
		world.setBlockMetadataWithNotify(i + 0, j + 38, k + 7, 15, 2);
		setBlock(world, i + 0, j + 38, k + 8, Blocks.log, 3);
		world.setBlockMetadataWithNotify(i + 0, j + 38, k + 8, 3, 2);
		setBlock(world, i + 0, j + 38, k + 9, Blocks.leaves, 15);
		world.setBlockMetadataWithNotify(i + 0, j + 38, k + 9, 15, 2);
		setBlock(world, i + 0, j + 38, k + 10, Blocks.log, 3);
		world.setBlockMetadataWithNotify(i + 0, j + 38, k + 10, 3, 2);
		setBlock(world, i + 0, j + 38, k + 15, Blocks.log, 1);
		world.setBlockMetadataWithNotify(i + 0, j + 38, k + 15, 1, 2);
		setBlock(world, i + 0, j + 38, k + 16, Blocks.log, 1);
		world.setBlockMetadataWithNotify(i + 0, j + 38, k + 16, 1, 2);
		setBlock(world, i + 0, j + 38, k + 17, Blocks.log, 1);
		world.setBlockMetadataWithNotify(i + 0, j + 38, k + 17, 1, 2);
		setBlock(world, i + 0, j + 38, k + 18, Blocks.log, 1);
		world.setBlockMetadataWithNotify(i + 0, j + 38, k + 18, 1, 2);
		setBlock(world, i + 0, j + 38, k + 19, Blocks.log, 1);
		world.setBlockMetadataWithNotify(i + 0, j + 38, k + 19, 1, 2);
		setBlock(world, i + 0, j + 38, k + 20, Blocks.log, 1);
		world.setBlockMetadataWithNotify(i + 0, j + 38, k + 20, 1, 2);
		setBlock(world, i + 0, j + 38, k + 21, Blocks.log, 1);
		world.setBlockMetadataWithNotify(i + 0, j + 38, k + 21, 1, 2);
		setBlock(world, i + 0, j + 38, k + 22, Blocks.log, 1);
		world.setBlockMetadataWithNotify(i + 0, j + 38, k + 22, 1, 2);
		setBlock(world, i + 0, j + 38, k + 27, Blocks.vine, 13);
		world.setBlockMetadataWithNotify(i + 0, j + 38, k + 27, 13, 2);
		setBlock(world, i + 0, j + 38, k + 29, Blocks.vine, 15);
		world.setBlockMetadataWithNotify(i + 0, j + 38, k + 29, 15, 2);
		setBlock(world, i + 0, j + 39, k + 2, Blocks.leaves, 15);
		world.setBlockMetadataWithNotify(i + 0, j + 39, k + 2, 15, 2);
		setBlock(world, i + 0, j + 39, k + 3, Blocks.leaves, 15);
		world.setBlockMetadataWithNotify(i + 0, j + 39, k + 3, 15, 2);
		setBlock(world, i + 0, j + 39, k + 15, Blocks.log, 1);
		world.setBlockMetadataWithNotify(i + 0, j + 39, k + 15, 1, 2);
		setBlock(world, i + 0, j + 39, k + 16, Blocks.log, 1);
		world.setBlockMetadataWithNotify(i + 0, j + 39, k + 16, 1, 2);
		setBlock(world, i + 0, j + 39, k + 17, Blocks.log, 1);
		world.setBlockMetadataWithNotify(i + 0, j + 39, k + 17, 1, 2);
		setBlock(world, i + 0, j + 39, k + 18, Blocks.log, 1);
		world.setBlockMetadataWithNotify(i + 0, j + 39, k + 18, 1, 2);
		setBlock(world, i + 0, j + 39, k + 19, Blocks.log, 1);
		world.setBlockMetadataWithNotify(i + 0, j + 39, k + 19, 1, 2);
		setBlock(world, i + 0, j + 39, k + 20, Blocks.log, 1);
		world.setBlockMetadataWithNotify(i + 0, j + 39, k + 20, 1, 2);
		setBlock(world, i + 0, j + 39, k + 21, Blocks.log, 1);
		world.setBlockMetadataWithNotify(i + 0, j + 39, k + 21, 1, 2);
		setBlock(world, i + 0, j + 39, k + 22, Blocks.log, 1);
		world.setBlockMetadataWithNotify(i + 0, j + 39, k + 22, 1, 2);
		setBlock(world, i + 0, j + 39, k + 27, Blocks.vine, 15);
		world.setBlockMetadataWithNotify(i + 0, j + 39, k + 27, 15, 2);
		setBlock(world, i + 0, j + 39, k + 28, Blocks.vine, 15);
		world.setBlockMetadataWithNotify(i + 0, j + 39, k + 28, 15, 2);
		setBlock(world, i + 0, j + 39, k + 29, Blocks.vine, 15);
		world.setBlockMetadataWithNotify(i + 0, j + 39, k + 29, 15, 2);
		setBlock(world, i + 0, j + 39, k + 30, Blocks.vine, 15);
		world.setBlockMetadataWithNotify(i + 0, j + 39, k + 30, 15, 2);
		setBlock(world, i + 0, j + 39, k + 31, Blocks.vine, 15);
		world.setBlockMetadataWithNotify(i + 0, j + 39, k + 31, 15, 2);
		setBlock(world, i + 0, j + 40, k + 0, Blocks.planks, 5);
		world.setBlockMetadataWithNotify(i + 0, j + 40, k + 0, 5, 2);
		setBlock(world, i + 0, j + 40, k + 1, Blocks.planks, 5);
		world.setBlockMetadataWithNotify(i + 0, j + 40, k + 1, 5, 2);
		setBlock(world, i + 0, j + 40, k + 2, Blocks.planks, 5);
		world.setBlockMetadataWithNotify(i + 0, j + 40, k + 2, 5, 2);
		setBlock(world, i + 0, j + 40, k + 3, Blocks.planks, 5);
		world.setBlockMetadataWithNotify(i + 0, j + 40, k + 3, 5, 2);
		setBlock(world, i + 0, j + 40, k + 4, Blocks.planks, 5);
		world.setBlockMetadataWithNotify(i + 0, j + 40, k + 4, 5, 2);
		setBlock(world, i + 0, j + 40, k + 5, Blocks.planks, 5);
		world.setBlockMetadataWithNotify(i + 0, j + 40, k + 5, 5, 2);
		setBlock(world, i + 0, j + 40, k + 6, Blocks.planks, 5);
		world.setBlockMetadataWithNotify(i + 0, j + 40, k + 6, 5, 2);
		setBlock(world, i + 0, j + 40, k + 7, Blocks.planks, 5);
		world.setBlockMetadataWithNotify(i + 0, j + 40, k + 7, 5, 2);
		setBlock(world, i + 0, j + 40, k + 8, Blocks.planks, 5);
		world.setBlockMetadataWithNotify(i + 0, j + 40, k + 8, 5, 2);
		setBlock(world, i + 0, j + 40, k + 9, Blocks.planks, 5);
		world.setBlockMetadataWithNotify(i + 0, j + 40, k + 9, 5, 2);
		setBlock(world, i + 0, j + 40, k + 10, Blocks.planks, 5);
		world.setBlockMetadataWithNotify(i + 0, j + 40, k + 10, 5, 2);
		setBlock(world, i + 0, j + 40, k + 11, Blocks.planks, 5);
		world.setBlockMetadataWithNotify(i + 0, j + 40, k + 11, 5, 2);
		setBlock(world, i + 0, j + 40, k + 12, Blocks.log, 1);
		world.setBlockMetadataWithNotify(i + 0, j + 40, k + 12, 1, 2);
		setBlock(world, i + 0, j + 40, k + 13, Blocks.planks, 5);
		world.setBlockMetadataWithNotify(i + 0, j + 40, k + 13, 5, 2);
		setBlock(world, i + 0, j + 40, k + 14, Blocks.planks, 5);
		world.setBlockMetadataWithNotify(i + 0, j + 40, k + 14, 5, 2);
		setBlock(world, i + 0, j + 40, k + 15, Blocks.log, 1);
		world.setBlockMetadataWithNotify(i + 0, j + 40, k + 15, 1, 2);
		setBlock(world, i + 0, j + 40, k + 16, Blocks.planks, 5);
		world.setBlockMetadataWithNotify(i + 0, j + 40, k + 16, 5, 2);
		setBlock(world, i + 0, j + 40, k + 17, Blocks.planks, 5);
		world.setBlockMetadataWithNotify(i + 0, j + 40, k + 17, 5, 2);
		setBlock(world, i + 0, j + 40, k + 18, Blocks.log, 1);
		world.setBlockMetadataWithNotify(i + 0, j + 40, k + 18, 1, 2);
		setBlock(world, i + 0, j + 40, k + 19, Blocks.planks, 5);
		world.setBlockMetadataWithNotify(i + 0, j + 40, k + 19, 5, 2);
		setBlock(world, i + 0, j + 40, k + 20, Blocks.planks, 5);
		world.setBlockMetadataWithNotify(i + 0, j + 40, k + 20, 5, 2);
		setBlock(world, i + 0, j + 40, k + 21, Blocks.log, 1);
		world.setBlockMetadataWithNotify(i + 0, j + 40, k + 21, 1, 2);
		setBlock(world, i + 0, j + 40, k + 22, Blocks.planks, 5);
		world.setBlockMetadataWithNotify(i + 0, j + 40, k + 22, 5, 2);
		setBlock(world, i + 0, j + 40, k + 23, Blocks.planks, 5);
		world.setBlockMetadataWithNotify(i + 0, j + 40, k + 23, 5, 2);
		setBlock(world, i + 0, j + 40, k + 24, Blocks.log, 1);
		world.setBlockMetadataWithNotify(i + 0, j + 40, k + 24, 1, 2);
		setBlock(world, i + 0, j + 40, k + 25, Blocks.planks, 5);
		world.setBlockMetadataWithNotify(i + 0, j + 40, k + 25, 5, 2);
		setBlock(world, i + 0, j + 40, k + 26, Blocks.planks, 5);
		world.setBlockMetadataWithNotify(i + 0, j + 40, k + 26, 5, 2);
		setBlock(world, i + 0, j + 40, k + 27, Blocks.planks, 5);
		world.setBlockMetadataWithNotify(i + 0, j + 40, k + 27, 5, 2);
		setBlock(world, i + 0, j + 40, k + 28, Blocks.planks, 5);
		world.setBlockMetadataWithNotify(i + 0, j + 40, k + 28, 5, 2);
		setBlock(world, i + 0, j + 40, k + 29, Blocks.planks, 5);
		world.setBlockMetadataWithNotify(i + 0, j + 40, k + 29, 5, 2);
		setBlock(world, i + 0, j + 40, k + 30, Blocks.planks, 5);
		world.setBlockMetadataWithNotify(i + 0, j + 40, k + 30, 5, 2);
		setBlock(world, i + 0, j + 40, k + 31, Blocks.planks, 5);
		world.setBlockMetadataWithNotify(i + 0, j + 40, k + 31, 5, 2);
		setBlock(world, i + 0, j + 41, k + 17, Blocks.chest, 2);
		LootGenUtils.fillLootChest(world.provider.dimensionId, world.rand, (TileEntityChest)world.getTileEntity(i + 0, j + 41, k + 17));
		world.setBlockMetadataWithNotify(i + 0, j + 41, k + 17, 2, 2);
		setBlock(world, i + 0, j + 43, k + 10, Blocks.torch, 1);
		world.setBlockMetadataWithNotify(i + 0, j + 43, k + 10, 1, 2);
		setBlock(world, i + 0, j + 43, k + 18, Blocks.torch, 2);
		world.setBlockMetadataWithNotify(i + 0, j + 43, k + 18, 2, 2);
		setBlock(world, i + 0, j + 43, k + 26, Blocks.torch, 1);
		world.setBlockMetadataWithNotify(i + 0, j + 43, k + 26, 1, 2);
		setBlock(world, i + 0, j + 44, k + 9, Blocks.log, 1);
		world.setBlockMetadataWithNotify(i + 0, j + 44, k + 9, 1, 2);
		setBlock(world, i + 0, j + 44, k + 10, Blocks.log, 1);
		world.setBlockMetadataWithNotify(i + 0, j + 44, k + 10, 1, 2);
		setBlock(world, i + 0, j + 44, k + 11, Blocks.log, 1);
		world.setBlockMetadataWithNotify(i + 0, j + 44, k + 11, 1, 2);
		setBlock(world, i + 0, j + 44, k + 12, Blocks.log, 1);
		world.setBlockMetadataWithNotify(i + 0, j + 44, k + 12, 1, 2);
		setBlock(world, i + 0, j + 44, k + 13, Blocks.log, 1);
		world.setBlockMetadataWithNotify(i + 0, j + 44, k + 13, 1, 2);
		setBlock(world, i + 0, j + 44, k + 23, Blocks.log, 1);
		world.setBlockMetadataWithNotify(i + 0, j + 44, k + 23, 1, 2);
		setBlock(world, i + 0, j + 44, k + 24, Blocks.log, 1);
		world.setBlockMetadataWithNotify(i + 0, j + 44, k + 24, 1, 2);
		setBlock(world, i + 0, j + 44, k + 25, Blocks.log, 1);
		world.setBlockMetadataWithNotify(i + 0, j + 44, k + 25, 1, 2);
		setBlock(world, i + 0, j + 44, k + 26, Blocks.log, 1);
		world.setBlockMetadataWithNotify(i + 0, j + 44, k + 26, 1, 2);
		setBlock(world, i + 0, j + 44, k + 27, Blocks.log, 1);
		world.setBlockMetadataWithNotify(i + 0, j + 44, k + 27, 1, 2);
		setBlock(world, i + 0, j + 45, k + 9, Blocks.log, 3);
		world.setBlockMetadataWithNotify(i + 0, j + 45, k + 9, 3, 2);
		setBlock(world, i + 0, j + 45, k + 10, Blocks.log, 1);
		world.setBlockMetadataWithNotify(i + 0, j + 45, k + 10, 1, 2);
		setBlock(world, i + 0, j + 45, k + 11, Blocks.log, 1);
		world.setBlockMetadataWithNotify(i + 0, j + 45, k + 11, 1, 2);
		setBlock(world, i + 0, j + 45, k + 12, Blocks.log, 1);
		world.setBlockMetadataWithNotify(i + 0, j + 45, k + 12, 1, 2);
		setBlock(world, i + 0, j + 45, k + 13, Blocks.log, 1);
		world.setBlockMetadataWithNotify(i + 0, j + 45, k + 13, 1, 2);
		setBlock(world, i + 0, j + 45, k + 14, Blocks.log, 1);
		world.setBlockMetadataWithNotify(i + 0, j + 45, k + 14, 1, 2);
		setBlock(world, i + 0, j + 45, k + 22, Blocks.log, 1);
		world.setBlockMetadataWithNotify(i + 0, j + 45, k + 22, 1, 2);
		setBlock(world, i + 0, j + 45, k + 23, Blocks.log, 1);
		world.setBlockMetadataWithNotify(i + 0, j + 45, k + 23, 1, 2);
		setBlock(world, i + 0, j + 45, k + 24, Blocks.log, 1);
		world.setBlockMetadataWithNotify(i + 0, j + 45, k + 24, 1, 2);
		setBlock(world, i + 0, j + 45, k + 25, Blocks.log, 1);
		world.setBlockMetadataWithNotify(i + 0, j + 45, k + 25, 1, 2);
		setBlock(world, i + 0, j + 45, k + 26, Blocks.log, 1);
		world.setBlockMetadataWithNotify(i + 0, j + 45, k + 26, 1, 2);
		setBlock(world, i + 0, j + 46, k + 9, Blocks.leaves, 15);
		world.setBlockMetadataWithNotify(i + 0, j + 46, k + 9, 15, 2);
		setBlock(world, i + 0, j + 46, k + 10, Blocks.log, 1);
		world.setBlockMetadataWithNotify(i + 0, j + 46, k + 10, 1, 2);
		setBlock(world, i + 0, j + 46, k + 11, Blocks.log, 1);
		world.setBlockMetadataWithNotify(i + 0, j + 46, k + 11, 1, 2);
		setBlock(world, i + 0, j + 46, k + 12, Blocks.log, 1);
		world.setBlockMetadataWithNotify(i + 0, j + 46, k + 12, 1, 2);
		setBlock(world, i + 0, j + 46, k + 13, Blocks.log, 1);
		world.setBlockMetadataWithNotify(i + 0, j + 46, k + 13, 1, 2);
		setBlock(world, i + 0, j + 46, k + 14, Blocks.log, 1);
		world.setBlockMetadataWithNotify(i + 0, j + 46, k + 14, 1, 2);
		setBlock(world, i + 0, j + 46, k + 15, Blocks.log, 1);
		world.setBlockMetadataWithNotify(i + 0, j + 46, k + 15, 1, 2);
		setBlock(world, i + 0, j + 46, k + 17, Blocks.log, 1);
		world.setBlockMetadataWithNotify(i + 0, j + 46, k + 17, 1, 2);
		setBlock(world, i + 0, j + 46, k + 18, Blocks.log, 1);
		world.setBlockMetadataWithNotify(i + 0, j + 46, k + 18, 1, 2);
		setBlock(world, i + 0, j + 46, k + 19, Blocks.log, 1);
		world.setBlockMetadataWithNotify(i + 0, j + 46, k + 19, 1, 2);
		setBlock(world, i + 0, j + 46, k + 21, Blocks.log, 1);
		world.setBlockMetadataWithNotify(i + 0, j + 46, k + 21, 1, 2);
		setBlock(world, i + 0, j + 46, k + 22, Blocks.log, 1);
		world.setBlockMetadataWithNotify(i + 0, j + 46, k + 22, 1, 2);
		setBlock(world, i + 0, j + 46, k + 23, Blocks.log, 1);
		world.setBlockMetadataWithNotify(i + 0, j + 46, k + 23, 1, 2);
		setBlock(world, i + 0, j + 46, k + 24, Blocks.log, 1);
		world.setBlockMetadataWithNotify(i + 0, j + 46, k + 24, 1, 2);
		setBlock(world, i + 0, j + 46, k + 25, Blocks.log, 1);
		world.setBlockMetadataWithNotify(i + 0, j + 46, k + 25, 1, 2);
		setBlock(world, i + 0, j + 46, k + 26, Blocks.log, 1);
		world.setBlockMetadataWithNotify(i + 0, j + 46, k + 26, 1, 2);
		setBlock(world, i + 0, j + 47, k + 7, Blocks.leaves, 15);
		world.setBlockMetadataWithNotify(i + 0, j + 47, k + 7, 15, 2);
		setBlock(world, i + 0, j + 47, k + 8, Blocks.leaves, 15);
		world.setBlockMetadataWithNotify(i + 0, j + 47, k + 8, 15, 2);
		setBlock(world, i + 0, j + 47, k + 9, Blocks.log, 3);
		world.setBlockMetadataWithNotify(i + 0, j + 47, k + 9, 3, 2);
		setBlock(world, i + 0, j + 47, k + 10, Blocks.leaves, 15);
		world.setBlockMetadataWithNotify(i + 0, j + 47, k + 10, 15, 2);
		setBlock(world, i + 0, j + 47, k + 11, Blocks.log, 1);
		world.setBlockMetadataWithNotify(i + 0, j + 47, k + 11, 1, 2);
		setBlock(world, i + 0, j + 47, k + 12, Blocks.log, 1);
		world.setBlockMetadataWithNotify(i + 0, j + 47, k + 12, 1, 2);
		setBlock(world, i + 0, j + 47, k + 13, Blocks.log, 1);
		world.setBlockMetadataWithNotify(i + 0, j + 47, k + 13, 1, 2);
		setBlock(world, i + 0, j + 47, k + 14, Blocks.log, 1);
		world.setBlockMetadataWithNotify(i + 0, j + 47, k + 14, 1, 2);
		setBlock(world, i + 0, j + 47, k + 15, Blocks.log, 1);
		world.setBlockMetadataWithNotify(i + 0, j + 47, k + 15, 1, 2);
		setBlock(world, i + 0, j + 47, k + 16, Blocks.log, 1);
		world.setBlockMetadataWithNotify(i + 0, j + 47, k + 16, 1, 2);
		setBlock(world, i + 0, j + 47, k + 17, Blocks.log, 1);
		world.setBlockMetadataWithNotify(i + 0, j + 47, k + 17, 1, 2);
		setBlock(world, i + 0, j + 47, k + 18, Blocks.log, 1);
		world.setBlockMetadataWithNotify(i + 0, j + 47, k + 18, 1, 2);
		setBlock(world, i + 0, j + 47, k + 19, Blocks.log, 1);
		world.setBlockMetadataWithNotify(i + 0, j + 47, k + 19, 1, 2);
		setBlock(world, i + 0, j + 47, k + 20, Blocks.log, 1);
		world.setBlockMetadataWithNotify(i + 0, j + 47, k + 20, 1, 2);
		setBlock(world, i + 0, j + 47, k + 21, Blocks.log, 1);
		world.setBlockMetadataWithNotify(i + 0, j + 47, k + 21, 1, 2);
		setBlock(world, i + 0, j + 47, k + 22, Blocks.log, 1);
		world.setBlockMetadataWithNotify(i + 0, j + 47, k + 22, 1, 2);
		setBlock(world, i + 0, j + 47, k + 23, Blocks.log, 1);
		world.setBlockMetadataWithNotify(i + 0, j + 47, k + 23, 1, 2);
		setBlock(world, i + 0, j + 47, k + 24, Blocks.log, 1);
		world.setBlockMetadataWithNotify(i + 0, j + 47, k + 24, 1, 2);
		setBlock(world, i + 0, j + 47, k + 25, Blocks.log, 1);
		world.setBlockMetadataWithNotify(i + 0, j + 47, k + 25, 1, 2);
		setBlock(world, i + 0, j + 48, k + 7, Blocks.leaves, 15);
		world.setBlockMetadataWithNotify(i + 0, j + 48, k + 7, 15, 2);
		setBlock(world, i + 0, j + 48, k + 8, Blocks.leaves, 15);
		world.setBlockMetadataWithNotify(i + 0, j + 48, k + 8, 15, 2);
		setBlock(world, i + 0, j + 48, k + 9, Blocks.leaves, 15);
		world.setBlockMetadataWithNotify(i + 0, j + 48, k + 9, 15, 2);
		setBlock(world, i + 0, j + 48, k + 10, Blocks.log, 3);
		world.setBlockMetadataWithNotify(i + 0, j + 48, k + 10, 3, 2);
		setBlock(world, i + 0, j + 48, k + 11, Blocks.leaves, 7);
		world.setBlockMetadataWithNotify(i + 0, j + 48, k + 11, 7, 2);
		setBlock(world, i + 0, j + 48, k + 12, Blocks.log, 1);
		world.setBlockMetadataWithNotify(i + 0, j + 48, k + 12, 1, 2);
		setBlock(world, i + 0, j + 48, k + 13, Blocks.log, 1);
		world.setBlockMetadataWithNotify(i + 0, j + 48, k + 13, 1, 2);
		setBlock(world, i + 0, j + 48, k + 14, Blocks.log, 1);
		world.setBlockMetadataWithNotify(i + 0, j + 48, k + 14, 1, 2);
		setBlock(world, i + 0, j + 48, k + 15, Blocks.log, 1);
		world.setBlockMetadataWithNotify(i + 0, j + 48, k + 15, 1, 2);
		setBlock(world, i + 0, j + 48, k + 16, Blocks.log, 1);
		world.setBlockMetadataWithNotify(i + 0, j + 48, k + 16, 1, 2);
		setBlock(world, i + 0, j + 48, k + 17, Blocks.log, 1);
		world.setBlockMetadataWithNotify(i + 0, j + 48, k + 17, 1, 2);
		setBlock(world, i + 0, j + 48, k + 18, Blocks.log, 1);
		world.setBlockMetadataWithNotify(i + 0, j + 48, k + 18, 1, 2);
		setBlock(world, i + 0, j + 48, k + 19, Blocks.log, 1);
		world.setBlockMetadataWithNotify(i + 0, j + 48, k + 19, 1, 2);
		setBlock(world, i + 0, j + 48, k + 20, Blocks.log, 1);
		world.setBlockMetadataWithNotify(i + 0, j + 48, k + 20, 1, 2);
		setBlock(world, i + 0, j + 48, k + 21, Blocks.log, 1);
		world.setBlockMetadataWithNotify(i + 0, j + 48, k + 21, 1, 2);
		setBlock(world, i + 0, j + 48, k + 22, Blocks.log, 1);
		world.setBlockMetadataWithNotify(i + 0, j + 48, k + 22, 1, 2);
		setBlock(world, i + 0, j + 48, k + 23, Blocks.log, 1);
		world.setBlockMetadataWithNotify(i + 0, j + 48, k + 23, 1, 2);
		setBlock(world, i + 0, j + 48, k + 24, Blocks.log, 1);
		world.setBlockMetadataWithNotify(i + 0, j + 48, k + 24, 1, 2);
		setBlock(world, i + 0, j + 49, k + 1, Blocks.leaves, 15);
		world.setBlockMetadataWithNotify(i + 0, j + 49, k + 1, 15, 2);
		setBlock(world, i + 0, j + 49, k + 2, Blocks.leaves, 7);
		world.setBlockMetadataWithNotify(i + 0, j + 49, k + 2, 7, 2);
		setBlock(world, i + 0, j + 49, k + 8, Blocks.leaves, 7);
		world.setBlockMetadataWithNotify(i + 0, j + 49, k + 8, 7, 2);
		setBlock(world, i + 0, j + 49, k + 9, Blocks.leaves, 7);
		world.setBlockMetadataWithNotify(i + 0, j + 49, k + 9, 7, 2);
		setBlock(world, i + 0, j + 49, k + 10, Blocks.leaves, 7);
		world.setBlockMetadataWithNotify(i + 0, j + 49, k + 10, 7, 2);
		setBlock(world, i + 0, j + 49, k + 11, Blocks.leaves, 7);
		world.setBlockMetadataWithNotify(i + 0, j + 49, k + 11, 7, 2);
		setBlock(world, i + 0, j + 49, k + 12, Blocks.log, 3);
		world.setBlockMetadataWithNotify(i + 0, j + 49, k + 12, 3, 2);
		setBlock(world, i + 0, j + 49, k + 13, Blocks.leaves, 7);
		world.setBlockMetadataWithNotify(i + 0, j + 49, k + 13, 7, 2);
		setBlock(world, i + 0, j + 49, k + 14, Blocks.leaves, 7);
		world.setBlockMetadataWithNotify(i + 0, j + 49, k + 14, 7, 2);
		setBlock(world, i + 0, j + 49, k + 15, Blocks.log, 1);
		world.setBlockMetadataWithNotify(i + 0, j + 49, k + 15, 1, 2);
		setBlock(world, i + 0, j + 49, k + 16, Blocks.log, 1);
		world.setBlockMetadataWithNotify(i + 0, j + 49, k + 16, 1, 2);
		setBlock(world, i + 0, j + 49, k + 17, Blocks.log, 1);
		world.setBlockMetadataWithNotify(i + 0, j + 49, k + 17, 1, 2);
		setBlock(world, i + 0, j + 49, k + 18, Blocks.log, 1);
		world.setBlockMetadataWithNotify(i + 0, j + 49, k + 18, 1, 2);
		setBlock(world, i + 0, j + 49, k + 19, Blocks.log, 1);
		world.setBlockMetadataWithNotify(i + 0, j + 49, k + 19, 1, 2);
		setBlock(world, i + 0, j + 49, k + 20, Blocks.log, 1);
		world.setBlockMetadataWithNotify(i + 0, j + 49, k + 20, 1, 2);
		setBlock(world, i + 0, j + 49, k + 21, Blocks.log, 1);
		world.setBlockMetadataWithNotify(i + 0, j + 49, k + 21, 1, 2);
		setBlock(world, i + 0, j + 50, k + 0, Blocks.leaves, 15);
		world.setBlockMetadataWithNotify(i + 0, j + 50, k + 0, 15, 2);
		setBlock(world, i + 0, j + 50, k + 1, Blocks.leaves, 15);
		world.setBlockMetadataWithNotify(i + 0, j + 50, k + 1, 15, 2);
		setBlock(world, i + 0, j + 50, k + 2, Blocks.leaves, 7);
		world.setBlockMetadataWithNotify(i + 0, j + 50, k + 2, 7, 2);
		setBlock(world, i + 0, j + 50, k + 3, Blocks.leaves, 7);
		world.setBlockMetadataWithNotify(i + 0, j + 50, k + 3, 7, 2);
		setBlock(world, i + 0, j + 50, k + 4, Blocks.leaves, 7);
		world.setBlockMetadataWithNotify(i + 0, j + 50, k + 4, 7, 2);
		setBlock(world, i + 0, j + 50, k + 5, Blocks.leaves, 7);
		world.setBlockMetadataWithNotify(i + 0, j + 50, k + 5, 7, 2);
		setBlock(world, i + 0, j + 50, k + 6, Blocks.leaves, 7);
		world.setBlockMetadataWithNotify(i + 0, j + 50, k + 6, 7, 2);
		setBlock(world, i + 0, j + 50, k + 9, Blocks.leaves, 7);
		world.setBlockMetadataWithNotify(i + 0, j + 50, k + 9, 7, 2);
		setBlock(world, i + 0, j + 50, k + 10, Blocks.leaves, 7);
		world.setBlockMetadataWithNotify(i + 0, j + 50, k + 10, 7, 2);
		setBlock(world, i + 0, j + 50, k + 11, Blocks.leaves, 7);
		world.setBlockMetadataWithNotify(i + 0, j + 50, k + 11, 7, 2);
		setBlock(world, i + 0, j + 50, k + 12, Blocks.leaves, 7);
		world.setBlockMetadataWithNotify(i + 0, j + 50, k + 12, 7, 2);
		setBlock(world, i + 0, j + 50, k + 13, Blocks.leaves, 7);
		world.setBlockMetadataWithNotify(i + 0, j + 50, k + 13, 7, 2);
		setBlock(world, i + 0, j + 50, k + 14, Blocks.leaves, 7);
		world.setBlockMetadataWithNotify(i + 0, j + 50, k + 14, 7, 2);
		setBlock(world, i + 0, j + 51, k + 0, Blocks.leaves, 7);
		world.setBlockMetadataWithNotify(i + 0, j + 51, k + 0, 7, 2);
		setBlock(world, i + 0, j + 51, k + 1, Blocks.leaves, 7);
		world.setBlockMetadataWithNotify(i + 0, j + 51, k + 1, 7, 2);
		setBlock(world, i + 0, j + 51, k + 2, Blocks.leaves, 7);
		world.setBlockMetadataWithNotify(i + 0, j + 51, k + 2, 7, 2);
		setBlock(world, i + 0, j + 51, k + 3, Blocks.leaves, 7);
		world.setBlockMetadataWithNotify(i + 0, j + 51, k + 3, 7, 2);
		setBlock(world, i + 0, j + 51, k + 4, Blocks.leaves, 7);
		world.setBlockMetadataWithNotify(i + 0, j + 51, k + 4, 7, 2);
		setBlock(world, i + 0, j + 51, k + 5, Blocks.leaves, 7);
		world.setBlockMetadataWithNotify(i + 0, j + 51, k + 5, 7, 2);
		setBlock(world, i + 0, j + 51, k + 10, Blocks.leaves, 7);
		world.setBlockMetadataWithNotify(i + 0, j + 51, k + 10, 7, 2);
		setBlock(world, i + 0, j + 51, k + 11, Blocks.leaves, 7);
		world.setBlockMetadataWithNotify(i + 0, j + 51, k + 11, 7, 2);
		setBlock(world, i + 0, j + 51, k + 12, Blocks.leaves, 7);
		world.setBlockMetadataWithNotify(i + 0, j + 51, k + 12, 7, 2);
		setBlock(world, i + 0, j + 51, k + 13, Blocks.leaves, 7);
		world.setBlockMetadataWithNotify(i + 0, j + 51, k + 13, 7, 2);
		setBlock(world, i + 0, j + 52, k + 1, Blocks.leaves, 7);
		world.setBlockMetadataWithNotify(i + 0, j + 52, k + 1, 7, 2);
		setBlock(world, i + 0, j + 52, k + 2, Blocks.leaves, 7);
		world.setBlockMetadataWithNotify(i + 0, j + 52, k + 2, 7, 2);
		setBlock(world, i + 0, j + 52, k + 3, Blocks.leaves, 7);
		world.setBlockMetadataWithNotify(i + 0, j + 52, k + 3, 7, 2);
		setBlock(world, i + 0, j + 52, k + 4, Blocks.leaves, 7);
		world.setBlockMetadataWithNotify(i + 0, j + 52, k + 4, 7, 2);
		setBlock(world, i + 0, j + 52, k + 12, Blocks.leaves, 7);
		world.setBlockMetadataWithNotify(i + 0, j + 52, k + 12, 7, 2);
		setBlock(world, i + 0, j + 53, k + 3, Blocks.leaves, 7);
		world.setBlockMetadataWithNotify(i + 0, j + 53, k + 3, 7, 2);
		setBlock(world, i + 0, j + 54, k + 1, Blocks.leaves, 7);
		world.setBlockMetadataWithNotify(i + 0, j + 54, k + 1, 7, 2);
		setBlock(world, i + 0, j + 54, k + 2, Blocks.leaves, 7);
		world.setBlockMetadataWithNotify(i + 0, j + 54, k + 2, 7, 2);
		setBlock(world, i + 0, j + 54, k + 3, Blocks.leaves, 7);
		world.setBlockMetadataWithNotify(i + 0, j + 54, k + 3, 7, 2);
		setBlock(world, i + 0, j + 54, k + 4, Blocks.leaves, 7);
		world.setBlockMetadataWithNotify(i + 0, j + 54, k + 4, 7, 2);
		setBlock(world, i + 0, j + 54, k + 5, Blocks.leaves, 7);
		world.setBlockMetadataWithNotify(i + 0, j + 54, k + 5, 7, 2);
		setBlock(world, i + 0, j + 55, k + 2, Blocks.leaves, 7);
		world.setBlockMetadataWithNotify(i + 0, j + 55, k + 2, 7, 2);
		setBlock(world, i + 0, j + 55, k + 3, Blocks.leaves, 7);
		world.setBlockMetadataWithNotify(i + 0, j + 55, k + 3, 7, 2);
		setBlock(world, i + 0, j + 55, k + 4, Blocks.leaves, 7);
		world.setBlockMetadataWithNotify(i + 0, j + 55, k + 4, 7, 2);
		setBlock(world, i + 0, j + 56, k + 3, Blocks.leaves, 7);
		world.setBlockMetadataWithNotify(i + 0, j + 56, k + 3, 7, 2);
		setBlock(world, i + 0, j + 57, k + 8, Blocks.leaves, 7);
		world.setBlockMetadataWithNotify(i + 0, j + 57, k + 8, 7, 2);
		setBlock(world, i + 0, j + 57, k + 9, Blocks.leaves, 7);
		world.setBlockMetadataWithNotify(i + 0, j + 57, k + 9, 7, 2);
		setBlock(world, i + 0, j + 57, k + 10, Blocks.log, 3);
		world.setBlockMetadataWithNotify(i + 0, j + 57, k + 10, 3, 2);
		setBlock(world, i + 0, j + 57, k + 11, Blocks.leaves, 7);
		world.setBlockMetadataWithNotify(i + 0, j + 57, k + 11, 7, 2);
		setBlock(world, i + 0, j + 57, k + 12, Blocks.leaves, 7);
		world.setBlockMetadataWithNotify(i + 0, j + 57, k + 12, 7, 2);
		setBlock(world, i + 0, j + 58, k + 8, Blocks.leaves, 7);
		world.setBlockMetadataWithNotify(i + 0, j + 58, k + 8, 7, 2);
		setBlock(world, i + 0, j + 58, k + 9, Blocks.leaves, 7);
		world.setBlockMetadataWithNotify(i + 0, j + 58, k + 9, 7, 2);
		setBlock(world, i + 0, j + 58, k + 10, Blocks.leaves, 7);
		world.setBlockMetadataWithNotify(i + 0, j + 58, k + 10, 7, 2);
		setBlock(world, i + 0, j + 58, k + 11, Blocks.leaves, 7);
		world.setBlockMetadataWithNotify(i + 0, j + 58, k + 11, 7, 2);
		setBlock(world, i + 0, j + 58, k + 12, Blocks.leaves, 7);
		world.setBlockMetadataWithNotify(i + 0, j + 58, k + 12, 7, 2);
		setBlock(world, i + 0, j + 59, k + 5, Blocks.leaves, 7);
		world.setBlockMetadataWithNotify(i + 0, j + 59, k + 5, 7, 2);
		setBlock(world, i + 0, j + 59, k + 6, Blocks.leaves, 7);
		world.setBlockMetadataWithNotify(i + 0, j + 59, k + 6, 7, 2);
		setBlock(world, i + 0, j + 59, k + 7, Blocks.leaves, 7);
		world.setBlockMetadataWithNotify(i + 0, j + 59, k + 7, 7, 2);
		setBlock(world, i + 0, j + 59, k + 9, Blocks.leaves, 7);
		world.setBlockMetadataWithNotify(i + 0, j + 59, k + 9, 7, 2);
		setBlock(world, i + 0, j + 59, k + 10, Blocks.leaves, 7);
		world.setBlockMetadataWithNotify(i + 0, j + 59, k + 10, 7, 2);
		setBlock(world, i + 0, j + 59, k + 11, Blocks.leaves, 7);
		world.setBlockMetadataWithNotify(i + 0, j + 59, k + 11, 7, 2);
		setBlock(world, i + 0, j + 60, k + 6, Blocks.leaves, 7);
		world.setBlockMetadataWithNotify(i + 0, j + 60, k + 6, 7, 2);
		setBlock(world, i + 0, j + 60, k + 10, Blocks.leaves, 7);
		world.setBlockMetadataWithNotify(i + 0, j + 60, k + 10, 7, 2);
		setBlock(world, i + 1, j + 0, k + 8, Blocks.log, 3);
		world.setBlockMetadataWithNotify(i + 1, j + 0, k + 8, 3, 2);
		setBlock(world, i + 1, j + 22, k + 4, Blocks.log, 3);
		world.setBlockMetadataWithNotify(i + 1, j + 22, k + 4, 3, 2);
		setBlock(world, i + 1, j + 22, k + 12, Blocks.log, 3);
		world.setBlockMetadataWithNotify(i + 1, j + 22, k + 12, 3, 2);
		setBlock(world, i + 1, j + 23, k + 17, Blocks.log, 3);
		world.setBlockMetadataWithNotify(i + 1, j + 23, k + 17, 3, 2);
		setBlock(world, i + 1, j + 23, k + 20, Blocks.log, 3);
		world.setBlockMetadataWithNotify(i + 1, j + 23, k + 20, 3, 2);
		setBlock(world, i + 1, j + 24, k + 4, Blocks.log, 3);
		world.setBlockMetadataWithNotify(i + 1, j + 24, k + 4, 3, 2);
		setBlock(world, i + 1, j + 24, k + 6, Blocks.leaves, 7);
		world.setBlockMetadataWithNotify(i + 1, j + 24, k + 6, 7, 2);
		setBlock(world, i + 1, j + 24, k + 7, Blocks.leaves, 7);
		world.setBlockMetadataWithNotify(i + 1, j + 24, k + 7, 7, 2);
		setBlock(world, i + 1, j + 24, k + 8, Blocks.leaves, 7);
		world.setBlockMetadataWithNotify(i + 1, j + 24, k + 8, 7, 2);
		setBlock(world, i + 1, j + 24, k + 9, Blocks.leaves, 7);
		world.setBlockMetadataWithNotify(i + 1, j + 24, k + 9, 7, 2);
		setBlock(world, i + 1, j + 24, k + 10, Blocks.leaves, 7);
		world.setBlockMetadataWithNotify(i + 1, j + 24, k + 10, 7, 2);
		setBlock(world, i + 1, j + 24, k + 15, Blocks.log, 3);
		world.setBlockMetadataWithNotify(i + 1, j + 24, k + 15, 3, 2);
		setBlock(world, i + 1, j + 24, k + 16, Blocks.log, 3);
		world.setBlockMetadataWithNotify(i + 1, j + 24, k + 16, 3, 2);
		setBlock(world, i + 1, j + 24, k + 17, Blocks.log, 3);
		world.setBlockMetadataWithNotify(i + 1, j + 24, k + 17, 3, 2);
		setBlock(world, i + 1, j + 24, k + 21, Blocks.leaves, 7);
		world.setBlockMetadataWithNotify(i + 1, j + 24, k + 21, 7, 2);
		setBlock(world, i + 1, j + 24, k + 22, Blocks.leaves, 7);
		world.setBlockMetadataWithNotify(i + 1, j + 24, k + 22, 7, 2);
		setBlock(world, i + 1, j + 24, k + 23, Blocks.leaves, 7);
		world.setBlockMetadataWithNotify(i + 1, j + 24, k + 23, 7, 2);
		setBlock(world, i + 1, j + 25, k + 7, Blocks.leaves, 7);
		world.setBlockMetadataWithNotify(i + 1, j + 25, k + 7, 7, 2);
		setBlock(world, i + 1, j + 25, k + 8, Blocks.leaves, 7);
		world.setBlockMetadataWithNotify(i + 1, j + 25, k + 8, 7, 2);
		setBlock(world, i + 1, j + 25, k + 9, Blocks.leaves, 7);
		world.setBlockMetadataWithNotify(i + 1, j + 25, k + 9, 7, 2);
		setBlock(world, i + 1, j + 25, k + 11, Blocks.log, 3);
		world.setBlockMetadataWithNotify(i + 1, j + 25, k + 11, 3, 2);
		setBlock(world, i + 1, j + 25, k + 17, Blocks.log, 3);
		world.setBlockMetadataWithNotify(i + 1, j + 25, k + 17, 3, 2);
		setBlock(world, i + 1, j + 25, k + 20, Blocks.log, 3);
		world.setBlockMetadataWithNotify(i + 1, j + 25, k + 20, 3, 2);
		setBlock(world, i + 1, j + 25, k + 22, Blocks.leaves, 7);
		world.setBlockMetadataWithNotify(i + 1, j + 25, k + 22, 7, 2);
		setBlock(world, i + 1, j + 26, k + 8, Blocks.leaves, 7);
		world.setBlockMetadataWithNotify(i + 1, j + 26, k + 8, 7, 2);
		setBlock(world, i + 1, j + 27, k + 3, Blocks.log, 3);
		world.setBlockMetadataWithNotify(i + 1, j + 27, k + 3, 3, 2);
		setBlock(world, i + 1, j + 31, k + 7, Blocks.log, 3);
		world.setBlockMetadataWithNotify(i + 1, j + 31, k + 7, 3, 2);
		setBlock(world, i + 1, j + 31, k + 20, Blocks.log, 3);
		world.setBlockMetadataWithNotify(i + 1, j + 31, k + 20, 3, 2);
		setBlock(world, i + 1, j + 32, k + 15, Blocks.log, 3);
		world.setBlockMetadataWithNotify(i + 1, j + 32, k + 15, 3, 2);
		setBlock(world, i + 1, j + 32, k + 21, Blocks.leaves, 7);
		world.setBlockMetadataWithNotify(i + 1, j + 32, k + 21, 7, 2);
		setBlock(world, i + 1, j + 32, k + 22, Blocks.log, 1);
		world.setBlockMetadataWithNotify(i + 1, j + 32, k + 22, 1, 2);
		setBlock(world, i + 1, j + 32, k + 23, Blocks.leaves, 7);
		world.setBlockMetadataWithNotify(i + 1, j + 32, k + 23, 7, 2);
		setBlock(world, i + 1, j + 33, k + 13, Blocks.log, 3);
		world.setBlockMetadataWithNotify(i + 1, j + 33, k + 13, 3, 2);
		setBlock(world, i + 1, j + 33, k + 15, Blocks.leaves, 7);
		world.setBlockMetadataWithNotify(i + 1, j + 33, k + 15, 7, 2);
		setBlock(world, i + 1, j + 33, k + 16, Blocks.leaves, 7);
		world.setBlockMetadataWithNotify(i + 1, j + 33, k + 16, 7, 2);
		setBlock(world, i + 1, j + 33, k + 17, Blocks.leaves, 7);
		world.setBlockMetadataWithNotify(i + 1, j + 33, k + 17, 7, 2);
		setBlock(world, i + 1, j + 33, k + 21, Blocks.log, 1);
		world.setBlockMetadataWithNotify(i + 1, j + 33, k + 21, 1, 2);
		setBlock(world, i + 1, j + 33, k + 22, Blocks.log, 1);
		world.setBlockMetadataWithNotify(i + 1, j + 33, k + 22, 1, 2);
		setBlock(world, i + 1, j + 33, k + 23, Blocks.log, 1);
		world.setBlockMetadataWithNotify(i + 1, j + 33, k + 23, 1, 2);
		setBlock(world, i + 1, j + 34, k + 11, Blocks.leaves, 7);
		world.setBlockMetadataWithNotify(i + 1, j + 34, k + 11, 7, 2);
		setBlock(world, i + 1, j + 34, k + 12, Blocks.leaves, 7);
		world.setBlockMetadataWithNotify(i + 1, j + 34, k + 12, 7, 2);
		setBlock(world, i + 1, j + 34, k + 13, Blocks.leaves, 7);
		world.setBlockMetadataWithNotify(i + 1, j + 34, k + 13, 7, 2);
		setBlock(world, i + 1, j + 34, k + 14, Blocks.leaves, 7);
		world.setBlockMetadataWithNotify(i + 1, j + 34, k + 14, 7, 2);
		setBlock(world, i + 1, j + 34, k + 15, Blocks.leaves, 7);
		world.setBlockMetadataWithNotify(i + 1, j + 34, k + 15, 7, 2);
		setBlock(world, i + 1, j + 34, k + 16, Blocks.leaves, 7);
		world.setBlockMetadataWithNotify(i + 1, j + 34, k + 16, 7, 2);
		setBlock(world, i + 1, j + 35, k + 12, Blocks.leaves, 7);
		world.setBlockMetadataWithNotify(i + 1, j + 35, k + 12, 7, 2);
		setBlock(world, i + 1, j + 35, k + 13, Blocks.leaves, 7);
		world.setBlockMetadataWithNotify(i + 1, j + 35, k + 13, 7, 2);
		setBlock(world, i + 1, j + 35, k + 14, Blocks.leaves, 7);
		world.setBlockMetadataWithNotify(i + 1, j + 35, k + 14, 7, 2);
		setBlock(world, i + 1, j + 35, k + 18, Blocks.log, 1);
		world.setBlockMetadataWithNotify(i + 1, j + 35, k + 18, 1, 2);
		setBlock(world, i + 1, j + 35, k + 19, Blocks.log, 1);
		world.setBlockMetadataWithNotify(i + 1, j + 35, k + 19, 1, 2);
		setBlock(world, i + 1, j + 35, k + 20, Blocks.log, 1);
		world.setBlockMetadataWithNotify(i + 1, j + 35, k + 20, 1, 2);
		setBlock(world, i + 1, j + 35, k + 21, Blocks.log, 1);
		world.setBlockMetadataWithNotify(i + 1, j + 35, k + 21, 1, 2);
		setBlock(world, i + 1, j + 36, k + 13, Blocks.leaves, 15);
		world.setBlockMetadataWithNotify(i + 1, j + 36, k + 13, 15, 2);
		setBlock(world, i + 1, j + 36, k + 18, Blocks.log, 1);
		world.setBlockMetadataWithNotify(i + 1, j + 36, k + 18, 1, 2);
		setBlock(world, i + 1, j + 36, k + 19, Blocks.log, 1);
		world.setBlockMetadataWithNotify(i + 1, j + 36, k + 19, 1, 2);
		setBlock(world, i + 1, j + 36, k + 20, Blocks.log, 1);
		world.setBlockMetadataWithNotify(i + 1, j + 36, k + 20, 1, 2);
		setBlock(world, i + 1, j + 36, k + 21, Blocks.log, 1);
		world.setBlockMetadataWithNotify(i + 1, j + 36, k + 21, 1, 2);
		setBlock(world, i + 1, j + 37, k + 16, Blocks.leaves, 15);
		world.setBlockMetadataWithNotify(i + 1, j + 37, k + 16, 15, 2);
		setBlock(world, i + 1, j + 37, k + 17, Blocks.log, 1);
		world.setBlockMetadataWithNotify(i + 1, j + 37, k + 17, 1, 2);
		setBlock(world, i + 1, j + 37, k + 18, Blocks.log, 1);
		world.setBlockMetadataWithNotify(i + 1, j + 37, k + 18, 1, 2);
		setBlock(world, i + 1, j + 37, k + 19, Blocks.log, 1);
		world.setBlockMetadataWithNotify(i + 1, j + 37, k + 19, 1, 2);
		setBlock(world, i + 1, j + 37, k + 20, Blocks.log, 1);
		world.setBlockMetadataWithNotify(i + 1, j + 37, k + 20, 1, 2);
		setBlock(world, i + 1, j + 37, k + 21, Blocks.log, 1);
		world.setBlockMetadataWithNotify(i + 1, j + 37, k + 21, 1, 2);
		setBlock(world, i + 1, j + 37, k + 29, Blocks.vine, 4);
		world.setBlockMetadataWithNotify(i + 1, j + 37, k + 29, 4, 2);
		setBlock(world, i + 1, j + 38, k + 6, Blocks.leaves, 15);
		world.setBlockMetadataWithNotify(i + 1, j + 38, k + 6, 15, 2);
		setBlock(world, i + 1, j + 38, k + 8, Blocks.leaves, 15);
		world.setBlockMetadataWithNotify(i + 1, j + 38, k + 8, 15, 2);
		setBlock(world, i + 1, j + 38, k + 9, Blocks.leaves, 15);
		world.setBlockMetadataWithNotify(i + 1, j + 38, k + 9, 15, 2);
		setBlock(world, i + 1, j + 38, k + 10, Blocks.log, 3);
		world.setBlockMetadataWithNotify(i + 1, j + 38, k + 10, 3, 2);
		setBlock(world, i + 1, j + 38, k + 17, Blocks.log, 1);
		world.setBlockMetadataWithNotify(i + 1, j + 38, k + 17, 1, 2);
		setBlock(world, i + 1, j + 38, k + 18, Blocks.log, 1);
		world.setBlockMetadataWithNotify(i + 1, j + 38, k + 18, 1, 2);
		setBlock(world, i + 1, j + 38, k + 19, Blocks.log, 1);
		world.setBlockMetadataWithNotify(i + 1, j + 38, k + 19, 1, 2);
		setBlock(world, i + 1, j + 38, k + 20, Blocks.log, 1);
		world.setBlockMetadataWithNotify(i + 1, j + 38, k + 20, 1, 2);
		setBlock(world, i + 1, j + 38, k + 21, Blocks.log, 1);
		world.setBlockMetadataWithNotify(i + 1, j + 38, k + 21, 1, 2);
		setBlock(world, i + 1, j + 38, k + 22, Blocks.log, 1);
		world.setBlockMetadataWithNotify(i + 1, j + 38, k + 22, 1, 2);
		setBlock(world, i + 1, j + 38, k + 24, Blocks.vine, 2);
		world.setBlockMetadataWithNotify(i + 1, j + 38, k + 24, 2, 2);
		setBlock(world, i + 1, j + 38, k + 25, Blocks.vine, 7);
		world.setBlockMetadataWithNotify(i + 1, j + 38, k + 25, 7, 2);
		setBlock(world, i + 1, j + 38, k + 26, Blocks.vine, 15);
		world.setBlockMetadataWithNotify(i + 1, j + 38, k + 26, 15, 2);
		setBlock(world, i + 1, j + 38, k + 27, Blocks.vine, 15);
		world.setBlockMetadataWithNotify(i + 1, j + 38, k + 27, 15, 2);
		setBlock(world, i + 1, j + 38, k + 28, Blocks.vine, 9);
		world.setBlockMetadataWithNotify(i + 1, j + 38, k + 28, 9, 2);
		setBlock(world, i + 1, j + 38, k + 29, Blocks.vine, 6);
		world.setBlockMetadataWithNotify(i + 1, j + 38, k + 29, 6, 2);
		setBlock(world, i + 1, j + 38, k + 30, Blocks.vine, 15);
		world.setBlockMetadataWithNotify(i + 1, j + 38, k + 30, 15, 2);
		setBlock(world, i + 1, j + 38, k + 31, Blocks.vine, 7);
		world.setBlockMetadataWithNotify(i + 1, j + 38, k + 31, 7, 2);
		setBlock(world, i + 1, j + 39, k + 16, Blocks.log, 1);
		world.setBlockMetadataWithNotify(i + 1, j + 39, k + 16, 1, 2);
		setBlock(world, i + 1, j + 39, k + 17, Blocks.log, 1);
		world.setBlockMetadataWithNotify(i + 1, j + 39, k + 17, 1, 2);
		setBlock(world, i + 1, j + 39, k + 18, Blocks.log, 1);
		world.setBlockMetadataWithNotify(i + 1, j + 39, k + 18, 1, 2);
		setBlock(world, i + 1, j + 39, k + 19, Blocks.log, 1);
		world.setBlockMetadataWithNotify(i + 1, j + 39, k + 19, 1, 2);
		setBlock(world, i + 1, j + 39, k + 20, Blocks.log, 1);
		world.setBlockMetadataWithNotify(i + 1, j + 39, k + 20, 1, 2);
		setBlock(world, i + 1, j + 39, k + 21, Blocks.log, 1);
		world.setBlockMetadataWithNotify(i + 1, j + 39, k + 21, 1, 2);
		setBlock(world, i + 1, j + 39, k + 22, Blocks.log, 1);
		world.setBlockMetadataWithNotify(i + 1, j + 39, k + 22, 1, 2);
		setBlock(world, i + 1, j + 39, k + 23, Blocks.vine, 15);
		world.setBlockMetadataWithNotify(i + 1, j + 39, k + 23, 15, 2);
		setBlock(world, i + 1, j + 39, k + 24, Blocks.vine, 15);
		world.setBlockMetadataWithNotify(i + 1, j + 39, k + 24, 15, 2);
		setBlock(world, i + 1, j + 39, k + 25, Blocks.vine, 15);
		world.setBlockMetadataWithNotify(i + 1, j + 39, k + 25, 15, 2);
		setBlock(world, i + 1, j + 39, k + 26, Blocks.vine, 15);
		world.setBlockMetadataWithNotify(i + 1, j + 39, k + 26, 15, 2);
		setBlock(world, i + 1, j + 39, k + 27, Blocks.vine, 15);
		world.setBlockMetadataWithNotify(i + 1, j + 39, k + 27, 15, 2);
		setBlock(world, i + 1, j + 39, k + 28, Blocks.vine, 15);
		world.setBlockMetadataWithNotify(i + 1, j + 39, k + 28, 15, 2);
		setBlock(world, i + 1, j + 39, k + 29, Blocks.vine, 15);
		world.setBlockMetadataWithNotify(i + 1, j + 39, k + 29, 15, 2);
		setBlock(world, i + 1, j + 39, k + 30, Blocks.vine, 15);
		world.setBlockMetadataWithNotify(i + 1, j + 39, k + 30, 15, 2);
		setBlock(world, i + 1, j + 39, k + 31, Blocks.vine, 15);
		world.setBlockMetadataWithNotify(i + 1, j + 39, k + 31, 15, 2);
		setBlock(world, i + 1, j + 40, k + 0, Blocks.planks, 5);
		world.setBlockMetadataWithNotify(i + 1, j + 40, k + 0, 5, 2);
		setBlock(world, i + 1, j + 40, k + 1, Blocks.planks, 5);
		world.setBlockMetadataWithNotify(i + 1, j + 40, k + 1, 5, 2);
		setBlock(world, i + 1, j + 40, k + 2, Blocks.planks, 5);
		world.setBlockMetadataWithNotify(i + 1, j + 40, k + 2, 5, 2);
		setBlock(world, i + 1, j + 40, k + 3, Blocks.planks, 5);
		world.setBlockMetadataWithNotify(i + 1, j + 40, k + 3, 5, 2);
		setBlock(world, i + 1, j + 40, k + 4, Blocks.planks, 5);
		world.setBlockMetadataWithNotify(i + 1, j + 40, k + 4, 5, 2);
		setBlock(world, i + 1, j + 40, k + 5, Blocks.planks, 5);
		world.setBlockMetadataWithNotify(i + 1, j + 40, k + 5, 5, 2);
		setBlock(world, i + 1, j + 40, k + 6, Blocks.planks, 5);
		world.setBlockMetadataWithNotify(i + 1, j + 40, k + 6, 5, 2);
		setBlock(world, i + 1, j + 40, k + 7, Blocks.planks, 5);
		world.setBlockMetadataWithNotify(i + 1, j + 40, k + 7, 5, 2);
		setBlock(world, i + 1, j + 40, k + 8, Blocks.planks, 5);
		world.setBlockMetadataWithNotify(i + 1, j + 40, k + 8, 5, 2);
		setBlock(world, i + 1, j + 40, k + 9, Blocks.planks, 5);
		world.setBlockMetadataWithNotify(i + 1, j + 40, k + 9, 5, 2);
		setBlock(world, i + 1, j + 40, k + 10, Blocks.planks, 5);
		world.setBlockMetadataWithNotify(i + 1, j + 40, k + 10, 5, 2);
		setBlock(world, i + 1, j + 40, k + 11, Blocks.planks, 5);
		world.setBlockMetadataWithNotify(i + 1, j + 40, k + 11, 5, 2);
		setBlock(world, i + 1, j + 40, k + 12, Blocks.log, 1);
		world.setBlockMetadataWithNotify(i + 1, j + 40, k + 12, 1, 2);
		setBlock(world, i + 1, j + 40, k + 13, Blocks.log, 1);
		world.setBlockMetadataWithNotify(i + 1, j + 40, k + 13, 1, 2);
		setBlock(world, i + 1, j + 40, k + 14, Blocks.planks, 5);
		world.setBlockMetadataWithNotify(i + 1, j + 40, k + 14, 5, 2);
		setBlock(world, i + 1, j + 40, k + 15, Blocks.log, 1);
		world.setBlockMetadataWithNotify(i + 1, j + 40, k + 15, 1, 2);
		setBlock(world, i + 1, j + 40, k + 16, Blocks.planks, 5);
		world.setBlockMetadataWithNotify(i + 1, j + 40, k + 16, 5, 2);
		setBlock(world, i + 1, j + 40, k + 17, Blocks.log, 1);
		world.setBlockMetadataWithNotify(i + 1, j + 40, k + 17, 1, 2);
		setBlock(world, i + 1, j + 40, k + 18, Blocks.log, 1);
		world.setBlockMetadataWithNotify(i + 1, j + 40, k + 18, 1, 2);
		setBlock(world, i + 1, j + 40, k + 19, Blocks.log, 1);
		world.setBlockMetadataWithNotify(i + 1, j + 40, k + 19, 1, 2);
		setBlock(world, i + 1, j + 40, k + 20, Blocks.planks, 5);
		world.setBlockMetadataWithNotify(i + 1, j + 40, k + 20, 5, 2);
		/* 1000 */setBlock(world, i + 1, j + 40, k + 21, Blocks.log, 1);
		/* 1001 */world.setBlockMetadataWithNotify(i + 1, j + 40, k + 21, 1, 2);
		/* 1002 */setBlock(world, i + 1, j + 40, k + 22, Blocks.planks, 5);
		/* 1003 */world.setBlockMetadataWithNotify(i + 1, j + 40, k + 22, 5, 2);
		/* 1004 */setBlock(world, i + 1, j + 40, k + 23, Blocks.log, 1);
		/* 1005 */world.setBlockMetadataWithNotify(i + 1, j + 40, k + 23, 1, 2);
		/* 1006 */setBlock(world, i + 1, j + 40, k + 24, Blocks.log, 1);
		/* 1007 */world.setBlockMetadataWithNotify(i + 1, j + 40, k + 24, 1, 2);
		/* 1008 */setBlock(world, i + 1, j + 40, k + 25, Blocks.planks, 5);
		/* 1009 */world.setBlockMetadataWithNotify(i + 1, j + 40, k + 25, 5, 2);
		/* 1010 */setBlock(world, i + 1, j + 40, k + 26, Blocks.planks, 5);
		/* 1011 */world.setBlockMetadataWithNotify(i + 1, j + 40, k + 26, 5, 2);
		/* 1012 */setBlock(world, i + 1, j + 40, k + 27, Blocks.planks, 5);
		/* 1013 */world.setBlockMetadataWithNotify(i + 1, j + 40, k + 27, 5, 2);
		/* 1014 */setBlock(world, i + 1, j + 40, k + 28, Blocks.planks, 5);
		/* 1015 */world.setBlockMetadataWithNotify(i + 1, j + 40, k + 28, 5, 2);
		/* 1016 */setBlock(world, i + 1, j + 40, k + 29, Blocks.planks, 5);
		/* 1017 */world.setBlockMetadataWithNotify(i + 1, j + 40, k + 29, 5, 2);
		/* 1018 */setBlock(world, i + 1, j + 40, k + 30, Blocks.planks, 5);
		/* 1019 */world.setBlockMetadataWithNotify(i + 1, j + 40, k + 30, 5, 2);
		/* 1020 */setBlock(world, i + 1, j + 40, k + 31, Blocks.planks, 5);
		/* 1021 */world.setBlockMetadataWithNotify(i + 1, j + 40, k + 31, 5, 2);
		/* 1022 */setBlock(world, i + 1, j + 41, k + 17, Blocks.spruce_stairs, 2);
		/* 1023 */world.setBlockMetadataWithNotify(i + 1, j + 41, k + 17, 2, 2);
		/* 1024 */setBlock(world, i + 1, j + 41, k + 18, Blocks.log, 1);
		/* 1025 */world.setBlockMetadataWithNotify(i + 1, j + 41, k + 18, 1, 2);
		/* 1026 */setBlock(world, i + 1, j + 41, k + 19, Blocks.spruce_stairs, 3);
		/* 1027 */world.setBlockMetadataWithNotify(i + 1, j + 41, k + 19, 3, 2);
		/* 1028 */setBlock(world, i + 1, j + 42, k + 18, Blocks.log, 1);
		/* 1029 */world.setBlockMetadataWithNotify(i + 1, j + 42, k + 18, 1, 2);
		/* 1030 */setBlock(world, i + 1, j + 43, k + 18, Blocks.log, 1);
		/* 1031 */world.setBlockMetadataWithNotify(i + 1, j + 43, k + 18, 1, 2);
		/* 1032 */setBlock(world, i + 1, j + 44, k + 9, Blocks.log, 1);
		/* 1033 */world.setBlockMetadataWithNotify(i + 1, j + 44, k + 9, 1, 2);
		/* 1034 */setBlock(world, i + 1, j + 44, k + 10, Blocks.log, 1);
		/* 1035 */world.setBlockMetadataWithNotify(i + 1, j + 44, k + 10, 1, 2);
		/* 1036 */setBlock(world, i + 1, j + 44, k + 11, Blocks.log, 1);
		/* 1037 */world.setBlockMetadataWithNotify(i + 1, j + 44, k + 11, 1, 2);
		/* 1038 */setBlock(world, i + 1, j + 44, k + 12, Blocks.log, 1);
		/* 1039 */world.setBlockMetadataWithNotify(i + 1, j + 44, k + 12, 1, 2);
		/* 1040 */setBlock(world, i + 1, j + 44, k + 13, Blocks.log, 1);
		/* 1041 */world.setBlockMetadataWithNotify(i + 1, j + 44, k + 13, 1, 2);
		/* 1042 */setBlock(world, i + 1, j + 44, k + 17, Blocks.torch, 4);
		/* 1043 */world.setBlockMetadataWithNotify(i + 1, j + 44, k + 17, 4, 2);
		/* 1044 */setBlock(world, i + 1, j + 44, k + 18, Blocks.log, 1);
		/* 1045 */world.setBlockMetadataWithNotify(i + 1, j + 44, k + 18, 1, 2);
		/* 1046 */setBlock(world, i + 1, j + 44, k + 19, Blocks.torch, 3);
		/* 1047 */world.setBlockMetadataWithNotify(i + 1, j + 44, k + 19, 3, 2);
		/* 1048 */setBlock(world, i + 1, j + 44, k + 23, Blocks.log, 1);
		/* 1049 */world.setBlockMetadataWithNotify(i + 1, j + 44, k + 23, 1, 2);
		/* 1050 */setBlock(world, i + 1, j + 44, k + 24, Blocks.log, 1);
		/* 1051 */world.setBlockMetadataWithNotify(i + 1, j + 44, k + 24, 1, 2);
		/* 1052 */setBlock(world, i + 1, j + 44, k + 25, Blocks.log, 1);
		/* 1053 */world.setBlockMetadataWithNotify(i + 1, j + 44, k + 25, 1, 2);
		/* 1054 */setBlock(world, i + 1, j + 44, k + 26, Blocks.log, 1);
		/* 1055 */world.setBlockMetadataWithNotify(i + 1, j + 44, k + 26, 1, 2);
		/* 1056 */setBlock(world, i + 1, j + 44, k + 27, Blocks.log, 1);
		/* 1057 */world.setBlockMetadataWithNotify(i + 1, j + 44, k + 27, 1, 2);
		/* 1058 */setBlock(world, i + 1, j + 45, k + 9, Blocks.log, 3);
		/* 1059 */world.setBlockMetadataWithNotify(i + 1, j + 45, k + 9, 3, 2);
		/* 1060 */setBlock(world, i + 1, j + 45, k + 10, Blocks.log, 1);
		/* 1061 */world.setBlockMetadataWithNotify(i + 1, j + 45, k + 10, 1, 2);
		/* 1062 */setBlock(world, i + 1, j + 45, k + 11, Blocks.log, 1);
		/* 1063 */world.setBlockMetadataWithNotify(i + 1, j + 45, k + 11, 1, 2);
		/* 1064 */setBlock(world, i + 1, j + 45, k + 12, Blocks.log, 1);
		/* 1065 */world.setBlockMetadataWithNotify(i + 1, j + 45, k + 12, 1, 2);
		/* 1066 */setBlock(world, i + 1, j + 45, k + 13, Blocks.log, 1);
		/* 1067 */world.setBlockMetadataWithNotify(i + 1, j + 45, k + 13, 1, 2);
		/* 1068 */setBlock(world, i + 1, j + 45, k + 14, Blocks.log, 1);
		/* 1069 */world.setBlockMetadataWithNotify(i + 1, j + 45, k + 14, 1, 2);
		/* 1070 */setBlock(world, i + 1, j + 45, k + 18, Blocks.log, 1);
		/* 1071 */world.setBlockMetadataWithNotify(i + 1, j + 45, k + 18, 1, 2);
		/* 1072 */setBlock(world, i + 1, j + 45, k + 22, Blocks.log, 1);
		/* 1073 */world.setBlockMetadataWithNotify(i + 1, j + 45, k + 22, 1, 2);
		/* 1074 */setBlock(world, i + 1, j + 45, k + 23, Blocks.log, 1);
		/* 1075 */world.setBlockMetadataWithNotify(i + 1, j + 45, k + 23, 1, 2);
		/* 1076 */setBlock(world, i + 1, j + 45, k + 24, Blocks.log, 1);
		/* 1077 */world.setBlockMetadataWithNotify(i + 1, j + 45, k + 24, 1, 2);
		/* 1078 */setBlock(world, i + 1, j + 45, k + 25, Blocks.log, 1);
		/* 1079 */world.setBlockMetadataWithNotify(i + 1, j + 45, k + 25, 1, 2);
		/* 1080 */setBlock(world, i + 1, j + 45, k + 26, Blocks.log, 1);
		/* 1081 */world.setBlockMetadataWithNotify(i + 1, j + 45, k + 26, 1, 2);
		/* 1082 */setBlock(world, i + 1, j + 46, k + 8, Blocks.leaves, 15);
		/* 1083 */world.setBlockMetadataWithNotify(i + 1, j + 46, k + 8, 15, 2);
		/* 1084 */setBlock(world, i + 1, j + 46, k + 9, Blocks.leaves, 15);
		/* 1085 */world.setBlockMetadataWithNotify(i + 1, j + 46, k + 9, 15, 2);
		/* 1086 */setBlock(world, i + 1, j + 46, k + 10, Blocks.log, 1);
		/* 1087 */world.setBlockMetadataWithNotify(i + 1, j + 46, k + 10, 1, 2);
		/* 1088 */setBlock(world, i + 1, j + 46, k + 11, Blocks.log, 1);
		/* 1089 */world.setBlockMetadataWithNotify(i + 1, j + 46, k + 11, 1, 2);
		/* 1090 */setBlock(world, i + 1, j + 46, k + 12, Blocks.log, 1);
		/* 1091 */world.setBlockMetadataWithNotify(i + 1, j + 46, k + 12, 1, 2);
		/* 1092 */setBlock(world, i + 1, j + 46, k + 13, Blocks.log, 1);
		/* 1093 */world.setBlockMetadataWithNotify(i + 1, j + 46, k + 13, 1, 2);
		/* 1094 */setBlock(world, i + 1, j + 46, k + 14, Blocks.log, 1);
		/* 1095 */world.setBlockMetadataWithNotify(i + 1, j + 46, k + 14, 1, 2);
		/* 1096 */setBlock(world, i + 1, j + 46, k + 15, Blocks.log, 1);
		/* 1097 */world.setBlockMetadataWithNotify(i + 1, j + 46, k + 15, 1, 2);
		/* 1098 */setBlock(world, i + 1, j + 46, k + 17, Blocks.log, 1);
		/* 1099 */world.setBlockMetadataWithNotify(i + 1, j + 46, k + 17, 1, 2);
		/* 1100 */setBlock(world, i + 1, j + 46, k + 18, Blocks.log, 1);
		/* 1101 */world.setBlockMetadataWithNotify(i + 1, j + 46, k + 18, 1, 2);
		/* 1102 */setBlock(world, i + 1, j + 46, k + 19, Blocks.log, 1);
		/* 1103 */world.setBlockMetadataWithNotify(i + 1, j + 46, k + 19, 1, 2);
		/* 1104 */setBlock(world, i + 1, j + 46, k + 21, Blocks.log, 1);
		/* 1105 */world.setBlockMetadataWithNotify(i + 1, j + 46, k + 21, 1, 2);
		/* 1106 */setBlock(world, i + 1, j + 46, k + 22, Blocks.log, 1);
		/* 1107 */world.setBlockMetadataWithNotify(i + 1, j + 46, k + 22, 1, 2);
		/* 1108 */setBlock(world, i + 1, j + 46, k + 23, Blocks.log, 1);
		/* 1109 */world.setBlockMetadataWithNotify(i + 1, j + 46, k + 23, 1, 2);
		/* 1110 */setBlock(world, i + 1, j + 46, k + 24, Blocks.log, 1);
		/* 1111 */world.setBlockMetadataWithNotify(i + 1, j + 46, k + 24, 1, 2);
		/* 1112 */setBlock(world, i + 1, j + 46, k + 25, Blocks.log, 1);
		/* 1113 */world.setBlockMetadataWithNotify(i + 1, j + 46, k + 25, 1, 2);
		/* 1114 */setBlock(world, i + 1, j + 46, k + 26, Blocks.log, 1);
		/* 1115 */world.setBlockMetadataWithNotify(i + 1, j + 46, k + 26, 1, 2);
		/* 1116 */setBlock(world, i + 1, j + 47, k + 7, Blocks.leaves, 15);
		/* 1117 */world.setBlockMetadataWithNotify(i + 1, j + 47, k + 7, 15, 2);
		/* 1118 */setBlock(world, i + 1, j + 47, k + 8, Blocks.leaves, 15);
		/* 1119 */world.setBlockMetadataWithNotify(i + 1, j + 47, k + 8, 15, 2);
		/* 1120 */setBlock(world, i + 1, j + 47, k + 9, Blocks.leaves, 15);
		/* 1121 */world.setBlockMetadataWithNotify(i + 1, j + 47, k + 9, 15, 2);
		/* 1122 */setBlock(world, i + 1, j + 47, k + 10, Blocks.leaves, 15);
		/* 1123 */world.setBlockMetadataWithNotify(i + 1, j + 47, k + 10, 15, 2);
		/* 1124 */setBlock(world, i + 1, j + 47, k + 11, Blocks.log, 1);
		/* 1125 */world.setBlockMetadataWithNotify(i + 1, j + 47, k + 11, 1, 2);
		/* 1126 */setBlock(world, i + 1, j + 47, k + 12, Blocks.log, 1);
		/* 1127 */world.setBlockMetadataWithNotify(i + 1, j + 47, k + 12, 1, 2);
		/* 1128 */setBlock(world, i + 1, j + 47, k + 13, Blocks.log, 1);
		/* 1129 */world.setBlockMetadataWithNotify(i + 1, j + 47, k + 13, 1, 2);
		/* 1130 */setBlock(world, i + 1, j + 47, k + 14, Blocks.log, 1);
		/* 1131 */world.setBlockMetadataWithNotify(i + 1, j + 47, k + 14, 1, 2);
		/* 1132 */setBlock(world, i + 1, j + 47, k + 15, Blocks.log, 1);
		/* 1133 */world.setBlockMetadataWithNotify(i + 1, j + 47, k + 15, 1, 2);
		/* 1134 */setBlock(world, i + 1, j + 47, k + 16, Blocks.log, 1);
		/* 1135 */world.setBlockMetadataWithNotify(i + 1, j + 47, k + 16, 1, 2);
		/* 1136 */setBlock(world, i + 1, j + 47, k + 17, Blocks.log, 1);
		/* 1137 */world.setBlockMetadataWithNotify(i + 1, j + 47, k + 17, 1, 2);
		/* 1138 */setBlock(world, i + 1, j + 47, k + 18, Blocks.log, 1);
		/* 1139 */world.setBlockMetadataWithNotify(i + 1, j + 47, k + 18, 1, 2);
		/* 1140 */setBlock(world, i + 1, j + 47, k + 19, Blocks.log, 1);
		/* 1141 */world.setBlockMetadataWithNotify(i + 1, j + 47, k + 19, 1, 2);
		/* 1142 */setBlock(world, i + 1, j + 47, k + 20, Blocks.log, 1);
		/* 1143 */world.setBlockMetadataWithNotify(i + 1, j + 47, k + 20, 1, 2);
		/* 1144 */setBlock(world, i + 1, j + 47, k + 21, Blocks.log, 1);
		/* 1145 */world.setBlockMetadataWithNotify(i + 1, j + 47, k + 21, 1, 2);
		/* 1146 */setBlock(world, i + 1, j + 47, k + 22, Blocks.log, 1);
		/* 1147 */world.setBlockMetadataWithNotify(i + 1, j + 47, k + 22, 1, 2);
		/* 1148 */setBlock(world, i + 1, j + 47, k + 23, Blocks.log, 1);
		/* 1149 */world.setBlockMetadataWithNotify(i + 1, j + 47, k + 23, 1, 2);
		/* 1150 */setBlock(world, i + 1, j + 47, k + 24, Blocks.log, 1);
		/* 1151 */world.setBlockMetadataWithNotify(i + 1, j + 47, k + 24, 1, 2);
		/* 1152 */setBlock(world, i + 1, j + 47, k + 25, Blocks.log, 1);
		/* 1153 */world.setBlockMetadataWithNotify(i + 1, j + 47, k + 25, 1, 2);
		/* 1154 */setBlock(world, i + 1, j + 48, k + 8, Blocks.leaves, 15);
		/* 1155 */world.setBlockMetadataWithNotify(i + 1, j + 48, k + 8, 15, 2);
		/* 1156 */setBlock(world, i + 1, j + 48, k + 9, Blocks.leaves, 15);
		/* 1157 */world.setBlockMetadataWithNotify(i + 1, j + 48, k + 9, 15, 2);
		/* 1158 */setBlock(world, i + 1, j + 48, k + 10, Blocks.leaves, 15);
		/* 1159 */world.setBlockMetadataWithNotify(i + 1, j + 48, k + 10, 15, 2);
		/* 1160 */setBlock(world, i + 1, j + 48, k + 11, Blocks.leaves, 7);
		/* 1161 */world.setBlockMetadataWithNotify(i + 1, j + 48, k + 11, 7, 2);
		/* 1162 */setBlock(world, i + 1, j + 48, k + 12, Blocks.log, 1);
		/* 1163 */world.setBlockMetadataWithNotify(i + 1, j + 48, k + 12, 1, 2);
		/* 1164 */setBlock(world, i + 1, j + 48, k + 13, Blocks.log, 1);
		/* 1165 */world.setBlockMetadataWithNotify(i + 1, j + 48, k + 13, 1, 2);
		/* 1166 */setBlock(world, i + 1, j + 48, k + 14, Blocks.log, 1);
		/* 1167 */world.setBlockMetadataWithNotify(i + 1, j + 48, k + 14, 1, 2);
		/* 1168 */setBlock(world, i + 1, j + 48, k + 15, Blocks.log, 1);
		/* 1169 */world.setBlockMetadataWithNotify(i + 1, j + 48, k + 15, 1, 2);
		/* 1170 */setBlock(world, i + 1, j + 48, k + 16, Blocks.log, 1);
		/* 1171 */world.setBlockMetadataWithNotify(i + 1, j + 48, k + 16, 1, 2);
		/* 1172 */setBlock(world, i + 1, j + 48, k + 17, Blocks.log, 1);
		/* 1173 */world.setBlockMetadataWithNotify(i + 1, j + 48, k + 17, 1, 2);
		/* 1174 */setBlock(world, i + 1, j + 48, k + 18, Blocks.log, 1);
		/* 1175 */world.setBlockMetadataWithNotify(i + 1, j + 48, k + 18, 1, 2);
		/* 1176 */setBlock(world, i + 1, j + 48, k + 19, Blocks.log, 1);
		/* 1177 */world.setBlockMetadataWithNotify(i + 1, j + 48, k + 19, 1, 2);
		/* 1178 */setBlock(world, i + 1, j + 48, k + 20, Blocks.log, 1);
		/* 1179 */world.setBlockMetadataWithNotify(i + 1, j + 48, k + 20, 1, 2);
		/* 1180 */setBlock(world, i + 1, j + 48, k + 21, Blocks.log, 1);
		/* 1181 */world.setBlockMetadataWithNotify(i + 1, j + 48, k + 21, 1, 2);
		/* 1182 */setBlock(world, i + 1, j + 48, k + 22, Blocks.log, 1);
		/* 1183 */world.setBlockMetadataWithNotify(i + 1, j + 48, k + 22, 1, 2);
		/* 1184 */setBlock(world, i + 1, j + 48, k + 23, Blocks.log, 1);
		/* 1185 */world.setBlockMetadataWithNotify(i + 1, j + 48, k + 23, 1, 2);
		/* 1186 */setBlock(world, i + 1, j + 48, k + 24, Blocks.log, 1);
		/* 1187 */world.setBlockMetadataWithNotify(i + 1, j + 48, k + 24, 1, 2);
		/* 1188 */setBlock(world, i + 1, j + 49, k + 1, Blocks.leaves, 15);
		/* 1189 */world.setBlockMetadataWithNotify(i + 1, j + 49, k + 1, 15, 2);
		/* 1190 */setBlock(world, i + 1, j + 49, k + 2, Blocks.leaves, 7);
		/* 1191 */world.setBlockMetadataWithNotify(i + 1, j + 49, k + 2, 7, 2);
		/* 1192 */setBlock(world, i + 1, j + 49, k + 3, Blocks.leaves, 7);
		/* 1193 */world.setBlockMetadataWithNotify(i + 1, j + 49, k + 3, 7, 2);
		/* 1194 */setBlock(world, i + 1, j + 49, k + 9, Blocks.leaves, 7);
		/* 1195 */world.setBlockMetadataWithNotify(i + 1, j + 49, k + 9, 7, 2);
		/* 1196 */setBlock(world, i + 1, j + 49, k + 10, Blocks.leaves, 7);
		/* 1197 */world.setBlockMetadataWithNotify(i + 1, j + 49, k + 10, 7, 2);
		/* 1198 */setBlock(world, i + 1, j + 49, k + 11, Blocks.leaves, 7);
		/* 1199 */world.setBlockMetadataWithNotify(i + 1, j + 49, k + 11, 7, 2);
		/* 1200 */setBlock(world, i + 1, j + 49, k + 12, Blocks.leaves, 7);
		/* 1201 */world.setBlockMetadataWithNotify(i + 1, j + 49, k + 12, 7, 2);
		/* 1202 */setBlock(world, i + 1, j + 49, k + 13, Blocks.leaves, 7);
		/* 1203 */world.setBlockMetadataWithNotify(i + 1, j + 49, k + 13, 7, 2);
		/* 1204 */setBlock(world, i + 1, j + 49, k + 14, Blocks.leaves, 7);
		/* 1205 */world.setBlockMetadataWithNotify(i + 1, j + 49, k + 14, 7, 2);
		/* 1206 */setBlock(world, i + 1, j + 49, k + 15, Blocks.log, 1);
		/* 1207 */world.setBlockMetadataWithNotify(i + 1, j + 49, k + 15, 1, 2);
		/* 1208 */setBlock(world, i + 1, j + 49, k + 16, Blocks.log, 1);
		/* 1209 */world.setBlockMetadataWithNotify(i + 1, j + 49, k + 16, 1, 2);
		/* 1210 */setBlock(world, i + 1, j + 49, k + 17, Blocks.log, 1);
		/* 1211 */world.setBlockMetadataWithNotify(i + 1, j + 49, k + 17, 1, 2);
		/* 1212 */setBlock(world, i + 1, j + 49, k + 18, Blocks.log, 1);
		/* 1213 */world.setBlockMetadataWithNotify(i + 1, j + 49, k + 18, 1, 2);
		/* 1214 */setBlock(world, i + 1, j + 49, k + 19, Blocks.log, 1);
		/* 1215 */world.setBlockMetadataWithNotify(i + 1, j + 49, k + 19, 1, 2);
		/* 1216 */setBlock(world, i + 1, j + 49, k + 20, Blocks.log, 1);
		/* 1217 */world.setBlockMetadataWithNotify(i + 1, j + 49, k + 20, 1, 2);
		/* 1218 */setBlock(world, i + 1, j + 49, k + 21, Blocks.log, 1);
		/* 1219 */world.setBlockMetadataWithNotify(i + 1, j + 49, k + 21, 1, 2);
		/* 1220 */setBlock(world, i + 1, j + 50, k + 0, Blocks.leaves, 15);
		/* 1221 */world.setBlockMetadataWithNotify(i + 1, j + 50, k + 0, 15, 2);
		/* 1222 */setBlock(world, i + 1, j + 50, k + 1, Blocks.log, 3);
		/* 1223 */world.setBlockMetadataWithNotify(i + 1, j + 50, k + 1, 3, 2);
		/* 1224 */setBlock(world, i + 1, j + 50, k + 2, Blocks.leaves, 7);
		/* 1225 */world.setBlockMetadataWithNotify(i + 1, j + 50, k + 2, 7, 2);
		/* 1226 */setBlock(world, i + 1, j + 50, k + 3, Blocks.leaves, 7);
		/* 1227 */world.setBlockMetadataWithNotify(i + 1, j + 50, k + 3, 7, 2);
		/* 1228 */setBlock(world, i + 1, j + 50, k + 10, Blocks.leaves, 7);
		/* 1229 */world.setBlockMetadataWithNotify(i + 1, j + 50, k + 10, 7, 2);
		/* 1230 */setBlock(world, i + 1, j + 50, k + 11, Blocks.leaves, 7);
		/* 1231 */world.setBlockMetadataWithNotify(i + 1, j + 50, k + 11, 7, 2);
		/* 1232 */setBlock(world, i + 1, j + 50, k + 12, Blocks.leaves, 7);
		/* 1233 */world.setBlockMetadataWithNotify(i + 1, j + 50, k + 12, 7, 2);
		/* 1234 */setBlock(world, i + 1, j + 50, k + 13, Blocks.leaves, 7);
		/* 1235 */world.setBlockMetadataWithNotify(i + 1, j + 50, k + 13, 7, 2);
		/* 1236 */setBlock(world, i + 1, j + 51, k + 0, Blocks.leaves, 7);
		/* 1237 */world.setBlockMetadataWithNotify(i + 1, j + 51, k + 0, 7, 2);
		/* 1238 */setBlock(world, i + 1, j + 51, k + 1, Blocks.leaves, 7);
		/* 1239 */world.setBlockMetadataWithNotify(i + 1, j + 51, k + 1, 7, 2);
		/* 1240 */setBlock(world, i + 1, j + 51, k + 2, Blocks.leaves, 7);
		/* 1241 */world.setBlockMetadataWithNotify(i + 1, j + 51, k + 2, 7, 2);
		/* 1242 */setBlock(world, i + 1, j + 51, k + 3, Blocks.leaves, 7);
		/* 1243 */world.setBlockMetadataWithNotify(i + 1, j + 51, k + 3, 7, 2);
		/* 1244 */setBlock(world, i + 1, j + 51, k + 4, Blocks.leaves, 7);
		/* 1245 */world.setBlockMetadataWithNotify(i + 1, j + 51, k + 4, 7, 2);
		/* 1246 */setBlock(world, i + 1, j + 51, k + 12, Blocks.leaves, 7);
		/* 1247 */world.setBlockMetadataWithNotify(i + 1, j + 51, k + 12, 7, 2);
		/* 1248 */setBlock(world, i + 1, j + 52, k + 0, Blocks.leaves, 7);
		/* 1249 */world.setBlockMetadataWithNotify(i + 1, j + 52, k + 0, 7, 2);
		/* 1250 */setBlock(world, i + 1, j + 52, k + 1, Blocks.leaves, 7);
		/* 1251 */world.setBlockMetadataWithNotify(i + 1, j + 52, k + 1, 7, 2);
		/* 1252 */setBlock(world, i + 1, j + 52, k + 2, Blocks.leaves, 7);
		/* 1253 */world.setBlockMetadataWithNotify(i + 1, j + 52, k + 2, 7, 2);
		/* 1254 */setBlock(world, i + 1, j + 52, k + 3, Blocks.leaves, 7);
		/* 1255 */world.setBlockMetadataWithNotify(i + 1, j + 52, k + 3, 7, 2);
		/* 1256 */setBlock(world, i + 1, j + 53, k + 1, Blocks.leaves, 7);
		/* 1257 */world.setBlockMetadataWithNotify(i + 1, j + 53, k + 1, 7, 2);
		/* 1258 */setBlock(world, i + 1, j + 54, k + 2, Blocks.leaves, 7);
		/* 1259 */world.setBlockMetadataWithNotify(i + 1, j + 54, k + 2, 7, 2);
		/* 1260 */setBlock(world, i + 1, j + 54, k + 3, Blocks.leaves, 7);
		/* 1261 */world.setBlockMetadataWithNotify(i + 1, j + 54, k + 3, 7, 2);
		/* 1262 */setBlock(world, i + 1, j + 54, k + 4, Blocks.leaves, 7);
		/* 1263 */world.setBlockMetadataWithNotify(i + 1, j + 54, k + 4, 7, 2);
		/* 1264 */setBlock(world, i + 1, j + 55, k + 3, Blocks.leaves, 7);
		/* 1265 */world.setBlockMetadataWithNotify(i + 1, j + 55, k + 3, 7, 2);
		/* 1266 */setBlock(world, i + 1, j + 57, k + 8, Blocks.leaves, 7);
		/* 1267 */world.setBlockMetadataWithNotify(i + 1, j + 57, k + 8, 7, 2);
		/* 1268 */setBlock(world, i + 1, j + 57, k + 9, Blocks.leaves, 7);
		/* 1269 */world.setBlockMetadataWithNotify(i + 1, j + 57, k + 9, 7, 2);
		/* 1270 */setBlock(world, i + 1, j + 57, k + 10, Blocks.leaves, 7);
		/* 1271 */world.setBlockMetadataWithNotify(i + 1, j + 57, k + 10, 7, 2);
		/* 1272 */setBlock(world, i + 1, j + 57, k + 11, Blocks.leaves, 7);
		/* 1273 */world.setBlockMetadataWithNotify(i + 1, j + 57, k + 11, 7, 2);
		/* 1274 */setBlock(world, i + 1, j + 57, k + 12, Blocks.leaves, 7);
		/* 1275 */world.setBlockMetadataWithNotify(i + 1, j + 57, k + 12, 7, 2);
		/* 1276 */setBlock(world, i + 1, j + 58, k + 9, Blocks.leaves, 7);
		/* 1277 */world.setBlockMetadataWithNotify(i + 1, j + 58, k + 9, 7, 2);
		/* 1278 */setBlock(world, i + 1, j + 58, k + 10, Blocks.leaves, 7);
		/* 1279 */world.setBlockMetadataWithNotify(i + 1, j + 58, k + 10, 7, 2);
		/* 1280 */setBlock(world, i + 1, j + 58, k + 11, Blocks.leaves, 7);
		/* 1281 */world.setBlockMetadataWithNotify(i + 1, j + 58, k + 11, 7, 2);
		/* 1282 */setBlock(world, i + 1, j + 59, k + 10, Blocks.leaves, 7);
		/* 1283 */world.setBlockMetadataWithNotify(i + 1, j + 59, k + 10, 7, 2);
		/* 1284 */setBlock(world, i + 2, j + 22, k + 4, Blocks.log, 3);
		/* 1285 */world.setBlockMetadataWithNotify(i + 2, j + 22, k + 4, 3, 2);
		/* 1286 */setBlock(world, i + 2, j + 23, k + 12, Blocks.log, 3);
		/* 1287 */world.setBlockMetadataWithNotify(i + 2, j + 23, k + 12, 3, 2);
		/* 1288 */setBlock(world, i + 2, j + 23, k + 21, Blocks.log, 3);
		/* 1289 */world.setBlockMetadataWithNotify(i + 2, j + 23, k + 21, 3, 2);
		/* 1290 */setBlock(world, i + 2, j + 24, k + 3, Blocks.log, 3);
		/* 1291 */world.setBlockMetadataWithNotify(i + 2, j + 24, k + 3, 3, 2);
		/* 1292 */setBlock(world, i + 2, j + 24, k + 7, Blocks.leaves, 7);
		/* 1293 */world.setBlockMetadataWithNotify(i + 2, j + 24, k + 7, 7, 2);
		/* 1294 */setBlock(world, i + 2, j + 24, k + 8, Blocks.leaves, 7);
		/* 1295 */world.setBlockMetadataWithNotify(i + 2, j + 24, k + 8, 7, 2);
		/* 1296 */setBlock(world, i + 2, j + 24, k + 9, Blocks.leaves, 7);
		/* 1297 */world.setBlockMetadataWithNotify(i + 2, j + 24, k + 9, 7, 2);
		/* 1298 */setBlock(world, i + 2, j + 24, k + 16, Blocks.log, 3);
		/* 1299 */world.setBlockMetadataWithNotify(i + 2, j + 24, k + 16, 3, 2);
		/* 1300 */setBlock(world, i + 2, j + 24, k + 17, Blocks.log, 3);
		/* 1301 */world.setBlockMetadataWithNotify(i + 2, j + 24, k + 17, 3, 2);
		/* 1302 */setBlock(world, i + 2, j + 24, k + 18, Blocks.log, 3);
		/* 1303 */world.setBlockMetadataWithNotify(i + 2, j + 24, k + 18, 3, 2);
		/* 1304 */setBlock(world, i + 2, j + 24, k + 20, Blocks.leaves, 7);
		/* 1305 */world.setBlockMetadataWithNotify(i + 2, j + 24, k + 20, 7, 2);
		/* 1306 */setBlock(world, i + 2, j + 24, k + 21, Blocks.leaves, 7);
		/* 1307 */world.setBlockMetadataWithNotify(i + 2, j + 24, k + 21, 7, 2);
		/* 1308 */setBlock(world, i + 2, j + 24, k + 22, Blocks.leaves, 7);
		/* 1309 */world.setBlockMetadataWithNotify(i + 2, j + 24, k + 22, 7, 2);
		/* 1310 */setBlock(world, i + 2, j + 24, k + 23, Blocks.leaves, 7);
		/* 1311 */world.setBlockMetadataWithNotify(i + 2, j + 24, k + 23, 7, 2);
		/* 1312 */setBlock(world, i + 2, j + 24, k + 24, Blocks.leaves, 7);
		/* 1313 */world.setBlockMetadataWithNotify(i + 2, j + 24, k + 24, 7, 2);
		/* 1314 */setBlock(world, i + 2, j + 25, k + 8, Blocks.leaves, 7);
		/* 1315 */world.setBlockMetadataWithNotify(i + 2, j + 25, k + 8, 7, 2);
		/* 1316 */setBlock(world, i + 2, j + 25, k + 11, Blocks.log, 3);
		/* 1317 */world.setBlockMetadataWithNotify(i + 2, j + 25, k + 11, 3, 2);
		/* 1318 */setBlock(world, i + 2, j + 25, k + 21, Blocks.log, 3);
		/* 1319 */world.setBlockMetadataWithNotify(i + 2, j + 25, k + 21, 3, 2);
		/* 1320 */setBlock(world, i + 2, j + 25, k + 22, Blocks.leaves, 7);
		/* 1321 */world.setBlockMetadataWithNotify(i + 2, j + 25, k + 22, 7, 2);
		/* 1322 */setBlock(world, i + 2, j + 25, k + 23, Blocks.leaves, 7);
		/* 1323 */world.setBlockMetadataWithNotify(i + 2, j + 25, k + 23, 7, 2);
		/* 1324 */setBlock(world, i + 2, j + 26, k + 22, Blocks.leaves, 7);
		/* 1325 */world.setBlockMetadataWithNotify(i + 2, j + 26, k + 22, 7, 2);
		/* 1326 */setBlock(world, i + 2, j + 28, k + 2, Blocks.log, 3);
		/* 1327 */world.setBlockMetadataWithNotify(i + 2, j + 28, k + 2, 3, 2);
		/* 1328 */setBlock(world, i + 2, j + 31, k + 21, Blocks.log, 3);
		/* 1329 */world.setBlockMetadataWithNotify(i + 2, j + 31, k + 21, 3, 2);
		/* 1330 */setBlock(world, i + 2, j + 32, k + 7, Blocks.log, 3);
		/* 1331 */world.setBlockMetadataWithNotify(i + 2, j + 32, k + 7, 3, 2);
		/* 1332 */setBlock(world, i + 2, j + 32, k + 16, Blocks.log, 3);
		/* 1333 */world.setBlockMetadataWithNotify(i + 2, j + 32, k + 16, 3, 2);
		/* 1334 */setBlock(world, i + 2, j + 32, k + 20, Blocks.leaves, 7);
		/* 1335 */world.setBlockMetadataWithNotify(i + 2, j + 32, k + 20, 7, 2);
		/* 1336 */setBlock(world, i + 2, j + 32, k + 21, Blocks.log, 1);
		/* 1337 */world.setBlockMetadataWithNotify(i + 2, j + 32, k + 21, 1, 2);
		/* 1338 */setBlock(world, i + 2, j + 32, k + 22, Blocks.log, 1);
		/* 1339 */world.setBlockMetadataWithNotify(i + 2, j + 32, k + 22, 1, 2);
		/* 1340 */setBlock(world, i + 2, j + 32, k + 23, Blocks.leaves, 7);
		/* 1341 */world.setBlockMetadataWithNotify(i + 2, j + 32, k + 23, 7, 2);
		/* 1342 */setBlock(world, i + 2, j + 32, k + 24, Blocks.leaves, 7);
		/* 1343 */world.setBlockMetadataWithNotify(i + 2, j + 32, k + 24, 7, 2);
		/* 1344 */setBlock(world, i + 2, j + 33, k + 14, Blocks.leaves, 7);
		/* 1345 */world.setBlockMetadataWithNotify(i + 2, j + 33, k + 14, 7, 2);
		/* 1346 */setBlock(world, i + 2, j + 33, k + 15, Blocks.leaves, 7);
		/* 1347 */world.setBlockMetadataWithNotify(i + 2, j + 33, k + 15, 7, 2);
		/* 1348 */setBlock(world, i + 2, j + 33, k + 16, Blocks.leaves, 7);
		/* 1349 */world.setBlockMetadataWithNotify(i + 2, j + 33, k + 16, 7, 2);
		/* 1350 */setBlock(world, i + 2, j + 33, k + 17, Blocks.leaves, 7);
		/* 1351 */world.setBlockMetadataWithNotify(i + 2, j + 33, k + 17, 7, 2);
		/* 1352 */setBlock(world, i + 2, j + 33, k + 18, Blocks.leaves, 7);
		/* 1353 */world.setBlockMetadataWithNotify(i + 2, j + 33, k + 18, 7, 2);
		/* 1354 */setBlock(world, i + 2, j + 33, k + 21, Blocks.log, 1);
		/* 1355 */world.setBlockMetadataWithNotify(i + 2, j + 33, k + 21, 1, 2);
		/* 1356 */setBlock(world, i + 2, j + 33, k + 22, Blocks.log, 1);
		/* 1357 */world.setBlockMetadataWithNotify(i + 2, j + 33, k + 22, 1, 2);
		/* 1358 */setBlock(world, i + 2, j + 33, k + 23, Blocks.log, 1);
		/* 1359 */world.setBlockMetadataWithNotify(i + 2, j + 33, k + 23, 1, 2);
		/* 1360 */setBlock(world, i + 2, j + 34, k + 11, Blocks.leaves, 7);
		/* 1361 */world.setBlockMetadataWithNotify(i + 2, j + 34, k + 11, 7, 2);
		/* 1362 */setBlock(world, i + 2, j + 34, k + 12, Blocks.leaves, 7);
		/* 1363 */world.setBlockMetadataWithNotify(i + 2, j + 34, k + 12, 7, 2);
		/* 1364 */setBlock(world, i + 2, j + 34, k + 13, Blocks.log, 3);
		/* 1365 */world.setBlockMetadataWithNotify(i + 2, j + 34, k + 13, 3, 2);
		/* 1366 */setBlock(world, i + 2, j + 34, k + 14, Blocks.leaves, 7);
		/* 1367 */world.setBlockMetadataWithNotify(i + 2, j + 34, k + 14, 7, 2);
		/* 1368 */setBlock(world, i + 2, j + 34, k + 15, Blocks.leaves, 7);
		/* 1369 */world.setBlockMetadataWithNotify(i + 2, j + 34, k + 15, 7, 2);
		/* 1370 */setBlock(world, i + 2, j + 34, k + 16, Blocks.leaves, 7);
		/* 1371 */world.setBlockMetadataWithNotify(i + 2, j + 34, k + 16, 7, 2);
		/* 1372 */setBlock(world, i + 2, j + 34, k + 17, Blocks.leaves, 7);
		/* 1373 */world.setBlockMetadataWithNotify(i + 2, j + 34, k + 17, 7, 2);
		/* 1374 */setBlock(world, i + 2, j + 34, k + 21, Blocks.log, 1);
		/* 1375 */world.setBlockMetadataWithNotify(i + 2, j + 34, k + 21, 1, 2);
		/* 1376 */setBlock(world, i + 2, j + 34, k + 22, Blocks.log, 1);
		/* 1377 */world.setBlockMetadataWithNotify(i + 2, j + 34, k + 22, 1, 2);
		/* 1378 */setBlock(world, i + 2, j + 34, k + 23, Blocks.log, 1);
		/* 1379 */world.setBlockMetadataWithNotify(i + 2, j + 34, k + 23, 1, 2);
		/* 1380 */setBlock(world, i + 2, j + 35, k + 11, Blocks.leaves, 7);
		/* 1381 */world.setBlockMetadataWithNotify(i + 2, j + 35, k + 11, 7, 2);
		/* 1382 */setBlock(world, i + 2, j + 35, k + 12, Blocks.leaves, 7);
		/* 1383 */world.setBlockMetadataWithNotify(i + 2, j + 35, k + 12, 7, 2);
		/* 1384 */setBlock(world, i + 2, j + 35, k + 13, Blocks.leaves, 7);
		/* 1385 */world.setBlockMetadataWithNotify(i + 2, j + 35, k + 13, 7, 2);
		/* 1386 */setBlock(world, i + 2, j + 35, k + 14, Blocks.leaves, 7);
		/* 1387 */world.setBlockMetadataWithNotify(i + 2, j + 35, k + 14, 7, 2);
		/* 1388 */setBlock(world, i + 2, j + 35, k + 15, Blocks.leaves, 7);
		/* 1389 */world.setBlockMetadataWithNotify(i + 2, j + 35, k + 15, 7, 2);
		/* 1390 */setBlock(world, i + 2, j + 35, k + 16, Blocks.leaves, 7);
		/* 1391 */world.setBlockMetadataWithNotify(i + 2, j + 35, k + 16, 7, 2);
		/* 1392 */setBlock(world, i + 2, j + 35, k + 18, Blocks.log, 1);
		/* 1393 */world.setBlockMetadataWithNotify(i + 2, j + 35, k + 18, 1, 2);
		/* 1394 */setBlock(world, i + 2, j + 35, k + 19, Blocks.log, 1);
		/* 1395 */world.setBlockMetadataWithNotify(i + 2, j + 35, k + 19, 1, 2);
		/* 1396 */setBlock(world, i + 2, j + 35, k + 20, Blocks.log, 1);
		/* 1397 */world.setBlockMetadataWithNotify(i + 2, j + 35, k + 20, 1, 2);
		/* 1398 */setBlock(world, i + 2, j + 35, k + 21, Blocks.log, 1);
		/* 1399 */world.setBlockMetadataWithNotify(i + 2, j + 35, k + 21, 1, 2);
		/* 1400 */setBlock(world, i + 2, j + 35, k + 22, Blocks.log, 1);
		/* 1401 */world.setBlockMetadataWithNotify(i + 2, j + 35, k + 22, 1, 2);
		/* 1402 */setBlock(world, i + 2, j + 36, k + 12, Blocks.leaves, 15);
		/* 1403 */world.setBlockMetadataWithNotify(i + 2, j + 36, k + 12, 15, 2);
		/* 1404 */setBlock(world, i + 2, j + 36, k + 13, Blocks.leaves, 15);
		/* 1405 */world.setBlockMetadataWithNotify(i + 2, j + 36, k + 13, 15, 2);
		/* 1406 */setBlock(world, i + 2, j + 36, k + 14, Blocks.leaves, 15);
		/* 1407 */world.setBlockMetadataWithNotify(i + 2, j + 36, k + 14, 15, 2);
		/* 1408 */setBlock(world, i + 2, j + 36, k + 18, Blocks.log, 1);
		/* 1409 */world.setBlockMetadataWithNotify(i + 2, j + 36, k + 18, 1, 2);
		/* 1410 */setBlock(world, i + 2, j + 36, k + 19, Blocks.log, 1);
		/* 1411 */world.setBlockMetadataWithNotify(i + 2, j + 36, k + 19, 1, 2);
		/* 1412 */setBlock(world, i + 2, j + 36, k + 20, Blocks.log, 1);
		/* 1413 */world.setBlockMetadataWithNotify(i + 2, j + 36, k + 20, 1, 2);
		/* 1414 */setBlock(world, i + 2, j + 36, k + 21, Blocks.log, 1);
		/* 1415 */world.setBlockMetadataWithNotify(i + 2, j + 36, k + 21, 1, 2);
		/* 1416 */setBlock(world, i + 2, j + 36, k + 28, Blocks.vine, 5);
		/* 1417 */world.setBlockMetadataWithNotify(i + 2, j + 36, k + 28, 5, 2);
		/* 1418 */setBlock(world, i + 2, j + 37, k + 13, Blocks.leaves, 15);
		/* 1419 */world.setBlockMetadataWithNotify(i + 2, j + 37, k + 13, 15, 2);
		/* 1420 */setBlock(world, i + 2, j + 37, k + 16, Blocks.leaves, 15);
		/* 1421 */world.setBlockMetadataWithNotify(i + 2, j + 37, k + 16, 15, 2);
		/* 1422 */setBlock(world, i + 2, j + 37, k + 17, Blocks.leaves, 15);
		/* 1423 */world.setBlockMetadataWithNotify(i + 2, j + 37, k + 17, 15, 2);
		/* 1424 */setBlock(world, i + 2, j + 37, k + 18, Blocks.log, 1);
		/* 1425 */world.setBlockMetadataWithNotify(i + 2, j + 37, k + 18, 1, 2);
		/* 1426 */setBlock(world, i + 2, j + 37, k + 19, Blocks.log, 1);
		/* 1427 */world.setBlockMetadataWithNotify(i + 2, j + 37, k + 19, 1, 2);
		/* 1428 */setBlock(world, i + 2, j + 37, k + 20, Blocks.log, 1);
		/* 1429 */world.setBlockMetadataWithNotify(i + 2, j + 37, k + 20, 1, 2);
		/* 1430 */setBlock(world, i + 2, j + 37, k + 21, Blocks.log, 1);
		/* 1431 */world.setBlockMetadataWithNotify(i + 2, j + 37, k + 21, 1, 2);
		/* 1432 */setBlock(world, i + 2, j + 37, k + 28, Blocks.vine, 13);
		/* 1433 */world.setBlockMetadataWithNotify(i + 2, j + 37, k + 28, 13, 2);
		/* 1434 */setBlock(world, i + 2, j + 38, k + 7, Blocks.leaves, 15);
		/* 1435 */world.setBlockMetadataWithNotify(i + 2, j + 38, k + 7, 15, 2);
		/* 1436 */setBlock(world, i + 2, j + 38, k + 8, Blocks.leaves, 15);
		/* 1437 */world.setBlockMetadataWithNotify(i + 2, j + 38, k + 8, 15, 2);
		/* 1438 */setBlock(world, i + 2, j + 38, k + 9, Blocks.leaves, 15);
		/* 1439 */world.setBlockMetadataWithNotify(i + 2, j + 38, k + 9, 15, 2);
		/* 1440 */setBlock(world, i + 2, j + 38, k + 10, Blocks.log, 3);
		/* 1441 */world.setBlockMetadataWithNotify(i + 2, j + 38, k + 10, 3, 2);
		/* 1442 */setBlock(world, i + 2, j + 38, k + 16, Blocks.leaves, 15);
		/* 1443 */world.setBlockMetadataWithNotify(i + 2, j + 38, k + 16, 15, 2);
		/* 1444 */setBlock(world, i + 2, j + 38, k + 17, Blocks.log, 1);
		/* 1445 */world.setBlockMetadataWithNotify(i + 2, j + 38, k + 17, 1, 2);
		/* 1446 */setBlock(world, i + 2, j + 38, k + 18, Blocks.log, 1);
		/* 1447 */world.setBlockMetadataWithNotify(i + 2, j + 38, k + 18, 1, 2);
		/* 1448 */setBlock(world, i + 2, j + 38, k + 19, Blocks.log, 1);
		/* 1449 */world.setBlockMetadataWithNotify(i + 2, j + 38, k + 19, 1, 2);
		/* 1450 */setBlock(world, i + 2, j + 38, k + 20, Blocks.log, 1);
		/* 1451 */world.setBlockMetadataWithNotify(i + 2, j + 38, k + 20, 1, 2);
		/* 1452 */setBlock(world, i + 2, j + 38, k + 21, Blocks.log, 1);
		/* 1453 */world.setBlockMetadataWithNotify(i + 2, j + 38, k + 21, 1, 2);
		/* 1454 */setBlock(world, i + 2, j + 38, k + 22, Blocks.log, 1);
		/* 1455 */world.setBlockMetadataWithNotify(i + 2, j + 38, k + 22, 1, 2);
		/* 1456 */setBlock(world, i + 2, j + 38, k + 23, Blocks.vine, 13);
		/* 1457 */world.setBlockMetadataWithNotify(i + 2, j + 38, k + 23, 13, 2);
		/* 1458 */setBlock(world, i + 2, j + 38, k + 24, Blocks.vine, 13);
		/* 1459 */world.setBlockMetadataWithNotify(i + 2, j + 38, k + 24, 13, 2);
		/* 1460 */setBlock(world, i + 2, j + 38, k + 25, Blocks.vine, 5);
		/* 1461 */world.setBlockMetadataWithNotify(i + 2, j + 38, k + 25, 5, 2);
		/* 1462 */setBlock(world, i + 2, j + 38, k + 28, Blocks.vine, 15);
		/* 1463 */world.setBlockMetadataWithNotify(i + 2, j + 38, k + 28, 15, 2);
		/* 1464 */setBlock(world, i + 2, j + 39, k + 17, Blocks.leaves, 15);
		/* 1465 */world.setBlockMetadataWithNotify(i + 2, j + 39, k + 17, 15, 2);
		/* 1466 */setBlock(world, i + 2, j + 39, k + 18, Blocks.log, 1);
		/* 1467 */world.setBlockMetadataWithNotify(i + 2, j + 39, k + 18, 1, 2);
		/* 1468 */setBlock(world, i + 2, j + 39, k + 19, Blocks.log, 1);
		/* 1469 */world.setBlockMetadataWithNotify(i + 2, j + 39, k + 19, 1, 2);
		/* 1470 */setBlock(world, i + 2, j + 39, k + 20, Blocks.log, 1);
		/* 1471 */world.setBlockMetadataWithNotify(i + 2, j + 39, k + 20, 1, 2);
		/* 1472 */setBlock(world, i + 2, j + 39, k + 21, Blocks.log, 1);
		/* 1473 */world.setBlockMetadataWithNotify(i + 2, j + 39, k + 21, 1, 2);
		/* 1474 */setBlock(world, i + 2, j + 39, k + 22, Blocks.log, 1);
		/* 1475 */world.setBlockMetadataWithNotify(i + 2, j + 39, k + 22, 1, 2);
		/* 1476 */setBlock(world, i + 2, j + 39, k + 23, Blocks.vine, 15);
		/* 1477 */world.setBlockMetadataWithNotify(i + 2, j + 39, k + 23, 15, 2);
		/* 1478 */setBlock(world, i + 2, j + 39, k + 24, Blocks.vine, 15);
		/* 1479 */world.setBlockMetadataWithNotify(i + 2, j + 39, k + 24, 15, 2);
		/* 1480 */setBlock(world, i + 2, j + 39, k + 25, Blocks.vine, 15);
		/* 1481 */world.setBlockMetadataWithNotify(i + 2, j + 39, k + 25, 15, 2);
		/* 1482 */setBlock(world, i + 2, j + 39, k + 26, Blocks.vine, 15);
		/* 1483 */world.setBlockMetadataWithNotify(i + 2, j + 39, k + 26, 15, 2);
		/* 1484 */setBlock(world, i + 2, j + 39, k + 27, Blocks.vine, 15);
		/* 1485 */world.setBlockMetadataWithNotify(i + 2, j + 39, k + 27, 15, 2);
		/* 1486 */setBlock(world, i + 2, j + 39, k + 28, Blocks.vine, 15);
		/* 1487 */world.setBlockMetadataWithNotify(i + 2, j + 39, k + 28, 15, 2);
		/* 1488 */setBlock(world, i + 2, j + 40, k + 0, Blocks.planks, 5);
		/* 1489 */world.setBlockMetadataWithNotify(i + 2, j + 40, k + 0, 5, 2);
		/* 1490 */setBlock(world, i + 2, j + 40, k + 1, Blocks.planks, 5);
		/* 1491 */world.setBlockMetadataWithNotify(i + 2, j + 40, k + 1, 5, 2);
		/* 1492 */setBlock(world, i + 2, j + 40, k + 2, Blocks.planks, 5);
		/* 1493 */world.setBlockMetadataWithNotify(i + 2, j + 40, k + 2, 5, 2);
		/* 1494 */setBlock(world, i + 2, j + 40, k + 3, Blocks.planks, 5);
		/* 1495 */world.setBlockMetadataWithNotify(i + 2, j + 40, k + 3, 5, 2);
		/* 1496 */setBlock(world, i + 2, j + 40, k + 4, Blocks.planks, 5);
		/* 1497 */world.setBlockMetadataWithNotify(i + 2, j + 40, k + 4, 5, 2);
		/* 1498 */setBlock(world, i + 2, j + 40, k + 5, Blocks.planks, 5);
		/* 1499 */world.setBlockMetadataWithNotify(i + 2, j + 40, k + 5, 5, 2);
		/* 1500 */setBlock(world, i + 2, j + 40, k + 6, Blocks.planks, 5);
		/* 1501 */world.setBlockMetadataWithNotify(i + 2, j + 40, k + 6, 5, 2);
		/* 1502 */setBlock(world, i + 2, j + 40, k + 7, Blocks.planks, 5);
		/* 1503 */world.setBlockMetadataWithNotify(i + 2, j + 40, k + 7, 5, 2);
		/* 1504 */setBlock(world, i + 2, j + 40, k + 8, Blocks.planks, 5);
		/* 1505 */world.setBlockMetadataWithNotify(i + 2, j + 40, k + 8, 5, 2);
		/* 1506 */setBlock(world, i + 2, j + 40, k + 9, Blocks.planks, 5);
		/* 1507 */world.setBlockMetadataWithNotify(i + 2, j + 40, k + 9, 5, 2);
		/* 1508 */setBlock(world, i + 2, j + 40, k + 10, Blocks.planks, 5);
		/* 1509 */world.setBlockMetadataWithNotify(i + 2, j + 40, k + 10, 5, 2);
		/* 1510 */setBlock(world, i + 2, j + 40, k + 11, Blocks.planks, 5);
		/* 1511 */world.setBlockMetadataWithNotify(i + 2, j + 40, k + 11, 5, 2);
		/* 1512 */setBlock(world, i + 2, j + 40, k + 12, Blocks.log, 1);
		/* 1513 */world.setBlockMetadataWithNotify(i + 2, j + 40, k + 12, 1, 2);
		/* 1514 */setBlock(world, i + 2, j + 40, k + 13, Blocks.planks, 5);
		/* 1515 */world.setBlockMetadataWithNotify(i + 2, j + 40, k + 13, 5, 2);
		/* 1516 */setBlock(world, i + 2, j + 40, k + 14, Blocks.planks, 5);
		/* 1517 */world.setBlockMetadataWithNotify(i + 2, j + 40, k + 14, 5, 2);
		/* 1518 */setBlock(world, i + 2, j + 40, k + 15, Blocks.log, 1);
		/* 1519 */world.setBlockMetadataWithNotify(i + 2, j + 40, k + 15, 1, 2);
		/* 1520 */setBlock(world, i + 2, j + 40, k + 16, Blocks.planks, 5);
		/* 1521 */world.setBlockMetadataWithNotify(i + 2, j + 40, k + 16, 5, 2);
		/* 1522 */setBlock(world, i + 2, j + 40, k + 17, Blocks.planks, 5);
		/* 1523 */world.setBlockMetadataWithNotify(i + 2, j + 40, k + 17, 5, 2);
		/* 1524 */setBlock(world, i + 2, j + 40, k + 18, Blocks.log, 1);
		/* 1525 */world.setBlockMetadataWithNotify(i + 2, j + 40, k + 18, 1, 2);
		/* 1526 */setBlock(world, i + 2, j + 40, k + 19, Blocks.planks, 5);
		/* 1527 */world.setBlockMetadataWithNotify(i + 2, j + 40, k + 19, 5, 2);
		/* 1528 */setBlock(world, i + 2, j + 40, k + 20, Blocks.planks, 5);
		/* 1529 */world.setBlockMetadataWithNotify(i + 2, j + 40, k + 20, 5, 2);
		/* 1530 */setBlock(world, i + 2, j + 40, k + 21, Blocks.log, 1);
		/* 1531 */world.setBlockMetadataWithNotify(i + 2, j + 40, k + 21, 1, 2);
		/* 1532 */setBlock(world, i + 2, j + 40, k + 22, Blocks.planks, 5);
		/* 1533 */world.setBlockMetadataWithNotify(i + 2, j + 40, k + 22, 5, 2);
		/* 1534 */setBlock(world, i + 2, j + 40, k + 23, Blocks.planks, 5);
		/* 1535 */world.setBlockMetadataWithNotify(i + 2, j + 40, k + 23, 5, 2);
		/* 1536 */setBlock(world, i + 2, j + 40, k + 24, Blocks.log, 1);
		/* 1537 */world.setBlockMetadataWithNotify(i + 2, j + 40, k + 24, 1, 2);
		/* 1538 */setBlock(world, i + 2, j + 40, k + 25, Blocks.planks, 5);
		/* 1539 */world.setBlockMetadataWithNotify(i + 2, j + 40, k + 25, 5, 2);
		/* 1540 */setBlock(world, i + 2, j + 40, k + 26, Blocks.planks, 5);
		/* 1541 */world.setBlockMetadataWithNotify(i + 2, j + 40, k + 26, 5, 2);
		/* 1542 */setBlock(world, i + 2, j + 40, k + 27, Blocks.planks, 5);
		/* 1543 */world.setBlockMetadataWithNotify(i + 2, j + 40, k + 27, 5, 2);
		/* 1544 */setBlock(world, i + 2, j + 40, k + 28, Blocks.planks, 5);
		/* 1545 */world.setBlockMetadataWithNotify(i + 2, j + 40, k + 28, 5, 2);
		/* 1546 */setBlock(world, i + 2, j + 40, k + 29, Blocks.planks, 5);
		/* 1547 */world.setBlockMetadataWithNotify(i + 2, j + 40, k + 29, 5, 2);
		/* 1548 */setBlock(world, i + 2, j + 40, k + 30, Blocks.planks, 5);
		/* 1549 */world.setBlockMetadataWithNotify(i + 2, j + 40, k + 30, 5, 2);
		/* 1550 */setBlock(world, i + 2, j + 40, k + 31, Blocks.planks, 5);
		/* 1551 */world.setBlockMetadataWithNotify(i + 2, j + 40, k + 31, 5, 2);
		/* 1552 */setBlock(world, i + 2, j + 41, k + 17, Blocks.chest, 2);
		/* 1553 */LootGenUtils.fillLootChest(world.provider.dimensionId, world.rand, (TileEntityChest)world.getTileEntity(i + 2, j + 41, k + 17));
		/* 1554 */world.setBlockMetadataWithNotify(i + 2, j + 41, k + 17, 2, 2);
		/* 1555 */setBlock(world, i + 2, j + 41, k + 18, Blocks.spruce_stairs, 1);
		/* 1556 */world.setBlockMetadataWithNotify(i + 2, j + 41, k + 18, 1, 2);
		/* 1557 */setBlock(world, i + 2, j + 41, k + 19, Blocks.furnace, 3);
		/* 1558 */world.setBlockMetadataWithNotify(i + 2, j + 41, k + 19, 3, 2);
		/* 1559 */setBlock(world, i + 2, j + 43, k + 10, Blocks.torch, 2);
