/*      */package com.parzivail.pswm.world.gen.wookietree;

/*      */
/*      *//*      */
/*      */
import com.parzivail.pswm.utils.LootGenUtils;
import com.parzivail.pswm.utils.NPCType;
import com.parzivail.pswm.utils.SpawnUtils;


/*      */
import cpw.mods.fml.common.IWorldGenerator;


/*      */
import java.util.Random;


/*      */
import net.minecraft.block.Block;
/*      */
import net.minecraft.init.Blocks;
/*      */
import net.minecraft.tileentity.TileEntityChest;
/*      */
import net.minecraft.world.World;
/*      */
import net.minecraft.world.WorldProvider;
/*      */
import net.minecraft.world.chunk.IChunkProvider;
/*      */
import net.minecraft.world.gen.feature.WorldGenerator;

/*      */
/*      */public class WT_22
/*      */extends WorldGenerator implements IWorldGenerator
/*      */
{
	/*      */protected Block[] getValidSpawnBlocks()
	/*      */
	{
		return new Block[0];
		/*      */}

	/*      */
	/*      */public boolean locationIsValidSpawn(World world, int i, int j, int k)
	/*      */
	{
		int distanceToAir = 0;
		Block check = world.getBlock(i, j, k);
		/*      */
		while (check != Blocks.air)
		{
			if (distanceToAir > 3) { return false;
			/*      */}
			/*      */
			distanceToAir++;
			check = world.getBlock(i, j + distanceToAir, k);
			/*      */}
		/*      */
		j += distanceToAir - 1;
		/*      */
		Block block = world.getBlock(i, j, k);
		Block blockAbove = world.getBlock(i, j + 1, k);
		Block blockBelow = world.getBlock(i, j - 1, k);
		/*      */
		for (Block x : getValidSpawnBlocks())
		{
			if (blockAbove != Blocks.air) { return false;
			/*      */}
			if (block == x) return true;
			if ((block == Blocks.snow) && (blockBelow == x)) { return true;
			/*      */}
			/*      */}
		/*      */
		return false;
		/*      */}

	/*      */
	/*      */
	/*      */
	/*      */public void generate(Random random, int chunkX, int chunkZ, World world, IChunkProvider chunkGenerator, IChunkProvider chunkProvider)
	{
	}

	/*      */
	/*      */
	/*      */public void setBlock(World world, int x, int y, int z, Block block, int metadata)
	/*      */
	{
		world.setBlock(x, y, z, block, metadata, 2);
		/*      */}

	/*      */
	/*      */public boolean generate(World world, Random rand, int i, int j, int k)
	/*      */
	{
		k -= 10;
		i -= 10;
		/*      */
		setBlock(world, i + 1, j + 36, k + 8, Blocks.fence, 0);
		setBlock(world, i + 1, j + 36, k + 9, Blocks.fence, 0);
		setBlock(world, i + 1, j + 36, k + 15, Blocks.fence, 0);
		setBlock(world, i + 1, j + 36, k + 16, Blocks.fence, 0);
		setBlock(world, i + 2, j + 36, k + 7, Blocks.fence, 0);
		setBlock(world, i + 2, j + 36, k + 8, Blocks.fence, 0);
		setBlock(world, i + 2, j + 36, k + 16, Blocks.fence, 0);
		setBlock(world, i + 2, j + 36, k + 17, Blocks.fence, 0);
		setBlock(world, i + 3, j + 36, k + 6, Blocks.spruce_stairs, 0);
		setBlock(world, i + 3, j + 36, k + 7, Blocks.fence, 0);
		SpawnUtils.spawnNPC(NPCType.WOOKIETREE, world, i + 3, j + 36, k + 12);
		setBlock(world, i + 3, j + 36, k + 17, Blocks.fence, 0);
		setBlock(world, i + 3, j + 36, k + 18, Blocks.spruce_stairs, 0);
		setBlock(world, i + 3, j + 38, k + 4, Blocks.fence, 0);
		setBlock(world, i + 3, j + 38, k + 5, Blocks.fence, 0);
		setBlock(world, i + 3, j + 38, k + 19, Blocks.fence, 0);
		setBlock(world, i + 3, j + 38, k + 20, Blocks.fence, 0);
		setBlock(world, i + 4, j + 66, k + 29, Blocks.spruce_stairs, 0);
		setBlock(world, i + 5, j + 36, k + 11, Blocks.crafting_table, 0);
		setBlock(world, i + 5, j + 36, k + 12, Blocks.spruce_stairs, 0);
		SpawnUtils.spawnNPC(NPCType.WOOKIETREE, world, i + 6, j + 36, k + 9);
		SpawnUtils.spawnNPC(NPCType.WOOKIETREE, world, i + 6, j + 36, k + 15);
		setBlock(world, i + 6, j + 66, k + 30, Blocks.fence, 0);
		setBlock(world, i + 6, j + 66, k + 31, Blocks.fence, 0);
		setBlock(world, i + 6, j + 69, k + 27, Blocks.fence, 0);
		setBlock(world, i + 6, j + 69, k + 28, Blocks.fence, 0);
		setBlock(world, i + 7, j + 69, k + 28, Blocks.fence, 0);
		setBlock(world, i + 7, j + 69, k + 29, Blocks.fence, 0);
		setBlock(world, i + 8, j + 69, k + 29, Blocks.fence, 0);
		setBlock(world, i + 8, j + 69, k + 30, Blocks.fence, 0);
		setBlock(world, i + 8, j + 69, k + 31, Blocks.fence, 0);
		setBlock(world, i + 9, j + 36, k + 7, Blocks.fence, 0);
		SpawnUtils.spawnNPC(NPCType.WOOKIETREE, world, i + 9, j + 36, k + 12);
		setBlock(world, i + 9, j + 36, k + 17, Blocks.fence, 0);
		setBlock(world, i + 9, j + 38, k + 4, Blocks.fence, 0);
		setBlock(world, i + 9, j + 38, k + 5, Blocks.fence, 0);
		setBlock(world, i + 9, j + 38, k + 19, Blocks.fence, 0);
		setBlock(world, i + 9, j + 38, k + 20, Blocks.fence, 0);
		setBlock(world, i + 9, j + 69, k + 31, Blocks.fence, 0);
		setBlock(world, i + 10, j + 36, k + 7, Blocks.fence, 0);
		setBlock(world, i + 10, j + 36, k + 8, Blocks.fence, 0);
		setBlock(world, i + 10, j + 36, k + 16, Blocks.fence, 0);
		setBlock(world, i + 10, j + 36, k + 17, Blocks.fence, 0);
		setBlock(world, i + 11, j + 36, k + 8, Blocks.fence, 0);
		setBlock(world, i + 11, j + 36, k + 9, Blocks.fence, 0);
		setBlock(world, i + 11, j + 36, k + 10, Blocks.spruce_stairs, 0);
		setBlock(world, i + 11, j + 36, k + 14, Blocks.spruce_stairs, 0);
		setBlock(world, i + 11, j + 36, k + 15, Blocks.fence, 0);
		setBlock(world, i + 11, j + 36, k + 16, Blocks.fence, 0);
		setBlock(world, i + 13, j + 38, k + 9, Blocks.fence, 0);
		setBlock(world, i + 13, j + 38, k + 15, Blocks.fence, 0);
		setBlock(world, i + 14, j + 38, k + 9, Blocks.fence, 0);
		setBlock(world, i + 14, j + 38, k + 15, Blocks.fence, 0);
		setBlock(world, i + 18, j + 41, k + 0, Blocks.fence, 0);
		setBlock(world, i + 19, j + 41, k + 0, Blocks.fence, 0);
		setBlock(world, i + 20, j + 41, k + 0, Blocks.fence, 0);
		setBlock(world, i + 21, j + 41, k + 0, Blocks.fence, 0);
		setBlock(world, i + 21, j + 41, k + 1, Blocks.fence, 0);
		setBlock(world, i + 26, j + 24, k + 19, Blocks.fence, 0);
		setBlock(world, i + 26, j + 24, k + 28, Blocks.fence, 0);
		setBlock(world, i + 27, j + 24, k + 16, Blocks.fence, 0);
		setBlock(world, i + 27, j + 24, k + 17, Blocks.fence, 0);
		setBlock(world, i + 27, j + 24, k + 18, Blocks.fence, 0);
		setBlock(world, i + 27, j + 24, k + 19, Blocks.fence, 0);
		setBlock(world, i + 27, j + 24, k + 28, Blocks.fence, 0);
		setBlock(world, i + 27, j + 24, k + 29, Blocks.fence, 0);
		setBlock(world, i + 27, j + 24, k + 30, Blocks.fence, 0);
		setBlock(world, i + 27, j + 24, k + 31, Blocks.fence, 0);
		setBlock(world, i + 28, j + 24, k + 14, Blocks.fence, 0);
		setBlock(world, i + 28, j + 24, k + 15, Blocks.fence, 0);
		setBlock(world, i + 28, j + 24, k + 16, Blocks.fence, 0);
		setBlock(world, i + 28, j + 24, k + 31, Blocks.fence, 0);
		setBlock(world, i + 29, j + 21, k + 17, Blocks.fence, 0);
		setBlock(world, i + 29, j + 21, k + 18, Blocks.fence, 0);
		setBlock(world, i + 29, j + 21, k + 19, Blocks.fence, 0);
		setBlock(world, i + 29, j + 21, k + 28, Blocks.fence, 0);
		setBlock(world, i + 29, j + 21, k + 29, Blocks.fence, 0);
		setBlock(world, i + 29, j + 21, k + 30, Blocks.fence, 0);
		setBlock(world, i + 29, j + 24, k + 13, Blocks.fence, 0);
		setBlock(world, i + 29, j + 24, k + 14, Blocks.fence, 0);
		setBlock(world, i + 30, j + 21, k + 15, Blocks.fence, 0);
		setBlock(world, i + 30, j + 21, k + 16, Blocks.fence, 0);
		setBlock(world, i + 30, j + 21, k + 17, Blocks.fence, 0);
		SpawnUtils.spawnNPC(NPCType.WOOKIETREE, world, i + 30, j + 21, k + 24);
		setBlock(world, i + 30, j + 21, k + 30, Blocks.fence, 0);
		setBlock(world, i + 30, j + 21, k + 31, Blocks.fence, 0);
		setBlock(world, i + 30, j + 24, k + 12, Blocks.fence, 0);
		setBlock(world, i + 30, j + 24, k + 13, Blocks.fence, 0);
		setBlock(world, i + 30, j + 41, k + 0, Blocks.fence, 0);
		setBlock(world, i + 30, j + 41, k + 1, Blocks.fence, 0);
		setBlock(world, i + 31, j + 41, k + 0, Blocks.fence, 0);
		setBlock(world, i + 0, j + 23, k + 3, Blocks.log, 3);
		world.setBlockMetadataWithNotify(i + 0, j + 23, k + 3, 3, 2);
		setBlock(world, i + 0, j + 23, k + 4, Blocks.log, 3);
		world.setBlockMetadataWithNotify(i + 0, j + 23, k + 4, 3, 2);
		setBlock(world, i + 0, j + 24, k + 4, Blocks.leaves, 15);
		world.setBlockMetadataWithNotify(i + 0, j + 24, k + 4, 15, 2);
		setBlock(world, i + 0, j + 24, k + 5, Blocks.leaves, 15);
		world.setBlockMetadataWithNotify(i + 0, j + 24, k + 5, 15, 2);
		setBlock(world, i + 0, j + 24, k + 6, Blocks.leaves, 7);
		world.setBlockMetadataWithNotify(i + 0, j + 24, k + 6, 7, 2);
		setBlock(world, i + 0, j + 24, k + 7, Blocks.leaves, 7);
		world.setBlockMetadataWithNotify(i + 0, j + 24, k + 7, 7, 2);
		setBlock(world, i + 0, j + 24, k + 8, Blocks.leaves, 7);
		world.setBlockMetadataWithNotify(i + 0, j + 24, k + 8, 7, 2);
		setBlock(world, i + 0, j + 25, k + 5, Blocks.leaves, 15);
		world.setBlockMetadataWithNotify(i + 0, j + 25, k + 5, 15, 2);
		setBlock(world, i + 0, j + 25, k + 6, Blocks.leaves, 7);
		world.setBlockMetadataWithNotify(i + 0, j + 25, k + 6, 7, 2);
		setBlock(world, i + 0, j + 25, k + 7, Blocks.leaves, 7);
		world.setBlockMetadataWithNotify(i + 0, j + 25, k + 7, 7, 2);
		setBlock(world, i + 0, j + 26, k + 6, Blocks.leaves, 7);
		world.setBlockMetadataWithNotify(i + 0, j + 26, k + 6, 7, 2);
		setBlock(world, i + 0, j + 27, k + 0, Blocks.leaves, 15);
		world.setBlockMetadataWithNotify(i + 0, j + 27, k + 0, 15, 2);
		setBlock(world, i + 0, j + 28, k + 0, Blocks.leaves, 15);
		world.setBlockMetadataWithNotify(i + 0, j + 28, k + 0, 15, 2);
		setBlock(world, i + 0, j + 31, k + 25, Blocks.leaves, 7);
		world.setBlockMetadataWithNotify(i + 0, j + 31, k + 25, 7, 2);
		setBlock(world, i + 0, j + 31, k + 26, Blocks.leaves, 7);
		world.setBlockMetadataWithNotify(i + 0, j + 31, k + 26, 7, 2);
		setBlock(world, i + 0, j + 31, k + 27, Blocks.leaves, 7);
		world.setBlockMetadataWithNotify(i + 0, j + 31, k + 27, 7, 2);
		setBlock(world, i + 0, j + 32, k + 26, Blocks.leaves, 7);
		world.setBlockMetadataWithNotify(i + 0, j + 32, k + 26, 7, 2);
		setBlock(world, i + 0, j + 35, k + 10, Blocks.log, 1);
		world.setBlockMetadataWithNotify(i + 0, j + 35, k + 10, 1, 2);
		setBlock(world, i + 0, j + 35, k + 11, Blocks.log, 1);
		world.setBlockMetadataWithNotify(i + 0, j + 35, k + 11, 1, 2);
		setBlock(world, i + 0, j + 35, k + 12, Blocks.log, 1);
		world.setBlockMetadataWithNotify(i + 0, j + 35, k + 12, 1, 2);
		setBlock(world, i + 0, j + 35, k + 13, Blocks.log, 1);
		world.setBlockMetadataWithNotify(i + 0, j + 35, k + 13, 1, 2);
		setBlock(world, i + 0, j + 35, k + 14, Blocks.log, 1);
		world.setBlockMetadataWithNotify(i + 0, j + 35, k + 14, 1, 2);
		setBlock(world, i + 0, j + 35, k + 21, Blocks.planks, 5);
		world.setBlockMetadataWithNotify(i + 0, j + 35, k + 21, 5, 2);
		setBlock(world, i + 0, j + 35, k + 22, Blocks.planks, 5);
		world.setBlockMetadataWithNotify(i + 0, j + 35, k + 22, 5, 2);
		setBlock(world, i + 0, j + 35, k + 23, Blocks.planks, 5);
		world.setBlockMetadataWithNotify(i + 0, j + 35, k + 23, 5, 2);
		setBlock(world, i + 0, j + 35, k + 24, Blocks.planks, 5);
		world.setBlockMetadataWithNotify(i + 0, j + 35, k + 24, 5, 2);
		setBlock(world, i + 0, j + 35, k + 25, Blocks.planks, 5);
		world.setBlockMetadataWithNotify(i + 0, j + 35, k + 25, 5, 2);
		setBlock(world, i + 0, j + 36, k + 9, Blocks.spruce_stairs, 2);
		world.setBlockMetadataWithNotify(i + 0, j + 36, k + 9, 2, 2);
		setBlock(world, i + 0, j + 36, k + 10, Blocks.log, 1);
		world.setBlockMetadataWithNotify(i + 0, j + 36, k + 10, 1, 2);
		setBlock(world, i + 0, j + 36, k + 14, Blocks.log, 1);
		world.setBlockMetadataWithNotify(i + 0, j + 36, k + 14, 1, 2);
		setBlock(world, i + 0, j + 36, k + 15, Blocks.spruce_stairs, 3);
		world.setBlockMetadataWithNotify(i + 0, j + 36, k + 15, 3, 2);
		setBlock(world, i + 0, j + 36, k + 21, Blocks.spruce_stairs, 1);
		world.setBlockMetadataWithNotify(i + 0, j + 36, k + 21, 1, 2);
		setBlock(world, i + 0, j + 36, k + 22, Blocks.spruce_stairs, 1);
		world.setBlockMetadataWithNotify(i + 0, j + 36, k + 22, 1, 2);
		setBlock(world, i + 0, j + 36, k + 23, Blocks.spruce_stairs, 1);
		world.setBlockMetadataWithNotify(i + 0, j + 36, k + 23, 1, 2);
		setBlock(world, i + 0, j + 36, k + 24, Blocks.spruce_stairs, 1);
		world.setBlockMetadataWithNotify(i + 0, j + 36, k + 24, 1, 2);
		setBlock(world, i + 0, j + 36, k + 25, Blocks.spruce_stairs, 1);
		world.setBlockMetadataWithNotify(i + 0, j + 36, k + 25, 1, 2);
		setBlock(world, i + 0, j + 37, k + 10, Blocks.log, 1);
		world.setBlockMetadataWithNotify(i + 0, j + 37, k + 10, 1, 2);
		setBlock(world, i + 0, j + 37, k + 14, Blocks.log, 1);
		world.setBlockMetadataWithNotify(i + 0, j + 37, k + 14, 1, 2);
		setBlock(world, i + 0, j + 38, k + 29, Blocks.log, 3);
		world.setBlockMetadataWithNotify(i + 0, j + 38, k + 29, 3, 2);
		setBlock(world, i + 0, j + 39, k + 5, Blocks.log, 1);
		world.setBlockMetadataWithNotify(i + 0, j + 39, k + 5, 1, 2);
		setBlock(world, i + 0, j + 39, k + 6, Blocks.log, 1);
		world.setBlockMetadataWithNotify(i + 0, j + 39, k + 6, 1, 2);
		setBlock(world, i + 0, j + 39, k + 7, Blocks.log, 1);
		world.setBlockMetadataWithNotify(i + 0, j + 39, k + 7, 1, 2);
		setBlock(world, i + 0, j + 39, k + 8, Blocks.log, 1);
		world.setBlockMetadataWithNotify(i + 0, j + 39, k + 8, 1, 2);
		setBlock(world, i + 0, j + 39, k + 9, Blocks.log, 1);
		world.setBlockMetadataWithNotify(i + 0, j + 39, k + 9, 1, 2);
		setBlock(world, i + 0, j + 39, k + 10, Blocks.log, 1);
		world.setBlockMetadataWithNotify(i + 0, j + 39, k + 10, 1, 2);
		setBlock(world, i + 0, j + 39, k + 11, Blocks.log, 1);
		world.setBlockMetadataWithNotify(i + 0, j + 39, k + 11, 1, 2);
		setBlock(world, i + 0, j + 39, k + 12, Blocks.log, 1);
		world.setBlockMetadataWithNotify(i + 0, j + 39, k + 12, 1, 2);
		setBlock(world, i + 0, j + 39, k + 13, Blocks.log, 1);
		world.setBlockMetadataWithNotify(i + 0, j + 39, k + 13, 1, 2);
		setBlock(world, i + 0, j + 39, k + 14, Blocks.log, 1);
		world.setBlockMetadataWithNotify(i + 0, j + 39, k + 14, 1, 2);
		setBlock(world, i + 0, j + 39, k + 15, Blocks.log, 1);
		world.setBlockMetadataWithNotify(i + 0, j + 39, k + 15, 1, 2);
		setBlock(world, i + 0, j + 39, k + 16, Blocks.log, 1);
		world.setBlockMetadataWithNotify(i + 0, j + 39, k + 16, 1, 2);
		setBlock(world, i + 0, j + 39, k + 17, Blocks.log, 1);
		world.setBlockMetadataWithNotify(i + 0, j + 39, k + 17, 1, 2);
		setBlock(world, i + 0, j + 39, k + 18, Blocks.log, 1);
		world.setBlockMetadataWithNotify(i + 0, j + 39, k + 18, 1, 2);
		setBlock(world, i + 0, j + 39, k + 19, Blocks.log, 1);
		world.setBlockMetadataWithNotify(i + 0, j + 39, k + 19, 1, 2);
		setBlock(world, i + 0, j + 39, k + 25, Blocks.leaves, 7);
		world.setBlockMetadataWithNotify(i + 0, j + 39, k + 25, 7, 2);
		setBlock(world, i + 0, j + 39, k + 26, Blocks.leaves, 7);
		world.setBlockMetadataWithNotify(i + 0, j + 39, k + 26, 7, 2);
		setBlock(world, i + 0, j + 39, k + 27, Blocks.leaves, 7);
		world.setBlockMetadataWithNotify(i + 0, j + 39, k + 27, 7, 2);
		setBlock(world, i + 0, j + 39, k + 28, Blocks.leaves, 7);
		world.setBlockMetadataWithNotify(i + 0, j + 39, k + 28, 7, 2);
		setBlock(world, i + 0, j + 39, k + 29, Blocks.leaves, 7);
		world.setBlockMetadataWithNotify(i + 0, j + 39, k + 29, 7, 2);
		setBlock(world, i + 0, j + 40, k + 6, Blocks.log, 1);
		world.setBlockMetadataWithNotify(i + 0, j + 40, k + 6, 1, 2);
		setBlock(world, i + 0, j + 40, k + 7, Blocks.log, 1);
		world.setBlockMetadataWithNotify(i + 0, j + 40, k + 7, 1, 2);
		setBlock(world, i + 0, j + 40, k + 8, Blocks.log, 1);
		world.setBlockMetadataWithNotify(i + 0, j + 40, k + 8, 1, 2);
		setBlock(world, i + 0, j + 40, k + 9, Blocks.log, 1);
		world.setBlockMetadataWithNotify(i + 0, j + 40, k + 9, 1, 2);
		setBlock(world, i + 0, j + 40, k + 10, Blocks.log, 1);
		world.setBlockMetadataWithNotify(i + 0, j + 40, k + 10, 1, 2);
		setBlock(world, i + 0, j + 40, k + 11, Blocks.log, 1);
		world.setBlockMetadataWithNotify(i + 0, j + 40, k + 11, 1, 2);
		setBlock(world, i + 0, j + 40, k + 12, Blocks.log, 1);
		world.setBlockMetadataWithNotify(i + 0, j + 40, k + 12, 1, 2);
		setBlock(world, i + 0, j + 40, k + 13, Blocks.log, 1);
		world.setBlockMetadataWithNotify(i + 0, j + 40, k + 13, 1, 2);
		setBlock(world, i + 0, j + 40, k + 14, Blocks.log, 1);
		world.setBlockMetadataWithNotify(i + 0, j + 40, k + 14, 1, 2);
		setBlock(world, i + 0, j + 40, k + 15, Blocks.log, 1);
		world.setBlockMetadataWithNotify(i + 0, j + 40, k + 15, 1, 2);
		setBlock(world, i + 0, j + 40, k + 16, Blocks.log, 1);
		world.setBlockMetadataWithNotify(i + 0, j + 40, k + 16, 1, 2);
		setBlock(world, i + 0, j + 40, k + 17, Blocks.log, 1);
		world.setBlockMetadataWithNotify(i + 0, j + 40, k + 17, 1, 2);
		setBlock(world, i + 0, j + 40, k + 18, Blocks.log, 1);
		world.setBlockMetadataWithNotify(i + 0, j + 40, k + 18, 1, 2);
		setBlock(world, i + 0, j + 40, k + 26, Blocks.leaves, 7);
		world.setBlockMetadataWithNotify(i + 0, j + 40, k + 26, 7, 2);
		setBlock(world, i + 0, j + 40, k + 27, Blocks.leaves, 7);
		world.setBlockMetadataWithNotify(i + 0, j + 40, k + 27, 7, 2);
		setBlock(world, i + 0, j + 40, k + 28, Blocks.leaves, 7);
		world.setBlockMetadataWithNotify(i + 0, j + 40, k + 28, 7, 2);
		setBlock(world, i + 0, j + 41, k + 7, Blocks.log, 1);
		world.setBlockMetadataWithNotify(i + 0, j + 41, k + 7, 1, 2);
		setBlock(world, i + 0, j + 41, k + 8, Blocks.log, 1);
		world.setBlockMetadataWithNotify(i + 0, j + 41, k + 8, 1, 2);
		setBlock(world, i + 0, j + 41, k + 9, Blocks.log, 1);
		world.setBlockMetadataWithNotify(i + 0, j + 41, k + 9, 1, 2);
		setBlock(world, i + 0, j + 41, k + 10, Blocks.log, 1);
		world.setBlockMetadataWithNotify(i + 0, j + 41, k + 10, 1, 2);
		setBlock(world, i + 0, j + 41, k + 11, Blocks.log, 1);
		world.setBlockMetadataWithNotify(i + 0, j + 41, k + 11, 1, 2);
		setBlock(world, i + 0, j + 41, k + 12, Blocks.log, 1);
		world.setBlockMetadataWithNotify(i + 0, j + 41, k + 12, 1, 2);
		setBlock(world, i + 0, j + 41, k + 13, Blocks.log, 1);
		world.setBlockMetadataWithNotify(i + 0, j + 41, k + 13, 1, 2);
		setBlock(world, i + 0, j + 41, k + 14, Blocks.log, 1);
		world.setBlockMetadataWithNotify(i + 0, j + 41, k + 14, 1, 2);
		setBlock(world, i + 0, j + 41, k + 15, Blocks.log, 1);
		world.setBlockMetadataWithNotify(i + 0, j + 41, k + 15, 1, 2);
		setBlock(world, i + 0, j + 41, k + 16, Blocks.log, 1);
		world.setBlockMetadataWithNotify(i + 0, j + 41, k + 16, 1, 2);
		setBlock(world, i + 0, j + 41, k + 17, Blocks.log, 1);
		world.setBlockMetadataWithNotify(i + 0, j + 41, k + 17, 1, 2);
		setBlock(world, i + 0, j + 41, k + 27, Blocks.leaves, 7);
		world.setBlockMetadataWithNotify(i + 0, j + 41, k + 27, 7, 2);
		setBlock(world, i + 0, j + 41, k + 29, Blocks.log, 3);
		world.setBlockMetadataWithNotify(i + 0, j + 41, k + 29, 3, 2);
		setBlock(world, i + 0, j + 42, k + 8, Blocks.log, 1);
		world.setBlockMetadataWithNotify(i + 0, j + 42, k + 8, 1, 2);
		setBlock(world, i + 0, j + 42, k + 9, Blocks.log, 1);
		world.setBlockMetadataWithNotify(i + 0, j + 42, k + 9, 1, 2);
		setBlock(world, i + 0, j + 42, k + 10, Blocks.log, 1);
		world.setBlockMetadataWithNotify(i + 0, j + 42, k + 10, 1, 2);
		setBlock(world, i + 0, j + 42, k + 11, Blocks.log, 1);
		world.setBlockMetadataWithNotify(i + 0, j + 42, k + 11, 1, 2);
		setBlock(world, i + 0, j + 42, k + 12, Blocks.log, 1);
		world.setBlockMetadataWithNotify(i + 0, j + 42, k + 12, 1, 2);
		setBlock(world, i + 0, j + 42, k + 13, Blocks.log, 1);
		world.setBlockMetadataWithNotify(i + 0, j + 42, k + 13, 1, 2);
		setBlock(world, i + 0, j + 42, k + 14, Blocks.log, 1);
		world.setBlockMetadataWithNotify(i + 0, j + 42, k + 14, 1, 2);
		setBlock(world, i + 0, j + 42, k + 15, Blocks.log, 1);
		world.setBlockMetadataWithNotify(i + 0, j + 42, k + 15, 1, 2);
		setBlock(world, i + 0, j + 42, k + 16, Blocks.log, 1);
		world.setBlockMetadataWithNotify(i + 0, j + 42, k + 16, 1, 2);
		setBlock(world, i + 0, j + 42, k + 25, Blocks.leaves, 7);
		world.setBlockMetadataWithNotify(i + 0, j + 42, k + 25, 7, 2);
		setBlock(world, i + 0, j + 42, k + 26, Blocks.leaves, 7);
		world.setBlockMetadataWithNotify(i + 0, j + 42, k + 26, 7, 2);
		setBlock(world, i + 0, j + 42, k + 27, Blocks.leaves, 7);
		world.setBlockMetadataWithNotify(i + 0, j + 42, k + 27, 7, 2);
		setBlock(world, i + 0, j + 42, k + 28, Blocks.leaves, 7);
		world.setBlockMetadataWithNotify(i + 0, j + 42, k + 28, 7, 2);
		setBlock(world, i + 0, j + 42, k + 29, Blocks.leaves, 7);
		world.setBlockMetadataWithNotify(i + 0, j + 42, k + 29, 7, 2);
		setBlock(world, i + 0, j + 42, k + 31, Blocks.log, 3);
		world.setBlockMetadataWithNotify(i + 0, j + 42, k + 31, 3, 2);
		setBlock(world, i + 0, j + 43, k + 0, Blocks.leaves, 7);
		world.setBlockMetadataWithNotify(i + 0, j + 43, k + 0, 7, 2);
		setBlock(world, i + 0, j + 43, k + 1, Blocks.leaves, 7);
		world.setBlockMetadataWithNotify(i + 0, j + 43, k + 1, 7, 2);
		setBlock(world, i + 0, j + 43, k + 2, Blocks.leaves, 7);
		world.setBlockMetadataWithNotify(i + 0, j + 43, k + 2, 7, 2);
		setBlock(world, i + 0, j + 43, k + 10, Blocks.log, 1);
		world.setBlockMetadataWithNotify(i + 0, j + 43, k + 10, 1, 2);
		setBlock(world, i + 0, j + 43, k + 11, Blocks.log, 1);
		world.setBlockMetadataWithNotify(i + 0, j + 43, k + 11, 1, 2);
		setBlock(world, i + 0, j + 43, k + 12, Blocks.log, 1);
		world.setBlockMetadataWithNotify(i + 0, j + 43, k + 12, 1, 2);
		setBlock(world, i + 0, j + 43, k + 13, Blocks.log, 1);
		world.setBlockMetadataWithNotify(i + 0, j + 43, k + 13, 1, 2);
		setBlock(world, i + 0, j + 43, k + 14, Blocks.log, 1);
		world.setBlockMetadataWithNotify(i + 0, j + 43, k + 14, 1, 2);
		setBlock(world, i + 0, j + 43, k + 26, Blocks.leaves, 7);
		world.setBlockMetadataWithNotify(i + 0, j + 43, k + 26, 7, 2);
		setBlock(world, i + 0, j + 43, k + 27, Blocks.leaves, 7);
		world.setBlockMetadataWithNotify(i + 0, j + 43, k + 27, 7, 2);
		setBlock(world, i + 0, j + 43, k + 28, Blocks.leaves, 7);
		world.setBlockMetadataWithNotify(i + 0, j + 43, k + 28, 7, 2);
		setBlock(world, i + 0, j + 43, k + 29, Blocks.leaves, 7);
		world.setBlockMetadataWithNotify(i + 0, j + 43, k + 29, 7, 2);
		setBlock(world, i + 0, j + 43, k + 30, Blocks.leaves, 7);
		world.setBlockMetadataWithNotify(i + 0, j + 43, k + 30, 7, 2);
		setBlock(world, i + 0, j + 43, k + 31, Blocks.leaves, 7);
		world.setBlockMetadataWithNotify(i + 0, j + 43, k + 31, 7, 2);
		setBlock(world, i + 0, j + 44, k + 0, Blocks.leaves, 7);
		world.setBlockMetadataWithNotify(i + 0, j + 44, k + 0, 7, 2);
		setBlock(world, i + 0, j + 44, k + 1, Blocks.leaves, 7);
		world.setBlockMetadataWithNotify(i + 0, j + 44, k + 1, 7, 2);
		setBlock(world, i + 0, j + 44, k + 27, Blocks.leaves, 7);
		world.setBlockMetadataWithNotify(i + 0, j + 44, k + 27, 7, 2);
		setBlock(world, i + 0, j + 44, k + 29, Blocks.leaves, 7);
		world.setBlockMetadataWithNotify(i + 0, j + 44, k + 29, 7, 2);
		setBlock(world, i + 0, j + 44, k + 30, Blocks.leaves, 7);
		world.setBlockMetadataWithNotify(i + 0, j + 44, k + 30, 7, 2);
		setBlock(world, i + 0, j + 44, k + 31, Blocks.leaves, 7);
		world.setBlockMetadataWithNotify(i + 0, j + 44, k + 31, 7, 2);
		setBlock(world, i + 0, j + 45, k + 0, Blocks.leaves, 7);
		world.setBlockMetadataWithNotify(i + 0, j + 45, k + 0, 7, 2);
		setBlock(world, i + 0, j + 45, k + 30, Blocks.leaves, 7);
		world.setBlockMetadataWithNotify(i + 0, j + 45, k + 30, 7, 2);
		setBlock(world, i + 0, j + 45, k + 31, Blocks.vine, 15);
		world.setBlockMetadataWithNotify(i + 0, j + 45, k + 31, 15, 2);
		setBlock(world, i + 0, j + 46, k + 27, Blocks.leaves, 7);
		world.setBlockMetadataWithNotify(i + 0, j + 46, k + 27, 7, 2);
		setBlock(world, i + 0, j + 46, k + 28, Blocks.leaves, 7);
		world.setBlockMetadataWithNotify(i + 0, j + 46, k + 28, 7, 2);
		setBlock(world, i + 0, j + 46, k + 29, Blocks.leaves, 7);
		world.setBlockMetadataWithNotify(i + 0, j + 46, k + 29, 7, 2);
		setBlock(world, i + 0, j + 46, k + 31, Blocks.vine, 15);
		world.setBlockMetadataWithNotify(i + 0, j + 46, k + 31, 15, 2);
		setBlock(world, i + 0, j + 47, k + 27, Blocks.vine, 15);
		world.setBlockMetadataWithNotify(i + 0, j + 47, k + 27, 15, 2);
		setBlock(world, i + 0, j + 47, k + 28, Blocks.leaves, 7);
		world.setBlockMetadataWithNotify(i + 0, j + 47, k + 28, 7, 2);
		setBlock(world, i + 0, j + 47, k + 29, Blocks.leaves, 7);
		world.setBlockMetadataWithNotify(i + 0, j + 47, k + 29, 7, 2);
		setBlock(world, i + 0, j + 47, k + 30, Blocks.leaves, 7);
		world.setBlockMetadataWithNotify(i + 0, j + 47, k + 30, 7, 2);
		setBlock(world, i + 0, j + 47, k + 31, Blocks.log, 3);
		world.setBlockMetadataWithNotify(i + 0, j + 47, k + 31, 3, 2);
		setBlock(world, i + 0, j + 48, k + 27, Blocks.vine, 15);
		world.setBlockMetadataWithNotify(i + 0, j + 48, k + 27, 15, 2);
		setBlock(world, i + 0, j + 48, k + 28, Blocks.vine, 15);
		world.setBlockMetadataWithNotify(i + 0, j + 48, k + 28, 15, 2);
		setBlock(world, i + 0, j + 48, k + 29, Blocks.leaves, 7);
		world.setBlockMetadataWithNotify(i + 0, j + 48, k + 29, 7, 2);
		setBlock(world, i + 0, j + 48, k + 30, Blocks.leaves, 7);
		world.setBlockMetadataWithNotify(i + 0, j + 48, k + 30, 7, 2);
		setBlock(world, i + 0, j + 48, k + 31, Blocks.leaves, 7);
		world.setBlockMetadataWithNotify(i + 0, j + 48, k + 31, 7, 2);
		setBlock(world, i + 0, j + 49, k + 30, Blocks.leaves, 7);
		world.setBlockMetadataWithNotify(i + 0, j + 49, k + 30, 7, 2);
		setBlock(world, i + 0, j + 49, k + 31, Blocks.leaves, 7);
		world.setBlockMetadataWithNotify(i + 0, j + 49, k + 31, 7, 2);
		setBlock(world, i + 0, j + 50, k + 30, Blocks.vine, 15);
		world.setBlockMetadataWithNotify(i + 0, j + 50, k + 30, 15, 2);
		setBlock(world, i + 0, j + 50, k + 31, Blocks.leaves, 7);
		world.setBlockMetadataWithNotify(i + 0, j + 50, k + 31, 7, 2);
		setBlock(world, i + 0, j + 63, k + 31, Blocks.log, 1);
		world.setBlockMetadataWithNotify(i + 0, j + 63, k + 31, 1, 2);
		setBlock(world, i + 0, j + 64, k + 31, Blocks.log, 1);
		world.setBlockMetadataWithNotify(i + 0, j + 64, k + 31, 1, 2);
		setBlock(world, i + 0, j + 65, k + 27, Blocks.log, 1);
		world.setBlockMetadataWithNotify(i + 0, j + 65, k + 27, 1, 2);
		setBlock(world, i + 0, j + 65, k + 28, Blocks.log, 1);
		world.setBlockMetadataWithNotify(i + 0, j + 65, k + 28, 1, 2);
		setBlock(world, i + 0, j + 65, k + 29, Blocks.log, 1);
		world.setBlockMetadataWithNotify(i + 0, j + 65, k + 29, 1, 2);
		setBlock(world, i + 0, j + 65, k + 30, Blocks.log, 1);
		world.setBlockMetadataWithNotify(i + 0, j + 65, k + 30, 1, 2);
		setBlock(world, i + 0, j + 65, k + 31, Blocks.log, 1);
		world.setBlockMetadataWithNotify(i + 0, j + 65, k + 31, 1, 2);
		setBlock(world, i + 0, j + 70, k + 25, Blocks.log, 1);
		world.setBlockMetadataWithNotify(i + 0, j + 70, k + 25, 1, 2);
		setBlock(world, i + 0, j + 70, k + 26, Blocks.log, 1);
		world.setBlockMetadataWithNotify(i + 0, j + 70, k + 26, 1, 2);
		setBlock(world, i + 0, j + 70, k + 27, Blocks.log, 1);
		world.setBlockMetadataWithNotify(i + 0, j + 70, k + 27, 1, 2);
		setBlock(world, i + 0, j + 70, k + 28, Blocks.log, 1);
		world.setBlockMetadataWithNotify(i + 0, j + 70, k + 28, 1, 2);
		setBlock(world, i + 0, j + 70, k + 29, Blocks.log, 1);
		world.setBlockMetadataWithNotify(i + 0, j + 70, k + 29, 1, 2);
		setBlock(world, i + 0, j + 70, k + 30, Blocks.log, 1);
		world.setBlockMetadataWithNotify(i + 0, j + 70, k + 30, 1, 2);
		setBlock(world, i + 0, j + 71, k + 26, Blocks.log, 1);
		world.setBlockMetadataWithNotify(i + 0, j + 71, k + 26, 1, 2);
		setBlock(world, i + 0, j + 71, k + 27, Blocks.log, 1);
		world.setBlockMetadataWithNotify(i + 0, j + 71, k + 27, 1, 2);
		setBlock(world, i + 0, j + 71, k + 28, Blocks.log, 1);
		world.setBlockMetadataWithNotify(i + 0, j + 71, k + 28, 1, 2);
		setBlock(world, i + 0, j + 71, k + 29, Blocks.log, 1);
		world.setBlockMetadataWithNotify(i + 0, j + 71, k + 29, 1, 2);
		setBlock(world, i + 0, j + 71, k + 30, Blocks.log, 1);
		world.setBlockMetadataWithNotify(i + 0, j + 71, k + 30, 1, 2);
		setBlock(world, i + 0, j + 71, k + 31, Blocks.log, 1);
		world.setBlockMetadataWithNotify(i + 0, j + 71, k + 31, 1, 2);
		setBlock(world, i + 0, j + 72, k + 28, Blocks.log, 1);
		world.setBlockMetadataWithNotify(i + 0, j + 72, k + 28, 1, 2);
		setBlock(world, i + 0, j + 72, k + 29, Blocks.log, 1);
		world.setBlockMetadataWithNotify(i + 0, j + 72, k + 29, 1, 2);
		setBlock(world, i + 0, j + 72, k + 30, Blocks.log, 1);
		world.setBlockMetadataWithNotify(i + 0, j + 72, k + 30, 1, 2);
		setBlock(world, i + 0, j + 72, k + 31, Blocks.log, 1);
		world.setBlockMetadataWithNotify(i + 0, j + 72, k + 31, 1, 2);
		setBlock(world, i + 1, j + 23, k + 2, Blocks.log, 3);
		world.setBlockMetadataWithNotify(i + 1, j + 23, k + 2, 3, 2);
		setBlock(world, i + 1, j + 24, k + 5, Blocks.leaves, 15);
		world.setBlockMetadataWithNotify(i + 1, j + 24, k + 5, 15, 2);
		setBlock(world, i + 1, j + 24, k + 6, Blocks.leaves, 7);
		world.setBlockMetadataWithNotify(i + 1, j + 24, k + 6, 7, 2);
		setBlock(world, i + 1, j + 24, k + 7, Blocks.leaves, 7);
		world.setBlockMetadataWithNotify(i + 1, j + 24, k + 7, 7, 2);
		setBlock(world, i + 1, j + 25, k + 6, Blocks.leaves, 7);
		world.setBlockMetadataWithNotify(i + 1, j + 25, k + 6, 7, 2);
		setBlock(world, i + 1, j + 27, k + 0, Blocks.leaves, 15);
		world.setBlockMetadataWithNotify(i + 1, j + 27, k + 0, 15, 2);
		setBlock(world, i + 1, j + 31, k + 24, Blocks.leaves, 7);
		world.setBlockMetadataWithNotify(i + 1, j + 31, k + 24, 7, 2);
		setBlock(world, i + 1, j + 31, k + 25, Blocks.leaves, 7);
		world.setBlockMetadataWithNotify(i + 1, j + 31, k + 25, 7, 2);
		setBlock(world, i + 1, j + 31, k + 26, Blocks.leaves, 7);
		world.setBlockMetadataWithNotify(i + 1, j + 31, k + 26, 7, 2);
		setBlock(world, i + 1, j + 31, k + 27, Blocks.leaves, 7);
		world.setBlockMetadataWithNotify(i + 1, j + 31, k + 27, 7, 2);
		setBlock(world, i + 1, j + 31, k + 28, Blocks.leaves, 7);
		world.setBlockMetadataWithNotify(i + 1, j + 31, k + 28, 7, 2);
		setBlock(world, i + 1, j + 32, k + 21, Blocks.leaves, 7);
		world.setBlockMetadataWithNotify(i + 1, j + 32, k + 21, 7, 2);
		setBlock(world, i + 1, j + 32, k + 22, Blocks.leaves, 7);
		world.setBlockMetadataWithNotify(i + 1, j + 32, k + 22, 7, 2);
		setBlock(world, i + 1, j + 32, k + 23, Blocks.leaves, 7);
		world.setBlockMetadataWithNotify(i + 1, j + 32, k + 23, 7, 2);
		setBlock(world, i + 1, j + 32, k + 25, Blocks.leaves, 7);
		world.setBlockMetadataWithNotify(i + 1, j + 32, k + 25, 7, 2);
		setBlock(world, i + 1, j + 32, k + 26, Blocks.leaves, 7);
		world.setBlockMetadataWithNotify(i + 1, j + 32, k + 26, 7, 2);
		setBlock(world, i + 1, j + 32, k + 27, Blocks.leaves, 7);
		world.setBlockMetadataWithNotify(i + 1, j + 32, k + 27, 7, 2);
		setBlock(world, i + 1, j + 33, k + 22, Blocks.leaves, 15);
		world.setBlockMetadataWithNotify(i + 1, j + 33, k + 22, 15, 2);
		setBlock(world, i + 1, j + 33, k + 26, Blocks.leaves, 7);
		world.setBlockMetadataWithNotify(i + 1, j + 33, k + 26, 7, 2);
		setBlock(world, i + 1, j + 35, k + 8, Blocks.log, 1);
		world.setBlockMetadataWithNotify(i + 1, j + 35, k + 8, 1, 2);
		setBlock(world, i + 1, j + 35, k + 9, Blocks.log, 1);
		world.setBlockMetadataWithNotify(i + 1, j + 35, k + 9, 1, 2);
		setBlock(world, i + 1, j + 35, k + 10, Blocks.log, 1);
		world.setBlockMetadataWithNotify(i + 1, j + 35, k + 10, 1, 2);
		setBlock(world, i + 1, j + 35, k + 11, Blocks.planks, 5);
		world.setBlockMetadataWithNotify(i + 1, j + 35, k + 11, 5, 2);
		setBlock(world, i + 1, j + 35, k + 12, Blocks.log, 1);
		world.setBlockMetadataWithNotify(i + 1, j + 35, k + 12, 1, 2);
		setBlock(world, i + 1, j + 35, k + 13, Blocks.planks, 5);
		world.setBlockMetadataWithNotify(i + 1, j + 35, k + 13, 5, 2);
		setBlock(world, i + 1, j + 35, k + 14, Blocks.log, 1);
		world.setBlockMetadataWithNotify(i + 1, j + 35, k + 14, 1, 2);
		setBlock(world, i + 1, j + 35, k + 15, Blocks.log, 1);
		world.setBlockMetadataWithNotify(i + 1, j + 35, k + 15, 1, 2);
		setBlock(world, i + 1, j + 35, k + 16, Blocks.log, 1);
		world.setBlockMetadataWithNotify(i + 1, j + 35, k + 16, 1, 2);
		setBlock(world, i + 1, j + 35, k + 21, Blocks.planks, 5);
		world.setBlockMetadataWithNotify(i + 1, j + 35, k + 21, 5, 2);
		setBlock(world, i + 1, j + 35, k + 22, Blocks.planks, 5);
		world.setBlockMetadataWithNotify(i + 1, j + 35, k + 22, 5, 2);
		setBlock(world, i + 1, j + 35, k + 23, Blocks.planks, 5);
		world.setBlockMetadataWithNotify(i + 1, j + 35, k + 23, 5, 2);
		setBlock(world, i + 1, j + 35, k + 24, Blocks.planks, 5);
		world.setBlockMetadataWithNotify(i + 1, j + 35, k + 24, 5, 2);
		setBlock(world, i + 1, j + 35, k + 25, Blocks.planks, 5);
		world.setBlockMetadataWithNotify(i + 1, j + 35, k + 25, 5, 2);
		setBlock(world, i + 1, j + 36, k + 10, Blocks.spruce_stairs, 1);
		world.setBlockMetadataWithNotify(i + 1, j + 36, k + 10, 1, 2);
		setBlock(world, i + 1, j + 36, k + 14, Blocks.spruce_stairs, 1);
		world.setBlockMetadataWithNotify(i + 1, j + 36, k + 14, 1, 2);
		setBlock(world, i + 1, j + 37, k + 9, Blocks.torch, 5);
		world.setBlockMetadataWithNotify(i + 1, j + 37, k + 9, 5, 2);
		setBlock(world, i + 1, j + 37, k + 15, Blocks.torch, 5);
		world.setBlockMetadataWithNotify(i + 1, j + 37, k + 15, 5, 2);
		setBlock(world, i + 1, j + 38, k + 0, Blocks.leaves, 7);
		world.setBlockMetadataWithNotify(i + 1, j + 38, k + 0, 7, 2);
		setBlock(world, i + 1, j + 38, k + 30, Blocks.log, 3);
		world.setBlockMetadataWithNotify(i + 1, j + 38, k + 30, 3, 2);
		setBlock(world, i + 1, j + 39, k + 4, Blocks.log, 1);
		world.setBlockMetadataWithNotify(i + 1, j + 39, k + 4, 1, 2);
		setBlock(world, i + 1, j + 39, k + 5, Blocks.log, 1);
		world.setBlockMetadataWithNotify(i + 1, j + 39, k + 5, 1, 2);
		setBlock(world, i + 1, j + 39, k + 6, Blocks.log, 1);
		world.setBlockMetadataWithNotify(i + 1, j + 39, k + 6, 1, 2);
		setBlock(world, i + 1, j + 39, k + 7, Blocks.log, 1);
		world.setBlockMetadataWithNotify(i + 1, j + 39, k + 7, 1, 2);
		setBlock(world, i + 1, j + 39, k + 8, Blocks.log, 1);
		world.setBlockMetadataWithNotify(i + 1, j + 39, k + 8, 1, 2);
		setBlock(world, i + 1, j + 39, k + 9, Blocks.log, 1);
		world.setBlockMetadataWithNotify(i + 1, j + 39, k + 9, 1, 2);
		setBlock(world, i + 1, j + 39, k + 10, Blocks.log, 1);
		world.setBlockMetadataWithNotify(i + 1, j + 39, k + 10, 1, 2);
		setBlock(world, i + 1, j + 39, k + 11, Blocks.log, 1);
		world.setBlockMetadataWithNotify(i + 1, j + 39, k + 11, 1, 2);
		setBlock(world, i + 1, j + 39, k + 12, Blocks.log, 1);
		world.setBlockMetadataWithNotify(i + 1, j + 39, k + 12, 1, 2);
		setBlock(world, i + 1, j + 39, k + 13, Blocks.log, 1);
		world.setBlockMetadataWithNotify(i + 1, j + 39, k + 13, 1, 2);
		setBlock(world, i + 1, j + 39, k + 14, Blocks.log, 1);
		world.setBlockMetadataWithNotify(i + 1, j + 39, k + 14, 1, 2);
		setBlock(world, i + 1, j + 39, k + 15, Blocks.log, 1);
		world.setBlockMetadataWithNotify(i + 1, j + 39, k + 15, 1, 2);
		setBlock(world, i + 1, j + 39, k + 16, Blocks.log, 1);
		world.setBlockMetadataWithNotify(i + 1, j + 39, k + 16, 1, 2);
		setBlock(world, i + 1, j + 39, k + 17, Blocks.log, 1);
		world.setBlockMetadataWithNotify(i + 1, j + 39, k + 17, 1, 2);
		setBlock(world, i + 1, j + 39, k + 18, Blocks.log, 1);
		world.setBlockMetadataWithNotify(i + 1, j + 39, k + 18, 1, 2);
		setBlock(world, i + 1, j + 39, k + 19, Blocks.log, 1);
		world.setBlockMetadataWithNotify(i + 1, j + 39, k + 19, 1, 2);
		setBlock(world, i + 1, j + 39, k + 20, Blocks.log, 1);
		world.setBlockMetadataWithNotify(i + 1, j + 39, k + 20, 1, 2);
		setBlock(world, i + 1, j + 39, k + 26, Blocks.leaves, 7);
		world.setBlockMetadataWithNotify(i + 1, j + 39, k + 26, 7, 2);
		setBlock(world, i + 1, j + 39, k + 27, Blocks.leaves, 7);
		world.setBlockMetadataWithNotify(i + 1, j + 39, k + 27, 7, 2);
		setBlock(world, i + 1, j + 39, k + 28, Blocks.leaves, 7);
		world.setBlockMetadataWithNotify(i + 1, j + 39, k + 28, 7, 2);
		setBlock(world, i + 1, j + 40, k + 6, Blocks.log, 1);
		world.setBlockMetadataWithNotify(i + 1, j + 40, k + 6, 1, 2);
		setBlock(world, i + 1, j + 40, k + 7, Blocks.log, 1);
		world.setBlockMetadataWithNotify(i + 1, j + 40, k + 7, 1, 2);
		setBlock(world, i + 1, j + 40, k + 8, Blocks.log, 1);
		world.setBlockMetadataWithNotify(i + 1, j + 40, k + 8, 1, 2);
		setBlock(world, i + 1, j + 40, k + 9, Blocks.log, 1);
		world.setBlockMetadataWithNotify(i + 1, j + 40, k + 9, 1, 2);
		setBlock(world, i + 1, j + 40, k + 10, Blocks.log, 1);
		world.setBlockMetadataWithNotify(i + 1, j + 40, k + 10, 1, 2);
		setBlock(world, i + 1, j + 40, k + 11, Blocks.log, 1);
		world.setBlockMetadataWithNotify(i + 1, j + 40, k + 11, 1, 2);
		setBlock(world, i + 1, j + 40, k + 12, Blocks.log, 1);
		world.setBlockMetadataWithNotify(i + 1, j + 40, k + 12, 1, 2);
		setBlock(world, i + 1, j + 40, k + 13, Blocks.log, 1);
		world.setBlockMetadataWithNotify(i + 1, j + 40, k + 13, 1, 2);
		setBlock(world, i + 1, j + 40, k + 14, Blocks.log, 1);
		world.setBlockMetadataWithNotify(i + 1, j + 40, k + 14, 1, 2);
		setBlock(world, i + 1, j + 40, k + 15, Blocks.log, 1);
		world.setBlockMetadataWithNotify(i + 1, j + 40, k + 15, 1, 2);
		setBlock(world, i + 1, j + 40, k + 16, Blocks.log, 1);
		world.setBlockMetadataWithNotify(i + 1, j + 40, k + 16, 1, 2);
		setBlock(world, i + 1, j + 40, k + 17, Blocks.log, 1);
		world.setBlockMetadataWithNotify(i + 1, j + 40, k + 17, 1, 2);
		setBlock(world, i + 1, j + 40, k + 18, Blocks.log, 1);
		world.setBlockMetadataWithNotify(i + 1, j + 40, k + 18, 1, 2);
		setBlock(world, i + 1, j + 40, k + 27, Blocks.leaves, 7);
		world.setBlockMetadataWithNotify(i + 1, j + 40, k + 27, 7, 2);
		setBlock(world, i + 1, j + 41, k + 0, Blocks.leaves, 7);
		world.setBlockMetadataWithNotify(i + 1, j + 41, k + 0, 7, 2);
		setBlock(world, i + 1, j + 41, k + 1, Blocks.leaves, 7);
		world.setBlockMetadataWithNotify(i + 1, j + 41, k + 1, 7, 2);
		setBlock(world, i + 1, j + 41, k + 6, Blocks.log, 1);
		world.setBlockMetadataWithNotify(i + 1, j + 41, k + 6, 1, 2);
		setBlock(world, i + 1, j + 41, k + 7, Blocks.log, 1);
		world.setBlockMetadataWithNotify(i + 1, j + 41, k + 7, 1, 2);
		setBlock(world, i + 1, j + 41, k + 8, Blocks.log, 1);
		world.setBlockMetadataWithNotify(i + 1, j + 41, k + 8, 1, 2);
		setBlock(world, i + 1, j + 41, k + 9, Blocks.log, 1);
		world.setBlockMetadataWithNotify(i + 1, j + 41, k + 9, 1, 2);
		setBlock(world, i + 1, j + 41, k + 10, Blocks.log, 1);
		world.setBlockMetadataWithNotify(i + 1, j + 41, k + 10, 1, 2);
		setBlock(world, i + 1, j + 41, k + 11, Blocks.log, 1);
		world.setBlockMetadataWithNotify(i + 1, j + 41, k + 11, 1, 2);
		setBlock(world, i + 1, j + 41, k + 12, Blocks.log, 1);
		world.setBlockMetadataWithNotify(i + 1, j + 41, k + 12, 1, 2);
		setBlock(world, i + 1, j + 41, k + 13, Blocks.log, 1);
		world.setBlockMetadataWithNotify(i + 1, j + 41, k + 13, 1, 2);
		setBlock(world, i + 1, j + 41, k + 14, Blocks.log, 1);
		world.setBlockMetadataWithNotify(i + 1, j + 41, k + 14, 1, 2);
		setBlock(world, i + 1, j + 41, k + 15, Blocks.log, 1);
		world.setBlockMetadataWithNotify(i + 1, j + 41, k + 15, 1, 2);
		setBlock(world, i + 1, j + 41, k + 16, Blocks.log, 1);
		world.setBlockMetadataWithNotify(i + 1, j + 41, k + 16, 1, 2);
		setBlock(world, i + 1, j + 41, k + 17, Blocks.log, 1);
		world.setBlockMetadataWithNotify(i + 1, j + 41, k + 17, 1, 2);
		setBlock(world, i + 1, j + 41, k + 18, Blocks.log, 1);
		world.setBlockMetadataWithNotify(i + 1, j + 41, k + 18, 1, 2);
		setBlock(world, i + 1, j + 41, k + 30, Blocks.log, 3);
		world.setBlockMetadataWithNotify(i + 1, j + 41, k + 30, 3, 2);
		setBlock(world, i + 1, j + 42, k + 0, Blocks.leaves, 7);
		world.setBlockMetadataWithNotify(i + 1, j + 42, k + 0, 7, 2);
		setBlock(world, i + 1, j + 42, k + 7, Blocks.log, 1);
		world.setBlockMetadataWithNotify(i + 1, j + 42, k + 7, 1, 2);
		setBlock(world, i + 1, j + 42, k + 8, Blocks.log, 1);
		world.setBlockMetadataWithNotify(i + 1, j + 42, k + 8, 1, 2);
		setBlock(world, i + 1, j + 42, k + 9, Blocks.log, 1);
		world.setBlockMetadataWithNotify(i + 1, j + 42, k + 9, 1, 2);
		setBlock(world, i + 1, j + 42, k + 10, Blocks.log, 1);
		world.setBlockMetadataWithNotify(i + 1, j + 42, k + 10, 1, 2);
		setBlock(world, i + 1, j + 42, k + 11, Blocks.log, 1);
		world.setBlockMetadataWithNotify(i + 1, j + 42, k + 11, 1, 2);
		setBlock(world, i + 1, j + 42, k + 12, Blocks.log, 1);
		world.setBlockMetadataWithNotify(i + 1, j + 42, k + 12, 1, 2);
		setBlock(world, i + 1, j + 42, k + 13, Blocks.log, 1);
		world.setBlockMetadataWithNotify(i + 1, j + 42, k + 13, 1, 2);
		setBlock(world, i + 1, j + 42, k + 14, Blocks.log, 1);
		world.setBlockMetadataWithNotify(i + 1, j + 42, k + 14, 1, 2);
		setBlock(world, i + 1, j + 42, k + 15, Blocks.log, 1);
		world.setBlockMetadataWithNotify(i + 1, j + 42, k + 15, 1, 2);
		setBlock(world, i + 1, j + 42, k + 16, Blocks.log, 1);
		world.setBlockMetadataWithNotify(i + 1, j + 42, k + 16, 1, 2);
		setBlock(world, i + 1, j + 42, k + 17, Blocks.log, 1);
		world.setBlockMetadataWithNotify(i + 1, j + 42, k + 17, 1, 2);
		setBlock(world, i + 1, j + 42, k + 26, Blocks.leaves, 7);
		world.setBlockMetadataWithNotify(i + 1, j + 42, k + 26, 7, 2);
		setBlock(world, i + 1, j + 42, k + 27, Blocks.leaves, 7);
		world.setBlockMetadataWithNotify(i + 1, j + 42, k + 27, 7, 2);
		setBlock(world, i + 1, j + 42, k + 28, Blocks.leaves, 7);
		world.setBlockMetadataWithNotify(i + 1, j + 42, k + 28, 7, 2);
		setBlock(world, i + 1, j + 42, k + 31, Blocks.log, 3);
		world.setBlockMetadataWithNotify(i + 1, j + 42, k + 31, 3, 2);
		setBlock(world, i + 1, j + 43, k + 0, Blocks.log, 3);
		world.setBlockMetadataWithNotify(i + 1, j + 43, k + 0, 3, 2);
		setBlock(world, i + 1, j + 43, k + 1, Blocks.leaves, 7);
		world.setBlockMetadataWithNotify(i + 1, j + 43, k + 1, 7, 2);
		setBlock(world, i + 1, j + 43, k + 2, Blocks.leaves, 7);
		world.setBlockMetadataWithNotify(i + 1, j + 43, k + 2, 7, 2);
		setBlock(world, i + 1, j + 43, k + 9, Blocks.log, 1);
		world.setBlockMetadataWithNotify(i + 1, j + 43, k + 9, 1, 2);
		setBlock(world, i + 1, j + 43, k + 10, Blocks.log, 1);
		world.setBlockMetadataWithNotify(i + 1, j + 43, k + 10, 1, 2);
		setBlock(world, i + 1, j + 43, k + 11, Blocks.log, 1);
		world.setBlockMetadataWithNotify(i + 1, j + 43, k + 11, 1, 2);
		setBlock(world, i + 1, j + 43, k + 12, Blocks.log, 1);
		world.setBlockMetadataWithNotify(i + 1, j + 43, k + 12, 1, 2);
		setBlock(world, i + 1, j + 43, k + 13, Blocks.log, 1);
		world.setBlockMetadataWithNotify(i + 1, j + 43, k + 13, 1, 2);
		setBlock(world, i + 1, j + 43, k + 14, Blocks.log, 1);
		world.setBlockMetadataWithNotify(i + 1, j + 43, k + 14, 1, 2);
		setBlock(world, i + 1, j + 43, k + 15, Blocks.log, 1);
		world.setBlockMetadataWithNotify(i + 1, j + 43, k + 15, 1, 2);
		setBlock(world, i + 1, j + 43, k + 27, Blocks.leaves, 7);
		world.setBlockMetadataWithNotify(i + 1, j + 43, k + 27, 7, 2);
		setBlock(world, i + 1, j + 43, k + 28, Blocks.leaves, 7);
		world.setBlockMetadataWithNotify(i + 1, j + 43, k + 28, 7, 2);
		setBlock(world, i + 1, j + 43, k + 29, Blocks.leaves, 7);
		world.setBlockMetadataWithNotify(i + 1, j + 43, k + 29, 7, 2);
		setBlock(world, i + 1, j + 43, k + 30, Blocks.log, 3);
		world.setBlockMetadataWithNotify(i + 1, j + 43, k + 30, 3, 2);
		setBlock(world, i + 1, j + 43, k + 31, Blocks.leaves, 7);
		world.setBlockMetadataWithNotify(i + 1, j + 43, k + 31, 7, 2);
		setBlock(world, i + 1, j + 44, k + 0, Blocks.leaves, 7);
		world.setBlockMetadataWithNotify(i + 1, j + 44, k + 0, 7, 2);
		setBlock(world, i + 1, j + 44, k + 1, Blocks.leaves, 7);
		world.setBlockMetadataWithNotify(i + 1, j + 44, k + 1, 7, 2);
		setBlock(world, i + 1, j + 44, k + 2, Blocks.leaves, 7);
		world.setBlockMetadataWithNotify(i + 1, j + 44, k + 2, 7, 2);
		setBlock(world, i + 1, j + 44, k + 28, Blocks.leaves, 7);
		world.setBlockMetadataWithNotify(i + 1, j + 44, k + 28, 7, 2);
		setBlock(world, i + 1, j + 44, k + 29, Blocks.leaves, 7);
		world.setBlockMetadataWithNotify(i + 1, j + 44, k + 29, 7, 2);
		setBlock(world, i + 1, j + 44, k + 30, Blocks.leaves, 7);
		world.setBlockMetadataWithNotify(i + 1, j + 44, k + 30, 7, 2);
		setBlock(world, i + 1, j + 44, k + 31, Blocks.leaves, 7);
		world.setBlockMetadataWithNotify(i + 1, j + 44, k + 31, 7, 2);
		setBlock(world, i + 1, j + 45, k + 0, Blocks.leaves, 7);
		world.setBlockMetadataWithNotify(i + 1, j + 45, k + 0, 7, 2);
		setBlock(world, i + 1, j + 45, k + 1, Blocks.leaves, 7);
		world.setBlockMetadataWithNotify(i + 1, j + 45, k + 1, 7, 2);
		setBlock(world, i + 1, j + 45, k + 29, Blocks.leaves, 7);
		world.setBlockMetadataWithNotify(i + 1, j + 45, k + 29, 7, 2);
		setBlock(world, i + 1, j + 45, k + 30, Blocks.leaves, 7);
		world.setBlockMetadataWithNotify(i + 1, j + 45, k + 30, 7, 2);
		setBlock(world, i + 1, j + 45, k + 31, Blocks.leaves, 7);
		world.setBlockMetadataWithNotify(i + 1, j + 45, k + 31, 7, 2);
		setBlock(world, i + 1, j + 46, k + 0, Blocks.leaves, 7);
		world.setBlockMetadataWithNotify(i + 1, j + 46, k + 0, 7, 2);
		setBlock(world, i + 1, j + 46, k + 26, Blocks.leaves, 7);
		world.setBlockMetadataWithNotify(i + 1, j + 46, k + 26, 7, 2);
		setBlock(world, i + 1, j + 46, k + 27, Blocks.leaves, 7);
		world.setBlockMetadataWithNotify(i + 1, j + 46, k + 27, 7, 2);
		setBlock(world, i + 1, j + 46, k + 28, Blocks.leaves, 7);
		world.setBlockMetadataWithNotify(i + 1, j + 46, k + 28, 7, 2);
		setBlock(world, i + 1, j + 46, k + 29, Blocks.leaves, 7);
		world.setBlockMetadataWithNotify(i + 1, j + 46, k + 29, 7, 2);
		setBlock(world, i + 1, j + 46, k + 30, Blocks.leaves, 7);
		world.setBlockMetadataWithNotify(i + 1, j + 46, k + 30, 7, 2);
		setBlock(world, i + 1, j + 46, k + 31, Blocks.leaves, 7);
		world.setBlockMetadataWithNotify(i + 1, j + 46, k + 31, 7, 2);
		setBlock(world, i + 1, j + 47, k + 27, Blocks.leaves, 7);
		world.setBlockMetadataWithNotify(i + 1, j + 47, k + 27, 7, 2);
		setBlock(world, i + 1, j + 47, k + 28, Blocks.leaves, 7);
		world.setBlockMetadataWithNotify(i + 1, j + 47, k + 28, 7, 2);
		setBlock(world, i + 1, j + 47, k + 29, Blocks.leaves, 7);
		world.setBlockMetadataWithNotify(i + 1, j + 47, k + 29, 7, 2);
		setBlock(world, i + 1, j + 47, k + 30, Blocks.leaves, 7);
		world.setBlockMetadataWithNotify(i + 1, j + 47, k + 30, 7, 2);
		setBlock(world, i + 1, j + 47, k + 31, Blocks.leaves, 7);
		world.setBlockMetadataWithNotify(i + 1, j + 47, k + 31, 7, 2);
		setBlock(world, i + 1, j + 48, k + 27, Blocks.vine, 15);
		world.setBlockMetadataWithNotify(i + 1, j + 48, k + 27, 15, 2);
		setBlock(world, i + 1, j + 48, k + 28, Blocks.leaves, 7);
		world.setBlockMetadataWithNotify(i + 1, j + 48, k + 28, 7, 2);
		setBlock(world, i + 1, j + 48, k + 30, Blocks.leaves, 7);
		world.setBlockMetadataWithNotify(i + 1, j + 48, k + 30, 7, 2);
		setBlock(world, i + 1, j + 48, k + 31, Blocks.leaves, 7);
		world.setBlockMetadataWithNotify(i + 1, j + 48, k + 31, 7, 2);
		setBlock(world, i + 1, j + 49, k + 0, Blocks.leaves, 7);
		world.setBlockMetadataWithNotify(i + 1, j + 49, k + 0, 7, 2);
		setBlock(world, i + 1, j + 49, k + 27, Blocks.vine, 15);
		world.setBlockMetadataWithNotify(i + 1, j + 49, k + 27, 15, 2);
		setBlock(world, i + 1, j + 49, k + 28, Blocks.vine, 15);
		world.setBlockMetadataWithNotify(i + 1, j + 49, k + 28, 15, 2);
		setBlock(world, i + 1, j + 49, k + 31, Blocks.leaves, 7);
		world.setBlockMetadataWithNotify(i + 1, j + 49, k + 31, 7, 2);
		setBlock(world, i + 1, j + 63, k + 31, Blocks.log, 1);
		world.setBlockMetadataWithNotify(i + 1, j + 63, k + 31, 1, 2);
		setBlock(world, i + 1, j + 64, k + 31, Blocks.log, 1);
		world.setBlockMetadataWithNotify(i + 1, j + 64, k + 31, 1, 2);
		setBlock(world, i + 1, j + 65, k + 27, Blocks.log, 1);
		world.setBlockMetadataWithNotify(i + 1, j + 65, k + 27, 1, 2);
		setBlock(world, i + 1, j + 65, k + 28, Blocks.log, 1);
		world.setBlockMetadataWithNotify(i + 1, j + 65, k + 28, 1, 2);
		setBlock(world, i + 1, j + 65, k + 29, Blocks.planks, 5);
		world.setBlockMetadataWithNotify(i + 1, j + 65, k + 29, 5, 2);
		setBlock(world, i + 1, j + 65, k + 30, Blocks.planks, 5);
		world.setBlockMetadataWithNotify(i + 1, j + 65, k + 30, 5, 2);
		setBlock(world, i + 1, j + 65, k + 31, Blocks.planks, 5);
		world.setBlockMetadataWithNotify(i + 1, j + 65, k + 31, 5, 2);
		setBlock(world, i + 1, j + 70, k + 25, Blocks.log, 1);
		world.setBlockMetadataWithNotify(i + 1, j + 70, k + 25, 1, 2);
		setBlock(world, i + 1, j + 70, k + 26, Blocks.log, 1);
		world.setBlockMetadataWithNotify(i + 1, j + 70, k + 26, 1, 2);
		setBlock(world, i + 1, j + 70, k + 27, Blocks.log, 1);
		world.setBlockMetadataWithNotify(i + 1, j + 70, k + 27, 1, 2);
		setBlock(world, i + 1, j + 70, k + 28, Blocks.log, 1);
		world.setBlockMetadataWithNotify(i + 1, j + 70, k + 28, 1, 2);
		setBlock(world, i + 1, j + 70, k + 29, Blocks.log, 1);
		world.setBlockMetadataWithNotify(i + 1, j + 70, k + 29, 1, 2);
		setBlock(world, i + 1, j + 71, k + 26, Blocks.log, 1);
		world.setBlockMetadataWithNotify(i + 1, j + 71, k + 26, 1, 2);
		setBlock(world, i + 1, j + 71, k + 27, Blocks.log, 1);
		world.setBlockMetadataWithNotify(i + 1, j + 71, k + 27, 1, 2);
		setBlock(world, i + 1, j + 71, k + 28, Blocks.log, 1);
		world.setBlockMetadataWithNotify(i + 1, j + 71, k + 28, 1, 2);
		setBlock(world, i + 1, j + 71, k + 29, Blocks.log, 1);
		world.setBlockMetadataWithNotify(i + 1, j + 71, k + 29, 1, 2);
		setBlock(world, i + 1, j + 71, k + 30, Blocks.log, 1);
		world.setBlockMetadataWithNotify(i + 1, j + 71, k + 30, 1, 2);
		setBlock(world, i + 1, j + 72, k + 28, Blocks.log, 1);
		world.setBlockMetadataWithNotify(i + 1, j + 72, k + 28, 1, 2);
		setBlock(world, i + 1, j + 72, k + 29, Blocks.log, 1);
		world.setBlockMetadataWithNotify(i + 1, j + 72, k + 29, 1, 2);
		setBlock(world, i + 1, j + 72, k + 30, Blocks.log, 1);
		world.setBlockMetadataWithNotify(i + 1, j + 72, k + 30, 1, 2);
		setBlock(world, i + 1, j + 72, k + 31, Blocks.log, 1);
		world.setBlockMetadataWithNotify(i + 1, j + 72, k + 31, 1, 2);
		setBlock(world, i + 2, j + 22, k + 0, Blocks.log, 3);
		world.setBlockMetadataWithNotify(i + 2, j + 22, k + 0, 3, 2);
		setBlock(world, i + 2, j + 22, k + 1, Blocks.log, 3);
		world.setBlockMetadataWithNotify(i + 2, j + 22, k + 1, 3, 2);
		setBlock(world, i + 2, j + 30, k + 27, Blocks.log, 3);
		world.setBlockMetadataWithNotify(i + 2, j + 30, k + 27, 3, 2);
		setBlock(world, i + 2, j + 30, k + 28, Blocks.log, 3);
		world.setBlockMetadataWithNotify(i + 2, j + 30, k + 28, 3, 2);
		setBlock(world, i + 2, j + 31, k + 24, Blocks.leaves, 7);
		world.setBlockMetadataWithNotify(i + 2, j + 31, k + 24, 7, 2);
		setBlock(world, i + 2, j + 31, k + 25, Blocks.leaves, 7);
		world.setBlockMetadataWithNotify(i + 2, j + 31, k + 25, 7, 2);
		setBlock(world, i + 2, j + 31, k + 26, Blocks.log, 3);
		world.setBlockMetadataWithNotify(i + 2, j + 31, k + 26, 3, 2);
		setBlock(world, i + 2, j + 31, k + 27, Blocks.leaves, 7);
		world.setBlockMetadataWithNotify(i + 2, j + 31, k + 27, 7, 2);
		/*      */
		generate91(world, rand, i, j, k);
		return true;
		/*      */}

	/*      */
	/*      */public boolean generate91(World world, Random rand, int i, int j, int k)
	/*      */
	{
		setBlock(world, i + 2, j + 31, k + 28, Blocks.leaves, 7);
		world.setBlockMetadataWithNotify(i + 2, j + 31, k + 28, 7, 2);
		setBlock(world, i + 2, j + 32, k + 20, Blocks.leaves, 15);
		world.setBlockMetadataWithNotify(i + 2, j + 32, k + 20, 15, 2);
		setBlock(world, i + 2, j + 32, k + 21, Blocks.leaves, 7);
		world.setBlockMetadataWithNotify(i + 2, j + 32, k + 21, 7, 2);
		setBlock(world, i + 2, j + 32, k + 22, Blocks.leaves, 7);
		world.setBlockMetadataWithNotify(i + 2, j + 32, k + 22, 7, 2);
		setBlock(world, i + 2, j + 32, k + 23, Blocks.leaves, 7);
		world.setBlockMetadataWithNotify(i + 2, j + 32, k + 23, 7, 2);
		setBlock(world, i + 2, j + 32, k + 24, Blocks.leaves, 7);
		world.setBlockMetadataWithNotify(i + 2, j + 32, k + 24, 7, 2);
		setBlock(world, i + 2, j + 32, k + 25, Blocks.leaves, 7);
		world.setBlockMetadataWithNotify(i + 2, j + 32, k + 25, 7, 2);
		setBlock(world, i + 2, j + 32, k + 26, Blocks.leaves, 7);
		world.setBlockMetadataWithNotify(i + 2, j + 32, k + 26, 7, 2);
		setBlock(world, i + 2, j + 32, k + 27, Blocks.leaves, 7);
		world.setBlockMetadataWithNotify(i + 2, j + 32, k + 27, 7, 2);
		setBlock(world, i + 2, j + 32, k + 28, Blocks.leaves, 7);
		world.setBlockMetadataWithNotify(i + 2, j + 32, k + 28, 7, 2);
		setBlock(world, i + 2, j + 33, k + 21, Blocks.leaves, 15);
		world.setBlockMetadataWithNotify(i + 2, j + 33, k + 21, 15, 2);
		setBlock(world, i + 2, j + 33, k + 22, Blocks.leaves, 15);
		world.setBlockMetadataWithNotify(i + 2, j + 33, k + 22, 15, 2);
		setBlock(world, i + 2, j + 33, k + 23, Blocks.leaves, 15);
		world.setBlockMetadataWithNotify(i + 2, j + 33, k + 23, 15, 2);
		setBlock(world, i + 2, j + 33, k + 25, Blocks.leaves, 7);
		world.setBlockMetadataWithNotify(i + 2, j + 33, k + 25, 7, 2);
		setBlock(world, i + 2, j + 33, k + 26, Blocks.leaves, 7);
		world.setBlockMetadataWithNotify(i + 2, j + 33, k + 26, 7, 2);
		setBlock(world, i + 2, j + 33, k + 27, Blocks.leaves, 7);
		world.setBlockMetadataWithNotify(i + 2, j + 33, k + 27, 7, 2);
		setBlock(world, i + 2, j + 34, k + 26, Blocks.leaves, 7);
		world.setBlockMetadataWithNotify(i + 2, j + 34, k + 26, 7, 2);
		setBlock(world, i + 2, j + 35, k + 7, Blocks.log, 1);
		world.setBlockMetadataWithNotify(i + 2, j + 35, k + 7, 1, 2);
		setBlock(world, i + 2, j + 35, k + 8, Blocks.log, 1);
		world.setBlockMetadataWithNotify(i + 2, j + 35, k + 8, 1, 2);
		setBlock(world, i + 2, j + 35, k + 9, Blocks.planks, 5);
		world.setBlockMetadataWithNotify(i + 2, j + 35, k + 9, 5, 2);
		setBlock(world, i + 2, j + 35, k + 10, Blocks.planks, 5);
		world.setBlockMetadataWithNotify(i + 2, j + 35, k + 10, 5, 2);
		setBlock(world, i + 2, j + 35, k + 11, Blocks.planks, 5);
		world.setBlockMetadataWithNotify(i + 2, j + 35, k + 11, 5, 2);
		setBlock(world, i + 2, j + 35, k + 12, Blocks.planks, 5);
		world.setBlockMetadataWithNotify(i + 2, j + 35, k + 12, 5, 2);
		setBlock(world, i + 2, j + 35, k + 13, Blocks.planks, 5);
		world.setBlockMetadataWithNotify(i + 2, j + 35, k + 13, 5, 2);
		setBlock(world, i + 2, j + 35, k + 14, Blocks.planks, 5);
		world.setBlockMetadataWithNotify(i + 2, j + 35, k + 14, 5, 2);
		setBlock(world, i + 2, j + 35, k + 15, Blocks.planks, 5);
		world.setBlockMetadataWithNotify(i + 2, j + 35, k + 15, 5, 2);
		setBlock(world, i + 2, j + 35, k + 16, Blocks.log, 1);
		world.setBlockMetadataWithNotify(i + 2, j + 35, k + 16, 1, 2);
		setBlock(world, i + 2, j + 35, k + 17, Blocks.log, 1);
		world.setBlockMetadataWithNotify(i + 2, j + 35, k + 17, 1, 2);
		setBlock(world, i + 2, j + 35, k + 21, Blocks.planks, 5);
		world.setBlockMetadataWithNotify(i + 2, j + 35, k + 21, 5, 2);
		setBlock(world, i + 2, j + 35, k + 22, Blocks.planks, 5);
		world.setBlockMetadataWithNotify(i + 2, j + 35, k + 22, 5, 2);
		setBlock(world, i + 2, j + 35, k + 23, Blocks.planks, 5);
		world.setBlockMetadataWithNotify(i + 2, j + 35, k + 23, 5, 2);
		setBlock(world, i + 2, j + 35, k + 24, Blocks.planks, 5);
		world.setBlockMetadataWithNotify(i + 2, j + 35, k + 24, 5, 2);
		setBlock(world, i + 2, j + 35, k + 25, Blocks.planks, 5);
		world.setBlockMetadataWithNotify(i + 2, j + 35, k + 25, 5, 2);
		setBlock(world, i + 2, j + 37, k + 31, Blocks.log, 3);
		world.setBlockMetadataWithNotify(i + 2, j + 37, k + 31, 3, 2);
		setBlock(world, i + 2, j + 38, k + 0, Blocks.leaves, 7);
		world.setBlockMetadataWithNotify(i + 2, j + 38, k + 0, 7, 2);
		setBlock(world, i + 2, j + 38, k + 1, Blocks.leaves, 7);
		world.setBlockMetadataWithNotify(i + 2, j + 38, k + 1, 7, 2);
		setBlock(world, i + 2, j + 39, k + 0, Blocks.leaves, 7);
		world.setBlockMetadataWithNotify(i + 2, j + 39, k + 0, 7, 2);
		setBlock(world, i + 2, j + 39, k + 4, Blocks.log, 1);
		world.setBlockMetadataWithNotify(i + 2, j + 39, k + 4, 1, 2);
		setBlock(world, i + 2, j + 39, k + 5, Blocks.log, 1);
		world.setBlockMetadataWithNotify(i + 2, j + 39, k + 5, 1, 2);
		setBlock(world, i + 2, j + 39, k + 6, Blocks.log, 1);
		world.setBlockMetadataWithNotify(i + 2, j + 39, k + 6, 1, 2);
		setBlock(world, i + 2, j + 39, k + 7, Blocks.log, 1);
		world.setBlockMetadataWithNotify(i + 2, j + 39, k + 7, 1, 2);
		setBlock(world, i + 2, j + 39, k + 17, Blocks.log, 1);
		world.setBlockMetadataWithNotify(i + 2, j + 39, k + 17, 1, 2);
		setBlock(world, i + 2, j + 39, k + 18, Blocks.log, 1);
		world.setBlockMetadataWithNotify(i + 2, j + 39, k + 18, 1, 2);
		setBlock(world, i + 2, j + 39, k + 19, Blocks.log, 1);
		world.setBlockMetadataWithNotify(i + 2, j + 39, k + 19, 1, 2);
		setBlock(world, i + 2, j + 39, k + 20, Blocks.log, 1);
		world.setBlockMetadataWithNotify(i + 2, j + 39, k + 20, 1, 2);
		setBlock(world, i + 2, j + 40, k + 5, Blocks.log, 1);
		world.setBlockMetadataWithNotify(i + 2, j + 40, k + 5, 1, 2);
		setBlock(world, i + 2, j + 40, k + 6, Blocks.log, 1);
		world.setBlockMetadataWithNotify(i + 2, j + 40, k + 6, 1, 2);
		setBlock(world, i + 2, j + 40, k + 7, Blocks.log, 1);
		world.setBlockMetadataWithNotify(i + 2, j + 40, k + 7, 1, 2);
		setBlock(world, i + 2, j + 40, k + 8, Blocks.log, 1);
		world.setBlockMetadataWithNotify(i + 2, j + 40, k + 8, 1, 2);
		setBlock(world, i + 2, j + 40, k + 9, Blocks.log, 1);
		world.setBlockMetadataWithNotify(i + 2, j + 40, k + 9, 1, 2);
		setBlock(world, i + 2, j + 40, k + 10, Blocks.log, 1);
		world.setBlockMetadataWithNotify(i + 2, j + 40, k + 10, 1, 2);
		setBlock(world, i + 2, j + 40, k + 11, Blocks.log, 1);
		world.setBlockMetadataWithNotify(i + 2, j + 40, k + 11, 1, 2);
		setBlock(world, i + 2, j + 40, k + 12, Blocks.log, 1);
		world.setBlockMetadataWithNotify(i + 2, j + 40, k + 12, 1, 2);
		setBlock(world, i + 2, j + 40, k + 13, Blocks.log, 1);
		world.setBlockMetadataWithNotify(i + 2, j + 40, k + 13, 1, 2);
		setBlock(world, i + 2, j + 40, k + 14, Blocks.log, 1);
		world.setBlockMetadataWithNotify(i + 2, j + 40, k + 14, 1, 2);
		setBlock(world, i + 2, j + 40, k + 15, Blocks.log, 1);
		world.setBlockMetadataWithNotify(i + 2, j + 40, k + 15, 1, 2);
		setBlock(world, i + 2, j + 40, k + 16, Blocks.log, 1);
		world.setBlockMetadataWithNotify(i + 2, j + 40, k + 16, 1, 2);
		setBlock(world, i + 2, j + 40, k + 17, Blocks.log, 1);
		world.setBlockMetadataWithNotify(i + 2, j + 40, k + 17, 1, 2);
		setBlock(world, i + 2, j + 40, k + 18, Blocks.log, 1);
		world.setBlockMetadataWithNotify(i + 2, j + 40, k + 18, 1, 2);
		setBlock(world, i + 2, j + 40, k + 19, Blocks.log, 1);
		world.setBlockMetadataWithNotify(i + 2, j + 40, k + 19, 1, 2);
		setBlock(world, i + 2, j + 41, k + 0, Blocks.leaves, 7);
		world.setBlockMetadataWithNotify(i + 2, j + 41, k + 0, 7, 2);
		setBlock(world, i + 2, j + 41, k + 1, Blocks.leaves, 7);
		world.setBlockMetadataWithNotify(i + 2, j + 41, k + 1, 7, 2);
		setBlock(world, i + 2, j + 41, k + 2, Blocks.leaves, 7);
		world.setBlockMetadataWithNotify(i + 2, j + 41, k + 2, 7, 2);
		setBlock(world, i + 2, j + 41, k + 5, Blocks.log, 1);
		world.setBlockMetadataWithNotify(i + 2, j + 41, k + 5, 1, 2);
		setBlock(world, i + 2, j + 41, k + 6, Blocks.log, 1);
		world.setBlockMetadataWithNotify(i + 2, j + 41, k + 6, 1, 2);
		setBlock(world, i + 2, j + 41, k + 7, Blocks.log, 1);
		world.setBlockMetadataWithNotify(i + 2, j + 41, k + 7, 1, 2);
		setBlock(world, i + 2, j + 41, k + 8, Blocks.log, 1);
		/* 1000 */world.setBlockMetadataWithNotify(i + 2, j + 41, k + 8, 1, 2);
		/* 1001 */setBlock(world, i + 2, j + 41, k + 9, Blocks.log, 1);
		/* 1002 */world.setBlockMetadataWithNotify(i + 2, j + 41, k + 9, 1, 2);
		/* 1003 */setBlock(world, i + 2, j + 41, k + 10, Blocks.log, 1);
		/* 1004 */world.setBlockMetadataWithNotify(i + 2, j + 41, k + 10, 1, 2);
		/* 1005 */setBlock(world, i + 2, j + 41, k + 11, Blocks.log, 1);
		/* 1006 */world.setBlockMetadataWithNotify(i + 2, j + 41, k + 11, 1, 2);
		/* 1007 */setBlock(world, i + 2, j + 41, k + 12, Blocks.log, 1);
		/* 1008 */world.setBlockMetadataWithNotify(i + 2, j + 41, k + 12, 1, 2);
		/* 1009 */setBlock(world, i + 2, j + 41, k + 13, Blocks.log, 1);
		/* 1010 */world.setBlockMetadataWithNotify(i + 2, j + 41, k + 13, 1, 2);
		/* 1011 */setBlock(world, i + 2, j + 41, k + 14, Blocks.log, 1);
		/* 1012 */world.setBlockMetadataWithNotify(i + 2, j + 41, k + 14, 1, 2);
		/* 1013 */setBlock(world, i + 2, j + 41, k + 15, Blocks.log, 1);
		/* 1014 */world.setBlockMetadataWithNotify(i + 2, j + 41, k + 15, 1, 2);
		/* 1015 */setBlock(world, i + 2, j + 41, k + 16, Blocks.log, 1);
		/* 1016 */world.setBlockMetadataWithNotify(i + 2, j + 41, k + 16, 1, 2);
		/* 1017 */setBlock(world, i + 2, j + 41, k + 17, Blocks.log, 1);
		/* 1018 */world.setBlockMetadataWithNotify(i + 2, j + 41, k + 17, 1, 2);
		/* 1019 */setBlock(world, i + 2, j + 41, k + 18, Blocks.log, 1);
		/* 1020 */world.setBlockMetadataWithNotify(i + 2, j + 41, k + 18, 1, 2);
		/* 1021 */setBlock(world, i + 2, j + 41, k + 19, Blocks.log, 1);
		/* 1022 */world.setBlockMetadataWithNotify(i + 2, j + 41, k + 19, 1, 2);
		/* 1023 */setBlock(world, i + 2, j + 41, k + 31, Blocks.log, 3);
		/* 1024 */world.setBlockMetadataWithNotify(i + 2, j + 41, k + 31, 3, 2);
		/* 1025 */setBlock(world, i + 2, j + 42, k + 0, Blocks.leaves, 7);
		/* 1026 */world.setBlockMetadataWithNotify(i + 2, j + 42, k + 0, 7, 2);
		/* 1027 */setBlock(world, i + 2, j + 42, k + 1, Blocks.leaves, 7);
		/* 1028 */world.setBlockMetadataWithNotify(i + 2, j + 42, k + 1, 7, 2);
		/* 1029 */setBlock(world, i + 2, j + 42, k + 6, Blocks.log, 1);
		/* 1030 */world.setBlockMetadataWithNotify(i + 2, j + 42, k + 6, 1, 2);
		/* 1031 */setBlock(world, i + 2, j + 42, k + 7, Blocks.log, 1);
		/* 1032 */world.setBlockMetadataWithNotify(i + 2, j + 42, k + 7, 1, 2);
		/* 1033 */setBlock(world, i + 2, j + 42, k + 8, Blocks.log, 1);
		/* 1034 */world.setBlockMetadataWithNotify(i + 2, j + 42, k + 8, 1, 2);
		/* 1035 */setBlock(world, i + 2, j + 42, k + 9, Blocks.log, 1);
		/* 1036 */world.setBlockMetadataWithNotify(i + 2, j + 42, k + 9, 1, 2);
		/* 1037 */setBlock(world, i + 2, j + 42, k + 10, Blocks.log, 1);
		/* 1038 */world.setBlockMetadataWithNotify(i + 2, j + 42, k + 10, 1, 2);
		/* 1039 */setBlock(world, i + 2, j + 42, k + 11, Blocks.log, 1);
		/* 1040 */world.setBlockMetadataWithNotify(i + 2, j + 42, k + 11, 1, 2);
		/* 1041 */setBlock(world, i + 2, j + 42, k + 12, Blocks.log, 1);
		/* 1042 */world.setBlockMetadataWithNotify(i + 2, j + 42, k + 12, 1, 2);
		/* 1043 */setBlock(world, i + 2, j + 42, k + 13, Blocks.log, 1);
		/* 1044 */world.setBlockMetadataWithNotify(i + 2, j + 42, k + 13, 1, 2);
		/* 1045 */setBlock(world, i + 2, j + 42, k + 14, Blocks.log, 1);
		/* 1046 */world.setBlockMetadataWithNotify(i + 2, j + 42, k + 14, 1, 2);
		/* 1047 */setBlock(world, i + 2, j + 42, k + 15, Blocks.log, 1);
		/* 1048 */world.setBlockMetadataWithNotify(i + 2, j + 42, k + 15, 1, 2);
		/* 1049 */setBlock(world, i + 2, j + 42, k + 16, Blocks.log, 1);
		/* 1050 */world.setBlockMetadataWithNotify(i + 2, j + 42, k + 16, 1, 2);
		/* 1051 */setBlock(world, i + 2, j + 42, k + 17, Blocks.log, 1);
		/* 1052 */world.setBlockMetadataWithNotify(i + 2, j + 42, k + 17, 1, 2);
		/* 1053 */setBlock(world, i + 2, j + 42, k + 18, Blocks.log, 1);
		/* 1054 */world.setBlockMetadataWithNotify(i + 2, j + 42, k + 18, 1, 2);
		/* 1055 */setBlock(world, i + 2, j + 43, k + 0, Blocks.leaves, 7);
		/* 1056 */world.setBlockMetadataWithNotify(i + 2, j + 43, k + 0, 7, 2);
		/* 1057 */setBlock(world, i + 2, j + 43, k + 1, Blocks.leaves, 7);
		/* 1058 */world.setBlockMetadataWithNotify(i + 2, j + 43, k + 1, 7, 2);
		/* 1059 */setBlock(world, i + 2, j + 43, k + 2, Blocks.leaves, 7);
		/* 1060 */world.setBlockMetadataWithNotify(i + 2, j + 43, k + 2, 7, 2);
		/* 1061 */setBlock(world, i + 2, j + 43, k + 8, Blocks.log, 1);
		/* 1062 */world.setBlockMetadataWithNotify(i + 2, j + 43, k + 8, 1, 2);
		/* 1063 */setBlock(world, i + 2, j + 43, k + 9, Blocks.log, 1);
		/* 1064 */world.setBlockMetadataWithNotify(i + 2, j + 43, k + 9, 1, 2);
		/* 1065 */setBlock(world, i + 2, j + 43, k + 10, Blocks.log, 1);
		/* 1066 */world.setBlockMetadataWithNotify(i + 2, j + 43, k + 10, 1, 2);
		/* 1067 */setBlock(world, i + 2, j + 43, k + 11, Blocks.log, 1);
		/* 1068 */world.setBlockMetadataWithNotify(i + 2, j + 43, k + 11, 1, 2);
		/* 1069 */setBlock(world, i + 2, j + 43, k + 12, Blocks.log, 1);
		/* 1070 */world.setBlockMetadataWithNotify(i + 2, j + 43, k + 12, 1, 2);
		/* 1071 */setBlock(world, i + 2, j + 43, k + 13, Blocks.log, 1);
		/* 1072 */world.setBlockMetadataWithNotify(i + 2, j + 43, k + 13, 1, 2);
		/* 1073 */setBlock(world, i + 2, j + 43, k + 14, Blocks.log, 1);
		/* 1074 */world.setBlockMetadataWithNotify(i + 2, j + 43, k + 14, 1, 2);
		/* 1075 */setBlock(world, i + 2, j + 43, k + 15, Blocks.log, 1);
		/* 1076 */world.setBlockMetadataWithNotify(i + 2, j + 43, k + 15, 1, 2);
		/* 1077 */setBlock(world, i + 2, j + 43, k + 16, Blocks.log, 1);
		/* 1078 */world.setBlockMetadataWithNotify(i + 2, j + 43, k + 16, 1, 2);
		/* 1079 */setBlock(world, i + 2, j + 43, k + 28, Blocks.leaves, 7);
		/* 1080 */world.setBlockMetadataWithNotify(i + 2, j + 43, k + 28, 7, 2);
		/* 1081 */setBlock(world, i + 2, j + 43, k + 29, Blocks.leaves, 7);
		/* 1082 */world.setBlockMetadataWithNotify(i + 2, j + 43, k + 29, 7, 2);
		/* 1083 */setBlock(world, i + 2, j + 43, k + 30, Blocks.leaves, 7);
		/* 1084 */world.setBlockMetadataWithNotify(i + 2, j + 43, k + 30, 7, 2);
		/* 1085 */setBlock(world, i + 2, j + 43, k + 31, Blocks.leaves, 7);
		/* 1086 */world.setBlockMetadataWithNotify(i + 2, j + 43, k + 31, 7, 2);
		/* 1087 */setBlock(world, i + 2, j + 44, k + 0, Blocks.leaves, 7);
		/* 1088 */world.setBlockMetadataWithNotify(i + 2, j + 44, k + 0, 7, 2);
		/* 1089 */setBlock(world, i + 2, j + 44, k + 1, Blocks.leaves, 7);
		/* 1090 */world.setBlockMetadataWithNotify(i + 2, j + 44, k + 1, 7, 2);
		/* 1091 */setBlock(world, i + 2, j + 44, k + 29, Blocks.leaves, 7);
		/* 1092 */world.setBlockMetadataWithNotify(i + 2, j + 44, k + 29, 7, 2);
		/* 1093 */setBlock(world, i + 2, j + 44, k + 30, Blocks.leaves, 7);
		/* 1094 */world.setBlockMetadataWithNotify(i + 2, j + 44, k + 30, 7, 2);
		/* 1095 */setBlock(world, i + 2, j + 44, k + 31, Blocks.leaves, 7);
		/* 1096 */world.setBlockMetadataWithNotify(i + 2, j + 44, k + 31, 7, 2);
		/* 1097 */setBlock(world, i + 2, j + 45, k + 0, Blocks.leaves, 7);
		/* 1098 */world.setBlockMetadataWithNotify(i + 2, j + 45, k + 0, 7, 2);
		/* 1099 */setBlock(world, i + 2, j + 45, k + 29, Blocks.log, 3);
		/* 1100 */world.setBlockMetadataWithNotify(i + 2, j + 45, k + 29, 3, 2);
		/* 1101 */setBlock(world, i + 2, j + 45, k + 30, Blocks.leaves, 7);
		/* 1102 */world.setBlockMetadataWithNotify(i + 2, j + 45, k + 30, 7, 2);
		/* 1103 */setBlock(world, i + 2, j + 46, k + 26, Blocks.leaves, 7);
		/* 1104 */world.setBlockMetadataWithNotify(i + 2, j + 46, k + 26, 7, 2);
		/* 1105 */setBlock(world, i + 2, j + 46, k + 27, Blocks.leaves, 7);
		/* 1106 */world.setBlockMetadataWithNotify(i + 2, j + 46, k + 27, 7, 2);
		/* 1107 */setBlock(world, i + 2, j + 46, k + 28, Blocks.log, 3);
		/* 1108 */world.setBlockMetadataWithNotify(i + 2, j + 46, k + 28, 3, 2);
		/* 1109 */setBlock(world, i + 2, j + 46, k + 29, Blocks.leaves, 7);
		/* 1110 */world.setBlockMetadataWithNotify(i + 2, j + 46, k + 29, 7, 2);
		/* 1111 */setBlock(world, i + 2, j + 46, k + 30, Blocks.leaves, 7);
		/* 1112 */world.setBlockMetadataWithNotify(i + 2, j + 46, k + 30, 7, 2);
		/* 1113 */setBlock(world, i + 2, j + 46, k + 31, Blocks.leaves, 7);
		/* 1114 */world.setBlockMetadataWithNotify(i + 2, j + 46, k + 31, 7, 2);
		/* 1115 */setBlock(world, i + 2, j + 47, k + 26, Blocks.leaves, 7);
		/* 1116 */world.setBlockMetadataWithNotify(i + 2, j + 47, k + 26, 7, 2);
		/* 1117 */setBlock(world, i + 2, j + 47, k + 27, Blocks.leaves, 7);
		/* 1118 */world.setBlockMetadataWithNotify(i + 2, j + 47, k + 27, 7, 2);
		/* 1119 */setBlock(world, i + 2, j + 47, k + 28, Blocks.leaves, 7);
		/* 1120 */world.setBlockMetadataWithNotify(i + 2, j + 47, k + 28, 7, 2);
		/* 1121 */setBlock(world, i + 2, j + 47, k + 29, Blocks.leaves, 7);
		/* 1122 */world.setBlockMetadataWithNotify(i + 2, j + 47, k + 29, 7, 2);
		/* 1123 */setBlock(world, i + 2, j + 47, k + 30, Blocks.leaves, 7);
		/* 1124 */world.setBlockMetadataWithNotify(i + 2, j + 47, k + 30, 7, 2);
		/* 1125 */setBlock(world, i + 2, j + 47, k + 31, Blocks.leaves, 7);
		/* 1126 */world.setBlockMetadataWithNotify(i + 2, j + 47, k + 31, 7, 2);
		/* 1127 */setBlock(world, i + 2, j + 48, k + 27, Blocks.leaves, 7);
		/* 1128 */world.setBlockMetadataWithNotify(i + 2, j + 48, k + 27, 7, 2);
		/* 1129 */setBlock(world, i + 2, j + 48, k + 28, Blocks.leaves, 7);
		/* 1130 */world.setBlockMetadataWithNotify(i + 2, j + 48, k + 28, 7, 2);
		/* 1131 */setBlock(world, i + 2, j + 48, k + 29, Blocks.leaves, 7);
		/* 1132 */world.setBlockMetadataWithNotify(i + 2, j + 48, k + 29, 7, 2);
		/* 1133 */setBlock(world, i + 2, j + 48, k + 31, Blocks.leaves, 7);
		/* 1134 */world.setBlockMetadataWithNotify(i + 2, j + 48, k + 31, 7, 2);
		/* 1135 */setBlock(world, i + 2, j + 49, k + 0, Blocks.leaves, 7);
		/* 1136 */world.setBlockMetadataWithNotify(i + 2, j + 49, k + 0, 7, 2);
		/* 1137 */setBlock(world, i + 2, j + 49, k + 2, Blocks.leaves, 7);
		/* 1138 */world.setBlockMetadataWithNotify(i + 2, j + 49, k + 2, 7, 2);
		/* 1139 */setBlock(world, i + 2, j + 49, k + 3, Blocks.leaves, 7);
		/* 1140 */world.setBlockMetadataWithNotify(i + 2, j + 49, k + 3, 7, 2);
		/* 1141 */setBlock(world, i + 2, j + 49, k + 4, Blocks.leaves, 7);
		/* 1142 */world.setBlockMetadataWithNotify(i + 2, j + 49, k + 4, 7, 2);
		/* 1143 */setBlock(world, i + 2, j + 49, k + 27, Blocks.vine, 15);
		/* 1144 */world.setBlockMetadataWithNotify(i + 2, j + 49, k + 27, 15, 2);
		/* 1145 */setBlock(world, i + 2, j + 49, k + 28, Blocks.leaves, 7);
		/* 1146 */world.setBlockMetadataWithNotify(i + 2, j + 49, k + 28, 7, 2);
		/* 1147 */setBlock(world, i + 2, j + 50, k + 0, Blocks.leaves, 7);
		/* 1148 */world.setBlockMetadataWithNotify(i + 2, j + 50, k + 0, 7, 2);
		/* 1149 */setBlock(world, i + 2, j + 50, k + 3, Blocks.leaves, 7);
		/* 1150 */world.setBlockMetadataWithNotify(i + 2, j + 50, k + 3, 7, 2);
		/* 1151 */setBlock(world, i + 2, j + 53, k + 0, Blocks.leaves, 7);
		/* 1152 */world.setBlockMetadataWithNotify(i + 2, j + 53, k + 0, 7, 2);
		/* 1153 */setBlock(world, i + 2, j + 64, k + 31, Blocks.log, 1);
		/* 1154 */world.setBlockMetadataWithNotify(i + 2, j + 64, k + 31, 1, 2);
		/* 1155 */setBlock(world, i + 2, j + 65, k + 27, Blocks.log, 1);
		/* 1156 */world.setBlockMetadataWithNotify(i + 2, j + 65, k + 27, 1, 2);
		/* 1157 */setBlock(world, i + 2, j + 65, k + 28, Blocks.log, 1);
		/* 1158 */world.setBlockMetadataWithNotify(i + 2, j + 65, k + 28, 1, 2);
		/* 1159 */setBlock(world, i + 2, j + 65, k + 29, Blocks.planks, 5);
		/* 1160 */world.setBlockMetadataWithNotify(i + 2, j + 65, k + 29, 5, 2);
		/* 1161 */setBlock(world, i + 2, j + 65, k + 30, Blocks.planks, 5);
		/* 1162 */world.setBlockMetadataWithNotify(i + 2, j + 65, k + 30, 5, 2);
		/* 1163 */setBlock(world, i + 2, j + 65, k + 31, Blocks.planks, 5);
		/* 1164 */world.setBlockMetadataWithNotify(i + 2, j + 65, k + 31, 5, 2);
		/* 1165 */setBlock(world, i + 2, j + 70, k + 25, Blocks.log, 1);
		/* 1166 */world.setBlockMetadataWithNotify(i + 2, j + 70, k + 25, 1, 2);
		/* 1167 */setBlock(world, i + 2, j + 70, k + 26, Blocks.log, 1);
		/* 1168 */world.setBlockMetadataWithNotify(i + 2, j + 70, k + 26, 1, 2);
		/* 1169 */setBlock(world, i + 2, j + 70, k + 27, Blocks.log, 1);
		/* 1170 */world.setBlockMetadataWithNotify(i + 2, j + 70, k + 27, 1, 2);
		/* 1171 */setBlock(world, i + 2, j + 70, k + 28, Blocks.log, 1);
		/* 1172 */world.setBlockMetadataWithNotify(i + 2, j + 70, k + 28, 1, 2);
		/* 1173 */setBlock(world, i + 2, j + 70, k + 29, Blocks.log, 1);
		/* 1174 */world.setBlockMetadataWithNotify(i + 2, j + 70, k + 29, 1, 2);
		/* 1175 */setBlock(world, i + 2, j + 71, k + 26, Blocks.log, 1);
		/* 1176 */world.setBlockMetadataWithNotify(i + 2, j + 71, k + 26, 1, 2);
		/* 1177 */setBlock(world, i + 2, j + 71, k + 27, Blocks.log, 1);
		/* 1178 */world.setBlockMetadataWithNotify(i + 2, j + 71, k + 27, 1, 2);
		/* 1179 */setBlock(world, i + 2, j + 71, k + 28, Blocks.log, 1);
		/* 1180 */world.setBlockMetadataWithNotify(i + 2, j + 71, k + 28, 1, 2);
		/* 1181 */setBlock(world, i + 2, j + 71, k + 29, Blocks.log, 1);
		/* 1182 */world.setBlockMetadataWithNotify(i + 2, j + 71, k + 29, 1, 2);
		/* 1183 */setBlock(world, i + 2, j + 71, k + 30, Blocks.log, 1);
		/* 1184 */world.setBlockMetadataWithNotify(i + 2, j + 71, k + 30, 1, 2);
		/* 1185 */setBlock(world, i + 2, j + 72, k + 28, Blocks.log, 1);
		/* 1186 */world.setBlockMetadataWithNotify(i + 2, j + 72, k + 28, 1, 2);
		/* 1187 */setBlock(world, i + 2, j + 72, k + 29, Blocks.log, 1);
		/* 1188 */world.setBlockMetadataWithNotify(i + 2, j + 72, k + 29, 1, 2);
		/* 1189 */setBlock(world, i + 2, j + 72, k + 30, Blocks.log, 1);
		/* 1190 */world.setBlockMetadataWithNotify(i + 2, j + 72, k + 30, 1, 2);
		/* 1191 */setBlock(world, i + 2, j + 72, k + 31, Blocks.log, 1);
		/* 1192 */world.setBlockMetadataWithNotify(i + 2, j + 72, k + 31, 1, 2);
		/* 1193 */setBlock(world, i + 3, j + 26, k + 8, Blocks.leaves, 7);
		/* 1194 */world.setBlockMetadataWithNotify(i + 3, j + 26, k + 8, 7, 2);
		/* 1195 */setBlock(world, i + 3, j + 26, k + 9, Blocks.leaves, 7);
		/* 1196 */world.setBlockMetadataWithNotify(i + 3, j + 26, k + 9, 7, 2);
		/* 1197 */setBlock(world, i + 3, j + 26, k + 10, Blocks.leaves, 7);
		/* 1198 */world.setBlockMetadataWithNotify(i + 3, j + 26, k + 10, 7, 2);
		/* 1199 */setBlock(world, i + 3, j + 27, k + 9, Blocks.leaves, 7);
		/* 1200 */world.setBlockMetadataWithNotify(i + 3, j + 27, k + 9, 7, 2);
		/* 1201 */setBlock(world, i + 3, j + 30, k + 29, Blocks.log, 3);
		/* 1202 */world.setBlockMetadataWithNotify(i + 3, j + 30, k + 29, 3, 2);
		/* 1203 */setBlock(world, i + 3, j + 30, k + 30, Blocks.log, 3);
		/* 1204 */world.setBlockMetadataWithNotify(i + 3, j + 30, k + 30, 3, 2);
		/* 1205 */setBlock(world, i + 3, j + 31, k + 23, Blocks.log, 3);
		/* 1206 */world.setBlockMetadataWithNotify(i + 3, j + 31, k + 23, 3, 2);
		/* 1207 */setBlock(world, i + 3, j + 31, k + 24, Blocks.log, 3);
		/* 1208 */world.setBlockMetadataWithNotify(i + 3, j + 31, k + 24, 3, 2);
		/* 1209 */setBlock(world, i + 3, j + 31, k + 25, Blocks.log, 3);
		/* 1210 */world.setBlockMetadataWithNotify(i + 3, j + 31, k + 25, 3, 2);
		/* 1211 */setBlock(world, i + 3, j + 31, k + 26, Blocks.leaves, 7);
		/* 1212 */world.setBlockMetadataWithNotify(i + 3, j + 31, k + 26, 7, 2);
		/* 1213 */setBlock(world, i + 3, j + 31, k + 27, Blocks.leaves, 7);
		/* 1214 */world.setBlockMetadataWithNotify(i + 3, j + 31, k + 27, 7, 2);
		/* 1215 */setBlock(world, i + 3, j + 31, k + 28, Blocks.leaves, 7);
		/* 1216 */world.setBlockMetadataWithNotify(i + 3, j + 31, k + 28, 7, 2);
		/* 1217 */setBlock(world, i + 3, j + 32, k + 20, Blocks.leaves, 15);
		/* 1218 */world.setBlockMetadataWithNotify(i + 3, j + 32, k + 20, 15, 2);
		/* 1219 */setBlock(world, i + 3, j + 32, k + 21, Blocks.leaves, 15);
		/* 1220 */world.setBlockMetadataWithNotify(i + 3, j + 32, k + 21, 15, 2);
		/* 1221 */setBlock(world, i + 3, j + 32, k + 22, Blocks.log, 3);
		/* 1222 */world.setBlockMetadataWithNotify(i + 3, j + 32, k + 22, 3, 2);
		/* 1223 */setBlock(world, i + 3, j + 32, k + 23, Blocks.leaves, 7);
		/* 1224 */world.setBlockMetadataWithNotify(i + 3, j + 32, k + 23, 7, 2);
		/* 1225 */setBlock(world, i + 3, j + 32, k + 24, Blocks.leaves, 7);
		/* 1226 */world.setBlockMetadataWithNotify(i + 3, j + 32, k + 24, 7, 2);
		/* 1227 */setBlock(world, i + 3, j + 32, k + 25, Blocks.leaves, 7);
		/* 1228 */world.setBlockMetadataWithNotify(i + 3, j + 32, k + 25, 7, 2);
		/* 1229 */setBlock(world, i + 3, j + 32, k + 26, Blocks.leaves, 7);
		/* 1230 */world.setBlockMetadataWithNotify(i + 3, j + 32, k + 26, 7, 2);
		/* 1231 */setBlock(world, i + 3, j + 32, k + 27, Blocks.leaves, 7);
		/* 1232 */world.setBlockMetadataWithNotify(i + 3, j + 32, k + 27, 7, 2);
		/* 1233 */setBlock(world, i + 3, j + 33, k + 20, Blocks.leaves, 15);
		/* 1234 */world.setBlockMetadataWithNotify(i + 3, j + 33, k + 20, 15, 2);
		/* 1235 */setBlock(world, i + 3, j + 33, k + 21, Blocks.leaves, 15);
		/* 1236 */world.setBlockMetadataWithNotify(i + 3, j + 33, k + 21, 15, 2);
		/* 1237 */setBlock(world, i + 3, j + 33, k + 22, Blocks.leaves, 15);
		/* 1238 */world.setBlockMetadataWithNotify(i + 3, j + 33, k + 22, 15, 2);
		/* 1239 */setBlock(world, i + 3, j + 33, k + 23, Blocks.leaves, 15);
		/* 1240 */world.setBlockMetadataWithNotify(i + 3, j + 33, k + 23, 15, 2);
		/* 1241 */setBlock(world, i + 3, j + 33, k + 24, Blocks.leaves, 15);
		/* 1242 */world.setBlockMetadataWithNotify(i + 3, j + 33, k + 24, 15, 2);
		/* 1243 */setBlock(world, i + 3, j + 33, k + 26, Blocks.leaves, 7);
		/* 1244 */world.setBlockMetadataWithNotify(i + 3, j + 33, k + 26, 7, 2);
		/* 1245 */setBlock(world, i + 3, j + 34, k + 9, Blocks.leaves, 15);
		/* 1246 */world.setBlockMetadataWithNotify(i + 3, j + 34, k + 9, 15, 2);
		/* 1247 */setBlock(world, i + 3, j + 34, k + 10, Blocks.leaves, 15);
		/* 1248 */world.setBlockMetadataWithNotify(i + 3, j + 34, k + 10, 15, 2);
		/* 1249 */setBlock(world, i + 3, j + 34, k + 11, Blocks.leaves, 15);
		/* 1250 */world.setBlockMetadataWithNotify(i + 3, j + 34, k + 11, 15, 2);
		/* 1251 */setBlock(world, i + 3, j + 35, k + 7, Blocks.log, 1);
		/* 1252 */world.setBlockMetadataWithNotify(i + 3, j + 35, k + 7, 1, 2);
		/* 1253 */setBlock(world, i + 3, j + 35, k + 8, Blocks.planks, 5);
		/* 1254 */world.setBlockMetadataWithNotify(i + 3, j + 35, k + 8, 5, 2);
		/* 1255 */setBlock(world, i + 3, j + 35, k + 9, Blocks.log, 1);
		/* 1256 */world.setBlockMetadataWithNotify(i + 3, j + 35, k + 9, 1, 2);
		/* 1257 */setBlock(world, i + 3, j + 35, k + 10, Blocks.log, 1);
		/* 1258 */world.setBlockMetadataWithNotify(i + 3, j + 35, k + 10, 1, 2);
		/* 1259 */setBlock(world, i + 3, j + 35, k + 11, Blocks.log, 1);
		/* 1260 */world.setBlockMetadataWithNotify(i + 3, j + 35, k + 11, 1, 2);
		/* 1261 */setBlock(world, i + 3, j + 35, k + 12, Blocks.log, 1);
		/* 1262 */world.setBlockMetadataWithNotify(i + 3, j + 35, k + 12, 1, 2);
		/* 1263 */setBlock(world, i + 3, j + 35, k + 13, Blocks.log, 1);
		/* 1264 */world.setBlockMetadataWithNotify(i + 3, j + 35, k + 13, 1, 2);
		/* 1265 */setBlock(world, i + 3, j + 35, k + 14, Blocks.log, 1);
		/* 1266 */world.setBlockMetadataWithNotify(i + 3, j + 35, k + 14, 1, 2);
		/* 1267 */setBlock(world, i + 3, j + 35, k + 15, Blocks.log, 1);
		/* 1268 */world.setBlockMetadataWithNotify(i + 3, j + 35, k + 15, 1, 2);
		/* 1269 */setBlock(world, i + 3, j + 35, k + 16, Blocks.planks, 5);
		/* 1270 */world.setBlockMetadataWithNotify(i + 3, j + 35, k + 16, 5, 2);
		/* 1271 */setBlock(world, i + 3, j + 35, k + 17, Blocks.log, 1);
		/* 1272 */world.setBlockMetadataWithNotify(i + 3, j + 35, k + 17, 1, 2);
		/* 1273 */setBlock(world, i + 3, j + 35, k + 20, Blocks.planks, 5);
		/* 1274 */world.setBlockMetadataWithNotify(i + 3, j + 35, k + 20, 5, 2);
		/* 1275 */setBlock(world, i + 3, j + 35, k + 21, Blocks.planks, 5);
		/* 1276 */world.setBlockMetadataWithNotify(i + 3, j + 35, k + 21, 5, 2);
		/* 1277 */setBlock(world, i + 3, j + 35, k + 22, Blocks.planks, 5);
		/* 1278 */world.setBlockMetadataWithNotify(i + 3, j + 35, k + 22, 5, 2);
		/* 1279 */setBlock(world, i + 3, j + 35, k + 23, Blocks.planks, 5);
		/* 1280 */world.setBlockMetadataWithNotify(i + 3, j + 35, k + 23, 5, 2);
		/* 1281 */setBlock(world, i + 3, j + 35, k + 24, Blocks.planks, 5);
		/* 1282 */world.setBlockMetadataWithNotify(i + 3, j + 35, k + 24, 5, 2);
		/* 1283 */setBlock(world, i + 3, j + 35, k + 25, Blocks.planks, 5);
		/* 1284 */world.setBlockMetadataWithNotify(i + 3, j + 35, k + 25, 5, 2);
		/* 1285 */setBlock(world, i + 3, j + 36, k + 21, Blocks.torch, 5);
		/* 1286 */world.setBlockMetadataWithNotify(i + 3, j + 36, k + 21, 5, 2);
		/* 1287 */setBlock(world, i + 3, j + 36, k + 25, Blocks.torch, 5);
		/* 1288 */world.setBlockMetadataWithNotify(i + 3, j + 36, k + 25, 5, 2);
		/* 1289 */setBlock(world, i + 3, j + 37, k + 7, Blocks.torch, 5);
		/* 1290 */world.setBlockMetadataWithNotify(i + 3, j + 37, k + 7, 5, 2);
		/* 1291 */setBlock(world, i + 3, j + 37, k + 17, Blocks.torch, 5);
		/* 1292 */world.setBlockMetadataWithNotify(i + 3, j + 37, k + 17, 5, 2);
		/* 1293 */setBlock(world, i + 3, j + 38, k + 0, Blocks.leaves, 7);
		/* 1294 */world.setBlockMetadataWithNotify(i + 3, j + 38, k + 0, 7, 2);
		/* 1295 */setBlock(world, i + 3, j + 38, k + 1, Blocks.leaves, 7);
		/* 1296 */world.setBlockMetadataWithNotify(i + 3, j + 38, k + 1, 7, 2);
		/* 1297 */setBlock(world, i + 3, j + 39, k + 0, Blocks.leaves, 7);
		/* 1298 */world.setBlockMetadataWithNotify(i + 3, j + 39, k + 0, 7, 2);
		/* 1299 */setBlock(world, i + 3, j + 39, k + 1, Blocks.leaves, 7);
		/* 1300 */world.setBlockMetadataWithNotify(i + 3, j + 39, k + 1, 7, 2);
		/* 1301 */setBlock(world, i + 3, j + 39, k + 3, Blocks.log, 1);
		/* 1302 */world.setBlockMetadataWithNotify(i + 3, j + 39, k + 3, 1, 2);
		/* 1303 */setBlock(world, i + 3, j + 39, k + 4, Blocks.log, 1);
		/* 1304 */world.setBlockMetadataWithNotify(i + 3, j + 39, k + 4, 1, 2);
		/* 1305 */setBlock(world, i + 3, j + 39, k + 5, Blocks.log, 1);
		/* 1306 */world.setBlockMetadataWithNotify(i + 3, j + 39, k + 5, 1, 2);
		/* 1307 */setBlock(world, i + 3, j + 39, k + 6, Blocks.log, 1);
		/* 1308 */world.setBlockMetadataWithNotify(i + 3, j + 39, k + 6, 1, 2);
		/* 1309 */setBlock(world, i + 3, j + 39, k + 7, Blocks.log, 1);
		/* 1310 */world.setBlockMetadataWithNotify(i + 3, j + 39, k + 7, 1, 2);
		/* 1311 */setBlock(world, i + 3, j + 39, k + 17, Blocks.log, 1);
		/* 1312 */world.setBlockMetadataWithNotify(i + 3, j + 39, k + 17, 1, 2);
		/* 1313 */setBlock(world, i + 3, j + 39, k + 18, Blocks.log, 1);
		/* 1314 */world.setBlockMetadataWithNotify(i + 3, j + 39, k + 18, 1, 2);
		/* 1315 */setBlock(world, i + 3, j + 39, k + 19, Blocks.log, 1);
		/* 1316 */world.setBlockMetadataWithNotify(i + 3, j + 39, k + 19, 1, 2);
		/* 1317 */setBlock(world, i + 3, j + 39, k + 20, Blocks.log, 1);
		/* 1318 */world.setBlockMetadataWithNotify(i + 3, j + 39, k + 20, 1, 2);
		/* 1319 */setBlock(world, i + 3, j + 39, k + 21, Blocks.log, 1);
		/* 1320 */world.setBlockMetadataWithNotify(i + 3, j + 39, k + 21, 1, 2);
		/* 1321 */setBlock(world, i + 3, j + 40, k + 0, Blocks.leaves, 7);
		/* 1322 */world.setBlockMetadataWithNotify(i + 3, j + 40, k + 0, 7, 2);
		/* 1323 */setBlock(world, i + 3, j + 40, k + 5, Blocks.log, 1);
		/* 1324 */world.setBlockMetadataWithNotify(i + 3, j + 40, k + 5, 1, 2);
		/* 1325 */setBlock(world, i + 3, j + 40, k + 6, Blocks.log, 1);
		/* 1326 */world.setBlockMetadataWithNotify(i + 3, j + 40, k + 6, 1, 2);
		/* 1327 */setBlock(world, i + 3, j + 40, k + 7, Blocks.log, 1);
		/* 1328 */world.setBlockMetadataWithNotify(i + 3, j + 40, k + 7, 1, 2);
		/* 1329 */setBlock(world, i + 3, j + 40, k + 8, Blocks.log, 1);
		/* 1330 */world.setBlockMetadataWithNotify(i + 3, j + 40, k + 8, 1, 2);
		/* 1331 */setBlock(world, i + 3, j + 40, k + 9, Blocks.torch, 1);
		/* 1332 */world.setBlockMetadataWithNotify(i + 3, j + 40, k + 9, 1, 2);
		/* 1333 */setBlock(world, i + 3, j + 40, k + 15, Blocks.torch, 1);
		/* 1334 */world.setBlockMetadataWithNotify(i + 3, j + 40, k + 15, 1, 2);
		/* 1335 */setBlock(world, i + 3, j + 40, k + 16, Blocks.log, 1);
		/* 1336 */world.setBlockMetadataWithNotify(i + 3, j + 40, k + 16, 1, 2);
		/* 1337 */setBlock(world, i + 3, j + 40, k + 17, Blocks.log, 1);
		/* 1338 */world.setBlockMetadataWithNotify(i + 3, j + 40, k + 17, 1, 2);
		/* 1339 */setBlock(world, i + 3, j + 40, k + 18, Blocks.log, 1);
		/* 1340 */world.setBlockMetadataWithNotify(i + 3, j + 40, k + 18, 1, 2);
		/* 1341 */setBlock(world, i + 3, j + 40, k + 19, Blocks.log, 1);
		/* 1342 */world.setBlockMetadataWithNotify(i + 3, j + 40, k + 19, 1, 2);
		/* 1343 */setBlock(world, i + 3, j + 41, k + 0, Blocks.log, 3);
		/* 1344 */world.setBlockMetadataWithNotify(i + 3, j + 41, k + 0, 3, 2);
		/* 1345 */setBlock(world, i + 3, j + 41, k + 1, Blocks.leaves, 7);
		/* 1346 */world.setBlockMetadataWithNotify(i + 3, j + 41, k + 1, 7, 2);
		/* 1347 */setBlock(world, i + 3, j + 41, k + 2, Blocks.leaves, 7);
		/* 1348 */world.setBlockMetadataWithNotify(i + 3, j + 41, k + 2, 7, 2);
		/* 1349 */setBlock(world, i + 3, j + 41, k + 5, Blocks.log, 1);
		/* 1350 */world.setBlockMetadataWithNotify(i + 3, j + 41, k + 5, 1, 2);
		/* 1351 */setBlock(world, i + 3, j + 41, k + 6, Blocks.log, 1);
		/* 1352 */world.setBlockMetadataWithNotify(i + 3, j + 41, k + 6, 1, 2);
		/* 1353 */setBlock(world, i + 3, j + 41, k + 7, Blocks.log, 1);
		/* 1354 */world.setBlockMetadataWithNotify(i + 3, j + 41, k + 7, 1, 2);
		/* 1355 */setBlock(world, i + 3, j + 41, k + 8, Blocks.log, 1);
		/* 1356 */world.setBlockMetadataWithNotify(i + 3, j + 41, k + 8, 1, 2);
		/* 1357 */setBlock(world, i + 3, j + 41, k + 9, Blocks.log, 1);
		/* 1358 */world.setBlockMetadataWithNotify(i + 3, j + 41, k + 9, 1, 2);
		/* 1359 */setBlock(world, i + 3, j + 41, k + 10, Blocks.log, 1);
		/* 1360 */world.setBlockMetadataWithNotify(i + 3, j + 41, k + 10, 1, 2);
		/* 1361 */setBlock(world, i + 3, j + 41, k + 11, Blocks.log, 1);
		/* 1362 */world.setBlockMetadataWithNotify(i + 3, j + 41, k + 11, 1, 2);
		/* 1363 */setBlock(world, i + 3, j + 41, k + 12, Blocks.log, 1);
		/* 1364 */world.setBlockMetadataWithNotify(i + 3, j + 41, k + 12, 1, 2);
		/* 1365 */setBlock(world, i + 3, j + 41, k + 13, Blocks.log, 1);
		/* 1366 */world.setBlockMetadataWithNotify(i + 3, j + 41, k + 13, 1, 2);
		/* 1367 */setBlock(world, i + 3, j + 41, k + 14, Blocks.log, 1);
		/* 1368 */world.setBlockMetadataWithNotify(i + 3, j + 41, k + 14, 1, 2);
		/* 1369 */setBlock(world, i + 3, j + 41, k + 15, Blocks.log, 1);
		/* 1370 */world.setBlockMetadataWithNotify(i + 3, j + 41, k + 15, 1, 2);
		/* 1371 */setBlock(world, i + 3, j + 41, k + 16, Blocks.log, 1);
		/* 1372 */world.setBlockMetadataWithNotify(i + 3, j + 41, k + 16, 1, 2);
		/* 1373 */setBlock(world, i + 3, j + 41, k + 17, Blocks.log, 1);
		/* 1374 */world.setBlockMetadataWithNotify(i + 3, j + 41, k + 17, 1, 2);
		/* 1375 */setBlock(world, i + 3, j + 41, k + 18, Blocks.log, 1);
		/* 1376 */world.setBlockMetadataWithNotify(i + 3, j + 41, k + 18, 1, 2);
		/* 1377 */setBlock(world, i + 3, j + 41, k + 19, Blocks.log, 1);
		/* 1378 */world.setBlockMetadataWithNotify(i + 3, j + 41, k + 19, 1, 2);
		/* 1379 */setBlock(world, i + 3, j + 42, k + 0, Blocks.leaves, 7);
		/* 1380 */world.setBlockMetadataWithNotify(i + 3, j + 42, k + 0, 7, 2);
		/* 1381 */setBlock(world, i + 3, j + 42, k + 1, Blocks.leaves, 7);
		/* 1382 */world.setBlockMetadataWithNotify(i + 3, j + 42, k + 1, 7, 2);
		/* 1383 */setBlock(world, i + 3, j + 42, k + 2, Blocks.leaves, 7);
		/* 1384 */world.setBlockMetadataWithNotify(i + 3, j + 42, k + 2, 7, 2);
		/* 1385 */setBlock(world, i + 3, j + 42, k + 6, Blocks.log, 1);
		/* 1386 */world.setBlockMetadataWithNotify(i + 3, j + 42, k + 6, 1, 2);
		/* 1387 */setBlock(world, i + 3, j + 42, k + 7, Blocks.log, 1);
		/* 1388 */world.setBlockMetadataWithNotify(i + 3, j + 42, k + 7, 1, 2);
		/* 1389 */setBlock(world, i + 3, j + 42, k + 8, Blocks.log, 1);
		/* 1390 */world.setBlockMetadataWithNotify(i + 3, j + 42, k + 8, 1, 2);
		/* 1391 */setBlock(world, i + 3, j + 42, k + 9, Blocks.log, 1);
		/* 1392 */world.setBlockMetadataWithNotify(i + 3, j + 42, k + 9, 1, 2);
		/* 1393 */setBlock(world, i + 3, j + 42, k + 10, Blocks.log, 1);
		/* 1394 */world.setBlockMetadataWithNotify(i + 3, j + 42, k + 10, 1, 2);
		/* 1395 */setBlock(world, i + 3, j + 42, k + 11, Blocks.log, 1);
		/* 1396 */world.setBlockMetadataWithNotify(i + 3, j + 42, k + 11, 1, 2);
		/* 1397 */setBlock(world, i + 3, j + 42, k + 12, Blocks.log, 1);
		/* 1398 */world.setBlockMetadataWithNotify(i + 3, j + 42, k + 12, 1, 2);
		/* 1399 */setBlock(world, i + 3, j + 42, k + 13, Blocks.log, 1);
		/* 1400 */world.setBlockMetadataWithNotify(i + 3, j + 42, k + 13, 1, 2);
		/* 1401 */setBlock(world, i + 3, j + 42, k + 14, Blocks.log, 1);
		/* 1402 */world.setBlockMetadataWithNotify(i + 3, j + 42, k + 14, 1, 2);
		/* 1403 */setBlock(world, i + 3, j + 42, k + 15, Blocks.log, 1);
		/* 1404 */world.setBlockMetadataWithNotify(i + 3, j + 42, k + 15, 1, 2);
		/* 1405 */setBlock(world, i + 3, j + 42, k + 16, Blocks.log, 1);
		/* 1406 */world.setBlockMetadataWithNotify(i + 3, j + 42, k + 16, 1, 2);
		/* 1407 */setBlock(world, i + 3, j + 42, k + 17, Blocks.log, 1);
		/* 1408 */world.setBlockMetadataWithNotify(i + 3, j + 42, k + 17, 1, 2);
		/* 1409 */setBlock(world, i + 3, j + 42, k + 18, Blocks.log, 1);
		/* 1410 */world.setBlockMetadataWithNotify(i + 3, j + 42, k + 18, 1, 2);
		/* 1411 */setBlock(world, i + 3, j + 43, k + 0, Blocks.leaves, 7);
		/* 1412 */world.setBlockMetadataWithNotify(i + 3, j + 43, k + 0, 7, 2);
		/* 1413 */setBlock(world, i + 3, j + 43, k + 1, Blocks.leaves, 7);
		/* 1414 */world.setBlockMetadataWithNotify(i + 3, j + 43, k + 1, 7, 2);
		/* 1415 */setBlock(world, i + 3, j + 43, k + 7, Blocks.log, 1);
		/* 1416 */world.setBlockMetadataWithNotify(i + 3, j + 43, k + 7, 1, 2);
		/* 1417 */setBlock(world, i + 3, j + 43, k + 8, Blocks.log, 1);
		/* 1418 */world.setBlockMetadataWithNotify(i + 3, j + 43, k + 8, 1, 2);
		/* 1419 */setBlock(world, i + 3, j + 43, k + 9, Blocks.log, 1);
		/* 1420 */world.setBlockMetadataWithNotify(i + 3, j + 43, k + 9, 1, 2);
		/* 1421 */setBlock(world, i + 3, j + 43, k + 10, Blocks.log, 1);
		/* 1422 */world.setBlockMetadataWithNotify(i + 3, j + 43, k + 10, 1, 2);
		/* 1423 */setBlock(world, i + 3, j + 43, k + 11, Blocks.log, 1);
		/* 1424 */world.setBlockMetadataWithNotify(i + 3, j + 43, k + 11, 1, 2);
		/* 1425 */setBlock(world, i + 3, j + 43, k + 12, Blocks.log, 1);
		/* 1426 */world.setBlockMetadataWithNotify(i + 3, j + 43, k + 12, 1, 2);
		/* 1427 */setBlock(world, i + 3, j + 43, k + 13, Blocks.log, 1);
		/* 1428 */world.setBlockMetadataWithNotify(i + 3, j + 43, k + 13, 1, 2);
		/* 1429 */setBlock(world, i + 3, j + 43, k + 14, Blocks.log, 1);
		/* 1430 */world.setBlockMetadataWithNotify(i + 3, j + 43, k + 14, 1, 2);
		/* 1431 */setBlock(world, i + 3, j + 43, k + 15, Blocks.log, 1);
		/* 1432 */world.setBlockMetadataWithNotify(i + 3, j + 43, k + 15, 1, 2);
		/* 1433 */setBlock(world, i + 3, j + 43, k + 16, Blocks.log, 1);
		/* 1434 */world.setBlockMetadataWithNotify(i + 3, j + 43, k + 16, 1, 2);
		/* 1435 */setBlock(world, i + 3, j + 43, k + 17, Blocks.log, 1);
		/* 1436 */world.setBlockMetadataWithNotify(i + 3, j + 43, k + 17, 1, 2);
		/* 1437 */setBlock(world, i + 3, j + 43, k + 29, Blocks.leaves, 7);
		/* 1438 */world.setBlockMetadataWithNotify(i + 3, j + 43, k + 29, 7, 2);
		/* 1439 */setBlock(world, i + 3, j + 43, k + 30, Blocks.leaves, 7);
		/* 1440 */world.setBlockMetadataWithNotify(i + 3, j + 43, k + 30, 7, 2);
		/* 1441 */setBlock(world, i + 3, j + 43, k + 31, Blocks.leaves, 7);
		/* 1442 */world.setBlockMetadataWithNotify(i + 3, j + 43, k + 31, 7, 2);
		/* 1443 */setBlock(world, i + 3, j + 44, k + 0, Blocks.leaves, 7);
		/* 1444 */world.setBlockMetadataWithNotify(i + 3, j + 44, k + 0, 7, 2);
		/* 1445 */setBlock(world, i + 3, j + 44, k + 10, Blocks.log, 1);
		/* 1446 */world.setBlockMetadataWithNotify(i + 3, j + 44, k + 10, 1, 2);
		/* 1447 */setBlock(world, i + 3, j + 44, k + 11, Blocks.log, 1);
		/* 1448 */world.setBlockMetadataWithNotify(i + 3, j + 44, k + 11, 1, 2);
		/* 1449 */setBlock(world, i + 3, j + 44, k + 12, Blocks.log, 1);
		/* 1450 */world.setBlockMetadataWithNotify(i + 3, j + 44, k + 12, 1, 2);
		/* 1451 */setBlock(world, i + 3, j + 44, k + 13, Blocks.log, 1);
		/* 1452 */world.setBlockMetadataWithNotify(i + 3, j + 44, k + 13, 1, 2);
		/* 1453 */setBlock(world, i + 3, j + 44, k + 14, Blocks.log, 1);
		/* 1454 */world.setBlockMetadataWithNotify(i + 3, j + 44, k + 14, 1, 2);
		/* 1455 */setBlock(world, i + 3, j + 44, k + 30, Blocks.leaves, 7);
		/* 1456 */world.setBlockMetadataWithNotify(i + 3, j + 44, k + 30, 7, 2);
		/* 1457 */setBlock(world, i + 3, j + 45, k + 30, Blocks.log, 3);
		/* 1458 */world.setBlockMetadataWithNotify(i + 3, j + 45, k + 30, 3, 2);
		/* 1459 */setBlock(world, i + 3, j + 45, k + 31, Blocks.log, 3);
		/* 1460 */world.setBlockMetadataWithNotify(i + 3, j + 45, k + 31, 3, 2);
		/* 1461 */setBlock(world, i + 3, j + 46, k + 26, Blocks.leaves, 7);
		/* 1462 */world.setBlockMetadataWithNotify(i + 3, j + 46, k + 26, 7, 2);
		/* 1463 */setBlock(world, i + 3, j + 46, k + 27, Blocks.leaves, 7);
		/* 1464 */world.setBlockMetadataWithNotify(i + 3, j + 46, k + 27, 7, 2);
		/* 1465 */setBlock(world, i + 3, j + 46, k + 28, Blocks.leaves, 7);
		/* 1466 */world.setBlockMetadataWithNotify(i + 3, j + 46, k + 28, 7, 2);
		/* 1467 */setBlock(world, i + 3, j + 46, k + 29, Blocks.leaves, 7);
		/* 1468 */world.setBlockMetadataWithNotify(i + 3, j + 46, k + 29, 7, 2);
		/* 1469 */setBlock(world, i + 3, j + 46, k + 30, Blocks.leaves, 7);
		/* 1470 */world.setBlockMetadataWithNotify(i + 3, j + 46, k + 30, 7, 2);
		/* 1471 */setBlock(world, i + 3, j + 46, k + 31, Blocks.log, 3);
		/* 1472 */world.setBlockMetadataWithNotify(i + 3, j + 46, k + 31, 3, 2);
		/* 1473 */setBlock(world, i + 3, j + 47, k + 27, Blocks.leaves, 7);
		/* 1474 */world.setBlockMetadataWithNotify(i + 3, j + 47, k + 27, 7, 2);
		/* 1475 */setBlock(world, i + 3, j + 47, k + 28, Blocks.leaves, 7);
		/* 1476 */world.setBlockMetadataWithNotify(i + 3, j + 47, k + 28, 7, 2);
		/* 1477 */setBlock(world, i + 3, j + 47, k + 29, Blocks.leaves, 7);
		/* 1478 */world.setBlockMetadataWithNotify(i + 3, j + 47, k + 29, 7, 2);
		/* 1479 */setBlock(world, i + 3, j + 47, k + 30, Blocks.leaves, 7);
		/* 1480 */world.setBlockMetadataWithNotify(i + 3, j + 47, k + 30, 7, 2);
		/* 1481 */setBlock(world, i + 3, j + 47, k + 31, Blocks.leaves, 7);
		/* 1482 */world.setBlockMetadataWithNotify(i + 3, j + 47, k + 31, 7, 2);
		/* 1483 */setBlock(world, i + 3, j + 48, k + 27, Blocks.vine, 15);
		/* 1484 */world.setBlockMetadataWithNotify(i + 3, j + 48, k + 27, 15, 2);
		/* 1485 */setBlock(world, i + 3, j + 48, k + 28, Blocks.leaves, 7);
		/* 1486 */world.setBlockMetadataWithNotify(i + 3, j + 48, k + 28, 7, 2);
		/* 1487 */setBlock(world, i + 3, j + 48, k + 30, Blocks.leaves, 7);
		/* 1488 */world.setBlockMetadataWithNotify(i + 3, j + 48, k + 30, 7, 2);
		/* 1489 */setBlock(world, i + 3, j + 48, k + 31, Blocks.leaves, 7);
		/* 1490 */world.setBlockMetadataWithNotify(i + 3, j + 48, k + 31, 7, 2);
		/* 1491 */setBlock(world, i + 3, j + 49, k + 0, Blocks.leaves, 7);
		/* 1492 */world.setBlockMetadataWithNotify(i + 3, j + 49, k + 0, 7, 2);
		/* 1493 */setBlock(world, i + 3, j + 49, k + 1, Blocks.leaves, 7);
		/* 1494 */world.setBlockMetadataWithNotify(i + 3, j + 49, k + 1, 7, 2);
		/* 1495 */setBlock(world, i + 3, j + 49, k + 2, Blocks.leaves, 7);
		/* 1496 */world.setBlockMetadataWithNotify(i + 3, j + 49, k + 2, 7, 2);
		/* 1497 */setBlock(world, i + 3, j + 49, k + 3, Blocks.leaves, 7);
		/* 1498 */world.setBlockMetadataWithNotify(i + 3, j + 49, k + 3, 7, 2);
		/* 1499 */setBlock(world, i + 3, j + 49, k + 4, Blocks.leaves, 7);
		/* 1500 */world.setBlockMetadataWithNotify(i + 3, j + 49, k + 4, 7, 2);
		/* 1501 */setBlock(world, i + 3, j + 49, k + 5, Blocks.leaves, 7);
		/* 1502 */world.setBlockMetadataWithNotify(i + 3, j + 49, k + 5, 7, 2);
		/* 1503 */setBlock(world, i + 3, j + 49, k + 27, Blocks.vine, 15);
		/* 1504 */world.setBlockMetadataWithNotify(i + 3, j + 49, k + 27, 15, 2);
		/* 1505 */setBlock(world, i + 3, j + 49, k + 28, Blocks.vine, 15);
		/* 1506 */world.setBlockMetadataWithNotify(i + 3, j + 49, k + 28, 15, 2);
		/* 1507 */setBlock(world, i + 3, j + 49, k + 29, Blocks.vine, 15);
		/* 1508 */world.setBlockMetadataWithNotify(i + 3, j + 49, k + 29, 15, 2);
		/* 1509 */setBlock(world, i + 3, j + 49, k + 31, Blocks.leaves, 7);
		/* 1510 */world.setBlockMetadataWithNotify(i + 3, j + 49, k + 31, 7, 2);
		/* 1511 */setBlock(world, i + 3, j + 50, k + 2, Blocks.leaves, 7);
		/* 1512 */world.setBlockMetadataWithNotify(i + 3, j + 50, k + 2, 7, 2);
		/* 1513 */setBlock(world, i + 3, j + 50, k + 3, Blocks.leaves, 7);
		/* 1514 */world.setBlockMetadataWithNotify(i + 3, j + 50, k + 3, 7, 2);
		/* 1515 */setBlock(world, i + 3, j + 50, k + 4, Blocks.leaves, 7);
		/* 1516 */world.setBlockMetadataWithNotify(i + 3, j + 50, k + 4, 7, 2);
		/* 1517 */setBlock(world, i + 3, j + 50, k + 28, Blocks.vine, 15);
		/* 1518 */world.setBlockMetadataWithNotify(i + 3, j + 50, k + 28, 15, 2);
		/* 1519 */setBlock(world, i + 3, j + 50, k + 29, Blocks.vine, 15);
		/* 1520 */world.setBlockMetadataWithNotify(i + 3, j + 50, k + 29, 15, 2);
		/* 1521 */setBlock(world, i + 3, j + 51, k + 3, Blocks.leaves, 7);
		/* 1522 */world.setBlockMetadataWithNotify(i + 3, j + 51, k + 3, 7, 2);
		/* 1523 */setBlock(world, i + 3, j + 53, k + 0, Blocks.leaves, 7);
		/* 1524 */world.setBlockMetadataWithNotify(i + 3, j + 53, k + 0, 7, 2);
		/* 1525 */setBlock(world, i + 3, j + 54, k + 0, Blocks.leaves, 7);
		/* 1526 */world.setBlockMetadataWithNotify(i + 3, j + 54, k + 0, 7, 2);
		/* 1527 */setBlock(world, i + 3, j + 65, k + 27, Blocks.log, 1);
		/* 1528 */world.setBlockMetadataWithNotify(i + 3, j + 65, k + 27, 1, 2);
		/* 1529 */setBlock(world, i + 3, j + 65, k + 28, Blocks.log, 1);
		/* 1530 */world.setBlockMetadataWithNotify(i + 3, j + 65, k + 28, 1, 2);
		/* 1531 */setBlock(world, i + 3, j + 65, k + 29, Blocks.log, 1);
		/* 1532 */world.setBlockMetadataWithNotify(i + 3, j + 65, k + 29, 1, 2);
		/* 1533 */setBlock(world, i + 3, j + 65, k + 30, Blocks.log, 1);
		/* 1534 */world.setBlockMetadataWithNotify(i + 3, j + 65, k + 30, 1, 2);
		/* 1535 */setBlock(world, i + 3, j + 65, k + 31, Blocks.log, 1);
		/* 1536 */world.setBlockMetadataWithNotify(i + 3, j + 65, k + 31, 1, 2);
		/* 1537 */setBlock(world, i + 3, j + 70, k + 25, Blocks.log, 1);
		/* 1538 */world.setBlockMetadataWithNotify(i + 3, j + 70, k + 25, 1, 2);
		/* 1539 */setBlock(world, i + 3, j + 70, k + 26, Blocks.log, 1);
		/* 1540 */world.setBlockMetadataWithNotify(i + 3, j + 70, k + 26, 1, 2);
		/* 1541 */setBlock(world, i + 3, j + 70, k + 27, Blocks.log, 1);
		/* 1542 */world.setBlockMetadataWithNotify(i + 3, j + 70, k + 27, 1, 2);
		/* 1543 */setBlock(world, i + 3, j + 70, k + 28, Blocks.log, 1);
		/* 1544 */world.setBlockMetadataWithNotify(i + 3, j + 70, k + 28, 1, 2);
		/* 1545 */setBlock(world, i + 3, j + 70, k + 29, Blocks.log, 1);
		/* 1546 */world.setBlockMetadataWithNotify(i + 3, j + 70, k + 29, 1, 2);
		/* 1547 */setBlock(world, i + 3, j + 70, k + 30, Blocks.log, 1);
		/* 1548 */world.setBlockMetadataWithNotify(i + 3, j + 70, k + 30, 1, 2);
		/* 1549 */setBlock(world, i + 3, j + 71, k + 26, Blocks.log, 1);
		/* 1550 */world.setBlockMetadataWithNotify(i + 3, j + 71, k + 26, 1, 2);
		/* 1551 */setBlock(world, i + 3, j + 71, k + 27, Blocks.log, 1);
		/* 1552 */world.setBlockMetadataWithNotify(i + 3, j + 71, k + 27, 1, 2);
		/* 1553 */setBlock(world, i + 3, j + 71, k + 28, Blocks.log, 1);
		/* 1554 */world.setBlockMetadataWithNotify(i + 3, j + 71, k + 28, 1, 2);
		/* 1555 */setBlock(world, i + 3, j + 71, k + 29, Blocks.log, 1);
		/* 1556 */world.setBlockMetadataWithNotify(i + 3, j + 71, k + 29, 1, 2);
		/* 1557 */setBlock(world, i + 3, j + 71, k + 30, Blocks.log, 1);
		/* 1558 */world.setBlockMetadataWithNotify(i + 3, j + 71, k + 30, 1, 2);
		/* 1559 */setBlock(world, i + 3, j + 71, k + 31, Blocks.log, 1);
		/* 1560 */world.setBlockMetadataWithNotify(i + 3, j + 71, k + 31, 1, 2);
		/* 1561 */setBlock(world, i + 3, j + 72, k + 28, Blocks.log, 1);
		/* 1562 */world.setBlockMetadataWithNotify(i + 3, j + 72, k + 28, 1, 2);
		/* 1563 */setBlock(world, i + 3, j + 72, k + 29, Blocks.log, 1);
		/* 1564 */world.setBlockMetadataWithNotify(i + 3, j + 72, k + 29, 1, 2);
		/* 1565 */setBlock(world, i + 3, j + 72, k + 30, Blocks.log, 1);
		/* 1566 */world.setBlockMetadataWithNotify(i + 3, j + 72, k + 30, 1, 2);
		/* 1567 */setBlock(world, i + 3, j + 72, k + 31, Blocks.log, 1);
		/* 1568 */world.setBlockMetadataWithNotify(i + 3, j + 72, k + 31, 1, 2);
		/* 1569 */setBlock(world, i + 4, j + 21, k + 0, Blocks.log, 1);
		/* 1570 */world.setBlockMetadataWithNotify(i + 4, j + 21, k + 0, 1, 2);
		/* 1571 */setBlock(world, i + 4, j + 25, k + 9, Blocks.leaves, 7);
		/* 1572 */world.setBlockMetadataWithNotify(i + 4, j + 25, k + 9, 7, 2);
