package com.parzivail.pswm.world.gen.wookietree;




import com.parzivail.pswm.utils.LootGenUtils;
import com.parzivail.pswm.utils.NPCType;
import com.parzivail.pswm.utils.SpawnUtils;



import cpw.mods.fml.common.IWorldGenerator;



import java.util.Random;



import net.minecraft.block.Block;

import net.minecraft.init.Blocks;

import net.minecraft.tileentity.TileEntityChest;

import net.minecraft.world.World;

import net.minecraft.world.WorldProvider;

import net.minecraft.world.chunk.IChunkProvider;

import net.minecraft.world.gen.feature.WorldGenerator;


public class WT_22
extends WorldGenerator implements IWorldGenerator

{
	protected Block[] getValidSpawnBlocks()
	
	{
		return new Block[0];
		}

	
	public boolean locationIsValidSpawn(World world, int i, int j, int k)
	
	{
		int distanceToAir = 0;
		Block check = world.getBlock(i, j, k);
		
		while (check != Blocks.air)
		{
			if (distanceToAir > 3) { return false;
			}
			
			distanceToAir++;
			check = world.getBlock(i, j + distanceToAir, k);
			}
		
		j += distanceToAir - 1;
		
		Block block = world.getBlock(i, j, k);
		Block blockAbove = world.getBlock(i, j + 1, k);
		Block blockBelow = world.getBlock(i, j - 1, k);
		
		for (Block x : getValidSpawnBlocks())
		{
			if (blockAbove != Blocks.air) { return false;
			}
			if (block == x) return true;
			if ((block == Blocks.snow) && (blockBelow == x)) { return true;
			}
			}
		
		return false;
		}

	
	
	
	public void generate(Random random, int chunkX, int chunkZ, World world, IChunkProvider chunkGenerator, IChunkProvider chunkProvider)
	{
	}

	
	
	public void setBlock(World world, int x, int y, int z, Block block, int metadata)
	
	{
		world.setBlock(x, y, z, block, metadata, 2);
		}

	
	public boolean generate(World world, Random rand, int i, int j, int k)
	
	{
		k -= 10;
		i -= 10;
		
		setBlock(world, i + 1, j + 36, k + 8, Blocks.fence, 0);
		setBlock(world, i + 1, j + 36, k + 9, Blocks.fence, 0);
		setBlock(world, i + 1, j + 36, k + 15, Blocks.fence, 0);
		setBlock(world, i + 1, j + 36, k + 16, Blocks.fence, 0);
		setBlock(world, i + 2, j + 36, k + 7, Blocks.fence, 0);
		setBlock(world, i + 2, j + 36, k + 8, Blocks.fence, 0);
		setBlock(world, i + 2, j + 36, k + 16, Blocks.fence, 0);
		setBlock(world, i + 2, j + 36, k + 17, Blocks.fence, 0);
		setBlock(world, i + 3, j + 36, k + 6, Blocks.spruce_stairs, 0);
		setBlock(world, i + 3, j + 36, k + 7, Blocks.fence, 0);
		SpawnUtils.spawnNPC(NPCType.WOOKIETREE, world, i + 3, j + 36, k + 12);
		setBlock(world, i + 3, j + 36, k + 17, Blocks.fence, 0);
		setBlock(world, i + 3, j + 36, k + 18, Blocks.spruce_stairs, 0);
		setBlock(world, i + 3, j + 38, k + 4, Blocks.fence, 0);
		setBlock(world, i + 3, j + 38, k + 5, Blocks.fence, 0);
		setBlock(world, i + 3, j + 38, k + 19, Blocks.fence, 0);
		setBlock(world, i + 3, j + 38, k + 20, Blocks.fence, 0);
		setBlock(world, i + 4, j + 66, k + 29, Blocks.spruce_stairs, 0);
		setBlock(world, i + 5, j + 36, k + 11, Blocks.crafting_table, 0);
		setBlock(world, i + 5, j + 36, k + 12, Blocks.spruce_stairs, 0);
		SpawnUtils.spawnNPC(NPCType.WOOKIETREE, world, i + 6, j + 36, k + 9);
		SpawnUtils.spawnNPC(NPCType.WOOKIETREE, world, i + 6, j + 36, k + 15);
		setBlock(world, i + 6, j + 66, k + 30, Blocks.fence, 0);
		setBlock(world, i + 6, j + 66, k + 31, Blocks.fence, 0);
		setBlock(world, i + 6, j + 69, k + 27, Blocks.fence, 0);
		setBlock(world, i + 6, j + 69, k + 28, Blocks.fence, 0);
		setBlock(world, i + 7, j + 69, k + 28, Blocks.fence, 0);
		setBlock(world, i + 7, j + 69, k + 29, Blocks.fence, 0);
		setBlock(world, i + 8, j + 69, k + 29, Blocks.fence, 0);
		setBlock(world, i + 8, j + 69, k + 30, Blocks.fence, 0);
		setBlock(world, i + 8, j + 69, k + 31, Blocks.fence, 0);
		setBlock(world, i + 9, j + 36, k + 7, Blocks.fence, 0);
		SpawnUtils.spawnNPC(NPCType.WOOKIETREE, world, i + 9, j + 36, k + 12);
		setBlock(world, i + 9, j + 36, k + 17, Blocks.fence, 0);
		setBlock(world, i + 9, j + 38, k + 4, Blocks.fence, 0);
		setBlock(world, i + 9, j + 38, k + 5, Blocks.fence, 0);
		setBlock(world, i + 9, j + 38, k + 19, Blocks.fence, 0);
		setBlock(world, i + 9, j + 38, k + 20, Blocks.fence, 0);
		setBlock(world, i + 9, j + 69, k + 31, Blocks.fence, 0);
		setBlock(world, i + 10, j + 36, k + 7, Blocks.fence, 0);
		setBlock(world, i + 10, j + 36, k + 8, Blocks.fence, 0);
		setBlock(world, i + 10, j + 36, k + 16, Blocks.fence, 0);
		setBlock(world, i + 10, j + 36, k + 17, Blocks.fence, 0);
		setBlock(world, i + 11, j + 36, k + 8, Blocks.fence, 0);
		setBlock(world, i + 11, j + 36, k + 9, Blocks.fence, 0);
		setBlock(world, i + 11, j + 36, k + 10, Blocks.spruce_stairs, 0);
		setBlock(world, i + 11, j + 36, k + 14, Blocks.spruce_stairs, 0);
		setBlock(world, i + 11, j + 36, k + 15, Blocks.fence, 0);
		setBlock(world, i + 11, j + 36, k + 16, Blocks.fence, 0);
		setBlock(world, i + 13, j + 38, k + 9, Blocks.fence, 0);
		setBlock(world, i + 13, j + 38, k + 15, Blocks.fence, 0);
		setBlock(world, i + 14, j + 38, k + 9, Blocks.fence, 0);
		setBlock(world, i + 14, j + 38, k + 15, Blocks.fence, 0);
		setBlock(world, i + 18, j + 41, k + 0, Blocks.fence, 0);
		setBlock(world, i + 19, j + 41, k + 0, Blocks.fence, 0);
		setBlock(world, i + 20, j + 41, k + 0, Blocks.fence, 0);
		setBlock(world, i + 21, j + 41, k + 0, Blocks.fence, 0);
		setBlock(world, i + 21, j + 41, k + 1, Blocks.fence, 0);
		setBlock(world, i + 26, j + 24, k + 19, Blocks.fence, 0);
		setBlock(world, i + 26, j + 24, k + 28, Blocks.fence, 0);
		setBlock(world, i + 27, j + 24, k + 16, Blocks.fence, 0);
		setBlock(world, i + 27, j + 24, k + 17, Blocks.fence, 0);
		setBlock(world, i + 27, j + 24, k + 18, Blocks.fence, 0);
		setBlock(world, i + 27, j + 24, k + 19, Blocks.fence, 0);
		setBlock(world, i + 27, j + 24, k + 28, Blocks.fence, 0);
		setBlock(world, i + 27, j + 24, k + 29, Blocks.fence, 0);
		setBlock(world, i + 27, j + 24, k + 30, Blocks.fence, 0);
		setBlock(world, i + 27, j + 24, k + 31, Blocks.fence, 0);
		setBlock(world, i + 28, j + 24, k + 14, Blocks.fence, 0);
		setBlock(world, i + 28, j + 24, k + 15, Blocks.fence, 0);
		setBlock(world, i + 28, j + 24, k + 16, Blocks.fence, 0);
		setBlock(world, i + 28, j + 24, k + 31, Blocks.fence, 0);
		setBlock(world, i + 29, j + 21, k + 17, Blocks.fence, 0);
		setBlock(world, i + 29, j + 21, k + 18, Blocks.fence, 0);
		setBlock(world, i + 29, j + 21, k + 19, Blocks.fence, 0);
		setBlock(world, i + 29, j + 21, k + 28, Blocks.fence, 0);
		setBlock(world, i + 29, j + 21, k + 29, Blocks.fence, 0);
		setBlock(world, i + 29, j + 21, k + 30, Blocks.fence, 0);
		setBlock(world, i + 29, j + 24, k + 13, Blocks.fence, 0);
		setBlock(world, i + 29, j + 24, k + 14, Blocks.fence, 0);
		setBlock(world, i + 30, j + 21, k + 15, Blocks.fence, 0);
		setBlock(world, i + 30, j + 21, k + 16, Blocks.fence, 0);
		setBlock(world, i + 30, j + 21, k + 17, Blocks.fence, 0);
		SpawnUtils.spawnNPC(NPCType.WOOKIETREE, world, i + 30, j + 21, k + 24);
		setBlock(world, i + 30, j + 21, k + 30, Blocks.fence, 0);
		setBlock(world, i + 30, j + 21, k + 31, Blocks.fence, 0);
		setBlock(world, i + 30, j + 24, k + 12, Blocks.fence, 0);
		setBlock(world, i + 30, j + 24, k + 13, Blocks.fence, 0);
		setBlock(world, i + 30, j + 41, k + 0, Blocks.fence, 0);
		setBlock(world, i + 30, j + 41, k + 1, Blocks.fence, 0);
		setBlock(world, i + 31, j + 41, k + 0, Blocks.fence, 0);
		setBlock(world, i + 0, j + 23, k + 3, Blocks.log, 3);
		world.setBlockMetadataWithNotify(i + 0, j + 23, k + 3, 3, 2);
		setBlock(world, i + 0, j + 23, k + 4, Blocks.log, 3);
		world.setBlockMetadataWithNotify(i + 0, j + 23, k + 4, 3, 2);
		setBlock(world, i + 0, j + 24, k + 4, Blocks.leaves, 15);
		world.setBlockMetadataWithNotify(i + 0, j + 24, k + 4, 15, 2);
		setBlock(world, i + 0, j + 24, k + 5, Blocks.leaves, 15);
		world.setBlockMetadataWithNotify(i + 0, j + 24, k + 5, 15, 2);
		setBlock(world, i + 0, j + 24, k + 6, Blocks.leaves, 7);
		world.setBlockMetadataWithNotify(i + 0, j + 24, k + 6, 7, 2);
		setBlock(world, i + 0, j + 24, k + 7, Blocks.leaves, 7);
		world.setBlockMetadataWithNotify(i + 0, j + 24, k + 7, 7, 2);
		setBlock(world, i + 0, j + 24, k + 8, Blocks.leaves, 7);
		world.setBlockMetadataWithNotify(i + 0, j + 24, k + 8, 7, 2);
		setBlock(world, i + 0, j + 25, k + 5, Blocks.leaves, 15);
		world.setBlockMetadataWithNotify(i + 0, j + 25, k + 5, 15, 2);
		setBlock(world, i + 0, j + 25, k + 6, Blocks.leaves, 7);
		world.setBlockMetadataWithNotify(i + 0, j + 25, k + 6, 7, 2);
		setBlock(world, i + 0, j + 25, k + 7, Blocks.leaves, 7);
		world.setBlockMetadataWithNotify(i + 0, j + 25, k + 7, 7, 2);
		setBlock(world, i + 0, j + 26, k + 6, Blocks.leaves, 7);
		world.setBlockMetadataWithNotify(i + 0, j + 26, k + 6, 7, 2);
		setBlock(world, i + 0, j + 27, k + 0, Blocks.leaves, 15);
		world.setBlockMetadataWithNotify(i + 0, j + 27, k + 0, 15, 2);
		setBlock(world, i + 0, j + 28, k + 0, Blocks.leaves, 15);
		world.setBlockMetadataWithNotify(i + 0, j + 28, k + 0, 15, 2);
		setBlock(world, i + 0, j + 31, k + 25, Blocks.leaves, 7);
		world.setBlockMetadataWithNotify(i + 0, j + 31, k + 25, 7, 2);
		setBlock(world, i + 0, j + 31, k + 26, Blocks.leaves, 7);
		world.setBlockMetadataWithNotify(i + 0, j + 31, k + 26, 7, 2);
		setBlock(world, i + 0, j + 31, k + 27, Blocks.leaves, 7);
		world.setBlockMetadataWithNotify(i + 0, j + 31, k + 27, 7, 2);
		setBlock(world, i + 0, j + 32, k + 26, Blocks.leaves, 7);
		world.setBlockMetadataWithNotify(i + 0, j + 32, k + 26, 7, 2);
		setBlock(world, i + 0, j + 35, k + 10, Blocks.log, 1);
		world.setBlockMetadataWithNotify(i + 0, j + 35, k + 10, 1, 2);
		setBlock(world, i + 0, j + 35, k + 11, Blocks.log, 1);
		world.setBlockMetadataWithNotify(i + 0, j + 35, k + 11, 1, 2);
		setBlock(world, i + 0, j + 35, k + 12, Blocks.log, 1);
		world.setBlockMetadataWithNotify(i + 0, j + 35, k + 12, 1, 2);
		setBlock(world, i + 0, j + 35, k + 13, Blocks.log, 1);
		world.setBlockMetadataWithNotify(i + 0, j + 35, k + 13, 1, 2);
		setBlock(world, i + 0, j + 35, k + 14, Blocks.log, 1);
		world.setBlockMetadataWithNotify(i + 0, j + 35, k + 14, 1, 2);
		setBlock(world, i + 0, j + 35, k + 21, Blocks.planks, 5);
		world.setBlockMetadataWithNotify(i + 0, j + 35, k + 21, 5, 2);
		setBlock(world, i + 0, j + 35, k + 22, Blocks.planks, 5);
		world.setBlockMetadataWithNotify(i + 0, j + 35, k + 22, 5, 2);
		setBlock(world, i + 0, j + 35, k + 23, Blocks.planks, 5);
		world.setBlockMetadataWithNotify(i + 0, j + 35, k + 23, 5, 2);
		setBlock(world, i + 0, j + 35, k + 24, Blocks.planks, 5);
		world.setBlockMetadataWithNotify(i + 0, j + 35, k + 24, 5, 2);
		setBlock(world, i + 0, j + 35, k + 25, Blocks.planks, 5);
		world.setBlockMetadataWithNotify(i + 0, j + 35, k + 25, 5, 2);
		setBlock(world, i + 0, j + 36, k + 9, Blocks.spruce_stairs, 2);
		world.setBlockMetadataWithNotify(i + 0, j + 36, k + 9, 2, 2);
		setBlock(world, i + 0, j + 36, k + 10, Blocks.log, 1);
		world.setBlockMetadataWithNotify(i + 0, j + 36, k + 10, 1, 2);
		setBlock(world, i + 0, j + 36, k + 14, Blocks.log, 1);
		world.setBlockMetadataWithNotify(i + 0, j + 36, k + 14, 1, 2);
		setBlock(world, i + 0, j + 36, k + 15, Blocks.spruce_stairs, 3);
		world.setBlockMetadataWithNotify(i + 0, j + 36, k + 15, 3, 2);
		setBlock(world, i + 0, j + 36, k + 21, Blocks.spruce_stairs, 1);
		world.setBlockMetadataWithNotify(i + 0, j + 36, k + 21, 1, 2);
		setBlock(world, i + 0, j + 36, k + 22, Blocks.spruce_stairs, 1);
		world.setBlockMetadataWithNotify(i + 0, j + 36, k + 22, 1, 2);
		setBlock(world, i + 0, j + 36, k + 23, Blocks.spruce_stairs, 1);
		world.setBlockMetadataWithNotify(i + 0, j + 36, k + 23, 1, 2);
		setBlock(world, i + 0, j + 36, k + 24, Blocks.spruce_stairs, 1);
		world.setBlockMetadataWithNotify(i + 0, j + 36, k + 24, 1, 2);
		setBlock(world, i + 0, j + 36, k + 25, Blocks.spruce_stairs, 1);
		world.setBlockMetadataWithNotify(i + 0, j + 36, k + 25, 1, 2);
		setBlock(world, i + 0, j + 37, k + 10, Blocks.log, 1);
		world.setBlockMetadataWithNotify(i + 0, j + 37, k + 10, 1, 2);
		setBlock(world, i + 0, j + 37, k + 14, Blocks.log, 1);
		world.setBlockMetadataWithNotify(i + 0, j + 37, k + 14, 1, 2);
		setBlock(world, i + 0, j + 38, k + 29, Blocks.log, 3);
		world.setBlockMetadataWithNotify(i + 0, j + 38, k + 29, 3, 2);
		setBlock(world, i + 0, j + 39, k + 5, Blocks.log, 1);
		world.setBlockMetadataWithNotify(i + 0, j + 39, k + 5, 1, 2);
		setBlock(world, i + 0, j + 39, k + 6, Blocks.log, 1);
		world.setBlockMetadataWithNotify(i + 0, j + 39, k + 6, 1, 2);
		setBlock(world, i + 0, j + 39, k + 7, Blocks.log, 1);
		world.setBlockMetadataWithNotify(i + 0, j + 39, k + 7, 1, 2);
		setBlock(world, i + 0, j + 39, k + 8, Blocks.log, 1);
		world.setBlockMetadataWithNotify(i + 0, j + 39, k + 8, 1, 2);
		setBlock(world, i + 0, j + 39, k + 9, Blocks.log, 1);
		world.setBlockMetadataWithNotify(i + 0, j + 39, k + 9, 1, 2);
		setBlock(world, i + 0, j + 39, k + 10, Blocks.log, 1);
		world.setBlockMetadataWithNotify(i + 0, j + 39, k + 10, 1, 2);
		setBlock(world, i + 0, j + 39, k + 11, Blocks.log, 1);
		world.setBlockMetadataWithNotify(i + 0, j + 39, k + 11, 1, 2);
		setBlock(world, i + 0, j + 39, k + 12, Blocks.log, 1);
		world.setBlockMetadataWithNotify(i + 0, j + 39, k + 12, 1, 2);
		setBlock(world, i + 0, j + 39, k + 13, Blocks.log, 1);
		world.setBlockMetadataWithNotify(i + 0, j + 39, k + 13, 1, 2);
		setBlock(world, i + 0, j + 39, k + 14, Blocks.log, 1);
		world.setBlockMetadataWithNotify(i + 0, j + 39, k + 14, 1, 2);
		setBlock(world, i + 0, j + 39, k + 15, Blocks.log, 1);
		world.setBlockMetadataWithNotify(i + 0, j + 39, k + 15, 1, 2);
		setBlock(world, i + 0, j + 39, k + 16, Blocks.log, 1);
		world.setBlockMetadataWithNotify(i + 0, j + 39, k + 16, 1, 2);
		setBlock(world, i + 0, j + 39, k + 17, Blocks.log, 1);
		world.setBlockMetadataWithNotify(i + 0, j + 39, k + 17, 1, 2);
		setBlock(world, i + 0, j + 39, k + 18, Blocks.log, 1);
		world.setBlockMetadataWithNotify(i + 0, j + 39, k + 18, 1, 2);
		setBlock(world, i + 0, j + 39, k + 19, Blocks.log, 1);
		world.setBlockMetadataWithNotify(i + 0, j + 39, k + 19, 1, 2);
		setBlock(world, i + 0, j + 39, k + 25, Blocks.leaves, 7);
		world.setBlockMetadataWithNotify(i + 0, j + 39, k + 25, 7, 2);
		setBlock(world, i + 0, j + 39, k + 26, Blocks.leaves, 7);
		world.setBlockMetadataWithNotify(i + 0, j + 39, k + 26, 7, 2);
		setBlock(world, i + 0, j + 39, k + 27, Blocks.leaves, 7);
		world.setBlockMetadataWithNotify(i + 0, j + 39, k + 27, 7, 2);
		setBlock(world, i + 0, j + 39, k + 28, Blocks.leaves, 7);
		world.setBlockMetadataWithNotify(i + 0, j + 39, k + 28, 7, 2);
		setBlock(world, i + 0, j + 39, k + 29, Blocks.leaves, 7);
		world.setBlockMetadataWithNotify(i + 0, j + 39, k + 29, 7, 2);
		setBlock(world, i + 0, j + 40, k + 6, Blocks.log, 1);
		world.setBlockMetadataWithNotify(i + 0, j + 40, k + 6, 1, 2);
		setBlock(world, i + 0, j + 40, k + 7, Blocks.log, 1);
		world.setBlockMetadataWithNotify(i + 0, j + 40, k + 7, 1, 2);
		setBlock(world, i + 0, j + 40, k + 8, Blocks.log, 1);
		world.setBlockMetadataWithNotify(i + 0, j + 40, k + 8, 1, 2);
		setBlock(world, i + 0, j + 40, k + 9, Blocks.log, 1);
		world.setBlockMetadataWithNotify(i + 0, j + 40, k + 9, 1, 2);
		setBlock(world, i + 0, j + 40, k + 10, Blocks.log, 1);
		world.setBlockMetadataWithNotify(i + 0, j + 40, k + 10, 1, 2);
		setBlock(world, i + 0, j + 40, k + 11, Blocks.log, 1);
		world.setBlockMetadataWithNotify(i + 0, j + 40, k + 11, 1, 2);
		setBlock(world, i + 0, j + 40, k + 12, Blocks.log, 1);
		world.setBlockMetadataWithNotify(i + 0, j + 40, k + 12, 1, 2);
		setBlock(world, i + 0, j + 40, k + 13, Blocks.log, 1);
		world.setBlockMetadataWithNotify(i + 0, j + 40, k + 13, 1, 2);
		setBlock(world, i + 0, j + 40, k + 14, Blocks.log, 1);
		world.setBlockMetadataWithNotify(i + 0, j + 40, k + 14, 1, 2);
		setBlock(world, i + 0, j + 40, k + 15, Blocks.log, 1);
		world.setBlockMetadataWithNotify(i + 0, j + 40, k + 15, 1, 2);
		setBlock(world, i + 0, j + 40, k + 16, Blocks.log, 1);
		world.setBlockMetadataWithNotify(i + 0, j + 40, k + 16, 1, 2);
		setBlock(world, i + 0, j + 40, k + 17, Blocks.log, 1);
		world.setBlockMetadataWithNotify(i + 0, j + 40, k + 17, 1, 2);
		setBlock(world, i + 0, j + 40, k + 18, Blocks.log, 1);
		world.setBlockMetadataWithNotify(i + 0, j + 40, k + 18, 1, 2);
		setBlock(world, i + 0, j + 40, k + 26, Blocks.leaves, 7);
		world.setBlockMetadataWithNotify(i + 0, j + 40, k + 26, 7, 2);
		setBlock(world, i + 0, j + 40, k + 27, Blocks.leaves, 7);
		world.setBlockMetadataWithNotify(i + 0, j + 40, k + 27, 7, 2);
		setBlock(world, i + 0, j + 40, k + 28, Blocks.leaves, 7);
		world.setBlockMetadataWithNotify(i + 0, j + 40, k + 28, 7, 2);
		setBlock(world, i + 0, j + 41, k + 7, Blocks.log, 1);
		world.setBlockMetadataWithNotify(i + 0, j + 41, k + 7, 1, 2);
		setBlock(world, i + 0, j + 41, k + 8, Blocks.log, 1);
		world.setBlockMetadataWithNotify(i + 0, j + 41, k + 8, 1, 2);
		setBlock(world, i + 0, j + 41, k + 9, Blocks.log, 1);
		world.setBlockMetadataWithNotify(i + 0, j + 41, k + 9, 1, 2);
		setBlock(world, i + 0, j + 41, k + 10, Blocks.log, 1);
		world.setBlockMetadataWithNotify(i + 0, j + 41, k + 10, 1, 2);
		setBlock(world, i + 0, j + 41, k + 11, Blocks.log, 1);
		world.setBlockMetadataWithNotify(i + 0, j + 41, k + 11, 1, 2);
		setBlock(world, i + 0, j + 41, k + 12, Blocks.log, 1);
		world.setBlockMetadataWithNotify(i + 0, j + 41, k + 12, 1, 2);
		setBlock(world, i + 0, j + 41, k + 13, Blocks.log, 1);
		world.setBlockMetadataWithNotify(i + 0, j + 41, k + 13, 1, 2);
		setBlock(world, i + 0, j + 41, k + 14, Blocks.log, 1);
		world.setBlockMetadataWithNotify(i + 0, j + 41, k + 14, 1, 2);
		setBlock(world, i + 0, j + 41, k + 15, Blocks.log, 1);
		world.setBlockMetadataWithNotify(i + 0, j + 41, k + 15, 1, 2);
		setBlock(world, i + 0, j + 41, k + 16, Blocks.log, 1);
		world.setBlockMetadataWithNotify(i + 0, j + 41, k + 16, 1, 2);
		setBlock(world, i + 0, j + 41, k + 17, Blocks.log, 1);
		world.setBlockMetadataWithNotify(i + 0, j + 41, k + 17, 1, 2);
		setBlock(world, i + 0, j + 41, k + 27, Blocks.leaves, 7);
		world.setBlockMetadataWithNotify(i + 0, j + 41, k + 27, 7, 2);
		setBlock(world, i + 0, j + 41, k + 29, Blocks.log, 3);
		world.setBlockMetadataWithNotify(i + 0, j + 41, k + 29, 3, 2);
		setBlock(world, i + 0, j + 42, k + 8, Blocks.log, 1);
		world.setBlockMetadataWithNotify(i + 0, j + 42, k + 8, 1, 2);
		setBlock(world, i + 0, j + 42, k + 9, Blocks.log, 1);
		world.setBlockMetadataWithNotify(i + 0, j + 42, k + 9, 1, 2);
		setBlock(world, i + 0, j + 42, k + 10, Blocks.log, 1);
		world.setBlockMetadataWithNotify(i + 0, j + 42, k + 10, 1, 2);
		setBlock(world, i + 0, j + 42, k + 11, Blocks.log, 1);
		world.setBlockMetadataWithNotify(i + 0, j + 42, k + 11, 1, 2);
		setBlock(world, i + 0, j + 42, k + 12, Blocks.log, 1);
		world.setBlockMetadataWithNotify(i + 0, j + 42, k + 12, 1, 2);
		setBlock(world, i + 0, j + 42, k + 13, Blocks.log, 1);
		world.setBlockMetadataWithNotify(i + 0, j + 42, k + 13, 1, 2);
		setBlock(world, i + 0, j + 42, k + 14, Blocks.log, 1);
		world.setBlockMetadataWithNotify(i + 0, j + 42, k + 14, 1, 2);
		setBlock(world, i + 0, j + 42, k + 15, Blocks.log, 1);
		world.setBlockMetadataWithNotify(i + 0, j + 42, k + 15, 1, 2);
		setBlock(world, i + 0, j + 42, k + 16, Blocks.log, 1);
		world.setBlockMetadataWithNotify(i + 0, j + 42, k + 16, 1, 2);
		setBlock(world, i + 0, j + 42, k + 25, Blocks.leaves, 7);
		world.setBlockMetadataWithNotify(i + 0, j + 42, k + 25, 7, 2);
		setBlock(world, i + 0, j + 42, k + 26, Blocks.leaves, 7);
		world.setBlockMetadataWithNotify(i + 0, j + 42, k + 26, 7, 2);
		setBlock(world, i + 0, j + 42, k + 27, Blocks.leaves, 7);
		world.setBlockMetadataWithNotify(i + 0, j + 42, k + 27, 7, 2);
		setBlock(world, i + 0, j + 42, k + 28, Blocks.leaves, 7);
		world.setBlockMetadataWithNotify(i + 0, j + 42, k + 28, 7, 2);
		setBlock(world, i + 0, j + 42, k + 29, Blocks.leaves, 7);
		world.setBlockMetadataWithNotify(i + 0, j + 42, k + 29, 7, 2);
		setBlock(world, i + 0, j + 42, k + 31, Blocks.log, 3);
		world.setBlockMetadataWithNotify(i + 0, j + 42, k + 31, 3, 2);
		setBlock(world, i + 0, j + 43, k + 0, Blocks.leaves, 7);
		world.setBlockMetadataWithNotify(i + 0, j + 43, k + 0, 7, 2);
		setBlock(world, i + 0, j + 43, k + 1, Blocks.leaves, 7);
		world.setBlockMetadataWithNotify(i + 0, j + 43, k + 1, 7, 2);
		setBlock(world, i + 0, j + 43, k + 2, Blocks.leaves, 7);
		world.setBlockMetadataWithNotify(i + 0, j + 43, k + 2, 7, 2);
		setBlock(world, i + 0, j + 43, k + 10, Blocks.log, 1);
		world.setBlockMetadataWithNotify(i + 0, j + 43, k + 10, 1, 2);
		setBlock(world, i + 0, j + 43, k + 11, Blocks.log, 1);
		world.setBlockMetadataWithNotify(i + 0, j + 43, k + 11, 1, 2);
		setBlock(world, i + 0, j + 43, k + 12, Blocks.log, 1);
		world.setBlockMetadataWithNotify(i + 0, j + 43, k + 12, 1, 2);
		setBlock(world, i + 0, j + 43, k + 13, Blocks.log, 1);
		world.setBlockMetadataWithNotify(i + 0, j + 43, k + 13, 1, 2);
		setBlock(world, i + 0, j + 43, k + 14, Blocks.log, 1);
		world.setBlockMetadataWithNotify(i + 0, j + 43, k + 14, 1, 2);
		setBlock(world, i + 0, j + 43, k + 26, Blocks.leaves, 7);
		world.setBlockMetadataWithNotify(i + 0, j + 43, k + 26, 7, 2);
		setBlock(world, i + 0, j + 43, k + 27, Blocks.leaves, 7);
		world.setBlockMetadataWithNotify(i + 0, j + 43, k + 27, 7, 2);
		setBlock(world, i + 0, j + 43, k + 28, Blocks.leaves, 7);
		world.setBlockMetadataWithNotify(i + 0, j + 43, k + 28, 7, 2);
		setBlock(world, i + 0, j + 43, k + 29, Blocks.leaves, 7);
		world.setBlockMetadataWithNotify(i + 0, j + 43, k + 29, 7, 2);
		setBlock(world, i + 0, j + 43, k + 30, Blocks.leaves, 7);
		world.setBlockMetadataWithNotify(i + 0, j + 43, k + 30, 7, 2);
		setBlock(world, i + 0, j + 43, k + 31, Blocks.leaves, 7);
		world.setBlockMetadataWithNotify(i + 0, j + 43, k + 31, 7, 2);
		setBlock(world, i + 0, j + 44, k + 0, Blocks.leaves, 7);
		world.setBlockMetadataWithNotify(i + 0, j + 44, k + 0, 7, 2);
		setBlock(world, i + 0, j + 44, k + 1, Blocks.leaves, 7);
		world.setBlockMetadataWithNotify(i + 0, j + 44, k + 1, 7, 2);
		setBlock(world, i + 0, j + 44, k + 27, Blocks.leaves, 7);
		world.setBlockMetadataWithNotify(i + 0, j + 44, k + 27, 7, 2);
		setBlock(world, i + 0, j + 44, k + 29, Blocks.leaves, 7);
		world.setBlockMetadataWithNotify(i + 0, j + 44, k + 29, 7, 2);
		setBlock(world, i + 0, j + 44, k + 30, Blocks.leaves, 7);
		world.setBlockMetadataWithNotify(i + 0, j + 44, k + 30, 7, 2);
		setBlock(world, i + 0, j + 44, k + 31, Blocks.leaves, 7);
		world.setBlockMetadataWithNotify(i + 0, j + 44, k + 31, 7, 2);
		setBlock(world, i + 0, j + 45, k + 0, Blocks.leaves, 7);
		world.setBlockMetadataWithNotify(i + 0, j + 45, k + 0, 7, 2);
		setBlock(world, i + 0, j + 45, k + 30, Blocks.leaves, 7);
		world.setBlockMetadataWithNotify(i + 0, j + 45, k + 30, 7, 2);
		setBlock(world, i + 0, j + 45, k + 31, Blocks.vine, 15);
		world.setBlockMetadataWithNotify(i + 0, j + 45, k + 31, 15, 2);
		setBlock(world, i + 0, j + 46, k + 27, Blocks.leaves, 7);
		world.setBlockMetadataWithNotify(i + 0, j + 46, k + 27, 7, 2);
		setBlock(world, i + 0, j + 46, k + 28, Blocks.leaves, 7);
		world.setBlockMetadataWithNotify(i + 0, j + 46, k + 28, 7, 2);
		setBlock(world, i + 0, j + 46, k + 29, Blocks.leaves, 7);
		world.setBlockMetadataWithNotify(i + 0, j + 46, k + 29, 7, 2);
		setBlock(world, i + 0, j + 46, k + 31, Blocks.vine, 15);
		world.setBlockMetadataWithNotify(i + 0, j + 46, k + 31, 15, 2);
		setBlock(world, i + 0, j + 47, k + 27, Blocks.vine, 15);
		world.setBlockMetadataWithNotify(i + 0, j + 47, k + 27, 15, 2);
		setBlock(world, i + 0, j + 47, k + 28, Blocks.leaves, 7);
		world.setBlockMetadataWithNotify(i + 0, j + 47, k + 28, 7, 2);
		setBlock(world, i + 0, j + 47, k + 29, Blocks.leaves, 7);
		world.setBlockMetadataWithNotify(i + 0, j + 47, k + 29, 7, 2);
		setBlock(world, i + 0, j + 47, k + 30, Blocks.leaves, 7);
		world.setBlockMetadataWithNotify(i + 0, j + 47, k + 30, 7, 2);
		setBlock(world, i + 0, j + 47, k + 31, Blocks.log, 3);
		world.setBlockMetadataWithNotify(i + 0, j + 47, k + 31, 3, 2);
		setBlock(world, i + 0, j + 48, k + 27, Blocks.vine, 15);
		world.setBlockMetadataWithNotify(i + 0, j + 48, k + 27, 15, 2);
		setBlock(world, i + 0, j + 48, k + 28, Blocks.vine, 15);
		world.setBlockMetadataWithNotify(i + 0, j + 48, k + 28, 15, 2);
		setBlock(world, i + 0, j + 48, k + 29, Blocks.leaves, 7);
		world.setBlockMetadataWithNotify(i + 0, j + 48, k + 29, 7, 2);
		setBlock(world, i + 0, j + 48, k + 30, Blocks.leaves, 7);
		world.setBlockMetadataWithNotify(i + 0, j + 48, k + 30, 7, 2);
		setBlock(world, i + 0, j + 48, k + 31, Blocks.leaves, 7);
		world.setBlockMetadataWithNotify(i + 0, j + 48, k + 31, 7, 2);
		setBlock(world, i + 0, j + 49, k + 30, Blocks.leaves, 7);
		world.setBlockMetadataWithNotify(i + 0, j + 49, k + 30, 7, 2);
		setBlock(world, i + 0, j + 49, k + 31, Blocks.leaves, 7);
		world.setBlockMetadataWithNotify(i + 0, j + 49, k + 31, 7, 2);
		setBlock(world, i + 0, j + 50, k + 30, Blocks.vine, 15);
		world.setBlockMetadataWithNotify(i + 0, j + 50, k + 30, 15, 2);
		setBlock(world, i + 0, j + 50, k + 31, Blocks.leaves, 7);
		world.setBlockMetadataWithNotify(i + 0, j + 50, k + 31, 7, 2);
		setBlock(world, i + 0, j + 63, k + 31, Blocks.log, 1);
		world.setBlockMetadataWithNotify(i + 0, j + 63, k + 31, 1, 2);
		setBlock(world, i + 0, j + 64, k + 31, Blocks.log, 1);
		world.setBlockMetadataWithNotify(i + 0, j + 64, k + 31, 1, 2);
		setBlock(world, i + 0, j + 65, k + 27, Blocks.log, 1);
		world.setBlockMetadataWithNotify(i + 0, j + 65, k + 27, 1, 2);
		setBlock(world, i + 0, j + 65, k + 28, Blocks.log, 1);
		world.setBlockMetadataWithNotify(i + 0, j + 65, k + 28, 1, 2);
		setBlock(world, i + 0, j + 65, k + 29, Blocks.log, 1);
		world.setBlockMetadataWithNotify(i + 0, j + 65, k + 29, 1, 2);
		setBlock(world, i + 0, j + 65, k + 30, Blocks.log, 1);
		world.setBlockMetadataWithNotify(i + 0, j + 65, k + 30, 1, 2);
		setBlock(world, i + 0, j + 65, k + 31, Blocks.log, 1);
		world.setBlockMetadataWithNotify(i + 0, j + 65, k + 31, 1, 2);
		setBlock(world, i + 0, j + 70, k + 25, Blocks.log, 1);
		world.setBlockMetadataWithNotify(i + 0, j + 70, k + 25, 1, 2);
		setBlock(world, i + 0, j + 70, k + 26, Blocks.log, 1);
		world.setBlockMetadataWithNotify(i + 0, j + 70, k + 26, 1, 2);
		setBlock(world, i + 0, j + 70, k + 27, Blocks.log, 1);
		world.setBlockMetadataWithNotify(i + 0, j + 70, k + 27, 1, 2);
		setBlock(world, i + 0, j + 70, k + 28, Blocks.log, 1);
		world.setBlockMetadataWithNotify(i + 0, j + 70, k + 28, 1, 2);
		setBlock(world, i + 0, j + 70, k + 29, Blocks.log, 1);
		world.setBlockMetadataWithNotify(i + 0, j + 70, k + 29, 1, 2);
		setBlock(world, i + 0, j + 70, k + 30, Blocks.log, 1);
		world.setBlockMetadataWithNotify(i + 0, j + 70, k + 30, 1, 2);
		setBlock(world, i + 0, j + 71, k + 26, Blocks.log, 1);
		world.setBlockMetadataWithNotify(i + 0, j + 71, k + 26, 1, 2);
		setBlock(world, i + 0, j + 71, k + 27, Blocks.log, 1);
		world.setBlockMetadataWithNotify(i + 0, j + 71, k + 27, 1, 2);
		setBlock(world, i + 0, j + 71, k + 28, Blocks.log, 1);
		world.setBlockMetadataWithNotify(i + 0, j + 71, k + 28, 1, 2);
		setBlock(world, i + 0, j + 71, k + 29, Blocks.log, 1);
		world.setBlockMetadataWithNotify(i + 0, j + 71, k + 29, 1, 2);
		setBlock(world, i + 0, j + 71, k + 30, Blocks.log, 1);
		world.setBlockMetadataWithNotify(i + 0, j + 71, k + 30, 1, 2);
		setBlock(world, i + 0, j + 71, k + 31, Blocks.log, 1);
		world.setBlockMetadataWithNotify(i + 0, j + 71, k + 31, 1, 2);
		setBlock(world, i + 0, j + 72, k + 28, Blocks.log, 1);
		world.setBlockMetadataWithNotify(i + 0, j + 72, k + 28, 1, 2);
		setBlock(world, i + 0, j + 72, k + 29, Blocks.log, 1);
		world.setBlockMetadataWithNotify(i + 0, j + 72, k + 29, 1, 2);
		setBlock(world, i + 0, j + 72, k + 30, Blocks.log, 1);
		world.setBlockMetadataWithNotify(i + 0, j + 72, k + 30, 1, 2);
		setBlock(world, i + 0, j + 72, k + 31, Blocks.log, 1);
		world.setBlockMetadataWithNotify(i + 0, j + 72, k + 31, 1, 2);
		setBlock(world, i + 1, j + 23, k + 2, Blocks.log, 3);
		world.setBlockMetadataWithNotify(i + 1, j + 23, k + 2, 3, 2);
		setBlock(world, i + 1, j + 24, k + 5, Blocks.leaves, 15);
		world.setBlockMetadataWithNotify(i + 1, j + 24, k + 5, 15, 2);
		setBlock(world, i + 1, j + 24, k + 6, Blocks.leaves, 7);
		world.setBlockMetadataWithNotify(i + 1, j + 24, k + 6, 7, 2);
		setBlock(world, i + 1, j + 24, k + 7, Blocks.leaves, 7);
		world.setBlockMetadataWithNotify(i + 1, j + 24, k + 7, 7, 2);
		setBlock(world, i + 1, j + 25, k + 6, Blocks.leaves, 7);
		world.setBlockMetadataWithNotify(i + 1, j + 25, k + 6, 7, 2);
		setBlock(world, i + 1, j + 27, k + 0, Blocks.leaves, 15);
		world.setBlockMetadataWithNotify(i + 1, j + 27, k + 0, 15, 2);
		setBlock(world, i + 1, j + 31, k + 24, Blocks.leaves, 7);
		world.setBlockMetadataWithNotify(i + 1, j + 31, k + 24, 7, 2);
		setBlock(world, i + 1, j + 31, k + 25, Blocks.leaves, 7);
		world.setBlockMetadataWithNotify(i + 1, j + 31, k + 25, 7, 2);
		setBlock(world, i + 1, j + 31, k + 26, Blocks.leaves, 7);
		world.setBlockMetadataWithNotify(i + 1, j + 31, k + 26, 7, 2);
		setBlock(world, i + 1, j + 31, k + 27, Blocks.leaves, 7);
		world.setBlockMetadataWithNotify(i + 1, j + 31, k + 27, 7, 2);
		setBlock(world, i + 1, j + 31, k + 28, Blocks.leaves, 7);
		world.setBlockMetadataWithNotify(i + 1, j + 31, k + 28, 7, 2);
		setBlock(world, i + 1, j + 32, k + 21, Blocks.leaves, 7);
		world.setBlockMetadataWithNotify(i + 1, j + 32, k + 21, 7, 2);
		setBlock(world, i + 1, j + 32, k + 22, Blocks.leaves, 7);
		world.setBlockMetadataWithNotify(i + 1, j + 32, k + 22, 7, 2);
		setBlock(world, i + 1, j + 32, k + 23, Blocks.leaves, 7);
		world.setBlockMetadataWithNotify(i + 1, j + 32, k + 23, 7, 2);
		setBlock(world, i + 1, j + 32, k + 25, Blocks.leaves, 7);
		world.setBlockMetadataWithNotify(i + 1, j + 32, k + 25, 7, 2);
		setBlock(world, i + 1, j + 32, k + 26, Blocks.leaves, 7);
		world.setBlockMetadataWithNotify(i + 1, j + 32, k + 26, 7, 2);
		setBlock(world, i + 1, j + 32, k + 27, Blocks.leaves, 7);
		world.setBlockMetadataWithNotify(i + 1, j + 32, k + 27, 7, 2);
		setBlock(world, i + 1, j + 33, k + 22, Blocks.leaves, 15);
		world.setBlockMetadataWithNotify(i + 1, j + 33, k + 22, 15, 2);
		setBlock(world, i + 1, j + 33, k + 26, Blocks.leaves, 7);
		world.setBlockMetadataWithNotify(i + 1, j + 33, k + 26, 7, 2);
		setBlock(world, i + 1, j + 35, k + 8, Blocks.log, 1);
		world.setBlockMetadataWithNotify(i + 1, j + 35, k + 8, 1, 2);
		setBlock(world, i + 1, j + 35, k + 9, Blocks.log, 1);
		world.setBlockMetadataWithNotify(i + 1, j + 35, k + 9, 1, 2);
		setBlock(world, i + 1, j + 35, k + 10, Blocks.log, 1);
		world.setBlockMetadataWithNotify(i + 1, j + 35, k + 10, 1, 2);
		setBlock(world, i + 1, j + 35, k + 11, Blocks.planks, 5);
		world.setBlockMetadataWithNotify(i + 1, j + 35, k + 11, 5, 2);
		setBlock(world, i + 1, j + 35, k + 12, Blocks.log, 1);
		world.setBlockMetadataWithNotify(i + 1, j + 35, k + 12, 1, 2);
		setBlock(world, i + 1, j + 35, k + 13, Blocks.planks, 5);
		world.setBlockMetadataWithNotify(i + 1, j + 35, k + 13, 5, 2);
		setBlock(world, i + 1, j + 35, k + 14, Blocks.log, 1);
		world.setBlockMetadataWithNotify(i + 1, j + 35, k + 14, 1, 2);
		setBlock(world, i + 1, j + 35, k + 15, Blocks.log, 1);
		world.setBlockMetadataWithNotify(i + 1, j + 35, k + 15, 1, 2);
		setBlock(world, i + 1, j + 35, k + 16, Blocks.log, 1);
		world.setBlockMetadataWithNotify(i + 1, j + 35, k + 16, 1, 2);
		setBlock(world, i + 1, j + 35, k + 21, Blocks.planks, 5);
		world.setBlockMetadataWithNotify(i + 1, j + 35, k + 21, 5, 2);
		setBlock(world, i + 1, j + 35, k + 22, Blocks.planks, 5);
		world.setBlockMetadataWithNotify(i + 1, j + 35, k + 22, 5, 2);
		setBlock(world, i + 1, j + 35, k + 23, Blocks.planks, 5);
		world.setBlockMetadataWithNotify(i + 1, j + 35, k + 23, 5, 2);
		setBlock(world, i + 1, j + 35, k + 24, Blocks.planks, 5);
		world.setBlockMetadataWithNotify(i + 1, j + 35, k + 24, 5, 2);
		setBlock(world, i + 1, j + 35, k + 25, Blocks.planks, 5);
		world.setBlockMetadataWithNotify(i + 1, j + 35, k + 25, 5, 2);
		setBlock(world, i + 1, j + 36, k + 10, Blocks.spruce_stairs, 1);
		world.setBlockMetadataWithNotify(i + 1, j + 36, k + 10, 1, 2);
		setBlock(world, i + 1, j + 36, k + 14, Blocks.spruce_stairs, 1);
		world.setBlockMetadataWithNotify(i + 1, j + 36, k + 14, 1, 2);
		setBlock(world, i + 1, j + 37, k + 9, Blocks.torch, 5);
		world.setBlockMetadataWithNotify(i + 1, j + 37, k + 9, 5, 2);
		setBlock(world, i + 1, j + 37, k + 15, Blocks.torch, 5);
		world.setBlockMetadataWithNotify(i + 1, j + 37, k + 15, 5, 2);
		setBlock(world, i + 1, j + 38, k + 0, Blocks.leaves, 7);
		world.setBlockMetadataWithNotify(i + 1, j + 38, k + 0, 7, 2);
		setBlock(world, i + 1, j + 38, k + 30, Blocks.log, 3);
		world.setBlockMetadataWithNotify(i + 1, j + 38, k + 30, 3, 2);
		setBlock(world, i + 1, j + 39, k + 4, Blocks.log, 1);
		world.setBlockMetadataWithNotify(i + 1, j + 39, k + 4, 1, 2);
		setBlock(world, i + 1, j + 39, k + 5, Blocks.log, 1);
		world.setBlockMetadataWithNotify(i + 1, j + 39, k + 5, 1, 2);
		setBlock(world, i + 1, j + 39, k + 6, Blocks.log, 1);
		world.setBlockMetadataWithNotify(i + 1, j + 39, k + 6, 1, 2);
		setBlock(world, i + 1, j + 39, k + 7, Blocks.log, 1);
		world.setBlockMetadataWithNotify(i + 1, j + 39, k + 7, 1, 2);
		setBlock(world, i + 1, j + 39, k + 8, Blocks.log, 1);
		world.setBlockMetadataWithNotify(i + 1, j + 39, k + 8, 1, 2);
		setBlock(world, i + 1, j + 39, k + 9, Blocks.log, 1);
		world.setBlockMetadataWithNotify(i + 1, j + 39, k + 9, 1, 2);
		setBlock(world, i + 1, j + 39, k + 10, Blocks.log, 1);
		world.setBlockMetadataWithNotify(i + 1, j + 39, k + 10, 1, 2);
		setBlock(world, i + 1, j + 39, k + 11, Blocks.log, 1);
		world.setBlockMetadataWithNotify(i + 1, j + 39, k + 11, 1, 2);
		setBlock(world, i + 1, j + 39, k + 12, Blocks.log, 1);
		world.setBlockMetadataWithNotify(i + 1, j + 39, k + 12, 1, 2);
		setBlock(world, i + 1, j + 39, k + 13, Blocks.log, 1);
		world.setBlockMetadataWithNotify(i + 1, j + 39, k + 13, 1, 2);
		setBlock(world, i + 1, j + 39, k + 14, Blocks.log, 1);
		world.setBlockMetadataWithNotify(i + 1, j + 39, k + 14, 1, 2);
		setBlock(world, i + 1, j + 39, k + 15, Blocks.log, 1);
		world.setBlockMetadataWithNotify(i + 1, j + 39, k + 15, 1, 2);
		setBlock(world, i + 1, j + 39, k + 16, Blocks.log, 1);
		world.setBlockMetadataWithNotify(i + 1, j + 39, k + 16, 1, 2);
		setBlock(world, i + 1, j + 39, k + 17, Blocks.log, 1);
		world.setBlockMetadataWithNotify(i + 1, j + 39, k + 17, 1, 2);
		setBlock(world, i + 1, j + 39, k + 18, Blocks.log, 1);
		world.setBlockMetadataWithNotify(i + 1, j + 39, k + 18, 1, 2);
		setBlock(world, i + 1, j + 39, k + 19, Blocks.log, 1);
		world.setBlockMetadataWithNotify(i + 1, j + 39, k + 19, 1, 2);
		setBlock(world, i + 1, j + 39, k + 20, Blocks.log, 1);
		world.setBlockMetadataWithNotify(i + 1, j + 39, k + 20, 1, 2);
		setBlock(world, i + 1, j + 39, k + 26, Blocks.leaves, 7);
		world.setBlockMetadataWithNotify(i + 1, j + 39, k + 26, 7, 2);
		setBlock(world, i + 1, j + 39, k + 27, Blocks.leaves, 7);
		world.setBlockMetadataWithNotify(i + 1, j + 39, k + 27, 7, 2);
		setBlock(world, i + 1, j + 39, k + 28, Blocks.leaves, 7);
		world.setBlockMetadataWithNotify(i + 1, j + 39, k + 28, 7, 2);
		setBlock(world, i + 1, j + 40, k + 6, Blocks.log, 1);
		world.setBlockMetadataWithNotify(i + 1, j + 40, k + 6, 1, 2);
		setBlock(world, i + 1, j + 40, k + 7, Blocks.log, 1);
		world.setBlockMetadataWithNotify(i + 1, j + 40, k + 7, 1, 2);
		setBlock(world, i + 1, j + 40, k + 8, Blocks.log, 1);
		world.setBlockMetadataWithNotify(i + 1, j + 40, k + 8, 1, 2);
		setBlock(world, i + 1, j + 40, k + 9, Blocks.log, 1);
		world.setBlockMetadataWithNotify(i + 1, j + 40, k + 9, 1, 2);
		setBlock(world, i + 1, j + 40, k + 10, Blocks.log, 1);
		world.setBlockMetadataWithNotify(i + 1, j + 40, k + 10, 1, 2);
		setBlock(world, i + 1, j + 40, k + 11, Blocks.log, 1);
		world.setBlockMetadataWithNotify(i + 1, j + 40, k + 11, 1, 2);
		setBlock(world, i + 1, j + 40, k + 12, Blocks.log, 1);
		world.setBlockMetadataWithNotify(i + 1, j + 40, k + 12, 1, 2);
		setBlock(world, i + 1, j + 40, k + 13, Blocks.log, 1);
		world.setBlockMetadataWithNotify(i + 1, j + 40, k + 13, 1, 2);
		setBlock(world, i + 1, j + 40, k + 14, Blocks.log, 1);
		world.setBlockMetadataWithNotify(i + 1, j + 40, k + 14, 1, 2);
		setBlock(world, i + 1, j + 40, k + 15, Blocks.log, 1);
		world.setBlockMetadataWithNotify(i + 1, j + 40, k + 15, 1, 2);
		setBlock(world, i + 1, j + 40, k + 16, Blocks.log, 1);
		world.setBlockMetadataWithNotify(i + 1, j + 40, k + 16, 1, 2);
		setBlock(world, i + 1, j + 40, k + 17, Blocks.log, 1);
		world.setBlockMetadataWithNotify(i + 1, j + 40, k + 17, 1, 2);
		setBlock(world, i + 1, j + 40, k + 18, Blocks.log, 1);
		world.setBlockMetadataWithNotify(i + 1, j + 40, k + 18, 1, 2);
		setBlock(world, i + 1, j + 40, k + 27, Blocks.leaves, 7);
		world.setBlockMetadataWithNotify(i + 1, j + 40, k + 27, 7, 2);
		setBlock(world, i + 1, j + 41, k + 0, Blocks.leaves, 7);
		world.setBlockMetadataWithNotify(i + 1, j + 41, k + 0, 7, 2);
		setBlock(world, i + 1, j + 41, k + 1, Blocks.leaves, 7);
		world.setBlockMetadataWithNotify(i + 1, j + 41, k + 1, 7, 2);
		setBlock(world, i + 1, j + 41, k + 6, Blocks.log, 1);
		world.setBlockMetadataWithNotify(i + 1, j + 41, k + 6, 1, 2);
		setBlock(world, i + 1, j + 41, k + 7, Blocks.log, 1);
		world.setBlockMetadataWithNotify(i + 1, j + 41, k + 7, 1, 2);
		setBlock(world, i + 1, j + 41, k + 8, Blocks.log, 1);
		world.setBlockMetadataWithNotify(i + 1, j + 41, k + 8, 1, 2);
		setBlock(world, i + 1, j + 41, k + 9, Blocks.log, 1);
		world.setBlockMetadataWithNotify(i + 1, j + 41, k + 9, 1, 2);
		setBlock(world, i + 1, j + 41, k + 10, Blocks.log, 1);
		world.setBlockMetadataWithNotify(i + 1, j + 41, k + 10, 1, 2);
		setBlock(world, i + 1, j + 41, k + 11, Blocks.log, 1);
		world.setBlockMetadataWithNotify(i + 1, j + 41, k + 11, 1, 2);
		setBlock(world, i + 1, j + 41, k + 12, Blocks.log, 1);
		world.setBlockMetadataWithNotify(i + 1, j + 41, k + 12, 1, 2);
		setBlock(world, i + 1, j + 41, k + 13, Blocks.log, 1);
		world.setBlockMetadataWithNotify(i + 1, j + 41, k + 13, 1, 2);
		setBlock(world, i + 1, j + 41, k + 14, Blocks.log, 1);
		world.setBlockMetadataWithNotify(i + 1, j + 41, k + 14, 1, 2);
		setBlock(world, i + 1, j + 41, k + 15, Blocks.log, 1);
		world.setBlockMetadataWithNotify(i + 1, j + 41, k + 15, 1, 2);
		setBlock(world, i + 1, j + 41, k + 16, Blocks.log, 1);
		world.setBlockMetadataWithNotify(i + 1, j + 41, k + 16, 1, 2);
		setBlock(world, i + 1, j + 41, k + 17, Blocks.log, 1);
		world.setBlockMetadataWithNotify(i + 1, j + 41, k + 17, 1, 2);
		setBlock(world, i + 1, j + 41, k + 18, Blocks.log, 1);
		world.setBlockMetadataWithNotify(i + 1, j + 41, k + 18, 1, 2);
		setBlock(world, i + 1, j + 41, k + 30, Blocks.log, 3);
		world.setBlockMetadataWithNotify(i + 1, j + 41, k + 30, 3, 2);
		setBlock(world, i + 1, j + 42, k + 0, Blocks.leaves, 7);
		world.setBlockMetadataWithNotify(i + 1, j + 42, k + 0, 7, 2);
		setBlock(world, i + 1, j + 42, k + 7, Blocks.log, 1);
		world.setBlockMetadataWithNotify(i + 1, j + 42, k + 7, 1, 2);
		setBlock(world, i + 1, j + 42, k + 8, Blocks.log, 1);
		world.setBlockMetadataWithNotify(i + 1, j + 42, k + 8, 1, 2);
		setBlock(world, i + 1, j + 42, k + 9, Blocks.log, 1);
		world.setBlockMetadataWithNotify(i + 1, j + 42, k + 9, 1, 2);
		setBlock(world, i + 1, j + 42, k + 10, Blocks.log, 1);
		world.setBlockMetadataWithNotify(i + 1, j + 42, k + 10, 1, 2);
		setBlock(world, i + 1, j + 42, k + 11, Blocks.log, 1);
		world.setBlockMetadataWithNotify(i + 1, j + 42, k + 11, 1, 2);
		setBlock(world, i + 1, j + 42, k + 12, Blocks.log, 1);
		world.setBlockMetadataWithNotify(i + 1, j + 42, k + 12, 1, 2);
		setBlock(world, i + 1, j + 42, k + 13, Blocks.log, 1);
		world.setBlockMetadataWithNotify(i + 1, j + 42, k + 13, 1, 2);
		setBlock(world, i + 1, j + 42, k + 14, Blocks.log, 1);
		world.setBlockMetadataWithNotify(i + 1, j + 42, k + 14, 1, 2);
		setBlock(world, i + 1, j + 42, k + 15, Blocks.log, 1);
		world.setBlockMetadataWithNotify(i + 1, j + 42, k + 15, 1, 2);
		setBlock(world, i + 1, j + 42, k + 16, Blocks.log, 1);
		world.setBlockMetadataWithNotify(i + 1, j + 42, k + 16, 1, 2);
		setBlock(world, i + 1, j + 42, k + 17, Blocks.log, 1);
		world.setBlockMetadataWithNotify(i + 1, j + 42, k + 17, 1, 2);
		setBlock(world, i + 1, j + 42, k + 26, Blocks.leaves, 7);
		world.setBlockMetadataWithNotify(i + 1, j + 42, k + 26, 7, 2);
		setBlock(world, i + 1, j + 42, k + 27, Blocks.leaves, 7);
		world.setBlockMetadataWithNotify(i + 1, j + 42, k + 27, 7, 2);
		setBlock(world, i + 1, j + 42, k + 28, Blocks.leaves, 7);
		world.setBlockMetadataWithNotify(i + 1, j + 42, k + 28, 7, 2);
		setBlock(world, i + 1, j + 42, k + 31, Blocks.log, 3);
		world.setBlockMetadataWithNotify(i + 1, j + 42, k + 31, 3, 2);
		setBlock(world, i + 1, j + 43, k + 0, Blocks.log, 3);
		world.setBlockMetadataWithNotify(i + 1, j + 43, k + 0, 3, 2);
		setBlock(world, i + 1, j + 43, k + 1, Blocks.leaves, 7);
		world.setBlockMetadataWithNotify(i + 1, j + 43, k + 1, 7, 2);
		setBlock(world, i + 1, j + 43, k + 2, Blocks.leaves, 7);
		world.setBlockMetadataWithNotify(i + 1, j + 43, k + 2, 7, 2);
		setBlock(world, i + 1, j + 43, k + 9, Blocks.log, 1);
		world.setBlockMetadataWithNotify(i + 1, j + 43, k + 9, 1, 2);
		setBlock(world, i + 1, j + 43, k + 10, Blocks.log, 1);
		world.setBlockMetadataWithNotify(i + 1, j + 43, k + 10, 1, 2);
		setBlock(world, i + 1, j + 43, k + 11, Blocks.log, 1);
		world.setBlockMetadataWithNotify(i + 1, j + 43, k + 11, 1, 2);
		setBlock(world, i + 1, j + 43, k + 12, Blocks.log, 1);
		world.setBlockMetadataWithNotify(i + 1, j + 43, k + 12, 1, 2);
		setBlock(world, i + 1, j + 43, k + 13, Blocks.log, 1);
		world.setBlockMetadataWithNotify(i + 1, j + 43, k + 13, 1, 2);
		setBlock(world, i + 1, j + 43, k + 14, Blocks.log, 1);
		world.setBlockMetadataWithNotify(i + 1, j + 43, k + 14, 1, 2);
		setBlock(world, i + 1, j + 43, k + 15, Blocks.log, 1);
		world.setBlockMetadataWithNotify(i + 1, j + 43, k + 15, 1, 2);
		setBlock(world, i + 1, j + 43, k + 27, Blocks.leaves, 7);
		world.setBlockMetadataWithNotify(i + 1, j + 43, k + 27, 7, 2);
		setBlock(world, i + 1, j + 43, k + 28, Blocks.leaves, 7);
		world.setBlockMetadataWithNotify(i + 1, j + 43, k + 28, 7, 2);
		setBlock(world, i + 1, j + 43, k + 29, Blocks.leaves, 7);
		world.setBlockMetadataWithNotify(i + 1, j + 43, k + 29, 7, 2);
		setBlock(world, i + 1, j + 43, k + 30, Blocks.log, 3);
		world.setBlockMetadataWithNotify(i + 1, j + 43, k + 30, 3, 2);
		setBlock(world, i + 1, j + 43, k + 31, Blocks.leaves, 7);
		world.setBlockMetadataWithNotify(i + 1, j + 43, k + 31, 7, 2);
		setBlock(world, i + 1, j + 44, k + 0, Blocks.leaves, 7);
		world.setBlockMetadataWithNotify(i + 1, j + 44, k + 0, 7, 2);
		setBlock(world, i + 1, j + 44, k + 1, Blocks.leaves, 7);
		world.setBlockMetadataWithNotify(i + 1, j + 44, k + 1, 7, 2);
		setBlock(world, i + 1, j + 44, k + 2, Blocks.leaves, 7);
		world.setBlockMetadataWithNotify(i + 1, j + 44, k + 2, 7, 2);
		setBlock(world, i + 1, j + 44, k + 28, Blocks.leaves, 7);
		world.setBlockMetadataWithNotify(i + 1, j + 44, k + 28, 7, 2);
		setBlock(world, i + 1, j + 44, k + 29, Blocks.leaves, 7);
		world.setBlockMetadataWithNotify(i + 1, j + 44, k + 29, 7, 2);
		setBlock(world, i + 1, j + 44, k + 30, Blocks.leaves, 7);
		world.setBlockMetadataWithNotify(i + 1, j + 44, k + 30, 7, 2);
		setBlock(world, i + 1, j + 44, k + 31, Blocks.leaves, 7);
		world.setBlockMetadataWithNotify(i + 1, j + 44, k + 31, 7, 2);
		setBlock(world, i + 1, j + 45, k + 0, Blocks.leaves, 7);
		world.setBlockMetadataWithNotify(i + 1, j + 45, k + 0, 7, 2);
		setBlock(world, i + 1, j + 45, k + 1, Blocks.leaves, 7);
		world.setBlockMetadataWithNotify(i + 1, j + 45, k + 1, 7, 2);
		setBlock(world, i + 1, j + 45, k + 29, Blocks.leaves, 7);
		world.setBlockMetadataWithNotify(i + 1, j + 45, k + 29, 7, 2);
		setBlock(world, i + 1, j + 45, k + 30, Blocks.leaves, 7);
		world.setBlockMetadataWithNotify(i + 1, j + 45, k + 30, 7, 2);
		setBlock(world, i + 1, j + 45, k + 31, Blocks.leaves, 7);
		world.setBlockMetadataWithNotify(i + 1, j + 45, k + 31, 7, 2);
		setBlock(world, i + 1, j + 46, k + 0, Blocks.leaves, 7);
		world.setBlockMetadataWithNotify(i + 1, j + 46, k + 0, 7, 2);
		setBlock(world, i + 1, j + 46, k + 26, Blocks.leaves, 7);
		world.setBlockMetadataWithNotify(i + 1, j + 46, k + 26, 7, 2);
		setBlock(world, i + 1, j + 46, k + 27, Blocks.leaves, 7);
		world.setBlockMetadataWithNotify(i + 1, j + 46, k + 27, 7, 2);
		setBlock(world, i + 1, j + 46, k + 28, Blocks.leaves, 7);
		world.setBlockMetadataWithNotify(i + 1, j + 46, k + 28, 7, 2);
		setBlock(world, i + 1, j + 46, k + 29, Blocks.leaves, 7);
		world.setBlockMetadataWithNotify(i + 1, j + 46, k + 29, 7, 2);
		setBlock(world, i + 1, j + 46, k + 30, Blocks.leaves, 7);
		world.setBlockMetadataWithNotify(i + 1, j + 46, k + 30, 7, 2);
		setBlock(world, i + 1, j + 46, k + 31, Blocks.leaves, 7);
		world.setBlockMetadataWithNotify(i + 1, j + 46, k + 31, 7, 2);
		setBlock(world, i + 1, j + 47, k + 27, Blocks.leaves, 7);
		world.setBlockMetadataWithNotify(i + 1, j + 47, k + 27, 7, 2);
		setBlock(world, i + 1, j + 47, k + 28, Blocks.leaves, 7);
		world.setBlockMetadataWithNotify(i + 1, j + 47, k + 28, 7, 2);
		setBlock(world, i + 1, j + 47, k + 29, Blocks.leaves, 7);
		world.setBlockMetadataWithNotify(i + 1, j + 47, k + 29, 7, 2);
		setBlock(world, i + 1, j + 47, k + 30, Blocks.leaves, 7);
		world.setBlockMetadataWithNotify(i + 1, j + 47, k + 30, 7, 2);
		setBlock(world, i + 1, j + 47, k + 31, Blocks.leaves, 7);
		world.setBlockMetadataWithNotify(i + 1, j + 47, k + 31, 7, 2);
		setBlock(world, i + 1, j + 48, k + 27, Blocks.vine, 15);
		world.setBlockMetadataWithNotify(i + 1, j + 48, k + 27, 15, 2);
		setBlock(world, i + 1, j + 48, k + 28, Blocks.leaves, 7);
		world.setBlockMetadataWithNotify(i + 1, j + 48, k + 28, 7, 2);
		setBlock(world, i + 1, j + 48, k + 30, Blocks.leaves, 7);
		world.setBlockMetadataWithNotify(i + 1, j + 48, k + 30, 7, 2);
		setBlock(world, i + 1, j + 48, k + 31, Blocks.leaves, 7);
		world.setBlockMetadataWithNotify(i + 1, j + 48, k + 31, 7, 2);
		setBlock(world, i + 1, j + 49, k + 0, Blocks.leaves, 7);
		world.setBlockMetadataWithNotify(i + 1, j + 49, k + 0, 7, 2);
		setBlock(world, i + 1, j + 49, k + 27, Blocks.vine, 15);
		world.setBlockMetadataWithNotify(i + 1, j + 49, k + 27, 15, 2);
		setBlock(world, i + 1, j + 49, k + 28, Blocks.vine, 15);
		world.setBlockMetadataWithNotify(i + 1, j + 49, k + 28, 15, 2);
		setBlock(world, i + 1, j + 49, k + 31, Blocks.leaves, 7);
		world.setBlockMetadataWithNotify(i + 1, j + 49, k + 31, 7, 2);
		setBlock(world, i + 1, j + 63, k + 31, Blocks.log, 1);
		world.setBlockMetadataWithNotify(i + 1, j + 63, k + 31, 1, 2);
		setBlock(world, i + 1, j + 64, k + 31, Blocks.log, 1);
		world.setBlockMetadataWithNotify(i + 1, j + 64, k + 31, 1, 2);
		setBlock(world, i + 1, j + 65, k + 27, Blocks.log, 1);
		world.setBlockMetadataWithNotify(i + 1, j + 65, k + 27, 1, 2);
		setBlock(world, i + 1, j + 65, k + 28, Blocks.log, 1);
		world.setBlockMetadataWithNotify(i + 1, j + 65, k + 28, 1, 2);
		setBlock(world, i + 1, j + 65, k + 29, Blocks.planks, 5);
		world.setBlockMetadataWithNotify(i + 1, j + 65, k + 29, 5, 2);
		setBlock(world, i + 1, j + 65, k + 30, Blocks.planks, 5);
		world.setBlockMetadataWithNotify(i + 1, j + 65, k + 30, 5, 2);
		setBlock(world, i + 1, j + 65, k + 31, Blocks.planks, 5);
		world.setBlockMetadataWithNotify(i + 1, j + 65, k + 31, 5, 2);
		setBlock(world, i + 1, j + 70, k + 25, Blocks.log, 1);
		world.setBlockMetadataWithNotify(i + 1, j + 70, k + 25, 1, 2);
		setBlock(world, i + 1, j + 70, k + 26, Blocks.log, 1);
		world.setBlockMetadataWithNotify(i + 1, j + 70, k + 26, 1, 2);
		setBlock(world, i + 1, j + 70, k + 27, Blocks.log, 1);
		world.setBlockMetadataWithNotify(i + 1, j + 70, k + 27, 1, 2);
		setBlock(world, i + 1, j + 70, k + 28, Blocks.log, 1);
		world.setBlockMetadataWithNotify(i + 1, j + 70, k + 28, 1, 2);
		setBlock(world, i + 1, j + 70, k + 29, Blocks.log, 1);
		world.setBlockMetadataWithNotify(i + 1, j + 70, k + 29, 1, 2);
		setBlock(world, i + 1, j + 71, k + 26, Blocks.log, 1);
		world.setBlockMetadataWithNotify(i + 1, j + 71, k + 26, 1, 2);
		setBlock(world, i + 1, j + 71, k + 27, Blocks.log, 1);
		world.setBlockMetadataWithNotify(i + 1, j + 71, k + 27, 1, 2);
		setBlock(world, i + 1, j + 71, k + 28, Blocks.log, 1);
		world.setBlockMetadataWithNotify(i + 1, j + 71, k + 28, 1, 2);
		setBlock(world, i + 1, j + 71, k + 29, Blocks.log, 1);
		world.setBlockMetadataWithNotify(i + 1, j + 71, k + 29, 1, 2);
		setBlock(world, i + 1, j + 71, k + 30, Blocks.log, 1);
		world.setBlockMetadataWithNotify(i + 1, j + 71, k + 30, 1, 2);
		setBlock(world, i + 1, j + 72, k + 28, Blocks.log, 1);
		world.setBlockMetadataWithNotify(i + 1, j + 72, k + 28, 1, 2);
		setBlock(world, i + 1, j + 72, k + 29, Blocks.log, 1);
		world.setBlockMetadataWithNotify(i + 1, j + 72, k + 29, 1, 2);
		setBlock(world, i + 1, j + 72, k + 30, Blocks.log, 1);
		world.setBlockMetadataWithNotify(i + 1, j + 72, k + 30, 1, 2);
		setBlock(world, i + 1, j + 72, k + 31, Blocks.log, 1);
		world.setBlockMetadataWithNotify(i + 1, j + 72, k + 31, 1, 2);
		setBlock(world, i + 2, j + 22, k + 0, Blocks.log, 3);
		world.setBlockMetadataWithNotify(i + 2, j + 22, k + 0, 3, 2);
		setBlock(world, i + 2, j + 22, k + 1, Blocks.log, 3);
		world.setBlockMetadataWithNotify(i + 2, j + 22, k + 1, 3, 2);
		setBlock(world, i + 2, j + 30, k + 27, Blocks.log, 3);
		world.setBlockMetadataWithNotify(i + 2, j + 30, k + 27, 3, 2);
		setBlock(world, i + 2, j + 30, k + 28, Blocks.log, 3);
		world.setBlockMetadataWithNotify(i + 2, j + 30, k + 28, 3, 2);
		setBlock(world, i + 2, j + 31, k + 24, Blocks.leaves, 7);
		world.setBlockMetadataWithNotify(i + 2, j + 31, k + 24, 7, 2);
		setBlock(world, i + 2, j + 31, k + 25, Blocks.leaves, 7);
		world.setBlockMetadataWithNotify(i + 2, j + 31, k + 25, 7, 2);
		setBlock(world, i + 2, j + 31, k + 26, Blocks.log, 3);
		world.setBlockMetadataWithNotify(i + 2, j + 31, k + 26, 3, 2);
		setBlock(world, i + 2, j + 31, k + 27, Blocks.leaves, 7);
		world.setBlockMetadataWithNotify(i + 2, j + 31, k + 27, 7, 2);
		
		generate91(world, rand, i, j, k);
		return true;
		}

	
	public boolean generate91(World world, Random rand, int i, int j, int k)
	
	{
		setBlock(world, i + 2, j + 31, k + 28, Blocks.leaves, 7);
		world.setBlockMetadataWithNotify(i + 2, j + 31, k + 28, 7, 2);
		setBlock(world, i + 2, j + 32, k + 20, Blocks.leaves, 15);
		world.setBlockMetadataWithNotify(i + 2, j + 32, k + 20, 15, 2);
		setBlock(world, i + 2, j + 32, k + 21, Blocks.leaves, 7);
		world.setBlockMetadataWithNotify(i + 2, j + 32, k + 21, 7, 2);
		setBlock(world, i + 2, j + 32, k + 22, Blocks.leaves, 7);
		world.setBlockMetadataWithNotify(i + 2, j + 32, k + 22, 7, 2);
		setBlock(world, i + 2, j + 32, k + 23, Blocks.leaves, 7);
		world.setBlockMetadataWithNotify(i + 2, j + 32, k + 23, 7, 2);
		setBlock(world, i + 2, j + 32, k + 24, Blocks.leaves, 7);
		world.setBlockMetadataWithNotify(i + 2, j + 32, k + 24, 7, 2);
		setBlock(world, i + 2, j + 32, k + 25, Blocks.leaves, 7);
		world.setBlockMetadataWithNotify(i + 2, j + 32, k + 25, 7, 2);
		setBlock(world, i + 2, j + 32, k + 26, Blocks.leaves, 7);
		world.setBlockMetadataWithNotify(i + 2, j + 32, k + 26, 7, 2);
		setBlock(world, i + 2, j + 32, k + 27, Blocks.leaves, 7);
		world.setBlockMetadataWithNotify(i + 2, j + 32, k + 27, 7, 2);
		setBlock(world, i + 2, j + 32, k + 28, Blocks.leaves, 7);
		world.setBlockMetadataWithNotify(i + 2, j + 32, k + 28, 7, 2);
		setBlock(world, i + 2, j + 33, k + 21, Blocks.leaves, 15);
		world.setBlockMetadataWithNotify(i + 2, j + 33, k + 21, 15, 2);
		setBlock(world, i + 2, j + 33, k + 22, Blocks.leaves, 15);
		world.setBlockMetadataWithNotify(i + 2, j + 33, k + 22, 15, 2);
		setBlock(world, i + 2, j + 33, k + 23, Blocks.leaves, 15);
		world.setBlockMetadataWithNotify(i + 2, j + 33, k + 23, 15, 2);
		setBlock(world, i + 2, j + 33, k + 25, Blocks.leaves, 7);
		world.setBlockMetadataWithNotify(i + 2, j + 33, k + 25, 7, 2);
		setBlock(world, i + 2, j + 33, k + 26, Blocks.leaves, 7);
		world.setBlockMetadataWithNotify(i + 2, j + 33, k + 26, 7, 2);
		setBlock(world, i + 2, j + 33, k + 27, Blocks.leaves, 7);
		world.setBlockMetadataWithNotify(i + 2, j + 33, k + 27, 7, 2);
		setBlock(world, i + 2, j + 34, k + 26, Blocks.leaves, 7);
		world.setBlockMetadataWithNotify(i + 2, j + 34, k + 26, 7, 2);
		setBlock(world, i + 2, j + 35, k + 7, Blocks.log, 1);
		world.setBlockMetadataWithNotify(i + 2, j + 35, k + 7, 1, 2);
		setBlock(world, i + 2, j + 35, k + 8, Blocks.log, 1);
		world.setBlockMetadataWithNotify(i + 2, j + 35, k + 8, 1, 2);
		setBlock(world, i + 2, j + 35, k + 9, Blocks.planks, 5);
		world.setBlockMetadataWithNotify(i + 2, j + 35, k + 9, 5, 2);
		setBlock(world, i + 2, j + 35, k + 10, Blocks.planks, 5);
		world.setBlockMetadataWithNotify(i + 2, j + 35, k + 10, 5, 2);
		setBlock(world, i + 2, j + 35, k + 11, Blocks.planks, 5);
		world.setBlockMetadataWithNotify(i + 2, j + 35, k + 11, 5, 2);
		setBlock(world, i + 2, j + 35, k + 12, Blocks.planks, 5);
		world.setBlockMetadataWithNotify(i + 2, j + 35, k + 12, 5, 2);
		setBlock(world, i + 2, j + 35, k + 13, Blocks.planks, 5);
		world.setBlockMetadataWithNotify(i + 2, j + 35, k + 13, 5, 2);
		setBlock(world, i + 2, j + 35, k + 14, Blocks.planks, 5);
		world.setBlockMetadataWithNotify(i + 2, j + 35, k + 14, 5, 2);
		setBlock(world, i + 2, j + 35, k + 15, Blocks.planks, 5);
		world.setBlockMetadataWithNotify(i + 2, j + 35, k + 15, 5, 2);
		setBlock(world, i + 2, j + 35, k + 16, Blocks.log, 1);
		world.setBlockMetadataWithNotify(i + 2, j + 35, k + 16, 1, 2);
		setBlock(world, i + 2, j + 35, k + 17, Blocks.log, 1);
		world.setBlockMetadataWithNotify(i + 2, j + 35, k + 17, 1, 2);
		setBlock(world, i + 2, j + 35, k + 21, Blocks.planks, 5);
		world.setBlockMetadataWithNotify(i + 2, j + 35, k + 21, 5, 2);
		setBlock(world, i + 2, j + 35, k + 22, Blocks.planks, 5);
		world.setBlockMetadataWithNotify(i + 2, j + 35, k + 22, 5, 2);
		setBlock(world, i + 2, j + 35, k + 23, Blocks.planks, 5);
		world.setBlockMetadataWithNotify(i + 2, j + 35, k + 23, 5, 2);
		setBlock(world, i + 2, j + 35, k + 24, Blocks.planks, 5);
		world.setBlockMetadataWithNotify(i + 2, j + 35, k + 24, 5, 2);
		setBlock(world, i + 2, j + 35, k + 25, Blocks.planks, 5);
		world.setBlockMetadataWithNotify(i + 2, j + 35, k + 25, 5, 2);
		setBlock(world, i + 2, j + 37, k + 31, Blocks.log, 3);
		world.setBlockMetadataWithNotify(i + 2, j + 37, k + 31, 3, 2);
		setBlock(world, i + 2, j + 38, k + 0, Blocks.leaves, 7);
		world.setBlockMetadataWithNotify(i + 2, j + 38, k + 0, 7, 2);
		setBlock(world, i + 2, j + 38, k + 1, Blocks.leaves, 7);
		world.setBlockMetadataWithNotify(i + 2, j + 38, k + 1, 7, 2);
		setBlock(world, i + 2, j + 39, k + 0, Blocks.leaves, 7);
		world.setBlockMetadataWithNotify(i + 2, j + 39, k + 0, 7, 2);
		setBlock(world, i + 2, j + 39, k + 4, Blocks.log, 1);
		world.setBlockMetadataWithNotify(i + 2, j + 39, k + 4, 1, 2);
		setBlock(world, i + 2, j + 39, k + 5, Blocks.log, 1);
		world.setBlockMetadataWithNotify(i + 2, j + 39, k + 5, 1, 2);
		setBlock(world, i + 2, j + 39, k + 6, Blocks.log, 1);
		world.setBlockMetadataWithNotify(i + 2, j + 39, k + 6, 1, 2);
		setBlock(world, i + 2, j + 39, k + 7, Blocks.log, 1);
		world.setBlockMetadataWithNotify(i + 2, j + 39, k + 7, 1, 2);
		setBlock(world, i + 2, j + 39, k + 17, Blocks.log, 1);
		world.setBlockMetadataWithNotify(i + 2, j + 39, k + 17, 1, 2);
		setBlock(world, i + 2, j + 39, k + 18, Blocks.log, 1);
		world.setBlockMetadataWithNotify(i + 2, j + 39, k + 18, 1, 2);
		setBlock(world, i + 2, j + 39, k + 19, Blocks.log, 1);
		world.setBlockMetadataWithNotify(i + 2, j + 39, k + 19, 1, 2);
		setBlock(world, i + 2, j + 39, k + 20, Blocks.log, 1);
		world.setBlockMetadataWithNotify(i + 2, j + 39, k + 20, 1, 2);
		setBlock(world, i + 2, j + 40, k + 5, Blocks.log, 1);
		world.setBlockMetadataWithNotify(i + 2, j + 40, k + 5, 1, 2);
		setBlock(world, i + 2, j + 40, k + 6, Blocks.log, 1);
		world.setBlockMetadataWithNotify(i + 2, j + 40, k + 6, 1, 2);
		setBlock(world, i + 2, j + 40, k + 7, Blocks.log, 1);
		world.setBlockMetadataWithNotify(i + 2, j + 40, k + 7, 1, 2);
		setBlock(world, i + 2, j + 40, k + 8, Blocks.log, 1);
		world.setBlockMetadataWithNotify(i + 2, j + 40, k + 8, 1, 2);
		setBlock(world, i + 2, j + 40, k + 9, Blocks.log, 1);
		world.setBlockMetadataWithNotify(i + 2, j + 40, k + 9, 1, 2);
		setBlock(world, i + 2, j + 40, k + 10, Blocks.log, 1);
		world.setBlockMetadataWithNotify(i + 2, j + 40, k + 10, 1, 2);
		setBlock(world, i + 2, j + 40, k + 11, Blocks.log, 1);
		world.setBlockMetadataWithNotify(i + 2, j + 40, k + 11, 1, 2);
		setBlock(world, i + 2, j + 40, k + 12, Blocks.log, 1);
		world.setBlockMetadataWithNotify(i + 2, j + 40, k + 12, 1, 2);
		setBlock(world, i + 2, j + 40, k + 13, Blocks.log, 1);
		world.setBlockMetadataWithNotify(i + 2, j + 40, k + 13, 1, 2);
		setBlock(world, i + 2, j + 40, k + 14, Blocks.log, 1);
		world.setBlockMetadataWithNotify(i + 2, j + 40, k + 14, 1, 2);
		setBlock(world, i + 2, j + 40, k + 15, Blocks.log, 1);
		world.setBlockMetadataWithNotify(i + 2, j + 40, k + 15, 1, 2);
		setBlock(world, i + 2, j + 40, k + 16, Blocks.log, 1);
		world.setBlockMetadataWithNotify(i + 2, j + 40, k + 16, 1, 2);
		setBlock(world, i + 2, j + 40, k + 17, Blocks.log, 1);
		world.setBlockMetadataWithNotify(i + 2, j + 40, k + 17, 1, 2);
		setBlock(world, i + 2, j + 40, k + 18, Blocks.log, 1);
		world.setBlockMetadataWithNotify(i + 2, j + 40, k + 18, 1, 2);
		setBlock(world, i + 2, j + 40, k + 19, Blocks.log, 1);
		world.setBlockMetadataWithNotify(i + 2, j + 40, k + 19, 1, 2);
		setBlock(world, i + 2, j + 41, k + 0, Blocks.leaves, 7);
		world.setBlockMetadataWithNotify(i + 2, j + 41, k + 0, 7, 2);
		setBlock(world, i + 2, j + 41, k + 1, Blocks.leaves, 7);
		world.setBlockMetadataWithNotify(i + 2, j + 41, k + 1, 7, 2);
		setBlock(world, i + 2, j + 41, k + 2, Blocks.leaves, 7);
		world.setBlockMetadataWithNotify(i + 2, j + 41, k + 2, 7, 2);
		setBlock(world, i + 2, j + 41, k + 5, Blocks.log, 1);
		world.setBlockMetadataWithNotify(i + 2, j + 41, k + 5, 1, 2);
		setBlock(world, i + 2, j + 41, k + 6, Blocks.log, 1);
		world.setBlockMetadataWithNotify(i + 2, j + 41, k + 6, 1, 2);
		setBlock(world, i + 2, j + 41, k + 7, Blocks.log, 1);
		world.setBlockMetadataWithNotify(i + 2, j + 41, k + 7, 1, 2);
		setBlock(world, i + 2, j + 41, k + 8, Blocks.log, 1);
		world.setBlockMetadataWithNotify(i + 2, j + 41, k + 8, 1, 2);
		setBlock(world, i + 2, j + 41, k + 9, Blocks.log, 1);
		world.setBlockMetadataWithNotify(i + 2, j + 41, k + 9, 1, 2);
		setBlock(world, i + 2, j + 41, k + 10, Blocks.log, 1);
		world.setBlockMetadataWithNotify(i + 2, j + 41, k + 10, 1, 2);
		setBlock(world, i + 2, j + 41, k + 11, Blocks.log, 1);
		world.setBlockMetadataWithNotify(i + 2, j + 41, k + 11, 1, 2);
		setBlock(world, i + 2, j + 41, k + 12, Blocks.log, 1);
		world.setBlockMetadataWithNotify(i + 2, j + 41, k + 12, 1, 2);
		setBlock(world, i + 2, j + 41, k + 13, Blocks.log, 1);
		world.setBlockMetadataWithNotify(i + 2, j + 41, k + 13, 1, 2);
		setBlock(world, i + 2, j + 41, k + 14, Blocks.log, 1);
		world.setBlockMetadataWithNotify(i + 2, j + 41, k + 14, 1, 2);
		setBlock(world, i + 2, j + 41, k + 15, Blocks.log, 1);
		world.setBlockMetadataWithNotify(i + 2, j + 41, k + 15, 1, 2);
		setBlock(world, i + 2, j + 41, k + 16, Blocks.log, 1);
		world.setBlockMetadataWithNotify(i + 2, j + 41, k + 16, 1, 2);
		setBlock(world, i + 2, j + 41, k + 17, Blocks.log, 1);
		world.setBlockMetadataWithNotify(i + 2, j + 41, k + 17, 1, 2);
		setBlock(world, i + 2, j + 41, k + 18, Blocks.log, 1);
		world.setBlockMetadataWithNotify(i + 2, j + 41, k + 18, 1, 2);
		setBlock(world, i + 2, j + 41, k + 19, Blocks.log, 1);
		world.setBlockMetadataWithNotify(i + 2, j + 41, k + 19, 1, 2);
		setBlock(world, i + 2, j + 41, k + 31, Blocks.log, 3);
		world.setBlockMetadataWithNotify(i + 2, j + 41, k + 31, 3, 2);
		setBlock(world, i + 2, j + 42, k + 0, Blocks.leaves, 7);
		world.setBlockMetadataWithNotify(i + 2, j + 42, k + 0, 7, 2);
		setBlock(world, i + 2, j + 42, k + 1, Blocks.leaves, 7);
		world.setBlockMetadataWithNotify(i + 2, j + 42, k + 1, 7, 2);
		setBlock(world, i + 2, j + 42, k + 6, Blocks.log, 1);
		world.setBlockMetadataWithNotify(i + 2, j + 42, k + 6, 1, 2);
		setBlock(world, i + 2, j + 42, k + 7, Blocks.log, 1);
		world.setBlockMetadataWithNotify(i + 2, j + 42, k + 7, 1, 2);
		setBlock(world, i + 2, j + 42, k + 8, Blocks.log, 1);
		world.setBlockMetadataWithNotify(i + 2, j + 42, k + 8, 1, 2);
		setBlock(world, i + 2, j + 42, k + 9, Blocks.log, 1);
		world.setBlockMetadataWithNotify(i + 2, j + 42, k + 9, 1, 2);
		setBlock(world, i + 2, j + 42, k + 10, Blocks.log, 1);
		world.setBlockMetadataWithNotify(i + 2, j + 42, k + 10, 1, 2);
		setBlock(world, i + 2, j + 42, k + 11, Blocks.log, 1);
		world.setBlockMetadataWithNotify(i + 2, j + 42, k + 11, 1, 2);
		setBlock(world, i + 2, j + 42, k + 12, Blocks.log, 1);
		world.setBlockMetadataWithNotify(i + 2, j + 42, k + 12, 1, 2);
		setBlock(world, i + 2, j + 42, k + 13, Blocks.log, 1);
		world.setBlockMetadataWithNotify(i + 2, j + 42, k + 13, 1, 2);
		setBlock(world, i + 2, j + 42, k + 14, Blocks.log, 1);
		world.setBlockMetadataWithNotify(i + 2, j + 42, k + 14, 1, 2);
		setBlock(world, i + 2, j + 42, k + 15, Blocks.log, 1);
		world.setBlockMetadataWithNotify(i + 2, j + 42, k + 15, 1, 2);
		setBlock(world, i + 2, j + 42, k + 16, Blocks.log, 1);
		world.setBlockMetadataWithNotify(i + 2, j + 42, k + 16, 1, 2);
		setBlock(world, i + 2, j + 42, k + 17, Blocks.log, 1);
		world.setBlockMetadataWithNotify(i + 2, j + 42, k + 17, 1, 2);
		setBlock(world, i + 2, j + 42, k + 18, Blocks.log, 1);
		world.setBlockMetadataWithNotify(i + 2, j + 42, k + 18, 1, 2);
		setBlock(world, i + 2, j + 43, k + 0, Blocks.leaves, 7);
		world.setBlockMetadataWithNotify(i + 2, j + 43, k + 0, 7, 2);
		setBlock(world, i + 2, j + 43, k + 1, Blocks.leaves, 7);
		world.setBlockMetadataWithNotify(i + 2, j + 43, k + 1, 7, 2);
		setBlock(world, i + 2, j + 43, k + 2, Blocks.leaves, 7);
		world.setBlockMetadataWithNotify(i + 2, j + 43, k + 2, 7, 2);
		setBlock(world, i + 2, j + 43, k + 8, Blocks.log, 1);
		world.setBlockMetadataWithNotify(i + 2, j + 43, k + 8, 1, 2);
		setBlock(world, i + 2, j + 43, k + 9, Blocks.log, 1);
		world.setBlockMetadataWithNotify(i + 2, j + 43, k + 9, 1, 2);
		setBlock(world, i + 2, j + 43, k + 10, Blocks.log, 1);
		world.setBlockMetadataWithNotify(i + 2, j + 43, k + 10, 1, 2);
		setBlock(world, i + 2, j + 43, k + 11, Blocks.log, 1);
		world.setBlockMetadataWithNotify(i + 2, j + 43, k + 11, 1, 2);
		setBlock(world, i + 2, j + 43, k + 12, Blocks.log, 1);
		world.setBlockMetadataWithNotify(i + 2, j + 43, k + 12, 1, 2);
		setBlock(world, i + 2, j + 43, k + 13, Blocks.log, 1);
		world.setBlockMetadataWithNotify(i + 2, j + 43, k + 13, 1, 2);
		setBlock(world, i + 2, j + 43, k + 14, Blocks.log, 1);
		world.setBlockMetadataWithNotify(i + 2, j + 43, k + 14, 1, 2);
		setBlock(world, i + 2, j + 43, k + 15, Blocks.log, 1);
		world.setBlockMetadataWithNotify(i + 2, j + 43, k + 15, 1, 2);
		setBlock(world, i + 2, j + 43, k + 16, Blocks.log, 1);
		world.setBlockMetadataWithNotify(i + 2, j + 43, k + 16, 1, 2);
		setBlock(world, i + 2, j + 43, k + 28, Blocks.leaves, 7);
		world.setBlockMetadataWithNotify(i + 2, j + 43, k + 28, 7, 2);
		setBlock(world, i + 2, j + 43, k + 29, Blocks.leaves, 7);
		world.setBlockMetadataWithNotify(i + 2, j + 43, k + 29, 7, 2);
		setBlock(world, i + 2, j + 43, k + 30, Blocks.leaves, 7);
		world.setBlockMetadataWithNotify(i + 2, j + 43, k + 30, 7, 2);
		setBlock(world, i + 2, j + 43, k + 31, Blocks.leaves, 7);
		world.setBlockMetadataWithNotify(i + 2, j + 43, k + 31, 7, 2);
		setBlock(world, i + 2, j + 44, k + 0, Blocks.leaves, 7);
		world.setBlockMetadataWithNotify(i + 2, j + 44, k + 0, 7, 2);
		setBlock(world, i + 2, j + 44, k + 1, Blocks.leaves, 7);
		world.setBlockMetadataWithNotify(i + 2, j + 44, k + 1, 7, 2);
		setBlock(world, i + 2, j + 44, k + 29, Blocks.leaves, 7);
		world.setBlockMetadataWithNotify(i + 2, j + 44, k + 29, 7, 2);
		setBlock(world, i + 2, j + 44, k + 30, Blocks.leaves, 7);
		world.setBlockMetadataWithNotify(i + 2, j + 44, k + 30, 7, 2);
		setBlock(world, i + 2, j + 44, k + 31, Blocks.leaves, 7);
		world.setBlockMetadataWithNotify(i + 2, j + 44, k + 31, 7, 2);
		setBlock(world, i + 2, j + 45, k + 0, Blocks.leaves, 7);
		world.setBlockMetadataWithNotify(i + 2, j + 45, k + 0, 7, 2);
		setBlock(world, i + 2, j + 45, k + 29, Blocks.log, 3);
		world.setBlockMetadataWithNotify(i + 2, j + 45, k + 29, 3, 2);
		setBlock(world, i + 2, j + 45, k + 30, Blocks.leaves, 7);
		world.setBlockMetadataWithNotify(i + 2, j + 45, k + 30, 7, 2);
		setBlock(world, i + 2, j + 46, k + 26, Blocks.leaves, 7);
		world.setBlockMetadataWithNotify(i + 2, j + 46, k + 26, 7, 2);
		setBlock(world, i + 2, j + 46, k + 27, Blocks.leaves, 7);
		world.setBlockMetadataWithNotify(i + 2, j + 46, k + 27, 7, 2);
		setBlock(world, i + 2, j + 46, k + 28, Blocks.log, 3);
		world.setBlockMetadataWithNotify(i + 2, j + 46, k + 28, 3, 2);
		setBlock(world, i + 2, j + 46, k + 29, Blocks.leaves, 7);
		world.setBlockMetadataWithNotify(i + 2, j + 46, k + 29, 7, 2);
		setBlock(world, i + 2, j + 46, k + 30, Blocks.leaves, 7);
		world.setBlockMetadataWithNotify(i + 2, j + 46, k + 30, 7, 2);
		setBlock(world, i + 2, j + 46, k + 31, Blocks.leaves, 7);
		world.setBlockMetadataWithNotify(i + 2, j + 46, k + 31, 7, 2);
		setBlock(world, i + 2, j + 47, k + 26, Blocks.leaves, 7);
		world.setBlockMetadataWithNotify(i + 2, j + 47, k + 26, 7, 2);
		setBlock(world, i + 2, j + 47, k + 27, Blocks.leaves, 7);
		world.setBlockMetadataWithNotify(i + 2, j + 47, k + 27, 7, 2);
		setBlock(world, i + 2, j + 47, k + 28, Blocks.leaves, 7);
		world.setBlockMetadataWithNotify(i + 2, j + 47, k + 28, 7, 2);
		setBlock(world, i + 2, j + 47, k + 29, Blocks.leaves, 7);
		world.setBlockMetadataWithNotify(i + 2, j + 47, k + 29, 7, 2);
		setBlock(world, i + 2, j + 47, k + 30, Blocks.leaves, 7);
		world.setBlockMetadataWithNotify(i + 2, j + 47, k + 30, 7, 2);
		setBlock(world, i + 2, j + 47, k + 31, Blocks.leaves, 7);
		world.setBlockMetadataWithNotify(i + 2, j + 47, k + 31, 7, 2);
		setBlock(world, i + 2, j + 48, k + 27, Blocks.leaves, 7);
		world.setBlockMetadataWithNotify(i + 2, j + 48, k + 27, 7, 2);
		setBlock(world, i + 2, j + 48, k + 28, Blocks.leaves, 7);
		world.setBlockMetadataWithNotify(i + 2, j + 48, k + 28, 7, 2);
		setBlock(world, i + 2, j + 48, k + 29, Blocks.leaves, 7);
		world.setBlockMetadataWithNotify(i + 2, j + 48, k + 29, 7, 2);
		setBlock(world, i + 2, j + 48, k + 31, Blocks.leaves, 7);
		world.setBlockMetadataWithNotify(i + 2, j + 48, k + 31, 7, 2);
		setBlock(world, i + 2, j + 49, k + 0, Blocks.leaves, 7);
		world.setBlockMetadataWithNotify(i + 2, j + 49, k + 0, 7, 2);
		setBlock(world, i + 2, j + 49, k + 2, Blocks.leaves, 7);
		world.setBlockMetadataWithNotify(i + 2, j + 49, k + 2, 7, 2);
		setBlock(world, i + 2, j + 49, k + 3, Blocks.leaves, 7);
		world.setBlockMetadataWithNotify(i + 2, j + 49, k + 3, 7, 2);
		setBlock(world, i + 2, j + 49, k + 4, Blocks.leaves, 7);
		world.setBlockMetadataWithNotify(i + 2, j + 49, k + 4, 7, 2);
		setBlock(world, i + 2, j + 49, k + 27, Blocks.vine, 15);
		world.setBlockMetadataWithNotify(i + 2, j + 49, k + 27, 15, 2);
		setBlock(world, i + 2, j + 49, k + 28, Blocks.leaves, 7);
		world.setBlockMetadataWithNotify(i + 2, j + 49, k + 28, 7, 2);
		setBlock(world, i + 2, j + 50, k + 0, Blocks.leaves, 7);
		world.setBlockMetadataWithNotify(i + 2, j + 50, k + 0, 7, 2);
		setBlock(world, i + 2, j + 50, k + 3, Blocks.leaves, 7);
		world.setBlockMetadataWithNotify(i + 2, j + 50, k + 3, 7, 2);
		setBlock(world, i + 2, j + 53, k + 0, Blocks.leaves, 7);
		world.setBlockMetadataWithNotify(i + 2, j + 53, k + 0, 7, 2);
		setBlock(world, i + 2, j + 64, k + 31, Blocks.log, 1);
		world.setBlockMetadataWithNotify(i + 2, j + 64, k + 31, 1, 2);
		setBlock(world, i + 2, j + 65, k + 27, Blocks.log, 1);
		world.setBlockMetadataWithNotify(i + 2, j + 65, k + 27, 1, 2);
		setBlock(world, i + 2, j + 65, k + 28, Blocks.log, 1);
		world.setBlockMetadataWithNotify(i + 2, j + 65, k + 28, 1, 2);
		setBlock(world, i + 2, j + 65, k + 29, Blocks.planks, 5);
		world.setBlockMetadataWithNotify(i + 2, j + 65, k + 29, 5, 2);
		setBlock(world, i + 2, j + 65, k + 30, Blocks.planks, 5);
		world.setBlockMetadataWithNotify(i + 2, j + 65, k + 30, 5, 2);
		setBlock(world, i + 2, j + 65, k + 31, Blocks.planks, 5);
		world.setBlockMetadataWithNotify(i + 2, j + 65, k + 31, 5, 2);
		setBlock(world, i + 2, j + 70, k + 25, Blocks.log, 1);
		world.setBlockMetadataWithNotify(i + 2, j + 70, k + 25, 1, 2);
		setBlock(world, i + 2, j + 70, k + 26, Blocks.log, 1);
		world.setBlockMetadataWithNotify(i + 2, j + 70, k + 26, 1, 2);
		setBlock(world, i + 2, j + 70, k + 27, Blocks.log, 1);
		world.setBlockMetadataWithNotify(i + 2, j + 70, k + 27, 1, 2);
		setBlock(world, i + 2, j + 70, k + 28, Blocks.log, 1);
		world.setBlockMetadataWithNotify(i + 2, j + 70, k + 28, 1, 2);
		setBlock(world, i + 2, j + 70, k + 29, Blocks.log, 1);
		world.setBlockMetadataWithNotify(i + 2, j + 70, k + 29, 1, 2);
		setBlock(world, i + 2, j + 71, k + 26, Blocks.log, 1);
		world.setBlockMetadataWithNotify(i + 2, j + 71, k + 26, 1, 2);
		setBlock(world, i + 2, j + 71, k + 27, Blocks.log, 1);
		world.setBlockMetadataWithNotify(i + 2, j + 71, k + 27, 1, 2);
		setBlock(world, i + 2, j + 71, k + 28, Blocks.log, 1);
		world.setBlockMetadataWithNotify(i + 2, j + 71, k + 28, 1, 2);
		setBlock(world, i + 2, j + 71, k + 29, Blocks.log, 1);
		world.setBlockMetadataWithNotify(i + 2, j + 71, k + 29, 1, 2);
		setBlock(world, i + 2, j + 71, k + 30, Blocks.log, 1);
		world.setBlockMetadataWithNotify(i + 2, j + 71, k + 30, 1, 2);
		setBlock(world, i + 2, j + 72, k + 28, Blocks.log, 1);
		world.setBlockMetadataWithNotify(i + 2, j + 72, k + 28, 1, 2);
		setBlock(world, i + 2, j + 72, k + 29, Blocks.log, 1);
		world.setBlockMetadataWithNotify(i + 2, j + 72, k + 29, 1, 2);
		setBlock(world, i + 2, j + 72, k + 30, Blocks.log, 1);
		world.setBlockMetadataWithNotify(i + 2, j + 72, k + 30, 1, 2);
		setBlock(world, i + 2, j + 72, k + 31, Blocks.log, 1);
		world.setBlockMetadataWithNotify(i + 2, j + 72, k + 31, 1, 2);
		setBlock(world, i + 3, j + 26, k + 8, Blocks.leaves, 7);
		world.setBlockMetadataWithNotify(i + 3, j + 26, k + 8, 7, 2);
		setBlock(world, i + 3, j + 26, k + 9, Blocks.leaves, 7);
		world.setBlockMetadataWithNotify(i + 3, j + 26, k + 9, 7, 2);
		setBlock(world, i + 3, j + 26, k + 10, Blocks.leaves, 7);
		world.setBlockMetadataWithNotify(i + 3, j + 26, k + 10, 7, 2);
		setBlock(world, i + 3, j + 27, k + 9, Blocks.leaves, 7);
		world.setBlockMetadataWithNotify(i + 3, j + 27, k + 9, 7, 2);
		setBlock(world, i + 3, j + 30, k + 29, Blocks.log, 3);
		world.setBlockMetadataWithNotify(i + 3, j + 30, k + 29, 3, 2);
		setBlock(world, i + 3, j + 30, k + 30, Blocks.log, 3);
		world.setBlockMetadataWithNotify(i + 3, j + 30, k + 30, 3, 2);
		setBlock(world, i + 3, j + 31, k + 23, Blocks.log, 3);
		world.setBlockMetadataWithNotify(i + 3, j + 31, k + 23, 3, 2);
		setBlock(world, i + 3, j + 31, k + 24, Blocks.log, 3);
		world.setBlockMetadataWithNotify(i + 3, j + 31, k + 24, 3, 2);
		setBlock(world, i + 3, j + 31, k + 25, Blocks.log, 3);
		world.setBlockMetadataWithNotify(i + 3, j + 31, k + 25, 3, 2);
		setBlock(world, i + 3, j + 31, k + 26, Blocks.leaves, 7);
		world.setBlockMetadataWithNotify(i + 3, j + 31, k + 26, 7, 2);
		setBlock(world, i + 3, j + 31, k + 27, Blocks.leaves, 7);
		world.setBlockMetadataWithNotify(i + 3, j + 31, k + 27, 7, 2);
		setBlock(world, i + 3, j + 31, k + 28, Blocks.leaves, 7);
		world.setBlockMetadataWithNotify(i + 3, j + 31, k + 28, 7, 2);
		setBlock(world, i + 3, j + 32, k + 20, Blocks.leaves, 15);
		world.setBlockMetadataWithNotify(i + 3, j + 32, k + 20, 15, 2);
		setBlock(world, i + 3, j + 32, k + 21, Blocks.leaves, 15);
		world.setBlockMetadataWithNotify(i + 3, j + 32, k + 21, 15, 2);
		setBlock(world, i + 3, j + 32, k + 22, Blocks.log, 3);
		world.setBlockMetadataWithNotify(i + 3, j + 32, k + 22, 3, 2);
		setBlock(world, i + 3, j + 32, k + 23, Blocks.leaves, 7);
		world.setBlockMetadataWithNotify(i + 3, j + 32, k + 23, 7, 2);
		setBlock(world, i + 3, j + 32, k + 24, Blocks.leaves, 7);
		world.setBlockMetadataWithNotify(i + 3, j + 32, k + 24, 7, 2);
		setBlock(world, i + 3, j + 32, k + 25, Blocks.leaves, 7);
		world.setBlockMetadataWithNotify(i + 3, j + 32, k + 25, 7, 2);
		setBlock(world, i + 3, j + 32, k + 26, Blocks.leaves, 7);
		world.setBlockMetadataWithNotify(i + 3, j + 32, k + 26, 7, 2);
		setBlock(world, i + 3, j + 32, k + 27, Blocks.leaves, 7);
		world.setBlockMetadataWithNotify(i + 3, j + 32, k + 27, 7, 2);
		setBlock(world, i + 3, j + 33, k + 20, Blocks.leaves, 15);
		world.setBlockMetadataWithNotify(i + 3, j + 33, k + 20, 15, 2);
		setBlock(world, i + 3, j + 33, k + 21, Blocks.leaves, 15);
		world.setBlockMetadataWithNotify(i + 3, j + 33, k + 21, 15, 2);
		setBlock(world, i + 3, j + 33, k + 22, Blocks.leaves, 15);
		world.setBlockMetadataWithNotify(i + 3, j + 33, k + 22, 15, 2);
		setBlock(world, i + 3, j + 33, k + 23, Blocks.leaves, 15);
		world.setBlockMetadataWithNotify(i + 3, j + 33, k + 23, 15, 2);
		setBlock(world, i + 3, j + 33, k + 24, Blocks.leaves, 15);
		world.setBlockMetadataWithNotify(i + 3, j + 33, k + 24, 15, 2);
		setBlock(world, i + 3, j + 33, k + 26, Blocks.leaves, 7);
		world.setBlockMetadataWithNotify(i + 3, j + 33, k + 26, 7, 2);
		setBlock(world, i + 3, j + 34, k + 9, Blocks.leaves, 15);
		world.setBlockMetadataWithNotify(i + 3, j + 34, k + 9, 15, 2);
		setBlock(world, i + 3, j + 34, k + 10, Blocks.leaves, 15);
		world.setBlockMetadataWithNotify(i + 3, j + 34, k + 10, 15, 2);
		setBlock(world, i + 3, j + 34, k + 11, Blocks.leaves, 15);
		world.setBlockMetadataWithNotify(i + 3, j + 34, k + 11, 15, 2);
		setBlock(world, i + 3, j + 35, k + 7, Blocks.log, 1);
		world.setBlockMetadataWithNotify(i + 3, j + 35, k + 7, 1, 2);
		setBlock(world, i + 3, j + 35, k + 8, Blocks.planks, 5);
		world.setBlockMetadataWithNotify(i + 3, j + 35, k + 8, 5, 2);
		setBlock(world, i + 3, j + 35, k + 9, Blocks.log, 1);
		world.setBlockMetadataWithNotify(i + 3, j + 35, k + 9, 1, 2);
		setBlock(world, i + 3, j + 35, k + 10, Blocks.log, 1);
		world.setBlockMetadataWithNotify(i + 3, j + 35, k + 10, 1, 2);
		setBlock(world, i + 3, j + 35, k + 11, Blocks.log, 1);
		world.setBlockMetadataWithNotify(i + 3, j + 35, k + 11, 1, 2);
		setBlock(world, i + 3, j + 35, k + 12, Blocks.log, 1);
		world.setBlockMetadataWithNotify(i + 3, j + 35, k + 12, 1, 2);
		setBlock(world, i + 3, j + 35, k + 13, Blocks.log, 1);
		world.setBlockMetadataWithNotify(i + 3, j + 35, k + 13, 1, 2);
		setBlock(world, i + 3, j + 35, k + 14, Blocks.log, 1);
		world.setBlockMetadataWithNotify(i + 3, j + 35, k + 14, 1, 2);
		setBlock(world, i + 3, j + 35, k + 15, Blocks.log, 1);
		world.setBlockMetadataWithNotify(i + 3, j + 35, k + 15, 1, 2);
		setBlock(world, i + 3, j + 35, k + 16, Blocks.planks, 5);
		world.setBlockMetadataWithNotify(i + 3, j + 35, k + 16, 5, 2);
		setBlock(world, i + 3, j + 35, k + 17, Blocks.log, 1);
		world.setBlockMetadataWithNotify(i + 3, j + 35, k + 17, 1, 2);
		setBlock(world, i + 3, j + 35, k + 20, Blocks.planks, 5);
		world.setBlockMetadataWithNotify(i + 3, j + 35, k + 20, 5, 2);
		setBlock(world, i + 3, j + 35, k + 21, Blocks.planks, 5);
		world.setBlockMetadataWithNotify(i + 3, j + 35, k + 21, 5, 2);
		setBlock(world, i + 3, j + 35, k + 22, Blocks.planks, 5);
		world.setBlockMetadataWithNotify(i + 3, j + 35, k + 22, 5, 2);
		setBlock(world, i + 3, j + 35, k + 23, Blocks.planks, 5);
		world.setBlockMetadataWithNotify(i + 3, j + 35, k + 23, 5, 2);
		setBlock(world, i + 3, j + 35, k + 24, Blocks.planks, 5);
		world.setBlockMetadataWithNotify(i + 3, j + 35, k + 24, 5, 2);
		setBlock(world, i + 3, j + 35, k + 25, Blocks.planks, 5);
		world.setBlockMetadataWithNotify(i + 3, j + 35, k + 25, 5, 2);
		setBlock(world, i + 3, j + 36, k + 21, Blocks.torch, 5);
		world.setBlockMetadataWithNotify(i + 3, j + 36, k + 21, 5, 2);
		setBlock(world, i + 3, j + 36, k + 25, Blocks.torch, 5);
		world.setBlockMetadataWithNotify(i + 3, j + 36, k + 25, 5, 2);
		setBlock(world, i + 3, j + 37, k + 7, Blocks.torch, 5);
		world.setBlockMetadataWithNotify(i + 3, j + 37, k + 7, 5, 2);
		setBlock(world, i + 3, j + 37, k + 17, Blocks.torch, 5);
		world.setBlockMetadataWithNotify(i + 3, j + 37, k + 17, 5, 2);
		setBlock(world, i + 3, j + 38, k + 0, Blocks.leaves, 7);
		world.setBlockMetadataWithNotify(i + 3, j + 38, k + 0, 7, 2);
		setBlock(world, i + 3, j + 38, k + 1, Blocks.leaves, 7);
		world.setBlockMetadataWithNotify(i + 3, j + 38, k + 1, 7, 2);
		setBlock(world, i + 3, j + 39, k + 0, Blocks.leaves, 7);
		world.setBlockMetadataWithNotify(i + 3, j + 39, k + 0, 7, 2);
		setBlock(world, i + 3, j + 39, k + 1, Blocks.leaves, 7);
		world.setBlockMetadataWithNotify(i + 3, j + 39, k + 1, 7, 2);
		setBlock(world, i + 3, j + 39, k + 3, Blocks.log, 1);
		world.setBlockMetadataWithNotify(i + 3, j + 39, k + 3, 1, 2);
		setBlock(world, i + 3, j + 39, k + 4, Blocks.log, 1);
		world.setBlockMetadataWithNotify(i + 3, j + 39, k + 4, 1, 2);
		setBlock(world, i + 3, j + 39, k + 5, Blocks.log, 1);
		world.setBlockMetadataWithNotify(i + 3, j + 39, k + 5, 1, 2);
		setBlock(world, i + 3, j + 39, k + 6, Blocks.log, 1);
		world.setBlockMetadataWithNotify(i + 3, j + 39, k + 6, 1, 2);
		setBlock(world, i + 3, j + 39, k + 7, Blocks.log, 1);
		world.setBlockMetadataWithNotify(i + 3, j + 39, k + 7, 1, 2);
		setBlock(world, i + 3, j + 39, k + 17, Blocks.log, 1);
		world.setBlockMetadataWithNotify(i + 3, j + 39, k + 17, 1, 2);
		setBlock(world, i + 3, j + 39, k + 18, Blocks.log, 1);
		world.setBlockMetadataWithNotify(i + 3, j + 39, k + 18, 1, 2);
		setBlock(world, i + 3, j + 39, k + 19, Blocks.log, 1);
		world.setBlockMetadataWithNotify(i + 3, j + 39, k + 19, 1, 2);
		setBlock(world, i + 3, j + 39, k + 20, Blocks.log, 1);
		world.setBlockMetadataWithNotify(i + 3, j + 39, k + 20, 1, 2);
		setBlock(world, i + 3, j + 39, k + 21, Blocks.log, 1);
		world.setBlockMetadataWithNotify(i + 3, j + 39, k + 21, 1, 2);
		setBlock(world, i + 3, j + 40, k + 0, Blocks.leaves, 7);
		world.setBlockMetadataWithNotify(i + 3, j + 40, k + 0, 7, 2);
		setBlock(world, i + 3, j + 40, k + 5, Blocks.log, 1);
		world.setBlockMetadataWithNotify(i + 3, j + 40, k + 5, 1, 2);
		setBlock(world, i + 3, j + 40, k + 6, Blocks.log, 1);
		world.setBlockMetadataWithNotify(i + 3, j + 40, k + 6, 1, 2);
		setBlock(world, i + 3, j + 40, k + 7, Blocks.log, 1);
		world.setBlockMetadataWithNotify(i + 3, j + 40, k + 7, 1, 2);
		setBlock(world, i + 3, j + 40, k + 8, Blocks.log, 1);
		world.setBlockMetadataWithNotify(i + 3, j + 40, k + 8, 1, 2);
		setBlock(world, i + 3, j + 40, k + 9, Blocks.torch, 1);
		world.setBlockMetadataWithNotify(i + 3, j + 40, k + 9, 1, 2);
		setBlock(world, i + 3, j + 40, k + 15, Blocks.torch, 1);
		world.setBlockMetadataWithNotify(i + 3, j + 40, k + 15, 1, 2);
		setBlock(world, i + 3, j + 40, k + 16, Blocks.log, 1);
		world.setBlockMetadataWithNotify(i + 3, j + 40, k + 16, 1, 2);
		setBlock(world, i + 3, j + 40, k + 17, Blocks.log, 1);
		world.setBlockMetadataWithNotify(i + 3, j + 40, k + 17, 1, 2);
		setBlock(world, i + 3, j + 40, k + 18, Blocks.log, 1);
		world.setBlockMetadataWithNotify(i + 3, j + 40, k + 18, 1, 2);
		setBlock(world, i + 3, j + 40, k + 19, Blocks.log, 1);
		world.setBlockMetadataWithNotify(i + 3, j + 40, k + 19, 1, 2);
		setBlock(world, i + 3, j + 41, k + 0, Blocks.log, 3);
		world.setBlockMetadataWithNotify(i + 3, j + 41, k + 0, 3, 2);
		setBlock(world, i + 3, j + 41, k + 1, Blocks.leaves, 7);
		world.setBlockMetadataWithNotify(i + 3, j + 41, k + 1, 7, 2);
		setBlock(world, i + 3, j + 41, k + 2, Blocks.leaves, 7);
		world.setBlockMetadataWithNotify(i + 3, j + 41, k + 2, 7, 2);
		setBlock(world, i + 3, j + 41, k + 5, Blocks.log, 1);
		world.setBlockMetadataWithNotify(i + 3, j + 41, k + 5, 1, 2);
		setBlock(world, i + 3, j + 41, k + 6, Blocks.log, 1);
		world.setBlockMetadataWithNotify(i + 3, j + 41, k + 6, 1, 2);
		setBlock(world, i + 3, j + 41, k + 7, Blocks.log, 1);
		world.setBlockMetadataWithNotify(i + 3, j + 41, k + 7, 1, 2);
		setBlock(world, i + 3, j + 41, k + 8, Blocks.log, 1);
		world.setBlockMetadataWithNotify(i + 3, j + 41, k + 8, 1, 2);
		setBlock(world, i + 3, j + 41, k + 9, Blocks.log, 1);
		world.setBlockMetadataWithNotify(i + 3, j + 41, k + 9, 1, 2);
		setBlock(world, i + 3, j + 41, k + 10, Blocks.log, 1);
		world.setBlockMetadataWithNotify(i + 3, j + 41, k + 10, 1, 2);
		setBlock(world, i + 3, j + 41, k + 11, Blocks.log, 1);
		world.setBlockMetadataWithNotify(i + 3, j + 41, k + 11, 1, 2);
		setBlock(world, i + 3, j + 41, k + 12, Blocks.log, 1);
		world.setBlockMetadataWithNotify(i + 3, j + 41, k + 12, 1, 2);
		setBlock(world, i + 3, j + 41, k + 13, Blocks.log, 1);
		world.setBlockMetadataWithNotify(i + 3, j + 41, k + 13, 1, 2);
		setBlock(world, i + 3, j + 41, k + 14, Blocks.log, 1);
		world.setBlockMetadataWithNotify(i + 3, j + 41, k + 14, 1, 2);
		setBlock(world, i + 3, j + 41, k + 15, Blocks.log, 1);
		world.setBlockMetadataWithNotify(i + 3, j + 41, k + 15, 1, 2);
		setBlock(world, i + 3, j + 41, k + 16, Blocks.log, 1);
		world.setBlockMetadataWithNotify(i + 3, j + 41, k + 16, 1, 2);
		setBlock(world, i + 3, j + 41, k + 17, Blocks.log, 1);
		world.setBlockMetadataWithNotify(i + 3, j + 41, k + 17, 1, 2);
		setBlock(world, i + 3, j + 41, k + 18, Blocks.log, 1);
		world.setBlockMetadataWithNotify(i + 3, j + 41, k + 18, 1, 2);
		setBlock(world, i + 3, j + 41, k + 19, Blocks.log, 1);
		world.setBlockMetadataWithNotify(i + 3, j + 41, k + 19, 1, 2);
		setBlock(world, i + 3, j + 42, k + 0, Blocks.leaves, 7);
		world.setBlockMetadataWithNotify(i + 3, j + 42, k + 0, 7, 2);
		setBlock(world, i + 3, j + 42, k + 1, Blocks.leaves, 7);
		world.setBlockMetadataWithNotify(i + 3, j + 42, k + 1, 7, 2);
		setBlock(world, i + 3, j + 42, k + 2, Blocks.leaves, 7);
		world.setBlockMetadataWithNotify(i + 3, j + 42, k + 2, 7, 2);
		setBlock(world, i + 3, j + 42, k + 6, Blocks.log, 1);
		world.setBlockMetadataWithNotify(i + 3, j + 42, k + 6, 1, 2);
		setBlock(world, i + 3, j + 42, k + 7, Blocks.log, 1);
		world.setBlockMetadataWithNotify(i + 3, j + 42, k + 7, 1, 2);
		setBlock(world, i + 3, j + 42, k + 8, Blocks.log, 1);
		world.setBlockMetadataWithNotify(i + 3, j + 42, k + 8, 1, 2);
		setBlock(world, i + 3, j + 42, k + 9, Blocks.log, 1);
		world.setBlockMetadataWithNotify(i + 3, j + 42, k + 9, 1, 2);
		setBlock(world, i + 3, j + 42, k + 10, Blocks.log, 1);
		world.setBlockMetadataWithNotify(i + 3, j + 42, k + 10, 1, 2);
		setBlock(world, i + 3, j + 42, k + 11, Blocks.log, 1);
		world.setBlockMetadataWithNotify(i + 3, j + 42, k + 11, 1, 2);
		setBlock(world, i + 3, j + 42, k + 12, Blocks.log, 1);
		world.setBlockMetadataWithNotify(i + 3, j + 42, k + 12, 1, 2);
		setBlock(world, i + 3, j + 42, k + 13, Blocks.log, 1);
		world.setBlockMetadataWithNotify(i + 3, j + 42, k + 13, 1, 2);
		setBlock(world, i + 3, j + 42, k + 14, Blocks.log, 1);
		world.setBlockMetadataWithNotify(i + 3, j + 42, k + 14, 1, 2);
		setBlock(world, i + 3, j + 42, k + 15, Blocks.log, 1);
		world.setBlockMetadataWithNotify(i + 3, j + 42, k + 15, 1, 2);
		setBlock(world, i + 3, j + 42, k + 16, Blocks.log, 1);
		world.setBlockMetadataWithNotify(i + 3, j + 42, k + 16, 1, 2);
		setBlock(world, i + 3, j + 42, k + 17, Blocks.log, 1);
		world.setBlockMetadataWithNotify(i + 3, j + 42, k + 17, 1, 2);
		setBlock(world, i + 3, j + 42, k + 18, Blocks.log, 1);
		world.setBlockMetadataWithNotify(i + 3, j + 42, k + 18, 1, 2);
		setBlock(world, i + 3, j + 43, k + 0, Blocks.leaves, 7);
		world.setBlockMetadataWithNotify(i + 3, j + 43, k + 0, 7, 2);
		setBlock(world, i + 3, j + 43, k + 1, Blocks.leaves, 7);
		world.setBlockMetadataWithNotify(i + 3, j + 43, k + 1, 7, 2);
		setBlock(world, i + 3, j + 43, k + 7, Blocks.log, 1);
		world.setBlockMetadataWithNotify(i + 3, j + 43, k + 7, 1, 2);
		setBlock(world, i + 3, j + 43, k + 8, Blocks.log, 1);
		world.setBlockMetadataWithNotify(i + 3, j + 43, k + 8, 1, 2);
		setBlock(world, i + 3, j + 43, k + 9, Blocks.log, 1);
		world.setBlockMetadataWithNotify(i + 3, j + 43, k + 9, 1, 2);
		setBlock(world, i + 3, j + 43, k + 10, Blocks.log, 1);
		world.setBlockMetadataWithNotify(i + 3, j + 43, k + 10, 1, 2);
		setBlock(world, i + 3, j + 43, k + 11, Blocks.log, 1);
		world.setBlockMetadataWithNotify(i + 3, j + 43, k + 11, 1, 2);
		setBlock(world, i + 3, j + 43, k + 12, Blocks.log, 1);
		world.setBlockMetadataWithNotify(i + 3, j + 43, k + 12, 1, 2);
		setBlock(world, i + 3, j + 43, k + 13, Blocks.log, 1);
		world.setBlockMetadataWithNotify(i + 3, j + 43, k + 13, 1, 2);
		setBlock(world, i + 3, j + 43, k + 14, Blocks.log, 1);
		world.setBlockMetadataWithNotify(i + 3, j + 43, k + 14, 1, 2);
		setBlock(world, i + 3, j + 43, k + 15, Blocks.log, 1);
		world.setBlockMetadataWithNotify(i + 3, j + 43, k + 15, 1, 2);
		setBlock(world, i + 3, j + 43, k + 16, Blocks.log, 1);
		world.setBlockMetadataWithNotify(i + 3, j + 43, k + 16, 1, 2);
		setBlock(world, i + 3, j + 43, k + 17, Blocks.log, 1);
		world.setBlockMetadataWithNotify(i + 3, j + 43, k + 17, 1, 2);
		setBlock(world, i + 3, j + 43, k + 29, Blocks.leaves, 7);
		world.setBlockMetadataWithNotify(i + 3, j + 43, k + 29, 7, 2);
		setBlock(world, i + 3, j + 43, k + 30, Blocks.leaves, 7);
		world.setBlockMetadataWithNotify(i + 3, j + 43, k + 30, 7, 2);
		setBlock(world, i + 3, j + 43, k + 31, Blocks.leaves, 7);
		world.setBlockMetadataWithNotify(i + 3, j + 43, k + 31, 7, 2);
		setBlock(world, i + 3, j + 44, k + 0, Blocks.leaves, 7);
		world.setBlockMetadataWithNotify(i + 3, j + 44, k + 0, 7, 2);
		setBlock(world, i + 3, j + 44, k + 10, Blocks.log, 1);
		world.setBlockMetadataWithNotify(i + 3, j + 44, k + 10, 1, 2);
		setBlock(world, i + 3, j + 44, k + 11, Blocks.log, 1);
		world.setBlockMetadataWithNotify(i + 3, j + 44, k + 11, 1, 2);
		setBlock(world, i + 3, j + 44, k + 12, Blocks.log, 1);
		world.setBlockMetadataWithNotify(i + 3, j + 44, k + 12, 1, 2);
		setBlock(world, i + 3, j + 44, k + 13, Blocks.log, 1);
		world.setBlockMetadataWithNotify(i + 3, j + 44, k + 13, 1, 2);
		setBlock(world, i + 3, j + 44, k + 14, Blocks.log, 1);
		world.setBlockMetadataWithNotify(i + 3, j + 44, k + 14, 1, 2);
		setBlock(world, i + 3, j + 44, k + 30, Blocks.leaves, 7);
		world.setBlockMetadataWithNotify(i + 3, j + 44, k + 30, 7, 2);
		setBlock(world, i + 3, j + 45, k + 30, Blocks.log, 3);
		world.setBlockMetadataWithNotify(i + 3, j + 45, k + 30, 3, 2);
		setBlock(world, i + 3, j + 45, k + 31, Blocks.log, 3);
		world.setBlockMetadataWithNotify(i + 3, j + 45, k + 31, 3, 2);
		setBlock(world, i + 3, j + 46, k + 26, Blocks.leaves, 7);
		world.setBlockMetadataWithNotify(i + 3, j + 46, k + 26, 7, 2);
		setBlock(world, i + 3, j + 46, k + 27, Blocks.leaves, 7);
		world.setBlockMetadataWithNotify(i + 3, j + 46, k + 27, 7, 2);
		setBlock(world, i + 3, j + 46, k + 28, Blocks.leaves, 7);
		world.setBlockMetadataWithNotify(i + 3, j + 46, k + 28, 7, 2);
		setBlock(world, i + 3, j + 46, k + 29, Blocks.leaves, 7);
		world.setBlockMetadataWithNotify(i + 3, j + 46, k + 29, 7, 2);
		setBlock(world, i + 3, j + 46, k + 30, Blocks.leaves, 7);
		world.setBlockMetadataWithNotify(i + 3, j + 46, k + 30, 7, 2);
		setBlock(world, i + 3, j + 46, k + 31, Blocks.log, 3);
		world.setBlockMetadataWithNotify(i + 3, j + 46, k + 31, 3, 2);
		setBlock(world, i + 3, j + 47, k + 27, Blocks.leaves, 7);
		world.setBlockMetadataWithNotify(i + 3, j + 47, k + 27, 7, 2);
		setBlock(world, i + 3, j + 47, k + 28, Blocks.leaves, 7);
		world.setBlockMetadataWithNotify(i + 3, j + 47, k + 28, 7, 2);
		setBlock(world, i + 3, j + 47, k + 29, Blocks.leaves, 7);
		world.setBlockMetadataWithNotify(i + 3, j + 47, k + 29, 7, 2);
		setBlock(world, i + 3, j + 47, k + 30, Blocks.leaves, 7);
		world.setBlockMetadataWithNotify(i + 3, j + 47, k + 30, 7, 2);
		setBlock(world, i + 3, j + 47, k + 31, Blocks.leaves, 7);
		world.setBlockMetadataWithNotify(i + 3, j + 47, k + 31, 7, 2);
		setBlock(world, i + 3, j + 48, k + 27, Blocks.vine, 15);
		world.setBlockMetadataWithNotify(i + 3, j + 48, k + 27, 15, 2);
		setBlock(world, i + 3, j + 48, k + 28, Blocks.leaves, 7);
		world.setBlockMetadataWithNotify(i + 3, j + 48, k + 28, 7, 2);
		setBlock(world, i + 3, j + 48, k + 30, Blocks.leaves, 7);
		world.setBlockMetadataWithNotify(i + 3, j + 48, k + 30, 7, 2);
		setBlock(world, i + 3, j + 48, k + 31, Blocks.leaves, 7);
		world.setBlockMetadataWithNotify(i + 3, j + 48, k + 31, 7, 2);
		setBlock(world, i + 3, j + 49, k + 0, Blocks.leaves, 7);
		world.setBlockMetadataWithNotify(i + 3, j + 49, k + 0, 7, 2);
		setBlock(world, i + 3, j + 49, k + 1, Blocks.leaves, 7);
		world.setBlockMetadataWithNotify(i + 3, j + 49, k + 1, 7, 2);
		setBlock(world, i + 3, j + 49, k + 2, Blocks.leaves, 7);
		world.setBlockMetadataWithNotify(i + 3, j + 49, k + 2, 7, 2);
		setBlock(world, i + 3, j + 49, k + 3, Blocks.leaves, 7);
		world.setBlockMetadataWithNotify(i + 3, j + 49, k + 3, 7, 2);
		setBlock(world, i + 3, j + 49, k + 4, Blocks.leaves, 7);
		world.setBlockMetadataWithNotify(i + 3, j + 49, k + 4, 7, 2);
		setBlock(world, i + 3, j + 49, k + 5, Blocks.leaves, 7);
		world.setBlockMetadataWithNotify(i + 3, j + 49, k + 5, 7, 2);
		setBlock(world, i + 3, j + 49, k + 27, Blocks.vine, 15);
		world.setBlockMetadataWithNotify(i + 3, j + 49, k + 27, 15, 2);
		setBlock(world, i + 3, j + 49, k + 28, Blocks.vine, 15);
		world.setBlockMetadataWithNotify(i + 3, j + 49, k + 28, 15, 2);
		setBlock(world, i + 3, j + 49, k + 29, Blocks.vine, 15);
		world.setBlockMetadataWithNotify(i + 3, j + 49, k + 29, 15, 2);
		setBlock(world, i + 3, j + 49, k + 31, Blocks.leaves, 7);
		world.setBlockMetadataWithNotify(i + 3, j + 49, k + 31, 7, 2);
		setBlock(world, i + 3, j + 50, k + 2, Blocks.leaves, 7);
		world.setBlockMetadataWithNotify(i + 3, j + 50, k + 2, 7, 2);
		setBlock(world, i + 3, j + 50, k + 3, Blocks.leaves, 7);
		world.setBlockMetadataWithNotify(i + 3, j + 50, k + 3, 7, 2);
		setBlock(world, i + 3, j + 50, k + 4, Blocks.leaves, 7);
		world.setBlockMetadataWithNotify(i + 3, j + 50, k + 4, 7, 2);
		setBlock(world, i + 3, j + 50, k + 28, Blocks.vine, 15);
		world.setBlockMetadataWithNotify(i + 3, j + 50, k + 28, 15, 2);
		setBlock(world, i + 3, j + 50, k + 29, Blocks.vine, 15);
		world.setBlockMetadataWithNotify(i + 3, j + 50, k + 29, 15, 2);
		setBlock(world, i + 3, j + 51, k + 3, Blocks.leaves, 7);
		world.setBlockMetadataWithNotify(i + 3, j + 51, k + 3, 7, 2);
		setBlock(world, i + 3, j + 53, k + 0, Blocks.leaves, 7);
		world.setBlockMetadataWithNotify(i + 3, j + 53, k + 0, 7, 2);
		setBlock(world, i + 3, j + 54, k + 0, Blocks.leaves, 7);
		world.setBlockMetadataWithNotify(i + 3, j + 54, k + 0, 7, 2);
		setBlock(world, i + 3, j + 65, k + 27, Blocks.log, 1);
		world.setBlockMetadataWithNotify(i + 3, j + 65, k + 27, 1, 2);
		setBlock(world, i + 3, j + 65, k + 28, Blocks.log, 1);
		world.setBlockMetadataWithNotify(i + 3, j + 65, k + 28, 1, 2);
		setBlock(world, i + 3, j + 65, k + 29, Blocks.log, 1);
		world.setBlockMetadataWithNotify(i + 3, j + 65, k + 29, 1, 2);
		setBlock(world, i + 3, j + 65, k + 30, Blocks.log, 1);
		world.setBlockMetadataWithNotify(i + 3, j + 65, k + 30, 1, 2);
		setBlock(world, i + 3, j + 65, k + 31, Blocks.log, 1);
		world.setBlockMetadataWithNotify(i + 3, j + 65, k + 31, 1, 2);
		setBlock(world, i + 3, j + 70, k + 25, Blocks.log, 1);
		world.setBlockMetadataWithNotify(i + 3, j + 70, k + 25, 1, 2);
		setBlock(world, i + 3, j + 70, k + 26, Blocks.log, 1);
		world.setBlockMetadataWithNotify(i + 3, j + 70, k + 26, 1, 2);
		setBlock(world, i + 3, j + 70, k + 27, Blocks.log, 1);
		world.setBlockMetadataWithNotify(i + 3, j + 70, k + 27, 1, 2);
		setBlock(world, i + 3, j + 70, k + 28, Blocks.log, 1);
		world.setBlockMetadataWithNotify(i + 3, j + 70, k + 28, 1, 2);
		setBlock(world, i + 3, j + 70, k + 29, Blocks.log, 1);
		world.setBlockMetadataWithNotify(i + 3, j + 70, k + 29, 1, 2);
		setBlock(world, i + 3, j + 70, k + 30, Blocks.log, 1);
		world.setBlockMetadataWithNotify(i + 3, j + 70, k + 30, 1, 2);
		setBlock(world, i + 3, j + 71, k + 26, Blocks.log, 1);
		world.setBlockMetadataWithNotify(i + 3, j + 71, k + 26, 1, 2);
		setBlock(world, i + 3, j + 71, k + 27, Blocks.log, 1);
		world.setBlockMetadataWithNotify(i + 3, j + 71, k + 27, 1, 2);
		setBlock(world, i + 3, j + 71, k + 28, Blocks.log, 1);
		world.setBlockMetadataWithNotify(i + 3, j + 71, k + 28, 1, 2);
		setBlock(world, i + 3, j + 71, k + 29, Blocks.log, 1);
		world.setBlockMetadataWithNotify(i + 3, j + 71, k + 29, 1, 2);
		setBlock(world, i + 3, j + 71, k + 30, Blocks.log, 1);
		world.setBlockMetadataWithNotify(i + 3, j + 71, k + 30, 1, 2);
		setBlock(world, i + 3, j + 71, k + 31, Blocks.log, 1);
		world.setBlockMetadataWithNotify(i + 3, j + 71, k + 31, 1, 2);
		setBlock(world, i + 3, j + 72, k + 28, Blocks.log, 1);
		world.setBlockMetadataWithNotify(i + 3, j + 72, k + 28, 1, 2);
		setBlock(world, i + 3, j + 72, k + 29, Blocks.log, 1);
		world.setBlockMetadataWithNotify(i + 3, j + 72, k + 29, 1, 2);
		setBlock(world, i + 3, j + 72, k + 30, Blocks.log, 1);
		world.setBlockMetadataWithNotify(i + 3, j + 72, k + 30, 1, 2);
		setBlock(world, i + 3, j + 72, k + 31, Blocks.log, 1);
		world.setBlockMetadataWithNotify(i + 3, j + 72, k + 31, 1, 2);
		setBlock(world, i + 4, j + 21, k + 0, Blocks.log, 1);
		world.setBlockMetadataWithNotify(i + 4, j + 21, k + 0, 1, 2);
		setBlock(world, i + 4, j + 25, k + 9, Blocks.leaves, 7);
		world.setBlockMetadataWithNotify(i + 4, j + 25, k + 9, 7, 2);
		setBlock(world, i + 4, j + 25, k + 10, Blocks.leaves, 7);
		world.setBlockMetadataWithNotify(i + 4, j + 25, k + 10, 7, 2);
		setBlock(world, i + 4, j + 25, k + 11, Blocks.leaves, 7);
		world.setBlockMetadataWithNotify(i + 4, j + 25, k + 11, 7, 2);
		setBlock(world, i + 4, j + 26, k + 7, Blocks.leaves, 7);
		world.setBlockMetadataWithNotify(i + 4, j + 26, k + 7, 7, 2);
		setBlock(world, i + 4, j + 26, k + 8, Blocks.leaves, 7);
		world.setBlockMetadataWithNotify(i + 4, j + 26, k + 8, 7, 2);
		setBlock(world, i + 4, j + 26, k + 9, Blocks.leaves, 7);
		world.setBlockMetadataWithNotify(i + 4, j + 26, k + 9, 7, 2);
		setBlock(world, i + 4, j + 26, k + 10, Blocks.leaves, 7);
		world.setBlockMetadataWithNotify(i + 4, j + 26, k + 10, 7, 2);
		setBlock(world, i + 4, j + 26, k + 11, Blocks.leaves, 7);
		world.setBlockMetadataWithNotify(i + 4, j + 26, k + 11, 7, 2);
		setBlock(world, i + 4, j + 27, k + 8, Blocks.leaves, 7);
		world.setBlockMetadataWithNotify(i + 4, j + 27, k + 8, 7, 2);
		setBlock(world, i + 4, j + 27, k + 9, Blocks.leaves, 7);
		world.setBlockMetadataWithNotify(i + 4, j + 27, k + 9, 7, 2);
		setBlock(world, i + 4, j + 27, k + 10, Blocks.leaves, 7);
		world.setBlockMetadataWithNotify(i + 4, j + 27, k + 10, 7, 2);
		setBlock(world, i + 4, j + 28, k + 9, Blocks.leaves, 7);
		world.setBlockMetadataWithNotify(i + 4, j + 28, k + 9, 7, 2);
		setBlock(world, i + 4, j + 29, k + 19, Blocks.leaves, 7);
		world.setBlockMetadataWithNotify(i + 4, j + 29, k + 19, 7, 2);
		setBlock(world, i + 4, j + 29, k + 20, Blocks.leaves, 7);
		world.setBlockMetadataWithNotify(i + 4, j + 29, k + 20, 7, 2);
		setBlock(world, i + 4, j + 29, k + 21, Blocks.leaves, 7);
		world.setBlockMetadataWithNotify(i + 4, j + 29, k + 21, 7, 2);
		setBlock(world, i + 4, j + 30, k + 20, Blocks.leaves, 7);
		world.setBlockMetadataWithNotify(i + 4, j + 30, k + 20, 7, 2);
		setBlock(world, i + 4, j + 30, k + 27, Blocks.leaves, 7);
		world.setBlockMetadataWithNotify(i + 4, j + 30, k + 27, 7, 2);
		setBlock(world, i + 4, j + 30, k + 28, Blocks.leaves, 7);
		world.setBlockMetadataWithNotify(i + 4, j + 30, k + 28, 7, 2);
		setBlock(world, i + 4, j + 30, k + 29, Blocks.leaves, 7);
		world.setBlockMetadataWithNotify(i + 4, j + 30, k + 29, 7, 2);
		setBlock(world, i + 4, j + 30, k + 31, Blocks.log, 3);
		world.setBlockMetadataWithNotify(i + 4, j + 30, k + 31, 3, 2);
		setBlock(world, i + 4, j + 31, k + 7, Blocks.log, 1);
		world.setBlockMetadataWithNotify(i + 4, j + 31, k + 7, 1, 2);
		setBlock(world, i + 4, j + 31, k + 8, Blocks.log, 1);
		world.setBlockMetadataWithNotify(i + 4, j + 31, k + 8, 1, 2);
		setBlock(world, i + 4, j + 31, k + 9, Blocks.log, 1);
		world.setBlockMetadataWithNotify(i + 4, j + 31, k + 9, 1, 2);
		setBlock(world, i + 4, j + 31, k + 25, Blocks.leaves, 7);
		world.setBlockMetadataWithNotify(i + 4, j + 31, k + 25, 7, 2);
		setBlock(world, i + 4, j + 31, k + 26, Blocks.log, 3);
		world.setBlockMetadataWithNotify(i + 4, j + 31, k + 26, 3, 2);
		setBlock(world, i + 4, j + 31, k + 27, Blocks.log, 3);
		world.setBlockMetadataWithNotify(i + 4, j + 31, k + 27, 3, 2);
		setBlock(world, i + 4, j + 31, k + 28, Blocks.log, 3);
		world.setBlockMetadataWithNotify(i + 4, j + 31, k + 28, 3, 2);
		setBlock(world, i + 4, j + 31, k + 29, Blocks.log, 3);
		world.setBlockMetadataWithNotify(i + 4, j + 31, k + 29, 3, 2);
		setBlock(world, i + 4, j + 32, k + 6, Blocks.log, 1);
		world.setBlockMetadataWithNotify(i + 4, j + 32, k + 6, 1, 2);
		setBlock(world, i + 4, j + 32, k + 7, Blocks.log, 1);
		world.setBlockMetadataWithNotify(i + 4, j + 32, k + 7, 1, 2);
		setBlock(world, i + 4, j + 32, k + 8, Blocks.log, 1);
		world.setBlockMetadataWithNotify(i + 4, j + 32, k + 8, 1, 2);
		setBlock(world, i + 4, j + 32, k + 9, Blocks.log, 1);
		world.setBlockMetadataWithNotify(i + 4, j + 32, k + 9, 1, 2);
		setBlock(world, i + 4, j + 32, k + 10, Blocks.log, 1);
		world.setBlockMetadataWithNotify(i + 4, j + 32, k + 10, 1, 2);
		setBlock(world, i + 4, j + 32, k + 20, Blocks.leaves, 15);
		world.setBlockMetadataWithNotify(i + 4, j + 32, k + 20, 15, 2);
		setBlock(world, i + 4, j + 32, k + 21, Blocks.leaves, 15);
		world.setBlockMetadataWithNotify(i + 4, j + 32, k + 21, 15, 2);
		setBlock(world, i + 4, j + 32, k + 22, Blocks.leaves, 7);
		world.setBlockMetadataWithNotify(i + 4, j + 32, k + 22, 7, 2);
		setBlock(world, i + 4, j + 32, k + 23, Blocks.leaves, 7);
		world.setBlockMetadataWithNotify(i + 4, j + 32, k + 23, 7, 2);
		setBlock(world, i + 4, j + 32, k + 24, Blocks.leaves, 7);
		world.setBlockMetadataWithNotify(i + 4, j + 32, k + 24, 7, 2);
		setBlock(world, i + 4, j + 32, k + 26, Blocks.leaves, 7);
		world.setBlockMetadataWithNotify(i + 4, j + 32, k + 26, 7, 2);
		setBlock(world, i + 4, j + 32, k + 31, Blocks.leaves, 7);
		world.setBlockMetadataWithNotify(i + 4, j + 32, k + 31, 7, 2);
		setBlock(world, i + 4, j + 33, k + 7, Blocks.log, 1);
		world.setBlockMetadataWithNotify(i + 4, j + 33, k + 7, 1, 2);
		setBlock(world, i + 4, j + 33, k + 8, Blocks.log, 1);
		world.setBlockMetadataWithNotify(i + 4, j + 33, k + 8, 1, 2);
		setBlock(world, i + 4, j + 33, k + 9, Blocks.log, 1);
		world.setBlockMetadataWithNotify(i + 4, j + 33, k + 9, 1, 2);
		setBlock(world, i + 4, j + 33, k + 21, Blocks.leaves, 15);
		world.setBlockMetadataWithNotify(i + 4, j + 33, k + 21, 15, 2);
		setBlock(world, i + 4, j + 33, k + 22, Blocks.leaves, 15);
		world.setBlockMetadataWithNotify(i + 4, j + 33, k + 22, 15, 2);
		setBlock(world, i + 4, j + 33, k + 23, Blocks.leaves, 15);
		world.setBlockMetadataWithNotify(i + 4, j + 33, k + 23, 15, 2);
		setBlock(world, i + 4, j + 34, k + 8, Blocks.leaves, 15);
		world.setBlockMetadataWithNotify(i + 4, j + 34, k + 8, 15, 2);
		setBlock(world, i + 4, j + 34, k + 9, Blocks.leaves, 15);
		world.setBlockMetadataWithNotify(i + 4, j + 34, k + 9, 15, 2);
		setBlock(world, i + 4, j + 34, k + 10, Blocks.leaves, 15);
		world.setBlockMetadataWithNotify(i + 4, j + 34, k + 10, 15, 2);
		setBlock(world, i + 4, j + 34, k + 11, Blocks.leaves, 15);
		world.setBlockMetadataWithNotify(i + 4, j + 34, k + 11, 15, 2);
		setBlock(world, i + 4, j + 34, k + 12, Blocks.leaves, 15);
		world.setBlockMetadataWithNotify(i + 4, j + 34, k + 12, 15, 2);
		setBlock(world, i + 4, j + 35, k + 6, Blocks.log, 1);
