package com.parzivail.pswm.world.gen.wookietree;



import com.parzivail.pswm.utils.NPCType;
import com.parzivail.pswm.utils.SpawnUtils;



import cpw.mods.fml.common.IWorldGenerator;



import java.util.Random;



import net.minecraft.block.Block;

import net.minecraft.init.Blocks;

import net.minecraft.world.World;

import net.minecraft.world.chunk.IChunkProvider;

import net.minecraft.world.gen.feature.WorldGenerator;


public class WT_20
extends WorldGenerator
implements IWorldGenerator

{
	protected Block[] getValidSpawnBlocks()
	
	{
		return new Block[0];
		}

	
	public boolean locationIsValidSpawn(World world, int i, int j, int k)
	
	{
		int distanceToAir = 0;
		Block check = world.getBlock(i, j, k);
		
		while (check != Blocks.air)
		{
			if (distanceToAir > 3) { return false;
			}
			
			distanceToAir++;
			check = world.getBlock(i, j + distanceToAir, k);
			}
		
		j += distanceToAir - 1;
		
		Block block = world.getBlock(i, j, k);
		Block blockAbove = world.getBlock(i, j + 1, k);
		Block blockBelow = world.getBlock(i, j - 1, k);
		
		for (Block x : getValidSpawnBlocks())
		{
			if (blockAbove != Blocks.air) { return false;
			}
			if (block == x) return true;
			if ((block == Blocks.snow) && (blockBelow == x)) { return true;
			}
			}
		
		return false;
		}

	
	
	
	public void generate(Random random, int chunkX, int chunkZ, World world, IChunkProvider chunkGenerator, IChunkProvider chunkProvider)
	{
	}

	
	
	public void setBlock(World world, int x, int y, int z, Block block, int metadata)
	
	{
		world.setBlock(x, y, z, block, metadata, 2);
		}

	
	public boolean generate(World world, Random rand, int i, int j, int k)
	
	{
		k -= 10;
		i -= 10;
		
		setBlock(world, i + 25, j + 43, k + 15, Blocks.fence, 0);
		setBlock(world, i + 25, j + 43, k + 21, Blocks.fence, 0);
		setBlock(world, i + 26, j + 43, k + 15, Blocks.fence, 0);
		setBlock(world, i + 26, j + 43, k + 21, Blocks.fence, 0);
		setBlock(world, i + 28, j + 41, k + 14, Blocks.fence, 0);
		setBlock(world, i + 28, j + 41, k + 15, Blocks.fence, 0);
		setBlock(world, i + 28, j + 41, k + 21, Blocks.fence, 0);
		setBlock(world, i + 28, j + 41, k + 22, Blocks.fence, 0);
		setBlock(world, i + 29, j + 41, k + 13, Blocks.fence, 0);
		setBlock(world, i + 29, j + 41, k + 14, Blocks.fence, 0);
		setBlock(world, i + 29, j + 41, k + 22, Blocks.fence, 0);
		setBlock(world, i + 29, j + 41, k + 23, Blocks.fence, 0);
		setBlock(world, i + 30, j + 41, k + 12, Blocks.spruce_stairs, 0);
		setBlock(world, i + 30, j + 41, k + 13, Blocks.fence, 0);
		setBlock(world, i + 30, j + 41, k + 23, Blocks.fence, 0);
		setBlock(world, i + 30, j + 41, k + 24, Blocks.spruce_stairs, 0);
		setBlock(world, i + 30, j + 43, k + 10, Blocks.fence, 0);
		setBlock(world, i + 30, j + 43, k + 11, Blocks.fence, 0);
		setBlock(world, i + 30, j + 43, k + 25, Blocks.fence, 0);
		setBlock(world, i + 30, j + 43, k + 26, Blocks.fence, 0);
		SpawnUtils.spawnNPC(NPCType.WOOKIETREE, world, i + 31, j + 41, k + 16);
		SpawnUtils.spawnNPC(NPCType.WOOKIETREE, world, i + 31, j + 41, k + 20);
		setBlock(world, i + 3, j + 28, k + 10, Blocks.leaves, 7);
		world.setBlockMetadataWithNotify(i + 3, j + 28, k + 10, 7, 2);
		setBlock(world, i + 3, j + 28, k + 11, Blocks.leaves, 7);
		world.setBlockMetadataWithNotify(i + 3, j + 28, k + 11, 7, 2);
		setBlock(world, i + 3, j + 28, k + 12, Blocks.leaves, 7);
		world.setBlockMetadataWithNotify(i + 3, j + 28, k + 12, 7, 2);
		setBlock(world, i + 3, j + 29, k + 11, Blocks.leaves, 7);
		world.setBlockMetadataWithNotify(i + 3, j + 29, k + 11, 7, 2);
		setBlock(world, i + 3, j + 30, k + 12, Blocks.leaves, 7);
		world.setBlockMetadataWithNotify(i + 3, j + 30, k + 12, 7, 2);
		setBlock(world, i + 3, j + 30, k + 13, Blocks.leaves, 7);
		world.setBlockMetadataWithNotify(i + 3, j + 30, k + 13, 7, 2);
		setBlock(world, i + 3, j + 30, k + 14, Blocks.leaves, 7);
		world.setBlockMetadataWithNotify(i + 3, j + 30, k + 14, 7, 2);
		setBlock(world, i + 3, j + 31, k + 13, Blocks.leaves, 7);
		world.setBlockMetadataWithNotify(i + 3, j + 31, k + 13, 7, 2);
		setBlock(world, i + 4, j + 28, k + 9, Blocks.leaves, 7);
		world.setBlockMetadataWithNotify(i + 4, j + 28, k + 9, 7, 2);
		setBlock(world, i + 4, j + 28, k + 10, Blocks.leaves, 7);
		world.setBlockMetadataWithNotify(i + 4, j + 28, k + 10, 7, 2);
		setBlock(world, i + 4, j + 28, k + 11, Blocks.leaves, 7);
		world.setBlockMetadataWithNotify(i + 4, j + 28, k + 11, 7, 2);
		setBlock(world, i + 4, j + 28, k + 12, Blocks.leaves, 7);
		world.setBlockMetadataWithNotify(i + 4, j + 28, k + 12, 7, 2);
		setBlock(world, i + 4, j + 28, k + 13, Blocks.leaves, 7);
		world.setBlockMetadataWithNotify(i + 4, j + 28, k + 13, 7, 2);
		setBlock(world, i + 4, j + 29, k + 10, Blocks.leaves, 7);
		world.setBlockMetadataWithNotify(i + 4, j + 29, k + 10, 7, 2);
		setBlock(world, i + 4, j + 29, k + 11, Blocks.leaves, 7);
		world.setBlockMetadataWithNotify(i + 4, j + 29, k + 11, 7, 2);
		setBlock(world, i + 4, j + 29, k + 12, Blocks.leaves, 7);
		world.setBlockMetadataWithNotify(i + 4, j + 29, k + 12, 7, 2);
		setBlock(world, i + 4, j + 30, k + 11, Blocks.leaves, 7);
		world.setBlockMetadataWithNotify(i + 4, j + 30, k + 11, 7, 2);
		setBlock(world, i + 4, j + 30, k + 12, Blocks.leaves, 7);
		world.setBlockMetadataWithNotify(i + 4, j + 30, k + 12, 7, 2);
		setBlock(world, i + 4, j + 30, k + 13, Blocks.leaves, 7);
		world.setBlockMetadataWithNotify(i + 4, j + 30, k + 13, 7, 2);
		setBlock(world, i + 4, j + 30, k + 14, Blocks.leaves, 7);
		world.setBlockMetadataWithNotify(i + 4, j + 30, k + 14, 7, 2);
		setBlock(world, i + 4, j + 30, k + 15, Blocks.leaves, 7);
		world.setBlockMetadataWithNotify(i + 4, j + 30, k + 15, 7, 2);
		setBlock(world, i + 4, j + 31, k + 12, Blocks.leaves, 7);
		world.setBlockMetadataWithNotify(i + 4, j + 31, k + 12, 7, 2);
		setBlock(world, i + 4, j + 31, k + 13, Blocks.leaves, 7);
		world.setBlockMetadataWithNotify(i + 4, j + 31, k + 13, 7, 2);
		setBlock(world, i + 4, j + 31, k + 14, Blocks.leaves, 7);
		world.setBlockMetadataWithNotify(i + 4, j + 31, k + 14, 7, 2);
		setBlock(world, i + 4, j + 32, k + 13, Blocks.leaves, 7);
		world.setBlockMetadataWithNotify(i + 4, j + 32, k + 13, 7, 2);
		setBlock(world, i + 5, j + 28, k + 9, Blocks.leaves, 7);
		world.setBlockMetadataWithNotify(i + 5, j + 28, k + 9, 7, 2);
		setBlock(world, i + 5, j + 28, k + 10, Blocks.leaves, 7);
		world.setBlockMetadataWithNotify(i + 5, j + 28, k + 10, 7, 2);
		setBlock(world, i + 5, j + 28, k + 11, Blocks.log, 3);
		world.setBlockMetadataWithNotify(i + 5, j + 28, k + 11, 3, 2);
		setBlock(world, i + 5, j + 28, k + 12, Blocks.leaves, 7);
		world.setBlockMetadataWithNotify(i + 5, j + 28, k + 12, 7, 2);
		setBlock(world, i + 5, j + 28, k + 13, Blocks.leaves, 7);
		world.setBlockMetadataWithNotify(i + 5, j + 28, k + 13, 7, 2);
		setBlock(world, i + 5, j + 29, k + 9, Blocks.leaves, 7);
		world.setBlockMetadataWithNotify(i + 5, j + 29, k + 9, 7, 2);
		setBlock(world, i + 5, j + 29, k + 10, Blocks.leaves, 7);
		world.setBlockMetadataWithNotify(i + 5, j + 29, k + 10, 7, 2);
		setBlock(world, i + 5, j + 29, k + 11, Blocks.leaves, 7);
		world.setBlockMetadataWithNotify(i + 5, j + 29, k + 11, 7, 2);
		setBlock(world, i + 5, j + 29, k + 12, Blocks.leaves, 7);
		world.setBlockMetadataWithNotify(i + 5, j + 29, k + 12, 7, 2);
		setBlock(world, i + 5, j + 29, k + 13, Blocks.leaves, 7);
		world.setBlockMetadataWithNotify(i + 5, j + 29, k + 13, 7, 2);
		setBlock(world, i + 5, j + 30, k + 10, Blocks.leaves, 7);
		world.setBlockMetadataWithNotify(i + 5, j + 30, k + 10, 7, 2);
		setBlock(world, i + 5, j + 30, k + 11, Blocks.leaves, 7);
		world.setBlockMetadataWithNotify(i + 5, j + 30, k + 11, 7, 2);
		setBlock(world, i + 5, j + 30, k + 12, Blocks.leaves, 7);
		world.setBlockMetadataWithNotify(i + 5, j + 30, k + 12, 7, 2);
		setBlock(world, i + 5, j + 30, k + 13, Blocks.log, 3);
		world.setBlockMetadataWithNotify(i + 5, j + 30, k + 13, 3, 2);
		setBlock(world, i + 5, j + 30, k + 14, Blocks.leaves, 7);
		world.setBlockMetadataWithNotify(i + 5, j + 30, k + 14, 7, 2);
		setBlock(world, i + 5, j + 30, k + 15, Blocks.leaves, 7);
		world.setBlockMetadataWithNotify(i + 5, j + 30, k + 15, 7, 2);
		setBlock(world, i + 5, j + 31, k + 11, Blocks.leaves, 7);
		world.setBlockMetadataWithNotify(i + 5, j + 31, k + 11, 7, 2);
		setBlock(world, i + 5, j + 31, k + 12, Blocks.leaves, 7);
		world.setBlockMetadataWithNotify(i + 5, j + 31, k + 12, 7, 2);
		setBlock(world, i + 5, j + 31, k + 13, Blocks.leaves, 7);
		world.setBlockMetadataWithNotify(i + 5, j + 31, k + 13, 7, 2);
		setBlock(world, i + 5, j + 31, k + 14, Blocks.leaves, 7);
		world.setBlockMetadataWithNotify(i + 5, j + 31, k + 14, 7, 2);
		setBlock(world, i + 5, j + 31, k + 15, Blocks.leaves, 7);
		world.setBlockMetadataWithNotify(i + 5, j + 31, k + 15, 7, 2);
		setBlock(world, i + 5, j + 32, k + 12, Blocks.leaves, 7);
		world.setBlockMetadataWithNotify(i + 5, j + 32, k + 12, 7, 2);
		setBlock(world, i + 5, j + 32, k + 13, Blocks.leaves, 7);
		world.setBlockMetadataWithNotify(i + 5, j + 32, k + 13, 7, 2);
		setBlock(world, i + 5, j + 32, k + 14, Blocks.leaves, 7);
		world.setBlockMetadataWithNotify(i + 5, j + 32, k + 14, 7, 2);
		setBlock(world, i + 5, j + 33, k + 13, Blocks.leaves, 7);
		world.setBlockMetadataWithNotify(i + 5, j + 33, k + 13, 7, 2);
		setBlock(world, i + 6, j + 27, k + 11, Blocks.log, 3);
		world.setBlockMetadataWithNotify(i + 6, j + 27, k + 11, 3, 2);
		setBlock(world, i + 6, j + 28, k + 9, Blocks.leaves, 7);
		world.setBlockMetadataWithNotify(i + 6, j + 28, k + 9, 7, 2);
		setBlock(world, i + 6, j + 28, k + 10, Blocks.leaves, 7);
		world.setBlockMetadataWithNotify(i + 6, j + 28, k + 10, 7, 2);
		setBlock(world, i + 6, j + 28, k + 11, Blocks.leaves, 7);
		world.setBlockMetadataWithNotify(i + 6, j + 28, k + 11, 7, 2);
		setBlock(world, i + 6, j + 28, k + 12, Blocks.leaves, 7);
		world.setBlockMetadataWithNotify(i + 6, j + 28, k + 12, 7, 2);
		setBlock(world, i + 6, j + 28, k + 13, Blocks.leaves, 7);
		world.setBlockMetadataWithNotify(i + 6, j + 28, k + 13, 7, 2);
		setBlock(world, i + 6, j + 29, k + 10, Blocks.leaves, 7);
		world.setBlockMetadataWithNotify(i + 6, j + 29, k + 10, 7, 2);
		setBlock(world, i + 6, j + 29, k + 11, Blocks.leaves, 7);
		world.setBlockMetadataWithNotify(i + 6, j + 29, k + 11, 7, 2);
		setBlock(world, i + 6, j + 29, k + 12, Blocks.leaves, 7);
		world.setBlockMetadataWithNotify(i + 6, j + 29, k + 12, 7, 2);
		setBlock(world, i + 6, j + 29, k + 13, Blocks.log, 3);
		world.setBlockMetadataWithNotify(i + 6, j + 29, k + 13, 3, 2);
		setBlock(world, i + 6, j + 30, k + 11, Blocks.leaves, 7);
		world.setBlockMetadataWithNotify(i + 6, j + 30, k + 11, 7, 2);
		setBlock(world, i + 6, j + 30, k + 12, Blocks.leaves, 7);
		world.setBlockMetadataWithNotify(i + 6, j + 30, k + 12, 7, 2);
		setBlock(world, i + 6, j + 30, k + 13, Blocks.leaves, 7);
		world.setBlockMetadataWithNotify(i + 6, j + 30, k + 13, 7, 2);
		setBlock(world, i + 6, j + 30, k + 14, Blocks.leaves, 7);
		world.setBlockMetadataWithNotify(i + 6, j + 30, k + 14, 7, 2);
		setBlock(world, i + 6, j + 30, k + 15, Blocks.leaves, 7);
		world.setBlockMetadataWithNotify(i + 6, j + 30, k + 15, 7, 2);
		setBlock(world, i + 6, j + 31, k + 12, Blocks.leaves, 7);
		world.setBlockMetadataWithNotify(i + 6, j + 31, k + 12, 7, 2);
		setBlock(world, i + 6, j + 31, k + 13, Blocks.leaves, 7);
		world.setBlockMetadataWithNotify(i + 6, j + 31, k + 13, 7, 2);
		setBlock(world, i + 6, j + 31, k + 14, Blocks.leaves, 7);
		world.setBlockMetadataWithNotify(i + 6, j + 31, k + 14, 7, 2);
		setBlock(world, i + 6, j + 32, k + 13, Blocks.leaves, 7);
		world.setBlockMetadataWithNotify(i + 6, j + 32, k + 13, 7, 2);
		setBlock(world, i + 7, j + 27, k + 11, Blocks.log, 3);
		world.setBlockMetadataWithNotify(i + 7, j + 27, k + 11, 3, 2);
		setBlock(world, i + 7, j + 28, k + 10, Blocks.leaves, 7);
		world.setBlockMetadataWithNotify(i + 7, j + 28, k + 10, 7, 2);
		setBlock(world, i + 7, j + 28, k + 11, Blocks.leaves, 7);
		world.setBlockMetadataWithNotify(i + 7, j + 28, k + 11, 7, 2);
		setBlock(world, i + 7, j + 28, k + 12, Blocks.leaves, 7);
		world.setBlockMetadataWithNotify(i + 7, j + 28, k + 12, 7, 2);
		setBlock(world, i + 7, j + 29, k + 11, Blocks.leaves, 7);
		world.setBlockMetadataWithNotify(i + 7, j + 29, k + 11, 7, 2);
		setBlock(world, i + 7, j + 29, k + 13, Blocks.log, 3);
		world.setBlockMetadataWithNotify(i + 7, j + 29, k + 13, 3, 2);
		setBlock(world, i + 7, j + 30, k + 12, Blocks.leaves, 7);
		world.setBlockMetadataWithNotify(i + 7, j + 30, k + 12, 7, 2);
		setBlock(world, i + 7, j + 30, k + 13, Blocks.leaves, 7);
		world.setBlockMetadataWithNotify(i + 7, j + 30, k + 13, 7, 2);
		setBlock(world, i + 7, j + 30, k + 14, Blocks.leaves, 7);
		world.setBlockMetadataWithNotify(i + 7, j + 30, k + 14, 7, 2);
		setBlock(world, i + 7, j + 31, k + 13, Blocks.leaves, 7);
		world.setBlockMetadataWithNotify(i + 7, j + 31, k + 13, 7, 2);
		setBlock(world, i + 8, j + 27, k + 11, Blocks.log, 3);
		world.setBlockMetadataWithNotify(i + 8, j + 27, k + 11, 3, 2);
		setBlock(world, i + 8, j + 29, k + 13, Blocks.log, 3);
		world.setBlockMetadataWithNotify(i + 8, j + 29, k + 13, 3, 2);
		setBlock(world, i + 8, j + 31, k + 13, Blocks.leaves, 7);
		world.setBlockMetadataWithNotify(i + 8, j + 31, k + 13, 7, 2);
		setBlock(world, i + 8, j + 31, k + 14, Blocks.leaves, 7);
		world.setBlockMetadataWithNotify(i + 8, j + 31, k + 14, 7, 2);
		setBlock(world, i + 8, j + 31, k + 15, Blocks.leaves, 7);
		world.setBlockMetadataWithNotify(i + 8, j + 31, k + 15, 7, 2);
		setBlock(world, i + 8, j + 32, k + 14, Blocks.leaves, 7);
		world.setBlockMetadataWithNotify(i + 8, j + 32, k + 14, 7, 2);
		setBlock(world, i + 8, j + 32, k + 19, Blocks.leaves, 7);
		world.setBlockMetadataWithNotify(i + 8, j + 32, k + 19, 7, 2);
		setBlock(world, i + 8, j + 32, k + 20, Blocks.leaves, 7);
		world.setBlockMetadataWithNotify(i + 8, j + 32, k + 20, 7, 2);
		setBlock(world, i + 8, j + 32, k + 21, Blocks.leaves, 7);
		world.setBlockMetadataWithNotify(i + 8, j + 32, k + 21, 7, 2);
		setBlock(world, i + 8, j + 33, k + 20, Blocks.leaves, 7);
		world.setBlockMetadataWithNotify(i + 8, j + 33, k + 20, 7, 2);
		setBlock(world, i + 8, j + 34, k + 2, Blocks.leaves, 7);
		world.setBlockMetadataWithNotify(i + 8, j + 34, k + 2, 7, 2);
		setBlock(world, i + 8, j + 34, k + 3, Blocks.leaves, 7);
		world.setBlockMetadataWithNotify(i + 8, j + 34, k + 3, 7, 2);
		setBlock(world, i + 8, j + 34, k + 4, Blocks.leaves, 7);
		world.setBlockMetadataWithNotify(i + 8, j + 34, k + 4, 7, 2);
		setBlock(world, i + 8, j + 35, k + 3, Blocks.leaves, 7);
		world.setBlockMetadataWithNotify(i + 8, j + 35, k + 3, 7, 2);
		setBlock(world, i + 9, j + 27, k + 11, Blocks.log, 3);
		world.setBlockMetadataWithNotify(i + 9, j + 27, k + 11, 3, 2);
		setBlock(world, i + 9, j + 29, k + 13, Blocks.log, 3);
		world.setBlockMetadataWithNotify(i + 9, j + 29, k + 13, 3, 2);
		setBlock(world, i + 9, j + 31, k + 12, Blocks.leaves, 7);
		world.setBlockMetadataWithNotify(i + 9, j + 31, k + 12, 7, 2);
		setBlock(world, i + 9, j + 31, k + 13, Blocks.leaves, 7);
		world.setBlockMetadataWithNotify(i + 9, j + 31, k + 13, 7, 2);
		setBlock(world, i + 9, j + 31, k + 14, Blocks.leaves, 7);
		world.setBlockMetadataWithNotify(i + 9, j + 31, k + 14, 7, 2);
		setBlock(world, i + 9, j + 31, k + 15, Blocks.leaves, 7);
		world.setBlockMetadataWithNotify(i + 9, j + 31, k + 15, 7, 2);
		setBlock(world, i + 9, j + 31, k + 16, Blocks.leaves, 7);
		world.setBlockMetadataWithNotify(i + 9, j + 31, k + 16, 7, 2);
		setBlock(world, i + 9, j + 32, k + 13, Blocks.leaves, 7);
		world.setBlockMetadataWithNotify(i + 9, j + 32, k + 13, 7, 2);
		setBlock(world, i + 9, j + 32, k + 14, Blocks.leaves, 7);
		world.setBlockMetadataWithNotify(i + 9, j + 32, k + 14, 7, 2);
		setBlock(world, i + 9, j + 32, k + 15, Blocks.leaves, 7);
		world.setBlockMetadataWithNotify(i + 9, j + 32, k + 15, 7, 2);
		setBlock(world, i + 9, j + 32, k + 18, Blocks.leaves, 7);
		world.setBlockMetadataWithNotify(i + 9, j + 32, k + 18, 7, 2);
		setBlock(world, i + 9, j + 32, k + 19, Blocks.leaves, 7);
		world.setBlockMetadataWithNotify(i + 9, j + 32, k + 19, 7, 2);
		setBlock(world, i + 9, j + 32, k + 20, Blocks.leaves, 7);
		world.setBlockMetadataWithNotify(i + 9, j + 32, k + 20, 7, 2);
		setBlock(world, i + 9, j + 32, k + 21, Blocks.leaves, 7);
		world.setBlockMetadataWithNotify(i + 9, j + 32, k + 21, 7, 2);
		setBlock(world, i + 9, j + 32, k + 22, Blocks.leaves, 7);
		world.setBlockMetadataWithNotify(i + 9, j + 32, k + 22, 7, 2);
		setBlock(world, i + 9, j + 33, k + 14, Blocks.leaves, 7);
		world.setBlockMetadataWithNotify(i + 9, j + 33, k + 14, 7, 2);
		setBlock(world, i + 9, j + 33, k + 19, Blocks.leaves, 7);
		world.setBlockMetadataWithNotify(i + 9, j + 33, k + 19, 7, 2);
		setBlock(world, i + 9, j + 33, k + 20, Blocks.leaves, 7);
		world.setBlockMetadataWithNotify(i + 9, j + 33, k + 20, 7, 2);
		setBlock(world, i + 9, j + 33, k + 21, Blocks.leaves, 7);
		world.setBlockMetadataWithNotify(i + 9, j + 33, k + 21, 7, 2);
		setBlock(world, i + 9, j + 34, k + 1, Blocks.leaves, 7);
		world.setBlockMetadataWithNotify(i + 9, j + 34, k + 1, 7, 2);
		setBlock(world, i + 9, j + 34, k + 2, Blocks.leaves, 7);
		world.setBlockMetadataWithNotify(i + 9, j + 34, k + 2, 7, 2);
		setBlock(world, i + 9, j + 34, k + 3, Blocks.leaves, 7);
		world.setBlockMetadataWithNotify(i + 9, j + 34, k + 3, 7, 2);
		setBlock(world, i + 9, j + 34, k + 4, Blocks.leaves, 7);
		world.setBlockMetadataWithNotify(i + 9, j + 34, k + 4, 7, 2);
		setBlock(world, i + 9, j + 34, k + 5, Blocks.leaves, 7);
		world.setBlockMetadataWithNotify(i + 9, j + 34, k + 5, 7, 2);
		setBlock(world, i + 9, j + 34, k + 20, Blocks.leaves, 7);
		world.setBlockMetadataWithNotify(i + 9, j + 34, k + 20, 7, 2);
		setBlock(world, i + 9, j + 35, k + 2, Blocks.leaves, 7);
		world.setBlockMetadataWithNotify(i + 9, j + 35, k + 2, 7, 2);
		setBlock(world, i + 9, j + 35, k + 3, Blocks.leaves, 7);
		world.setBlockMetadataWithNotify(i + 9, j + 35, k + 3, 7, 2);
		setBlock(world, i + 9, j + 35, k + 4, Blocks.leaves, 7);
		world.setBlockMetadataWithNotify(i + 9, j + 35, k + 4, 7, 2);
		setBlock(world, i + 9, j + 35, k + 7, Blocks.leaves, 7);
		world.setBlockMetadataWithNotify(i + 9, j + 35, k + 7, 7, 2);
		setBlock(world, i + 9, j + 35, k + 8, Blocks.leaves, 7);
		world.setBlockMetadataWithNotify(i + 9, j + 35, k + 8, 7, 2);
		setBlock(world, i + 9, j + 35, k + 9, Blocks.leaves, 7);
		world.setBlockMetadataWithNotify(i + 9, j + 35, k + 9, 7, 2);
		setBlock(world, i + 9, j + 36, k + 3, Blocks.leaves, 7);
		world.setBlockMetadataWithNotify(i + 9, j + 36, k + 3, 7, 2);
		setBlock(world, i + 9, j + 36, k + 8, Blocks.leaves, 7);
		world.setBlockMetadataWithNotify(i + 9, j + 36, k + 8, 7, 2);
		setBlock(world, i + 10, j + 26, k + 11, Blocks.log, 3);
		world.setBlockMetadataWithNotify(i + 10, j + 26, k + 11, 3, 2);
		setBlock(world, i + 10, j + 28, k + 13, Blocks.log, 3);
		world.setBlockMetadataWithNotify(i + 10, j + 28, k + 13, 3, 2);
		setBlock(world, i + 10, j + 31, k + 12, Blocks.leaves, 7);
		world.setBlockMetadataWithNotify(i + 10, j + 31, k + 12, 7, 2);
		setBlock(world, i + 10, j + 31, k + 13, Blocks.leaves, 7);
		world.setBlockMetadataWithNotify(i + 10, j + 31, k + 13, 7, 2);
		setBlock(world, i + 10, j + 31, k + 14, Blocks.log, 3);
		world.setBlockMetadataWithNotify(i + 10, j + 31, k + 14, 3, 2);
		setBlock(world, i + 10, j + 31, k + 15, Blocks.leaves, 7);
		world.setBlockMetadataWithNotify(i + 10, j + 31, k + 15, 7, 2);
		setBlock(world, i + 10, j + 31, k + 16, Blocks.leaves, 7);
		world.setBlockMetadataWithNotify(i + 10, j + 31, k + 16, 7, 2);
		setBlock(world, i + 10, j + 32, k + 12, Blocks.leaves, 7);
		world.setBlockMetadataWithNotify(i + 10, j + 32, k + 12, 7, 2);
		setBlock(world, i + 10, j + 32, k + 13, Blocks.leaves, 7);
		world.setBlockMetadataWithNotify(i + 10, j + 32, k + 13, 7, 2);
		setBlock(world, i + 10, j + 32, k + 14, Blocks.leaves, 7);
		world.setBlockMetadataWithNotify(i + 10, j + 32, k + 14, 7, 2);
		setBlock(world, i + 10, j + 32, k + 15, Blocks.leaves, 7);
		world.setBlockMetadataWithNotify(i + 10, j + 32, k + 15, 7, 2);
		setBlock(world, i + 10, j + 32, k + 16, Blocks.leaves, 7);
		world.setBlockMetadataWithNotify(i + 10, j + 32, k + 16, 7, 2);
		setBlock(world, i + 10, j + 32, k + 18, Blocks.leaves, 7);
		world.setBlockMetadataWithNotify(i + 10, j + 32, k + 18, 7, 2);
		setBlock(world, i + 10, j + 32, k + 19, Blocks.leaves, 7);
		world.setBlockMetadataWithNotify(i + 10, j + 32, k + 19, 7, 2);
		setBlock(world, i + 10, j + 32, k + 20, Blocks.log, 3);
		world.setBlockMetadataWithNotify(i + 10, j + 32, k + 20, 3, 2);
		setBlock(world, i + 10, j + 32, k + 21, Blocks.leaves, 7);
		world.setBlockMetadataWithNotify(i + 10, j + 32, k + 21, 7, 2);
		setBlock(world, i + 10, j + 32, k + 22, Blocks.leaves, 7);
		world.setBlockMetadataWithNotify(i + 10, j + 32, k + 22, 7, 2);
		setBlock(world, i + 10, j + 33, k + 13, Blocks.leaves, 7);
		world.setBlockMetadataWithNotify(i + 10, j + 33, k + 13, 7, 2);
		setBlock(world, i + 10, j + 33, k + 14, Blocks.leaves, 7);
		world.setBlockMetadataWithNotify(i + 10, j + 33, k + 14, 7, 2);
		setBlock(world, i + 10, j + 33, k + 15, Blocks.leaves, 7);
		world.setBlockMetadataWithNotify(i + 10, j + 33, k + 15, 7, 2);
		setBlock(world, i + 10, j + 33, k + 18, Blocks.leaves, 7);
		world.setBlockMetadataWithNotify(i + 10, j + 33, k + 18, 7, 2);
		setBlock(world, i + 10, j + 33, k + 19, Blocks.leaves, 7);
		world.setBlockMetadataWithNotify(i + 10, j + 33, k + 19, 7, 2);
		setBlock(world, i + 10, j + 33, k + 20, Blocks.leaves, 7);
		world.setBlockMetadataWithNotify(i + 10, j + 33, k + 20, 7, 2);
		setBlock(world, i + 10, j + 33, k + 21, Blocks.leaves, 7);
		world.setBlockMetadataWithNotify(i + 10, j + 33, k + 21, 7, 2);
		setBlock(world, i + 10, j + 33, k + 22, Blocks.leaves, 7);
		world.setBlockMetadataWithNotify(i + 10, j + 33, k + 22, 7, 2);
		setBlock(world, i + 10, j + 34, k + 1, Blocks.leaves, 7);
		world.setBlockMetadataWithNotify(i + 10, j + 34, k + 1, 7, 2);
		setBlock(world, i + 10, j + 34, k + 2, Blocks.leaves, 7);
		world.setBlockMetadataWithNotify(i + 10, j + 34, k + 2, 7, 2);
		setBlock(world, i + 10, j + 34, k + 3, Blocks.log, 3);
		world.setBlockMetadataWithNotify(i + 10, j + 34, k + 3, 3, 2);
		setBlock(world, i + 10, j + 34, k + 4, Blocks.leaves, 7);
		world.setBlockMetadataWithNotify(i + 10, j + 34, k + 4, 7, 2);
		setBlock(world, i + 10, j + 34, k + 5, Blocks.leaves, 7);
		world.setBlockMetadataWithNotify(i + 10, j + 34, k + 5, 7, 2);
		setBlock(world, i + 10, j + 34, k + 14, Blocks.leaves, 7);
		world.setBlockMetadataWithNotify(i + 10, j + 34, k + 14, 7, 2);
		setBlock(world, i + 10, j + 34, k + 19, Blocks.leaves, 7);
		world.setBlockMetadataWithNotify(i + 10, j + 34, k + 19, 7, 2);
		setBlock(world, i + 10, j + 34, k + 20, Blocks.leaves, 7);
		world.setBlockMetadataWithNotify(i + 10, j + 34, k + 20, 7, 2);
		setBlock(world, i + 10, j + 34, k + 21, Blocks.leaves, 7);
		world.setBlockMetadataWithNotify(i + 10, j + 34, k + 21, 7, 2);
		setBlock(world, i + 10, j + 35, k + 1, Blocks.leaves, 7);
		world.setBlockMetadataWithNotify(i + 10, j + 35, k + 1, 7, 2);
		setBlock(world, i + 10, j + 35, k + 2, Blocks.leaves, 7);
		world.setBlockMetadataWithNotify(i + 10, j + 35, k + 2, 7, 2);
		setBlock(world, i + 10, j + 35, k + 3, Blocks.leaves, 7);
		world.setBlockMetadataWithNotify(i + 10, j + 35, k + 3, 7, 2);
		setBlock(world, i + 10, j + 35, k + 4, Blocks.leaves, 7);
		world.setBlockMetadataWithNotify(i + 10, j + 35, k + 4, 7, 2);
		setBlock(world, i + 10, j + 35, k + 5, Blocks.leaves, 7);
		world.setBlockMetadataWithNotify(i + 10, j + 35, k + 5, 7, 2);
		setBlock(world, i + 10, j + 35, k + 6, Blocks.leaves, 7);
		world.setBlockMetadataWithNotify(i + 10, j + 35, k + 6, 7, 2);
		setBlock(world, i + 10, j + 35, k + 7, Blocks.leaves, 7);
		world.setBlockMetadataWithNotify(i + 10, j + 35, k + 7, 7, 2);
		setBlock(world, i + 10, j + 35, k + 8, Blocks.leaves, 7);
		world.setBlockMetadataWithNotify(i + 10, j + 35, k + 8, 7, 2);
		setBlock(world, i + 10, j + 35, k + 9, Blocks.leaves, 7);
		world.setBlockMetadataWithNotify(i + 10, j + 35, k + 9, 7, 2);
		setBlock(world, i + 10, j + 35, k + 10, Blocks.leaves, 7);
		world.setBlockMetadataWithNotify(i + 10, j + 35, k + 10, 7, 2);
		setBlock(world, i + 10, j + 35, k + 20, Blocks.leaves, 7);
		world.setBlockMetadataWithNotify(i + 10, j + 35, k + 20, 7, 2);
		setBlock(world, i + 10, j + 36, k + 2, Blocks.leaves, 7);
		world.setBlockMetadataWithNotify(i + 10, j + 36, k + 2, 7, 2);
		setBlock(world, i + 10, j + 36, k + 3, Blocks.leaves, 7);
		world.setBlockMetadataWithNotify(i + 10, j + 36, k + 3, 7, 2);
		setBlock(world, i + 10, j + 36, k + 4, Blocks.leaves, 7);
		world.setBlockMetadataWithNotify(i + 10, j + 36, k + 4, 7, 2);
		setBlock(world, i + 10, j + 36, k + 7, Blocks.leaves, 7);
		world.setBlockMetadataWithNotify(i + 10, j + 36, k + 7, 7, 2);
		setBlock(world, i + 10, j + 36, k + 8, Blocks.leaves, 7);
		world.setBlockMetadataWithNotify(i + 10, j + 36, k + 8, 7, 2);
		setBlock(world, i + 10, j + 36, k + 9, Blocks.leaves, 7);
		world.setBlockMetadataWithNotify(i + 10, j + 36, k + 9, 7, 2);
		setBlock(world, i + 10, j + 37, k + 3, Blocks.leaves, 7);
		world.setBlockMetadataWithNotify(i + 10, j + 37, k + 3, 7, 2);
		setBlock(world, i + 10, j + 37, k + 8, Blocks.leaves, 7);
		world.setBlockMetadataWithNotify(i + 10, j + 37, k + 8, 7, 2);
		setBlock(world, i + 11, j + 26, k + 11, Blocks.log, 3);
		world.setBlockMetadataWithNotify(i + 11, j + 26, k + 11, 3, 2);
		setBlock(world, i + 11, j + 28, k + 13, Blocks.log, 3);
		world.setBlockMetadataWithNotify(i + 11, j + 28, k + 13, 3, 2);
		setBlock(world, i + 11, j + 29, k + 0, Blocks.leaves, 7);
		world.setBlockMetadataWithNotify(i + 11, j + 29, k + 0, 7, 2);
		setBlock(world, i + 11, j + 29, k + 1, Blocks.leaves, 7);
		world.setBlockMetadataWithNotify(i + 11, j + 29, k + 1, 7, 2);
		setBlock(world, i + 11, j + 29, k + 2, Blocks.leaves, 7);
		world.setBlockMetadataWithNotify(i + 11, j + 29, k + 2, 7, 2);
		setBlock(world, i + 11, j + 30, k + 1, Blocks.leaves, 7);
		world.setBlockMetadataWithNotify(i + 11, j + 30, k + 1, 7, 2);
		setBlock(world, i + 11, j + 30, k + 14, Blocks.log, 3);
		world.setBlockMetadataWithNotify(i + 11, j + 30, k + 14, 3, 2);
		setBlock(world, i + 11, j + 31, k + 12, Blocks.leaves, 7);
		world.setBlockMetadataWithNotify(i + 11, j + 31, k + 12, 7, 2);
		setBlock(world, i + 11, j + 31, k + 13, Blocks.leaves, 7);
		world.setBlockMetadataWithNotify(i + 11, j + 31, k + 13, 7, 2);
		setBlock(world, i + 11, j + 31, k + 14, Blocks.leaves, 7);
		world.setBlockMetadataWithNotify(i + 11, j + 31, k + 14, 7, 2);
		setBlock(world, i + 11, j + 31, k + 15, Blocks.leaves, 7);
		world.setBlockMetadataWithNotify(i + 11, j + 31, k + 15, 7, 2);
		setBlock(world, i + 11, j + 31, k + 16, Blocks.leaves, 7);
		world.setBlockMetadataWithNotify(i + 11, j + 31, k + 16, 7, 2);
		setBlock(world, i + 11, j + 31, k + 20, Blocks.log, 3);
		world.setBlockMetadataWithNotify(i + 11, j + 31, k + 20, 3, 2);
		setBlock(world, i + 11, j + 32, k + 13, Blocks.leaves, 7);
		world.setBlockMetadataWithNotify(i + 11, j + 32, k + 13, 7, 2);
		setBlock(world, i + 11, j + 32, k + 14, Blocks.leaves, 7);
		world.setBlockMetadataWithNotify(i + 11, j + 32, k + 14, 7, 2);
		setBlock(world, i + 11, j + 32, k + 15, Blocks.leaves, 7);
		world.setBlockMetadataWithNotify(i + 11, j + 32, k + 15, 7, 2);
		setBlock(world, i + 11, j + 32, k + 18, Blocks.leaves, 7);
		world.setBlockMetadataWithNotify(i + 11, j + 32, k + 18, 7, 2);
		setBlock(world, i + 11, j + 32, k + 19, Blocks.leaves, 7);
		world.setBlockMetadataWithNotify(i + 11, j + 32, k + 19, 7, 2);
		setBlock(world, i + 11, j + 32, k + 20, Blocks.leaves, 7);
		world.setBlockMetadataWithNotify(i + 11, j + 32, k + 20, 7, 2);
		setBlock(world, i + 11, j + 32, k + 21, Blocks.leaves, 7);
		world.setBlockMetadataWithNotify(i + 11, j + 32, k + 21, 7, 2);
		setBlock(world, i + 11, j + 32, k + 22, Blocks.leaves, 7);
		world.setBlockMetadataWithNotify(i + 11, j + 32, k + 22, 7, 2);
		setBlock(world, i + 11, j + 33, k + 4, Blocks.log, 3);
		world.setBlockMetadataWithNotify(i + 11, j + 33, k + 4, 3, 2);
		setBlock(world, i + 11, j + 33, k + 14, Blocks.leaves, 7);
		world.setBlockMetadataWithNotify(i + 11, j + 33, k + 14, 7, 2);
		setBlock(world, i + 11, j + 33, k + 19, Blocks.leaves, 7);
		world.setBlockMetadataWithNotify(i + 11, j + 33, k + 19, 7, 2);
		setBlock(world, i + 11, j + 33, k + 20, Blocks.leaves, 7);
		world.setBlockMetadataWithNotify(i + 11, j + 33, k + 20, 7, 2);
		setBlock(world, i + 11, j + 33, k + 21, Blocks.leaves, 7);
		world.setBlockMetadataWithNotify(i + 11, j + 33, k + 21, 7, 2);
		setBlock(world, i + 11, j + 34, k + 1, Blocks.leaves, 7);
		world.setBlockMetadataWithNotify(i + 11, j + 34, k + 1, 7, 2);
		setBlock(world, i + 11, j + 34, k + 2, Blocks.leaves, 7);
		world.setBlockMetadataWithNotify(i + 11, j + 34, k + 2, 7, 2);
		setBlock(world, i + 11, j + 34, k + 3, Blocks.leaves, 7);
		world.setBlockMetadataWithNotify(i + 11, j + 34, k + 3, 7, 2);
		setBlock(world, i + 11, j + 34, k + 4, Blocks.leaves, 7);
		world.setBlockMetadataWithNotify(i + 11, j + 34, k + 4, 7, 2);
		setBlock(world, i + 11, j + 34, k + 5, Blocks.leaves, 7);
		world.setBlockMetadataWithNotify(i + 11, j + 34, k + 5, 7, 2);
		setBlock(world, i + 11, j + 34, k + 20, Blocks.leaves, 7);
		world.setBlockMetadataWithNotify(i + 11, j + 34, k + 20, 7, 2);
		setBlock(world, i + 11, j + 35, k + 2, Blocks.leaves, 7);
		world.setBlockMetadataWithNotify(i + 11, j + 35, k + 2, 7, 2);
		setBlock(world, i + 11, j + 35, k + 3, Blocks.leaves, 7);
		world.setBlockMetadataWithNotify(i + 11, j + 35, k + 3, 7, 2);
		setBlock(world, i + 11, j + 35, k + 4, Blocks.leaves, 7);
		world.setBlockMetadataWithNotify(i + 11, j + 35, k + 4, 7, 2);
		setBlock(world, i + 11, j + 35, k + 6, Blocks.leaves, 7);
		world.setBlockMetadataWithNotify(i + 11, j + 35, k + 6, 7, 2);
		setBlock(world, i + 11, j + 35, k + 7, Blocks.leaves, 7);
		world.setBlockMetadataWithNotify(i + 11, j + 35, k + 7, 7, 2);
		setBlock(world, i + 11, j + 35, k + 8, Blocks.log, 3);
		world.setBlockMetadataWithNotify(i + 11, j + 35, k + 8, 3, 2);
		setBlock(world, i + 11, j + 35, k + 9, Blocks.leaves, 7);
		world.setBlockMetadataWithNotify(i + 11, j + 35, k + 9, 7, 2);
		setBlock(world, i + 11, j + 35, k + 10, Blocks.leaves, 7);
		world.setBlockMetadataWithNotify(i + 11, j + 35, k + 10, 7, 2);
		setBlock(world, i + 11, j + 36, k + 3, Blocks.leaves, 7);
		world.setBlockMetadataWithNotify(i + 11, j + 36, k + 3, 7, 2);
		setBlock(world, i + 11, j + 36, k + 6, Blocks.leaves, 7);
		world.setBlockMetadataWithNotify(i + 11, j + 36, k + 6, 7, 2);
		setBlock(world, i + 11, j + 36, k + 7, Blocks.leaves, 7);
		world.setBlockMetadataWithNotify(i + 11, j + 36, k + 7, 7, 2);
		setBlock(world, i + 11, j + 36, k + 8, Blocks.leaves, 7);
		world.setBlockMetadataWithNotify(i + 11, j + 36, k + 8, 7, 2);
		setBlock(world, i + 11, j + 36, k + 9, Blocks.leaves, 7);
		world.setBlockMetadataWithNotify(i + 11, j + 36, k + 9, 7, 2);
		setBlock(world, i + 11, j + 36, k + 10, Blocks.leaves, 7);
		world.setBlockMetadataWithNotify(i + 11, j + 36, k + 10, 7, 2);
		setBlock(world, i + 11, j + 37, k + 7, Blocks.leaves, 7);
		world.setBlockMetadataWithNotify(i + 11, j + 37, k + 7, 7, 2);
		setBlock(world, i + 11, j + 37, k + 8, Blocks.leaves, 7);
		world.setBlockMetadataWithNotify(i + 11, j + 37, k + 8, 7, 2);
		setBlock(world, i + 11, j + 37, k + 9, Blocks.leaves, 7);
		world.setBlockMetadataWithNotify(i + 11, j + 37, k + 9, 7, 2);
		setBlock(world, i + 11, j + 38, k + 8, Blocks.leaves, 7);
		world.setBlockMetadataWithNotify(i + 11, j + 38, k + 8, 7, 2);
		setBlock(world, i + 11, j + 39, k + 16, Blocks.leaves, 7);
		world.setBlockMetadataWithNotify(i + 11, j + 39, k + 16, 7, 2);
		setBlock(world, i + 11, j + 39, k + 17, Blocks.leaves, 7);
		world.setBlockMetadataWithNotify(i + 11, j + 39, k + 17, 7, 2);
		setBlock(world, i + 11, j + 39, k + 18, Blocks.leaves, 7);
		world.setBlockMetadataWithNotify(i + 11, j + 39, k + 18, 7, 2);
		setBlock(world, i + 11, j + 40, k + 17, Blocks.leaves, 7);
		world.setBlockMetadataWithNotify(i + 11, j + 40, k + 17, 7, 2);
		setBlock(world, i + 12, j + 25, k + 6, Blocks.leaves, 7);
		world.setBlockMetadataWithNotify(i + 12, j + 25, k + 6, 7, 2);
		setBlock(world, i + 12, j + 25, k + 7, Blocks.leaves, 7);
		world.setBlockMetadataWithNotify(i + 12, j + 25, k + 7, 7, 2);
		setBlock(world, i + 12, j + 25, k + 8, Blocks.leaves, 7);
		world.setBlockMetadataWithNotify(i + 12, j + 25, k + 8, 7, 2);
		setBlock(world, i + 12, j + 26, k + 7, Blocks.leaves, 7);
		world.setBlockMetadataWithNotify(i + 12, j + 26, k + 7, 7, 2);
		setBlock(world, i + 12, j + 26, k + 10, Blocks.log, 3);
		world.setBlockMetadataWithNotify(i + 12, j + 26, k + 10, 3, 2);
		setBlock(world, i + 12, j + 28, k + 13, Blocks.log, 3);
		world.setBlockMetadataWithNotify(i + 12, j + 28, k + 13, 3, 2);
		setBlock(world, i + 12, j + 29, k + 0, Blocks.leaves, 7);
		world.setBlockMetadataWithNotify(i + 12, j + 29, k + 0, 7, 2);
		setBlock(world, i + 12, j + 29, k + 1, Blocks.leaves, 7);
		world.setBlockMetadataWithNotify(i + 12, j + 29, k + 1, 7, 2);
		setBlock(world, i + 12, j + 29, k + 2, Blocks.leaves, 7);
		world.setBlockMetadataWithNotify(i + 12, j + 29, k + 2, 7, 2);
		setBlock(world, i + 12, j + 29, k + 3, Blocks.leaves, 7);
		world.setBlockMetadataWithNotify(i + 12, j + 29, k + 3, 7, 2);
		setBlock(world, i + 12, j + 30, k + 0, Blocks.leaves, 7);
		world.setBlockMetadataWithNotify(i + 12, j + 30, k + 0, 7, 2);
		setBlock(world, i + 12, j + 30, k + 1, Blocks.leaves, 7);
		world.setBlockMetadataWithNotify(i + 12, j + 30, k + 1, 7, 2);
		setBlock(world, i + 12, j + 30, k + 2, Blocks.leaves, 7);
		world.setBlockMetadataWithNotify(i + 12, j + 30, k + 2, 7, 2);
		setBlock(world, i + 12, j + 30, k + 14, Blocks.log, 3);
		world.setBlockMetadataWithNotify(i + 12, j + 30, k + 14, 3, 2);
		setBlock(world, i + 12, j + 31, k + 1, Blocks.leaves, 7);
		world.setBlockMetadataWithNotify(i + 12, j + 31, k + 1, 7, 2);
		setBlock(world, i + 12, j + 31, k + 13, Blocks.leaves, 7);
		world.setBlockMetadataWithNotify(i + 12, j + 31, k + 13, 7, 2);
		setBlock(world, i + 12, j + 31, k + 14, Blocks.leaves, 7);
		world.setBlockMetadataWithNotify(i + 12, j + 31, k + 14, 7, 2);
		setBlock(world, i + 12, j + 31, k + 15, Blocks.leaves, 7);
		world.setBlockMetadataWithNotify(i + 12, j + 31, k + 15, 7, 2);
		setBlock(world, i + 12, j + 31, k + 19, Blocks.log, 3);
		world.setBlockMetadataWithNotify(i + 12, j + 31, k + 19, 3, 2);
		setBlock(world, i + 12, j + 32, k + 6, Blocks.leaves, 7);
		world.setBlockMetadataWithNotify(i + 12, j + 32, k + 6, 7, 2);
		setBlock(world, i + 12, j + 32, k + 7, Blocks.leaves, 7);
		world.setBlockMetadataWithNotify(i + 12, j + 32, k + 7, 7, 2);
		setBlock(world, i + 12, j + 32, k + 8, Blocks.leaves, 7);
		world.setBlockMetadataWithNotify(i + 12, j + 32, k + 8, 7, 2);
		setBlock(world, i + 12, j + 32, k + 14, Blocks.leaves, 7);
		world.setBlockMetadataWithNotify(i + 12, j + 32, k + 14, 7, 2);
		setBlock(world, i + 12, j + 32, k + 19, Blocks.leaves, 7);
		world.setBlockMetadataWithNotify(i + 12, j + 32, k + 19, 7, 2);
		setBlock(world, i + 12, j + 32, k + 20, Blocks.leaves, 7);
		world.setBlockMetadataWithNotify(i + 12, j + 32, k + 20, 7, 2);
		setBlock(world, i + 12, j + 32, k + 21, Blocks.leaves, 7);
		world.setBlockMetadataWithNotify(i + 12, j + 32, k + 21, 7, 2);
		setBlock(world, i + 12, j + 33, k + 4, Blocks.log, 3);
		world.setBlockMetadataWithNotify(i + 12, j + 33, k + 4, 3, 2);
		setBlock(world, i + 12, j + 33, k + 7, Blocks.leaves, 7);
		world.setBlockMetadataWithNotify(i + 12, j + 33, k + 7, 7, 2);
		setBlock(world, i + 12, j + 33, k + 20, Blocks.leaves, 7);
		world.setBlockMetadataWithNotify(i + 12, j + 33, k + 20, 7, 2);
		setBlock(world, i + 12, j + 34, k + 2, Blocks.leaves, 7);
		world.setBlockMetadataWithNotify(i + 12, j + 34, k + 2, 7, 2);
		setBlock(world, i + 12, j + 34, k + 3, Blocks.leaves, 7);
		world.setBlockMetadataWithNotify(i + 12, j + 34, k + 3, 7, 2);
		setBlock(world, i + 12, j + 34, k + 4, Blocks.leaves, 7);
		world.setBlockMetadataWithNotify(i + 12, j + 34, k + 4, 7, 2);
		setBlock(world, i + 12, j + 34, k + 8, Blocks.log, 3);
		world.setBlockMetadataWithNotify(i + 12, j + 34, k + 8, 3, 2);
		setBlock(world, i + 12, j + 35, k + 3, Blocks.leaves, 7);
		world.setBlockMetadataWithNotify(i + 12, j + 35, k + 3, 7, 2);
		setBlock(world, i + 12, j + 35, k + 6, Blocks.leaves, 7);
		world.setBlockMetadataWithNotify(i + 12, j + 35, k + 6, 7, 2);
		setBlock(world, i + 12, j + 35, k + 7, Blocks.leaves, 7);
		world.setBlockMetadataWithNotify(i + 12, j + 35, k + 7, 7, 2);
		setBlock(world, i + 12, j + 35, k + 8, Blocks.leaves, 7);
		world.setBlockMetadataWithNotify(i + 12, j + 35, k + 8, 7, 2);
		setBlock(world, i + 12, j + 35, k + 9, Blocks.leaves, 7);
		world.setBlockMetadataWithNotify(i + 12, j + 35, k + 9, 7, 2);
		setBlock(world, i + 12, j + 35, k + 10, Blocks.leaves, 7);
		world.setBlockMetadataWithNotify(i + 12, j + 35, k + 10, 7, 2);
		setBlock(world, i + 12, j + 35, k + 16, Blocks.leaves, 7);
		world.setBlockMetadataWithNotify(i + 12, j + 35, k + 16, 7, 2);
		setBlock(world, i + 12, j + 35, k + 17, Blocks.leaves, 7);
		world.setBlockMetadataWithNotify(i + 12, j + 35, k + 17, 7, 2);
		setBlock(world, i + 12, j + 35, k + 18, Blocks.leaves, 7);
		world.setBlockMetadataWithNotify(i + 12, j + 35, k + 18, 7, 2);
		setBlock(world, i + 12, j + 36, k + 7, Blocks.leaves, 7);
		world.setBlockMetadataWithNotify(i + 12, j + 36, k + 7, 7, 2);
		setBlock(world, i + 12, j + 36, k + 8, Blocks.leaves, 7);
		world.setBlockMetadataWithNotify(i + 12, j + 36, k + 8, 7, 2);
		setBlock(world, i + 12, j + 36, k + 9, Blocks.leaves, 7);
		world.setBlockMetadataWithNotify(i + 12, j + 36, k + 9, 7, 2);
		setBlock(world, i + 12, j + 36, k + 17, Blocks.leaves, 7);
		world.setBlockMetadataWithNotify(i + 12, j + 36, k + 17, 7, 2);
		setBlock(world, i + 12, j + 37, k + 8, Blocks.leaves, 7);
		world.setBlockMetadataWithNotify(i + 12, j + 37, k + 8, 7, 2);
		setBlock(world, i + 12, j + 39, k + 15, Blocks.leaves, 7);
		world.setBlockMetadataWithNotify(i + 12, j + 39, k + 15, 7, 2);
		setBlock(world, i + 12, j + 39, k + 16, Blocks.leaves, 7);
		world.setBlockMetadataWithNotify(i + 12, j + 39, k + 16, 7, 2);
		setBlock(world, i + 12, j + 39, k + 17, Blocks.leaves, 7);
		world.setBlockMetadataWithNotify(i + 12, j + 39, k + 17, 7, 2);
		setBlock(world, i + 12, j + 39, k + 18, Blocks.leaves, 7);
		world.setBlockMetadataWithNotify(i + 12, j + 39, k + 18, 7, 2);
		setBlock(world, i + 12, j + 39, k + 19, Blocks.leaves, 7);
		world.setBlockMetadataWithNotify(i + 12, j + 39, k + 19, 7, 2);
		setBlock(world, i + 12, j + 40, k + 16, Blocks.leaves, 7);
		world.setBlockMetadataWithNotify(i + 12, j + 40, k + 16, 7, 2);
		setBlock(world, i + 12, j + 40, k + 17, Blocks.leaves, 7);
		world.setBlockMetadataWithNotify(i + 12, j + 40, k + 17, 7, 2);
		setBlock(world, i + 12, j + 40, k + 18, Blocks.leaves, 7);
		world.setBlockMetadataWithNotify(i + 12, j + 40, k + 18, 7, 2);
		setBlock(world, i + 12, j + 41, k + 17, Blocks.leaves, 7);
		world.setBlockMetadataWithNotify(i + 12, j + 41, k + 17, 7, 2);
		setBlock(world, i + 13, j + 25, k + 5, Blocks.leaves, 7);
		world.setBlockMetadataWithNotify(i + 13, j + 25, k + 5, 7, 2);
		setBlock(world, i + 13, j + 25, k + 6, Blocks.leaves, 7);
		world.setBlockMetadataWithNotify(i + 13, j + 25, k + 6, 7, 2);
		setBlock(world, i + 13, j + 25, k + 7, Blocks.leaves, 7);
		world.setBlockMetadataWithNotify(i + 13, j + 25, k + 7, 7, 2);
		setBlock(world, i + 13, j + 25, k + 8, Blocks.leaves, 7);
		world.setBlockMetadataWithNotify(i + 13, j + 25, k + 8, 7, 2);
		setBlock(world, i + 13, j + 25, k + 9, Blocks.leaves, 7);
		world.setBlockMetadataWithNotify(i + 13, j + 25, k + 9, 7, 2);
		setBlock(world, i + 13, j + 26, k + 6, Blocks.leaves, 7);
		world.setBlockMetadataWithNotify(i + 13, j + 26, k + 6, 7, 2);
		setBlock(world, i + 13, j + 26, k + 7, Blocks.leaves, 7);
		world.setBlockMetadataWithNotify(i + 13, j + 26, k + 7, 7, 2);
		setBlock(world, i + 13, j + 26, k + 8, Blocks.leaves, 7);
		world.setBlockMetadataWithNotify(i + 13, j + 26, k + 8, 7, 2);
		setBlock(world, i + 13, j + 26, k + 10, Blocks.log, 3);
		world.setBlockMetadataWithNotify(i + 13, j + 26, k + 10, 3, 2);
		setBlock(world, i + 13, j + 27, k + 7, Blocks.leaves, 7);
		world.setBlockMetadataWithNotify(i + 13, j + 27, k + 7, 7, 2);
		setBlock(world, i + 13, j + 28, k + 13, Blocks.log, 3);
		world.setBlockMetadataWithNotify(i + 13, j + 28, k + 13, 3, 2);
		setBlock(world, i + 13, j + 29, k + 0, Blocks.leaves, 7);
		world.setBlockMetadataWithNotify(i + 13, j + 29, k + 0, 7, 2);
		setBlock(world, i + 13, j + 29, k + 1, Blocks.log, 3);
		world.setBlockMetadataWithNotify(i + 13, j + 29, k + 1, 3, 2);
		setBlock(world, i + 13, j + 29, k + 2, Blocks.leaves, 7);
		world.setBlockMetadataWithNotify(i + 13, j + 29, k + 2, 7, 2);
		setBlock(world, i + 13, j + 29, k + 3, Blocks.leaves, 7);
		world.setBlockMetadataWithNotify(i + 13, j + 29, k + 3, 7, 2);
		setBlock(world, i + 13, j + 30, k + 0, Blocks.leaves, 7);
		world.setBlockMetadataWithNotify(i + 13, j + 30, k + 0, 7, 2);
		setBlock(world, i + 13, j + 30, k + 1, Blocks.leaves, 7);
		world.setBlockMetadataWithNotify(i + 13, j + 30, k + 1, 7, 2);
		setBlock(world, i + 13, j + 30, k + 2, Blocks.leaves, 7);
		world.setBlockMetadataWithNotify(i + 13, j + 30, k + 2, 7, 2);
		setBlock(world, i + 13, j + 30, k + 3, Blocks.leaves, 7);
		world.setBlockMetadataWithNotify(i + 13, j + 30, k + 3, 7, 2);
		setBlock(world, i + 13, j + 30, k + 14, Blocks.log, 3);
		world.setBlockMetadataWithNotify(i + 13, j + 30, k + 14, 3, 2);
		setBlock(world, i + 13, j + 31, k + 0, Blocks.leaves, 7);
		world.setBlockMetadataWithNotify(i + 13, j + 31, k + 0, 7, 2);
		setBlock(world, i + 13, j + 31, k + 1, Blocks.leaves, 7);
		world.setBlockMetadataWithNotify(i + 13, j + 31, k + 1, 7, 2);
		setBlock(world, i + 13, j + 31, k + 2, Blocks.leaves, 7);
		world.setBlockMetadataWithNotify(i + 13, j + 31, k + 2, 7, 2);
		setBlock(world, i + 13, j + 31, k + 18, Blocks.log, 3);
		world.setBlockMetadataWithNotify(i + 13, j + 31, k + 18, 3, 2);
		setBlock(world, i + 13, j + 32, k + 1, Blocks.leaves, 7);
		world.setBlockMetadataWithNotify(i + 13, j + 32, k + 1, 7, 2);
		setBlock(world, i + 13, j + 32, k + 5, Blocks.leaves, 7);
		world.setBlockMetadataWithNotify(i + 13, j + 32, k + 5, 7, 2);
		setBlock(world, i + 13, j + 32, k + 6, Blocks.leaves, 7);
		world.setBlockMetadataWithNotify(i + 13, j + 32, k + 6, 7, 2);
		setBlock(world, i + 13, j + 32, k + 7, Blocks.leaves, 7);
		world.setBlockMetadataWithNotify(i + 13, j + 32, k + 7, 7, 2);
		setBlock(world, i + 13, j + 32, k + 8, Blocks.leaves, 7);
		world.setBlockMetadataWithNotify(i + 13, j + 32, k + 8, 7, 2);
		setBlock(world, i + 13, j + 32, k + 9, Blocks.leaves, 7);
		world.setBlockMetadataWithNotify(i + 13, j + 32, k + 9, 7, 2);
		setBlock(world, i + 13, j + 33, k + 5, Blocks.log, 3);
		world.setBlockMetadataWithNotify(i + 13, j + 33, k + 5, 3, 2);
		setBlock(world, i + 13, j + 33, k + 6, Blocks.leaves, 7);
		world.setBlockMetadataWithNotify(i + 13, j + 33, k + 6, 7, 2);
		setBlock(world, i + 13, j + 33, k + 7, Blocks.leaves, 7);
		world.setBlockMetadataWithNotify(i + 13, j + 33, k + 7, 7, 2);
		setBlock(world, i + 13, j + 33, k + 8, Blocks.leaves, 7);
		world.setBlockMetadataWithNotify(i + 13, j + 33, k + 8, 7, 2);
		setBlock(world, i + 13, j + 34, k + 7, Blocks.leaves, 7);
		world.setBlockMetadataWithNotify(i + 13, j + 34, k + 7, 7, 2);
		setBlock(world, i + 13, j + 34, k + 8, Blocks.log, 3);
		world.setBlockMetadataWithNotify(i + 13, j + 34, k + 8, 3, 2);
		setBlock(world, i + 13, j + 35, k + 7, Blocks.leaves, 7);
		world.setBlockMetadataWithNotify(i + 13, j + 35, k + 7, 7, 2);
		setBlock(world, i + 13, j + 35, k + 8, Blocks.leaves, 7);
		world.setBlockMetadataWithNotify(i + 13, j + 35, k + 8, 7, 2);
		setBlock(world, i + 13, j + 35, k + 9, Blocks.leaves, 7);
		world.setBlockMetadataWithNotify(i + 13, j + 35, k + 9, 7, 2);
		setBlock(world, i + 13, j + 35, k + 15, Blocks.leaves, 7);
		world.setBlockMetadataWithNotify(i + 13, j + 35, k + 15, 7, 2);
		setBlock(world, i + 13, j + 35, k + 16, Blocks.leaves, 7);
		world.setBlockMetadataWithNotify(i + 13, j + 35, k + 16, 7, 2);
		setBlock(world, i + 13, j + 35, k + 17, Blocks.leaves, 7);
		world.setBlockMetadataWithNotify(i + 13, j + 35, k + 17, 7, 2);
		setBlock(world, i + 13, j + 35, k + 18, Blocks.leaves, 7);
		world.setBlockMetadataWithNotify(i + 13, j + 35, k + 18, 7, 2);
		setBlock(world, i + 13, j + 35, k + 19, Blocks.leaves, 7);
		world.setBlockMetadataWithNotify(i + 13, j + 35, k + 19, 7, 2);
		setBlock(world, i + 13, j + 36, k + 8, Blocks.leaves, 7);
		world.setBlockMetadataWithNotify(i + 13, j + 36, k + 8, 7, 2);
		setBlock(world, i + 13, j + 36, k + 16, Blocks.leaves, 7);
		world.setBlockMetadataWithNotify(i + 13, j + 36, k + 16, 7, 2);
		setBlock(world, i + 13, j + 36, k + 17, Blocks.leaves, 7);
		world.setBlockMetadataWithNotify(i + 13, j + 36, k + 17, 7, 2);
		setBlock(world, i + 13, j + 36, k + 18, Blocks.leaves, 7);
		world.setBlockMetadataWithNotify(i + 13, j + 36, k + 18, 7, 2);
		setBlock(world, i + 13, j + 37, k + 17, Blocks.leaves, 7);
		world.setBlockMetadataWithNotify(i + 13, j + 37, k + 17, 7, 2);
		setBlock(world, i + 13, j + 38, k + 0, Blocks.leaves, 7);
		world.setBlockMetadataWithNotify(i + 13, j + 38, k + 0, 7, 2);
		setBlock(world, i + 13, j + 39, k + 15, Blocks.leaves, 7);
		world.setBlockMetadataWithNotify(i + 13, j + 39, k + 15, 7, 2);
		setBlock(world, i + 13, j + 39, k + 16, Blocks.leaves, 7);
		world.setBlockMetadataWithNotify(i + 13, j + 39, k + 16, 7, 2);
		setBlock(world, i + 13, j + 39, k + 17, Blocks.log, 3);
		world.setBlockMetadataWithNotify(i + 13, j + 39, k + 17, 3, 2);
		setBlock(world, i + 13, j + 39, k + 18, Blocks.leaves, 7);
		world.setBlockMetadataWithNotify(i + 13, j + 39, k + 18, 7, 2);
		setBlock(world, i + 13, j + 39, k + 19, Blocks.leaves, 7);
		world.setBlockMetadataWithNotify(i + 13, j + 39, k + 19, 7, 2);
		setBlock(world, i + 13, j + 40, k + 15, Blocks.leaves, 7);
		world.setBlockMetadataWithNotify(i + 13, j + 40, k + 15, 7, 2);
		setBlock(world, i + 13, j + 40, k + 16, Blocks.leaves, 7);
		world.setBlockMetadataWithNotify(i + 13, j + 40, k + 16, 7, 2);
		setBlock(world, i + 13, j + 40, k + 17, Blocks.leaves, 7);
		world.setBlockMetadataWithNotify(i + 13, j + 40, k + 17, 7, 2);
		setBlock(world, i + 13, j + 40, k + 18, Blocks.leaves, 7);
		world.setBlockMetadataWithNotify(i + 13, j + 40, k + 18, 7, 2);
		setBlock(world, i + 13, j + 40, k + 19, Blocks.leaves, 7);
		world.setBlockMetadataWithNotify(i + 13, j + 40, k + 19, 7, 2);
		setBlock(world, i + 13, j + 41, k + 16, Blocks.leaves, 7);
		world.setBlockMetadataWithNotify(i + 13, j + 41, k + 16, 7, 2);
		setBlock(world, i + 13, j + 41, k + 17, Blocks.leaves, 7);
		world.setBlockMetadataWithNotify(i + 13, j + 41, k + 17, 7, 2);
		setBlock(world, i + 13, j + 41, k + 18, Blocks.leaves, 7);
		world.setBlockMetadataWithNotify(i + 13, j + 41, k + 18, 7, 2);
		setBlock(world, i + 13, j + 42, k + 17, Blocks.leaves, 7);
		world.setBlockMetadataWithNotify(i + 13, j + 42, k + 17, 7, 2);
		setBlock(world, i + 13, j + 53, k + 11, Blocks.leaves, 7);
		world.setBlockMetadataWithNotify(i + 13, j + 53, k + 11, 7, 2);
		setBlock(world, i + 13, j + 53, k + 12, Blocks.leaves, 7);
		world.setBlockMetadataWithNotify(i + 13, j + 53, k + 12, 7, 2);
		setBlock(world, i + 13, j + 53, k + 13, Blocks.leaves, 7);
		world.setBlockMetadataWithNotify(i + 13, j + 53, k + 13, 7, 2);
		setBlock(world, i + 13, j + 54, k + 12, Blocks.leaves, 7);
		world.setBlockMetadataWithNotify(i + 13, j + 54, k + 12, 7, 2);
		setBlock(world, i + 14, j + 25, k + 5, Blocks.leaves, 7);
		world.setBlockMetadataWithNotify(i + 14, j + 25, k + 5, 7, 2);
		setBlock(world, i + 14, j + 25, k + 6, Blocks.leaves, 7);
		world.setBlockMetadataWithNotify(i + 14, j + 25, k + 6, 7, 2);
		setBlock(world, i + 14, j + 25, k + 7, Blocks.log, 3);
		world.setBlockMetadataWithNotify(i + 14, j + 25, k + 7, 3, 2);
		setBlock(world, i + 14, j + 25, k + 8, Blocks.leaves, 7);
		world.setBlockMetadataWithNotify(i + 14, j + 25, k + 8, 7, 2);
		setBlock(world, i + 14, j + 25, k + 9, Blocks.leaves, 7);
		world.setBlockMetadataWithNotify(i + 14, j + 25, k + 9, 7, 2);
		setBlock(world, i + 14, j + 26, k + 5, Blocks.leaves, 7);
		world.setBlockMetadataWithNotify(i + 14, j + 26, k + 5, 7, 2);
		setBlock(world, i + 14, j + 26, k + 6, Blocks.leaves, 7);
		world.setBlockMetadataWithNotify(i + 14, j + 26, k + 6, 7, 2);
		setBlock(world, i + 14, j + 26, k + 7, Blocks.leaves, 7);
		world.setBlockMetadataWithNotify(i + 14, j + 26, k + 7, 7, 2);
		setBlock(world, i + 14, j + 26, k + 8, Blocks.leaves, 7);
		world.setBlockMetadataWithNotify(i + 14, j + 26, k + 8, 7, 2);
		setBlock(world, i + 14, j + 26, k + 9, Blocks.leaves, 7);
		world.setBlockMetadataWithNotify(i + 14, j + 26, k + 9, 7, 2);
		setBlock(world, i + 14, j + 26, k + 10, Blocks.log, 3);
		world.setBlockMetadataWithNotify(i + 14, j + 26, k + 10, 3, 2);
		setBlock(world, i + 14, j + 27, k + 6, Blocks.leaves, 7);
		world.setBlockMetadataWithNotify(i + 14, j + 27, k + 6, 7, 2);
		setBlock(world, i + 14, j + 27, k + 7, Blocks.leaves, 7);
		world.setBlockMetadataWithNotify(i + 14, j + 27, k + 7, 7, 2);
		setBlock(world, i + 14, j + 27, k + 8, Blocks.leaves, 7);
		world.setBlockMetadataWithNotify(i + 14, j + 27, k + 8, 7, 2);
		setBlock(world, i + 14, j + 28, k + 2, Blocks.log, 3);
		world.setBlockMetadataWithNotify(i + 14, j + 28, k + 2, 3, 2);
		setBlock(world, i + 14, j + 28, k + 7, Blocks.leaves, 7);
		world.setBlockMetadataWithNotify(i + 14, j + 28, k + 7, 7, 2);
		setBlock(world, i + 14, j + 28, k + 13, Blocks.log, 3);
		world.setBlockMetadataWithNotify(i + 14, j + 28, k + 13, 3, 2);
		setBlock(world, i + 14, j + 28, k + 23, Blocks.leaves, 7);
		world.setBlockMetadataWithNotify(i + 14, j + 28, k + 23, 7, 2);
		setBlock(world, i + 14, j + 28, k + 24, Blocks.leaves, 7);
		world.setBlockMetadataWithNotify(i + 14, j + 28, k + 24, 7, 2);
		setBlock(world, i + 14, j + 28, k + 25, Blocks.leaves, 7);
		world.setBlockMetadataWithNotify(i + 14, j + 28, k + 25, 7, 2);
		setBlock(world, i + 14, j + 29, k + 0, Blocks.leaves, 7);
		world.setBlockMetadataWithNotify(i + 14, j + 29, k + 0, 7, 2);
		setBlock(world, i + 14, j + 29, k + 1, Blocks.leaves, 7);
		world.setBlockMetadataWithNotify(i + 14, j + 29, k + 1, 7, 2);
		setBlock(world, i + 14, j + 29, k + 2, Blocks.leaves, 7);
		world.setBlockMetadataWithNotify(i + 14, j + 29, k + 2, 7, 2);
		setBlock(world, i + 14, j + 29, k + 3, Blocks.leaves, 7);
		world.setBlockMetadataWithNotify(i + 14, j + 29, k + 3, 7, 2);
		setBlock(world, i + 14, j + 29, k + 24, Blocks.leaves, 7);
		world.setBlockMetadataWithNotify(i + 14, j + 29, k + 24, 7, 2);
		setBlock(world, i + 14, j + 30, k + 0, Blocks.leaves, 7);
		world.setBlockMetadataWithNotify(i + 14, j + 30, k + 0, 7, 2);
		setBlock(world, i + 14, j + 30, k + 1, Blocks.leaves, 7);
		world.setBlockMetadataWithNotify(i + 14, j + 30, k + 1, 7, 2);
		setBlock(world, i + 14, j + 30, k + 2, Blocks.leaves, 7);
		world.setBlockMetadataWithNotify(i + 14, j + 30, k + 2, 7, 2);
		setBlock(world, i + 14, j + 30, k + 13, Blocks.log, 3);
		world.setBlockMetadataWithNotify(i + 14, j + 30, k + 13, 3, 2);
		setBlock(world, i + 14, j + 30, k + 17, Blocks.log, 3);
		world.setBlockMetadataWithNotify(i + 14, j + 30, k + 17, 3, 2);
		setBlock(world, i + 14, j + 30, k + 27, Blocks.leaves, 7);
		world.setBlockMetadataWithNotify(i + 14, j + 30, k + 27, 7, 2);
		setBlock(world, i + 14, j + 30, k + 28, Blocks.leaves, 7);
		world.setBlockMetadataWithNotify(i + 14, j + 30, k + 28, 7, 2);
		setBlock(world, i + 14, j + 30, k + 29, Blocks.leaves, 7);
		world.setBlockMetadataWithNotify(i + 14, j + 30, k + 29, 7, 2);
		setBlock(world, i + 14, j + 31, k + 1, Blocks.leaves, 7);
		world.setBlockMetadataWithNotify(i + 14, j + 31, k + 1, 7, 2);
		setBlock(world, i + 14, j + 31, k + 28, Blocks.leaves, 7);
		world.setBlockMetadataWithNotify(i + 14, j + 31, k + 28, 7, 2);
		setBlock(world, i + 14, j + 32, k + 5, Blocks.leaves, 7);
		world.setBlockMetadataWithNotify(i + 14, j + 32, k + 5, 7, 2);
		setBlock(world, i + 14, j + 32, k + 6, Blocks.leaves, 7);
		world.setBlockMetadataWithNotify(i + 14, j + 32, k + 6, 7, 2);
		setBlock(world, i + 14, j + 32, k + 7, Blocks.log, 3);
		world.setBlockMetadataWithNotify(i + 14, j + 32, k + 7, 3, 2);
		setBlock(world, i + 14, j + 32, k + 8, Blocks.leaves, 7);
		world.setBlockMetadataWithNotify(i + 14, j + 32, k + 8, 7, 2);
		setBlock(world, i + 14, j + 32, k + 9, Blocks.leaves, 7);
		world.setBlockMetadataWithNotify(i + 14, j + 32, k + 9, 7, 2);
		setBlock(world, i + 14, j + 33, k + 5, Blocks.log, 3);
		world.setBlockMetadataWithNotify(i + 14, j + 33, k + 5, 3, 2);
		setBlock(world, i + 14, j + 33, k + 6, Blocks.leaves, 7);
		world.setBlockMetadataWithNotify(i + 14, j + 33, k + 6, 7, 2);
		setBlock(world, i + 14, j + 33, k + 7, Blocks.leaves, 7);
		world.setBlockMetadataWithNotify(i + 14, j + 33, k + 7, 7, 2);
		setBlock(world, i + 14, j + 33, k + 8, Blocks.leaves, 7);
		world.setBlockMetadataWithNotify(i + 14, j + 33, k + 8, 7, 2);
		setBlock(world, i + 14, j + 33, k + 9, Blocks.leaves, 7);
		world.setBlockMetadataWithNotify(i + 14, j + 33, k + 9, 7, 2);
		setBlock(world, i + 14, j + 34, k + 6, Blocks.leaves, 7);
		world.setBlockMetadataWithNotify(i + 14, j + 34, k + 6, 7, 2);
		setBlock(world, i + 14, j + 34, k + 7, Blocks.leaves, 7);
		world.setBlockMetadataWithNotify(i + 14, j + 34, k + 7, 7, 2);
		setBlock(world, i + 14, j + 34, k + 8, Blocks.log, 3);
		world.setBlockMetadataWithNotify(i + 14, j + 34, k + 8, 3, 2);
		setBlock(world, i + 14, j + 35, k + 7, Blocks.leaves, 7);
		world.setBlockMetadataWithNotify(i + 14, j + 35, k + 7, 7, 2);
		setBlock(world, i + 14, j + 35, k + 15, Blocks.leaves, 7);
		world.setBlockMetadataWithNotify(i + 14, j + 35, k + 15, 7, 2);
		setBlock(world, i + 14, j + 35, k + 16, Blocks.leaves, 7);
		world.setBlockMetadataWithNotify(i + 14, j + 35, k + 16, 7, 2);
		setBlock(world, i + 14, j + 35, k + 17, Blocks.log, 3);
		world.setBlockMetadataWithNotify(i + 14, j + 35, k + 17, 3, 2);
		setBlock(world, i + 14, j + 35, k + 18, Blocks.leaves, 7);
		world.setBlockMetadataWithNotify(i + 14, j + 35, k + 18, 7, 2);
		setBlock(world, i + 14, j + 35, k + 19, Blocks.leaves, 7);
		world.setBlockMetadataWithNotify(i + 14, j + 35, k + 19, 7, 2);
		setBlock(world, i + 14, j + 36, k + 15, Blocks.leaves, 7);
		world.setBlockMetadataWithNotify(i + 14, j + 36, k + 15, 7, 2);
		setBlock(world, i + 14, j + 36, k + 16, Blocks.leaves, 7);
		world.setBlockMetadataWithNotify(i + 14, j + 36, k + 16, 7, 2);
		setBlock(world, i + 14, j + 36, k + 17, Blocks.leaves, 7);
		world.setBlockMetadataWithNotify(i + 14, j + 36, k + 17, 7, 2);
		setBlock(world, i + 14, j + 36, k + 18, Blocks.leaves, 7);
		world.setBlockMetadataWithNotify(i + 14, j + 36, k + 18, 7, 2);
		setBlock(world, i + 14, j + 36, k + 19, Blocks.leaves, 7);
		world.setBlockMetadataWithNotify(i + 14, j + 36, k + 19, 7, 2);
		setBlock(world, i + 14, j + 37, k + 16, Blocks.leaves, 7);
		world.setBlockMetadataWithNotify(i + 14, j + 37, k + 16, 7, 2);
		setBlock(world, i + 14, j + 37, k + 17, Blocks.leaves, 7);
		world.setBlockMetadataWithNotify(i + 14, j + 37, k + 17, 7, 2);
		setBlock(world, i + 14, j + 37, k + 18, Blocks.leaves, 7);
		world.setBlockMetadataWithNotify(i + 14, j + 37, k + 18, 7, 2);
		setBlock(world, i + 14, j + 38, k + 0, Blocks.leaves, 7);
		world.setBlockMetadataWithNotify(i + 14, j + 38, k + 0, 7, 2);
		setBlock(world, i + 14, j + 38, k + 1, Blocks.leaves, 7);
		world.setBlockMetadataWithNotify(i + 14, j + 38, k + 1, 7, 2);
		setBlock(world, i + 14, j + 38, k + 17, Blocks.log, 3);
		world.setBlockMetadataWithNotify(i + 14, j + 38, k + 17, 3, 2);
		setBlock(world, i + 14, j + 39, k + 0, Blocks.leaves, 7);
		world.setBlockMetadataWithNotify(i + 14, j + 39, k + 0, 7, 2);
		setBlock(world, i + 14, j + 39, k + 15, Blocks.leaves, 7);
		world.setBlockMetadataWithNotify(i + 14, j + 39, k + 15, 7, 2);
		setBlock(world, i + 14, j + 39, k + 16, Blocks.leaves, 7);
		world.setBlockMetadataWithNotify(i + 14, j + 39, k + 16, 7, 2);
		setBlock(world, i + 14, j + 39, k + 17, Blocks.leaves, 7);
		world.setBlockMetadataWithNotify(i + 14, j + 39, k + 17, 7, 2);
		setBlock(world, i + 14, j + 39, k + 18, Blocks.leaves, 7);
		world.setBlockMetadataWithNotify(i + 14, j + 39, k + 18, 7, 2);
		setBlock(world, i + 14, j + 39, k + 19, Blocks.leaves, 7);
		world.setBlockMetadataWithNotify(i + 14, j + 39, k + 19, 7, 2);
		setBlock(world, i + 14, j + 40, k + 16, Blocks.leaves, 7);
		world.setBlockMetadataWithNotify(i + 14, j + 40, k + 16, 7, 2);
		setBlock(world, i + 14, j + 40, k + 17, Blocks.leaves, 7);
		world.setBlockMetadataWithNotify(i + 14, j + 40, k + 17, 7, 2);
		setBlock(world, i + 14, j + 40, k + 18, Blocks.leaves, 7);
		world.setBlockMetadataWithNotify(i + 14, j + 40, k + 18, 7, 2);
		setBlock(world, i + 14, j + 41, k + 17, Blocks.leaves, 7);
		world.setBlockMetadataWithNotify(i + 14, j + 41, k + 17, 7, 2);
		setBlock(world, i + 14, j + 46, k + 0, Blocks.leaves, 7);
		world.setBlockMetadataWithNotify(i + 14, j + 46, k + 0, 7, 2);
		setBlock(world, i + 14, j + 46, k + 1, Blocks.leaves, 7);
		world.setBlockMetadataWithNotify(i + 14, j + 46, k + 1, 7, 2);
		setBlock(world, i + 14, j + 47, k + 0, Blocks.leaves, 7);
		world.setBlockMetadataWithNotify(i + 14, j + 47, k + 0, 7, 2);
		setBlock(world, i + 14, j + 53, k + 10, Blocks.leaves, 7);
		world.setBlockMetadataWithNotify(i + 14, j + 53, k + 10, 7, 2);
		setBlock(world, i + 14, j + 53, k + 11, Blocks.leaves, 7);
		world.setBlockMetadataWithNotify(i + 14, j + 53, k + 11, 7, 2);
		setBlock(world, i + 14, j + 53, k + 12, Blocks.leaves, 7);
		world.setBlockMetadataWithNotify(i + 14, j + 53, k + 12, 7, 2);
		setBlock(world, i + 14, j + 53, k + 13, Blocks.leaves, 7);
		world.setBlockMetadataWithNotify(i + 14, j + 53, k + 13, 7, 2);
		setBlock(world, i + 14, j + 53, k + 14, Blocks.leaves, 7);
		world.setBlockMetadataWithNotify(i + 14, j + 53, k + 14, 7, 2);
		setBlock(world, i + 14, j + 54, k + 11, Blocks.leaves, 7);
		world.setBlockMetadataWithNotify(i + 14, j + 54, k + 11, 7, 2);
		setBlock(world, i + 14, j + 54, k + 12, Blocks.leaves, 7);
		world.setBlockMetadataWithNotify(i + 14, j + 54, k + 12, 7, 2);
		setBlock(world, i + 14, j + 54, k + 13, Blocks.leaves, 7);
		world.setBlockMetadataWithNotify(i + 14, j + 54, k + 13, 7, 2);
		setBlock(world, i + 14, j + 55, k + 7, Blocks.leaves, 7);
		world.setBlockMetadataWithNotify(i + 14, j + 55, k + 7, 7, 2);
		setBlock(world, i + 14, j + 55, k + 8, Blocks.leaves, 7);
		world.setBlockMetadataWithNotify(i + 14, j + 55, k + 8, 7, 2);
		setBlock(world, i + 14, j + 55, k + 9, Blocks.leaves, 7);
		world.setBlockMetadataWithNotify(i + 14, j + 55, k + 9, 7, 2);
		setBlock(world, i + 14, j + 55, k + 12, Blocks.leaves, 7);
		world.setBlockMetadataWithNotify(i + 14, j + 55, k + 12, 7, 2);
		setBlock(world, i + 14, j + 56, k + 8, Blocks.leaves, 7);
		world.setBlockMetadataWithNotify(i + 14, j + 56, k + 8, 7, 2);
		setBlock(world, i + 14, j + 56, k + 9, Blocks.leaves, 7);
		world.setBlockMetadataWithNotify(i + 14, j + 56, k + 9, 7, 2);
		setBlock(world, i + 14, j + 56, k + 10, Blocks.leaves, 7);
		world.setBlockMetadataWithNotify(i + 14, j + 56, k + 10, 7, 2);
		setBlock(world, i + 14, j + 56, k + 11, Blocks.leaves, 7);
		world.setBlockMetadataWithNotify(i + 14, j + 56, k + 11, 7, 2);
		setBlock(world, i + 14, j + 57, k + 10, Blocks.leaves, 7);
		world.setBlockMetadataWithNotify(i + 14, j + 57, k + 10, 7, 2);
		setBlock(world, i + 15, j + 24, k + 8, Blocks.log, 3);
		world.setBlockMetadataWithNotify(i + 15, j + 24, k + 8, 3, 2);
		setBlock(world, i + 15, j + 24, k + 10, Blocks.log, 3);
		world.setBlockMetadataWithNotify(i + 15, j + 24, k + 10, 3, 2);
		setBlock(world, i + 15, j + 25, k + 5, Blocks.leaves, 7);
		world.setBlockMetadataWithNotify(i + 15, j + 25, k + 5, 7, 2);
		setBlock(world, i + 15, j + 25, k + 6, Blocks.leaves, 7);
		world.setBlockMetadataWithNotify(i + 15, j + 25, k + 6, 7, 2);
		setBlock(world, i + 15, j + 25, k + 7, Blocks.leaves, 7);
		world.setBlockMetadataWithNotify(i + 15, j + 25, k + 7, 7, 2);
		setBlock(world, i + 15, j + 25, k + 8, Blocks.leaves, 7);
		world.setBlockMetadataWithNotify(i + 15, j + 25, k + 8, 7, 2);
		setBlock(world, i + 15, j + 25, k + 9, Blocks.log, 3);
		world.setBlockMetadataWithNotify(i + 15, j + 25, k + 9, 3, 2);
		setBlock(world, i + 15, j + 25, k + 10, Blocks.log, 3);
		world.setBlockMetadataWithNotify(i + 15, j + 25, k + 10, 3, 2);
		setBlock(world, i + 15, j + 25, k + 11, Blocks.log, 3);
		world.setBlockMetadataWithNotify(i + 15, j + 25, k + 11, 3, 2);
		setBlock(world, i + 15, j + 26, k + 6, Blocks.leaves, 7);
		world.setBlockMetadataWithNotify(i + 15, j + 26, k + 6, 7, 2);
		setBlock(world, i + 15, j + 26, k + 7, Blocks.leaves, 7);
		world.setBlockMetadataWithNotify(i + 15, j + 26, k + 7, 7, 2);
		setBlock(world, i + 15, j + 26, k + 8, Blocks.leaves, 7);
		world.setBlockMetadataWithNotify(i + 15, j + 26, k + 8, 7, 2);
		setBlock(world, i + 15, j + 26, k + 10, Blocks.log, 3);
		world.setBlockMetadataWithNotify(i + 15, j + 26, k + 10, 3, 2);
		setBlock(world, i + 15, j + 27, k + 7, Blocks.leaves, 7);
		world.setBlockMetadataWithNotify(i + 15, j + 27, k + 7, 7, 2);
		setBlock(world, i + 15, j + 27, k + 12, Blocks.log, 3);
		world.setBlockMetadataWithNotify(i + 15, j + 27, k + 12, 3, 2);
		setBlock(world, i + 15, j + 28, k + 3, Blocks.log, 3);
		world.setBlockMetadataWithNotify(i + 15, j + 28, k + 3, 3, 2);
		setBlock(world, i + 15, j + 28, k + 22, Blocks.leaves, 7);
		world.setBlockMetadataWithNotify(i + 15, j + 28, k + 22, 7, 2);
		setBlock(world, i + 15, j + 28, k + 23, Blocks.leaves, 7);
		world.setBlockMetadataWithNotify(i + 15, j + 28, k + 23, 7, 2);
		setBlock(world, i + 15, j + 28, k + 24, Blocks.leaves, 7);
		world.setBlockMetadataWithNotify(i + 15, j + 28, k + 24, 7, 2);
		setBlock(world, i + 15, j + 28, k + 25, Blocks.leaves, 7);
		world.setBlockMetadataWithNotify(i + 15, j + 28, k + 25, 7, 2);
		setBlock(world, i + 15, j + 28, k + 26, Blocks.leaves, 7);
		world.setBlockMetadataWithNotify(i + 15, j + 28, k + 26, 7, 2);
		setBlock(world, i + 15, j + 29, k + 0, Blocks.leaves, 7);
		world.setBlockMetadataWithNotify(i + 15, j + 29, k + 0, 7, 2);
		setBlock(world, i + 15, j + 29, k + 1, Blocks.leaves, 7);
		world.setBlockMetadataWithNotify(i + 15, j + 29, k + 1, 7, 2);
		setBlock(world, i + 15, j + 29, k + 2, Blocks.leaves, 7);
		world.setBlockMetadataWithNotify(i + 15, j + 29, k + 2, 7, 2);
		setBlock(world, i + 15, j + 29, k + 23, Blocks.leaves, 7);
		world.setBlockMetadataWithNotify(i + 15, j + 29, k + 23, 7, 2);
		setBlock(world, i + 15, j + 29, k + 24, Blocks.leaves, 7);
		world.setBlockMetadataWithNotify(i + 15, j + 29, k + 24, 7, 2);
		setBlock(world, i + 15, j + 29, k + 25, Blocks.leaves, 7);
		world.setBlockMetadataWithNotify(i + 15, j + 29, k + 25, 7, 2);
		setBlock(world, i + 15, j + 30, k + 1, Blocks.leaves, 7);
		world.setBlockMetadataWithNotify(i + 15, j + 30, k + 1, 7, 2);
		setBlock(world, i + 15, j + 30, k + 13, Blocks.log, 3);
		world.setBlockMetadataWithNotify(i + 15, j + 30, k + 13, 3, 2);
		setBlock(world, i + 15, j + 30, k + 16, Blocks.log, 3);
		world.setBlockMetadataWithNotify(i + 15, j + 30, k + 16, 3, 2);
		setBlock(world, i + 15, j + 30, k + 24, Blocks.leaves, 7);
		world.setBlockMetadataWithNotify(i + 15, j + 30, k + 24, 7, 2);
		setBlock(world, i + 15, j + 30, k + 26, Blocks.leaves, 7);
		world.setBlockMetadataWithNotify(i + 15, j + 30, k + 26, 7, 2);
		setBlock(world, i + 15, j + 30, k + 27, Blocks.leaves, 7);
		world.setBlockMetadataWithNotify(i + 15, j + 30, k + 27, 7, 2);
		setBlock(world, i + 15, j + 30, k + 28, Blocks.leaves, 7);
		world.setBlockMetadataWithNotify(i + 15, j + 30, k + 28, 7, 2);
		setBlock(world, i + 15, j + 30, k + 29, Blocks.leaves, 7);
		world.setBlockMetadataWithNotify(i + 15, j + 30, k + 29, 7, 2);
		setBlock(world, i + 15, j + 30, k + 30, Blocks.leaves, 7);
		world.setBlockMetadataWithNotify(i + 15, j + 30, k + 30, 7, 2);
		setBlock(world, i + 15, j + 31, k + 8, Blocks.log, 3);
		world.setBlockMetadataWithNotify(i + 15, j + 31, k + 8, 3, 2);
		setBlock(world, i + 15, j + 31, k + 27, Blocks.leaves, 7);
		world.setBlockMetadataWithNotify(i + 15, j + 31, k + 27, 7, 2);
		setBlock(world, i + 15, j + 31, k + 28, Blocks.leaves, 7);
		world.setBlockMetadataWithNotify(i + 15, j + 31, k + 28, 7, 2);
		setBlock(world, i + 15, j + 31, k + 29, Blocks.leaves, 7);
		world.setBlockMetadataWithNotify(i + 15, j + 31, k + 29, 7, 2);
		setBlock(world, i + 15, j + 32, k + 5, Blocks.leaves, 7);
		world.setBlockMetadataWithNotify(i + 15, j + 32, k + 5, 7, 2);
		setBlock(world, i + 15, j + 32, k + 6, Blocks.leaves, 7);
		world.setBlockMetadataWithNotify(i + 15, j + 32, k + 6, 7, 2);
		setBlock(world, i + 15, j + 32, k + 7, Blocks.leaves, 7);
		world.setBlockMetadataWithNotify(i + 15, j + 32, k + 7, 7, 2);
		setBlock(world, i + 15, j + 32, k + 8, Blocks.leaves, 7);
		world.setBlockMetadataWithNotify(i + 15, j + 32, k + 8, 7, 2);
		setBlock(world, i + 15, j + 32, k + 9, Blocks.leaves, 7);
		world.setBlockMetadataWithNotify(i + 15, j + 32, k + 9, 7, 2);
		setBlock(world, i + 15, j + 32, k + 28, Blocks.leaves, 7);
		world.setBlockMetadataWithNotify(i + 15, j + 32, k + 28, 7, 2);
		setBlock(world, i + 15, j + 33, k + 5, Blocks.log, 3);
		world.setBlockMetadataWithNotify(i + 15, j + 33, k + 5, 3, 2);
		setBlock(world, i + 15, j + 33, k + 6, Blocks.leaves, 7);
		world.setBlockMetadataWithNotify(i + 15, j + 33, k + 6, 7, 2);
		setBlock(world, i + 15, j + 33, k + 7, Blocks.leaves, 7);
		world.setBlockMetadataWithNotify(i + 15, j + 33, k + 7, 7, 2);
		setBlock(world, i + 15, j + 33, k + 8, Blocks.leaves, 7);
		world.setBlockMetadataWithNotify(i + 15, j + 33, k + 8, 7, 2);
		setBlock(world, i + 15, j + 34, k + 7, Blocks.leaves, 7);
		world.setBlockMetadataWithNotify(i + 15, j + 34, k + 7, 7, 2);
		setBlock(world, i + 15, j + 34, k + 8, Blocks.log, 3);
		world.setBlockMetadataWithNotify(i + 15, j + 34, k + 8, 3, 2);
		setBlock(world, i + 15, j + 34, k + 17, Blocks.log, 3);
		world.setBlockMetadataWithNotify(i + 15, j + 34, k + 17, 3, 2);
		setBlock(world, i + 15, j + 35, k + 15, Blocks.leaves, 7);
		world.setBlockMetadataWithNotify(i + 15, j + 35, k + 15, 7, 2);
		setBlock(world, i + 15, j + 35, k + 16, Blocks.leaves, 7);
		world.setBlockMetadataWithNotify(i + 15, j + 35, k + 16, 7, 2);
		setBlock(world, i + 15, j + 35, k + 17, Blocks.leaves, 7);
		world.setBlockMetadataWithNotify(i + 15, j + 35, k + 17, 7, 2);
		setBlock(world, i + 15, j + 35, k + 18, Blocks.leaves, 7);
		world.setBlockMetadataWithNotify(i + 15, j + 35, k + 18, 7, 2);
		setBlock(world, i + 15, j + 35, k + 19, Blocks.leaves, 7);
		world.setBlockMetadataWithNotify(i + 15, j + 35, k + 19, 7, 2);
		setBlock(world, i + 15, j + 36, k + 16, Blocks.leaves, 7);
		world.setBlockMetadataWithNotify(i + 15, j + 36, k + 16, 7, 2);
		setBlock(world, i + 15, j + 36, k + 17, Blocks.leaves, 7);
		world.setBlockMetadataWithNotify(i + 15, j + 36, k + 17, 7, 2);
		setBlock(world, i + 15, j + 36, k + 18, Blocks.leaves, 7);
		world.setBlockMetadataWithNotify(i + 15, j + 36, k + 18, 7, 2);
		setBlock(world, i + 15, j + 36, k + 22, Blocks.leaves, 7);
		world.setBlockMetadataWithNotify(i + 15, j + 36, k + 22, 7, 2);
		setBlock(world, i + 15, j + 36, k + 23, Blocks.leaves, 7);
		world.setBlockMetadataWithNotify(i + 15, j + 36, k + 23, 7, 2);
		setBlock(world, i + 15, j + 36, k + 24, Blocks.leaves, 7);
		world.setBlockMetadataWithNotify(i + 15, j + 36, k + 24, 7, 2);
		setBlock(world, i + 15, j + 37, k + 0, Blocks.log, 3);
		world.setBlockMetadataWithNotify(i + 15, j + 37, k + 0, 3, 2);
		setBlock(world, i + 15, j + 37, k + 17, Blocks.leaves, 7);
		world.setBlockMetadataWithNotify(i + 15, j + 37, k + 17, 7, 2);
		setBlock(world, i + 15, j + 37, k + 23, Blocks.leaves, 7);
		world.setBlockMetadataWithNotify(i + 15, j + 37, k + 23, 7, 2);
		setBlock(world, i + 15, j + 38, k + 0, Blocks.leaves, 7);
		world.setBlockMetadataWithNotify(i + 15, j + 38, k + 0, 7, 2);
		setBlock(world, i + 15, j + 38, k + 1, Blocks.leaves, 7);
		world.setBlockMetadataWithNotify(i + 15, j + 38, k + 1, 7, 2);
		setBlock(world, i + 15, j + 38, k + 16, Blocks.log, 3);
		world.setBlockMetadataWithNotify(i + 15, j + 38, k + 16, 3, 2);
		setBlock(world, i + 15, j + 39, k + 0, Blocks.leaves, 7);
		world.setBlockMetadataWithNotify(i + 15, j + 39, k + 0, 7, 2);
		setBlock(world, i + 15, j + 39, k + 1, Blocks.leaves, 7);
		world.setBlockMetadataWithNotify(i + 15, j + 39, k + 1, 7, 2);
		setBlock(world, i + 15, j + 39, k + 16, Blocks.leaves, 7);
		world.setBlockMetadataWithNotify(i + 15, j + 39, k + 16, 7, 2);
		setBlock(world, i + 15, j + 39, k + 17, Blocks.leaves, 7);
		world.setBlockMetadataWithNotify(i + 15, j + 39, k + 17, 7, 2);
		setBlock(world, i + 15, j + 39, k + 18, Blocks.leaves, 7);
		world.setBlockMetadataWithNotify(i + 15, j + 39, k + 18, 7, 2);
		setBlock(world, i + 15, j + 40, k + 0, Blocks.leaves, 7);
		world.setBlockMetadataWithNotify(i + 15, j + 40, k + 0, 7, 2);
		setBlock(world, i + 15, j + 40, k + 17, Blocks.leaves, 7);
		world.setBlockMetadataWithNotify(i + 15, j + 40, k + 17, 7, 2);
		setBlock(world, i + 15, j + 46, k + 0, Blocks.leaves, 7);
		world.setBlockMetadataWithNotify(i + 15, j + 46, k + 0, 7, 2);
		setBlock(world, i + 15, j + 46, k + 1, Blocks.leaves, 7);
		world.setBlockMetadataWithNotify(i + 15, j + 46, k + 1, 7, 2);
		setBlock(world, i + 15, j + 46, k + 2, Blocks.leaves, 7);
		world.setBlockMetadataWithNotify(i + 15, j + 46, k + 2, 7, 2);
		setBlock(world, i + 15, j + 47, k + 0, Blocks.leaves, 7);
		world.setBlockMetadataWithNotify(i + 15, j + 47, k + 0, 7, 2);
		setBlock(world, i + 15, j + 47, k + 1, Blocks.leaves, 7);
		world.setBlockMetadataWithNotify(i + 15, j + 47, k + 1, 7, 2);
		setBlock(world, i + 15, j + 48, k + 0, Blocks.leaves, 7);
		world.setBlockMetadataWithNotify(i + 15, j + 48, k + 0, 7, 2);
		setBlock(world, i + 15, j + 52, k + 7, Blocks.leaves, 7);
		world.setBlockMetadataWithNotify(i + 15, j + 52, k + 7, 7, 2);
		setBlock(world, i + 15, j + 52, k + 8, Blocks.leaves, 7);
		world.setBlockMetadataWithNotify(i + 15, j + 52, k + 8, 7, 2);
		setBlock(world, i + 15, j + 52, k + 9, Blocks.leaves, 7);
		world.setBlockMetadataWithNotify(i + 15, j + 52, k + 9, 7, 2);
		setBlock(world, i + 15, j + 53, k + 8, Blocks.leaves, 7);
		world.setBlockMetadataWithNotify(i + 15, j + 53, k + 8, 7, 2);
		setBlock(world, i + 15, j + 53, k + 10, Blocks.leaves, 7);
		world.setBlockMetadataWithNotify(i + 15, j + 53, k + 10, 7, 2);
		setBlock(world, i + 15, j + 53, k + 11, Blocks.leaves, 7);
		world.setBlockMetadataWithNotify(i + 15, j + 53, k + 11, 7, 2);
		setBlock(world, i + 15, j + 53, k + 12, Blocks.log, 3);
		world.setBlockMetadataWithNotify(i + 15, j + 53, k + 12, 3, 2);
		setBlock(world, i + 15, j + 53, k + 13, Blocks.leaves, 7);
		world.setBlockMetadataWithNotify(i + 15, j + 53, k + 13, 7, 2);
		setBlock(world, i + 15, j + 53, k + 14, Blocks.leaves, 7);
		world.setBlockMetadataWithNotify(i + 15, j + 53, k + 14, 7, 2);
		setBlock(world, i + 15, j + 54, k + 10, Blocks.leaves, 7);
		world.setBlockMetadataWithNotify(i + 15, j + 54, k + 10, 7, 2);
		setBlock(world, i + 15, j + 54, k + 11, Blocks.leaves, 7);
		world.setBlockMetadataWithNotify(i + 15, j + 54, k + 11, 7, 2);
		setBlock(world, i + 15, j + 54, k + 12, Blocks.leaves, 7);
		world.setBlockMetadataWithNotify(i + 15, j + 54, k + 12, 7, 2);
		setBlock(world, i + 15, j + 54, k + 13, Blocks.leaves, 7);
		world.setBlockMetadataWithNotify(i + 15, j + 54, k + 13, 7, 2);
		setBlock(world, i + 15, j + 54, k + 14, Blocks.leaves, 7);
		world.setBlockMetadataWithNotify(i + 15, j + 54, k + 14, 7, 2);
		setBlock(world, i + 15, j + 55, k + 6, Blocks.leaves, 7);
		world.setBlockMetadataWithNotify(i + 15, j + 55, k + 6, 7, 2);
		setBlock(world, i + 15, j + 55, k + 7, Blocks.leaves, 7);
		world.setBlockMetadataWithNotify(i + 15, j + 55, k + 7, 7, 2);
		setBlock(world, i + 15, j + 55, k + 8, Blocks.leaves, 7);
		world.setBlockMetadataWithNotify(i + 15, j + 55, k + 8, 7, 2);
		setBlock(world, i + 15, j + 55, k + 9, Blocks.leaves, 7);
		world.setBlockMetadataWithNotify(i + 15, j + 55, k + 9, 7, 2);
		setBlock(world, i + 15, j + 55, k + 10, Blocks.leaves, 7);
		world.setBlockMetadataWithNotify(i + 15, j + 55, k + 10, 7, 2);
		setBlock(world, i + 15, j + 55, k + 11, Blocks.leaves, 7);
		world.setBlockMetadataWithNotify(i + 15, j + 55, k + 11, 7, 2);
		setBlock(world, i + 15, j + 55, k + 12, Blocks.leaves, 7);
		world.setBlockMetadataWithNotify(i + 15, j + 55, k + 12, 7, 2);
		setBlock(world, i + 15, j + 55, k + 13, Blocks.leaves, 7);
		world.setBlockMetadataWithNotify(i + 15, j + 55, k + 13, 7, 2);
		setBlock(world, i + 15, j + 56, k + 7, Blocks.leaves, 7);
		world.setBlockMetadataWithNotify(i + 15, j + 56, k + 7, 7, 2);
		setBlock(world, i + 15, j + 56, k + 8, Blocks.leaves, 7);
		world.setBlockMetadataWithNotify(i + 15, j + 56, k + 8, 7, 2);
		setBlock(world, i + 15, j + 56, k + 9, Blocks.leaves, 7);
		world.setBlockMetadataWithNotify(i + 15, j + 56, k + 9, 7, 2);
		setBlock(world, i + 15, j + 56, k + 10, Blocks.leaves, 7);
		world.setBlockMetadataWithNotify(i + 15, j + 56, k + 10, 7, 2);
		setBlock(world, i + 15, j + 56, k + 11, Blocks.leaves, 7);
		world.setBlockMetadataWithNotify(i + 15, j + 56, k + 11, 7, 2);
		setBlock(world, i + 15, j + 56, k + 12, Blocks.leaves, 7);
		world.setBlockMetadataWithNotify(i + 15, j + 56, k + 12, 7, 2);
		setBlock(world, i + 15, j + 57, k + 8, Blocks.leaves, 7);
		world.setBlockMetadataWithNotify(i + 15, j + 57, k + 8, 7, 2);
		setBlock(world, i + 15, j + 57, k + 9, Blocks.leaves, 7);
		world.setBlockMetadataWithNotify(i + 15, j + 57, k + 9, 7, 2);
		setBlock(world, i + 15, j + 57, k + 10, Blocks.leaves, 7);
		world.setBlockMetadataWithNotify(i + 15, j + 57, k + 10, 7, 2);
		setBlock(world, i + 15, j + 57, k + 11, Blocks.leaves, 7);
		world.setBlockMetadataWithNotify(i + 15, j + 57, k + 11, 7, 2);
		setBlock(world, i + 15, j + 58, k + 10, Blocks.leaves, 7);
		world.setBlockMetadataWithNotify(i + 15, j + 58, k + 10, 7, 2);
		setBlock(world, i + 16, j + 20, k + 0, Blocks.log, 3);
		world.setBlockMetadataWithNotify(i + 16, j + 20, k + 0, 3, 2);
		setBlock(world, i + 16, j + 24, k + 8, Blocks.log, 3);
		world.setBlockMetadataWithNotify(i + 16, j + 24, k + 8, 3, 2);
		setBlock(world, i + 16, j + 24, k + 10, Blocks.log, 3);
		world.setBlockMetadataWithNotify(i + 16, j + 24, k + 10, 3, 2);
		setBlock(world, i + 16, j + 25, k + 6, Blocks.leaves, 7);
		world.setBlockMetadataWithNotify(i + 16, j + 25, k + 6, 7, 2);
		setBlock(world, i + 16, j + 25, k + 7, Blocks.leaves, 7);
		world.setBlockMetadataWithNotify(i + 16, j + 25, k + 7, 7, 2);
		setBlock(world, i + 16, j + 25, k + 8, Blocks.leaves, 7);
		world.setBlockMetadataWithNotify(i + 16, j + 25, k + 8, 7, 2);
		setBlock(world, i + 16, j + 25, k + 9, Blocks.log, 3);
		world.setBlockMetadataWithNotify(i + 16, j + 25, k + 9, 3, 2);
		setBlock(world, i + 16, j + 25, k + 10, Blocks.log, 3);
		world.setBlockMetadataWithNotify(i + 16, j + 25, k + 10, 3, 2);
		setBlock(world, i + 16, j + 25, k + 11, Blocks.log, 3);
		world.setBlockMetadataWithNotify(i + 16, j + 25, k + 11, 3, 2);
		setBlock(world, i + 16, j + 26, k + 7, Blocks.leaves, 7);
		world.setBlockMetadataWithNotify(i + 16, j + 26, k + 7, 7, 2);
		setBlock(world, i + 16, j + 26, k + 10, Blocks.log, 3);
		world.setBlockMetadataWithNotify(i + 16, j + 26, k + 10, 3, 2);
		setBlock(world, i + 16, j + 27, k + 12, Blocks.log, 3);
		world.setBlockMetadataWithNotify(i + 16, j + 27, k + 12, 3, 2);
		setBlock(world, i + 16, j + 27, k + 23, Blocks.log, 3);
		world.setBlockMetadataWithNotify(i + 16, j + 27, k + 23, 3, 2);
		setBlock(world, i + 16, j + 28, k + 3, Blocks.log, 3);
		world.setBlockMetadataWithNotify(i + 16, j + 28, k + 3, 3, 2);
		setBlock(world, i + 16, j + 28, k + 22, Blocks.leaves, 7);
		world.setBlockMetadataWithNotify(i + 16, j + 28, k + 22, 7, 2);
		setBlock(world, i + 16, j + 28, k + 23, Blocks.leaves, 7);
		world.setBlockMetadataWithNotify(i + 16, j + 28, k + 23, 7, 2);
		setBlock(world, i + 16, j + 28, k + 24, Blocks.log, 3);
		world.setBlockMetadataWithNotify(i + 16, j + 28, k + 24, 3, 2);
		setBlock(world, i + 16, j + 28, k + 25, Blocks.leaves, 7);
		world.setBlockMetadataWithNotify(i + 16, j + 28, k + 25, 7, 2);
		setBlock(world, i + 16, j + 28, k + 26, Blocks.leaves, 7);
		world.setBlockMetadataWithNotify(i + 16, j + 28, k + 26, 7, 2);
		setBlock(world, i + 16, j + 29, k + 22, Blocks.leaves, 7);
		world.setBlockMetadataWithNotify(i + 16, j + 29, k + 22, 7, 2);
		setBlock(world, i + 16, j + 29, k + 23, Blocks.leaves, 7);
		world.setBlockMetadataWithNotify(i + 16, j + 29, k + 23, 7, 2);
		setBlock(world, i + 16, j + 29, k + 24, Blocks.leaves, 7);
		world.setBlockMetadataWithNotify(i + 16, j + 29, k + 24, 7, 2);
		setBlock(world, i + 16, j + 29, k + 25, Blocks.leaves, 7);
		world.setBlockMetadataWithNotify(i + 16, j + 29, k + 25, 7, 2);
		setBlock(world, i + 16, j + 29, k + 26, Blocks.log, 3);
		world.setBlockMetadataWithNotify(i + 16, j + 29, k + 26, 3, 2);
		setBlock(world, i + 16, j + 29, k + 27, Blocks.log, 3);
		world.setBlockMetadataWithNotify(i + 16, j + 29, k + 27, 3, 2);
		setBlock(world, i + 16, j + 30, k + 13, Blocks.log, 3);
		world.setBlockMetadataWithNotify(i + 16, j + 30, k + 13, 3, 2);
		setBlock(world, i + 16, j + 30, k + 16, Blocks.log, 3);
		world.setBlockMetadataWithNotify(i + 16, j + 30, k + 16, 3, 2);
		setBlock(world, i + 16, j + 30, k + 23, Blocks.leaves, 7);
		world.setBlockMetadataWithNotify(i + 16, j + 30, k + 23, 7, 2);
		setBlock(world, i + 16, j + 30, k + 24, Blocks.leaves, 7);
		world.setBlockMetadataWithNotify(i + 16, j + 30, k + 24, 7, 2);
		setBlock(world, i + 16, j + 30, k + 25, Blocks.leaves, 7);
		world.setBlockMetadataWithNotify(i + 16, j + 30, k + 25, 7, 2);
		setBlock(world, i + 16, j + 30, k + 26, Blocks.leaves, 7);
		world.setBlockMetadataWithNotify(i + 16, j + 30, k + 26, 7, 2);
		setBlock(world, i + 16, j + 30, k + 27, Blocks.leaves, 7);
		world.setBlockMetadataWithNotify(i + 16, j + 30, k + 27, 7, 2);
		setBlock(world, i + 16, j + 30, k + 28, Blocks.log, 3);
		world.setBlockMetadataWithNotify(i + 16, j + 30, k + 28, 3, 2);
		setBlock(world, i + 16, j + 30, k + 29, Blocks.leaves, 7);
		world.setBlockMetadataWithNotify(i + 16, j + 30, k + 29, 7, 2);
		setBlock(world, i + 16, j + 30, k + 30, Blocks.leaves, 7);
		world.setBlockMetadataWithNotify(i + 16, j + 30, k + 30, 7, 2);
		setBlock(world, i + 16, j + 31, k + 8, Blocks.log, 3);
		world.setBlockMetadataWithNotify(i + 16, j + 31, k + 8, 3, 2);
		setBlock(world, i + 16, j + 31, k + 24, Blocks.leaves, 7);
		world.setBlockMetadataWithNotify(i + 16, j + 31, k + 24, 7, 2);
		setBlock(world, i + 16, j + 31, k + 26, Blocks.leaves, 7);
		world.setBlockMetadataWithNotify(i + 16, j + 31, k + 26, 7, 2);
		setBlock(world, i + 16, j + 31, k + 27, Blocks.leaves, 7);
		world.setBlockMetadataWithNotify(i + 16, j + 31, k + 27, 7, 2);
		setBlock(world, i + 16, j + 31, k + 28, Blocks.leaves, 7);
		world.setBlockMetadataWithNotify(i + 16, j + 31, k + 28, 7, 2);
		setBlock(world, i + 16, j + 31, k + 29, Blocks.leaves, 7);
		world.setBlockMetadataWithNotify(i + 16, j + 31, k + 29, 7, 2);
		setBlock(world, i + 16, j + 31, k + 30, Blocks.leaves, 7);
		world.setBlockMetadataWithNotify(i + 16, j + 31, k + 30, 7, 2);
		setBlock(world, i + 16, j + 32, k + 6, Blocks.leaves, 7);
		world.setBlockMetadataWithNotify(i + 16, j + 32, k + 6, 7, 2);
		setBlock(world, i + 16, j + 32, k + 7, Blocks.leaves, 7);
		world.setBlockMetadataWithNotify(i + 16, j + 32, k + 7, 7, 2);
		setBlock(world, i + 16, j + 32, k + 8, Blocks.leaves, 7);
		world.setBlockMetadataWithNotify(i + 16, j + 32, k + 8, 7, 2);
		setBlock(world, i + 16, j + 32, k + 27, Blocks.leaves, 7);
		world.setBlockMetadataWithNotify(i + 16, j + 32, k + 27, 7, 2);
		setBlock(world, i + 16, j + 32, k + 28, Blocks.leaves, 7);
		world.setBlockMetadataWithNotify(i + 16, j + 32, k + 28, 7, 2);
		setBlock(world, i + 16, j + 32, k + 29, Blocks.leaves, 7);
		world.setBlockMetadataWithNotify(i + 16, j + 32, k + 29, 7, 2);
		setBlock(world, i + 16, j + 33, k + 6, Blocks.log, 3);
		world.setBlockMetadataWithNotify(i + 16, j + 33, k + 6, 3, 2);
		setBlock(world, i + 16, j + 33, k + 7, Blocks.leaves, 7);
		world.setBlockMetadataWithNotify(i + 16, j + 33, k + 7, 7, 2);
		setBlock(world, i + 16, j + 33, k + 8, Blocks.log, 3);
		world.setBlockMetadataWithNotify(i + 16, j + 33, k + 8, 3, 2);
		setBlock(world, i + 16, j + 33, k + 28, Blocks.leaves, 7);
		world.setBlockMetadataWithNotify(i + 16, j + 33, k + 28, 7, 2);
		setBlock(world, i + 16, j + 34, k + 16, Blocks.log, 3);
		world.setBlockMetadataWithNotify(i + 16, j + 34, k + 16, 3, 2);
		setBlock(world, i + 16, j + 35, k + 16, Blocks.leaves, 7);
		world.setBlockMetadataWithNotify(i + 16, j + 35, k + 16, 7, 2);
		setBlock(world, i + 16, j + 35, k + 17, Blocks.leaves, 7);
		world.setBlockMetadataWithNotify(i + 16, j + 35, k + 17, 7, 2);
		setBlock(world, i + 16, j + 35, k + 18, Blocks.leaves, 7);
		world.setBlockMetadataWithNotify(i + 16, j + 35, k + 18, 7, 2);
		setBlock(world, i + 16, j + 36, k + 17, Blocks.leaves, 7);
		world.setBlockMetadataWithNotify(i + 16, j + 36, k + 17, 7, 2);
		setBlock(world, i + 16, j + 36, k + 21, Blocks.leaves, 7);
		world.setBlockMetadataWithNotify(i + 16, j + 36, k + 21, 7, 2);
		setBlock(world, i + 16, j + 36, k + 22, Blocks.leaves, 7);
		world.setBlockMetadataWithNotify(i + 16, j + 36, k + 22, 7, 2);
		setBlock(world, i + 16, j + 36, k + 23, Blocks.leaves, 7);
		world.setBlockMetadataWithNotify(i + 16, j + 36, k + 23, 7, 2);
		setBlock(world, i + 16, j + 36, k + 24, Blocks.leaves, 7);
		world.setBlockMetadataWithNotify(i + 16, j + 36, k + 24, 7, 2);
		setBlock(world, i + 16, j + 36, k + 25, Blocks.leaves, 7);
		world.setBlockMetadataWithNotify(i + 16, j + 36, k + 25, 7, 2);
		setBlock(world, i + 16, j + 37, k + 1, Blocks.log, 3);
		world.setBlockMetadataWithNotify(i + 16, j + 37, k + 1, 3, 2);
		setBlock(world, i + 16, j + 37, k + 22, Blocks.leaves, 7);
		world.setBlockMetadataWithNotify(i + 16, j + 37, k + 22, 7, 2);
		setBlock(world, i + 16, j + 37, k + 23, Blocks.leaves, 7);
		world.setBlockMetadataWithNotify(i + 16, j + 37, k + 23, 7, 2);
		setBlock(world, i + 16, j + 37, k + 24, Blocks.leaves, 7);
		world.setBlockMetadataWithNotify(i + 16, j + 37, k + 24, 7, 2);
		setBlock(world, i + 16, j + 38, k + 0, Blocks.leaves, 7);
		world.setBlockMetadataWithNotify(i + 16, j + 38, k + 0, 7, 2);
		setBlock(world, i + 16, j + 38, k + 1, Blocks.leaves, 7);
		world.setBlockMetadataWithNotify(i + 16, j + 38, k + 1, 7, 2);
		setBlock(world, i + 16, j + 38, k + 15, Blocks.log, 3);
		world.setBlockMetadataWithNotify(i + 16, j + 38, k + 15, 3, 2);
		setBlock(world, i + 16, j + 38, k + 23, Blocks.leaves, 7);
		world.setBlockMetadataWithNotify(i + 16, j + 38, k + 23, 7, 2);
		setBlock(world, i + 16, j + 39, k + 0, Blocks.leaves, 7);
		world.setBlockMetadataWithNotify(i + 16, j + 39, k + 0, 7, 2);
		setBlock(world, i + 16, j + 46, k + 0, Blocks.log, 3);
		world.setBlockMetadataWithNotify(i + 16, j + 46, k + 0, 3, 2);
		setBlock(world, i + 16, j + 46, k + 1, Blocks.leaves, 7);
		world.setBlockMetadataWithNotify(i + 16, j + 46, k + 1, 7, 2);
		setBlock(world, i + 16, j + 46, k + 2, Blocks.leaves, 7);
		world.setBlockMetadataWithNotify(i + 16, j + 46, k + 2, 7, 2);
		setBlock(world, i + 16, j + 47, k + 0, Blocks.leaves, 7);
		world.setBlockMetadataWithNotify(i + 16, j + 47, k + 0, 7, 2);
		setBlock(world, i + 16, j + 47, k + 1, Blocks.leaves, 7);
		world.setBlockMetadataWithNotify(i + 16, j + 47, k + 1, 7, 2);
		setBlock(world, i + 16, j + 47, k + 2, Blocks.leaves, 7);
		world.setBlockMetadataWithNotify(i + 16, j + 47, k + 2, 7, 2);
		setBlock(world, i + 16, j + 48, k + 0, Blocks.leaves, 7);
		world.setBlockMetadataWithNotify(i + 16, j + 48, k + 0, 7, 2);
		setBlock(world, i + 16, j + 48, k + 1, Blocks.leaves, 7);
		world.setBlockMetadataWithNotify(i + 16, j + 48, k + 1, 7, 2);
		setBlock(world, i + 16, j + 49, k + 0, Blocks.leaves, 7);
		world.setBlockMetadataWithNotify(i + 16, j + 49, k + 0, 7, 2);
		setBlock(world, i + 16, j + 52, k + 6, Blocks.leaves, 7);
		world.setBlockMetadataWithNotify(i + 16, j + 52, k + 6, 7, 2);
		setBlock(world, i + 16, j + 52, k + 7, Blocks.leaves, 7);
		world.setBlockMetadataWithNotify(i + 16, j + 52, k + 7, 7, 2);
		setBlock(world, i + 16, j + 52, k + 8, Blocks.leaves, 7);
		world.setBlockMetadataWithNotify(i + 16, j + 52, k + 8, 7, 2);
		setBlock(world, i + 16, j + 52, k + 9, Blocks.leaves, 7);
		world.setBlockMetadataWithNotify(i + 16, j + 52, k + 9, 7, 2);
		setBlock(world, i + 16, j + 52, k + 10, Blocks.leaves, 7);
		world.setBlockMetadataWithNotify(i + 16, j + 52, k + 10, 7, 2);
		setBlock(world, i + 16, j + 53, k + 7, Blocks.leaves, 7);
		world.setBlockMetadataWithNotify(i + 16, j + 53, k + 7, 7, 2);
		setBlock(world, i + 16, j + 53, k + 8, Blocks.leaves, 7);
		world.setBlockMetadataWithNotify(i + 16, j + 53, k + 8, 7, 2);
		setBlock(world, i + 16, j + 53, k + 9, Blocks.leaves, 7);
		world.setBlockMetadataWithNotify(i + 16, j + 53, k + 9, 7, 2);
		setBlock(world, i + 16, j + 53, k + 10, Blocks.leaves, 7);
		world.setBlockMetadataWithNotify(i + 16, j + 53, k + 10, 7, 2);
		setBlock(world, i + 16, j + 53, k + 11, Blocks.leaves, 7);
		world.setBlockMetadataWithNotify(i + 16, j + 53, k + 11, 7, 2);
		setBlock(world, i + 16, j + 53, k + 12, Blocks.leaves, 7);
		world.setBlockMetadataWithNotify(i + 16, j + 53, k + 12, 7, 2);
		setBlock(world, i + 16, j + 53, k + 13, Blocks.leaves, 7);
		world.setBlockMetadataWithNotify(i + 16, j + 53, k + 13, 7, 2);
		setBlock(world, i + 16, j + 53, k + 14, Blocks.leaves, 7);
		world.setBlockMetadataWithNotify(i + 16, j + 53, k + 14, 7, 2);
		setBlock(world, i + 16, j + 54, k + 8, Blocks.leaves, 7);
		world.setBlockMetadataWithNotify(i + 16, j + 54, k + 8, 7, 2);
		setBlock(world, i + 16, j + 54, k + 11, Blocks.leaves, 7);
		world.setBlockMetadataWithNotify(i + 16, j + 54, k + 11, 7, 2);
		setBlock(world, i + 16, j + 54, k + 12, Blocks.leaves, 7);
		world.setBlockMetadataWithNotify(i + 16, j + 54, k + 12, 7, 2);
		setBlock(world, i + 16, j + 54, k + 13, Blocks.leaves, 7);
		world.setBlockMetadataWithNotify(i + 16, j + 54, k + 13, 7, 2);
		setBlock(world, i + 16, j + 55, k + 6, Blocks.leaves, 7);
		world.setBlockMetadataWithNotify(i + 16, j + 55, k + 6, 7, 2);
		setBlock(world, i + 16, j + 55, k + 7, Blocks.leaves, 7);
		world.setBlockMetadataWithNotify(i + 16, j + 55, k + 7, 7, 2);
		setBlock(world, i + 16, j + 55, k + 8, Blocks.log, 3);
		world.setBlockMetadataWithNotify(i + 16, j + 55, k + 8, 3, 2);
		setBlock(world, i + 16, j + 55, k + 9, Blocks.leaves, 7);
		world.setBlockMetadataWithNotify(i + 16, j + 55, k + 9, 7, 2);
		setBlock(world, i + 16, j + 55, k + 10, Blocks.leaves, 7);
		world.setBlockMetadataWithNotify(i + 16, j + 55, k + 10, 7, 2);
		setBlock(world, i + 16, j + 55, k + 12, Blocks.leaves, 7);
		world.setBlockMetadataWithNotify(i + 16, j + 55, k + 12, 7, 2);
		setBlock(world, i + 16, j + 56, k + 6, Blocks.leaves, 7);
		world.setBlockMetadataWithNotify(i + 16, j + 56, k + 6, 7, 2);
		setBlock(world, i + 16, j + 56, k + 7, Blocks.leaves, 7);
		world.setBlockMetadataWithNotify(i + 16, j + 56, k + 7, 7, 2);
		setBlock(world, i + 16, j + 56, k + 8, Blocks.leaves, 7);
		world.setBlockMetadataWithNotify(i + 16, j + 56, k + 8, 7, 2);
		setBlock(world, i + 16, j + 56, k + 9, Blocks.leaves, 7);
		world.setBlockMetadataWithNotify(i + 16, j + 56, k + 9, 7, 2);
		setBlock(world, i + 16, j + 56, k + 10, Blocks.log, 3);
		world.setBlockMetadataWithNotify(i + 16, j + 56, k + 10, 3, 2);
		setBlock(world, i + 16, j + 56, k + 11, Blocks.leaves, 7);
		world.setBlockMetadataWithNotify(i + 16, j + 56, k + 11, 7, 2);
		setBlock(world, i + 16, j + 56, k + 12, Blocks.leaves, 7);
		world.setBlockMetadataWithNotify(i + 16, j + 56, k + 12, 7, 2);
		setBlock(world, i + 16, j + 57, k + 7, Blocks.leaves, 7);
		world.setBlockMetadataWithNotify(i + 16, j + 57, k + 7, 7, 2);
		setBlock(world, i + 16, j + 57, k + 8, Blocks.leaves, 7);
		world.setBlockMetadataWithNotify(i + 16, j + 57, k + 8, 7, 2);
		setBlock(world, i + 16, j + 57, k + 9, Blocks.leaves, 7);
		world.setBlockMetadataWithNotify(i + 16, j + 57, k + 9, 7, 2);
		setBlock(world, i + 16, j + 57, k + 10, Blocks.leaves, 7);
		world.setBlockMetadataWithNotify(i + 16, j + 57, k + 10, 7, 2);
		setBlock(world, i + 16, j + 57, k + 11, Blocks.leaves, 7);
		world.setBlockMetadataWithNotify(i + 16, j + 57, k + 11, 7, 2);
		setBlock(world, i + 16, j + 57, k + 12, Blocks.leaves, 7);
		world.setBlockMetadataWithNotify(i + 16, j + 57, k + 12, 7, 2);
		setBlock(world, i + 16, j + 58, k + 8, Blocks.leaves, 7);
		world.setBlockMetadataWithNotify(i + 16, j + 58, k + 8, 7, 2);
		setBlock(world, i + 16, j + 58, k + 9, Blocks.leaves, 7);
		world.setBlockMetadataWithNotify(i + 16, j + 58, k + 9, 7, 2);
		setBlock(world, i + 16, j + 58, k + 10, Blocks.leaves, 7);
		world.setBlockMetadataWithNotify(i + 16, j + 58, k + 10, 7, 2);
		setBlock(world, i + 16, j + 58, k + 11, Blocks.leaves, 7);
		world.setBlockMetadataWithNotify(i + 16, j + 58, k + 11, 7, 2);
		setBlock(world, i + 16, j + 59, k + 10, Blocks.leaves, 7);
		world.setBlockMetadataWithNotify(i + 16, j + 59, k + 10, 7, 2);
		setBlock(world, i + 16, j + 61, k + 7, Blocks.leaves, 7);
		world.setBlockMetadataWithNotify(i + 16, j + 61, k + 7, 7, 2);
		setBlock(world, i + 16, j + 61, k + 8, Blocks.leaves, 7);
		world.setBlockMetadataWithNotify(i + 16, j + 61, k + 8, 7, 2);
		setBlock(world, i + 16, j + 61, k + 9, Blocks.leaves, 7);
		world.setBlockMetadataWithNotify(i + 16, j + 61, k + 9, 7, 2);
		setBlock(world, i + 16, j + 61, k + 10, Blocks.leaves, 7);
		world.setBlockMetadataWithNotify(i + 16, j + 61, k + 10, 7, 2);
		setBlock(world, i + 16, j + 61, k + 11, Blocks.leaves, 7);
		world.setBlockMetadataWithNotify(i + 16, j + 61, k + 11, 7, 2);
		setBlock(world, i + 16, j + 62, k + 8, Blocks.leaves, 7);
		world.setBlockMetadataWithNotify(i + 16, j + 62, k + 8, 7, 2);
		setBlock(world, i + 16, j + 62, k + 10, Blocks.leaves, 7);
		world.setBlockMetadataWithNotify(i + 16, j + 62, k + 10, 7, 2);
		setBlock(world, i + 17, j + 0, k + 9, Blocks.log, 3);
		world.setBlockMetadataWithNotify(i + 17, j + 0, k + 9, 3, 2);
		setBlock(world, i + 17, j + 0, k + 10, Blocks.log, 3);
		world.setBlockMetadataWithNotify(i + 17, j + 0, k + 10, 3, 2);
		setBlock(world, i + 17, j + 0, k + 11, Blocks.log, 3);
		world.setBlockMetadataWithNotify(i + 17, j + 0, k + 11, 3, 2);
		setBlock(world, i + 17, j + 0, k + 12, Blocks.log, 3);
		world.setBlockMetadataWithNotify(i + 17, j + 0, k + 12, 3, 2);
		setBlock(world, i + 17, j + 1, k + 12, Blocks.log, 3);
		world.setBlockMetadataWithNotify(i + 17, j + 1, k + 12, 3, 2);
		setBlock(world, i + 17, j + 2, k + 12, Blocks.log, 3);
		world.setBlockMetadataWithNotify(i + 17, j + 2, k + 12, 3, 2);
		setBlock(world, i + 17, j + 19, k + 1, Blocks.log, 3);
		world.setBlockMetadataWithNotify(i + 17, j + 19, k + 1, 3, 2);
		setBlock(world, i + 17, j + 19, k + 2, Blocks.log, 3);
		world.setBlockMetadataWithNotify(i + 17, j + 19, k + 2, 3, 2);
		setBlock(world, i + 17, j + 24, k + 8, Blocks.log, 3);
		world.setBlockMetadataWithNotify(i + 17, j + 24, k + 8, 3, 2);
		setBlock(world, i + 17, j + 24, k + 10, Blocks.log, 3);
		world.setBlockMetadataWithNotify(i + 17, j + 24, k + 10, 3, 2);
		setBlock(world, i + 17, j + 25, k + 9, Blocks.log, 3);
		world.setBlockMetadataWithNotify(i + 17, j + 25, k + 9, 3, 2);
		setBlock(world, i + 17, j + 25, k + 10, Blocks.log, 3);
		world.setBlockMetadataWithNotify(i + 17, j + 25, k + 10, 3, 2);
		setBlock(world, i + 17, j + 25, k + 11, Blocks.log, 3);
		world.setBlockMetadataWithNotify(i + 17, j + 25, k + 11, 3, 2);
		setBlock(world, i + 17, j + 26, k + 10, Blocks.log, 3);
		world.setBlockMetadataWithNotify(i + 17, j + 26, k + 10, 3, 2);
		setBlock(world, i + 17, j + 27, k + 12, Blocks.log, 3);
		world.setBlockMetadataWithNotify(i + 17, j + 27, k + 12, 3, 2);
		setBlock(world, i + 17, j + 27, k + 21, Blocks.log, 3);
		world.setBlockMetadataWithNotify(i + 17, j + 27, k + 21, 3, 2);
		setBlock(world, i + 17, j + 27, k + 22, Blocks.log, 3);
		world.setBlockMetadataWithNotify(i + 17, j + 27, k + 22, 3, 2);
		setBlock(world, i + 17, j + 28, k + 4, Blocks.log, 3);
		world.setBlockMetadataWithNotify(i + 17, j + 28, k + 4, 3, 2);
		setBlock(world, i + 17, j + 28, k + 22, Blocks.leaves, 7);
		world.setBlockMetadataWithNotify(i + 17, j + 28, k + 22, 7, 2);
		setBlock(world, i + 17, j + 28, k + 23, Blocks.leaves, 7);
		world.setBlockMetadataWithNotify(i + 17, j + 28, k + 23, 7, 2);
		setBlock(world, i + 17, j + 28, k + 24, Blocks.leaves, 7);
		world.setBlockMetadataWithNotify(i + 17, j + 28, k + 24, 7, 2);
		setBlock(world, i + 17, j + 28, k + 25, Blocks.leaves, 7);
		world.setBlockMetadataWithNotify(i + 17, j + 28, k + 25, 7, 2);
		setBlock(world, i + 17, j + 28, k + 26, Blocks.leaves, 7);
		world.setBlockMetadataWithNotify(i + 17, j + 28, k + 26, 7, 2);
		setBlock(world, i + 17, j + 29, k + 12, Blocks.log, 3);
		world.setBlockMetadataWithNotify(i + 17, j + 29, k + 12, 3, 2);
		setBlock(world, i + 17, j + 29, k + 23, Blocks.leaves, 7);
		world.setBlockMetadataWithNotify(i + 17, j + 29, k + 23, 7, 2);
		setBlock(world, i + 17, j + 29, k + 24, Blocks.log, 3);
		world.setBlockMetadataWithNotify(i + 17, j + 29, k + 24, 3, 2);
		setBlock(world, i + 17, j + 29, k + 25, Blocks.log, 3);
		world.setBlockMetadataWithNotify(i + 17, j + 29, k + 25, 3, 2);
		setBlock(world, i + 17, j + 30, k + 15, Blocks.log, 3);
		world.setBlockMetadataWithNotify(i + 17, j + 30, k + 15, 3, 2);
		setBlock(world, i + 17, j + 30, k + 24, Blocks.leaves, 7);
		world.setBlockMetadataWithNotify(i + 17, j + 30, k + 24, 7, 2);
		setBlock(world, i + 17, j + 30, k + 26, Blocks.leaves, 7);
		world.setBlockMetadataWithNotify(i + 17, j + 30, k + 26, 7, 2);
		setBlock(world, i + 17, j + 30, k + 27, Blocks.leaves, 7);
		world.setBlockMetadataWithNotify(i + 17, j + 30, k + 27, 7, 2);
		setBlock(world, i + 17, j + 30, k + 28, Blocks.leaves, 7);
		world.setBlockMetadataWithNotify(i + 17, j + 30, k + 28, 7, 2);
		setBlock(world, i + 17, j + 30, k + 29, Blocks.leaves, 7);
		world.setBlockMetadataWithNotify(i + 17, j + 30, k + 29, 7, 2);
		setBlock(world, i + 17, j + 30, k + 30, Blocks.leaves, 7);
		world.setBlockMetadataWithNotify(i + 17, j + 30, k + 30, 7, 2);
		setBlock(world, i + 17, j + 31, k + 8, Blocks.log, 3);
		world.setBlockMetadataWithNotify(i + 17, j + 31, k + 8, 3, 2);
		setBlock(world, i + 17, j + 31, k + 27, Blocks.leaves, 7);
		world.setBlockMetadataWithNotify(i + 17, j + 31, k + 27, 7, 2);
		setBlock(world, i + 17, j + 31, k + 28, Blocks.leaves, 7);
		world.setBlockMetadataWithNotify(i + 17, j + 31, k + 28, 7, 2);
		setBlock(world, i + 17, j + 31, k + 29, Blocks.leaves, 7);
		world.setBlockMetadataWithNotify(i + 17, j + 31, k + 29, 7, 2);
		setBlock(world, i + 17, j + 32, k + 28, Blocks.leaves, 7);
		world.setBlockMetadataWithNotify(i + 17, j + 32, k + 28, 7, 2);
		setBlock(world, i + 17, j + 33, k + 6, Blocks.log, 3);
		world.setBlockMetadataWithNotify(i + 17, j + 33, k + 6, 3, 2);
		setBlock(world, i + 17, j + 33, k + 8, Blocks.log, 3);
		world.setBlockMetadataWithNotify(i + 17, j + 33, k + 8, 3, 2);
		setBlock(world, i + 17, j + 34, k + 15, Blocks.log, 3);
		world.setBlockMetadataWithNotify(i + 17, j + 34, k + 15, 3, 2);
		setBlock(world, i + 17, j + 36, k + 21, Blocks.leaves, 7);
		world.setBlockMetadataWithNotify(i + 17, j + 36, k + 21, 7, 2);
		
		generate2(world, rand, i, j, k);
		return true;
		}

	
	public boolean generate2(World world, Random rand, int i, int j, int k)
	{
		setBlock(world, i + 17, j + 36, k + 22, Blocks.leaves, 7);
		world.setBlockMetadataWithNotify(i + 17, j + 36, k + 22, 7, 2);
		setBlock(world, i + 17, j + 36, k + 23, Blocks.log, 3);
		world.setBlockMetadataWithNotify(i + 17, j + 36, k + 23, 3, 2);
		setBlock(world, i + 17, j + 36, k + 24, Blocks.leaves, 7);
		world.setBlockMetadataWithNotify(i + 17, j + 36, k + 24, 7, 2);
		setBlock(world, i + 17, j + 36, k + 25, Blocks.leaves, 7);
		world.setBlockMetadataWithNotify(i + 17, j + 36, k + 25, 7, 2);
		setBlock(world, i + 17, j + 37, k + 2, Blocks.log, 3);
		world.setBlockMetadataWithNotify(i + 17, j + 37, k + 2, 3, 2);
		setBlock(world, i + 17, j + 37, k + 21, Blocks.leaves, 7);
		world.setBlockMetadataWithNotify(i + 17, j + 37, k + 21, 7, 2);
		setBlock(world, i + 17, j + 37, k + 22, Blocks.leaves, 7);
		world.setBlockMetadataWithNotify(i + 17, j + 37, k + 22, 7, 2);
		setBlock(world, i + 17, j + 37, k + 23, Blocks.leaves, 7);
		world.setBlockMetadataWithNotify(i + 17, j + 37, k + 23, 7, 2);
		setBlock(world, i + 17, j + 37, k + 24, Blocks.leaves, 7);
		world.setBlockMetadataWithNotify(i + 17, j + 37, k + 24, 7, 2);
		setBlock(world, i + 17, j + 37, k + 25, Blocks.leaves, 7);
		world.setBlockMetadataWithNotify(i + 17, j + 37, k + 25, 7, 2);
		setBlock(world, i + 17, j + 38, k + 0, Blocks.leaves, 7);
		world.setBlockMetadataWithNotify(i + 17, j + 38, k + 0, 7, 2);
		setBlock(world, i + 17, j + 38, k + 14, Blocks.log, 3);
		world.setBlockMetadataWithNotify(i + 17, j + 38, k + 14, 3, 2);
		setBlock(world, i + 17, j + 38, k + 22, Blocks.leaves, 7);
		world.setBlockMetadataWithNotify(i + 17, j + 38, k + 22, 7, 2);
		setBlock(world, i + 17, j + 38, k + 23, Blocks.leaves, 7);
		world.setBlockMetadataWithNotify(i + 17, j + 38, k + 23, 7, 2);
		setBlock(world, i + 17, j + 38, k + 24, Blocks.leaves, 7);
		world.setBlockMetadataWithNotify(i + 17, j + 38, k + 24, 7, 2);
		setBlock(world, i + 17, j + 39, k + 23, Blocks.leaves, 7);
		world.setBlockMetadataWithNotify(i + 17, j + 39, k + 23, 7, 2);
		setBlock(world, i + 17, j + 41, k + 14, Blocks.leaves, 7);
		world.setBlockMetadataWithNotify(i + 17, j + 41, k + 14, 7, 2);
		setBlock(world, i + 17, j + 41, k + 15, Blocks.leaves, 7);
		world.setBlockMetadataWithNotify(i + 17, j + 41, k + 15, 7, 2);
		setBlock(world, i + 17, j + 41, k + 16, Blocks.leaves, 7);
		world.setBlockMetadataWithNotify(i + 17, j + 41, k + 16, 7, 2);
		setBlock(world, i + 17, j + 42, k + 15, Blocks.leaves, 7);
		world.setBlockMetadataWithNotify(i + 17, j + 42, k + 15, 7, 2);
		setBlock(world, i + 17, j + 45, k + 1, Blocks.log, 3);
		world.setBlockMetadataWithNotify(i + 17, j + 45, k + 1, 3, 2);
		setBlock(world, i + 17, j + 45, k + 17, Blocks.leaves, 7);
		world.setBlockMetadataWithNotify(i + 17, j + 45, k + 17, 7, 2);
		setBlock(world, i + 17, j + 45, k + 18, Blocks.leaves, 7);
		world.setBlockMetadataWithNotify(i + 17, j + 45, k + 18, 7, 2);
		setBlock(world, i + 17, j + 45, k + 19, Blocks.leaves, 7);
		world.setBlockMetadataWithNotify(i + 17, j + 45, k + 19, 7, 2);
		setBlock(world, i + 17, j + 46, k + 0, Blocks.leaves, 7);
		world.setBlockMetadataWithNotify(i + 17, j + 46, k + 0, 7, 2);
		setBlock(world, i + 17, j + 46, k + 1, Blocks.leaves, 7);
		world.setBlockMetadataWithNotify(i + 17, j + 46, k + 1, 7, 2);
		setBlock(world, i + 17, j + 46, k + 2, Blocks.leaves, 7);
		world.setBlockMetadataWithNotify(i + 17, j + 46, k + 2, 7, 2);
		setBlock(world, i + 17, j + 46, k + 18, Blocks.leaves, 7);
		world.setBlockMetadataWithNotify(i + 17, j + 46, k + 18, 7, 2);
		setBlock(world, i + 17, j + 47, k + 0, Blocks.leaves, 7);
		world.setBlockMetadataWithNotify(i + 17, j + 47, k + 0, 7, 2);
		setBlock(world, i + 17, j + 47, k + 1, Blocks.leaves, 7);
		world.setBlockMetadataWithNotify(i + 17, j + 47, k + 1, 7, 2);
		setBlock(world, i + 17, j + 48, k + 0, Blocks.leaves, 7);
		world.setBlockMetadataWithNotify(i + 17, j + 48, k + 0, 7, 2);
		setBlock(world, i + 17, j + 52, k + 6, Blocks.leaves, 7);
		world.setBlockMetadataWithNotify(i + 17, j + 52, k + 6, 7, 2);
		setBlock(world, i + 17, j + 52, k + 7, Blocks.leaves, 7);
		world.setBlockMetadataWithNotify(i + 17, j + 52, k + 7, 7, 2);
