package com.parzivail.pswm.world.gen.wookietree;




import com.parzivail.pswm.utils.LootGenUtils;
import com.parzivail.pswm.utils.NPCType;
import com.parzivail.pswm.utils.SpawnUtils;



import cpw.mods.fml.common.IWorldGenerator;



import java.util.Random;



import net.minecraft.block.Block;

import net.minecraft.init.Blocks;

import net.minecraft.tileentity.TileEntityChest;

import net.minecraft.world.World;

import net.minecraft.world.WorldProvider;

import net.minecraft.world.chunk.IChunkProvider;

import net.minecraft.world.gen.feature.WorldGenerator;


public class WT_23
extends WorldGenerator implements IWorldGenerator

{
	protected Block[] getValidSpawnBlocks()
	
	{
		return new Block[0];
		}

	
	public boolean locationIsValidSpawn(World world, int i, int j, int k)
	
	{
		int distanceToAir = 0;
		Block check = world.getBlock(i, j, k);
		
		while (check != Blocks.air)
		{
			if (distanceToAir > 3) { return false;
			}
			
			distanceToAir++;
			check = world.getBlock(i, j + distanceToAir, k);
			}
		
		j += distanceToAir - 1;
		
		Block block = world.getBlock(i, j, k);
		Block blockAbove = world.getBlock(i, j + 1, k);
		Block blockBelow = world.getBlock(i, j - 1, k);
		
		for (Block x : getValidSpawnBlocks())
		{
			if (blockAbove != Blocks.air) { return false;
			}
			if (block == x) return true;
			if ((block == Blocks.snow) && (blockBelow == x)) { return true;
			}
			}
		
		return false;
		}

	
	
	
	public void generate(Random random, int chunkX, int chunkZ, World world, IChunkProvider chunkGenerator, IChunkProvider chunkProvider)
	{
	}

	
	
	public void setBlock(World world, int x, int y, int z, Block block, int metadata)
	
	{
		world.setBlock(x, y, z, block, metadata, 2);
		}

	
	public boolean generate(World world, Random rand, int i, int j, int k)
	
	{
		k -= 10;
		i -= 10;
		
		setBlock(world, i + 0, j + 0, k + 28, Blocks.spruce_stairs, 0);
		setBlock(world, i + 0, j + 0, k + 29, Blocks.spruce_stairs, 0);
		setBlock(world, i + 0, j + 10, k + 28, Blocks.spruce_stairs, 0);
		setBlock(world, i + 0, j + 10, k + 29, Blocks.spruce_stairs, 0);
		setBlock(world, i + 0, j + 41, k + 0, Blocks.fence, 0);
		setBlock(world, i + 1, j + 1, k + 28, Blocks.spruce_stairs, 0);
		setBlock(world, i + 1, j + 1, k + 29, Blocks.spruce_stairs, 0);
		setBlock(world, i + 1, j + 11, k + 28, Blocks.spruce_stairs, 0);
		setBlock(world, i + 1, j + 11, k + 29, Blocks.spruce_stairs, 0);
		setBlock(world, i + 1, j + 21, k + 22, Blocks.crafting_table, 0);
		setBlock(world, i + 1, j + 21, k + 23, Blocks.spruce_stairs, 0);
		setBlock(world, i + 1, j + 21, k + 24, Blocks.spruce_stairs, 0);
		setBlock(world, i + 1, j + 41, k + 0, Blocks.fence, 0);
		setBlock(world, i + 2, j + 2, k + 28, Blocks.spruce_stairs, 0);
		setBlock(world, i + 2, j + 2, k + 29, Blocks.spruce_stairs, 0);
		SpawnUtils.spawnNPC(NPCType.WOOKIETREE, world, i + 2, j + 21, k + 17);
		setBlock(world, i + 3, j + 12, k + 28, Blocks.spruce_stairs, 0);
		setBlock(world, i + 3, j + 12, k + 29, Blocks.spruce_stairs, 0);
		SpawnUtils.spawnNPC(NPCType.WOOKIETREE, world, i + 3, j + 21, k + 29);
		setBlock(world, i + 4, j + 13, k + 28, Blocks.spruce_stairs, 0);
		setBlock(world, i + 4, j + 13, k + 29, Blocks.spruce_stairs, 0);
		setBlock(world, i + 5, j + 14, k + 28, Blocks.spruce_stairs, 0);
		setBlock(world, i + 5, j + 14, k + 29, Blocks.spruce_stairs, 0);
		setBlock(world, i + 5, j + 21, k + 14, Blocks.spruce_stairs, 0);
		setBlock(world, i + 6, j + 15, k + 28, Blocks.spruce_stairs, 0);
		setBlock(world, i + 6, j + 15, k + 29, Blocks.spruce_stairs, 0);
		setBlock(world, i + 7, j + 21, k + 15, Blocks.fence, 0);
		setBlock(world, i + 7, j + 21, k + 16, Blocks.fence, 0);
		setBlock(world, i + 7, j + 21, k + 17, Blocks.fence, 0);
		SpawnUtils.spawnNPC(NPCType.WOOKIETREE, world, i + 7, j + 21, k + 23);
		setBlock(world, i + 7, j + 21, k + 30, Blocks.fence, 0);
		setBlock(world, i + 7, j + 21, k + 31, Blocks.fence, 0);
		setBlock(world, i + 7, j + 24, k + 12, Blocks.fence, 0);
		setBlock(world, i + 7, j + 24, k + 13, Blocks.fence, 0);
		setBlock(world, i + 8, j + 21, k + 17, Blocks.fence, 0);
		setBlock(world, i + 8, j + 21, k + 18, Blocks.fence, 0);
		setBlock(world, i + 8, j + 21, k + 19, Blocks.fence, 0);
		setBlock(world, i + 8, j + 21, k + 20, Blocks.spruce_stairs, 0);
		setBlock(world, i + 8, j + 21, k + 27, Blocks.spruce_stairs, 0);
		setBlock(world, i + 8, j + 21, k + 28, Blocks.fence, 0);
		setBlock(world, i + 8, j + 21, k + 29, Blocks.fence, 0);
		setBlock(world, i + 8, j + 21, k + 30, Blocks.fence, 0);
		setBlock(world, i + 8, j + 24, k + 13, Blocks.fence, 0);
		setBlock(world, i + 8, j + 24, k + 14, Blocks.fence, 0);
		setBlock(world, i + 9, j + 24, k + 14, Blocks.fence, 0);
		setBlock(world, i + 9, j + 24, k + 15, Blocks.fence, 0);
		setBlock(world, i + 9, j + 24, k + 16, Blocks.fence, 0);
		setBlock(world, i + 9, j + 24, k + 31, Blocks.fence, 0);
		setBlock(world, i + 10, j + 24, k + 16, Blocks.fence, 0);
		setBlock(world, i + 10, j + 24, k + 17, Blocks.fence, 0);
		setBlock(world, i + 10, j + 24, k + 18, Blocks.fence, 0);
		setBlock(world, i + 10, j + 24, k + 19, Blocks.fence, 0);
		setBlock(world, i + 10, j + 24, k + 28, Blocks.fence, 0);
		setBlock(world, i + 10, j + 24, k + 29, Blocks.fence, 0);
		setBlock(world, i + 10, j + 24, k + 30, Blocks.fence, 0);
		setBlock(world, i + 10, j + 24, k + 31, Blocks.fence, 0);
		setBlock(world, i + 11, j + 24, k + 19, Blocks.fence, 0);
		setBlock(world, i + 11, j + 24, k + 28, Blocks.fence, 0);
		setBlock(world, i + 18, j + 55, k + 25, Blocks.fence, 0);
		setBlock(world, i + 18, j + 55, k + 31, Blocks.fence, 0);
		setBlock(world, i + 19, j + 55, k + 25, Blocks.fence, 0);
		setBlock(world, i + 19, j + 55, k + 31, Blocks.fence, 0);
		setBlock(world, i + 21, j + 53, k + 24, Blocks.fence, 0);
		setBlock(world, i + 21, j + 53, k + 25, Blocks.fence, 0);
		setBlock(world, i + 21, j + 53, k + 31, Blocks.fence, 0);
		setBlock(world, i + 22, j + 53, k + 23, Blocks.fence, 0);
		setBlock(world, i + 22, j + 53, k + 24, Blocks.fence, 0);
		setBlock(world, i + 23, j + 53, k + 22, Blocks.spruce_stairs, 0);
		setBlock(world, i + 23, j + 53, k + 23, Blocks.fence, 0);
		setBlock(world, i + 23, j + 55, k + 20, Blocks.fence, 0);
		setBlock(world, i + 23, j + 55, k + 21, Blocks.fence, 0);
		SpawnUtils.spawnNPC(NPCType.WOOKIETREE, world, i + 24, j + 53, k + 26);
		SpawnUtils.spawnNPC(NPCType.WOOKIETREE, world, i + 24, j + 53, k + 30);
		setBlock(world, i + 25, j + 53, k + 27, Blocks.crafting_table, 0);
		setBlock(world, i + 25, j + 53, k + 28, Blocks.spruce_stairs, 0);
		SpawnUtils.spawnNPC(NPCType.WOOKIETREE, world, i + 28, j + 53, k + 26);
		SpawnUtils.spawnNPC(NPCType.WOOKIETREE, world, i + 28, j + 53, k + 30);
		setBlock(world, i + 29, j + 53, k + 23, Blocks.fence, 0);
		setBlock(world, i + 29, j + 55, k + 20, Blocks.fence, 0);
		setBlock(world, i + 29, j + 55, k + 21, Blocks.fence, 0);
		setBlock(world, i + 30, j + 53, k + 23, Blocks.fence, 0);
		setBlock(world, i + 30, j + 53, k + 24, Blocks.fence, 0);
		setBlock(world, i + 31, j + 53, k + 24, Blocks.fence, 0);
		setBlock(world, i + 31, j + 53, k + 25, Blocks.fence, 0);
		setBlock(world, i + 31, j + 53, k + 26, Blocks.spruce_stairs, 0);
		setBlock(world, i + 31, j + 53, k + 30, Blocks.spruce_stairs, 0);
		setBlock(world, i + 31, j + 53, k + 31, Blocks.fence, 0);
		setBlock(world, i + 33, j + 55, k + 25, Blocks.fence, 0);
		setBlock(world, i + 33, j + 55, k + 31, Blocks.fence, 0);
		setBlock(world, i + 34, j + 55, k + 25, Blocks.fence, 0);
		setBlock(world, i + 34, j + 55, k + 31, Blocks.fence, 0);
		setBlock(world, i + 0, j + 0, k + 26, Blocks.log, 1);
		world.setBlockMetadataWithNotify(i + 0, j + 0, k + 26, 1, 2);
		setBlock(world, i + 0, j + 0, k + 27, Blocks.log, 1);
		world.setBlockMetadataWithNotify(i + 0, j + 0, k + 27, 1, 2);
		setBlock(world, i + 0, j + 1, k + 25, Blocks.log, 1);
		world.setBlockMetadataWithNotify(i + 0, j + 1, k + 25, 1, 2);
		setBlock(world, i + 0, j + 1, k + 26, Blocks.log, 1);
		world.setBlockMetadataWithNotify(i + 0, j + 1, k + 26, 1, 2);
		setBlock(world, i + 0, j + 1, k + 27, Blocks.log, 1);
		world.setBlockMetadataWithNotify(i + 0, j + 1, k + 27, 1, 2);
		setBlock(world, i + 0, j + 2, k + 25, Blocks.log, 1);
		world.setBlockMetadataWithNotify(i + 0, j + 2, k + 25, 1, 2);
		setBlock(world, i + 0, j + 2, k + 27, Blocks.log, 1);
		world.setBlockMetadataWithNotify(i + 0, j + 2, k + 27, 1, 2);
		setBlock(world, i + 0, j + 3, k + 26, Blocks.log, 1);
		world.setBlockMetadataWithNotify(i + 0, j + 3, k + 26, 1, 2);
		setBlock(world, i + 0, j + 3, k + 27, Blocks.log, 1);
		world.setBlockMetadataWithNotify(i + 0, j + 3, k + 27, 1, 2);
		setBlock(world, i + 0, j + 4, k + 26, Blocks.log, 1);
		world.setBlockMetadataWithNotify(i + 0, j + 4, k + 26, 1, 2);
		setBlock(world, i + 0, j + 5, k + 25, Blocks.log, 1);
		world.setBlockMetadataWithNotify(i + 0, j + 5, k + 25, 1, 2);
		setBlock(world, i + 0, j + 5, k + 26, Blocks.log, 1);
		world.setBlockMetadataWithNotify(i + 0, j + 5, k + 26, 1, 2);
		setBlock(world, i + 0, j + 6, k + 23, Blocks.planks, 5);
		world.setBlockMetadataWithNotify(i + 0, j + 6, k + 23, 5, 2);
		setBlock(world, i + 0, j + 6, k + 24, Blocks.planks, 5);
		world.setBlockMetadataWithNotify(i + 0, j + 6, k + 24, 5, 2);
		setBlock(world, i + 0, j + 6, k + 25, Blocks.log, 1);
		world.setBlockMetadataWithNotify(i + 0, j + 6, k + 25, 1, 2);
		setBlock(world, i + 0, j + 6, k + 26, Blocks.log, 1);
		world.setBlockMetadataWithNotify(i + 0, j + 6, k + 26, 1, 2);
		setBlock(world, i + 0, j + 7, k + 23, Blocks.planks, 5);
		world.setBlockMetadataWithNotify(i + 0, j + 7, k + 23, 5, 2);
		setBlock(world, i + 0, j + 7, k + 24, Blocks.planks, 5);
		world.setBlockMetadataWithNotify(i + 0, j + 7, k + 24, 5, 2);
		setBlock(world, i + 0, j + 7, k + 25, Blocks.log, 1);
		world.setBlockMetadataWithNotify(i + 0, j + 7, k + 25, 1, 2);
		setBlock(world, i + 0, j + 7, k + 26, Blocks.log, 1);
		world.setBlockMetadataWithNotify(i + 0, j + 7, k + 26, 1, 2);
		setBlock(world, i + 0, j + 7, k + 27, Blocks.log, 1);
		world.setBlockMetadataWithNotify(i + 0, j + 7, k + 27, 1, 2);
		setBlock(world, i + 0, j + 8, k + 25, Blocks.log, 1);
		world.setBlockMetadataWithNotify(i + 0, j + 8, k + 25, 1, 2);
		setBlock(world, i + 0, j + 8, k + 26, Blocks.log, 1);
		world.setBlockMetadataWithNotify(i + 0, j + 8, k + 26, 1, 2);
		setBlock(world, i + 0, j + 8, k + 27, Blocks.log, 1);
		world.setBlockMetadataWithNotify(i + 0, j + 8, k + 27, 1, 2);
		setBlock(world, i + 0, j + 9, k + 25, Blocks.log, 1);
		world.setBlockMetadataWithNotify(i + 0, j + 9, k + 25, 1, 2);
		setBlock(world, i + 0, j + 9, k + 26, Blocks.log, 1);
		world.setBlockMetadataWithNotify(i + 0, j + 9, k + 26, 1, 2);
		setBlock(world, i + 0, j + 9, k + 27, Blocks.log, 1);
		world.setBlockMetadataWithNotify(i + 0, j + 9, k + 27, 1, 2);
		setBlock(world, i + 0, j + 9, k + 28, Blocks.planks, 5);
		world.setBlockMetadataWithNotify(i + 0, j + 9, k + 28, 5, 2);
		setBlock(world, i + 0, j + 9, k + 29, Blocks.planks, 5);
		world.setBlockMetadataWithNotify(i + 0, j + 9, k + 29, 5, 2);
		setBlock(world, i + 0, j + 10, k + 24, Blocks.torch, 4);
		world.setBlockMetadataWithNotify(i + 0, j + 10, k + 24, 4, 2);
		setBlock(world, i + 0, j + 10, k + 25, Blocks.log, 1);
		world.setBlockMetadataWithNotify(i + 0, j + 10, k + 25, 1, 2);
		setBlock(world, i + 0, j + 10, k + 26, Blocks.log, 1);
		world.setBlockMetadataWithNotify(i + 0, j + 10, k + 26, 1, 2);
		setBlock(world, i + 0, j + 10, k + 27, Blocks.log, 1);
		world.setBlockMetadataWithNotify(i + 0, j + 10, k + 27, 1, 2);
		setBlock(world, i + 0, j + 11, k + 26, Blocks.log, 1);
		world.setBlockMetadataWithNotify(i + 0, j + 11, k + 26, 1, 2);
		setBlock(world, i + 0, j + 11, k + 27, Blocks.log, 1);
		world.setBlockMetadataWithNotify(i + 0, j + 11, k + 27, 1, 2);
		setBlock(world, i + 0, j + 12, k + 25, Blocks.log, 1);
		world.setBlockMetadataWithNotify(i + 0, j + 12, k + 25, 1, 2);
		setBlock(world, i + 0, j + 12, k + 26, Blocks.log, 1);
		world.setBlockMetadataWithNotify(i + 0, j + 12, k + 26, 1, 2);
		setBlock(world, i + 0, j + 12, k + 27, Blocks.log, 1);
		world.setBlockMetadataWithNotify(i + 0, j + 12, k + 27, 1, 2);
		setBlock(world, i + 0, j + 13, k + 20, Blocks.vine, 8);
		world.setBlockMetadataWithNotify(i + 0, j + 13, k + 20, 8, 2);
		setBlock(world, i + 0, j + 13, k + 21, Blocks.vine, 15);
		world.setBlockMetadataWithNotify(i + 0, j + 13, k + 21, 15, 2);
		setBlock(world, i + 0, j + 13, k + 22, Blocks.vine, 15);
		world.setBlockMetadataWithNotify(i + 0, j + 13, k + 22, 15, 2);
		setBlock(world, i + 0, j + 13, k + 25, Blocks.log, 1);
		world.setBlockMetadataWithNotify(i + 0, j + 13, k + 25, 1, 2);
		setBlock(world, i + 0, j + 13, k + 26, Blocks.log, 1);
		world.setBlockMetadataWithNotify(i + 0, j + 13, k + 26, 1, 2);
		setBlock(world, i + 0, j + 14, k + 20, Blocks.vine, 15);
		world.setBlockMetadataWithNotify(i + 0, j + 14, k + 20, 15, 2);
		setBlock(world, i + 0, j + 14, k + 21, Blocks.vine, 15);
		world.setBlockMetadataWithNotify(i + 0, j + 14, k + 21, 15, 2);
		setBlock(world, i + 0, j + 14, k + 22, Blocks.vine, 15);
		world.setBlockMetadataWithNotify(i + 0, j + 14, k + 22, 15, 2);
		setBlock(world, i + 0, j + 14, k + 25, Blocks.log, 1);
		world.setBlockMetadataWithNotify(i + 0, j + 14, k + 25, 1, 2);
		setBlock(world, i + 0, j + 15, k + 20, Blocks.vine, 15);
		world.setBlockMetadataWithNotify(i + 0, j + 15, k + 20, 15, 2);
		setBlock(world, i + 0, j + 15, k + 21, Blocks.log, 1);
		world.setBlockMetadataWithNotify(i + 0, j + 15, k + 21, 1, 2);
		setBlock(world, i + 0, j + 15, k + 22, Blocks.log, 1);
		world.setBlockMetadataWithNotify(i + 0, j + 15, k + 22, 1, 2);
		setBlock(world, i + 0, j + 15, k + 23, Blocks.log, 1);
		world.setBlockMetadataWithNotify(i + 0, j + 15, k + 23, 1, 2);
		setBlock(world, i + 0, j + 15, k + 24, Blocks.log, 1);
		world.setBlockMetadataWithNotify(i + 0, j + 15, k + 24, 1, 2);
		setBlock(world, i + 0, j + 15, k + 25, Blocks.log, 1);
		world.setBlockMetadataWithNotify(i + 0, j + 15, k + 25, 1, 2);
		setBlock(world, i + 0, j + 15, k + 26, Blocks.log, 1);
		world.setBlockMetadataWithNotify(i + 0, j + 15, k + 26, 1, 2);
		setBlock(world, i + 0, j + 15, k + 27, Blocks.log, 1);
		world.setBlockMetadataWithNotify(i + 0, j + 15, k + 27, 1, 2);
		setBlock(world, i + 0, j + 16, k + 19, Blocks.log, 1);
		world.setBlockMetadataWithNotify(i + 0, j + 16, k + 19, 1, 2);
		setBlock(world, i + 0, j + 16, k + 20, Blocks.log, 1);
		world.setBlockMetadataWithNotify(i + 0, j + 16, k + 20, 1, 2);
		setBlock(world, i + 0, j + 16, k + 21, Blocks.log, 1);
		world.setBlockMetadataWithNotify(i + 0, j + 16, k + 21, 1, 2);
		setBlock(world, i + 0, j + 16, k + 22, Blocks.log, 1);
		world.setBlockMetadataWithNotify(i + 0, j + 16, k + 22, 1, 2);
		setBlock(world, i + 0, j + 16, k + 23, Blocks.log, 1);
		world.setBlockMetadataWithNotify(i + 0, j + 16, k + 23, 1, 2);
		setBlock(world, i + 0, j + 16, k + 24, Blocks.log, 1);
		world.setBlockMetadataWithNotify(i + 0, j + 16, k + 24, 1, 2);
		setBlock(world, i + 0, j + 16, k + 25, Blocks.log, 1);
		world.setBlockMetadataWithNotify(i + 0, j + 16, k + 25, 1, 2);
		setBlock(world, i + 0, j + 16, k + 26, Blocks.log, 1);
		world.setBlockMetadataWithNotify(i + 0, j + 16, k + 26, 1, 2);
		setBlock(world, i + 0, j + 16, k + 27, Blocks.log, 1);
		world.setBlockMetadataWithNotify(i + 0, j + 16, k + 27, 1, 2);
		setBlock(world, i + 0, j + 16, k + 28, Blocks.log, 1);
		world.setBlockMetadataWithNotify(i + 0, j + 16, k + 28, 1, 2);
		setBlock(world, i + 0, j + 17, k + 14, Blocks.log, 1);
		world.setBlockMetadataWithNotify(i + 0, j + 17, k + 14, 1, 2);
		setBlock(world, i + 0, j + 17, k + 15, Blocks.log, 1);
		world.setBlockMetadataWithNotify(i + 0, j + 17, k + 15, 1, 2);
		setBlock(world, i + 0, j + 17, k + 16, Blocks.log, 1);
		world.setBlockMetadataWithNotify(i + 0, j + 17, k + 16, 1, 2);
		setBlock(world, i + 0, j + 17, k + 17, Blocks.log, 1);
		world.setBlockMetadataWithNotify(i + 0, j + 17, k + 17, 1, 2);
		setBlock(world, i + 0, j + 17, k + 18, Blocks.log, 1);
		world.setBlockMetadataWithNotify(i + 0, j + 17, k + 18, 1, 2);
		setBlock(world, i + 0, j + 17, k + 19, Blocks.log, 1);
		world.setBlockMetadataWithNotify(i + 0, j + 17, k + 19, 1, 2);
		setBlock(world, i + 0, j + 17, k + 21, Blocks.log, 1);
		world.setBlockMetadataWithNotify(i + 0, j + 17, k + 21, 1, 2);
		setBlock(world, i + 0, j + 17, k + 22, Blocks.log, 1);
		world.setBlockMetadataWithNotify(i + 0, j + 17, k + 22, 1, 2);
		setBlock(world, i + 0, j + 17, k + 23, Blocks.log, 1);
		world.setBlockMetadataWithNotify(i + 0, j + 17, k + 23, 1, 2);
		setBlock(world, i + 0, j + 17, k + 24, Blocks.log, 1);
		world.setBlockMetadataWithNotify(i + 0, j + 17, k + 24, 1, 2);
		setBlock(world, i + 0, j + 17, k + 25, Blocks.log, 1);
		world.setBlockMetadataWithNotify(i + 0, j + 17, k + 25, 1, 2);
		setBlock(world, i + 0, j + 17, k + 26, Blocks.log, 1);
		world.setBlockMetadataWithNotify(i + 0, j + 17, k + 26, 1, 2);
		setBlock(world, i + 0, j + 17, k + 27, Blocks.log, 1);
		world.setBlockMetadataWithNotify(i + 0, j + 17, k + 27, 1, 2);
		setBlock(world, i + 0, j + 17, k + 28, Blocks.log, 1);
		world.setBlockMetadataWithNotify(i + 0, j + 17, k + 28, 1, 2);
		setBlock(world, i + 0, j + 17, k + 29, Blocks.log, 1);
		world.setBlockMetadataWithNotify(i + 0, j + 17, k + 29, 1, 2);
		setBlock(world, i + 0, j + 17, k + 30, Blocks.log, 1);
		world.setBlockMetadataWithNotify(i + 0, j + 17, k + 30, 1, 2);
		setBlock(world, i + 0, j + 18, k + 13, Blocks.log, 1);
		world.setBlockMetadataWithNotify(i + 0, j + 18, k + 13, 1, 2);
		setBlock(world, i + 0, j + 18, k + 14, Blocks.log, 1);
		world.setBlockMetadataWithNotify(i + 0, j + 18, k + 14, 1, 2);
		setBlock(world, i + 0, j + 18, k + 15, Blocks.log, 1);
		world.setBlockMetadataWithNotify(i + 0, j + 18, k + 15, 1, 2);
		setBlock(world, i + 0, j + 18, k + 16, Blocks.log, 1);
		world.setBlockMetadataWithNotify(i + 0, j + 18, k + 16, 1, 2);
		setBlock(world, i + 0, j + 18, k + 17, Blocks.log, 1);
		world.setBlockMetadataWithNotify(i + 0, j + 18, k + 17, 1, 2);
		setBlock(world, i + 0, j + 18, k + 18, Blocks.log, 1);
		world.setBlockMetadataWithNotify(i + 0, j + 18, k + 18, 1, 2);
		setBlock(world, i + 0, j + 18, k + 19, Blocks.log, 1);
		world.setBlockMetadataWithNotify(i + 0, j + 18, k + 19, 1, 2);
		setBlock(world, i + 0, j + 18, k + 20, Blocks.log, 1);
		world.setBlockMetadataWithNotify(i + 0, j + 18, k + 20, 1, 2);
		setBlock(world, i + 0, j + 18, k + 21, Blocks.log, 1);
		world.setBlockMetadataWithNotify(i + 0, j + 18, k + 21, 1, 2);
		setBlock(world, i + 0, j + 18, k + 22, Blocks.log, 1);
		world.setBlockMetadataWithNotify(i + 0, j + 18, k + 22, 1, 2);
		setBlock(world, i + 0, j + 18, k + 23, Blocks.log, 1);
		world.setBlockMetadataWithNotify(i + 0, j + 18, k + 23, 1, 2);
		setBlock(world, i + 0, j + 18, k + 24, Blocks.log, 1);
		world.setBlockMetadataWithNotify(i + 0, j + 18, k + 24, 1, 2);
		setBlock(world, i + 0, j + 18, k + 25, Blocks.log, 1);
		world.setBlockMetadataWithNotify(i + 0, j + 18, k + 25, 1, 2);
		setBlock(world, i + 0, j + 18, k + 26, Blocks.log, 1);
		world.setBlockMetadataWithNotify(i + 0, j + 18, k + 26, 1, 2);
		setBlock(world, i + 0, j + 18, k + 27, Blocks.log, 1);
		world.setBlockMetadataWithNotify(i + 0, j + 18, k + 27, 1, 2);
		setBlock(world, i + 0, j + 18, k + 28, Blocks.log, 1);
		world.setBlockMetadataWithNotify(i + 0, j + 18, k + 28, 1, 2);
		setBlock(world, i + 0, j + 18, k + 29, Blocks.log, 1);
		world.setBlockMetadataWithNotify(i + 0, j + 18, k + 29, 1, 2);
		setBlock(world, i + 0, j + 18, k + 30, Blocks.log, 1);
		world.setBlockMetadataWithNotify(i + 0, j + 18, k + 30, 1, 2);
		setBlock(world, i + 0, j + 19, k + 14, Blocks.log, 1);
		world.setBlockMetadataWithNotify(i + 0, j + 19, k + 14, 1, 2);
		setBlock(world, i + 0, j + 19, k + 15, Blocks.log, 1);
		world.setBlockMetadataWithNotify(i + 0, j + 19, k + 15, 1, 2);
		setBlock(world, i + 0, j + 19, k + 16, Blocks.log, 1);
		world.setBlockMetadataWithNotify(i + 0, j + 19, k + 16, 1, 2);
		setBlock(world, i + 0, j + 19, k + 17, Blocks.log, 1);
		world.setBlockMetadataWithNotify(i + 0, j + 19, k + 17, 1, 2);
		setBlock(world, i + 0, j + 19, k + 18, Blocks.log, 1);
		world.setBlockMetadataWithNotify(i + 0, j + 19, k + 18, 1, 2);
		setBlock(world, i + 0, j + 19, k + 19, Blocks.log, 1);
		world.setBlockMetadataWithNotify(i + 0, j + 19, k + 19, 1, 2);
		setBlock(world, i + 0, j + 19, k + 20, Blocks.log, 1);
		world.setBlockMetadataWithNotify(i + 0, j + 19, k + 20, 1, 2);
		setBlock(world, i + 0, j + 19, k + 21, Blocks.log, 1);
		world.setBlockMetadataWithNotify(i + 0, j + 19, k + 21, 1, 2);
		setBlock(world, i + 0, j + 19, k + 22, Blocks.log, 1);
		world.setBlockMetadataWithNotify(i + 0, j + 19, k + 22, 1, 2);
		setBlock(world, i + 0, j + 19, k + 23, Blocks.log, 1);
		world.setBlockMetadataWithNotify(i + 0, j + 19, k + 23, 1, 2);
		setBlock(world, i + 0, j + 19, k + 24, Blocks.log, 1);
		world.setBlockMetadataWithNotify(i + 0, j + 19, k + 24, 1, 2);
		setBlock(world, i + 0, j + 19, k + 25, Blocks.log, 1);
		world.setBlockMetadataWithNotify(i + 0, j + 19, k + 25, 1, 2);
		setBlock(world, i + 0, j + 19, k + 26, Blocks.log, 1);
		world.setBlockMetadataWithNotify(i + 0, j + 19, k + 26, 1, 2);
		setBlock(world, i + 0, j + 19, k + 27, Blocks.log, 1);
		world.setBlockMetadataWithNotify(i + 0, j + 19, k + 27, 1, 2);
		setBlock(world, i + 0, j + 19, k + 28, Blocks.log, 1);
		world.setBlockMetadataWithNotify(i + 0, j + 19, k + 28, 1, 2);
		setBlock(world, i + 0, j + 19, k + 29, Blocks.log, 1);
		world.setBlockMetadataWithNotify(i + 0, j + 19, k + 29, 1, 2);
		setBlock(world, i + 0, j + 19, k + 30, Blocks.log, 1);
		world.setBlockMetadataWithNotify(i + 0, j + 19, k + 30, 1, 2);
		setBlock(world, i + 0, j + 20, k + 13, Blocks.log, 1);
		world.setBlockMetadataWithNotify(i + 0, j + 20, k + 13, 1, 2);
		setBlock(world, i + 0, j + 20, k + 14, Blocks.log, 1);
		world.setBlockMetadataWithNotify(i + 0, j + 20, k + 14, 1, 2);
		setBlock(world, i + 0, j + 20, k + 15, Blocks.log, 1);
		world.setBlockMetadataWithNotify(i + 0, j + 20, k + 15, 1, 2);
		setBlock(world, i + 0, j + 20, k + 16, Blocks.log, 1);
		world.setBlockMetadataWithNotify(i + 0, j + 20, k + 16, 1, 2);
		setBlock(world, i + 0, j + 20, k + 17, Blocks.log, 1);
		world.setBlockMetadataWithNotify(i + 0, j + 20, k + 17, 1, 2);
		setBlock(world, i + 0, j + 20, k + 18, Blocks.log, 1);
		world.setBlockMetadataWithNotify(i + 0, j + 20, k + 18, 1, 2);
		setBlock(world, i + 0, j + 20, k + 19, Blocks.planks, 5);
		world.setBlockMetadataWithNotify(i + 0, j + 20, k + 19, 5, 2);
		setBlock(world, i + 0, j + 20, k + 20, Blocks.log, 1);
		world.setBlockMetadataWithNotify(i + 0, j + 20, k + 20, 1, 2);
		setBlock(world, i + 0, j + 20, k + 21, Blocks.log, 1);
		world.setBlockMetadataWithNotify(i + 0, j + 20, k + 21, 1, 2);
		setBlock(world, i + 0, j + 20, k + 22, Blocks.planks, 5);
		world.setBlockMetadataWithNotify(i + 0, j + 20, k + 22, 5, 2);
		setBlock(world, i + 0, j + 20, k + 23, Blocks.planks, 5);
		world.setBlockMetadataWithNotify(i + 0, j + 20, k + 23, 5, 2);
		setBlock(world, i + 0, j + 20, k + 24, Blocks.planks, 5);
		world.setBlockMetadataWithNotify(i + 0, j + 20, k + 24, 5, 2);
		setBlock(world, i + 0, j + 20, k + 25, Blocks.planks, 5);
		world.setBlockMetadataWithNotify(i + 0, j + 20, k + 25, 5, 2);
		setBlock(world, i + 0, j + 20, k + 26, Blocks.log, 1);
		world.setBlockMetadataWithNotify(i + 0, j + 20, k + 26, 1, 2);
		setBlock(world, i + 0, j + 20, k + 27, Blocks.log, 1);
		world.setBlockMetadataWithNotify(i + 0, j + 20, k + 27, 1, 2);
		setBlock(world, i + 0, j + 20, k + 28, Blocks.planks, 5);
		world.setBlockMetadataWithNotify(i + 0, j + 20, k + 28, 5, 2);
		setBlock(world, i + 0, j + 20, k + 29, Blocks.log, 1);
		world.setBlockMetadataWithNotify(i + 0, j + 20, k + 29, 1, 2);
		setBlock(world, i + 0, j + 20, k + 30, Blocks.log, 1);
		world.setBlockMetadataWithNotify(i + 0, j + 20, k + 30, 1, 2);
		setBlock(world, i + 0, j + 20, k + 31, Blocks.log, 1);
		world.setBlockMetadataWithNotify(i + 0, j + 20, k + 31, 1, 2);
		setBlock(world, i + 0, j + 21, k + 14, Blocks.spruce_stairs, 1);
		world.setBlockMetadataWithNotify(i + 0, j + 21, k + 14, 1, 2);
		setBlock(world, i + 0, j + 23, k + 13, Blocks.torch, 1);
		world.setBlockMetadataWithNotify(i + 0, j + 23, k + 13, 1, 2);
		setBlock(world, i + 0, j + 24, k + 12, Blocks.spruce_stairs, 5);
		world.setBlockMetadataWithNotify(i + 0, j + 24, k + 12, 5, 2);
		setBlock(world, i + 0, j + 25, k + 11, Blocks.log, 1);
		world.setBlockMetadataWithNotify(i + 0, j + 25, k + 11, 1, 2);
		setBlock(world, i + 0, j + 25, k + 12, Blocks.log, 1);
		world.setBlockMetadataWithNotify(i + 0, j + 25, k + 12, 1, 2);
		setBlock(world, i + 0, j + 25, k + 13, Blocks.log, 1);
		world.setBlockMetadataWithNotify(i + 0, j + 25, k + 13, 1, 2);
		setBlock(world, i + 0, j + 25, k + 14, Blocks.log, 1);
		world.setBlockMetadataWithNotify(i + 0, j + 25, k + 14, 1, 2);
		setBlock(world, i + 0, j + 25, k + 15, Blocks.log, 1);
		world.setBlockMetadataWithNotify(i + 0, j + 25, k + 15, 1, 2);
		setBlock(world, i + 0, j + 25, k + 16, Blocks.log, 1);
		world.setBlockMetadataWithNotify(i + 0, j + 25, k + 16, 1, 2);
		setBlock(world, i + 0, j + 25, k + 17, Blocks.torch, 3);
		world.setBlockMetadataWithNotify(i + 0, j + 25, k + 17, 3, 2);
		setBlock(world, i + 0, j + 25, k + 30, Blocks.torch, 4);
		world.setBlockMetadataWithNotify(i + 0, j + 25, k + 30, 4, 2);
		setBlock(world, i + 0, j + 25, k + 31, Blocks.log, 1);
		world.setBlockMetadataWithNotify(i + 0, j + 25, k + 31, 1, 2);
		setBlock(world, i + 0, j + 26, k + 12, Blocks.log, 1);
		world.setBlockMetadataWithNotify(i + 0, j + 26, k + 12, 1, 2);
		setBlock(world, i + 0, j + 26, k + 13, Blocks.log, 1);
		world.setBlockMetadataWithNotify(i + 0, j + 26, k + 13, 1, 2);
		setBlock(world, i + 0, j + 26, k + 14, Blocks.log, 1);
		world.setBlockMetadataWithNotify(i + 0, j + 26, k + 14, 1, 2);
		setBlock(world, i + 0, j + 26, k + 15, Blocks.log, 1);
		world.setBlockMetadataWithNotify(i + 0, j + 26, k + 15, 1, 2);
		setBlock(world, i + 0, j + 26, k + 16, Blocks.log, 1);
		world.setBlockMetadataWithNotify(i + 0, j + 26, k + 16, 1, 2);
		setBlock(world, i + 0, j + 26, k + 17, Blocks.log, 1);
		world.setBlockMetadataWithNotify(i + 0, j + 26, k + 17, 1, 2);
		setBlock(world, i + 0, j + 26, k + 30, Blocks.log, 1);
		world.setBlockMetadataWithNotify(i + 0, j + 26, k + 30, 1, 2);
		setBlock(world, i + 0, j + 26, k + 31, Blocks.log, 1);
		world.setBlockMetadataWithNotify(i + 0, j + 26, k + 31, 1, 2);
		setBlock(world, i + 0, j + 27, k + 14, Blocks.log, 1);
		world.setBlockMetadataWithNotify(i + 0, j + 27, k + 14, 1, 2);
		setBlock(world, i + 0, j + 27, k + 15, Blocks.log, 1);
		world.setBlockMetadataWithNotify(i + 0, j + 27, k + 15, 1, 2);
		setBlock(world, i + 0, j + 27, k + 16, Blocks.log, 1);
		world.setBlockMetadataWithNotify(i + 0, j + 27, k + 16, 1, 2);
		setBlock(world, i + 0, j + 27, k + 17, Blocks.log, 1);
		world.setBlockMetadataWithNotify(i + 0, j + 27, k + 17, 1, 2);
		setBlock(world, i + 0, j + 27, k + 18, Blocks.log, 1);
		world.setBlockMetadataWithNotify(i + 0, j + 27, k + 18, 1, 2);
		setBlock(world, i + 0, j + 27, k + 19, Blocks.torch, 3);
		world.setBlockMetadataWithNotify(i + 0, j + 27, k + 19, 3, 2);
		setBlock(world, i + 0, j + 27, k + 22, Blocks.torch, 2);
		world.setBlockMetadataWithNotify(i + 0, j + 27, k + 22, 2, 2);
		setBlock(world, i + 0, j + 27, k + 25, Blocks.torch, 2);
		world.setBlockMetadataWithNotify(i + 0, j + 27, k + 25, 2, 2);
		setBlock(world, i + 0, j + 27, k + 28, Blocks.torch, 4);
		world.setBlockMetadataWithNotify(i + 0, j + 27, k + 28, 4, 2);
		setBlock(world, i + 0, j + 27, k + 29, Blocks.log, 1);
		world.setBlockMetadataWithNotify(i + 0, j + 27, k + 29, 1, 2);
		setBlock(world, i + 0, j + 27, k + 30, Blocks.log, 1);
		world.setBlockMetadataWithNotify(i + 0, j + 27, k + 30, 1, 2);
		setBlock(world, i + 0, j + 27, k + 31, Blocks.log, 1);
		world.setBlockMetadataWithNotify(i + 0, j + 27, k + 31, 1, 2);
		setBlock(world, i + 0, j + 28, k + 18, Blocks.log, 1);
		world.setBlockMetadataWithNotify(i + 0, j + 28, k + 18, 1, 2);
		setBlock(world, i + 0, j + 28, k + 19, Blocks.log, 1);
		world.setBlockMetadataWithNotify(i + 0, j + 28, k + 19, 1, 2);
		setBlock(world, i + 0, j + 28, k + 20, Blocks.log, 1);
		world.setBlockMetadataWithNotify(i + 0, j + 28, k + 20, 1, 2);
		setBlock(world, i + 0, j + 28, k + 21, Blocks.log, 1);
		world.setBlockMetadataWithNotify(i + 0, j + 28, k + 21, 1, 2);
		setBlock(world, i + 0, j + 28, k + 22, Blocks.log, 1);
		world.setBlockMetadataWithNotify(i + 0, j + 28, k + 22, 1, 2);
		setBlock(world, i + 0, j + 28, k + 23, Blocks.log, 1);
		world.setBlockMetadataWithNotify(i + 0, j + 28, k + 23, 1, 2);
		setBlock(world, i + 0, j + 28, k + 24, Blocks.log, 1);
		world.setBlockMetadataWithNotify(i + 0, j + 28, k + 24, 1, 2);
		setBlock(world, i + 0, j + 28, k + 25, Blocks.log, 1);
		world.setBlockMetadataWithNotify(i + 0, j + 28, k + 25, 1, 2);
		setBlock(world, i + 0, j + 28, k + 26, Blocks.log, 1);
		world.setBlockMetadataWithNotify(i + 0, j + 28, k + 26, 1, 2);
		setBlock(world, i + 0, j + 28, k + 27, Blocks.log, 1);
		world.setBlockMetadataWithNotify(i + 0, j + 28, k + 27, 1, 2);
		setBlock(world, i + 0, j + 28, k + 28, Blocks.log, 1);
		world.setBlockMetadataWithNotify(i + 0, j + 28, k + 28, 1, 2);
		setBlock(world, i + 0, j + 28, k + 29, Blocks.log, 1);
		world.setBlockMetadataWithNotify(i + 0, j + 28, k + 29, 1, 2);
		setBlock(world, i + 0, j + 42, k + 0, Blocks.log, 1);
		world.setBlockMetadataWithNotify(i + 0, j + 42, k + 0, 1, 2);
		setBlock(world, i + 0, j + 61, k + 25, Blocks.planks, 5);
		world.setBlockMetadataWithNotify(i + 0, j + 61, k + 25, 5, 2);
		setBlock(world, i + 0, j + 61, k + 26, Blocks.planks, 5);
		world.setBlockMetadataWithNotify(i + 0, j + 61, k + 26, 5, 2);
		setBlock(world, i + 0, j + 61, k + 27, Blocks.planks, 5);
		world.setBlockMetadataWithNotify(i + 0, j + 61, k + 27, 5, 2);
		setBlock(world, i + 0, j + 61, k + 28, Blocks.planks, 5);
		world.setBlockMetadataWithNotify(i + 0, j + 61, k + 28, 5, 2);
		setBlock(world, i + 0, j + 61, k + 29, Blocks.planks, 5);
		world.setBlockMetadataWithNotify(i + 0, j + 61, k + 29, 5, 2);
		setBlock(world, i + 0, j + 61, k + 30, Blocks.planks, 5);
		world.setBlockMetadataWithNotify(i + 0, j + 61, k + 30, 5, 2);
		setBlock(world, i + 0, j + 62, k + 25, Blocks.planks, 5);
		world.setBlockMetadataWithNotify(i + 0, j + 62, k + 25, 5, 2);
		setBlock(world, i + 0, j + 62, k + 26, Blocks.planks, 5);
		world.setBlockMetadataWithNotify(i + 0, j + 62, k + 26, 5, 2);
		setBlock(world, i + 0, j + 62, k + 27, Blocks.planks, 5);
		world.setBlockMetadataWithNotify(i + 0, j + 62, k + 27, 5, 2);
		setBlock(world, i + 0, j + 62, k + 28, Blocks.planks, 5);
		world.setBlockMetadataWithNotify(i + 0, j + 62, k + 28, 5, 2);
		setBlock(world, i + 0, j + 62, k + 29, Blocks.planks, 5);
		world.setBlockMetadataWithNotify(i + 0, j + 62, k + 29, 5, 2);
		setBlock(world, i + 0, j + 62, k + 30, Blocks.planks, 5);
		world.setBlockMetadataWithNotify(i + 0, j + 62, k + 30, 5, 2);
		setBlock(world, i + 0, j + 63, k + 25, Blocks.spruce_stairs, 1);
		world.setBlockMetadataWithNotify(i + 0, j + 63, k + 25, 1, 2);
		setBlock(world, i + 0, j + 63, k + 26, Blocks.spruce_stairs, 1);
		world.setBlockMetadataWithNotify(i + 0, j + 63, k + 26, 1, 2);
		setBlock(world, i + 0, j + 63, k + 27, Blocks.spruce_stairs, 1);
		world.setBlockMetadataWithNotify(i + 0, j + 63, k + 27, 1, 2);
		setBlock(world, i + 0, j + 63, k + 28, Blocks.spruce_stairs, 1);
		world.setBlockMetadataWithNotify(i + 0, j + 63, k + 28, 1, 2);
		setBlock(world, i + 0, j + 63, k + 29, Blocks.spruce_stairs, 1);
		world.setBlockMetadataWithNotify(i + 0, j + 63, k + 29, 1, 2);
		setBlock(world, i + 0, j + 63, k + 30, Blocks.spruce_stairs, 1);
		world.setBlockMetadataWithNotify(i + 0, j + 63, k + 30, 1, 2);
		setBlock(world, i + 1, j + 0, k + 25, Blocks.log, 1);
		world.setBlockMetadataWithNotify(i + 1, j + 0, k + 25, 1, 2);
		setBlock(world, i + 1, j + 0, k + 26, Blocks.log, 1);
		world.setBlockMetadataWithNotify(i + 1, j + 0, k + 26, 1, 2);
		setBlock(world, i + 1, j + 0, k + 27, Blocks.log, 1);
		world.setBlockMetadataWithNotify(i + 1, j + 0, k + 27, 1, 2);
		setBlock(world, i + 1, j + 0, k + 28, Blocks.planks, 5);
		world.setBlockMetadataWithNotify(i + 1, j + 0, k + 28, 5, 2);
		setBlock(world, i + 1, j + 0, k + 29, Blocks.planks, 5);
		world.setBlockMetadataWithNotify(i + 1, j + 0, k + 29, 5, 2);
		setBlock(world, i + 1, j + 1, k + 25, Blocks.log, 1);
		world.setBlockMetadataWithNotify(i + 1, j + 1, k + 25, 1, 2);
		setBlock(world, i + 1, j + 1, k + 26, Blocks.log, 1);
		world.setBlockMetadataWithNotify(i + 1, j + 1, k + 26, 1, 2);
		setBlock(world, i + 1, j + 1, k + 27, Blocks.log, 1);
		world.setBlockMetadataWithNotify(i + 1, j + 1, k + 27, 1, 2);
		setBlock(world, i + 1, j + 2, k + 26, Blocks.log, 1);
		world.setBlockMetadataWithNotify(i + 1, j + 2, k + 26, 1, 2);
		setBlock(world, i + 1, j + 2, k + 27, Blocks.log, 1);
		world.setBlockMetadataWithNotify(i + 1, j + 2, k + 27, 1, 2);
		setBlock(world, i + 1, j + 3, k + 26, Blocks.log, 1);
		world.setBlockMetadataWithNotify(i + 1, j + 3, k + 26, 1, 2);
		setBlock(world, i + 1, j + 3, k + 27, Blocks.log, 1);
		world.setBlockMetadataWithNotify(i + 1, j + 3, k + 27, 1, 2);
		setBlock(world, i + 1, j + 4, k + 25, Blocks.log, 1);
		world.setBlockMetadataWithNotify(i + 1, j + 4, k + 25, 1, 2);
		setBlock(world, i + 1, j + 4, k + 26, Blocks.log, 1);
		world.setBlockMetadataWithNotify(i + 1, j + 4, k + 26, 1, 2);
		setBlock(world, i + 1, j + 4, k + 27, Blocks.log, 1);
		world.setBlockMetadataWithNotify(i + 1, j + 4, k + 27, 1, 2);
		setBlock(world, i + 1, j + 5, k + 23, Blocks.planks, 5);
		world.setBlockMetadataWithNotify(i + 1, j + 5, k + 23, 5, 2);
		setBlock(world, i + 1, j + 5, k + 24, Blocks.planks, 5);
		world.setBlockMetadataWithNotify(i + 1, j + 5, k + 24, 5, 2);
		setBlock(world, i + 1, j + 5, k + 25, Blocks.log, 1);
		world.setBlockMetadataWithNotify(i + 1, j + 5, k + 25, 1, 2);
		setBlock(world, i + 1, j + 5, k + 26, Blocks.log, 1);
		world.setBlockMetadataWithNotify(i + 1, j + 5, k + 26, 1, 2);
		setBlock(world, i + 1, j + 6, k + 23, Blocks.planks, 5);
		world.setBlockMetadataWithNotify(i + 1, j + 6, k + 23, 5, 2);
		setBlock(world, i + 1, j + 6, k + 24, Blocks.planks, 5);
		world.setBlockMetadataWithNotify(i + 1, j + 6, k + 24, 5, 2);
		setBlock(world, i + 1, j + 6, k + 25, Blocks.log, 1);
		world.setBlockMetadataWithNotify(i + 1, j + 6, k + 25, 1, 2);
		setBlock(world, i + 1, j + 6, k + 26, Blocks.log, 1);
		world.setBlockMetadataWithNotify(i + 1, j + 6, k + 26, 1, 2);
		setBlock(world, i + 1, j + 6, k + 27, Blocks.log, 1);
		world.setBlockMetadataWithNotify(i + 1, j + 6, k + 27, 1, 2);
		setBlock(world, i + 1, j + 7, k + 23, Blocks.spruce_stairs, 1);
		world.setBlockMetadataWithNotify(i + 1, j + 7, k + 23, 1, 2);
		setBlock(world, i + 1, j + 7, k + 24, Blocks.spruce_stairs, 1);
		world.setBlockMetadataWithNotify(i + 1, j + 7, k + 24, 1, 2);
		setBlock(world, i + 1, j + 7, k + 25, Blocks.log, 1);
		world.setBlockMetadataWithNotify(i + 1, j + 7, k + 25, 1, 2);
		setBlock(world, i + 1, j + 7, k + 26, Blocks.log, 1);
		world.setBlockMetadataWithNotify(i + 1, j + 7, k + 26, 1, 2);
		setBlock(world, i + 1, j + 7, k + 27, Blocks.log, 1);
		world.setBlockMetadataWithNotify(i + 1, j + 7, k + 27, 1, 2);
		setBlock(world, i + 1, j + 8, k + 25, Blocks.log, 1);
		world.setBlockMetadataWithNotify(i + 1, j + 8, k + 25, 1, 2);
		setBlock(world, i + 1, j + 8, k + 26, Blocks.log, 1);
		world.setBlockMetadataWithNotify(i + 1, j + 8, k + 26, 1, 2);
		setBlock(world, i + 1, j + 8, k + 27, Blocks.log, 1);
		world.setBlockMetadataWithNotify(i + 1, j + 8, k + 27, 1, 2);
		setBlock(world, i + 1, j + 9, k + 25, Blocks.log, 1);
		world.setBlockMetadataWithNotify(i + 1, j + 9, k + 25, 1, 2);
		setBlock(world, i + 1, j + 9, k + 26, Blocks.log, 1);
		world.setBlockMetadataWithNotify(i + 1, j + 9, k + 26, 1, 2);
		setBlock(world, i + 1, j + 9, k + 27, Blocks.log, 1);
		world.setBlockMetadataWithNotify(i + 1, j + 9, k + 27, 1, 2);
		setBlock(world, i + 1, j + 9, k + 28, Blocks.planks, 5);
		world.setBlockMetadataWithNotify(i + 1, j + 9, k + 28, 5, 2);
		setBlock(world, i + 1, j + 9, k + 29, Blocks.planks, 5);
		world.setBlockMetadataWithNotify(i + 1, j + 9, k + 29, 5, 2);
		setBlock(world, i + 1, j + 10, k + 25, Blocks.log, 1);
		world.setBlockMetadataWithNotify(i + 1, j + 10, k + 25, 1, 2);
		setBlock(world, i + 1, j + 10, k + 26, Blocks.log, 1);
		world.setBlockMetadataWithNotify(i + 1, j + 10, k + 26, 1, 2);
		setBlock(world, i + 1, j + 10, k + 27, Blocks.log, 1);
		world.setBlockMetadataWithNotify(i + 1, j + 10, k + 27, 1, 2);
		setBlock(world, i + 1, j + 10, k + 28, Blocks.planks, 5);
		world.setBlockMetadataWithNotify(i + 1, j + 10, k + 28, 5, 2);
		setBlock(world, i + 1, j + 10, k + 29, Blocks.planks, 5);
		world.setBlockMetadataWithNotify(i + 1, j + 10, k + 29, 5, 2);
		setBlock(world, i + 1, j + 11, k + 25, Blocks.log, 1);
		world.setBlockMetadataWithNotify(i + 1, j + 11, k + 25, 1, 2);
		setBlock(world, i + 1, j + 11, k + 26, Blocks.log, 1);
		world.setBlockMetadataWithNotify(i + 1, j + 11, k + 26, 1, 2);
		setBlock(world, i + 1, j + 11, k + 27, Blocks.log, 1);
		world.setBlockMetadataWithNotify(i + 1, j + 11, k + 27, 1, 2);
		setBlock(world, i + 1, j + 12, k + 20, Blocks.vine, 4);
		world.setBlockMetadataWithNotify(i + 1, j + 12, k + 20, 4, 2);
		setBlock(world, i + 1, j + 12, k + 21, Blocks.vine, 1);
		world.setBlockMetadataWithNotify(i + 1, j + 12, k + 21, 1, 2);
		setBlock(world, i + 1, j + 12, k + 23, Blocks.vine, 12);
		world.setBlockMetadataWithNotify(i + 1, j + 12, k + 23, 12, 2);
		setBlock(world, i + 1, j + 12, k + 26, Blocks.log, 1);
		world.setBlockMetadataWithNotify(i + 1, j + 12, k + 26, 1, 2);
		setBlock(world, i + 1, j + 12, k + 27, Blocks.log, 1);
		world.setBlockMetadataWithNotify(i + 1, j + 12, k + 27, 1, 2);
		setBlock(world, i + 1, j + 13, k + 16, Blocks.vine, 3);
		world.setBlockMetadataWithNotify(i + 1, j + 13, k + 16, 3, 2);
		setBlock(world, i + 1, j + 13, k + 20, Blocks.vine, 6);
		world.setBlockMetadataWithNotify(i + 1, j + 13, k + 20, 6, 2);
		setBlock(world, i + 1, j + 13, k + 21, Blocks.vine, 15);
		world.setBlockMetadataWithNotify(i + 1, j + 13, k + 21, 15, 2);
		setBlock(world, i + 1, j + 13, k + 23, Blocks.vine, 12);
		world.setBlockMetadataWithNotify(i + 1, j + 13, k + 23, 12, 2);
		setBlock(world, i + 1, j + 13, k + 26, Blocks.log, 1);
		world.setBlockMetadataWithNotify(i + 1, j + 13, k + 26, 1, 2);
		setBlock(world, i + 1, j + 13, k + 27, Blocks.log, 1);
		world.setBlockMetadataWithNotify(i + 1, j + 13, k + 27, 1, 2);
		setBlock(world, i + 1, j + 14, k + 15, Blocks.vine, 3);
		world.setBlockMetadataWithNotify(i + 1, j + 14, k + 15, 3, 2);
		setBlock(world, i + 1, j + 14, k + 16, Blocks.vine, 7);
		world.setBlockMetadataWithNotify(i + 1, j + 14, k + 16, 7, 2);
		setBlock(world, i + 1, j + 14, k + 17, Blocks.vine, 5);
		world.setBlockMetadataWithNotify(i + 1, j + 14, k + 17, 5, 2);
		setBlock(world, i + 1, j + 14, k + 18, Blocks.vine, 1);
		world.setBlockMetadataWithNotify(i + 1, j + 14, k + 18, 1, 2);
		setBlock(world, i + 1, j + 14, k + 19, Blocks.vine, 5);
		world.setBlockMetadataWithNotify(i + 1, j + 14, k + 19, 5, 2);
		setBlock(world, i + 1, j + 14, k + 20, Blocks.vine, 15);
		world.setBlockMetadataWithNotify(i + 1, j + 14, k + 20, 15, 2);
		setBlock(world, i + 1, j + 14, k + 21, Blocks.vine, 15);
		world.setBlockMetadataWithNotify(i + 1, j + 14, k + 21, 15, 2);
		setBlock(world, i + 1, j + 14, k + 22, Blocks.vine, 15);
		world.setBlockMetadataWithNotify(i + 1, j + 14, k + 22, 15, 2);
		setBlock(world, i + 1, j + 14, k + 23, Blocks.vine, 15);
		world.setBlockMetadataWithNotify(i + 1, j + 14, k + 23, 15, 2);
		setBlock(world, i + 1, j + 14, k + 25, Blocks.log, 1);
		world.setBlockMetadataWithNotify(i + 1, j + 14, k + 25, 1, 2);
		setBlock(world, i + 1, j + 14, k + 26, Blocks.log, 1);
		world.setBlockMetadataWithNotify(i + 1, j + 14, k + 26, 1, 2);
		setBlock(world, i + 1, j + 14, k + 27, Blocks.log, 1);
		world.setBlockMetadataWithNotify(i + 1, j + 14, k + 27, 1, 2);
		setBlock(world, i + 1, j + 15, k + 15, Blocks.vine, 11);
		world.setBlockMetadataWithNotify(i + 1, j + 15, k + 15, 11, 2);
		setBlock(world, i + 1, j + 15, k + 16, Blocks.vine, 15);
		world.setBlockMetadataWithNotify(i + 1, j + 15, k + 16, 15, 2);
		setBlock(world, i + 1, j + 15, k + 17, Blocks.vine, 15);
		world.setBlockMetadataWithNotify(i + 1, j + 15, k + 17, 15, 2);
		setBlock(world, i + 1, j + 15, k + 18, Blocks.vine, 15);
		world.setBlockMetadataWithNotify(i + 1, j + 15, k + 18, 15, 2);
		setBlock(world, i + 1, j + 15, k + 19, Blocks.vine, 15);
		world.setBlockMetadataWithNotify(i + 1, j + 15, k + 19, 15, 2);
		setBlock(world, i + 1, j + 15, k + 20, Blocks.log, 1);
		world.setBlockMetadataWithNotify(i + 1, j + 15, k + 20, 1, 2);
		setBlock(world, i + 1, j + 15, k + 21, Blocks.log, 1);
		world.setBlockMetadataWithNotify(i + 1, j + 15, k + 21, 1, 2);
		setBlock(world, i + 1, j + 15, k + 22, Blocks.log, 1);
		world.setBlockMetadataWithNotify(i + 1, j + 15, k + 22, 1, 2);
		setBlock(world, i + 1, j + 15, k + 23, Blocks.log, 1);
		world.setBlockMetadataWithNotify(i + 1, j + 15, k + 23, 1, 2);
		setBlock(world, i + 1, j + 15, k + 24, Blocks.log, 1);
		world.setBlockMetadataWithNotify(i + 1, j + 15, k + 24, 1, 2);
		setBlock(world, i + 1, j + 15, k + 25, Blocks.log, 1);
		world.setBlockMetadataWithNotify(i + 1, j + 15, k + 25, 1, 2);
		setBlock(world, i + 1, j + 15, k + 26, Blocks.log, 1);
		world.setBlockMetadataWithNotify(i + 1, j + 15, k + 26, 1, 2);
		setBlock(world, i + 1, j + 15, k + 27, Blocks.log, 1);
		world.setBlockMetadataWithNotify(i + 1, j + 15, k + 27, 1, 2);
		setBlock(world, i + 1, j + 16, k + 14, Blocks.vine, 15);
		world.setBlockMetadataWithNotify(i + 1, j + 16, k + 14, 15, 2);
		setBlock(world, i + 1, j + 16, k + 15, Blocks.vine, 15);
		world.setBlockMetadataWithNotify(i + 1, j + 16, k + 15, 15, 2);
		setBlock(world, i + 1, j + 16, k + 16, Blocks.vine, 15);
		world.setBlockMetadataWithNotify(i + 1, j + 16, k + 16, 15, 2);
		setBlock(world, i + 1, j + 16, k + 17, Blocks.vine, 15);
		world.setBlockMetadataWithNotify(i + 1, j + 16, k + 17, 15, 2);
		setBlock(world, i + 1, j + 16, k + 18, Blocks.log, 1);
		world.setBlockMetadataWithNotify(i + 1, j + 16, k + 18, 1, 2);
		setBlock(world, i + 1, j + 16, k + 19, Blocks.log, 1);
		world.setBlockMetadataWithNotify(i + 1, j + 16, k + 19, 1, 2);
		setBlock(world, i + 1, j + 16, k + 20, Blocks.log, 1);
		world.setBlockMetadataWithNotify(i + 1, j + 16, k + 20, 1, 2);
		setBlock(world, i + 1, j + 16, k + 21, Blocks.log, 1);
		world.setBlockMetadataWithNotify(i + 1, j + 16, k + 21, 1, 2);
		setBlock(world, i + 1, j + 16, k + 22, Blocks.log, 1);
		world.setBlockMetadataWithNotify(i + 1, j + 16, k + 22, 1, 2);
		setBlock(world, i + 1, j + 16, k + 23, Blocks.log, 1);
		world.setBlockMetadataWithNotify(i + 1, j + 16, k + 23, 1, 2);
		setBlock(world, i + 1, j + 16, k + 24, Blocks.log, 1);
		world.setBlockMetadataWithNotify(i + 1, j + 16, k + 24, 1, 2);
		setBlock(world, i + 1, j + 16, k + 25, Blocks.log, 1);
		world.setBlockMetadataWithNotify(i + 1, j + 16, k + 25, 1, 2);
		setBlock(world, i + 1, j + 16, k + 26, Blocks.log, 1);
		world.setBlockMetadataWithNotify(i + 1, j + 16, k + 26, 1, 2);
		setBlock(world, i + 1, j + 16, k + 27, Blocks.log, 1);
		world.setBlockMetadataWithNotify(i + 1, j + 16, k + 27, 1, 2);
		setBlock(world, i + 1, j + 16, k + 28, Blocks.log, 1);
		world.setBlockMetadataWithNotify(i + 1, j + 16, k + 28, 1, 2);
		setBlock(world, i + 1, j + 17, k + 13, Blocks.log, 1);
		world.setBlockMetadataWithNotify(i + 1, j + 17, k + 13, 1, 2);
		setBlock(world, i + 1, j + 17, k + 14, Blocks.log, 1);
		world.setBlockMetadataWithNotify(i + 1, j + 17, k + 14, 1, 2);
		setBlock(world, i + 1, j + 17, k + 15, Blocks.log, 1);
		world.setBlockMetadataWithNotify(i + 1, j + 17, k + 15, 1, 2);
		setBlock(world, i + 1, j + 17, k + 16, Blocks.log, 1);
		world.setBlockMetadataWithNotify(i + 1, j + 17, k + 16, 1, 2);
		setBlock(world, i + 1, j + 17, k + 17, Blocks.log, 1);
		world.setBlockMetadataWithNotify(i + 1, j + 17, k + 17, 1, 2);
		setBlock(world, i + 1, j + 17, k + 18, Blocks.log, 1);
		world.setBlockMetadataWithNotify(i + 1, j + 17, k + 18, 1, 2);
		setBlock(world, i + 1, j + 17, k + 19, Blocks.log, 1);
		world.setBlockMetadataWithNotify(i + 1, j + 17, k + 19, 1, 2);
		setBlock(world, i + 1, j + 17, k + 20, Blocks.log, 1);
		world.setBlockMetadataWithNotify(i + 1, j + 17, k + 20, 1, 2);
		setBlock(world, i + 1, j + 17, k + 21, Blocks.log, 1);
		world.setBlockMetadataWithNotify(i + 1, j + 17, k + 21, 1, 2);
		setBlock(world, i + 1, j + 17, k + 22, Blocks.log, 1);
		world.setBlockMetadataWithNotify(i + 1, j + 17, k + 22, 1, 2);
		setBlock(world, i + 1, j + 17, k + 23, Blocks.log, 1);
		world.setBlockMetadataWithNotify(i + 1, j + 17, k + 23, 1, 2);
		setBlock(world, i + 1, j + 17, k + 24, Blocks.log, 1);
		world.setBlockMetadataWithNotify(i + 1, j + 17, k + 24, 1, 2);
		setBlock(world, i + 1, j + 17, k + 25, Blocks.log, 1);
		world.setBlockMetadataWithNotify(i + 1, j + 17, k + 25, 1, 2);
		setBlock(world, i + 1, j + 17, k + 26, Blocks.log, 1);
		world.setBlockMetadataWithNotify(i + 1, j + 17, k + 26, 1, 2);
		setBlock(world, i + 1, j + 17, k + 27, Blocks.log, 1);
		world.setBlockMetadataWithNotify(i + 1, j + 17, k + 27, 1, 2);
		setBlock(world, i + 1, j + 17, k + 28, Blocks.log, 1);
		world.setBlockMetadataWithNotify(i + 1, j + 17, k + 28, 1, 2);
		setBlock(world, i + 1, j + 17, k + 29, Blocks.log, 1);
		world.setBlockMetadataWithNotify(i + 1, j + 17, k + 29, 1, 2);
		setBlock(world, i + 1, j + 17, k + 30, Blocks.log, 1);
		world.setBlockMetadataWithNotify(i + 1, j + 17, k + 30, 1, 2);
		setBlock(world, i + 1, j + 18, k + 13, Blocks.log, 1);
		world.setBlockMetadataWithNotify(i + 1, j + 18, k + 13, 1, 2);
		setBlock(world, i + 1, j + 18, k + 14, Blocks.log, 1);
		world.setBlockMetadataWithNotify(i + 1, j + 18, k + 14, 1, 2);
		setBlock(world, i + 1, j + 18, k + 15, Blocks.log, 1);
		world.setBlockMetadataWithNotify(i + 1, j + 18, k + 15, 1, 2);
		setBlock(world, i + 1, j + 18, k + 16, Blocks.log, 1);
		world.setBlockMetadataWithNotify(i + 1, j + 18, k + 16, 1, 2);
		setBlock(world, i + 1, j + 18, k + 17, Blocks.log, 1);
		world.setBlockMetadataWithNotify(i + 1, j + 18, k + 17, 1, 2);
		setBlock(world, i + 1, j + 18, k + 18, Blocks.log, 1);
		world.setBlockMetadataWithNotify(i + 1, j + 18, k + 18, 1, 2);
		setBlock(world, i + 1, j + 18, k + 19, Blocks.log, 1);
		world.setBlockMetadataWithNotify(i + 1, j + 18, k + 19, 1, 2);
		setBlock(world, i + 1, j + 18, k + 20, Blocks.log, 1);
		world.setBlockMetadataWithNotify(i + 1, j + 18, k + 20, 1, 2);
		setBlock(world, i + 1, j + 18, k + 21, Blocks.log, 1);
		world.setBlockMetadataWithNotify(i + 1, j + 18, k + 21, 1, 2);
		setBlock(world, i + 1, j + 18, k + 22, Blocks.log, 1);
		world.setBlockMetadataWithNotify(i + 1, j + 18, k + 22, 1, 2);
		setBlock(world, i + 1, j + 18, k + 23, Blocks.log, 1);
		world.setBlockMetadataWithNotify(i + 1, j + 18, k + 23, 1, 2);
		setBlock(world, i + 1, j + 18, k + 24, Blocks.log, 1);
		world.setBlockMetadataWithNotify(i + 1, j + 18, k + 24, 1, 2);
		setBlock(world, i + 1, j + 18, k + 25, Blocks.log, 1);
		world.setBlockMetadataWithNotify(i + 1, j + 18, k + 25, 1, 2);
		setBlock(world, i + 1, j + 18, k + 26, Blocks.log, 1);
		world.setBlockMetadataWithNotify(i + 1, j + 18, k + 26, 1, 2);
		setBlock(world, i + 1, j + 18, k + 27, Blocks.log, 1);
		world.setBlockMetadataWithNotify(i + 1, j + 18, k + 27, 1, 2);
		setBlock(world, i + 1, j + 18, k + 28, Blocks.log, 1);
		world.setBlockMetadataWithNotify(i + 1, j + 18, k + 28, 1, 2);
		setBlock(world, i + 1, j + 18, k + 29, Blocks.log, 1);
		world.setBlockMetadataWithNotify(i + 1, j + 18, k + 29, 1, 2);
		setBlock(world, i + 1, j + 18, k + 30, Blocks.log, 1);
		world.setBlockMetadataWithNotify(i + 1, j + 18, k + 30, 1, 2);
		setBlock(world, i + 1, j + 18, k + 31, Blocks.log, 1);
		world.setBlockMetadataWithNotify(i + 1, j + 18, k + 31, 1, 2);
		setBlock(world, i + 1, j + 19, k + 13, Blocks.log, 1);
		world.setBlockMetadataWithNotify(i + 1, j + 19, k + 13, 1, 2);
		setBlock(world, i + 1, j + 19, k + 14, Blocks.log, 1);
		world.setBlockMetadataWithNotify(i + 1, j + 19, k + 14, 1, 2);
		setBlock(world, i + 1, j + 19, k + 15, Blocks.log, 1);
		world.setBlockMetadataWithNotify(i + 1, j + 19, k + 15, 1, 2);
		setBlock(world, i + 1, j + 19, k + 16, Blocks.log, 1);
		world.setBlockMetadataWithNotify(i + 1, j + 19, k + 16, 1, 2);
		setBlock(world, i + 1, j + 19, k + 17, Blocks.log, 1);
		world.setBlockMetadataWithNotify(i + 1, j + 19, k + 17, 1, 2);
		setBlock(world, i + 1, j + 19, k + 18, Blocks.log, 1);
		world.setBlockMetadataWithNotify(i + 1, j + 19, k + 18, 1, 2);
		setBlock(world, i + 1, j + 19, k + 19, Blocks.log, 1);
		world.setBlockMetadataWithNotify(i + 1, j + 19, k + 19, 1, 2);
		setBlock(world, i + 1, j + 19, k + 20, Blocks.log, 1);
		world.setBlockMetadataWithNotify(i + 1, j + 19, k + 20, 1, 2);
		setBlock(world, i + 1, j + 19, k + 21, Blocks.log, 1);
		world.setBlockMetadataWithNotify(i + 1, j + 19, k + 21, 1, 2);
		setBlock(world, i + 1, j + 19, k + 22, Blocks.log, 1);
		world.setBlockMetadataWithNotify(i + 1, j + 19, k + 22, 1, 2);
		setBlock(world, i + 1, j + 19, k + 23, Blocks.log, 1);
		world.setBlockMetadataWithNotify(i + 1, j + 19, k + 23, 1, 2);
		setBlock(world, i + 1, j + 19, k + 24, Blocks.log, 1);
		world.setBlockMetadataWithNotify(i + 1, j + 19, k + 24, 1, 2);
		setBlock(world, i + 1, j + 19, k + 25, Blocks.log, 1);
		world.setBlockMetadataWithNotify(i + 1, j + 19, k + 25, 1, 2);
		setBlock(world, i + 1, j + 19, k + 26, Blocks.log, 1);
		world.setBlockMetadataWithNotify(i + 1, j + 19, k + 26, 1, 2);
		setBlock(world, i + 1, j + 19, k + 27, Blocks.log, 1);
		world.setBlockMetadataWithNotify(i + 1, j + 19, k + 27, 1, 2);
		setBlock(world, i + 1, j + 19, k + 28, Blocks.log, 1);
		world.setBlockMetadataWithNotify(i + 1, j + 19, k + 28, 1, 2);
		setBlock(world, i + 1, j + 19, k + 29, Blocks.log, 1);
		world.setBlockMetadataWithNotify(i + 1, j + 19, k + 29, 1, 2);
		setBlock(world, i + 1, j + 19, k + 30, Blocks.log, 1);
		world.setBlockMetadataWithNotify(i + 1, j + 19, k + 30, 1, 2);
		setBlock(world, i + 1, j + 19, k + 31, Blocks.log, 1);
		world.setBlockMetadataWithNotify(i + 1, j + 19, k + 31, 1, 2);
		setBlock(world, i + 1, j + 20, k + 12, Blocks.log, 1);
		world.setBlockMetadataWithNotify(i + 1, j + 20, k + 12, 1, 2);
		setBlock(world, i + 1, j + 20, k + 13, Blocks.log, 1);
		world.setBlockMetadataWithNotify(i + 1, j + 20, k + 13, 1, 2);
		setBlock(world, i + 1, j + 20, k + 14, Blocks.log, 1);
		world.setBlockMetadataWithNotify(i + 1, j + 20, k + 14, 1, 2);
		setBlock(world, i + 1, j + 20, k + 15, Blocks.log, 1);
		world.setBlockMetadataWithNotify(i + 1, j + 20, k + 15, 1, 2);
		setBlock(world, i + 1, j + 20, k + 16, Blocks.log, 1);
		world.setBlockMetadataWithNotify(i + 1, j + 20, k + 16, 1, 2);
		setBlock(world, i + 1, j + 20, k + 17, Blocks.log, 1);
		world.setBlockMetadataWithNotify(i + 1, j + 20, k + 17, 1, 2);
		setBlock(world, i + 1, j + 20, k + 18, Blocks.planks, 5);
		world.setBlockMetadataWithNotify(i + 1, j + 20, k + 18, 5, 2);
		setBlock(world, i + 1, j + 20, k + 19, Blocks.log, 1);
		world.setBlockMetadataWithNotify(i + 1, j + 20, k + 19, 1, 2);
		setBlock(world, i + 1, j + 20, k + 20, Blocks.log, 1);
		world.setBlockMetadataWithNotify(i + 1, j + 20, k + 20, 1, 2);
		setBlock(world, i + 1, j + 20, k + 21, Blocks.planks, 5);
		world.setBlockMetadataWithNotify(i + 1, j + 20, k + 21, 5, 2);
		setBlock(world, i + 1, j + 20, k + 22, Blocks.planks, 5);
		world.setBlockMetadataWithNotify(i + 1, j + 20, k + 22, 5, 2);
		setBlock(world, i + 1, j + 20, k + 23, Blocks.log, 1);
		world.setBlockMetadataWithNotify(i + 1, j + 20, k + 23, 1, 2);
		setBlock(world, i + 1, j + 20, k + 24, Blocks.log, 1);
		world.setBlockMetadataWithNotify(i + 1, j + 20, k + 24, 1, 2);
		setBlock(world, i + 1, j + 20, k + 25, Blocks.planks, 5);
		world.setBlockMetadataWithNotify(i + 1, j + 20, k + 25, 5, 2);
		setBlock(world, i + 1, j + 20, k + 26, Blocks.planks, 5);
		world.setBlockMetadataWithNotify(i + 1, j + 20, k + 26, 5, 2);
		setBlock(world, i + 1, j + 20, k + 27, Blocks.log, 1);
		world.setBlockMetadataWithNotify(i + 1, j + 20, k + 27, 1, 2);
		setBlock(world, i + 1, j + 20, k + 28, Blocks.log, 1);
		world.setBlockMetadataWithNotify(i + 1, j + 20, k + 28, 1, 2);
		setBlock(world, i + 1, j + 20, k + 29, Blocks.planks, 5);
		world.setBlockMetadataWithNotify(i + 1, j + 20, k + 29, 5, 2);
		setBlock(world, i + 1, j + 20, k + 30, Blocks.log, 1);
		world.setBlockMetadataWithNotify(i + 1, j + 20, k + 30, 1, 2);
		setBlock(world, i + 1, j + 20, k + 31, Blocks.log, 1);
		world.setBlockMetadataWithNotify(i + 1, j + 20, k + 31, 1, 2);
		setBlock(world, i + 1, j + 21, k + 25, Blocks.furnace, 4);
		world.setBlockMetadataWithNotify(i + 1, j + 21, k + 25, 4, 2);
		setBlock(world, i + 1, j + 23, k + 24, Blocks.torch, 2);
		world.setBlockMetadataWithNotify(i + 1, j + 23, k + 24, 2, 2);
		setBlock(world, i + 1, j + 24, k + 23, Blocks.torch, 2);
		world.setBlockMetadataWithNotify(i + 1, j + 24, k + 23, 2, 2);
		setBlock(world, i + 1, j + 25, k + 10, Blocks.log, 1);
		world.setBlockMetadataWithNotify(i + 1, j + 25, k + 10, 1, 2);
		setBlock(world, i + 1, j + 25, k + 11, Blocks.log, 1);
		world.setBlockMetadataWithNotify(i + 1, j + 25, k + 11, 1, 2);
		setBlock(world, i + 1, j + 25, k + 12, Blocks.log, 1);
		world.setBlockMetadataWithNotify(i + 1, j + 25, k + 12, 1, 2);
		setBlock(world, i + 1, j + 25, k + 13, Blocks.log, 1);
		world.setBlockMetadataWithNotify(i + 1, j + 25, k + 13, 1, 2);
		setBlock(world, i + 1, j + 25, k + 14, Blocks.log, 1);
		world.setBlockMetadataWithNotify(i + 1, j + 25, k + 14, 1, 2);
		setBlock(world, i + 1, j + 25, k + 15, Blocks.log, 1);
		world.setBlockMetadataWithNotify(i + 1, j + 25, k + 15, 1, 2);
		setBlock(world, i + 1, j + 26, k + 11, Blocks.log, 1);
		world.setBlockMetadataWithNotify(i + 1, j + 26, k + 11, 1, 2);
		setBlock(world, i + 1, j + 26, k + 12, Blocks.log, 1);
		world.setBlockMetadataWithNotify(i + 1, j + 26, k + 12, 1, 2);
		setBlock(world, i + 1, j + 26, k + 13, Blocks.log, 1);
		world.setBlockMetadataWithNotify(i + 1, j + 26, k + 13, 1, 2);
		setBlock(world, i + 1, j + 26, k + 14, Blocks.log, 1);
		world.setBlockMetadataWithNotify(i + 1, j + 26, k + 14, 1, 2);
		setBlock(world, i + 1, j + 26, k + 15, Blocks.log, 1);
		world.setBlockMetadataWithNotify(i + 1, j + 26, k + 15, 1, 2);
		setBlock(world, i + 1, j + 26, k + 16, Blocks.log, 1);
		world.setBlockMetadataWithNotify(i + 1, j + 26, k + 16, 1, 2);
		setBlock(world, i + 1, j + 26, k + 31, Blocks.log, 1);
		world.setBlockMetadataWithNotify(i + 1, j + 26, k + 31, 1, 2);
		setBlock(world, i + 1, j + 27, k + 13, Blocks.log, 1);
		world.setBlockMetadataWithNotify(i + 1, j + 27, k + 13, 1, 2);
		setBlock(world, i + 1, j + 27, k + 14, Blocks.log, 1);
		world.setBlockMetadataWithNotify(i + 1, j + 27, k + 14, 1, 2);
		setBlock(world, i + 1, j + 27, k + 15, Blocks.log, 1);
		world.setBlockMetadataWithNotify(i + 1, j + 27, k + 15, 1, 2);
		setBlock(world, i + 1, j + 27, k + 16, Blocks.log, 1);
		world.setBlockMetadataWithNotify(i + 1, j + 27, k + 16, 1, 2);
		setBlock(world, i + 1, j + 27, k + 17, Blocks.log, 1);
		world.setBlockMetadataWithNotify(i + 1, j + 27, k + 17, 1, 2);
		setBlock(world, i + 1, j + 27, k + 21, Blocks.torch, 4);
		world.setBlockMetadataWithNotify(i + 1, j + 27, k + 21, 4, 2);
		setBlock(world, i + 1, j + 27, k + 22, Blocks.log, 1);
		world.setBlockMetadataWithNotify(i + 1, j + 27, k + 22, 1, 2);
		setBlock(world, i + 1, j + 27, k + 23, Blocks.log, 1);
		world.setBlockMetadataWithNotify(i + 1, j + 27, k + 23, 1, 2);
		setBlock(world, i + 1, j + 27, k + 24, Blocks.log, 1);
		world.setBlockMetadataWithNotify(i + 1, j + 27, k + 24, 1, 2);
		setBlock(world, i + 1, j + 27, k + 25, Blocks.log, 1);
		world.setBlockMetadataWithNotify(i + 1, j + 27, k + 25, 1, 2);
		setBlock(world, i + 1, j + 27, k + 26, Blocks.torch, 3);
		world.setBlockMetadataWithNotify(i + 1, j + 27, k + 26, 3, 2);
		setBlock(world, i + 1, j + 27, k + 30, Blocks.log, 1);
		world.setBlockMetadataWithNotify(i + 1, j + 27, k + 30, 1, 2);
		setBlock(world, i + 1, j + 27, k + 31, Blocks.log, 1);
		world.setBlockMetadataWithNotify(i + 1, j + 27, k + 31, 1, 2);
		setBlock(world, i + 1, j + 28, k + 18, Blocks.log, 1);
		world.setBlockMetadataWithNotify(i + 1, j + 28, k + 18, 1, 2);
		setBlock(world, i + 1, j + 28, k + 19, Blocks.log, 1);
		world.setBlockMetadataWithNotify(i + 1, j + 28, k + 19, 1, 2);
		setBlock(world, i + 1, j + 28, k + 20, Blocks.log, 1);
		world.setBlockMetadataWithNotify(i + 1, j + 28, k + 20, 1, 2);
		setBlock(world, i + 1, j + 28, k + 21, Blocks.log, 1);
		world.setBlockMetadataWithNotify(i + 1, j + 28, k + 21, 1, 2);
		setBlock(world, i + 1, j + 28, k + 22, Blocks.log, 1);
		world.setBlockMetadataWithNotify(i + 1, j + 28, k + 22, 1, 2);
		setBlock(world, i + 1, j + 28, k + 23, Blocks.log, 1);
		world.setBlockMetadataWithNotify(i + 1, j + 28, k + 23, 1, 2);
		setBlock(world, i + 1, j + 28, k + 24, Blocks.log, 1);
		world.setBlockMetadataWithNotify(i + 1, j + 28, k + 24, 1, 2);
		setBlock(world, i + 1, j + 28, k + 25, Blocks.log, 1);
		world.setBlockMetadataWithNotify(i + 1, j + 28, k + 25, 1, 2);
		setBlock(world, i + 1, j + 28, k + 26, Blocks.log, 1);
		world.setBlockMetadataWithNotify(i + 1, j + 28, k + 26, 1, 2);
		setBlock(world, i + 1, j + 28, k + 27, Blocks.log, 1);
		world.setBlockMetadataWithNotify(i + 1, j + 28, k + 27, 1, 2);
		setBlock(world, i + 1, j + 28, k + 28, Blocks.log, 1);
		world.setBlockMetadataWithNotify(i + 1, j + 28, k + 28, 1, 2);
		setBlock(world, i + 1, j + 28, k + 29, Blocks.log, 1);
		world.setBlockMetadataWithNotify(i + 1, j + 28, k + 29, 1, 2);
		setBlock(world, i + 1, j + 42, k + 0, Blocks.log, 1);
		world.setBlockMetadataWithNotify(i + 1, j + 42, k + 0, 1, 2);
		setBlock(world, i + 1, j + 60, k + 25, Blocks.planks, 5);
		world.setBlockMetadataWithNotify(i + 1, j + 60, k + 25, 5, 2);
		setBlock(world, i + 1, j + 60, k + 26, Blocks.planks, 5);
		world.setBlockMetadataWithNotify(i + 1, j + 60, k + 26, 5, 2);
		setBlock(world, i + 1, j + 60, k + 27, Blocks.planks, 5);
		world.setBlockMetadataWithNotify(i + 1, j + 60, k + 27, 5, 2);
		setBlock(world, i + 1, j + 60, k + 28, Blocks.planks, 5);
		world.setBlockMetadataWithNotify(i + 1, j + 60, k + 28, 5, 2);
		setBlock(world, i + 1, j + 60, k + 29, Blocks.planks, 5);
		world.setBlockMetadataWithNotify(i + 1, j + 60, k + 29, 5, 2);
		setBlock(world, i + 1, j + 60, k + 30, Blocks.planks, 5);
		world.setBlockMetadataWithNotify(i + 1, j + 60, k + 30, 5, 2);
		setBlock(world, i + 1, j + 61, k + 25, Blocks.planks, 5);
		world.setBlockMetadataWithNotify(i + 1, j + 61, k + 25, 5, 2);
		setBlock(world, i + 1, j + 61, k + 26, Blocks.planks, 5);
		world.setBlockMetadataWithNotify(i + 1, j + 61, k + 26, 5, 2);
		setBlock(world, i + 1, j + 61, k + 27, Blocks.planks, 5);
		world.setBlockMetadataWithNotify(i + 1, j + 61, k + 27, 5, 2);
		setBlock(world, i + 1, j + 61, k + 28, Blocks.planks, 5);
		world.setBlockMetadataWithNotify(i + 1, j + 61, k + 28, 5, 2);
		setBlock(world, i + 1, j + 61, k + 29, Blocks.planks, 5);
		world.setBlockMetadataWithNotify(i + 1, j + 61, k + 29, 5, 2);
		setBlock(world, i + 1, j + 61, k + 30, Blocks.planks, 5);
		world.setBlockMetadataWithNotify(i + 1, j + 61, k + 30, 5, 2);
		setBlock(world, i + 1, j + 62, k + 25, Blocks.spruce_stairs, 1);
		world.setBlockMetadataWithNotify(i + 1, j + 62, k + 25, 1, 2);
		setBlock(world, i + 1, j + 62, k + 26, Blocks.spruce_stairs, 1);
		world.setBlockMetadataWithNotify(i + 1, j + 62, k + 26, 1, 2);
		setBlock(world, i + 1, j + 62, k + 27, Blocks.spruce_stairs, 1);
		world.setBlockMetadataWithNotify(i + 1, j + 62, k + 27, 1, 2);
		setBlock(world, i + 1, j + 62, k + 28, Blocks.spruce_stairs, 1);
		world.setBlockMetadataWithNotify(i + 1, j + 62, k + 28, 1, 2);
		setBlock(world, i + 1, j + 62, k + 29, Blocks.spruce_stairs, 1);
		world.setBlockMetadataWithNotify(i + 1, j + 62, k + 29, 1, 2);
		setBlock(world, i + 1, j + 62, k + 30, Blocks.spruce_stairs, 1);
		world.setBlockMetadataWithNotify(i + 1, j + 62, k + 30, 1, 2);
		setBlock(world, i + 2, j + 0, k + 25, Blocks.log, 1);
		world.setBlockMetadataWithNotify(i + 2, j + 0, k + 25, 1, 2);
		setBlock(world, i + 2, j + 0, k + 26, Blocks.log, 1);
		world.setBlockMetadataWithNotify(i + 2, j + 0, k + 26, 1, 2);
		setBlock(world, i + 2, j + 0, k + 27, Blocks.log, 1);
		world.setBlockMetadataWithNotify(i + 2, j + 0, k + 27, 1, 2);
		setBlock(world, i + 2, j + 0, k + 28, Blocks.planks, 5);
		world.setBlockMetadataWithNotify(i + 2, j + 0, k + 28, 5, 2);
		setBlock(world, i + 2, j + 0, k + 29, Blocks.planks, 5);
		world.setBlockMetadataWithNotify(i + 2, j + 0, k + 29, 5, 2);
		setBlock(world, i + 2, j + 1, k + 26, Blocks.log, 1);
		world.setBlockMetadataWithNotify(i + 2, j + 1, k + 26, 1, 2);
		setBlock(world, i + 2, j + 1, k + 27, Blocks.log, 1);
		world.setBlockMetadataWithNotify(i + 2, j + 1, k + 27, 1, 2);
		setBlock(world, i + 2, j + 1, k + 28, Blocks.planks, 5);
		world.setBlockMetadataWithNotify(i + 2, j + 1, k + 28, 5, 2);
		setBlock(world, i + 2, j + 1, k + 29, Blocks.planks, 5);
		world.setBlockMetadataWithNotify(i + 2, j + 1, k + 29, 5, 2);
		setBlock(world, i + 2, j + 2, k + 25, Blocks.log, 1);
		world.setBlockMetadataWithNotify(i + 2, j + 2, k + 25, 1, 2);
		setBlock(world, i + 2, j + 2, k + 26, Blocks.log, 1);
		world.setBlockMetadataWithNotify(i + 2, j + 2, k + 26, 1, 2);
		setBlock(world, i + 2, j + 2, k + 27, Blocks.log, 1);
		world.setBlockMetadataWithNotify(i + 2, j + 2, k + 27, 1, 2);
		setBlock(world, i + 2, j + 3, k + 25, Blocks.log, 1);
		world.setBlockMetadataWithNotify(i + 2, j + 3, k + 25, 1, 2);
		setBlock(world, i + 2, j + 3, k + 26, Blocks.log, 1);
		world.setBlockMetadataWithNotify(i + 2, j + 3, k + 26, 1, 2);
		setBlock(world, i + 2, j + 3, k + 27, Blocks.log, 1);
		world.setBlockMetadataWithNotify(i + 2, j + 3, k + 27, 1, 2);
		setBlock(world, i + 2, j + 4, k + 25, Blocks.log, 1);
		world.setBlockMetadataWithNotify(i + 2, j + 4, k + 25, 1, 2);
		setBlock(world, i + 2, j + 4, k + 26, Blocks.log, 1);
		world.setBlockMetadataWithNotify(i + 2, j + 4, k + 26, 1, 2);
		setBlock(world, i + 2, j + 4, k + 27, Blocks.log, 1);
		world.setBlockMetadataWithNotify(i + 2, j + 4, k + 27, 1, 2);
		setBlock(world, i + 2, j + 5, k + 23, Blocks.planks, 5);
		world.setBlockMetadataWithNotify(i + 2, j + 5, k + 23, 5, 2);
		setBlock(world, i + 2, j + 5, k + 24, Blocks.planks, 5);
		world.setBlockMetadataWithNotify(i + 2, j + 5, k + 24, 5, 2);
		setBlock(world, i + 2, j + 5, k + 25, Blocks.log, 1);
		world.setBlockMetadataWithNotify(i + 2, j + 5, k + 25, 1, 2);
		setBlock(world, i + 2, j + 5, k + 26, Blocks.log, 1);
		world.setBlockMetadataWithNotify(i + 2, j + 5, k + 26, 1, 2);
		setBlock(world, i + 2, j + 5, k + 27, Blocks.log, 1);
		world.setBlockMetadataWithNotify(i + 2, j + 5, k + 27, 1, 2);
		setBlock(world, i + 2, j + 5, k + 28, Blocks.torch, 3);
		world.setBlockMetadataWithNotify(i + 2, j + 5, k + 28, 3, 2);
		setBlock(world, i + 2, j + 6, k + 23, Blocks.spruce_stairs, 1);
		world.setBlockMetadataWithNotify(i + 2, j + 6, k + 23, 1, 2);
		setBlock(world, i + 2, j + 6, k + 24, Blocks.spruce_stairs, 1);
		world.setBlockMetadataWithNotify(i + 2, j + 6, k + 24, 1, 2);
		setBlock(world, i + 2, j + 6, k + 25, Blocks.log, 1);
		world.setBlockMetadataWithNotify(i + 2, j + 6, k + 25, 1, 2);
		setBlock(world, i + 2, j + 6, k + 26, Blocks.log, 1);
		world.setBlockMetadataWithNotify(i + 2, j + 6, k + 26, 1, 2);
		setBlock(world, i + 2, j + 7, k + 25, Blocks.log, 1);
		world.setBlockMetadataWithNotify(i + 2, j + 7, k + 25, 1, 2);
		setBlock(world, i + 2, j + 8, k + 25, Blocks.log, 1);
		world.setBlockMetadataWithNotify(i + 2, j + 8, k + 25, 1, 2);
		setBlock(world, i + 2, j + 8, k + 26, Blocks.log, 1);
		world.setBlockMetadataWithNotify(i + 2, j + 8, k + 26, 1, 2);
		setBlock(world, i + 2, j + 8, k + 27, Blocks.log, 1);
		world.setBlockMetadataWithNotify(i + 2, j + 8, k + 27, 1, 2);
		setBlock(world, i + 2, j + 9, k + 25, Blocks.log, 1);
		world.setBlockMetadataWithNotify(i + 2, j + 9, k + 25, 1, 2);
		setBlock(world, i + 2, j + 9, k + 27, Blocks.log, 1);
		world.setBlockMetadataWithNotify(i + 2, j + 9, k + 27, 1, 2);
		setBlock(world, i + 2, j + 9, k + 28, Blocks.planks, 5);
		world.setBlockMetadataWithNotify(i + 2, j + 9, k + 28, 5, 2);
		setBlock(world, i + 2, j + 9, k + 29, Blocks.planks, 5);
		world.setBlockMetadataWithNotify(i + 2, j + 9, k + 29, 5, 2);
		setBlock(world, i + 2, j + 10, k + 27, Blocks.log, 1);
		world.setBlockMetadataWithNotify(i + 2, j + 10, k + 27, 1, 2);
		setBlock(world, i + 2, j + 10, k + 28, Blocks.planks, 5);
		world.setBlockMetadataWithNotify(i + 2, j + 10, k + 28, 5, 2);
		setBlock(world, i + 2, j + 10, k + 29, Blocks.planks, 5);
		world.setBlockMetadataWithNotify(i + 2, j + 10, k + 29, 5, 2);
		setBlock(world, i + 2, j + 11, k + 18, Blocks.vine, 1);
		world.setBlockMetadataWithNotify(i + 2, j + 11, k + 18, 1, 2);
		setBlock(world, i + 2, j + 11, k + 26, Blocks.log, 1);
		world.setBlockMetadataWithNotify(i + 2, j + 11, k + 26, 1, 2);
		setBlock(world, i + 2, j + 11, k + 27, Blocks.log, 1);
		world.setBlockMetadataWithNotify(i + 2, j + 11, k + 27, 1, 2);
		setBlock(world, i + 2, j + 11, k + 28, Blocks.planks, 5);
		world.setBlockMetadataWithNotify(i + 2, j + 11, k + 28, 5, 2);
		setBlock(world, i + 2, j + 11, k + 29, Blocks.planks, 5);
		world.setBlockMetadataWithNotify(i + 2, j + 11, k + 29, 5, 2);
		setBlock(world, i + 2, j + 12, k + 18, Blocks.vine, 1);
		world.setBlockMetadataWithNotify(i + 2, j + 12, k + 18, 1, 2);
		setBlock(world, i + 2, j + 12, k + 26, Blocks.log, 1);
		world.setBlockMetadataWithNotify(i + 2, j + 12, k + 26, 1, 2);
		setBlock(world, i + 2, j + 12, k + 27, Blocks.log, 1);
		world.setBlockMetadataWithNotify(i + 2, j + 12, k + 27, 1, 2);
		setBlock(world, i + 2, j + 13, k + 18, Blocks.vine, 3);
		world.setBlockMetadataWithNotify(i + 2, j + 13, k + 18, 3, 2);
		setBlock(world, i + 2, j + 13, k + 20, Blocks.vine, 5);
		world.setBlockMetadataWithNotify(i + 2, j + 13, k + 20, 5, 2);
		setBlock(world, i + 2, j + 13, k + 23, Blocks.vine, 15);
		world.setBlockMetadataWithNotify(i + 2, j + 13, k + 23, 15, 2);
		setBlock(world, i + 2, j + 13, k + 24, Blocks.vine, 15);
		world.setBlockMetadataWithNotify(i + 2, j + 13, k + 24, 15, 2);
		setBlock(world, i + 2, j + 13, k + 25, Blocks.log, 1);
		world.setBlockMetadataWithNotify(i + 2, j + 13, k + 25, 1, 2);
		setBlock(world, i + 2, j + 13, k + 26, Blocks.log, 1);
		world.setBlockMetadataWithNotify(i + 2, j + 13, k + 26, 1, 2);
		setBlock(world, i + 2, j + 13, k + 27, Blocks.log, 1);
		world.setBlockMetadataWithNotify(i + 2, j + 13, k + 27, 1, 2);
		setBlock(world, i + 2, j + 14, k + 15, Blocks.vine, 1);
		world.setBlockMetadataWithNotify(i + 2, j + 14, k + 15, 1, 2);
		setBlock(world, i + 2, j + 14, k + 17, Blocks.vine, 8);
		world.setBlockMetadataWithNotify(i + 2, j + 14, k + 17, 8, 2);
		setBlock(world, i + 2, j + 14, k + 18, Blocks.vine, 7);
		world.setBlockMetadataWithNotify(i + 2, j + 14, k + 18, 7, 2);
		setBlock(world, i + 2, j + 14, k + 19, Blocks.vine, 15);
		world.setBlockMetadataWithNotify(i + 2, j + 14, k + 19, 15, 2);
		setBlock(world, i + 2, j + 14, k + 20, Blocks.vine, 15);
		world.setBlockMetadataWithNotify(i + 2, j + 14, k + 20, 15, 2);
		setBlock(world, i + 2, j + 14, k + 21, Blocks.vine, 15);
		world.setBlockMetadataWithNotify(i + 2, j + 14, k + 21, 15, 2);
		setBlock(world, i + 2, j + 14, k + 22, Blocks.vine, 15);
		world.setBlockMetadataWithNotify(i + 2, j + 14, k + 22, 15, 2);
		setBlock(world, i + 2, j + 14, k + 23, Blocks.vine, 15);
		world.setBlockMetadataWithNotify(i + 2, j + 14, k + 23, 15, 2);
		setBlock(world, i + 2, j + 14, k + 24, Blocks.vine, 15);
		world.setBlockMetadataWithNotify(i + 2, j + 14, k + 24, 15, 2);
		setBlock(world, i + 2, j + 14, k + 25, Blocks.log, 1);
		world.setBlockMetadataWithNotify(i + 2, j + 14, k + 25, 1, 2);
		setBlock(world, i + 2, j + 14, k + 26, Blocks.log, 1);
		world.setBlockMetadataWithNotify(i + 2, j + 14, k + 26, 1, 2);
		setBlock(world, i + 2, j + 14, k + 27, Blocks.log, 1);
		world.setBlockMetadataWithNotify(i + 2, j + 14, k + 27, 1, 2);
		setBlock(world, i + 2, j + 14, k + 28, Blocks.torch, 3);
		world.setBlockMetadataWithNotify(i + 2, j + 14, k + 28, 3, 2);
		setBlock(world, i + 2, j + 15, k + 14, Blocks.vine, 5);
		world.setBlockMetadataWithNotify(i + 2, j + 15, k + 14, 5, 2);
		setBlock(world, i + 2, j + 15, k + 15, Blocks.vine, 7);
		world.setBlockMetadataWithNotify(i + 2, j + 15, k + 15, 7, 2);
		setBlock(world, i + 2, j + 15, k + 16, Blocks.vine, 15);
		world.setBlockMetadataWithNotify(i + 2, j + 15, k + 16, 15, 2);
		setBlock(world, i + 2, j + 15, k + 17, Blocks.vine, 15);
		world.setBlockMetadataWithNotify(i + 2, j + 15, k + 17, 15, 2);
		setBlock(world, i + 2, j + 15, k + 18, Blocks.vine, 15);
		world.setBlockMetadataWithNotify(i + 2, j + 15, k + 18, 15, 2);
		setBlock(world, i + 2, j + 15, k + 19, Blocks.vine, 15);
		world.setBlockMetadataWithNotify(i + 2, j + 15, k + 19, 15, 2);
		setBlock(world, i + 2, j + 15, k + 20, Blocks.vine, 15);
		world.setBlockMetadataWithNotify(i + 2, j + 15, k + 20, 15, 2);
		setBlock(world, i + 2, j + 15, k + 21, Blocks.log, 1);
		world.setBlockMetadataWithNotify(i + 2, j + 15, k + 21, 1, 2);
		setBlock(world, i + 2, j + 15, k + 22, Blocks.log, 1);
		world.setBlockMetadataWithNotify(i + 2, j + 15, k + 22, 1, 2);
		setBlock(world, i + 2, j + 15, k + 23, Blocks.log, 1);
		world.setBlockMetadataWithNotify(i + 2, j + 15, k + 23, 1, 2);
		setBlock(world, i + 2, j + 15, k + 24, Blocks.log, 1);
		world.setBlockMetadataWithNotify(i + 2, j + 15, k + 24, 1, 2);
		setBlock(world, i + 2, j + 15, k + 25, Blocks.log, 1);
		world.setBlockMetadataWithNotify(i + 2, j + 15, k + 25, 1, 2);
		setBlock(world, i + 2, j + 15, k + 26, Blocks.log, 1);
		world.setBlockMetadataWithNotify(i + 2, j + 15, k + 26, 1, 2);
		setBlock(world, i + 2, j + 15, k + 27, Blocks.log, 1);
		world.setBlockMetadataWithNotify(i + 2, j + 15, k + 27, 1, 2);
		setBlock(world, i + 2, j + 16, k + 14, Blocks.vine, 15);
		world.setBlockMetadataWithNotify(i + 2, j + 16, k + 14, 15, 2);
		setBlock(world, i + 2, j + 16, k + 15, Blocks.vine, 15);
		world.setBlockMetadataWithNotify(i + 2, j + 16, k + 15, 15, 2);
		setBlock(world, i + 2, j + 16, k + 16, Blocks.vine, 15);
		world.setBlockMetadataWithNotify(i + 2, j + 16, k + 16, 15, 2);
		setBlock(world, i + 2, j + 16, k + 17, Blocks.log, 1);
		world.setBlockMetadataWithNotify(i + 2, j + 16, k + 17, 1, 2);
		setBlock(world, i + 2, j + 16, k + 18, Blocks.log, 1);
		world.setBlockMetadataWithNotify(i + 2, j + 16, k + 18, 1, 2);
		setBlock(world, i + 2, j + 16, k + 19, Blocks.log, 1);
		world.setBlockMetadataWithNotify(i + 2, j + 16, k + 19, 1, 2);
		setBlock(world, i + 2, j + 16, k + 20, Blocks.log, 1);
		world.setBlockMetadataWithNotify(i + 2, j + 16, k + 20, 1, 2);
		setBlock(world, i + 2, j + 16, k + 21, Blocks.log, 1);
		world.setBlockMetadataWithNotify(i + 2, j + 16, k + 21, 1, 2);
		setBlock(world, i + 2, j + 16, k + 22, Blocks.log, 1);
		world.setBlockMetadataWithNotify(i + 2, j + 16, k + 22, 1, 2);
		setBlock(world, i + 2, j + 16, k + 23, Blocks.log, 1);
		world.setBlockMetadataWithNotify(i + 2, j + 16, k + 23, 1, 2);
		setBlock(world, i + 2, j + 16, k + 24, Blocks.log, 1);
		world.setBlockMetadataWithNotify(i + 2, j + 16, k + 24, 1, 2);
		setBlock(world, i + 2, j + 16, k + 25, Blocks.log, 1);
		world.setBlockMetadataWithNotify(i + 2, j + 16, k + 25, 1, 2);
		setBlock(world, i + 2, j + 16, k + 26, Blocks.log, 1);
		world.setBlockMetadataWithNotify(i + 2, j + 16, k + 26, 1, 2);
		setBlock(world, i + 2, j + 16, k + 27, Blocks.log, 1);
		world.setBlockMetadataWithNotify(i + 2, j + 16, k + 27, 1, 2);
		setBlock(world, i + 2, j + 17, k + 13, Blocks.log, 1);
		world.setBlockMetadataWithNotify(i + 2, j + 17, k + 13, 1, 2);
		setBlock(world, i + 2, j + 17, k + 14, Blocks.log, 1);
		world.setBlockMetadataWithNotify(i + 2, j + 17, k + 14, 1, 2);
		setBlock(world, i + 2, j + 17, k + 15, Blocks.log, 1);
		world.setBlockMetadataWithNotify(i + 2, j + 17, k + 15, 1, 2);
		setBlock(world, i + 2, j + 17, k + 16, Blocks.log, 1);
		world.setBlockMetadataWithNotify(i + 2, j + 17, k + 16, 1, 2);
		setBlock(world, i + 2, j + 17, k + 17, Blocks.log, 1);
		world.setBlockMetadataWithNotify(i + 2, j + 17, k + 17, 1, 2);
		setBlock(world, i + 2, j + 17, k + 18, Blocks.log, 1);
		world.setBlockMetadataWithNotify(i + 2, j + 17, k + 18, 1, 2);
		setBlock(world, i + 2, j + 17, k + 19, Blocks.log, 1);
		world.setBlockMetadataWithNotify(i + 2, j + 17, k + 19, 1, 2);
		setBlock(world, i + 2, j + 17, k + 20, Blocks.log, 1);
		world.setBlockMetadataWithNotify(i + 2, j + 17, k + 20, 1, 2);
		setBlock(world, i + 2, j + 17, k + 21, Blocks.log, 1);
		world.setBlockMetadataWithNotify(i + 2, j + 17, k + 21, 1, 2);
		setBlock(world, i + 2, j + 17, k + 22, Blocks.log, 1);
		world.setBlockMetadataWithNotify(i + 2, j + 17, k + 22, 1, 2);
		setBlock(world, i + 2, j + 17, k + 23, Blocks.log, 1);
		world.setBlockMetadataWithNotify(i + 2, j + 17, k + 23, 1, 2);
		setBlock(world, i + 2, j + 17, k + 24, Blocks.log, 1);
		world.setBlockMetadataWithNotify(i + 2, j + 17, k + 24, 1, 2);
		setBlock(world, i + 2, j + 17, k + 25, Blocks.log, 1);
		world.setBlockMetadataWithNotify(i + 2, j + 17, k + 25, 1, 2);
		setBlock(world, i + 2, j + 17, k + 26, Blocks.log, 1);
		world.setBlockMetadataWithNotify(i + 2, j + 17, k + 26, 1, 2);
		setBlock(world, i + 2, j + 17, k + 27, Blocks.log, 1);
		world.setBlockMetadataWithNotify(i + 2, j + 17, k + 27, 1, 2);
		setBlock(world, i + 2, j + 17, k + 28, Blocks.log, 1);
		world.setBlockMetadataWithNotify(i + 2, j + 17, k + 28, 1, 2);
		setBlock(world, i + 2, j + 17, k + 29, Blocks.log, 1);
		world.setBlockMetadataWithNotify(i + 2, j + 17, k + 29, 1, 2);
		setBlock(world, i + 2, j + 17, k + 30, Blocks.log, 1);
		world.setBlockMetadataWithNotify(i + 2, j + 17, k + 30, 1, 2);
		setBlock(world, i + 2, j + 18, k + 13, Blocks.log, 1);
		world.setBlockMetadataWithNotify(i + 2, j + 18, k + 13, 1, 2);
		setBlock(world, i + 2, j + 18, k + 14, Blocks.log, 1);
		world.setBlockMetadataWithNotify(i + 2, j + 18, k + 14, 1, 2);
		setBlock(world, i + 2, j + 18, k + 15, Blocks.log, 1);
		world.setBlockMetadataWithNotify(i + 2, j + 18, k + 15, 1, 2);
		setBlock(world, i + 2, j + 18, k + 16, Blocks.log, 1);
		world.setBlockMetadataWithNotify(i + 2, j + 18, k + 16, 1, 2);
		setBlock(world, i + 2, j + 18, k + 17, Blocks.log, 1);
		world.setBlockMetadataWithNotify(i + 2, j + 18, k + 17, 1, 2);
		setBlock(world, i + 2, j + 18, k + 18, Blocks.log, 1);
		world.setBlockMetadataWithNotify(i + 2, j + 18, k + 18, 1, 2);
		setBlock(world, i + 2, j + 18, k + 19, Blocks.log, 1);
		world.setBlockMetadataWithNotify(i + 2, j + 18, k + 19, 1, 2);
		setBlock(world, i + 2, j + 18, k + 20, Blocks.log, 1);
		world.setBlockMetadataWithNotify(i + 2, j + 18, k + 20, 1, 2);
		setBlock(world, i + 2, j + 18, k + 21, Blocks.log, 1);
		world.setBlockMetadataWithNotify(i + 2, j + 18, k + 21, 1, 2);
		setBlock(world, i + 2, j + 18, k + 22, Blocks.log, 1);
		world.setBlockMetadataWithNotify(i + 2, j + 18, k + 22, 1, 2);
		setBlock(world, i + 2, j + 18, k + 23, Blocks.log, 1);
		world.setBlockMetadataWithNotify(i + 2, j + 18, k + 23, 1, 2);
		setBlock(world, i + 2, j + 18, k + 24, Blocks.log, 1);
		world.setBlockMetadataWithNotify(i + 2, j + 18, k + 24, 1, 2);
		setBlock(world, i + 2, j + 18, k + 25, Blocks.log, 1);
		world.setBlockMetadataWithNotify(i + 2, j + 18, k + 25, 1, 2);
		setBlock(world, i + 2, j + 18, k + 26, Blocks.log, 1);
		world.setBlockMetadataWithNotify(i + 2, j + 18, k + 26, 1, 2);
		setBlock(world, i + 2, j + 18, k + 27, Blocks.log, 1);
		world.setBlockMetadataWithNotify(i + 2, j + 18, k + 27, 1, 2);
		setBlock(world, i + 2, j + 18, k + 28, Blocks.log, 1);
		world.setBlockMetadataWithNotify(i + 2, j + 18, k + 28, 1, 2);
		setBlock(world, i + 2, j + 18, k + 29, Blocks.log, 1);
		world.setBlockMetadataWithNotify(i + 2, j + 18, k + 29, 1, 2);
		setBlock(world, i + 2, j + 18, k + 30, Blocks.log, 1);
		world.setBlockMetadataWithNotify(i + 2, j + 18, k + 30, 1, 2);
		setBlock(world, i + 2, j + 18, k + 31, Blocks.log, 1);
		world.setBlockMetadataWithNotify(i + 2, j + 18, k + 31, 1, 2);
		setBlock(world, i + 2, j + 19, k + 12, Blocks.log, 1);
		world.setBlockMetadataWithNotify(i + 2, j + 19, k + 12, 1, 2);
		setBlock(world, i + 2, j + 19, k + 13, Blocks.log, 1);
		world.setBlockMetadataWithNotify(i + 2, j + 19, k + 13, 1, 2);
		setBlock(world, i + 2, j + 19, k + 14, Blocks.log, 1);
		world.setBlockMetadataWithNotify(i + 2, j + 19, k + 14, 1, 2);
		setBlock(world, i + 2, j + 19, k + 15, Blocks.log, 1);
		world.setBlockMetadataWithNotify(i + 2, j + 19, k + 15, 1, 2);
		setBlock(world, i + 2, j + 19, k + 16, Blocks.log, 1);
		world.setBlockMetadataWithNotify(i + 2, j + 19, k + 16, 1, 2);
		setBlock(world, i + 2, j + 19, k + 17, Blocks.log, 1);
		world.setBlockMetadataWithNotify(i + 2, j + 19, k + 17, 1, 2);
		setBlock(world, i + 2, j + 19, k + 18, Blocks.log, 1);
		world.setBlockMetadataWithNotify(i + 2, j + 19, k + 18, 1, 2);
		setBlock(world, i + 2, j + 19, k + 19, Blocks.log, 1);
		world.setBlockMetadataWithNotify(i + 2, j + 19, k + 19, 1, 2);
		setBlock(world, i + 2, j + 19, k + 20, Blocks.log, 1);
		world.setBlockMetadataWithNotify(i + 2, j + 19, k + 20, 1, 2);
		setBlock(world, i + 2, j + 19, k + 21, Blocks.log, 1);
		world.setBlockMetadataWithNotify(i + 2, j + 19, k + 21, 1, 2);
		setBlock(world, i + 2, j + 19, k + 22, Blocks.log, 1);
		world.setBlockMetadataWithNotify(i + 2, j + 19, k + 22, 1, 2);
		setBlock(world, i + 2, j + 19, k + 23, Blocks.log, 1);
		world.setBlockMetadataWithNotify(i + 2, j + 19, k + 23, 1, 2);
		setBlock(world, i + 2, j + 19, k + 24, Blocks.log, 1);
		world.setBlockMetadataWithNotify(i + 2, j + 19, k + 24, 1, 2);
		setBlock(world, i + 2, j + 19, k + 25, Blocks.log, 1);
		world.setBlockMetadataWithNotify(i + 2, j + 19, k + 25, 1, 2);
		setBlock(world, i + 2, j + 19, k + 26, Blocks.log, 1);
		world.setBlockMetadataWithNotify(i + 2, j + 19, k + 26, 1, 2);
		setBlock(world, i + 2, j + 19, k + 27, Blocks.log, 1);
		world.setBlockMetadataWithNotify(i + 2, j + 19, k + 27, 1, 2);
		setBlock(world, i + 2, j + 19, k + 28, Blocks.log, 1);
		world.setBlockMetadataWithNotify(i + 2, j + 19, k + 28, 1, 2);
		setBlock(world, i + 2, j + 19, k + 29, Blocks.log, 1);
		world.setBlockMetadataWithNotify(i + 2, j + 19, k + 29, 1, 2);
		setBlock(world, i + 2, j + 19, k + 30, Blocks.log, 1);
		world.setBlockMetadataWithNotify(i + 2, j + 19, k + 30, 1, 2);
		setBlock(world, i + 2, j + 19, k + 31, Blocks.log, 1);
		world.setBlockMetadataWithNotify(i + 2, j + 19, k + 31, 1, 2);
		setBlock(world, i + 2, j + 20, k + 12, Blocks.log, 1);
		world.setBlockMetadataWithNotify(i + 2, j + 20, k + 12, 1, 2);
		setBlock(world, i + 2, j + 20, k + 13, Blocks.log, 1);
		world.setBlockMetadataWithNotify(i + 2, j + 20, k + 13, 1, 2);
		setBlock(world, i + 2, j + 20, k + 14, Blocks.planks, 5);
		world.setBlockMetadataWithNotify(i + 2, j + 20, k + 14, 5, 2);
		setBlock(world, i + 2, j + 20, k + 15, Blocks.planks, 5);
		world.setBlockMetadataWithNotify(i + 2, j + 20, k + 15, 5, 2);
		setBlock(world, i + 2, j + 20, k + 16, Blocks.planks, 5);
		world.setBlockMetadataWithNotify(i + 2, j + 20, k + 16, 5, 2);
		setBlock(world, i + 2, j + 20, k + 17, Blocks.planks, 5);
		world.setBlockMetadataWithNotify(i + 2, j + 20, k + 17, 5, 2);
		setBlock(world, i + 2, j + 20, k + 18, Blocks.planks, 5);
		world.setBlockMetadataWithNotify(i + 2, j + 20, k + 18, 5, 2);
		setBlock(world, i + 2, j + 20, k + 19, Blocks.planks, 5);
		world.setBlockMetadataWithNotify(i + 2, j + 20, k + 19, 5, 2);
		setBlock(world, i + 2, j + 20, k + 20, Blocks.log, 1);
		world.setBlockMetadataWithNotify(i + 2, j + 20, k + 20, 1, 2);
		setBlock(world, i + 2, j + 20, k + 21, Blocks.planks, 5);
		world.setBlockMetadataWithNotify(i + 2, j + 20, k + 21, 5, 2);
		setBlock(world, i + 2, j + 20, k + 22, Blocks.log, 1);
		world.setBlockMetadataWithNotify(i + 2, j + 20, k + 22, 1, 2);
		setBlock(world, i + 2, j + 20, k + 23, Blocks.log, 1);
		world.setBlockMetadataWithNotify(i + 2, j + 20, k + 23, 1, 2);
		setBlock(world, i + 2, j + 20, k + 24, Blocks.log, 1);
		world.setBlockMetadataWithNotify(i + 2, j + 20, k + 24, 1, 2);
		setBlock(world, i + 2, j + 20, k + 25, Blocks.log, 1);
		world.setBlockMetadataWithNotify(i + 2, j + 20, k + 25, 1, 2);
		setBlock(world, i + 2, j + 20, k + 26, Blocks.planks, 5);
		world.setBlockMetadataWithNotify(i + 2, j + 20, k + 26, 5, 2);
		setBlock(world, i + 2, j + 20, k + 27, Blocks.log, 1);
		world.setBlockMetadataWithNotify(i + 2, j + 20, k + 27, 1, 2);
		setBlock(world, i + 2, j + 20, k + 28, Blocks.planks, 5);
		world.setBlockMetadataWithNotify(i + 2, j + 20, k + 28, 5, 2);
		setBlock(world, i + 2, j + 20, k + 29, Blocks.planks, 5);
		world.setBlockMetadataWithNotify(i + 2, j + 20, k + 29, 5, 2);
		setBlock(world, i + 2, j + 20, k + 30, Blocks.planks, 5);
		world.setBlockMetadataWithNotify(i + 2, j + 20, k + 30, 5, 2);
		setBlock(world, i + 2, j + 20, k + 31, Blocks.planks, 5);
		world.setBlockMetadataWithNotify(i + 2, j + 20, k + 31, 5, 2);
		setBlock(world, i + 2, j + 21, k + 22, Blocks.spruce_stairs, 2);
		world.setBlockMetadataWithNotify(i + 2, j + 21, k + 22, 2, 2);
		setBlock(world, i + 2, j + 21, k + 23, Blocks.log, 1);
		world.setBlockMetadataWithNotify(i + 2, j + 21, k + 23, 1, 2);
		setBlock(world, i + 2, j + 21, k + 24, Blocks.log, 1);
		world.setBlockMetadataWithNotify(i + 2, j + 21, k + 24, 1, 2);
		setBlock(world, i + 2, j + 21, k + 25, Blocks.spruce_stairs, 3);
		world.setBlockMetadataWithNotify(i + 2, j + 21, k + 25, 3, 2);
		setBlock(world, i + 2, j + 22, k + 23, Blocks.log, 1);
		world.setBlockMetadataWithNotify(i + 2, j + 22, k + 23, 1, 2);
		setBlock(world, i + 2, j + 22, k + 24, Blocks.log, 1);
		world.setBlockMetadataWithNotify(i + 2, j + 22, k + 24, 1, 2);
		setBlock(world, i + 2, j + 23, k + 22, Blocks.torch, 4);
		world.setBlockMetadataWithNotify(i + 2, j + 23, k + 22, 4, 2);
		setBlock(world, i + 2, j + 23, k + 23, Blocks.log, 1);
		world.setBlockMetadataWithNotify(i + 2, j + 23, k + 23, 1, 2);
		setBlock(world, i + 2, j + 23, k + 24, Blocks.log, 1);
		world.setBlockMetadataWithNotify(i + 2, j + 23, k + 24, 1, 2);
		setBlock(world, i + 2, j + 24, k + 23, Blocks.log, 1);
		world.setBlockMetadataWithNotify(i + 2, j + 24, k + 23, 1, 2);
		setBlock(world, i + 2, j + 24, k + 24, Blocks.log, 1);
		world.setBlockMetadataWithNotify(i + 2, j + 24, k + 24, 1, 2);
		setBlock(world, i + 2, j + 24, k + 25, Blocks.torch, 3);
		world.setBlockMetadataWithNotify(i + 2, j + 24, k + 25, 3, 2);
		setBlock(world, i + 2, j + 25, k + 10, Blocks.log, 1);
		world.setBlockMetadataWithNotify(i + 2, j + 25, k + 10, 1, 2);
		setBlock(world, i + 2, j + 25, k + 11, Blocks.log, 1);
		world.setBlockMetadataWithNotify(i + 2, j + 25, k + 11, 1, 2);
		setBlock(world, i + 2, j + 25, k + 12, Blocks.log, 1);
		world.setBlockMetadataWithNotify(i + 2, j + 25, k + 12, 1, 2);
		setBlock(world, i + 2, j + 25, k + 13, Blocks.log, 1);
		world.setBlockMetadataWithNotify(i + 2, j + 25, k + 13, 1, 2);
		setBlock(world, i + 2, j + 25, k + 14, Blocks.log, 1);
		world.setBlockMetadataWithNotify(i + 2, j + 25, k + 14, 1, 2);
		setBlock(world, i + 2, j + 25, k + 23, Blocks.log, 1);
		world.setBlockMetadataWithNotify(i + 2, j + 25, k + 23, 1, 2);
		setBlock(world, i + 2, j + 25, k + 24, Blocks.log, 1);
		world.setBlockMetadataWithNotify(i + 2, j + 25, k + 24, 1, 2);
		setBlock(world, i + 2, j + 26, k + 11, Blocks.log, 1);
		world.setBlockMetadataWithNotify(i + 2, j + 26, k + 11, 1, 2);
		setBlock(world, i + 2, j + 26, k + 12, Blocks.log, 1);
		world.setBlockMetadataWithNotify(i + 2, j + 26, k + 12, 1, 2);
		setBlock(world, i + 2, j + 26, k + 13, Blocks.log, 1);
		world.setBlockMetadataWithNotify(i + 2, j + 26, k + 13, 1, 2);
		setBlock(world, i + 2, j + 26, k + 14, Blocks.log, 1);
		world.setBlockMetadataWithNotify(i + 2, j + 26, k + 14, 1, 2);
		setBlock(world, i + 2, j + 26, k + 15, Blocks.log, 1);
		world.setBlockMetadataWithNotify(i + 2, j + 26, k + 15, 1, 2);
		setBlock(world, i + 2, j + 26, k + 23, Blocks.log, 1);
		world.setBlockMetadataWithNotify(i + 2, j + 26, k + 23, 1, 2);
		setBlock(world, i + 2, j + 26, k + 24, Blocks.log, 1);
		world.setBlockMetadataWithNotify(i + 2, j + 26, k + 24, 1, 2);
		setBlock(world, i + 2, j + 27, k + 13, Blocks.log, 1);
		world.setBlockMetadataWithNotify(i + 2, j + 27, k + 13, 1, 2);
		setBlock(world, i + 2, j + 27, k + 14, Blocks.log, 1);
		world.setBlockMetadataWithNotify(i + 2, j + 27, k + 14, 1, 2);
		setBlock(world, i + 2, j + 27, k + 15, Blocks.log, 1);
		world.setBlockMetadataWithNotify(i + 2, j + 27, k + 15, 1, 2);
		setBlock(world, i + 2, j + 27, k + 16, Blocks.log, 1);
		world.setBlockMetadataWithNotify(i + 2, j + 27, k + 16, 1, 2);
		setBlock(world, i + 2, j + 27, k + 22, Blocks.log, 1);
		world.setBlockMetadataWithNotify(i + 2, j + 27, k + 22, 1, 2);
		setBlock(world, i + 2, j + 27, k + 23, Blocks.log, 1);
		world.setBlockMetadataWithNotify(i + 2, j + 27, k + 23, 1, 2);
		setBlock(world, i + 2, j + 27, k + 24, Blocks.log, 1);
		world.setBlockMetadataWithNotify(i + 2, j + 27, k + 24, 1, 2);
		setBlock(world, i + 2, j + 27, k + 25, Blocks.log, 1);
		world.setBlockMetadataWithNotify(i + 2, j + 27, k + 25, 1, 2);
		setBlock(world, i + 2, j + 27, k + 31, Blocks.log, 1);
		world.setBlockMetadataWithNotify(i + 2, j + 27, k + 31, 1, 2);
		setBlock(world, i + 2, j + 28, k + 17, Blocks.log, 1);
		world.setBlockMetadataWithNotify(i + 2, j + 28, k + 17, 1, 2);
		setBlock(world, i + 2, j + 28, k + 18, Blocks.log, 1);
		world.setBlockMetadataWithNotify(i + 2, j + 28, k + 18, 1, 2);
		setBlock(world, i + 2, j + 28, k + 19, Blocks.log, 1);
		world.setBlockMetadataWithNotify(i + 2, j + 28, k + 19, 1, 2);
		setBlock(world, i + 2, j + 28, k + 20, Blocks.log, 1);
		world.setBlockMetadataWithNotify(i + 2, j + 28, k + 20, 1, 2);
		setBlock(world, i + 2, j + 28, k + 21, Blocks.log, 1);
		world.setBlockMetadataWithNotify(i + 2, j + 28, k + 21, 1, 2);
		setBlock(world, i + 2, j + 28, k + 22, Blocks.log, 1);
		world.setBlockMetadataWithNotify(i + 2, j + 28, k + 22, 1, 2);
		setBlock(world, i + 2, j + 28, k + 23, Blocks.log, 1);
		world.setBlockMetadataWithNotify(i + 2, j + 28, k + 23, 1, 2);
		setBlock(world, i + 2, j + 28, k + 24, Blocks.log, 1);
		world.setBlockMetadataWithNotify(i + 2, j + 28, k + 24, 1, 2);
		setBlock(world, i + 2, j + 28, k + 25, Blocks.log, 1);
		world.setBlockMetadataWithNotify(i + 2, j + 28, k + 25, 1, 2);
		setBlock(world, i + 2, j + 28, k + 26, Blocks.log, 1);
		world.setBlockMetadataWithNotify(i + 2, j + 28, k + 26, 1, 2);
		setBlock(world, i + 2, j + 28, k + 27, Blocks.log, 1);
		world.setBlockMetadataWithNotify(i + 2, j + 28, k + 27, 1, 2);
		setBlock(world, i + 2, j + 28, k + 28, Blocks.log, 1);
		world.setBlockMetadataWithNotify(i + 2, j + 28, k + 28, 1, 2);
		setBlock(world, i + 2, j + 28, k + 29, Blocks.log, 1);
		world.setBlockMetadataWithNotify(i + 2, j + 28, k + 29, 1, 2);
		setBlock(world, i + 2, j + 28, k + 30, Blocks.log, 1);
		world.setBlockMetadataWithNotify(i + 2, j + 28, k + 30, 1, 2);
		setBlock(world, i + 2, j + 31, k + 2, Blocks.leaves, 7);
		world.setBlockMetadataWithNotify(i + 2, j + 31, k + 2, 7, 2);
		setBlock(world, i + 2, j + 31, k + 3, Blocks.leaves, 7);
		world.setBlockMetadataWithNotify(i + 2, j + 31, k + 3, 7, 2);
		setBlock(world, i + 2, j + 31, k + 4, Blocks.leaves, 7);
		world.setBlockMetadataWithNotify(i + 2, j + 31, k + 4, 7, 2);
		setBlock(world, i + 2, j + 32, k + 3, Blocks.leaves, 7);
		world.setBlockMetadataWithNotify(i + 2, j + 32, k + 3, 7, 2);
		setBlock(world, i + 2, j + 59, k + 25, Blocks.planks, 5);
		world.setBlockMetadataWithNotify(i + 2, j + 59, k + 25, 5, 2);
		setBlock(world, i + 2, j + 59, k + 26, Blocks.planks, 5);
		world.setBlockMetadataWithNotify(i + 2, j + 59, k + 26, 5, 2);
		setBlock(world, i + 2, j + 59, k + 27, Blocks.planks, 5);
		world.setBlockMetadataWithNotify(i + 2, j + 59, k + 27, 5, 2);
		setBlock(world, i + 2, j + 59, k + 28, Blocks.planks, 5);
		world.setBlockMetadataWithNotify(i + 2, j + 59, k + 28, 5, 2);
		setBlock(world, i + 2, j + 59, k + 29, Blocks.planks, 5);
		world.setBlockMetadataWithNotify(i + 2, j + 59, k + 29, 5, 2);
		setBlock(world, i + 2, j + 59, k + 30, Blocks.planks, 5);
		world.setBlockMetadataWithNotify(i + 2, j + 59, k + 30, 5, 2);
		setBlock(world, i + 2, j + 60, k + 25, Blocks.planks, 5);
		world.setBlockMetadataWithNotify(i + 2, j + 60, k + 25, 5, 2);
		setBlock(world, i + 2, j + 60, k + 26, Blocks.planks, 5);
		world.setBlockMetadataWithNotify(i + 2, j + 60, k + 26, 5, 2);
		setBlock(world, i + 2, j + 60, k + 27, Blocks.planks, 5);
		world.setBlockMetadataWithNotify(i + 2, j + 60, k + 27, 5, 2);
		setBlock(world, i + 2, j + 60, k + 28, Blocks.planks, 5);
		world.setBlockMetadataWithNotify(i + 2, j + 60, k + 28, 5, 2);
		setBlock(world, i + 2, j + 60, k + 29, Blocks.planks, 5);
		world.setBlockMetadataWithNotify(i + 2, j + 60, k + 29, 5, 2);
		setBlock(world, i + 2, j + 60, k + 30, Blocks.planks, 5);
		world.setBlockMetadataWithNotify(i + 2, j + 60, k + 30, 5, 2);
		setBlock(world, i + 2, j + 61, k + 25, Blocks.spruce_stairs, 1);
		world.setBlockMetadataWithNotify(i + 2, j + 61, k + 25, 1, 2);
		setBlock(world, i + 2, j + 61, k + 26, Blocks.spruce_stairs, 1);
		world.setBlockMetadataWithNotify(i + 2, j + 61, k + 26, 1, 2);
		setBlock(world, i + 2, j + 61, k + 27, Blocks.spruce_stairs, 1);
		world.setBlockMetadataWithNotify(i + 2, j + 61, k + 27, 1, 2);
		setBlock(world, i + 2, j + 61, k + 28, Blocks.spruce_stairs, 1);
		world.setBlockMetadataWithNotify(i + 2, j + 61, k + 28, 1, 2);
		setBlock(world, i + 2, j + 61, k + 29, Blocks.spruce_stairs, 1);
		world.setBlockMetadataWithNotify(i + 2, j + 61, k + 29, 1, 2);
		setBlock(world, i + 2, j + 61, k + 30, Blocks.spruce_stairs, 1);
		world.setBlockMetadataWithNotify(i + 2, j + 61, k + 30, 1, 2);
		setBlock(world, i + 3, j + 1, k + 28, Blocks.planks, 5);
		world.setBlockMetadataWithNotify(i + 3, j + 1, k + 28, 5, 2);
		setBlock(world, i + 3, j + 1, k + 29, Blocks.planks, 5);
		world.setBlockMetadataWithNotify(i + 3, j + 1, k + 29, 5, 2);
		setBlock(world, i + 3, j + 2, k + 26, Blocks.planks, 5);
		world.setBlockMetadataWithNotify(i + 3, j + 2, k + 26, 5, 2);
		setBlock(world, i + 3, j + 2, k + 27, Blocks.planks, 5);
		world.setBlockMetadataWithNotify(i + 3, j + 2, k + 27, 5, 2);
		setBlock(world, i + 3, j + 2, k + 28, Blocks.planks, 5);
		world.setBlockMetadataWithNotify(i + 3, j + 2, k + 28, 5, 2);
		setBlock(world, i + 3, j + 2, k + 29, Blocks.planks, 5);
		world.setBlockMetadataWithNotify(i + 3, j + 2, k + 29, 5, 2);
		setBlock(world, i + 3, j + 3, k + 25, Blocks.planks, 5);
		world.setBlockMetadataWithNotify(i + 3, j + 3, k + 25, 5, 2);
		setBlock(world, i + 3, j + 3, k + 26, Blocks.planks, 5);
		world.setBlockMetadataWithNotify(i + 3, j + 3, k + 26, 5, 2);
		setBlock(world, i + 3, j + 3, k + 27, Blocks.spruce_stairs, 3);
		world.setBlockMetadataWithNotify(i + 3, j + 3, k + 27, 3, 2);
		setBlock(world, i + 3, j + 4, k + 24, Blocks.planks, 5);
		world.setBlockMetadataWithNotify(i + 3, j + 4, k + 24, 5, 2);
		setBlock(world, i + 3, j + 4, k + 25, Blocks.planks, 5);
		world.setBlockMetadataWithNotify(i + 3, j + 4, k + 25, 5, 2);
		setBlock(world, i + 3, j + 4, k + 26, Blocks.spruce_stairs, 3);
		world.setBlockMetadataWithNotify(i + 3, j + 4, k + 26, 3, 2);
		setBlock(world, i + 3, j + 5, k + 23, Blocks.planks, 5);
		world.setBlockMetadataWithNotify(i + 3, j + 5, k + 23, 5, 2);
		setBlock(world, i + 3, j + 5, k + 24, Blocks.planks, 5);
		world.setBlockMetadataWithNotify(i + 3, j + 5, k + 24, 5, 2);
		setBlock(world, i + 3, j + 5, k + 25, Blocks.spruce_stairs, 3);
		world.setBlockMetadataWithNotify(i + 3, j + 5, k + 25, 3, 2);
		setBlock(world, i + 3, j + 8, k + 25, Blocks.torch, 1);
		world.setBlockMetadataWithNotify(i + 3, j + 8, k + 25, 1, 2);
		setBlock(world, i + 3, j + 10, k + 28, Blocks.planks, 5);
		world.setBlockMetadataWithNotify(i + 3, j + 10, k + 28, 5, 2);
		setBlock(world, i + 3, j + 10, k + 29, Blocks.planks, 5);
		world.setBlockMetadataWithNotify(i + 3, j + 10, k + 29, 5, 2);
		setBlock(world, i + 3, j + 11, k + 28, Blocks.planks, 5);
		world.setBlockMetadataWithNotify(i + 3, j + 11, k + 28, 5, 2);
		setBlock(world, i + 3, j + 11, k + 29, Blocks.planks, 5);
		world.setBlockMetadataWithNotify(i + 3, j + 11, k + 29, 5, 2);
		setBlock(world, i + 3, j + 12, k + 19, Blocks.vine, 1);
		world.setBlockMetadataWithNotify(i + 3, j + 12, k + 19, 1, 2);
		setBlock(world, i + 3, j + 13, k + 19, Blocks.vine, 7);
		world.setBlockMetadataWithNotify(i + 3, j + 13, k + 19, 7, 2);
		setBlock(world, i + 3, j + 13, k + 20, Blocks.vine, 14);
		world.setBlockMetadataWithNotify(i + 3, j + 13, k + 20, 14, 2);
		setBlock(world, i + 3, j + 13, k + 23, Blocks.vine, 14);
		world.setBlockMetadataWithNotify(i + 3, j + 13, k + 23, 14, 2);
		setBlock(world, i + 3, j + 13, k + 24, Blocks.vine, 14);
		world.setBlockMetadataWithNotify(i + 3, j + 13, k + 24, 14, 2);
		setBlock(world, i + 3, j + 14, k + 17, Blocks.vine, 15);
		world.setBlockMetadataWithNotify(i + 3, j + 14, k + 17, 15, 2);
		setBlock(world, i + 3, j + 14, k + 18, Blocks.vine, 11);
		world.setBlockMetadataWithNotify(i + 3, j + 14, k + 18, 11, 2);
		setBlock(world, i + 3, j + 14, k + 19, Blocks.vine, 15);
		world.setBlockMetadataWithNotify(i + 3, j + 14, k + 19, 15, 2);
		setBlock(world, i + 3, j + 14, k + 20, Blocks.vine, 15);
		world.setBlockMetadataWithNotify(i + 3, j + 14, k + 20, 15, 2);
		setBlock(world, i + 3, j + 14, k + 21, Blocks.vine, 15);
		world.setBlockMetadataWithNotify(i + 3, j + 14, k + 21, 15, 2);
		setBlock(world, i + 3, j + 14, k + 23, Blocks.vine, 15);
		world.setBlockMetadataWithNotify(i + 3, j + 14, k + 23, 15, 2);
		setBlock(world, i + 3, j + 14, k + 24, Blocks.vine, 15);
		world.setBlockMetadataWithNotify(i + 3, j + 14, k + 24, 15, 2);
		setBlock(world, i + 3, j + 15, k + 17, Blocks.vine, 15);
		world.setBlockMetadataWithNotify(i + 3, j + 15, k + 17, 15, 2);
		setBlock(world, i + 3, j + 15, k + 18, Blocks.vine, 15);
		world.setBlockMetadataWithNotify(i + 3, j + 15, k + 18, 15, 2);
		setBlock(world, i + 3, j + 15, k + 19, Blocks.vine, 15);
		world.setBlockMetadataWithNotify(i + 3, j + 15, k + 19, 15, 2);
		setBlock(world, i + 3, j + 15, k + 20, Blocks.log, 1);
		world.setBlockMetadataWithNotify(i + 3, j + 15, k + 20, 1, 2);
		setBlock(world, i + 3, j + 15, k + 21, Blocks.log, 1);
		world.setBlockMetadataWithNotify(i + 3, j + 15, k + 21, 1, 2);
		setBlock(world, i + 3, j + 15, k + 22, Blocks.log, 1);
		world.setBlockMetadataWithNotify(i + 3, j + 15, k + 22, 1, 2);
		setBlock(world, i + 3, j + 15, k + 23, Blocks.vine, 15);
		world.setBlockMetadataWithNotify(i + 3, j + 15, k + 23, 15, 2);
		setBlock(world, i + 3, j + 15, k + 24, Blocks.log, 1);
		world.setBlockMetadataWithNotify(i + 3, j + 15, k + 24, 1, 2);
		setBlock(world, i + 3, j + 15, k + 25, Blocks.log, 1);
		world.setBlockMetadataWithNotify(i + 3, j + 15, k + 25, 1, 2);
		setBlock(world, i + 3, j + 15, k + 26, Blocks.log, 1);
		world.setBlockMetadataWithNotify(i + 3, j + 15, k + 26, 1, 2);
		setBlock(world, i + 3, j + 15, k + 27, Blocks.log, 1);
		world.setBlockMetadataWithNotify(i + 3, j + 15, k + 27, 1, 2);
		setBlock(world, i + 3, j + 16, k + 17, Blocks.vine, 15);
		world.setBlockMetadataWithNotify(i + 3, j + 16, k + 17, 15, 2);
		setBlock(world, i + 3, j + 16, k + 18, Blocks.log, 1);
		world.setBlockMetadataWithNotify(i + 3, j + 16, k + 18, 1, 2);
		setBlock(world, i + 3, j + 16, k + 19, Blocks.vine, 15);
		world.setBlockMetadataWithNotify(i + 3, j + 16, k + 19, 15, 2);
		setBlock(world, i + 3, j + 16, k + 20, Blocks.log, 1);
		world.setBlockMetadataWithNotify(i + 3, j + 16, k + 20, 1, 2);
		setBlock(world, i + 3, j + 16, k + 21, Blocks.log, 1);
		world.setBlockMetadataWithNotify(i + 3, j + 16, k + 21, 1, 2);
		setBlock(world, i + 3, j + 16, k + 22, Blocks.log, 1);
		world.setBlockMetadataWithNotify(i + 3, j + 16, k + 22, 1, 2);
		setBlock(world, i + 3, j + 16, k + 23, Blocks.log, 1);
		world.setBlockMetadataWithNotify(i + 3, j + 16, k + 23, 1, 2);
		setBlock(world, i + 3, j + 16, k + 24, Blocks.log, 1);
		world.setBlockMetadataWithNotify(i + 3, j + 16, k + 24, 1, 2);
		setBlock(world, i + 3, j + 16, k + 25, Blocks.log, 1);
		world.setBlockMetadataWithNotify(i + 3, j + 16, k + 25, 1, 2);
		setBlock(world, i + 3, j + 16, k + 26, Blocks.log, 1);
		world.setBlockMetadataWithNotify(i + 3, j + 16, k + 26, 1, 2);
		setBlock(world, i + 3, j + 16, k + 27, Blocks.log, 1);
		world.setBlockMetadataWithNotify(i + 3, j + 16, k + 27, 1, 2);
		setBlock(world, i + 3, j + 17, k + 13, Blocks.log, 1);
		world.setBlockMetadataWithNotify(i + 3, j + 17, k + 13, 1, 2);
		setBlock(world, i + 3, j + 17, k + 14, Blocks.log, 1);
		world.setBlockMetadataWithNotify(i + 3, j + 17, k + 14, 1, 2);
		setBlock(world, i + 3, j + 17, k + 15, Blocks.log, 1);
		world.setBlockMetadataWithNotify(i + 3, j + 17, k + 15, 1, 2);
		setBlock(world, i + 3, j + 17, k + 16, Blocks.log, 1);
		world.setBlockMetadataWithNotify(i + 3, j + 17, k + 16, 1, 2);
		setBlock(world, i + 3, j + 17, k + 17, Blocks.log, 1);
		world.setBlockMetadataWithNotify(i + 3, j + 17, k + 17, 1, 2);
		setBlock(world, i + 3, j + 17, k + 18, Blocks.log, 1);
		world.setBlockMetadataWithNotify(i + 3, j + 17, k + 18, 1, 2);
		setBlock(world, i + 3, j + 17, k + 19, Blocks.log, 1);
		world.setBlockMetadataWithNotify(i + 3, j + 17, k + 19, 1, 2);
		setBlock(world, i + 3, j + 17, k + 20, Blocks.log, 1);
		world.setBlockMetadataWithNotify(i + 3, j + 17, k + 20, 1, 2);
		setBlock(world, i + 3, j + 17, k + 21, Blocks.log, 1);
		world.setBlockMetadataWithNotify(i + 3, j + 17, k + 21, 1, 2);
		setBlock(world, i + 3, j + 17, k + 22, Blocks.log, 1);
		world.setBlockMetadataWithNotify(i + 3, j + 17, k + 22, 1, 2);
		setBlock(world, i + 3, j + 17, k + 23, Blocks.log, 1);
		world.setBlockMetadataWithNotify(i + 3, j + 17, k + 23, 1, 2);
		setBlock(world, i + 3, j + 17, k + 24, Blocks.log, 1);
		world.setBlockMetadataWithNotify(i + 3, j + 17, k + 24, 1, 2);
		setBlock(world, i + 3, j + 17, k + 25, Blocks.log, 1);
		world.setBlockMetadataWithNotify(i + 3, j + 17, k + 25, 1, 2);
		setBlock(world, i + 3, j + 17, k + 26, Blocks.log, 1);
		world.setBlockMetadataWithNotify(i + 3, j + 17, k + 26, 1, 2);
		setBlock(world, i + 3, j + 17, k + 27, Blocks.log, 1);
		world.setBlockMetadataWithNotify(i + 3, j + 17, k + 27, 1, 2);
		setBlock(world, i + 3, j + 17, k + 29, Blocks.log, 1);
		world.setBlockMetadataWithNotify(i + 3, j + 17, k + 29, 1, 2);
		setBlock(world, i + 3, j + 17, k + 30, Blocks.log, 1);
		world.setBlockMetadataWithNotify(i + 3, j + 17, k + 30, 1, 2);
		setBlock(world, i + 3, j + 18, k + 13, Blocks.log, 1);
		world.setBlockMetadataWithNotify(i + 3, j + 18, k + 13, 1, 2);
		setBlock(world, i + 3, j + 18, k + 14, Blocks.log, 1);
		world.setBlockMetadataWithNotify(i + 3, j + 18, k + 14, 1, 2);
		setBlock(world, i + 3, j + 18, k + 15, Blocks.log, 1);
		world.setBlockMetadataWithNotify(i + 3, j + 18, k + 15, 1, 2);
		setBlock(world, i + 3, j + 18, k + 16, Blocks.log, 1);
		world.setBlockMetadataWithNotify(i + 3, j + 18, k + 16, 1, 2);
		setBlock(world, i + 3, j + 18, k + 17, Blocks.log, 1);
		world.setBlockMetadataWithNotify(i + 3, j + 18, k + 17, 1, 2);
		setBlock(world, i + 3, j + 18, k + 18, Blocks.log, 1);
		world.setBlockMetadataWithNotify(i + 3, j + 18, k + 18, 1, 2);
		setBlock(world, i + 3, j + 18, k + 19, Blocks.log, 1);
		world.setBlockMetadataWithNotify(i + 3, j + 18, k + 19, 1, 2);
		setBlock(world, i + 3, j + 18, k + 20, Blocks.log, 1);
		world.setBlockMetadataWithNotify(i + 3, j + 18, k + 20, 1, 2);
		setBlock(world, i + 3, j + 18, k + 21, Blocks.log, 1);
