/*      */package com.parzivail.pswm.world.gen.wookietree;

/*      */
/*      */import cpw.mods.fml.common.IWorldGenerator;
/*      */
import java.util.Random;
/*      */
import net.minecraft.block.Block;
/*      */
import net.minecraft.init.Blocks;
/*      */
import net.minecraft.world.World;
/*      */
import net.minecraft.world.chunk.IChunkProvider;
/*      */
import net.minecraft.world.gen.feature.WorldGenerator;

/*      */
/*      */public class WT_30 extends WorldGenerator implements IWorldGenerator
/*      */
{
	/*      */protected Block[] getValidSpawnBlocks()
	/*      */
	{
		return new Block[0];
		/*      */}

	/*      */
	/*      */public boolean locationIsValidSpawn(World world, int i, int j, int k)
	/*      */
	{
		int distanceToAir = 0;
		Block check = world.getBlock(i, j, k);
		/*      */
		while (check != Blocks.air)
		{
			if (distanceToAir > 3) { return false;
			/*      */}
			/*      */
			distanceToAir++;
			check = world.getBlock(i, j + distanceToAir, k);
			/*      */}
		/*      */
		j += distanceToAir - 1;
		/*      */
		Block block = world.getBlock(i, j, k);
		Block blockAbove = world.getBlock(i, j + 1, k);
		Block blockBelow = world.getBlock(i, j - 1, k);
		/*      */
		for (Block x : getValidSpawnBlocks())
		{
			if (blockAbove != Blocks.air) { return false;
			/*      */}
			if (block == x) return true;
			if ((block == Blocks.snow) && (blockBelow == x)) { return true;
			/*      */}
			/*      */}
		/*      */
		return false;
		/*      */}

	/*      */
	/*      */
	/*      */
	/*      */public void generate(Random random, int chunkX, int chunkZ, World world, IChunkProvider chunkGenerator, IChunkProvider chunkProvider)
	{
	}

	/*      */
	/*      */
	/*      */public void setBlock(World world, int x, int y, int z, Block block, int metadata)
	/*      */
	{
		world.setBlock(x, y, z, block, metadata, 2);
		/*      */}

	/*      */
	/*      */public boolean generate(World world, Random rand, int i, int j, int k)
	/*      */
	{
		k -= 10;
		i -= 10;
		/*      */
		setBlock(world, i + 29, j + 47, k + 26, Blocks.fence, 0);
		setBlock(world, i + 30, j + 47, k + 23, Blocks.fence, 0);
		setBlock(world, i + 30, j + 47, k + 24, Blocks.fence, 0);
		setBlock(world, i + 30, j + 47, k + 25, Blocks.fence, 0);
		setBlock(world, i + 30, j + 47, k + 26, Blocks.fence, 0);
		setBlock(world, i + 31, j + 47, k + 21, Blocks.fence, 0);
		setBlock(world, i + 31, j + 47, k + 22, Blocks.fence, 0);
		setBlock(world, i + 31, j + 47, k + 23, Blocks.fence, 0);
		setBlock(world, i + 1, j + 27, k + 28, Blocks.leaves, 7);
		world.setBlockMetadataWithNotify(i + 1, j + 27, k + 28, 7, 2);
		setBlock(world, i + 1, j + 27, k + 29, Blocks.leaves, 7);
		world.setBlockMetadataWithNotify(i + 1, j + 27, k + 29, 7, 2);
		setBlock(world, i + 1, j + 27, k + 30, Blocks.leaves, 7);
		world.setBlockMetadataWithNotify(i + 1, j + 27, k + 30, 7, 2);
		setBlock(world, i + 1, j + 28, k + 29, Blocks.leaves, 7);
		world.setBlockMetadataWithNotify(i + 1, j + 28, k + 29, 7, 2);
		setBlock(world, i + 2, j + 27, k + 27, Blocks.leaves, 7);
		world.setBlockMetadataWithNotify(i + 2, j + 27, k + 27, 7, 2);
		setBlock(world, i + 2, j + 27, k + 28, Blocks.leaves, 7);
		world.setBlockMetadataWithNotify(i + 2, j + 27, k + 28, 7, 2);
		setBlock(world, i + 2, j + 27, k + 29, Blocks.leaves, 7);
		world.setBlockMetadataWithNotify(i + 2, j + 27, k + 29, 7, 2);
		setBlock(world, i + 2, j + 27, k + 30, Blocks.leaves, 7);
		world.setBlockMetadataWithNotify(i + 2, j + 27, k + 30, 7, 2);
		setBlock(world, i + 2, j + 27, k + 31, Blocks.leaves, 7);
		world.setBlockMetadataWithNotify(i + 2, j + 27, k + 31, 7, 2);
		setBlock(world, i + 2, j + 28, k + 28, Blocks.leaves, 7);
		world.setBlockMetadataWithNotify(i + 2, j + 28, k + 28, 7, 2);
		setBlock(world, i + 2, j + 28, k + 29, Blocks.leaves, 7);
		world.setBlockMetadataWithNotify(i + 2, j + 28, k + 29, 7, 2);
		setBlock(world, i + 2, j + 28, k + 30, Blocks.leaves, 7);
		world.setBlockMetadataWithNotify(i + 2, j + 28, k + 30, 7, 2);
		setBlock(world, i + 2, j + 29, k + 29, Blocks.leaves, 7);
		world.setBlockMetadataWithNotify(i + 2, j + 29, k + 29, 7, 2);
		setBlock(world, i + 3, j + 23, k + 23, Blocks.leaves, 7);
		world.setBlockMetadataWithNotify(i + 3, j + 23, k + 23, 7, 2);
		setBlock(world, i + 3, j + 23, k + 24, Blocks.leaves, 7);
		world.setBlockMetadataWithNotify(i + 3, j + 23, k + 24, 7, 2);
		setBlock(world, i + 3, j + 23, k + 25, Blocks.leaves, 7);
		world.setBlockMetadataWithNotify(i + 3, j + 23, k + 25, 7, 2);
		setBlock(world, i + 3, j + 24, k + 24, Blocks.leaves, 7);
		world.setBlockMetadataWithNotify(i + 3, j + 24, k + 24, 7, 2);
		setBlock(world, i + 3, j + 27, k + 27, Blocks.leaves, 7);
		world.setBlockMetadataWithNotify(i + 3, j + 27, k + 27, 7, 2);
		setBlock(world, i + 3, j + 27, k + 28, Blocks.leaves, 7);
		world.setBlockMetadataWithNotify(i + 3, j + 27, k + 28, 7, 2);
		setBlock(world, i + 3, j + 27, k + 29, Blocks.log, 3);
		world.setBlockMetadataWithNotify(i + 3, j + 27, k + 29, 3, 2);
		setBlock(world, i + 3, j + 27, k + 30, Blocks.leaves, 7);
		world.setBlockMetadataWithNotify(i + 3, j + 27, k + 30, 7, 2);
		setBlock(world, i + 3, j + 27, k + 31, Blocks.leaves, 7);
		world.setBlockMetadataWithNotify(i + 3, j + 27, k + 31, 7, 2);
		setBlock(world, i + 3, j + 28, k + 27, Blocks.leaves, 7);
		world.setBlockMetadataWithNotify(i + 3, j + 28, k + 27, 7, 2);
		setBlock(world, i + 3, j + 28, k + 28, Blocks.leaves, 7);
		world.setBlockMetadataWithNotify(i + 3, j + 28, k + 28, 7, 2);
		setBlock(world, i + 3, j + 28, k + 29, Blocks.leaves, 7);
		world.setBlockMetadataWithNotify(i + 3, j + 28, k + 29, 7, 2);
		setBlock(world, i + 3, j + 28, k + 30, Blocks.leaves, 7);
		world.setBlockMetadataWithNotify(i + 3, j + 28, k + 30, 7, 2);
		setBlock(world, i + 3, j + 28, k + 31, Blocks.leaves, 7);
		world.setBlockMetadataWithNotify(i + 3, j + 28, k + 31, 7, 2);
		setBlock(world, i + 3, j + 29, k + 28, Blocks.leaves, 7);
		world.setBlockMetadataWithNotify(i + 3, j + 29, k + 28, 7, 2);
		setBlock(world, i + 3, j + 29, k + 29, Blocks.leaves, 7);
		world.setBlockMetadataWithNotify(i + 3, j + 29, k + 29, 7, 2);
		setBlock(world, i + 3, j + 29, k + 30, Blocks.leaves, 7);
		world.setBlockMetadataWithNotify(i + 3, j + 29, k + 30, 7, 2);
		setBlock(world, i + 3, j + 29, k + 31, Blocks.leaves, 7);
		world.setBlockMetadataWithNotify(i + 3, j + 29, k + 31, 7, 2);
		setBlock(world, i + 3, j + 30, k + 29, Blocks.leaves, 7);
		world.setBlockMetadataWithNotify(i + 3, j + 30, k + 29, 7, 2);
		setBlock(world, i + 4, j + 23, k + 22, Blocks.leaves, 7);
		world.setBlockMetadataWithNotify(i + 4, j + 23, k + 22, 7, 2);
		setBlock(world, i + 4, j + 23, k + 23, Blocks.leaves, 7);
		world.setBlockMetadataWithNotify(i + 4, j + 23, k + 23, 7, 2);
		setBlock(world, i + 4, j + 23, k + 24, Blocks.leaves, 7);
		world.setBlockMetadataWithNotify(i + 4, j + 23, k + 24, 7, 2);
		setBlock(world, i + 4, j + 23, k + 25, Blocks.leaves, 7);
		world.setBlockMetadataWithNotify(i + 4, j + 23, k + 25, 7, 2);
		setBlock(world, i + 4, j + 23, k + 26, Blocks.leaves, 7);
		world.setBlockMetadataWithNotify(i + 4, j + 23, k + 26, 7, 2);
		setBlock(world, i + 4, j + 24, k + 23, Blocks.leaves, 7);
		world.setBlockMetadataWithNotify(i + 4, j + 24, k + 23, 7, 2);
		setBlock(world, i + 4, j + 24, k + 24, Blocks.leaves, 7);
		world.setBlockMetadataWithNotify(i + 4, j + 24, k + 24, 7, 2);
		setBlock(world, i + 4, j + 24, k + 25, Blocks.leaves, 7);
		world.setBlockMetadataWithNotify(i + 4, j + 24, k + 25, 7, 2);
		setBlock(world, i + 4, j + 25, k + 24, Blocks.leaves, 7);
		world.setBlockMetadataWithNotify(i + 4, j + 25, k + 24, 7, 2);
		setBlock(world, i + 4, j + 26, k + 30, Blocks.log, 3);
		world.setBlockMetadataWithNotify(i + 4, j + 26, k + 30, 3, 2);
		setBlock(world, i + 4, j + 27, k + 27, Blocks.leaves, 7);
		world.setBlockMetadataWithNotify(i + 4, j + 27, k + 27, 7, 2);
		setBlock(world, i + 4, j + 27, k + 28, Blocks.leaves, 7);
		world.setBlockMetadataWithNotify(i + 4, j + 27, k + 28, 7, 2);
		setBlock(world, i + 4, j + 27, k + 29, Blocks.leaves, 7);
		world.setBlockMetadataWithNotify(i + 4, j + 27, k + 29, 7, 2);
		setBlock(world, i + 4, j + 27, k + 30, Blocks.leaves, 7);
		world.setBlockMetadataWithNotify(i + 4, j + 27, k + 30, 7, 2);
		setBlock(world, i + 4, j + 27, k + 31, Blocks.leaves, 7);
		world.setBlockMetadataWithNotify(i + 4, j + 27, k + 31, 7, 2);
		setBlock(world, i + 4, j + 28, k + 28, Blocks.leaves, 7);
		world.setBlockMetadataWithNotify(i + 4, j + 28, k + 28, 7, 2);
		setBlock(world, i + 4, j + 28, k + 29, Blocks.leaves, 7);
		world.setBlockMetadataWithNotify(i + 4, j + 28, k + 29, 7, 2);
		setBlock(world, i + 4, j + 28, k + 30, Blocks.leaves, 7);
		world.setBlockMetadataWithNotify(i + 4, j + 28, k + 30, 7, 2);
		setBlock(world, i + 4, j + 28, k + 31, Blocks.leaves, 7);
		world.setBlockMetadataWithNotify(i + 4, j + 28, k + 31, 7, 2);
		setBlock(world, i + 4, j + 29, k + 29, Blocks.leaves, 7);
		world.setBlockMetadataWithNotify(i + 4, j + 29, k + 29, 7, 2);
		setBlock(world, i + 4, j + 29, k + 30, Blocks.leaves, 7);
		world.setBlockMetadataWithNotify(i + 4, j + 29, k + 30, 7, 2);
		setBlock(world, i + 4, j + 29, k + 31, Blocks.leaves, 7);
		world.setBlockMetadataWithNotify(i + 4, j + 29, k + 31, 7, 2);
		setBlock(world, i + 4, j + 30, k + 31, Blocks.leaves, 7);
		world.setBlockMetadataWithNotify(i + 4, j + 30, k + 31, 7, 2);
		setBlock(world, i + 5, j + 23, k + 22, Blocks.leaves, 7);
		world.setBlockMetadataWithNotify(i + 5, j + 23, k + 22, 7, 2);
		setBlock(world, i + 5, j + 23, k + 23, Blocks.leaves, 7);
		world.setBlockMetadataWithNotify(i + 5, j + 23, k + 23, 7, 2);
		setBlock(world, i + 5, j + 23, k + 24, Blocks.log, 3);
		world.setBlockMetadataWithNotify(i + 5, j + 23, k + 24, 3, 2);
		setBlock(world, i + 5, j + 23, k + 25, Blocks.leaves, 7);
		world.setBlockMetadataWithNotify(i + 5, j + 23, k + 25, 7, 2);
		setBlock(world, i + 5, j + 23, k + 26, Blocks.leaves, 7);
		world.setBlockMetadataWithNotify(i + 5, j + 23, k + 26, 7, 2);
		setBlock(world, i + 5, j + 24, k + 22, Blocks.leaves, 7);
		world.setBlockMetadataWithNotify(i + 5, j + 24, k + 22, 7, 2);
		setBlock(world, i + 5, j + 24, k + 23, Blocks.leaves, 7);
		world.setBlockMetadataWithNotify(i + 5, j + 24, k + 23, 7, 2);
		setBlock(world, i + 5, j + 24, k + 24, Blocks.leaves, 7);
		world.setBlockMetadataWithNotify(i + 5, j + 24, k + 24, 7, 2);
		setBlock(world, i + 5, j + 24, k + 25, Blocks.leaves, 7);
		world.setBlockMetadataWithNotify(i + 5, j + 24, k + 25, 7, 2);
		setBlock(world, i + 5, j + 24, k + 26, Blocks.leaves, 7);
		world.setBlockMetadataWithNotify(i + 5, j + 24, k + 26, 7, 2);
		setBlock(world, i + 5, j + 25, k + 23, Blocks.leaves, 7);
		world.setBlockMetadataWithNotify(i + 5, j + 25, k + 23, 7, 2);
		setBlock(world, i + 5, j + 25, k + 24, Blocks.leaves, 7);
		world.setBlockMetadataWithNotify(i + 5, j + 25, k + 24, 7, 2);
		setBlock(world, i + 5, j + 25, k + 25, Blocks.leaves, 7);
		world.setBlockMetadataWithNotify(i + 5, j + 25, k + 25, 7, 2);
		setBlock(world, i + 5, j + 26, k + 24, Blocks.leaves, 7);
		world.setBlockMetadataWithNotify(i + 5, j + 26, k + 24, 7, 2);
		setBlock(world, i + 5, j + 26, k + 30, Blocks.log, 3);
		world.setBlockMetadataWithNotify(i + 5, j + 26, k + 30, 3, 2);
		setBlock(world, i + 5, j + 27, k + 28, Blocks.leaves, 7);
		world.setBlockMetadataWithNotify(i + 5, j + 27, k + 28, 7, 2);
		setBlock(world, i + 5, j + 27, k + 29, Blocks.leaves, 7);
		world.setBlockMetadataWithNotify(i + 5, j + 27, k + 29, 7, 2);
		setBlock(world, i + 5, j + 27, k + 30, Blocks.leaves, 7);
		world.setBlockMetadataWithNotify(i + 5, j + 27, k + 30, 7, 2);
		setBlock(world, i + 5, j + 28, k + 29, Blocks.leaves, 7);
		world.setBlockMetadataWithNotify(i + 5, j + 28, k + 29, 7, 2);
		setBlock(world, i + 5, j + 28, k + 30, Blocks.leaves, 7);
		world.setBlockMetadataWithNotify(i + 5, j + 28, k + 30, 7, 2);
		setBlock(world, i + 5, j + 28, k + 31, Blocks.log, 3);
		world.setBlockMetadataWithNotify(i + 5, j + 28, k + 31, 3, 2);
		setBlock(world, i + 5, j + 29, k + 29, Blocks.leaves, 7);
		world.setBlockMetadataWithNotify(i + 5, j + 29, k + 29, 7, 2);
		setBlock(world, i + 5, j + 29, k + 30, Blocks.leaves, 7);
		world.setBlockMetadataWithNotify(i + 5, j + 29, k + 30, 7, 2);
		setBlock(world, i + 5, j + 29, k + 31, Blocks.leaves, 7);
		world.setBlockMetadataWithNotify(i + 5, j + 29, k + 31, 7, 2);
		setBlock(world, i + 5, j + 30, k + 30, Blocks.leaves, 7);
		world.setBlockMetadataWithNotify(i + 5, j + 30, k + 30, 7, 2);
		setBlock(world, i + 5, j + 30, k + 31, Blocks.leaves, 7);
		world.setBlockMetadataWithNotify(i + 5, j + 30, k + 31, 7, 2);
		setBlock(world, i + 5, j + 31, k + 31, Blocks.leaves, 7);
		world.setBlockMetadataWithNotify(i + 5, j + 31, k + 31, 7, 2);
		setBlock(world, i + 6, j + 22, k + 25, Blocks.log, 3);
		world.setBlockMetadataWithNotify(i + 6, j + 22, k + 25, 3, 2);
		setBlock(world, i + 6, j + 23, k + 22, Blocks.leaves, 7);
		world.setBlockMetadataWithNotify(i + 6, j + 23, k + 22, 7, 2);
		setBlock(world, i + 6, j + 23, k + 23, Blocks.leaves, 7);
		world.setBlockMetadataWithNotify(i + 6, j + 23, k + 23, 7, 2);
		setBlock(world, i + 6, j + 23, k + 24, Blocks.leaves, 7);
		world.setBlockMetadataWithNotify(i + 6, j + 23, k + 24, 7, 2);
		setBlock(world, i + 6, j + 23, k + 25, Blocks.leaves, 7);
		world.setBlockMetadataWithNotify(i + 6, j + 23, k + 25, 7, 2);
		setBlock(world, i + 6, j + 23, k + 26, Blocks.leaves, 7);
		world.setBlockMetadataWithNotify(i + 6, j + 23, k + 26, 7, 2);
		setBlock(world, i + 6, j + 24, k + 23, Blocks.leaves, 7);
		world.setBlockMetadataWithNotify(i + 6, j + 24, k + 23, 7, 2);
		setBlock(world, i + 6, j + 24, k + 24, Blocks.leaves, 7);
		world.setBlockMetadataWithNotify(i + 6, j + 24, k + 24, 7, 2);
		setBlock(world, i + 6, j + 24, k + 25, Blocks.leaves, 7);
		world.setBlockMetadataWithNotify(i + 6, j + 24, k + 25, 7, 2);
		setBlock(world, i + 6, j + 25, k + 24, Blocks.leaves, 7);
		world.setBlockMetadataWithNotify(i + 6, j + 25, k + 24, 7, 2);
		setBlock(world, i + 6, j + 26, k + 31, Blocks.log, 3);
		world.setBlockMetadataWithNotify(i + 6, j + 26, k + 31, 3, 2);
		setBlock(world, i + 6, j + 28, k + 29, Blocks.leaves, 7);
		world.setBlockMetadataWithNotify(i + 6, j + 28, k + 29, 7, 2);
		setBlock(world, i + 6, j + 28, k + 30, Blocks.leaves, 7);
		world.setBlockMetadataWithNotify(i + 6, j + 28, k + 30, 7, 2);
		setBlock(world, i + 6, j + 28, k + 31, Blocks.leaves, 7);
		world.setBlockMetadataWithNotify(i + 6, j + 28, k + 31, 7, 2);
		setBlock(world, i + 6, j + 29, k + 30, Blocks.leaves, 7);
		world.setBlockMetadataWithNotify(i + 6, j + 29, k + 30, 7, 2);
		setBlock(world, i + 6, j + 29, k + 31, Blocks.leaves, 7);
		world.setBlockMetadataWithNotify(i + 6, j + 29, k + 31, 7, 2);
		setBlock(world, i + 6, j + 30, k + 31, Blocks.leaves, 7);
		world.setBlockMetadataWithNotify(i + 6, j + 30, k + 31, 7, 2);
		setBlock(world, i + 7, j + 22, k + 26, Blocks.log, 3);
		world.setBlockMetadataWithNotify(i + 7, j + 22, k + 26, 3, 2);
		setBlock(world, i + 7, j + 23, k + 19, Blocks.leaves, 7);
		world.setBlockMetadataWithNotify(i + 7, j + 23, k + 19, 7, 2);
		setBlock(world, i + 7, j + 23, k + 20, Blocks.leaves, 7);
		world.setBlockMetadataWithNotify(i + 7, j + 23, k + 20, 7, 2);
		setBlock(world, i + 7, j + 23, k + 21, Blocks.leaves, 7);
		world.setBlockMetadataWithNotify(i + 7, j + 23, k + 21, 7, 2);
		setBlock(world, i + 7, j + 23, k + 23, Blocks.leaves, 7);
		world.setBlockMetadataWithNotify(i + 7, j + 23, k + 23, 7, 2);
		setBlock(world, i + 7, j + 23, k + 24, Blocks.leaves, 7);
		world.setBlockMetadataWithNotify(i + 7, j + 23, k + 24, 7, 2);
		setBlock(world, i + 7, j + 23, k + 25, Blocks.leaves, 7);
		world.setBlockMetadataWithNotify(i + 7, j + 23, k + 25, 7, 2);
		setBlock(world, i + 7, j + 24, k + 20, Blocks.leaves, 7);
		world.setBlockMetadataWithNotify(i + 7, j + 24, k + 20, 7, 2);
		setBlock(world, i + 7, j + 24, k + 24, Blocks.leaves, 7);
		world.setBlockMetadataWithNotify(i + 7, j + 24, k + 24, 7, 2);
		setBlock(world, i + 7, j + 25, k + 31, Blocks.log, 3);
		world.setBlockMetadataWithNotify(i + 7, j + 25, k + 31, 3, 2);
		setBlock(world, i + 7, j + 28, k + 30, Blocks.leaves, 7);
		world.setBlockMetadataWithNotify(i + 7, j + 28, k + 30, 7, 2);
		setBlock(world, i + 7, j + 28, k + 31, Blocks.leaves, 7);
		world.setBlockMetadataWithNotify(i + 7, j + 28, k + 31, 7, 2);
		setBlock(world, i + 7, j + 29, k + 31, Blocks.leaves, 7);
		world.setBlockMetadataWithNotify(i + 7, j + 29, k + 31, 7, 2);
		setBlock(world, i + 8, j + 22, k + 27, Blocks.log, 3);
		world.setBlockMetadataWithNotify(i + 8, j + 22, k + 27, 3, 2);
		setBlock(world, i + 8, j + 23, k + 18, Blocks.leaves, 7);
		world.setBlockMetadataWithNotify(i + 8, j + 23, k + 18, 7, 2);
		setBlock(world, i + 8, j + 23, k + 19, Blocks.leaves, 7);
		world.setBlockMetadataWithNotify(i + 8, j + 23, k + 19, 7, 2);
		setBlock(world, i + 8, j + 23, k + 20, Blocks.leaves, 7);
		world.setBlockMetadataWithNotify(i + 8, j + 23, k + 20, 7, 2);
		setBlock(world, i + 8, j + 23, k + 21, Blocks.leaves, 7);
		world.setBlockMetadataWithNotify(i + 8, j + 23, k + 21, 7, 2);
		setBlock(world, i + 8, j + 23, k + 22, Blocks.leaves, 7);
		world.setBlockMetadataWithNotify(i + 8, j + 23, k + 22, 7, 2);
		setBlock(world, i + 8, j + 24, k + 19, Blocks.leaves, 7);
		world.setBlockMetadataWithNotify(i + 8, j + 24, k + 19, 7, 2);
		setBlock(world, i + 8, j + 24, k + 20, Blocks.leaves, 7);
		world.setBlockMetadataWithNotify(i + 8, j + 24, k + 20, 7, 2);
		setBlock(world, i + 8, j + 24, k + 21, Blocks.leaves, 7);
		world.setBlockMetadataWithNotify(i + 8, j + 24, k + 21, 7, 2);
		setBlock(world, i + 8, j + 25, k + 20, Blocks.leaves, 7);
		world.setBlockMetadataWithNotify(i + 8, j + 25, k + 20, 7, 2);
		setBlock(world, i + 9, j + 21, k + 28, Blocks.log, 3);
		world.setBlockMetadataWithNotify(i + 9, j + 21, k + 28, 3, 2);
		setBlock(world, i + 9, j + 22, k + 21, Blocks.log, 3);
		world.setBlockMetadataWithNotify(i + 9, j + 22, k + 21, 3, 2);
		setBlock(world, i + 9, j + 23, k + 18, Blocks.leaves, 7);
		world.setBlockMetadataWithNotify(i + 9, j + 23, k + 18, 7, 2);
		setBlock(world, i + 9, j + 23, k + 19, Blocks.leaves, 7);
		world.setBlockMetadataWithNotify(i + 9, j + 23, k + 19, 7, 2);
		setBlock(world, i + 9, j + 23, k + 20, Blocks.log, 3);
		world.setBlockMetadataWithNotify(i + 9, j + 23, k + 20, 3, 2);
		setBlock(world, i + 9, j + 23, k + 21, Blocks.leaves, 7);
		world.setBlockMetadataWithNotify(i + 9, j + 23, k + 21, 7, 2);
		setBlock(world, i + 9, j + 23, k + 22, Blocks.leaves, 7);
		world.setBlockMetadataWithNotify(i + 9, j + 23, k + 22, 7, 2);
		setBlock(world, i + 9, j + 24, k + 18, Blocks.leaves, 7);
		world.setBlockMetadataWithNotify(i + 9, j + 24, k + 18, 7, 2);
		setBlock(world, i + 9, j + 24, k + 19, Blocks.leaves, 7);
		world.setBlockMetadataWithNotify(i + 9, j + 24, k + 19, 7, 2);
		setBlock(world, i + 9, j + 24, k + 20, Blocks.leaves, 7);
		world.setBlockMetadataWithNotify(i + 9, j + 24, k + 20, 7, 2);
		setBlock(world, i + 9, j + 24, k + 21, Blocks.leaves, 7);
		world.setBlockMetadataWithNotify(i + 9, j + 24, k + 21, 7, 2);
		setBlock(world, i + 9, j + 24, k + 22, Blocks.leaves, 7);
		world.setBlockMetadataWithNotify(i + 9, j + 24, k + 22, 7, 2);
		setBlock(world, i + 9, j + 25, k + 19, Blocks.leaves, 7);
		world.setBlockMetadataWithNotify(i + 9, j + 25, k + 19, 7, 2);
		setBlock(world, i + 9, j + 25, k + 20, Blocks.leaves, 7);
		world.setBlockMetadataWithNotify(i + 9, j + 25, k + 20, 7, 2);
		setBlock(world, i + 9, j + 25, k + 21, Blocks.leaves, 7);
		world.setBlockMetadataWithNotify(i + 9, j + 25, k + 21, 7, 2);
		setBlock(world, i + 9, j + 26, k + 20, Blocks.leaves, 7);
		world.setBlockMetadataWithNotify(i + 9, j + 26, k + 20, 7, 2);
		setBlock(world, i + 9, j + 34, k + 26, Blocks.log, 1);
		world.setBlockMetadataWithNotify(i + 9, j + 34, k + 26, 1, 2);
		setBlock(world, i + 9, j + 35, k + 25, Blocks.log, 1);
		world.setBlockMetadataWithNotify(i + 9, j + 35, k + 25, 1, 2);
		setBlock(world, i + 9, j + 35, k + 27, Blocks.log, 1);
		world.setBlockMetadataWithNotify(i + 9, j + 35, k + 27, 1, 2);
		setBlock(world, i + 9, j + 36, k + 26, Blocks.log, 1);
		world.setBlockMetadataWithNotify(i + 9, j + 36, k + 26, 1, 2);
		setBlock(world, i + 9, j + 36, k + 27, Blocks.leaves, 7);
		world.setBlockMetadataWithNotify(i + 9, j + 36, k + 27, 7, 2);
		setBlock(world, i + 9, j + 36, k + 28, Blocks.leaves, 7);
		world.setBlockMetadataWithNotify(i + 9, j + 36, k + 28, 7, 2);
		setBlock(world, i + 9, j + 37, k + 27, Blocks.leaves, 7);
		world.setBlockMetadataWithNotify(i + 9, j + 37, k + 27, 7, 2);
		setBlock(world, i + 10, j + 21, k + 28, Blocks.log, 3);
		world.setBlockMetadataWithNotify(i + 10, j + 21, k + 28, 3, 2);
		setBlock(world, i + 10, j + 22, k + 22, Blocks.log, 3);
		world.setBlockMetadataWithNotify(i + 10, j + 22, k + 22, 3, 2);
		setBlock(world, i + 10, j + 22, k + 23, Blocks.log, 3);
		world.setBlockMetadataWithNotify(i + 10, j + 22, k + 23, 3, 2);
		setBlock(world, i + 10, j + 23, k + 18, Blocks.leaves, 7);
		world.setBlockMetadataWithNotify(i + 10, j + 23, k + 18, 7, 2);
		setBlock(world, i + 10, j + 23, k + 19, Blocks.leaves, 7);
		world.setBlockMetadataWithNotify(i + 10, j + 23, k + 19, 7, 2);
		setBlock(world, i + 10, j + 23, k + 20, Blocks.leaves, 7);
		world.setBlockMetadataWithNotify(i + 10, j + 23, k + 20, 7, 2);
		setBlock(world, i + 10, j + 23, k + 21, Blocks.leaves, 7);
		world.setBlockMetadataWithNotify(i + 10, j + 23, k + 21, 7, 2);
		setBlock(world, i + 10, j + 23, k + 22, Blocks.leaves, 7);
		world.setBlockMetadataWithNotify(i + 10, j + 23, k + 22, 7, 2);
		setBlock(world, i + 10, j + 24, k + 19, Blocks.leaves, 7);
		world.setBlockMetadataWithNotify(i + 10, j + 24, k + 19, 7, 2);
		setBlock(world, i + 10, j + 24, k + 20, Blocks.leaves, 7);
		world.setBlockMetadataWithNotify(i + 10, j + 24, k + 20, 7, 2);
		setBlock(world, i + 10, j + 24, k + 21, Blocks.leaves, 7);
		world.setBlockMetadataWithNotify(i + 10, j + 24, k + 21, 7, 2);
		setBlock(world, i + 10, j + 25, k + 20, Blocks.leaves, 7);
		world.setBlockMetadataWithNotify(i + 10, j + 25, k + 20, 7, 2);
		setBlock(world, i + 10, j + 34, k + 25, Blocks.log, 1);
		world.setBlockMetadataWithNotify(i + 10, j + 34, k + 25, 1, 2);
		setBlock(world, i + 10, j + 34, k + 27, Blocks.log, 1);
		world.setBlockMetadataWithNotify(i + 10, j + 34, k + 27, 1, 2);
		setBlock(world, i + 10, j + 35, k + 25, Blocks.log, 1);
		world.setBlockMetadataWithNotify(i + 10, j + 35, k + 25, 1, 2);
		setBlock(world, i + 10, j + 35, k + 26, Blocks.log, 1);
		world.setBlockMetadataWithNotify(i + 10, j + 35, k + 26, 1, 2);
		setBlock(world, i + 10, j + 35, k + 27, Blocks.log, 1);
		world.setBlockMetadataWithNotify(i + 10, j + 35, k + 27, 1, 2);
		setBlock(world, i + 10, j + 36, k + 25, Blocks.log, 1);
		world.setBlockMetadataWithNotify(i + 10, j + 36, k + 25, 1, 2);
		setBlock(world, i + 10, j + 36, k + 26, Blocks.log, 1);
		world.setBlockMetadataWithNotify(i + 10, j + 36, k + 26, 1, 2);
		setBlock(world, i + 10, j + 36, k + 27, Blocks.log, 1);
		world.setBlockMetadataWithNotify(i + 10, j + 36, k + 27, 1, 2);
		setBlock(world, i + 10, j + 36, k + 28, Blocks.leaves, 7);
		world.setBlockMetadataWithNotify(i + 10, j + 36, k + 28, 7, 2);
		setBlock(world, i + 10, j + 36, k + 29, Blocks.leaves, 7);
		world.setBlockMetadataWithNotify(i + 10, j + 36, k + 29, 7, 2);
		setBlock(world, i + 10, j + 37, k + 26, Blocks.leaves, 7);
		world.setBlockMetadataWithNotify(i + 10, j + 37, k + 26, 7, 2);
		setBlock(world, i + 10, j + 37, k + 27, Blocks.leaves, 7);
		world.setBlockMetadataWithNotify(i + 10, j + 37, k + 27, 7, 2);
		setBlock(world, i + 10, j + 37, k + 28, Blocks.leaves, 7);
		world.setBlockMetadataWithNotify(i + 10, j + 37, k + 28, 7, 2);
		setBlock(world, i + 10, j + 38, k + 27, Blocks.leaves, 7);
		world.setBlockMetadataWithNotify(i + 10, j + 38, k + 27, 7, 2);
		setBlock(world, i + 10, j + 39, k + 31, Blocks.leaves, 7);
		world.setBlockMetadataWithNotify(i + 10, j + 39, k + 31, 7, 2);
		setBlock(world, i + 11, j + 21, k + 29, Blocks.log, 3);
		world.setBlockMetadataWithNotify(i + 11, j + 21, k + 29, 3, 2);
		setBlock(world, i + 11, j + 22, k + 24, Blocks.log, 3);
		world.setBlockMetadataWithNotify(i + 11, j + 22, k + 24, 3, 2);
		setBlock(world, i + 11, j + 23, k + 19, Blocks.leaves, 7);
		world.setBlockMetadataWithNotify(i + 11, j + 23, k + 19, 7, 2);
		setBlock(world, i + 11, j + 23, k + 20, Blocks.leaves, 7);
		world.setBlockMetadataWithNotify(i + 11, j + 23, k + 20, 7, 2);
		setBlock(world, i + 11, j + 23, k + 21, Blocks.leaves, 7);
		world.setBlockMetadataWithNotify(i + 11, j + 23, k + 21, 7, 2);
		setBlock(world, i + 11, j + 24, k + 20, Blocks.leaves, 7);
		world.setBlockMetadataWithNotify(i + 11, j + 24, k + 20, 7, 2);
		setBlock(world, i + 11, j + 34, k + 26, Blocks.log, 1);
		world.setBlockMetadataWithNotify(i + 11, j + 34, k + 26, 1, 2);
		setBlock(world, i + 11, j + 34, k + 28, Blocks.log, 1);
		world.setBlockMetadataWithNotify(i + 11, j + 34, k + 28, 1, 2);
		setBlock(world, i + 11, j + 35, k + 25, Blocks.log, 1);
		world.setBlockMetadataWithNotify(i + 11, j + 35, k + 25, 1, 2);
		setBlock(world, i + 11, j + 35, k + 26, Blocks.log, 1);
		world.setBlockMetadataWithNotify(i + 11, j + 35, k + 26, 1, 2);
		setBlock(world, i + 11, j + 35, k + 27, Blocks.log, 1);
		world.setBlockMetadataWithNotify(i + 11, j + 35, k + 27, 1, 2);
		setBlock(world, i + 11, j + 35, k + 28, Blocks.log, 1);
		world.setBlockMetadataWithNotify(i + 11, j + 35, k + 28, 1, 2);
		setBlock(world, i + 11, j + 36, k + 25, Blocks.leaves, 7);
		world.setBlockMetadataWithNotify(i + 11, j + 36, k + 25, 7, 2);
		setBlock(world, i + 11, j + 36, k + 26, Blocks.log, 1);
		world.setBlockMetadataWithNotify(i + 11, j + 36, k + 26, 1, 2);
		setBlock(world, i + 11, j + 36, k + 27, Blocks.log, 1);
		world.setBlockMetadataWithNotify(i + 11, j + 36, k + 27, 1, 2);
		setBlock(world, i + 11, j + 36, k + 28, Blocks.log, 1);
		world.setBlockMetadataWithNotify(i + 11, j + 36, k + 28, 1, 2);
		setBlock(world, i + 11, j + 36, k + 29, Blocks.leaves, 7);
		world.setBlockMetadataWithNotify(i + 11, j + 36, k + 29, 7, 2);
		setBlock(world, i + 11, j + 37, k + 25, Blocks.leaves, 7);
		world.setBlockMetadataWithNotify(i + 11, j + 37, k + 25, 7, 2);
		setBlock(world, i + 11, j + 37, k + 26, Blocks.leaves, 7);
		world.setBlockMetadataWithNotify(i + 11, j + 37, k + 26, 7, 2);
		setBlock(world, i + 11, j + 37, k + 27, Blocks.leaves, 7);
		world.setBlockMetadataWithNotify(i + 11, j + 37, k + 27, 7, 2);
		setBlock(world, i + 11, j + 37, k + 28, Blocks.leaves, 7);
		world.setBlockMetadataWithNotify(i + 11, j + 37, k + 28, 7, 2);
		setBlock(world, i + 11, j + 37, k + 29, Blocks.leaves, 7);
		world.setBlockMetadataWithNotify(i + 11, j + 37, k + 29, 7, 2);
		setBlock(world, i + 11, j + 38, k + 26, Blocks.leaves, 7);
		world.setBlockMetadataWithNotify(i + 11, j + 38, k + 26, 7, 2);
		setBlock(world, i + 11, j + 38, k + 27, Blocks.leaves, 7);
		world.setBlockMetadataWithNotify(i + 11, j + 38, k + 27, 7, 2);
		setBlock(world, i + 11, j + 38, k + 28, Blocks.leaves, 7);
		world.setBlockMetadataWithNotify(i + 11, j + 38, k + 28, 7, 2);
		setBlock(world, i + 11, j + 38, k + 29, Blocks.leaves, 7);
		world.setBlockMetadataWithNotify(i + 11, j + 38, k + 29, 7, 2);
		setBlock(world, i + 11, j + 39, k + 27, Blocks.leaves, 7);
		world.setBlockMetadataWithNotify(i + 11, j + 39, k + 27, 7, 2);
		setBlock(world, i + 11, j + 39, k + 28, Blocks.leaves, 7);
		world.setBlockMetadataWithNotify(i + 11, j + 39, k + 28, 7, 2);
		setBlock(world, i + 11, j + 39, k + 30, Blocks.leaves, 7);
		world.setBlockMetadataWithNotify(i + 11, j + 39, k + 30, 7, 2);
		setBlock(world, i + 11, j + 39, k + 31, Blocks.leaves, 7);
		world.setBlockMetadataWithNotify(i + 11, j + 39, k + 31, 7, 2);
		setBlock(world, i + 11, j + 40, k + 31, Blocks.leaves, 7);
		world.setBlockMetadataWithNotify(i + 11, j + 40, k + 31, 7, 2);
		setBlock(world, i + 12, j + 20, k + 30, Blocks.log, 3);
		world.setBlockMetadataWithNotify(i + 12, j + 20, k + 30, 3, 2);
		setBlock(world, i + 12, j + 21, k + 26, Blocks.log, 3);
		world.setBlockMetadataWithNotify(i + 12, j + 21, k + 26, 3, 2);
		setBlock(world, i + 12, j + 22, k + 25, Blocks.log, 3);
		world.setBlockMetadataWithNotify(i + 12, j + 22, k + 25, 3, 2);
		setBlock(world, i + 12, j + 34, k + 27, Blocks.log, 1);
		world.setBlockMetadataWithNotify(i + 12, j + 34, k + 27, 1, 2);
		setBlock(world, i + 12, j + 35, k + 26, Blocks.log, 1);
		world.setBlockMetadataWithNotify(i + 12, j + 35, k + 26, 1, 2);
		setBlock(world, i + 12, j + 35, k + 27, Blocks.log, 1);
		world.setBlockMetadataWithNotify(i + 12, j + 35, k + 27, 1, 2);
		setBlock(world, i + 12, j + 36, k + 25, Blocks.leaves, 7);
		world.setBlockMetadataWithNotify(i + 12, j + 36, k + 25, 7, 2);
		setBlock(world, i + 12, j + 36, k + 26, Blocks.leaves, 7);
		world.setBlockMetadataWithNotify(i + 12, j + 36, k + 26, 7, 2);
		setBlock(world, i + 12, j + 36, k + 27, Blocks.log, 1);
		world.setBlockMetadataWithNotify(i + 12, j + 36, k + 27, 1, 2);
		setBlock(world, i + 12, j + 36, k + 28, Blocks.leaves, 7);
		world.setBlockMetadataWithNotify(i + 12, j + 36, k + 28, 7, 2);
		setBlock(world, i + 12, j + 36, k + 29, Blocks.leaves, 7);
		world.setBlockMetadataWithNotify(i + 12, j + 36, k + 29, 7, 2);
		setBlock(world, i + 12, j + 37, k + 26, Blocks.leaves, 7);
		world.setBlockMetadataWithNotify(i + 12, j + 37, k + 26, 7, 2);
		setBlock(world, i + 12, j + 37, k + 27, Blocks.leaves, 7);
		world.setBlockMetadataWithNotify(i + 12, j + 37, k + 27, 7, 2);
		setBlock(world, i + 12, j + 37, k + 28, Blocks.leaves, 7);
		world.setBlockMetadataWithNotify(i + 12, j + 37, k + 28, 7, 2);
		setBlock(world, i + 12, j + 38, k + 26, Blocks.leaves, 7);
		world.setBlockMetadataWithNotify(i + 12, j + 38, k + 26, 7, 2);
		setBlock(world, i + 12, j + 38, k + 27, Blocks.leaves, 7);
		world.setBlockMetadataWithNotify(i + 12, j + 38, k + 27, 7, 2);
		setBlock(world, i + 12, j + 38, k + 28, Blocks.leaves, 7);
		world.setBlockMetadataWithNotify(i + 12, j + 38, k + 28, 7, 2);
		setBlock(world, i + 12, j + 38, k + 29, Blocks.leaves, 7);
		world.setBlockMetadataWithNotify(i + 12, j + 38, k + 29, 7, 2);
		setBlock(world, i + 12, j + 38, k + 30, Blocks.leaves, 7);
		world.setBlockMetadataWithNotify(i + 12, j + 38, k + 30, 7, 2);
		setBlock(world, i + 12, j + 39, k + 27, Blocks.leaves, 7);
		world.setBlockMetadataWithNotify(i + 12, j + 39, k + 27, 7, 2);
		setBlock(world, i + 12, j + 39, k + 28, Blocks.leaves, 7);
		world.setBlockMetadataWithNotify(i + 12, j + 39, k + 28, 7, 2);
		setBlock(world, i + 12, j + 39, k + 29, Blocks.leaves, 7);
		world.setBlockMetadataWithNotify(i + 12, j + 39, k + 29, 7, 2);
		setBlock(world, i + 12, j + 39, k + 30, Blocks.leaves, 7);
		world.setBlockMetadataWithNotify(i + 12, j + 39, k + 30, 7, 2);
		setBlock(world, i + 12, j + 39, k + 31, Blocks.leaves, 7);
		world.setBlockMetadataWithNotify(i + 12, j + 39, k + 31, 7, 2);
		setBlock(world, i + 12, j + 40, k + 28, Blocks.leaves, 7);
		world.setBlockMetadataWithNotify(i + 12, j + 40, k + 28, 7, 2);
		setBlock(world, i + 12, j + 40, k + 30, Blocks.leaves, 7);
		world.setBlockMetadataWithNotify(i + 12, j + 40, k + 30, 7, 2);
		setBlock(world, i + 12, j + 40, k + 31, Blocks.leaves, 7);
		world.setBlockMetadataWithNotify(i + 12, j + 40, k + 31, 7, 2);
		setBlock(world, i + 12, j + 41, k + 31, Blocks.leaves, 7);
		world.setBlockMetadataWithNotify(i + 12, j + 41, k + 31, 7, 2);
		setBlock(world, i + 12, j + 46, k + 31, Blocks.leaves, 7);
		world.setBlockMetadataWithNotify(i + 12, j + 46, k + 31, 7, 2);
		setBlock(world, i + 13, j + 20, k + 31, Blocks.log, 3);
		world.setBlockMetadataWithNotify(i + 13, j + 20, k + 31, 3, 2);
		setBlock(world, i + 13, j + 21, k + 27, Blocks.log, 3);
		world.setBlockMetadataWithNotify(i + 13, j + 21, k + 27, 3, 2);
		setBlock(world, i + 13, j + 36, k + 26, Blocks.leaves, 7);
		world.setBlockMetadataWithNotify(i + 13, j + 36, k + 26, 7, 2);
		setBlock(world, i + 13, j + 36, k + 27, Blocks.leaves, 7);
		world.setBlockMetadataWithNotify(i + 13, j + 36, k + 27, 7, 2);
		setBlock(world, i + 13, j + 36, k + 28, Blocks.leaves, 7);
		world.setBlockMetadataWithNotify(i + 13, j + 36, k + 28, 7, 2);
		setBlock(world, i + 13, j + 37, k + 27, Blocks.leaves, 7);
		world.setBlockMetadataWithNotify(i + 13, j + 37, k + 27, 7, 2);
		setBlock(world, i + 13, j + 37, k + 29, Blocks.log, 3);
		world.setBlockMetadataWithNotify(i + 13, j + 37, k + 29, 3, 2);
		setBlock(world, i + 13, j + 38, k + 26, Blocks.leaves, 7);
		world.setBlockMetadataWithNotify(i + 13, j + 38, k + 26, 7, 2);
		setBlock(world, i + 13, j + 38, k + 27, Blocks.leaves, 7);
		world.setBlockMetadataWithNotify(i + 13, j + 38, k + 27, 7, 2);
		setBlock(world, i + 13, j + 38, k + 28, Blocks.log, 3);
		world.setBlockMetadataWithNotify(i + 13, j + 38, k + 28, 3, 2);
		setBlock(world, i + 13, j + 38, k + 29, Blocks.leaves, 7);
		world.setBlockMetadataWithNotify(i + 13, j + 38, k + 29, 7, 2);
		setBlock(world, i + 13, j + 38, k + 30, Blocks.leaves, 7);
		world.setBlockMetadataWithNotify(i + 13, j + 38, k + 30, 7, 2);
		setBlock(world, i + 13, j + 39, k + 26, Blocks.leaves, 7);
		world.setBlockMetadataWithNotify(i + 13, j + 39, k + 26, 7, 2);
		setBlock(world, i + 13, j + 39, k + 27, Blocks.leaves, 7);
		world.setBlockMetadataWithNotify(i + 13, j + 39, k + 27, 7, 2);
		setBlock(world, i + 13, j + 39, k + 28, Blocks.leaves, 7);
		world.setBlockMetadataWithNotify(i + 13, j + 39, k + 28, 7, 2);
		setBlock(world, i + 13, j + 39, k + 29, Blocks.leaves, 7);
		world.setBlockMetadataWithNotify(i + 13, j + 39, k + 29, 7, 2);
		setBlock(world, i + 13, j + 39, k + 30, Blocks.leaves, 7);
		world.setBlockMetadataWithNotify(i + 13, j + 39, k + 30, 7, 2);
		setBlock(world, i + 13, j + 39, k + 31, Blocks.leaves, 7);
		world.setBlockMetadataWithNotify(i + 13, j + 39, k + 31, 7, 2);
		setBlock(world, i + 13, j + 40, k + 27, Blocks.leaves, 7);
		world.setBlockMetadataWithNotify(i + 13, j + 40, k + 27, 7, 2);
		setBlock(world, i + 13, j + 40, k + 28, Blocks.leaves, 7);
		world.setBlockMetadataWithNotify(i + 13, j + 40, k + 28, 7, 2);
		setBlock(world, i + 13, j + 40, k + 29, Blocks.leaves, 7);
		world.setBlockMetadataWithNotify(i + 13, j + 40, k + 29, 7, 2);
		setBlock(world, i + 13, j + 40, k + 31, Blocks.leaves, 7);
		world.setBlockMetadataWithNotify(i + 13, j + 40, k + 31, 7, 2);
		setBlock(world, i + 13, j + 41, k + 28, Blocks.leaves, 7);
		world.setBlockMetadataWithNotify(i + 13, j + 41, k + 28, 7, 2);
		setBlock(world, i + 13, j + 46, k + 31, Blocks.leaves, 7);
		world.setBlockMetadataWithNotify(i + 13, j + 46, k + 31, 7, 2);
		setBlock(world, i + 13, j + 47, k + 31, Blocks.leaves, 7);
		world.setBlockMetadataWithNotify(i + 13, j + 47, k + 31, 7, 2);
		setBlock(world, i + 14, j + 21, k + 28, Blocks.log, 3);
		world.setBlockMetadataWithNotify(i + 14, j + 21, k + 28, 3, 2);
		setBlock(world, i + 14, j + 21, k + 29, Blocks.log, 3);
		world.setBlockMetadataWithNotify(i + 14, j + 21, k + 29, 3, 2);
		setBlock(world, i + 14, j + 37, k + 30, Blocks.log, 3);
		world.setBlockMetadataWithNotify(i + 14, j + 37, k + 30, 3, 2);
		setBlock(world, i + 14, j + 38, k + 26, Blocks.leaves, 7);
		world.setBlockMetadataWithNotify(i + 14, j + 38, k + 26, 7, 2);
		setBlock(world, i + 14, j + 38, k + 27, Blocks.leaves, 7);
		world.setBlockMetadataWithNotify(i + 14, j + 38, k + 27, 7, 2);
		setBlock(world, i + 14, j + 38, k + 28, Blocks.leaves, 7);
		world.setBlockMetadataWithNotify(i + 14, j + 38, k + 28, 7, 2);
		setBlock(world, i + 14, j + 38, k + 29, Blocks.leaves, 7);
		world.setBlockMetadataWithNotify(i + 14, j + 38, k + 29, 7, 2);
		setBlock(world, i + 14, j + 38, k + 30, Blocks.leaves, 7);
		world.setBlockMetadataWithNotify(i + 14, j + 38, k + 30, 7, 2);
		setBlock(world, i + 14, j + 39, k + 27, Blocks.leaves, 7);
		world.setBlockMetadataWithNotify(i + 14, j + 39, k + 27, 7, 2);
		setBlock(world, i + 14, j + 39, k + 28, Blocks.leaves, 7);
		world.setBlockMetadataWithNotify(i + 14, j + 39, k + 28, 7, 2);
		setBlock(world, i + 14, j + 39, k + 29, Blocks.leaves, 7);
		world.setBlockMetadataWithNotify(i + 14, j + 39, k + 29, 7, 2);
		setBlock(world, i + 14, j + 39, k + 31, Blocks.leaves, 7);
		world.setBlockMetadataWithNotify(i + 14, j + 39, k + 31, 7, 2);
		setBlock(world, i + 14, j + 40, k + 28, Blocks.leaves, 7);
		world.setBlockMetadataWithNotify(i + 14, j + 40, k + 28, 7, 2);
		setBlock(world, i + 14, j + 46, k + 31, Blocks.leaves, 7);
		world.setBlockMetadataWithNotify(i + 14, j + 46, k + 31, 7, 2);
		setBlock(world, i + 15, j + 21, k + 30, Blocks.log, 3);
		world.setBlockMetadataWithNotify(i + 15, j + 21, k + 30, 3, 2);
		setBlock(world, i + 15, j + 37, k + 31, Blocks.log, 3);
		world.setBlockMetadataWithNotify(i + 15, j + 37, k + 31, 3, 2);
		setBlock(world, i + 15, j + 38, k + 27, Blocks.leaves, 7);
		world.setBlockMetadataWithNotify(i + 15, j + 38, k + 27, 7, 2);
		setBlock(world, i + 15, j + 38, k + 28, Blocks.leaves, 7);
		world.setBlockMetadataWithNotify(i + 15, j + 38, k + 28, 7, 2);
		setBlock(world, i + 15, j + 38, k + 29, Blocks.leaves, 7);
		world.setBlockMetadataWithNotify(i + 15, j + 38, k + 29, 7, 2);
		setBlock(world, i + 15, j + 39, k + 28, Blocks.leaves, 7);
		world.setBlockMetadataWithNotify(i + 15, j + 39, k + 28, 7, 2);
		setBlock(world, i + 16, j + 21, k + 31, Blocks.log, 3);
		world.setBlockMetadataWithNotify(i + 16, j + 21, k + 31, 3, 2);
		setBlock(world, i + 16, j + 24, k + 26, Blocks.leaves, 7);
		world.setBlockMetadataWithNotify(i + 16, j + 24, k + 26, 7, 2);
		setBlock(world, i + 16, j + 24, k + 27, Blocks.leaves, 7);
		world.setBlockMetadataWithNotify(i + 16, j + 24, k + 27, 7, 2);
		setBlock(world, i + 16, j + 24, k + 28, Blocks.leaves, 7);
		world.setBlockMetadataWithNotify(i + 16, j + 24, k + 28, 7, 2);
		setBlock(world, i + 16, j + 25, k + 27, Blocks.leaves, 7);
		world.setBlockMetadataWithNotify(i + 16, j + 25, k + 27, 7, 2);
		setBlock(world, i + 17, j + 24, k + 25, Blocks.leaves, 7);
		world.setBlockMetadataWithNotify(i + 17, j + 24, k + 25, 7, 2);
		setBlock(world, i + 17, j + 24, k + 26, Blocks.leaves, 7);
		world.setBlockMetadataWithNotify(i + 17, j + 24, k + 26, 7, 2);
		setBlock(world, i + 17, j + 24, k + 27, Blocks.leaves, 7);
		world.setBlockMetadataWithNotify(i + 17, j + 24, k + 27, 7, 2);
		setBlock(world, i + 17, j + 24, k + 28, Blocks.leaves, 7);
		world.setBlockMetadataWithNotify(i + 17, j + 24, k + 28, 7, 2);
		setBlock(world, i + 17, j + 24, k + 29, Blocks.leaves, 7);
		world.setBlockMetadataWithNotify(i + 17, j + 24, k + 29, 7, 2);
		setBlock(world, i + 17, j + 25, k + 26, Blocks.leaves, 7);
		world.setBlockMetadataWithNotify(i + 17, j + 25, k + 26, 7, 2);
		setBlock(world, i + 17, j + 25, k + 27, Blocks.leaves, 7);
		world.setBlockMetadataWithNotify(i + 17, j + 25, k + 27, 7, 2);
		setBlock(world, i + 17, j + 25, k + 28, Blocks.leaves, 7);
		world.setBlockMetadataWithNotify(i + 17, j + 25, k + 28, 7, 2);
		setBlock(world, i + 17, j + 26, k + 27, Blocks.leaves, 7);
		world.setBlockMetadataWithNotify(i + 17, j + 26, k + 27, 7, 2);
		setBlock(world, i + 17, j + 37, k + 29, Blocks.leaves, 7);
		world.setBlockMetadataWithNotify(i + 17, j + 37, k + 29, 7, 2);
		setBlock(world, i + 17, j + 37, k + 30, Blocks.leaves, 7);
		world.setBlockMetadataWithNotify(i + 17, j + 37, k + 30, 7, 2);
		setBlock(world, i + 17, j + 37, k + 31, Blocks.leaves, 7);
		world.setBlockMetadataWithNotify(i + 17, j + 37, k + 31, 7, 2);
		setBlock(world, i + 17, j + 38, k + 30, Blocks.leaves, 7);
		world.setBlockMetadataWithNotify(i + 17, j + 38, k + 30, 7, 2);
		setBlock(world, i + 17, j + 50, k + 31, Blocks.leaves, 7);
		world.setBlockMetadataWithNotify(i + 17, j + 50, k + 31, 7, 2);
		setBlock(world, i + 18, j + 23, k + 28, Blocks.log, 3);
		world.setBlockMetadataWithNotify(i + 18, j + 23, k + 28, 3, 2);
		setBlock(world, i + 18, j + 24, k + 25, Blocks.leaves, 7);
		world.setBlockMetadataWithNotify(i + 18, j + 24, k + 25, 7, 2);
		setBlock(world, i + 18, j + 24, k + 26, Blocks.leaves, 7);
		world.setBlockMetadataWithNotify(i + 18, j + 24, k + 26, 7, 2);
		setBlock(world, i + 18, j + 24, k + 27, Blocks.log, 3);
		world.setBlockMetadataWithNotify(i + 18, j + 24, k + 27, 3, 2);
		setBlock(world, i + 18, j + 24, k + 28, Blocks.leaves, 7);
		world.setBlockMetadataWithNotify(i + 18, j + 24, k + 28, 7, 2);
		setBlock(world, i + 18, j + 24, k + 29, Blocks.leaves, 7);
		world.setBlockMetadataWithNotify(i + 18, j + 24, k + 29, 7, 2);
		setBlock(world, i + 18, j + 25, k + 25, Blocks.leaves, 7);
		world.setBlockMetadataWithNotify(i + 18, j + 25, k + 25, 7, 2);
		setBlock(world, i + 18, j + 25, k + 26, Blocks.leaves, 7);
		world.setBlockMetadataWithNotify(i + 18, j + 25, k + 26, 7, 2);
		setBlock(world, i + 18, j + 25, k + 27, Blocks.leaves, 7);
		world.setBlockMetadataWithNotify(i + 18, j + 25, k + 27, 7, 2);
		setBlock(world, i + 18, j + 25, k + 28, Blocks.leaves, 7);
		world.setBlockMetadataWithNotify(i + 18, j + 25, k + 28, 7, 2);
		setBlock(world, i + 18, j + 25, k + 29, Blocks.leaves, 7);
		world.setBlockMetadataWithNotify(i + 18, j + 25, k + 29, 7, 2);
		setBlock(world, i + 18, j + 26, k + 26, Blocks.leaves, 7);
		world.setBlockMetadataWithNotify(i + 18, j + 26, k + 26, 7, 2);
		setBlock(world, i + 18, j + 26, k + 27, Blocks.leaves, 7);
		world.setBlockMetadataWithNotify(i + 18, j + 26, k + 27, 7, 2);
		setBlock(world, i + 18, j + 26, k + 28, Blocks.leaves, 7);
		world.setBlockMetadataWithNotify(i + 18, j + 26, k + 28, 7, 2);
		setBlock(world, i + 18, j + 27, k + 27, Blocks.leaves, 7);
		world.setBlockMetadataWithNotify(i + 18, j + 27, k + 27, 7, 2);
		setBlock(world, i + 18, j + 37, k + 28, Blocks.leaves, 7);
		world.setBlockMetadataWithNotify(i + 18, j + 37, k + 28, 7, 2);
		setBlock(world, i + 18, j + 37, k + 29, Blocks.leaves, 7);
		world.setBlockMetadataWithNotify(i + 18, j + 37, k + 29, 7, 2);
		setBlock(world, i + 18, j + 37, k + 30, Blocks.leaves, 7);
		world.setBlockMetadataWithNotify(i + 18, j + 37, k + 30, 7, 2);
		setBlock(world, i + 18, j + 37, k + 31, Blocks.leaves, 7);
		world.setBlockMetadataWithNotify(i + 18, j + 37, k + 31, 7, 2);
		setBlock(world, i + 18, j + 38, k + 29, Blocks.leaves, 7);
		world.setBlockMetadataWithNotify(i + 18, j + 38, k + 29, 7, 2);
		setBlock(world, i + 18, j + 38, k + 30, Blocks.leaves, 7);
		world.setBlockMetadataWithNotify(i + 18, j + 38, k + 30, 7, 2);
		setBlock(world, i + 18, j + 38, k + 31, Blocks.leaves, 7);
		world.setBlockMetadataWithNotify(i + 18, j + 38, k + 31, 7, 2);
		setBlock(world, i + 18, j + 39, k + 30, Blocks.leaves, 7);
		world.setBlockMetadataWithNotify(i + 18, j + 39, k + 30, 7, 2);
		setBlock(world, i + 18, j + 50, k + 31, Blocks.leaves, 7);
		world.setBlockMetadataWithNotify(i + 18, j + 50, k + 31, 7, 2);
		setBlock(world, i + 18, j + 51, k + 31, Blocks.leaves, 7);
		world.setBlockMetadataWithNotify(i + 18, j + 51, k + 31, 7, 2);
		setBlock(world, i + 19, j + 23, k + 29, Blocks.log, 3);
		world.setBlockMetadataWithNotify(i + 19, j + 23, k + 29, 3, 2);
		setBlock(world, i + 19, j + 23, k + 30, Blocks.log, 3);
		world.setBlockMetadataWithNotify(i + 19, j + 23, k + 30, 3, 2);
		setBlock(world, i + 19, j + 24, k + 25, Blocks.leaves, 7);
		world.setBlockMetadataWithNotify(i + 19, j + 24, k + 25, 7, 2);
		setBlock(world, i + 19, j + 24, k + 26, Blocks.leaves, 7);
		world.setBlockMetadataWithNotify(i + 19, j + 24, k + 26, 7, 2);
		setBlock(world, i + 19, j + 24, k + 27, Blocks.leaves, 7);
		world.setBlockMetadataWithNotify(i + 19, j + 24, k + 27, 7, 2);
		setBlock(world, i + 19, j + 24, k + 28, Blocks.leaves, 7);
		world.setBlockMetadataWithNotify(i + 19, j + 24, k + 28, 7, 2);
		setBlock(world, i + 19, j + 24, k + 29, Blocks.leaves, 7);
		world.setBlockMetadataWithNotify(i + 19, j + 24, k + 29, 7, 2);
		setBlock(world, i + 19, j + 25, k + 26, Blocks.leaves, 7);
		world.setBlockMetadataWithNotify(i + 19, j + 25, k + 26, 7, 2);
		setBlock(world, i + 19, j + 25, k + 27, Blocks.leaves, 7);
		world.setBlockMetadataWithNotify(i + 19, j + 25, k + 27, 7, 2);
		setBlock(world, i + 19, j + 25, k + 28, Blocks.leaves, 7);
		world.setBlockMetadataWithNotify(i + 19, j + 25, k + 28, 7, 2);
		setBlock(world, i + 19, j + 26, k + 27, Blocks.leaves, 7);
		world.setBlockMetadataWithNotify(i + 19, j + 26, k + 27, 7, 2);
		setBlock(world, i + 19, j + 36, k + 31, Blocks.log, 3);
		world.setBlockMetadataWithNotify(i + 19, j + 36, k + 31, 3, 2);
		setBlock(world, i + 19, j + 37, k + 28, Blocks.leaves, 7);
		world.setBlockMetadataWithNotify(i + 19, j + 37, k + 28, 7, 2);
		setBlock(world, i + 19, j + 37, k + 29, Blocks.leaves, 7);
		world.setBlockMetadataWithNotify(i + 19, j + 37, k + 29, 7, 2);
		setBlock(world, i + 19, j + 37, k + 30, Blocks.log, 3);
		world.setBlockMetadataWithNotify(i + 19, j + 37, k + 30, 3, 2);
		setBlock(world, i + 19, j + 37, k + 31, Blocks.leaves, 7);
		world.setBlockMetadataWithNotify(i + 19, j + 37, k + 31, 7, 2);
		setBlock(world, i + 19, j + 38, k + 28, Blocks.leaves, 7);
		world.setBlockMetadataWithNotify(i + 19, j + 38, k + 28, 7, 2);
		setBlock(world, i + 19, j + 38, k + 29, Blocks.leaves, 7);
		world.setBlockMetadataWithNotify(i + 19, j + 38, k + 29, 7, 2);
		setBlock(world, i + 19, j + 38, k + 30, Blocks.leaves, 7);
		world.setBlockMetadataWithNotify(i + 19, j + 38, k + 30, 7, 2);
		setBlock(world, i + 19, j + 38, k + 31, Blocks.leaves, 7);
		world.setBlockMetadataWithNotify(i + 19, j + 38, k + 31, 7, 2);
		setBlock(world, i + 19, j + 39, k + 29, Blocks.leaves, 7);
		world.setBlockMetadataWithNotify(i + 19, j + 39, k + 29, 7, 2);
		setBlock(world, i + 19, j + 39, k + 30, Blocks.leaves, 7);
		world.setBlockMetadataWithNotify(i + 19, j + 39, k + 30, 7, 2);
		setBlock(world, i + 19, j + 39, k + 31, Blocks.leaves, 7);
		world.setBlockMetadataWithNotify(i + 19, j + 39, k + 31, 7, 2);
		setBlock(world, i + 19, j + 40, k + 30, Blocks.leaves, 7);
		world.setBlockMetadataWithNotify(i + 19, j + 40, k + 30, 7, 2);
		setBlock(world, i + 19, j + 50, k + 31, Blocks.leaves, 7);
		world.setBlockMetadataWithNotify(i + 19, j + 50, k + 31, 7, 2);
		setBlock(world, i + 20, j + 22, k + 31, Blocks.log, 3);
		world.setBlockMetadataWithNotify(i + 20, j + 22, k + 31, 3, 2);
		setBlock(world, i + 20, j + 24, k + 26, Blocks.leaves, 7);
		world.setBlockMetadataWithNotify(i + 20, j + 24, k + 26, 7, 2);
		setBlock(world, i + 20, j + 24, k + 27, Blocks.leaves, 7);
		world.setBlockMetadataWithNotify(i + 20, j + 24, k + 27, 7, 2);
		setBlock(world, i + 20, j + 24, k + 28, Blocks.leaves, 7);
		world.setBlockMetadataWithNotify(i + 20, j + 24, k + 28, 7, 2);
		setBlock(world, i + 20, j + 25, k + 27, Blocks.leaves, 7);
		world.setBlockMetadataWithNotify(i + 20, j + 25, k + 27, 7, 2);
		setBlock(world, i + 20, j + 37, k + 28, Blocks.leaves, 7);
		world.setBlockMetadataWithNotify(i + 20, j + 37, k + 28, 7, 2);
		setBlock(world, i + 20, j + 37, k + 29, Blocks.leaves, 7);
		world.setBlockMetadataWithNotify(i + 20, j + 37, k + 29, 7, 2);
		setBlock(world, i + 20, j + 37, k + 30, Blocks.leaves, 7);
		world.setBlockMetadataWithNotify(i + 20, j + 37, k + 30, 7, 2);
		setBlock(world, i + 20, j + 37, k + 31, Blocks.leaves, 7);
		world.setBlockMetadataWithNotify(i + 20, j + 37, k + 31, 7, 2);
		setBlock(world, i + 20, j + 38, k + 29, Blocks.leaves, 7);
		world.setBlockMetadataWithNotify(i + 20, j + 38, k + 29, 7, 2);
		setBlock(world, i + 20, j + 38, k + 30, Blocks.leaves, 7);
		world.setBlockMetadataWithNotify(i + 20, j + 38, k + 30, 7, 2);
		setBlock(world, i + 20, j + 38, k + 31, Blocks.leaves, 7);
		world.setBlockMetadataWithNotify(i + 20, j + 38, k + 31, 7, 2);
		setBlock(world, i + 20, j + 39, k + 30, Blocks.leaves, 7);
		world.setBlockMetadataWithNotify(i + 20, j + 39, k + 30, 7, 2);
		setBlock(world, i + 20, j + 59, k + 31, Blocks.leaves, 7);
		world.setBlockMetadataWithNotify(i + 20, j + 59, k + 31, 7, 2);
		setBlock(world, i + 21, j + 34, k + 22, Blocks.leaves, 7);
		world.setBlockMetadataWithNotify(i + 21, j + 34, k + 22, 7, 2);
		setBlock(world, i + 21, j + 34, k + 23, Blocks.leaves, 7);
		world.setBlockMetadataWithNotify(i + 21, j + 34, k + 23, 7, 2);
		setBlock(world, i + 21, j + 34, k + 24, Blocks.leaves, 7);
		world.setBlockMetadataWithNotify(i + 21, j + 34, k + 24, 7, 2);
		setBlock(world, i + 21, j + 34, k + 31, Blocks.leaves, 7);
		world.setBlockMetadataWithNotify(i + 21, j + 34, k + 31, 7, 2);
		setBlock(world, i + 21, j + 35, k + 23, Blocks.leaves, 7);
		world.setBlockMetadataWithNotify(i + 21, j + 35, k + 23, 7, 2);
		setBlock(world, i + 21, j + 35, k + 27, Blocks.leaves, 7);
		world.setBlockMetadataWithNotify(i + 21, j + 35, k + 27, 7, 2);
		setBlock(world, i + 21, j + 35, k + 28, Blocks.leaves, 7);
		world.setBlockMetadataWithNotify(i + 21, j + 35, k + 28, 7, 2);
		setBlock(world, i + 21, j + 35, k + 29, Blocks.leaves, 7);
		world.setBlockMetadataWithNotify(i + 21, j + 35, k + 29, 7, 2);
		setBlock(world, i + 21, j + 36, k + 28, Blocks.leaves, 7);
		world.setBlockMetadataWithNotify(i + 21, j + 36, k + 28, 7, 2);
		setBlock(world, i + 21, j + 37, k + 29, Blocks.leaves, 7);
		world.setBlockMetadataWithNotify(i + 21, j + 37, k + 29, 7, 2);
		setBlock(world, i + 21, j + 37, k + 30, Blocks.leaves, 7);
		world.setBlockMetadataWithNotify(i + 21, j + 37, k + 30, 7, 2);
		setBlock(world, i + 21, j + 37, k + 31, Blocks.leaves, 7);
		world.setBlockMetadataWithNotify(i + 21, j + 37, k + 31, 7, 2);
		setBlock(world, i + 21, j + 38, k + 30, Blocks.leaves, 7);
		world.setBlockMetadataWithNotify(i + 21, j + 38, k + 30, 7, 2);
		setBlock(world, i + 21, j + 59, k + 31, Blocks.leaves, 7);
		world.setBlockMetadataWithNotify(i + 21, j + 59, k + 31, 7, 2);
		setBlock(world, i + 21, j + 60, k + 31, Blocks.leaves, 7);
		world.setBlockMetadataWithNotify(i + 21, j + 60, k + 31, 7, 2);
		setBlock(world, i + 22, j + 27, k + 22, Blocks.leaves, 7);
		world.setBlockMetadataWithNotify(i + 22, j + 27, k + 22, 7, 2);
		setBlock(world, i + 22, j + 27, k + 23, Blocks.leaves, 7);
		world.setBlockMetadataWithNotify(i + 22, j + 27, k + 23, 7, 2);
		setBlock(world, i + 22, j + 27, k + 24, Blocks.leaves, 7);
		world.setBlockMetadataWithNotify(i + 22, j + 27, k + 24, 7, 2);
		setBlock(world, i + 22, j + 28, k + 23, Blocks.leaves, 7);
		world.setBlockMetadataWithNotify(i + 22, j + 28, k + 23, 7, 2);
		setBlock(world, i + 22, j + 32, k + 29, Blocks.log, 1);
		world.setBlockMetadataWithNotify(i + 22, j + 32, k + 29, 1, 2);
		setBlock(world, i + 22, j + 33, k + 29, Blocks.log, 1);
		world.setBlockMetadataWithNotify(i + 22, j + 33, k + 29, 1, 2);
		setBlock(world, i + 22, j + 33, k + 30, Blocks.log, 1);
		world.setBlockMetadataWithNotify(i + 22, j + 33, k + 30, 1, 2);
		setBlock(world, i + 22, j + 33, k + 31, Blocks.log, 1);
		world.setBlockMetadataWithNotify(i + 22, j + 33, k + 31, 1, 2);
		setBlock(world, i + 22, j + 34, k + 21, Blocks.leaves, 7);
		world.setBlockMetadataWithNotify(i + 22, j + 34, k + 21, 7, 2);
		setBlock(world, i + 22, j + 34, k + 22, Blocks.leaves, 7);
		world.setBlockMetadataWithNotify(i + 22, j + 34, k + 22, 7, 2);
		setBlock(world, i + 22, j + 34, k + 23, Blocks.leaves, 7);
		world.setBlockMetadataWithNotify(i + 22, j + 34, k + 23, 7, 2);
		setBlock(world, i + 22, j + 34, k + 24, Blocks.leaves, 7);
		world.setBlockMetadataWithNotify(i + 22, j + 34, k + 24, 7, 2);
		setBlock(world, i + 22, j + 34, k + 25, Blocks.leaves, 7);
		world.setBlockMetadataWithNotify(i + 22, j + 34, k + 25, 7, 2);
		setBlock(world, i + 22, j + 34, k + 29, Blocks.log, 1);
		world.setBlockMetadataWithNotify(i + 22, j + 34, k + 29, 1, 2);
		setBlock(world, i + 22, j + 34, k + 30, Blocks.leaves, 7);
		world.setBlockMetadataWithNotify(i + 22, j + 34, k + 30, 7, 2);
		setBlock(world, i + 22, j + 34, k + 31, Blocks.leaves, 7);
		world.setBlockMetadataWithNotify(i + 22, j + 34, k + 31, 7, 2);
		setBlock(world, i + 22, j + 35, k + 22, Blocks.leaves, 7);
		world.setBlockMetadataWithNotify(i + 22, j + 35, k + 22, 7, 2);
		setBlock(world, i + 22, j + 35, k + 23, Blocks.leaves, 7);
		world.setBlockMetadataWithNotify(i + 22, j + 35, k + 23, 7, 2);
		setBlock(world, i + 22, j + 35, k + 24, Blocks.leaves, 7);
		world.setBlockMetadataWithNotify(i + 22, j + 35, k + 24, 7, 2);
		setBlock(world, i + 22, j + 35, k + 26, Blocks.leaves, 7);
		world.setBlockMetadataWithNotify(i + 22, j + 35, k + 26, 7, 2);
		setBlock(world, i + 22, j + 35, k + 27, Blocks.leaves, 7);
		world.setBlockMetadataWithNotify(i + 22, j + 35, k + 27, 7, 2);
		setBlock(world, i + 22, j + 35, k + 28, Blocks.leaves, 7);
		world.setBlockMetadataWithNotify(i + 22, j + 35, k + 28, 7, 2);
		setBlock(world, i + 22, j + 35, k + 29, Blocks.leaves, 7);
		world.setBlockMetadataWithNotify(i + 22, j + 35, k + 29, 7, 2);
		setBlock(world, i + 22, j + 35, k + 30, Blocks.leaves, 7);
		world.setBlockMetadataWithNotify(i + 22, j + 35, k + 30, 7, 2);
		setBlock(world, i + 22, j + 35, k + 31, Blocks.leaves, 7);
		world.setBlockMetadataWithNotify(i + 22, j + 35, k + 31, 7, 2);
		setBlock(world, i + 22, j + 36, k + 23, Blocks.leaves, 7);
		world.setBlockMetadataWithNotify(i + 22, j + 36, k + 23, 7, 2);
		setBlock(world, i + 22, j + 36, k + 27, Blocks.leaves, 7);
		world.setBlockMetadataWithNotify(i + 22, j + 36, k + 27, 7, 2);
		setBlock(world, i + 22, j + 36, k + 28, Blocks.leaves, 7);
		world.setBlockMetadataWithNotify(i + 22, j + 36, k + 28, 7, 2);
		setBlock(world, i + 22, j + 36, k + 29, Blocks.leaves, 7);
		world.setBlockMetadataWithNotify(i + 22, j + 36, k + 29, 7, 2);
		setBlock(world, i + 22, j + 37, k + 28, Blocks.leaves, 7);
		world.setBlockMetadataWithNotify(i + 22, j + 37, k + 28, 7, 2);
		setBlock(world, i + 22, j + 59, k + 31, Blocks.leaves, 7);
		world.setBlockMetadataWithNotify(i + 22, j + 59, k + 31, 7, 2);
		setBlock(world, i + 23, j + 24, k + 29, Blocks.leaves, 7);
		world.setBlockMetadataWithNotify(i + 23, j + 24, k + 29, 7, 2);
		setBlock(world, i + 23, j + 24, k + 30, Blocks.leaves, 7);
		world.setBlockMetadataWithNotify(i + 23, j + 24, k + 30, 7, 2);
		setBlock(world, i + 23, j + 24, k + 31, Blocks.leaves, 7);
		world.setBlockMetadataWithNotify(i + 23, j + 24, k + 31, 7, 2);
		setBlock(world, i + 23, j + 25, k + 30, Blocks.leaves, 7);
		world.setBlockMetadataWithNotify(i + 23, j + 25, k + 30, 7, 2);
		setBlock(world, i + 23, j + 27, k + 21, Blocks.leaves, 7);
		world.setBlockMetadataWithNotify(i + 23, j + 27, k + 21, 7, 2);
		setBlock(world, i + 23, j + 27, k + 22, Blocks.leaves, 7);
		world.setBlockMetadataWithNotify(i + 23, j + 27, k + 22, 7, 2);
		setBlock(world, i + 23, j + 27, k + 23, Blocks.leaves, 7);
		world.setBlockMetadataWithNotify(i + 23, j + 27, k + 23, 7, 2);
		setBlock(world, i + 23, j + 27, k + 24, Blocks.leaves, 7);
		world.setBlockMetadataWithNotify(i + 23, j + 27, k + 24, 7, 2);
		setBlock(world, i + 23, j + 27, k + 25, Blocks.leaves, 7);
		world.setBlockMetadataWithNotify(i + 23, j + 27, k + 25, 7, 2);
		setBlock(world, i + 23, j + 28, k + 22, Blocks.leaves, 7);
		world.setBlockMetadataWithNotify(i + 23, j + 28, k + 22, 7, 2);
		setBlock(world, i + 23, j + 28, k + 23, Blocks.leaves, 7);
		world.setBlockMetadataWithNotify(i + 23, j + 28, k + 23, 7, 2);
		setBlock(world, i + 23, j + 28, k + 24, Blocks.leaves, 7);
		world.setBlockMetadataWithNotify(i + 23, j + 28, k + 24, 7, 2);
		setBlock(world, i + 23, j + 29, k + 23, Blocks.leaves, 7);
		world.setBlockMetadataWithNotify(i + 23, j + 29, k + 23, 7, 2);
		setBlock(world, i + 23, j + 32, k + 28, Blocks.log, 1);
		world.setBlockMetadataWithNotify(i + 23, j + 32, k + 28, 1, 2);
		setBlock(world, i + 23, j + 32, k + 29, Blocks.log, 1);
		world.setBlockMetadataWithNotify(i + 23, j + 32, k + 29, 1, 2);
		setBlock(world, i + 23, j + 32, k + 30, Blocks.log, 1);
		world.setBlockMetadataWithNotify(i + 23, j + 32, k + 30, 1, 2);
		setBlock(world, i + 23, j + 32, k + 31, Blocks.log, 1);
		world.setBlockMetadataWithNotify(i + 23, j + 32, k + 31, 1, 2);
		setBlock(world, i + 23, j + 33, k + 24, Blocks.log, 3);
		world.setBlockMetadataWithNotify(i + 23, j + 33, k + 24, 3, 2);
		setBlock(world, i + 23, j + 33, k + 25, Blocks.log, 3);
		world.setBlockMetadataWithNotify(i + 23, j + 33, k + 25, 3, 2);
		setBlock(world, i + 23, j + 33, k + 26, Blocks.log, 3);
		world.setBlockMetadataWithNotify(i + 23, j + 33, k + 26, 3, 2);
		setBlock(world, i + 23, j + 33, k + 27, Blocks.log, 3);
		world.setBlockMetadataWithNotify(i + 23, j + 33, k + 27, 3, 2);
		setBlock(world, i + 23, j + 33, k + 28, Blocks.log, 1);
		world.setBlockMetadataWithNotify(i + 23, j + 33, k + 28, 1, 2);
		setBlock(world, i + 23, j + 33, k + 29, Blocks.log, 1);
		world.setBlockMetadataWithNotify(i + 23, j + 33, k + 29, 1, 2);
		setBlock(world, i + 23, j + 33, k + 31, Blocks.log, 1);
		world.setBlockMetadataWithNotify(i + 23, j + 33, k + 31, 1, 2);
		setBlock(world, i + 23, j + 34, k + 21, Blocks.leaves, 7);
		world.setBlockMetadataWithNotify(i + 23, j + 34, k + 21, 7, 2);
		setBlock(world, i + 23, j + 34, k + 22, Blocks.leaves, 7);
		world.setBlockMetadataWithNotify(i + 23, j + 34, k + 22, 7, 2);
		setBlock(world, i + 23, j + 34, k + 23, Blocks.log, 3);
		world.setBlockMetadataWithNotify(i + 23, j + 34, k + 23, 3, 2);
		setBlock(world, i + 23, j + 34, k + 24, Blocks.leaves, 7);
		world.setBlockMetadataWithNotify(i + 23, j + 34, k + 24, 7, 2);
		setBlock(world, i + 23, j + 34, k + 25, Blocks.leaves, 7);
		world.setBlockMetadataWithNotify(i + 23, j + 34, k + 25, 7, 2);
		setBlock(world, i + 23, j + 34, k + 28, Blocks.log, 1);
		world.setBlockMetadataWithNotify(i + 23, j + 34, k + 28, 1, 2);
		setBlock(world, i + 23, j + 34, k + 29, Blocks.log, 1);
		world.setBlockMetadataWithNotify(i + 23, j + 34, k + 29, 1, 2);
		setBlock(world, i + 23, j + 34, k + 30, Blocks.log, 1);
		world.setBlockMetadataWithNotify(i + 23, j + 34, k + 30, 1, 2);
		setBlock(world, i + 23, j + 34, k + 31, Blocks.log, 1);
		world.setBlockMetadataWithNotify(i + 23, j + 34, k + 31, 1, 2);
		setBlock(world, i + 23, j + 35, k + 21, Blocks.leaves, 7);
		world.setBlockMetadataWithNotify(i + 23, j + 35, k + 21, 7, 2);
		setBlock(world, i + 23, j + 35, k + 22, Blocks.leaves, 7);
		world.setBlockMetadataWithNotify(i + 23, j + 35, k + 22, 7, 2);
		setBlock(world, i + 23, j + 35, k + 23, Blocks.leaves, 7);
		world.setBlockMetadataWithNotify(i + 23, j + 35, k + 23, 7, 2);
		setBlock(world, i + 23, j + 35, k + 24, Blocks.leaves, 7);
		world.setBlockMetadataWithNotify(i + 23, j + 35, k + 24, 7, 2);
		setBlock(world, i + 23, j + 35, k + 25, Blocks.leaves, 7);
		world.setBlockMetadataWithNotify(i + 23, j + 35, k + 25, 7, 2);
		setBlock(world, i + 23, j + 35, k + 26, Blocks.leaves, 7);
		world.setBlockMetadataWithNotify(i + 23, j + 35, k + 26, 7, 2);
		setBlock(world, i + 23, j + 35, k + 27, Blocks.leaves, 7);
		world.setBlockMetadataWithNotify(i + 23, j + 35, k + 27, 7, 2);
		setBlock(world, i + 23, j + 35, k + 28, Blocks.log, 3);
		world.setBlockMetadataWithNotify(i + 23, j + 35, k + 28, 3, 2);
		setBlock(world, i + 23, j + 35, k + 29, Blocks.leaves, 7);
		world.setBlockMetadataWithNotify(i + 23, j + 35, k + 29, 7, 2);
		setBlock(world, i + 23, j + 35, k + 30, Blocks.leaves, 7);
		world.setBlockMetadataWithNotify(i + 23, j + 35, k + 30, 7, 2);
		setBlock(world, i + 23, j + 35, k + 31, Blocks.leaves, 7);
		world.setBlockMetadataWithNotify(i + 23, j + 35, k + 31, 7, 2);
		setBlock(world, i + 23, j + 36, k + 22, Blocks.leaves, 7);
		world.setBlockMetadataWithNotify(i + 23, j + 36, k + 22, 7, 2);
		setBlock(world, i + 23, j + 36, k + 23, Blocks.leaves, 7);
		world.setBlockMetadataWithNotify(i + 23, j + 36, k + 23, 7, 2);
		setBlock(world, i + 23, j + 36, k + 24, Blocks.leaves, 7);
		world.setBlockMetadataWithNotify(i + 23, j + 36, k + 24, 7, 2);
		setBlock(world, i + 23, j + 36, k + 26, Blocks.leaves, 7);
		world.setBlockMetadataWithNotify(i + 23, j + 36, k + 26, 7, 2);
		setBlock(world, i + 23, j + 36, k + 27, Blocks.leaves, 7);
		world.setBlockMetadataWithNotify(i + 23, j + 36, k + 27, 7, 2);
		setBlock(world, i + 23, j + 36, k + 28, Blocks.leaves, 7);
		world.setBlockMetadataWithNotify(i + 23, j + 36, k + 28, 7, 2);
		setBlock(world, i + 23, j + 36, k + 29, Blocks.leaves, 7);
		world.setBlockMetadataWithNotify(i + 23, j + 36, k + 29, 7, 2);
		setBlock(world, i + 23, j + 36, k + 30, Blocks.leaves, 7);
		world.setBlockMetadataWithNotify(i + 23, j + 36, k + 30, 7, 2);
		setBlock(world, i + 23, j + 36, k + 31, Blocks.leaves, 7);
		world.setBlockMetadataWithNotify(i + 23, j + 36, k + 31, 7, 2);
		setBlock(world, i + 23, j + 37, k + 23, Blocks.leaves, 7);
		world.setBlockMetadataWithNotify(i + 23, j + 37, k + 23, 7, 2);
		setBlock(world, i + 23, j + 37, k + 27, Blocks.leaves, 7);
		world.setBlockMetadataWithNotify(i + 23, j + 37, k + 27, 7, 2);
		setBlock(world, i + 23, j + 37, k + 28, Blocks.leaves, 7);
		world.setBlockMetadataWithNotify(i + 23, j + 37, k + 28, 7, 2);
		setBlock(world, i + 23, j + 37, k + 29, Blocks.leaves, 7);
		/* 1000 */world.setBlockMetadataWithNotify(i + 23, j + 37, k + 29, 7, 2);
		/* 1001 */setBlock(world, i + 23, j + 38, k + 28, Blocks.leaves, 7);
		/* 1002 */world.setBlockMetadataWithNotify(i + 23, j + 38, k + 28, 7, 2);
		/* 1003 */setBlock(world, i + 24, j + 24, k + 28, Blocks.leaves, 7);
		/* 1004 */world.setBlockMetadataWithNotify(i + 24, j + 24, k + 28, 7, 2);
		/* 1005 */setBlock(world, i + 24, j + 24, k + 29, Blocks.leaves, 7);
		/* 1006 */world.setBlockMetadataWithNotify(i + 24, j + 24, k + 29, 7, 2);
		/* 1007 */setBlock(world, i + 24, j + 24, k + 30, Blocks.leaves, 7);
		/* 1008 */world.setBlockMetadataWithNotify(i + 24, j + 24, k + 30, 7, 2);
		/* 1009 */setBlock(world, i + 24, j + 24, k + 31, Blocks.leaves, 7);
		/* 1010 */world.setBlockMetadataWithNotify(i + 24, j + 24, k + 31, 7, 2);
		/* 1011 */setBlock(world, i + 24, j + 25, k + 29, Blocks.leaves, 7);
		/* 1012 */world.setBlockMetadataWithNotify(i + 24, j + 25, k + 29, 7, 2);
		/* 1013 */setBlock(world, i + 24, j + 25, k + 30, Blocks.leaves, 7);
		/* 1014 */world.setBlockMetadataWithNotify(i + 24, j + 25, k + 30, 7, 2);
		/* 1015 */setBlock(world, i + 24, j + 25, k + 31, Blocks.leaves, 7);
		/* 1016 */world.setBlockMetadataWithNotify(i + 24, j + 25, k + 31, 7, 2);
		/* 1017 */setBlock(world, i + 24, j + 26, k + 24, Blocks.log, 3);
		/* 1018 */world.setBlockMetadataWithNotify(i + 24, j + 26, k + 24, 3, 2);
		/* 1019 */setBlock(world, i + 24, j + 26, k + 25, Blocks.log, 3);
		/* 1020 */world.setBlockMetadataWithNotify(i + 24, j + 26, k + 25, 3, 2);
		/* 1021 */setBlock(world, i + 24, j + 26, k + 26, Blocks.log, 3);
		/* 1022 */world.setBlockMetadataWithNotify(i + 24, j + 26, k + 26, 3, 2);
		/* 1023 */setBlock(world, i + 24, j + 26, k + 27, Blocks.log, 3);
		/* 1024 */world.setBlockMetadataWithNotify(i + 24, j + 26, k + 27, 3, 2);
		/* 1025 */setBlock(world, i + 24, j + 26, k + 28, Blocks.log, 3);
		/* 1026 */world.setBlockMetadataWithNotify(i + 24, j + 26, k + 28, 3, 2);
		/* 1027 */setBlock(world, i + 24, j + 26, k + 29, Blocks.log, 3);
		/* 1028 */world.setBlockMetadataWithNotify(i + 24, j + 26, k + 29, 3, 2);
		/* 1029 */setBlock(world, i + 24, j + 26, k + 30, Blocks.log, 3);
		/* 1030 */world.setBlockMetadataWithNotify(i + 24, j + 26, k + 30, 3, 2);
		/* 1031 */setBlock(world, i + 24, j + 26, k + 31, Blocks.log, 3);
		/* 1032 */world.setBlockMetadataWithNotify(i + 24, j + 26, k + 31, 3, 2);
		/* 1033 */setBlock(world, i + 24, j + 27, k + 21, Blocks.leaves, 7);
		/* 1034 */world.setBlockMetadataWithNotify(i + 24, j + 27, k + 21, 7, 2);
		/* 1035 */setBlock(world, i + 24, j + 27, k + 22, Blocks.leaves, 7);
		/* 1036 */world.setBlockMetadataWithNotify(i + 24, j + 27, k + 22, 7, 2);
		/* 1037 */setBlock(world, i + 24, j + 27, k + 23, Blocks.log, 3);
		/* 1038 */world.setBlockMetadataWithNotify(i + 24, j + 27, k + 23, 3, 2);
		/* 1039 */setBlock(world, i + 24, j + 27, k + 24, Blocks.leaves, 7);
		/* 1040 */world.setBlockMetadataWithNotify(i + 24, j + 27, k + 24, 7, 2);
		/* 1041 */setBlock(world, i + 24, j + 27, k + 25, Blocks.leaves, 7);
		/* 1042 */world.setBlockMetadataWithNotify(i + 24, j + 27, k + 25, 7, 2);
		/* 1043 */setBlock(world, i + 24, j + 28, k + 21, Blocks.leaves, 7);
		/* 1044 */world.setBlockMetadataWithNotify(i + 24, j + 28, k + 21, 7, 2);
		/* 1045 */setBlock(world, i + 24, j + 28, k + 22, Blocks.leaves, 7);
		/* 1046 */world.setBlockMetadataWithNotify(i + 24, j + 28, k + 22, 7, 2);
		/* 1047 */setBlock(world, i + 24, j + 28, k + 23, Blocks.leaves, 7);
		/* 1048 */world.setBlockMetadataWithNotify(i + 24, j + 28, k + 23, 7, 2);
		/* 1049 */setBlock(world, i + 24, j + 28, k + 24, Blocks.leaves, 7);
		/* 1050 */world.setBlockMetadataWithNotify(i + 24, j + 28, k + 24, 7, 2);
		/* 1051 */setBlock(world, i + 24, j + 28, k + 25, Blocks.leaves, 7);
		/* 1052 */world.setBlockMetadataWithNotify(i + 24, j + 28, k + 25, 7, 2);
		/* 1053 */setBlock(world, i + 24, j + 29, k + 22, Blocks.leaves, 7);
		/* 1054 */world.setBlockMetadataWithNotify(i + 24, j + 29, k + 22, 7, 2);
		/* 1055 */setBlock(world, i + 24, j + 29, k + 23, Blocks.leaves, 7);
		/* 1056 */world.setBlockMetadataWithNotify(i + 24, j + 29, k + 23, 7, 2);
		/* 1057 */setBlock(world, i + 24, j + 29, k + 24, Blocks.leaves, 7);
		/* 1058 */world.setBlockMetadataWithNotify(i + 24, j + 29, k + 24, 7, 2);
		/* 1059 */setBlock(world, i + 24, j + 30, k + 23, Blocks.leaves, 7);
		/* 1060 */world.setBlockMetadataWithNotify(i + 24, j + 30, k + 23, 7, 2);
		/* 1061 */setBlock(world, i + 24, j + 32, k + 29, Blocks.log, 1);
		/* 1062 */world.setBlockMetadataWithNotify(i + 24, j + 32, k + 29, 1, 2);
		/* 1063 */setBlock(world, i + 24, j + 33, k + 29, Blocks.log, 1);
		/* 1064 */world.setBlockMetadataWithNotify(i + 24, j + 33, k + 29, 1, 2);
		/* 1065 */setBlock(world, i + 24, j + 33, k + 30, Blocks.log, 1);
		/* 1066 */world.setBlockMetadataWithNotify(i + 24, j + 33, k + 30, 1, 2);
		/* 1067 */setBlock(world, i + 24, j + 33, k + 31, Blocks.log, 1);
		/* 1068 */world.setBlockMetadataWithNotify(i + 24, j + 33, k + 31, 1, 2);
		/* 1069 */setBlock(world, i + 24, j + 34, k + 21, Blocks.leaves, 7);
		/* 1070 */world.setBlockMetadataWithNotify(i + 24, j + 34, k + 21, 7, 2);
		/* 1071 */setBlock(world, i + 24, j + 34, k + 22, Blocks.leaves, 7);
		/* 1072 */world.setBlockMetadataWithNotify(i + 24, j + 34, k + 22, 7, 2);
		/* 1073 */setBlock(world, i + 24, j + 34, k + 23, Blocks.leaves, 7);
		/* 1074 */world.setBlockMetadataWithNotify(i + 24, j + 34, k + 23, 7, 2);
		/* 1075 */setBlock(world, i + 24, j + 34, k + 24, Blocks.leaves, 7);
		/* 1076 */world.setBlockMetadataWithNotify(i + 24, j + 34, k + 24, 7, 2);
		/* 1077 */setBlock(world, i + 24, j + 34, k + 25, Blocks.leaves, 7);
		/* 1078 */world.setBlockMetadataWithNotify(i + 24, j + 34, k + 25, 7, 2);
		/* 1079 */setBlock(world, i + 24, j + 34, k + 29, Blocks.log, 1);
		/* 1080 */world.setBlockMetadataWithNotify(i + 24, j + 34, k + 29, 1, 2);
		/* 1081 */setBlock(world, i + 24, j + 34, k + 30, Blocks.leaves, 7);
		/* 1082 */world.setBlockMetadataWithNotify(i + 24, j + 34, k + 30, 7, 2);
		/* 1083 */setBlock(world, i + 24, j + 34, k + 31, Blocks.leaves, 7);
		/* 1084 */world.setBlockMetadataWithNotify(i + 24, j + 34, k + 31, 7, 2);
		/* 1085 */setBlock(world, i + 24, j + 35, k + 22, Blocks.leaves, 7);
		/* 1086 */world.setBlockMetadataWithNotify(i + 24, j + 35, k + 22, 7, 2);
		/* 1087 */setBlock(world, i + 24, j + 35, k + 23, Blocks.leaves, 7);
		/* 1088 */world.setBlockMetadataWithNotify(i + 24, j + 35, k + 23, 7, 2);
		/* 1089 */setBlock(world, i + 24, j + 35, k + 24, Blocks.leaves, 7);
		/* 1090 */world.setBlockMetadataWithNotify(i + 24, j + 35, k + 24, 7, 2);
		/* 1091 */setBlock(world, i + 24, j + 35, k + 26, Blocks.leaves, 7);
		/* 1092 */world.setBlockMetadataWithNotify(i + 24, j + 35, k + 26, 7, 2);
		/* 1093 */setBlock(world, i + 24, j + 35, k + 27, Blocks.leaves, 7);
		/* 1094 */world.setBlockMetadataWithNotify(i + 24, j + 35, k + 27, 7, 2);
		/* 1095 */setBlock(world, i + 24, j + 35, k + 28, Blocks.leaves, 7);
		/* 1096 */world.setBlockMetadataWithNotify(i + 24, j + 35, k + 28, 7, 2);
		/* 1097 */setBlock(world, i + 24, j + 35, k + 29, Blocks.leaves, 7);
		/* 1098 */world.setBlockMetadataWithNotify(i + 24, j + 35, k + 29, 7, 2);
		/* 1099 */setBlock(world, i + 24, j + 35, k + 30, Blocks.leaves, 7);
		/* 1100 */world.setBlockMetadataWithNotify(i + 24, j + 35, k + 30, 7, 2);
		/* 1101 */setBlock(world, i + 24, j + 35, k + 31, Blocks.leaves, 7);
		/* 1102 */world.setBlockMetadataWithNotify(i + 24, j + 35, k + 31, 7, 2);
		/* 1103 */setBlock(world, i + 24, j + 36, k + 23, Blocks.leaves, 7);
		/* 1104 */world.setBlockMetadataWithNotify(i + 24, j + 36, k + 23, 7, 2);
		/* 1105 */setBlock(world, i + 24, j + 36, k + 27, Blocks.leaves, 7);
		/* 1106 */world.setBlockMetadataWithNotify(i + 24, j + 36, k + 27, 7, 2);
		/* 1107 */setBlock(world, i + 24, j + 36, k + 28, Blocks.leaves, 7);
		/* 1108 */world.setBlockMetadataWithNotify(i + 24, j + 36, k + 28, 7, 2);
		/* 1109 */setBlock(world, i + 24, j + 36, k + 29, Blocks.leaves, 7);
		/* 1110 */world.setBlockMetadataWithNotify(i + 24, j + 36, k + 29, 7, 2);
		/* 1111 */setBlock(world, i + 24, j + 37, k + 28, Blocks.leaves, 7);
		/* 1112 */world.setBlockMetadataWithNotify(i + 24, j + 37, k + 28, 7, 2);
		/* 1113 */setBlock(world, i + 25, j + 23, k + 31, Blocks.log, 3);
		/* 1114 */world.setBlockMetadataWithNotify(i + 25, j + 23, k + 31, 3, 2);
		/* 1115 */setBlock(world, i + 25, j + 24, k + 28, Blocks.leaves, 7);
		/* 1116 */world.setBlockMetadataWithNotify(i + 25, j + 24, k + 28, 7, 2);
		/* 1117 */setBlock(world, i + 25, j + 24, k + 29, Blocks.leaves, 7);
		/* 1118 */world.setBlockMetadataWithNotify(i + 25, j + 24, k + 29, 7, 2);
		/* 1119 */setBlock(world, i + 25, j + 24, k + 30, Blocks.log, 3);
		/* 1120 */world.setBlockMetadataWithNotify(i + 25, j + 24, k + 30, 3, 2);
		/* 1121 */setBlock(world, i + 25, j + 24, k + 31, Blocks.leaves, 7);
		/* 1122 */world.setBlockMetadataWithNotify(i + 25, j + 24, k + 31, 7, 2);
		/* 1123 */setBlock(world, i + 25, j + 25, k + 28, Blocks.leaves, 7);
		/* 1124 */world.setBlockMetadataWithNotify(i + 25, j + 25, k + 28, 7, 2);
		/* 1125 */setBlock(world, i + 25, j + 25, k + 29, Blocks.leaves, 7);
		/* 1126 */world.setBlockMetadataWithNotify(i + 25, j + 25, k + 29, 7, 2);
		/* 1127 */setBlock(world, i + 25, j + 25, k + 30, Blocks.leaves, 7);
		/* 1128 */world.setBlockMetadataWithNotify(i + 25, j + 25, k + 30, 7, 2);
		/* 1129 */setBlock(world, i + 25, j + 25, k + 31, Blocks.leaves, 7);
		/* 1130 */world.setBlockMetadataWithNotify(i + 25, j + 25, k + 31, 7, 2);
		/* 1131 */setBlock(world, i + 25, j + 26, k + 29, Blocks.leaves, 7);
		/* 1132 */world.setBlockMetadataWithNotify(i + 25, j + 26, k + 29, 7, 2);
		/* 1133 */setBlock(world, i + 25, j + 26, k + 30, Blocks.leaves, 7);
		/* 1134 */world.setBlockMetadataWithNotify(i + 25, j + 26, k + 30, 7, 2);
		/* 1135 */setBlock(world, i + 25, j + 26, k + 31, Blocks.leaves, 7);
		/* 1136 */world.setBlockMetadataWithNotify(i + 25, j + 26, k + 31, 7, 2);
		/* 1137 */setBlock(world, i + 25, j + 27, k + 21, Blocks.leaves, 7);
		/* 1138 */world.setBlockMetadataWithNotify(i + 25, j + 27, k + 21, 7, 2);
		/* 1139 */setBlock(world, i + 25, j + 27, k + 22, Blocks.leaves, 7);
		/* 1140 */world.setBlockMetadataWithNotify(i + 25, j + 27, k + 22, 7, 2);
		/* 1141 */setBlock(world, i + 25, j + 27, k + 23, Blocks.leaves, 7);
		/* 1142 */world.setBlockMetadataWithNotify(i + 25, j + 27, k + 23, 7, 2);
		/* 1143 */setBlock(world, i + 25, j + 27, k + 24, Blocks.leaves, 7);
		/* 1144 */world.setBlockMetadataWithNotify(i + 25, j + 27, k + 24, 7, 2);
		/* 1145 */setBlock(world, i + 25, j + 27, k + 25, Blocks.leaves, 7);
		/* 1146 */world.setBlockMetadataWithNotify(i + 25, j + 27, k + 25, 7, 2);
		/* 1147 */setBlock(world, i + 25, j + 27, k + 30, Blocks.leaves, 7);
		/* 1148 */world.setBlockMetadataWithNotify(i + 25, j + 27, k + 30, 7, 2);
		/* 1149 */setBlock(world, i + 25, j + 28, k + 22, Blocks.leaves, 7);
		/* 1150 */world.setBlockMetadataWithNotify(i + 25, j + 28, k + 22, 7, 2);
		/* 1151 */setBlock(world, i + 25, j + 28, k + 23, Blocks.leaves, 7);
		/* 1152 */world.setBlockMetadataWithNotify(i + 25, j + 28, k + 23, 7, 2);
		/* 1153 */setBlock(world, i + 25, j + 28, k + 24, Blocks.leaves, 7);
		/* 1154 */world.setBlockMetadataWithNotify(i + 25, j + 28, k + 24, 7, 2);
		/* 1155 */setBlock(world, i + 25, j + 28, k + 30, Blocks.log, 1);
		/* 1156 */world.setBlockMetadataWithNotify(i + 25, j + 28, k + 30, 1, 2);
		/* 1157 */setBlock(world, i + 25, j + 28, k + 31, Blocks.log, 1);
		/* 1158 */world.setBlockMetadataWithNotify(i + 25, j + 28, k + 31, 1, 2);
		/* 1159 */setBlock(world, i + 25, j + 29, k + 23, Blocks.leaves, 7);
		/* 1160 */world.setBlockMetadataWithNotify(i + 25, j + 29, k + 23, 7, 2);
		/* 1161 */setBlock(world, i + 25, j + 29, k + 29, Blocks.log, 1);
		/* 1162 */world.setBlockMetadataWithNotify(i + 25, j + 29, k + 29, 1, 2);
		/* 1163 */setBlock(world, i + 25, j + 29, k + 30, Blocks.log, 1);
		/* 1164 */world.setBlockMetadataWithNotify(i + 25, j + 29, k + 30, 1, 2);
		/* 1165 */setBlock(world, i + 25, j + 29, k + 31, Blocks.log, 1);
		/* 1166 */world.setBlockMetadataWithNotify(i + 25, j + 29, k + 31, 1, 2);
		/* 1167 */setBlock(world, i + 25, j + 34, k + 22, Blocks.leaves, 7);
		/* 1168 */world.setBlockMetadataWithNotify(i + 25, j + 34, k + 22, 7, 2);
		/* 1169 */setBlock(world, i + 25, j + 34, k + 23, Blocks.leaves, 7);
		/* 1170 */world.setBlockMetadataWithNotify(i + 25, j + 34, k + 23, 7, 2);
		/* 1171 */setBlock(world, i + 25, j + 34, k + 24, Blocks.leaves, 7);
		/* 1172 */world.setBlockMetadataWithNotify(i + 25, j + 34, k + 24, 7, 2);
		/* 1173 */setBlock(world, i + 25, j + 34, k + 31, Blocks.leaves, 7);
		/* 1174 */world.setBlockMetadataWithNotify(i + 25, j + 34, k + 31, 7, 2);
		/* 1175 */setBlock(world, i + 25, j + 35, k + 23, Blocks.leaves, 7);
		/* 1176 */world.setBlockMetadataWithNotify(i + 25, j + 35, k + 23, 7, 2);
		/* 1177 */setBlock(world, i + 25, j + 35, k + 27, Blocks.leaves, 7);
		/* 1178 */world.setBlockMetadataWithNotify(i + 25, j + 35, k + 27, 7, 2);
		/* 1179 */setBlock(world, i + 25, j + 35, k + 28, Blocks.leaves, 7);
		/* 1180 */world.setBlockMetadataWithNotify(i + 25, j + 35, k + 28, 7, 2);
		/* 1181 */setBlock(world, i + 25, j + 35, k + 29, Blocks.leaves, 7);
		/* 1182 */world.setBlockMetadataWithNotify(i + 25, j + 35, k + 29, 7, 2);
		/* 1183 */setBlock(world, i + 25, j + 36, k + 28, Blocks.leaves, 7);
		/* 1184 */world.setBlockMetadataWithNotify(i + 25, j + 36, k + 28, 7, 2);
		/* 1185 */setBlock(world, i + 26, j + 24, k + 28, Blocks.leaves, 7);
		/* 1186 */world.setBlockMetadataWithNotify(i + 26, j + 24, k + 28, 7, 2);
		/* 1187 */setBlock(world, i + 26, j + 24, k + 29, Blocks.leaves, 7);
		/* 1188 */world.setBlockMetadataWithNotify(i + 26, j + 24, k + 29, 7, 2);
		/* 1189 */setBlock(world, i + 26, j + 24, k + 30, Blocks.leaves, 7);
		/* 1190 */world.setBlockMetadataWithNotify(i + 26, j + 24, k + 30, 7, 2);
		/* 1191 */setBlock(world, i + 26, j + 24, k + 31, Blocks.log, 1);
		/* 1192 */world.setBlockMetadataWithNotify(i + 26, j + 24, k + 31, 1, 2);
		/* 1193 */setBlock(world, i + 26, j + 25, k + 29, Blocks.leaves, 7);
		/* 1194 */world.setBlockMetadataWithNotify(i + 26, j + 25, k + 29, 7, 2);
		/* 1195 */setBlock(world, i + 26, j + 25, k + 30, Blocks.leaves, 7);
		/* 1196 */world.setBlockMetadataWithNotify(i + 26, j + 25, k + 30, 7, 2);
		/* 1197 */setBlock(world, i + 26, j + 25, k + 31, Blocks.leaves, 7);
		/* 1198 */world.setBlockMetadataWithNotify(i + 26, j + 25, k + 31, 7, 2);
		/* 1199 */setBlock(world, i + 26, j + 26, k + 30, Blocks.leaves, 7);
		/* 1200 */world.setBlockMetadataWithNotify(i + 26, j + 26, k + 30, 7, 2);
		/* 1201 */setBlock(world, i + 26, j + 27, k + 22, Blocks.leaves, 7);
		/* 1202 */world.setBlockMetadataWithNotify(i + 26, j + 27, k + 22, 7, 2);
		/* 1203 */setBlock(world, i + 26, j + 27, k + 23, Blocks.leaves, 7);
		/* 1204 */world.setBlockMetadataWithNotify(i + 26, j + 27, k + 23, 7, 2);
		/* 1205 */setBlock(world, i + 26, j + 27, k + 24, Blocks.leaves, 7);
		/* 1206 */world.setBlockMetadataWithNotify(i + 26, j + 27, k + 24, 7, 2);
		/* 1207 */setBlock(world, i + 26, j + 28, k + 23, Blocks.leaves, 7);
		/* 1208 */world.setBlockMetadataWithNotify(i + 26, j + 28, k + 23, 7, 2);
		/* 1209 */setBlock(world, i + 26, j + 28, k + 29, Blocks.log, 1);
		/* 1210 */world.setBlockMetadataWithNotify(i + 26, j + 28, k + 29, 1, 2);
		/* 1211 */setBlock(world, i + 26, j + 28, k + 30, Blocks.log, 1);
		/* 1212 */world.setBlockMetadataWithNotify(i + 26, j + 28, k + 30, 1, 2);
		/* 1213 */setBlock(world, i + 26, j + 28, k + 31, Blocks.log, 1);
		/* 1214 */world.setBlockMetadataWithNotify(i + 26, j + 28, k + 31, 1, 2);
		/* 1215 */setBlock(world, i + 26, j + 29, k + 29, Blocks.log, 1);
		/* 1216 */world.setBlockMetadataWithNotify(i + 26, j + 29, k + 29, 1, 2);
		/* 1217 */setBlock(world, i + 26, j + 29, k + 30, Blocks.log, 1);
		/* 1218 */world.setBlockMetadataWithNotify(i + 26, j + 29, k + 30, 1, 2);
		/* 1219 */setBlock(world, i + 26, j + 29, k + 31, Blocks.log, 1);
		/* 1220 */world.setBlockMetadataWithNotify(i + 26, j + 29, k + 31, 1, 2);
		/* 1221 */setBlock(world, i + 26, j + 30, k + 29, Blocks.log, 1);
		/* 1222 */world.setBlockMetadataWithNotify(i + 26, j + 30, k + 29, 1, 2);
		/* 1223 */setBlock(world, i + 26, j + 30, k + 30, Blocks.log, 1);
		/* 1224 */world.setBlockMetadataWithNotify(i + 26, j + 30, k + 30, 1, 2);
		/* 1225 */setBlock(world, i + 26, j + 30, k + 31, Blocks.log, 1);
		/* 1226 */world.setBlockMetadataWithNotify(i + 26, j + 30, k + 31, 1, 2);
		/* 1227 */setBlock(world, i + 26, j + 35, k + 31, Blocks.leaves, 7);
		/* 1228 */world.setBlockMetadataWithNotify(i + 26, j + 35, k + 31, 7, 2);
		/* 1229 */setBlock(world, i + 26, j + 41, k + 28, Blocks.leaves, 15);
		/* 1230 */world.setBlockMetadataWithNotify(i + 26, j + 41, k + 28, 15, 2);
		/* 1231 */setBlock(world, i + 26, j + 41, k + 29, Blocks.leaves, 15);
		/* 1232 */world.setBlockMetadataWithNotify(i + 26, j + 41, k + 29, 15, 2);
		/* 1233 */setBlock(world, i + 26, j + 41, k + 30, Blocks.leaves, 15);
		/* 1234 */world.setBlockMetadataWithNotify(i + 26, j + 41, k + 30, 15, 2);
		/* 1235 */setBlock(world, i + 26, j + 42, k + 29, Blocks.leaves, 15);
		/* 1236 */world.setBlockMetadataWithNotify(i + 26, j + 42, k + 29, 15, 2);
		/* 1237 */setBlock(world, i + 27, j + 18, k + 31, Blocks.log, 3);
		/* 1238 */world.setBlockMetadataWithNotify(i + 27, j + 18, k + 31, 3, 2);
		/* 1239 */setBlock(world, i + 27, j + 23, k + 31, Blocks.log, 1);
		/* 1240 */world.setBlockMetadataWithNotify(i + 27, j + 23, k + 31, 1, 2);
		/* 1241 */setBlock(world, i + 27, j + 24, k + 29, Blocks.leaves, 7);
		/* 1242 */world.setBlockMetadataWithNotify(i + 27, j + 24, k + 29, 7, 2);
		/* 1243 */setBlock(world, i + 27, j + 24, k + 30, Blocks.log, 1);
		/* 1244 */world.setBlockMetadataWithNotify(i + 27, j + 24, k + 30, 1, 2);
		/* 1245 */setBlock(world, i + 27, j + 24, k + 31, Blocks.log, 1);
		/* 1246 */world.setBlockMetadataWithNotify(i + 27, j + 24, k + 31, 1, 2);
		/* 1247 */setBlock(world, i + 27, j + 25, k + 30, Blocks.log, 1);
		/* 1248 */world.setBlockMetadataWithNotify(i + 27, j + 25, k + 30, 1, 2);
		/* 1249 */setBlock(world, i + 27, j + 25, k + 31, Blocks.log, 1);
		/* 1250 */world.setBlockMetadataWithNotify(i + 27, j + 25, k + 31, 1, 2);
		/* 1251 */setBlock(world, i + 27, j + 26, k + 30, Blocks.log, 1);
		/* 1252 */world.setBlockMetadataWithNotify(i + 27, j + 26, k + 30, 1, 2);
		/* 1253 */setBlock(world, i + 27, j + 26, k + 31, Blocks.log, 1);
		/* 1254 */world.setBlockMetadataWithNotify(i + 27, j + 26, k + 31, 1, 2);
		/* 1255 */setBlock(world, i + 27, j + 28, k + 30, Blocks.log, 1);
		/* 1256 */world.setBlockMetadataWithNotify(i + 27, j + 28, k + 30, 1, 2);
		/* 1257 */setBlock(world, i + 27, j + 29, k + 29, Blocks.log, 1);
		/* 1258 */world.setBlockMetadataWithNotify(i + 27, j + 29, k + 29, 1, 2);
		/* 1259 */setBlock(world, i + 27, j + 29, k + 30, Blocks.log, 1);
		/* 1260 */world.setBlockMetadataWithNotify(i + 27, j + 29, k + 30, 1, 2);
		/* 1261 */setBlock(world, i + 27, j + 29, k + 31, Blocks.log, 1);
		/* 1262 */world.setBlockMetadataWithNotify(i + 27, j + 29, k + 31, 1, 2);
		/* 1263 */setBlock(world, i + 27, j + 30, k + 26, Blocks.log, 3);
		/* 1264 */world.setBlockMetadataWithNotify(i + 27, j + 30, k + 26, 3, 2);
		/* 1265 */setBlock(world, i + 27, j + 30, k + 27, Blocks.log, 3);
		/* 1266 */world.setBlockMetadataWithNotify(i + 27, j + 30, k + 27, 3, 2);
		/* 1267 */setBlock(world, i + 27, j + 30, k + 28, Blocks.log, 3);
		/* 1268 */world.setBlockMetadataWithNotify(i + 27, j + 30, k + 28, 3, 2);
		/* 1269 */setBlock(world, i + 27, j + 30, k + 29, Blocks.log, 3);
		/* 1270 */world.setBlockMetadataWithNotify(i + 27, j + 30, k + 29, 3, 2);
		/* 1271 */setBlock(world, i + 27, j + 30, k + 30, Blocks.log, 1);
		/* 1272 */world.setBlockMetadataWithNotify(i + 27, j + 30, k + 30, 1, 2);
		/* 1273 */setBlock(world, i + 27, j + 31, k + 20, Blocks.leaves, 7);
		/* 1274 */world.setBlockMetadataWithNotify(i + 27, j + 31, k + 20, 7, 2);
		/* 1275 */setBlock(world, i + 27, j + 31, k + 21, Blocks.leaves, 7);
		/* 1276 */world.setBlockMetadataWithNotify(i + 27, j + 31, k + 21, 7, 2);
		/* 1277 */setBlock(world, i + 27, j + 31, k + 22, Blocks.leaves, 7);
		/* 1278 */world.setBlockMetadataWithNotify(i + 27, j + 31, k + 22, 7, 2);
		/* 1279 */setBlock(world, i + 27, j + 32, k + 21, Blocks.leaves, 7);
		/* 1280 */world.setBlockMetadataWithNotify(i + 27, j + 32, k + 21, 7, 2);
		/* 1281 */setBlock(world, i + 27, j + 35, k + 30, Blocks.leaves, 7);
		/* 1282 */world.setBlockMetadataWithNotify(i + 27, j + 35, k + 30, 7, 2);
		/* 1283 */setBlock(world, i + 27, j + 35, k + 31, Blocks.leaves, 7);
		/* 1284 */world.setBlockMetadataWithNotify(i + 27, j + 35, k + 31, 7, 2);
		/* 1285 */setBlock(world, i + 27, j + 36, k + 31, Blocks.leaves, 7);
		/* 1286 */world.setBlockMetadataWithNotify(i + 27, j + 36, k + 31, 7, 2);
		/* 1287 */setBlock(world, i + 27, j + 40, k + 30, Blocks.log, 3);
		/* 1288 */world.setBlockMetadataWithNotify(i + 27, j + 40, k + 30, 3, 2);
		/* 1289 */setBlock(world, i + 27, j + 40, k + 31, Blocks.log, 3);
		/* 1290 */world.setBlockMetadataWithNotify(i + 27, j + 40, k + 31, 3, 2);
		/* 1291 */setBlock(world, i + 27, j + 41, k + 27, Blocks.leaves, 15);
		/* 1292 */world.setBlockMetadataWithNotify(i + 27, j + 41, k + 27, 15, 2);
		/* 1293 */setBlock(world, i + 27, j + 41, k + 28, Blocks.leaves, 15);
		/* 1294 */world.setBlockMetadataWithNotify(i + 27, j + 41, k + 28, 15, 2);
		/* 1295 */setBlock(world, i + 27, j + 41, k + 29, Blocks.leaves, 15);
		/* 1296 */world.setBlockMetadataWithNotify(i + 27, j + 41, k + 29, 15, 2);
		/* 1297 */setBlock(world, i + 27, j + 41, k + 30, Blocks.leaves, 15);
		/* 1298 */world.setBlockMetadataWithNotify(i + 27, j + 41, k + 30, 15, 2);
		/* 1299 */setBlock(world, i + 27, j + 41, k + 31, Blocks.leaves, 15);
		/* 1300 */world.setBlockMetadataWithNotify(i + 27, j + 41, k + 31, 15, 2);
		/* 1301 */setBlock(world, i + 27, j + 42, k + 28, Blocks.leaves, 15);
		/* 1302 */world.setBlockMetadataWithNotify(i + 27, j + 42, k + 28, 15, 2);
		/* 1303 */setBlock(world, i + 27, j + 42, k + 29, Blocks.leaves, 15);
		/* 1304 */world.setBlockMetadataWithNotify(i + 27, j + 42, k + 29, 15, 2);
		/* 1305 */setBlock(world, i + 27, j + 42, k + 30, Blocks.leaves, 15);
		/* 1306 */world.setBlockMetadataWithNotify(i + 27, j + 42, k + 30, 15, 2);
		/* 1307 */setBlock(world, i + 27, j + 52, k + 31, Blocks.leaves, 15);
		/* 1308 */world.setBlockMetadataWithNotify(i + 27, j + 52, k + 31, 15, 2);
		/* 1309 */setBlock(world, i + 28, j + 17, k + 31, Blocks.log, 3);
		/* 1310 */world.setBlockMetadataWithNotify(i + 28, j + 17, k + 31, 3, 2);
		/* 1311 */setBlock(world, i + 28, j + 18, k + 29, Blocks.log, 3);
		/* 1312 */world.setBlockMetadataWithNotify(i + 28, j + 18, k + 29, 3, 2);
		/* 1313 */setBlock(world, i + 28, j + 18, k + 30, Blocks.log, 3);
		/* 1314 */world.setBlockMetadataWithNotify(i + 28, j + 18, k + 30, 3, 2);
		/* 1315 */setBlock(world, i + 28, j + 18, k + 31, Blocks.log, 3);
		/* 1316 */world.setBlockMetadataWithNotify(i + 28, j + 18, k + 31, 3, 2);
		/* 1317 */setBlock(world, i + 28, j + 19, k + 27, Blocks.log, 3);
		/* 1318 */world.setBlockMetadataWithNotify(i + 28, j + 19, k + 27, 3, 2);
		/* 1319 */setBlock(world, i + 28, j + 19, k + 28, Blocks.log, 3);
		/* 1320 */world.setBlockMetadataWithNotify(i + 28, j + 19, k + 28, 3, 2);
		/* 1321 */setBlock(world, i + 28, j + 19, k + 31, Blocks.log, 3);
		/* 1322 */world.setBlockMetadataWithNotify(i + 28, j + 19, k + 31, 3, 2);
		/* 1323 */setBlock(world, i + 28, j + 24, k + 30, Blocks.log, 1);
		/* 1324 */world.setBlockMetadataWithNotify(i + 28, j + 24, k + 30, 1, 2);
		/* 1325 */setBlock(world, i + 28, j + 24, k + 31, Blocks.log, 1);
		/* 1326 */world.setBlockMetadataWithNotify(i + 28, j + 24, k + 31, 1, 2);
		/* 1327 */setBlock(world, i + 28, j + 25, k + 29, Blocks.log, 1);
		/* 1328 */world.setBlockMetadataWithNotify(i + 28, j + 25, k + 29, 1, 2);
		/* 1329 */setBlock(world, i + 28, j + 25, k + 30, Blocks.log, 1);
		/* 1330 */world.setBlockMetadataWithNotify(i + 28, j + 25, k + 30, 1, 2);
		/* 1331 */setBlock(world, i + 28, j + 25, k + 31, Blocks.log, 1);
		/* 1332 */world.setBlockMetadataWithNotify(i + 28, j + 25, k + 31, 1, 2);
		/* 1333 */setBlock(world, i + 28, j + 26, k + 29, Blocks.log, 1);
		/* 1334 */world.setBlockMetadataWithNotify(i + 28, j + 26, k + 29, 1, 2);
		/* 1335 */setBlock(world, i + 28, j + 26, k + 30, Blocks.log, 1);
		/* 1336 */world.setBlockMetadataWithNotify(i + 28, j + 26, k + 30, 1, 2);
		/* 1337 */setBlock(world, i + 28, j + 30, k + 22, Blocks.log, 3);
		/* 1338 */world.setBlockMetadataWithNotify(i + 28, j + 30, k + 22, 3, 2);
		/* 1339 */setBlock(world, i + 28, j + 30, k + 23, Blocks.log, 3);
		/* 1340 */world.setBlockMetadataWithNotify(i + 28, j + 30, k + 23, 3, 2);
		/* 1341 */setBlock(world, i + 28, j + 30, k + 24, Blocks.log, 3);
		/* 1342 */world.setBlockMetadataWithNotify(i + 28, j + 30, k + 24, 3, 2);
		/* 1343 */setBlock(world, i + 28, j + 30, k + 25, Blocks.log, 3);
		/* 1344 */world.setBlockMetadataWithNotify(i + 28, j + 30, k + 25, 3, 2);
		/* 1345 */setBlock(world, i + 28, j + 31, k + 19, Blocks.leaves, 7);
		/* 1346 */world.setBlockMetadataWithNotify(i + 28, j + 31, k + 19, 7, 2);
		/* 1347 */setBlock(world, i + 28, j + 31, k + 20, Blocks.leaves, 7);
		/* 1348 */world.setBlockMetadataWithNotify(i + 28, j + 31, k + 20, 7, 2);
		/* 1349 */setBlock(world, i + 28, j + 31, k + 21, Blocks.leaves, 7);
		/* 1350 */world.setBlockMetadataWithNotify(i + 28, j + 31, k + 21, 7, 2);
		/* 1351 */setBlock(world, i + 28, j + 31, k + 22, Blocks.leaves, 7);
		/* 1352 */world.setBlockMetadataWithNotify(i + 28, j + 31, k + 22, 7, 2);
		/* 1353 */setBlock(world, i + 28, j + 31, k + 23, Blocks.leaves, 7);
		/* 1354 */world.setBlockMetadataWithNotify(i + 28, j + 31, k + 23, 7, 2);
		/* 1355 */setBlock(world, i + 28, j + 32, k + 20, Blocks.leaves, 7);
		/* 1356 */world.setBlockMetadataWithNotify(i + 28, j + 32, k + 20, 7, 2);
		/* 1357 */setBlock(world, i + 28, j + 32, k + 21, Blocks.leaves, 7);
		/* 1358 */world.setBlockMetadataWithNotify(i + 28, j + 32, k + 21, 7, 2);
		/* 1359 */setBlock(world, i + 28, j + 32, k + 22, Blocks.leaves, 7);
		/* 1360 */world.setBlockMetadataWithNotify(i + 28, j + 32, k + 22, 7, 2);
		/* 1361 */setBlock(world, i + 28, j + 33, k + 21, Blocks.leaves, 7);
		/* 1362 */world.setBlockMetadataWithNotify(i + 28, j + 33, k + 21, 7, 2);
		/* 1363 */setBlock(world, i + 28, j + 33, k + 30, Blocks.log, 3);
		/* 1364 */world.setBlockMetadataWithNotify(i + 28, j + 33, k + 30, 3, 2);
		/* 1365 */setBlock(world, i + 28, j + 33, k + 31, Blocks.log, 3);
		/* 1366 */world.setBlockMetadataWithNotify(i + 28, j + 33, k + 31, 3, 2);
		/* 1367 */setBlock(world, i + 28, j + 34, k + 26, Blocks.leaves, 7);
		/* 1368 */world.setBlockMetadataWithNotify(i + 28, j + 34, k + 26, 7, 2);
		/* 1369 */setBlock(world, i + 28, j + 34, k + 27, Blocks.leaves, 7);
		/* 1370 */world.setBlockMetadataWithNotify(i + 28, j + 34, k + 27, 7, 2);
		/* 1371 */setBlock(world, i + 28, j + 34, k + 28, Blocks.leaves, 7);
		/* 1372 */world.setBlockMetadataWithNotify(i + 28, j + 34, k + 28, 7, 2);
		/* 1373 */setBlock(world, i + 28, j + 35, k + 27, Blocks.leaves, 7);
		/* 1374 */world.setBlockMetadataWithNotify(i + 28, j + 35, k + 27, 7, 2);
		/* 1375 */setBlock(world, i + 28, j + 35, k + 30, Blocks.leaves, 7);
		/* 1376 */world.setBlockMetadataWithNotify(i + 28, j + 35, k + 30, 7, 2);
		/* 1377 */setBlock(world, i + 28, j + 35, k + 31, Blocks.leaves, 7);
		/* 1378 */world.setBlockMetadataWithNotify(i + 28, j + 35, k + 31, 7, 2);
		/* 1379 */setBlock(world, i + 28, j + 36, k + 30, Blocks.leaves, 7);
		/* 1380 */world.setBlockMetadataWithNotify(i + 28, j + 36, k + 30, 7, 2);
		/* 1381 */setBlock(world, i + 28, j + 36, k + 31, Blocks.leaves, 7);
		/* 1382 */world.setBlockMetadataWithNotify(i + 28, j + 36, k + 31, 7, 2);
		/* 1383 */setBlock(world, i + 28, j + 37, k + 31, Blocks.leaves, 7);
		/* 1384 */world.setBlockMetadataWithNotify(i + 28, j + 37, k + 31, 7, 2);
		/* 1385 */setBlock(world, i + 28, j + 41, k + 27, Blocks.leaves, 15);
		/* 1386 */world.setBlockMetadataWithNotify(i + 28, j + 41, k + 27, 15, 2);
		/* 1387 */setBlock(world, i + 28, j + 41, k + 28, Blocks.leaves, 15);
		/* 1388 */world.setBlockMetadataWithNotify(i + 28, j + 41, k + 28, 15, 2);
		/* 1389 */setBlock(world, i + 28, j + 41, k + 29, Blocks.log, 3);
		/* 1390 */world.setBlockMetadataWithNotify(i + 28, j + 41, k + 29, 3, 2);
		/* 1391 */setBlock(world, i + 28, j + 41, k + 30, Blocks.leaves, 15);
		/* 1392 */world.setBlockMetadataWithNotify(i + 28, j + 41, k + 30, 15, 2);
		/* 1393 */setBlock(world, i + 28, j + 41, k + 31, Blocks.leaves, 15);
		/* 1394 */world.setBlockMetadataWithNotify(i + 28, j + 41, k + 31, 15, 2);
		/* 1395 */setBlock(world, i + 28, j + 42, k + 27, Blocks.leaves, 15);
		/* 1396 */world.setBlockMetadataWithNotify(i + 28, j + 42, k + 27, 15, 2);
		/* 1397 */setBlock(world, i + 28, j + 42, k + 28, Blocks.leaves, 15);
		/* 1398 */world.setBlockMetadataWithNotify(i + 28, j + 42, k + 28, 15, 2);
		/* 1399 */setBlock(world, i + 28, j + 42, k + 29, Blocks.leaves, 15);
		/* 1400 */world.setBlockMetadataWithNotify(i + 28, j + 42, k + 29, 15, 2);
		/* 1401 */setBlock(world, i + 28, j + 42, k + 30, Blocks.leaves, 15);
		/* 1402 */world.setBlockMetadataWithNotify(i + 28, j + 42, k + 30, 15, 2);
		/* 1403 */setBlock(world, i + 28, j + 42, k + 31, Blocks.leaves, 15);
		/* 1404 */world.setBlockMetadataWithNotify(i + 28, j + 42, k + 31, 15, 2);
		/* 1405 */setBlock(world, i + 28, j + 51, k + 31, Blocks.leaves, 15);
		/* 1406 */world.setBlockMetadataWithNotify(i + 28, j + 51, k + 31, 15, 2);
		/* 1407 */setBlock(world, i + 28, j + 53, k + 31, Blocks.leaves, 15);
		/* 1408 */world.setBlockMetadataWithNotify(i + 28, j + 53, k + 31, 15, 2);
		/* 1409 */setBlock(world, i + 29, j + 17, k + 29, Blocks.log, 3);
		/* 1410 */world.setBlockMetadataWithNotify(i + 29, j + 17, k + 29, 3, 2);
		/* 1411 */setBlock(world, i + 29, j + 17, k + 30, Blocks.log, 3);
		/* 1412 */world.setBlockMetadataWithNotify(i + 29, j + 17, k + 30, 3, 2);
		/* 1413 */setBlock(world, i + 29, j + 18, k + 27, Blocks.log, 3);
		/* 1414 */world.setBlockMetadataWithNotify(i + 29, j + 18, k + 27, 3, 2);
		/* 1415 */setBlock(world, i + 29, j + 18, k + 28, Blocks.log, 3);
		/* 1416 */world.setBlockMetadataWithNotify(i + 29, j + 18, k + 28, 3, 2);
		/* 1417 */setBlock(world, i + 29, j + 18, k + 29, Blocks.log, 3);
		/* 1418 */world.setBlockMetadataWithNotify(i + 29, j + 18, k + 29, 3, 2);
		/* 1419 */setBlock(world, i + 29, j + 18, k + 30, Blocks.log, 3);
		/* 1420 */world.setBlockMetadataWithNotify(i + 29, j + 18, k + 30, 3, 2);
		/* 1421 */setBlock(world, i + 29, j + 18, k + 31, Blocks.log, 3);
		/* 1422 */world.setBlockMetadataWithNotify(i + 29, j + 18, k + 31, 3, 2);
		/* 1423 */setBlock(world, i + 29, j + 19, k + 27, Blocks.log, 3);
		/* 1424 */world.setBlockMetadataWithNotify(i + 29, j + 19, k + 27, 3, 2);
		/* 1425 */setBlock(world, i + 29, j + 19, k + 28, Blocks.log, 3);
		/* 1426 */world.setBlockMetadataWithNotify(i + 29, j + 19, k + 28, 3, 2);
		/* 1427 */setBlock(world, i + 29, j + 19, k + 29, Blocks.log, 3);
		/* 1428 */world.setBlockMetadataWithNotify(i + 29, j + 19, k + 29, 3, 2);
		/* 1429 */setBlock(world, i + 29, j + 19, k + 30, Blocks.log, 3);
		/* 1430 */world.setBlockMetadataWithNotify(i + 29, j + 19, k + 30, 3, 2);
		/* 1431 */setBlock(world, i + 29, j + 20, k + 27, Blocks.log, 3);
		/* 1432 */world.setBlockMetadataWithNotify(i + 29, j + 20, k + 27, 3, 2);
		/* 1433 */setBlock(world, i + 29, j + 20, k + 28, Blocks.log, 3);
		/* 1434 */world.setBlockMetadataWithNotify(i + 29, j + 20, k + 28, 3, 2);
		/* 1435 */setBlock(world, i + 29, j + 20, k + 30, Blocks.log, 3);
		/* 1436 */world.setBlockMetadataWithNotify(i + 29, j + 20, k + 30, 3, 2);
		/* 1437 */setBlock(world, i + 29, j + 20, k + 31, Blocks.log, 3);
		/* 1438 */world.setBlockMetadataWithNotify(i + 29, j + 20, k + 31, 3, 2);
		/* 1439 */setBlock(world, i + 29, j + 21, k + 27, Blocks.leaves, 7);
		/* 1440 */world.setBlockMetadataWithNotify(i + 29, j + 21, k + 27, 7, 2);
		/* 1441 */setBlock(world, i + 29, j + 21, k + 28, Blocks.leaves, 7);
		/* 1442 */world.setBlockMetadataWithNotify(i + 29, j + 21, k + 28, 7, 2);
		/* 1443 */setBlock(world, i + 29, j + 21, k + 29, Blocks.leaves, 7);
		/* 1444 */world.setBlockMetadataWithNotify(i + 29, j + 21, k + 29, 7, 2);
		/* 1445 */setBlock(world, i + 29, j + 22, k + 28, Blocks.leaves, 7);
		/* 1446 */world.setBlockMetadataWithNotify(i + 29, j + 22, k + 28, 7, 2);
		/* 1447 */setBlock(world, i + 29, j + 24, k + 30, Blocks.log, 1);
		/* 1448 */world.setBlockMetadataWithNotify(i + 29, j + 24, k + 30, 1, 2);
		/* 1449 */setBlock(world, i + 29, j + 25, k + 29, Blocks.log, 1);
		/* 1450 */world.setBlockMetadataWithNotify(i + 29, j + 25, k + 29, 1, 2);
		/* 1451 */setBlock(world, i + 29, j + 25, k + 30, Blocks.log, 1);
		/* 1452 */world.setBlockMetadataWithNotify(i + 29, j + 25, k + 30, 1, 2);
		/* 1453 */setBlock(world, i + 29, j + 25, k + 31, Blocks.log, 1);
		/* 1454 */world.setBlockMetadataWithNotify(i + 29, j + 25, k + 31, 1, 2);
		/* 1455 */setBlock(world, i + 29, j + 26, k + 30, Blocks.log, 1);
		/* 1456 */world.setBlockMetadataWithNotify(i + 29, j + 26, k + 30, 1, 2);
		/* 1457 */setBlock(world, i + 29, j + 31, k + 19, Blocks.leaves, 7);
		/* 1458 */world.setBlockMetadataWithNotify(i + 29, j + 31, k + 19, 7, 2);
		/* 1459 */setBlock(world, i + 29, j + 31, k + 20, Blocks.leaves, 7);
		/* 1460 */world.setBlockMetadataWithNotify(i + 29, j + 31, k + 20, 7, 2);
		/* 1461 */setBlock(world, i + 29, j + 31, k + 21, Blocks.log, 3);
		/* 1462 */world.setBlockMetadataWithNotify(i + 29, j + 31, k + 21, 3, 2);
		/* 1463 */setBlock(world, i + 29, j + 31, k + 22, Blocks.leaves, 7);
		/* 1464 */world.setBlockMetadataWithNotify(i + 29, j + 31, k + 22, 7, 2);
		/* 1465 */setBlock(world, i + 29, j + 31, k + 23, Blocks.leaves, 7);
		/* 1466 */world.setBlockMetadataWithNotify(i + 29, j + 31, k + 23, 7, 2);
		/* 1467 */setBlock(world, i + 29, j + 32, k + 19, Blocks.leaves, 7);
		/* 1468 */world.setBlockMetadataWithNotify(i + 29, j + 32, k + 19, 7, 2);
		/* 1469 */setBlock(world, i + 29, j + 32, k + 20, Blocks.leaves, 7);
		/* 1470 */world.setBlockMetadataWithNotify(i + 29, j + 32, k + 20, 7, 2);
		/* 1471 */setBlock(world, i + 29, j + 32, k + 21, Blocks.leaves, 7);
		/* 1472 */world.setBlockMetadataWithNotify(i + 29, j + 32, k + 21, 7, 2);
		/* 1473 */setBlock(world, i + 29, j + 32, k + 22, Blocks.leaves, 7);
		/* 1474 */world.setBlockMetadataWithNotify(i + 29, j + 32, k + 22, 7, 2);
		/* 1475 */setBlock(world, i + 29, j + 32, k + 23, Blocks.leaves, 7);
		/* 1476 */world.setBlockMetadataWithNotify(i + 29, j + 32, k + 23, 7, 2);
		/* 1477 */setBlock(world, i + 29, j + 33, k + 20, Blocks.leaves, 7);
		/* 1478 */world.setBlockMetadataWithNotify(i + 29, j + 33, k + 20, 7, 2);
		/* 1479 */setBlock(world, i + 29, j + 33, k + 21, Blocks.leaves, 7);
		/* 1480 */world.setBlockMetadataWithNotify(i + 29, j + 33, k + 21, 7, 2);
		/* 1481 */setBlock(world, i + 29, j + 33, k + 22, Blocks.leaves, 7);
		/* 1482 */world.setBlockMetadataWithNotify(i + 29, j + 33, k + 22, 7, 2);
		/* 1483 */setBlock(world, i + 29, j + 33, k + 28, Blocks.log, 3);
		/* 1484 */world.setBlockMetadataWithNotify(i + 29, j + 33, k + 28, 3, 2);
		/* 1485 */setBlock(world, i + 29, j + 33, k + 29, Blocks.log, 3);
		/* 1486 */world.setBlockMetadataWithNotify(i + 29, j + 33, k + 29, 3, 2);
		/* 1487 */setBlock(world, i + 29, j + 34, k + 21, Blocks.leaves, 7);
		/* 1488 */world.setBlockMetadataWithNotify(i + 29, j + 34, k + 21, 7, 2);
		/* 1489 */setBlock(world, i + 29, j + 34, k + 25, Blocks.leaves, 7);
		/* 1490 */world.setBlockMetadataWithNotify(i + 29, j + 34, k + 25, 7, 2);
		/* 1491 */setBlock(world, i + 29, j + 34, k + 26, Blocks.leaves, 7);
		/* 1492 */world.setBlockMetadataWithNotify(i + 29, j + 34, k + 26, 7, 2);
		/* 1493 */setBlock(world, i + 29, j + 34, k + 27, Blocks.leaves, 7);
		/* 1494 */world.setBlockMetadataWithNotify(i + 29, j + 34, k + 27, 7, 2);
		/* 1495 */setBlock(world, i + 29, j + 34, k + 28, Blocks.leaves, 7);
		/* 1496 */world.setBlockMetadataWithNotify(i + 29, j + 34, k + 28, 7, 2);
		/* 1497 */setBlock(world, i + 29, j + 34, k + 29, Blocks.leaves, 7);
		/* 1498 */world.setBlockMetadataWithNotify(i + 29, j + 34, k + 29, 7, 2);
		/* 1499 */setBlock(world, i + 29, j + 35, k + 26, Blocks.leaves, 7);
		/* 1500 */world.setBlockMetadataWithNotify(i + 29, j + 35, k + 26, 7, 2);
		/* 1501 */setBlock(world, i + 29, j + 35, k + 27, Blocks.leaves, 7);
		/* 1502 */world.setBlockMetadataWithNotify(i + 29, j + 35, k + 27, 7, 2);
		/* 1503 */setBlock(world, i + 29, j + 35, k + 28, Blocks.leaves, 7);
		/* 1504 */world.setBlockMetadataWithNotify(i + 29, j + 35, k + 28, 7, 2);
		/* 1505 */setBlock(world, i + 29, j + 35, k + 30, Blocks.leaves, 7);
		/* 1506 */world.setBlockMetadataWithNotify(i + 29, j + 35, k + 30, 7, 2);
		/* 1507 */setBlock(world, i + 29, j + 35, k + 31, Blocks.leaves, 7);
		/* 1508 */world.setBlockMetadataWithNotify(i + 29, j + 35, k + 31, 7, 2);
		/* 1509 */setBlock(world, i + 29, j + 36, k + 27, Blocks.leaves, 7);
		/* 1510 */world.setBlockMetadataWithNotify(i + 29, j + 36, k + 27, 7, 2);
		/* 1511 */setBlock(world, i + 29, j + 36, k + 31, Blocks.leaves, 7);
		/* 1512 */world.setBlockMetadataWithNotify(i + 29, j + 36, k + 31, 7, 2);
		/* 1513 */setBlock(world, i + 29, j + 41, k + 27, Blocks.leaves, 15);
		/* 1514 */world.setBlockMetadataWithNotify(i + 29, j + 41, k + 27, 15, 2);
		/* 1515 */setBlock(world, i + 29, j + 41, k + 28, Blocks.leaves, 15);
		/* 1516 */world.setBlockMetadataWithNotify(i + 29, j + 41, k + 28, 15, 2);
		/* 1517 */setBlock(world, i + 29, j + 41, k + 29, Blocks.leaves, 15);
		/* 1518 */world.setBlockMetadataWithNotify(i + 29, j + 41, k + 29, 15, 2);
		/* 1519 */setBlock(world, i + 29, j + 41, k + 30, Blocks.leaves, 15);
		/* 1520 */world.setBlockMetadataWithNotify(i + 29, j + 41, k + 30, 15, 2);
		/* 1521 */setBlock(world, i + 29, j + 41, k + 31, Blocks.leaves, 15);
		/* 1522 */world.setBlockMetadataWithNotify(i + 29, j + 41, k + 31, 15, 2);
		/* 1523 */setBlock(world, i + 29, j + 42, k + 28, Blocks.leaves, 15);
		/* 1524 */world.setBlockMetadataWithNotify(i + 29, j + 42, k + 28, 15, 2);
		/* 1525 */setBlock(world, i + 29, j + 45, k + 27, Blocks.spruce_stairs, 4);
		/* 1526 */world.setBlockMetadataWithNotify(i + 29, j + 45, k + 27, 4, 2);
		/* 1527 */setBlock(world, i + 29, j + 46, k + 27, Blocks.log, 1);
		/* 1528 */world.setBlockMetadataWithNotify(i + 29, j + 46, k + 27, 1, 2);
		/* 1529 */setBlock(world, i + 29, j + 47, k + 27, Blocks.log, 1);
		/* 1530 */world.setBlockMetadataWithNotify(i + 29, j + 47, k + 27, 1, 2);
		/* 1531 */setBlock(world, i + 29, j + 47, k + 28, Blocks.spruce_stairs, 7);
		/* 1532 */world.setBlockMetadataWithNotify(i + 29, j + 47, k + 28, 7, 2);
		/* 1533 */setBlock(world, i + 29, j + 48, k + 26, Blocks.log, 1);
		/* 1534 */world.setBlockMetadataWithNotify(i + 29, j + 48, k + 26, 1, 2);
		/* 1535 */setBlock(world, i + 29, j + 48, k + 27, Blocks.log, 1);
		/* 1536 */world.setBlockMetadataWithNotify(i + 29, j + 48, k + 27, 1, 2);
