package com.parzivail.pswm.world.gen.wookietree;




import com.parzivail.pswm.utils.LootGenUtils;
import com.parzivail.pswm.utils.NPCType;
import com.parzivail.pswm.utils.SpawnUtils;



import cpw.mods.fml.common.IWorldGenerator;



import java.util.Random;



import net.minecraft.block.Block;

import net.minecraft.init.Blocks;

import net.minecraft.tileentity.TileEntityChest;

import net.minecraft.world.World;

import net.minecraft.world.WorldProvider;

import net.minecraft.world.chunk.IChunkProvider;

import net.minecraft.world.gen.feature.WorldGenerator;


public class WT_31
extends WorldGenerator implements IWorldGenerator

{
	protected Block[] getValidSpawnBlocks()
	
	{
		return new Block[0];
		}

	
	public boolean locationIsValidSpawn(World world, int i, int j, int k)
	
	{
		int distanceToAir = 0;
		Block check = world.getBlock(i, j, k);
		
		while (check != Blocks.air)
		{
			if (distanceToAir > 3) { return false;
			}
			
			distanceToAir++;
			check = world.getBlock(i, j + distanceToAir, k);
			}
		
		j += distanceToAir - 1;
		
		Block block = world.getBlock(i, j, k);
		Block blockAbove = world.getBlock(i, j + 1, k);
		Block blockBelow = world.getBlock(i, j - 1, k);
		
		for (Block x : getValidSpawnBlocks())
		{
			if (blockAbove != Blocks.air) { return false;
			}
			if (block == x) return true;
			if ((block == Blocks.snow) && (blockBelow == x)) { return true;
			}
			}
		
		return false;
		}

	
	
	
	public void generate(Random random, int chunkX, int chunkZ, World world, IChunkProvider chunkGenerator, IChunkProvider chunkProvider)
	{
	}

	
	
	public void setBlock(World world, int x, int y, int z, Block block, int metadata)
	
	{
		world.setBlock(x, y, z, block, metadata, 2);
		}

	
	public boolean generate(World world, Random rand, int i, int j, int k)
	
	{
		k -= 10;
		i -= 10;
		
		setBlock(world, i + 0, j + 44, k + 24, Blocks.fence, 0);
		setBlock(world, i + 0, j + 44, k + 25, Blocks.fence, 0);
		setBlock(world, i + 0, j + 44, k + 26, Blocks.fence, 0);
		setBlock(world, i + 0, j + 47, k + 20, Blocks.fence, 0);
		setBlock(world, i + 0, j + 47, k + 21, Blocks.fence, 0);
		setBlock(world, i + 1, j + 44, k + 22, Blocks.fence, 0);
		setBlock(world, i + 1, j + 44, k + 23, Blocks.fence, 0);
		setBlock(world, i + 1, j + 44, k + 24, Blocks.fence, 0);
		setBlock(world, i + 1, j + 47, k + 19, Blocks.fence, 0);
		setBlock(world, i + 1, j + 47, k + 20, Blocks.fence, 0);
		SpawnUtils.spawnNPC(NPCType.WOOKIETREE, world, i + 3, j + 44, k + 28);
		setBlock(world, i + 4, j + 28, k + 31, Blocks.fence, 0);
		setBlock(world, i + 4, j + 44, k + 30, Blocks.spruce_stairs, 0);
		setBlock(world, i + 4, j + 44, k + 31, Blocks.spruce_stairs, 0);
		setBlock(world, i + 5, j + 28, k + 30, Blocks.fence, 0);
		setBlock(world, i + 5, j + 28, k + 31, Blocks.fence, 0);
		setBlock(world, i + 6, j + 28, k + 29, Blocks.spruce_stairs, 0);
		setBlock(world, i + 6, j + 28, k + 30, Blocks.fence, 0);
		setBlock(world, i + 6, j + 30, k + 27, Blocks.fence, 0);
		setBlock(world, i + 6, j + 30, k + 28, Blocks.fence, 0);
		setBlock(world, i + 8, j + 44, k + 21, Blocks.spruce_stairs, 0);
		SpawnUtils.spawnNPC(NPCType.WOOKIETREE, world, i + 8, j + 44, k + 28);
		setBlock(world, i + 10, j + 44, k + 22, Blocks.fence, 0);
		setBlock(world, i + 10, j + 44, k + 23, Blocks.fence, 0);
		setBlock(world, i + 10, j + 44, k + 24, Blocks.fence, 0);
		setBlock(world, i + 10, j + 47, k + 19, Blocks.fence, 0);
		setBlock(world, i + 10, j + 47, k + 20, Blocks.fence, 0);
		setBlock(world, i + 11, j + 44, k + 24, Blocks.fence, 0);
		setBlock(world, i + 11, j + 44, k + 25, Blocks.fence, 0);
		setBlock(world, i + 11, j + 44, k + 26, Blocks.fence, 0);
		setBlock(world, i + 11, j + 44, k + 27, Blocks.spruce_stairs, 0);
		setBlock(world, i + 11, j + 47, k + 20, Blocks.fence, 0);
		setBlock(world, i + 11, j + 47, k + 21, Blocks.fence, 0);
		setBlock(world, i + 12, j + 28, k + 30, Blocks.fence, 0);
		setBlock(world, i + 12, j + 30, k + 27, Blocks.fence, 0);
		setBlock(world, i + 12, j + 30, k + 28, Blocks.fence, 0);
		setBlock(world, i + 12, j + 47, k + 21, Blocks.fence, 0);
		setBlock(world, i + 12, j + 47, k + 22, Blocks.fence, 0);
		setBlock(world, i + 12, j + 47, k + 23, Blocks.fence, 0);
		setBlock(world, i + 13, j + 28, k + 30, Blocks.fence, 0);
		setBlock(world, i + 13, j + 28, k + 31, Blocks.fence, 0);
		setBlock(world, i + 13, j + 47, k + 23, Blocks.fence, 0);
		setBlock(world, i + 13, j + 47, k + 24, Blocks.fence, 0);
		setBlock(world, i + 13, j + 47, k + 25, Blocks.fence, 0);
		setBlock(world, i + 13, j + 47, k + 26, Blocks.fence, 0);
		setBlock(world, i + 14, j + 28, k + 31, Blocks.fence, 0);
		setBlock(world, i + 14, j + 47, k + 26, Blocks.fence, 0);
		setBlock(world, i + 25, j + 69, k + 2, Blocks.fence, 0);
		setBlock(world, i + 25, j + 69, k + 11, Blocks.fence, 0);
		setBlock(world, i + 26, j + 69, k + 0, Blocks.fence, 0);
		setBlock(world, i + 26, j + 69, k + 1, Blocks.fence, 0);
		setBlock(world, i + 26, j + 69, k + 2, Blocks.fence, 0);
		setBlock(world, i + 26, j + 69, k + 11, Blocks.fence, 0);
		setBlock(world, i + 26, j + 69, k + 12, Blocks.fence, 0);
		setBlock(world, i + 26, j + 69, k + 13, Blocks.fence, 0);
		setBlock(world, i + 26, j + 69, k + 14, Blocks.fence, 0);
		setBlock(world, i + 27, j + 69, k + 14, Blocks.fence, 0);
		setBlock(world, i + 27, j + 69, k + 15, Blocks.fence, 0);
		setBlock(world, i + 27, j + 69, k + 16, Blocks.fence, 0);
		setBlock(world, i + 28, j + 66, k + 0, Blocks.fence, 0);
		setBlock(world, i + 28, j + 66, k + 1, Blocks.fence, 0);
		setBlock(world, i + 28, j + 66, k + 2, Blocks.fence, 0);
		setBlock(world, i + 28, j + 66, k + 11, Blocks.fence, 0);
		setBlock(world, i + 28, j + 66, k + 12, Blocks.fence, 0);
		setBlock(world, i + 28, j + 66, k + 13, Blocks.fence, 0);
		setBlock(world, i + 28, j + 69, k + 16, Blocks.fence, 0);
		setBlock(world, i + 28, j + 69, k + 17, Blocks.fence, 0);
		setBlock(world, i + 29, j + 66, k + 0, Blocks.fence, 0);
		setBlock(world, i + 29, j + 66, k + 13, Blocks.fence, 0);
		setBlock(world, i + 29, j + 66, k + 14, Blocks.fence, 0);
		setBlock(world, i + 29, j + 66, k + 15, Blocks.fence, 0);
		setBlock(world, i + 29, j + 69, k + 17, Blocks.fence, 0);
		setBlock(world, i + 29, j + 69, k + 18, Blocks.fence, 0);
		SpawnUtils.spawnNPC(NPCType.WOOKIETREE, world, i + 30, j + 66, k + 4);
		SpawnUtils.spawnNPC(NPCType.WOOKIETREE, world, i + 30, j + 66, k + 9);
		setBlock(world, i + 0, j + 21, k + 18, Blocks.leaves, 7);
		world.setBlockMetadataWithNotify(i + 0, j + 21, k + 18, 7, 2);
		setBlock(world, i + 0, j + 21, k + 19, Blocks.leaves, 7);
		world.setBlockMetadataWithNotify(i + 0, j + 21, k + 19, 7, 2);
		setBlock(world, i + 0, j + 21, k + 20, Blocks.log, 3);
		world.setBlockMetadataWithNotify(i + 0, j + 21, k + 20, 3, 2);
		setBlock(world, i + 0, j + 21, k + 21, Blocks.leaves, 7);
		world.setBlockMetadataWithNotify(i + 0, j + 21, k + 21, 7, 2);
		setBlock(world, i + 0, j + 21, k + 22, Blocks.leaves, 7);
		world.setBlockMetadataWithNotify(i + 0, j + 21, k + 22, 7, 2);
		setBlock(world, i + 0, j + 21, k + 26, Blocks.leaves, 7);
		world.setBlockMetadataWithNotify(i + 0, j + 21, k + 26, 7, 2);
		setBlock(world, i + 0, j + 21, k + 27, Blocks.leaves, 7);
		world.setBlockMetadataWithNotify(i + 0, j + 21, k + 27, 7, 2);
		setBlock(world, i + 0, j + 21, k + 28, Blocks.leaves, 7);
		world.setBlockMetadataWithNotify(i + 0, j + 21, k + 28, 7, 2);
		setBlock(world, i + 0, j + 21, k + 29, Blocks.leaves, 7);
		world.setBlockMetadataWithNotify(i + 0, j + 21, k + 29, 7, 2);
		setBlock(world, i + 0, j + 21, k + 30, Blocks.leaves, 7);
		world.setBlockMetadataWithNotify(i + 0, j + 21, k + 30, 7, 2);
		setBlock(world, i + 0, j + 22, k + 18, Blocks.leaves, 7);
		world.setBlockMetadataWithNotify(i + 0, j + 22, k + 18, 7, 2);
		setBlock(world, i + 0, j + 22, k + 19, Blocks.leaves, 7);
		world.setBlockMetadataWithNotify(i + 0, j + 22, k + 19, 7, 2);
		setBlock(world, i + 0, j + 22, k + 20, Blocks.leaves, 7);
		world.setBlockMetadataWithNotify(i + 0, j + 22, k + 20, 7, 2);
		setBlock(world, i + 0, j + 22, k + 21, Blocks.leaves, 7);
		world.setBlockMetadataWithNotify(i + 0, j + 22, k + 21, 7, 2);
		setBlock(world, i + 0, j + 22, k + 22, Blocks.leaves, 7);
		world.setBlockMetadataWithNotify(i + 0, j + 22, k + 22, 7, 2);
		setBlock(world, i + 0, j + 22, k + 27, Blocks.leaves, 7);
		world.setBlockMetadataWithNotify(i + 0, j + 22, k + 27, 7, 2);
		setBlock(world, i + 0, j + 22, k + 28, Blocks.leaves, 7);
		world.setBlockMetadataWithNotify(i + 0, j + 22, k + 28, 7, 2);
		setBlock(world, i + 0, j + 22, k + 29, Blocks.leaves, 7);
		world.setBlockMetadataWithNotify(i + 0, j + 22, k + 29, 7, 2);
		setBlock(world, i + 0, j + 23, k + 19, Blocks.leaves, 7);
		world.setBlockMetadataWithNotify(i + 0, j + 23, k + 19, 7, 2);
		setBlock(world, i + 0, j + 23, k + 20, Blocks.leaves, 7);
		world.setBlockMetadataWithNotify(i + 0, j + 23, k + 20, 7, 2);
		setBlock(world, i + 0, j + 23, k + 21, Blocks.leaves, 7);
		world.setBlockMetadataWithNotify(i + 0, j + 23, k + 21, 7, 2);
		setBlock(world, i + 0, j + 23, k + 28, Blocks.leaves, 7);
		world.setBlockMetadataWithNotify(i + 0, j + 23, k + 28, 7, 2);
		setBlock(world, i + 0, j + 24, k + 20, Blocks.leaves, 7);
		world.setBlockMetadataWithNotify(i + 0, j + 24, k + 20, 7, 2);
		setBlock(world, i + 0, j + 24, k + 29, Blocks.leaves, 7);
		world.setBlockMetadataWithNotify(i + 0, j + 24, k + 29, 7, 2);
		setBlock(world, i + 0, j + 24, k + 30, Blocks.leaves, 7);
		world.setBlockMetadataWithNotify(i + 0, j + 24, k + 30, 7, 2);
		setBlock(world, i + 0, j + 24, k + 31, Blocks.log, 3);
		world.setBlockMetadataWithNotify(i + 0, j + 24, k + 31, 3, 2);
		setBlock(world, i + 0, j + 25, k + 29, Blocks.leaves, 7);
		world.setBlockMetadataWithNotify(i + 0, j + 25, k + 29, 7, 2);
		setBlock(world, i + 0, j + 25, k + 30, Blocks.leaves, 7);
		world.setBlockMetadataWithNotify(i + 0, j + 25, k + 30, 7, 2);
		setBlock(world, i + 0, j + 25, k + 31, Blocks.leaves, 7);
		world.setBlockMetadataWithNotify(i + 0, j + 25, k + 31, 7, 2);
		setBlock(world, i + 0, j + 26, k + 30, Blocks.leaves, 7);
		world.setBlockMetadataWithNotify(i + 0, j + 26, k + 30, 7, 2);
		setBlock(world, i + 0, j + 26, k + 31, Blocks.leaves, 7);
		world.setBlockMetadataWithNotify(i + 0, j + 26, k + 31, 7, 2);
		setBlock(world, i + 0, j + 27, k + 31, Blocks.leaves, 7);
		world.setBlockMetadataWithNotify(i + 0, j + 27, k + 31, 7, 2);
		setBlock(world, i + 0, j + 30, k + 28, Blocks.log, 3);
		world.setBlockMetadataWithNotify(i + 0, j + 30, k + 28, 3, 2);
		setBlock(world, i + 0, j + 30, k + 29, Blocks.log, 3);
		world.setBlockMetadataWithNotify(i + 0, j + 30, k + 29, 3, 2);
		setBlock(world, i + 0, j + 34, k + 26, Blocks.leaves, 7);
		world.setBlockMetadataWithNotify(i + 0, j + 34, k + 26, 7, 2);
		setBlock(world, i + 0, j + 34, k + 27, Blocks.leaves, 7);
		world.setBlockMetadataWithNotify(i + 0, j + 34, k + 27, 7, 2);
		setBlock(world, i + 0, j + 34, k + 28, Blocks.leaves, 7);
		world.setBlockMetadataWithNotify(i + 0, j + 34, k + 28, 7, 2);
		setBlock(world, i + 0, j + 35, k + 27, Blocks.leaves, 7);
		world.setBlockMetadataWithNotify(i + 0, j + 35, k + 27, 7, 2);
		setBlock(world, i + 0, j + 38, k + 1, Blocks.vine, 8);
		world.setBlockMetadataWithNotify(i + 0, j + 38, k + 1, 8, 2);
		setBlock(world, i + 0, j + 39, k + 0, Blocks.vine, 15);
		world.setBlockMetadataWithNotify(i + 0, j + 39, k + 0, 15, 2);
		setBlock(world, i + 0, j + 39, k + 1, Blocks.vine, 15);
		world.setBlockMetadataWithNotify(i + 0, j + 39, k + 1, 15, 2);
		setBlock(world, i + 0, j + 40, k + 0, Blocks.planks, 5);
		world.setBlockMetadataWithNotify(i + 0, j + 40, k + 0, 5, 2);
		setBlock(world, i + 0, j + 40, k + 1, Blocks.planks, 5);
		world.setBlockMetadataWithNotify(i + 0, j + 40, k + 1, 5, 2);
		setBlock(world, i + 0, j + 40, k + 2, Blocks.planks, 5);
		world.setBlockMetadataWithNotify(i + 0, j + 40, k + 2, 5, 2);
		setBlock(world, i + 0, j + 41, k + 0, Blocks.spruce_stairs, 2);
		world.setBlockMetadataWithNotify(i + 0, j + 41, k + 0, 2, 2);
		setBlock(world, i + 0, j + 41, k + 1, Blocks.planks, 5);
		world.setBlockMetadataWithNotify(i + 0, j + 41, k + 1, 5, 2);
		setBlock(world, i + 0, j + 41, k + 2, Blocks.planks, 5);
		world.setBlockMetadataWithNotify(i + 0, j + 41, k + 2, 5, 2);
		setBlock(world, i + 0, j + 41, k + 3, Blocks.planks, 5);
		world.setBlockMetadataWithNotify(i + 0, j + 41, k + 3, 5, 2);
		setBlock(world, i + 0, j + 41, k + 4, Blocks.planks, 5);
		world.setBlockMetadataWithNotify(i + 0, j + 41, k + 4, 5, 2);
		setBlock(world, i + 0, j + 41, k + 5, Blocks.planks, 5);
		world.setBlockMetadataWithNotify(i + 0, j + 41, k + 5, 5, 2);
		setBlock(world, i + 0, j + 42, k + 3, Blocks.spruce_stairs, 2);
		world.setBlockMetadataWithNotify(i + 0, j + 42, k + 3, 2, 2);
		setBlock(world, i + 0, j + 42, k + 4, Blocks.planks, 5);
		world.setBlockMetadataWithNotify(i + 0, j + 42, k + 4, 5, 2);
		setBlock(world, i + 0, j + 42, k + 5, Blocks.planks, 5);
		world.setBlockMetadataWithNotify(i + 0, j + 42, k + 5, 5, 2);
		setBlock(world, i + 0, j + 42, k + 6, Blocks.planks, 5);
		world.setBlockMetadataWithNotify(i + 0, j + 42, k + 6, 5, 2);
		setBlock(world, i + 0, j + 42, k + 7, Blocks.planks, 5);
		world.setBlockMetadataWithNotify(i + 0, j + 42, k + 7, 5, 2);
		setBlock(world, i + 0, j + 43, k + 24, Blocks.log, 1);
		world.setBlockMetadataWithNotify(i + 0, j + 43, k + 24, 1, 2);
		setBlock(world, i + 0, j + 43, k + 25, Blocks.log, 1);
		world.setBlockMetadataWithNotify(i + 0, j + 43, k + 25, 1, 2);
		setBlock(world, i + 0, j + 43, k + 26, Blocks.log, 1);
		world.setBlockMetadataWithNotify(i + 0, j + 43, k + 26, 1, 2);
		setBlock(world, i + 0, j + 43, k + 27, Blocks.log, 1);
		world.setBlockMetadataWithNotify(i + 0, j + 43, k + 27, 1, 2);
		setBlock(world, i + 0, j + 43, k + 28, Blocks.log, 1);
		world.setBlockMetadataWithNotify(i + 0, j + 43, k + 28, 1, 2);
		setBlock(world, i + 0, j + 43, k + 29, Blocks.log, 1);
		world.setBlockMetadataWithNotify(i + 0, j + 43, k + 29, 1, 2);
		setBlock(world, i + 0, j + 43, k + 30, Blocks.planks, 5);
		world.setBlockMetadataWithNotify(i + 0, j + 43, k + 30, 5, 2);
		setBlock(world, i + 0, j + 43, k + 31, Blocks.planks, 5);
		world.setBlockMetadataWithNotify(i + 0, j + 43, k + 31, 5, 2);
		setBlock(world, i + 0, j + 44, k + 27, Blocks.spruce_stairs, 1);
		world.setBlockMetadataWithNotify(i + 0, j + 44, k + 27, 1, 2);
		setBlock(world, i + 0, j + 45, k + 26, Blocks.torch, 5);
		world.setBlockMetadataWithNotify(i + 0, j + 45, k + 26, 5, 2);
		setBlock(world, i + 0, j + 48, k + 20, Blocks.log, 1);
		world.setBlockMetadataWithNotify(i + 0, j + 48, k + 20, 1, 2);
		setBlock(world, i + 0, j + 48, k + 21, Blocks.log, 1);
		world.setBlockMetadataWithNotify(i + 0, j + 48, k + 21, 1, 2);
		setBlock(world, i + 0, j + 48, k + 22, Blocks.log, 1);
		world.setBlockMetadataWithNotify(i + 0, j + 48, k + 22, 1, 2);
		setBlock(world, i + 0, j + 48, k + 23, Blocks.log, 1);
		world.setBlockMetadataWithNotify(i + 0, j + 48, k + 23, 1, 2);
		setBlock(world, i + 0, j + 48, k + 24, Blocks.log, 1);
		world.setBlockMetadataWithNotify(i + 0, j + 48, k + 24, 1, 2);
		setBlock(world, i + 0, j + 48, k + 25, Blocks.log, 1);
		world.setBlockMetadataWithNotify(i + 0, j + 48, k + 25, 1, 2);
		setBlock(world, i + 0, j + 48, k + 26, Blocks.log, 1);
		world.setBlockMetadataWithNotify(i + 0, j + 48, k + 26, 1, 2);
		setBlock(world, i + 0, j + 48, k + 27, Blocks.log, 1);
		world.setBlockMetadataWithNotify(i + 0, j + 48, k + 27, 1, 2);
		setBlock(world, i + 0, j + 48, k + 28, Blocks.log, 1);
		world.setBlockMetadataWithNotify(i + 0, j + 48, k + 28, 1, 2);
		setBlock(world, i + 0, j + 48, k + 29, Blocks.log, 1);
		world.setBlockMetadataWithNotify(i + 0, j + 48, k + 29, 1, 2);
		setBlock(world, i + 0, j + 48, k + 30, Blocks.log, 1);
		world.setBlockMetadataWithNotify(i + 0, j + 48, k + 30, 1, 2);
		setBlock(world, i + 0, j + 48, k + 31, Blocks.log, 1);
		world.setBlockMetadataWithNotify(i + 0, j + 48, k + 31, 1, 2);
		setBlock(world, i + 0, j + 49, k + 21, Blocks.log, 1);
		world.setBlockMetadataWithNotify(i + 0, j + 49, k + 21, 1, 2);
		setBlock(world, i + 0, j + 49, k + 22, Blocks.log, 1);
		world.setBlockMetadataWithNotify(i + 0, j + 49, k + 22, 1, 2);
		setBlock(world, i + 0, j + 49, k + 23, Blocks.log, 1);
		world.setBlockMetadataWithNotify(i + 0, j + 49, k + 23, 1, 2);
		setBlock(world, i + 0, j + 49, k + 24, Blocks.log, 1);
		world.setBlockMetadataWithNotify(i + 0, j + 49, k + 24, 1, 2);
		setBlock(world, i + 0, j + 49, k + 25, Blocks.log, 1);
		world.setBlockMetadataWithNotify(i + 0, j + 49, k + 25, 1, 2);
		setBlock(world, i + 0, j + 49, k + 26, Blocks.log, 1);
		world.setBlockMetadataWithNotify(i + 0, j + 49, k + 26, 1, 2);
		setBlock(world, i + 0, j + 49, k + 27, Blocks.log, 1);
		world.setBlockMetadataWithNotify(i + 0, j + 49, k + 27, 1, 2);
		setBlock(world, i + 0, j + 49, k + 28, Blocks.log, 1);
		world.setBlockMetadataWithNotify(i + 0, j + 49, k + 28, 1, 2);
		setBlock(world, i + 0, j + 49, k + 29, Blocks.log, 1);
		world.setBlockMetadataWithNotify(i + 0, j + 49, k + 29, 1, 2);
		setBlock(world, i + 0, j + 49, k + 30, Blocks.log, 1);
		world.setBlockMetadataWithNotify(i + 0, j + 49, k + 30, 1, 2);
		setBlock(world, i + 0, j + 49, k + 31, Blocks.log, 1);
		world.setBlockMetadataWithNotify(i + 0, j + 49, k + 31, 1, 2);
		setBlock(world, i + 0, j + 50, k + 24, Blocks.log, 1);
		world.setBlockMetadataWithNotify(i + 0, j + 50, k + 24, 1, 2);
		setBlock(world, i + 0, j + 50, k + 25, Blocks.log, 1);
		world.setBlockMetadataWithNotify(i + 0, j + 50, k + 25, 1, 2);
		setBlock(world, i + 0, j + 50, k + 26, Blocks.log, 1);
		world.setBlockMetadataWithNotify(i + 0, j + 50, k + 26, 1, 2);
		setBlock(world, i + 0, j + 50, k + 27, Blocks.log, 1);
		world.setBlockMetadataWithNotify(i + 0, j + 50, k + 27, 1, 2);
		setBlock(world, i + 0, j + 50, k + 28, Blocks.log, 1);
		world.setBlockMetadataWithNotify(i + 0, j + 50, k + 28, 1, 2);
		setBlock(world, i + 0, j + 50, k + 29, Blocks.log, 1);
		world.setBlockMetadataWithNotify(i + 0, j + 50, k + 29, 1, 2);
		setBlock(world, i + 0, j + 50, k + 30, Blocks.log, 1);
		world.setBlockMetadataWithNotify(i + 0, j + 50, k + 30, 1, 2);
		setBlock(world, i + 0, j + 50, k + 31, Blocks.log, 1);
		world.setBlockMetadataWithNotify(i + 0, j + 50, k + 31, 1, 2);
		setBlock(world, i + 1, j + 21, k + 18, Blocks.leaves, 7);
		world.setBlockMetadataWithNotify(i + 1, j + 21, k + 18, 7, 2);
		setBlock(world, i + 1, j + 21, k + 19, Blocks.leaves, 7);
		world.setBlockMetadataWithNotify(i + 1, j + 21, k + 19, 7, 2);
		setBlock(world, i + 1, j + 21, k + 20, Blocks.leaves, 7);
		world.setBlockMetadataWithNotify(i + 1, j + 21, k + 20, 7, 2);
		setBlock(world, i + 1, j + 21, k + 21, Blocks.leaves, 7);
		world.setBlockMetadataWithNotify(i + 1, j + 21, k + 21, 7, 2);
		setBlock(world, i + 1, j + 21, k + 22, Blocks.leaves, 7);
		world.setBlockMetadataWithNotify(i + 1, j + 21, k + 22, 7, 2);
		setBlock(world, i + 1, j + 21, k + 27, Blocks.leaves, 7);
		world.setBlockMetadataWithNotify(i + 1, j + 21, k + 27, 7, 2);
		setBlock(world, i + 1, j + 21, k + 28, Blocks.leaves, 7);
		world.setBlockMetadataWithNotify(i + 1, j + 21, k + 28, 7, 2);
		setBlock(world, i + 1, j + 21, k + 29, Blocks.leaves, 7);
		world.setBlockMetadataWithNotify(i + 1, j + 21, k + 29, 7, 2);
		setBlock(world, i + 1, j + 22, k + 19, Blocks.leaves, 7);
		world.setBlockMetadataWithNotify(i + 1, j + 22, k + 19, 7, 2);
		setBlock(world, i + 1, j + 22, k + 20, Blocks.leaves, 7);
		world.setBlockMetadataWithNotify(i + 1, j + 22, k + 20, 7, 2);
		setBlock(world, i + 1, j + 22, k + 21, Blocks.leaves, 7);
		world.setBlockMetadataWithNotify(i + 1, j + 22, k + 21, 7, 2);
		setBlock(world, i + 1, j + 22, k + 28, Blocks.leaves, 7);
		world.setBlockMetadataWithNotify(i + 1, j + 22, k + 28, 7, 2);
		setBlock(world, i + 1, j + 23, k + 20, Blocks.leaves, 7);
		world.setBlockMetadataWithNotify(i + 1, j + 23, k + 20, 7, 2);
		setBlock(world, i + 1, j + 24, k + 29, Blocks.leaves, 7);
		world.setBlockMetadataWithNotify(i + 1, j + 24, k + 29, 7, 2);
		setBlock(world, i + 1, j + 24, k + 30, Blocks.leaves, 15);
		world.setBlockMetadataWithNotify(i + 1, j + 24, k + 30, 15, 2);
		setBlock(world, i + 1, j + 24, k + 31, Blocks.leaves, 15);
		world.setBlockMetadataWithNotify(i + 1, j + 24, k + 31, 15, 2);
		setBlock(world, i + 1, j + 25, k + 30, Blocks.leaves, 15);
		world.setBlockMetadataWithNotify(i + 1, j + 25, k + 30, 15, 2);
		setBlock(world, i + 1, j + 25, k + 31, Blocks.leaves, 15);
		world.setBlockMetadataWithNotify(i + 1, j + 25, k + 31, 15, 2);
		setBlock(world, i + 1, j + 26, k + 31, Blocks.leaves, 15);
		world.setBlockMetadataWithNotify(i + 1, j + 26, k + 31, 15, 2);
		setBlock(world, i + 1, j + 31, k + 27, Blocks.log, 3);
		world.setBlockMetadataWithNotify(i + 1, j + 31, k + 27, 3, 2);
		setBlock(world, i + 1, j + 31, k + 30, Blocks.log, 1);
		world.setBlockMetadataWithNotify(i + 1, j + 31, k + 30, 1, 2);
		setBlock(world, i + 1, j + 31, k + 31, Blocks.log, 1);
		world.setBlockMetadataWithNotify(i + 1, j + 31, k + 31, 1, 2);
		setBlock(world, i + 1, j + 38, k + 0, Blocks.vine, 14);
		world.setBlockMetadataWithNotify(i + 1, j + 38, k + 0, 14, 2);
		setBlock(world, i + 1, j + 38, k + 1, Blocks.vine, 8);
		world.setBlockMetadataWithNotify(i + 1, j + 38, k + 1, 8, 2);
		setBlock(world, i + 1, j + 39, k + 0, Blocks.vine, 15);
		world.setBlockMetadataWithNotify(i + 1, j + 39, k + 0, 15, 2);
		setBlock(world, i + 1, j + 39, k + 1, Blocks.vine, 15);
		world.setBlockMetadataWithNotify(i + 1, j + 39, k + 1, 15, 2);
		setBlock(world, i + 1, j + 40, k + 0, Blocks.planks, 5);
		world.setBlockMetadataWithNotify(i + 1, j + 40, k + 0, 5, 2);
		setBlock(world, i + 1, j + 40, k + 1, Blocks.planks, 5);
		world.setBlockMetadataWithNotify(i + 1, j + 40, k + 1, 5, 2);
		setBlock(world, i + 1, j + 40, k + 2, Blocks.planks, 5);
		world.setBlockMetadataWithNotify(i + 1, j + 40, k + 2, 5, 2);
		setBlock(world, i + 1, j + 41, k + 0, Blocks.spruce_stairs, 2);
		world.setBlockMetadataWithNotify(i + 1, j + 41, k + 0, 2, 2);
		setBlock(world, i + 1, j + 41, k + 1, Blocks.planks, 5);
		world.setBlockMetadataWithNotify(i + 1, j + 41, k + 1, 5, 2);
		setBlock(world, i + 1, j + 41, k + 2, Blocks.planks, 5);
		world.setBlockMetadataWithNotify(i + 1, j + 41, k + 2, 5, 2);
		setBlock(world, i + 1, j + 41, k + 3, Blocks.planks, 5);
		world.setBlockMetadataWithNotify(i + 1, j + 41, k + 3, 5, 2);
		setBlock(world, i + 1, j + 41, k + 4, Blocks.planks, 5);
		world.setBlockMetadataWithNotify(i + 1, j + 41, k + 4, 5, 2);
		setBlock(world, i + 1, j + 41, k + 5, Blocks.planks, 5);
		world.setBlockMetadataWithNotify(i + 1, j + 41, k + 5, 5, 2);
		setBlock(world, i + 1, j + 42, k + 3, Blocks.spruce_stairs, 2);
		world.setBlockMetadataWithNotify(i + 1, j + 42, k + 3, 2, 2);
		setBlock(world, i + 1, j + 42, k + 4, Blocks.planks, 5);
		world.setBlockMetadataWithNotify(i + 1, j + 42, k + 4, 5, 2);
		setBlock(world, i + 1, j + 42, k + 5, Blocks.planks, 5);
		world.setBlockMetadataWithNotify(i + 1, j + 42, k + 5, 5, 2);
		setBlock(world, i + 1, j + 42, k + 6, Blocks.planks, 5);
		world.setBlockMetadataWithNotify(i + 1, j + 42, k + 6, 5, 2);
		setBlock(world, i + 1, j + 42, k + 7, Blocks.planks, 5);
		world.setBlockMetadataWithNotify(i + 1, j + 42, k + 7, 5, 2);
		setBlock(world, i + 1, j + 42, k + 8, Blocks.planks, 5);
		world.setBlockMetadataWithNotify(i + 1, j + 42, k + 8, 5, 2);
		setBlock(world, i + 1, j + 43, k + 22, Blocks.log, 1);
		world.setBlockMetadataWithNotify(i + 1, j + 43, k + 22, 1, 2);
		setBlock(world, i + 1, j + 43, k + 23, Blocks.log, 1);
		world.setBlockMetadataWithNotify(i + 1, j + 43, k + 23, 1, 2);
		setBlock(world, i + 1, j + 43, k + 24, Blocks.log, 1);
		world.setBlockMetadataWithNotify(i + 1, j + 43, k + 24, 1, 2);
		setBlock(world, i + 1, j + 43, k + 25, Blocks.log, 1);
		world.setBlockMetadataWithNotify(i + 1, j + 43, k + 25, 1, 2);
		setBlock(world, i + 1, j + 43, k + 26, Blocks.log, 1);
		world.setBlockMetadataWithNotify(i + 1, j + 43, k + 26, 1, 2);
		setBlock(world, i + 1, j + 43, k + 27, Blocks.log, 1);
		world.setBlockMetadataWithNotify(i + 1, j + 43, k + 27, 1, 2);
		setBlock(world, i + 1, j + 43, k + 28, Blocks.planks, 5);
		world.setBlockMetadataWithNotify(i + 1, j + 43, k + 28, 5, 2);
		setBlock(world, i + 1, j + 43, k + 29, Blocks.planks, 5);
		world.setBlockMetadataWithNotify(i + 1, j + 43, k + 29, 5, 2);
		setBlock(world, i + 1, j + 43, k + 30, Blocks.planks, 5);
		world.setBlockMetadataWithNotify(i + 1, j + 43, k + 30, 5, 2);
		setBlock(world, i + 1, j + 43, k + 31, Blocks.planks, 5);
		world.setBlockMetadataWithNotify(i + 1, j + 43, k + 31, 5, 2);
		setBlock(world, i + 1, j + 45, k + 22, Blocks.torch, 5);
		world.setBlockMetadataWithNotify(i + 1, j + 45, k + 22, 5, 2);
		setBlock(world, i + 1, j + 48, k + 19, Blocks.log, 1);
		world.setBlockMetadataWithNotify(i + 1, j + 48, k + 19, 1, 2);
		setBlock(world, i + 1, j + 48, k + 20, Blocks.log, 1);
		world.setBlockMetadataWithNotify(i + 1, j + 48, k + 20, 1, 2);
		setBlock(world, i + 1, j + 48, k + 21, Blocks.log, 1);
		world.setBlockMetadataWithNotify(i + 1, j + 48, k + 21, 1, 2);
		setBlock(world, i + 1, j + 48, k + 22, Blocks.log, 1);
		world.setBlockMetadataWithNotify(i + 1, j + 48, k + 22, 1, 2);
		setBlock(world, i + 1, j + 48, k + 23, Blocks.log, 1);
		world.setBlockMetadataWithNotify(i + 1, j + 48, k + 23, 1, 2);
		setBlock(world, i + 1, j + 48, k + 24, Blocks.log, 1);
		world.setBlockMetadataWithNotify(i + 1, j + 48, k + 24, 1, 2);
		setBlock(world, i + 1, j + 48, k + 25, Blocks.log, 1);
		world.setBlockMetadataWithNotify(i + 1, j + 48, k + 25, 1, 2);
		setBlock(world, i + 1, j + 48, k + 26, Blocks.torch, 1);
		world.setBlockMetadataWithNotify(i + 1, j + 48, k + 26, 1, 2);
		setBlock(world, i + 1, j + 49, k + 20, Blocks.log, 1);
		world.setBlockMetadataWithNotify(i + 1, j + 49, k + 20, 1, 2);
		setBlock(world, i + 1, j + 49, k + 21, Blocks.log, 1);
		world.setBlockMetadataWithNotify(i + 1, j + 49, k + 21, 1, 2);
		setBlock(world, i + 1, j + 49, k + 22, Blocks.log, 1);
		world.setBlockMetadataWithNotify(i + 1, j + 49, k + 22, 1, 2);
		setBlock(world, i + 1, j + 49, k + 23, Blocks.log, 1);
		world.setBlockMetadataWithNotify(i + 1, j + 49, k + 23, 1, 2);
		setBlock(world, i + 1, j + 49, k + 24, Blocks.log, 1);
		world.setBlockMetadataWithNotify(i + 1, j + 49, k + 24, 1, 2);
		setBlock(world, i + 1, j + 49, k + 25, Blocks.log, 1);
		world.setBlockMetadataWithNotify(i + 1, j + 49, k + 25, 1, 2);
		setBlock(world, i + 1, j + 49, k + 26, Blocks.log, 1);
		world.setBlockMetadataWithNotify(i + 1, j + 49, k + 26, 1, 2);
		setBlock(world, i + 1, j + 49, k + 27, Blocks.log, 1);
		world.setBlockMetadataWithNotify(i + 1, j + 49, k + 27, 1, 2);
		setBlock(world, i + 1, j + 49, k + 28, Blocks.log, 1);
		world.setBlockMetadataWithNotify(i + 1, j + 49, k + 28, 1, 2);
		setBlock(world, i + 1, j + 49, k + 29, Blocks.log, 1);
		world.setBlockMetadataWithNotify(i + 1, j + 49, k + 29, 1, 2);
		setBlock(world, i + 1, j + 49, k + 30, Blocks.log, 1);
		world.setBlockMetadataWithNotify(i + 1, j + 49, k + 30, 1, 2);
		setBlock(world, i + 1, j + 49, k + 31, Blocks.log, 1);
		world.setBlockMetadataWithNotify(i + 1, j + 49, k + 31, 1, 2);
		setBlock(world, i + 1, j + 50, k + 23, Blocks.log, 1);
		world.setBlockMetadataWithNotify(i + 1, j + 50, k + 23, 1, 2);
		setBlock(world, i + 1, j + 50, k + 24, Blocks.log, 1);
		world.setBlockMetadataWithNotify(i + 1, j + 50, k + 24, 1, 2);
		setBlock(world, i + 1, j + 50, k + 25, Blocks.log, 1);
		world.setBlockMetadataWithNotify(i + 1, j + 50, k + 25, 1, 2);
		setBlock(world, i + 1, j + 50, k + 26, Blocks.log, 1);
		world.setBlockMetadataWithNotify(i + 1, j + 50, k + 26, 1, 2);
		setBlock(world, i + 1, j + 50, k + 27, Blocks.log, 1);
		world.setBlockMetadataWithNotify(i + 1, j + 50, k + 27, 1, 2);
		setBlock(world, i + 1, j + 50, k + 28, Blocks.log, 1);
		world.setBlockMetadataWithNotify(i + 1, j + 50, k + 28, 1, 2);
		setBlock(world, i + 1, j + 50, k + 29, Blocks.log, 1);
		world.setBlockMetadataWithNotify(i + 1, j + 50, k + 29, 1, 2);
		setBlock(world, i + 1, j + 50, k + 30, Blocks.log, 1);
		world.setBlockMetadataWithNotify(i + 1, j + 50, k + 30, 1, 2);
		setBlock(world, i + 1, j + 50, k + 31, Blocks.log, 1);
		world.setBlockMetadataWithNotify(i + 1, j + 50, k + 31, 1, 2);
		setBlock(world, i + 2, j + 21, k + 19, Blocks.leaves, 7);
		world.setBlockMetadataWithNotify(i + 2, j + 21, k + 19, 7, 2);
		setBlock(world, i + 2, j + 21, k + 20, Blocks.leaves, 7);
		world.setBlockMetadataWithNotify(i + 2, j + 21, k + 20, 7, 2);
		setBlock(world, i + 2, j + 21, k + 21, Blocks.leaves, 7);
		world.setBlockMetadataWithNotify(i + 2, j + 21, k + 21, 7, 2);
		setBlock(world, i + 2, j + 22, k + 20, Blocks.leaves, 7);
		world.setBlockMetadataWithNotify(i + 2, j + 22, k + 20, 7, 2);
		setBlock(world, i + 2, j + 24, k + 30, Blocks.leaves, 15);
		world.setBlockMetadataWithNotify(i + 2, j + 24, k + 30, 15, 2);
		setBlock(world, i + 2, j + 24, k + 31, Blocks.log, 3);
		world.setBlockMetadataWithNotify(i + 2, j + 24, k + 31, 3, 2);
		setBlock(world, i + 2, j + 25, k + 31, Blocks.leaves, 15);
		world.setBlockMetadataWithNotify(i + 2, j + 25, k + 31, 15, 2);
		setBlock(world, i + 2, j + 31, k + 25, Blocks.log, 3);
		world.setBlockMetadataWithNotify(i + 2, j + 31, k + 25, 3, 2);
		setBlock(world, i + 2, j + 31, k + 26, Blocks.log, 3);
		world.setBlockMetadataWithNotify(i + 2, j + 31, k + 26, 3, 2);
		setBlock(world, i + 2, j + 31, k + 29, Blocks.log, 1);
		world.setBlockMetadataWithNotify(i + 2, j + 31, k + 29, 1, 2);
		setBlock(world, i + 2, j + 31, k + 30, Blocks.log, 1);
		world.setBlockMetadataWithNotify(i + 2, j + 31, k + 30, 1, 2);
		setBlock(world, i + 2, j + 31, k + 31, Blocks.log, 1);
		world.setBlockMetadataWithNotify(i + 2, j + 31, k + 31, 1, 2);
		setBlock(world, i + 2, j + 32, k + 22, Blocks.leaves, 7);
		world.setBlockMetadataWithNotify(i + 2, j + 32, k + 22, 7, 2);
		setBlock(world, i + 2, j + 32, k + 23, Blocks.leaves, 7);
		world.setBlockMetadataWithNotify(i + 2, j + 32, k + 23, 7, 2);
		setBlock(world, i + 2, j + 32, k + 24, Blocks.leaves, 7);
		world.setBlockMetadataWithNotify(i + 2, j + 32, k + 24, 7, 2);
		setBlock(world, i + 2, j + 32, k + 31, Blocks.log, 1);
		world.setBlockMetadataWithNotify(i + 2, j + 32, k + 31, 1, 2);
		setBlock(world, i + 2, j + 33, k + 23, Blocks.leaves, 7);
		world.setBlockMetadataWithNotify(i + 2, j + 33, k + 23, 7, 2);
		setBlock(world, i + 2, j + 33, k + 31, Blocks.log, 1);
		world.setBlockMetadataWithNotify(i + 2, j + 33, k + 31, 1, 2);
		setBlock(world, i + 2, j + 38, k + 31, Blocks.leaves, 7);
		world.setBlockMetadataWithNotify(i + 2, j + 38, k + 31, 7, 2);
		setBlock(world, i + 2, j + 40, k + 0, Blocks.planks, 5);
		world.setBlockMetadataWithNotify(i + 2, j + 40, k + 0, 5, 2);
		setBlock(world, i + 2, j + 40, k + 1, Blocks.planks, 5);
		world.setBlockMetadataWithNotify(i + 2, j + 40, k + 1, 5, 2);
		setBlock(world, i + 2, j + 40, k + 2, Blocks.planks, 5);
		world.setBlockMetadataWithNotify(i + 2, j + 40, k + 2, 5, 2);
		setBlock(world, i + 2, j + 41, k + 0, Blocks.spruce_stairs, 2);
		world.setBlockMetadataWithNotify(i + 2, j + 41, k + 0, 2, 2);
		setBlock(world, i + 2, j + 41, k + 1, Blocks.planks, 5);
		world.setBlockMetadataWithNotify(i + 2, j + 41, k + 1, 5, 2);
		setBlock(world, i + 2, j + 41, k + 2, Blocks.planks, 5);
		world.setBlockMetadataWithNotify(i + 2, j + 41, k + 2, 5, 2);
		setBlock(world, i + 2, j + 41, k + 3, Blocks.planks, 5);
		world.setBlockMetadataWithNotify(i + 2, j + 41, k + 3, 5, 2);
		setBlock(world, i + 2, j + 41, k + 4, Blocks.planks, 5);
		world.setBlockMetadataWithNotify(i + 2, j + 41, k + 4, 5, 2);
		setBlock(world, i + 2, j + 41, k + 5, Blocks.planks, 5);
		world.setBlockMetadataWithNotify(i + 2, j + 41, k + 5, 5, 2);
		setBlock(world, i + 2, j + 42, k + 3, Blocks.spruce_stairs, 2);
		world.setBlockMetadataWithNotify(i + 2, j + 42, k + 3, 2, 2);
		setBlock(world, i + 2, j + 42, k + 4, Blocks.planks, 5);
		world.setBlockMetadataWithNotify(i + 2, j + 42, k + 4, 5, 2);
		setBlock(world, i + 2, j + 42, k + 5, Blocks.planks, 5);
		world.setBlockMetadataWithNotify(i + 2, j + 42, k + 5, 5, 2);
		setBlock(world, i + 2, j + 42, k + 6, Blocks.planks, 5);
		world.setBlockMetadataWithNotify(i + 2, j + 42, k + 6, 5, 2);
		setBlock(world, i + 2, j + 42, k + 7, Blocks.planks, 5);
		world.setBlockMetadataWithNotify(i + 2, j + 42, k + 7, 5, 2);
		setBlock(world, i + 2, j + 42, k + 8, Blocks.planks, 5);
		world.setBlockMetadataWithNotify(i + 2, j + 42, k + 8, 5, 2);
		setBlock(world, i + 2, j + 42, k + 9, Blocks.planks, 5);
		world.setBlockMetadataWithNotify(i + 2, j + 42, k + 9, 5, 2);
		setBlock(world, i + 2, j + 42, k + 26, Blocks.log, 1);
		world.setBlockMetadataWithNotify(i + 2, j + 42, k + 26, 1, 2);
		setBlock(world, i + 2, j + 43, k + 9, Blocks.torch, 5);
		world.setBlockMetadataWithNotify(i + 2, j + 43, k + 9, 5, 2);
		setBlock(world, i + 2, j + 43, k + 21, Blocks.log, 1);
		world.setBlockMetadataWithNotify(i + 2, j + 43, k + 21, 1, 2);
		setBlock(world, i + 2, j + 43, k + 22, Blocks.log, 1);
		world.setBlockMetadataWithNotify(i + 2, j + 43, k + 22, 1, 2);
		setBlock(world, i + 2, j + 43, k + 23, Blocks.log, 1);
		world.setBlockMetadataWithNotify(i + 2, j + 43, k + 23, 1, 2);
		setBlock(world, i + 2, j + 43, k + 24, Blocks.log, 1);
		world.setBlockMetadataWithNotify(i + 2, j + 43, k + 24, 1, 2);
		setBlock(world, i + 2, j + 43, k + 25, Blocks.log, 1);
		world.setBlockMetadataWithNotify(i + 2, j + 43, k + 25, 1, 2);
		setBlock(world, i + 2, j + 43, k + 26, Blocks.log, 1);
		world.setBlockMetadataWithNotify(i + 2, j + 43, k + 26, 1, 2);
		setBlock(world, i + 2, j + 43, k + 27, Blocks.planks, 5);
		world.setBlockMetadataWithNotify(i + 2, j + 43, k + 27, 5, 2);
		setBlock(world, i + 2, j + 43, k + 28, Blocks.log, 1);
		world.setBlockMetadataWithNotify(i + 2, j + 43, k + 28, 1, 2);
		setBlock(world, i + 2, j + 43, k + 29, Blocks.log, 1);
		world.setBlockMetadataWithNotify(i + 2, j + 43, k + 29, 1, 2);
		setBlock(world, i + 2, j + 43, k + 30, Blocks.planks, 5);
		world.setBlockMetadataWithNotify(i + 2, j + 43, k + 30, 5, 2);
		setBlock(world, i + 2, j + 43, k + 31, Blocks.planks, 5);
		world.setBlockMetadataWithNotify(i + 2, j + 43, k + 31, 5, 2);
		setBlock(world, i + 2, j + 44, k + 20, Blocks.spruce_stairs, 6);
		world.setBlockMetadataWithNotify(i + 2, j + 44, k + 20, 6, 2);
		setBlock(world, i + 2, j + 44, k + 21, Blocks.log, 1);
		world.setBlockMetadataWithNotify(i + 2, j + 44, k + 21, 1, 2);
		setBlock(world, i + 2, j + 44, k + 22, Blocks.spruce_stairs, 3);
		world.setBlockMetadataWithNotify(i + 2, j + 44, k + 22, 3, 2);
		setBlock(world, i + 2, j + 45, k + 19, Blocks.spruce_stairs, 6);
		world.setBlockMetadataWithNotify(i + 2, j + 45, k + 19, 6, 2);
		setBlock(world, i + 2, j + 45, k + 20, Blocks.log, 1);
		world.setBlockMetadataWithNotify(i + 2, j + 45, k + 20, 1, 2);
		setBlock(world, i + 2, j + 45, k + 21, Blocks.log, 1);
		world.setBlockMetadataWithNotify(i + 2, j + 45, k + 21, 1, 2);
		setBlock(world, i + 2, j + 46, k + 19, Blocks.log, 1);
		world.setBlockMetadataWithNotify(i + 2, j + 46, k + 19, 1, 2);
		setBlock(world, i + 2, j + 46, k + 20, Blocks.log, 1);
		world.setBlockMetadataWithNotify(i + 2, j + 46, k + 20, 1, 2);
		setBlock(world, i + 2, j + 47, k + 19, Blocks.log, 1);
		world.setBlockMetadataWithNotify(i + 2, j + 47, k + 19, 1, 2);
		setBlock(world, i + 2, j + 48, k + 18, Blocks.log, 1);
		world.setBlockMetadataWithNotify(i + 2, j + 48, k + 18, 1, 2);
		setBlock(world, i + 2, j + 48, k + 19, Blocks.log, 1);
		world.setBlockMetadataWithNotify(i + 2, j + 48, k + 19, 1, 2);
		setBlock(world, i + 2, j + 48, k + 20, Blocks.log, 1);
		world.setBlockMetadataWithNotify(i + 2, j + 48, k + 20, 1, 2);
		setBlock(world, i + 2, j + 48, k + 21, Blocks.log, 1);
		world.setBlockMetadataWithNotify(i + 2, j + 48, k + 21, 1, 2);
		setBlock(world, i + 2, j + 48, k + 22, Blocks.log, 1);
		world.setBlockMetadataWithNotify(i + 2, j + 48, k + 22, 1, 2);
		setBlock(world, i + 2, j + 48, k + 23, Blocks.log, 1);
		world.setBlockMetadataWithNotify(i + 2, j + 48, k + 23, 1, 2);
		setBlock(world, i + 2, j + 48, k + 24, Blocks.log, 1);
		world.setBlockMetadataWithNotify(i + 2, j + 48, k + 24, 1, 2);
		setBlock(world, i + 2, j + 49, k + 19, Blocks.log, 1);
		world.setBlockMetadataWithNotify(i + 2, j + 49, k + 19, 1, 2);
		setBlock(world, i + 2, j + 49, k + 20, Blocks.log, 1);
		world.setBlockMetadataWithNotify(i + 2, j + 49, k + 20, 1, 2);
		setBlock(world, i + 2, j + 49, k + 21, Blocks.log, 1);
		world.setBlockMetadataWithNotify(i + 2, j + 49, k + 21, 1, 2);
		setBlock(world, i + 2, j + 49, k + 22, Blocks.log, 1);
		world.setBlockMetadataWithNotify(i + 2, j + 49, k + 22, 1, 2);
		setBlock(world, i + 2, j + 49, k + 23, Blocks.log, 1);
		world.setBlockMetadataWithNotify(i + 2, j + 49, k + 23, 1, 2);
		setBlock(world, i + 2, j + 49, k + 24, Blocks.log, 1);
		world.setBlockMetadataWithNotify(i + 2, j + 49, k + 24, 1, 2);
		setBlock(world, i + 2, j + 49, k + 25, Blocks.log, 1);
		world.setBlockMetadataWithNotify(i + 2, j + 49, k + 25, 1, 2);
		setBlock(world, i + 2, j + 50, k + 22, Blocks.log, 1);
		world.setBlockMetadataWithNotify(i + 2, j + 50, k + 22, 1, 2);
		setBlock(world, i + 2, j + 50, k + 23, Blocks.log, 1);
		world.setBlockMetadataWithNotify(i + 2, j + 50, k + 23, 1, 2);
		setBlock(world, i + 2, j + 50, k + 24, Blocks.log, 1);
		world.setBlockMetadataWithNotify(i + 2, j + 50, k + 24, 1, 2);
		setBlock(world, i + 2, j + 50, k + 25, Blocks.log, 1);
		world.setBlockMetadataWithNotify(i + 2, j + 50, k + 25, 1, 2);
		setBlock(world, i + 2, j + 50, k + 26, Blocks.log, 1);
		world.setBlockMetadataWithNotify(i + 2, j + 50, k + 26, 1, 2);
		setBlock(world, i + 2, j + 50, k + 27, Blocks.log, 1);
		world.setBlockMetadataWithNotify(i + 2, j + 50, k + 27, 1, 2);
		setBlock(world, i + 2, j + 50, k + 28, Blocks.log, 1);
		world.setBlockMetadataWithNotify(i + 2, j + 50, k + 28, 1, 2);
		setBlock(world, i + 2, j + 50, k + 29, Blocks.log, 1);
		world.setBlockMetadataWithNotify(i + 2, j + 50, k + 29, 1, 2);
		setBlock(world, i + 2, j + 50, k + 30, Blocks.log, 1);
		world.setBlockMetadataWithNotify(i + 2, j + 50, k + 30, 1, 2);
		setBlock(world, i + 2, j + 50, k + 31, Blocks.log, 1);
		world.setBlockMetadataWithNotify(i + 2, j + 50, k + 31, 1, 2);
		setBlock(world, i + 2, j + 51, k + 27, Blocks.log, 1);
		world.setBlockMetadataWithNotify(i + 2, j + 51, k + 27, 1, 2);
		setBlock(world, i + 2, j + 51, k + 28, Blocks.log, 1);
		
		generate9(world, rand, i, j, k);
		return true;
		}

	
	public boolean generate9(World world, Random rand, int i, int j, int k)
	
	{
		world.setBlockMetadataWithNotify(i + 2, j + 51, k + 28, 1, 2);
		setBlock(world, i + 2, j + 51, k + 29, Blocks.log, 1);
		world.setBlockMetadataWithNotify(i + 2, j + 51, k + 29, 1, 2);
		setBlock(world, i + 2, j + 51, k + 30, Blocks.log, 1);
		world.setBlockMetadataWithNotify(i + 2, j + 51, k + 30, 1, 2);
		setBlock(world, i + 2, j + 51, k + 31, Blocks.log, 1);
		world.setBlockMetadataWithNotify(i + 2, j + 51, k + 31, 1, 2);
		setBlock(world, i + 3, j + 25, k + 30, Blocks.log, 3);
		world.setBlockMetadataWithNotify(i + 3, j + 25, k + 30, 3, 2);
		setBlock(world, i + 3, j + 26, k + 27, Blocks.leaves, 7);
		world.setBlockMetadataWithNotify(i + 3, j + 26, k + 27, 7, 2);
		setBlock(world, i + 3, j + 26, k + 28, Blocks.leaves, 7);
		world.setBlockMetadataWithNotify(i + 3, j + 26, k + 28, 7, 2);
		setBlock(world, i + 3, j + 26, k + 29, Blocks.leaves, 7);
		world.setBlockMetadataWithNotify(i + 3, j + 26, k + 29, 7, 2);
		setBlock(world, i + 3, j + 27, k + 28, Blocks.leaves, 7);
		world.setBlockMetadataWithNotify(i + 3, j + 27, k + 28, 7, 2);
		setBlock(world, i + 3, j + 31, k + 24, Blocks.log, 3);
		world.setBlockMetadataWithNotify(i + 3, j + 31, k + 24, 3, 2);
		setBlock(world, i + 3, j + 31, k + 28, Blocks.log, 1);
		world.setBlockMetadataWithNotify(i + 3, j + 31, k + 28, 1, 2);
		setBlock(world, i + 3, j + 31, k + 29, Blocks.log, 1);
		world.setBlockMetadataWithNotify(i + 3, j + 31, k + 29, 1, 2);
		setBlock(world, i + 3, j + 31, k + 30, Blocks.log, 1);
		world.setBlockMetadataWithNotify(i + 3, j + 31, k + 30, 1, 2);
		setBlock(world, i + 3, j + 31, k + 31, Blocks.log, 1);
		world.setBlockMetadataWithNotify(i + 3, j + 31, k + 31, 1, 2);
		setBlock(world, i + 3, j + 32, k + 11, Blocks.vine, 3);
		world.setBlockMetadataWithNotify(i + 3, j + 32, k + 11, 3, 2);
		setBlock(world, i + 3, j + 32, k + 21, Blocks.leaves, 7);
		world.setBlockMetadataWithNotify(i + 3, j + 32, k + 21, 7, 2);
		setBlock(world, i + 3, j + 32, k + 22, Blocks.leaves, 7);
		world.setBlockMetadataWithNotify(i + 3, j + 32, k + 22, 7, 2);
		setBlock(world, i + 3, j + 32, k + 23, Blocks.leaves, 7);
		world.setBlockMetadataWithNotify(i + 3, j + 32, k + 23, 7, 2);
		setBlock(world, i + 3, j + 32, k + 24, Blocks.leaves, 7);
		world.setBlockMetadataWithNotify(i + 3, j + 32, k + 24, 7, 2);
		setBlock(world, i + 3, j + 32, k + 25, Blocks.leaves, 7);
		world.setBlockMetadataWithNotify(i + 3, j + 32, k + 25, 7, 2);
		setBlock(world, i + 3, j + 32, k + 29, Blocks.log, 1);
		world.setBlockMetadataWithNotify(i + 3, j + 32, k + 29, 1, 2);
		setBlock(world, i + 3, j + 32, k + 30, Blocks.log, 1);
		world.setBlockMetadataWithNotify(i + 3, j + 32, k + 30, 1, 2);
		setBlock(world, i + 3, j + 32, k + 31, Blocks.log, 1);
		world.setBlockMetadataWithNotify(i + 3, j + 32, k + 31, 1, 2);
		setBlock(world, i + 3, j + 33, k + 11, Blocks.vine, 3);
		world.setBlockMetadataWithNotify(i + 3, j + 33, k + 11, 3, 2);
		setBlock(world, i + 3, j + 33, k + 22, Blocks.leaves, 7);
		world.setBlockMetadataWithNotify(i + 3, j + 33, k + 22, 7, 2);
		setBlock(world, i + 3, j + 33, k + 23, Blocks.leaves, 7);
		world.setBlockMetadataWithNotify(i + 3, j + 33, k + 23, 7, 2);
		setBlock(world, i + 3, j + 33, k + 24, Blocks.leaves, 7);
		world.setBlockMetadataWithNotify(i + 3, j + 33, k + 24, 7, 2);
		setBlock(world, i + 3, j + 33, k + 30, Blocks.log, 1);
		world.setBlockMetadataWithNotify(i + 3, j + 33, k + 30, 1, 2);
		setBlock(world, i + 3, j + 33, k + 31, Blocks.log, 1);
		world.setBlockMetadataWithNotify(i + 3, j + 33, k + 31, 1, 2);
		setBlock(world, i + 3, j + 34, k + 11, Blocks.vine, 15);
		world.setBlockMetadataWithNotify(i + 3, j + 34, k + 11, 15, 2);
		setBlock(world, i + 3, j + 34, k + 12, Blocks.vine, 15);
		world.setBlockMetadataWithNotify(i + 3, j + 34, k + 12, 15, 2);
		setBlock(world, i + 3, j + 34, k + 23, Blocks.leaves, 7);
		world.setBlockMetadataWithNotify(i + 3, j + 34, k + 23, 7, 2);
		setBlock(world, i + 3, j + 34, k + 31, Blocks.log, 1);
		world.setBlockMetadataWithNotify(i + 3, j + 34, k + 31, 1, 2);
		setBlock(world, i + 3, j + 35, k + 11, Blocks.vine, 15);
		world.setBlockMetadataWithNotify(i + 3, j + 35, k + 11, 15, 2);
		setBlock(world, i + 3, j + 35, k + 12, Blocks.vine, 15);
		world.setBlockMetadataWithNotify(i + 3, j + 35, k + 12, 15, 2);
		setBlock(world, i + 3, j + 36, k + 11, Blocks.vine, 15);
		world.setBlockMetadataWithNotify(i + 3, j + 36, k + 11, 15, 2);
		setBlock(world, i + 3, j + 36, k + 12, Blocks.vine, 15);
		world.setBlockMetadataWithNotify(i + 3, j + 36, k + 12, 15, 2);
		setBlock(world, i + 3, j + 37, k + 11, Blocks.vine, 15);
		world.setBlockMetadataWithNotify(i + 3, j + 37, k + 11, 15, 2);
		setBlock(world, i + 3, j + 37, k + 12, Blocks.vine, 15);
		world.setBlockMetadataWithNotify(i + 3, j + 37, k + 12, 15, 2);
		setBlock(world, i + 3, j + 38, k + 11, Blocks.vine, 15);
		world.setBlockMetadataWithNotify(i + 3, j + 38, k + 11, 15, 2);
		setBlock(world, i + 3, j + 38, k + 12, Blocks.vine, 15);
		world.setBlockMetadataWithNotify(i + 3, j + 38, k + 12, 15, 2);
		setBlock(world, i + 3, j + 38, k + 30, Blocks.leaves, 7);
		world.setBlockMetadataWithNotify(i + 3, j + 38, k + 30, 7, 2);
		setBlock(world, i + 3, j + 38, k + 31, Blocks.leaves, 7);
		world.setBlockMetadataWithNotify(i + 3, j + 38, k + 31, 7, 2);
		setBlock(world, i + 3, j + 39, k + 11, Blocks.vine, 15);
		world.setBlockMetadataWithNotify(i + 3, j + 39, k + 11, 15, 2);
		setBlock(world, i + 3, j + 39, k + 12, Blocks.vine, 15);
		world.setBlockMetadataWithNotify(i + 3, j + 39, k + 12, 15, 2);
		setBlock(world, i + 3, j + 39, k + 31, Blocks.leaves, 15);
		world.setBlockMetadataWithNotify(i + 3, j + 39, k + 31, 15, 2);
		setBlock(world, i + 3, j + 40, k + 0, Blocks.planks, 5);
		world.setBlockMetadataWithNotify(i + 3, j + 40, k + 0, 5, 2);
		setBlock(world, i + 3, j + 40, k + 1, Blocks.planks, 5);
		world.setBlockMetadataWithNotify(i + 3, j + 40, k + 1, 5, 2);
		setBlock(world, i + 3, j + 40, k + 2, Blocks.planks, 5);
		world.setBlockMetadataWithNotify(i + 3, j + 40, k + 2, 5, 2);
		setBlock(world, i + 3, j + 40, k + 11, Blocks.vine, 15);
		world.setBlockMetadataWithNotify(i + 3, j + 40, k + 11, 15, 2);
		setBlock(world, i + 3, j + 40, k + 12, Blocks.vine, 15);
		world.setBlockMetadataWithNotify(i + 3, j + 40, k + 12, 15, 2);
		setBlock(world, i + 3, j + 41, k + 0, Blocks.spruce_stairs, 2);
		world.setBlockMetadataWithNotify(i + 3, j + 41, k + 0, 2, 2);
		setBlock(world, i + 3, j + 41, k + 1, Blocks.planks, 5);
		world.setBlockMetadataWithNotify(i + 3, j + 41, k + 1, 5, 2);
		setBlock(world, i + 3, j + 41, k + 2, Blocks.planks, 5);
		world.setBlockMetadataWithNotify(i + 3, j + 41, k + 2, 5, 2);
		setBlock(world, i + 3, j + 41, k + 3, Blocks.planks, 5);
		world.setBlockMetadataWithNotify(i + 3, j + 41, k + 3, 5, 2);
		setBlock(world, i + 3, j + 41, k + 4, Blocks.planks, 5);
		world.setBlockMetadataWithNotify(i + 3, j + 41, k + 4, 5, 2);
		setBlock(world, i + 3, j + 41, k + 5, Blocks.planks, 5);
		world.setBlockMetadataWithNotify(i + 3, j + 41, k + 5, 5, 2);
		setBlock(world, i + 3, j + 41, k + 11, Blocks.vine, 15);
		world.setBlockMetadataWithNotify(i + 3, j + 41, k + 11, 15, 2);
		setBlock(world, i + 3, j + 41, k + 12, Blocks.vine, 15);
		world.setBlockMetadataWithNotify(i + 3, j + 41, k + 12, 15, 2);
		setBlock(world, i + 3, j + 41, k + 30, Blocks.leaves, 15);
		world.setBlockMetadataWithNotify(i + 3, j + 41, k + 30, 15, 2);
		setBlock(world, i + 3, j + 41, k + 31, Blocks.leaves, 15);
		world.setBlockMetadataWithNotify(i + 3, j + 41, k + 31, 15, 2);
		setBlock(world, i + 3, j + 42, k + 1, Blocks.torch, 5);
		world.setBlockMetadataWithNotify(i + 3, j + 42, k + 1, 5, 2);
		setBlock(world, i + 3, j + 42, k + 3, Blocks.spruce_stairs, 2);
		world.setBlockMetadataWithNotify(i + 3, j + 42, k + 3, 2, 2);
		setBlock(world, i + 3, j + 42, k + 4, Blocks.planks, 5);
		world.setBlockMetadataWithNotify(i + 3, j + 42, k + 4, 5, 2);
		setBlock(world, i + 3, j + 42, k + 5, Blocks.planks, 5);
		world.setBlockMetadataWithNotify(i + 3, j + 42, k + 5, 5, 2);
		setBlock(world, i + 3, j + 42, k + 6, Blocks.planks, 5);
		world.setBlockMetadataWithNotify(i + 3, j + 42, k + 6, 5, 2);
		setBlock(world, i + 3, j + 42, k + 7, Blocks.planks, 5);
		world.setBlockMetadataWithNotify(i + 3, j + 42, k + 7, 5, 2);
		setBlock(world, i + 3, j + 42, k + 8, Blocks.planks, 5);
		world.setBlockMetadataWithNotify(i + 3, j + 42, k + 8, 5, 2);
		setBlock(world, i + 3, j + 42, k + 9, Blocks.planks, 5);
		world.setBlockMetadataWithNotify(i + 3, j + 42, k + 9, 5, 2);
		setBlock(world, i + 3, j + 42, k + 10, Blocks.planks, 5);
		world.setBlockMetadataWithNotify(i + 3, j + 42, k + 10, 5, 2);
		setBlock(world, i + 3, j + 42, k + 11, Blocks.planks, 5);
		world.setBlockMetadataWithNotify(i + 3, j + 42, k + 11, 5, 2);
		setBlock(world, i + 3, j + 42, k + 12, Blocks.planks, 5);
		world.setBlockMetadataWithNotify(i + 3, j + 42, k + 12, 5, 2);
		setBlock(world, i + 3, j + 42, k + 13, Blocks.planks, 5);
		world.setBlockMetadataWithNotify(i + 3, j + 42, k + 13, 5, 2);
		setBlock(world, i + 3, j + 42, k + 14, Blocks.planks, 5);
		world.setBlockMetadataWithNotify(i + 3, j + 42, k + 14, 5, 2);
		setBlock(world, i + 3, j + 42, k + 15, Blocks.planks, 5);
		world.setBlockMetadataWithNotify(i + 3, j + 42, k + 15, 5, 2);
		setBlock(world, i + 3, j + 42, k + 16, Blocks.planks, 5);
		world.setBlockMetadataWithNotify(i + 3, j + 42, k + 16, 5, 2);
		setBlock(world, i + 3, j + 42, k + 25, Blocks.log, 1);
		world.setBlockMetadataWithNotify(i + 3, j + 42, k + 25, 1, 2);
		setBlock(world, i + 3, j + 42, k + 26, Blocks.log, 1);
		world.setBlockMetadataWithNotify(i + 3, j + 42, k + 26, 1, 2);
		setBlock(world, i + 3, j + 42, k + 27, Blocks.log, 1);
		world.setBlockMetadataWithNotify(i + 3, j + 42, k + 27, 1, 2);
		setBlock(world, i + 3, j + 42, k + 31, Blocks.leaves, 15);
		world.setBlockMetadataWithNotify(i + 3, j + 42, k + 31, 15, 2);
		setBlock(world, i + 3, j + 43, k + 5, Blocks.torch, 5);
		world.setBlockMetadataWithNotify(i + 3, j + 43, k + 5, 5, 2);
		setBlock(world, i + 3, j + 43, k + 15, Blocks.spruce_stairs, 2);
		world.setBlockMetadataWithNotify(i + 3, j + 43, k + 15, 2, 2);
		setBlock(world, i + 3, j + 43, k + 16, Blocks.planks, 5);
		world.setBlockMetadataWithNotify(i + 3, j + 43, k + 16, 5, 2);
		setBlock(world, i + 3, j + 43, k + 17, Blocks.planks, 5);
		world.setBlockMetadataWithNotify(i + 3, j + 43, k + 17, 5, 2);
		setBlock(world, i + 3, j + 43, k + 18, Blocks.planks, 5);
		world.setBlockMetadataWithNotify(i + 3, j + 43, k + 18, 5, 2);
		setBlock(world, i + 3, j + 43, k + 19, Blocks.planks, 5);
		world.setBlockMetadataWithNotify(i + 3, j + 43, k + 19, 5, 2);
		setBlock(world, i + 3, j + 43, k + 20, Blocks.log, 1);
		world.setBlockMetadataWithNotify(i + 3, j + 43, k + 20, 1, 2);
		setBlock(world, i + 3, j + 43, k + 21, Blocks.log, 1);
		world.setBlockMetadataWithNotify(i + 3, j + 43, k + 21, 1, 2);
		setBlock(world, i + 3, j + 43, k + 22, Blocks.log, 1);
		world.setBlockMetadataWithNotify(i + 3, j + 43, k + 22, 1, 2);
		setBlock(world, i + 3, j + 43, k + 23, Blocks.log, 1);
		world.setBlockMetadataWithNotify(i + 3, j + 43, k + 23, 1, 2);
		setBlock(world, i + 3, j + 43, k + 24, Blocks.log, 1);
		world.setBlockMetadataWithNotify(i + 3, j + 43, k + 24, 1, 2);
		setBlock(world, i + 3, j + 43, k + 25, Blocks.log, 1);
		world.setBlockMetadataWithNotify(i + 3, j + 43, k + 25, 1, 2);
		setBlock(world, i + 3, j + 43, k + 26, Blocks.log, 1);
		world.setBlockMetadataWithNotify(i + 3, j + 43, k + 26, 1, 2);
		setBlock(world, i + 3, j + 43, k + 27, Blocks.log, 1);
		world.setBlockMetadataWithNotify(i + 3, j + 43, k + 27, 1, 2);
		setBlock(world, i + 3, j + 43, k + 28, Blocks.log, 1);
		world.setBlockMetadataWithNotify(i + 3, j + 43, k + 28, 1, 2);
		setBlock(world, i + 3, j + 43, k + 29, Blocks.planks, 5);
		world.setBlockMetadataWithNotify(i + 3, j + 43, k + 29, 5, 2);
		setBlock(world, i + 3, j + 43, k + 30, Blocks.planks, 5);
		world.setBlockMetadataWithNotify(i + 3, j + 43, k + 30, 5, 2);
		setBlock(world, i + 3, j + 43, k + 31, Blocks.planks, 5);
		world.setBlockMetadataWithNotify(i + 3, j + 43, k + 31, 5, 2);
		setBlock(world, i + 3, j + 44, k + 17, Blocks.torch, 5);
		world.setBlockMetadataWithNotify(i + 3, j + 44, k + 17, 5, 2);
		setBlock(world, i + 3, j + 44, k + 21, Blocks.spruce_stairs, 1);
		world.setBlockMetadataWithNotify(i + 3, j + 44, k + 21, 1, 2);
		setBlock(world, i + 3, j + 46, k + 20, Blocks.torch, 1);
		world.setBlockMetadataWithNotify(i + 3, j + 46, k + 20, 1, 2);
		setBlock(world, i + 3, j + 47, k + 19, Blocks.spruce_stairs, 5);
		world.setBlockMetadataWithNotify(i + 3, j + 47, k + 19, 5, 2);
		setBlock(world, i + 3, j + 48, k + 18, Blocks.log, 1);
		world.setBlockMetadataWithNotify(i + 3, j + 48, k + 18, 1, 2);
		setBlock(world, i + 3, j + 48, k + 19, Blocks.log, 1);
		world.setBlockMetadataWithNotify(i + 3, j + 48, k + 19, 1, 2);
		setBlock(world, i + 3, j + 48, k + 20, Blocks.log, 1);
		world.setBlockMetadataWithNotify(i + 3, j + 48, k + 20, 1, 2);
		setBlock(world, i + 3, j + 48, k + 21, Blocks.log, 1);
		world.setBlockMetadataWithNotify(i + 3, j + 48, k + 21, 1, 2);
		setBlock(world, i + 3, j + 48, k + 22, Blocks.log, 1);
		world.setBlockMetadataWithNotify(i + 3, j + 48, k + 22, 1, 2);
		setBlock(world, i + 3, j + 48, k + 23, Blocks.log, 1);
		world.setBlockMetadataWithNotify(i + 3, j + 48, k + 23, 1, 2);
		setBlock(world, i + 3, j + 48, k + 24, Blocks.torch, 3);
		world.setBlockMetadataWithNotify(i + 3, j + 48, k + 24, 3, 2);
		setBlock(world, i + 3, j + 49, k + 19, Blocks.log, 1);
		world.setBlockMetadataWithNotify(i + 3, j + 49, k + 19, 1, 2);
		setBlock(world, i + 3, j + 49, k + 20, Blocks.log, 1);
		world.setBlockMetadataWithNotify(i + 3, j + 49, k + 20, 1, 2);
		setBlock(world, i + 3, j + 49, k + 21, Blocks.log, 1);
		world.setBlockMetadataWithNotify(i + 3, j + 49, k + 21, 1, 2);
		setBlock(world, i + 3, j + 49, k + 22, Blocks.log, 1);
		world.setBlockMetadataWithNotify(i + 3, j + 49, k + 22, 1, 2);
		setBlock(world, i + 3, j + 49, k + 23, Blocks.log, 1);
		world.setBlockMetadataWithNotify(i + 3, j + 49, k + 23, 1, 2);
		setBlock(world, i + 3, j + 49, k + 24, Blocks.log, 1);
		world.setBlockMetadataWithNotify(i + 3, j + 49, k + 24, 1, 2);
		setBlock(world, i + 3, j + 50, k + 21, Blocks.log, 1);
		world.setBlockMetadataWithNotify(i + 3, j + 50, k + 21, 1, 2);
		setBlock(world, i + 3, j + 50, k + 22, Blocks.log, 1);
		world.setBlockMetadataWithNotify(i + 3, j + 50, k + 22, 1, 2);
		setBlock(world, i + 3, j + 50, k + 23, Blocks.log, 1);
		world.setBlockMetadataWithNotify(i + 3, j + 50, k + 23, 1, 2);
		setBlock(world, i + 3, j + 50, k + 24, Blocks.log, 1);
		world.setBlockMetadataWithNotify(i + 3, j + 50, k + 24, 1, 2);
		setBlock(world, i + 3, j + 50, k + 25, Blocks.log, 1);
		world.setBlockMetadataWithNotify(i + 3, j + 50, k + 25, 1, 2);
		setBlock(world, i + 3, j + 50, k + 26, Blocks.torch, 3);
		world.setBlockMetadataWithNotify(i + 3, j + 50, k + 26, 3, 2);
		setBlock(world, i + 3, j + 50, k + 29, Blocks.torch, 2);
		world.setBlockMetadataWithNotify(i + 3, j + 50, k + 29, 2, 2);
		setBlock(world, i + 3, j + 51, k + 25, Blocks.log, 1);
		world.setBlockMetadataWithNotify(i + 3, j + 51, k + 25, 1, 2);
		setBlock(world, i + 3, j + 51, k + 26, Blocks.log, 1);
		world.setBlockMetadataWithNotify(i + 3, j + 51, k + 26, 1, 2);
		setBlock(world, i + 3, j + 51, k + 27, Blocks.log, 1);
		world.setBlockMetadataWithNotify(i + 3, j + 51, k + 27, 1, 2);
		setBlock(world, i + 3, j + 51, k + 28, Blocks.log, 1);
		world.setBlockMetadataWithNotify(i + 3, j + 51, k + 28, 1, 2);
		setBlock(world, i + 3, j + 51, k + 29, Blocks.log, 1);
		world.setBlockMetadataWithNotify(i + 3, j + 51, k + 29, 1, 2);
		setBlock(world, i + 3, j + 51, k + 30, Blocks.log, 1);
		world.setBlockMetadataWithNotify(i + 3, j + 51, k + 30, 1, 2);
		setBlock(world, i + 3, j + 51, k + 31, Blocks.log, 1);
		world.setBlockMetadataWithNotify(i + 3, j + 51, k + 31, 1, 2);
		setBlock(world, i + 4, j + 25, k + 29, Blocks.log, 3);
		world.setBlockMetadataWithNotify(i + 4, j + 25, k + 29, 3, 2);
		setBlock(world, i + 4, j + 26, k + 26, Blocks.leaves, 7);
		world.setBlockMetadataWithNotify(i + 4, j + 26, k + 26, 7, 2);
		setBlock(world, i + 4, j + 26, k + 27, Blocks.leaves, 7);
		world.setBlockMetadataWithNotify(i + 4, j + 26, k + 27, 7, 2);
		setBlock(world, i + 4, j + 26, k + 28, Blocks.leaves, 7);
		world.setBlockMetadataWithNotify(i + 4, j + 26, k + 28, 7, 2);
		setBlock(world, i + 4, j + 26, k + 29, Blocks.leaves, 7);
		world.setBlockMetadataWithNotify(i + 4, j + 26, k + 29, 7, 2);
		setBlock(world, i + 4, j + 26, k + 30, Blocks.leaves, 15);
		world.setBlockMetadataWithNotify(i + 4, j + 26, k + 30, 15, 2);
		setBlock(world, i + 4, j + 27, k + 27, Blocks.leaves, 15);
		world.setBlockMetadataWithNotify(i + 4, j + 27, k + 27, 15, 2);
		setBlock(world, i + 4, j + 27, k + 28, Blocks.leaves, 15);
		world.setBlockMetadataWithNotify(i + 4, j + 27, k + 28, 15, 2);
		setBlock(world, i + 4, j + 27, k + 29, Blocks.leaves, 7);
		world.setBlockMetadataWithNotify(i + 4, j + 27, k + 29, 7, 2);
		setBlock(world, i + 4, j + 27, k + 31, Blocks.log, 1);
		world.setBlockMetadataWithNotify(i + 4, j + 27, k + 31, 1, 2);
		setBlock(world, i + 4, j + 28, k + 28, Blocks.leaves, 15);
		world.setBlockMetadataWithNotify(i + 4, j + 28, k + 28, 15, 2);
		setBlock(world, i + 4, j + 31, k + 27, Blocks.log, 1);
		world.setBlockMetadataWithNotify(i + 4, j + 31, k + 27, 1, 2);
		setBlock(world, i + 4, j + 31, k + 28, Blocks.log, 1);
		world.setBlockMetadataWithNotify(i + 4, j + 31, k + 28, 1, 2);
		setBlock(world, i + 4, j + 31, k + 29, Blocks.log, 1);
		world.setBlockMetadataWithNotify(i + 4, j + 31, k + 29, 1, 2);
		setBlock(world, i + 4, j + 31, k + 30, Blocks.log, 1);
		world.setBlockMetadataWithNotify(i + 4, j + 31, k + 30, 1, 2);
		setBlock(world, i + 4, j + 31, k + 31, Blocks.log, 1);
		world.setBlockMetadataWithNotify(i + 4, j + 31, k + 31, 1, 2);
		setBlock(world, i + 4, j + 32, k + 21, Blocks.leaves, 7);
		world.setBlockMetadataWithNotify(i + 4, j + 32, k + 21, 7, 2);
		setBlock(world, i + 4, j + 32, k + 22, Blocks.leaves, 7);
		world.setBlockMetadataWithNotify(i + 4, j + 32, k + 22, 7, 2);
		setBlock(world, i + 4, j + 32, k + 23, Blocks.log, 3);
		world.setBlockMetadataWithNotify(i + 4, j + 32, k + 23, 3, 2);
		setBlock(world, i + 4, j + 32, k + 24, Blocks.leaves, 7);
		world.setBlockMetadataWithNotify(i + 4, j + 32, k + 24, 7, 2);
		setBlock(world, i + 4, j + 32, k + 25, Blocks.leaves, 7);
		world.setBlockMetadataWithNotify(i + 4, j + 32, k + 25, 7, 2);
		setBlock(world, i + 4, j + 32, k + 29, Blocks.log, 1);
		world.setBlockMetadataWithNotify(i + 4, j + 32, k + 29, 1, 2);
		setBlock(world, i + 4, j + 32, k + 30, Blocks.log, 1);
		world.setBlockMetadataWithNotify(i + 4, j + 32, k + 30, 1, 2);
		setBlock(world, i + 4, j + 32, k + 31, Blocks.log, 1);
		world.setBlockMetadataWithNotify(i + 4, j + 32, k + 31, 1, 2);
		setBlock(world, i + 4, j + 33, k + 12, Blocks.vine, 13);
		world.setBlockMetadataWithNotify(i + 4, j + 33, k + 12, 13, 2);
		setBlock(world, i + 4, j + 33, k + 21, Blocks.leaves, 7);
		world.setBlockMetadataWithNotify(i + 4, j + 33, k + 21, 7, 2);
		setBlock(world, i + 4, j + 33, k + 22, Blocks.leaves, 7);
		world.setBlockMetadataWithNotify(i + 4, j + 33, k + 22, 7, 2);
		setBlock(world, i + 4, j + 33, k + 23, Blocks.leaves, 7);
		world.setBlockMetadataWithNotify(i + 4, j + 33, k + 23, 7, 2);
		setBlock(world, i + 4, j + 33, k + 24, Blocks.leaves, 7);
		world.setBlockMetadataWithNotify(i + 4, j + 33, k + 24, 7, 2);
		setBlock(world, i + 4, j + 33, k + 25, Blocks.leaves, 7);
		world.setBlockMetadataWithNotify(i + 4, j + 33, k + 25, 7, 2);
		setBlock(world, i + 4, j + 33, k + 29, Blocks.log, 1);
		world.setBlockMetadataWithNotify(i + 4, j + 33, k + 29, 1, 2);
		setBlock(world, i + 4, j + 33, k + 30, Blocks.log, 1);
		world.setBlockMetadataWithNotify(i + 4, j + 33, k + 30, 1, 2);
		setBlock(world, i + 4, j + 33, k + 31, Blocks.log, 1);
		world.setBlockMetadataWithNotify(i + 4, j + 33, k + 31, 1, 2);
		setBlock(world, i + 4, j + 34, k + 11, Blocks.vine, 15);
		world.setBlockMetadataWithNotify(i + 4, j + 34, k + 11, 15, 2);
		setBlock(world, i + 4, j + 34, k + 12, Blocks.vine, 15);
		world.setBlockMetadataWithNotify(i + 4, j + 34, k + 12, 15, 2);
		setBlock(world, i + 4, j + 34, k + 22, Blocks.leaves, 7);
		world.setBlockMetadataWithNotify(i + 4, j + 34, k + 22, 7, 2);
		setBlock(world, i + 4, j + 34, k + 23, Blocks.leaves, 7);
		world.setBlockMetadataWithNotify(i + 4, j + 34, k + 23, 7, 2);
		setBlock(world, i + 4, j + 34, k + 24, Blocks.leaves, 7);
		world.setBlockMetadataWithNotify(i + 4, j + 34, k + 24, 7, 2);
		setBlock(world, i + 4, j + 34, k + 30, Blocks.log, 1);
		world.setBlockMetadataWithNotify(i + 4, j + 34, k + 30, 1, 2);
		setBlock(world, i + 4, j + 34, k + 31, Blocks.log, 1);
		world.setBlockMetadataWithNotify(i + 4, j + 34, k + 31, 1, 2);
		setBlock(world, i + 4, j + 35, k + 11, Blocks.vine, 15);
		world.setBlockMetadataWithNotify(i + 4, j + 35, k + 11, 15, 2);
		setBlock(world, i + 4, j + 35, k + 12, Blocks.vine, 15);
		world.setBlockMetadataWithNotify(i + 4, j + 35, k + 12, 15, 2);
		setBlock(world, i + 4, j + 35, k + 23, Blocks.leaves, 7);
		world.setBlockMetadataWithNotify(i + 4, j + 35, k + 23, 7, 2);
		setBlock(world, i + 4, j + 36, k + 11, Blocks.vine, 15);
		world.setBlockMetadataWithNotify(i + 4, j + 36, k + 11, 15, 2);
		setBlock(world, i + 4, j + 36, k + 12, Blocks.vine, 15);
		world.setBlockMetadataWithNotify(i + 4, j + 36, k + 12, 15, 2);
		setBlock(world, i + 4, j + 37, k + 11, Blocks.vine, 15);
		world.setBlockMetadataWithNotify(i + 4, j + 37, k + 11, 15, 2);
		setBlock(world, i + 4, j + 37, k + 12, Blocks.vine, 15);
		world.setBlockMetadataWithNotify(i + 4, j + 37, k + 12, 15, 2);
		setBlock(world, i + 4, j + 38, k + 11, Blocks.vine, 15);
		world.setBlockMetadataWithNotify(i + 4, j + 38, k + 11, 15, 2);
		setBlock(world, i + 4, j + 38, k + 12, Blocks.vine, 15);
		world.setBlockMetadataWithNotify(i + 4, j + 38, k + 12, 15, 2);
		setBlock(world, i + 4, j + 38, k + 30, Blocks.leaves, 7);
		world.setBlockMetadataWithNotify(i + 4, j + 38, k + 30, 7, 2);
		setBlock(world, i + 4, j + 38, k + 31, Blocks.leaves, 7);
		world.setBlockMetadataWithNotify(i + 4, j + 38, k + 31, 7, 2);
		setBlock(world, i + 4, j + 39, k + 11, Blocks.vine, 15);
		world.setBlockMetadataWithNotify(i + 4, j + 39, k + 11, 15, 2);
		setBlock(world, i + 4, j + 39, k + 12, Blocks.vine, 15);
		world.setBlockMetadataWithNotify(i + 4, j + 39, k + 12, 15, 2);
		setBlock(world, i + 4, j + 39, k + 30, Blocks.leaves, 15);
		world.setBlockMetadataWithNotify(i + 4, j + 39, k + 30, 15, 2);
		setBlock(world, i + 4, j + 39, k + 31, Blocks.log, 1);
		world.setBlockMetadataWithNotify(i + 4, j + 39, k + 31, 1, 2);
		setBlock(world, i + 4, j + 40, k + 11, Blocks.vine, 15);
		world.setBlockMetadataWithNotify(i + 4, j + 40, k + 11, 15, 2);
		setBlock(world, i + 4, j + 40, k + 12, Blocks.vine, 15);
		world.setBlockMetadataWithNotify(i + 4, j + 40, k + 12, 15, 2);
		setBlock(world, i + 4, j + 40, k + 30, Blocks.log, 1);
		world.setBlockMetadataWithNotify(i + 4, j + 40, k + 30, 1, 2);
		setBlock(world, i + 4, j + 40, k + 31, Blocks.leaves, 15);
		world.setBlockMetadataWithNotify(i + 4, j + 40, k + 31, 15, 2);
		setBlock(world, i + 4, j + 41, k + 11, Blocks.vine, 15);
		world.setBlockMetadataWithNotify(i + 4, j + 41, k + 11, 15, 2);
		setBlock(world, i + 4, j + 41, k + 12, Blocks.vine, 15);
		world.setBlockMetadataWithNotify(i + 4, j + 41, k + 12, 15, 2);
		setBlock(world, i + 4, j + 41, k + 29, Blocks.leaves, 15);
		world.setBlockMetadataWithNotify(i + 4, j + 41, k + 29, 15, 2);
		setBlock(world, i + 4, j + 41, k + 30, Blocks.leaves, 15);
		world.setBlockMetadataWithNotify(i + 4, j + 41, k + 30, 15, 2);
		setBlock(world, i + 4, j + 41, k + 31, Blocks.log, 1);
		world.setBlockMetadataWithNotify(i + 4, j + 41, k + 31, 1, 2);
		setBlock(world, i + 4, j + 42, k + 7, Blocks.planks, 5);
		world.setBlockMetadataWithNotify(i + 4, j + 42, k + 7, 5, 2);
		setBlock(world, i + 4, j + 42, k + 8, Blocks.planks, 5);
		world.setBlockMetadataWithNotify(i + 4, j + 42, k + 8, 5, 2);
		setBlock(world, i + 4, j + 42, k + 9, Blocks.planks, 5);
		world.setBlockMetadataWithNotify(i + 4, j + 42, k + 9, 5, 2);
		setBlock(world, i + 4, j + 42, k + 10, Blocks.planks, 5);
		world.setBlockMetadataWithNotify(i + 4, j + 42, k + 10, 5, 2);
		setBlock(world, i + 4, j + 42, k + 11, Blocks.planks, 5);
		world.setBlockMetadataWithNotify(i + 4, j + 42, k + 11, 5, 2);
		setBlock(world, i + 4, j + 42, k + 12, Blocks.planks, 5);
		world.setBlockMetadataWithNotify(i + 4, j + 42, k + 12, 5, 2);
		setBlock(world, i + 4, j + 42, k + 13, Blocks.planks, 5);
		world.setBlockMetadataWithNotify(i + 4, j + 42, k + 13, 5, 2);
		setBlock(world, i + 4, j + 42, k + 14, Blocks.planks, 5);
		world.setBlockMetadataWithNotify(i + 4, j + 42, k + 14, 5, 2);
		setBlock(world, i + 4, j + 42, k + 15, Blocks.planks, 5);
		world.setBlockMetadataWithNotify(i + 4, j + 42, k + 15, 5, 2);
		setBlock(world, i + 4, j + 42, k + 16, Blocks.planks, 5);
		world.setBlockMetadataWithNotify(i + 4, j + 42, k + 16, 5, 2);
		setBlock(world, i + 4, j + 42, k + 26, Blocks.log, 1);
		world.setBlockMetadataWithNotify(i + 4, j + 42, k + 26, 1, 2);
		setBlock(world, i + 4, j + 42, k + 27, Blocks.log, 1);
		world.setBlockMetadataWithNotify(i + 4, j + 42, k + 27, 1, 2);
		setBlock(world, i + 4, j + 42, k + 28, Blocks.log, 1);
		world.setBlockMetadataWithNotify(i + 4, j + 42, k + 28, 1, 2);
		setBlock(world, i + 4, j + 42, k + 30, Blocks.leaves, 15);
		world.setBlockMetadataWithNotify(i + 4, j + 42, k + 30, 15, 2);
		setBlock(world, i + 4, j + 42, k + 31, Blocks.leaves, 15);
		world.setBlockMetadataWithNotify(i + 4, j + 42, k + 31, 15, 2);
		setBlock(world, i + 4, j + 43, k + 15, Blocks.spruce_stairs, 2);
		world.setBlockMetadataWithNotify(i + 4, j + 43, k + 15, 2, 2);
		setBlock(world, i + 4, j + 43, k + 16, Blocks.planks, 5);
		world.setBlockMetadataWithNotify(i + 4, j + 43, k + 16, 5, 2);
		setBlock(world, i + 4, j + 43, k + 17, Blocks.planks, 5);
		world.setBlockMetadataWithNotify(i + 4, j + 43, k + 17, 5, 2);
		setBlock(world, i + 4, j + 43, k + 18, Blocks.planks, 5);
		world.setBlockMetadataWithNotify(i + 4, j + 43, k + 18, 5, 2);
		setBlock(world, i + 4, j + 43, k + 19, Blocks.log, 1);
		world.setBlockMetadataWithNotify(i + 4, j + 43, k + 19, 1, 2);
		setBlock(world, i + 4, j + 43, k + 20, Blocks.log, 1);
		world.setBlockMetadataWithNotify(i + 4, j + 43, k + 20, 1, 2);
		setBlock(world, i + 4, j + 43, k + 21, Blocks.log, 1);
		world.setBlockMetadataWithNotify(i + 4, j + 43, k + 21, 1, 2);
		setBlock(world, i + 4, j + 43, k + 22, Blocks.log, 1);
		world.setBlockMetadataWithNotify(i + 4, j + 43, k + 22, 1, 2);
		setBlock(world, i + 4, j + 43, k + 23, Blocks.log, 1);
		world.setBlockMetadataWithNotify(i + 4, j + 43, k + 23, 1, 2);
		setBlock(world, i + 4, j + 43, k + 24, Blocks.log, 1);
		world.setBlockMetadataWithNotify(i + 4, j + 43, k + 24, 1, 2);
		setBlock(world, i + 4, j + 43, k + 25, Blocks.log, 1);
		world.setBlockMetadataWithNotify(i + 4, j + 43, k + 25, 1, 2);
		setBlock(world, i + 4, j + 43, k + 26, Blocks.log, 1);
		world.setBlockMetadataWithNotify(i + 4, j + 43, k + 26, 1, 2);
		setBlock(world, i + 4, j + 43, k + 27, Blocks.log, 1);
		world.setBlockMetadataWithNotify(i + 4, j + 43, k + 27, 1, 2);
		setBlock(world, i + 4, j + 43, k + 28, Blocks.planks, 5);
		world.setBlockMetadataWithNotify(i + 4, j + 43, k + 28, 5, 2);
		setBlock(world, i + 4, j + 43, k + 29, Blocks.planks, 5);
		world.setBlockMetadataWithNotify(i + 4, j + 43, k + 29, 5, 2);
		setBlock(world, i + 4, j + 43, k + 30, Blocks.log, 1);
		world.setBlockMetadataWithNotify(i + 4, j + 43, k + 30, 1, 2);
		setBlock(world, i + 4, j + 43, k + 31, Blocks.log, 1);
		world.setBlockMetadataWithNotify(i + 4, j + 43, k + 31, 1, 2);
		setBlock(world, i + 4, j + 44, k + 29, Blocks.chest, 4);
		LootGenUtils.fillLootChest(world.provider.dimensionId, world.rand, (TileEntityChest)world.getTileEntity(i + 4, j + 44, k + 29));
		world.setBlockMetadataWithNotify(i + 4, j + 44, k + 29, 4, 2);
		setBlock(world, i + 4, j + 46, k + 31, Blocks.torch, 2);
		world.setBlockMetadataWithNotify(i + 4, j + 46, k + 31, 2, 2);
		setBlock(world, i + 4, j + 47, k + 30, Blocks.torch, 2);
		world.setBlockMetadataWithNotify(i + 4, j + 47, k + 30, 2, 2);
		setBlock(world, i + 4, j + 48, k + 17, Blocks.log, 1);
		world.setBlockMetadataWithNotify(i + 4, j + 48, k + 17, 1, 2);
		setBlock(world, i + 4, j + 48, k + 18, Blocks.log, 1);
		world.setBlockMetadataWithNotify(i + 4, j + 48, k + 18, 1, 2);
		setBlock(world, i + 4, j + 48, k + 19, Blocks.log, 1);
		world.setBlockMetadataWithNotify(i + 4, j + 48, k + 19, 1, 2);
		setBlock(world, i + 4, j + 48, k + 20, Blocks.log, 1);
		world.setBlockMetadataWithNotify(i + 4, j + 48, k + 20, 1, 2);
		setBlock(world, i + 4, j + 48, k + 21, Blocks.log, 1);
		world.setBlockMetadataWithNotify(i + 4, j + 48, k + 21, 1, 2);
		setBlock(world, i + 4, j + 48, k + 22, Blocks.log, 1);
		world.setBlockMetadataWithNotify(i + 4, j + 48, k + 22, 1, 2);
		setBlock(world, i + 4, j + 49, k + 18, Blocks.log, 1);
		world.setBlockMetadataWithNotify(i + 4, j + 49, k + 18, 1, 2);
		setBlock(world, i + 4, j + 49, k + 19, Blocks.log, 1);
		world.setBlockMetadataWithNotify(i + 4, j + 49, k + 19, 1, 2);
		setBlock(world, i + 4, j + 49, k + 20, Blocks.log, 1);
		world.setBlockMetadataWithNotify(i + 4, j + 49, k + 20, 1, 2);
		setBlock(world, i + 4, j + 49, k + 21, Blocks.log, 1);
		world.setBlockMetadataWithNotify(i + 4, j + 49, k + 21, 1, 2);
		setBlock(world, i + 4, j + 49, k + 22, Blocks.log, 1);
		world.setBlockMetadataWithNotify(i + 4, j + 49, k + 22, 1, 2);
		setBlock(world, i + 4, j + 49, k + 23, Blocks.log, 1);
		world.setBlockMetadataWithNotify(i + 4, j + 49, k + 23, 1, 2);
		setBlock(world, i + 4, j + 50, k + 20, Blocks.log, 1);
		world.setBlockMetadataWithNotify(i + 4, j + 50, k + 20, 1, 2);
		setBlock(world, i + 4, j + 50, k + 21, Blocks.log, 1);
		world.setBlockMetadataWithNotify(i + 4, j + 50, k + 21, 1, 2);
		setBlock(world, i + 4, j + 50, k + 22, Blocks.log, 1);
		world.setBlockMetadataWithNotify(i + 4, j + 50, k + 22, 1, 2);
		setBlock(world, i + 4, j + 50, k + 23, Blocks.log, 1);
		world.setBlockMetadataWithNotify(i + 4, j + 50, k + 23, 1, 2);
		setBlock(world, i + 4, j + 50, k + 24, Blocks.log, 1);
		world.setBlockMetadataWithNotify(i + 4, j + 50, k + 24, 1, 2);
		setBlock(world, i + 4, j + 50, k + 28, Blocks.torch, 4);
		world.setBlockMetadataWithNotify(i + 4, j + 50, k + 28, 4, 2);
		setBlock(world, i + 4, j + 50, k + 29, Blocks.log, 1);
		world.setBlockMetadataWithNotify(i + 4, j + 50, k + 29, 1, 2);
		setBlock(world, i + 4, j + 50, k + 30, Blocks.log, 1);
		world.setBlockMetadataWithNotify(i + 4, j + 50, k + 30, 1, 2);
		setBlock(world, i + 4, j + 50, k + 31, Blocks.log, 1);
		world.setBlockMetadataWithNotify(i + 4, j + 50, k + 31, 1, 2);
		setBlock(world, i + 4, j + 51, k + 25, Blocks.log, 1);
		world.setBlockMetadataWithNotify(i + 4, j + 51, k + 25, 1, 2);
		setBlock(world, i + 4, j + 51, k + 26, Blocks.log, 1);
		world.setBlockMetadataWithNotify(i + 4, j + 51, k + 26, 1, 2);
		setBlock(world, i + 4, j + 51, k + 27, Blocks.log, 1);
		world.setBlockMetadataWithNotify(i + 4, j + 51, k + 27, 1, 2);
		setBlock(world, i + 4, j + 51, k + 28, Blocks.log, 1);
		world.setBlockMetadataWithNotify(i + 4, j + 51, k + 28, 1, 2);
		setBlock(world, i + 4, j + 51, k + 29, Blocks.log, 1);
		world.setBlockMetadataWithNotify(i + 4, j + 51, k + 29, 1, 2);
		setBlock(world, i + 4, j + 51, k + 30, Blocks.log, 1);
		world.setBlockMetadataWithNotify(i + 4, j + 51, k + 30, 1, 2);
		setBlock(world, i + 4, j + 51, k + 31, Blocks.log, 1);
		world.setBlockMetadataWithNotify(i + 4, j + 51, k + 31, 1, 2);
		setBlock(world, i + 5, j + 26, k + 26, Blocks.leaves, 15);
		world.setBlockMetadataWithNotify(i + 5, j + 26, k + 26, 15, 2);
		setBlock(world, i + 5, j + 26, k + 27, Blocks.leaves, 15);
		world.setBlockMetadataWithNotify(i + 5, j + 26, k + 27, 15, 2);
		setBlock(world, i + 5, j + 26, k + 28, Blocks.log, 3);
		world.setBlockMetadataWithNotify(i + 5, j + 26, k + 28, 3, 2);
		setBlock(world, i + 5, j + 26, k + 29, Blocks.leaves, 7);
		world.setBlockMetadataWithNotify(i + 5, j + 26, k + 29, 7, 2);
		setBlock(world, i + 5, j + 26, k + 30, Blocks.leaves, 15);
		world.setBlockMetadataWithNotify(i + 5, j + 26, k + 30, 15, 2);
		setBlock(world, i + 5, j + 27, k + 26, Blocks.leaves, 15);
		world.setBlockMetadataWithNotify(i + 5, j + 27, k + 26, 15, 2);
		setBlock(world, i + 5, j + 27, k + 27, Blocks.leaves, 15);
		world.setBlockMetadataWithNotify(i + 5, j + 27, k + 27, 15, 2);
		setBlock(world, i + 5, j + 27, k + 28, Blocks.leaves, 15);
		world.setBlockMetadataWithNotify(i + 5, j + 27, k + 28, 15, 2);
		setBlock(world, i + 5, j + 27, k + 29, Blocks.leaves, 15);
		world.setBlockMetadataWithNotify(i + 5, j + 27, k + 29, 15, 2);
		setBlock(world, i + 5, j + 27, k + 30, Blocks.log, 1);
		world.setBlockMetadataWithNotify(i + 5, j + 27, k + 30, 1, 2);
		setBlock(world, i + 5, j + 27, k + 31, Blocks.log, 1);
		world.setBlockMetadataWithNotify(i + 5, j + 27, k + 31, 1, 2);
		setBlock(world, i + 5, j + 28, k + 28, Blocks.leaves, 15);
		world.setBlockMetadataWithNotify(i + 5, j + 28, k + 28, 15, 2);
		setBlock(world, i + 5, j + 28, k + 29, Blocks.leaves, 15);
		world.setBlockMetadataWithNotify(i + 5, j + 28, k + 29, 15, 2);
		setBlock(world, i + 5, j + 31, k + 27, Blocks.log, 1);
		world.setBlockMetadataWithNotify(i + 5, j + 31, k + 27, 1, 2);
		setBlock(world, i + 5, j + 31, k + 28, Blocks.log, 1);
		world.setBlockMetadataWithNotify(i + 5, j + 31, k + 28, 1, 2);
		setBlock(world, i + 5, j + 31, k + 29, Blocks.log, 1);
		world.setBlockMetadataWithNotify(i + 5, j + 31, k + 29, 1, 2);
		setBlock(world, i + 5, j + 31, k + 30, Blocks.log, 1);
		world.setBlockMetadataWithNotify(i + 5, j + 31, k + 30, 1, 2);
		setBlock(world, i + 5, j + 32, k + 21, Blocks.leaves, 7);
		world.setBlockMetadataWithNotify(i + 5, j + 32, k + 21, 7, 2);
		setBlock(world, i + 5, j + 32, k + 22, Blocks.leaves, 7);
		world.setBlockMetadataWithNotify(i + 5, j + 32, k + 22, 7, 2);
		setBlock(world, i + 5, j + 32, k + 23, Blocks.leaves, 7);
		world.setBlockMetadataWithNotify(i + 5, j + 32, k + 23, 7, 2);
		setBlock(world, i + 5, j + 32, k + 24, Blocks.leaves, 7);
		world.setBlockMetadataWithNotify(i + 5, j + 32, k + 24, 7, 2);
		setBlock(world, i + 5, j + 32, k + 25, Blocks.leaves, 7);
		world.setBlockMetadataWithNotify(i + 5, j + 32, k + 25, 7, 2);
		setBlock(world, i + 5, j + 32, k + 28, Blocks.log, 1);
		world.setBlockMetadataWithNotify(i + 5, j + 32, k + 28, 1, 2);
		setBlock(world, i + 5, j + 32, k + 29, Blocks.log, 1);
		world.setBlockMetadataWithNotify(i + 5, j + 32, k + 29, 1, 2);
		setBlock(world, i + 5, j + 32, k + 30, Blocks.log, 1);
		world.setBlockMetadataWithNotify(i + 5, j + 32, k + 30, 1, 2);
		setBlock(world, i + 5, j + 32, k + 31, Blocks.log, 1);
		world.setBlockMetadataWithNotify(i + 5, j + 32, k + 31, 1, 2);
		setBlock(world, i + 5, j + 33, k + 22, Blocks.leaves, 7);
		world.setBlockMetadataWithNotify(i + 5, j + 33, k + 22, 7, 2);
		setBlock(world, i + 5, j + 33, k + 23, Blocks.leaves, 7);
		world.setBlockMetadataWithNotify(i + 5, j + 33, k + 23, 7, 2);
		setBlock(world, i + 5, j + 33, k + 24, Blocks.leaves, 7);
		world.setBlockMetadataWithNotify(i + 5, j + 33, k + 24, 7, 2);
		setBlock(world, i + 5, j + 33, k + 28, Blocks.log, 1);
		world.setBlockMetadataWithNotify(i + 5, j + 33, k + 28, 1, 2);
		setBlock(world, i + 5, j + 33, k + 29, Blocks.log, 1);
		world.setBlockMetadataWithNotify(i + 5, j + 33, k + 29, 1, 2);
		setBlock(world, i + 5, j + 33, k + 30, Blocks.log, 1);
		world.setBlockMetadataWithNotify(i + 5, j + 33, k + 30, 1, 2);
		setBlock(world, i + 5, j + 33, k + 31, Blocks.log, 1);
		world.setBlockMetadataWithNotify(i + 5, j + 33, k + 31, 1, 2);
		setBlock(world, i + 5, j + 34, k + 23, Blocks.leaves, 7);
		world.setBlockMetadataWithNotify(i + 5, j + 34, k + 23, 7, 2);
		setBlock(world, i + 5, j + 34, k + 29, Blocks.log, 1);
		world.setBlockMetadataWithNotify(i + 5, j + 34, k + 29, 1, 2);
		setBlock(world, i + 5, j + 34, k + 30, Blocks.log, 1);
		world.setBlockMetadataWithNotify(i + 5, j + 34, k + 30, 1, 2);
		setBlock(world, i + 5, j + 34, k + 31, Blocks.log, 1);
		world.setBlockMetadataWithNotify(i + 5, j + 34, k + 31, 1, 2);
		setBlock(world, i + 5, j + 35, k + 15, Blocks.vine, 8);
		world.setBlockMetadataWithNotify(i + 5, j + 35, k + 15, 8, 2);
		setBlock(world, i + 5, j + 35, k + 31, Blocks.log, 1);
		world.setBlockMetadataWithNotify(i + 5, j + 35, k + 31, 1, 2);
		setBlock(world, i + 5, j + 36, k + 15, Blocks.vine, 15);
		world.setBlockMetadataWithNotify(i + 5, j + 36, k + 15, 15, 2);
		setBlock(world, i + 5, j + 37, k + 14, Blocks.vine, 15);
		world.setBlockMetadataWithNotify(i + 5, j + 37, k + 14, 15, 2);
		setBlock(world, i + 5, j + 37, k + 15, Blocks.vine, 15);
		world.setBlockMetadataWithNotify(i + 5, j + 37, k + 15, 15, 2);
		setBlock(world, i + 5, j + 38, k + 14, Blocks.vine, 15);
		world.setBlockMetadataWithNotify(i + 5, j + 38, k + 14, 15, 2);
		setBlock(world, i + 5, j + 38, k + 15, Blocks.vine, 15);
		world.setBlockMetadataWithNotify(i + 5, j + 38, k + 15, 15, 2);
		setBlock(world, i + 5, j + 38, k + 30, Blocks.leaves, 7);
		world.setBlockMetadataWithNotify(i + 5, j + 38, k + 30, 7, 2);
		setBlock(world, i + 5, j + 38, k + 31, Blocks.leaves, 7);
		world.setBlockMetadataWithNotify(i + 5, j + 38, k + 31, 7, 2);
		setBlock(world, i + 5, j + 39, k + 14, Blocks.vine, 15);
		world.setBlockMetadataWithNotify(i + 5, j + 39, k + 14, 15, 2);
		setBlock(world, i + 5, j + 39, k + 15, Blocks.vine, 15);
		world.setBlockMetadataWithNotify(i + 5, j + 39, k + 15, 15, 2);
		setBlock(world, i + 5, j + 39, k + 30, Blocks.log, 1);
		world.setBlockMetadataWithNotify(i + 5, j + 39, k + 30, 1, 2);
		setBlock(world, i + 5, j + 39, k + 31, Blocks.log, 1);
		world.setBlockMetadataWithNotify(i + 5, j + 39, k + 31, 1, 2);
		setBlock(world, i + 5, j + 40, k + 14, Blocks.vine, 15);
		world.setBlockMetadataWithNotify(i + 5, j + 40, k + 14, 15, 2);
		setBlock(world, i + 5, j + 40, k + 15, Blocks.vine, 15);
		world.setBlockMetadataWithNotify(i + 5, j + 40, k + 15, 15, 2);
		setBlock(world, i + 5, j + 40, k + 30, Blocks.log, 1);
		world.setBlockMetadataWithNotify(i + 5, j + 40, k + 30, 1, 2);
		setBlock(world, i + 5, j + 40, k + 31, Blocks.log, 1);
		world.setBlockMetadataWithNotify(i + 5, j + 40, k + 31, 1, 2);
		setBlock(world, i + 5, j + 41, k + 29, Blocks.leaves, 15);
		world.setBlockMetadataWithNotify(i + 5, j + 41, k + 29, 15, 2);
		setBlock(world, i + 5, j + 41, k + 30, Blocks.log, 1);
		world.setBlockMetadataWithNotify(i + 5, j + 41, k + 30, 1, 2);
		setBlock(world, i + 5, j + 41, k + 31, Blocks.log, 1);
		world.setBlockMetadataWithNotify(i + 5, j + 41, k + 31, 1, 2);
		setBlock(world, i + 5, j + 42, k + 8, Blocks.planks, 5);
		world.setBlockMetadataWithNotify(i + 5, j + 42, k + 8, 5, 2);
		setBlock(world, i + 5, j + 42, k + 9, Blocks.planks, 5);
		world.setBlockMetadataWithNotify(i + 5, j + 42, k + 9, 5, 2);
		setBlock(world, i + 5, j + 42, k + 10, Blocks.planks, 5);
		world.setBlockMetadataWithNotify(i + 5, j + 42, k + 10, 5, 2);
		setBlock(world, i + 5, j + 42, k + 11, Blocks.planks, 5);
		world.setBlockMetadataWithNotify(i + 5, j + 42, k + 11, 5, 2);
		setBlock(world, i + 5, j + 42, k + 12, Blocks.planks, 5);
		world.setBlockMetadataWithNotify(i + 5, j + 42, k + 12, 5, 2);
		setBlock(world, i + 5, j + 42, k + 13, Blocks.planks, 5);
		world.setBlockMetadataWithNotify(i + 5, j + 42, k + 13, 5, 2);
		setBlock(world, i + 5, j + 42, k + 14, Blocks.planks, 5);
		world.setBlockMetadataWithNotify(i + 5, j + 42, k + 14, 5, 2);
		setBlock(world, i + 5, j + 42, k + 15, Blocks.planks, 5);
		world.setBlockMetadataWithNotify(i + 5, j + 42, k + 15, 5, 2);
		setBlock(world, i + 5, j + 42, k + 16, Blocks.planks, 5);
		world.setBlockMetadataWithNotify(i + 5, j + 42, k + 16, 5, 2);
		setBlock(world, i + 5, j + 42, k + 26, Blocks.log, 1);
		world.setBlockMetadataWithNotify(i + 5, j + 42, k + 26, 1, 2);
		setBlock(world, i + 5, j + 42, k + 27, Blocks.log, 1);
		world.setBlockMetadataWithNotify(i + 5, j + 42, k + 27, 1, 2);
		setBlock(world, i + 5, j + 42, k + 28, Blocks.log, 1);
		world.setBlockMetadataWithNotify(i + 5, j + 42, k + 28, 1, 2);
		setBlock(world, i + 5, j + 42, k + 29, Blocks.leaves, 15);
		world.setBlockMetadataWithNotify(i + 5, j + 42, k + 29, 15, 2);
		setBlock(world, i + 5, j + 42, k + 30, Blocks.leaves, 15);
		world.setBlockMetadataWithNotify(i + 5, j + 42, k + 30, 15, 2);
		setBlock(world, i + 5, j + 42, k + 31, Blocks.leaves, 15);
		world.setBlockMetadataWithNotify(i + 5, j + 42, k + 31, 15, 2);
		setBlock(world, i + 5, j + 43, k + 15, Blocks.spruce_stairs, 2);
		world.setBlockMetadataWithNotify(i + 5, j + 43, k + 15, 2, 2);
		setBlock(world, i + 5, j + 43, k + 16, Blocks.planks, 5);
		world.setBlockMetadataWithNotify(i + 5, j + 43, k + 16, 5, 2);
		setBlock(world, i + 5, j + 43, k + 17, Blocks.planks, 5);
		world.setBlockMetadataWithNotify(i + 5, j + 43, k + 17, 5, 2);
		setBlock(world, i + 5, j + 43, k + 18, Blocks.planks, 5);
		world.setBlockMetadataWithNotify(i + 5, j + 43, k + 18, 5, 2);
		setBlock(world, i + 5, j + 43, k + 19, Blocks.log, 1);
		world.setBlockMetadataWithNotify(i + 5, j + 43, k + 19, 1, 2);
		setBlock(world, i + 5, j + 43, k + 20, Blocks.log, 1);
		world.setBlockMetadataWithNotify(i + 5, j + 43, k + 20, 1, 2);
		setBlock(world, i + 5, j + 43, k + 21, Blocks.planks, 5);
		world.setBlockMetadataWithNotify(i + 5, j + 43, k + 21, 5, 2);
		setBlock(world, i + 5, j + 43, k + 22, Blocks.planks, 5);
		world.setBlockMetadataWithNotify(i + 5, j + 43, k + 22, 5, 2);
		setBlock(world, i + 5, j + 43, k + 23, Blocks.planks, 5);
		world.setBlockMetadataWithNotify(i + 5, j + 43, k + 23, 5, 2);
		setBlock(world, i + 5, j + 43, k + 24, Blocks.planks, 5);
		world.setBlockMetadataWithNotify(i + 5, j + 43, k + 24, 5, 2);
		setBlock(world, i + 5, j + 43, k + 25, Blocks.planks, 5);
		world.setBlockMetadataWithNotify(i + 5, j + 43, k + 25, 5, 2);
		setBlock(world, i + 5, j + 43, k + 26, Blocks.log, 1);
		world.setBlockMetadataWithNotify(i + 5, j + 43, k + 26, 1, 2);
		setBlock(world, i + 5, j + 43, k + 27, Blocks.log, 1);
		world.setBlockMetadataWithNotify(i + 5, j + 43, k + 27, 1, 2);
		setBlock(world, i + 5, j + 43, k + 28, Blocks.planks, 5);
		world.setBlockMetadataWithNotify(i + 5, j + 43, k + 28, 5, 2);
		setBlock(world, i + 5, j + 43, k + 29, Blocks.log, 1);
		world.setBlockMetadataWithNotify(i + 5, j + 43, k + 29, 1, 2);
		setBlock(world, i + 5, j + 43, k + 30, Blocks.log, 1);
		world.setBlockMetadataWithNotify(i + 5, j + 43, k + 30, 1, 2);
		setBlock(world, i + 5, j + 43, k + 31, Blocks.log, 1);
		world.setBlockMetadataWithNotify(i + 5, j + 43, k + 31, 1, 2);
		setBlock(world, i + 5, j + 44, k + 29, Blocks.spruce_stairs, 2);
		world.setBlockMetadataWithNotify(i + 5, j + 44, k + 29, 2, 2);
		setBlock(world, i + 5, j + 44, k + 30, Blocks.log, 1);
		world.setBlockMetadataWithNotify(i + 5, j + 44, k + 30, 1, 2);
		setBlock(world, i + 5, j + 44, k + 31, Blocks.log, 1);
		world.setBlockMetadataWithNotify(i + 5, j + 44, k + 31, 1, 2);
		setBlock(world, i + 5, j + 45, k + 30, Blocks.log, 1);
		world.setBlockMetadataWithNotify(i + 5, j + 45, k + 30, 1, 2);
		setBlock(world, i + 5, j + 45, k + 31, Blocks.log, 1);
		world.setBlockMetadataWithNotify(i + 5, j + 45, k + 31, 1, 2);
		setBlock(world, i + 5, j + 46, k + 29, Blocks.torch, 4);
		world.setBlockMetadataWithNotify(i + 5, j + 46, k + 29, 4, 2);
		setBlock(world, i + 5, j + 46, k + 30, Blocks.log, 1);
		world.setBlockMetadataWithNotify(i + 5, j + 46, k + 30, 1, 2);
		setBlock(world, i + 5, j + 46, k + 31, Blocks.log, 1);
		world.setBlockMetadataWithNotify(i + 5, j + 46, k + 31, 1, 2);
		setBlock(world, i + 5, j + 47, k + 30, Blocks.log, 1);
		world.setBlockMetadataWithNotify(i + 5, j + 47, k + 30, 1, 2);
		setBlock(world, i + 5, j + 47, k + 31, Blocks.log, 1);
		world.setBlockMetadataWithNotify(i + 5, j + 47, k + 31, 1, 2);
		setBlock(world, i + 5, j + 48, k + 17, Blocks.log, 1);
		world.setBlockMetadataWithNotify(i + 5, j + 48, k + 17, 1, 2);
		setBlock(world, i + 5, j + 48, k + 18, Blocks.log, 1);
		world.setBlockMetadataWithNotify(i + 5, j + 48, k + 18, 1, 2);
		setBlock(world, i + 5, j + 48, k + 19, Blocks.log, 1);
		world.setBlockMetadataWithNotify(i + 5, j + 48, k + 19, 1, 2);
		setBlock(world, i + 5, j + 48, k + 20, Blocks.log, 1);
		world.setBlockMetadataWithNotify(i + 5, j + 48, k + 20, 1, 2);
		setBlock(world, i + 5, j + 48, k + 21, Blocks.log, 1);
		world.setBlockMetadataWithNotify(i + 5, j + 48, k + 21, 1, 2);
		setBlock(world, i + 5, j + 48, k + 30, Blocks.log, 1);
		world.setBlockMetadataWithNotify(i + 5, j + 48, k + 30, 1, 2);
		setBlock(world, i + 5, j + 48, k + 31, Blocks.log, 1);
		world.setBlockMetadataWithNotify(i + 5, j + 48, k + 31, 1, 2);
		setBlock(world, i + 5, j + 49, k + 18, Blocks.log, 1);
		world.setBlockMetadataWithNotify(i + 5, j + 49, k + 18, 1, 2);
		setBlock(world, i + 5, j + 49, k + 19, Blocks.log, 1);
		world.setBlockMetadataWithNotify(i + 5, j + 49, k + 19, 1, 2);
		setBlock(world, i + 5, j + 49, k + 20, Blocks.log, 1);
		world.setBlockMetadataWithNotify(i + 5, j + 49, k + 20, 1, 2);
		setBlock(world, i + 5, j + 49, k + 21, Blocks.log, 1);
		world.setBlockMetadataWithNotify(i + 5, j + 49, k + 21, 1, 2);
		setBlock(world, i + 5, j + 49, k + 22, Blocks.log, 1);
		world.setBlockMetadataWithNotify(i + 5, j + 49, k + 22, 1, 2);
		setBlock(world, i + 5, j + 49, k + 30, Blocks.log, 1);
		world.setBlockMetadataWithNotify(i + 5, j + 49, k + 30, 1, 2);
		setBlock(world, i + 5, j + 49, k + 31, Blocks.log, 1);
		world.setBlockMetadataWithNotify(i + 5, j + 49, k + 31, 1, 2);
		setBlock(world, i + 5, j + 50, k + 20, Blocks.log, 1);
		world.setBlockMetadataWithNotify(i + 5, j + 50, k + 20, 1, 2);
		setBlock(world, i + 5, j + 50, k + 21, Blocks.log, 1);
		world.setBlockMetadataWithNotify(i + 5, j + 50, k + 21, 1, 2);
		setBlock(world, i + 5, j + 50, k + 22, Blocks.log, 1);
		world.setBlockMetadataWithNotify(i + 5, j + 50, k + 22, 1, 2);
		setBlock(world, i + 5, j + 50, k + 23, Blocks.log, 1);
		world.setBlockMetadataWithNotify(i + 5, j + 50, k + 23, 1, 2);
		setBlock(world, i + 5, j + 50, k + 29, Blocks.log, 1);
		world.setBlockMetadataWithNotify(i + 5, j + 50, k + 29, 1, 2);
		setBlock(world, i + 5, j + 50, k + 30, Blocks.log, 1);
		world.setBlockMetadataWithNotify(i + 5, j + 50, k + 30, 1, 2);
		setBlock(world, i + 5, j + 50, k + 31, Blocks.log, 1);
		world.setBlockMetadataWithNotify(i + 5, j + 50, k + 31, 1, 2);
		setBlock(world, i + 5, j + 51, k + 24, Blocks.log, 1);
		world.setBlockMetadataWithNotify(i + 5, j + 51, k + 24, 1, 2);
		setBlock(world, i + 5, j + 51, k + 25, Blocks.log, 1);
		world.setBlockMetadataWithNotify(i + 5, j + 51, k + 25, 1, 2);
		setBlock(world, i + 5, j + 51, k + 26, Blocks.log, 1);
		world.setBlockMetadataWithNotify(i + 5, j + 51, k + 26, 1, 2);
		setBlock(world, i + 5, j + 51, k + 27, Blocks.log, 1);
		world.setBlockMetadataWithNotify(i + 5, j + 51, k + 27, 1, 2);
		setBlock(world, i + 5, j + 51, k + 28, Blocks.log, 1);
		world.setBlockMetadataWithNotify(i + 5, j + 51, k + 28, 1, 2);
		setBlock(world, i + 5, j + 51, k + 29, Blocks.log, 1);
		world.setBlockMetadataWithNotify(i + 5, j + 51, k + 29, 1, 2);
		setBlock(world, i + 5, j + 51, k + 30, Blocks.log, 1);
		world.setBlockMetadataWithNotify(i + 5, j + 51, k + 30, 1, 2);
		setBlock(world, i + 5, j + 51, k + 31, Blocks.log, 1);
		world.setBlockMetadataWithNotify(i + 5, j + 51, k + 31, 1, 2);
		setBlock(world, i + 6, j + 26, k + 26, Blocks.leaves, 15);
		world.setBlockMetadataWithNotify(i + 6, j + 26, k + 26, 15, 2);
		setBlock(world, i + 6, j + 26, k + 27, Blocks.leaves, 15);
		world.setBlockMetadataWithNotify(i + 6, j + 26, k + 27, 15, 2);
		setBlock(world, i + 6, j + 26, k + 28, Blocks.leaves, 15);
		world.setBlockMetadataWithNotify(i + 6, j + 26, k + 28, 15, 2);
		setBlock(world, i + 6, j + 26, k + 29, Blocks.leaves, 15);
		world.setBlockMetadataWithNotify(i + 6, j + 26, k + 29, 15, 2);
		setBlock(world, i + 6, j + 26, k + 30, Blocks.leaves, 15);
		world.setBlockMetadataWithNotify(i + 6, j + 26, k + 30, 15, 2);
		setBlock(world, i + 6, j + 27, k + 28, Blocks.leaves, 15);
		world.setBlockMetadataWithNotify(i + 6, j + 27, k + 28, 15, 2);
		setBlock(world, i + 6, j + 27, k + 29, Blocks.leaves, 15);
		world.setBlockMetadataWithNotify(i + 6, j + 27, k + 29, 15, 2);
		setBlock(world, i + 6, j + 27, k + 30, Blocks.log, 1);
		world.setBlockMetadataWithNotify(i + 6, j + 27, k + 30, 1, 2);
		setBlock(world, i + 6, j + 27, k + 31, Blocks.planks, 5);
		world.setBlockMetadataWithNotify(i + 6, j + 27, k + 31, 5, 2);
		setBlock(world, i + 6, j + 29, k + 30, Blocks.torch, 5);
		world.setBlockMetadataWithNotify(i + 6, j + 29, k + 30, 5, 2);
		setBlock(world, i + 6, j + 31, k + 26, Blocks.log, 1);
		world.setBlockMetadataWithNotify(i + 6, j + 31, k + 26, 1, 2);
		setBlock(world, i + 6, j + 31, k + 27, Blocks.log, 1);
		world.setBlockMetadataWithNotify(i + 6, j + 31, k + 27, 1, 2);
		setBlock(world, i + 6, j + 31, k + 28, Blocks.log, 1);
		world.setBlockMetadataWithNotify(i + 6, j + 31, k + 28, 1, 2);
		setBlock(world, i + 6, j + 31, k + 29, Blocks.log, 1);
		world.setBlockMetadataWithNotify(i + 6, j + 31, k + 29, 1, 2);
		setBlock(world, i + 6, j + 31, k + 30, Blocks.log, 1);
		world.setBlockMetadataWithNotify(i + 6, j + 31, k + 30, 1, 2);
		setBlock(world, i + 6, j + 32, k + 22, Blocks.leaves, 7);
		world.setBlockMetadataWithNotify(i + 6, j + 32, k + 22, 7, 2);
		setBlock(world, i + 6, j + 32, k + 23, Blocks.leaves, 7);
		world.setBlockMetadataWithNotify(i + 6, j + 32, k + 23, 7, 2);
		setBlock(world, i + 6, j + 32, k + 24, Blocks.leaves, 7);
		world.setBlockMetadataWithNotify(i + 6, j + 32, k + 24, 7, 2);
		setBlock(world, i + 6, j + 32, k + 28, Blocks.log, 1);
		world.setBlockMetadataWithNotify(i + 6, j + 32, k + 28, 1, 2);
		setBlock(world, i + 6, j + 32, k + 29, Blocks.log, 1);
		world.setBlockMetadataWithNotify(i + 6, j + 32, k + 29, 1, 2);
		setBlock(world, i + 6, j + 32, k + 30, Blocks.log, 1);
		world.setBlockMetadataWithNotify(i + 6, j + 32, k + 30, 1, 2);
		setBlock(world, i + 6, j + 32, k + 31, Blocks.log, 1);
		world.setBlockMetadataWithNotify(i + 6, j + 32, k + 31, 1, 2);
		setBlock(world, i + 6, j + 33, k + 23, Blocks.leaves, 7);
		world.setBlockMetadataWithNotify(i + 6, j + 33, k + 23, 7, 2);
		setBlock(world, i + 6, j + 33, k + 28, Blocks.log, 1);
		world.setBlockMetadataWithNotify(i + 6, j + 33, k + 28, 1, 2);
		setBlock(world, i + 6, j + 33, k + 29, Blocks.log, 1);
		world.setBlockMetadataWithNotify(i + 6, j + 33, k + 29, 1, 2);
		setBlock(world, i + 6, j + 33, k + 30, Blocks.log, 1);
		world.setBlockMetadataWithNotify(i + 6, j + 33, k + 30, 1, 2);
		setBlock(world, i + 6, j + 33, k + 31, Blocks.log, 1);
		world.setBlockMetadataWithNotify(i + 6, j + 33, k + 31, 1, 2);
		setBlock(world, i + 6, j + 34, k + 29, Blocks.log, 1);
		world.setBlockMetadataWithNotify(i + 6, j + 34, k + 29, 1, 2);
		setBlock(world, i + 6, j + 34, k + 30, Blocks.log, 1);
		world.setBlockMetadataWithNotify(i + 6, j + 34, k + 30, 1, 2);
		
		generate91(world, rand, i, j, k);
		return true;
		}

	
	public boolean generate91(World world, Random rand, int i, int j, int k)
	
	{
		setBlock(world, i + 6, j + 34, k + 31, Blocks.log, 1);
		world.setBlockMetadataWithNotify(i + 6, j + 34, k + 31, 1, 2);
		setBlock(world, i + 6, j + 35, k + 15, Blocks.vine, 14);
		world.setBlockMetadataWithNotify(i + 6, j + 35, k + 15, 14, 2);
		setBlock(world, i + 6, j + 35, k + 30, Blocks.log, 1);
		world.setBlockMetadataWithNotify(i + 6, j + 35, k + 30, 1, 2);
		setBlock(world, i + 6, j + 35, k + 31, Blocks.log, 1);
		world.setBlockMetadataWithNotify(i + 6, j + 35, k + 31, 1, 2);
		setBlock(world, i + 6, j + 36, k + 15, Blocks.vine, 14);
		world.setBlockMetadataWithNotify(i + 6, j + 36, k + 15, 14, 2);
		setBlock(world, i + 6, j + 37, k + 14, Blocks.vine, 15);
		world.setBlockMetadataWithNotify(i + 6, j + 37, k + 14, 15, 2);
		setBlock(world, i + 6, j + 37, k + 15, Blocks.vine, 15);
		world.setBlockMetadataWithNotify(i + 6, j + 37, k + 15, 15, 2);
		setBlock(world, i + 6, j + 37, k + 30, Blocks.leaves, 7);
		world.setBlockMetadataWithNotify(i + 6, j + 37, k + 30, 7, 2);
		setBlock(world, i + 6, j + 37, k + 31, Blocks.leaves, 7);
		world.setBlockMetadataWithNotify(i + 6, j + 37, k + 31, 7, 2);
		setBlock(world, i + 6, j + 38, k + 14, Blocks.vine, 15);
		world.setBlockMetadataWithNotify(i + 6, j + 38, k + 14, 15, 2);
		setBlock(world, i + 6, j + 38, k + 15, Blocks.vine, 15);
		world.setBlockMetadataWithNotify(i + 6, j + 38, k + 15, 15, 2);
		setBlock(world, i + 6, j + 38, k + 31, Blocks.leaves, 7);
		world.setBlockMetadataWithNotify(i + 6, j + 38, k + 31, 7, 2);
		setBlock(world, i + 6, j + 39, k + 14, Blocks.vine, 15);
		world.setBlockMetadataWithNotify(i + 6, j + 39, k + 14, 15, 2);
		setBlock(world, i + 6, j + 39, k + 15, Blocks.vine, 15);
		world.setBlockMetadataWithNotify(i + 6, j + 39, k + 15, 15, 2);
		setBlock(world, i + 6, j + 39, k + 31, Blocks.log, 1);
		world.setBlockMetadataWithNotify(i + 6, j + 39, k + 31, 1, 2);
		setBlock(world, i + 6, j + 40, k + 14, Blocks.vine, 15);
		world.setBlockMetadataWithNotify(i + 6, j + 40, k + 14, 15, 2);
		setBlock(world, i + 6, j + 40, k + 15, Blocks.vine, 15);
		world.setBlockMetadataWithNotify(i + 6, j + 40, k + 15, 15, 2);
		setBlock(world, i + 6, j + 40, k + 29, Blocks.log, 1);
		world.setBlockMetadataWithNotify(i + 6, j + 40, k + 29, 1, 2);
		setBlock(world, i + 6, j + 40, k + 30, Blocks.log, 1);
		world.setBlockMetadataWithNotify(i + 6, j + 40, k + 30, 1, 2);
		setBlock(world, i + 6, j + 40, k + 31, Blocks.log, 1);
		world.setBlockMetadataWithNotify(i + 6, j + 40, k + 31, 1, 2);
		setBlock(world, i + 6, j + 41, k + 14, Blocks.vine, 15);
		world.setBlockMetadataWithNotify(i + 6, j + 41, k + 14, 15, 2);
		setBlock(world, i + 6, j + 41, k + 15, Blocks.vine, 15);
		world.setBlockMetadataWithNotify(i + 6, j + 41, k + 15, 15, 2);
		setBlock(world, i + 6, j + 41, k + 28, Blocks.log, 1);
		world.setBlockMetadataWithNotify(i + 6, j + 41, k + 28, 1, 2);
		setBlock(world, i + 6, j + 41, k + 29, Blocks.log, 1);
		world.setBlockMetadataWithNotify(i + 6, j + 41, k + 29, 1, 2);
		setBlock(world, i + 6, j + 41, k + 30, Blocks.log, 1);
		world.setBlockMetadataWithNotify(i + 6, j + 41, k + 30, 1, 2);
		setBlock(world, i + 6, j + 41, k + 31, Blocks.log, 1);
		world.setBlockMetadataWithNotify(i + 6, j + 41, k + 31, 1, 2);
		setBlock(world, i + 6, j + 42, k + 9, Blocks.planks, 5);
		world.setBlockMetadataWithNotify(i + 6, j + 42, k + 9, 5, 2);
		setBlock(world, i + 6, j + 42, k + 10, Blocks.planks, 5);
		world.setBlockMetadataWithNotify(i + 6, j + 42, k + 10, 5, 2);
		setBlock(world, i + 6, j + 42, k + 11, Blocks.planks, 5);
		world.setBlockMetadataWithNotify(i + 6, j + 42, k + 11, 5, 2);
		setBlock(world, i + 6, j + 42, k + 12, Blocks.planks, 5);
		world.setBlockMetadataWithNotify(i + 6, j + 42, k + 12, 5, 2);
		setBlock(world, i + 6, j + 42, k + 13, Blocks.planks, 5);
		world.setBlockMetadataWithNotify(i + 6, j + 42, k + 13, 5, 2);
		setBlock(world, i + 6, j + 42, k + 14, Blocks.planks, 5);
		world.setBlockMetadataWithNotify(i + 6, j + 42, k + 14, 5, 2);
		setBlock(world, i + 6, j + 42, k + 15, Blocks.planks, 5);
		world.setBlockMetadataWithNotify(i + 6, j + 42, k + 15, 5, 2);
		setBlock(world, i + 6, j + 42, k + 16, Blocks.planks, 5);
		world.setBlockMetadataWithNotify(i + 6, j + 42, k + 16, 5, 2);
		setBlock(world, i + 6, j + 42, k + 27, Blocks.log, 1);
		world.setBlockMetadataWithNotify(i + 6, j + 42, k + 27, 1, 2);
		setBlock(world, i + 6, j + 42, k + 28, Blocks.log, 1);
		world.setBlockMetadataWithNotify(i + 6, j + 42, k + 28, 1, 2);
		setBlock(world, i + 6, j + 42, k + 29, Blocks.log, 1);
		world.setBlockMetadataWithNotify(i + 6, j + 42, k + 29, 1, 2);
		setBlock(world, i + 6, j + 42, k + 30, Blocks.leaves, 15);
		world.setBlockMetadataWithNotify(i + 6, j + 42, k + 30, 15, 2);
		setBlock(world, i + 6, j + 42, k + 31, Blocks.log, 1);
		world.setBlockMetadataWithNotify(i + 6, j + 42, k + 31, 1, 2);
		setBlock(world, i + 6, j + 43, k + 15, Blocks.spruce_stairs, 2);
		world.setBlockMetadataWithNotify(i + 6, j + 43, k + 15, 2, 2);
		setBlock(world, i + 6, j + 43, k + 16, Blocks.planks, 5);
		world.setBlockMetadataWithNotify(i + 6, j + 43, k + 16, 5, 2);
		setBlock(world, i + 6, j + 43, k + 17, Blocks.planks, 5);
		world.setBlockMetadataWithNotify(i + 6, j + 43, k + 17, 5, 2);
		setBlock(world, i + 6, j + 43, k + 18, Blocks.planks, 5);
		world.setBlockMetadataWithNotify(i + 6, j + 43, k + 18, 5, 2);
		setBlock(world, i + 6, j + 43, k + 19, Blocks.log, 1);
		world.setBlockMetadataWithNotify(i + 6, j + 43, k + 19, 1, 2);
		setBlock(world, i + 6, j + 43, k + 20, Blocks.log, 1);
		world.setBlockMetadataWithNotify(i + 6, j + 43, k + 20, 1, 2);
		setBlock(world, i + 6, j + 43, k + 21, Blocks.planks, 5);
		world.setBlockMetadataWithNotify(i + 6, j + 43, k + 21, 5, 2);
		setBlock(world, i + 6, j + 43, k + 22, Blocks.planks, 5);
		world.setBlockMetadataWithNotify(i + 6, j + 43, k + 22, 5, 2);
		setBlock(world, i + 6, j + 43, k + 23, Blocks.planks, 5);
		world.setBlockMetadataWithNotify(i + 6, j + 43, k + 23, 5, 2);
		setBlock(world, i + 6, j + 43, k + 24, Blocks.planks, 5);
		world.setBlockMetadataWithNotify(i + 6, j + 43, k + 24, 5, 2);
		setBlock(world, i + 6, j + 43, k + 25, Blocks.planks, 5);
		world.setBlockMetadataWithNotify(i + 6, j + 43, k + 25, 5, 2);
		setBlock(world, i + 6, j + 43, k + 26, Blocks.planks, 5);
		world.setBlockMetadataWithNotify(i + 6, j + 43, k + 26, 5, 2);
		setBlock(world, i + 6, j + 43, k + 27, Blocks.log, 1);
		world.setBlockMetadataWithNotify(i + 6, j + 43, k + 27, 1, 2);
		setBlock(world, i + 6, j + 43, k + 28, Blocks.planks, 5);
		world.setBlockMetadataWithNotify(i + 6, j + 43, k + 28, 5, 2);
		setBlock(world, i + 6, j + 43, k + 29, Blocks.log, 1);
		world.setBlockMetadataWithNotify(i + 6, j + 43, k + 29, 1, 2);
		setBlock(world, i + 6, j + 43, k + 30, Blocks.log, 1);
		world.setBlockMetadataWithNotify(i + 6, j + 43, k + 30, 1, 2);
		setBlock(world, i + 6, j + 43, k + 31, Blocks.log, 1);
		world.setBlockMetadataWithNotify(i + 6, j + 43, k + 31, 1, 2);
		setBlock(world, i + 6, j + 44, k + 29, Blocks.spruce_stairs, 2);
		world.setBlockMetadataWithNotify(i + 6, j + 44, k + 29, 2, 2);
		setBlock(world, i + 6, j + 44, k + 30, Blocks.log, 1);
		world.setBlockMetadataWithNotify(i + 6, j + 44, k + 30, 1, 2);
		setBlock(world, i + 6, j + 44, k + 31, Blocks.log, 1);
		world.setBlockMetadataWithNotify(i + 6, j + 44, k + 31, 1, 2);
		setBlock(world, i + 6, j + 45, k + 30, Blocks.log, 1);
		world.setBlockMetadataWithNotify(i + 6, j + 45, k + 30, 1, 2);
		setBlock(world, i + 6, j + 45, k + 31, Blocks.log, 1);
		world.setBlockMetadataWithNotify(i + 6, j + 45, k + 31, 1, 2);
		setBlock(world, i + 6, j + 46, k + 30, Blocks.log, 1);
		world.setBlockMetadataWithNotify(i + 6, j + 46, k + 30, 1, 2);
		setBlock(world, i + 6, j + 46, k + 31, Blocks.log, 1);
		world.setBlockMetadataWithNotify(i + 6, j + 46, k + 31, 1, 2);
		setBlock(world, i + 6, j + 47, k + 29, Blocks.torch, 4);
		world.setBlockMetadataWithNotify(i + 6, j + 47, k + 29, 4, 2);
		setBlock(world, i + 6, j + 47, k + 30, Blocks.log, 1);
		world.setBlockMetadataWithNotify(i + 6, j + 47, k + 30, 1, 2);
		setBlock(world, i + 6, j + 47, k + 31, Blocks.log, 1);
		world.setBlockMetadataWithNotify(i + 6, j + 47, k + 31, 1, 2);
		setBlock(world, i + 6, j + 48, k + 17, Blocks.log, 1);
		world.setBlockMetadataWithNotify(i + 6, j + 48, k + 17, 1, 2);
		setBlock(world, i + 6, j + 48, k + 18, Blocks.log, 1);
		world.setBlockMetadataWithNotify(i + 6, j + 48, k + 18, 1, 2);
		setBlock(world, i + 6, j + 48, k + 19, Blocks.log, 1);
		world.setBlockMetadataWithNotify(i + 6, j + 48, k + 19, 1, 2);
		setBlock(world, i + 6, j + 48, k + 20, Blocks.log, 1);
		world.setBlockMetadataWithNotify(i + 6, j + 48, k + 20, 1, 2);
		setBlock(world, i + 6, j + 48, k + 21, Blocks.log, 1);
		world.setBlockMetadataWithNotify(i + 6, j + 48, k + 21, 1, 2);
		setBlock(world, i + 6, j + 48, k + 30, Blocks.log, 1);
		world.setBlockMetadataWithNotify(i + 6, j + 48, k + 30, 1, 2);
		setBlock(world, i + 6, j + 48, k + 31, Blocks.log, 1);
		world.setBlockMetadataWithNotify(i + 6, j + 48, k + 31, 1, 2);
		setBlock(world, i + 6, j + 49, k + 18, Blocks.log, 1);
		world.setBlockMetadataWithNotify(i + 6, j + 49, k + 18, 1, 2);
		setBlock(world, i + 6, j + 49, k + 19, Blocks.log, 1);
		world.setBlockMetadataWithNotify(i + 6, j + 49, k + 19, 1, 2);
		setBlock(world, i + 6, j + 49, k + 20, Blocks.log, 1);
		world.setBlockMetadataWithNotify(i + 6, j + 49, k + 20, 1, 2);
		setBlock(world, i + 6, j + 49, k + 21, Blocks.log, 1);
		world.setBlockMetadataWithNotify(i + 6, j + 49, k + 21, 1, 2);
		setBlock(world, i + 6, j + 49, k + 22, Blocks.log, 1);
		world.setBlockMetadataWithNotify(i + 6, j + 49, k + 22, 1, 2);
		setBlock(world, i + 6, j + 49, k + 30, Blocks.log, 1);
		world.setBlockMetadataWithNotify(i + 6, j + 49, k + 30, 1, 2);
		setBlock(world, i + 6, j + 49, k + 31, Blocks.log, 1);
		world.setBlockMetadataWithNotify(i + 6, j + 49, k + 31, 1, 2);
		setBlock(world, i + 6, j + 50, k + 20, Blocks.log, 1);
		world.setBlockMetadataWithNotify(i + 6, j + 50, k + 20, 1, 2);
		setBlock(world, i + 6, j + 50, k + 21, Blocks.log, 1);
		world.setBlockMetadataWithNotify(i + 6, j + 50, k + 21, 1, 2);
