package com.parzivail.pswm.world.gen.wookietree;




import com.parzivail.pswm.utils.LootGenUtils;
import com.parzivail.pswm.utils.NPCType;
import com.parzivail.pswm.utils.SpawnUtils;



import cpw.mods.fml.common.IWorldGenerator;



import java.util.Random;



import net.minecraft.block.Block;

import net.minecraft.init.Blocks;

import net.minecraft.tileentity.TileEntityChest;

import net.minecraft.world.World;

import net.minecraft.world.WorldProvider;

import net.minecraft.world.chunk.IChunkProvider;

import net.minecraft.world.gen.feature.WorldGenerator;


public class WT_33
extends WorldGenerator implements IWorldGenerator

{
	protected Block[] getValidSpawnBlocks()
	
	{
		return new Block[0];
		}

	
	public boolean locationIsValidSpawn(World world, int i, int j, int k)
	
	{
		int distanceToAir = 0;
		Block check = world.getBlock(i, j, k);
		
		while (check != Blocks.air)
		{
			if (distanceToAir > 3) { return false;
			}
			
			distanceToAir++;
			check = world.getBlock(i, j + distanceToAir, k);
			}
		
		j += distanceToAir - 1;
		
		Block block = world.getBlock(i, j, k);
		Block blockAbove = world.getBlock(i, j + 1, k);
		Block blockBelow = world.getBlock(i, j - 1, k);
		
		for (Block x : getValidSpawnBlocks())
		{
			if (blockAbove != Blocks.air) { return false;
			}
			if (block == x) return true;
			if ((block == Blocks.snow) && (blockBelow == x)) { return true;
			}
			}
		
		return false;
		}

	
	
	
	public void generate(Random random, int chunkX, int chunkZ, World world, IChunkProvider chunkGenerator, IChunkProvider chunkProvider)
	{
	}

	
	
	public void setBlock(World world, int x, int y, int z, Block block, int metadata)
	
	{
		world.setBlock(x, y, z, block, metadata, 2);
		}

	
	public boolean generate(World world, Random rand, int i, int j, int k)
	
	{
		k -= 10;
		i -= 10;
		
		setBlock(world, i + 3, j + 49, k + 7, Blocks.spruce_stairs, 0);
		setBlock(world, i + 3, j + 49, k + 8, Blocks.spruce_stairs, 0);
		setBlock(world, i + 3, j + 49, k + 9, Blocks.spruce_stairs, 0);
		setBlock(world, i + 3, j + 49, k + 10, Blocks.spruce_stairs, 0);
		setBlock(world, i + 3, j + 49, k + 11, Blocks.spruce_stairs, 0);
		setBlock(world, i + 4, j + 36, k + 22, Blocks.fence, 0);
		setBlock(world, i + 4, j + 36, k + 28, Blocks.fence, 0);
		setBlock(world, i + 5, j + 21, k + 1, Blocks.spruce_stairs, 0);
		setBlock(world, i + 5, j + 36, k + 22, Blocks.fence, 0);
		setBlock(world, i + 5, j + 36, k + 28, Blocks.fence, 0);
		setBlock(world, i + 7, j + 21, k + 0, Blocks.fence, 0);
		setBlock(world, i + 7, j + 24, k + 2, Blocks.fence, 0);
		setBlock(world, i + 7, j + 24, k + 3, Blocks.fence, 0);
		setBlock(world, i + 7, j + 34, k + 21, Blocks.fence, 0);
		setBlock(world, i + 7, j + 34, k + 22, Blocks.fence, 0);
		setBlock(world, i + 7, j + 34, k + 28, Blocks.fence, 0);
		setBlock(world, i + 7, j + 34, k + 29, Blocks.fence, 0);
		setBlock(world, i + 7, j + 50, k + 7, Blocks.spruce_stairs, 0);
		setBlock(world, i + 7, j + 50, k + 8, Blocks.spruce_stairs, 0);
		setBlock(world, i + 7, j + 50, k + 9, Blocks.spruce_stairs, 0);
		setBlock(world, i + 7, j + 50, k + 10, Blocks.spruce_stairs, 0);
		setBlock(world, i + 7, j + 50, k + 11, Blocks.spruce_stairs, 0);
		setBlock(world, i + 8, j + 24, k + 1, Blocks.fence, 0);
		setBlock(world, i + 8, j + 24, k + 2, Blocks.fence, 0);
		setBlock(world, i + 8, j + 34, k + 20, Blocks.fence, 0);
		setBlock(world, i + 8, j + 34, k + 21, Blocks.fence, 0);
		setBlock(world, i + 8, j + 34, k + 29, Blocks.fence, 0);
		setBlock(world, i + 8, j + 34, k + 30, Blocks.fence, 0);
		setBlock(world, i + 9, j + 24, k + 0, Blocks.fence, 0);
		setBlock(world, i + 9, j + 24, k + 1, Blocks.fence, 0);
		setBlock(world, i + 9, j + 34, k + 19, Blocks.spruce_stairs, 0);
		setBlock(world, i + 9, j + 34, k + 20, Blocks.fence, 0);
		setBlock(world, i + 9, j + 34, k + 30, Blocks.fence, 0);
		setBlock(world, i + 9, j + 34, k + 31, Blocks.spruce_stairs, 0);
		setBlock(world, i + 9, j + 36, k + 17, Blocks.fence, 0);
		setBlock(world, i + 9, j + 36, k + 18, Blocks.fence, 0);
		SpawnUtils.spawnNPC(NPCType.WOOKIETREE, world, i + 10, j + 34, k + 23);
		SpawnUtils.spawnNPC(NPCType.WOOKIETREE, world, i + 10, j + 34, k + 27);
		setBlock(world, i + 11, j + 34, k + 24, Blocks.crafting_table, 0);
		setBlock(world, i + 11, j + 34, k + 25, Blocks.spruce_stairs, 0);
		setBlock(world, i + 11, j + 51, k + 7, Blocks.spruce_stairs, 0);
		setBlock(world, i + 11, j + 51, k + 8, Blocks.spruce_stairs, 0);
		setBlock(world, i + 11, j + 51, k + 9, Blocks.spruce_stairs, 0);
		setBlock(world, i + 11, j + 51, k + 10, Blocks.spruce_stairs, 0);
		setBlock(world, i + 11, j + 51, k + 11, Blocks.spruce_stairs, 0);
		SpawnUtils.spawnNPC(NPCType.WOOKIETREE, world, i + 14, j + 34, k + 23);
		SpawnUtils.spawnNPC(NPCType.WOOKIETREE, world, i + 14, j + 34, k + 27);
		setBlock(world, i + 14, j + 52, k + 7, Blocks.spruce_stairs, 0);
		setBlock(world, i + 14, j + 52, k + 8, Blocks.spruce_stairs, 0);
		setBlock(world, i + 14, j + 52, k + 9, Blocks.spruce_stairs, 0);
		setBlock(world, i + 14, j + 52, k + 10, Blocks.spruce_stairs, 0);
		setBlock(world, i + 14, j + 52, k + 11, Blocks.spruce_stairs, 0);
		setBlock(world, i + 15, j + 34, k + 20, Blocks.fence, 0);
		setBlock(world, i + 15, j + 34, k + 30, Blocks.fence, 0);
		setBlock(world, i + 15, j + 36, k + 17, Blocks.fence, 0);
		setBlock(world, i + 15, j + 36, k + 18, Blocks.fence, 0);
		setBlock(world, i + 16, j + 34, k + 20, Blocks.fence, 0);
		setBlock(world, i + 16, j + 34, k + 21, Blocks.fence, 0);
		setBlock(world, i + 16, j + 34, k + 29, Blocks.fence, 0);
		setBlock(world, i + 16, j + 34, k + 30, Blocks.fence, 0);
		setBlock(world, i + 17, j + 34, k + 21, Blocks.fence, 0);
		setBlock(world, i + 17, j + 34, k + 22, Blocks.fence, 0);
		setBlock(world, i + 17, j + 34, k + 23, Blocks.spruce_stairs, 0);
		setBlock(world, i + 17, j + 34, k + 27, Blocks.spruce_stairs, 0);
		setBlock(world, i + 17, j + 34, k + 28, Blocks.fence, 0);
		setBlock(world, i + 17, j + 34, k + 29, Blocks.fence, 0);
		setBlock(world, i + 19, j + 36, k + 22, Blocks.fence, 0);
		setBlock(world, i + 19, j + 36, k + 28, Blocks.fence, 0);
		setBlock(world, i + 20, j + 36, k + 22, Blocks.fence, 0);
		setBlock(world, i + 20, j + 36, k + 28, Blocks.fence, 0);
		setBlock(world, i + 21, j + 53, k + 0, Blocks.fence, 0);
		setBlock(world, i + 22, j + 53, k + 0, Blocks.fence, 0);
		setBlock(world, i + 22, j + 53, k + 1, Blocks.fence, 0);
		setBlock(world, i + 23, j + 53, k + 1, Blocks.fence, 0);
		setBlock(world, i + 23, j + 53, k + 2, Blocks.spruce_stairs, 0);
		setBlock(world, i + 23, j + 55, k + 3, Blocks.fence, 0);
		setBlock(world, i + 23, j + 55, k + 4, Blocks.fence, 0);
		setBlock(world, i + 29, j + 53, k + 1, Blocks.fence, 0);
		setBlock(world, i + 29, j + 55, k + 3, Blocks.fence, 0);
		setBlock(world, i + 29, j + 55, k + 4, Blocks.fence, 0);
		setBlock(world, i + 30, j + 53, k + 0, Blocks.fence, 0);
		setBlock(world, i + 30, j + 53, k + 1, Blocks.fence, 0);
		setBlock(world, i + 31, j + 53, k + 0, Blocks.fence, 0);
		setBlock(world, i + 0, j + 20, k + 0, Blocks.log, 1);
		world.setBlockMetadataWithNotify(i + 0, j + 20, k + 0, 1, 2);
		setBlock(world, i + 0, j + 20, k + 1, Blocks.log, 1);
		world.setBlockMetadataWithNotify(i + 0, j + 20, k + 1, 1, 2);
		setBlock(world, i + 0, j + 20, k + 2, Blocks.log, 1);
		world.setBlockMetadataWithNotify(i + 0, j + 20, k + 2, 1, 2);
		setBlock(world, i + 0, j + 20, k + 3, Blocks.planks, 5);
		world.setBlockMetadataWithNotify(i + 0, j + 20, k + 3, 5, 2);
		setBlock(world, i + 0, j + 20, k + 4, Blocks.planks, 5);
		world.setBlockMetadataWithNotify(i + 0, j + 20, k + 4, 5, 2);
		setBlock(world, i + 0, j + 20, k + 5, Blocks.planks, 5);
		world.setBlockMetadataWithNotify(i + 0, j + 20, k + 5, 5, 2);
		setBlock(world, i + 0, j + 20, k + 6, Blocks.planks, 5);
		world.setBlockMetadataWithNotify(i + 0, j + 20, k + 6, 5, 2);
		setBlock(world, i + 0, j + 20, k + 7, Blocks.planks, 5);
		world.setBlockMetadataWithNotify(i + 0, j + 20, k + 7, 5, 2);
		setBlock(world, i + 0, j + 20, k + 8, Blocks.planks, 5);
		world.setBlockMetadataWithNotify(i + 0, j + 20, k + 8, 5, 2);
		setBlock(world, i + 0, j + 21, k + 1, Blocks.spruce_stairs, 1);
		world.setBlockMetadataWithNotify(i + 0, j + 21, k + 1, 1, 2);
		setBlock(world, i + 0, j + 21, k + 5, Blocks.torch, 5);
		world.setBlockMetadataWithNotify(i + 0, j + 21, k + 5, 5, 2);
		setBlock(world, i + 0, j + 21, k + 7, Blocks.spruce_stairs, 2);
		world.setBlockMetadataWithNotify(i + 0, j + 21, k + 7, 2, 2);
		setBlock(world, i + 0, j + 21, k + 8, Blocks.planks, 5);
		world.setBlockMetadataWithNotify(i + 0, j + 21, k + 8, 5, 2);
		setBlock(world, i + 0, j + 21, k + 9, Blocks.planks, 5);
		world.setBlockMetadataWithNotify(i + 0, j + 21, k + 9, 5, 2);
		setBlock(world, i + 0, j + 22, k + 8, Blocks.spruce_stairs, 2);
		world.setBlockMetadataWithNotify(i + 0, j + 22, k + 8, 2, 2);
		setBlock(world, i + 0, j + 22, k + 9, Blocks.planks, 5);
		world.setBlockMetadataWithNotify(i + 0, j + 22, k + 9, 5, 2);
		setBlock(world, i + 0, j + 22, k + 10, Blocks.planks, 5);
		world.setBlockMetadataWithNotify(i + 0, j + 22, k + 10, 5, 2);
		setBlock(world, i + 0, j + 23, k + 2, Blocks.torch, 1);
		world.setBlockMetadataWithNotify(i + 0, j + 23, k + 2, 1, 2);
		setBlock(world, i + 0, j + 23, k + 9, Blocks.spruce_stairs, 2);
		world.setBlockMetadataWithNotify(i + 0, j + 23, k + 9, 2, 2);
		setBlock(world, i + 0, j + 23, k + 10, Blocks.planks, 5);
		world.setBlockMetadataWithNotify(i + 0, j + 23, k + 10, 5, 2);
		setBlock(world, i + 0, j + 23, k + 11, Blocks.planks, 5);
		world.setBlockMetadataWithNotify(i + 0, j + 23, k + 11, 5, 2);
		setBlock(world, i + 0, j + 24, k + 3, Blocks.spruce_stairs, 5);
		world.setBlockMetadataWithNotify(i + 0, j + 24, k + 3, 5, 2);
		setBlock(world, i + 0, j + 24, k + 10, Blocks.spruce_stairs, 2);
		world.setBlockMetadataWithNotify(i + 0, j + 24, k + 10, 2, 2);
		setBlock(world, i + 0, j + 24, k + 11, Blocks.planks, 5);
		world.setBlockMetadataWithNotify(i + 0, j + 24, k + 11, 5, 2);
		setBlock(world, i + 0, j + 24, k + 12, Blocks.planks, 5);
		world.setBlockMetadataWithNotify(i + 0, j + 24, k + 12, 5, 2);
		setBlock(world, i + 0, j + 25, k + 0, Blocks.log, 1);
		world.setBlockMetadataWithNotify(i + 0, j + 25, k + 0, 1, 2);
		setBlock(world, i + 0, j + 25, k + 1, Blocks.log, 1);
		world.setBlockMetadataWithNotify(i + 0, j + 25, k + 1, 1, 2);
		setBlock(world, i + 0, j + 25, k + 2, Blocks.log, 1);
		world.setBlockMetadataWithNotify(i + 0, j + 25, k + 2, 1, 2);
		setBlock(world, i + 0, j + 25, k + 3, Blocks.log, 1);
		world.setBlockMetadataWithNotify(i + 0, j + 25, k + 3, 1, 2);
		setBlock(world, i + 0, j + 25, k + 4, Blocks.log, 1);
		world.setBlockMetadataWithNotify(i + 0, j + 25, k + 4, 1, 2);
		setBlock(world, i + 0, j + 25, k + 11, Blocks.spruce_stairs, 2);
		world.setBlockMetadataWithNotify(i + 0, j + 25, k + 11, 2, 2);
		setBlock(world, i + 0, j + 25, k + 12, Blocks.planks, 5);
		world.setBlockMetadataWithNotify(i + 0, j + 25, k + 12, 5, 2);
		setBlock(world, i + 0, j + 25, k + 13, Blocks.planks, 5);
		world.setBlockMetadataWithNotify(i + 0, j + 25, k + 13, 5, 2);
		setBlock(world, i + 0, j + 25, k + 28, Blocks.leaves, 7);
		world.setBlockMetadataWithNotify(i + 0, j + 25, k + 28, 7, 2);
		setBlock(world, i + 0, j + 25, k + 29, Blocks.leaves, 7);
		world.setBlockMetadataWithNotify(i + 0, j + 25, k + 29, 7, 2);
		setBlock(world, i + 0, j + 25, k + 30, Blocks.leaves, 7);
		world.setBlockMetadataWithNotify(i + 0, j + 25, k + 30, 7, 2);
		setBlock(world, i + 0, j + 26, k + 0, Blocks.log, 1);
		world.setBlockMetadataWithNotify(i + 0, j + 26, k + 0, 1, 2);
		setBlock(world, i + 0, j + 26, k + 1, Blocks.log, 1);
		world.setBlockMetadataWithNotify(i + 0, j + 26, k + 1, 1, 2);
		setBlock(world, i + 0, j + 26, k + 2, Blocks.log, 1);
		world.setBlockMetadataWithNotify(i + 0, j + 26, k + 2, 1, 2);
		setBlock(world, i + 0, j + 26, k + 3, Blocks.log, 1);
		world.setBlockMetadataWithNotify(i + 0, j + 26, k + 3, 1, 2);
		setBlock(world, i + 0, j + 26, k + 12, Blocks.spruce_stairs, 2);
		world.setBlockMetadataWithNotify(i + 0, j + 26, k + 12, 2, 2);
		setBlock(world, i + 0, j + 26, k + 13, Blocks.planks, 5);
		world.setBlockMetadataWithNotify(i + 0, j + 26, k + 13, 5, 2);
		setBlock(world, i + 0, j + 26, k + 14, Blocks.planks, 5);
		world.setBlockMetadataWithNotify(i + 0, j + 26, k + 14, 5, 2);
		setBlock(world, i + 0, j + 26, k + 29, Blocks.leaves, 7);
		world.setBlockMetadataWithNotify(i + 0, j + 26, k + 29, 7, 2);
		setBlock(world, i + 0, j + 27, k + 0, Blocks.log, 1);
		world.setBlockMetadataWithNotify(i + 0, j + 27, k + 0, 1, 2);
		setBlock(world, i + 0, j + 27, k + 1, Blocks.log, 1);
		world.setBlockMetadataWithNotify(i + 0, j + 27, k + 1, 1, 2);
		setBlock(world, i + 0, j + 27, k + 13, Blocks.spruce_stairs, 2);
		world.setBlockMetadataWithNotify(i + 0, j + 27, k + 13, 2, 2);
		setBlock(world, i + 0, j + 27, k + 14, Blocks.planks, 5);
		world.setBlockMetadataWithNotify(i + 0, j + 27, k + 14, 5, 2);
		setBlock(world, i + 0, j + 27, k + 15, Blocks.planks, 5);
		world.setBlockMetadataWithNotify(i + 0, j + 27, k + 15, 5, 2);
		setBlock(world, i + 0, j + 28, k + 14, Blocks.spruce_stairs, 2);
		world.setBlockMetadataWithNotify(i + 0, j + 28, k + 14, 2, 2);
		setBlock(world, i + 0, j + 28, k + 15, Blocks.planks, 5);
		world.setBlockMetadataWithNotify(i + 0, j + 28, k + 15, 5, 2);
		setBlock(world, i + 0, j + 28, k + 16, Blocks.planks, 5);
		world.setBlockMetadataWithNotify(i + 0, j + 28, k + 16, 5, 2);
		setBlock(world, i + 0, j + 29, k + 15, Blocks.spruce_stairs, 2);
		world.setBlockMetadataWithNotify(i + 0, j + 29, k + 15, 2, 2);
		setBlock(world, i + 0, j + 29, k + 16, Blocks.planks, 5);
		world.setBlockMetadataWithNotify(i + 0, j + 29, k + 16, 5, 2);
		setBlock(world, i + 0, j + 29, k + 17, Blocks.planks, 5);
		world.setBlockMetadataWithNotify(i + 0, j + 29, k + 17, 5, 2);
		setBlock(world, i + 0, j + 30, k + 16, Blocks.spruce_stairs, 2);
		world.setBlockMetadataWithNotify(i + 0, j + 30, k + 16, 2, 2);
		setBlock(world, i + 0, j + 30, k + 17, Blocks.planks, 5);
		world.setBlockMetadataWithNotify(i + 0, j + 30, k + 17, 5, 2);
		setBlock(world, i + 0, j + 30, k + 18, Blocks.planks, 5);
		world.setBlockMetadataWithNotify(i + 0, j + 30, k + 18, 5, 2);
		setBlock(world, i + 0, j + 31, k + 17, Blocks.spruce_stairs, 2);
		world.setBlockMetadataWithNotify(i + 0, j + 31, k + 17, 2, 2);
		setBlock(world, i + 0, j + 31, k + 18, Blocks.planks, 5);
		world.setBlockMetadataWithNotify(i + 0, j + 31, k + 18, 5, 2);
		setBlock(world, i + 0, j + 31, k + 19, Blocks.planks, 5);
		world.setBlockMetadataWithNotify(i + 0, j + 31, k + 19, 5, 2);
		setBlock(world, i + 0, j + 32, k + 18, Blocks.spruce_stairs, 2);
		world.setBlockMetadataWithNotify(i + 0, j + 32, k + 18, 2, 2);
		setBlock(world, i + 0, j + 32, k + 19, Blocks.planks, 5);
		world.setBlockMetadataWithNotify(i + 0, j + 32, k + 19, 5, 2);
		setBlock(world, i + 0, j + 32, k + 20, Blocks.planks, 5);
		world.setBlockMetadataWithNotify(i + 0, j + 32, k + 20, 5, 2);
		setBlock(world, i + 0, j + 33, k + 19, Blocks.spruce_stairs, 2);
		world.setBlockMetadataWithNotify(i + 0, j + 33, k + 19, 2, 2);
		setBlock(world, i + 0, j + 33, k + 20, Blocks.planks, 5);
		world.setBlockMetadataWithNotify(i + 0, j + 33, k + 20, 5, 2);
		setBlock(world, i + 0, j + 33, k + 21, Blocks.planks, 5);
		world.setBlockMetadataWithNotify(i + 0, j + 33, k + 21, 5, 2);
		setBlock(world, i + 0, j + 33, k + 22, Blocks.planks, 5);
		world.setBlockMetadataWithNotify(i + 0, j + 33, k + 22, 5, 2);
		setBlock(world, i + 0, j + 33, k + 23, Blocks.planks, 5);
		world.setBlockMetadataWithNotify(i + 0, j + 33, k + 23, 5, 2);
		setBlock(world, i + 0, j + 33, k + 24, Blocks.planks, 5);
		world.setBlockMetadataWithNotify(i + 0, j + 33, k + 24, 5, 2);
		setBlock(world, i + 0, j + 33, k + 25, Blocks.planks, 5);
		world.setBlockMetadataWithNotify(i + 0, j + 33, k + 25, 5, 2);
		setBlock(world, i + 0, j + 33, k + 26, Blocks.planks, 5);
		world.setBlockMetadataWithNotify(i + 0, j + 33, k + 26, 5, 2);
		setBlock(world, i + 0, j + 33, k + 27, Blocks.planks, 5);
		world.setBlockMetadataWithNotify(i + 0, j + 33, k + 27, 5, 2);
		setBlock(world, i + 0, j + 33, k + 28, Blocks.planks, 5);
		world.setBlockMetadataWithNotify(i + 0, j + 33, k + 28, 5, 2);
		setBlock(world, i + 0, j + 33, k + 29, Blocks.planks, 5);
		world.setBlockMetadataWithNotify(i + 0, j + 33, k + 29, 5, 2);
		setBlock(world, i + 0, j + 33, k + 30, Blocks.planks, 5);
		world.setBlockMetadataWithNotify(i + 0, j + 33, k + 30, 5, 2);
		setBlock(world, i + 0, j + 33, k + 31, Blocks.planks, 5);
		world.setBlockMetadataWithNotify(i + 0, j + 33, k + 31, 5, 2);
		setBlock(world, i + 0, j + 34, k + 21, Blocks.torch, 5);
		world.setBlockMetadataWithNotify(i + 0, j + 34, k + 21, 5, 2);
		setBlock(world, i + 0, j + 48, k + 9, Blocks.planks, 5);
		world.setBlockMetadataWithNotify(i + 0, j + 48, k + 9, 5, 2);
		setBlock(world, i + 0, j + 48, k + 10, Blocks.planks, 5);
		world.setBlockMetadataWithNotify(i + 0, j + 48, k + 10, 5, 2);
		setBlock(world, i + 0, j + 48, k + 11, Blocks.planks, 5);
		world.setBlockMetadataWithNotify(i + 0, j + 48, k + 11, 5, 2);
		setBlock(world, i + 0, j + 48, k + 12, Blocks.planks, 5);
		world.setBlockMetadataWithNotify(i + 0, j + 48, k + 12, 5, 2);
		setBlock(world, i + 0, j + 48, k + 13, Blocks.planks, 5);
		world.setBlockMetadataWithNotify(i + 0, j + 48, k + 13, 5, 2);
		setBlock(world, i + 1, j + 19, k + 0, Blocks.log, 1);
		world.setBlockMetadataWithNotify(i + 1, j + 19, k + 0, 1, 2);
		setBlock(world, i + 1, j + 19, k + 1, Blocks.log, 1);
		world.setBlockMetadataWithNotify(i + 1, j + 19, k + 1, 1, 2);
		setBlock(world, i + 1, j + 20, k + 0, Blocks.log, 1);
		world.setBlockMetadataWithNotify(i + 1, j + 20, k + 0, 1, 2);
		setBlock(world, i + 1, j + 20, k + 1, Blocks.log, 1);
		world.setBlockMetadataWithNotify(i + 1, j + 20, k + 1, 1, 2);
		setBlock(world, i + 1, j + 20, k + 2, Blocks.log, 1);
		world.setBlockMetadataWithNotify(i + 1, j + 20, k + 2, 1, 2);
		setBlock(world, i + 1, j + 20, k + 3, Blocks.log, 1);
		world.setBlockMetadataWithNotify(i + 1, j + 20, k + 3, 1, 2);
		setBlock(world, i + 1, j + 20, k + 4, Blocks.planks, 5);
		world.setBlockMetadataWithNotify(i + 1, j + 20, k + 4, 5, 2);
		setBlock(world, i + 1, j + 20, k + 5, Blocks.planks, 5);
		world.setBlockMetadataWithNotify(i + 1, j + 20, k + 5, 5, 2);
		setBlock(world, i + 1, j + 20, k + 6, Blocks.planks, 5);
		world.setBlockMetadataWithNotify(i + 1, j + 20, k + 6, 5, 2);
		setBlock(world, i + 1, j + 20, k + 7, Blocks.planks, 5);
		world.setBlockMetadataWithNotify(i + 1, j + 20, k + 7, 5, 2);
		setBlock(world, i + 1, j + 20, k + 8, Blocks.planks, 5);
		world.setBlockMetadataWithNotify(i + 1, j + 20, k + 8, 5, 2);
		setBlock(world, i + 1, j + 21, k + 7, Blocks.spruce_stairs, 2);
		world.setBlockMetadataWithNotify(i + 1, j + 21, k + 7, 2, 2);
		setBlock(world, i + 1, j + 21, k + 8, Blocks.planks, 5);
		world.setBlockMetadataWithNotify(i + 1, j + 21, k + 8, 5, 2);
		setBlock(world, i + 1, j + 21, k + 9, Blocks.planks, 5);
		world.setBlockMetadataWithNotify(i + 1, j + 21, k + 9, 5, 2);
		setBlock(world, i + 1, j + 22, k + 8, Blocks.spruce_stairs, 2);
		world.setBlockMetadataWithNotify(i + 1, j + 22, k + 8, 2, 2);
		setBlock(world, i + 1, j + 22, k + 9, Blocks.planks, 5);
		world.setBlockMetadataWithNotify(i + 1, j + 22, k + 9, 5, 2);
		setBlock(world, i + 1, j + 22, k + 10, Blocks.planks, 5);
		world.setBlockMetadataWithNotify(i + 1, j + 22, k + 10, 5, 2);
		setBlock(world, i + 1, j + 23, k + 9, Blocks.spruce_stairs, 2);
		world.setBlockMetadataWithNotify(i + 1, j + 23, k + 9, 2, 2);
		setBlock(world, i + 1, j + 23, k + 10, Blocks.planks, 5);
		world.setBlockMetadataWithNotify(i + 1, j + 23, k + 10, 5, 2);
		setBlock(world, i + 1, j + 23, k + 11, Blocks.planks, 5);
		world.setBlockMetadataWithNotify(i + 1, j + 23, k + 11, 5, 2);
		setBlock(world, i + 1, j + 24, k + 10, Blocks.spruce_stairs, 2);
		world.setBlockMetadataWithNotify(i + 1, j + 24, k + 10, 2, 2);
		setBlock(world, i + 1, j + 24, k + 11, Blocks.planks, 5);
		world.setBlockMetadataWithNotify(i + 1, j + 24, k + 11, 5, 2);
		setBlock(world, i + 1, j + 24, k + 12, Blocks.planks, 5);
		world.setBlockMetadataWithNotify(i + 1, j + 24, k + 12, 5, 2);
		setBlock(world, i + 1, j + 25, k + 0, Blocks.log, 1);
		world.setBlockMetadataWithNotify(i + 1, j + 25, k + 0, 1, 2);
		setBlock(world, i + 1, j + 25, k + 1, Blocks.log, 1);
		world.setBlockMetadataWithNotify(i + 1, j + 25, k + 1, 1, 2);
		setBlock(world, i + 1, j + 25, k + 2, Blocks.log, 1);
		world.setBlockMetadataWithNotify(i + 1, j + 25, k + 2, 1, 2);
		setBlock(world, i + 1, j + 25, k + 3, Blocks.log, 1);
		world.setBlockMetadataWithNotify(i + 1, j + 25, k + 3, 1, 2);
		setBlock(world, i + 1, j + 25, k + 4, Blocks.log, 1);
		world.setBlockMetadataWithNotify(i + 1, j + 25, k + 4, 1, 2);
		setBlock(world, i + 1, j + 25, k + 5, Blocks.log, 1);
		world.setBlockMetadataWithNotify(i + 1, j + 25, k + 5, 1, 2);
		setBlock(world, i + 1, j + 25, k + 11, Blocks.spruce_stairs, 2);
		world.setBlockMetadataWithNotify(i + 1, j + 25, k + 11, 2, 2);
		setBlock(world, i + 1, j + 25, k + 12, Blocks.planks, 5);
		world.setBlockMetadataWithNotify(i + 1, j + 25, k + 12, 5, 2);
		setBlock(world, i + 1, j + 25, k + 13, Blocks.planks, 5);
		world.setBlockMetadataWithNotify(i + 1, j + 25, k + 13, 5, 2);
		setBlock(world, i + 1, j + 25, k + 27, Blocks.leaves, 7);
		world.setBlockMetadataWithNotify(i + 1, j + 25, k + 27, 7, 2);
		setBlock(world, i + 1, j + 25, k + 28, Blocks.leaves, 7);
		world.setBlockMetadataWithNotify(i + 1, j + 25, k + 28, 7, 2);
		setBlock(world, i + 1, j + 25, k + 29, Blocks.leaves, 7);
		world.setBlockMetadataWithNotify(i + 1, j + 25, k + 29, 7, 2);
		setBlock(world, i + 1, j + 25, k + 30, Blocks.leaves, 7);
		world.setBlockMetadataWithNotify(i + 1, j + 25, k + 30, 7, 2);
		setBlock(world, i + 1, j + 25, k + 31, Blocks.leaves, 7);
		world.setBlockMetadataWithNotify(i + 1, j + 25, k + 31, 7, 2);
		setBlock(world, i + 1, j + 26, k + 0, Blocks.log, 1);
		world.setBlockMetadataWithNotify(i + 1, j + 26, k + 0, 1, 2);
		setBlock(world, i + 1, j + 26, k + 1, Blocks.log, 1);
		world.setBlockMetadataWithNotify(i + 1, j + 26, k + 1, 1, 2);
		setBlock(world, i + 1, j + 26, k + 2, Blocks.log, 1);
		world.setBlockMetadataWithNotify(i + 1, j + 26, k + 2, 1, 2);
		setBlock(world, i + 1, j + 26, k + 3, Blocks.log, 1);
		world.setBlockMetadataWithNotify(i + 1, j + 26, k + 3, 1, 2);
		setBlock(world, i + 1, j + 26, k + 4, Blocks.log, 1);
		world.setBlockMetadataWithNotify(i + 1, j + 26, k + 4, 1, 2);
		setBlock(world, i + 1, j + 26, k + 12, Blocks.spruce_stairs, 2);
		world.setBlockMetadataWithNotify(i + 1, j + 26, k + 12, 2, 2);
		setBlock(world, i + 1, j + 26, k + 13, Blocks.planks, 5);
		world.setBlockMetadataWithNotify(i + 1, j + 26, k + 13, 5, 2);
		setBlock(world, i + 1, j + 26, k + 14, Blocks.planks, 5);
		world.setBlockMetadataWithNotify(i + 1, j + 26, k + 14, 5, 2);
		setBlock(world, i + 1, j + 26, k + 28, Blocks.leaves, 7);
		world.setBlockMetadataWithNotify(i + 1, j + 26, k + 28, 7, 2);
		setBlock(world, i + 1, j + 26, k + 29, Blocks.leaves, 7);
		world.setBlockMetadataWithNotify(i + 1, j + 26, k + 29, 7, 2);
		setBlock(world, i + 1, j + 26, k + 30, Blocks.leaves, 7);
		world.setBlockMetadataWithNotify(i + 1, j + 26, k + 30, 7, 2);
		setBlock(world, i + 1, j + 27, k + 0, Blocks.log, 1);
		world.setBlockMetadataWithNotify(i + 1, j + 27, k + 0, 1, 2);
		setBlock(world, i + 1, j + 27, k + 1, Blocks.log, 1);
		world.setBlockMetadataWithNotify(i + 1, j + 27, k + 1, 1, 2);
		setBlock(world, i + 1, j + 27, k + 2, Blocks.log, 1);
		world.setBlockMetadataWithNotify(i + 1, j + 27, k + 2, 1, 2);
		setBlock(world, i + 1, j + 27, k + 13, Blocks.spruce_stairs, 2);
		world.setBlockMetadataWithNotify(i + 1, j + 27, k + 13, 2, 2);
		setBlock(world, i + 1, j + 27, k + 14, Blocks.planks, 5);
		world.setBlockMetadataWithNotify(i + 1, j + 27, k + 14, 5, 2);
		setBlock(world, i + 1, j + 27, k + 15, Blocks.planks, 5);
		world.setBlockMetadataWithNotify(i + 1, j + 27, k + 15, 5, 2);
		setBlock(world, i + 1, j + 27, k + 29, Blocks.leaves, 7);
		world.setBlockMetadataWithNotify(i + 1, j + 27, k + 29, 7, 2);
		setBlock(world, i + 1, j + 28, k + 14, Blocks.spruce_stairs, 2);
		world.setBlockMetadataWithNotify(i + 1, j + 28, k + 14, 2, 2);
		setBlock(world, i + 1, j + 28, k + 15, Blocks.planks, 5);
		world.setBlockMetadataWithNotify(i + 1, j + 28, k + 15, 5, 2);
		setBlock(world, i + 1, j + 28, k + 16, Blocks.planks, 5);
		world.setBlockMetadataWithNotify(i + 1, j + 28, k + 16, 5, 2);
		setBlock(world, i + 1, j + 29, k + 15, Blocks.spruce_stairs, 2);
		world.setBlockMetadataWithNotify(i + 1, j + 29, k + 15, 2, 2);
		setBlock(world, i + 1, j + 29, k + 16, Blocks.planks, 5);
		world.setBlockMetadataWithNotify(i + 1, j + 29, k + 16, 5, 2);
		setBlock(world, i + 1, j + 29, k + 17, Blocks.planks, 5);
		world.setBlockMetadataWithNotify(i + 1, j + 29, k + 17, 5, 2);
		setBlock(world, i + 1, j + 30, k + 16, Blocks.spruce_stairs, 2);
		world.setBlockMetadataWithNotify(i + 1, j + 30, k + 16, 2, 2);
		setBlock(world, i + 1, j + 30, k + 17, Blocks.planks, 5);
		world.setBlockMetadataWithNotify(i + 1, j + 30, k + 17, 5, 2);
		setBlock(world, i + 1, j + 30, k + 18, Blocks.planks, 5);
		world.setBlockMetadataWithNotify(i + 1, j + 30, k + 18, 5, 2);
		setBlock(world, i + 1, j + 31, k + 17, Blocks.spruce_stairs, 2);
		world.setBlockMetadataWithNotify(i + 1, j + 31, k + 17, 2, 2);
		setBlock(world, i + 1, j + 31, k + 18, Blocks.planks, 5);
		world.setBlockMetadataWithNotify(i + 1, j + 31, k + 18, 5, 2);
		setBlock(world, i + 1, j + 31, k + 19, Blocks.planks, 5);
		world.setBlockMetadataWithNotify(i + 1, j + 31, k + 19, 5, 2);
		setBlock(world, i + 1, j + 32, k + 18, Blocks.spruce_stairs, 2);
		world.setBlockMetadataWithNotify(i + 1, j + 32, k + 18, 2, 2);
		setBlock(world, i + 1, j + 32, k + 19, Blocks.planks, 5);
		world.setBlockMetadataWithNotify(i + 1, j + 32, k + 19, 5, 2);
		setBlock(world, i + 1, j + 32, k + 20, Blocks.planks, 5);
		world.setBlockMetadataWithNotify(i + 1, j + 32, k + 20, 5, 2);
		setBlock(world, i + 1, j + 33, k + 19, Blocks.spruce_stairs, 2);
		world.setBlockMetadataWithNotify(i + 1, j + 33, k + 19, 2, 2);
		setBlock(world, i + 1, j + 33, k + 20, Blocks.planks, 5);
		world.setBlockMetadataWithNotify(i + 1, j + 33, k + 20, 5, 2);
		setBlock(world, i + 1, j + 33, k + 21, Blocks.planks, 5);
		world.setBlockMetadataWithNotify(i + 1, j + 33, k + 21, 5, 2);
		setBlock(world, i + 1, j + 33, k + 22, Blocks.planks, 5);
		world.setBlockMetadataWithNotify(i + 1, j + 33, k + 22, 5, 2);
		setBlock(world, i + 1, j + 33, k + 23, Blocks.planks, 5);
		world.setBlockMetadataWithNotify(i + 1, j + 33, k + 23, 5, 2);
		setBlock(world, i + 1, j + 33, k + 24, Blocks.planks, 5);
		world.setBlockMetadataWithNotify(i + 1, j + 33, k + 24, 5, 2);
		setBlock(world, i + 1, j + 33, k + 25, Blocks.planks, 5);
		world.setBlockMetadataWithNotify(i + 1, j + 33, k + 25, 5, 2);
		setBlock(world, i + 1, j + 33, k + 26, Blocks.planks, 5);
		world.setBlockMetadataWithNotify(i + 1, j + 33, k + 26, 5, 2);
		setBlock(world, i + 1, j + 33, k + 27, Blocks.planks, 5);
		world.setBlockMetadataWithNotify(i + 1, j + 33, k + 27, 5, 2);
		setBlock(world, i + 1, j + 33, k + 28, Blocks.planks, 5);
		world.setBlockMetadataWithNotify(i + 1, j + 33, k + 28, 5, 2);
		setBlock(world, i + 1, j + 33, k + 29, Blocks.planks, 5);
		world.setBlockMetadataWithNotify(i + 1, j + 33, k + 29, 5, 2);
		setBlock(world, i + 1, j + 33, k + 30, Blocks.planks, 5);
		world.setBlockMetadataWithNotify(i + 1, j + 33, k + 30, 5, 2);
		setBlock(world, i + 1, j + 48, k + 8, Blocks.planks, 5);
		world.setBlockMetadataWithNotify(i + 1, j + 48, k + 8, 5, 2);
		setBlock(world, i + 1, j + 48, k + 9, Blocks.planks, 5);
		world.setBlockMetadataWithNotify(i + 1, j + 48, k + 9, 5, 2);
		setBlock(world, i + 1, j + 48, k + 10, Blocks.planks, 5);
		world.setBlockMetadataWithNotify(i + 1, j + 48, k + 10, 5, 2);
		setBlock(world, i + 1, j + 48, k + 11, Blocks.planks, 5);
		world.setBlockMetadataWithNotify(i + 1, j + 48, k + 11, 5, 2);
		setBlock(world, i + 1, j + 48, k + 12, Blocks.planks, 5);
		world.setBlockMetadataWithNotify(i + 1, j + 48, k + 12, 5, 2);
		setBlock(world, i + 2, j + 19, k + 0, Blocks.log, 1);
		world.setBlockMetadataWithNotify(i + 2, j + 19, k + 0, 1, 2);
		setBlock(world, i + 2, j + 19, k + 1, Blocks.log, 1);
		world.setBlockMetadataWithNotify(i + 2, j + 19, k + 1, 1, 2);
		setBlock(world, i + 2, j + 19, k + 2, Blocks.log, 1);
		world.setBlockMetadataWithNotify(i + 2, j + 19, k + 2, 1, 2);
		setBlock(world, i + 2, j + 20, k + 0, Blocks.planks, 5);
		world.setBlockMetadataWithNotify(i + 2, j + 20, k + 0, 5, 2);
		setBlock(world, i + 2, j + 20, k + 1, Blocks.planks, 5);
		world.setBlockMetadataWithNotify(i + 2, j + 20, k + 1, 5, 2);
		setBlock(world, i + 2, j + 20, k + 2, Blocks.log, 1);
		world.setBlockMetadataWithNotify(i + 2, j + 20, k + 2, 1, 2);
		setBlock(world, i + 2, j + 20, k + 3, Blocks.log, 1);
		world.setBlockMetadataWithNotify(i + 2, j + 20, k + 3, 1, 2);
		setBlock(world, i + 2, j + 20, k + 4, Blocks.planks, 5);
		world.setBlockMetadataWithNotify(i + 2, j + 20, k + 4, 5, 2);
		setBlock(world, i + 2, j + 20, k + 5, Blocks.planks, 5);
		world.setBlockMetadataWithNotify(i + 2, j + 20, k + 5, 5, 2);
		setBlock(world, i + 2, j + 20, k + 6, Blocks.planks, 5);
		world.setBlockMetadataWithNotify(i + 2, j + 20, k + 6, 5, 2);
		setBlock(world, i + 2, j + 20, k + 7, Blocks.planks, 5);
		world.setBlockMetadataWithNotify(i + 2, j + 20, k + 7, 5, 2);
		setBlock(world, i + 2, j + 20, k + 8, Blocks.planks, 5);
		world.setBlockMetadataWithNotify(i + 2, j + 20, k + 8, 5, 2);
		setBlock(world, i + 2, j + 21, k + 7, Blocks.spruce_stairs, 2);
		world.setBlockMetadataWithNotify(i + 2, j + 21, k + 7, 2, 2);
		setBlock(world, i + 2, j + 21, k + 8, Blocks.planks, 5);
		world.setBlockMetadataWithNotify(i + 2, j + 21, k + 8, 5, 2);
		setBlock(world, i + 2, j + 21, k + 9, Blocks.planks, 5);
		world.setBlockMetadataWithNotify(i + 2, j + 21, k + 9, 5, 2);
		setBlock(world, i + 2, j + 22, k + 8, Blocks.spruce_stairs, 2);
		world.setBlockMetadataWithNotify(i + 2, j + 22, k + 8, 2, 2);
		setBlock(world, i + 2, j + 22, k + 9, Blocks.planks, 5);
		world.setBlockMetadataWithNotify(i + 2, j + 22, k + 9, 5, 2);
		setBlock(world, i + 2, j + 22, k + 10, Blocks.planks, 5);
		world.setBlockMetadataWithNotify(i + 2, j + 22, k + 10, 5, 2);
		setBlock(world, i + 2, j + 23, k + 9, Blocks.spruce_stairs, 2);
		world.setBlockMetadataWithNotify(i + 2, j + 23, k + 9, 2, 2);
		setBlock(world, i + 2, j + 23, k + 10, Blocks.planks, 5);
		world.setBlockMetadataWithNotify(i + 2, j + 23, k + 10, 5, 2);
		setBlock(world, i + 2, j + 23, k + 11, Blocks.planks, 5);
		world.setBlockMetadataWithNotify(i + 2, j + 23, k + 11, 5, 2);
		setBlock(world, i + 2, j + 24, k + 10, Blocks.spruce_stairs, 2);
		world.setBlockMetadataWithNotify(i + 2, j + 24, k + 10, 2, 2);
		setBlock(world, i + 2, j + 24, k + 11, Blocks.planks, 5);
		world.setBlockMetadataWithNotify(i + 2, j + 24, k + 11, 5, 2);
		setBlock(world, i + 2, j + 24, k + 12, Blocks.planks, 5);
		world.setBlockMetadataWithNotify(i + 2, j + 24, k + 12, 5, 2);
		setBlock(world, i + 2, j + 25, k + 1, Blocks.log, 1);
		world.setBlockMetadataWithNotify(i + 2, j + 25, k + 1, 1, 2);
		setBlock(world, i + 2, j + 25, k + 2, Blocks.log, 1);
		world.setBlockMetadataWithNotify(i + 2, j + 25, k + 2, 1, 2);
		setBlock(world, i + 2, j + 25, k + 3, Blocks.log, 1);
		world.setBlockMetadataWithNotify(i + 2, j + 25, k + 3, 1, 2);
		setBlock(world, i + 2, j + 25, k + 4, Blocks.log, 1);
		world.setBlockMetadataWithNotify(i + 2, j + 25, k + 4, 1, 2);
		setBlock(world, i + 2, j + 25, k + 5, Blocks.log, 1);
		world.setBlockMetadataWithNotify(i + 2, j + 25, k + 5, 1, 2);
		setBlock(world, i + 2, j + 25, k + 11, Blocks.spruce_stairs, 2);
		world.setBlockMetadataWithNotify(i + 2, j + 25, k + 11, 2, 2);
		setBlock(world, i + 2, j + 25, k + 12, Blocks.planks, 5);
		world.setBlockMetadataWithNotify(i + 2, j + 25, k + 12, 5, 2);
		setBlock(world, i + 2, j + 25, k + 13, Blocks.planks, 5);
		world.setBlockMetadataWithNotify(i + 2, j + 25, k + 13, 5, 2);
		setBlock(world, i + 2, j + 25, k + 27, Blocks.leaves, 7);
		world.setBlockMetadataWithNotify(i + 2, j + 25, k + 27, 7, 2);
		setBlock(world, i + 2, j + 25, k + 28, Blocks.leaves, 7);
		world.setBlockMetadataWithNotify(i + 2, j + 25, k + 28, 7, 2);
		setBlock(world, i + 2, j + 25, k + 29, Blocks.log, 3);
		world.setBlockMetadataWithNotify(i + 2, j + 25, k + 29, 3, 2);
		setBlock(world, i + 2, j + 25, k + 30, Blocks.leaves, 7);
		world.setBlockMetadataWithNotify(i + 2, j + 25, k + 30, 7, 2);
		setBlock(world, i + 2, j + 25, k + 31, Blocks.leaves, 7);
		world.setBlockMetadataWithNotify(i + 2, j + 25, k + 31, 7, 2);
		setBlock(world, i + 2, j + 26, k + 0, Blocks.log, 1);
		world.setBlockMetadataWithNotify(i + 2, j + 26, k + 0, 1, 2);
		setBlock(world, i + 2, j + 26, k + 1, Blocks.log, 1);
		world.setBlockMetadataWithNotify(i + 2, j + 26, k + 1, 1, 2);
		setBlock(world, i + 2, j + 26, k + 2, Blocks.log, 1);
		world.setBlockMetadataWithNotify(i + 2, j + 26, k + 2, 1, 2);
		setBlock(world, i + 2, j + 26, k + 3, Blocks.log, 1);
		world.setBlockMetadataWithNotify(i + 2, j + 26, k + 3, 1, 2);
		setBlock(world, i + 2, j + 26, k + 4, Blocks.log, 1);
		world.setBlockMetadataWithNotify(i + 2, j + 26, k + 4, 1, 2);
		setBlock(world, i + 2, j + 26, k + 12, Blocks.spruce_stairs, 2);
		world.setBlockMetadataWithNotify(i + 2, j + 26, k + 12, 2, 2);
		setBlock(world, i + 2, j + 26, k + 13, Blocks.planks, 5);
		world.setBlockMetadataWithNotify(i + 2, j + 26, k + 13, 5, 2);
		setBlock(world, i + 2, j + 26, k + 14, Blocks.planks, 5);
		world.setBlockMetadataWithNotify(i + 2, j + 26, k + 14, 5, 2);
		setBlock(world, i + 2, j + 26, k + 27, Blocks.leaves, 7);
		world.setBlockMetadataWithNotify(i + 2, j + 26, k + 27, 7, 2);
		setBlock(world, i + 2, j + 26, k + 28, Blocks.leaves, 7);
		world.setBlockMetadataWithNotify(i + 2, j + 26, k + 28, 7, 2);
		setBlock(world, i + 2, j + 26, k + 29, Blocks.leaves, 7);
		world.setBlockMetadataWithNotify(i + 2, j + 26, k + 29, 7, 2);
		setBlock(world, i + 2, j + 26, k + 30, Blocks.leaves, 7);
		world.setBlockMetadataWithNotify(i + 2, j + 26, k + 30, 7, 2);
		setBlock(world, i + 2, j + 26, k + 31, Blocks.leaves, 7);
		world.setBlockMetadataWithNotify(i + 2, j + 26, k + 31, 7, 2);
		setBlock(world, i + 2, j + 27, k + 0, Blocks.log, 1);
		world.setBlockMetadataWithNotify(i + 2, j + 27, k + 0, 1, 2);
		setBlock(world, i + 2, j + 27, k + 1, Blocks.log, 1);
		world.setBlockMetadataWithNotify(i + 2, j + 27, k + 1, 1, 2);
		setBlock(world, i + 2, j + 27, k + 2, Blocks.log, 1);
		world.setBlockMetadataWithNotify(i + 2, j + 27, k + 2, 1, 2);
		setBlock(world, i + 2, j + 27, k + 13, Blocks.spruce_stairs, 2);
		world.setBlockMetadataWithNotify(i + 2, j + 27, k + 13, 2, 2);
		setBlock(world, i + 2, j + 27, k + 14, Blocks.planks, 5);
		world.setBlockMetadataWithNotify(i + 2, j + 27, k + 14, 5, 2);
		setBlock(world, i + 2, j + 27, k + 15, Blocks.planks, 5);
		world.setBlockMetadataWithNotify(i + 2, j + 27, k + 15, 5, 2);
		setBlock(world, i + 2, j + 27, k + 28, Blocks.leaves, 7);
		world.setBlockMetadataWithNotify(i + 2, j + 27, k + 28, 7, 2);
		setBlock(world, i + 2, j + 27, k + 29, Blocks.leaves, 7);
		world.setBlockMetadataWithNotify(i + 2, j + 27, k + 29, 7, 2);
		setBlock(world, i + 2, j + 27, k + 30, Blocks.leaves, 7);
		world.setBlockMetadataWithNotify(i + 2, j + 27, k + 30, 7, 2);
		setBlock(world, i + 2, j + 28, k + 14, Blocks.spruce_stairs, 2);
		world.setBlockMetadataWithNotify(i + 2, j + 28, k + 14, 2, 2);
		setBlock(world, i + 2, j + 28, k + 15, Blocks.planks, 5);
		world.setBlockMetadataWithNotify(i + 2, j + 28, k + 15, 5, 2);
		setBlock(world, i + 2, j + 28, k + 16, Blocks.planks, 5);
		world.setBlockMetadataWithNotify(i + 2, j + 28, k + 16, 5, 2);
		setBlock(world, i + 2, j + 28, k + 29, Blocks.leaves, 7);
		world.setBlockMetadataWithNotify(i + 2, j + 28, k + 29, 7, 2);
		setBlock(world, i + 2, j + 29, k + 15, Blocks.spruce_stairs, 2);
		world.setBlockMetadataWithNotify(i + 2, j + 29, k + 15, 2, 2);
		setBlock(world, i + 2, j + 29, k + 16, Blocks.planks, 5);
		world.setBlockMetadataWithNotify(i + 2, j + 29, k + 16, 5, 2);
		setBlock(world, i + 2, j + 29, k + 17, Blocks.planks, 5);
		world.setBlockMetadataWithNotify(i + 2, j + 29, k + 17, 5, 2);
		setBlock(world, i + 2, j + 30, k + 16, Blocks.spruce_stairs, 2);
		world.setBlockMetadataWithNotify(i + 2, j + 30, k + 16, 2, 2);
		setBlock(world, i + 2, j + 30, k + 17, Blocks.planks, 5);
		world.setBlockMetadataWithNotify(i + 2, j + 30, k + 17, 5, 2);
		setBlock(world, i + 2, j + 30, k + 18, Blocks.planks, 5);
		world.setBlockMetadataWithNotify(i + 2, j + 30, k + 18, 5, 2);
		setBlock(world, i + 2, j + 31, k + 17, Blocks.spruce_stairs, 2);
		world.setBlockMetadataWithNotify(i + 2, j + 31, k + 17, 2, 2);
		setBlock(world, i + 2, j + 31, k + 18, Blocks.planks, 5);
		world.setBlockMetadataWithNotify(i + 2, j + 31, k + 18, 5, 2);
		setBlock(world, i + 2, j + 31, k + 19, Blocks.planks, 5);
		world.setBlockMetadataWithNotify(i + 2, j + 31, k + 19, 5, 2);
		setBlock(world, i + 2, j + 32, k + 18, Blocks.spruce_stairs, 2);
		world.setBlockMetadataWithNotify(i + 2, j + 32, k + 18, 2, 2);
		setBlock(world, i + 2, j + 32, k + 19, Blocks.planks, 5);
		world.setBlockMetadataWithNotify(i + 2, j + 32, k + 19, 5, 2);
		setBlock(world, i + 2, j + 32, k + 20, Blocks.planks, 5);
		world.setBlockMetadataWithNotify(i + 2, j + 32, k + 20, 5, 2);
		setBlock(world, i + 2, j + 33, k + 19, Blocks.spruce_stairs, 2);
		world.setBlockMetadataWithNotify(i + 2, j + 33, k + 19, 2, 2);
		setBlock(world, i + 2, j + 33, k + 20, Blocks.planks, 5);
		world.setBlockMetadataWithNotify(i + 2, j + 33, k + 20, 5, 2);
		setBlock(world, i + 2, j + 33, k + 21, Blocks.planks, 5);
		world.setBlockMetadataWithNotify(i + 2, j + 33, k + 21, 5, 2);
		setBlock(world, i + 2, j + 33, k + 22, Blocks.planks, 5);
		world.setBlockMetadataWithNotify(i + 2, j + 33, k + 22, 5, 2);
		setBlock(world, i + 2, j + 33, k + 23, Blocks.planks, 5);
		world.setBlockMetadataWithNotify(i + 2, j + 33, k + 23, 5, 2);
		setBlock(world, i + 2, j + 33, k + 24, Blocks.planks, 5);
		world.setBlockMetadataWithNotify(i + 2, j + 33, k + 24, 5, 2);
		setBlock(world, i + 2, j + 33, k + 25, Blocks.planks, 5);
		world.setBlockMetadataWithNotify(i + 2, j + 33, k + 25, 5, 2);
		setBlock(world, i + 2, j + 33, k + 26, Blocks.planks, 5);
		world.setBlockMetadataWithNotify(i + 2, j + 33, k + 26, 5, 2);
		setBlock(world, i + 2, j + 33, k + 27, Blocks.planks, 5);
		world.setBlockMetadataWithNotify(i + 2, j + 33, k + 27, 5, 2);
		setBlock(world, i + 2, j + 33, k + 28, Blocks.planks, 5);
		world.setBlockMetadataWithNotify(i + 2, j + 33, k + 28, 5, 2);
		setBlock(world, i + 2, j + 33, k + 29, Blocks.planks, 5);
		world.setBlockMetadataWithNotify(i + 2, j + 33, k + 29, 5, 2);
		setBlock(world, i + 2, j + 34, k + 29, Blocks.torch, 5);
		world.setBlockMetadataWithNotify(i + 2, j + 34, k + 29, 5, 2);
		setBlock(world, i + 2, j + 48, k + 7, Blocks.planks, 5);
		world.setBlockMetadataWithNotify(i + 2, j + 48, k + 7, 5, 2);
		setBlock(world, i + 2, j + 48, k + 8, Blocks.planks, 5);
		world.setBlockMetadataWithNotify(i + 2, j + 48, k + 8, 5, 2);
		setBlock(world, i + 2, j + 48, k + 9, Blocks.planks, 5);
		world.setBlockMetadataWithNotify(i + 2, j + 48, k + 9, 5, 2);
		setBlock(world, i + 2, j + 48, k + 10, Blocks.planks, 5);
		world.setBlockMetadataWithNotify(i + 2, j + 48, k + 10, 5, 2);
		setBlock(world, i + 2, j + 48, k + 11, Blocks.planks, 5);
		world.setBlockMetadataWithNotify(i + 2, j + 48, k + 11, 5, 2);
		setBlock(world, i + 2, j + 49, k + 7, Blocks.torch, 5);
		world.setBlockMetadataWithNotify(i + 2, j + 49, k + 7, 5, 2);
		setBlock(world, i + 2, j + 49, k + 11, Blocks.torch, 5);
		world.setBlockMetadataWithNotify(i + 2, j + 49, k + 11, 5, 2);
		setBlock(world, i + 3, j + 19, k + 0, Blocks.log, 1);
		world.setBlockMetadataWithNotify(i + 3, j + 19, k + 0, 1, 2);
		setBlock(world, i + 3, j + 19, k + 1, Blocks.log, 1);
		world.setBlockMetadataWithNotify(i + 3, j + 19, k + 1, 1, 2);
		setBlock(world, i + 3, j + 20, k + 0, Blocks.planks, 5);
		world.setBlockMetadataWithNotify(i + 3, j + 20, k + 0, 5, 2);
		setBlock(world, i + 3, j + 20, k + 1, Blocks.planks, 5);
		world.setBlockMetadataWithNotify(i + 3, j + 20, k + 1, 5, 2);
		setBlock(world, i + 3, j + 20, k + 2, Blocks.log, 1);
		world.setBlockMetadataWithNotify(i + 3, j + 20, k + 2, 1, 2);
		setBlock(world, i + 3, j + 20, k + 3, Blocks.log, 1);
		world.setBlockMetadataWithNotify(i + 3, j + 20, k + 3, 1, 2);
		setBlock(world, i + 3, j + 20, k + 4, Blocks.planks, 5);
		world.setBlockMetadataWithNotify(i + 3, j + 20, k + 4, 5, 2);
		setBlock(world, i + 3, j + 20, k + 5, Blocks.planks, 5);
		world.setBlockMetadataWithNotify(i + 3, j + 20, k + 5, 5, 2);
		setBlock(world, i + 3, j + 20, k + 6, Blocks.planks, 5);
		world.setBlockMetadataWithNotify(i + 3, j + 20, k + 6, 5, 2);
		setBlock(world, i + 3, j + 20, k + 7, Blocks.planks, 5);
		world.setBlockMetadataWithNotify(i + 3, j + 20, k + 7, 5, 2);
		setBlock(world, i + 3, j + 20, k + 8, Blocks.planks, 5);
		world.setBlockMetadataWithNotify(i + 3, j + 20, k + 8, 5, 2);
		setBlock(world, i + 3, j + 21, k + 7, Blocks.spruce_stairs, 2);
		world.setBlockMetadataWithNotify(i + 3, j + 21, k + 7, 2, 2);
		setBlock(world, i + 3, j + 21, k + 8, Blocks.planks, 5);
		world.setBlockMetadataWithNotify(i + 3, j + 21, k + 8, 5, 2);
		setBlock(world, i + 3, j + 21, k + 9, Blocks.planks, 5);
		world.setBlockMetadataWithNotify(i + 3, j + 21, k + 9, 5, 2);
		setBlock(world, i + 3, j + 22, k + 8, Blocks.spruce_stairs, 2);
		world.setBlockMetadataWithNotify(i + 3, j + 22, k + 8, 2, 2);
		setBlock(world, i + 3, j + 22, k + 9, Blocks.planks, 5);
		world.setBlockMetadataWithNotify(i + 3, j + 22, k + 9, 5, 2);
		setBlock(world, i + 3, j + 22, k + 10, Blocks.planks, 5);
		world.setBlockMetadataWithNotify(i + 3, j + 22, k + 10, 5, 2);
		setBlock(world, i + 3, j + 23, k + 9, Blocks.spruce_stairs, 2);
		world.setBlockMetadataWithNotify(i + 3, j + 23, k + 9, 2, 2);
		setBlock(world, i + 3, j + 23, k + 10, Blocks.planks, 5);
		world.setBlockMetadataWithNotify(i + 3, j + 23, k + 10, 5, 2);
		setBlock(world, i + 3, j + 23, k + 11, Blocks.planks, 5);
		world.setBlockMetadataWithNotify(i + 3, j + 23, k + 11, 5, 2);
		setBlock(world, i + 3, j + 24, k + 10, Blocks.spruce_stairs, 2);
		world.setBlockMetadataWithNotify(i + 3, j + 24, k + 10, 2, 2);
		setBlock(world, i + 3, j + 24, k + 11, Blocks.planks, 5);
		world.setBlockMetadataWithNotify(i + 3, j + 24, k + 11, 5, 2);
		setBlock(world, i + 3, j + 24, k + 12, Blocks.planks, 5);
		world.setBlockMetadataWithNotify(i + 3, j + 24, k + 12, 5, 2);
		setBlock(world, i + 3, j + 24, k + 30, Blocks.log, 3);
		world.setBlockMetadataWithNotify(i + 3, j + 24, k + 30, 3, 2);
		setBlock(world, i + 3, j + 25, k + 1, Blocks.log, 1);
		world.setBlockMetadataWithNotify(i + 3, j + 25, k + 1, 1, 2);
		setBlock(world, i + 3, j + 25, k + 2, Blocks.log, 1);
		world.setBlockMetadataWithNotify(i + 3, j + 25, k + 2, 1, 2);
		setBlock(world, i + 3, j + 25, k + 3, Blocks.log, 1);
		world.setBlockMetadataWithNotify(i + 3, j + 25, k + 3, 1, 2);
		setBlock(world, i + 3, j + 25, k + 4, Blocks.log, 1);
		world.setBlockMetadataWithNotify(i + 3, j + 25, k + 4, 1, 2);
		setBlock(world, i + 3, j + 25, k + 5, Blocks.log, 1);
		world.setBlockMetadataWithNotify(i + 3, j + 25, k + 5, 1, 2);
		setBlock(world, i + 3, j + 25, k + 11, Blocks.spruce_stairs, 2);
		world.setBlockMetadataWithNotify(i + 3, j + 25, k + 11, 2, 2);
		setBlock(world, i + 3, j + 25, k + 12, Blocks.planks, 5);
		world.setBlockMetadataWithNotify(i + 3, j + 25, k + 12, 5, 2);
		setBlock(world, i + 3, j + 25, k + 13, Blocks.planks, 5);
		world.setBlockMetadataWithNotify(i + 3, j + 25, k + 13, 5, 2);
		setBlock(world, i + 3, j + 25, k + 27, Blocks.leaves, 7);
		world.setBlockMetadataWithNotify(i + 3, j + 25, k + 27, 7, 2);
		setBlock(world, i + 3, j + 25, k + 28, Blocks.leaves, 7);
		world.setBlockMetadataWithNotify(i + 3, j + 25, k + 28, 7, 2);
		setBlock(world, i + 3, j + 25, k + 29, Blocks.leaves, 7);
		world.setBlockMetadataWithNotify(i + 3, j + 25, k + 29, 7, 2);
		setBlock(world, i + 3, j + 25, k + 30, Blocks.leaves, 7);
		world.setBlockMetadataWithNotify(i + 3, j + 25, k + 30, 7, 2);
		setBlock(world, i + 3, j + 25, k + 31, Blocks.leaves, 7);
		world.setBlockMetadataWithNotify(i + 3, j + 25, k + 31, 7, 2);
		setBlock(world, i + 3, j + 26, k + 0, Blocks.log, 1);
		world.setBlockMetadataWithNotify(i + 3, j + 26, k + 0, 1, 2);
		setBlock(world, i + 3, j + 26, k + 1, Blocks.log, 1);
		world.setBlockMetadataWithNotify(i + 3, j + 26, k + 1, 1, 2);
		setBlock(world, i + 3, j + 26, k + 2, Blocks.log, 1);
		world.setBlockMetadataWithNotify(i + 3, j + 26, k + 2, 1, 2);
		setBlock(world, i + 3, j + 26, k + 3, Blocks.log, 1);
		world.setBlockMetadataWithNotify(i + 3, j + 26, k + 3, 1, 2);
		setBlock(world, i + 3, j + 26, k + 4, Blocks.log, 1);
		world.setBlockMetadataWithNotify(i + 3, j + 26, k + 4, 1, 2);
		setBlock(world, i + 3, j + 26, k + 12, Blocks.spruce_stairs, 2);
		world.setBlockMetadataWithNotify(i + 3, j + 26, k + 12, 2, 2);
		setBlock(world, i + 3, j + 26, k + 13, Blocks.planks, 5);
		world.setBlockMetadataWithNotify(i + 3, j + 26, k + 13, 5, 2);
		setBlock(world, i + 3, j + 26, k + 14, Blocks.planks, 5);
		world.setBlockMetadataWithNotify(i + 3, j + 26, k + 14, 5, 2);
		setBlock(world, i + 3, j + 26, k + 28, Blocks.leaves, 7);
		world.setBlockMetadataWithNotify(i + 3, j + 26, k + 28, 7, 2);
		setBlock(world, i + 3, j + 26, k + 29, Blocks.leaves, 7);
		world.setBlockMetadataWithNotify(i + 3, j + 26, k + 29, 7, 2);
		setBlock(world, i + 3, j + 26, k + 30, Blocks.leaves, 7);
		world.setBlockMetadataWithNotify(i + 3, j + 26, k + 30, 7, 2);
		setBlock(world, i + 3, j + 27, k + 0, Blocks.log, 1);
		world.setBlockMetadataWithNotify(i + 3, j + 27, k + 0, 1, 2);
		setBlock(world, i + 3, j + 27, k + 1, Blocks.log, 1);
		world.setBlockMetadataWithNotify(i + 3, j + 27, k + 1, 1, 2);
		setBlock(world, i + 3, j + 27, k + 2, Blocks.log, 1);
		world.setBlockMetadataWithNotify(i + 3, j + 27, k + 2, 1, 2);
		setBlock(world, i + 3, j + 27, k + 13, Blocks.spruce_stairs, 2);
		world.setBlockMetadataWithNotify(i + 3, j + 27, k + 13, 2, 2);
		setBlock(world, i + 3, j + 27, k + 14, Blocks.planks, 5);
		world.setBlockMetadataWithNotify(i + 3, j + 27, k + 14, 5, 2);
		setBlock(world, i + 3, j + 27, k + 15, Blocks.planks, 5);
		world.setBlockMetadataWithNotify(i + 3, j + 27, k + 15, 5, 2);
		setBlock(world, i + 3, j + 27, k + 29, Blocks.leaves, 7);
		world.setBlockMetadataWithNotify(i + 3, j + 27, k + 29, 7, 2);
		setBlock(world, i + 3, j + 28, k + 14, Blocks.spruce_stairs, 2);
		world.setBlockMetadataWithNotify(i + 3, j + 28, k + 14, 2, 2);
		setBlock(world, i + 3, j + 28, k + 15, Blocks.planks, 5);
		world.setBlockMetadataWithNotify(i + 3, j + 28, k + 15, 5, 2);
		setBlock(world, i + 3, j + 28, k + 16, Blocks.planks, 5);
		world.setBlockMetadataWithNotify(i + 3, j + 28, k + 16, 5, 2);
		setBlock(world, i + 3, j + 29, k + 15, Blocks.spruce_stairs, 2);
		world.setBlockMetadataWithNotify(i + 3, j + 29, k + 15, 2, 2);
		setBlock(world, i + 3, j + 29, k + 16, Blocks.planks, 5);
		world.setBlockMetadataWithNotify(i + 3, j + 29, k + 16, 5, 2);
		setBlock(world, i + 3, j + 29, k + 17, Blocks.planks, 5);
		world.setBlockMetadataWithNotify(i + 3, j + 29, k + 17, 5, 2);
		setBlock(world, i + 3, j + 30, k + 16, Blocks.spruce_stairs, 2);
		world.setBlockMetadataWithNotify(i + 3, j + 30, k + 16, 2, 2);
		setBlock(world, i + 3, j + 30, k + 17, Blocks.planks, 5);
		world.setBlockMetadataWithNotify(i + 3, j + 30, k + 17, 5, 2);
		setBlock(world, i + 3, j + 30, k + 18, Blocks.planks, 5);
		world.setBlockMetadataWithNotify(i + 3, j + 30, k + 18, 5, 2);
		setBlock(world, i + 3, j + 31, k + 17, Blocks.spruce_stairs, 2);
		world.setBlockMetadataWithNotify(i + 3, j + 31, k + 17, 2, 2);
		setBlock(world, i + 3, j + 31, k + 18, Blocks.planks, 5);
		world.setBlockMetadataWithNotify(i + 3, j + 31, k + 18, 5, 2);
		setBlock(world, i + 3, j + 31, k + 19, Blocks.planks, 5);
		world.setBlockMetadataWithNotify(i + 3, j + 31, k + 19, 5, 2);
		setBlock(world, i + 3, j + 32, k + 18, Blocks.spruce_stairs, 2);
		world.setBlockMetadataWithNotify(i + 3, j + 32, k + 18, 2, 2);
		setBlock(world, i + 3, j + 32, k + 19, Blocks.planks, 5);
		world.setBlockMetadataWithNotify(i + 3, j + 32, k + 19, 5, 2);
		setBlock(world, i + 3, j + 32, k + 20, Blocks.planks, 5);
		world.setBlockMetadataWithNotify(i + 3, j + 32, k + 20, 5, 2);
		setBlock(world, i + 3, j + 33, k + 19, Blocks.spruce_stairs, 2);
		world.setBlockMetadataWithNotify(i + 3, j + 33, k + 19, 2, 2);
		setBlock(world, i + 3, j + 33, k + 20, Blocks.planks, 5);
		world.setBlockMetadataWithNotify(i + 3, j + 33, k + 20, 5, 2);
		setBlock(world, i + 3, j + 33, k + 21, Blocks.planks, 5);
		world.setBlockMetadataWithNotify(i + 3, j + 33, k + 21, 5, 2);
		setBlock(world, i + 3, j + 33, k + 22, Blocks.planks, 5);
		world.setBlockMetadataWithNotify(i + 3, j + 33, k + 22, 5, 2);
		setBlock(world, i + 3, j + 33, k + 23, Blocks.planks, 5);
		world.setBlockMetadataWithNotify(i + 3, j + 33, k + 23, 5, 2);
		setBlock(world, i + 3, j + 33, k + 24, Blocks.planks, 5);
		world.setBlockMetadataWithNotify(i + 3, j + 33, k + 24, 5, 2);
		setBlock(world, i + 3, j + 33, k + 25, Blocks.planks, 5);
		world.setBlockMetadataWithNotify(i + 3, j + 33, k + 25, 5, 2);
		setBlock(world, i + 3, j + 33, k + 26, Blocks.planks, 5);
		world.setBlockMetadataWithNotify(i + 3, j + 33, k + 26, 5, 2);
		setBlock(world, i + 3, j + 33, k + 27, Blocks.planks, 5);
		world.setBlockMetadataWithNotify(i + 3, j + 33, k + 27, 5, 2);
		setBlock(world, i + 3, j + 33, k + 28, Blocks.planks, 5);
		world.setBlockMetadataWithNotify(i + 3, j + 33, k + 28, 5, 2);
		setBlock(world, i + 3, j + 37, k + 22, Blocks.log, 1);
		world.setBlockMetadataWithNotify(i + 3, j + 37, k + 22, 1, 2);
		setBlock(world, i + 3, j + 37, k + 23, Blocks.log, 1);
		world.setBlockMetadataWithNotify(i + 3, j + 37, k + 23, 1, 2);
		setBlock(world, i + 3, j + 37, k + 24, Blocks.log, 1);
		world.setBlockMetadataWithNotify(i + 3, j + 37, k + 24, 1, 2);
		setBlock(world, i + 3, j + 37, k + 25, Blocks.log, 1);
		world.setBlockMetadataWithNotify(i + 3, j + 37, k + 25, 1, 2);
		setBlock(world, i + 3, j + 37, k + 26, Blocks.log, 1);
		world.setBlockMetadataWithNotify(i + 3, j + 37, k + 26, 1, 2);
		setBlock(world, i + 3, j + 37, k + 27, Blocks.log, 1);
		world.setBlockMetadataWithNotify(i + 3, j + 37, k + 27, 1, 2);
		setBlock(world, i + 3, j + 37, k + 28, Blocks.log, 1);
		world.setBlockMetadataWithNotify(i + 3, j + 37, k + 28, 1, 2);
		setBlock(world, i + 3, j + 48, k + 7, Blocks.planks, 5);
		world.setBlockMetadataWithNotify(i + 3, j + 48, k + 7, 5, 2);
		setBlock(world, i + 3, j + 48, k + 8, Blocks.planks, 5);
		world.setBlockMetadataWithNotify(i + 3, j + 48, k + 8, 5, 2);
		setBlock(world, i + 3, j + 48, k + 9, Blocks.planks, 5);
		world.setBlockMetadataWithNotify(i + 3, j + 48, k + 9, 5, 2);
		setBlock(world, i + 3, j + 48, k + 10, Blocks.planks, 5);
		world.setBlockMetadataWithNotify(i + 3, j + 48, k + 10, 5, 2);
		setBlock(world, i + 3, j + 48, k + 11, Blocks.planks, 5);
		world.setBlockMetadataWithNotify(i + 3, j + 48, k + 11, 5, 2);
		setBlock(world, i + 4, j + 19, k + 0, Blocks.log, 1);
		world.setBlockMetadataWithNotify(i + 4, j + 19, k + 0, 1, 2);
		setBlock(world, i + 4, j + 20, k + 0, Blocks.log, 1);
		world.setBlockMetadataWithNotify(i + 4, j + 20, k + 0, 1, 2);
		setBlock(world, i + 4, j + 20, k + 1, Blocks.log, 1);
		world.setBlockMetadataWithNotify(i + 4, j + 20, k + 1, 1, 2);
		setBlock(world, i + 4, j + 20, k + 2, Blocks.log, 1);
		world.setBlockMetadataWithNotify(i + 4, j + 20, k + 2, 1, 2);
		setBlock(world, i + 4, j + 20, k + 3, Blocks.log, 1);
		
		generate96(world, rand, i, j, k);
		return true;
		}

	
	public boolean generate96(World world, Random rand, int i, int j, int k)
	
	{
		world.setBlockMetadataWithNotify(i + 4, j + 20, k + 3, 1, 2);
		setBlock(world, i + 4, j + 20, k + 4, Blocks.planks, 5);
		world.setBlockMetadataWithNotify(i + 4, j + 20, k + 4, 5, 2);
		setBlock(world, i + 4, j + 20, k + 5, Blocks.planks, 5);
		world.setBlockMetadataWithNotify(i + 4, j + 20, k + 5, 5, 2);
		setBlock(world, i + 4, j + 20, k + 6, Blocks.planks, 5);
		world.setBlockMetadataWithNotify(i + 4, j + 20, k + 6, 5, 2);
		setBlock(world, i + 4, j + 20, k + 7, Blocks.planks, 5);
		world.setBlockMetadataWithNotify(i + 4, j + 20, k + 7, 5, 2);
		setBlock(world, i + 4, j + 20, k + 8, Blocks.planks, 5);
		world.setBlockMetadataWithNotify(i + 4, j + 20, k + 8, 5, 2);
		setBlock(world, i + 4, j + 21, k + 7, Blocks.spruce_stairs, 2);
		world.setBlockMetadataWithNotify(i + 4, j + 21, k + 7, 2, 2);
		setBlock(world, i + 4, j + 21, k + 8, Blocks.planks, 5);
		world.setBlockMetadataWithNotify(i + 4, j + 21, k + 8, 5, 2);
		setBlock(world, i + 4, j + 21, k + 9, Blocks.planks, 5);
		world.setBlockMetadataWithNotify(i + 4, j + 21, k + 9, 5, 2);
		setBlock(world, i + 4, j + 22, k + 8, Blocks.spruce_stairs, 2);
		world.setBlockMetadataWithNotify(i + 4, j + 22, k + 8, 2, 2);
		setBlock(world, i + 4, j + 22, k + 9, Blocks.planks, 5);
		world.setBlockMetadataWithNotify(i + 4, j + 22, k + 9, 5, 2);
		setBlock(world, i + 4, j + 22, k + 10, Blocks.planks, 5);
		world.setBlockMetadataWithNotify(i + 4, j + 22, k + 10, 5, 2);
		setBlock(world, i + 4, j + 23, k + 9, Blocks.spruce_stairs, 2);
		world.setBlockMetadataWithNotify(i + 4, j + 23, k + 9, 2, 2);
		setBlock(world, i + 4, j + 23, k + 10, Blocks.planks, 5);
		world.setBlockMetadataWithNotify(i + 4, j + 23, k + 10, 5, 2);
		setBlock(world, i + 4, j + 23, k + 11, Blocks.planks, 5);
		world.setBlockMetadataWithNotify(i + 4, j + 23, k + 11, 5, 2);
		setBlock(world, i + 4, j + 24, k + 10, Blocks.spruce_stairs, 2);
		world.setBlockMetadataWithNotify(i + 4, j + 24, k + 10, 2, 2);
		setBlock(world, i + 4, j + 24, k + 11, Blocks.planks, 5);
		world.setBlockMetadataWithNotify(i + 4, j + 24, k + 11, 5, 2);
		setBlock(world, i + 4, j + 24, k + 12, Blocks.planks, 5);
		world.setBlockMetadataWithNotify(i + 4, j + 24, k + 12, 5, 2);
		setBlock(world, i + 4, j + 24, k + 31, Blocks.log, 3);
		world.setBlockMetadataWithNotify(i + 4, j + 24, k + 31, 3, 2);
		setBlock(world, i + 4, j + 25, k + 0, Blocks.log, 1);
		world.setBlockMetadataWithNotify(i + 4, j + 25, k + 0, 1, 2);
		setBlock(world, i + 4, j + 25, k + 1, Blocks.log, 1);
		world.setBlockMetadataWithNotify(i + 4, j + 25, k + 1, 1, 2);
		setBlock(world, i + 4, j + 25, k + 2, Blocks.log, 1);
		world.setBlockMetadataWithNotify(i + 4, j + 25, k + 2, 1, 2);
		setBlock(world, i + 4, j + 25, k + 3, Blocks.log, 1);
		world.setBlockMetadataWithNotify(i + 4, j + 25, k + 3, 1, 2);
		setBlock(world, i + 4, j + 25, k + 4, Blocks.log, 1);
		world.setBlockMetadataWithNotify(i + 4, j + 25, k + 4, 1, 2);
		setBlock(world, i + 4, j + 25, k + 5, Blocks.log, 1);
		world.setBlockMetadataWithNotify(i + 4, j + 25, k + 5, 1, 2);
		setBlock(world, i + 4, j + 25, k + 11, Blocks.spruce_stairs, 2);
		world.setBlockMetadataWithNotify(i + 4, j + 25, k + 11, 2, 2);
		setBlock(world, i + 4, j + 25, k + 12, Blocks.planks, 5);
		world.setBlockMetadataWithNotify(i + 4, j + 25, k + 12, 5, 2);
		setBlock(world, i + 4, j + 25, k + 13, Blocks.planks, 5);
		world.setBlockMetadataWithNotify(i + 4, j + 25, k + 13, 5, 2);
		setBlock(world, i + 4, j + 25, k + 28, Blocks.leaves, 7);
		world.setBlockMetadataWithNotify(i + 4, j + 25, k + 28, 7, 2);
		setBlock(world, i + 4, j + 25, k + 29, Blocks.leaves, 7);
		world.setBlockMetadataWithNotify(i + 4, j + 25, k + 29, 7, 2);
		setBlock(world, i + 4, j + 25, k + 30, Blocks.leaves, 7);
		world.setBlockMetadataWithNotify(i + 4, j + 25, k + 30, 7, 2);
		setBlock(world, i + 4, j + 26, k + 0, Blocks.log, 1);
		world.setBlockMetadataWithNotify(i + 4, j + 26, k + 0, 1, 2);
		setBlock(world, i + 4, j + 26, k + 1, Blocks.log, 1);
		world.setBlockMetadataWithNotify(i + 4, j + 26, k + 1, 1, 2);
		setBlock(world, i + 4, j + 26, k + 2, Blocks.log, 1);
		world.setBlockMetadataWithNotify(i + 4, j + 26, k + 2, 1, 2);
		setBlock(world, i + 4, j + 26, k + 3, Blocks.log, 1);
		world.setBlockMetadataWithNotify(i + 4, j + 26, k + 3, 1, 2);
		setBlock(world, i + 4, j + 26, k + 4, Blocks.log, 1);
		world.setBlockMetadataWithNotify(i + 4, j + 26, k + 4, 1, 2);
		setBlock(world, i + 4, j + 26, k + 12, Blocks.spruce_stairs, 2);
		world.setBlockMetadataWithNotify(i + 4, j + 26, k + 12, 2, 2);
		setBlock(world, i + 4, j + 26, k + 13, Blocks.planks, 5);
		world.setBlockMetadataWithNotify(i + 4, j + 26, k + 13, 5, 2);
		setBlock(world, i + 4, j + 26, k + 14, Blocks.planks, 5);
		world.setBlockMetadataWithNotify(i + 4, j + 26, k + 14, 5, 2);
		setBlock(world, i + 4, j + 26, k + 29, Blocks.leaves, 7);
		world.setBlockMetadataWithNotify(i + 4, j + 26, k + 29, 7, 2);
		setBlock(world, i + 4, j + 27, k + 0, Blocks.log, 1);
		world.setBlockMetadataWithNotify(i + 4, j + 27, k + 0, 1, 2);
		setBlock(world, i + 4, j + 27, k + 1, Blocks.log, 1);
		world.setBlockMetadataWithNotify(i + 4, j + 27, k + 1, 1, 2);
		setBlock(world, i + 4, j + 27, k + 2, Blocks.log, 1);
		world.setBlockMetadataWithNotify(i + 4, j + 27, k + 2, 1, 2);
		setBlock(world, i + 4, j + 27, k + 13, Blocks.spruce_stairs, 2);
		world.setBlockMetadataWithNotify(i + 4, j + 27, k + 13, 2, 2);
		setBlock(world, i + 4, j + 27, k + 14, Blocks.planks, 5);
		world.setBlockMetadataWithNotify(i + 4, j + 27, k + 14, 5, 2);
		setBlock(world, i + 4, j + 27, k + 15, Blocks.planks, 5);
		world.setBlockMetadataWithNotify(i + 4, j + 27, k + 15, 5, 2);
		setBlock(world, i + 4, j + 28, k + 14, Blocks.spruce_stairs, 2);
		world.setBlockMetadataWithNotify(i + 4, j + 28, k + 14, 2, 2);
		setBlock(world, i + 4, j + 28, k + 15, Blocks.planks, 5);
		world.setBlockMetadataWithNotify(i + 4, j + 28, k + 15, 5, 2);
		setBlock(world, i + 4, j + 28, k + 16, Blocks.planks, 5);
		world.setBlockMetadataWithNotify(i + 4, j + 28, k + 16, 5, 2);
		setBlock(world, i + 4, j + 29, k + 15, Blocks.spruce_stairs, 2);
		world.setBlockMetadataWithNotify(i + 4, j + 29, k + 15, 2, 2);
		setBlock(world, i + 4, j + 29, k + 16, Blocks.planks, 5);
		world.setBlockMetadataWithNotify(i + 4, j + 29, k + 16, 5, 2);
		setBlock(world, i + 4, j + 29, k + 17, Blocks.planks, 5);
		world.setBlockMetadataWithNotify(i + 4, j + 29, k + 17, 5, 2);
		setBlock(world, i + 4, j + 30, k + 16, Blocks.spruce_stairs, 2);
		world.setBlockMetadataWithNotify(i + 4, j + 30, k + 16, 2, 2);
		setBlock(world, i + 4, j + 30, k + 17, Blocks.planks, 5);
		world.setBlockMetadataWithNotify(i + 4, j + 30, k + 17, 5, 2);
		setBlock(world, i + 4, j + 30, k + 18, Blocks.planks, 5);
		world.setBlockMetadataWithNotify(i + 4, j + 30, k + 18, 5, 2);
		setBlock(world, i + 4, j + 31, k + 17, Blocks.spruce_stairs, 2);
		world.setBlockMetadataWithNotify(i + 4, j + 31, k + 17, 2, 2);
		setBlock(world, i + 4, j + 31, k + 18, Blocks.planks, 5);
		world.setBlockMetadataWithNotify(i + 4, j + 31, k + 18, 5, 2);
		setBlock(world, i + 4, j + 31, k + 19, Blocks.planks, 5);
		world.setBlockMetadataWithNotify(i + 4, j + 31, k + 19, 5, 2);
		setBlock(world, i + 4, j + 32, k + 18, Blocks.spruce_stairs, 2);
		world.setBlockMetadataWithNotify(i + 4, j + 32, k + 18, 2, 2);
		setBlock(world, i + 4, j + 32, k + 19, Blocks.planks, 5);
		world.setBlockMetadataWithNotify(i + 4, j + 32, k + 19, 5, 2);
		setBlock(world, i + 4, j + 32, k + 20, Blocks.planks, 5);
		world.setBlockMetadataWithNotify(i + 4, j + 32, k + 20, 5, 2);
		setBlock(world, i + 4, j + 33, k + 19, Blocks.spruce_stairs, 2);
		world.setBlockMetadataWithNotify(i + 4, j + 33, k + 19, 2, 2);
		setBlock(world, i + 4, j + 33, k + 20, Blocks.planks, 5);
		world.setBlockMetadataWithNotify(i + 4, j + 33, k + 20, 5, 2);
		setBlock(world, i + 4, j + 33, k + 21, Blocks.planks, 5);
		world.setBlockMetadataWithNotify(i + 4, j + 33, k + 21, 5, 2);
		setBlock(world, i + 4, j + 33, k + 22, Blocks.planks, 5);
		world.setBlockMetadataWithNotify(i + 4, j + 33, k + 22, 5, 2);
		setBlock(world, i + 4, j + 33, k + 23, Blocks.planks, 5);
		world.setBlockMetadataWithNotify(i + 4, j + 33, k + 23, 5, 2);
		setBlock(world, i + 4, j + 33, k + 24, Blocks.planks, 5);
		world.setBlockMetadataWithNotify(i + 4, j + 33, k + 24, 5, 2);
		setBlock(world, i + 4, j + 33, k + 25, Blocks.planks, 5);
		world.setBlockMetadataWithNotify(i + 4, j + 33, k + 25, 5, 2);
		setBlock(world, i + 4, j + 33, k + 26, Blocks.planks, 5);
		world.setBlockMetadataWithNotify(i + 4, j + 33, k + 26, 5, 2);
		setBlock(world, i + 4, j + 33, k + 27, Blocks.planks, 5);
		world.setBlockMetadataWithNotify(i + 4, j + 33, k + 27, 5, 2);
		setBlock(world, i + 4, j + 35, k + 23, Blocks.spruce_stairs, 4);
		world.setBlockMetadataWithNotify(i + 4, j + 35, k + 23, 4, 2);
		setBlock(world, i + 4, j + 35, k + 27, Blocks.spruce_stairs, 4);
		world.setBlockMetadataWithNotify(i + 4, j + 35, k + 27, 4, 2);
		setBlock(world, i + 4, j + 36, k + 23, Blocks.log, 1);
		world.setBlockMetadataWithNotify(i + 4, j + 36, k + 23, 1, 2);
		setBlock(world, i + 4, j + 36, k + 24, Blocks.torch, 3);
		world.setBlockMetadataWithNotify(i + 4, j + 36, k + 24, 3, 2);
		setBlock(world, i + 4, j + 36, k + 26, Blocks.torch, 4);
		world.setBlockMetadataWithNotify(i + 4, j + 36, k + 26, 4, 2);
		setBlock(world, i + 4, j + 36, k + 27, Blocks.log, 1);
		world.setBlockMetadataWithNotify(i + 4, j + 36, k + 27, 1, 2);
		setBlock(world, i + 4, j + 37, k + 20, Blocks.log, 1);
		world.setBlockMetadataWithNotify(i + 4, j + 37, k + 20, 1, 2);
		setBlock(world, i + 4, j + 37, k + 21, Blocks.log, 1);
		world.setBlockMetadataWithNotify(i + 4, j + 37, k + 21, 1, 2);
		setBlock(world, i + 4, j + 37, k + 22, Blocks.log, 1);
		world.setBlockMetadataWithNotify(i + 4, j + 37, k + 22, 1, 2);
		setBlock(world, i + 4, j + 37, k + 23, Blocks.log, 1);
		world.setBlockMetadataWithNotify(i + 4, j + 37, k + 23, 1, 2);
		setBlock(world, i + 4, j + 37, k + 24, Blocks.log, 1);
		world.setBlockMetadataWithNotify(i + 4, j + 37, k + 24, 1, 2);
		setBlock(world, i + 4, j + 37, k + 25, Blocks.log, 1);
		world.setBlockMetadataWithNotify(i + 4, j + 37, k + 25, 1, 2);
		setBlock(world, i + 4, j + 37, k + 26, Blocks.log, 1);
		world.setBlockMetadataWithNotify(i + 4, j + 37, k + 26, 1, 2);
		setBlock(world, i + 4, j + 37, k + 27, Blocks.log, 1);
		world.setBlockMetadataWithNotify(i + 4, j + 37, k + 27, 1, 2);
		setBlock(world, i + 4, j + 37, k + 28, Blocks.log, 1);
		world.setBlockMetadataWithNotify(i + 4, j + 37, k + 28, 1, 2);
		setBlock(world, i + 4, j + 37, k + 29, Blocks.log, 1);
		world.setBlockMetadataWithNotify(i + 4, j + 37, k + 29, 1, 2);
		setBlock(world, i + 4, j + 37, k + 30, Blocks.log, 1);
		world.setBlockMetadataWithNotify(i + 4, j + 37, k + 30, 1, 2);
		setBlock(world, i + 4, j + 38, k + 23, Blocks.log, 1);
		world.setBlockMetadataWithNotify(i + 4, j + 38, k + 23, 1, 2);
		setBlock(world, i + 4, j + 38, k + 24, Blocks.log, 1);
		world.setBlockMetadataWithNotify(i + 4, j + 38, k + 24, 1, 2);
		setBlock(world, i + 4, j + 38, k + 25, Blocks.log, 1);
		world.setBlockMetadataWithNotify(i + 4, j + 38, k + 25, 1, 2);
		setBlock(world, i + 4, j + 38, k + 26, Blocks.log, 1);
		world.setBlockMetadataWithNotify(i + 4, j + 38, k + 26, 1, 2);
		setBlock(world, i + 4, j + 38, k + 27, Blocks.log, 1);
		world.setBlockMetadataWithNotify(i + 4, j + 38, k + 27, 1, 2);
		setBlock(world, i + 4, j + 39, k + 23, Blocks.log, 1);
		world.setBlockMetadataWithNotify(i + 4, j + 39, k + 23, 1, 2);
		setBlock(world, i + 4, j + 39, k + 24, Blocks.log, 1);
		world.setBlockMetadataWithNotify(i + 4, j + 39, k + 24, 1, 2);
		setBlock(world, i + 4, j + 39, k + 25, Blocks.log, 1);
		world.setBlockMetadataWithNotify(i + 4, j + 39, k + 25, 1, 2);
		setBlock(world, i + 4, j + 39, k + 26, Blocks.log, 1);
		world.setBlockMetadataWithNotify(i + 4, j + 39, k + 26, 1, 2);
		setBlock(world, i + 4, j + 39, k + 27, Blocks.log, 1);
		world.setBlockMetadataWithNotify(i + 4, j + 39, k + 27, 1, 2);
		setBlock(world, i + 4, j + 48, k + 7, Blocks.planks, 5);
		world.setBlockMetadataWithNotify(i + 4, j + 48, k + 7, 5, 2);
		setBlock(world, i + 4, j + 48, k + 8, Blocks.planks, 5);
		world.setBlockMetadataWithNotify(i + 4, j + 48, k + 8, 5, 2);
		setBlock(world, i + 4, j + 48, k + 9, Blocks.planks, 5);
		world.setBlockMetadataWithNotify(i + 4, j + 48, k + 9, 5, 2);
		setBlock(world, i + 4, j + 48, k + 10, Blocks.planks, 5);
		world.setBlockMetadataWithNotify(i + 4, j + 48, k + 10, 5, 2);
		setBlock(world, i + 4, j + 48, k + 11, Blocks.planks, 5);
		world.setBlockMetadataWithNotify(i + 4, j + 48, k + 11, 5, 2);
		setBlock(world, i + 4, j + 49, k + 7, Blocks.planks, 5);
		world.setBlockMetadataWithNotify(i + 4, j + 49, k + 7, 5, 2);
		setBlock(world, i + 4, j + 49, k + 8, Blocks.planks, 5);
		world.setBlockMetadataWithNotify(i + 4, j + 49, k + 8, 5, 2);
		setBlock(world, i + 4, j + 49, k + 9, Blocks.planks, 5);
		world.setBlockMetadataWithNotify(i + 4, j + 49, k + 9, 5, 2);
		setBlock(world, i + 4, j + 49, k + 10, Blocks.planks, 5);
		world.setBlockMetadataWithNotify(i + 4, j + 49, k + 10, 5, 2);
		setBlock(world, i + 4, j + 49, k + 11, Blocks.planks, 5);
		world.setBlockMetadataWithNotify(i + 4, j + 49, k + 11, 5, 2);
		setBlock(world, i + 5, j + 20, k + 0, Blocks.log, 1);
		world.setBlockMetadataWithNotify(i + 5, j + 20, k + 0, 1, 2);
		setBlock(world, i + 5, j + 20, k + 1, Blocks.log, 1);
		world.setBlockMetadataWithNotify(i + 5, j + 20, k + 1, 1, 2);
		setBlock(world, i + 5, j + 20, k + 2, Blocks.log, 1);
		world.setBlockMetadataWithNotify(i + 5, j + 20, k + 2, 1, 2);
		setBlock(world, i + 5, j + 20, k + 3, Blocks.planks, 5);
		world.setBlockMetadataWithNotify(i + 5, j + 20, k + 3, 5, 2);
		setBlock(world, i + 5, j + 20, k + 4, Blocks.planks, 5);
		world.setBlockMetadataWithNotify(i + 5, j + 20, k + 4, 5, 2);
		setBlock(world, i + 5, j + 20, k + 5, Blocks.planks, 5);
		world.setBlockMetadataWithNotify(i + 5, j + 20, k + 5, 5, 2);
		setBlock(world, i + 5, j + 20, k + 6, Blocks.planks, 5);
		world.setBlockMetadataWithNotify(i + 5, j + 20, k + 6, 5, 2);
		setBlock(world, i + 5, j + 20, k + 7, Blocks.planks, 5);
		world.setBlockMetadataWithNotify(i + 5, j + 20, k + 7, 5, 2);
		setBlock(world, i + 5, j + 20, k + 8, Blocks.planks, 5);
		world.setBlockMetadataWithNotify(i + 5, j + 20, k + 8, 5, 2);
		setBlock(world, i + 5, j + 21, k + 3, Blocks.torch, 5);
		world.setBlockMetadataWithNotify(i + 5, j + 21, k + 3, 5, 2);
		setBlock(world, i + 5, j + 21, k + 6, Blocks.torch, 5);
		world.setBlockMetadataWithNotify(i + 5, j + 21, k + 6, 5, 2);
		setBlock(world, i + 5, j + 21, k + 7, Blocks.spruce_stairs, 2);
		world.setBlockMetadataWithNotify(i + 5, j + 21, k + 7, 2, 2);
		setBlock(world, i + 5, j + 21, k + 8, Blocks.planks, 5);
		world.setBlockMetadataWithNotify(i + 5, j + 21, k + 8, 5, 2);
		setBlock(world, i + 5, j + 21, k + 9, Blocks.planks, 5);
		world.setBlockMetadataWithNotify(i + 5, j + 21, k + 9, 5, 2);
		setBlock(world, i + 5, j + 22, k + 8, Blocks.spruce_stairs, 2);
		world.setBlockMetadataWithNotify(i + 5, j + 22, k + 8, 2, 2);
		setBlock(world, i + 5, j + 22, k + 9, Blocks.planks, 5);
		world.setBlockMetadataWithNotify(i + 5, j + 22, k + 9, 5, 2);
		setBlock(world, i + 5, j + 22, k + 10, Blocks.planks, 5);
		world.setBlockMetadataWithNotify(i + 5, j + 22, k + 10, 5, 2);
		setBlock(world, i + 5, j + 23, k + 2, Blocks.torch, 2);
		world.setBlockMetadataWithNotify(i + 5, j + 23, k + 2, 2, 2);
		setBlock(world, i + 5, j + 23, k + 9, Blocks.spruce_stairs, 2);
		world.setBlockMetadataWithNotify(i + 5, j + 23, k + 9, 2, 2);
		setBlock(world, i + 5, j + 23, k + 10, Blocks.planks, 5);
		world.setBlockMetadataWithNotify(i + 5, j + 23, k + 10, 5, 2);
		setBlock(world, i + 5, j + 23, k + 11, Blocks.planks, 5);
		world.setBlockMetadataWithNotify(i + 5, j + 23, k + 11, 5, 2);
		setBlock(world, i + 5, j + 24, k + 3, Blocks.spruce_stairs, 4);
		world.setBlockMetadataWithNotify(i + 5, j + 24, k + 3, 4, 2);
		setBlock(world, i + 5, j + 24, k + 10, Blocks.spruce_stairs, 2);
		world.setBlockMetadataWithNotify(i + 5, j + 24, k + 10, 2, 2);
		setBlock(world, i + 5, j + 24, k + 11, Blocks.planks, 5);
		world.setBlockMetadataWithNotify(i + 5, j + 24, k + 11, 5, 2);
		setBlock(world, i + 5, j + 24, k + 12, Blocks.planks, 5);
		world.setBlockMetadataWithNotify(i + 5, j + 24, k + 12, 5, 2);
		setBlock(world, i + 5, j + 24, k + 31, Blocks.log, 3);
		world.setBlockMetadataWithNotify(i + 5, j + 24, k + 31, 3, 2);
		setBlock(world, i + 5, j + 25, k + 0, Blocks.log, 1);
		world.setBlockMetadataWithNotify(i + 5, j + 25, k + 0, 1, 2);
		setBlock(world, i + 5, j + 25, k + 1, Blocks.log, 1);
		world.setBlockMetadataWithNotify(i + 5, j + 25, k + 1, 1, 2);
		setBlock(world, i + 5, j + 25, k + 2, Blocks.log, 1);
		world.setBlockMetadataWithNotify(i + 5, j + 25, k + 2, 1, 2);
		setBlock(world, i + 5, j + 25, k + 3, Blocks.log, 1);
		world.setBlockMetadataWithNotify(i + 5, j + 25, k + 3, 1, 2);
		setBlock(world, i + 5, j + 25, k + 4, Blocks.log, 1);
		world.setBlockMetadataWithNotify(i + 5, j + 25, k + 4, 1, 2);
		setBlock(world, i + 5, j + 25, k + 11, Blocks.spruce_stairs, 2);
		world.setBlockMetadataWithNotify(i + 5, j + 25, k + 11, 2, 2);
		setBlock(world, i + 5, j + 25, k + 12, Blocks.planks, 5);
		world.setBlockMetadataWithNotify(i + 5, j + 25, k + 12, 5, 2);
		setBlock(world, i + 5, j + 25, k + 13, Blocks.planks, 5);
		world.setBlockMetadataWithNotify(i + 5, j + 25, k + 13, 5, 2);
		setBlock(world, i + 5, j + 26, k + 0, Blocks.log, 1);
		world.setBlockMetadataWithNotify(i + 5, j + 26, k + 0, 1, 2);
		setBlock(world, i + 5, j + 26, k + 1, Blocks.log, 1);
		world.setBlockMetadataWithNotify(i + 5, j + 26, k + 1, 1, 2);
		setBlock(world, i + 5, j + 26, k + 2, Blocks.log, 1);
		world.setBlockMetadataWithNotify(i + 5, j + 26, k + 2, 1, 2);
		setBlock(world, i + 5, j + 26, k + 3, Blocks.log, 1);
		world.setBlockMetadataWithNotify(i + 5, j + 26, k + 3, 1, 2);
		setBlock(world, i + 5, j + 26, k + 12, Blocks.spruce_stairs, 2);
		world.setBlockMetadataWithNotify(i + 5, j + 26, k + 12, 2, 2);
		setBlock(world, i + 5, j + 26, k + 13, Blocks.planks, 5);
		world.setBlockMetadataWithNotify(i + 5, j + 26, k + 13, 5, 2);
		setBlock(world, i + 5, j + 26, k + 14, Blocks.planks, 5);
		world.setBlockMetadataWithNotify(i + 5, j + 26, k + 14, 5, 2);
		setBlock(world, i + 5, j + 27, k + 0, Blocks.log, 1);
		world.setBlockMetadataWithNotify(i + 5, j + 27, k + 0, 1, 2);
		setBlock(world, i + 5, j + 27, k + 1, Blocks.log, 1);
		world.setBlockMetadataWithNotify(i + 5, j + 27, k + 1, 1, 2);
		setBlock(world, i + 5, j + 27, k + 13, Blocks.spruce_stairs, 2);
		world.setBlockMetadataWithNotify(i + 5, j + 27, k + 13, 2, 2);
		setBlock(world, i + 5, j + 27, k + 14, Blocks.planks, 5);
		world.setBlockMetadataWithNotify(i + 5, j + 27, k + 14, 5, 2);
		setBlock(world, i + 5, j + 27, k + 15, Blocks.planks, 5);
		world.setBlockMetadataWithNotify(i + 5, j + 27, k + 15, 5, 2);
		setBlock(world, i + 5, j + 28, k + 14, Blocks.spruce_stairs, 2);
		world.setBlockMetadataWithNotify(i + 5, j + 28, k + 14, 2, 2);
		setBlock(world, i + 5, j + 28, k + 15, Blocks.planks, 5);
		world.setBlockMetadataWithNotify(i + 5, j + 28, k + 15, 5, 2);
		setBlock(world, i + 5, j + 28, k + 16, Blocks.planks, 5);
		world.setBlockMetadataWithNotify(i + 5, j + 28, k + 16, 5, 2);
		setBlock(world, i + 5, j + 29, k + 15, Blocks.spruce_stairs, 2);
		world.setBlockMetadataWithNotify(i + 5, j + 29, k + 15, 2, 2);
		setBlock(world, i + 5, j + 29, k + 16, Blocks.planks, 5);
		world.setBlockMetadataWithNotify(i + 5, j + 29, k + 16, 5, 2);
		setBlock(world, i + 5, j + 29, k + 17, Blocks.planks, 5);
		world.setBlockMetadataWithNotify(i + 5, j + 29, k + 17, 5, 2);
		setBlock(world, i + 5, j + 30, k + 16, Blocks.spruce_stairs, 2);
		world.setBlockMetadataWithNotify(i + 5, j + 30, k + 16, 2, 2);
		setBlock(world, i + 5, j + 30, k + 17, Blocks.planks, 5);
		world.setBlockMetadataWithNotify(i + 5, j + 30, k + 17, 5, 2);
		setBlock(world, i + 5, j + 30, k + 18, Blocks.planks, 5);
		world.setBlockMetadataWithNotify(i + 5, j + 30, k + 18, 5, 2);
		setBlock(world, i + 5, j + 31, k + 17, Blocks.spruce_stairs, 2);
		world.setBlockMetadataWithNotify(i + 5, j + 31, k + 17, 2, 2);
		setBlock(world, i + 5, j + 31, k + 18, Blocks.planks, 5);
		world.setBlockMetadataWithNotify(i + 5, j + 31, k + 18, 5, 2);
		setBlock(world, i + 5, j + 31, k + 19, Blocks.planks, 5);
		world.setBlockMetadataWithNotify(i + 5, j + 31, k + 19, 5, 2);
		setBlock(world, i + 5, j + 32, k + 18, Blocks.spruce_stairs, 2);
		world.setBlockMetadataWithNotify(i + 5, j + 32, k + 18, 2, 2);
		setBlock(world, i + 5, j + 32, k + 19, Blocks.planks, 5);
		world.setBlockMetadataWithNotify(i + 5, j + 32, k + 19, 5, 2);
		setBlock(world, i + 5, j + 32, k + 20, Blocks.planks, 5);
		world.setBlockMetadataWithNotify(i + 5, j + 32, k + 20, 5, 2);
		setBlock(world, i + 5, j + 33, k + 19, Blocks.spruce_stairs, 2);
		world.setBlockMetadataWithNotify(i + 5, j + 33, k + 19, 2, 2);
		setBlock(world, i + 5, j + 33, k + 20, Blocks.planks, 5);
		world.setBlockMetadataWithNotify(i + 5, j + 33, k + 20, 5, 2);
		setBlock(world, i + 5, j + 33, k + 21, Blocks.planks, 5);
		world.setBlockMetadataWithNotify(i + 5, j + 33, k + 21, 5, 2);
		setBlock(world, i + 5, j + 33, k + 22, Blocks.planks, 5);
		world.setBlockMetadataWithNotify(i + 5, j + 33, k + 22, 5, 2);
		setBlock(world, i + 5, j + 33, k + 23, Blocks.planks, 5);
		world.setBlockMetadataWithNotify(i + 5, j + 33, k + 23, 5, 2);
		setBlock(world, i + 5, j + 33, k + 24, Blocks.planks, 5);
		world.setBlockMetadataWithNotify(i + 5, j + 33, k + 24, 5, 2);
		setBlock(world, i + 5, j + 33, k + 25, Blocks.planks, 5);
		world.setBlockMetadataWithNotify(i + 5, j + 33, k + 25, 5, 2);
		setBlock(world, i + 5, j + 33, k + 26, Blocks.planks, 5);
		world.setBlockMetadataWithNotify(i + 5, j + 33, k + 26, 5, 2);
		setBlock(world, i + 5, j + 33, k + 27, Blocks.planks, 5);
		world.setBlockMetadataWithNotify(i + 5, j + 33, k + 27, 5, 2);
		setBlock(world, i + 5, j + 34, k + 21, Blocks.torch, 5);
		world.setBlockMetadataWithNotify(i + 5, j + 34, k + 21, 5, 2);
		setBlock(world, i + 5, j + 34, k + 23, Blocks.spruce_stairs, 4);
		world.setBlockMetadataWithNotify(i + 5, j + 34, k + 23, 4, 2);
		setBlock(world, i + 5, j + 34, k + 27, Blocks.spruce_stairs, 4);
		world.setBlockMetadataWithNotify(i + 5, j + 34, k + 27, 4, 2);
		setBlock(world, i + 5, j + 35, k + 23, Blocks.log, 1);
		world.setBlockMetadataWithNotify(i + 5, j + 35, k + 23, 1, 2);
		setBlock(world, i + 5, j + 35, k + 27, Blocks.log, 1);
		world.setBlockMetadataWithNotify(i + 5, j + 35, k + 27, 1, 2);
		setBlock(world, i + 5, j + 36, k + 23, Blocks.log, 1);
		world.setBlockMetadataWithNotify(i + 5, j + 36, k + 23, 1, 2);
		setBlock(world, i + 5, j + 36, k + 27, Blocks.log, 1);
		world.setBlockMetadataWithNotify(i + 5, j + 36, k + 27, 1, 2);
		setBlock(world, i + 5, j + 37, k + 19, Blocks.log, 1);
		world.setBlockMetadataWithNotify(i + 5, j + 37, k + 19, 1, 2);
		setBlock(world, i + 5, j + 37, k + 20, Blocks.log, 1);
		world.setBlockMetadataWithNotify(i + 5, j + 37, k + 20, 1, 2);
		setBlock(world, i + 5, j + 37, k + 21, Blocks.log, 1);
		world.setBlockMetadataWithNotify(i + 5, j + 37, k + 21, 1, 2);
		setBlock(world, i + 5, j + 37, k + 22, Blocks.log, 1);
		world.setBlockMetadataWithNotify(i + 5, j + 37, k + 22, 1, 2);
		setBlock(world, i + 5, j + 37, k + 23, Blocks.log, 1);
		world.setBlockMetadataWithNotify(i + 5, j + 37, k + 23, 1, 2);
		setBlock(world, i + 5, j + 37, k + 24, Blocks.log, 1);
		world.setBlockMetadataWithNotify(i + 5, j + 37, k + 24, 1, 2);
		setBlock(world, i + 5, j + 37, k + 25, Blocks.log, 1);
		world.setBlockMetadataWithNotify(i + 5, j + 37, k + 25, 1, 2);
		setBlock(world, i + 5, j + 37, k + 26, Blocks.log, 1);
		world.setBlockMetadataWithNotify(i + 5, j + 37, k + 26, 1, 2);
		setBlock(world, i + 5, j + 37, k + 27, Blocks.log, 1);
		world.setBlockMetadataWithNotify(i + 5, j + 37, k + 27, 1, 2);
		setBlock(world, i + 5, j + 37, k + 28, Blocks.log, 1);
		world.setBlockMetadataWithNotify(i + 5, j + 37, k + 28, 1, 2);
		setBlock(world, i + 5, j + 37, k + 29, Blocks.log, 1);
		world.setBlockMetadataWithNotify(i + 5, j + 37, k + 29, 1, 2);
		setBlock(world, i + 5, j + 37, k + 30, Blocks.log, 1);
		world.setBlockMetadataWithNotify(i + 5, j + 37, k + 30, 1, 2);
		setBlock(world, i + 5, j + 37, k + 31, Blocks.log, 1);
		world.setBlockMetadataWithNotify(i + 5, j + 37, k + 31, 1, 2);
		setBlock(world, i + 5, j + 38, k + 21, Blocks.log, 1);
		world.setBlockMetadataWithNotify(i + 5, j + 38, k + 21, 1, 2);
		setBlock(world, i + 5, j + 38, k + 22, Blocks.log, 1);
		world.setBlockMetadataWithNotify(i + 5, j + 38, k + 22, 1, 2);
		setBlock(world, i + 5, j + 38, k + 23, Blocks.log, 1);
		world.setBlockMetadataWithNotify(i + 5, j + 38, k + 23, 1, 2);
		setBlock(world, i + 5, j + 38, k + 24, Blocks.log, 1);
		world.setBlockMetadataWithNotify(i + 5, j + 38, k + 24, 1, 2);
		setBlock(world, i + 5, j + 38, k + 25, Blocks.log, 1);
		world.setBlockMetadataWithNotify(i + 5, j + 38, k + 25, 1, 2);
		setBlock(world, i + 5, j + 38, k + 26, Blocks.log, 1);
		world.setBlockMetadataWithNotify(i + 5, j + 38, k + 26, 1, 2);
		setBlock(world, i + 5, j + 38, k + 27, Blocks.log, 1);
		world.setBlockMetadataWithNotify(i + 5, j + 38, k + 27, 1, 2);
		setBlock(world, i + 5, j + 38, k + 28, Blocks.log, 1);
		world.setBlockMetadataWithNotify(i + 5, j + 38, k + 28, 1, 2);
		setBlock(world, i + 5, j + 38, k + 29, Blocks.log, 1);
		world.setBlockMetadataWithNotify(i + 5, j + 38, k + 29, 1, 2);
		setBlock(world, i + 5, j + 39, k + 21, Blocks.log, 1);
		world.setBlockMetadataWithNotify(i + 5, j + 39, k + 21, 1, 2);
		setBlock(world, i + 5, j + 39, k + 22, Blocks.log, 1);
		world.setBlockMetadataWithNotify(i + 5, j + 39, k + 22, 1, 2);
		setBlock(world, i + 5, j + 39, k + 23, Blocks.log, 1);
		world.setBlockMetadataWithNotify(i + 5, j + 39, k + 23, 1, 2);
		setBlock(world, i + 5, j + 39, k + 24, Blocks.log, 1);
		world.setBlockMetadataWithNotify(i + 5, j + 39, k + 24, 1, 2);
		setBlock(world, i + 5, j + 39, k + 25, Blocks.log, 1);
		world.setBlockMetadataWithNotify(i + 5, j + 39, k + 25, 1, 2);
		setBlock(world, i + 5, j + 39, k + 26, Blocks.log, 1);
		world.setBlockMetadataWithNotify(i + 5, j + 39, k + 26, 1, 2);
		setBlock(world, i + 5, j + 39, k + 27, Blocks.log, 1);
		world.setBlockMetadataWithNotify(i + 5, j + 39, k + 27, 1, 2);
		setBlock(world, i + 5, j + 39, k + 28, Blocks.log, 1);
		world.setBlockMetadataWithNotify(i + 5, j + 39, k + 28, 1, 2);
		setBlock(world, i + 5, j + 39, k + 29, Blocks.log, 1);
		world.setBlockMetadataWithNotify(i + 5, j + 39, k + 29, 1, 2);
		setBlock(world, i + 5, j + 40, k + 23, Blocks.log, 1);
		world.setBlockMetadataWithNotify(i + 5, j + 40, k + 23, 1, 2);
		setBlock(world, i + 5, j + 40, k + 24, Blocks.log, 1);
		world.setBlockMetadataWithNotify(i + 5, j + 40, k + 24, 1, 2);
		setBlock(world, i + 5, j + 40, k + 25, Blocks.log, 1);
		world.setBlockMetadataWithNotify(i + 5, j + 40, k + 25, 1, 2);
		setBlock(world, i + 5, j + 40, k + 26, Blocks.log, 1);
		world.setBlockMetadataWithNotify(i + 5, j + 40, k + 26, 1, 2);
		setBlock(world, i + 5, j + 40, k + 27, Blocks.log, 1);
		world.setBlockMetadataWithNotify(i + 5, j + 40, k + 27, 1, 2);
		setBlock(world, i + 5, j + 49, k + 7, Blocks.planks, 5);
		world.setBlockMetadataWithNotify(i + 5, j + 49, k + 7, 5, 2);
		setBlock(world, i + 5, j + 49, k + 8, Blocks.planks, 5);
		world.setBlockMetadataWithNotify(i + 5, j + 49, k + 8, 5, 2);
		setBlock(world, i + 5, j + 49, k + 9, Blocks.planks, 5);
		world.setBlockMetadataWithNotify(i + 5, j + 49, k + 9, 5, 2);
		setBlock(world, i + 5, j + 49, k + 10, Blocks.planks, 5);
		world.setBlockMetadataWithNotify(i + 5, j + 49, k + 10, 5, 2);
		setBlock(world, i + 5, j + 49, k + 11, Blocks.planks, 5);
		world.setBlockMetadataWithNotify(i + 5, j + 49, k + 11, 5, 2);
		setBlock(world, i + 5, j + 50, k + 7, Blocks.torch, 5);
		world.setBlockMetadataWithNotify(i + 5, j + 50, k + 7, 5, 2);
		setBlock(world, i + 5, j + 50, k + 11, Blocks.torch, 5);
		world.setBlockMetadataWithNotify(i + 5, j + 50, k + 11, 5, 2);
		setBlock(world, i + 6, j + 19, k + 3, Blocks.planks, 5);
		world.setBlockMetadataWithNotify(i + 6, j + 19, k + 3, 5, 2);
		setBlock(world, i + 6, j + 19, k + 4, Blocks.planks, 5);
		world.setBlockMetadataWithNotify(i + 6, j + 19, k + 4, 5, 2);
		setBlock(world, i + 6, j + 19, k + 5, Blocks.planks, 5);
		world.setBlockMetadataWithNotify(i + 6, j + 19, k + 5, 5, 2);
		setBlock(world, i + 6, j + 19, k + 6, Blocks.planks, 5);
		world.setBlockMetadataWithNotify(i + 6, j + 19, k + 6, 5, 2);
		setBlock(world, i + 6, j + 20, k + 0, Blocks.log, 1);
		world.setBlockMetadataWithNotify(i + 6, j + 20, k + 0, 1, 2);
		setBlock(world, i + 6, j + 20, k + 1, Blocks.log, 1);
		world.setBlockMetadataWithNotify(i + 6, j + 20, k + 1, 1, 2);
		setBlock(world, i + 6, j + 20, k + 3, Blocks.spruce_stairs, 1);
		world.setBlockMetadataWithNotify(i + 6, j + 20, k + 3, 1, 2);
		setBlock(world, i + 6, j + 20, k + 4, Blocks.spruce_stairs, 1);
		world.setBlockMetadataWithNotify(i + 6, j + 20, k + 4, 1, 2);
		setBlock(world, i + 6, j + 20, k + 5, Blocks.spruce_stairs, 1);
		world.setBlockMetadataWithNotify(i + 6, j + 20, k + 5, 1, 2);
		setBlock(world, i + 6, j + 20, k + 6, Blocks.spruce_stairs, 1);
		world.setBlockMetadataWithNotify(i + 6, j + 20, k + 6, 1, 2);
		setBlock(world, i + 6, j + 21, k + 0, Blocks.spruce_stairs, 2);
		world.setBlockMetadataWithNotify(i + 6, j + 21, k + 0, 2, 2);
		setBlock(world, i + 6, j + 21, k + 1, Blocks.log, 1);
		world.setBlockMetadataWithNotify(i + 6, j + 21, k + 1, 1, 2);
		setBlock(world, i + 6, j + 21, k + 2, Blocks.spruce_stairs, 7);
		world.setBlockMetadataWithNotify(i + 6, j + 21, k + 2, 7, 2);
		setBlock(world, i + 6, j + 22, k + 1, Blocks.log, 1);
		world.setBlockMetadataWithNotify(i + 6, j + 22, k + 1, 1, 2);
		setBlock(world, i + 6, j + 22, k + 2, Blocks.log, 1);
		world.setBlockMetadataWithNotify(i + 6, j + 22, k + 2, 1, 2);
		setBlock(world, i + 6, j + 22, k + 3, Blocks.spruce_stairs, 7);
		world.setBlockMetadataWithNotify(i + 6, j + 22, k + 3, 7, 2);
		setBlock(world, i + 6, j + 23, k + 2, Blocks.log, 1);
		world.setBlockMetadataWithNotify(i + 6, j + 23, k + 2, 1, 2);
		setBlock(world, i + 6, j + 23, k + 3, Blocks.log, 1);
		world.setBlockMetadataWithNotify(i + 6, j + 23, k + 3, 1, 2);
		setBlock(world, i + 6, j + 24, k + 3, Blocks.log, 1);
		world.setBlockMetadataWithNotify(i + 6, j + 24, k + 3, 1, 2);
		setBlock(world, i + 6, j + 25, k + 0, Blocks.log, 1);
		world.setBlockMetadataWithNotify(i + 6, j + 25, k + 0, 1, 2);
		setBlock(world, i + 6, j + 25, k + 1, Blocks.log, 1);
		world.setBlockMetadataWithNotify(i + 6, j + 25, k + 1, 1, 2);
		setBlock(world, i + 6, j + 25, k + 2, Blocks.log, 1);
		world.setBlockMetadataWithNotify(i + 6, j + 25, k + 2, 1, 2);
		setBlock(world, i + 6, j + 25, k + 3, Blocks.log, 1);
		world.setBlockMetadataWithNotify(i + 6, j + 25, k + 3, 1, 2);
		setBlock(world, i + 6, j + 25, k + 4, Blocks.log, 1);
		world.setBlockMetadataWithNotify(i + 6, j + 25, k + 4, 1, 2);
		setBlock(world, i + 6, j + 26, k + 0, Blocks.log, 1);
		world.setBlockMetadataWithNotify(i + 6, j + 26, k + 0, 1, 2);
		setBlock(world, i + 6, j + 26, k + 1, Blocks.log, 1);
		world.setBlockMetadataWithNotify(i + 6, j + 26, k + 1, 1, 2);
		setBlock(world, i + 6, j + 26, k + 2, Blocks.log, 1);
		world.setBlockMetadataWithNotify(i + 6, j + 26, k + 2, 1, 2);
		setBlock(world, i + 6, j + 26, k + 3, Blocks.log, 1);
		world.setBlockMetadataWithNotify(i + 6, j + 26, k + 3, 1, 2);
		setBlock(world, i + 6, j + 27, k + 0, Blocks.log, 1);
		world.setBlockMetadataWithNotify(i + 6, j + 27, k + 0, 1, 2);
		setBlock(world, i + 6, j + 27, k + 24, Blocks.vine, 3);
		world.setBlockMetadataWithNotify(i + 6, j + 27, k + 24, 3, 2);
		setBlock(world, i + 6, j + 28, k + 22, Blocks.vine, 10);
		world.setBlockMetadataWithNotify(i + 6, j + 28, k + 22, 10, 2);
		setBlock(world, i + 6, j + 28, k + 24, Blocks.vine, 3);
		world.setBlockMetadataWithNotify(i + 6, j + 28, k + 24, 3, 2);
		setBlock(world, i + 6, j + 29, k + 22, Blocks.vine, 15);
		world.setBlockMetadataWithNotify(i + 6, j + 29, k + 22, 15, 2);
		setBlock(world, i + 6, j + 29, k + 23, Blocks.vine, 15);
		world.setBlockMetadataWithNotify(i + 6, j + 29, k + 23, 15, 2);
		setBlock(world, i + 6, j + 29, k + 24, Blocks.vine, 11);
		world.setBlockMetadataWithNotify(i + 6, j + 29, k + 24, 11, 2);
		setBlock(world, i + 6, j + 29, k + 25, Blocks.vine, 9);
		world.setBlockMetadataWithNotify(i + 6, j + 29, k + 25, 9, 2);
		setBlock(world, i + 6, j + 30, k + 22, Blocks.vine, 15);
		world.setBlockMetadataWithNotify(i + 6, j + 30, k + 22, 15, 2);
		setBlock(world, i + 6, j + 30, k + 23, Blocks.vine, 15);
		world.setBlockMetadataWithNotify(i + 6, j + 30, k + 23, 15, 2);
		setBlock(world, i + 6, j + 30, k + 24, Blocks.vine, 15);
		world.setBlockMetadataWithNotify(i + 6, j + 30, k + 24, 15, 2);
		setBlock(world, i + 6, j + 30, k + 25, Blocks.vine, 9);
		world.setBlockMetadataWithNotify(i + 6, j + 30, k + 25, 9, 2);
		setBlock(world, i + 6, j + 31, k + 21, Blocks.vine, 13);
		world.setBlockMetadataWithNotify(i + 6, j + 31, k + 21, 13, 2);
		setBlock(world, i + 6, j + 31, k + 22, Blocks.vine, 15);
		world.setBlockMetadataWithNotify(i + 6, j + 31, k + 22, 15, 2);
		setBlock(world, i + 6, j + 31, k + 23, Blocks.vine, 15);
		world.setBlockMetadataWithNotify(i + 6, j + 31, k + 23, 15, 2);
		setBlock(world, i + 6, j + 31, k + 24, Blocks.vine, 15);
		world.setBlockMetadataWithNotify(i + 6, j + 31, k + 24, 15, 2);
		setBlock(world, i + 6, j + 31, k + 25, Blocks.vine, 15);
		world.setBlockMetadataWithNotify(i + 6, j + 31, k + 25, 15, 2);
		setBlock(world, i + 6, j + 31, k + 26, Blocks.vine, 15);
		world.setBlockMetadataWithNotify(i + 6, j + 31, k + 26, 15, 2);
		setBlock(world, i + 6, j + 31, k + 27, Blocks.vine, 14);
		world.setBlockMetadataWithNotify(i + 6, j + 31, k + 27, 14, 2);
		setBlock(world, i + 6, j + 32, k + 20, Blocks.vine, 15);
		world.setBlockMetadataWithNotify(i + 6, j + 32, k + 20, 15, 2);
		setBlock(world, i + 6, j + 32, k + 21, Blocks.vine, 15);
		world.setBlockMetadataWithNotify(i + 6, j + 32, k + 21, 15, 2);
		setBlock(world, i + 6, j + 32, k + 22, Blocks.vine, 15);
		world.setBlockMetadataWithNotify(i + 6, j + 32, k + 22, 15, 2);
		setBlock(world, i + 6, j + 32, k + 24, Blocks.vine, 15);
		world.setBlockMetadataWithNotify(i + 6, j + 32, k + 24, 15, 2);
		setBlock(world, i + 6, j + 32, k + 25, Blocks.vine, 15);
		world.setBlockMetadataWithNotify(i + 6, j + 32, k + 25, 15, 2);
		setBlock(world, i + 6, j + 32, k + 26, Blocks.vine, 15);
		world.setBlockMetadataWithNotify(i + 6, j + 32, k + 26, 15, 2);
		setBlock(world, i + 6, j + 32, k + 27, Blocks.vine, 15);
		world.setBlockMetadataWithNotify(i + 6, j + 32, k + 27, 15, 2);
		setBlock(world, i + 6, j + 33, k + 20, Blocks.vine, 15);
		world.setBlockMetadataWithNotify(i + 6, j + 33, k + 20, 15, 2);
		setBlock(world, i + 6, j + 33, k + 21, Blocks.vine, 15);
		world.setBlockMetadataWithNotify(i + 6, j + 33, k + 21, 15, 2);
		setBlock(world, i + 6, j + 33, k + 22, Blocks.vine, 15);
		world.setBlockMetadataWithNotify(i + 6, j + 33, k + 22, 15, 2);
		setBlock(world, i + 6, j + 33, k + 23, Blocks.log, 1);
		world.setBlockMetadataWithNotify(i + 6, j + 33, k + 23, 1, 2);
		setBlock(world, i + 6, j + 33, k + 24, Blocks.log, 1);
		world.setBlockMetadataWithNotify(i + 6, j + 33, k + 24, 1, 2);
		setBlock(world, i + 6, j + 33, k + 25, Blocks.log, 1);
		world.setBlockMetadataWithNotify(i + 6, j + 33, k + 25, 1, 2);
		setBlock(world, i + 6, j + 33, k + 26, Blocks.log, 1);
		world.setBlockMetadataWithNotify(i + 6, j + 33, k + 26, 1, 2);
		setBlock(world, i + 6, j + 33, k + 27, Blocks.log, 1);
		world.setBlockMetadataWithNotify(i + 6, j + 33, k + 27, 1, 2);
		setBlock(world, i + 6, j + 34, k + 22, Blocks.spruce_stairs, 2);
		world.setBlockMetadataWithNotify(i + 6, j + 34, k + 22, 2, 2);
		setBlock(world, i + 6, j + 34, k + 23, Blocks.log, 1);
		world.setBlockMetadataWithNotify(i + 6, j + 34, k + 23, 1, 2);
		setBlock(world, i + 6, j + 34, k + 27, Blocks.log, 1);
		world.setBlockMetadataWithNotify(i + 6, j + 34, k + 27, 1, 2);
		setBlock(world, i + 6, j + 34, k + 28, Blocks.spruce_stairs, 3);
		world.setBlockMetadataWithNotify(i + 6, j + 34, k + 28, 3, 2);
		setBlock(world, i + 6, j + 35, k + 23, Blocks.log, 1);
		world.setBlockMetadataWithNotify(i + 6, j + 35, k + 23, 1, 2);
		setBlock(world, i + 6, j + 35, k + 27, Blocks.log, 1);
		world.setBlockMetadataWithNotify(i + 6, j + 35, k + 27, 1, 2);
		setBlock(world, i + 6, j + 37, k + 18, Blocks.log, 1);
		world.setBlockMetadataWithNotify(i + 6, j + 37, k + 18, 1, 2);
		setBlock(world, i + 6, j + 37, k + 19, Blocks.log, 1);
		world.setBlockMetadataWithNotify(i + 6, j + 37, k + 19, 1, 2);
		setBlock(world, i + 6, j + 37, k + 20, Blocks.log, 1);
		world.setBlockMetadataWithNotify(i + 6, j + 37, k + 20, 1, 2);
		setBlock(world, i + 6, j + 37, k + 21, Blocks.log, 1);
		world.setBlockMetadataWithNotify(i + 6, j + 37, k + 21, 1, 2);
		setBlock(world, i + 6, j + 37, k + 22, Blocks.log, 1);
		world.setBlockMetadataWithNotify(i + 6, j + 37, k + 22, 1, 2);
		setBlock(world, i + 6, j + 37, k + 23, Blocks.log, 1);
		world.setBlockMetadataWithNotify(i + 6, j + 37, k + 23, 1, 2);
		setBlock(world, i + 6, j + 37, k + 24, Blocks.log, 1);
		world.setBlockMetadataWithNotify(i + 6, j + 37, k + 24, 1, 2);
		setBlock(world, i + 6, j + 37, k + 25, Blocks.log, 1);
		world.setBlockMetadataWithNotify(i + 6, j + 37, k + 25, 1, 2);
		setBlock(world, i + 6, j + 37, k + 26, Blocks.log, 1);
		world.setBlockMetadataWithNotify(i + 6, j + 37, k + 26, 1, 2);
		setBlock(world, i + 6, j + 37, k + 27, Blocks.log, 1);
		world.setBlockMetadataWithNotify(i + 6, j + 37, k + 27, 1, 2);
		setBlock(world, i + 6, j + 37, k + 28, Blocks.log, 1);
		world.setBlockMetadataWithNotify(i + 6, j + 37, k + 28, 1, 2);
		setBlock(world, i + 6, j + 37, k + 29, Blocks.log, 1);
		world.setBlockMetadataWithNotify(i + 6, j + 37, k + 29, 1, 2);
		setBlock(world, i + 6, j + 37, k + 30, Blocks.log, 1);
		world.setBlockMetadataWithNotify(i + 6, j + 37, k + 30, 1, 2);
		setBlock(world, i + 6, j + 37, k + 31, Blocks.log, 1);
		world.setBlockMetadataWithNotify(i + 6, j + 37, k + 31, 1, 2);
		setBlock(world, i + 6, j + 38, k + 19, Blocks.log, 1);
		world.setBlockMetadataWithNotify(i + 6, j + 38, k + 19, 1, 2);
		setBlock(world, i + 6, j + 38, k + 20, Blocks.log, 1);
		world.setBlockMetadataWithNotify(i + 6, j + 38, k + 20, 1, 2);
		setBlock(world, i + 6, j + 38, k + 21, Blocks.log, 1);
		world.setBlockMetadataWithNotify(i + 6, j + 38, k + 21, 1, 2);
		setBlock(world, i + 6, j + 38, k + 22, Blocks.log, 1);
		world.setBlockMetadataWithNotify(i + 6, j + 38, k + 22, 1, 2);
		setBlock(world, i + 6, j + 38, k + 23, Blocks.log, 1);
		world.setBlockMetadataWithNotify(i + 6, j + 38, k + 23, 1, 2);
		setBlock(world, i + 6, j + 38, k + 24, Blocks.log, 1);
		world.setBlockMetadataWithNotify(i + 6, j + 38, k + 24, 1, 2);
		setBlock(world, i + 6, j + 38, k + 25, Blocks.log, 1);
		world.setBlockMetadataWithNotify(i + 6, j + 38, k + 25, 1, 2);
		setBlock(world, i + 6, j + 38, k + 26, Blocks.log, 1);
		world.setBlockMetadataWithNotify(i + 6, j + 38, k + 26, 1, 2);
		setBlock(world, i + 6, j + 38, k + 27, Blocks.log, 1);
		world.setBlockMetadataWithNotify(i + 6, j + 38, k + 27, 1, 2);
		setBlock(world, i + 6, j + 38, k + 28, Blocks.log, 1);
		world.setBlockMetadataWithNotify(i + 6, j + 38, k + 28, 1, 2);
		setBlock(world, i + 6, j + 38, k + 29, Blocks.log, 1);
		world.setBlockMetadataWithNotify(i + 6, j + 38, k + 29, 1, 2);
		setBlock(world, i + 6, j + 38, k + 30, Blocks.log, 1);
		world.setBlockMetadataWithNotify(i + 6, j + 38, k + 30, 1, 2);
		setBlock(world, i + 6, j + 38, k + 31, Blocks.log, 1);
		world.setBlockMetadataWithNotify(i + 6, j + 38, k + 31, 1, 2);
		setBlock(world, i + 6, j + 39, k + 20, Blocks.log, 1);
		world.setBlockMetadataWithNotify(i + 6, j + 39, k + 20, 1, 2);
		setBlock(world, i + 6, j + 39, k + 21, Blocks.log, 1);
		world.setBlockMetadataWithNotify(i + 6, j + 39, k + 21, 1, 2);
		setBlock(world, i + 6, j + 39, k + 22, Blocks.log, 1);
		world.setBlockMetadataWithNotify(i + 6, j + 39, k + 22, 1, 2);
		setBlock(world, i + 6, j + 39, k + 23, Blocks.log, 1);
		world.setBlockMetadataWithNotify(i + 6, j + 39, k + 23, 1, 2);
		setBlock(world, i + 6, j + 39, k + 24, Blocks.log, 1);
		world.setBlockMetadataWithNotify(i + 6, j + 39, k + 24, 1, 2);
		setBlock(world, i + 6, j + 39, k + 25, Blocks.log, 1);
		world.setBlockMetadataWithNotify(i + 6, j + 39, k + 25, 1, 2);
		setBlock(world, i + 6, j + 39, k + 26, Blocks.log, 1);
		world.setBlockMetadataWithNotify(i + 6, j + 39, k + 26, 1, 2);
		setBlock(world, i + 6, j + 39, k + 27, Blocks.log, 1);
		world.setBlockMetadataWithNotify(i + 6, j + 39, k + 27, 1, 2);
		setBlock(world, i + 6, j + 39, k + 28, Blocks.log, 1);
		world.setBlockMetadataWithNotify(i + 6, j + 39, k + 28, 1, 2);
		setBlock(world, i + 6, j + 39, k + 29, Blocks.log, 1);
		world.setBlockMetadataWithNotify(i + 6, j + 39, k + 29, 1, 2);
		setBlock(world, i + 6, j + 39, k + 30, Blocks.log, 1);
		world.setBlockMetadataWithNotify(i + 6, j + 39, k + 30, 1, 2);
		setBlock(world, i + 6, j + 40, k + 21, Blocks.log, 1);
		world.setBlockMetadataWithNotify(i + 6, j + 40, k + 21, 1, 2);
		setBlock(world, i + 6, j + 40, k + 22, Blocks.log, 1);
		world.setBlockMetadataWithNotify(i + 6, j + 40, k + 22, 1, 2);
		setBlock(world, i + 6, j + 40, k + 23, Blocks.log, 1);
		world.setBlockMetadataWithNotify(i + 6, j + 40, k + 23, 1, 2);
		setBlock(world, i + 6, j + 40, k + 24, Blocks.log, 1);
		world.setBlockMetadataWithNotify(i + 6, j + 40, k + 24, 1, 2);
		setBlock(world, i + 6, j + 40, k + 25, Blocks.log, 1);
		world.setBlockMetadataWithNotify(i + 6, j + 40, k + 25, 1, 2);
		setBlock(world, i + 6, j + 40, k + 26, Blocks.log, 1);
		world.setBlockMetadataWithNotify(i + 6, j + 40, k + 26, 1, 2);
		setBlock(world, i + 6, j + 40, k + 27, Blocks.log, 1);
		world.setBlockMetadataWithNotify(i + 6, j + 40, k + 27, 1, 2);
		setBlock(world, i + 6, j + 40, k + 28, Blocks.log, 1);
		world.setBlockMetadataWithNotify(i + 6, j + 40, k + 28, 1, 2);
		setBlock(world, i + 6, j + 40, k + 29, Blocks.log, 1);
		world.setBlockMetadataWithNotify(i + 6, j + 40, k + 29, 1, 2);
		setBlock(world, i + 6, j + 41, k + 23, Blocks.log, 1);
		world.setBlockMetadataWithNotify(i + 6, j + 41, k + 23, 1, 2);
		setBlock(world, i + 6, j + 41, k + 24, Blocks.log, 1);
		world.setBlockMetadataWithNotify(i + 6, j + 41, k + 24, 1, 2);
		setBlock(world, i + 6, j + 41, k + 25, Blocks.log, 1);
		world.setBlockMetadataWithNotify(i + 6, j + 41, k + 25, 1, 2);
		setBlock(world, i + 6, j + 41, k + 26, Blocks.log, 1);
		world.setBlockMetadataWithNotify(i + 6, j + 41, k + 26, 1, 2);
		setBlock(world, i + 6, j + 41, k + 27, Blocks.log, 1);
		world.setBlockMetadataWithNotify(i + 6, j + 41, k + 27, 1, 2);
		setBlock(world, i + 6, j + 49, k + 7, Blocks.planks, 5);
		world.setBlockMetadataWithNotify(i + 6, j + 49, k + 7, 5, 2);
		setBlock(world, i + 6, j + 49, k + 8, Blocks.planks, 5);
		world.setBlockMetadataWithNotify(i + 6, j + 49, k + 8, 5, 2);
		setBlock(world, i + 6, j + 49, k + 9, Blocks.planks, 5);
		world.setBlockMetadataWithNotify(i + 6, j + 49, k + 9, 5, 2);
		setBlock(world, i + 6, j + 49, k + 10, Blocks.planks, 5);
		world.setBlockMetadataWithNotify(i + 6, j + 49, k + 10, 5, 2);
		setBlock(world, i + 6, j + 49, k + 11, Blocks.planks, 5);
		world.setBlockMetadataWithNotify(i + 6, j + 49, k + 11, 5, 2);
		setBlock(world, i + 7, j + 18, k + 3, Blocks.planks, 5);
		world.setBlockMetadataWithNotify(i + 7, j + 18, k + 3, 5, 2);
		setBlock(world, i + 7, j + 18, k + 4, Blocks.planks, 5);
		world.setBlockMetadataWithNotify(i + 7, j + 18, k + 4, 5, 2);
		setBlock(world, i + 7, j + 18, k + 5, Blocks.planks, 5);
		world.setBlockMetadataWithNotify(i + 7, j + 18, k + 5, 5, 2);
		setBlock(world, i + 7, j + 18, k + 6, Blocks.planks, 5);
		world.setBlockMetadataWithNotify(i + 7, j + 18, k + 6, 5, 2);
		setBlock(world, i + 7, j + 19, k + 3, Blocks.spruce_stairs, 1);
		world.setBlockMetadataWithNotify(i + 7, j + 19, k + 3, 1, 2);
		setBlock(world, i + 7, j + 19, k + 4, Blocks.spruce_stairs, 1);
		world.setBlockMetadataWithNotify(i + 7, j + 19, k + 4, 1, 2);
		setBlock(world, i + 7, j + 19, k + 5, Blocks.spruce_stairs, 1);
		world.setBlockMetadataWithNotify(i + 7, j + 19, k + 5, 1, 2);
		setBlock(world, i + 7, j + 19, k + 6, Blocks.spruce_stairs, 1);
		world.setBlockMetadataWithNotify(i + 7, j + 19, k + 6, 1, 2);
		setBlock(world, i + 7, j + 20, k + 0, Blocks.log, 1);
		world.setBlockMetadataWithNotify(i + 7, j + 20, k + 0, 1, 2);
		setBlock(world, i + 7, j + 22, k + 0, Blocks.torch, 5);
		world.setBlockMetadataWithNotify(i + 7, j + 22, k + 0, 5, 2);
		setBlock(world, i + 7, j + 25, k + 0, Blocks.log, 1);
		world.setBlockMetadataWithNotify(i + 7, j + 25, k + 0, 1, 2);
		setBlock(world, i + 7, j + 25, k + 1, Blocks.log, 1);
		world.setBlockMetadataWithNotify(i + 7, j + 25, k + 1, 1, 2);
		setBlock(world, i + 7, j + 25, k + 2, Blocks.log, 1);
		world.setBlockMetadataWithNotify(i + 7, j + 25, k + 2, 1, 2);
		setBlock(world, i + 7, j + 25, k + 3, Blocks.log, 1);
		world.setBlockMetadataWithNotify(i + 7, j + 25, k + 3, 1, 2);
		setBlock(world, i + 7, j + 26, k + 0, Blocks.log, 1);
		world.setBlockMetadataWithNotify(i + 7, j + 26, k + 0, 1, 2);
		setBlock(world, i + 7, j + 26, k + 1, Blocks.log, 1);
		world.setBlockMetadataWithNotify(i + 7, j + 26, k + 1, 1, 2);
		setBlock(world, i + 7, j + 26, k + 2, Blocks.log, 1);
		world.setBlockMetadataWithNotify(i + 7, j + 26, k + 2, 1, 2);
		setBlock(world, i + 7, j + 27, k + 21, Blocks.vine, 8);
		world.setBlockMetadataWithNotify(i + 7, j + 27, k + 21, 8, 2);
		setBlock(world, i + 7, j + 27, k + 22, Blocks.vine, 11);
		world.setBlockMetadataWithNotify(i + 7, j + 27, k + 22, 11, 2);
		setBlock(world, i + 7, j + 27, k + 24, Blocks.vine, 6);
		world.setBlockMetadataWithNotify(i + 7, j + 27, k + 24, 6, 2);
		setBlock(world, i + 7, j + 28, k + 21, Blocks.vine, 15);
		world.setBlockMetadataWithNotify(i + 7, j + 28, k + 21, 15, 2);
		setBlock(world, i + 7, j + 28, k + 22, Blocks.vine, 15);
		world.setBlockMetadataWithNotify(i + 7, j + 28, k + 22, 15, 2);
		setBlock(world, i + 7, j + 28, k + 23, Blocks.vine, 2);
		world.setBlockMetadataWithNotify(i + 7, j + 28, k + 23, 2, 2);
		setBlock(world, i + 7, j + 28, k + 24, Blocks.vine, 15);
		world.setBlockMetadataWithNotify(i + 7, j + 28, k + 24, 15, 2);
		setBlock(world, i + 7, j + 28, k + 26, Blocks.vine, 5);
		world.setBlockMetadataWithNotify(i + 7, j + 28, k + 26, 5, 2);
		setBlock(world, i + 7, j + 29, k + 21, Blocks.vine, 15);
		world.setBlockMetadataWithNotify(i + 7, j + 29, k + 21, 15, 2);
		setBlock(world, i + 7, j + 29, k + 22, Blocks.vine, 15);
		world.setBlockMetadataWithNotify(i + 7, j + 29, k + 22, 15, 2);
		setBlock(world, i + 7, j + 29, k + 23, Blocks.vine, 15);
		world.setBlockMetadataWithNotify(i + 7, j + 29, k + 23, 15, 2);
		setBlock(world, i + 7, j + 29, k + 24, Blocks.vine, 15);
		world.setBlockMetadataWithNotify(i + 7, j + 29, k + 24, 15, 2);
		
		generate97(world, rand, i, j, k);
		return true;
		}

	
	public boolean generate97(World world, Random rand, int i, int j, int k)
	
	{
		setBlock(world, i + 7, j + 29, k + 26, Blocks.vine, 13);
		world.setBlockMetadataWithNotify(i + 7, j + 29, k + 26, 13, 2);
		setBlock(world, i + 7, j + 30, k + 20, Blocks.vine, 6);
		world.setBlockMetadataWithNotify(i + 7, j + 30, k + 20, 6, 2);
		setBlock(world, i + 7, j + 30, k + 21, Blocks.vine, 15);
		world.setBlockMetadataWithNotify(i + 7, j + 30, k + 21, 15, 2);
		setBlock(world, i + 7, j + 30, k + 22, Blocks.vine, 15);
		world.setBlockMetadataWithNotify(i + 7, j + 30, k + 22, 15, 2);
		setBlock(world, i + 7, j + 30, k + 23, Blocks.log, 1);
		world.setBlockMetadataWithNotify(i + 7, j + 30, k + 23, 1, 2);
		setBlock(world, i + 7, j + 30, k + 24, Blocks.vine, 15);
