package com.parzivail.pswm.world.gen.wookietree;


import cpw.mods.fml.common.IWorldGenerator;

import java.util.Random;

import net.minecraft.block.Block;

import net.minecraft.init.Blocks;

import net.minecraft.world.World;

import net.minecraft.world.chunk.IChunkProvider;

import net.minecraft.world.gen.feature.WorldGenerator;


public class WT_30 extends WorldGenerator implements IWorldGenerator

{
	protected Block[] getValidSpawnBlocks()
	
	{
		return new Block[0];
		}

	
	public boolean locationIsValidSpawn(World world, int i, int j, int k)
	
	{
		int distanceToAir = 0;
		Block check = world.getBlock(i, j, k);
		
		while (check != Blocks.air)
		{
			if (distanceToAir > 3) { return false;
			}
			
			distanceToAir++;
			check = world.getBlock(i, j + distanceToAir, k);
			}
		
		j += distanceToAir - 1;
		
		Block block = world.getBlock(i, j, k);
		Block blockAbove = world.getBlock(i, j + 1, k);
		Block blockBelow = world.getBlock(i, j - 1, k);
		
		for (Block x : getValidSpawnBlocks())
		{
			if (blockAbove != Blocks.air) { return false;
			}
			if (block == x) return true;
			if ((block == Blocks.snow) && (blockBelow == x)) { return true;
			}
			}
		
		return false;
		}

	
	
	
	public void generate(Random random, int chunkX, int chunkZ, World world, IChunkProvider chunkGenerator, IChunkProvider chunkProvider)
	{
	}

	
	
	public void setBlock(World world, int x, int y, int z, Block block, int metadata)
	
	{
		world.setBlock(x, y, z, block, metadata, 2);
		}

	
	public boolean generate(World world, Random rand, int i, int j, int k)
	
	{
		k -= 10;
		i -= 10;
		
		setBlock(world, i + 29, j + 47, k + 26, Blocks.fence, 0);
		setBlock(world, i + 30, j + 47, k + 23, Blocks.fence, 0);
		setBlock(world, i + 30, j + 47, k + 24, Blocks.fence, 0);
		setBlock(world, i + 30, j + 47, k + 25, Blocks.fence, 0);
		setBlock(world, i + 30, j + 47, k + 26, Blocks.fence, 0);
		setBlock(world, i + 31, j + 47, k + 21, Blocks.fence, 0);
		setBlock(world, i + 31, j + 47, k + 22, Blocks.fence, 0);
		setBlock(world, i + 31, j + 47, k + 23, Blocks.fence, 0);
		setBlock(world, i + 1, j + 27, k + 28, Blocks.leaves, 7);
		world.setBlockMetadataWithNotify(i + 1, j + 27, k + 28, 7, 2);
		setBlock(world, i + 1, j + 27, k + 29, Blocks.leaves, 7);
		world.setBlockMetadataWithNotify(i + 1, j + 27, k + 29, 7, 2);
		setBlock(world, i + 1, j + 27, k + 30, Blocks.leaves, 7);
		world.setBlockMetadataWithNotify(i + 1, j + 27, k + 30, 7, 2);
		setBlock(world, i + 1, j + 28, k + 29, Blocks.leaves, 7);
		world.setBlockMetadataWithNotify(i + 1, j + 28, k + 29, 7, 2);
		setBlock(world, i + 2, j + 27, k + 27, Blocks.leaves, 7);
		world.setBlockMetadataWithNotify(i + 2, j + 27, k + 27, 7, 2);
		setBlock(world, i + 2, j + 27, k + 28, Blocks.leaves, 7);
		world.setBlockMetadataWithNotify(i + 2, j + 27, k + 28, 7, 2);
		setBlock(world, i + 2, j + 27, k + 29, Blocks.leaves, 7);
		world.setBlockMetadataWithNotify(i + 2, j + 27, k + 29, 7, 2);
		setBlock(world, i + 2, j + 27, k + 30, Blocks.leaves, 7);
		world.setBlockMetadataWithNotify(i + 2, j + 27, k + 30, 7, 2);
		setBlock(world, i + 2, j + 27, k + 31, Blocks.leaves, 7);
		world.setBlockMetadataWithNotify(i + 2, j + 27, k + 31, 7, 2);
		setBlock(world, i + 2, j + 28, k + 28, Blocks.leaves, 7);
		world.setBlockMetadataWithNotify(i + 2, j + 28, k + 28, 7, 2);
		setBlock(world, i + 2, j + 28, k + 29, Blocks.leaves, 7);
		world.setBlockMetadataWithNotify(i + 2, j + 28, k + 29, 7, 2);
		setBlock(world, i + 2, j + 28, k + 30, Blocks.leaves, 7);
		world.setBlockMetadataWithNotify(i + 2, j + 28, k + 30, 7, 2);
		setBlock(world, i + 2, j + 29, k + 29, Blocks.leaves, 7);
		world.setBlockMetadataWithNotify(i + 2, j + 29, k + 29, 7, 2);
		setBlock(world, i + 3, j + 23, k + 23, Blocks.leaves, 7);
		world.setBlockMetadataWithNotify(i + 3, j + 23, k + 23, 7, 2);
		setBlock(world, i + 3, j + 23, k + 24, Blocks.leaves, 7);
		world.setBlockMetadataWithNotify(i + 3, j + 23, k + 24, 7, 2);
		setBlock(world, i + 3, j + 23, k + 25, Blocks.leaves, 7);
		world.setBlockMetadataWithNotify(i + 3, j + 23, k + 25, 7, 2);
		setBlock(world, i + 3, j + 24, k + 24, Blocks.leaves, 7);
		world.setBlockMetadataWithNotify(i + 3, j + 24, k + 24, 7, 2);
		setBlock(world, i + 3, j + 27, k + 27, Blocks.leaves, 7);
		world.setBlockMetadataWithNotify(i + 3, j + 27, k + 27, 7, 2);
		setBlock(world, i + 3, j + 27, k + 28, Blocks.leaves, 7);
		world.setBlockMetadataWithNotify(i + 3, j + 27, k + 28, 7, 2);
		setBlock(world, i + 3, j + 27, k + 29, Blocks.log, 3);
		world.setBlockMetadataWithNotify(i + 3, j + 27, k + 29, 3, 2);
		setBlock(world, i + 3, j + 27, k + 30, Blocks.leaves, 7);
		world.setBlockMetadataWithNotify(i + 3, j + 27, k + 30, 7, 2);
		setBlock(world, i + 3, j + 27, k + 31, Blocks.leaves, 7);
		world.setBlockMetadataWithNotify(i + 3, j + 27, k + 31, 7, 2);
		setBlock(world, i + 3, j + 28, k + 27, Blocks.leaves, 7);
		world.setBlockMetadataWithNotify(i + 3, j + 28, k + 27, 7, 2);
		setBlock(world, i + 3, j + 28, k + 28, Blocks.leaves, 7);
		world.setBlockMetadataWithNotify(i + 3, j + 28, k + 28, 7, 2);
		setBlock(world, i + 3, j + 28, k + 29, Blocks.leaves, 7);
		world.setBlockMetadataWithNotify(i + 3, j + 28, k + 29, 7, 2);
		setBlock(world, i + 3, j + 28, k + 30, Blocks.leaves, 7);
		world.setBlockMetadataWithNotify(i + 3, j + 28, k + 30, 7, 2);
		setBlock(world, i + 3, j + 28, k + 31, Blocks.leaves, 7);
		world.setBlockMetadataWithNotify(i + 3, j + 28, k + 31, 7, 2);
		setBlock(world, i + 3, j + 29, k + 28, Blocks.leaves, 7);
		world.setBlockMetadataWithNotify(i + 3, j + 29, k + 28, 7, 2);
		setBlock(world, i + 3, j + 29, k + 29, Blocks.leaves, 7);
		world.setBlockMetadataWithNotify(i + 3, j + 29, k + 29, 7, 2);
		setBlock(world, i + 3, j + 29, k + 30, Blocks.leaves, 7);
		world.setBlockMetadataWithNotify(i + 3, j + 29, k + 30, 7, 2);
		setBlock(world, i + 3, j + 29, k + 31, Blocks.leaves, 7);
		world.setBlockMetadataWithNotify(i + 3, j + 29, k + 31, 7, 2);
		setBlock(world, i + 3, j + 30, k + 29, Blocks.leaves, 7);
		world.setBlockMetadataWithNotify(i + 3, j + 30, k + 29, 7, 2);
		setBlock(world, i + 4, j + 23, k + 22, Blocks.leaves, 7);
		world.setBlockMetadataWithNotify(i + 4, j + 23, k + 22, 7, 2);
		setBlock(world, i + 4, j + 23, k + 23, Blocks.leaves, 7);
		world.setBlockMetadataWithNotify(i + 4, j + 23, k + 23, 7, 2);
		setBlock(world, i + 4, j + 23, k + 24, Blocks.leaves, 7);
		world.setBlockMetadataWithNotify(i + 4, j + 23, k + 24, 7, 2);
		setBlock(world, i + 4, j + 23, k + 25, Blocks.leaves, 7);
		world.setBlockMetadataWithNotify(i + 4, j + 23, k + 25, 7, 2);
		setBlock(world, i + 4, j + 23, k + 26, Blocks.leaves, 7);
		world.setBlockMetadataWithNotify(i + 4, j + 23, k + 26, 7, 2);
		setBlock(world, i + 4, j + 24, k + 23, Blocks.leaves, 7);
		world.setBlockMetadataWithNotify(i + 4, j + 24, k + 23, 7, 2);
		setBlock(world, i + 4, j + 24, k + 24, Blocks.leaves, 7);
		world.setBlockMetadataWithNotify(i + 4, j + 24, k + 24, 7, 2);
		setBlock(world, i + 4, j + 24, k + 25, Blocks.leaves, 7);
		world.setBlockMetadataWithNotify(i + 4, j + 24, k + 25, 7, 2);
		setBlock(world, i + 4, j + 25, k + 24, Blocks.leaves, 7);
		world.setBlockMetadataWithNotify(i + 4, j + 25, k + 24, 7, 2);
		setBlock(world, i + 4, j + 26, k + 30, Blocks.log, 3);
		world.setBlockMetadataWithNotify(i + 4, j + 26, k + 30, 3, 2);
		setBlock(world, i + 4, j + 27, k + 27, Blocks.leaves, 7);
		world.setBlockMetadataWithNotify(i + 4, j + 27, k + 27, 7, 2);
		setBlock(world, i + 4, j + 27, k + 28, Blocks.leaves, 7);
		world.setBlockMetadataWithNotify(i + 4, j + 27, k + 28, 7, 2);
		setBlock(world, i + 4, j + 27, k + 29, Blocks.leaves, 7);
		world.setBlockMetadataWithNotify(i + 4, j + 27, k + 29, 7, 2);
		setBlock(world, i + 4, j + 27, k + 30, Blocks.leaves, 7);
		world.setBlockMetadataWithNotify(i + 4, j + 27, k + 30, 7, 2);
		setBlock(world, i + 4, j + 27, k + 31, Blocks.leaves, 7);
		world.setBlockMetadataWithNotify(i + 4, j + 27, k + 31, 7, 2);
		setBlock(world, i + 4, j + 28, k + 28, Blocks.leaves, 7);
		world.setBlockMetadataWithNotify(i + 4, j + 28, k + 28, 7, 2);
		setBlock(world, i + 4, j + 28, k + 29, Blocks.leaves, 7);
		world.setBlockMetadataWithNotify(i + 4, j + 28, k + 29, 7, 2);
		setBlock(world, i + 4, j + 28, k + 30, Blocks.leaves, 7);
		world.setBlockMetadataWithNotify(i + 4, j + 28, k + 30, 7, 2);
		setBlock(world, i + 4, j + 28, k + 31, Blocks.leaves, 7);
		world.setBlockMetadataWithNotify(i + 4, j + 28, k + 31, 7, 2);
		setBlock(world, i + 4, j + 29, k + 29, Blocks.leaves, 7);
		world.setBlockMetadataWithNotify(i + 4, j + 29, k + 29, 7, 2);
		setBlock(world, i + 4, j + 29, k + 30, Blocks.leaves, 7);
		world.setBlockMetadataWithNotify(i + 4, j + 29, k + 30, 7, 2);
		setBlock(world, i + 4, j + 29, k + 31, Blocks.leaves, 7);
		world.setBlockMetadataWithNotify(i + 4, j + 29, k + 31, 7, 2);
		setBlock(world, i + 4, j + 30, k + 31, Blocks.leaves, 7);
		world.setBlockMetadataWithNotify(i + 4, j + 30, k + 31, 7, 2);
		setBlock(world, i + 5, j + 23, k + 22, Blocks.leaves, 7);
		world.setBlockMetadataWithNotify(i + 5, j + 23, k + 22, 7, 2);
		setBlock(world, i + 5, j + 23, k + 23, Blocks.leaves, 7);
		world.setBlockMetadataWithNotify(i + 5, j + 23, k + 23, 7, 2);
		setBlock(world, i + 5, j + 23, k + 24, Blocks.log, 3);
		world.setBlockMetadataWithNotify(i + 5, j + 23, k + 24, 3, 2);
		setBlock(world, i + 5, j + 23, k + 25, Blocks.leaves, 7);
		world.setBlockMetadataWithNotify(i + 5, j + 23, k + 25, 7, 2);
		setBlock(world, i + 5, j + 23, k + 26, Blocks.leaves, 7);
		world.setBlockMetadataWithNotify(i + 5, j + 23, k + 26, 7, 2);
		setBlock(world, i + 5, j + 24, k + 22, Blocks.leaves, 7);
		world.setBlockMetadataWithNotify(i + 5, j + 24, k + 22, 7, 2);
		setBlock(world, i + 5, j + 24, k + 23, Blocks.leaves, 7);
		world.setBlockMetadataWithNotify(i + 5, j + 24, k + 23, 7, 2);
		setBlock(world, i + 5, j + 24, k + 24, Blocks.leaves, 7);
		world.setBlockMetadataWithNotify(i + 5, j + 24, k + 24, 7, 2);
		setBlock(world, i + 5, j + 24, k + 25, Blocks.leaves, 7);
		world.setBlockMetadataWithNotify(i + 5, j + 24, k + 25, 7, 2);
		setBlock(world, i + 5, j + 24, k + 26, Blocks.leaves, 7);
		world.setBlockMetadataWithNotify(i + 5, j + 24, k + 26, 7, 2);
		setBlock(world, i + 5, j + 25, k + 23, Blocks.leaves, 7);
		world.setBlockMetadataWithNotify(i + 5, j + 25, k + 23, 7, 2);
		setBlock(world, i + 5, j + 25, k + 24, Blocks.leaves, 7);
		world.setBlockMetadataWithNotify(i + 5, j + 25, k + 24, 7, 2);
		setBlock(world, i + 5, j + 25, k + 25, Blocks.leaves, 7);
		world.setBlockMetadataWithNotify(i + 5, j + 25, k + 25, 7, 2);
		setBlock(world, i + 5, j + 26, k + 24, Blocks.leaves, 7);
		world.setBlockMetadataWithNotify(i + 5, j + 26, k + 24, 7, 2);
		setBlock(world, i + 5, j + 26, k + 30, Blocks.log, 3);
		world.setBlockMetadataWithNotify(i + 5, j + 26, k + 30, 3, 2);
		setBlock(world, i + 5, j + 27, k + 28, Blocks.leaves, 7);
		world.setBlockMetadataWithNotify(i + 5, j + 27, k + 28, 7, 2);
		setBlock(world, i + 5, j + 27, k + 29, Blocks.leaves, 7);
		world.setBlockMetadataWithNotify(i + 5, j + 27, k + 29, 7, 2);
		setBlock(world, i + 5, j + 27, k + 30, Blocks.leaves, 7);
		world.setBlockMetadataWithNotify(i + 5, j + 27, k + 30, 7, 2);
		setBlock(world, i + 5, j + 28, k + 29, Blocks.leaves, 7);
		world.setBlockMetadataWithNotify(i + 5, j + 28, k + 29, 7, 2);
		setBlock(world, i + 5, j + 28, k + 30, Blocks.leaves, 7);
		world.setBlockMetadataWithNotify(i + 5, j + 28, k + 30, 7, 2);
		setBlock(world, i + 5, j + 28, k + 31, Blocks.log, 3);
		world.setBlockMetadataWithNotify(i + 5, j + 28, k + 31, 3, 2);
		setBlock(world, i + 5, j + 29, k + 29, Blocks.leaves, 7);
		world.setBlockMetadataWithNotify(i + 5, j + 29, k + 29, 7, 2);
		setBlock(world, i + 5, j + 29, k + 30, Blocks.leaves, 7);
		world.setBlockMetadataWithNotify(i + 5, j + 29, k + 30, 7, 2);
		setBlock(world, i + 5, j + 29, k + 31, Blocks.leaves, 7);
		world.setBlockMetadataWithNotify(i + 5, j + 29, k + 31, 7, 2);
		setBlock(world, i + 5, j + 30, k + 30, Blocks.leaves, 7);
		world.setBlockMetadataWithNotify(i + 5, j + 30, k + 30, 7, 2);
		setBlock(world, i + 5, j + 30, k + 31, Blocks.leaves, 7);
		world.setBlockMetadataWithNotify(i + 5, j + 30, k + 31, 7, 2);
		setBlock(world, i + 5, j + 31, k + 31, Blocks.leaves, 7);
		world.setBlockMetadataWithNotify(i + 5, j + 31, k + 31, 7, 2);
		setBlock(world, i + 6, j + 22, k + 25, Blocks.log, 3);
		world.setBlockMetadataWithNotify(i + 6, j + 22, k + 25, 3, 2);
		setBlock(world, i + 6, j + 23, k + 22, Blocks.leaves, 7);
		world.setBlockMetadataWithNotify(i + 6, j + 23, k + 22, 7, 2);
		setBlock(world, i + 6, j + 23, k + 23, Blocks.leaves, 7);
		world.setBlockMetadataWithNotify(i + 6, j + 23, k + 23, 7, 2);
		setBlock(world, i + 6, j + 23, k + 24, Blocks.leaves, 7);
		world.setBlockMetadataWithNotify(i + 6, j + 23, k + 24, 7, 2);
		setBlock(world, i + 6, j + 23, k + 25, Blocks.leaves, 7);
		world.setBlockMetadataWithNotify(i + 6, j + 23, k + 25, 7, 2);
		setBlock(world, i + 6, j + 23, k + 26, Blocks.leaves, 7);
		world.setBlockMetadataWithNotify(i + 6, j + 23, k + 26, 7, 2);
		setBlock(world, i + 6, j + 24, k + 23, Blocks.leaves, 7);
		world.setBlockMetadataWithNotify(i + 6, j + 24, k + 23, 7, 2);
		setBlock(world, i + 6, j + 24, k + 24, Blocks.leaves, 7);
		world.setBlockMetadataWithNotify(i + 6, j + 24, k + 24, 7, 2);
		setBlock(world, i + 6, j + 24, k + 25, Blocks.leaves, 7);
		world.setBlockMetadataWithNotify(i + 6, j + 24, k + 25, 7, 2);
		setBlock(world, i + 6, j + 25, k + 24, Blocks.leaves, 7);
		world.setBlockMetadataWithNotify(i + 6, j + 25, k + 24, 7, 2);
		setBlock(world, i + 6, j + 26, k + 31, Blocks.log, 3);
		world.setBlockMetadataWithNotify(i + 6, j + 26, k + 31, 3, 2);
		setBlock(world, i + 6, j + 28, k + 29, Blocks.leaves, 7);
		world.setBlockMetadataWithNotify(i + 6, j + 28, k + 29, 7, 2);
		setBlock(world, i + 6, j + 28, k + 30, Blocks.leaves, 7);
		world.setBlockMetadataWithNotify(i + 6, j + 28, k + 30, 7, 2);
		setBlock(world, i + 6, j + 28, k + 31, Blocks.leaves, 7);
		world.setBlockMetadataWithNotify(i + 6, j + 28, k + 31, 7, 2);
		setBlock(world, i + 6, j + 29, k + 30, Blocks.leaves, 7);
		world.setBlockMetadataWithNotify(i + 6, j + 29, k + 30, 7, 2);
		setBlock(world, i + 6, j + 29, k + 31, Blocks.leaves, 7);
		world.setBlockMetadataWithNotify(i + 6, j + 29, k + 31, 7, 2);
		setBlock(world, i + 6, j + 30, k + 31, Blocks.leaves, 7);
		world.setBlockMetadataWithNotify(i + 6, j + 30, k + 31, 7, 2);
		setBlock(world, i + 7, j + 22, k + 26, Blocks.log, 3);
		world.setBlockMetadataWithNotify(i + 7, j + 22, k + 26, 3, 2);
		setBlock(world, i + 7, j + 23, k + 19, Blocks.leaves, 7);
		world.setBlockMetadataWithNotify(i + 7, j + 23, k + 19, 7, 2);
		setBlock(world, i + 7, j + 23, k + 20, Blocks.leaves, 7);
		world.setBlockMetadataWithNotify(i + 7, j + 23, k + 20, 7, 2);
		setBlock(world, i + 7, j + 23, k + 21, Blocks.leaves, 7);
		world.setBlockMetadataWithNotify(i + 7, j + 23, k + 21, 7, 2);
		setBlock(world, i + 7, j + 23, k + 23, Blocks.leaves, 7);
		world.setBlockMetadataWithNotify(i + 7, j + 23, k + 23, 7, 2);
		setBlock(world, i + 7, j + 23, k + 24, Blocks.leaves, 7);
		world.setBlockMetadataWithNotify(i + 7, j + 23, k + 24, 7, 2);
		setBlock(world, i + 7, j + 23, k + 25, Blocks.leaves, 7);
		world.setBlockMetadataWithNotify(i + 7, j + 23, k + 25, 7, 2);
		setBlock(world, i + 7, j + 24, k + 20, Blocks.leaves, 7);
		world.setBlockMetadataWithNotify(i + 7, j + 24, k + 20, 7, 2);
		setBlock(world, i + 7, j + 24, k + 24, Blocks.leaves, 7);
		world.setBlockMetadataWithNotify(i + 7, j + 24, k + 24, 7, 2);
		setBlock(world, i + 7, j + 25, k + 31, Blocks.log, 3);
		world.setBlockMetadataWithNotify(i + 7, j + 25, k + 31, 3, 2);
		setBlock(world, i + 7, j + 28, k + 30, Blocks.leaves, 7);
		world.setBlockMetadataWithNotify(i + 7, j + 28, k + 30, 7, 2);
		setBlock(world, i + 7, j + 28, k + 31, Blocks.leaves, 7);
		world.setBlockMetadataWithNotify(i + 7, j + 28, k + 31, 7, 2);
		setBlock(world, i + 7, j + 29, k + 31, Blocks.leaves, 7);
		world.setBlockMetadataWithNotify(i + 7, j + 29, k + 31, 7, 2);
		setBlock(world, i + 8, j + 22, k + 27, Blocks.log, 3);
		world.setBlockMetadataWithNotify(i + 8, j + 22, k + 27, 3, 2);
		setBlock(world, i + 8, j + 23, k + 18, Blocks.leaves, 7);
		world.setBlockMetadataWithNotify(i + 8, j + 23, k + 18, 7, 2);
		setBlock(world, i + 8, j + 23, k + 19, Blocks.leaves, 7);
		world.setBlockMetadataWithNotify(i + 8, j + 23, k + 19, 7, 2);
		setBlock(world, i + 8, j + 23, k + 20, Blocks.leaves, 7);
		world.setBlockMetadataWithNotify(i + 8, j + 23, k + 20, 7, 2);
		setBlock(world, i + 8, j + 23, k + 21, Blocks.leaves, 7);
		world.setBlockMetadataWithNotify(i + 8, j + 23, k + 21, 7, 2);
		setBlock(world, i + 8, j + 23, k + 22, Blocks.leaves, 7);
		world.setBlockMetadataWithNotify(i + 8, j + 23, k + 22, 7, 2);
		setBlock(world, i + 8, j + 24, k + 19, Blocks.leaves, 7);
		world.setBlockMetadataWithNotify(i + 8, j + 24, k + 19, 7, 2);
		setBlock(world, i + 8, j + 24, k + 20, Blocks.leaves, 7);
		world.setBlockMetadataWithNotify(i + 8, j + 24, k + 20, 7, 2);
		setBlock(world, i + 8, j + 24, k + 21, Blocks.leaves, 7);
		world.setBlockMetadataWithNotify(i + 8, j + 24, k + 21, 7, 2);
		setBlock(world, i + 8, j + 25, k + 20, Blocks.leaves, 7);
		world.setBlockMetadataWithNotify(i + 8, j + 25, k + 20, 7, 2);
		setBlock(world, i + 9, j + 21, k + 28, Blocks.log, 3);
		world.setBlockMetadataWithNotify(i + 9, j + 21, k + 28, 3, 2);
		setBlock(world, i + 9, j + 22, k + 21, Blocks.log, 3);
		world.setBlockMetadataWithNotify(i + 9, j + 22, k + 21, 3, 2);
		setBlock(world, i + 9, j + 23, k + 18, Blocks.leaves, 7);
		world.setBlockMetadataWithNotify(i + 9, j + 23, k + 18, 7, 2);
		setBlock(world, i + 9, j + 23, k + 19, Blocks.leaves, 7);
		world.setBlockMetadataWithNotify(i + 9, j + 23, k + 19, 7, 2);
		setBlock(world, i + 9, j + 23, k + 20, Blocks.log, 3);
		world.setBlockMetadataWithNotify(i + 9, j + 23, k + 20, 3, 2);
		setBlock(world, i + 9, j + 23, k + 21, Blocks.leaves, 7);
		world.setBlockMetadataWithNotify(i + 9, j + 23, k + 21, 7, 2);
		setBlock(world, i + 9, j + 23, k + 22, Blocks.leaves, 7);
		world.setBlockMetadataWithNotify(i + 9, j + 23, k + 22, 7, 2);
		setBlock(world, i + 9, j + 24, k + 18, Blocks.leaves, 7);
		world.setBlockMetadataWithNotify(i + 9, j + 24, k + 18, 7, 2);
		setBlock(world, i + 9, j + 24, k + 19, Blocks.leaves, 7);
		world.setBlockMetadataWithNotify(i + 9, j + 24, k + 19, 7, 2);
		setBlock(world, i + 9, j + 24, k + 20, Blocks.leaves, 7);
		world.setBlockMetadataWithNotify(i + 9, j + 24, k + 20, 7, 2);
		setBlock(world, i + 9, j + 24, k + 21, Blocks.leaves, 7);
		world.setBlockMetadataWithNotify(i + 9, j + 24, k + 21, 7, 2);
		setBlock(world, i + 9, j + 24, k + 22, Blocks.leaves, 7);
		world.setBlockMetadataWithNotify(i + 9, j + 24, k + 22, 7, 2);
		setBlock(world, i + 9, j + 25, k + 19, Blocks.leaves, 7);
		world.setBlockMetadataWithNotify(i + 9, j + 25, k + 19, 7, 2);
		setBlock(world, i + 9, j + 25, k + 20, Blocks.leaves, 7);
		world.setBlockMetadataWithNotify(i + 9, j + 25, k + 20, 7, 2);
		setBlock(world, i + 9, j + 25, k + 21, Blocks.leaves, 7);
		world.setBlockMetadataWithNotify(i + 9, j + 25, k + 21, 7, 2);
		setBlock(world, i + 9, j + 26, k + 20, Blocks.leaves, 7);
		world.setBlockMetadataWithNotify(i + 9, j + 26, k + 20, 7, 2);
		setBlock(world, i + 9, j + 34, k + 26, Blocks.log, 1);
		world.setBlockMetadataWithNotify(i + 9, j + 34, k + 26, 1, 2);
		setBlock(world, i + 9, j + 35, k + 25, Blocks.log, 1);
		world.setBlockMetadataWithNotify(i + 9, j + 35, k + 25, 1, 2);
		setBlock(world, i + 9, j + 35, k + 27, Blocks.log, 1);
		world.setBlockMetadataWithNotify(i + 9, j + 35, k + 27, 1, 2);
		setBlock(world, i + 9, j + 36, k + 26, Blocks.log, 1);
		world.setBlockMetadataWithNotify(i + 9, j + 36, k + 26, 1, 2);
		setBlock(world, i + 9, j + 36, k + 27, Blocks.leaves, 7);
		world.setBlockMetadataWithNotify(i + 9, j + 36, k + 27, 7, 2);
		setBlock(world, i + 9, j + 36, k + 28, Blocks.leaves, 7);
		world.setBlockMetadataWithNotify(i + 9, j + 36, k + 28, 7, 2);
		setBlock(world, i + 9, j + 37, k + 27, Blocks.leaves, 7);
		world.setBlockMetadataWithNotify(i + 9, j + 37, k + 27, 7, 2);
		setBlock(world, i + 10, j + 21, k + 28, Blocks.log, 3);
		world.setBlockMetadataWithNotify(i + 10, j + 21, k + 28, 3, 2);
		setBlock(world, i + 10, j + 22, k + 22, Blocks.log, 3);
		world.setBlockMetadataWithNotify(i + 10, j + 22, k + 22, 3, 2);
		setBlock(world, i + 10, j + 22, k + 23, Blocks.log, 3);
		world.setBlockMetadataWithNotify(i + 10, j + 22, k + 23, 3, 2);
		setBlock(world, i + 10, j + 23, k + 18, Blocks.leaves, 7);
		world.setBlockMetadataWithNotify(i + 10, j + 23, k + 18, 7, 2);
		setBlock(world, i + 10, j + 23, k + 19, Blocks.leaves, 7);
		world.setBlockMetadataWithNotify(i + 10, j + 23, k + 19, 7, 2);
		setBlock(world, i + 10, j + 23, k + 20, Blocks.leaves, 7);
		world.setBlockMetadataWithNotify(i + 10, j + 23, k + 20, 7, 2);
		setBlock(world, i + 10, j + 23, k + 21, Blocks.leaves, 7);
		world.setBlockMetadataWithNotify(i + 10, j + 23, k + 21, 7, 2);
		setBlock(world, i + 10, j + 23, k + 22, Blocks.leaves, 7);
		world.setBlockMetadataWithNotify(i + 10, j + 23, k + 22, 7, 2);
		setBlock(world, i + 10, j + 24, k + 19, Blocks.leaves, 7);
		world.setBlockMetadataWithNotify(i + 10, j + 24, k + 19, 7, 2);
		setBlock(world, i + 10, j + 24, k + 20, Blocks.leaves, 7);
		world.setBlockMetadataWithNotify(i + 10, j + 24, k + 20, 7, 2);
		setBlock(world, i + 10, j + 24, k + 21, Blocks.leaves, 7);
		world.setBlockMetadataWithNotify(i + 10, j + 24, k + 21, 7, 2);
		setBlock(world, i + 10, j + 25, k + 20, Blocks.leaves, 7);
		world.setBlockMetadataWithNotify(i + 10, j + 25, k + 20, 7, 2);
		setBlock(world, i + 10, j + 34, k + 25, Blocks.log, 1);
		world.setBlockMetadataWithNotify(i + 10, j + 34, k + 25, 1, 2);
		setBlock(world, i + 10, j + 34, k + 27, Blocks.log, 1);
		world.setBlockMetadataWithNotify(i + 10, j + 34, k + 27, 1, 2);
		setBlock(world, i + 10, j + 35, k + 25, Blocks.log, 1);
		world.setBlockMetadataWithNotify(i + 10, j + 35, k + 25, 1, 2);
		setBlock(world, i + 10, j + 35, k + 26, Blocks.log, 1);
		world.setBlockMetadataWithNotify(i + 10, j + 35, k + 26, 1, 2);
		setBlock(world, i + 10, j + 35, k + 27, Blocks.log, 1);
		world.setBlockMetadataWithNotify(i + 10, j + 35, k + 27, 1, 2);
		setBlock(world, i + 10, j + 36, k + 25, Blocks.log, 1);
		world.setBlockMetadataWithNotify(i + 10, j + 36, k + 25, 1, 2);
		setBlock(world, i + 10, j + 36, k + 26, Blocks.log, 1);
		world.setBlockMetadataWithNotify(i + 10, j + 36, k + 26, 1, 2);
		setBlock(world, i + 10, j + 36, k + 27, Blocks.log, 1);
		world.setBlockMetadataWithNotify(i + 10, j + 36, k + 27, 1, 2);
		setBlock(world, i + 10, j + 36, k + 28, Blocks.leaves, 7);
		world.setBlockMetadataWithNotify(i + 10, j + 36, k + 28, 7, 2);
		setBlock(world, i + 10, j + 36, k + 29, Blocks.leaves, 7);
		world.setBlockMetadataWithNotify(i + 10, j + 36, k + 29, 7, 2);
		setBlock(world, i + 10, j + 37, k + 26, Blocks.leaves, 7);
		world.setBlockMetadataWithNotify(i + 10, j + 37, k + 26, 7, 2);
		setBlock(world, i + 10, j + 37, k + 27, Blocks.leaves, 7);
		world.setBlockMetadataWithNotify(i + 10, j + 37, k + 27, 7, 2);
		setBlock(world, i + 10, j + 37, k + 28, Blocks.leaves, 7);
		world.setBlockMetadataWithNotify(i + 10, j + 37, k + 28, 7, 2);
		setBlock(world, i + 10, j + 38, k + 27, Blocks.leaves, 7);
		world.setBlockMetadataWithNotify(i + 10, j + 38, k + 27, 7, 2);
		setBlock(world, i + 10, j + 39, k + 31, Blocks.leaves, 7);
		world.setBlockMetadataWithNotify(i + 10, j + 39, k + 31, 7, 2);
		setBlock(world, i + 11, j + 21, k + 29, Blocks.log, 3);
		world.setBlockMetadataWithNotify(i + 11, j + 21, k + 29, 3, 2);
		setBlock(world, i + 11, j + 22, k + 24, Blocks.log, 3);
		world.setBlockMetadataWithNotify(i + 11, j + 22, k + 24, 3, 2);
		setBlock(world, i + 11, j + 23, k + 19, Blocks.leaves, 7);
		world.setBlockMetadataWithNotify(i + 11, j + 23, k + 19, 7, 2);
		setBlock(world, i + 11, j + 23, k + 20, Blocks.leaves, 7);
		world.setBlockMetadataWithNotify(i + 11, j + 23, k + 20, 7, 2);
		setBlock(world, i + 11, j + 23, k + 21, Blocks.leaves, 7);
		world.setBlockMetadataWithNotify(i + 11, j + 23, k + 21, 7, 2);
		setBlock(world, i + 11, j + 24, k + 20, Blocks.leaves, 7);
		world.setBlockMetadataWithNotify(i + 11, j + 24, k + 20, 7, 2);
		setBlock(world, i + 11, j + 34, k + 26, Blocks.log, 1);
		world.setBlockMetadataWithNotify(i + 11, j + 34, k + 26, 1, 2);
		setBlock(world, i + 11, j + 34, k + 28, Blocks.log, 1);
		world.setBlockMetadataWithNotify(i + 11, j + 34, k + 28, 1, 2);
		setBlock(world, i + 11, j + 35, k + 25, Blocks.log, 1);
		world.setBlockMetadataWithNotify(i + 11, j + 35, k + 25, 1, 2);
		setBlock(world, i + 11, j + 35, k + 26, Blocks.log, 1);
		world.setBlockMetadataWithNotify(i + 11, j + 35, k + 26, 1, 2);
		setBlock(world, i + 11, j + 35, k + 27, Blocks.log, 1);
		world.setBlockMetadataWithNotify(i + 11, j + 35, k + 27, 1, 2);
		setBlock(world, i + 11, j + 35, k + 28, Blocks.log, 1);
		world.setBlockMetadataWithNotify(i + 11, j + 35, k + 28, 1, 2);
		setBlock(world, i + 11, j + 36, k + 25, Blocks.leaves, 7);
		world.setBlockMetadataWithNotify(i + 11, j + 36, k + 25, 7, 2);
		setBlock(world, i + 11, j + 36, k + 26, Blocks.log, 1);
		world.setBlockMetadataWithNotify(i + 11, j + 36, k + 26, 1, 2);
		setBlock(world, i + 11, j + 36, k + 27, Blocks.log, 1);
		world.setBlockMetadataWithNotify(i + 11, j + 36, k + 27, 1, 2);
		setBlock(world, i + 11, j + 36, k + 28, Blocks.log, 1);
		world.setBlockMetadataWithNotify(i + 11, j + 36, k + 28, 1, 2);
		setBlock(world, i + 11, j + 36, k + 29, Blocks.leaves, 7);
		world.setBlockMetadataWithNotify(i + 11, j + 36, k + 29, 7, 2);
		setBlock(world, i + 11, j + 37, k + 25, Blocks.leaves, 7);
		world.setBlockMetadataWithNotify(i + 11, j + 37, k + 25, 7, 2);
		setBlock(world, i + 11, j + 37, k + 26, Blocks.leaves, 7);
		world.setBlockMetadataWithNotify(i + 11, j + 37, k + 26, 7, 2);
		setBlock(world, i + 11, j + 37, k + 27, Blocks.leaves, 7);
		world.setBlockMetadataWithNotify(i + 11, j + 37, k + 27, 7, 2);
		setBlock(world, i + 11, j + 37, k + 28, Blocks.leaves, 7);
		world.setBlockMetadataWithNotify(i + 11, j + 37, k + 28, 7, 2);
		setBlock(world, i + 11, j + 37, k + 29, Blocks.leaves, 7);
		world.setBlockMetadataWithNotify(i + 11, j + 37, k + 29, 7, 2);
		setBlock(world, i + 11, j + 38, k + 26, Blocks.leaves, 7);
		world.setBlockMetadataWithNotify(i + 11, j + 38, k + 26, 7, 2);
		setBlock(world, i + 11, j + 38, k + 27, Blocks.leaves, 7);
		world.setBlockMetadataWithNotify(i + 11, j + 38, k + 27, 7, 2);
		setBlock(world, i + 11, j + 38, k + 28, Blocks.leaves, 7);
		world.setBlockMetadataWithNotify(i + 11, j + 38, k + 28, 7, 2);
		setBlock(world, i + 11, j + 38, k + 29, Blocks.leaves, 7);
		world.setBlockMetadataWithNotify(i + 11, j + 38, k + 29, 7, 2);
		setBlock(world, i + 11, j + 39, k + 27, Blocks.leaves, 7);
		world.setBlockMetadataWithNotify(i + 11, j + 39, k + 27, 7, 2);
		setBlock(world, i + 11, j + 39, k + 28, Blocks.leaves, 7);
		world.setBlockMetadataWithNotify(i + 11, j + 39, k + 28, 7, 2);
		setBlock(world, i + 11, j + 39, k + 30, Blocks.leaves, 7);
		world.setBlockMetadataWithNotify(i + 11, j + 39, k + 30, 7, 2);
		setBlock(world, i + 11, j + 39, k + 31, Blocks.leaves, 7);
		world.setBlockMetadataWithNotify(i + 11, j + 39, k + 31, 7, 2);
		setBlock(world, i + 11, j + 40, k + 31, Blocks.leaves, 7);
		world.setBlockMetadataWithNotify(i + 11, j + 40, k + 31, 7, 2);
		setBlock(world, i + 12, j + 20, k + 30, Blocks.log, 3);
		world.setBlockMetadataWithNotify(i + 12, j + 20, k + 30, 3, 2);
		setBlock(world, i + 12, j + 21, k + 26, Blocks.log, 3);
		world.setBlockMetadataWithNotify(i + 12, j + 21, k + 26, 3, 2);
		setBlock(world, i + 12, j + 22, k + 25, Blocks.log, 3);
		world.setBlockMetadataWithNotify(i + 12, j + 22, k + 25, 3, 2);
		setBlock(world, i + 12, j + 34, k + 27, Blocks.log, 1);
		world.setBlockMetadataWithNotify(i + 12, j + 34, k + 27, 1, 2);
		setBlock(world, i + 12, j + 35, k + 26, Blocks.log, 1);
		world.setBlockMetadataWithNotify(i + 12, j + 35, k + 26, 1, 2);
		setBlock(world, i + 12, j + 35, k + 27, Blocks.log, 1);
		world.setBlockMetadataWithNotify(i + 12, j + 35, k + 27, 1, 2);
		setBlock(world, i + 12, j + 36, k + 25, Blocks.leaves, 7);
		world.setBlockMetadataWithNotify(i + 12, j + 36, k + 25, 7, 2);
		setBlock(world, i + 12, j + 36, k + 26, Blocks.leaves, 7);
		world.setBlockMetadataWithNotify(i + 12, j + 36, k + 26, 7, 2);
		setBlock(world, i + 12, j + 36, k + 27, Blocks.log, 1);
		world.setBlockMetadataWithNotify(i + 12, j + 36, k + 27, 1, 2);
		setBlock(world, i + 12, j + 36, k + 28, Blocks.leaves, 7);
		world.setBlockMetadataWithNotify(i + 12, j + 36, k + 28, 7, 2);
		setBlock(world, i + 12, j + 36, k + 29, Blocks.leaves, 7);
		world.setBlockMetadataWithNotify(i + 12, j + 36, k + 29, 7, 2);
		setBlock(world, i + 12, j + 37, k + 26, Blocks.leaves, 7);
		world.setBlockMetadataWithNotify(i + 12, j + 37, k + 26, 7, 2);
		setBlock(world, i + 12, j + 37, k + 27, Blocks.leaves, 7);
		world.setBlockMetadataWithNotify(i + 12, j + 37, k + 27, 7, 2);
		setBlock(world, i + 12, j + 37, k + 28, Blocks.leaves, 7);
		world.setBlockMetadataWithNotify(i + 12, j + 37, k + 28, 7, 2);
		setBlock(world, i + 12, j + 38, k + 26, Blocks.leaves, 7);
		world.setBlockMetadataWithNotify(i + 12, j + 38, k + 26, 7, 2);
		setBlock(world, i + 12, j + 38, k + 27, Blocks.leaves, 7);
		world.setBlockMetadataWithNotify(i + 12, j + 38, k + 27, 7, 2);
		setBlock(world, i + 12, j + 38, k + 28, Blocks.leaves, 7);
		world.setBlockMetadataWithNotify(i + 12, j + 38, k + 28, 7, 2);
		setBlock(world, i + 12, j + 38, k + 29, Blocks.leaves, 7);
		world.setBlockMetadataWithNotify(i + 12, j + 38, k + 29, 7, 2);
		setBlock(world, i + 12, j + 38, k + 30, Blocks.leaves, 7);
		world.setBlockMetadataWithNotify(i + 12, j + 38, k + 30, 7, 2);
		setBlock(world, i + 12, j + 39, k + 27, Blocks.leaves, 7);
		world.setBlockMetadataWithNotify(i + 12, j + 39, k + 27, 7, 2);
		setBlock(world, i + 12, j + 39, k + 28, Blocks.leaves, 7);
		world.setBlockMetadataWithNotify(i + 12, j + 39, k + 28, 7, 2);
		setBlock(world, i + 12, j + 39, k + 29, Blocks.leaves, 7);
		world.setBlockMetadataWithNotify(i + 12, j + 39, k + 29, 7, 2);
		setBlock(world, i + 12, j + 39, k + 30, Blocks.leaves, 7);
		world.setBlockMetadataWithNotify(i + 12, j + 39, k + 30, 7, 2);
		setBlock(world, i + 12, j + 39, k + 31, Blocks.leaves, 7);
		world.setBlockMetadataWithNotify(i + 12, j + 39, k + 31, 7, 2);
		setBlock(world, i + 12, j + 40, k + 28, Blocks.leaves, 7);
		world.setBlockMetadataWithNotify(i + 12, j + 40, k + 28, 7, 2);
		setBlock(world, i + 12, j + 40, k + 30, Blocks.leaves, 7);
		world.setBlockMetadataWithNotify(i + 12, j + 40, k + 30, 7, 2);
		setBlock(world, i + 12, j + 40, k + 31, Blocks.leaves, 7);
		world.setBlockMetadataWithNotify(i + 12, j + 40, k + 31, 7, 2);
		setBlock(world, i + 12, j + 41, k + 31, Blocks.leaves, 7);
		world.setBlockMetadataWithNotify(i + 12, j + 41, k + 31, 7, 2);
		setBlock(world, i + 12, j + 46, k + 31, Blocks.leaves, 7);
		world.setBlockMetadataWithNotify(i + 12, j + 46, k + 31, 7, 2);
		setBlock(world, i + 13, j + 20, k + 31, Blocks.log, 3);
		world.setBlockMetadataWithNotify(i + 13, j + 20, k + 31, 3, 2);
		setBlock(world, i + 13, j + 21, k + 27, Blocks.log, 3);
		world.setBlockMetadataWithNotify(i + 13, j + 21, k + 27, 3, 2);
		setBlock(world, i + 13, j + 36, k + 26, Blocks.leaves, 7);
		world.setBlockMetadataWithNotify(i + 13, j + 36, k + 26, 7, 2);
		setBlock(world, i + 13, j + 36, k + 27, Blocks.leaves, 7);
		world.setBlockMetadataWithNotify(i + 13, j + 36, k + 27, 7, 2);
		setBlock(world, i + 13, j + 36, k + 28, Blocks.leaves, 7);
		world.setBlockMetadataWithNotify(i + 13, j + 36, k + 28, 7, 2);
		setBlock(world, i + 13, j + 37, k + 27, Blocks.leaves, 7);
		world.setBlockMetadataWithNotify(i + 13, j + 37, k + 27, 7, 2);
		setBlock(world, i + 13, j + 37, k + 29, Blocks.log, 3);
		world.setBlockMetadataWithNotify(i + 13, j + 37, k + 29, 3, 2);
		setBlock(world, i + 13, j + 38, k + 26, Blocks.leaves, 7);
		world.setBlockMetadataWithNotify(i + 13, j + 38, k + 26, 7, 2);
		setBlock(world, i + 13, j + 38, k + 27, Blocks.leaves, 7);
		world.setBlockMetadataWithNotify(i + 13, j + 38, k + 27, 7, 2);
		setBlock(world, i + 13, j + 38, k + 28, Blocks.log, 3);
		world.setBlockMetadataWithNotify(i + 13, j + 38, k + 28, 3, 2);
		setBlock(world, i + 13, j + 38, k + 29, Blocks.leaves, 7);
		world.setBlockMetadataWithNotify(i + 13, j + 38, k + 29, 7, 2);
		setBlock(world, i + 13, j + 38, k + 30, Blocks.leaves, 7);
		world.setBlockMetadataWithNotify(i + 13, j + 38, k + 30, 7, 2);
		setBlock(world, i + 13, j + 39, k + 26, Blocks.leaves, 7);
		world.setBlockMetadataWithNotify(i + 13, j + 39, k + 26, 7, 2);
		setBlock(world, i + 13, j + 39, k + 27, Blocks.leaves, 7);
		world.setBlockMetadataWithNotify(i + 13, j + 39, k + 27, 7, 2);
		setBlock(world, i + 13, j + 39, k + 28, Blocks.leaves, 7);
		world.setBlockMetadataWithNotify(i + 13, j + 39, k + 28, 7, 2);
		setBlock(world, i + 13, j + 39, k + 29, Blocks.leaves, 7);
		world.setBlockMetadataWithNotify(i + 13, j + 39, k + 29, 7, 2);
		setBlock(world, i + 13, j + 39, k + 30, Blocks.leaves, 7);
		world.setBlockMetadataWithNotify(i + 13, j + 39, k + 30, 7, 2);
		setBlock(world, i + 13, j + 39, k + 31, Blocks.leaves, 7);
		world.setBlockMetadataWithNotify(i + 13, j + 39, k + 31, 7, 2);
		setBlock(world, i + 13, j + 40, k + 27, Blocks.leaves, 7);
		world.setBlockMetadataWithNotify(i + 13, j + 40, k + 27, 7, 2);
		setBlock(world, i + 13, j + 40, k + 28, Blocks.leaves, 7);
		world.setBlockMetadataWithNotify(i + 13, j + 40, k + 28, 7, 2);
		setBlock(world, i + 13, j + 40, k + 29, Blocks.leaves, 7);
		world.setBlockMetadataWithNotify(i + 13, j + 40, k + 29, 7, 2);
		setBlock(world, i + 13, j + 40, k + 31, Blocks.leaves, 7);
		world.setBlockMetadataWithNotify(i + 13, j + 40, k + 31, 7, 2);
		setBlock(world, i + 13, j + 41, k + 28, Blocks.leaves, 7);
		world.setBlockMetadataWithNotify(i + 13, j + 41, k + 28, 7, 2);
		setBlock(world, i + 13, j + 46, k + 31, Blocks.leaves, 7);
		world.setBlockMetadataWithNotify(i + 13, j + 46, k + 31, 7, 2);
		setBlock(world, i + 13, j + 47, k + 31, Blocks.leaves, 7);
		world.setBlockMetadataWithNotify(i + 13, j + 47, k + 31, 7, 2);
		setBlock(world, i + 14, j + 21, k + 28, Blocks.log, 3);
		world.setBlockMetadataWithNotify(i + 14, j + 21, k + 28, 3, 2);
		setBlock(world, i + 14, j + 21, k + 29, Blocks.log, 3);
		world.setBlockMetadataWithNotify(i + 14, j + 21, k + 29, 3, 2);
		setBlock(world, i + 14, j + 37, k + 30, Blocks.log, 3);
		world.setBlockMetadataWithNotify(i + 14, j + 37, k + 30, 3, 2);
		setBlock(world, i + 14, j + 38, k + 26, Blocks.leaves, 7);
		world.setBlockMetadataWithNotify(i + 14, j + 38, k + 26, 7, 2);
		setBlock(world, i + 14, j + 38, k + 27, Blocks.leaves, 7);
		world.setBlockMetadataWithNotify(i + 14, j + 38, k + 27, 7, 2);
		setBlock(world, i + 14, j + 38, k + 28, Blocks.leaves, 7);
		world.setBlockMetadataWithNotify(i + 14, j + 38, k + 28, 7, 2);
		setBlock(world, i + 14, j + 38, k + 29, Blocks.leaves, 7);
		world.setBlockMetadataWithNotify(i + 14, j + 38, k + 29, 7, 2);
		setBlock(world, i + 14, j + 38, k + 30, Blocks.leaves, 7);
		world.setBlockMetadataWithNotify(i + 14, j + 38, k + 30, 7, 2);
		setBlock(world, i + 14, j + 39, k + 27, Blocks.leaves, 7);
		world.setBlockMetadataWithNotify(i + 14, j + 39, k + 27, 7, 2);
		setBlock(world, i + 14, j + 39, k + 28, Blocks.leaves, 7);
		world.setBlockMetadataWithNotify(i + 14, j + 39, k + 28, 7, 2);
		setBlock(world, i + 14, j + 39, k + 29, Blocks.leaves, 7);
		world.setBlockMetadataWithNotify(i + 14, j + 39, k + 29, 7, 2);
		setBlock(world, i + 14, j + 39, k + 31, Blocks.leaves, 7);
		world.setBlockMetadataWithNotify(i + 14, j + 39, k + 31, 7, 2);
		setBlock(world, i + 14, j + 40, k + 28, Blocks.leaves, 7);
		world.setBlockMetadataWithNotify(i + 14, j + 40, k + 28, 7, 2);
		setBlock(world, i + 14, j + 46, k + 31, Blocks.leaves, 7);
		world.setBlockMetadataWithNotify(i + 14, j + 46, k + 31, 7, 2);
		setBlock(world, i + 15, j + 21, k + 30, Blocks.log, 3);
		world.setBlockMetadataWithNotify(i + 15, j + 21, k + 30, 3, 2);
		setBlock(world, i + 15, j + 37, k + 31, Blocks.log, 3);
		world.setBlockMetadataWithNotify(i + 15, j + 37, k + 31, 3, 2);
		setBlock(world, i + 15, j + 38, k + 27, Blocks.leaves, 7);
		world.setBlockMetadataWithNotify(i + 15, j + 38, k + 27, 7, 2);
		setBlock(world, i + 15, j + 38, k + 28, Blocks.leaves, 7);
		world.setBlockMetadataWithNotify(i + 15, j + 38, k + 28, 7, 2);
		setBlock(world, i + 15, j + 38, k + 29, Blocks.leaves, 7);
		world.setBlockMetadataWithNotify(i + 15, j + 38, k + 29, 7, 2);
		setBlock(world, i + 15, j + 39, k + 28, Blocks.leaves, 7);
		world.setBlockMetadataWithNotify(i + 15, j + 39, k + 28, 7, 2);
		setBlock(world, i + 16, j + 21, k + 31, Blocks.log, 3);
		world.setBlockMetadataWithNotify(i + 16, j + 21, k + 31, 3, 2);
		setBlock(world, i + 16, j + 24, k + 26, Blocks.leaves, 7);
		world.setBlockMetadataWithNotify(i + 16, j + 24, k + 26, 7, 2);
		setBlock(world, i + 16, j + 24, k + 27, Blocks.leaves, 7);
		world.setBlockMetadataWithNotify(i + 16, j + 24, k + 27, 7, 2);
		setBlock(world, i + 16, j + 24, k + 28, Blocks.leaves, 7);
		world.setBlockMetadataWithNotify(i + 16, j + 24, k + 28, 7, 2);
		setBlock(world, i + 16, j + 25, k + 27, Blocks.leaves, 7);
		world.setBlockMetadataWithNotify(i + 16, j + 25, k + 27, 7, 2);
		setBlock(world, i + 17, j + 24, k + 25, Blocks.leaves, 7);
		world.setBlockMetadataWithNotify(i + 17, j + 24, k + 25, 7, 2);
		setBlock(world, i + 17, j + 24, k + 26, Blocks.leaves, 7);
		world.setBlockMetadataWithNotify(i + 17, j + 24, k + 26, 7, 2);
		setBlock(world, i + 17, j + 24, k + 27, Blocks.leaves, 7);
		world.setBlockMetadataWithNotify(i + 17, j + 24, k + 27, 7, 2);
		setBlock(world, i + 17, j + 24, k + 28, Blocks.leaves, 7);
		world.setBlockMetadataWithNotify(i + 17, j + 24, k + 28, 7, 2);
		setBlock(world, i + 17, j + 24, k + 29, Blocks.leaves, 7);
		world.setBlockMetadataWithNotify(i + 17, j + 24, k + 29, 7, 2);
		setBlock(world, i + 17, j + 25, k + 26, Blocks.leaves, 7);
		world.setBlockMetadataWithNotify(i + 17, j + 25, k + 26, 7, 2);
		setBlock(world, i + 17, j + 25, k + 27, Blocks.leaves, 7);
		world.setBlockMetadataWithNotify(i + 17, j + 25, k + 27, 7, 2);
		setBlock(world, i + 17, j + 25, k + 28, Blocks.leaves, 7);
		world.setBlockMetadataWithNotify(i + 17, j + 25, k + 28, 7, 2);
		setBlock(world, i + 17, j + 26, k + 27, Blocks.leaves, 7);
		world.setBlockMetadataWithNotify(i + 17, j + 26, k + 27, 7, 2);
		setBlock(world, i + 17, j + 37, k + 29, Blocks.leaves, 7);
		world.setBlockMetadataWithNotify(i + 17, j + 37, k + 29, 7, 2);
		setBlock(world, i + 17, j + 37, k + 30, Blocks.leaves, 7);
		world.setBlockMetadataWithNotify(i + 17, j + 37, k + 30, 7, 2);
		setBlock(world, i + 17, j + 37, k + 31, Blocks.leaves, 7);
		world.setBlockMetadataWithNotify(i + 17, j + 37, k + 31, 7, 2);
		setBlock(world, i + 17, j + 38, k + 30, Blocks.leaves, 7);
		world.setBlockMetadataWithNotify(i + 17, j + 38, k + 30, 7, 2);
		setBlock(world, i + 17, j + 50, k + 31, Blocks.leaves, 7);
		world.setBlockMetadataWithNotify(i + 17, j + 50, k + 31, 7, 2);
		setBlock(world, i + 18, j + 23, k + 28, Blocks.log, 3);
		world.setBlockMetadataWithNotify(i + 18, j + 23, k + 28, 3, 2);
		setBlock(world, i + 18, j + 24, k + 25, Blocks.leaves, 7);
		world.setBlockMetadataWithNotify(i + 18, j + 24, k + 25, 7, 2);
		setBlock(world, i + 18, j + 24, k + 26, Blocks.leaves, 7);
		world.setBlockMetadataWithNotify(i + 18, j + 24, k + 26, 7, 2);
		setBlock(world, i + 18, j + 24, k + 27, Blocks.log, 3);
		world.setBlockMetadataWithNotify(i + 18, j + 24, k + 27, 3, 2);
		setBlock(world, i + 18, j + 24, k + 28, Blocks.leaves, 7);
		world.setBlockMetadataWithNotify(i + 18, j + 24, k + 28, 7, 2);
		setBlock(world, i + 18, j + 24, k + 29, Blocks.leaves, 7);
		world.setBlockMetadataWithNotify(i + 18, j + 24, k + 29, 7, 2);
		setBlock(world, i + 18, j + 25, k + 25, Blocks.leaves, 7);
		world.setBlockMetadataWithNotify(i + 18, j + 25, k + 25, 7, 2);
		setBlock(world, i + 18, j + 25, k + 26, Blocks.leaves, 7);
		world.setBlockMetadataWithNotify(i + 18, j + 25, k + 26, 7, 2);
		setBlock(world, i + 18, j + 25, k + 27, Blocks.leaves, 7);
		world.setBlockMetadataWithNotify(i + 18, j + 25, k + 27, 7, 2);
		setBlock(world, i + 18, j + 25, k + 28, Blocks.leaves, 7);
		world.setBlockMetadataWithNotify(i + 18, j + 25, k + 28, 7, 2);
		setBlock(world, i + 18, j + 25, k + 29, Blocks.leaves, 7);
		world.setBlockMetadataWithNotify(i + 18, j + 25, k + 29, 7, 2);
		setBlock(world, i + 18, j + 26, k + 26, Blocks.leaves, 7);
		world.setBlockMetadataWithNotify(i + 18, j + 26, k + 26, 7, 2);
		setBlock(world, i + 18, j + 26, k + 27, Blocks.leaves, 7);
		world.setBlockMetadataWithNotify(i + 18, j + 26, k + 27, 7, 2);
		setBlock(world, i + 18, j + 26, k + 28, Blocks.leaves, 7);
		world.setBlockMetadataWithNotify(i + 18, j + 26, k + 28, 7, 2);
		setBlock(world, i + 18, j + 27, k + 27, Blocks.leaves, 7);
		world.setBlockMetadataWithNotify(i + 18, j + 27, k + 27, 7, 2);
		setBlock(world, i + 18, j + 37, k + 28, Blocks.leaves, 7);
		world.setBlockMetadataWithNotify(i + 18, j + 37, k + 28, 7, 2);
		setBlock(world, i + 18, j + 37, k + 29, Blocks.leaves, 7);
		world.setBlockMetadataWithNotify(i + 18, j + 37, k + 29, 7, 2);
		setBlock(world, i + 18, j + 37, k + 30, Blocks.leaves, 7);
		world.setBlockMetadataWithNotify(i + 18, j + 37, k + 30, 7, 2);
		setBlock(world, i + 18, j + 37, k + 31, Blocks.leaves, 7);
		world.setBlockMetadataWithNotify(i + 18, j + 37, k + 31, 7, 2);
		setBlock(world, i + 18, j + 38, k + 29, Blocks.leaves, 7);
		world.setBlockMetadataWithNotify(i + 18, j + 38, k + 29, 7, 2);
		setBlock(world, i + 18, j + 38, k + 30, Blocks.leaves, 7);
		world.setBlockMetadataWithNotify(i + 18, j + 38, k + 30, 7, 2);
		setBlock(world, i + 18, j + 38, k + 31, Blocks.leaves, 7);
		world.setBlockMetadataWithNotify(i + 18, j + 38, k + 31, 7, 2);
		setBlock(world, i + 18, j + 39, k + 30, Blocks.leaves, 7);
		world.setBlockMetadataWithNotify(i + 18, j + 39, k + 30, 7, 2);
		setBlock(world, i + 18, j + 50, k + 31, Blocks.leaves, 7);
		world.setBlockMetadataWithNotify(i + 18, j + 50, k + 31, 7, 2);
		setBlock(world, i + 18, j + 51, k + 31, Blocks.leaves, 7);
		world.setBlockMetadataWithNotify(i + 18, j + 51, k + 31, 7, 2);
		setBlock(world, i + 19, j + 23, k + 29, Blocks.log, 3);
		world.setBlockMetadataWithNotify(i + 19, j + 23, k + 29, 3, 2);
		setBlock(world, i + 19, j + 23, k + 30, Blocks.log, 3);
		world.setBlockMetadataWithNotify(i + 19, j + 23, k + 30, 3, 2);
		setBlock(world, i + 19, j + 24, k + 25, Blocks.leaves, 7);
		world.setBlockMetadataWithNotify(i + 19, j + 24, k + 25, 7, 2);
		setBlock(world, i + 19, j + 24, k + 26, Blocks.leaves, 7);
		world.setBlockMetadataWithNotify(i + 19, j + 24, k + 26, 7, 2);
		setBlock(world, i + 19, j + 24, k + 27, Blocks.leaves, 7);
		world.setBlockMetadataWithNotify(i + 19, j + 24, k + 27, 7, 2);
		setBlock(world, i + 19, j + 24, k + 28, Blocks.leaves, 7);
		world.setBlockMetadataWithNotify(i + 19, j + 24, k + 28, 7, 2);
		setBlock(world, i + 19, j + 24, k + 29, Blocks.leaves, 7);
		world.setBlockMetadataWithNotify(i + 19, j + 24, k + 29, 7, 2);
		setBlock(world, i + 19, j + 25, k + 26, Blocks.leaves, 7);
		world.setBlockMetadataWithNotify(i + 19, j + 25, k + 26, 7, 2);
		setBlock(world, i + 19, j + 25, k + 27, Blocks.leaves, 7);
		world.setBlockMetadataWithNotify(i + 19, j + 25, k + 27, 7, 2);
		setBlock(world, i + 19, j + 25, k + 28, Blocks.leaves, 7);
		world.setBlockMetadataWithNotify(i + 19, j + 25, k + 28, 7, 2);
		setBlock(world, i + 19, j + 26, k + 27, Blocks.leaves, 7);
		world.setBlockMetadataWithNotify(i + 19, j + 26, k + 27, 7, 2);
		setBlock(world, i + 19, j + 36, k + 31, Blocks.log, 3);
		world.setBlockMetadataWithNotify(i + 19, j + 36, k + 31, 3, 2);
		setBlock(world, i + 19, j + 37, k + 28, Blocks.leaves, 7);
		world.setBlockMetadataWithNotify(i + 19, j + 37, k + 28, 7, 2);
		setBlock(world, i + 19, j + 37, k + 29, Blocks.leaves, 7);
		world.setBlockMetadataWithNotify(i + 19, j + 37, k + 29, 7, 2);
		setBlock(world, i + 19, j + 37, k + 30, Blocks.log, 3);
		world.setBlockMetadataWithNotify(i + 19, j + 37, k + 30, 3, 2);
		setBlock(world, i + 19, j + 37, k + 31, Blocks.leaves, 7);
		world.setBlockMetadataWithNotify(i + 19, j + 37, k + 31, 7, 2);
		setBlock(world, i + 19, j + 38, k + 28, Blocks.leaves, 7);
		world.setBlockMetadataWithNotify(i + 19, j + 38, k + 28, 7, 2);
		setBlock(world, i + 19, j + 38, k + 29, Blocks.leaves, 7);
		world.setBlockMetadataWithNotify(i + 19, j + 38, k + 29, 7, 2);
		setBlock(world, i + 19, j + 38, k + 30, Blocks.leaves, 7);
		world.setBlockMetadataWithNotify(i + 19, j + 38, k + 30, 7, 2);
		setBlock(world, i + 19, j + 38, k + 31, Blocks.leaves, 7);
		world.setBlockMetadataWithNotify(i + 19, j + 38, k + 31, 7, 2);
		setBlock(world, i + 19, j + 39, k + 29, Blocks.leaves, 7);
		world.setBlockMetadataWithNotify(i + 19, j + 39, k + 29, 7, 2);
		setBlock(world, i + 19, j + 39, k + 30, Blocks.leaves, 7);
		world.setBlockMetadataWithNotify(i + 19, j + 39, k + 30, 7, 2);
		setBlock(world, i + 19, j + 39, k + 31, Blocks.leaves, 7);
		world.setBlockMetadataWithNotify(i + 19, j + 39, k + 31, 7, 2);
		setBlock(world, i + 19, j + 40, k + 30, Blocks.leaves, 7);
		world.setBlockMetadataWithNotify(i + 19, j + 40, k + 30, 7, 2);
		setBlock(world, i + 19, j + 50, k + 31, Blocks.leaves, 7);
		world.setBlockMetadataWithNotify(i + 19, j + 50, k + 31, 7, 2);
		setBlock(world, i + 20, j + 22, k + 31, Blocks.log, 3);
		world.setBlockMetadataWithNotify(i + 20, j + 22, k + 31, 3, 2);
		setBlock(world, i + 20, j + 24, k + 26, Blocks.leaves, 7);
		world.setBlockMetadataWithNotify(i + 20, j + 24, k + 26, 7, 2);
		setBlock(world, i + 20, j + 24, k + 27, Blocks.leaves, 7);
		world.setBlockMetadataWithNotify(i + 20, j + 24, k + 27, 7, 2);
		setBlock(world, i + 20, j + 24, k + 28, Blocks.leaves, 7);
		world.setBlockMetadataWithNotify(i + 20, j + 24, k + 28, 7, 2);
		setBlock(world, i + 20, j + 25, k + 27, Blocks.leaves, 7);
		world.setBlockMetadataWithNotify(i + 20, j + 25, k + 27, 7, 2);
		setBlock(world, i + 20, j + 37, k + 28, Blocks.leaves, 7);
		world.setBlockMetadataWithNotify(i + 20, j + 37, k + 28, 7, 2);
		setBlock(world, i + 20, j + 37, k + 29, Blocks.leaves, 7);
		world.setBlockMetadataWithNotify(i + 20, j + 37, k + 29, 7, 2);
		setBlock(world, i + 20, j + 37, k + 30, Blocks.leaves, 7);
		world.setBlockMetadataWithNotify(i + 20, j + 37, k + 30, 7, 2);
		setBlock(world, i + 20, j + 37, k + 31, Blocks.leaves, 7);
		world.setBlockMetadataWithNotify(i + 20, j + 37, k + 31, 7, 2);
		setBlock(world, i + 20, j + 38, k + 29, Blocks.leaves, 7);
		world.setBlockMetadataWithNotify(i + 20, j + 38, k + 29, 7, 2);
		setBlock(world, i + 20, j + 38, k + 30, Blocks.leaves, 7);
		world.setBlockMetadataWithNotify(i + 20, j + 38, k + 30, 7, 2);
		setBlock(world, i + 20, j + 38, k + 31, Blocks.leaves, 7);
		world.setBlockMetadataWithNotify(i + 20, j + 38, k + 31, 7, 2);
		setBlock(world, i + 20, j + 39, k + 30, Blocks.leaves, 7);
		world.setBlockMetadataWithNotify(i + 20, j + 39, k + 30, 7, 2);
		setBlock(world, i + 20, j + 59, k + 31, Blocks.leaves, 7);
		world.setBlockMetadataWithNotify(i + 20, j + 59, k + 31, 7, 2);
		setBlock(world, i + 21, j + 34, k + 22, Blocks.leaves, 7);
		world.setBlockMetadataWithNotify(i + 21, j + 34, k + 22, 7, 2);
		setBlock(world, i + 21, j + 34, k + 23, Blocks.leaves, 7);
		world.setBlockMetadataWithNotify(i + 21, j + 34, k + 23, 7, 2);
		setBlock(world, i + 21, j + 34, k + 24, Blocks.leaves, 7);
		world.setBlockMetadataWithNotify(i + 21, j + 34, k + 24, 7, 2);
		setBlock(world, i + 21, j + 34, k + 31, Blocks.leaves, 7);
		world.setBlockMetadataWithNotify(i + 21, j + 34, k + 31, 7, 2);
		setBlock(world, i + 21, j + 35, k + 23, Blocks.leaves, 7);
		world.setBlockMetadataWithNotify(i + 21, j + 35, k + 23, 7, 2);
		setBlock(world, i + 21, j + 35, k + 27, Blocks.leaves, 7);
		world.setBlockMetadataWithNotify(i + 21, j + 35, k + 27, 7, 2);
		setBlock(world, i + 21, j + 35, k + 28, Blocks.leaves, 7);
		world.setBlockMetadataWithNotify(i + 21, j + 35, k + 28, 7, 2);
		setBlock(world, i + 21, j + 35, k + 29, Blocks.leaves, 7);
		world.setBlockMetadataWithNotify(i + 21, j + 35, k + 29, 7, 2);
		setBlock(world, i + 21, j + 36, k + 28, Blocks.leaves, 7);
		world.setBlockMetadataWithNotify(i + 21, j + 36, k + 28, 7, 2);
		setBlock(world, i + 21, j + 37, k + 29, Blocks.leaves, 7);
		world.setBlockMetadataWithNotify(i + 21, j + 37, k + 29, 7, 2);
		setBlock(world, i + 21, j + 37, k + 30, Blocks.leaves, 7);
		world.setBlockMetadataWithNotify(i + 21, j + 37, k + 30, 7, 2);
		setBlock(world, i + 21, j + 37, k + 31, Blocks.leaves, 7);
		world.setBlockMetadataWithNotify(i + 21, j + 37, k + 31, 7, 2);
		setBlock(world, i + 21, j + 38, k + 30, Blocks.leaves, 7);
		world.setBlockMetadataWithNotify(i + 21, j + 38, k + 30, 7, 2);
		setBlock(world, i + 21, j + 59, k + 31, Blocks.leaves, 7);
		world.setBlockMetadataWithNotify(i + 21, j + 59, k + 31, 7, 2);
		setBlock(world, i + 21, j + 60, k + 31, Blocks.leaves, 7);
		world.setBlockMetadataWithNotify(i + 21, j + 60, k + 31, 7, 2);
		setBlock(world, i + 22, j + 27, k + 22, Blocks.leaves, 7);
		world.setBlockMetadataWithNotify(i + 22, j + 27, k + 22, 7, 2);
		setBlock(world, i + 22, j + 27, k + 23, Blocks.leaves, 7);
		world.setBlockMetadataWithNotify(i + 22, j + 27, k + 23, 7, 2);
		setBlock(world, i + 22, j + 27, k + 24, Blocks.leaves, 7);
		world.setBlockMetadataWithNotify(i + 22, j + 27, k + 24, 7, 2);
		setBlock(world, i + 22, j + 28, k + 23, Blocks.leaves, 7);
		world.setBlockMetadataWithNotify(i + 22, j + 28, k + 23, 7, 2);
		setBlock(world, i + 22, j + 32, k + 29, Blocks.log, 1);
		world.setBlockMetadataWithNotify(i + 22, j + 32, k + 29, 1, 2);
		setBlock(world, i + 22, j + 33, k + 29, Blocks.log, 1);
		world.setBlockMetadataWithNotify(i + 22, j + 33, k + 29, 1, 2);
		setBlock(world, i + 22, j + 33, k + 30, Blocks.log, 1);
		world.setBlockMetadataWithNotify(i + 22, j + 33, k + 30, 1, 2);
		setBlock(world, i + 22, j + 33, k + 31, Blocks.log, 1);
		world.setBlockMetadataWithNotify(i + 22, j + 33, k + 31, 1, 2);
		setBlock(world, i + 22, j + 34, k + 21, Blocks.leaves, 7);
		world.setBlockMetadataWithNotify(i + 22, j + 34, k + 21, 7, 2);
		setBlock(world, i + 22, j + 34, k + 22, Blocks.leaves, 7);
		world.setBlockMetadataWithNotify(i + 22, j + 34, k + 22, 7, 2);
		setBlock(world, i + 22, j + 34, k + 23, Blocks.leaves, 7);
		world.setBlockMetadataWithNotify(i + 22, j + 34, k + 23, 7, 2);
		setBlock(world, i + 22, j + 34, k + 24, Blocks.leaves, 7);
		world.setBlockMetadataWithNotify(i + 22, j + 34, k + 24, 7, 2);
		setBlock(world, i + 22, j + 34, k + 25, Blocks.leaves, 7);
		world.setBlockMetadataWithNotify(i + 22, j + 34, k + 25, 7, 2);
		setBlock(world, i + 22, j + 34, k + 29, Blocks.log, 1);
		world.setBlockMetadataWithNotify(i + 22, j + 34, k + 29, 1, 2);
		setBlock(world, i + 22, j + 34, k + 30, Blocks.leaves, 7);
		world.setBlockMetadataWithNotify(i + 22, j + 34, k + 30, 7, 2);
		setBlock(world, i + 22, j + 34, k + 31, Blocks.leaves, 7);
		world.setBlockMetadataWithNotify(i + 22, j + 34, k + 31, 7, 2);
		setBlock(world, i + 22, j + 35, k + 22, Blocks.leaves, 7);
		world.setBlockMetadataWithNotify(i + 22, j + 35, k + 22, 7, 2);
		setBlock(world, i + 22, j + 35, k + 23, Blocks.leaves, 7);
		world.setBlockMetadataWithNotify(i + 22, j + 35, k + 23, 7, 2);
		setBlock(world, i + 22, j + 35, k + 24, Blocks.leaves, 7);
		world.setBlockMetadataWithNotify(i + 22, j + 35, k + 24, 7, 2);
		setBlock(world, i + 22, j + 35, k + 26, Blocks.leaves, 7);
		world.setBlockMetadataWithNotify(i + 22, j + 35, k + 26, 7, 2);
		setBlock(world, i + 22, j + 35, k + 27, Blocks.leaves, 7);
		world.setBlockMetadataWithNotify(i + 22, j + 35, k + 27, 7, 2);
		setBlock(world, i + 22, j + 35, k + 28, Blocks.leaves, 7);
		world.setBlockMetadataWithNotify(i + 22, j + 35, k + 28, 7, 2);
		setBlock(world, i + 22, j + 35, k + 29, Blocks.leaves, 7);
		world.setBlockMetadataWithNotify(i + 22, j + 35, k + 29, 7, 2);
		setBlock(world, i + 22, j + 35, k + 30, Blocks.leaves, 7);
		world.setBlockMetadataWithNotify(i + 22, j + 35, k + 30, 7, 2);
		setBlock(world, i + 22, j + 35, k + 31, Blocks.leaves, 7);
		world.setBlockMetadataWithNotify(i + 22, j + 35, k + 31, 7, 2);
		setBlock(world, i + 22, j + 36, k + 23, Blocks.leaves, 7);
		world.setBlockMetadataWithNotify(i + 22, j + 36, k + 23, 7, 2);
		setBlock(world, i + 22, j + 36, k + 27, Blocks.leaves, 7);
		world.setBlockMetadataWithNotify(i + 22, j + 36, k + 27, 7, 2);
		setBlock(world, i + 22, j + 36, k + 28, Blocks.leaves, 7);
		world.setBlockMetadataWithNotify(i + 22, j + 36, k + 28, 7, 2);
		setBlock(world, i + 22, j + 36, k + 29, Blocks.leaves, 7);
		world.setBlockMetadataWithNotify(i + 22, j + 36, k + 29, 7, 2);
		setBlock(world, i + 22, j + 37, k + 28, Blocks.leaves, 7);
		world.setBlockMetadataWithNotify(i + 22, j + 37, k + 28, 7, 2);
		setBlock(world, i + 22, j + 59, k + 31, Blocks.leaves, 7);
		world.setBlockMetadataWithNotify(i + 22, j + 59, k + 31, 7, 2);
		setBlock(world, i + 23, j + 24, k + 29, Blocks.leaves, 7);
		world.setBlockMetadataWithNotify(i + 23, j + 24, k + 29, 7, 2);
		setBlock(world, i + 23, j + 24, k + 30, Blocks.leaves, 7);
		world.setBlockMetadataWithNotify(i + 23, j + 24, k + 30, 7, 2);
		setBlock(world, i + 23, j + 24, k + 31, Blocks.leaves, 7);
		world.setBlockMetadataWithNotify(i + 23, j + 24, k + 31, 7, 2);
		setBlock(world, i + 23, j + 25, k + 30, Blocks.leaves, 7);
		world.setBlockMetadataWithNotify(i + 23, j + 25, k + 30, 7, 2);
		setBlock(world, i + 23, j + 27, k + 21, Blocks.leaves, 7);
		world.setBlockMetadataWithNotify(i + 23, j + 27, k + 21, 7, 2);
		setBlock(world, i + 23, j + 27, k + 22, Blocks.leaves, 7);
		world.setBlockMetadataWithNotify(i + 23, j + 27, k + 22, 7, 2);
		setBlock(world, i + 23, j + 27, k + 23, Blocks.leaves, 7);
		world.setBlockMetadataWithNotify(i + 23, j + 27, k + 23, 7, 2);
		setBlock(world, i + 23, j + 27, k + 24, Blocks.leaves, 7);
		world.setBlockMetadataWithNotify(i + 23, j + 27, k + 24, 7, 2);
		setBlock(world, i + 23, j + 27, k + 25, Blocks.leaves, 7);
		world.setBlockMetadataWithNotify(i + 23, j + 27, k + 25, 7, 2);
		setBlock(world, i + 23, j + 28, k + 22, Blocks.leaves, 7);
		world.setBlockMetadataWithNotify(i + 23, j + 28, k + 22, 7, 2);
		setBlock(world, i + 23, j + 28, k + 23, Blocks.leaves, 7);
		world.setBlockMetadataWithNotify(i + 23, j + 28, k + 23, 7, 2);
		setBlock(world, i + 23, j + 28, k + 24, Blocks.leaves, 7);
		world.setBlockMetadataWithNotify(i + 23, j + 28, k + 24, 7, 2);
		setBlock(world, i + 23, j + 29, k + 23, Blocks.leaves, 7);
		world.setBlockMetadataWithNotify(i + 23, j + 29, k + 23, 7, 2);
		setBlock(world, i + 23, j + 32, k + 28, Blocks.log, 1);
		world.setBlockMetadataWithNotify(i + 23, j + 32, k + 28, 1, 2);
		setBlock(world, i + 23, j + 32, k + 29, Blocks.log, 1);
		world.setBlockMetadataWithNotify(i + 23, j + 32, k + 29, 1, 2);
		setBlock(world, i + 23, j + 32, k + 30, Blocks.log, 1);
		world.setBlockMetadataWithNotify(i + 23, j + 32, k + 30, 1, 2);
		setBlock(world, i + 23, j + 32, k + 31, Blocks.log, 1);
		world.setBlockMetadataWithNotify(i + 23, j + 32, k + 31, 1, 2);
		setBlock(world, i + 23, j + 33, k + 24, Blocks.log, 3);
		world.setBlockMetadataWithNotify(i + 23, j + 33, k + 24, 3, 2);
		setBlock(world, i + 23, j + 33, k + 25, Blocks.log, 3);
		world.setBlockMetadataWithNotify(i + 23, j + 33, k + 25, 3, 2);
		setBlock(world, i + 23, j + 33, k + 26, Blocks.log, 3);
		world.setBlockMetadataWithNotify(i + 23, j + 33, k + 26, 3, 2);
		setBlock(world, i + 23, j + 33, k + 27, Blocks.log, 3);
		world.setBlockMetadataWithNotify(i + 23, j + 33, k + 27, 3, 2);
		setBlock(world, i + 23, j + 33, k + 28, Blocks.log, 1);
		world.setBlockMetadataWithNotify(i + 23, j + 33, k + 28, 1, 2);
		setBlock(world, i + 23, j + 33, k + 29, Blocks.log, 1);
		world.setBlockMetadataWithNotify(i + 23, j + 33, k + 29, 1, 2);
		setBlock(world, i + 23, j + 33, k + 31, Blocks.log, 1);
		world.setBlockMetadataWithNotify(i + 23, j + 33, k + 31, 1, 2);
		setBlock(world, i + 23, j + 34, k + 21, Blocks.leaves, 7);
		world.setBlockMetadataWithNotify(i + 23, j + 34, k + 21, 7, 2);
		setBlock(world, i + 23, j + 34, k + 22, Blocks.leaves, 7);
		world.setBlockMetadataWithNotify(i + 23, j + 34, k + 22, 7, 2);
		setBlock(world, i + 23, j + 34, k + 23, Blocks.log, 3);
		world.setBlockMetadataWithNotify(i + 23, j + 34, k + 23, 3, 2);
		setBlock(world, i + 23, j + 34, k + 24, Blocks.leaves, 7);
		world.setBlockMetadataWithNotify(i + 23, j + 34, k + 24, 7, 2);
		setBlock(world, i + 23, j + 34, k + 25, Blocks.leaves, 7);
		world.setBlockMetadataWithNotify(i + 23, j + 34, k + 25, 7, 2);
		setBlock(world, i + 23, j + 34, k + 28, Blocks.log, 1);
		world.setBlockMetadataWithNotify(i + 23, j + 34, k + 28, 1, 2);
		setBlock(world, i + 23, j + 34, k + 29, Blocks.log, 1);
		world.setBlockMetadataWithNotify(i + 23, j + 34, k + 29, 1, 2);
		setBlock(world, i + 23, j + 34, k + 30, Blocks.log, 1);
		world.setBlockMetadataWithNotify(i + 23, j + 34, k + 30, 1, 2);
		setBlock(world, i + 23, j + 34, k + 31, Blocks.log, 1);
		world.setBlockMetadataWithNotify(i + 23, j + 34, k + 31, 1, 2);
		setBlock(world, i + 23, j + 35, k + 21, Blocks.leaves, 7);
		world.setBlockMetadataWithNotify(i + 23, j + 35, k + 21, 7, 2);
		setBlock(world, i + 23, j + 35, k + 22, Blocks.leaves, 7);
		world.setBlockMetadataWithNotify(i + 23, j + 35, k + 22, 7, 2);
		setBlock(world, i + 23, j + 35, k + 23, Blocks.leaves, 7);
		world.setBlockMetadataWithNotify(i + 23, j + 35, k + 23, 7, 2);
		setBlock(world, i + 23, j + 35, k + 24, Blocks.leaves, 7);
		world.setBlockMetadataWithNotify(i + 23, j + 35, k + 24, 7, 2);
		setBlock(world, i + 23, j + 35, k + 25, Blocks.leaves, 7);
		world.setBlockMetadataWithNotify(i + 23, j + 35, k + 25, 7, 2);
		setBlock(world, i + 23, j + 35, k + 26, Blocks.leaves, 7);
		world.setBlockMetadataWithNotify(i + 23, j + 35, k + 26, 7, 2);
		setBlock(world, i + 23, j + 35, k + 27, Blocks.leaves, 7);
		world.setBlockMetadataWithNotify(i + 23, j + 35, k + 27, 7, 2);
		setBlock(world, i + 23, j + 35, k + 28, Blocks.log, 3);
		world.setBlockMetadataWithNotify(i + 23, j + 35, k + 28, 3, 2);
		setBlock(world, i + 23, j + 35, k + 29, Blocks.leaves, 7);
		world.setBlockMetadataWithNotify(i + 23, j + 35, k + 29, 7, 2);
		setBlock(world, i + 23, j + 35, k + 30, Blocks.leaves, 7);
		world.setBlockMetadataWithNotify(i + 23, j + 35, k + 30, 7, 2);
		setBlock(world, i + 23, j + 35, k + 31, Blocks.leaves, 7);
		world.setBlockMetadataWithNotify(i + 23, j + 35, k + 31, 7, 2);
		setBlock(world, i + 23, j + 36, k + 22, Blocks.leaves, 7);
		world.setBlockMetadataWithNotify(i + 23, j + 36, k + 22, 7, 2);
		setBlock(world, i + 23, j + 36, k + 23, Blocks.leaves, 7);
		world.setBlockMetadataWithNotify(i + 23, j + 36, k + 23, 7, 2);
		setBlock(world, i + 23, j + 36, k + 24, Blocks.leaves, 7);
		world.setBlockMetadataWithNotify(i + 23, j + 36, k + 24, 7, 2);
		setBlock(world, i + 23, j + 36, k + 26, Blocks.leaves, 7);
		world.setBlockMetadataWithNotify(i + 23, j + 36, k + 26, 7, 2);
		setBlock(world, i + 23, j + 36, k + 27, Blocks.leaves, 7);
		world.setBlockMetadataWithNotify(i + 23, j + 36, k + 27, 7, 2);
		setBlock(world, i + 23, j + 36, k + 28, Blocks.leaves, 7);
		world.setBlockMetadataWithNotify(i + 23, j + 36, k + 28, 7, 2);
		setBlock(world, i + 23, j + 36, k + 29, Blocks.leaves, 7);
		world.setBlockMetadataWithNotify(i + 23, j + 36, k + 29, 7, 2);
		setBlock(world, i + 23, j + 36, k + 30, Blocks.leaves, 7);
		world.setBlockMetadataWithNotify(i + 23, j + 36, k + 30, 7, 2);
		setBlock(world, i + 23, j + 36, k + 31, Blocks.leaves, 7);
		world.setBlockMetadataWithNotify(i + 23, j + 36, k + 31, 7, 2);
		setBlock(world, i + 23, j + 37, k + 23, Blocks.leaves, 7);
		world.setBlockMetadataWithNotify(i + 23, j + 37, k + 23, 7, 2);
		setBlock(world, i + 23, j + 37, k + 27, Blocks.leaves, 7);
		world.setBlockMetadataWithNotify(i + 23, j + 37, k + 27, 7, 2);
		setBlock(world, i + 23, j + 37, k + 28, Blocks.leaves, 7);
		world.setBlockMetadataWithNotify(i + 23, j + 37, k + 28, 7, 2);
		setBlock(world, i + 23, j + 37, k + 29, Blocks.leaves, 7);
		world.setBlockMetadataWithNotify(i + 23, j + 37, k + 29, 7, 2);
		setBlock(world, i + 23, j + 38, k + 28, Blocks.leaves, 7);
		world.setBlockMetadataWithNotify(i + 23, j + 38, k + 28, 7, 2);
		setBlock(world, i + 24, j + 24, k + 28, Blocks.leaves, 7);
		world.setBlockMetadataWithNotify(i + 24, j + 24, k + 28, 7, 2);
		setBlock(world, i + 24, j + 24, k + 29, Blocks.leaves, 7);
		world.setBlockMetadataWithNotify(i + 24, j + 24, k + 29, 7, 2);
		setBlock(world, i + 24, j + 24, k + 30, Blocks.leaves, 7);
		world.setBlockMetadataWithNotify(i + 24, j + 24, k + 30, 7, 2);
		setBlock(world, i + 24, j + 24, k + 31, Blocks.leaves, 7);
		world.setBlockMetadataWithNotify(i + 24, j + 24, k + 31, 7, 2);
		setBlock(world, i + 24, j + 25, k + 29, Blocks.leaves, 7);
		world.setBlockMetadataWithNotify(i + 24, j + 25, k + 29, 7, 2);
		setBlock(world, i + 24, j + 25, k + 30, Blocks.leaves, 7);
		world.setBlockMetadataWithNotify(i + 24, j + 25, k + 30, 7, 2);
		setBlock(world, i + 24, j + 25, k + 31, Blocks.leaves, 7);
		world.setBlockMetadataWithNotify(i + 24, j + 25, k + 31, 7, 2);
		setBlock(world, i + 24, j + 26, k + 24, Blocks.log, 3);
		world.setBlockMetadataWithNotify(i + 24, j + 26, k + 24, 3, 2);
		setBlock(world, i + 24, j + 26, k + 25, Blocks.log, 3);
		world.setBlockMetadataWithNotify(i + 24, j + 26, k + 25, 3, 2);
		setBlock(world, i + 24, j + 26, k + 26, Blocks.log, 3);
		world.setBlockMetadataWithNotify(i + 24, j + 26, k + 26, 3, 2);
		setBlock(world, i + 24, j + 26, k + 27, Blocks.log, 3);
		world.setBlockMetadataWithNotify(i + 24, j + 26, k + 27, 3, 2);
		setBlock(world, i + 24, j + 26, k + 28, Blocks.log, 3);
		world.setBlockMetadataWithNotify(i + 24, j + 26, k + 28, 3, 2);
		setBlock(world, i + 24, j + 26, k + 29, Blocks.log, 3);
		world.setBlockMetadataWithNotify(i + 24, j + 26, k + 29, 3, 2);
		setBlock(world, i + 24, j + 26, k + 30, Blocks.log, 3);
		world.setBlockMetadataWithNotify(i + 24, j + 26, k + 30, 3, 2);
		setBlock(world, i + 24, j + 26, k + 31, Blocks.log, 3);
		world.setBlockMetadataWithNotify(i + 24, j + 26, k + 31, 3, 2);
		setBlock(world, i + 24, j + 27, k + 21, Blocks.leaves, 7);
		world.setBlockMetadataWithNotify(i + 24, j + 27, k + 21, 7, 2);
		setBlock(world, i + 24, j + 27, k + 22, Blocks.leaves, 7);
		world.setBlockMetadataWithNotify(i + 24, j + 27, k + 22, 7, 2);
		setBlock(world, i + 24, j + 27, k + 23, Blocks.log, 3);
		world.setBlockMetadataWithNotify(i + 24, j + 27, k + 23, 3, 2);
		setBlock(world, i + 24, j + 27, k + 24, Blocks.leaves, 7);
		world.setBlockMetadataWithNotify(i + 24, j + 27, k + 24, 7, 2);
		setBlock(world, i + 24, j + 27, k + 25, Blocks.leaves, 7);
		world.setBlockMetadataWithNotify(i + 24, j + 27, k + 25, 7, 2);
		setBlock(world, i + 24, j + 28, k + 21, Blocks.leaves, 7);
		world.setBlockMetadataWithNotify(i + 24, j + 28, k + 21, 7, 2);
		setBlock(world, i + 24, j + 28, k + 22, Blocks.leaves, 7);
		world.setBlockMetadataWithNotify(i + 24, j + 28, k + 22, 7, 2);
		setBlock(world, i + 24, j + 28, k + 23, Blocks.leaves, 7);
		world.setBlockMetadataWithNotify(i + 24, j + 28, k + 23, 7, 2);
		setBlock(world, i + 24, j + 28, k + 24, Blocks.leaves, 7);
		world.setBlockMetadataWithNotify(i + 24, j + 28, k + 24, 7, 2);
		setBlock(world, i + 24, j + 28, k + 25, Blocks.leaves, 7);
		world.setBlockMetadataWithNotify(i + 24, j + 28, k + 25, 7, 2);
		setBlock(world, i + 24, j + 29, k + 22, Blocks.leaves, 7);
		world.setBlockMetadataWithNotify(i + 24, j + 29, k + 22, 7, 2);
		setBlock(world, i + 24, j + 29, k + 23, Blocks.leaves, 7);
		world.setBlockMetadataWithNotify(i + 24, j + 29, k + 23, 7, 2);
		setBlock(world, i + 24, j + 29, k + 24, Blocks.leaves, 7);
		world.setBlockMetadataWithNotify(i + 24, j + 29, k + 24, 7, 2);
		setBlock(world, i + 24, j + 30, k + 23, Blocks.leaves, 7);
		world.setBlockMetadataWithNotify(i + 24, j + 30, k + 23, 7, 2);
		setBlock(world, i + 24, j + 32, k + 29, Blocks.log, 1);
		world.setBlockMetadataWithNotify(i + 24, j + 32, k + 29, 1, 2);
		setBlock(world, i + 24, j + 33, k + 29, Blocks.log, 1);
		world.setBlockMetadataWithNotify(i + 24, j + 33, k + 29, 1, 2);
		setBlock(world, i + 24, j + 33, k + 30, Blocks.log, 1);
		world.setBlockMetadataWithNotify(i + 24, j + 33, k + 30, 1, 2);
		setBlock(world, i + 24, j + 33, k + 31, Blocks.log, 1);
		world.setBlockMetadataWithNotify(i + 24, j + 33, k + 31, 1, 2);
		setBlock(world, i + 24, j + 34, k + 21, Blocks.leaves, 7);
		world.setBlockMetadataWithNotify(i + 24, j + 34, k + 21, 7, 2);
		setBlock(world, i + 24, j + 34, k + 22, Blocks.leaves, 7);
		world.setBlockMetadataWithNotify(i + 24, j + 34, k + 22, 7, 2);
		setBlock(world, i + 24, j + 34, k + 23, Blocks.leaves, 7);
		world.setBlockMetadataWithNotify(i + 24, j + 34, k + 23, 7, 2);
		setBlock(world, i + 24, j + 34, k + 24, Blocks.leaves, 7);
		world.setBlockMetadataWithNotify(i + 24, j + 34, k + 24, 7, 2);
		setBlock(world, i + 24, j + 34, k + 25, Blocks.leaves, 7);
		world.setBlockMetadataWithNotify(i + 24, j + 34, k + 25, 7, 2);
		setBlock(world, i + 24, j + 34, k + 29, Blocks.log, 1);
		world.setBlockMetadataWithNotify(i + 24, j + 34, k + 29, 1, 2);
		setBlock(world, i + 24, j + 34, k + 30, Blocks.leaves, 7);
		world.setBlockMetadataWithNotify(i + 24, j + 34, k + 30, 7, 2);
		setBlock(world, i + 24, j + 34, k + 31, Blocks.leaves, 7);
		world.setBlockMetadataWithNotify(i + 24, j + 34, k + 31, 7, 2);
		setBlock(world, i + 24, j + 35, k + 22, Blocks.leaves, 7);
		world.setBlockMetadataWithNotify(i + 24, j + 35, k + 22, 7, 2);
		setBlock(world, i + 24, j + 35, k + 23, Blocks.leaves, 7);
		world.setBlockMetadataWithNotify(i + 24, j + 35, k + 23, 7, 2);
		setBlock(world, i + 24, j + 35, k + 24, Blocks.leaves, 7);
		world.setBlockMetadataWithNotify(i + 24, j + 35, k + 24, 7, 2);
		setBlock(world, i + 24, j + 35, k + 26, Blocks.leaves, 7);
		world.setBlockMetadataWithNotify(i + 24, j + 35, k + 26, 7, 2);
		setBlock(world, i + 24, j + 35, k + 27, Blocks.leaves, 7);
		world.setBlockMetadataWithNotify(i + 24, j + 35, k + 27, 7, 2);
		setBlock(world, i + 24, j + 35, k + 28, Blocks.leaves, 7);
		world.setBlockMetadataWithNotify(i + 24, j + 35, k + 28, 7, 2);
		setBlock(world, i + 24, j + 35, k + 29, Blocks.leaves, 7);
		world.setBlockMetadataWithNotify(i + 24, j + 35, k + 29, 7, 2);
		setBlock(world, i + 24, j + 35, k + 30, Blocks.leaves, 7);
		world.setBlockMetadataWithNotify(i + 24, j + 35, k + 30, 7, 2);
		setBlock(world, i + 24, j + 35, k + 31, Blocks.leaves, 7);
		world.setBlockMetadataWithNotify(i + 24, j + 35, k + 31, 7, 2);
		setBlock(world, i + 24, j + 36, k + 23, Blocks.leaves, 7);
		world.setBlockMetadataWithNotify(i + 24, j + 36, k + 23, 7, 2);
		setBlock(world, i + 24, j + 36, k + 27, Blocks.leaves, 7);
		world.setBlockMetadataWithNotify(i + 24, j + 36, k + 27, 7, 2);
		setBlock(world, i + 24, j + 36, k + 28, Blocks.leaves, 7);
		world.setBlockMetadataWithNotify(i + 24, j + 36, k + 28, 7, 2);
		setBlock(world, i + 24, j + 36, k + 29, Blocks.leaves, 7);
		world.setBlockMetadataWithNotify(i + 24, j + 36, k + 29, 7, 2);
		setBlock(world, i + 24, j + 37, k + 28, Blocks.leaves, 7);
		world.setBlockMetadataWithNotify(i + 24, j + 37, k + 28, 7, 2);
		setBlock(world, i + 25, j + 23, k + 31, Blocks.log, 3);
		world.setBlockMetadataWithNotify(i + 25, j + 23, k + 31, 3, 2);
		setBlock(world, i + 25, j + 24, k + 28, Blocks.leaves, 7);
		world.setBlockMetadataWithNotify(i + 25, j + 24, k + 28, 7, 2);
		setBlock(world, i + 25, j + 24, k + 29, Blocks.leaves, 7);
		world.setBlockMetadataWithNotify(i + 25, j + 24, k + 29, 7, 2);
		setBlock(world, i + 25, j + 24, k + 30, Blocks.log, 3);
		world.setBlockMetadataWithNotify(i + 25, j + 24, k + 30, 3, 2);
		setBlock(world, i + 25, j + 24, k + 31, Blocks.leaves, 7);
		world.setBlockMetadataWithNotify(i + 25, j + 24, k + 31, 7, 2);
		setBlock(world, i + 25, j + 25, k + 28, Blocks.leaves, 7);
		world.setBlockMetadataWithNotify(i + 25, j + 25, k + 28, 7, 2);
		setBlock(world, i + 25, j + 25, k + 29, Blocks.leaves, 7);
		world.setBlockMetadataWithNotify(i + 25, j + 25, k + 29, 7, 2);
		setBlock(world, i + 25, j + 25, k + 30, Blocks.leaves, 7);
		world.setBlockMetadataWithNotify(i + 25, j + 25, k + 30, 7, 2);
		setBlock(world, i + 25, j + 25, k + 31, Blocks.leaves, 7);
		world.setBlockMetadataWithNotify(i + 25, j + 25, k + 31, 7, 2);
		setBlock(world, i + 25, j + 26, k + 29, Blocks.leaves, 7);
		world.setBlockMetadataWithNotify(i + 25, j + 26, k + 29, 7, 2);
		setBlock(world, i + 25, j + 26, k + 30, Blocks.leaves, 7);
		world.setBlockMetadataWithNotify(i + 25, j + 26, k + 30, 7, 2);
		setBlock(world, i + 25, j + 26, k + 31, Blocks.leaves, 7);
		world.setBlockMetadataWithNotify(i + 25, j + 26, k + 31, 7, 2);
		setBlock(world, i + 25, j + 27, k + 21, Blocks.leaves, 7);
		world.setBlockMetadataWithNotify(i + 25, j + 27, k + 21, 7, 2);
		setBlock(world, i + 25, j + 27, k + 22, Blocks.leaves, 7);
		world.setBlockMetadataWithNotify(i + 25, j + 27, k + 22, 7, 2);
		setBlock(world, i + 25, j + 27, k + 23, Blocks.leaves, 7);
		world.setBlockMetadataWithNotify(i + 25, j + 27, k + 23, 7, 2);
		setBlock(world, i + 25, j + 27, k + 24, Blocks.leaves, 7);
		world.setBlockMetadataWithNotify(i + 25, j + 27, k + 24, 7, 2);
		setBlock(world, i + 25, j + 27, k + 25, Blocks.leaves, 7);
		world.setBlockMetadataWithNotify(i + 25, j + 27, k + 25, 7, 2);
		setBlock(world, i + 25, j + 27, k + 30, Blocks.leaves, 7);
		world.setBlockMetadataWithNotify(i + 25, j + 27, k + 30, 7, 2);
		setBlock(world, i + 25, j + 28, k + 22, Blocks.leaves, 7);
		world.setBlockMetadataWithNotify(i + 25, j + 28, k + 22, 7, 2);
		setBlock(world, i + 25, j + 28, k + 23, Blocks.leaves, 7);
		world.setBlockMetadataWithNotify(i + 25, j + 28, k + 23, 7, 2);
		setBlock(world, i + 25, j + 28, k + 24, Blocks.leaves, 7);
		world.setBlockMetadataWithNotify(i + 25, j + 28, k + 24, 7, 2);
		setBlock(world, i + 25, j + 28, k + 30, Blocks.log, 1);
		world.setBlockMetadataWithNotify(i + 25, j + 28, k + 30, 1, 2);
		setBlock(world, i + 25, j + 28, k + 31, Blocks.log, 1);
		world.setBlockMetadataWithNotify(i + 25, j + 28, k + 31, 1, 2);
		setBlock(world, i + 25, j + 29, k + 23, Blocks.leaves, 7);
		world.setBlockMetadataWithNotify(i + 25, j + 29, k + 23, 7, 2);
		setBlock(world, i + 25, j + 29, k + 29, Blocks.log, 1);
		world.setBlockMetadataWithNotify(i + 25, j + 29, k + 29, 1, 2);
		setBlock(world, i + 25, j + 29, k + 30, Blocks.log, 1);
		world.setBlockMetadataWithNotify(i + 25, j + 29, k + 30, 1, 2);
		setBlock(world, i + 25, j + 29, k + 31, Blocks.log, 1);
		world.setBlockMetadataWithNotify(i + 25, j + 29, k + 31, 1, 2);
		setBlock(world, i + 25, j + 34, k + 22, Blocks.leaves, 7);
		world.setBlockMetadataWithNotify(i + 25, j + 34, k + 22, 7, 2);
		setBlock(world, i + 25, j + 34, k + 23, Blocks.leaves, 7);
		world.setBlockMetadataWithNotify(i + 25, j + 34, k + 23, 7, 2);
		setBlock(world, i + 25, j + 34, k + 24, Blocks.leaves, 7);
		world.setBlockMetadataWithNotify(i + 25, j + 34, k + 24, 7, 2);
		setBlock(world, i + 25, j + 34, k + 31, Blocks.leaves, 7);
		world.setBlockMetadataWithNotify(i + 25, j + 34, k + 31, 7, 2);
		setBlock(world, i + 25, j + 35, k + 23, Blocks.leaves, 7);
		world.setBlockMetadataWithNotify(i + 25, j + 35, k + 23, 7, 2);
		setBlock(world, i + 25, j + 35, k + 27, Blocks.leaves, 7);
		world.setBlockMetadataWithNotify(i + 25, j + 35, k + 27, 7, 2);
		setBlock(world, i + 25, j + 35, k + 28, Blocks.leaves, 7);
		world.setBlockMetadataWithNotify(i + 25, j + 35, k + 28, 7, 2);
		setBlock(world, i + 25, j + 35, k + 29, Blocks.leaves, 7);
		world.setBlockMetadataWithNotify(i + 25, j + 35, k + 29, 7, 2);
		setBlock(world, i + 25, j + 36, k + 28, Blocks.leaves, 7);
		world.setBlockMetadataWithNotify(i + 25, j + 36, k + 28, 7, 2);
		setBlock(world, i + 26, j + 24, k + 28, Blocks.leaves, 7);
		world.setBlockMetadataWithNotify(i + 26, j + 24, k + 28, 7, 2);
		setBlock(world, i + 26, j + 24, k + 29, Blocks.leaves, 7);
		world.setBlockMetadataWithNotify(i + 26, j + 24, k + 29, 7, 2);
		setBlock(world, i + 26, j + 24, k + 30, Blocks.leaves, 7);
		world.setBlockMetadataWithNotify(i + 26, j + 24, k + 30, 7, 2);
		setBlock(world, i + 26, j + 24, k + 31, Blocks.log, 1);
		world.setBlockMetadataWithNotify(i + 26, j + 24, k + 31, 1, 2);
		setBlock(world, i + 26, j + 25, k + 29, Blocks.leaves, 7);
		world.setBlockMetadataWithNotify(i + 26, j + 25, k + 29, 7, 2);
		setBlock(world, i + 26, j + 25, k + 30, Blocks.leaves, 7);
		world.setBlockMetadataWithNotify(i + 26, j + 25, k + 30, 7, 2);
		setBlock(world, i + 26, j + 25, k + 31, Blocks.leaves, 7);
		world.setBlockMetadataWithNotify(i + 26, j + 25, k + 31, 7, 2);
		setBlock(world, i + 26, j + 26, k + 30, Blocks.leaves, 7);
		world.setBlockMetadataWithNotify(i + 26, j + 26, k + 30, 7, 2);
		setBlock(world, i + 26, j + 27, k + 22, Blocks.leaves, 7);
		world.setBlockMetadataWithNotify(i + 26, j + 27, k + 22, 7, 2);
		setBlock(world, i + 26, j + 27, k + 23, Blocks.leaves, 7);
		world.setBlockMetadataWithNotify(i + 26, j + 27, k + 23, 7, 2);
		setBlock(world, i + 26, j + 27, k + 24, Blocks.leaves, 7);
		world.setBlockMetadataWithNotify(i + 26, j + 27, k + 24, 7, 2);
		setBlock(world, i + 26, j + 28, k + 23, Blocks.leaves, 7);
		world.setBlockMetadataWithNotify(i + 26, j + 28, k + 23, 7, 2);
		setBlock(world, i + 26, j + 28, k + 29, Blocks.log, 1);
		world.setBlockMetadataWithNotify(i + 26, j + 28, k + 29, 1, 2);
		setBlock(world, i + 26, j + 28, k + 30, Blocks.log, 1);
		world.setBlockMetadataWithNotify(i + 26, j + 28, k + 30, 1, 2);
		setBlock(world, i + 26, j + 28, k + 31, Blocks.log, 1);
		world.setBlockMetadataWithNotify(i + 26, j + 28, k + 31, 1, 2);
		setBlock(world, i + 26, j + 29, k + 29, Blocks.log, 1);
		world.setBlockMetadataWithNotify(i + 26, j + 29, k + 29, 1, 2);
		setBlock(world, i + 26, j + 29, k + 30, Blocks.log, 1);
		world.setBlockMetadataWithNotify(i + 26, j + 29, k + 30, 1, 2);
		setBlock(world, i + 26, j + 29, k + 31, Blocks.log, 1);
		world.setBlockMetadataWithNotify(i + 26, j + 29, k + 31, 1, 2);
		setBlock(world, i + 26, j + 30, k + 29, Blocks.log, 1);
		world.setBlockMetadataWithNotify(i + 26, j + 30, k + 29, 1, 2);
		setBlock(world, i + 26, j + 30, k + 30, Blocks.log, 1);
		world.setBlockMetadataWithNotify(i + 26, j + 30, k + 30, 1, 2);
		setBlock(world, i + 26, j + 30, k + 31, Blocks.log, 1);
		world.setBlockMetadataWithNotify(i + 26, j + 30, k + 31, 1, 2);
		setBlock(world, i + 26, j + 35, k + 31, Blocks.leaves, 7);
		world.setBlockMetadataWithNotify(i + 26, j + 35, k + 31, 7, 2);
		setBlock(world, i + 26, j + 41, k + 28, Blocks.leaves, 15);
		world.setBlockMetadataWithNotify(i + 26, j + 41, k + 28, 15, 2);
		setBlock(world, i + 26, j + 41, k + 29, Blocks.leaves, 15);
		world.setBlockMetadataWithNotify(i + 26, j + 41, k + 29, 15, 2);
		setBlock(world, i + 26, j + 41, k + 30, Blocks.leaves, 15);
		world.setBlockMetadataWithNotify(i + 26, j + 41, k + 30, 15, 2);
		setBlock(world, i + 26, j + 42, k + 29, Blocks.leaves, 15);
		world.setBlockMetadataWithNotify(i + 26, j + 42, k + 29, 15, 2);
		setBlock(world, i + 27, j + 18, k + 31, Blocks.log, 3);
		world.setBlockMetadataWithNotify(i + 27, j + 18, k + 31, 3, 2);
		setBlock(world, i + 27, j + 23, k + 31, Blocks.log, 1);
		world.setBlockMetadataWithNotify(i + 27, j + 23, k + 31, 1, 2);
		setBlock(world, i + 27, j + 24, k + 29, Blocks.leaves, 7);
		world.setBlockMetadataWithNotify(i + 27, j + 24, k + 29, 7, 2);
		setBlock(world, i + 27, j + 24, k + 30, Blocks.log, 1);
		world.setBlockMetadataWithNotify(i + 27, j + 24, k + 30, 1, 2);
		setBlock(world, i + 27, j + 24, k + 31, Blocks.log, 1);
		world.setBlockMetadataWithNotify(i + 27, j + 24, k + 31, 1, 2);
		setBlock(world, i + 27, j + 25, k + 30, Blocks.log, 1);
		world.setBlockMetadataWithNotify(i + 27, j + 25, k + 30, 1, 2);
		setBlock(world, i + 27, j + 25, k + 31, Blocks.log, 1);
		world.setBlockMetadataWithNotify(i + 27, j + 25, k + 31, 1, 2);
		setBlock(world, i + 27, j + 26, k + 30, Blocks.log, 1);
		world.setBlockMetadataWithNotify(i + 27, j + 26, k + 30, 1, 2);
		setBlock(world, i + 27, j + 26, k + 31, Blocks.log, 1);
		world.setBlockMetadataWithNotify(i + 27, j + 26, k + 31, 1, 2);
		setBlock(world, i + 27, j + 28, k + 30, Blocks.log, 1);
		world.setBlockMetadataWithNotify(i + 27, j + 28, k + 30, 1, 2);
		setBlock(world, i + 27, j + 29, k + 29, Blocks.log, 1);
		world.setBlockMetadataWithNotify(i + 27, j + 29, k + 29, 1, 2);
		setBlock(world, i + 27, j + 29, k + 30, Blocks.log, 1);
		world.setBlockMetadataWithNotify(i + 27, j + 29, k + 30, 1, 2);
		setBlock(world, i + 27, j + 29, k + 31, Blocks.log, 1);
		world.setBlockMetadataWithNotify(i + 27, j + 29, k + 31, 1, 2);
		setBlock(world, i + 27, j + 30, k + 26, Blocks.log, 3);
		world.setBlockMetadataWithNotify(i + 27, j + 30, k + 26, 3, 2);
		setBlock(world, i + 27, j + 30, k + 27, Blocks.log, 3);
		world.setBlockMetadataWithNotify(i + 27, j + 30, k + 27, 3, 2);
		setBlock(world, i + 27, j + 30, k + 28, Blocks.log, 3);
		world.setBlockMetadataWithNotify(i + 27, j + 30, k + 28, 3, 2);
		setBlock(world, i + 27, j + 30, k + 29, Blocks.log, 3);
		world.setBlockMetadataWithNotify(i + 27, j + 30, k + 29, 3, 2);
		setBlock(world, i + 27, j + 30, k + 30, Blocks.log, 1);
		world.setBlockMetadataWithNotify(i + 27, j + 30, k + 30, 1, 2);
		setBlock(world, i + 27, j + 31, k + 20, Blocks.leaves, 7);
		world.setBlockMetadataWithNotify(i + 27, j + 31, k + 20, 7, 2);
		setBlock(world, i + 27, j + 31, k + 21, Blocks.leaves, 7);
		world.setBlockMetadataWithNotify(i + 27, j + 31, k + 21, 7, 2);
		setBlock(world, i + 27, j + 31, k + 22, Blocks.leaves, 7);
		world.setBlockMetadataWithNotify(i + 27, j + 31, k + 22, 7, 2);
		setBlock(world, i + 27, j + 32, k + 21, Blocks.leaves, 7);
		world.setBlockMetadataWithNotify(i + 27, j + 32, k + 21, 7, 2);
		setBlock(world, i + 27, j + 35, k + 30, Blocks.leaves, 7);
		world.setBlockMetadataWithNotify(i + 27, j + 35, k + 30, 7, 2);
		setBlock(world, i + 27, j + 35, k + 31, Blocks.leaves, 7);
		world.setBlockMetadataWithNotify(i + 27, j + 35, k + 31, 7, 2);
		setBlock(world, i + 27, j + 36, k + 31, Blocks.leaves, 7);
		world.setBlockMetadataWithNotify(i + 27, j + 36, k + 31, 7, 2);
		setBlock(world, i + 27, j + 40, k + 30, Blocks.log, 3);
		world.setBlockMetadataWithNotify(i + 27, j + 40, k + 30, 3, 2);
		setBlock(world, i + 27, j + 40, k + 31, Blocks.log, 3);
		world.setBlockMetadataWithNotify(i + 27, j + 40, k + 31, 3, 2);
		setBlock(world, i + 27, j + 41, k + 27, Blocks.leaves, 15);
		world.setBlockMetadataWithNotify(i + 27, j + 41, k + 27, 15, 2);
		setBlock(world, i + 27, j + 41, k + 28, Blocks.leaves, 15);
		world.setBlockMetadataWithNotify(i + 27, j + 41, k + 28, 15, 2);
		setBlock(world, i + 27, j + 41, k + 29, Blocks.leaves, 15);
		world.setBlockMetadataWithNotify(i + 27, j + 41, k + 29, 15, 2);
		setBlock(world, i + 27, j + 41, k + 30, Blocks.leaves, 15);
		world.setBlockMetadataWithNotify(i + 27, j + 41, k + 30, 15, 2);
		setBlock(world, i + 27, j + 41, k + 31, Blocks.leaves, 15);
		world.setBlockMetadataWithNotify(i + 27, j + 41, k + 31, 15, 2);
		setBlock(world, i + 27, j + 42, k + 28, Blocks.leaves, 15);
		world.setBlockMetadataWithNotify(i + 27, j + 42, k + 28, 15, 2);
		setBlock(world, i + 27, j + 42, k + 29, Blocks.leaves, 15);
		world.setBlockMetadataWithNotify(i + 27, j + 42, k + 29, 15, 2);
		setBlock(world, i + 27, j + 42, k + 30, Blocks.leaves, 15);
		world.setBlockMetadataWithNotify(i + 27, j + 42, k + 30, 15, 2);
		setBlock(world, i + 27, j + 52, k + 31, Blocks.leaves, 15);
		world.setBlockMetadataWithNotify(i + 27, j + 52, k + 31, 15, 2);
		setBlock(world, i + 28, j + 17, k + 31, Blocks.log, 3);
		world.setBlockMetadataWithNotify(i + 28, j + 17, k + 31, 3, 2);
		setBlock(world, i + 28, j + 18, k + 29, Blocks.log, 3);
		world.setBlockMetadataWithNotify(i + 28, j + 18, k + 29, 3, 2);
		setBlock(world, i + 28, j + 18, k + 30, Blocks.log, 3);
		world.setBlockMetadataWithNotify(i + 28, j + 18, k + 30, 3, 2);
		setBlock(world, i + 28, j + 18, k + 31, Blocks.log, 3);
		world.setBlockMetadataWithNotify(i + 28, j + 18, k + 31, 3, 2);
		setBlock(world, i + 28, j + 19, k + 27, Blocks.log, 3);
		world.setBlockMetadataWithNotify(i + 28, j + 19, k + 27, 3, 2);
		setBlock(world, i + 28, j + 19, k + 28, Blocks.log, 3);
		world.setBlockMetadataWithNotify(i + 28, j + 19, k + 28, 3, 2);
		setBlock(world, i + 28, j + 19, k + 31, Blocks.log, 3);
		world.setBlockMetadataWithNotify(i + 28, j + 19, k + 31, 3, 2);
		setBlock(world, i + 28, j + 24, k + 30, Blocks.log, 1);
		world.setBlockMetadataWithNotify(i + 28, j + 24, k + 30, 1, 2);
		setBlock(world, i + 28, j + 24, k + 31, Blocks.log, 1);
		world.setBlockMetadataWithNotify(i + 28, j + 24, k + 31, 1, 2);
		setBlock(world, i + 28, j + 25, k + 29, Blocks.log, 1);
		world.setBlockMetadataWithNotify(i + 28, j + 25, k + 29, 1, 2);
		setBlock(world, i + 28, j + 25, k + 30, Blocks.log, 1);
		world.setBlockMetadataWithNotify(i + 28, j + 25, k + 30, 1, 2);
		setBlock(world, i + 28, j + 25, k + 31, Blocks.log, 1);
		world.setBlockMetadataWithNotify(i + 28, j + 25, k + 31, 1, 2);
		setBlock(world, i + 28, j + 26, k + 29, Blocks.log, 1);
		world.setBlockMetadataWithNotify(i + 28, j + 26, k + 29, 1, 2);
		setBlock(world, i + 28, j + 26, k + 30, Blocks.log, 1);
		world.setBlockMetadataWithNotify(i + 28, j + 26, k + 30, 1, 2);
		setBlock(world, i + 28, j + 30, k + 22, Blocks.log, 3);
		world.setBlockMetadataWithNotify(i + 28, j + 30, k + 22, 3, 2);
		setBlock(world, i + 28, j + 30, k + 23, Blocks.log, 3);
		world.setBlockMetadataWithNotify(i + 28, j + 30, k + 23, 3, 2);
		setBlock(world, i + 28, j + 30, k + 24, Blocks.log, 3);
		world.setBlockMetadataWithNotify(i + 28, j + 30, k + 24, 3, 2);
		setBlock(world, i + 28, j + 30, k + 25, Blocks.log, 3);
		world.setBlockMetadataWithNotify(i + 28, j + 30, k + 25, 3, 2);
		setBlock(world, i + 28, j + 31, k + 19, Blocks.leaves, 7);
		world.setBlockMetadataWithNotify(i + 28, j + 31, k + 19, 7, 2);
		setBlock(world, i + 28, j + 31, k + 20, Blocks.leaves, 7);
		world.setBlockMetadataWithNotify(i + 28, j + 31, k + 20, 7, 2);
		setBlock(world, i + 28, j + 31, k + 21, Blocks.leaves, 7);
		world.setBlockMetadataWithNotify(i + 28, j + 31, k + 21, 7, 2);
		setBlock(world, i + 28, j + 31, k + 22, Blocks.leaves, 7);
		world.setBlockMetadataWithNotify(i + 28, j + 31, k + 22, 7, 2);
		setBlock(world, i + 28, j + 31, k + 23, Blocks.leaves, 7);
		world.setBlockMetadataWithNotify(i + 28, j + 31, k + 23, 7, 2);
		setBlock(world, i + 28, j + 32, k + 20, Blocks.leaves, 7);
		world.setBlockMetadataWithNotify(i + 28, j + 32, k + 20, 7, 2);
		setBlock(world, i + 28, j + 32, k + 21, Blocks.leaves, 7);
		world.setBlockMetadataWithNotify(i + 28, j + 32, k + 21, 7, 2);
		setBlock(world, i + 28, j + 32, k + 22, Blocks.leaves, 7);
		world.setBlockMetadataWithNotify(i + 28, j + 32, k + 22, 7, 2);
		setBlock(world, i + 28, j + 33, k + 21, Blocks.leaves, 7);
		world.setBlockMetadataWithNotify(i + 28, j + 33, k + 21, 7, 2);
		setBlock(world, i + 28, j + 33, k + 30, Blocks.log, 3);
		world.setBlockMetadataWithNotify(i + 28, j + 33, k + 30, 3, 2);
		setBlock(world, i + 28, j + 33, k + 31, Blocks.log, 3);
		world.setBlockMetadataWithNotify(i + 28, j + 33, k + 31, 3, 2);
		setBlock(world, i + 28, j + 34, k + 26, Blocks.leaves, 7);
		world.setBlockMetadataWithNotify(i + 28, j + 34, k + 26, 7, 2);
		setBlock(world, i + 28, j + 34, k + 27, Blocks.leaves, 7);
		world.setBlockMetadataWithNotify(i + 28, j + 34, k + 27, 7, 2);
		setBlock(world, i + 28, j + 34, k + 28, Blocks.leaves, 7);
		world.setBlockMetadataWithNotify(i + 28, j + 34, k + 28, 7, 2);
		setBlock(world, i + 28, j + 35, k + 27, Blocks.leaves, 7);
		world.setBlockMetadataWithNotify(i + 28, j + 35, k + 27, 7, 2);
		setBlock(world, i + 28, j + 35, k + 30, Blocks.leaves, 7);
		world.setBlockMetadataWithNotify(i + 28, j + 35, k + 30, 7, 2);
		setBlock(world, i + 28, j + 35, k + 31, Blocks.leaves, 7);
		world.setBlockMetadataWithNotify(i + 28, j + 35, k + 31, 7, 2);
		setBlock(world, i + 28, j + 36, k + 30, Blocks.leaves, 7);
		world.setBlockMetadataWithNotify(i + 28, j + 36, k + 30, 7, 2);
		setBlock(world, i + 28, j + 36, k + 31, Blocks.leaves, 7);
		world.setBlockMetadataWithNotify(i + 28, j + 36, k + 31, 7, 2);
		setBlock(world, i + 28, j + 37, k + 31, Blocks.leaves, 7);
		world.setBlockMetadataWithNotify(i + 28, j + 37, k + 31, 7, 2);
		setBlock(world, i + 28, j + 41, k + 27, Blocks.leaves, 15);
		world.setBlockMetadataWithNotify(i + 28, j + 41, k + 27, 15, 2);
		setBlock(world, i + 28, j + 41, k + 28, Blocks.leaves, 15);
		world.setBlockMetadataWithNotify(i + 28, j + 41, k + 28, 15, 2);
		setBlock(world, i + 28, j + 41, k + 29, Blocks.log, 3);
		world.setBlockMetadataWithNotify(i + 28, j + 41, k + 29, 3, 2);
		setBlock(world, i + 28, j + 41, k + 30, Blocks.leaves, 15);
		world.setBlockMetadataWithNotify(i + 28, j + 41, k + 30, 15, 2);
		setBlock(world, i + 28, j + 41, k + 31, Blocks.leaves, 15);
		world.setBlockMetadataWithNotify(i + 28, j + 41, k + 31, 15, 2);
		setBlock(world, i + 28, j + 42, k + 27, Blocks.leaves, 15);
		world.setBlockMetadataWithNotify(i + 28, j + 42, k + 27, 15, 2);
		setBlock(world, i + 28, j + 42, k + 28, Blocks.leaves, 15);
		world.setBlockMetadataWithNotify(i + 28, j + 42, k + 28, 15, 2);
		setBlock(world, i + 28, j + 42, k + 29, Blocks.leaves, 15);
		world.setBlockMetadataWithNotify(i + 28, j + 42, k + 29, 15, 2);
		setBlock(world, i + 28, j + 42, k + 30, Blocks.leaves, 15);
		world.setBlockMetadataWithNotify(i + 28, j + 42, k + 30, 15, 2);
		setBlock(world, i + 28, j + 42, k + 31, Blocks.leaves, 15);
		world.setBlockMetadataWithNotify(i + 28, j + 42, k + 31, 15, 2);
		setBlock(world, i + 28, j + 51, k + 31, Blocks.leaves, 15);
		world.setBlockMetadataWithNotify(i + 28, j + 51, k + 31, 15, 2);
		setBlock(world, i + 28, j + 53, k + 31, Blocks.leaves, 15);
		world.setBlockMetadataWithNotify(i + 28, j + 53, k + 31, 15, 2);
		setBlock(world, i + 29, j + 17, k + 29, Blocks.log, 3);
		world.setBlockMetadataWithNotify(i + 29, j + 17, k + 29, 3, 2);
		setBlock(world, i + 29, j + 17, k + 30, Blocks.log, 3);
		world.setBlockMetadataWithNotify(i + 29, j + 17, k + 30, 3, 2);
		setBlock(world, i + 29, j + 18, k + 27, Blocks.log, 3);
		world.setBlockMetadataWithNotify(i + 29, j + 18, k + 27, 3, 2);
		setBlock(world, i + 29, j + 18, k + 28, Blocks.log, 3);
		world.setBlockMetadataWithNotify(i + 29, j + 18, k + 28, 3, 2);
		setBlock(world, i + 29, j + 18, k + 29, Blocks.log, 3);
		world.setBlockMetadataWithNotify(i + 29, j + 18, k + 29, 3, 2);
		setBlock(world, i + 29, j + 18, k + 30, Blocks.log, 3);
		world.setBlockMetadataWithNotify(i + 29, j + 18, k + 30, 3, 2);
		setBlock(world, i + 29, j + 18, k + 31, Blocks.log, 3);
		world.setBlockMetadataWithNotify(i + 29, j + 18, k + 31, 3, 2);
		setBlock(world, i + 29, j + 19, k + 27, Blocks.log, 3);
		world.setBlockMetadataWithNotify(i + 29, j + 19, k + 27, 3, 2);
		setBlock(world, i + 29, j + 19, k + 28, Blocks.log, 3);
		world.setBlockMetadataWithNotify(i + 29, j + 19, k + 28, 3, 2);
		setBlock(world, i + 29, j + 19, k + 29, Blocks.log, 3);
		world.setBlockMetadataWithNotify(i + 29, j + 19, k + 29, 3, 2);
		setBlock(world, i + 29, j + 19, k + 30, Blocks.log, 3);
		world.setBlockMetadataWithNotify(i + 29, j + 19, k + 30, 3, 2);
		setBlock(world, i + 29, j + 20, k + 27, Blocks.log, 3);
		world.setBlockMetadataWithNotify(i + 29, j + 20, k + 27, 3, 2);
		setBlock(world, i + 29, j + 20, k + 28, Blocks.log, 3);
		world.setBlockMetadataWithNotify(i + 29, j + 20, k + 28, 3, 2);
		setBlock(world, i + 29, j + 20, k + 30, Blocks.log, 3);
		world.setBlockMetadataWithNotify(i + 29, j + 20, k + 30, 3, 2);
		setBlock(world, i + 29, j + 20, k + 31, Blocks.log, 3);
		world.setBlockMetadataWithNotify(i + 29, j + 20, k + 31, 3, 2);
		setBlock(world, i + 29, j + 21, k + 27, Blocks.leaves, 7);
		world.setBlockMetadataWithNotify(i + 29, j + 21, k + 27, 7, 2);
		setBlock(world, i + 29, j + 21, k + 28, Blocks.leaves, 7);
		world.setBlockMetadataWithNotify(i + 29, j + 21, k + 28, 7, 2);
		setBlock(world, i + 29, j + 21, k + 29, Blocks.leaves, 7);
		world.setBlockMetadataWithNotify(i + 29, j + 21, k + 29, 7, 2);
		setBlock(world, i + 29, j + 22, k + 28, Blocks.leaves, 7);
		world.setBlockMetadataWithNotify(i + 29, j + 22, k + 28, 7, 2);
		setBlock(world, i + 29, j + 24, k + 30, Blocks.log, 1);
		world.setBlockMetadataWithNotify(i + 29, j + 24, k + 30, 1, 2);
		setBlock(world, i + 29, j + 25, k + 29, Blocks.log, 1);
		world.setBlockMetadataWithNotify(i + 29, j + 25, k + 29, 1, 2);
		setBlock(world, i + 29, j + 25, k + 30, Blocks.log, 1);
		world.setBlockMetadataWithNotify(i + 29, j + 25, k + 30, 1, 2);
		setBlock(world, i + 29, j + 25, k + 31, Blocks.log, 1);
		world.setBlockMetadataWithNotify(i + 29, j + 25, k + 31, 1, 2);
		setBlock(world, i + 29, j + 26, k + 30, Blocks.log, 1);
		world.setBlockMetadataWithNotify(i + 29, j + 26, k + 30, 1, 2);
		setBlock(world, i + 29, j + 31, k + 19, Blocks.leaves, 7);
		world.setBlockMetadataWithNotify(i + 29, j + 31, k + 19, 7, 2);
		setBlock(world, i + 29, j + 31, k + 20, Blocks.leaves, 7);
		world.setBlockMetadataWithNotify(i + 29, j + 31, k + 20, 7, 2);
		setBlock(world, i + 29, j + 31, k + 21, Blocks.log, 3);
		world.setBlockMetadataWithNotify(i + 29, j + 31, k + 21, 3, 2);
		setBlock(world, i + 29, j + 31, k + 22, Blocks.leaves, 7);
		world.setBlockMetadataWithNotify(i + 29, j + 31, k + 22, 7, 2);
		setBlock(world, i + 29, j + 31, k + 23, Blocks.leaves, 7);
		world.setBlockMetadataWithNotify(i + 29, j + 31, k + 23, 7, 2);
		setBlock(world, i + 29, j + 32, k + 19, Blocks.leaves, 7);
		world.setBlockMetadataWithNotify(i + 29, j + 32, k + 19, 7, 2);
		setBlock(world, i + 29, j + 32, k + 20, Blocks.leaves, 7);
		world.setBlockMetadataWithNotify(i + 29, j + 32, k + 20, 7, 2);
		setBlock(world, i + 29, j + 32, k + 21, Blocks.leaves, 7);
		world.setBlockMetadataWithNotify(i + 29, j + 32, k + 21, 7, 2);
		setBlock(world, i + 29, j + 32, k + 22, Blocks.leaves, 7);
		world.setBlockMetadataWithNotify(i + 29, j + 32, k + 22, 7, 2);
		setBlock(world, i + 29, j + 32, k + 23, Blocks.leaves, 7);
		world.setBlockMetadataWithNotify(i + 29, j + 32, k + 23, 7, 2);
		setBlock(world, i + 29, j + 33, k + 20, Blocks.leaves, 7);
		world.setBlockMetadataWithNotify(i + 29, j + 33, k + 20, 7, 2);
		setBlock(world, i + 29, j + 33, k + 21, Blocks.leaves, 7);
		world.setBlockMetadataWithNotify(i + 29, j + 33, k + 21, 7, 2);
		setBlock(world, i + 29, j + 33, k + 22, Blocks.leaves, 7);
		world.setBlockMetadataWithNotify(i + 29, j + 33, k + 22, 7, 2);
		setBlock(world, i + 29, j + 33, k + 28, Blocks.log, 3);
		world.setBlockMetadataWithNotify(i + 29, j + 33, k + 28, 3, 2);
		setBlock(world, i + 29, j + 33, k + 29, Blocks.log, 3);
		world.setBlockMetadataWithNotify(i + 29, j + 33, k + 29, 3, 2);
		setBlock(world, i + 29, j + 34, k + 21, Blocks.leaves, 7);
		world.setBlockMetadataWithNotify(i + 29, j + 34, k + 21, 7, 2);
		setBlock(world, i + 29, j + 34, k + 25, Blocks.leaves, 7);
		world.setBlockMetadataWithNotify(i + 29, j + 34, k + 25, 7, 2);
		setBlock(world, i + 29, j + 34, k + 26, Blocks.leaves, 7);
		world.setBlockMetadataWithNotify(i + 29, j + 34, k + 26, 7, 2);
		setBlock(world, i + 29, j + 34, k + 27, Blocks.leaves, 7);
		world.setBlockMetadataWithNotify(i + 29, j + 34, k + 27, 7, 2);
		setBlock(world, i + 29, j + 34, k + 28, Blocks.leaves, 7);
		world.setBlockMetadataWithNotify(i + 29, j + 34, k + 28, 7, 2);
		setBlock(world, i + 29, j + 34, k + 29, Blocks.leaves, 7);
		world.setBlockMetadataWithNotify(i + 29, j + 34, k + 29, 7, 2);
		setBlock(world, i + 29, j + 35, k + 26, Blocks.leaves, 7);
		world.setBlockMetadataWithNotify(i + 29, j + 35, k + 26, 7, 2);
		setBlock(world, i + 29, j + 35, k + 27, Blocks.leaves, 7);
		world.setBlockMetadataWithNotify(i + 29, j + 35, k + 27, 7, 2);
		setBlock(world, i + 29, j + 35, k + 28, Blocks.leaves, 7);
		world.setBlockMetadataWithNotify(i + 29, j + 35, k + 28, 7, 2);
		setBlock(world, i + 29, j + 35, k + 30, Blocks.leaves, 7);
		world.setBlockMetadataWithNotify(i + 29, j + 35, k + 30, 7, 2);
		setBlock(world, i + 29, j + 35, k + 31, Blocks.leaves, 7);
		world.setBlockMetadataWithNotify(i + 29, j + 35, k + 31, 7, 2);
		setBlock(world, i + 29, j + 36, k + 27, Blocks.leaves, 7);
		world.setBlockMetadataWithNotify(i + 29, j + 36, k + 27, 7, 2);
		setBlock(world, i + 29, j + 36, k + 31, Blocks.leaves, 7);
		world.setBlockMetadataWithNotify(i + 29, j + 36, k + 31, 7, 2);
		setBlock(world, i + 29, j + 41, k + 27, Blocks.leaves, 15);
		world.setBlockMetadataWithNotify(i + 29, j + 41, k + 27, 15, 2);
		setBlock(world, i + 29, j + 41, k + 28, Blocks.leaves, 15);
		world.setBlockMetadataWithNotify(i + 29, j + 41, k + 28, 15, 2);
		setBlock(world, i + 29, j + 41, k + 29, Blocks.leaves, 15);
		world.setBlockMetadataWithNotify(i + 29, j + 41, k + 29, 15, 2);
		setBlock(world, i + 29, j + 41, k + 30, Blocks.leaves, 15);
		world.setBlockMetadataWithNotify(i + 29, j + 41, k + 30, 15, 2);
		setBlock(world, i + 29, j + 41, k + 31, Blocks.leaves, 15);
		world.setBlockMetadataWithNotify(i + 29, j + 41, k + 31, 15, 2);
		setBlock(world, i + 29, j + 42, k + 28, Blocks.leaves, 15);
		world.setBlockMetadataWithNotify(i + 29, j + 42, k + 28, 15, 2);
		setBlock(world, i + 29, j + 45, k + 27, Blocks.spruce_stairs, 4);
		world.setBlockMetadataWithNotify(i + 29, j + 45, k + 27, 4, 2);
		setBlock(world, i + 29, j + 46, k + 27, Blocks.log, 1);
		world.setBlockMetadataWithNotify(i + 29, j + 46, k + 27, 1, 2);
		setBlock(world, i + 29, j + 47, k + 27, Blocks.log, 1);
		world.setBlockMetadataWithNotify(i + 29, j + 47, k + 27, 1, 2);
		setBlock(world, i + 29, j + 47, k + 28, Blocks.spruce_stairs, 7);
		world.setBlockMetadataWithNotify(i + 29, j + 47, k + 28, 7, 2);
		setBlock(world, i + 29, j + 48, k + 26, Blocks.log, 1);
		world.setBlockMetadataWithNotify(i + 29, j + 48, k + 26, 1, 2);
		setBlock(world, i + 29, j + 48, k + 27, Blocks.log, 1);
		world.setBlockMetadataWithNotify(i + 29, j + 48, k + 27, 1, 2);
		setBlock(world, i + 29, j + 48, k + 28, Blocks.log, 1);
		world.setBlockMetadataWithNotify(i + 29, j + 48, k + 28, 1, 2);
		setBlock(world, i + 29, j + 48, k + 29, Blocks.log, 1);
		world.setBlockMetadataWithNotify(i + 29, j + 48, k + 29, 1, 2);
		setBlock(world, i + 29, j + 48, k + 30, Blocks.log, 1);
		world.setBlockMetadataWithNotify(i + 29, j + 48, k + 30, 1, 2);
		setBlock(world, i + 29, j + 48, k + 31, Blocks.log, 1);
		world.setBlockMetadataWithNotify(i + 29, j + 48, k + 31, 1, 2);
		setBlock(world, i + 29, j + 53, k + 31, Blocks.leaves, 7);
		world.setBlockMetadataWithNotify(i + 29, j + 53, k + 31, 7, 2);
		setBlock(world, i + 29, j + 54, k + 31, Blocks.leaves, 7);
		world.setBlockMetadataWithNotify(i + 29, j + 54, k + 31, 7, 2);
		setBlock(world, i + 30, j + 18, k + 29, Blocks.log, 3);
		world.setBlockMetadataWithNotify(i + 30, j + 18, k + 29, 3, 2);
		setBlock(world, i + 30, j + 18, k + 30, Blocks.log, 3);
		world.setBlockMetadataWithNotify(i + 30, j + 18, k + 30, 3, 2);
		setBlock(world, i + 30, j + 19, k + 25, Blocks.log, 3);
		world.setBlockMetadataWithNotify(i + 30, j + 19, k + 25, 3, 2);
		setBlock(world, i + 30, j + 19, k + 26, Blocks.log, 3);
		world.setBlockMetadataWithNotify(i + 30, j + 19, k + 26, 3, 2);
		setBlock(world, i + 30, j + 19, k + 27, Blocks.log, 3);
		world.setBlockMetadataWithNotify(i + 30, j + 19, k + 27, 3, 2);
		setBlock(world, i + 30, j + 19, k + 28, Blocks.log, 3);
		world.setBlockMetadataWithNotify(i + 30, j + 19, k + 28, 3, 2);
		setBlock(world, i + 30, j + 20, k + 24, Blocks.log, 3);
		world.setBlockMetadataWithNotify(i + 30, j + 20, k + 24, 3, 2);
		setBlock(world, i + 30, j + 20, k + 29, Blocks.log, 3);
		world.setBlockMetadataWithNotify(i + 30, j + 20, k + 29, 3, 2);
		setBlock(world, i + 30, j + 21, k + 19, Blocks.leaves, 7);
		world.setBlockMetadataWithNotify(i + 30, j + 21, k + 19, 7, 2);
		
		generate2(world, rand, i, j, k);
		return true;
		}

	
	public boolean generate2(World world, Random rand, int i, int j, int k)
	{
		setBlock(world, i + 30, j + 21, k + 20, Blocks.leaves, 7);
		world.setBlockMetadataWithNotify(i + 30, j + 21, k + 20, 7, 2);
		setBlock(world, i + 30, j + 21, k + 21, Blocks.leaves, 7);
		world.setBlockMetadataWithNotify(i + 30, j + 21, k + 21, 7, 2);
		setBlock(world, i + 30, j + 21, k + 26, Blocks.leaves, 7);
		world.setBlockMetadataWithNotify(i + 30, j + 21, k + 26, 7, 2);
		setBlock(world, i + 30, j + 21, k + 27, Blocks.leaves, 7);
		world.setBlockMetadataWithNotify(i + 30, j + 21, k + 27, 7, 2);
		setBlock(world, i + 30, j + 21, k + 28, Blocks.leaves, 7);
		world.setBlockMetadataWithNotify(i + 30, j + 21, k + 28, 7, 2);
		setBlock(world, i + 30, j + 21, k + 29, Blocks.leaves, 7);
		world.setBlockMetadataWithNotify(i + 30, j + 21, k + 29, 7, 2);
		setBlock(world, i + 30, j + 21, k + 30, Blocks.leaves, 7);
		world.setBlockMetadataWithNotify(i + 30, j + 21, k + 30, 7, 2);
		setBlock(world, i + 30, j + 22, k + 20, Blocks.leaves, 7);
		world.setBlockMetadataWithNotify(i + 30, j + 22, k + 20, 7, 2);
		setBlock(world, i + 30, j + 22, k + 27, Blocks.leaves, 7);
		world.setBlockMetadataWithNotify(i + 30, j + 22, k + 27, 7, 2);
		setBlock(world, i + 30, j + 22, k + 28, Blocks.leaves, 7);
		world.setBlockMetadataWithNotify(i + 30, j + 22, k + 28, 7, 2);
		setBlock(world, i + 30, j + 22, k + 29, Blocks.leaves, 7);
		world.setBlockMetadataWithNotify(i + 30, j + 22, k + 29, 7, 2);
		setBlock(world, i + 30, j + 23, k + 28, Blocks.leaves, 7);
		world.setBlockMetadataWithNotify(i + 30, j + 23, k + 28, 7, 2);
		setBlock(world, i + 30, j + 24, k + 30, Blocks.leaves, 7);
		world.setBlockMetadataWithNotify(i + 30, j + 24, k + 30, 7, 2);
		setBlock(world, i + 30, j + 24, k + 31, Blocks.leaves, 7);
		world.setBlockMetadataWithNotify(i + 30, j + 24, k + 31, 7, 2);
		setBlock(world, i + 30, j + 25, k + 31, Blocks.leaves, 7);
		world.setBlockMetadataWithNotify(i + 30, j + 25, k + 31, 7, 2);
		setBlock(world, i + 30, j + 30, k + 31, Blocks.log, 3);
		world.setBlockMetadataWithNotify(i + 30, j + 30, k + 31, 3, 2);
		setBlock(world, i + 30, j + 31, k + 19, Blocks.leaves, 7);
		world.setBlockMetadataWithNotify(i + 30, j + 31, k + 19, 7, 2);
		setBlock(world, i + 30, j + 31, k + 20, Blocks.leaves, 7);
		world.setBlockMetadataWithNotify(i + 30, j + 31, k + 20, 7, 2);
		setBlock(world, i + 30, j + 31, k + 21, Blocks.leaves, 7);
		world.setBlockMetadataWithNotify(i + 30, j + 31, k + 21, 7, 2);
		setBlock(world, i + 30, j + 31, k + 22, Blocks.leaves, 7);
		world.setBlockMetadataWithNotify(i + 30, j + 31, k + 22, 7, 2);
		setBlock(world, i + 30, j + 31, k + 23, Blocks.leaves, 7);
		world.setBlockMetadataWithNotify(i + 30, j + 31, k + 23, 7, 2);
		setBlock(world, i + 30, j + 32, k + 20, Blocks.leaves, 7);
		world.setBlockMetadataWithNotify(i + 30, j + 32, k + 20, 7, 2);
		setBlock(world, i + 30, j + 32, k + 21, Blocks.leaves, 7);
		world.setBlockMetadataWithNotify(i + 30, j + 32, k + 21, 7, 2);
		setBlock(world, i + 30, j + 32, k + 22, Blocks.leaves, 7);
		world.setBlockMetadataWithNotify(i + 30, j + 32, k + 22, 7, 2);
		setBlock(world, i + 30, j + 33, k + 21, Blocks.leaves, 7);
		world.setBlockMetadataWithNotify(i + 30, j + 33, k + 21, 7, 2);
		setBlock(world, i + 30, j + 34, k + 25, Blocks.leaves, 7);
		world.setBlockMetadataWithNotify(i + 30, j + 34, k + 25, 7, 2);
		setBlock(world, i + 30, j + 34, k + 26, Blocks.leaves, 7);
		world.setBlockMetadataWithNotify(i + 30, j + 34, k + 26, 7, 2);
		setBlock(world, i + 30, j + 34, k + 27, Blocks.log, 3);
		world.setBlockMetadataWithNotify(i + 30, j + 34, k + 27, 3, 2);
		setBlock(world, i + 30, j + 34, k + 28, Blocks.leaves, 7);
		world.setBlockMetadataWithNotify(i + 30, j + 34, k + 28, 7, 2);
		setBlock(world, i + 30, j + 34, k + 29, Blocks.leaves, 7);
		world.setBlockMetadataWithNotify(i + 30, j + 34, k + 29, 7, 2);
