/*      */package com.parzivail.pswm.world.gen.wookietree;

/*      */
/*      *//*      */
/*      */
import com.parzivail.pswm.utils.LootGenUtils;
import com.parzivail.pswm.utils.NPCType;
import com.parzivail.pswm.utils.SpawnUtils;


/*      */
import cpw.mods.fml.common.IWorldGenerator;


/*      */
import java.util.Random;


/*      */
import net.minecraft.block.Block;
/*      */
import net.minecraft.init.Blocks;
/*      */
import net.minecraft.tileentity.TileEntityChest;
/*      */
import net.minecraft.world.World;
/*      */
import net.minecraft.world.WorldProvider;
/*      */
import net.minecraft.world.chunk.IChunkProvider;
/*      */
import net.minecraft.world.gen.feature.WorldGenerator;

/*      */
/*      */public class WT_31
/*      */extends WorldGenerator implements IWorldGenerator
/*      */
{
	/*      */protected Block[] getValidSpawnBlocks()
	/*      */
	{
		return new Block[0];
		/*      */}

	/*      */
	/*      */public boolean locationIsValidSpawn(World world, int i, int j, int k)
	/*      */
	{
		int distanceToAir = 0;
		Block check = world.getBlock(i, j, k);
		/*      */
		while (check != Blocks.air)
		{
			if (distanceToAir > 3) { return false;
			/*      */}
			/*      */
			distanceToAir++;
			check = world.getBlock(i, j + distanceToAir, k);
			/*      */}
		/*      */
		j += distanceToAir - 1;
		/*      */
		Block block = world.getBlock(i, j, k);
		Block blockAbove = world.getBlock(i, j + 1, k);
		Block blockBelow = world.getBlock(i, j - 1, k);
		/*      */
		for (Block x : getValidSpawnBlocks())
		{
			if (blockAbove != Blocks.air) { return false;
			/*      */}
			if (block == x) return true;
			if ((block == Blocks.snow) && (blockBelow == x)) { return true;
			/*      */}
			/*      */}
		/*      */
		return false;
		/*      */}

	/*      */
	/*      */
	/*      */
	/*      */public void generate(Random random, int chunkX, int chunkZ, World world, IChunkProvider chunkGenerator, IChunkProvider chunkProvider)
	{
	}

	/*      */
	/*      */
	/*      */public void setBlock(World world, int x, int y, int z, Block block, int metadata)
	/*      */
	{
		world.setBlock(x, y, z, block, metadata, 2);
		/*      */}

	/*      */
	/*      */public boolean generate(World world, Random rand, int i, int j, int k)
	/*      */
	{
		k -= 10;
		i -= 10;
		/*      */
		setBlock(world, i + 0, j + 44, k + 24, Blocks.fence, 0);
		setBlock(world, i + 0, j + 44, k + 25, Blocks.fence, 0);
		setBlock(world, i + 0, j + 44, k + 26, Blocks.fence, 0);
		setBlock(world, i + 0, j + 47, k + 20, Blocks.fence, 0);
		setBlock(world, i + 0, j + 47, k + 21, Blocks.fence, 0);
		setBlock(world, i + 1, j + 44, k + 22, Blocks.fence, 0);
		setBlock(world, i + 1, j + 44, k + 23, Blocks.fence, 0);
		setBlock(world, i + 1, j + 44, k + 24, Blocks.fence, 0);
		setBlock(world, i + 1, j + 47, k + 19, Blocks.fence, 0);
		setBlock(world, i + 1, j + 47, k + 20, Blocks.fence, 0);
		SpawnUtils.spawnNPC(NPCType.WOOKIETREE, world, i + 3, j + 44, k + 28);
		setBlock(world, i + 4, j + 28, k + 31, Blocks.fence, 0);
		setBlock(world, i + 4, j + 44, k + 30, Blocks.spruce_stairs, 0);
		setBlock(world, i + 4, j + 44, k + 31, Blocks.spruce_stairs, 0);
		setBlock(world, i + 5, j + 28, k + 30, Blocks.fence, 0);
		setBlock(world, i + 5, j + 28, k + 31, Blocks.fence, 0);
		setBlock(world, i + 6, j + 28, k + 29, Blocks.spruce_stairs, 0);
		setBlock(world, i + 6, j + 28, k + 30, Blocks.fence, 0);
		setBlock(world, i + 6, j + 30, k + 27, Blocks.fence, 0);
		setBlock(world, i + 6, j + 30, k + 28, Blocks.fence, 0);
		setBlock(world, i + 8, j + 44, k + 21, Blocks.spruce_stairs, 0);
		SpawnUtils.spawnNPC(NPCType.WOOKIETREE, world, i + 8, j + 44, k + 28);
		setBlock(world, i + 10, j + 44, k + 22, Blocks.fence, 0);
		setBlock(world, i + 10, j + 44, k + 23, Blocks.fence, 0);
		setBlock(world, i + 10, j + 44, k + 24, Blocks.fence, 0);
		setBlock(world, i + 10, j + 47, k + 19, Blocks.fence, 0);
		setBlock(world, i + 10, j + 47, k + 20, Blocks.fence, 0);
		setBlock(world, i + 11, j + 44, k + 24, Blocks.fence, 0);
		setBlock(world, i + 11, j + 44, k + 25, Blocks.fence, 0);
		setBlock(world, i + 11, j + 44, k + 26, Blocks.fence, 0);
		setBlock(world, i + 11, j + 44, k + 27, Blocks.spruce_stairs, 0);
		setBlock(world, i + 11, j + 47, k + 20, Blocks.fence, 0);
		setBlock(world, i + 11, j + 47, k + 21, Blocks.fence, 0);
		setBlock(world, i + 12, j + 28, k + 30, Blocks.fence, 0);
		setBlock(world, i + 12, j + 30, k + 27, Blocks.fence, 0);
		setBlock(world, i + 12, j + 30, k + 28, Blocks.fence, 0);
		setBlock(world, i + 12, j + 47, k + 21, Blocks.fence, 0);
		setBlock(world, i + 12, j + 47, k + 22, Blocks.fence, 0);
		setBlock(world, i + 12, j + 47, k + 23, Blocks.fence, 0);
		setBlock(world, i + 13, j + 28, k + 30, Blocks.fence, 0);
		setBlock(world, i + 13, j + 28, k + 31, Blocks.fence, 0);
		setBlock(world, i + 13, j + 47, k + 23, Blocks.fence, 0);
		setBlock(world, i + 13, j + 47, k + 24, Blocks.fence, 0);
		setBlock(world, i + 13, j + 47, k + 25, Blocks.fence, 0);
		setBlock(world, i + 13, j + 47, k + 26, Blocks.fence, 0);
		setBlock(world, i + 14, j + 28, k + 31, Blocks.fence, 0);
		setBlock(world, i + 14, j + 47, k + 26, Blocks.fence, 0);
		setBlock(world, i + 25, j + 69, k + 2, Blocks.fence, 0);
		setBlock(world, i + 25, j + 69, k + 11, Blocks.fence, 0);
		setBlock(world, i + 26, j + 69, k + 0, Blocks.fence, 0);
		setBlock(world, i + 26, j + 69, k + 1, Blocks.fence, 0);
		setBlock(world, i + 26, j + 69, k + 2, Blocks.fence, 0);
		setBlock(world, i + 26, j + 69, k + 11, Blocks.fence, 0);
		setBlock(world, i + 26, j + 69, k + 12, Blocks.fence, 0);
		setBlock(world, i + 26, j + 69, k + 13, Blocks.fence, 0);
		setBlock(world, i + 26, j + 69, k + 14, Blocks.fence, 0);
		setBlock(world, i + 27, j + 69, k + 14, Blocks.fence, 0);
		setBlock(world, i + 27, j + 69, k + 15, Blocks.fence, 0);
		setBlock(world, i + 27, j + 69, k + 16, Blocks.fence, 0);
		setBlock(world, i + 28, j + 66, k + 0, Blocks.fence, 0);
		setBlock(world, i + 28, j + 66, k + 1, Blocks.fence, 0);
		setBlock(world, i + 28, j + 66, k + 2, Blocks.fence, 0);
		setBlock(world, i + 28, j + 66, k + 11, Blocks.fence, 0);
		setBlock(world, i + 28, j + 66, k + 12, Blocks.fence, 0);
		setBlock(world, i + 28, j + 66, k + 13, Blocks.fence, 0);
		setBlock(world, i + 28, j + 69, k + 16, Blocks.fence, 0);
		setBlock(world, i + 28, j + 69, k + 17, Blocks.fence, 0);
		setBlock(world, i + 29, j + 66, k + 0, Blocks.fence, 0);
		setBlock(world, i + 29, j + 66, k + 13, Blocks.fence, 0);
		setBlock(world, i + 29, j + 66, k + 14, Blocks.fence, 0);
		setBlock(world, i + 29, j + 66, k + 15, Blocks.fence, 0);
		setBlock(world, i + 29, j + 69, k + 17, Blocks.fence, 0);
		setBlock(world, i + 29, j + 69, k + 18, Blocks.fence, 0);
		SpawnUtils.spawnNPC(NPCType.WOOKIETREE, world, i + 30, j + 66, k + 4);
		SpawnUtils.spawnNPC(NPCType.WOOKIETREE, world, i + 30, j + 66, k + 9);
		setBlock(world, i + 0, j + 21, k + 18, Blocks.leaves, 7);
		world.setBlockMetadataWithNotify(i + 0, j + 21, k + 18, 7, 2);
		setBlock(world, i + 0, j + 21, k + 19, Blocks.leaves, 7);
		world.setBlockMetadataWithNotify(i + 0, j + 21, k + 19, 7, 2);
		setBlock(world, i + 0, j + 21, k + 20, Blocks.log, 3);
		world.setBlockMetadataWithNotify(i + 0, j + 21, k + 20, 3, 2);
		setBlock(world, i + 0, j + 21, k + 21, Blocks.leaves, 7);
		world.setBlockMetadataWithNotify(i + 0, j + 21, k + 21, 7, 2);
		setBlock(world, i + 0, j + 21, k + 22, Blocks.leaves, 7);
		world.setBlockMetadataWithNotify(i + 0, j + 21, k + 22, 7, 2);
		setBlock(world, i + 0, j + 21, k + 26, Blocks.leaves, 7);
		world.setBlockMetadataWithNotify(i + 0, j + 21, k + 26, 7, 2);
		setBlock(world, i + 0, j + 21, k + 27, Blocks.leaves, 7);
		world.setBlockMetadataWithNotify(i + 0, j + 21, k + 27, 7, 2);
		setBlock(world, i + 0, j + 21, k + 28, Blocks.leaves, 7);
		world.setBlockMetadataWithNotify(i + 0, j + 21, k + 28, 7, 2);
		setBlock(world, i + 0, j + 21, k + 29, Blocks.leaves, 7);
		world.setBlockMetadataWithNotify(i + 0, j + 21, k + 29, 7, 2);
		setBlock(world, i + 0, j + 21, k + 30, Blocks.leaves, 7);
		world.setBlockMetadataWithNotify(i + 0, j + 21, k + 30, 7, 2);
		setBlock(world, i + 0, j + 22, k + 18, Blocks.leaves, 7);
		world.setBlockMetadataWithNotify(i + 0, j + 22, k + 18, 7, 2);
		setBlock(world, i + 0, j + 22, k + 19, Blocks.leaves, 7);
		world.setBlockMetadataWithNotify(i + 0, j + 22, k + 19, 7, 2);
		setBlock(world, i + 0, j + 22, k + 20, Blocks.leaves, 7);
		world.setBlockMetadataWithNotify(i + 0, j + 22, k + 20, 7, 2);
		setBlock(world, i + 0, j + 22, k + 21, Blocks.leaves, 7);
		world.setBlockMetadataWithNotify(i + 0, j + 22, k + 21, 7, 2);
		setBlock(world, i + 0, j + 22, k + 22, Blocks.leaves, 7);
		world.setBlockMetadataWithNotify(i + 0, j + 22, k + 22, 7, 2);
		setBlock(world, i + 0, j + 22, k + 27, Blocks.leaves, 7);
		world.setBlockMetadataWithNotify(i + 0, j + 22, k + 27, 7, 2);
		setBlock(world, i + 0, j + 22, k + 28, Blocks.leaves, 7);
		world.setBlockMetadataWithNotify(i + 0, j + 22, k + 28, 7, 2);
		setBlock(world, i + 0, j + 22, k + 29, Blocks.leaves, 7);
		world.setBlockMetadataWithNotify(i + 0, j + 22, k + 29, 7, 2);
		setBlock(world, i + 0, j + 23, k + 19, Blocks.leaves, 7);
		world.setBlockMetadataWithNotify(i + 0, j + 23, k + 19, 7, 2);
		setBlock(world, i + 0, j + 23, k + 20, Blocks.leaves, 7);
		world.setBlockMetadataWithNotify(i + 0, j + 23, k + 20, 7, 2);
		setBlock(world, i + 0, j + 23, k + 21, Blocks.leaves, 7);
		world.setBlockMetadataWithNotify(i + 0, j + 23, k + 21, 7, 2);
		setBlock(world, i + 0, j + 23, k + 28, Blocks.leaves, 7);
		world.setBlockMetadataWithNotify(i + 0, j + 23, k + 28, 7, 2);
		setBlock(world, i + 0, j + 24, k + 20, Blocks.leaves, 7);
		world.setBlockMetadataWithNotify(i + 0, j + 24, k + 20, 7, 2);
		setBlock(world, i + 0, j + 24, k + 29, Blocks.leaves, 7);
		world.setBlockMetadataWithNotify(i + 0, j + 24, k + 29, 7, 2);
		setBlock(world, i + 0, j + 24, k + 30, Blocks.leaves, 7);
		world.setBlockMetadataWithNotify(i + 0, j + 24, k + 30, 7, 2);
		setBlock(world, i + 0, j + 24, k + 31, Blocks.log, 3);
		world.setBlockMetadataWithNotify(i + 0, j + 24, k + 31, 3, 2);
		setBlock(world, i + 0, j + 25, k + 29, Blocks.leaves, 7);
		world.setBlockMetadataWithNotify(i + 0, j + 25, k + 29, 7, 2);
		setBlock(world, i + 0, j + 25, k + 30, Blocks.leaves, 7);
		world.setBlockMetadataWithNotify(i + 0, j + 25, k + 30, 7, 2);
		setBlock(world, i + 0, j + 25, k + 31, Blocks.leaves, 7);
		world.setBlockMetadataWithNotify(i + 0, j + 25, k + 31, 7, 2);
		setBlock(world, i + 0, j + 26, k + 30, Blocks.leaves, 7);
		world.setBlockMetadataWithNotify(i + 0, j + 26, k + 30, 7, 2);
		setBlock(world, i + 0, j + 26, k + 31, Blocks.leaves, 7);
		world.setBlockMetadataWithNotify(i + 0, j + 26, k + 31, 7, 2);
		setBlock(world, i + 0, j + 27, k + 31, Blocks.leaves, 7);
		world.setBlockMetadataWithNotify(i + 0, j + 27, k + 31, 7, 2);
		setBlock(world, i + 0, j + 30, k + 28, Blocks.log, 3);
		world.setBlockMetadataWithNotify(i + 0, j + 30, k + 28, 3, 2);
		setBlock(world, i + 0, j + 30, k + 29, Blocks.log, 3);
		world.setBlockMetadataWithNotify(i + 0, j + 30, k + 29, 3, 2);
		setBlock(world, i + 0, j + 34, k + 26, Blocks.leaves, 7);
		world.setBlockMetadataWithNotify(i + 0, j + 34, k + 26, 7, 2);
		setBlock(world, i + 0, j + 34, k + 27, Blocks.leaves, 7);
		world.setBlockMetadataWithNotify(i + 0, j + 34, k + 27, 7, 2);
		setBlock(world, i + 0, j + 34, k + 28, Blocks.leaves, 7);
		world.setBlockMetadataWithNotify(i + 0, j + 34, k + 28, 7, 2);
		setBlock(world, i + 0, j + 35, k + 27, Blocks.leaves, 7);
		world.setBlockMetadataWithNotify(i + 0, j + 35, k + 27, 7, 2);
		setBlock(world, i + 0, j + 38, k + 1, Blocks.vine, 8);
		world.setBlockMetadataWithNotify(i + 0, j + 38, k + 1, 8, 2);
		setBlock(world, i + 0, j + 39, k + 0, Blocks.vine, 15);
		world.setBlockMetadataWithNotify(i + 0, j + 39, k + 0, 15, 2);
		setBlock(world, i + 0, j + 39, k + 1, Blocks.vine, 15);
		world.setBlockMetadataWithNotify(i + 0, j + 39, k + 1, 15, 2);
		setBlock(world, i + 0, j + 40, k + 0, Blocks.planks, 5);
		world.setBlockMetadataWithNotify(i + 0, j + 40, k + 0, 5, 2);
		setBlock(world, i + 0, j + 40, k + 1, Blocks.planks, 5);
		world.setBlockMetadataWithNotify(i + 0, j + 40, k + 1, 5, 2);
		setBlock(world, i + 0, j + 40, k + 2, Blocks.planks, 5);
		world.setBlockMetadataWithNotify(i + 0, j + 40, k + 2, 5, 2);
		setBlock(world, i + 0, j + 41, k + 0, Blocks.spruce_stairs, 2);
		world.setBlockMetadataWithNotify(i + 0, j + 41, k + 0, 2, 2);
		setBlock(world, i + 0, j + 41, k + 1, Blocks.planks, 5);
		world.setBlockMetadataWithNotify(i + 0, j + 41, k + 1, 5, 2);
		setBlock(world, i + 0, j + 41, k + 2, Blocks.planks, 5);
		world.setBlockMetadataWithNotify(i + 0, j + 41, k + 2, 5, 2);
		setBlock(world, i + 0, j + 41, k + 3, Blocks.planks, 5);
		world.setBlockMetadataWithNotify(i + 0, j + 41, k + 3, 5, 2);
		setBlock(world, i + 0, j + 41, k + 4, Blocks.planks, 5);
		world.setBlockMetadataWithNotify(i + 0, j + 41, k + 4, 5, 2);
		setBlock(world, i + 0, j + 41, k + 5, Blocks.planks, 5);
		world.setBlockMetadataWithNotify(i + 0, j + 41, k + 5, 5, 2);
		setBlock(world, i + 0, j + 42, k + 3, Blocks.spruce_stairs, 2);
		world.setBlockMetadataWithNotify(i + 0, j + 42, k + 3, 2, 2);
		setBlock(world, i + 0, j + 42, k + 4, Blocks.planks, 5);
		world.setBlockMetadataWithNotify(i + 0, j + 42, k + 4, 5, 2);
		setBlock(world, i + 0, j + 42, k + 5, Blocks.planks, 5);
		world.setBlockMetadataWithNotify(i + 0, j + 42, k + 5, 5, 2);
		setBlock(world, i + 0, j + 42, k + 6, Blocks.planks, 5);
		world.setBlockMetadataWithNotify(i + 0, j + 42, k + 6, 5, 2);
		setBlock(world, i + 0, j + 42, k + 7, Blocks.planks, 5);
		world.setBlockMetadataWithNotify(i + 0, j + 42, k + 7, 5, 2);
		setBlock(world, i + 0, j + 43, k + 24, Blocks.log, 1);
		world.setBlockMetadataWithNotify(i + 0, j + 43, k + 24, 1, 2);
		setBlock(world, i + 0, j + 43, k + 25, Blocks.log, 1);
		world.setBlockMetadataWithNotify(i + 0, j + 43, k + 25, 1, 2);
		setBlock(world, i + 0, j + 43, k + 26, Blocks.log, 1);
		world.setBlockMetadataWithNotify(i + 0, j + 43, k + 26, 1, 2);
		setBlock(world, i + 0, j + 43, k + 27, Blocks.log, 1);
		world.setBlockMetadataWithNotify(i + 0, j + 43, k + 27, 1, 2);
		setBlock(world, i + 0, j + 43, k + 28, Blocks.log, 1);
		world.setBlockMetadataWithNotify(i + 0, j + 43, k + 28, 1, 2);
		setBlock(world, i + 0, j + 43, k + 29, Blocks.log, 1);
		world.setBlockMetadataWithNotify(i + 0, j + 43, k + 29, 1, 2);
		setBlock(world, i + 0, j + 43, k + 30, Blocks.planks, 5);
		world.setBlockMetadataWithNotify(i + 0, j + 43, k + 30, 5, 2);
		setBlock(world, i + 0, j + 43, k + 31, Blocks.planks, 5);
		world.setBlockMetadataWithNotify(i + 0, j + 43, k + 31, 5, 2);
		setBlock(world, i + 0, j + 44, k + 27, Blocks.spruce_stairs, 1);
		world.setBlockMetadataWithNotify(i + 0, j + 44, k + 27, 1, 2);
		setBlock(world, i + 0, j + 45, k + 26, Blocks.torch, 5);
		world.setBlockMetadataWithNotify(i + 0, j + 45, k + 26, 5, 2);
		setBlock(world, i + 0, j + 48, k + 20, Blocks.log, 1);
		world.setBlockMetadataWithNotify(i + 0, j + 48, k + 20, 1, 2);
		setBlock(world, i + 0, j + 48, k + 21, Blocks.log, 1);
		world.setBlockMetadataWithNotify(i + 0, j + 48, k + 21, 1, 2);
		setBlock(world, i + 0, j + 48, k + 22, Blocks.log, 1);
		world.setBlockMetadataWithNotify(i + 0, j + 48, k + 22, 1, 2);
		setBlock(world, i + 0, j + 48, k + 23, Blocks.log, 1);
		world.setBlockMetadataWithNotify(i + 0, j + 48, k + 23, 1, 2);
		setBlock(world, i + 0, j + 48, k + 24, Blocks.log, 1);
		world.setBlockMetadataWithNotify(i + 0, j + 48, k + 24, 1, 2);
		setBlock(world, i + 0, j + 48, k + 25, Blocks.log, 1);
		world.setBlockMetadataWithNotify(i + 0, j + 48, k + 25, 1, 2);
		setBlock(world, i + 0, j + 48, k + 26, Blocks.log, 1);
		world.setBlockMetadataWithNotify(i + 0, j + 48, k + 26, 1, 2);
		setBlock(world, i + 0, j + 48, k + 27, Blocks.log, 1);
		world.setBlockMetadataWithNotify(i + 0, j + 48, k + 27, 1, 2);
		setBlock(world, i + 0, j + 48, k + 28, Blocks.log, 1);
		world.setBlockMetadataWithNotify(i + 0, j + 48, k + 28, 1, 2);
		setBlock(world, i + 0, j + 48, k + 29, Blocks.log, 1);
		world.setBlockMetadataWithNotify(i + 0, j + 48, k + 29, 1, 2);
		setBlock(world, i + 0, j + 48, k + 30, Blocks.log, 1);
		world.setBlockMetadataWithNotify(i + 0, j + 48, k + 30, 1, 2);
		setBlock(world, i + 0, j + 48, k + 31, Blocks.log, 1);
		world.setBlockMetadataWithNotify(i + 0, j + 48, k + 31, 1, 2);
		setBlock(world, i + 0, j + 49, k + 21, Blocks.log, 1);
		world.setBlockMetadataWithNotify(i + 0, j + 49, k + 21, 1, 2);
		setBlock(world, i + 0, j + 49, k + 22, Blocks.log, 1);
		world.setBlockMetadataWithNotify(i + 0, j + 49, k + 22, 1, 2);
		setBlock(world, i + 0, j + 49, k + 23, Blocks.log, 1);
		world.setBlockMetadataWithNotify(i + 0, j + 49, k + 23, 1, 2);
		setBlock(world, i + 0, j + 49, k + 24, Blocks.log, 1);
		world.setBlockMetadataWithNotify(i + 0, j + 49, k + 24, 1, 2);
		setBlock(world, i + 0, j + 49, k + 25, Blocks.log, 1);
		world.setBlockMetadataWithNotify(i + 0, j + 49, k + 25, 1, 2);
		setBlock(world, i + 0, j + 49, k + 26, Blocks.log, 1);
		world.setBlockMetadataWithNotify(i + 0, j + 49, k + 26, 1, 2);
		setBlock(world, i + 0, j + 49, k + 27, Blocks.log, 1);
		world.setBlockMetadataWithNotify(i + 0, j + 49, k + 27, 1, 2);
		setBlock(world, i + 0, j + 49, k + 28, Blocks.log, 1);
		world.setBlockMetadataWithNotify(i + 0, j + 49, k + 28, 1, 2);
		setBlock(world, i + 0, j + 49, k + 29, Blocks.log, 1);
		world.setBlockMetadataWithNotify(i + 0, j + 49, k + 29, 1, 2);
		setBlock(world, i + 0, j + 49, k + 30, Blocks.log, 1);
		world.setBlockMetadataWithNotify(i + 0, j + 49, k + 30, 1, 2);
		setBlock(world, i + 0, j + 49, k + 31, Blocks.log, 1);
		world.setBlockMetadataWithNotify(i + 0, j + 49, k + 31, 1, 2);
		setBlock(world, i + 0, j + 50, k + 24, Blocks.log, 1);
		world.setBlockMetadataWithNotify(i + 0, j + 50, k + 24, 1, 2);
		setBlock(world, i + 0, j + 50, k + 25, Blocks.log, 1);
		world.setBlockMetadataWithNotify(i + 0, j + 50, k + 25, 1, 2);
		setBlock(world, i + 0, j + 50, k + 26, Blocks.log, 1);
		world.setBlockMetadataWithNotify(i + 0, j + 50, k + 26, 1, 2);
		setBlock(world, i + 0, j + 50, k + 27, Blocks.log, 1);
		world.setBlockMetadataWithNotify(i + 0, j + 50, k + 27, 1, 2);
		setBlock(world, i + 0, j + 50, k + 28, Blocks.log, 1);
		world.setBlockMetadataWithNotify(i + 0, j + 50, k + 28, 1, 2);
		setBlock(world, i + 0, j + 50, k + 29, Blocks.log, 1);
		world.setBlockMetadataWithNotify(i + 0, j + 50, k + 29, 1, 2);
		setBlock(world, i + 0, j + 50, k + 30, Blocks.log, 1);
		world.setBlockMetadataWithNotify(i + 0, j + 50, k + 30, 1, 2);
		setBlock(world, i + 0, j + 50, k + 31, Blocks.log, 1);
		world.setBlockMetadataWithNotify(i + 0, j + 50, k + 31, 1, 2);
		setBlock(world, i + 1, j + 21, k + 18, Blocks.leaves, 7);
		world.setBlockMetadataWithNotify(i + 1, j + 21, k + 18, 7, 2);
		setBlock(world, i + 1, j + 21, k + 19, Blocks.leaves, 7);
		world.setBlockMetadataWithNotify(i + 1, j + 21, k + 19, 7, 2);
		setBlock(world, i + 1, j + 21, k + 20, Blocks.leaves, 7);
		world.setBlockMetadataWithNotify(i + 1, j + 21, k + 20, 7, 2);
		setBlock(world, i + 1, j + 21, k + 21, Blocks.leaves, 7);
		world.setBlockMetadataWithNotify(i + 1, j + 21, k + 21, 7, 2);
		setBlock(world, i + 1, j + 21, k + 22, Blocks.leaves, 7);
		world.setBlockMetadataWithNotify(i + 1, j + 21, k + 22, 7, 2);
		setBlock(world, i + 1, j + 21, k + 27, Blocks.leaves, 7);
		world.setBlockMetadataWithNotify(i + 1, j + 21, k + 27, 7, 2);
		setBlock(world, i + 1, j + 21, k + 28, Blocks.leaves, 7);
		world.setBlockMetadataWithNotify(i + 1, j + 21, k + 28, 7, 2);
		setBlock(world, i + 1, j + 21, k + 29, Blocks.leaves, 7);
		world.setBlockMetadataWithNotify(i + 1, j + 21, k + 29, 7, 2);
		setBlock(world, i + 1, j + 22, k + 19, Blocks.leaves, 7);
		world.setBlockMetadataWithNotify(i + 1, j + 22, k + 19, 7, 2);
		setBlock(world, i + 1, j + 22, k + 20, Blocks.leaves, 7);
		world.setBlockMetadataWithNotify(i + 1, j + 22, k + 20, 7, 2);
		setBlock(world, i + 1, j + 22, k + 21, Blocks.leaves, 7);
		world.setBlockMetadataWithNotify(i + 1, j + 22, k + 21, 7, 2);
		setBlock(world, i + 1, j + 22, k + 28, Blocks.leaves, 7);
		world.setBlockMetadataWithNotify(i + 1, j + 22, k + 28, 7, 2);
		setBlock(world, i + 1, j + 23, k + 20, Blocks.leaves, 7);
		world.setBlockMetadataWithNotify(i + 1, j + 23, k + 20, 7, 2);
		setBlock(world, i + 1, j + 24, k + 29, Blocks.leaves, 7);
		world.setBlockMetadataWithNotify(i + 1, j + 24, k + 29, 7, 2);
		setBlock(world, i + 1, j + 24, k + 30, Blocks.leaves, 15);
		world.setBlockMetadataWithNotify(i + 1, j + 24, k + 30, 15, 2);
		setBlock(world, i + 1, j + 24, k + 31, Blocks.leaves, 15);
		world.setBlockMetadataWithNotify(i + 1, j + 24, k + 31, 15, 2);
		setBlock(world, i + 1, j + 25, k + 30, Blocks.leaves, 15);
		world.setBlockMetadataWithNotify(i + 1, j + 25, k + 30, 15, 2);
		setBlock(world, i + 1, j + 25, k + 31, Blocks.leaves, 15);
		world.setBlockMetadataWithNotify(i + 1, j + 25, k + 31, 15, 2);
		setBlock(world, i + 1, j + 26, k + 31, Blocks.leaves, 15);
		world.setBlockMetadataWithNotify(i + 1, j + 26, k + 31, 15, 2);
		setBlock(world, i + 1, j + 31, k + 27, Blocks.log, 3);
		world.setBlockMetadataWithNotify(i + 1, j + 31, k + 27, 3, 2);
		setBlock(world, i + 1, j + 31, k + 30, Blocks.log, 1);
		world.setBlockMetadataWithNotify(i + 1, j + 31, k + 30, 1, 2);
		setBlock(world, i + 1, j + 31, k + 31, Blocks.log, 1);
		world.setBlockMetadataWithNotify(i + 1, j + 31, k + 31, 1, 2);
		setBlock(world, i + 1, j + 38, k + 0, Blocks.vine, 14);
		world.setBlockMetadataWithNotify(i + 1, j + 38, k + 0, 14, 2);
		setBlock(world, i + 1, j + 38, k + 1, Blocks.vine, 8);
		world.setBlockMetadataWithNotify(i + 1, j + 38, k + 1, 8, 2);
		setBlock(world, i + 1, j + 39, k + 0, Blocks.vine, 15);
		world.setBlockMetadataWithNotify(i + 1, j + 39, k + 0, 15, 2);
		setBlock(world, i + 1, j + 39, k + 1, Blocks.vine, 15);
		world.setBlockMetadataWithNotify(i + 1, j + 39, k + 1, 15, 2);
		setBlock(world, i + 1, j + 40, k + 0, Blocks.planks, 5);
		world.setBlockMetadataWithNotify(i + 1, j + 40, k + 0, 5, 2);
		setBlock(world, i + 1, j + 40, k + 1, Blocks.planks, 5);
		world.setBlockMetadataWithNotify(i + 1, j + 40, k + 1, 5, 2);
		setBlock(world, i + 1, j + 40, k + 2, Blocks.planks, 5);
		world.setBlockMetadataWithNotify(i + 1, j + 40, k + 2, 5, 2);
		setBlock(world, i + 1, j + 41, k + 0, Blocks.spruce_stairs, 2);
		world.setBlockMetadataWithNotify(i + 1, j + 41, k + 0, 2, 2);
		setBlock(world, i + 1, j + 41, k + 1, Blocks.planks, 5);
		world.setBlockMetadataWithNotify(i + 1, j + 41, k + 1, 5, 2);
		setBlock(world, i + 1, j + 41, k + 2, Blocks.planks, 5);
		world.setBlockMetadataWithNotify(i + 1, j + 41, k + 2, 5, 2);
		setBlock(world, i + 1, j + 41, k + 3, Blocks.planks, 5);
		world.setBlockMetadataWithNotify(i + 1, j + 41, k + 3, 5, 2);
		setBlock(world, i + 1, j + 41, k + 4, Blocks.planks, 5);
		world.setBlockMetadataWithNotify(i + 1, j + 41, k + 4, 5, 2);
		setBlock(world, i + 1, j + 41, k + 5, Blocks.planks, 5);
		world.setBlockMetadataWithNotify(i + 1, j + 41, k + 5, 5, 2);
		setBlock(world, i + 1, j + 42, k + 3, Blocks.spruce_stairs, 2);
		world.setBlockMetadataWithNotify(i + 1, j + 42, k + 3, 2, 2);
		setBlock(world, i + 1, j + 42, k + 4, Blocks.planks, 5);
		world.setBlockMetadataWithNotify(i + 1, j + 42, k + 4, 5, 2);
		setBlock(world, i + 1, j + 42, k + 5, Blocks.planks, 5);
		world.setBlockMetadataWithNotify(i + 1, j + 42, k + 5, 5, 2);
		setBlock(world, i + 1, j + 42, k + 6, Blocks.planks, 5);
		world.setBlockMetadataWithNotify(i + 1, j + 42, k + 6, 5, 2);
		setBlock(world, i + 1, j + 42, k + 7, Blocks.planks, 5);
		world.setBlockMetadataWithNotify(i + 1, j + 42, k + 7, 5, 2);
		setBlock(world, i + 1, j + 42, k + 8, Blocks.planks, 5);
		world.setBlockMetadataWithNotify(i + 1, j + 42, k + 8, 5, 2);
		setBlock(world, i + 1, j + 43, k + 22, Blocks.log, 1);
		world.setBlockMetadataWithNotify(i + 1, j + 43, k + 22, 1, 2);
		setBlock(world, i + 1, j + 43, k + 23, Blocks.log, 1);
		world.setBlockMetadataWithNotify(i + 1, j + 43, k + 23, 1, 2);
		setBlock(world, i + 1, j + 43, k + 24, Blocks.log, 1);
		world.setBlockMetadataWithNotify(i + 1, j + 43, k + 24, 1, 2);
		setBlock(world, i + 1, j + 43, k + 25, Blocks.log, 1);
		world.setBlockMetadataWithNotify(i + 1, j + 43, k + 25, 1, 2);
		setBlock(world, i + 1, j + 43, k + 26, Blocks.log, 1);
		world.setBlockMetadataWithNotify(i + 1, j + 43, k + 26, 1, 2);
		setBlock(world, i + 1, j + 43, k + 27, Blocks.log, 1);
		world.setBlockMetadataWithNotify(i + 1, j + 43, k + 27, 1, 2);
		setBlock(world, i + 1, j + 43, k + 28, Blocks.planks, 5);
		world.setBlockMetadataWithNotify(i + 1, j + 43, k + 28, 5, 2);
		setBlock(world, i + 1, j + 43, k + 29, Blocks.planks, 5);
		world.setBlockMetadataWithNotify(i + 1, j + 43, k + 29, 5, 2);
		setBlock(world, i + 1, j + 43, k + 30, Blocks.planks, 5);
		world.setBlockMetadataWithNotify(i + 1, j + 43, k + 30, 5, 2);
		setBlock(world, i + 1, j + 43, k + 31, Blocks.planks, 5);
		world.setBlockMetadataWithNotify(i + 1, j + 43, k + 31, 5, 2);
		setBlock(world, i + 1, j + 45, k + 22, Blocks.torch, 5);
		world.setBlockMetadataWithNotify(i + 1, j + 45, k + 22, 5, 2);
		setBlock(world, i + 1, j + 48, k + 19, Blocks.log, 1);
		world.setBlockMetadataWithNotify(i + 1, j + 48, k + 19, 1, 2);
		setBlock(world, i + 1, j + 48, k + 20, Blocks.log, 1);
		world.setBlockMetadataWithNotify(i + 1, j + 48, k + 20, 1, 2);
		setBlock(world, i + 1, j + 48, k + 21, Blocks.log, 1);
		world.setBlockMetadataWithNotify(i + 1, j + 48, k + 21, 1, 2);
		setBlock(world, i + 1, j + 48, k + 22, Blocks.log, 1);
		world.setBlockMetadataWithNotify(i + 1, j + 48, k + 22, 1, 2);
		setBlock(world, i + 1, j + 48, k + 23, Blocks.log, 1);
		world.setBlockMetadataWithNotify(i + 1, j + 48, k + 23, 1, 2);
		setBlock(world, i + 1, j + 48, k + 24, Blocks.log, 1);
		world.setBlockMetadataWithNotify(i + 1, j + 48, k + 24, 1, 2);
		setBlock(world, i + 1, j + 48, k + 25, Blocks.log, 1);
		world.setBlockMetadataWithNotify(i + 1, j + 48, k + 25, 1, 2);
		setBlock(world, i + 1, j + 48, k + 26, Blocks.torch, 1);
		world.setBlockMetadataWithNotify(i + 1, j + 48, k + 26, 1, 2);
		setBlock(world, i + 1, j + 49, k + 20, Blocks.log, 1);
		world.setBlockMetadataWithNotify(i + 1, j + 49, k + 20, 1, 2);
		setBlock(world, i + 1, j + 49, k + 21, Blocks.log, 1);
		world.setBlockMetadataWithNotify(i + 1, j + 49, k + 21, 1, 2);
		setBlock(world, i + 1, j + 49, k + 22, Blocks.log, 1);
		world.setBlockMetadataWithNotify(i + 1, j + 49, k + 22, 1, 2);
		setBlock(world, i + 1, j + 49, k + 23, Blocks.log, 1);
		world.setBlockMetadataWithNotify(i + 1, j + 49, k + 23, 1, 2);
		setBlock(world, i + 1, j + 49, k + 24, Blocks.log, 1);
		world.setBlockMetadataWithNotify(i + 1, j + 49, k + 24, 1, 2);
		setBlock(world, i + 1, j + 49, k + 25, Blocks.log, 1);
		world.setBlockMetadataWithNotify(i + 1, j + 49, k + 25, 1, 2);
		setBlock(world, i + 1, j + 49, k + 26, Blocks.log, 1);
		world.setBlockMetadataWithNotify(i + 1, j + 49, k + 26, 1, 2);
		setBlock(world, i + 1, j + 49, k + 27, Blocks.log, 1);
		world.setBlockMetadataWithNotify(i + 1, j + 49, k + 27, 1, 2);
		setBlock(world, i + 1, j + 49, k + 28, Blocks.log, 1);
		world.setBlockMetadataWithNotify(i + 1, j + 49, k + 28, 1, 2);
		setBlock(world, i + 1, j + 49, k + 29, Blocks.log, 1);
		world.setBlockMetadataWithNotify(i + 1, j + 49, k + 29, 1, 2);
		setBlock(world, i + 1, j + 49, k + 30, Blocks.log, 1);
		world.setBlockMetadataWithNotify(i + 1, j + 49, k + 30, 1, 2);
		setBlock(world, i + 1, j + 49, k + 31, Blocks.log, 1);
		world.setBlockMetadataWithNotify(i + 1, j + 49, k + 31, 1, 2);
		setBlock(world, i + 1, j + 50, k + 23, Blocks.log, 1);
		world.setBlockMetadataWithNotify(i + 1, j + 50, k + 23, 1, 2);
		setBlock(world, i + 1, j + 50, k + 24, Blocks.log, 1);
		world.setBlockMetadataWithNotify(i + 1, j + 50, k + 24, 1, 2);
		setBlock(world, i + 1, j + 50, k + 25, Blocks.log, 1);
		world.setBlockMetadataWithNotify(i + 1, j + 50, k + 25, 1, 2);
		setBlock(world, i + 1, j + 50, k + 26, Blocks.log, 1);
		world.setBlockMetadataWithNotify(i + 1, j + 50, k + 26, 1, 2);
		setBlock(world, i + 1, j + 50, k + 27, Blocks.log, 1);
		world.setBlockMetadataWithNotify(i + 1, j + 50, k + 27, 1, 2);
		setBlock(world, i + 1, j + 50, k + 28, Blocks.log, 1);
		world.setBlockMetadataWithNotify(i + 1, j + 50, k + 28, 1, 2);
		setBlock(world, i + 1, j + 50, k + 29, Blocks.log, 1);
		world.setBlockMetadataWithNotify(i + 1, j + 50, k + 29, 1, 2);
		setBlock(world, i + 1, j + 50, k + 30, Blocks.log, 1);
		world.setBlockMetadataWithNotify(i + 1, j + 50, k + 30, 1, 2);
		setBlock(world, i + 1, j + 50, k + 31, Blocks.log, 1);
		world.setBlockMetadataWithNotify(i + 1, j + 50, k + 31, 1, 2);
		setBlock(world, i + 2, j + 21, k + 19, Blocks.leaves, 7);
		world.setBlockMetadataWithNotify(i + 2, j + 21, k + 19, 7, 2);
		setBlock(world, i + 2, j + 21, k + 20, Blocks.leaves, 7);
		world.setBlockMetadataWithNotify(i + 2, j + 21, k + 20, 7, 2);
		setBlock(world, i + 2, j + 21, k + 21, Blocks.leaves, 7);
		world.setBlockMetadataWithNotify(i + 2, j + 21, k + 21, 7, 2);
		setBlock(world, i + 2, j + 22, k + 20, Blocks.leaves, 7);
		world.setBlockMetadataWithNotify(i + 2, j + 22, k + 20, 7, 2);
		setBlock(world, i + 2, j + 24, k + 30, Blocks.leaves, 15);
		world.setBlockMetadataWithNotify(i + 2, j + 24, k + 30, 15, 2);
		setBlock(world, i + 2, j + 24, k + 31, Blocks.log, 3);
		world.setBlockMetadataWithNotify(i + 2, j + 24, k + 31, 3, 2);
		setBlock(world, i + 2, j + 25, k + 31, Blocks.leaves, 15);
		world.setBlockMetadataWithNotify(i + 2, j + 25, k + 31, 15, 2);
		setBlock(world, i + 2, j + 31, k + 25, Blocks.log, 3);
		world.setBlockMetadataWithNotify(i + 2, j + 31, k + 25, 3, 2);
		setBlock(world, i + 2, j + 31, k + 26, Blocks.log, 3);
		world.setBlockMetadataWithNotify(i + 2, j + 31, k + 26, 3, 2);
		setBlock(world, i + 2, j + 31, k + 29, Blocks.log, 1);
		world.setBlockMetadataWithNotify(i + 2, j + 31, k + 29, 1, 2);
		setBlock(world, i + 2, j + 31, k + 30, Blocks.log, 1);
		world.setBlockMetadataWithNotify(i + 2, j + 31, k + 30, 1, 2);
		setBlock(world, i + 2, j + 31, k + 31, Blocks.log, 1);
		world.setBlockMetadataWithNotify(i + 2, j + 31, k + 31, 1, 2);
		setBlock(world, i + 2, j + 32, k + 22, Blocks.leaves, 7);
		world.setBlockMetadataWithNotify(i + 2, j + 32, k + 22, 7, 2);
		setBlock(world, i + 2, j + 32, k + 23, Blocks.leaves, 7);
		world.setBlockMetadataWithNotify(i + 2, j + 32, k + 23, 7, 2);
		setBlock(world, i + 2, j + 32, k + 24, Blocks.leaves, 7);
		world.setBlockMetadataWithNotify(i + 2, j + 32, k + 24, 7, 2);
		setBlock(world, i + 2, j + 32, k + 31, Blocks.log, 1);
		world.setBlockMetadataWithNotify(i + 2, j + 32, k + 31, 1, 2);
		setBlock(world, i + 2, j + 33, k + 23, Blocks.leaves, 7);
		world.setBlockMetadataWithNotify(i + 2, j + 33, k + 23, 7, 2);
		setBlock(world, i + 2, j + 33, k + 31, Blocks.log, 1);
		world.setBlockMetadataWithNotify(i + 2, j + 33, k + 31, 1, 2);
		setBlock(world, i + 2, j + 38, k + 31, Blocks.leaves, 7);
		world.setBlockMetadataWithNotify(i + 2, j + 38, k + 31, 7, 2);
		setBlock(world, i + 2, j + 40, k + 0, Blocks.planks, 5);
		world.setBlockMetadataWithNotify(i + 2, j + 40, k + 0, 5, 2);
		setBlock(world, i + 2, j + 40, k + 1, Blocks.planks, 5);
		world.setBlockMetadataWithNotify(i + 2, j + 40, k + 1, 5, 2);
		setBlock(world, i + 2, j + 40, k + 2, Blocks.planks, 5);
		world.setBlockMetadataWithNotify(i + 2, j + 40, k + 2, 5, 2);
		setBlock(world, i + 2, j + 41, k + 0, Blocks.spruce_stairs, 2);
		world.setBlockMetadataWithNotify(i + 2, j + 41, k + 0, 2, 2);
		setBlock(world, i + 2, j + 41, k + 1, Blocks.planks, 5);
		world.setBlockMetadataWithNotify(i + 2, j + 41, k + 1, 5, 2);
		setBlock(world, i + 2, j + 41, k + 2, Blocks.planks, 5);
		world.setBlockMetadataWithNotify(i + 2, j + 41, k + 2, 5, 2);
		setBlock(world, i + 2, j + 41, k + 3, Blocks.planks, 5);
		world.setBlockMetadataWithNotify(i + 2, j + 41, k + 3, 5, 2);
		setBlock(world, i + 2, j + 41, k + 4, Blocks.planks, 5);
		world.setBlockMetadataWithNotify(i + 2, j + 41, k + 4, 5, 2);
		setBlock(world, i + 2, j + 41, k + 5, Blocks.planks, 5);
		world.setBlockMetadataWithNotify(i + 2, j + 41, k + 5, 5, 2);
		setBlock(world, i + 2, j + 42, k + 3, Blocks.spruce_stairs, 2);
		world.setBlockMetadataWithNotify(i + 2, j + 42, k + 3, 2, 2);
		setBlock(world, i + 2, j + 42, k + 4, Blocks.planks, 5);
		world.setBlockMetadataWithNotify(i + 2, j + 42, k + 4, 5, 2);
		setBlock(world, i + 2, j + 42, k + 5, Blocks.planks, 5);
		world.setBlockMetadataWithNotify(i + 2, j + 42, k + 5, 5, 2);
		setBlock(world, i + 2, j + 42, k + 6, Blocks.planks, 5);
		world.setBlockMetadataWithNotify(i + 2, j + 42, k + 6, 5, 2);
		setBlock(world, i + 2, j + 42, k + 7, Blocks.planks, 5);
		world.setBlockMetadataWithNotify(i + 2, j + 42, k + 7, 5, 2);
		setBlock(world, i + 2, j + 42, k + 8, Blocks.planks, 5);
		world.setBlockMetadataWithNotify(i + 2, j + 42, k + 8, 5, 2);
		setBlock(world, i + 2, j + 42, k + 9, Blocks.planks, 5);
		world.setBlockMetadataWithNotify(i + 2, j + 42, k + 9, 5, 2);
		setBlock(world, i + 2, j + 42, k + 26, Blocks.log, 1);
		world.setBlockMetadataWithNotify(i + 2, j + 42, k + 26, 1, 2);
		setBlock(world, i + 2, j + 43, k + 9, Blocks.torch, 5);
		world.setBlockMetadataWithNotify(i + 2, j + 43, k + 9, 5, 2);
		setBlock(world, i + 2, j + 43, k + 21, Blocks.log, 1);
		world.setBlockMetadataWithNotify(i + 2, j + 43, k + 21, 1, 2);
		setBlock(world, i + 2, j + 43, k + 22, Blocks.log, 1);
		world.setBlockMetadataWithNotify(i + 2, j + 43, k + 22, 1, 2);
		setBlock(world, i + 2, j + 43, k + 23, Blocks.log, 1);
		world.setBlockMetadataWithNotify(i + 2, j + 43, k + 23, 1, 2);
		setBlock(world, i + 2, j + 43, k + 24, Blocks.log, 1);
		world.setBlockMetadataWithNotify(i + 2, j + 43, k + 24, 1, 2);
		setBlock(world, i + 2, j + 43, k + 25, Blocks.log, 1);
		world.setBlockMetadataWithNotify(i + 2, j + 43, k + 25, 1, 2);
		setBlock(world, i + 2, j + 43, k + 26, Blocks.log, 1);
		world.setBlockMetadataWithNotify(i + 2, j + 43, k + 26, 1, 2);
		setBlock(world, i + 2, j + 43, k + 27, Blocks.planks, 5);
		world.setBlockMetadataWithNotify(i + 2, j + 43, k + 27, 5, 2);
		setBlock(world, i + 2, j + 43, k + 28, Blocks.log, 1);
		world.setBlockMetadataWithNotify(i + 2, j + 43, k + 28, 1, 2);
		setBlock(world, i + 2, j + 43, k + 29, Blocks.log, 1);
		world.setBlockMetadataWithNotify(i + 2, j + 43, k + 29, 1, 2);
		setBlock(world, i + 2, j + 43, k + 30, Blocks.planks, 5);
		world.setBlockMetadataWithNotify(i + 2, j + 43, k + 30, 5, 2);
		setBlock(world, i + 2, j + 43, k + 31, Blocks.planks, 5);
		world.setBlockMetadataWithNotify(i + 2, j + 43, k + 31, 5, 2);
		setBlock(world, i + 2, j + 44, k + 20, Blocks.spruce_stairs, 6);
		world.setBlockMetadataWithNotify(i + 2, j + 44, k + 20, 6, 2);
		setBlock(world, i + 2, j + 44, k + 21, Blocks.log, 1);
		world.setBlockMetadataWithNotify(i + 2, j + 44, k + 21, 1, 2);
		setBlock(world, i + 2, j + 44, k + 22, Blocks.spruce_stairs, 3);
		world.setBlockMetadataWithNotify(i + 2, j + 44, k + 22, 3, 2);
		setBlock(world, i + 2, j + 45, k + 19, Blocks.spruce_stairs, 6);
		world.setBlockMetadataWithNotify(i + 2, j + 45, k + 19, 6, 2);
		setBlock(world, i + 2, j + 45, k + 20, Blocks.log, 1);
		world.setBlockMetadataWithNotify(i + 2, j + 45, k + 20, 1, 2);
		setBlock(world, i + 2, j + 45, k + 21, Blocks.log, 1);
		world.setBlockMetadataWithNotify(i + 2, j + 45, k + 21, 1, 2);
		setBlock(world, i + 2, j + 46, k + 19, Blocks.log, 1);
		world.setBlockMetadataWithNotify(i + 2, j + 46, k + 19, 1, 2);
		setBlock(world, i + 2, j + 46, k + 20, Blocks.log, 1);
		world.setBlockMetadataWithNotify(i + 2, j + 46, k + 20, 1, 2);
		setBlock(world, i + 2, j + 47, k + 19, Blocks.log, 1);
		world.setBlockMetadataWithNotify(i + 2, j + 47, k + 19, 1, 2);
		setBlock(world, i + 2, j + 48, k + 18, Blocks.log, 1);
		world.setBlockMetadataWithNotify(i + 2, j + 48, k + 18, 1, 2);
		setBlock(world, i + 2, j + 48, k + 19, Blocks.log, 1);
		world.setBlockMetadataWithNotify(i + 2, j + 48, k + 19, 1, 2);
		setBlock(world, i + 2, j + 48, k + 20, Blocks.log, 1);
		world.setBlockMetadataWithNotify(i + 2, j + 48, k + 20, 1, 2);
		setBlock(world, i + 2, j + 48, k + 21, Blocks.log, 1);
		world.setBlockMetadataWithNotify(i + 2, j + 48, k + 21, 1, 2);
		setBlock(world, i + 2, j + 48, k + 22, Blocks.log, 1);
		world.setBlockMetadataWithNotify(i + 2, j + 48, k + 22, 1, 2);
		setBlock(world, i + 2, j + 48, k + 23, Blocks.log, 1);
		world.setBlockMetadataWithNotify(i + 2, j + 48, k + 23, 1, 2);
		setBlock(world, i + 2, j + 48, k + 24, Blocks.log, 1);
		world.setBlockMetadataWithNotify(i + 2, j + 48, k + 24, 1, 2);
		setBlock(world, i + 2, j + 49, k + 19, Blocks.log, 1);
		world.setBlockMetadataWithNotify(i + 2, j + 49, k + 19, 1, 2);
		setBlock(world, i + 2, j + 49, k + 20, Blocks.log, 1);
		world.setBlockMetadataWithNotify(i + 2, j + 49, k + 20, 1, 2);
		setBlock(world, i + 2, j + 49, k + 21, Blocks.log, 1);
		world.setBlockMetadataWithNotify(i + 2, j + 49, k + 21, 1, 2);
		setBlock(world, i + 2, j + 49, k + 22, Blocks.log, 1);
		world.setBlockMetadataWithNotify(i + 2, j + 49, k + 22, 1, 2);
		setBlock(world, i + 2, j + 49, k + 23, Blocks.log, 1);
		world.setBlockMetadataWithNotify(i + 2, j + 49, k + 23, 1, 2);
		setBlock(world, i + 2, j + 49, k + 24, Blocks.log, 1);
		world.setBlockMetadataWithNotify(i + 2, j + 49, k + 24, 1, 2);
		setBlock(world, i + 2, j + 49, k + 25, Blocks.log, 1);
		world.setBlockMetadataWithNotify(i + 2, j + 49, k + 25, 1, 2);
		setBlock(world, i + 2, j + 50, k + 22, Blocks.log, 1);
		world.setBlockMetadataWithNotify(i + 2, j + 50, k + 22, 1, 2);
		setBlock(world, i + 2, j + 50, k + 23, Blocks.log, 1);
		world.setBlockMetadataWithNotify(i + 2, j + 50, k + 23, 1, 2);
		setBlock(world, i + 2, j + 50, k + 24, Blocks.log, 1);
		world.setBlockMetadataWithNotify(i + 2, j + 50, k + 24, 1, 2);
		setBlock(world, i + 2, j + 50, k + 25, Blocks.log, 1);
		world.setBlockMetadataWithNotify(i + 2, j + 50, k + 25, 1, 2);
		setBlock(world, i + 2, j + 50, k + 26, Blocks.log, 1);
		world.setBlockMetadataWithNotify(i + 2, j + 50, k + 26, 1, 2);
		setBlock(world, i + 2, j + 50, k + 27, Blocks.log, 1);
		world.setBlockMetadataWithNotify(i + 2, j + 50, k + 27, 1, 2);
		setBlock(world, i + 2, j + 50, k + 28, Blocks.log, 1);
		world.setBlockMetadataWithNotify(i + 2, j + 50, k + 28, 1, 2);
		setBlock(world, i + 2, j + 50, k + 29, Blocks.log, 1);
		world.setBlockMetadataWithNotify(i + 2, j + 50, k + 29, 1, 2);
		setBlock(world, i + 2, j + 50, k + 30, Blocks.log, 1);
		world.setBlockMetadataWithNotify(i + 2, j + 50, k + 30, 1, 2);
		setBlock(world, i + 2, j + 50, k + 31, Blocks.log, 1);
		world.setBlockMetadataWithNotify(i + 2, j + 50, k + 31, 1, 2);
		setBlock(world, i + 2, j + 51, k + 27, Blocks.log, 1);
		world.setBlockMetadataWithNotify(i + 2, j + 51, k + 27, 1, 2);
		setBlock(world, i + 2, j + 51, k + 28, Blocks.log, 1);
		/*      */
		generate9(world, rand, i, j, k);
		return true;
		/*      */}

	/*      */
	/*      */public boolean generate9(World world, Random rand, int i, int j, int k)
	/*      */
	{
		world.setBlockMetadataWithNotify(i + 2, j + 51, k + 28, 1, 2);
		setBlock(world, i + 2, j + 51, k + 29, Blocks.log, 1);
		world.setBlockMetadataWithNotify(i + 2, j + 51, k + 29, 1, 2);
		setBlock(world, i + 2, j + 51, k + 30, Blocks.log, 1);
		world.setBlockMetadataWithNotify(i + 2, j + 51, k + 30, 1, 2);
		setBlock(world, i + 2, j + 51, k + 31, Blocks.log, 1);
		world.setBlockMetadataWithNotify(i + 2, j + 51, k + 31, 1, 2);
		setBlock(world, i + 3, j + 25, k + 30, Blocks.log, 3);
		world.setBlockMetadataWithNotify(i + 3, j + 25, k + 30, 3, 2);
		setBlock(world, i + 3, j + 26, k + 27, Blocks.leaves, 7);
		world.setBlockMetadataWithNotify(i + 3, j + 26, k + 27, 7, 2);
		setBlock(world, i + 3, j + 26, k + 28, Blocks.leaves, 7);
		world.setBlockMetadataWithNotify(i + 3, j + 26, k + 28, 7, 2);
		setBlock(world, i + 3, j + 26, k + 29, Blocks.leaves, 7);
		world.setBlockMetadataWithNotify(i + 3, j + 26, k + 29, 7, 2);
		setBlock(world, i + 3, j + 27, k + 28, Blocks.leaves, 7);
		world.setBlockMetadataWithNotify(i + 3, j + 27, k + 28, 7, 2);
		setBlock(world, i + 3, j + 31, k + 24, Blocks.log, 3);
		world.setBlockMetadataWithNotify(i + 3, j + 31, k + 24, 3, 2);
		setBlock(world, i + 3, j + 31, k + 28, Blocks.log, 1);
		world.setBlockMetadataWithNotify(i + 3, j + 31, k + 28, 1, 2);
		setBlock(world, i + 3, j + 31, k + 29, Blocks.log, 1);
		world.setBlockMetadataWithNotify(i + 3, j + 31, k + 29, 1, 2);
		setBlock(world, i + 3, j + 31, k + 30, Blocks.log, 1);
		world.setBlockMetadataWithNotify(i + 3, j + 31, k + 30, 1, 2);
		setBlock(world, i + 3, j + 31, k + 31, Blocks.log, 1);
		world.setBlockMetadataWithNotify(i + 3, j + 31, k + 31, 1, 2);
		setBlock(world, i + 3, j + 32, k + 11, Blocks.vine, 3);
		world.setBlockMetadataWithNotify(i + 3, j + 32, k + 11, 3, 2);
		setBlock(world, i + 3, j + 32, k + 21, Blocks.leaves, 7);
		world.setBlockMetadataWithNotify(i + 3, j + 32, k + 21, 7, 2);
		setBlock(world, i + 3, j + 32, k + 22, Blocks.leaves, 7);
		world.setBlockMetadataWithNotify(i + 3, j + 32, k + 22, 7, 2);
		setBlock(world, i + 3, j + 32, k + 23, Blocks.leaves, 7);
		world.setBlockMetadataWithNotify(i + 3, j + 32, k + 23, 7, 2);
		setBlock(world, i + 3, j + 32, k + 24, Blocks.leaves, 7);
		world.setBlockMetadataWithNotify(i + 3, j + 32, k + 24, 7, 2);
		setBlock(world, i + 3, j + 32, k + 25, Blocks.leaves, 7);
		world.setBlockMetadataWithNotify(i + 3, j + 32, k + 25, 7, 2);
		setBlock(world, i + 3, j + 32, k + 29, Blocks.log, 1);
		world.setBlockMetadataWithNotify(i + 3, j + 32, k + 29, 1, 2);
		setBlock(world, i + 3, j + 32, k + 30, Blocks.log, 1);
		world.setBlockMetadataWithNotify(i + 3, j + 32, k + 30, 1, 2);
		setBlock(world, i + 3, j + 32, k + 31, Blocks.log, 1);
		world.setBlockMetadataWithNotify(i + 3, j + 32, k + 31, 1, 2);
		setBlock(world, i + 3, j + 33, k + 11, Blocks.vine, 3);
		world.setBlockMetadataWithNotify(i + 3, j + 33, k + 11, 3, 2);
		setBlock(world, i + 3, j + 33, k + 22, Blocks.leaves, 7);
		world.setBlockMetadataWithNotify(i + 3, j + 33, k + 22, 7, 2);
		setBlock(world, i + 3, j + 33, k + 23, Blocks.leaves, 7);
		world.setBlockMetadataWithNotify(i + 3, j + 33, k + 23, 7, 2);
		setBlock(world, i + 3, j + 33, k + 24, Blocks.leaves, 7);
		world.setBlockMetadataWithNotify(i + 3, j + 33, k + 24, 7, 2);
		setBlock(world, i + 3, j + 33, k + 30, Blocks.log, 1);
		world.setBlockMetadataWithNotify(i + 3, j + 33, k + 30, 1, 2);
		setBlock(world, i + 3, j + 33, k + 31, Blocks.log, 1);
		world.setBlockMetadataWithNotify(i + 3, j + 33, k + 31, 1, 2);
		setBlock(world, i + 3, j + 34, k + 11, Blocks.vine, 15);
		world.setBlockMetadataWithNotify(i + 3, j + 34, k + 11, 15, 2);
		setBlock(world, i + 3, j + 34, k + 12, Blocks.vine, 15);
		world.setBlockMetadataWithNotify(i + 3, j + 34, k + 12, 15, 2);
		setBlock(world, i + 3, j + 34, k + 23, Blocks.leaves, 7);
		world.setBlockMetadataWithNotify(i + 3, j + 34, k + 23, 7, 2);
		setBlock(world, i + 3, j + 34, k + 31, Blocks.log, 1);
		world.setBlockMetadataWithNotify(i + 3, j + 34, k + 31, 1, 2);
		setBlock(world, i + 3, j + 35, k + 11, Blocks.vine, 15);
		world.setBlockMetadataWithNotify(i + 3, j + 35, k + 11, 15, 2);
		setBlock(world, i + 3, j + 35, k + 12, Blocks.vine, 15);
		world.setBlockMetadataWithNotify(i + 3, j + 35, k + 12, 15, 2);
		setBlock(world, i + 3, j + 36, k + 11, Blocks.vine, 15);
		world.setBlockMetadataWithNotify(i + 3, j + 36, k + 11, 15, 2);
		setBlock(world, i + 3, j + 36, k + 12, Blocks.vine, 15);
		world.setBlockMetadataWithNotify(i + 3, j + 36, k + 12, 15, 2);
		setBlock(world, i + 3, j + 37, k + 11, Blocks.vine, 15);
		world.setBlockMetadataWithNotify(i + 3, j + 37, k + 11, 15, 2);
		setBlock(world, i + 3, j + 37, k + 12, Blocks.vine, 15);
		world.setBlockMetadataWithNotify(i + 3, j + 37, k + 12, 15, 2);
		setBlock(world, i + 3, j + 38, k + 11, Blocks.vine, 15);
		world.setBlockMetadataWithNotify(i + 3, j + 38, k + 11, 15, 2);
		setBlock(world, i + 3, j + 38, k + 12, Blocks.vine, 15);
		world.setBlockMetadataWithNotify(i + 3, j + 38, k + 12, 15, 2);
		setBlock(world, i + 3, j + 38, k + 30, Blocks.leaves, 7);
		world.setBlockMetadataWithNotify(i + 3, j + 38, k + 30, 7, 2);
		setBlock(world, i + 3, j + 38, k + 31, Blocks.leaves, 7);
		world.setBlockMetadataWithNotify(i + 3, j + 38, k + 31, 7, 2);
		setBlock(world, i + 3, j + 39, k + 11, Blocks.vine, 15);
		world.setBlockMetadataWithNotify(i + 3, j + 39, k + 11, 15, 2);
		setBlock(world, i + 3, j + 39, k + 12, Blocks.vine, 15);
		world.setBlockMetadataWithNotify(i + 3, j + 39, k + 12, 15, 2);
		setBlock(world, i + 3, j + 39, k + 31, Blocks.leaves, 15);
		world.setBlockMetadataWithNotify(i + 3, j + 39, k + 31, 15, 2);
		setBlock(world, i + 3, j + 40, k + 0, Blocks.planks, 5);
		world.setBlockMetadataWithNotify(i + 3, j + 40, k + 0, 5, 2);
		setBlock(world, i + 3, j + 40, k + 1, Blocks.planks, 5);
		world.setBlockMetadataWithNotify(i + 3, j + 40, k + 1, 5, 2);
		setBlock(world, i + 3, j + 40, k + 2, Blocks.planks, 5);
		world.setBlockMetadataWithNotify(i + 3, j + 40, k + 2, 5, 2);
		setBlock(world, i + 3, j + 40, k + 11, Blocks.vine, 15);
		world.setBlockMetadataWithNotify(i + 3, j + 40, k + 11, 15, 2);
		setBlock(world, i + 3, j + 40, k + 12, Blocks.vine, 15);
		world.setBlockMetadataWithNotify(i + 3, j + 40, k + 12, 15, 2);
		setBlock(world, i + 3, j + 41, k + 0, Blocks.spruce_stairs, 2);
		world.setBlockMetadataWithNotify(i + 3, j + 41, k + 0, 2, 2);
		setBlock(world, i + 3, j + 41, k + 1, Blocks.planks, 5);
		world.setBlockMetadataWithNotify(i + 3, j + 41, k + 1, 5, 2);
		setBlock(world, i + 3, j + 41, k + 2, Blocks.planks, 5);
		world.setBlockMetadataWithNotify(i + 3, j + 41, k + 2, 5, 2);
		setBlock(world, i + 3, j + 41, k + 3, Blocks.planks, 5);
		world.setBlockMetadataWithNotify(i + 3, j + 41, k + 3, 5, 2);
		setBlock(world, i + 3, j + 41, k + 4, Blocks.planks, 5);
		world.setBlockMetadataWithNotify(i + 3, j + 41, k + 4, 5, 2);
		setBlock(world, i + 3, j + 41, k + 5, Blocks.planks, 5);
		world.setBlockMetadataWithNotify(i + 3, j + 41, k + 5, 5, 2);
		setBlock(world, i + 3, j + 41, k + 11, Blocks.vine, 15);
		world.setBlockMetadataWithNotify(i + 3, j + 41, k + 11, 15, 2);
		setBlock(world, i + 3, j + 41, k + 12, Blocks.vine, 15);
		world.setBlockMetadataWithNotify(i + 3, j + 41, k + 12, 15, 2);
		setBlock(world, i + 3, j + 41, k + 30, Blocks.leaves, 15);
		world.setBlockMetadataWithNotify(i + 3, j + 41, k + 30, 15, 2);
		setBlock(world, i + 3, j + 41, k + 31, Blocks.leaves, 15);
		world.setBlockMetadataWithNotify(i + 3, j + 41, k + 31, 15, 2);
		setBlock(world, i + 3, j + 42, k + 1, Blocks.torch, 5);
		world.setBlockMetadataWithNotify(i + 3, j + 42, k + 1, 5, 2);
		setBlock(world, i + 3, j + 42, k + 3, Blocks.spruce_stairs, 2);
		world.setBlockMetadataWithNotify(i + 3, j + 42, k + 3, 2, 2);
		setBlock(world, i + 3, j + 42, k + 4, Blocks.planks, 5);
		world.setBlockMetadataWithNotify(i + 3, j + 42, k + 4, 5, 2);
		setBlock(world, i + 3, j + 42, k + 5, Blocks.planks, 5);
		world.setBlockMetadataWithNotify(i + 3, j + 42, k + 5, 5, 2);
		setBlock(world, i + 3, j + 42, k + 6, Blocks.planks, 5);
		world.setBlockMetadataWithNotify(i + 3, j + 42, k + 6, 5, 2);
		setBlock(world, i + 3, j + 42, k + 7, Blocks.planks, 5);
		world.setBlockMetadataWithNotify(i + 3, j + 42, k + 7, 5, 2);
		setBlock(world, i + 3, j + 42, k + 8, Blocks.planks, 5);
		world.setBlockMetadataWithNotify(i + 3, j + 42, k + 8, 5, 2);
		setBlock(world, i + 3, j + 42, k + 9, Blocks.planks, 5);
		world.setBlockMetadataWithNotify(i + 3, j + 42, k + 9, 5, 2);
		setBlock(world, i + 3, j + 42, k + 10, Blocks.planks, 5);
		world.setBlockMetadataWithNotify(i + 3, j + 42, k + 10, 5, 2);
		setBlock(world, i + 3, j + 42, k + 11, Blocks.planks, 5);
		world.setBlockMetadataWithNotify(i + 3, j + 42, k + 11, 5, 2);
		setBlock(world, i + 3, j + 42, k + 12, Blocks.planks, 5);
		world.setBlockMetadataWithNotify(i + 3, j + 42, k + 12, 5, 2);
		setBlock(world, i + 3, j + 42, k + 13, Blocks.planks, 5);
		world.setBlockMetadataWithNotify(i + 3, j + 42, k + 13, 5, 2);
		setBlock(world, i + 3, j + 42, k + 14, Blocks.planks, 5);
		world.setBlockMetadataWithNotify(i + 3, j + 42, k + 14, 5, 2);
		setBlock(world, i + 3, j + 42, k + 15, Blocks.planks, 5);
		world.setBlockMetadataWithNotify(i + 3, j + 42, k + 15, 5, 2);
		setBlock(world, i + 3, j + 42, k + 16, Blocks.planks, 5);
		world.setBlockMetadataWithNotify(i + 3, j + 42, k + 16, 5, 2);
		setBlock(world, i + 3, j + 42, k + 25, Blocks.log, 1);
		world.setBlockMetadataWithNotify(i + 3, j + 42, k + 25, 1, 2);
		setBlock(world, i + 3, j + 42, k + 26, Blocks.log, 1);
		world.setBlockMetadataWithNotify(i + 3, j + 42, k + 26, 1, 2);
		setBlock(world, i + 3, j + 42, k + 27, Blocks.log, 1);
		world.setBlockMetadataWithNotify(i + 3, j + 42, k + 27, 1, 2);
		setBlock(world, i + 3, j + 42, k + 31, Blocks.leaves, 15);
		world.setBlockMetadataWithNotify(i + 3, j + 42, k + 31, 15, 2);
		setBlock(world, i + 3, j + 43, k + 5, Blocks.torch, 5);
		world.setBlockMetadataWithNotify(i + 3, j + 43, k + 5, 5, 2);
		setBlock(world, i + 3, j + 43, k + 15, Blocks.spruce_stairs, 2);
		world.setBlockMetadataWithNotify(i + 3, j + 43, k + 15, 2, 2);
		setBlock(world, i + 3, j + 43, k + 16, Blocks.planks, 5);
		world.setBlockMetadataWithNotify(i + 3, j + 43, k + 16, 5, 2);
		setBlock(world, i + 3, j + 43, k + 17, Blocks.planks, 5);
		world.setBlockMetadataWithNotify(i + 3, j + 43, k + 17, 5, 2);
		setBlock(world, i + 3, j + 43, k + 18, Blocks.planks, 5);
		world.setBlockMetadataWithNotify(i + 3, j + 43, k + 18, 5, 2);
		setBlock(world, i + 3, j + 43, k + 19, Blocks.planks, 5);
		world.setBlockMetadataWithNotify(i + 3, j + 43, k + 19, 5, 2);
		setBlock(world, i + 3, j + 43, k + 20, Blocks.log, 1);
		world.setBlockMetadataWithNotify(i + 3, j + 43, k + 20, 1, 2);
		setBlock(world, i + 3, j + 43, k + 21, Blocks.log, 1);
		world.setBlockMetadataWithNotify(i + 3, j + 43, k + 21, 1, 2);
		setBlock(world, i + 3, j + 43, k + 22, Blocks.log, 1);
		world.setBlockMetadataWithNotify(i + 3, j + 43, k + 22, 1, 2);
		setBlock(world, i + 3, j + 43, k + 23, Blocks.log, 1);
		world.setBlockMetadataWithNotify(i + 3, j + 43, k + 23, 1, 2);
		setBlock(world, i + 3, j + 43, k + 24, Blocks.log, 1);
		world.setBlockMetadataWithNotify(i + 3, j + 43, k + 24, 1, 2);
		setBlock(world, i + 3, j + 43, k + 25, Blocks.log, 1);
		world.setBlockMetadataWithNotify(i + 3, j + 43, k + 25, 1, 2);
		setBlock(world, i + 3, j + 43, k + 26, Blocks.log, 1);
		world.setBlockMetadataWithNotify(i + 3, j + 43, k + 26, 1, 2);
		setBlock(world, i + 3, j + 43, k + 27, Blocks.log, 1);
		world.setBlockMetadataWithNotify(i + 3, j + 43, k + 27, 1, 2);
		setBlock(world, i + 3, j + 43, k + 28, Blocks.log, 1);
		world.setBlockMetadataWithNotify(i + 3, j + 43, k + 28, 1, 2);
		setBlock(world, i + 3, j + 43, k + 29, Blocks.planks, 5);
		world.setBlockMetadataWithNotify(i + 3, j + 43, k + 29, 5, 2);
		setBlock(world, i + 3, j + 43, k + 30, Blocks.planks, 5);
		world.setBlockMetadataWithNotify(i + 3, j + 43, k + 30, 5, 2);
		setBlock(world, i + 3, j + 43, k + 31, Blocks.planks, 5);
		world.setBlockMetadataWithNotify(i + 3, j + 43, k + 31, 5, 2);
		setBlock(world, i + 3, j + 44, k + 17, Blocks.torch, 5);
		world.setBlockMetadataWithNotify(i + 3, j + 44, k + 17, 5, 2);
		setBlock(world, i + 3, j + 44, k + 21, Blocks.spruce_stairs, 1);
		world.setBlockMetadataWithNotify(i + 3, j + 44, k + 21, 1, 2);
		setBlock(world, i + 3, j + 46, k + 20, Blocks.torch, 1);
		world.setBlockMetadataWithNotify(i + 3, j + 46, k + 20, 1, 2);
		setBlock(world, i + 3, j + 47, k + 19, Blocks.spruce_stairs, 5);
		world.setBlockMetadataWithNotify(i + 3, j + 47, k + 19, 5, 2);
		setBlock(world, i + 3, j + 48, k + 18, Blocks.log, 1);
		world.setBlockMetadataWithNotify(i + 3, j + 48, k + 18, 1, 2);
		setBlock(world, i + 3, j + 48, k + 19, Blocks.log, 1);
		world.setBlockMetadataWithNotify(i + 3, j + 48, k + 19, 1, 2);
		setBlock(world, i + 3, j + 48, k + 20, Blocks.log, 1);
		world.setBlockMetadataWithNotify(i + 3, j + 48, k + 20, 1, 2);
		setBlock(world, i + 3, j + 48, k + 21, Blocks.log, 1);
		world.setBlockMetadataWithNotify(i + 3, j + 48, k + 21, 1, 2);
		setBlock(world, i + 3, j + 48, k + 22, Blocks.log, 1);
		world.setBlockMetadataWithNotify(i + 3, j + 48, k + 22, 1, 2);
		setBlock(world, i + 3, j + 48, k + 23, Blocks.log, 1);
		world.setBlockMetadataWithNotify(i + 3, j + 48, k + 23, 1, 2);
		setBlock(world, i + 3, j + 48, k + 24, Blocks.torch, 3);
		world.setBlockMetadataWithNotify(i + 3, j + 48, k + 24, 3, 2);
		setBlock(world, i + 3, j + 49, k + 19, Blocks.log, 1);
		world.setBlockMetadataWithNotify(i + 3, j + 49, k + 19, 1, 2);
		setBlock(world, i + 3, j + 49, k + 20, Blocks.log, 1);
		world.setBlockMetadataWithNotify(i + 3, j + 49, k + 20, 1, 2);
		setBlock(world, i + 3, j + 49, k + 21, Blocks.log, 1);
		world.setBlockMetadataWithNotify(i + 3, j + 49, k + 21, 1, 2);
		setBlock(world, i + 3, j + 49, k + 22, Blocks.log, 1);
		world.setBlockMetadataWithNotify(i + 3, j + 49, k + 22, 1, 2);
		setBlock(world, i + 3, j + 49, k + 23, Blocks.log, 1);
		world.setBlockMetadataWithNotify(i + 3, j + 49, k + 23, 1, 2);
		setBlock(world, i + 3, j + 49, k + 24, Blocks.log, 1);
		world.setBlockMetadataWithNotify(i + 3, j + 49, k + 24, 1, 2);
		setBlock(world, i + 3, j + 50, k + 21, Blocks.log, 1);
		world.setBlockMetadataWithNotify(i + 3, j + 50, k + 21, 1, 2);
		setBlock(world, i + 3, j + 50, k + 22, Blocks.log, 1);
		world.setBlockMetadataWithNotify(i + 3, j + 50, k + 22, 1, 2);
		setBlock(world, i + 3, j + 50, k + 23, Blocks.log, 1);
		world.setBlockMetadataWithNotify(i + 3, j + 50, k + 23, 1, 2);
		setBlock(world, i + 3, j + 50, k + 24, Blocks.log, 1);
		world.setBlockMetadataWithNotify(i + 3, j + 50, k + 24, 1, 2);
		setBlock(world, i + 3, j + 50, k + 25, Blocks.log, 1);
		world.setBlockMetadataWithNotify(i + 3, j + 50, k + 25, 1, 2);
		setBlock(world, i + 3, j + 50, k + 26, Blocks.torch, 3);
		world.setBlockMetadataWithNotify(i + 3, j + 50, k + 26, 3, 2);
		setBlock(world, i + 3, j + 50, k + 29, Blocks.torch, 2);
		world.setBlockMetadataWithNotify(i + 3, j + 50, k + 29, 2, 2);
		setBlock(world, i + 3, j + 51, k + 25, Blocks.log, 1);
		world.setBlockMetadataWithNotify(i + 3, j + 51, k + 25, 1, 2);
		setBlock(world, i + 3, j + 51, k + 26, Blocks.log, 1);
		world.setBlockMetadataWithNotify(i + 3, j + 51, k + 26, 1, 2);
		setBlock(world, i + 3, j + 51, k + 27, Blocks.log, 1);
		world.setBlockMetadataWithNotify(i + 3, j + 51, k + 27, 1, 2);
		setBlock(world, i + 3, j + 51, k + 28, Blocks.log, 1);
		world.setBlockMetadataWithNotify(i + 3, j + 51, k + 28, 1, 2);
		setBlock(world, i + 3, j + 51, k + 29, Blocks.log, 1);
		world.setBlockMetadataWithNotify(i + 3, j + 51, k + 29, 1, 2);
		setBlock(world, i + 3, j + 51, k + 30, Blocks.log, 1);
		world.setBlockMetadataWithNotify(i + 3, j + 51, k + 30, 1, 2);
		setBlock(world, i + 3, j + 51, k + 31, Blocks.log, 1);
		world.setBlockMetadataWithNotify(i + 3, j + 51, k + 31, 1, 2);
		setBlock(world, i + 4, j + 25, k + 29, Blocks.log, 3);
		world.setBlockMetadataWithNotify(i + 4, j + 25, k + 29, 3, 2);
		setBlock(world, i + 4, j + 26, k + 26, Blocks.leaves, 7);
		world.setBlockMetadataWithNotify(i + 4, j + 26, k + 26, 7, 2);
		setBlock(world, i + 4, j + 26, k + 27, Blocks.leaves, 7);
		world.setBlockMetadataWithNotify(i + 4, j + 26, k + 27, 7, 2);
		setBlock(world, i + 4, j + 26, k + 28, Blocks.leaves, 7);
		world.setBlockMetadataWithNotify(i + 4, j + 26, k + 28, 7, 2);
		setBlock(world, i + 4, j + 26, k + 29, Blocks.leaves, 7);
		world.setBlockMetadataWithNotify(i + 4, j + 26, k + 29, 7, 2);
		setBlock(world, i + 4, j + 26, k + 30, Blocks.leaves, 15);
		world.setBlockMetadataWithNotify(i + 4, j + 26, k + 30, 15, 2);
		setBlock(world, i + 4, j + 27, k + 27, Blocks.leaves, 15);
		world.setBlockMetadataWithNotify(i + 4, j + 27, k + 27, 15, 2);
		setBlock(world, i + 4, j + 27, k + 28, Blocks.leaves, 15);
		world.setBlockMetadataWithNotify(i + 4, j + 27, k + 28, 15, 2);
		setBlock(world, i + 4, j + 27, k + 29, Blocks.leaves, 7);
		world.setBlockMetadataWithNotify(i + 4, j + 27, k + 29, 7, 2);
		setBlock(world, i + 4, j + 27, k + 31, Blocks.log, 1);
		world.setBlockMetadataWithNotify(i + 4, j + 27, k + 31, 1, 2);
		setBlock(world, i + 4, j + 28, k + 28, Blocks.leaves, 15);
		world.setBlockMetadataWithNotify(i + 4, j + 28, k + 28, 15, 2);
		setBlock(world, i + 4, j + 31, k + 27, Blocks.log, 1);
		world.setBlockMetadataWithNotify(i + 4, j + 31, k + 27, 1, 2);
		setBlock(world, i + 4, j + 31, k + 28, Blocks.log, 1);
		world.setBlockMetadataWithNotify(i + 4, j + 31, k + 28, 1, 2);
		setBlock(world, i + 4, j + 31, k + 29, Blocks.log, 1);
		world.setBlockMetadataWithNotify(i + 4, j + 31, k + 29, 1, 2);
		setBlock(world, i + 4, j + 31, k + 30, Blocks.log, 1);
		world.setBlockMetadataWithNotify(i + 4, j + 31, k + 30, 1, 2);
		setBlock(world, i + 4, j + 31, k + 31, Blocks.log, 1);
		world.setBlockMetadataWithNotify(i + 4, j + 31, k + 31, 1, 2);
		setBlock(world, i + 4, j + 32, k + 21, Blocks.leaves, 7);
		world.setBlockMetadataWithNotify(i + 4, j + 32, k + 21, 7, 2);
		setBlock(world, i + 4, j + 32, k + 22, Blocks.leaves, 7);
		world.setBlockMetadataWithNotify(i + 4, j + 32, k + 22, 7, 2);
		setBlock(world, i + 4, j + 32, k + 23, Blocks.log, 3);
		world.setBlockMetadataWithNotify(i + 4, j + 32, k + 23, 3, 2);
		setBlock(world, i + 4, j + 32, k + 24, Blocks.leaves, 7);
		world.setBlockMetadataWithNotify(i + 4, j + 32, k + 24, 7, 2);
		setBlock(world, i + 4, j + 32, k + 25, Blocks.leaves, 7);
		world.setBlockMetadataWithNotify(i + 4, j + 32, k + 25, 7, 2);
		setBlock(world, i + 4, j + 32, k + 29, Blocks.log, 1);
		world.setBlockMetadataWithNotify(i + 4, j + 32, k + 29, 1, 2);
		setBlock(world, i + 4, j + 32, k + 30, Blocks.log, 1);
		world.setBlockMetadataWithNotify(i + 4, j + 32, k + 30, 1, 2);
		setBlock(world, i + 4, j + 32, k + 31, Blocks.log, 1);
		world.setBlockMetadataWithNotify(i + 4, j + 32, k + 31, 1, 2);
		setBlock(world, i + 4, j + 33, k + 12, Blocks.vine, 13);
		world.setBlockMetadataWithNotify(i + 4, j + 33, k + 12, 13, 2);
		setBlock(world, i + 4, j + 33, k + 21, Blocks.leaves, 7);
		world.setBlockMetadataWithNotify(i + 4, j + 33, k + 21, 7, 2);
		setBlock(world, i + 4, j + 33, k + 22, Blocks.leaves, 7);
		world.setBlockMetadataWithNotify(i + 4, j + 33, k + 22, 7, 2);
		setBlock(world, i + 4, j + 33, k + 23, Blocks.leaves, 7);
		world.setBlockMetadataWithNotify(i + 4, j + 33, k + 23, 7, 2);
		setBlock(world, i + 4, j + 33, k + 24, Blocks.leaves, 7);
		world.setBlockMetadataWithNotify(i + 4, j + 33, k + 24, 7, 2);
		setBlock(world, i + 4, j + 33, k + 25, Blocks.leaves, 7);
		world.setBlockMetadataWithNotify(i + 4, j + 33, k + 25, 7, 2);
		setBlock(world, i + 4, j + 33, k + 29, Blocks.log, 1);
		world.setBlockMetadataWithNotify(i + 4, j + 33, k + 29, 1, 2);
		setBlock(world, i + 4, j + 33, k + 30, Blocks.log, 1);
		world.setBlockMetadataWithNotify(i + 4, j + 33, k + 30, 1, 2);
		setBlock(world, i + 4, j + 33, k + 31, Blocks.log, 1);
		world.setBlockMetadataWithNotify(i + 4, j + 33, k + 31, 1, 2);
		setBlock(world, i + 4, j + 34, k + 11, Blocks.vine, 15);
		world.setBlockMetadataWithNotify(i + 4, j + 34, k + 11, 15, 2);
		setBlock(world, i + 4, j + 34, k + 12, Blocks.vine, 15);
		/* 1000 */world.setBlockMetadataWithNotify(i + 4, j + 34, k + 12, 15, 2);
		/* 1001 */setBlock(world, i + 4, j + 34, k + 22, Blocks.leaves, 7);
		/* 1002 */world.setBlockMetadataWithNotify(i + 4, j + 34, k + 22, 7, 2);
		/* 1003 */setBlock(world, i + 4, j + 34, k + 23, Blocks.leaves, 7);
		/* 1004 */world.setBlockMetadataWithNotify(i + 4, j + 34, k + 23, 7, 2);
		/* 1005 */setBlock(world, i + 4, j + 34, k + 24, Blocks.leaves, 7);
		/* 1006 */world.setBlockMetadataWithNotify(i + 4, j + 34, k + 24, 7, 2);
		/* 1007 */setBlock(world, i + 4, j + 34, k + 30, Blocks.log, 1);
		/* 1008 */world.setBlockMetadataWithNotify(i + 4, j + 34, k + 30, 1, 2);
		/* 1009 */setBlock(world, i + 4, j + 34, k + 31, Blocks.log, 1);
		/* 1010 */world.setBlockMetadataWithNotify(i + 4, j + 34, k + 31, 1, 2);
		/* 1011 */setBlock(world, i + 4, j + 35, k + 11, Blocks.vine, 15);
		/* 1012 */world.setBlockMetadataWithNotify(i + 4, j + 35, k + 11, 15, 2);
		/* 1013 */setBlock(world, i + 4, j + 35, k + 12, Blocks.vine, 15);
		/* 1014 */world.setBlockMetadataWithNotify(i + 4, j + 35, k + 12, 15, 2);
		/* 1015 */setBlock(world, i + 4, j + 35, k + 23, Blocks.leaves, 7);
		/* 1016 */world.setBlockMetadataWithNotify(i + 4, j + 35, k + 23, 7, 2);
		/* 1017 */setBlock(world, i + 4, j + 36, k + 11, Blocks.vine, 15);
		/* 1018 */world.setBlockMetadataWithNotify(i + 4, j + 36, k + 11, 15, 2);
		/* 1019 */setBlock(world, i + 4, j + 36, k + 12, Blocks.vine, 15);
		/* 1020 */world.setBlockMetadataWithNotify(i + 4, j + 36, k + 12, 15, 2);
		/* 1021 */setBlock(world, i + 4, j + 37, k + 11, Blocks.vine, 15);
		/* 1022 */world.setBlockMetadataWithNotify(i + 4, j + 37, k + 11, 15, 2);
		/* 1023 */setBlock(world, i + 4, j + 37, k + 12, Blocks.vine, 15);
		/* 1024 */world.setBlockMetadataWithNotify(i + 4, j + 37, k + 12, 15, 2);
		/* 1025 */setBlock(world, i + 4, j + 38, k + 11, Blocks.vine, 15);
		/* 1026 */world.setBlockMetadataWithNotify(i + 4, j + 38, k + 11, 15, 2);
		/* 1027 */setBlock(world, i + 4, j + 38, k + 12, Blocks.vine, 15);
		/* 1028 */world.setBlockMetadataWithNotify(i + 4, j + 38, k + 12, 15, 2);
		/* 1029 */setBlock(world, i + 4, j + 38, k + 30, Blocks.leaves, 7);
		/* 1030 */world.setBlockMetadataWithNotify(i + 4, j + 38, k + 30, 7, 2);
		/* 1031 */setBlock(world, i + 4, j + 38, k + 31, Blocks.leaves, 7);
		/* 1032 */world.setBlockMetadataWithNotify(i + 4, j + 38, k + 31, 7, 2);
		/* 1033 */setBlock(world, i + 4, j + 39, k + 11, Blocks.vine, 15);
		/* 1034 */world.setBlockMetadataWithNotify(i + 4, j + 39, k + 11, 15, 2);
		/* 1035 */setBlock(world, i + 4, j + 39, k + 12, Blocks.vine, 15);
		/* 1036 */world.setBlockMetadataWithNotify(i + 4, j + 39, k + 12, 15, 2);
		/* 1037 */setBlock(world, i + 4, j + 39, k + 30, Blocks.leaves, 15);
		/* 1038 */world.setBlockMetadataWithNotify(i + 4, j + 39, k + 30, 15, 2);
		/* 1039 */setBlock(world, i + 4, j + 39, k + 31, Blocks.log, 1);
		/* 1040 */world.setBlockMetadataWithNotify(i + 4, j + 39, k + 31, 1, 2);
		/* 1041 */setBlock(world, i + 4, j + 40, k + 11, Blocks.vine, 15);
		/* 1042 */world.setBlockMetadataWithNotify(i + 4, j + 40, k + 11, 15, 2);
		/* 1043 */setBlock(world, i + 4, j + 40, k + 12, Blocks.vine, 15);
		/* 1044 */world.setBlockMetadataWithNotify(i + 4, j + 40, k + 12, 15, 2);
		/* 1045 */setBlock(world, i + 4, j + 40, k + 30, Blocks.log, 1);
		/* 1046 */world.setBlockMetadataWithNotify(i + 4, j + 40, k + 30, 1, 2);
		/* 1047 */setBlock(world, i + 4, j + 40, k + 31, Blocks.leaves, 15);
		/* 1048 */world.setBlockMetadataWithNotify(i + 4, j + 40, k + 31, 15, 2);
		/* 1049 */setBlock(world, i + 4, j + 41, k + 11, Blocks.vine, 15);
		/* 1050 */world.setBlockMetadataWithNotify(i + 4, j + 41, k + 11, 15, 2);
		/* 1051 */setBlock(world, i + 4, j + 41, k + 12, Blocks.vine, 15);
		/* 1052 */world.setBlockMetadataWithNotify(i + 4, j + 41, k + 12, 15, 2);
		/* 1053 */setBlock(world, i + 4, j + 41, k + 29, Blocks.leaves, 15);
		/* 1054 */world.setBlockMetadataWithNotify(i + 4, j + 41, k + 29, 15, 2);
		/* 1055 */setBlock(world, i + 4, j + 41, k + 30, Blocks.leaves, 15);
		/* 1056 */world.setBlockMetadataWithNotify(i + 4, j + 41, k + 30, 15, 2);
		/* 1057 */setBlock(world, i + 4, j + 41, k + 31, Blocks.log, 1);
		/* 1058 */world.setBlockMetadataWithNotify(i + 4, j + 41, k + 31, 1, 2);
		/* 1059 */setBlock(world, i + 4, j + 42, k + 7, Blocks.planks, 5);
		/* 1060 */world.setBlockMetadataWithNotify(i + 4, j + 42, k + 7, 5, 2);
		/* 1061 */setBlock(world, i + 4, j + 42, k + 8, Blocks.planks, 5);
		/* 1062 */world.setBlockMetadataWithNotify(i + 4, j + 42, k + 8, 5, 2);
		/* 1063 */setBlock(world, i + 4, j + 42, k + 9, Blocks.planks, 5);
		/* 1064 */world.setBlockMetadataWithNotify(i + 4, j + 42, k + 9, 5, 2);
		/* 1065 */setBlock(world, i + 4, j + 42, k + 10, Blocks.planks, 5);
		/* 1066 */world.setBlockMetadataWithNotify(i + 4, j + 42, k + 10, 5, 2);
		/* 1067 */setBlock(world, i + 4, j + 42, k + 11, Blocks.planks, 5);
		/* 1068 */world.setBlockMetadataWithNotify(i + 4, j + 42, k + 11, 5, 2);
		/* 1069 */setBlock(world, i + 4, j + 42, k + 12, Blocks.planks, 5);
		/* 1070 */world.setBlockMetadataWithNotify(i + 4, j + 42, k + 12, 5, 2);
		/* 1071 */setBlock(world, i + 4, j + 42, k + 13, Blocks.planks, 5);
		/* 1072 */world.setBlockMetadataWithNotify(i + 4, j + 42, k + 13, 5, 2);
		/* 1073 */setBlock(world, i + 4, j + 42, k + 14, Blocks.planks, 5);
		/* 1074 */world.setBlockMetadataWithNotify(i + 4, j + 42, k + 14, 5, 2);
		/* 1075 */setBlock(world, i + 4, j + 42, k + 15, Blocks.planks, 5);
		/* 1076 */world.setBlockMetadataWithNotify(i + 4, j + 42, k + 15, 5, 2);
		/* 1077 */setBlock(world, i + 4, j + 42, k + 16, Blocks.planks, 5);
		/* 1078 */world.setBlockMetadataWithNotify(i + 4, j + 42, k + 16, 5, 2);
		/* 1079 */setBlock(world, i + 4, j + 42, k + 26, Blocks.log, 1);
		/* 1080 */world.setBlockMetadataWithNotify(i + 4, j + 42, k + 26, 1, 2);
		/* 1081 */setBlock(world, i + 4, j + 42, k + 27, Blocks.log, 1);
		/* 1082 */world.setBlockMetadataWithNotify(i + 4, j + 42, k + 27, 1, 2);
		/* 1083 */setBlock(world, i + 4, j + 42, k + 28, Blocks.log, 1);
		/* 1084 */world.setBlockMetadataWithNotify(i + 4, j + 42, k + 28, 1, 2);
		/* 1085 */setBlock(world, i + 4, j + 42, k + 30, Blocks.leaves, 15);
		/* 1086 */world.setBlockMetadataWithNotify(i + 4, j + 42, k + 30, 15, 2);
		/* 1087 */setBlock(world, i + 4, j + 42, k + 31, Blocks.leaves, 15);
		/* 1088 */world.setBlockMetadataWithNotify(i + 4, j + 42, k + 31, 15, 2);
		/* 1089 */setBlock(world, i + 4, j + 43, k + 15, Blocks.spruce_stairs, 2);
		/* 1090 */world.setBlockMetadataWithNotify(i + 4, j + 43, k + 15, 2, 2);
		/* 1091 */setBlock(world, i + 4, j + 43, k + 16, Blocks.planks, 5);
		/* 1092 */world.setBlockMetadataWithNotify(i + 4, j + 43, k + 16, 5, 2);
		/* 1093 */setBlock(world, i + 4, j + 43, k + 17, Blocks.planks, 5);
		/* 1094 */world.setBlockMetadataWithNotify(i + 4, j + 43, k + 17, 5, 2);
		/* 1095 */setBlock(world, i + 4, j + 43, k + 18, Blocks.planks, 5);
		/* 1096 */world.setBlockMetadataWithNotify(i + 4, j + 43, k + 18, 5, 2);
		/* 1097 */setBlock(world, i + 4, j + 43, k + 19, Blocks.log, 1);
		/* 1098 */world.setBlockMetadataWithNotify(i + 4, j + 43, k + 19, 1, 2);
		/* 1099 */setBlock(world, i + 4, j + 43, k + 20, Blocks.log, 1);
		/* 1100 */world.setBlockMetadataWithNotify(i + 4, j + 43, k + 20, 1, 2);
		/* 1101 */setBlock(world, i + 4, j + 43, k + 21, Blocks.log, 1);
		/* 1102 */world.setBlockMetadataWithNotify(i + 4, j + 43, k + 21, 1, 2);
		/* 1103 */setBlock(world, i + 4, j + 43, k + 22, Blocks.log, 1);
		/* 1104 */world.setBlockMetadataWithNotify(i + 4, j + 43, k + 22, 1, 2);
		/* 1105 */setBlock(world, i + 4, j + 43, k + 23, Blocks.log, 1);
		/* 1106 */world.setBlockMetadataWithNotify(i + 4, j + 43, k + 23, 1, 2);
		/* 1107 */setBlock(world, i + 4, j + 43, k + 24, Blocks.log, 1);
		/* 1108 */world.setBlockMetadataWithNotify(i + 4, j + 43, k + 24, 1, 2);
		/* 1109 */setBlock(world, i + 4, j + 43, k + 25, Blocks.log, 1);
		/* 1110 */world.setBlockMetadataWithNotify(i + 4, j + 43, k + 25, 1, 2);
		/* 1111 */setBlock(world, i + 4, j + 43, k + 26, Blocks.log, 1);
		/* 1112 */world.setBlockMetadataWithNotify(i + 4, j + 43, k + 26, 1, 2);
		/* 1113 */setBlock(world, i + 4, j + 43, k + 27, Blocks.log, 1);
		/* 1114 */world.setBlockMetadataWithNotify(i + 4, j + 43, k + 27, 1, 2);
		/* 1115 */setBlock(world, i + 4, j + 43, k + 28, Blocks.planks, 5);
		/* 1116 */world.setBlockMetadataWithNotify(i + 4, j + 43, k + 28, 5, 2);
		/* 1117 */setBlock(world, i + 4, j + 43, k + 29, Blocks.planks, 5);
		/* 1118 */world.setBlockMetadataWithNotify(i + 4, j + 43, k + 29, 5, 2);
		/* 1119 */setBlock(world, i + 4, j + 43, k + 30, Blocks.log, 1);
		/* 1120 */world.setBlockMetadataWithNotify(i + 4, j + 43, k + 30, 1, 2);
		/* 1121 */setBlock(world, i + 4, j + 43, k + 31, Blocks.log, 1);
		/* 1122 */world.setBlockMetadataWithNotify(i + 4, j + 43, k + 31, 1, 2);
		/* 1123 */setBlock(world, i + 4, j + 44, k + 29, Blocks.chest, 4);
		/* 1124 */LootGenUtils.fillLootChest(world.provider.dimensionId, world.rand, (TileEntityChest)world.getTileEntity(i + 4, j + 44, k + 29));
		/* 1125 */world.setBlockMetadataWithNotify(i + 4, j + 44, k + 29, 4, 2);
		/* 1126 */setBlock(world, i + 4, j + 46, k + 31, Blocks.torch, 2);
		/* 1127 */world.setBlockMetadataWithNotify(i + 4, j + 46, k + 31, 2, 2);
		/* 1128 */setBlock(world, i + 4, j + 47, k + 30, Blocks.torch, 2);
		/* 1129 */world.setBlockMetadataWithNotify(i + 4, j + 47, k + 30, 2, 2);
		/* 1130 */setBlock(world, i + 4, j + 48, k + 17, Blocks.log, 1);
		/* 1131 */world.setBlockMetadataWithNotify(i + 4, j + 48, k + 17, 1, 2);
		/* 1132 */setBlock(world, i + 4, j + 48, k + 18, Blocks.log, 1);
		/* 1133 */world.setBlockMetadataWithNotify(i + 4, j + 48, k + 18, 1, 2);
		/* 1134 */setBlock(world, i + 4, j + 48, k + 19, Blocks.log, 1);
		/* 1135 */world.setBlockMetadataWithNotify(i + 4, j + 48, k + 19, 1, 2);
		/* 1136 */setBlock(world, i + 4, j + 48, k + 20, Blocks.log, 1);
		/* 1137 */world.setBlockMetadataWithNotify(i + 4, j + 48, k + 20, 1, 2);
		/* 1138 */setBlock(world, i + 4, j + 48, k + 21, Blocks.log, 1);
		/* 1139 */world.setBlockMetadataWithNotify(i + 4, j + 48, k + 21, 1, 2);
		/* 1140 */setBlock(world, i + 4, j + 48, k + 22, Blocks.log, 1);
		/* 1141 */world.setBlockMetadataWithNotify(i + 4, j + 48, k + 22, 1, 2);
		/* 1142 */setBlock(world, i + 4, j + 49, k + 18, Blocks.log, 1);
		/* 1143 */world.setBlockMetadataWithNotify(i + 4, j + 49, k + 18, 1, 2);
		/* 1144 */setBlock(world, i + 4, j + 49, k + 19, Blocks.log, 1);
		/* 1145 */world.setBlockMetadataWithNotify(i + 4, j + 49, k + 19, 1, 2);
		/* 1146 */setBlock(world, i + 4, j + 49, k + 20, Blocks.log, 1);
		/* 1147 */world.setBlockMetadataWithNotify(i + 4, j + 49, k + 20, 1, 2);
		/* 1148 */setBlock(world, i + 4, j + 49, k + 21, Blocks.log, 1);
		/* 1149 */world.setBlockMetadataWithNotify(i + 4, j + 49, k + 21, 1, 2);
		/* 1150 */setBlock(world, i + 4, j + 49, k + 22, Blocks.log, 1);
		/* 1151 */world.setBlockMetadataWithNotify(i + 4, j + 49, k + 22, 1, 2);
		/* 1152 */setBlock(world, i + 4, j + 49, k + 23, Blocks.log, 1);
		/* 1153 */world.setBlockMetadataWithNotify(i + 4, j + 49, k + 23, 1, 2);
		/* 1154 */setBlock(world, i + 4, j + 50, k + 20, Blocks.log, 1);
		/* 1155 */world.setBlockMetadataWithNotify(i + 4, j + 50, k + 20, 1, 2);
		/* 1156 */setBlock(world, i + 4, j + 50, k + 21, Blocks.log, 1);
		/* 1157 */world.setBlockMetadataWithNotify(i + 4, j + 50, k + 21, 1, 2);
		/* 1158 */setBlock(world, i + 4, j + 50, k + 22, Blocks.log, 1);
		/* 1159 */world.setBlockMetadataWithNotify(i + 4, j + 50, k + 22, 1, 2);
		/* 1160 */setBlock(world, i + 4, j + 50, k + 23, Blocks.log, 1);
		/* 1161 */world.setBlockMetadataWithNotify(i + 4, j + 50, k + 23, 1, 2);
		/* 1162 */setBlock(world, i + 4, j + 50, k + 24, Blocks.log, 1);
		/* 1163 */world.setBlockMetadataWithNotify(i + 4, j + 50, k + 24, 1, 2);
		/* 1164 */setBlock(world, i + 4, j + 50, k + 28, Blocks.torch, 4);
		/* 1165 */world.setBlockMetadataWithNotify(i + 4, j + 50, k + 28, 4, 2);
		/* 1166 */setBlock(world, i + 4, j + 50, k + 29, Blocks.log, 1);
		/* 1167 */world.setBlockMetadataWithNotify(i + 4, j + 50, k + 29, 1, 2);
		/* 1168 */setBlock(world, i + 4, j + 50, k + 30, Blocks.log, 1);
		/* 1169 */world.setBlockMetadataWithNotify(i + 4, j + 50, k + 30, 1, 2);
		/* 1170 */setBlock(world, i + 4, j + 50, k + 31, Blocks.log, 1);
		/* 1171 */world.setBlockMetadataWithNotify(i + 4, j + 50, k + 31, 1, 2);
		/* 1172 */setBlock(world, i + 4, j + 51, k + 25, Blocks.log, 1);
		/* 1173 */world.setBlockMetadataWithNotify(i + 4, j + 51, k + 25, 1, 2);
		/* 1174 */setBlock(world, i + 4, j + 51, k + 26, Blocks.log, 1);
		/* 1175 */world.setBlockMetadataWithNotify(i + 4, j + 51, k + 26, 1, 2);
		/* 1176 */setBlock(world, i + 4, j + 51, k + 27, Blocks.log, 1);
		/* 1177 */world.setBlockMetadataWithNotify(i + 4, j + 51, k + 27, 1, 2);
		/* 1178 */setBlock(world, i + 4, j + 51, k + 28, Blocks.log, 1);
		/* 1179 */world.setBlockMetadataWithNotify(i + 4, j + 51, k + 28, 1, 2);
		/* 1180 */setBlock(world, i + 4, j + 51, k + 29, Blocks.log, 1);
		/* 1181 */world.setBlockMetadataWithNotify(i + 4, j + 51, k + 29, 1, 2);
		/* 1182 */setBlock(world, i + 4, j + 51, k + 30, Blocks.log, 1);
		/* 1183 */world.setBlockMetadataWithNotify(i + 4, j + 51, k + 30, 1, 2);
		/* 1184 */setBlock(world, i + 4, j + 51, k + 31, Blocks.log, 1);
		/* 1185 */world.setBlockMetadataWithNotify(i + 4, j + 51, k + 31, 1, 2);
		/* 1186 */setBlock(world, i + 5, j + 26, k + 26, Blocks.leaves, 15);
		/* 1187 */world.setBlockMetadataWithNotify(i + 5, j + 26, k + 26, 15, 2);
		/* 1188 */setBlock(world, i + 5, j + 26, k + 27, Blocks.leaves, 15);
		/* 1189 */world.setBlockMetadataWithNotify(i + 5, j + 26, k + 27, 15, 2);
		/* 1190 */setBlock(world, i + 5, j + 26, k + 28, Blocks.log, 3);
		/* 1191 */world.setBlockMetadataWithNotify(i + 5, j + 26, k + 28, 3, 2);
		/* 1192 */setBlock(world, i + 5, j + 26, k + 29, Blocks.leaves, 7);
		/* 1193 */world.setBlockMetadataWithNotify(i + 5, j + 26, k + 29, 7, 2);
		/* 1194 */setBlock(world, i + 5, j + 26, k + 30, Blocks.leaves, 15);
		/* 1195 */world.setBlockMetadataWithNotify(i + 5, j + 26, k + 30, 15, 2);
		/* 1196 */setBlock(world, i + 5, j + 27, k + 26, Blocks.leaves, 15);
		/* 1197 */world.setBlockMetadataWithNotify(i + 5, j + 27, k + 26, 15, 2);
		/* 1198 */setBlock(world, i + 5, j + 27, k + 27, Blocks.leaves, 15);
		/* 1199 */world.setBlockMetadataWithNotify(i + 5, j + 27, k + 27, 15, 2);
		/* 1200 */setBlock(world, i + 5, j + 27, k + 28, Blocks.leaves, 15);
		/* 1201 */world.setBlockMetadataWithNotify(i + 5, j + 27, k + 28, 15, 2);
		/* 1202 */setBlock(world, i + 5, j + 27, k + 29, Blocks.leaves, 15);
		/* 1203 */world.setBlockMetadataWithNotify(i + 5, j + 27, k + 29, 15, 2);
		/* 1204 */setBlock(world, i + 5, j + 27, k + 30, Blocks.log, 1);
		/* 1205 */world.setBlockMetadataWithNotify(i + 5, j + 27, k + 30, 1, 2);
		/* 1206 */setBlock(world, i + 5, j + 27, k + 31, Blocks.log, 1);
		/* 1207 */world.setBlockMetadataWithNotify(i + 5, j + 27, k + 31, 1, 2);
		/* 1208 */setBlock(world, i + 5, j + 28, k + 28, Blocks.leaves, 15);
		/* 1209 */world.setBlockMetadataWithNotify(i + 5, j + 28, k + 28, 15, 2);
		/* 1210 */setBlock(world, i + 5, j + 28, k + 29, Blocks.leaves, 15);
		/* 1211 */world.setBlockMetadataWithNotify(i + 5, j + 28, k + 29, 15, 2);
		/* 1212 */setBlock(world, i + 5, j + 31, k + 27, Blocks.log, 1);
		/* 1213 */world.setBlockMetadataWithNotify(i + 5, j + 31, k + 27, 1, 2);
		/* 1214 */setBlock(world, i + 5, j + 31, k + 28, Blocks.log, 1);
		/* 1215 */world.setBlockMetadataWithNotify(i + 5, j + 31, k + 28, 1, 2);
		/* 1216 */setBlock(world, i + 5, j + 31, k + 29, Blocks.log, 1);
		/* 1217 */world.setBlockMetadataWithNotify(i + 5, j + 31, k + 29, 1, 2);
		/* 1218 */setBlock(world, i + 5, j + 31, k + 30, Blocks.log, 1);
		/* 1219 */world.setBlockMetadataWithNotify(i + 5, j + 31, k + 30, 1, 2);
		/* 1220 */setBlock(world, i + 5, j + 32, k + 21, Blocks.leaves, 7);
		/* 1221 */world.setBlockMetadataWithNotify(i + 5, j + 32, k + 21, 7, 2);
		/* 1222 */setBlock(world, i + 5, j + 32, k + 22, Blocks.leaves, 7);
		/* 1223 */world.setBlockMetadataWithNotify(i + 5, j + 32, k + 22, 7, 2);
		/* 1224 */setBlock(world, i + 5, j + 32, k + 23, Blocks.leaves, 7);
		/* 1225 */world.setBlockMetadataWithNotify(i + 5, j + 32, k + 23, 7, 2);
		/* 1226 */setBlock(world, i + 5, j + 32, k + 24, Blocks.leaves, 7);
		/* 1227 */world.setBlockMetadataWithNotify(i + 5, j + 32, k + 24, 7, 2);
		/* 1228 */setBlock(world, i + 5, j + 32, k + 25, Blocks.leaves, 7);
		/* 1229 */world.setBlockMetadataWithNotify(i + 5, j + 32, k + 25, 7, 2);
		/* 1230 */setBlock(world, i + 5, j + 32, k + 28, Blocks.log, 1);
		/* 1231 */world.setBlockMetadataWithNotify(i + 5, j + 32, k + 28, 1, 2);
		/* 1232 */setBlock(world, i + 5, j + 32, k + 29, Blocks.log, 1);
		/* 1233 */world.setBlockMetadataWithNotify(i + 5, j + 32, k + 29, 1, 2);
		/* 1234 */setBlock(world, i + 5, j + 32, k + 30, Blocks.log, 1);
		/* 1235 */world.setBlockMetadataWithNotify(i + 5, j + 32, k + 30, 1, 2);
		/* 1236 */setBlock(world, i + 5, j + 32, k + 31, Blocks.log, 1);
		/* 1237 */world.setBlockMetadataWithNotify(i + 5, j + 32, k + 31, 1, 2);
		/* 1238 */setBlock(world, i + 5, j + 33, k + 22, Blocks.leaves, 7);
		/* 1239 */world.setBlockMetadataWithNotify(i + 5, j + 33, k + 22, 7, 2);
		/* 1240 */setBlock(world, i + 5, j + 33, k + 23, Blocks.leaves, 7);
		/* 1241 */world.setBlockMetadataWithNotify(i + 5, j + 33, k + 23, 7, 2);
		/* 1242 */setBlock(world, i + 5, j + 33, k + 24, Blocks.leaves, 7);
		/* 1243 */world.setBlockMetadataWithNotify(i + 5, j + 33, k + 24, 7, 2);
		/* 1244 */setBlock(world, i + 5, j + 33, k + 28, Blocks.log, 1);
		/* 1245 */world.setBlockMetadataWithNotify(i + 5, j + 33, k + 28, 1, 2);
		/* 1246 */setBlock(world, i + 5, j + 33, k + 29, Blocks.log, 1);
		/* 1247 */world.setBlockMetadataWithNotify(i + 5, j + 33, k + 29, 1, 2);
		/* 1248 */setBlock(world, i + 5, j + 33, k + 30, Blocks.log, 1);
		/* 1249 */world.setBlockMetadataWithNotify(i + 5, j + 33, k + 30, 1, 2);
		/* 1250 */setBlock(world, i + 5, j + 33, k + 31, Blocks.log, 1);
		/* 1251 */world.setBlockMetadataWithNotify(i + 5, j + 33, k + 31, 1, 2);
		/* 1252 */setBlock(world, i + 5, j + 34, k + 23, Blocks.leaves, 7);
		/* 1253 */world.setBlockMetadataWithNotify(i + 5, j + 34, k + 23, 7, 2);
		/* 1254 */setBlock(world, i + 5, j + 34, k + 29, Blocks.log, 1);
		/* 1255 */world.setBlockMetadataWithNotify(i + 5, j + 34, k + 29, 1, 2);
		/* 1256 */setBlock(world, i + 5, j + 34, k + 30, Blocks.log, 1);
		/* 1257 */world.setBlockMetadataWithNotify(i + 5, j + 34, k + 30, 1, 2);
		/* 1258 */setBlock(world, i + 5, j + 34, k + 31, Blocks.log, 1);
		/* 1259 */world.setBlockMetadataWithNotify(i + 5, j + 34, k + 31, 1, 2);
		/* 1260 */setBlock(world, i + 5, j + 35, k + 15, Blocks.vine, 8);
		/* 1261 */world.setBlockMetadataWithNotify(i + 5, j + 35, k + 15, 8, 2);
		/* 1262 */setBlock(world, i + 5, j + 35, k + 31, Blocks.log, 1);
		/* 1263 */world.setBlockMetadataWithNotify(i + 5, j + 35, k + 31, 1, 2);
		/* 1264 */setBlock(world, i + 5, j + 36, k + 15, Blocks.vine, 15);
		/* 1265 */world.setBlockMetadataWithNotify(i + 5, j + 36, k + 15, 15, 2);
		/* 1266 */setBlock(world, i + 5, j + 37, k + 14, Blocks.vine, 15);
		/* 1267 */world.setBlockMetadataWithNotify(i + 5, j + 37, k + 14, 15, 2);
		/* 1268 */setBlock(world, i + 5, j + 37, k + 15, Blocks.vine, 15);
		/* 1269 */world.setBlockMetadataWithNotify(i + 5, j + 37, k + 15, 15, 2);
		/* 1270 */setBlock(world, i + 5, j + 38, k + 14, Blocks.vine, 15);
		/* 1271 */world.setBlockMetadataWithNotify(i + 5, j + 38, k + 14, 15, 2);
		/* 1272 */setBlock(world, i + 5, j + 38, k + 15, Blocks.vine, 15);
		/* 1273 */world.setBlockMetadataWithNotify(i + 5, j + 38, k + 15, 15, 2);
		/* 1274 */setBlock(world, i + 5, j + 38, k + 30, Blocks.leaves, 7);
		/* 1275 */world.setBlockMetadataWithNotify(i + 5, j + 38, k + 30, 7, 2);
		/* 1276 */setBlock(world, i + 5, j + 38, k + 31, Blocks.leaves, 7);
		/* 1277 */world.setBlockMetadataWithNotify(i + 5, j + 38, k + 31, 7, 2);
		/* 1278 */setBlock(world, i + 5, j + 39, k + 14, Blocks.vine, 15);
		/* 1279 */world.setBlockMetadataWithNotify(i + 5, j + 39, k + 14, 15, 2);
		/* 1280 */setBlock(world, i + 5, j + 39, k + 15, Blocks.vine, 15);
		/* 1281 */world.setBlockMetadataWithNotify(i + 5, j + 39, k + 15, 15, 2);
		/* 1282 */setBlock(world, i + 5, j + 39, k + 30, Blocks.log, 1);
		/* 1283 */world.setBlockMetadataWithNotify(i + 5, j + 39, k + 30, 1, 2);
		/* 1284 */setBlock(world, i + 5, j + 39, k + 31, Blocks.log, 1);
		/* 1285 */world.setBlockMetadataWithNotify(i + 5, j + 39, k + 31, 1, 2);
		/* 1286 */setBlock(world, i + 5, j + 40, k + 14, Blocks.vine, 15);
		/* 1287 */world.setBlockMetadataWithNotify(i + 5, j + 40, k + 14, 15, 2);
		/* 1288 */setBlock(world, i + 5, j + 40, k + 15, Blocks.vine, 15);
		/* 1289 */world.setBlockMetadataWithNotify(i + 5, j + 40, k + 15, 15, 2);
		/* 1290 */setBlock(world, i + 5, j + 40, k + 30, Blocks.log, 1);
		/* 1291 */world.setBlockMetadataWithNotify(i + 5, j + 40, k + 30, 1, 2);
		/* 1292 */setBlock(world, i + 5, j + 40, k + 31, Blocks.log, 1);
		/* 1293 */world.setBlockMetadataWithNotify(i + 5, j + 40, k + 31, 1, 2);
		/* 1294 */setBlock(world, i + 5, j + 41, k + 29, Blocks.leaves, 15);
		/* 1295 */world.setBlockMetadataWithNotify(i + 5, j + 41, k + 29, 15, 2);
		/* 1296 */setBlock(world, i + 5, j + 41, k + 30, Blocks.log, 1);
		/* 1297 */world.setBlockMetadataWithNotify(i + 5, j + 41, k + 30, 1, 2);
		/* 1298 */setBlock(world, i + 5, j + 41, k + 31, Blocks.log, 1);
		/* 1299 */world.setBlockMetadataWithNotify(i + 5, j + 41, k + 31, 1, 2);
		/* 1300 */setBlock(world, i + 5, j + 42, k + 8, Blocks.planks, 5);
		/* 1301 */world.setBlockMetadataWithNotify(i + 5, j + 42, k + 8, 5, 2);
		/* 1302 */setBlock(world, i + 5, j + 42, k + 9, Blocks.planks, 5);
		/* 1303 */world.setBlockMetadataWithNotify(i + 5, j + 42, k + 9, 5, 2);
		/* 1304 */setBlock(world, i + 5, j + 42, k + 10, Blocks.planks, 5);
		/* 1305 */world.setBlockMetadataWithNotify(i + 5, j + 42, k + 10, 5, 2);
		/* 1306 */setBlock(world, i + 5, j + 42, k + 11, Blocks.planks, 5);
		/* 1307 */world.setBlockMetadataWithNotify(i + 5, j + 42, k + 11, 5, 2);
		/* 1308 */setBlock(world, i + 5, j + 42, k + 12, Blocks.planks, 5);
		/* 1309 */world.setBlockMetadataWithNotify(i + 5, j + 42, k + 12, 5, 2);
		/* 1310 */setBlock(world, i + 5, j + 42, k + 13, Blocks.planks, 5);
		/* 1311 */world.setBlockMetadataWithNotify(i + 5, j + 42, k + 13, 5, 2);
		/* 1312 */setBlock(world, i + 5, j + 42, k + 14, Blocks.planks, 5);
		/* 1313 */world.setBlockMetadataWithNotify(i + 5, j + 42, k + 14, 5, 2);
		/* 1314 */setBlock(world, i + 5, j + 42, k + 15, Blocks.planks, 5);
		/* 1315 */world.setBlockMetadataWithNotify(i + 5, j + 42, k + 15, 5, 2);
		/* 1316 */setBlock(world, i + 5, j + 42, k + 16, Blocks.planks, 5);
		/* 1317 */world.setBlockMetadataWithNotify(i + 5, j + 42, k + 16, 5, 2);
		/* 1318 */setBlock(world, i + 5, j + 42, k + 26, Blocks.log, 1);
		/* 1319 */world.setBlockMetadataWithNotify(i + 5, j + 42, k + 26, 1, 2);
		/* 1320 */setBlock(world, i + 5, j + 42, k + 27, Blocks.log, 1);
		/* 1321 */world.setBlockMetadataWithNotify(i + 5, j + 42, k + 27, 1, 2);
		/* 1322 */setBlock(world, i + 5, j + 42, k + 28, Blocks.log, 1);
		/* 1323 */world.setBlockMetadataWithNotify(i + 5, j + 42, k + 28, 1, 2);
		/* 1324 */setBlock(world, i + 5, j + 42, k + 29, Blocks.leaves, 15);
		/* 1325 */world.setBlockMetadataWithNotify(i + 5, j + 42, k + 29, 15, 2);
		/* 1326 */setBlock(world, i + 5, j + 42, k + 30, Blocks.leaves, 15);
		/* 1327 */world.setBlockMetadataWithNotify(i + 5, j + 42, k + 30, 15, 2);
		/* 1328 */setBlock(world, i + 5, j + 42, k + 31, Blocks.leaves, 15);
		/* 1329 */world.setBlockMetadataWithNotify(i + 5, j + 42, k + 31, 15, 2);
		/* 1330 */setBlock(world, i + 5, j + 43, k + 15, Blocks.spruce_stairs, 2);
		/* 1331 */world.setBlockMetadataWithNotify(i + 5, j + 43, k + 15, 2, 2);
		/* 1332 */setBlock(world, i + 5, j + 43, k + 16, Blocks.planks, 5);
		/* 1333 */world.setBlockMetadataWithNotify(i + 5, j + 43, k + 16, 5, 2);
		/* 1334 */setBlock(world, i + 5, j + 43, k + 17, Blocks.planks, 5);
		/* 1335 */world.setBlockMetadataWithNotify(i + 5, j + 43, k + 17, 5, 2);
		/* 1336 */setBlock(world, i + 5, j + 43, k + 18, Blocks.planks, 5);
		/* 1337 */world.setBlockMetadataWithNotify(i + 5, j + 43, k + 18, 5, 2);
		/* 1338 */setBlock(world, i + 5, j + 43, k + 19, Blocks.log, 1);
		/* 1339 */world.setBlockMetadataWithNotify(i + 5, j + 43, k + 19, 1, 2);
		/* 1340 */setBlock(world, i + 5, j + 43, k + 20, Blocks.log, 1);
		/* 1341 */world.setBlockMetadataWithNotify(i + 5, j + 43, k + 20, 1, 2);
		/* 1342 */setBlock(world, i + 5, j + 43, k + 21, Blocks.planks, 5);
		/* 1343 */world.setBlockMetadataWithNotify(i + 5, j + 43, k + 21, 5, 2);
		/* 1344 */setBlock(world, i + 5, j + 43, k + 22, Blocks.planks, 5);
		/* 1345 */world.setBlockMetadataWithNotify(i + 5, j + 43, k + 22, 5, 2);
		/* 1346 */setBlock(world, i + 5, j + 43, k + 23, Blocks.planks, 5);
		/* 1347 */world.setBlockMetadataWithNotify(i + 5, j + 43, k + 23, 5, 2);
		/* 1348 */setBlock(world, i + 5, j + 43, k + 24, Blocks.planks, 5);
		/* 1349 */world.setBlockMetadataWithNotify(i + 5, j + 43, k + 24, 5, 2);
		/* 1350 */setBlock(world, i + 5, j + 43, k + 25, Blocks.planks, 5);
		/* 1351 */world.setBlockMetadataWithNotify(i + 5, j + 43, k + 25, 5, 2);
		/* 1352 */setBlock(world, i + 5, j + 43, k + 26, Blocks.log, 1);
		/* 1353 */world.setBlockMetadataWithNotify(i + 5, j + 43, k + 26, 1, 2);
		/* 1354 */setBlock(world, i + 5, j + 43, k + 27, Blocks.log, 1);
		/* 1355 */world.setBlockMetadataWithNotify(i + 5, j + 43, k + 27, 1, 2);
		/* 1356 */setBlock(world, i + 5, j + 43, k + 28, Blocks.planks, 5);
		/* 1357 */world.setBlockMetadataWithNotify(i + 5, j + 43, k + 28, 5, 2);
		/* 1358 */setBlock(world, i + 5, j + 43, k + 29, Blocks.log, 1);
		/* 1359 */world.setBlockMetadataWithNotify(i + 5, j + 43, k + 29, 1, 2);
		/* 1360 */setBlock(world, i + 5, j + 43, k + 30, Blocks.log, 1);
		/* 1361 */world.setBlockMetadataWithNotify(i + 5, j + 43, k + 30, 1, 2);
		/* 1362 */setBlock(world, i + 5, j + 43, k + 31, Blocks.log, 1);
		/* 1363 */world.setBlockMetadataWithNotify(i + 5, j + 43, k + 31, 1, 2);
		/* 1364 */setBlock(world, i + 5, j + 44, k + 29, Blocks.spruce_stairs, 2);
		/* 1365 */world.setBlockMetadataWithNotify(i + 5, j + 44, k + 29, 2, 2);
		/* 1366 */setBlock(world, i + 5, j + 44, k + 30, Blocks.log, 1);
		/* 1367 */world.setBlockMetadataWithNotify(i + 5, j + 44, k + 30, 1, 2);
		/* 1368 */setBlock(world, i + 5, j + 44, k + 31, Blocks.log, 1);
		/* 1369 */world.setBlockMetadataWithNotify(i + 5, j + 44, k + 31, 1, 2);
		/* 1370 */setBlock(world, i + 5, j + 45, k + 30, Blocks.log, 1);
		/* 1371 */world.setBlockMetadataWithNotify(i + 5, j + 45, k + 30, 1, 2);
		/* 1372 */setBlock(world, i + 5, j + 45, k + 31, Blocks.log, 1);
		/* 1373 */world.setBlockMetadataWithNotify(i + 5, j + 45, k + 31, 1, 2);
		/* 1374 */setBlock(world, i + 5, j + 46, k + 29, Blocks.torch, 4);
		/* 1375 */world.setBlockMetadataWithNotify(i + 5, j + 46, k + 29, 4, 2);
		/* 1376 */setBlock(world, i + 5, j + 46, k + 30, Blocks.log, 1);
		/* 1377 */world.setBlockMetadataWithNotify(i + 5, j + 46, k + 30, 1, 2);
		/* 1378 */setBlock(world, i + 5, j + 46, k + 31, Blocks.log, 1);
		/* 1379 */world.setBlockMetadataWithNotify(i + 5, j + 46, k + 31, 1, 2);
		/* 1380 */setBlock(world, i + 5, j + 47, k + 30, Blocks.log, 1);
		/* 1381 */world.setBlockMetadataWithNotify(i + 5, j + 47, k + 30, 1, 2);
		/* 1382 */setBlock(world, i + 5, j + 47, k + 31, Blocks.log, 1);
		/* 1383 */world.setBlockMetadataWithNotify(i + 5, j + 47, k + 31, 1, 2);
		/* 1384 */setBlock(world, i + 5, j + 48, k + 17, Blocks.log, 1);
		/* 1385 */world.setBlockMetadataWithNotify(i + 5, j + 48, k + 17, 1, 2);
		/* 1386 */setBlock(world, i + 5, j + 48, k + 18, Blocks.log, 1);
		/* 1387 */world.setBlockMetadataWithNotify(i + 5, j + 48, k + 18, 1, 2);
		/* 1388 */setBlock(world, i + 5, j + 48, k + 19, Blocks.log, 1);
		/* 1389 */world.setBlockMetadataWithNotify(i + 5, j + 48, k + 19, 1, 2);
		/* 1390 */setBlock(world, i + 5, j + 48, k + 20, Blocks.log, 1);
		/* 1391 */world.setBlockMetadataWithNotify(i + 5, j + 48, k + 20, 1, 2);
		/* 1392 */setBlock(world, i + 5, j + 48, k + 21, Blocks.log, 1);
		/* 1393 */world.setBlockMetadataWithNotify(i + 5, j + 48, k + 21, 1, 2);
		/* 1394 */setBlock(world, i + 5, j + 48, k + 30, Blocks.log, 1);
		/* 1395 */world.setBlockMetadataWithNotify(i + 5, j + 48, k + 30, 1, 2);
		/* 1396 */setBlock(world, i + 5, j + 48, k + 31, Blocks.log, 1);
		/* 1397 */world.setBlockMetadataWithNotify(i + 5, j + 48, k + 31, 1, 2);
		/* 1398 */setBlock(world, i + 5, j + 49, k + 18, Blocks.log, 1);
		/* 1399 */world.setBlockMetadataWithNotify(i + 5, j + 49, k + 18, 1, 2);
		/* 1400 */setBlock(world, i + 5, j + 49, k + 19, Blocks.log, 1);
		/* 1401 */world.setBlockMetadataWithNotify(i + 5, j + 49, k + 19, 1, 2);
		/* 1402 */setBlock(world, i + 5, j + 49, k + 20, Blocks.log, 1);
		/* 1403 */world.setBlockMetadataWithNotify(i + 5, j + 49, k + 20, 1, 2);
		/* 1404 */setBlock(world, i + 5, j + 49, k + 21, Blocks.log, 1);
		/* 1405 */world.setBlockMetadataWithNotify(i + 5, j + 49, k + 21, 1, 2);
		/* 1406 */setBlock(world, i + 5, j + 49, k + 22, Blocks.log, 1);
		/* 1407 */world.setBlockMetadataWithNotify(i + 5, j + 49, k + 22, 1, 2);
		/* 1408 */setBlock(world, i + 5, j + 49, k + 30, Blocks.log, 1);
		/* 1409 */world.setBlockMetadataWithNotify(i + 5, j + 49, k + 30, 1, 2);
		/* 1410 */setBlock(world, i + 5, j + 49, k + 31, Blocks.log, 1);
		/* 1411 */world.setBlockMetadataWithNotify(i + 5, j + 49, k + 31, 1, 2);
		/* 1412 */setBlock(world, i + 5, j + 50, k + 20, Blocks.log, 1);
		/* 1413 */world.setBlockMetadataWithNotify(i + 5, j + 50, k + 20, 1, 2);
		/* 1414 */setBlock(world, i + 5, j + 50, k + 21, Blocks.log, 1);
		/* 1415 */world.setBlockMetadataWithNotify(i + 5, j + 50, k + 21, 1, 2);
		/* 1416 */setBlock(world, i + 5, j + 50, k + 22, Blocks.log, 1);
		/* 1417 */world.setBlockMetadataWithNotify(i + 5, j + 50, k + 22, 1, 2);
		/* 1418 */setBlock(world, i + 5, j + 50, k + 23, Blocks.log, 1);
		/* 1419 */world.setBlockMetadataWithNotify(i + 5, j + 50, k + 23, 1, 2);
		/* 1420 */setBlock(world, i + 5, j + 50, k + 29, Blocks.log, 1);
		/* 1421 */world.setBlockMetadataWithNotify(i + 5, j + 50, k + 29, 1, 2);
		/* 1422 */setBlock(world, i + 5, j + 50, k + 30, Blocks.log, 1);
		/* 1423 */world.setBlockMetadataWithNotify(i + 5, j + 50, k + 30, 1, 2);
		/* 1424 */setBlock(world, i + 5, j + 50, k + 31, Blocks.log, 1);
		/* 1425 */world.setBlockMetadataWithNotify(i + 5, j + 50, k + 31, 1, 2);
		/* 1426 */setBlock(world, i + 5, j + 51, k + 24, Blocks.log, 1);
		/* 1427 */world.setBlockMetadataWithNotify(i + 5, j + 51, k + 24, 1, 2);
		/* 1428 */setBlock(world, i + 5, j + 51, k + 25, Blocks.log, 1);
		/* 1429 */world.setBlockMetadataWithNotify(i + 5, j + 51, k + 25, 1, 2);
		/* 1430 */setBlock(world, i + 5, j + 51, k + 26, Blocks.log, 1);
		/* 1431 */world.setBlockMetadataWithNotify(i + 5, j + 51, k + 26, 1, 2);
		/* 1432 */setBlock(world, i + 5, j + 51, k + 27, Blocks.log, 1);
		/* 1433 */world.setBlockMetadataWithNotify(i + 5, j + 51, k + 27, 1, 2);
		/* 1434 */setBlock(world, i + 5, j + 51, k + 28, Blocks.log, 1);
		/* 1435 */world.setBlockMetadataWithNotify(i + 5, j + 51, k + 28, 1, 2);
		/* 1436 */setBlock(world, i + 5, j + 51, k + 29, Blocks.log, 1);
		/* 1437 */world.setBlockMetadataWithNotify(i + 5, j + 51, k + 29, 1, 2);
		/* 1438 */setBlock(world, i + 5, j + 51, k + 30, Blocks.log, 1);
		/* 1439 */world.setBlockMetadataWithNotify(i + 5, j + 51, k + 30, 1, 2);
		/* 1440 */setBlock(world, i + 5, j + 51, k + 31, Blocks.log, 1);
		/* 1441 */world.setBlockMetadataWithNotify(i + 5, j + 51, k + 31, 1, 2);
		/* 1442 */setBlock(world, i + 6, j + 26, k + 26, Blocks.leaves, 15);
		/* 1443 */world.setBlockMetadataWithNotify(i + 6, j + 26, k + 26, 15, 2);
		/* 1444 */setBlock(world, i + 6, j + 26, k + 27, Blocks.leaves, 15);
		/* 1445 */world.setBlockMetadataWithNotify(i + 6, j + 26, k + 27, 15, 2);
		/* 1446 */setBlock(world, i + 6, j + 26, k + 28, Blocks.leaves, 15);
		/* 1447 */world.setBlockMetadataWithNotify(i + 6, j + 26, k + 28, 15, 2);
		/* 1448 */setBlock(world, i + 6, j + 26, k + 29, Blocks.leaves, 15);
		/* 1449 */world.setBlockMetadataWithNotify(i + 6, j + 26, k + 29, 15, 2);
		/* 1450 */setBlock(world, i + 6, j + 26, k + 30, Blocks.leaves, 15);
		/* 1451 */world.setBlockMetadataWithNotify(i + 6, j + 26, k + 30, 15, 2);
		/* 1452 */setBlock(world, i + 6, j + 27, k + 28, Blocks.leaves, 15);
		/* 1453 */world.setBlockMetadataWithNotify(i + 6, j + 27, k + 28, 15, 2);
		/* 1454 */setBlock(world, i + 6, j + 27, k + 29, Blocks.leaves, 15);
		/* 1455 */world.setBlockMetadataWithNotify(i + 6, j + 27, k + 29, 15, 2);
		/* 1456 */setBlock(world, i + 6, j + 27, k + 30, Blocks.log, 1);
		/* 1457 */world.setBlockMetadataWithNotify(i + 6, j + 27, k + 30, 1, 2);
		/* 1458 */setBlock(world, i + 6, j + 27, k + 31, Blocks.planks, 5);
		/* 1459 */world.setBlockMetadataWithNotify(i + 6, j + 27, k + 31, 5, 2);
		/* 1460 */setBlock(world, i + 6, j + 29, k + 30, Blocks.torch, 5);
		/* 1461 */world.setBlockMetadataWithNotify(i + 6, j + 29, k + 30, 5, 2);
		/* 1462 */setBlock(world, i + 6, j + 31, k + 26, Blocks.log, 1);
		/* 1463 */world.setBlockMetadataWithNotify(i + 6, j + 31, k + 26, 1, 2);
		/* 1464 */setBlock(world, i + 6, j + 31, k + 27, Blocks.log, 1);
		/* 1465 */world.setBlockMetadataWithNotify(i + 6, j + 31, k + 27, 1, 2);
		/* 1466 */setBlock(world, i + 6, j + 31, k + 28, Blocks.log, 1);
		/* 1467 */world.setBlockMetadataWithNotify(i + 6, j + 31, k + 28, 1, 2);
		/* 1468 */setBlock(world, i + 6, j + 31, k + 29, Blocks.log, 1);
		/* 1469 */world.setBlockMetadataWithNotify(i + 6, j + 31, k + 29, 1, 2);
		/* 1470 */setBlock(world, i + 6, j + 31, k + 30, Blocks.log, 1);
		/* 1471 */world.setBlockMetadataWithNotify(i + 6, j + 31, k + 30, 1, 2);
		/* 1472 */setBlock(world, i + 6, j + 32, k + 22, Blocks.leaves, 7);
		/* 1473 */world.setBlockMetadataWithNotify(i + 6, j + 32, k + 22, 7, 2);
		/* 1474 */setBlock(world, i + 6, j + 32, k + 23, Blocks.leaves, 7);
		/* 1475 */world.setBlockMetadataWithNotify(i + 6, j + 32, k + 23, 7, 2);
		/* 1476 */setBlock(world, i + 6, j + 32, k + 24, Blocks.leaves, 7);
		/* 1477 */world.setBlockMetadataWithNotify(i + 6, j + 32, k + 24, 7, 2);
		/* 1478 */setBlock(world, i + 6, j + 32, k + 28, Blocks.log, 1);
		/* 1479 */world.setBlockMetadataWithNotify(i + 6, j + 32, k + 28, 1, 2);
		/* 1480 */setBlock(world, i + 6, j + 32, k + 29, Blocks.log, 1);
		/* 1481 */world.setBlockMetadataWithNotify(i + 6, j + 32, k + 29, 1, 2);
		/* 1482 */setBlock(world, i + 6, j + 32, k + 30, Blocks.log, 1);
		/* 1483 */world.setBlockMetadataWithNotify(i + 6, j + 32, k + 30, 1, 2);
		/* 1484 */setBlock(world, i + 6, j + 32, k + 31, Blocks.log, 1);
		/* 1485 */world.setBlockMetadataWithNotify(i + 6, j + 32, k + 31, 1, 2);
		/* 1486 */setBlock(world, i + 6, j + 33, k + 23, Blocks.leaves, 7);
		/* 1487 */world.setBlockMetadataWithNotify(i + 6, j + 33, k + 23, 7, 2);
		/* 1488 */setBlock(world, i + 6, j + 33, k + 28, Blocks.log, 1);
		/* 1489 */world.setBlockMetadataWithNotify(i + 6, j + 33, k + 28, 1, 2);
		/* 1490 */setBlock(world, i + 6, j + 33, k + 29, Blocks.log, 1);
		/* 1491 */world.setBlockMetadataWithNotify(i + 6, j + 33, k + 29, 1, 2);
		/* 1492 */setBlock(world, i + 6, j + 33, k + 30, Blocks.log, 1);
		/* 1493 */world.setBlockMetadataWithNotify(i + 6, j + 33, k + 30, 1, 2);
		/* 1494 */setBlock(world, i + 6, j + 33, k + 31, Blocks.log, 1);
		/* 1495 */world.setBlockMetadataWithNotify(i + 6, j + 33, k + 31, 1, 2);
		/* 1496 */setBlock(world, i + 6, j + 34, k + 29, Blocks.log, 1);
		/* 1497 */world.setBlockMetadataWithNotify(i + 6, j + 34, k + 29, 1, 2);
		/* 1498 */setBlock(world, i + 6, j + 34, k + 30, Blocks.log, 1);
		/* 1499 */world.setBlockMetadataWithNotify(i + 6, j + 34, k + 30, 1, 2);
		/*      */
		/* 1501 */generate91(world, rand, i, j, k);
		/* 1502 */return true;
		/*      */}

	/*      */
	/*      */public boolean generate91(World world, Random rand, int i, int j, int k)
	/*      */
	{
		/* 1507 */setBlock(world, i + 6, j + 34, k + 31, Blocks.log, 1);
		/* 1508 */world.setBlockMetadataWithNotify(i + 6, j + 34, k + 31, 1, 2);
		/* 1509 */setBlock(world, i + 6, j + 35, k + 15, Blocks.vine, 14);
		/* 1510 */world.setBlockMetadataWithNotify(i + 6, j + 35, k + 15, 14, 2);
		/* 1511 */setBlock(world, i + 6, j + 35, k + 30, Blocks.log, 1);
		/* 1512 */world.setBlockMetadataWithNotify(i + 6, j + 35, k + 30, 1, 2);
		/* 1513 */setBlock(world, i + 6, j + 35, k + 31, Blocks.log, 1);
		/* 1514 */world.setBlockMetadataWithNotify(i + 6, j + 35, k + 31, 1, 2);
		/* 1515 */setBlock(world, i + 6, j + 36, k + 15, Blocks.vine, 14);
		/* 1516 */world.setBlockMetadataWithNotify(i + 6, j + 36, k + 15, 14, 2);
		/* 1517 */setBlock(world, i + 6, j + 37, k + 14, Blocks.vine, 15);
		/* 1518 */world.setBlockMetadataWithNotify(i + 6, j + 37, k + 14, 15, 2);
		/* 1519 */setBlock(world, i + 6, j + 37, k + 15, Blocks.vine, 15);
		/* 1520 */world.setBlockMetadataWithNotify(i + 6, j + 37, k + 15, 15, 2);
		/* 1521 */setBlock(world, i + 6, j + 37, k + 30, Blocks.leaves, 7);
		/* 1522 */world.setBlockMetadataWithNotify(i + 6, j + 37, k + 30, 7, 2);
		/* 1523 */setBlock(world, i + 6, j + 37, k + 31, Blocks.leaves, 7);
		/* 1524 */world.setBlockMetadataWithNotify(i + 6, j + 37, k + 31, 7, 2);
		/* 1525 */setBlock(world, i + 6, j + 38, k + 14, Blocks.vine, 15);
		/* 1526 */world.setBlockMetadataWithNotify(i + 6, j + 38, k + 14, 15, 2);
		/* 1527 */setBlock(world, i + 6, j + 38, k + 15, Blocks.vine, 15);
		/* 1528 */world.setBlockMetadataWithNotify(i + 6, j + 38, k + 15, 15, 2);
		/* 1529 */setBlock(world, i + 6, j + 38, k + 31, Blocks.leaves, 7);
		/* 1530 */world.setBlockMetadataWithNotify(i + 6, j + 38, k + 31, 7, 2);
		/* 1531 */setBlock(world, i + 6, j + 39, k + 14, Blocks.vine, 15);
		/* 1532 */world.setBlockMetadataWithNotify(i + 6, j + 39, k + 14, 15, 2);
		/* 1533 */setBlock(world, i + 6, j + 39, k + 15, Blocks.vine, 15);
		/* 1534 */world.setBlockMetadataWithNotify(i + 6, j + 39, k + 15, 15, 2);
		/* 1535 */setBlock(world, i + 6, j + 39, k + 31, Blocks.log, 1);
		/* 1536 */world.setBlockMetadataWithNotify(i + 6, j + 39, k + 31, 1, 2);
		/* 1537 */setBlock(world, i + 6, j + 40, k + 14, Blocks.vine, 15);
		/* 1538 */world.setBlockMetadataWithNotify(i + 6, j + 40, k + 14, 15, 2);
		/* 1539 */setBlock(world, i + 6, j + 40, k + 15, Blocks.vine, 15);
		/* 1540 */world.setBlockMetadataWithNotify(i + 6, j + 40, k + 15, 15, 2);
		/* 1541 */setBlock(world, i + 6, j + 40, k + 29, Blocks.log, 1);
		/* 1542 */world.setBlockMetadataWithNotify(i + 6, j + 40, k + 29, 1, 2);
		/* 1543 */setBlock(world, i + 6, j + 40, k + 30, Blocks.log, 1);
		/* 1544 */world.setBlockMetadataWithNotify(i + 6, j + 40, k + 30, 1, 2);
		/* 1545 */setBlock(world, i + 6, j + 40, k + 31, Blocks.log, 1);
		/* 1546 */world.setBlockMetadataWithNotify(i + 6, j + 40, k + 31, 1, 2);
		/* 1547 */setBlock(world, i + 6, j + 41, k + 14, Blocks.vine, 15);
		/* 1548 */world.setBlockMetadataWithNotify(i + 6, j + 41, k + 14, 15, 2);
		/* 1549 */setBlock(world, i + 6, j + 41, k + 15, Blocks.vine, 15);
		/* 1550 */world.setBlockMetadataWithNotify(i + 6, j + 41, k + 15, 15, 2);
		/* 1551 */setBlock(world, i + 6, j + 41, k + 28, Blocks.log, 1);
		/* 1552 */world.setBlockMetadataWithNotify(i + 6, j + 41, k + 28, 1, 2);
		/* 1553 */setBlock(world, i + 6, j + 41, k + 29, Blocks.log, 1);
		/* 1554 */world.setBlockMetadataWithNotify(i + 6, j + 41, k + 29, 1, 2);
		/* 1555 */setBlock(world, i + 6, j + 41, k + 30, Blocks.log, 1);
		/* 1556 */world.setBlockMetadataWithNotify(i + 6, j + 41, k + 30, 1, 2);
		/* 1557 */setBlock(world, i + 6, j + 41, k + 31, Blocks.log, 1);
		/* 1558 */world.setBlockMetadataWithNotify(i + 6, j + 41, k + 31, 1, 2);
		/* 1559 */setBlock(world, i + 6, j + 42, k + 9, Blocks.planks, 5);
		/* 1560 */world.setBlockMetadataWithNotify(i + 6, j + 42, k + 9, 5, 2);
		/* 1561 */setBlock(world, i + 6, j + 42, k + 10, Blocks.planks, 5);
		/* 1562 */world.setBlockMetadataWithNotify(i + 6, j + 42, k + 10, 5, 2);
		/* 1563 */setBlock(world, i + 6, j + 42, k + 11, Blocks.planks, 5);
		/* 1564 */world.setBlockMetadataWithNotify(i + 6, j + 42, k + 11, 5, 2);
		/* 1565 */setBlock(world, i + 6, j + 42, k + 12, Blocks.planks, 5);
		/* 1566 */world.setBlockMetadataWithNotify(i + 6, j + 42, k + 12, 5, 2);
		/* 1567 */setBlock(world, i + 6, j + 42, k + 13, Blocks.planks, 5);
		/* 1568 */world.setBlockMetadataWithNotify(i + 6, j + 42, k + 13, 5, 2);
		/* 1569 */setBlock(world, i + 6, j + 42, k + 14, Blocks.planks, 5);
