package com.parzivail.pswm.world.gen.wookietree;




import com.parzivail.pswm.utils.LootGenUtils;
import com.parzivail.pswm.utils.NPCType;
import com.parzivail.pswm.utils.SpawnUtils;



import cpw.mods.fml.common.IWorldGenerator;



import java.util.Random;



import net.minecraft.block.Block;

import net.minecraft.init.Blocks;

import net.minecraft.tileentity.TileEntityChest;

import net.minecraft.world.World;

import net.minecraft.world.WorldProvider;

import net.minecraft.world.chunk.IChunkProvider;

import net.minecraft.world.gen.feature.WorldGenerator;


public class WT_42
extends WorldGenerator implements IWorldGenerator

{
	protected Block[] getValidSpawnBlocks()
	
	{
		return new Block[0];
		}

	
	public boolean locationIsValidSpawn(World world, int i, int j, int k)
	
	{
		int distanceToAir = 0;
		Block check = world.getBlock(i, j, k);
		
		while (check != Blocks.air)
		{
			if (distanceToAir > 3) { return false;
			}
			
			distanceToAir++;
			check = world.getBlock(i, j + distanceToAir, k);
			}
		
		j += distanceToAir - 1;
		
		Block block = world.getBlock(i, j, k);
		Block blockAbove = world.getBlock(i, j + 1, k);
		Block blockBelow = world.getBlock(i, j - 1, k);
		
		for (Block x : getValidSpawnBlocks())
		{
			if (blockAbove != Blocks.air) { return false;
			}
			if (block == x) return true;
			if ((block == Blocks.snow) && (blockBelow == x)) { return true;
			}
			}
		
		return false;
		}

	
	
	
	public void generate(Random random, int chunkX, int chunkZ, World world, IChunkProvider chunkGenerator, IChunkProvider chunkProvider)
	{
	}

	
	
	public void setBlock(World world, int x, int y, int z, Block block, int metadata)
	
	{
		world.setBlock(x, y, z, block, metadata, 2);
		}

	
	public boolean generate(World world, Random rand, int i, int j, int k)
	
	{
		k -= 10;
		i -= 10;
		
		setBlock(world, i + 0, j + 21, k + 20, Blocks.crafting_table, 0);
		setBlock(world, i + 0, j + 21, k + 21, Blocks.spruce_stairs, 0);
		setBlock(world, i + 1, j + 50, k + 17, Blocks.fence, 0);
		setBlock(world, i + 1, j + 50, k + 26, Blocks.fence, 0);
		setBlock(world, i + 2, j + 50, k + 16, Blocks.fence, 0);
		setBlock(world, i + 2, j + 50, k + 17, Blocks.fence, 0);
		setBlock(world, i + 2, j + 50, k + 26, Blocks.fence, 0);
		setBlock(world, i + 2, j + 50, k + 27, Blocks.fence, 0);
		SpawnUtils.spawnNPC(NPCType.WOOKIETREE, world, i + 3, j + 21, k + 19);
		SpawnUtils.spawnNPC(NPCType.WOOKIETREE, world, i + 3, j + 21, k + 23);
		setBlock(world, i + 3, j + 50, k + 15, Blocks.fence, 0);
		setBlock(world, i + 3, j + 50, k + 16, Blocks.fence, 0);
		setBlock(world, i + 3, j + 50, k + 27, Blocks.fence, 0);
		setBlock(world, i + 3, j + 50, k + 28, Blocks.fence, 0);
		setBlock(world, i + 4, j + 21, k + 16, Blocks.fence, 0);
		setBlock(world, i + 4, j + 21, k + 26, Blocks.fence, 0);
		setBlock(world, i + 4, j + 23, k + 13, Blocks.fence, 0);
		setBlock(world, i + 4, j + 23, k + 14, Blocks.fence, 0);
		setBlock(world, i + 4, j + 23, k + 28, Blocks.fence, 0);
		setBlock(world, i + 4, j + 23, k + 29, Blocks.fence, 0);
		setBlock(world, i + 4, j + 47, k + 17, Blocks.fence, 0);
		setBlock(world, i + 4, j + 47, k + 26, Blocks.fence, 0);
		setBlock(world, i + 4, j + 50, k + 15, Blocks.fence, 0);
		setBlock(world, i + 4, j + 50, k + 28, Blocks.fence, 0);
		setBlock(world, i + 5, j + 21, k + 16, Blocks.fence, 0);
		setBlock(world, i + 5, j + 21, k + 17, Blocks.fence, 0);
		setBlock(world, i + 5, j + 21, k + 25, Blocks.fence, 0);
		setBlock(world, i + 5, j + 21, k + 26, Blocks.fence, 0);
		setBlock(world, i + 5, j + 47, k + 17, Blocks.fence, 0);
		setBlock(world, i + 5, j + 47, k + 26, Blocks.fence, 0);
		setBlock(world, i + 5, j + 50, k + 14, Blocks.fence, 0);
		setBlock(world, i + 5, j + 50, k + 15, Blocks.fence, 0);
		setBlock(world, i + 5, j + 50, k + 28, Blocks.fence, 0);
		setBlock(world, i + 5, j + 50, k + 29, Blocks.fence, 0);
		setBlock(world, i + 6, j + 21, k + 17, Blocks.fence, 0);
		setBlock(world, i + 6, j + 21, k + 18, Blocks.fence, 0);
		setBlock(world, i + 6, j + 21, k + 19, Blocks.spruce_stairs, 0);
		setBlock(world, i + 6, j + 21, k + 23, Blocks.spruce_stairs, 0);
		setBlock(world, i + 6, j + 21, k + 24, Blocks.fence, 0);
		setBlock(world, i + 6, j + 21, k + 25, Blocks.fence, 0);
		setBlock(world, i + 6, j + 47, k + 16, Blocks.fence, 0);
		setBlock(world, i + 6, j + 47, k + 17, Blocks.fence, 0);
		setBlock(world, i + 6, j + 47, k + 26, Blocks.fence, 0);
		setBlock(world, i + 6, j + 47, k + 27, Blocks.fence, 0);
		setBlock(world, i + 6, j + 50, k + 14, Blocks.fence, 0);
		setBlock(world, i + 6, j + 50, k + 29, Blocks.fence, 0);
		setBlock(world, i + 7, j + 47, k + 16, Blocks.fence, 0);
		setBlock(world, i + 7, j + 47, k + 27, Blocks.fence, 0);
		setBlock(world, i + 7, j + 50, k + 14, Blocks.fence, 0);
		setBlock(world, i + 7, j + 50, k + 29, Blocks.fence, 0);
		setBlock(world, i + 8, j + 23, k + 18, Blocks.fence, 0);
		setBlock(world, i + 8, j + 23, k + 24, Blocks.fence, 0);
		setBlock(world, i + 8, j + 47, k + 15, Blocks.spruce_stairs, 0);
		setBlock(world, i + 8, j + 47, k + 16, Blocks.fence, 0);
		setBlock(world, i + 8, j + 47, k + 27, Blocks.fence, 0);
		setBlock(world, i + 8, j + 50, k + 13, Blocks.fence, 0);
		setBlock(world, i + 8, j + 50, k + 14, Blocks.fence, 0);
		setBlock(world, i + 8, j + 50, k + 29, Blocks.fence, 0);
		setBlock(world, i + 8, j + 50, k + 30, Blocks.fence, 0);
		setBlock(world, i + 9, j + 23, k + 18, Blocks.fence, 0);
		setBlock(world, i + 9, j + 23, k + 24, Blocks.fence, 0);
		SpawnUtils.spawnNPC(NPCType.WOOKIETREE, world, i + 9, j + 47, k + 19);
		SpawnUtils.spawnNPC(NPCType.WOOKIETREE, world, i + 9, j + 47, k + 24);
		setBlock(world, i + 11, j + 47, k + 21, Blocks.spruce_stairs, 0);
		setBlock(world, i + 11, j + 47, k + 22, Blocks.spruce_stairs, 0);
		setBlock(world, i + 14, j + 47, k + 20, Blocks.crafting_table, 0);
		setBlock(world, i + 15, j + 21, k + 15, Blocks.spruce_stairs, 0);
		setBlock(world, i + 15, j + 21, k + 16, Blocks.spruce_stairs, 0);
		setBlock(world, i + 15, j + 21, k + 17, Blocks.spruce_stairs, 0);
		setBlock(world, i + 15, j + 21, k + 18, Blocks.spruce_stairs, 0);
		setBlock(world, i + 15, j + 21, k + 19, Blocks.spruce_stairs, 0);
		setBlock(world, i + 15, j + 47, k + 15, Blocks.spruce_stairs, 0);
		setBlock(world, i + 15, j + 47, k + 28, Blocks.spruce_stairs, 0);
		setBlock(world, i + 16, j + 22, k + 15, Blocks.spruce_stairs, 0);
		setBlock(world, i + 16, j + 22, k + 16, Blocks.spruce_stairs, 0);
		setBlock(world, i + 16, j + 22, k + 17, Blocks.spruce_stairs, 0);
		setBlock(world, i + 16, j + 22, k + 18, Blocks.spruce_stairs, 0);
		setBlock(world, i + 16, j + 22, k + 19, Blocks.spruce_stairs, 0);
		SpawnUtils.spawnNPC(NPCType.WOOKIETREE, world, i + 16, j + 47, k + 19);
		SpawnUtils.spawnNPC(NPCType.WOOKIETREE, world, i + 16, j + 47, k + 24);
		setBlock(world, i + 17, j + 23, k + 15, Blocks.spruce_stairs, 0);
		setBlock(world, i + 17, j + 23, k + 16, Blocks.spruce_stairs, 0);
		setBlock(world, i + 17, j + 23, k + 17, Blocks.spruce_stairs, 0);
		setBlock(world, i + 17, j + 23, k + 18, Blocks.spruce_stairs, 0);
		setBlock(world, i + 17, j + 23, k + 19, Blocks.spruce_stairs, 0);
		setBlock(world, i + 17, j + 47, k + 16, Blocks.fence, 0);
		setBlock(world, i + 17, j + 47, k + 27, Blocks.fence, 0);
		setBlock(world, i + 17, j + 50, k + 13, Blocks.fence, 0);
		setBlock(world, i + 17, j + 50, k + 14, Blocks.fence, 0);
		setBlock(world, i + 17, j + 50, k + 29, Blocks.fence, 0);
		setBlock(world, i + 17, j + 50, k + 30, Blocks.fence, 0);
		setBlock(world, i + 18, j + 24, k + 15, Blocks.spruce_stairs, 0);
		setBlock(world, i + 18, j + 24, k + 16, Blocks.spruce_stairs, 0);
		setBlock(world, i + 18, j + 24, k + 17, Blocks.spruce_stairs, 0);
		setBlock(world, i + 18, j + 24, k + 18, Blocks.spruce_stairs, 0);
		setBlock(world, i + 18, j + 24, k + 19, Blocks.spruce_stairs, 0);
		setBlock(world, i + 18, j + 47, k + 16, Blocks.fence, 0);
		setBlock(world, i + 18, j + 47, k + 27, Blocks.fence, 0);
		setBlock(world, i + 18, j + 50, k + 14, Blocks.fence, 0);
		setBlock(world, i + 18, j + 50, k + 29, Blocks.fence, 0);
		setBlock(world, i + 19, j + 25, k + 15, Blocks.spruce_stairs, 0);
		setBlock(world, i + 19, j + 25, k + 16, Blocks.spruce_stairs, 0);
		setBlock(world, i + 19, j + 25, k + 17, Blocks.spruce_stairs, 0);
		setBlock(world, i + 19, j + 25, k + 18, Blocks.spruce_stairs, 0);
		setBlock(world, i + 19, j + 25, k + 19, Blocks.spruce_stairs, 0);
		setBlock(world, i + 19, j + 47, k + 16, Blocks.fence, 0);
		setBlock(world, i + 19, j + 47, k + 17, Blocks.fence, 0);
		setBlock(world, i + 19, j + 47, k + 26, Blocks.fence, 0);
		setBlock(world, i + 19, j + 47, k + 27, Blocks.fence, 0);
		setBlock(world, i + 19, j + 50, k + 14, Blocks.fence, 0);
		setBlock(world, i + 19, j + 50, k + 29, Blocks.fence, 0);
		setBlock(world, i + 20, j + 26, k + 15, Blocks.spruce_stairs, 0);
		setBlock(world, i + 20, j + 26, k + 16, Blocks.spruce_stairs, 0);
		setBlock(world, i + 20, j + 26, k + 17, Blocks.spruce_stairs, 0);
		setBlock(world, i + 20, j + 26, k + 18, Blocks.spruce_stairs, 0);
		setBlock(world, i + 20, j + 26, k + 19, Blocks.spruce_stairs, 0);
		setBlock(world, i + 20, j + 47, k + 17, Blocks.fence, 0);
		setBlock(world, i + 20, j + 47, k + 26, Blocks.fence, 0);
		setBlock(world, i + 20, j + 50, k + 14, Blocks.fence, 0);
		setBlock(world, i + 20, j + 50, k + 15, Blocks.fence, 0);
		setBlock(world, i + 20, j + 50, k + 28, Blocks.fence, 0);
		setBlock(world, i + 20, j + 50, k + 29, Blocks.fence, 0);
		setBlock(world, i + 21, j + 47, k + 17, Blocks.fence, 0);
		setBlock(world, i + 21, j + 47, k + 18, Blocks.spruce_stairs, 0);
		setBlock(world, i + 21, j + 47, k + 25, Blocks.spruce_stairs, 0);
		setBlock(world, i + 21, j + 47, k + 26, Blocks.fence, 0);
		setBlock(world, i + 21, j + 50, k + 15, Blocks.fence, 0);
		setBlock(world, i + 21, j + 50, k + 28, Blocks.fence, 0);
		setBlock(world, i + 22, j + 50, k + 15, Blocks.fence, 0);
		setBlock(world, i + 22, j + 50, k + 16, Blocks.fence, 0);
		setBlock(world, i + 22, j + 50, k + 27, Blocks.fence, 0);
		setBlock(world, i + 22, j + 50, k + 28, Blocks.fence, 0);
		setBlock(world, i + 23, j + 50, k + 16, Blocks.fence, 0);
		setBlock(world, i + 23, j + 50, k + 17, Blocks.fence, 0);
		setBlock(world, i + 23, j + 50, k + 26, Blocks.fence, 0);
		setBlock(world, i + 23, j + 50, k + 27, Blocks.fence, 0);
		setBlock(world, i + 24, j + 50, k + 17, Blocks.fence, 0);
		setBlock(world, i + 24, j + 50, k + 26, Blocks.fence, 0);
		setBlock(world, i + 0, j + 11, k + 20, Blocks.log, 1);
		world.setBlockMetadataWithNotify(i + 0, j + 11, k + 20, 1, 2);
		setBlock(world, i + 0, j + 11, k + 21, Blocks.log, 1);
		world.setBlockMetadataWithNotify(i + 0, j + 11, k + 21, 1, 2);
		setBlock(world, i + 0, j + 11, k + 22, Blocks.log, 1);
		world.setBlockMetadataWithNotify(i + 0, j + 11, k + 22, 1, 2);
		setBlock(world, i + 0, j + 12, k + 20, Blocks.log, 1);
		world.setBlockMetadataWithNotify(i + 0, j + 12, k + 20, 1, 2);
		setBlock(world, i + 0, j + 12, k + 21, Blocks.log, 1);
		world.setBlockMetadataWithNotify(i + 0, j + 12, k + 21, 1, 2);
		setBlock(world, i + 0, j + 12, k + 22, Blocks.log, 1);
		world.setBlockMetadataWithNotify(i + 0, j + 12, k + 22, 1, 2);
		setBlock(world, i + 0, j + 13, k + 17, Blocks.vine, 10);
		world.setBlockMetadataWithNotify(i + 0, j + 13, k + 17, 10, 2);
		setBlock(world, i + 0, j + 13, k + 18, Blocks.vine, 14);
		world.setBlockMetadataWithNotify(i + 0, j + 13, k + 18, 14, 2);
		setBlock(world, i + 0, j + 13, k + 19, Blocks.vine, 5);
		world.setBlockMetadataWithNotify(i + 0, j + 13, k + 19, 5, 2);
		setBlock(world, i + 0, j + 13, k + 20, Blocks.log, 1);
		world.setBlockMetadataWithNotify(i + 0, j + 13, k + 20, 1, 2);
		setBlock(world, i + 0, j + 13, k + 21, Blocks.log, 1);
		world.setBlockMetadataWithNotify(i + 0, j + 13, k + 21, 1, 2);
		setBlock(world, i + 0, j + 13, k + 22, Blocks.log, 1);
		world.setBlockMetadataWithNotify(i + 0, j + 13, k + 22, 1, 2);
		setBlock(world, i + 0, j + 14, k + 17, Blocks.vine, 15);
		world.setBlockMetadataWithNotify(i + 0, j + 14, k + 17, 15, 2);
		setBlock(world, i + 0, j + 14, k + 18, Blocks.vine, 15);
		world.setBlockMetadataWithNotify(i + 0, j + 14, k + 18, 15, 2);
		setBlock(world, i + 0, j + 14, k + 19, Blocks.vine, 15);
		world.setBlockMetadataWithNotify(i + 0, j + 14, k + 19, 15, 2);
		setBlock(world, i + 0, j + 14, k + 20, Blocks.log, 1);
		world.setBlockMetadataWithNotify(i + 0, j + 14, k + 20, 1, 2);
		setBlock(world, i + 0, j + 14, k + 21, Blocks.log, 1);
		world.setBlockMetadataWithNotify(i + 0, j + 14, k + 21, 1, 2);
		setBlock(world, i + 0, j + 14, k + 22, Blocks.log, 1);
		world.setBlockMetadataWithNotify(i + 0, j + 14, k + 22, 1, 2);
		setBlock(world, i + 0, j + 14, k + 23, Blocks.log, 1);
		world.setBlockMetadataWithNotify(i + 0, j + 14, k + 23, 1, 2);
		setBlock(world, i + 0, j + 14, k + 24, Blocks.log, 1);
		world.setBlockMetadataWithNotify(i + 0, j + 14, k + 24, 1, 2);
		setBlock(world, i + 0, j + 14, k + 25, Blocks.log, 1);
		world.setBlockMetadataWithNotify(i + 0, j + 14, k + 25, 1, 2);
		setBlock(world, i + 0, j + 14, k + 26, Blocks.log, 1);
		world.setBlockMetadataWithNotify(i + 0, j + 14, k + 26, 1, 2);
		setBlock(world, i + 0, j + 15, k + 17, Blocks.vine, 15);
		world.setBlockMetadataWithNotify(i + 0, j + 15, k + 17, 15, 2);
		setBlock(world, i + 0, j + 15, k + 18, Blocks.vine, 15);
		world.setBlockMetadataWithNotify(i + 0, j + 15, k + 18, 15, 2);
		setBlock(world, i + 0, j + 15, k + 19, Blocks.log, 1);
		world.setBlockMetadataWithNotify(i + 0, j + 15, k + 19, 1, 2);
		setBlock(world, i + 0, j + 15, k + 20, Blocks.vine, 15);
		world.setBlockMetadataWithNotify(i + 0, j + 15, k + 20, 15, 2);
		setBlock(world, i + 0, j + 15, k + 21, Blocks.log, 1);
		world.setBlockMetadataWithNotify(i + 0, j + 15, k + 21, 1, 2);
		setBlock(world, i + 0, j + 15, k + 22, Blocks.log, 1);
		world.setBlockMetadataWithNotify(i + 0, j + 15, k + 22, 1, 2);
		setBlock(world, i + 0, j + 15, k + 23, Blocks.log, 1);
		world.setBlockMetadataWithNotify(i + 0, j + 15, k + 23, 1, 2);
		setBlock(world, i + 0, j + 15, k + 24, Blocks.log, 1);
		world.setBlockMetadataWithNotify(i + 0, j + 15, k + 24, 1, 2);
		setBlock(world, i + 0, j + 15, k + 25, Blocks.log, 1);
		world.setBlockMetadataWithNotify(i + 0, j + 15, k + 25, 1, 2);
		setBlock(world, i + 0, j + 15, k + 26, Blocks.log, 1);
		world.setBlockMetadataWithNotify(i + 0, j + 15, k + 26, 1, 2);
		setBlock(world, i + 0, j + 15, k + 28, Blocks.log, 1);
		world.setBlockMetadataWithNotify(i + 0, j + 15, k + 28, 1, 2);
		setBlock(world, i + 0, j + 16, k + 12, Blocks.vine, 2);
		world.setBlockMetadataWithNotify(i + 0, j + 16, k + 12, 2, 2);
		setBlock(world, i + 0, j + 16, k + 17, Blocks.vine, 15);
		world.setBlockMetadataWithNotify(i + 0, j + 16, k + 17, 15, 2);
		setBlock(world, i + 0, j + 16, k + 18, Blocks.log, 1);
		world.setBlockMetadataWithNotify(i + 0, j + 16, k + 18, 1, 2);
		setBlock(world, i + 0, j + 16, k + 19, Blocks.log, 1);
		world.setBlockMetadataWithNotify(i + 0, j + 16, k + 19, 1, 2);
		setBlock(world, i + 0, j + 16, k + 20, Blocks.log, 1);
		world.setBlockMetadataWithNotify(i + 0, j + 16, k + 20, 1, 2);
		setBlock(world, i + 0, j + 16, k + 22, Blocks.log, 1);
		world.setBlockMetadataWithNotify(i + 0, j + 16, k + 22, 1, 2);
		setBlock(world, i + 0, j + 16, k + 23, Blocks.log, 1);
		world.setBlockMetadataWithNotify(i + 0, j + 16, k + 23, 1, 2);
		setBlock(world, i + 0, j + 16, k + 24, Blocks.log, 1);
		world.setBlockMetadataWithNotify(i + 0, j + 16, k + 24, 1, 2);
		setBlock(world, i + 0, j + 16, k + 25, Blocks.log, 1);
		world.setBlockMetadataWithNotify(i + 0, j + 16, k + 25, 1, 2);
		setBlock(world, i + 0, j + 16, k + 26, Blocks.log, 1);
		world.setBlockMetadataWithNotify(i + 0, j + 16, k + 26, 1, 2);
		setBlock(world, i + 0, j + 16, k + 27, Blocks.log, 1);
		world.setBlockMetadataWithNotify(i + 0, j + 16, k + 27, 1, 2);
		setBlock(world, i + 0, j + 16, k + 29, Blocks.log, 1);
		world.setBlockMetadataWithNotify(i + 0, j + 16, k + 29, 1, 2);
		setBlock(world, i + 0, j + 17, k + 12, Blocks.vine, 2);
		world.setBlockMetadataWithNotify(i + 0, j + 17, k + 12, 2, 2);
		setBlock(world, i + 0, j + 17, k + 17, Blocks.vine, 9);
		world.setBlockMetadataWithNotify(i + 0, j + 17, k + 17, 9, 2);
		setBlock(world, i + 0, j + 17, k + 19, Blocks.vine, 15);
		world.setBlockMetadataWithNotify(i + 0, j + 17, k + 19, 15, 2);
		setBlock(world, i + 0, j + 17, k + 20, Blocks.vine, 15);
		world.setBlockMetadataWithNotify(i + 0, j + 17, k + 20, 15, 2);
		setBlock(world, i + 0, j + 17, k + 21, Blocks.vine, 7);
		world.setBlockMetadataWithNotify(i + 0, j + 17, k + 21, 7, 2);
		setBlock(world, i + 0, j + 17, k + 22, Blocks.vine, 15);
		world.setBlockMetadataWithNotify(i + 0, j + 17, k + 22, 15, 2);
		setBlock(world, i + 0, j + 17, k + 23, Blocks.log, 1);
		world.setBlockMetadataWithNotify(i + 0, j + 17, k + 23, 1, 2);
		setBlock(world, i + 0, j + 17, k + 24, Blocks.log, 1);
		world.setBlockMetadataWithNotify(i + 0, j + 17, k + 24, 1, 2);
		setBlock(world, i + 0, j + 17, k + 25, Blocks.log, 1);
		world.setBlockMetadataWithNotify(i + 0, j + 17, k + 25, 1, 2);
		setBlock(world, i + 0, j + 17, k + 26, Blocks.log, 1);
		world.setBlockMetadataWithNotify(i + 0, j + 17, k + 26, 1, 2);
		setBlock(world, i + 0, j + 17, k + 28, Blocks.log, 1);
		world.setBlockMetadataWithNotify(i + 0, j + 17, k + 28, 1, 2);
		setBlock(world, i + 0, j + 18, k + 11, Blocks.vine, 15);
		world.setBlockMetadataWithNotify(i + 0, j + 18, k + 11, 15, 2);
		setBlock(world, i + 0, j + 18, k + 12, Blocks.vine, 7);
		world.setBlockMetadataWithNotify(i + 0, j + 18, k + 12, 7, 2);
		setBlock(world, i + 0, j + 18, k + 13, Blocks.vine, 11);
		world.setBlockMetadataWithNotify(i + 0, j + 18, k + 13, 11, 2);
		setBlock(world, i + 0, j + 18, k + 14, Blocks.vine, 13);
		world.setBlockMetadataWithNotify(i + 0, j + 18, k + 14, 13, 2);
		setBlock(world, i + 0, j + 18, k + 15, Blocks.vine, 14);
		world.setBlockMetadataWithNotify(i + 0, j + 18, k + 15, 14, 2);
		setBlock(world, i + 0, j + 18, k + 17, Blocks.vine, 15);
		world.setBlockMetadataWithNotify(i + 0, j + 18, k + 17, 15, 2);
		setBlock(world, i + 0, j + 18, k + 18, Blocks.vine, 15);
		world.setBlockMetadataWithNotify(i + 0, j + 18, k + 18, 15, 2);
		setBlock(world, i + 0, j + 18, k + 19, Blocks.vine, 15);
		world.setBlockMetadataWithNotify(i + 0, j + 18, k + 19, 15, 2);
		setBlock(world, i + 0, j + 18, k + 20, Blocks.vine, 15);
		world.setBlockMetadataWithNotify(i + 0, j + 18, k + 20, 15, 2);
		setBlock(world, i + 0, j + 18, k + 21, Blocks.vine, 15);
		world.setBlockMetadataWithNotify(i + 0, j + 18, k + 21, 15, 2);
		setBlock(world, i + 0, j + 18, k + 22, Blocks.vine, 15);
		world.setBlockMetadataWithNotify(i + 0, j + 18, k + 22, 15, 2);
		setBlock(world, i + 0, j + 18, k + 23, Blocks.vine, 15);
		world.setBlockMetadataWithNotify(i + 0, j + 18, k + 23, 15, 2);
		setBlock(world, i + 0, j + 18, k + 25, Blocks.log, 1);
		world.setBlockMetadataWithNotify(i + 0, j + 18, k + 25, 1, 2);
		setBlock(world, i + 0, j + 19, k + 10, Blocks.vine, 15);
		world.setBlockMetadataWithNotify(i + 0, j + 19, k + 10, 15, 2);
		setBlock(world, i + 0, j + 19, k + 11, Blocks.vine, 15);
		world.setBlockMetadataWithNotify(i + 0, j + 19, k + 11, 15, 2);
		setBlock(world, i + 0, j + 19, k + 12, Blocks.vine, 15);
		world.setBlockMetadataWithNotify(i + 0, j + 19, k + 12, 15, 2);
		setBlock(world, i + 0, j + 19, k + 13, Blocks.vine, 15);
		world.setBlockMetadataWithNotify(i + 0, j + 19, k + 13, 15, 2);
		setBlock(world, i + 0, j + 19, k + 14, Blocks.vine, 15);
		world.setBlockMetadataWithNotify(i + 0, j + 19, k + 14, 15, 2);
		setBlock(world, i + 0, j + 19, k + 15, Blocks.vine, 15);
		world.setBlockMetadataWithNotify(i + 0, j + 19, k + 15, 15, 2);
		setBlock(world, i + 0, j + 19, k + 16, Blocks.vine, 15);
		world.setBlockMetadataWithNotify(i + 0, j + 19, k + 16, 15, 2);
		setBlock(world, i + 0, j + 19, k + 17, Blocks.vine, 15);
		world.setBlockMetadataWithNotify(i + 0, j + 19, k + 17, 15, 2);
		setBlock(world, i + 0, j + 19, k + 18, Blocks.vine, 15);
		world.setBlockMetadataWithNotify(i + 0, j + 19, k + 18, 15, 2);
		setBlock(world, i + 0, j + 19, k + 19, Blocks.log, 1);
		world.setBlockMetadataWithNotify(i + 0, j + 19, k + 19, 1, 2);
		setBlock(world, i + 0, j + 19, k + 20, Blocks.log, 1);
		world.setBlockMetadataWithNotify(i + 0, j + 19, k + 20, 1, 2);
		setBlock(world, i + 0, j + 19, k + 21, Blocks.log, 1);
		world.setBlockMetadataWithNotify(i + 0, j + 19, k + 21, 1, 2);
		setBlock(world, i + 0, j + 19, k + 22, Blocks.log, 1);
		world.setBlockMetadataWithNotify(i + 0, j + 19, k + 22, 1, 2);
		setBlock(world, i + 0, j + 19, k + 23, Blocks.log, 1);
		world.setBlockMetadataWithNotify(i + 0, j + 19, k + 23, 1, 2);
		setBlock(world, i + 0, j + 19, k + 24, Blocks.log, 1);
		world.setBlockMetadataWithNotify(i + 0, j + 19, k + 24, 1, 2);
		setBlock(world, i + 0, j + 20, k + 7, Blocks.planks, 5);
		world.setBlockMetadataWithNotify(i + 0, j + 20, k + 7, 5, 2);
		setBlock(world, i + 0, j + 20, k + 8, Blocks.planks, 5);
		world.setBlockMetadataWithNotify(i + 0, j + 20, k + 8, 5, 2);
		setBlock(world, i + 0, j + 20, k + 9, Blocks.planks, 5);
		world.setBlockMetadataWithNotify(i + 0, j + 20, k + 9, 5, 2);
		setBlock(world, i + 0, j + 20, k + 10, Blocks.planks, 5);
		world.setBlockMetadataWithNotify(i + 0, j + 20, k + 10, 5, 2);
		setBlock(world, i + 0, j + 20, k + 11, Blocks.planks, 5);
		world.setBlockMetadataWithNotify(i + 0, j + 20, k + 11, 5, 2);
		setBlock(world, i + 0, j + 20, k + 12, Blocks.planks, 5);
		world.setBlockMetadataWithNotify(i + 0, j + 20, k + 12, 5, 2);
		setBlock(world, i + 0, j + 20, k + 13, Blocks.planks, 5);
		world.setBlockMetadataWithNotify(i + 0, j + 20, k + 13, 5, 2);
		setBlock(world, i + 0, j + 20, k + 14, Blocks.planks, 5);
		world.setBlockMetadataWithNotify(i + 0, j + 20, k + 14, 5, 2);
		setBlock(world, i + 0, j + 20, k + 15, Blocks.log, 1);
		world.setBlockMetadataWithNotify(i + 0, j + 20, k + 15, 1, 2);
		setBlock(world, i + 0, j + 20, k + 16, Blocks.planks, 5);
		world.setBlockMetadataWithNotify(i + 0, j + 20, k + 16, 5, 2);
		setBlock(world, i + 0, j + 20, k + 17, Blocks.planks, 5);
		world.setBlockMetadataWithNotify(i + 0, j + 20, k + 17, 5, 2);
		setBlock(world, i + 0, j + 20, k + 18, Blocks.log, 1);
		world.setBlockMetadataWithNotify(i + 0, j + 20, k + 18, 1, 2);
		setBlock(world, i + 0, j + 20, k + 19, Blocks.planks, 5);
		world.setBlockMetadataWithNotify(i + 0, j + 20, k + 19, 5, 2);
		setBlock(world, i + 0, j + 20, k + 20, Blocks.planks, 5);
		world.setBlockMetadataWithNotify(i + 0, j + 20, k + 20, 5, 2);
		setBlock(world, i + 0, j + 20, k + 21, Blocks.log, 1);
		world.setBlockMetadataWithNotify(i + 0, j + 20, k + 21, 1, 2);
		setBlock(world, i + 0, j + 20, k + 22, Blocks.planks, 5);
		world.setBlockMetadataWithNotify(i + 0, j + 20, k + 22, 5, 2);
		setBlock(world, i + 0, j + 20, k + 23, Blocks.planks, 5);
		world.setBlockMetadataWithNotify(i + 0, j + 20, k + 23, 5, 2);
		setBlock(world, i + 0, j + 20, k + 24, Blocks.log, 1);
		world.setBlockMetadataWithNotify(i + 0, j + 20, k + 24, 1, 2);
		setBlock(world, i + 0, j + 20, k + 25, Blocks.planks, 5);
		world.setBlockMetadataWithNotify(i + 0, j + 20, k + 25, 5, 2);
		setBlock(world, i + 0, j + 20, k + 26, Blocks.planks, 5);
		world.setBlockMetadataWithNotify(i + 0, j + 20, k + 26, 5, 2);
		setBlock(world, i + 0, j + 20, k + 27, Blocks.log, 1);
		world.setBlockMetadataWithNotify(i + 0, j + 20, k + 27, 1, 2);
		setBlock(world, i + 0, j + 21, k + 22, Blocks.furnace, 4);
		world.setBlockMetadataWithNotify(i + 0, j + 21, k + 22, 4, 2);
		setBlock(world, i + 0, j + 23, k + 13, Blocks.torch, 1);
		world.setBlockMetadataWithNotify(i + 0, j + 23, k + 13, 1, 2);
		setBlock(world, i + 0, j + 23, k + 21, Blocks.torch, 2);
		world.setBlockMetadataWithNotify(i + 0, j + 23, k + 21, 2, 2);
		setBlock(world, i + 0, j + 23, k + 29, Blocks.torch, 1);
		world.setBlockMetadataWithNotify(i + 0, j + 23, k + 29, 1, 2);
		setBlock(world, i + 0, j + 24, k + 12, Blocks.log, 1);
		world.setBlockMetadataWithNotify(i + 0, j + 24, k + 12, 1, 2);
		setBlock(world, i + 0, j + 24, k + 13, Blocks.log, 1);
		world.setBlockMetadataWithNotify(i + 0, j + 24, k + 13, 1, 2);
		setBlock(world, i + 0, j + 24, k + 14, Blocks.log, 1);
		world.setBlockMetadataWithNotify(i + 0, j + 24, k + 14, 1, 2);
		setBlock(world, i + 0, j + 24, k + 15, Blocks.log, 1);
		world.setBlockMetadataWithNotify(i + 0, j + 24, k + 15, 1, 2);
		setBlock(world, i + 0, j + 24, k + 16, Blocks.log, 1);
		world.setBlockMetadataWithNotify(i + 0, j + 24, k + 16, 1, 2);
		setBlock(world, i + 0, j + 24, k + 26, Blocks.log, 1);
		world.setBlockMetadataWithNotify(i + 0, j + 24, k + 26, 1, 2);
		setBlock(world, i + 0, j + 24, k + 27, Blocks.log, 1);
		world.setBlockMetadataWithNotify(i + 0, j + 24, k + 27, 1, 2);
		setBlock(world, i + 0, j + 24, k + 28, Blocks.log, 1);
		world.setBlockMetadataWithNotify(i + 0, j + 24, k + 28, 1, 2);
		setBlock(world, i + 0, j + 24, k + 29, Blocks.log, 1);
		world.setBlockMetadataWithNotify(i + 0, j + 24, k + 29, 1, 2);
		setBlock(world, i + 0, j + 24, k + 30, Blocks.log, 1);
		world.setBlockMetadataWithNotify(i + 0, j + 24, k + 30, 1, 2);
		setBlock(world, i + 0, j + 24, k + 31, Blocks.log, 3);
		world.setBlockMetadataWithNotify(i + 0, j + 24, k + 31, 3, 2);
		setBlock(world, i + 0, j + 25, k + 13, Blocks.log, 1);
		world.setBlockMetadataWithNotify(i + 0, j + 25, k + 13, 1, 2);
		setBlock(world, i + 0, j + 25, k + 14, Blocks.log, 1);
		world.setBlockMetadataWithNotify(i + 0, j + 25, k + 14, 1, 2);
		setBlock(world, i + 0, j + 25, k + 15, Blocks.log, 1);
		world.setBlockMetadataWithNotify(i + 0, j + 25, k + 15, 1, 2);
		setBlock(world, i + 0, j + 25, k + 16, Blocks.log, 1);
		world.setBlockMetadataWithNotify(i + 0, j + 25, k + 16, 1, 2);
		setBlock(world, i + 0, j + 25, k + 17, Blocks.log, 1);
		world.setBlockMetadataWithNotify(i + 0, j + 25, k + 17, 1, 2);
		setBlock(world, i + 0, j + 25, k + 25, Blocks.log, 1);
		world.setBlockMetadataWithNotify(i + 0, j + 25, k + 25, 1, 2);
		setBlock(world, i + 0, j + 25, k + 26, Blocks.log, 1);
		world.setBlockMetadataWithNotify(i + 0, j + 25, k + 26, 1, 2);
		setBlock(world, i + 0, j + 25, k + 27, Blocks.log, 1);
		world.setBlockMetadataWithNotify(i + 0, j + 25, k + 27, 1, 2);
		setBlock(world, i + 0, j + 25, k + 28, Blocks.log, 1);
		world.setBlockMetadataWithNotify(i + 0, j + 25, k + 28, 1, 2);
		setBlock(world, i + 0, j + 25, k + 29, Blocks.log, 1);
		world.setBlockMetadataWithNotify(i + 0, j + 25, k + 29, 1, 2);
		setBlock(world, i + 0, j + 25, k + 30, Blocks.log, 3);
		world.setBlockMetadataWithNotify(i + 0, j + 25, k + 30, 3, 2);
		setBlock(world, i + 0, j + 25, k + 31, Blocks.log, 3);
		world.setBlockMetadataWithNotify(i + 0, j + 25, k + 31, 3, 2);
		setBlock(world, i + 0, j + 26, k + 13, Blocks.log, 1);
		world.setBlockMetadataWithNotify(i + 0, j + 26, k + 13, 1, 2);
		setBlock(world, i + 0, j + 26, k + 14, Blocks.log, 1);
		world.setBlockMetadataWithNotify(i + 0, j + 26, k + 14, 1, 2);
		setBlock(world, i + 0, j + 26, k + 15, Blocks.log, 1);
		world.setBlockMetadataWithNotify(i + 0, j + 26, k + 15, 1, 2);
		setBlock(world, i + 0, j + 26, k + 16, Blocks.log, 1);
		world.setBlockMetadataWithNotify(i + 0, j + 26, k + 16, 1, 2);
		setBlock(world, i + 0, j + 26, k + 17, Blocks.log, 1);
		world.setBlockMetadataWithNotify(i + 0, j + 26, k + 17, 1, 2);
		setBlock(world, i + 0, j + 26, k + 18, Blocks.log, 1);
		world.setBlockMetadataWithNotify(i + 0, j + 26, k + 18, 1, 2);
		setBlock(world, i + 0, j + 26, k + 20, Blocks.log, 1);
		world.setBlockMetadataWithNotify(i + 0, j + 26, k + 20, 1, 2);
		setBlock(world, i + 0, j + 26, k + 21, Blocks.log, 1);
		world.setBlockMetadataWithNotify(i + 0, j + 26, k + 21, 1, 2);
		setBlock(world, i + 0, j + 26, k + 22, Blocks.log, 1);
		world.setBlockMetadataWithNotify(i + 0, j + 26, k + 22, 1, 2);
		setBlock(world, i + 0, j + 26, k + 24, Blocks.log, 1);
		world.setBlockMetadataWithNotify(i + 0, j + 26, k + 24, 1, 2);
		setBlock(world, i + 0, j + 26, k + 25, Blocks.log, 1);
		world.setBlockMetadataWithNotify(i + 0, j + 26, k + 25, 1, 2);
		setBlock(world, i + 0, j + 26, k + 26, Blocks.log, 1);
		world.setBlockMetadataWithNotify(i + 0, j + 26, k + 26, 1, 2);
		setBlock(world, i + 0, j + 26, k + 27, Blocks.log, 1);
		world.setBlockMetadataWithNotify(i + 0, j + 26, k + 27, 1, 2);
		setBlock(world, i + 0, j + 26, k + 28, Blocks.log, 1);
		world.setBlockMetadataWithNotify(i + 0, j + 26, k + 28, 1, 2);
		setBlock(world, i + 0, j + 26, k + 29, Blocks.log, 1);
		world.setBlockMetadataWithNotify(i + 0, j + 26, k + 29, 1, 2);
		setBlock(world, i + 0, j + 26, k + 31, Blocks.log, 3);
		world.setBlockMetadataWithNotify(i + 0, j + 26, k + 31, 3, 2);
		setBlock(world, i + 0, j + 27, k + 14, Blocks.log, 1);
		world.setBlockMetadataWithNotify(i + 0, j + 27, k + 14, 1, 2);
		setBlock(world, i + 0, j + 27, k + 15, Blocks.log, 1);
		world.setBlockMetadataWithNotify(i + 0, j + 27, k + 15, 1, 2);
		setBlock(world, i + 0, j + 27, k + 16, Blocks.log, 1);
		world.setBlockMetadataWithNotify(i + 0, j + 27, k + 16, 1, 2);
		setBlock(world, i + 0, j + 27, k + 17, Blocks.log, 1);
		world.setBlockMetadataWithNotify(i + 0, j + 27, k + 17, 1, 2);
		setBlock(world, i + 0, j + 27, k + 18, Blocks.log, 1);
		world.setBlockMetadataWithNotify(i + 0, j + 27, k + 18, 1, 2);
		setBlock(world, i + 0, j + 27, k + 19, Blocks.log, 1);
		world.setBlockMetadataWithNotify(i + 0, j + 27, k + 19, 1, 2);
		setBlock(world, i + 0, j + 27, k + 20, Blocks.log, 1);
		world.setBlockMetadataWithNotify(i + 0, j + 27, k + 20, 1, 2);
		setBlock(world, i + 0, j + 27, k + 21, Blocks.log, 1);
		world.setBlockMetadataWithNotify(i + 0, j + 27, k + 21, 1, 2);
		setBlock(world, i + 0, j + 27, k + 22, Blocks.log, 1);
		world.setBlockMetadataWithNotify(i + 0, j + 27, k + 22, 1, 2);
		setBlock(world, i + 0, j + 27, k + 23, Blocks.log, 1);
		world.setBlockMetadataWithNotify(i + 0, j + 27, k + 23, 1, 2);
		setBlock(world, i + 0, j + 27, k + 24, Blocks.log, 1);
		world.setBlockMetadataWithNotify(i + 0, j + 27, k + 24, 1, 2);
		setBlock(world, i + 0, j + 27, k + 25, Blocks.log, 1);
		world.setBlockMetadataWithNotify(i + 0, j + 27, k + 25, 1, 2);
		setBlock(world, i + 0, j + 27, k + 26, Blocks.log, 1);
		world.setBlockMetadataWithNotify(i + 0, j + 27, k + 26, 1, 2);
		setBlock(world, i + 0, j + 27, k + 27, Blocks.log, 1);
		world.setBlockMetadataWithNotify(i + 0, j + 27, k + 27, 1, 2);
		setBlock(world, i + 0, j + 27, k + 28, Blocks.log, 1);
		world.setBlockMetadataWithNotify(i + 0, j + 27, k + 28, 1, 2);
		setBlock(world, i + 0, j + 28, k + 15, Blocks.log, 1);
		world.setBlockMetadataWithNotify(i + 0, j + 28, k + 15, 1, 2);
		setBlock(world, i + 0, j + 28, k + 16, Blocks.log, 1);
		world.setBlockMetadataWithNotify(i + 0, j + 28, k + 16, 1, 2);
		setBlock(world, i + 0, j + 28, k + 17, Blocks.log, 1);
		world.setBlockMetadataWithNotify(i + 0, j + 28, k + 17, 1, 2);
		setBlock(world, i + 0, j + 28, k + 18, Blocks.log, 1);
		world.setBlockMetadataWithNotify(i + 0, j + 28, k + 18, 1, 2);
		setBlock(world, i + 0, j + 28, k + 19, Blocks.log, 1);
		world.setBlockMetadataWithNotify(i + 0, j + 28, k + 19, 1, 2);
		setBlock(world, i + 0, j + 28, k + 20, Blocks.log, 1);
		world.setBlockMetadataWithNotify(i + 0, j + 28, k + 20, 1, 2);
		setBlock(world, i + 0, j + 28, k + 21, Blocks.log, 1);
		world.setBlockMetadataWithNotify(i + 0, j + 28, k + 21, 1, 2);
		setBlock(world, i + 0, j + 28, k + 22, Blocks.log, 1);
		world.setBlockMetadataWithNotify(i + 0, j + 28, k + 22, 1, 2);
		setBlock(world, i + 0, j + 28, k + 23, Blocks.log, 1);
		world.setBlockMetadataWithNotify(i + 0, j + 28, k + 23, 1, 2);
		setBlock(world, i + 0, j + 28, k + 24, Blocks.log, 1);
		world.setBlockMetadataWithNotify(i + 0, j + 28, k + 24, 1, 2);
		setBlock(world, i + 0, j + 28, k + 25, Blocks.log, 1);
		world.setBlockMetadataWithNotify(i + 0, j + 28, k + 25, 1, 2);
		setBlock(world, i + 0, j + 28, k + 26, Blocks.log, 1);
		world.setBlockMetadataWithNotify(i + 0, j + 28, k + 26, 1, 2);
		setBlock(world, i + 0, j + 28, k + 27, Blocks.log, 1);
		world.setBlockMetadataWithNotify(i + 0, j + 28, k + 27, 1, 2);
		setBlock(world, i + 0, j + 29, k + 18, Blocks.log, 1);
		world.setBlockMetadataWithNotify(i + 0, j + 29, k + 18, 1, 2);
		setBlock(world, i + 0, j + 29, k + 19, Blocks.log, 1);
		world.setBlockMetadataWithNotify(i + 0, j + 29, k + 19, 1, 2);
		setBlock(world, i + 0, j + 29, k + 20, Blocks.log, 1);
		world.setBlockMetadataWithNotify(i + 0, j + 29, k + 20, 1, 2);
		setBlock(world, i + 0, j + 29, k + 21, Blocks.log, 1);
		world.setBlockMetadataWithNotify(i + 0, j + 29, k + 21, 1, 2);
		setBlock(world, i + 0, j + 29, k + 22, Blocks.log, 1);
		world.setBlockMetadataWithNotify(i + 0, j + 29, k + 22, 1, 2);
		setBlock(world, i + 0, j + 29, k + 23, Blocks.log, 1);
		world.setBlockMetadataWithNotify(i + 0, j + 29, k + 23, 1, 2);
		setBlock(world, i + 0, j + 29, k + 24, Blocks.log, 1);
		world.setBlockMetadataWithNotify(i + 0, j + 29, k + 24, 1, 2);
		setBlock(world, i + 0, j + 36, k + 31, Blocks.log, 3);
		world.setBlockMetadataWithNotify(i + 0, j + 36, k + 31, 3, 2);
		setBlock(world, i + 0, j + 37, k + 25, Blocks.leaves, 7);
		world.setBlockMetadataWithNotify(i + 0, j + 37, k + 25, 7, 2);
		setBlock(world, i + 0, j + 37, k + 26, Blocks.leaves, 7);
		world.setBlockMetadataWithNotify(i + 0, j + 37, k + 26, 7, 2);
		setBlock(world, i + 0, j + 37, k + 27, Blocks.leaves, 7);
		world.setBlockMetadataWithNotify(i + 0, j + 37, k + 27, 7, 2);
		setBlock(world, i + 0, j + 37, k + 28, Blocks.leaves, 7);
		world.setBlockMetadataWithNotify(i + 0, j + 37, k + 28, 7, 2);
		setBlock(world, i + 0, j + 37, k + 29, Blocks.leaves, 7);
		world.setBlockMetadataWithNotify(i + 0, j + 37, k + 29, 7, 2);
		setBlock(world, i + 0, j + 38, k + 26, Blocks.leaves, 7);
		world.setBlockMetadataWithNotify(i + 0, j + 38, k + 26, 7, 2);
		setBlock(world, i + 0, j + 38, k + 27, Blocks.leaves, 7);
		world.setBlockMetadataWithNotify(i + 0, j + 38, k + 27, 7, 2);
		setBlock(world, i + 0, j + 38, k + 28, Blocks.leaves, 7);
		world.setBlockMetadataWithNotify(i + 0, j + 38, k + 28, 7, 2);
		setBlock(world, i + 0, j + 39, k + 27, Blocks.leaves, 7);
		world.setBlockMetadataWithNotify(i + 0, j + 39, k + 27, 7, 2);
		setBlock(world, i + 0, j + 46, k + 19, Blocks.planks, 5);
		world.setBlockMetadataWithNotify(i + 0, j + 46, k + 19, 5, 2);
		setBlock(world, i + 0, j + 46, k + 20, Blocks.planks, 5);
		world.setBlockMetadataWithNotify(i + 0, j + 46, k + 20, 5, 2);
		setBlock(world, i + 0, j + 46, k + 21, Blocks.planks, 5);
		world.setBlockMetadataWithNotify(i + 0, j + 46, k + 21, 5, 2);
		setBlock(world, i + 0, j + 46, k + 22, Blocks.planks, 5);
		world.setBlockMetadataWithNotify(i + 0, j + 46, k + 22, 5, 2);
		setBlock(world, i + 0, j + 46, k + 23, Blocks.planks, 5);
		world.setBlockMetadataWithNotify(i + 0, j + 46, k + 23, 5, 2);
		setBlock(world, i + 0, j + 46, k + 24, Blocks.planks, 5);
		world.setBlockMetadataWithNotify(i + 0, j + 46, k + 24, 5, 2);
		setBlock(world, i + 0, j + 51, k + 18, Blocks.log, 1);
		world.setBlockMetadataWithNotify(i + 0, j + 51, k + 18, 1, 2);
		setBlock(world, i + 0, j + 51, k + 19, Blocks.log, 1);
		world.setBlockMetadataWithNotify(i + 0, j + 51, k + 19, 1, 2);
		setBlock(world, i + 0, j + 51, k + 20, Blocks.log, 1);
		world.setBlockMetadataWithNotify(i + 0, j + 51, k + 20, 1, 2);
		setBlock(world, i + 0, j + 51, k + 21, Blocks.log, 1);
		world.setBlockMetadataWithNotify(i + 0, j + 51, k + 21, 1, 2);
		setBlock(world, i + 0, j + 51, k + 22, Blocks.log, 1);
		world.setBlockMetadataWithNotify(i + 0, j + 51, k + 22, 1, 2);
		setBlock(world, i + 0, j + 51, k + 23, Blocks.log, 1);
		world.setBlockMetadataWithNotify(i + 0, j + 51, k + 23, 1, 2);
		setBlock(world, i + 0, j + 51, k + 24, Blocks.log, 1);
		world.setBlockMetadataWithNotify(i + 0, j + 51, k + 24, 1, 2);
		setBlock(world, i + 0, j + 51, k + 25, Blocks.log, 1);
		world.setBlockMetadataWithNotify(i + 0, j + 51, k + 25, 1, 2);
		setBlock(world, i + 0, j + 52, k + 20, Blocks.log, 1);
		world.setBlockMetadataWithNotify(i + 0, j + 52, k + 20, 1, 2);
		setBlock(world, i + 0, j + 52, k + 21, Blocks.log, 1);
		world.setBlockMetadataWithNotify(i + 0, j + 52, k + 21, 1, 2);
		setBlock(world, i + 0, j + 52, k + 22, Blocks.log, 1);
		world.setBlockMetadataWithNotify(i + 0, j + 52, k + 22, 1, 2);
		setBlock(world, i + 0, j + 52, k + 23, Blocks.log, 1);
		world.setBlockMetadataWithNotify(i + 0, j + 52, k + 23, 1, 2);
		setBlock(world, i + 1, j + 12, k + 20, Blocks.log, 1);
		world.setBlockMetadataWithNotify(i + 1, j + 12, k + 20, 1, 2);
		setBlock(world, i + 1, j + 12, k + 21, Blocks.log, 1);
		world.setBlockMetadataWithNotify(i + 1, j + 12, k + 21, 1, 2);
		setBlock(world, i + 1, j + 12, k + 22, Blocks.log, 1);
		world.setBlockMetadataWithNotify(i + 1, j + 12, k + 22, 1, 2);
		setBlock(world, i + 1, j + 13, k + 17, Blocks.vine, 8);
		world.setBlockMetadataWithNotify(i + 1, j + 13, k + 17, 8, 2);
		setBlock(world, i + 1, j + 13, k + 18, Blocks.vine, 15);
		world.setBlockMetadataWithNotify(i + 1, j + 13, k + 18, 15, 2);
		setBlock(world, i + 1, j + 13, k + 19, Blocks.vine, 15);
		world.setBlockMetadataWithNotify(i + 1, j + 13, k + 19, 15, 2);
		setBlock(world, i + 1, j + 13, k + 21, Blocks.log, 1);
		world.setBlockMetadataWithNotify(i + 1, j + 13, k + 21, 1, 2);
		setBlock(world, i + 1, j + 13, k + 22, Blocks.log, 1);
		world.setBlockMetadataWithNotify(i + 1, j + 13, k + 22, 1, 2);
		setBlock(world, i + 1, j + 14, k + 17, Blocks.vine, 15);
		world.setBlockMetadataWithNotify(i + 1, j + 14, k + 17, 15, 2);
		setBlock(world, i + 1, j + 14, k + 18, Blocks.vine, 15);
		world.setBlockMetadataWithNotify(i + 1, j + 14, k + 18, 15, 2);
		setBlock(world, i + 1, j + 14, k + 19, Blocks.vine, 15);
		world.setBlockMetadataWithNotify(i + 1, j + 14, k + 19, 15, 2);
		setBlock(world, i + 1, j + 14, k + 20, Blocks.vine, 15);
		world.setBlockMetadataWithNotify(i + 1, j + 14, k + 20, 15, 2);
		setBlock(world, i + 1, j + 14, k + 21, Blocks.log, 1);
		world.setBlockMetadataWithNotify(i + 1, j + 14, k + 21, 1, 2);
		setBlock(world, i + 1, j + 14, k + 22, Blocks.log, 1);
		world.setBlockMetadataWithNotify(i + 1, j + 14, k + 22, 1, 2);
		setBlock(world, i + 1, j + 14, k + 23, Blocks.log, 1);
		world.setBlockMetadataWithNotify(i + 1, j + 14, k + 23, 1, 2);
		setBlock(world, i + 1, j + 14, k + 24, Blocks.log, 1);
		world.setBlockMetadataWithNotify(i + 1, j + 14, k + 24, 1, 2);
		setBlock(world, i + 1, j + 14, k + 25, Blocks.log, 1);
		world.setBlockMetadataWithNotify(i + 1, j + 14, k + 25, 1, 2);
		setBlock(world, i + 1, j + 15, k + 17, Blocks.vine, 15);
		world.setBlockMetadataWithNotify(i + 1, j + 15, k + 17, 15, 2);
		setBlock(world, i + 1, j + 15, k + 18, Blocks.log, 1);
		world.setBlockMetadataWithNotify(i + 1, j + 15, k + 18, 1, 2);
		setBlock(world, i + 1, j + 15, k + 19, Blocks.log, 1);
		world.setBlockMetadataWithNotify(i + 1, j + 15, k + 19, 1, 2);
		setBlock(world, i + 1, j + 15, k + 20, Blocks.log, 1);
		world.setBlockMetadataWithNotify(i + 1, j + 15, k + 20, 1, 2);
		setBlock(world, i + 1, j + 15, k + 22, Blocks.log, 1);
		world.setBlockMetadataWithNotify(i + 1, j + 15, k + 22, 1, 2);
		setBlock(world, i + 1, j + 15, k + 23, Blocks.log, 1);
		world.setBlockMetadataWithNotify(i + 1, j + 15, k + 23, 1, 2);
		setBlock(world, i + 1, j + 15, k + 24, Blocks.log, 1);
		world.setBlockMetadataWithNotify(i + 1, j + 15, k + 24, 1, 2);
		setBlock(world, i + 1, j + 15, k + 25, Blocks.log, 1);
		world.setBlockMetadataWithNotify(i + 1, j + 15, k + 25, 1, 2);
		setBlock(world, i + 1, j + 15, k + 26, Blocks.log, 1);
		world.setBlockMetadataWithNotify(i + 1, j + 15, k + 26, 1, 2);
		setBlock(world, i + 1, j + 15, k + 27, Blocks.log, 1);
		world.setBlockMetadataWithNotify(i + 1, j + 15, k + 27, 1, 2);
		setBlock(world, i + 1, j + 15, k + 28, Blocks.log, 1);
		world.setBlockMetadataWithNotify(i + 1, j + 15, k + 28, 1, 2);
		setBlock(world, i + 1, j + 15, k + 29, Blocks.log, 1);
		world.setBlockMetadataWithNotify(i + 1, j + 15, k + 29, 1, 2);
		setBlock(world, i + 1, j + 15, k + 31, Blocks.log, 1);
		world.setBlockMetadataWithNotify(i + 1, j + 15, k + 31, 1, 2);
		setBlock(world, i + 1, j + 16, k + 15, Blocks.vine, 5);
		world.setBlockMetadataWithNotify(i + 1, j + 16, k + 15, 5, 2);
		setBlock(world, i + 1, j + 16, k + 17, Blocks.vine, 15);
		world.setBlockMetadataWithNotify(i + 1, j + 16, k + 17, 15, 2);
		setBlock(world, i + 1, j + 16, k + 18, Blocks.log, 1);
		world.setBlockMetadataWithNotify(i + 1, j + 16, k + 18, 1, 2);
		setBlock(world, i + 1, j + 16, k + 19, Blocks.log, 1);
		world.setBlockMetadataWithNotify(i + 1, j + 16, k + 19, 1, 2);
		setBlock(world, i + 1, j + 16, k + 20, Blocks.log, 1);
		world.setBlockMetadataWithNotify(i + 1, j + 16, k + 20, 1, 2);
		setBlock(world, i + 1, j + 16, k + 22, Blocks.log, 1);
		world.setBlockMetadataWithNotify(i + 1, j + 16, k + 22, 1, 2);
		setBlock(world, i + 1, j + 16, k + 23, Blocks.log, 1);
		world.setBlockMetadataWithNotify(i + 1, j + 16, k + 23, 1, 2);
		setBlock(world, i + 1, j + 16, k + 24, Blocks.log, 1);
		world.setBlockMetadataWithNotify(i + 1, j + 16, k + 24, 1, 2);
		setBlock(world, i + 1, j + 16, k + 25, Blocks.log, 1);
		world.setBlockMetadataWithNotify(i + 1, j + 16, k + 25, 1, 2);
		setBlock(world, i + 1, j + 16, k + 26, Blocks.log, 1);
		world.setBlockMetadataWithNotify(i + 1, j + 16, k + 26, 1, 2);
		setBlock(world, i + 1, j + 16, k + 27, Blocks.log, 1);
		world.setBlockMetadataWithNotify(i + 1, j + 16, k + 27, 1, 2);
		setBlock(world, i + 1, j + 16, k + 28, Blocks.log, 1);
		world.setBlockMetadataWithNotify(i + 1, j + 16, k + 28, 1, 2);
		setBlock(world, i + 1, j + 16, k + 29, Blocks.log, 1);
		world.setBlockMetadataWithNotify(i + 1, j + 16, k + 29, 1, 2);
		setBlock(world, i + 1, j + 16, k + 30, Blocks.log, 1);
		world.setBlockMetadataWithNotify(i + 1, j + 16, k + 30, 1, 2);
		setBlock(world, i + 1, j + 16, k + 31, Blocks.log, 1);
		world.setBlockMetadataWithNotify(i + 1, j + 16, k + 31, 1, 2);
		setBlock(world, i + 1, j + 17, k + 15, Blocks.vine, 5);
		world.setBlockMetadataWithNotify(i + 1, j + 17, k + 15, 5, 2);
		setBlock(world, i + 1, j + 17, k + 17, Blocks.vine, 15);
		world.setBlockMetadataWithNotify(i + 1, j + 17, k + 17, 15, 2);
		setBlock(world, i + 1, j + 17, k + 18, Blocks.vine, 15);
		world.setBlockMetadataWithNotify(i + 1, j + 17, k + 18, 15, 2);
		setBlock(world, i + 1, j + 17, k + 19, Blocks.log, 1);
		world.setBlockMetadataWithNotify(i + 1, j + 17, k + 19, 1, 2);
		setBlock(world, i + 1, j + 17, k + 20, Blocks.log, 1);
		world.setBlockMetadataWithNotify(i + 1, j + 17, k + 20, 1, 2);
		setBlock(world, i + 1, j + 17, k + 22, Blocks.log, 1);
		world.setBlockMetadataWithNotify(i + 1, j + 17, k + 22, 1, 2);
		setBlock(world, i + 1, j + 17, k + 23, Blocks.vine, 15);
		world.setBlockMetadataWithNotify(i + 1, j + 17, k + 23, 15, 2);
		setBlock(world, i + 1, j + 17, k + 24, Blocks.log, 1);
		world.setBlockMetadataWithNotify(i + 1, j + 17, k + 24, 1, 2);
		setBlock(world, i + 1, j + 17, k + 25, Blocks.log, 1);
		world.setBlockMetadataWithNotify(i + 1, j + 17, k + 25, 1, 2);
		setBlock(world, i + 1, j + 17, k + 26, Blocks.log, 1);
		world.setBlockMetadataWithNotify(i + 1, j + 17, k + 26, 1, 2);
		setBlock(world, i + 1, j + 17, k + 28, Blocks.log, 1);
		world.setBlockMetadataWithNotify(i + 1, j + 17, k + 28, 1, 2);
		setBlock(world, i + 1, j + 17, k + 29, Blocks.log, 1);
		world.setBlockMetadataWithNotify(i + 1, j + 17, k + 29, 1, 2);
		setBlock(world, i + 1, j + 17, k + 31, Blocks.log, 1);
		world.setBlockMetadataWithNotify(i + 1, j + 17, k + 31, 1, 2);
		setBlock(world, i + 1, j + 18, k + 10, Blocks.vine, 14);
		world.setBlockMetadataWithNotify(i + 1, j + 18, k + 10, 14, 2);
		setBlock(world, i + 1, j + 18, k + 13, Blocks.vine, 5);
		world.setBlockMetadataWithNotify(i + 1, j + 18, k + 13, 5, 2);
		setBlock(world, i + 1, j + 18, k + 14, Blocks.vine, 13);
		world.setBlockMetadataWithNotify(i + 1, j + 18, k + 14, 13, 2);
		setBlock(world, i + 1, j + 18, k + 15, Blocks.vine, 5);
		world.setBlockMetadataWithNotify(i + 1, j + 18, k + 15, 5, 2);
		setBlock(world, i + 1, j + 18, k + 16, Blocks.vine, 11);
		world.setBlockMetadataWithNotify(i + 1, j + 18, k + 16, 11, 2);
		setBlock(world, i + 1, j + 18, k + 17, Blocks.vine, 15);
		world.setBlockMetadataWithNotify(i + 1, j + 18, k + 17, 15, 2);
		setBlock(world, i + 1, j + 18, k + 18, Blocks.vine, 15);
		world.setBlockMetadataWithNotify(i + 1, j + 18, k + 18, 15, 2);
		setBlock(world, i + 1, j + 18, k + 19, Blocks.log, 1);
		world.setBlockMetadataWithNotify(i + 1, j + 18, k + 19, 1, 2);
		setBlock(world, i + 1, j + 18, k + 20, Blocks.log, 1);
		world.setBlockMetadataWithNotify(i + 1, j + 18, k + 20, 1, 2);
		setBlock(world, i + 1, j + 18, k + 22, Blocks.vine, 15);
		world.setBlockMetadataWithNotify(i + 1, j + 18, k + 22, 15, 2);
		setBlock(world, i + 1, j + 18, k + 23, Blocks.vine, 15);
		world.setBlockMetadataWithNotify(i + 1, j + 18, k + 23, 15, 2);
		setBlock(world, i + 1, j + 18, k + 24, Blocks.log, 1);
		world.setBlockMetadataWithNotify(i + 1, j + 18, k + 24, 1, 2);
		setBlock(world, i + 1, j + 18, k + 25, Blocks.log, 1);
		world.setBlockMetadataWithNotify(i + 1, j + 18, k + 25, 1, 2);
		setBlock(world, i + 1, j + 18, k + 26, Blocks.log, 1);
		world.setBlockMetadataWithNotify(i + 1, j + 18, k + 26, 1, 2);
		setBlock(world, i + 1, j + 18, k + 27, Blocks.log, 1);
		world.setBlockMetadataWithNotify(i + 1, j + 18, k + 27, 1, 2);
		setBlock(world, i + 1, j + 18, k + 28, Blocks.log, 1);
		world.setBlockMetadataWithNotify(i + 1, j + 18, k + 28, 1, 2);
		setBlock(world, i + 1, j + 18, k + 29, Blocks.log, 1);
		world.setBlockMetadataWithNotify(i + 1, j + 18, k + 29, 1, 2);
		setBlock(world, i + 1, j + 19, k + 10, Blocks.vine, 15);
		world.setBlockMetadataWithNotify(i + 1, j + 19, k + 10, 15, 2);
		setBlock(world, i + 1, j + 19, k + 11, Blocks.vine, 15);
		world.setBlockMetadataWithNotify(i + 1, j + 19, k + 11, 15, 2);
		setBlock(world, i + 1, j + 19, k + 12, Blocks.vine, 15);
		world.setBlockMetadataWithNotify(i + 1, j + 19, k + 12, 15, 2);
		setBlock(world, i + 1, j + 19, k + 13, Blocks.vine, 15);
		world.setBlockMetadataWithNotify(i + 1, j + 19, k + 13, 15, 2);
		setBlock(world, i + 1, j + 19, k + 14, Blocks.vine, 15);
		world.setBlockMetadataWithNotify(i + 1, j + 19, k + 14, 15, 2);
		setBlock(world, i + 1, j + 19, k + 15, Blocks.vine, 15);
		world.setBlockMetadataWithNotify(i + 1, j + 19, k + 15, 15, 2);
		setBlock(world, i + 1, j + 19, k + 16, Blocks.vine, 15);
		world.setBlockMetadataWithNotify(i + 1, j + 19, k + 16, 15, 2);
		setBlock(world, i + 1, j + 19, k + 17, Blocks.vine, 15);
		world.setBlockMetadataWithNotify(i + 1, j + 19, k + 17, 15, 2);
		setBlock(world, i + 1, j + 19, k + 18, Blocks.vine, 15);
		world.setBlockMetadataWithNotify(i + 1, j + 19, k + 18, 15, 2);
		setBlock(world, i + 1, j + 19, k + 19, Blocks.log, 1);
		world.setBlockMetadataWithNotify(i + 1, j + 19, k + 19, 1, 2);
		setBlock(world, i + 1, j + 19, k + 20, Blocks.log, 1);
		world.setBlockMetadataWithNotify(i + 1, j + 19, k + 20, 1, 2);
		setBlock(world, i + 1, j + 19, k + 21, Blocks.log, 1);
		world.setBlockMetadataWithNotify(i + 1, j + 19, k + 21, 1, 2);
		setBlock(world, i + 1, j + 19, k + 22, Blocks.log, 1);
		world.setBlockMetadataWithNotify(i + 1, j + 19, k + 22, 1, 2);
		setBlock(world, i + 1, j + 19, k + 23, Blocks.log, 1);
		world.setBlockMetadataWithNotify(i + 1, j + 19, k + 23, 1, 2);
		setBlock(world, i + 1, j + 19, k + 24, Blocks.log, 1);
		world.setBlockMetadataWithNotify(i + 1, j + 19, k + 24, 1, 2);
		setBlock(world, i + 1, j + 19, k + 25, Blocks.log, 1);
		world.setBlockMetadataWithNotify(i + 1, j + 19, k + 25, 1, 2);
		setBlock(world, i + 1, j + 19, k + 26, Blocks.log, 1);
		world.setBlockMetadataWithNotify(i + 1, j + 19, k + 26, 1, 2);
		setBlock(world, i + 1, j + 19, k + 28, Blocks.log, 1);
		world.setBlockMetadataWithNotify(i + 1, j + 19, k + 28, 1, 2);
		setBlock(world, i + 1, j + 20, k + 8, Blocks.planks, 5);
		world.setBlockMetadataWithNotify(i + 1, j + 20, k + 8, 5, 2);
		setBlock(world, i + 1, j + 20, k + 9, Blocks.planks, 5);
		world.setBlockMetadataWithNotify(i + 1, j + 20, k + 9, 5, 2);
		setBlock(world, i + 1, j + 20, k + 10, Blocks.planks, 5);
		world.setBlockMetadataWithNotify(i + 1, j + 20, k + 10, 5, 2);
		setBlock(world, i + 1, j + 20, k + 11, Blocks.planks, 5);
		world.setBlockMetadataWithNotify(i + 1, j + 20, k + 11, 5, 2);
		setBlock(world, i + 1, j + 20, k + 12, Blocks.planks, 5);
		world.setBlockMetadataWithNotify(i + 1, j + 20, k + 12, 5, 2);
		setBlock(world, i + 1, j + 20, k + 13, Blocks.planks, 5);
		world.setBlockMetadataWithNotify(i + 1, j + 20, k + 13, 5, 2);
		setBlock(world, i + 1, j + 20, k + 14, Blocks.planks, 5);
		world.setBlockMetadataWithNotify(i + 1, j + 20, k + 14, 5, 2);
		setBlock(world, i + 1, j + 20, k + 15, Blocks.log, 1);
		world.setBlockMetadataWithNotify(i + 1, j + 20, k + 15, 1, 2);
		setBlock(world, i + 1, j + 20, k + 16, Blocks.log, 1);
		world.setBlockMetadataWithNotify(i + 1, j + 20, k + 16, 1, 2);
		setBlock(world, i + 1, j + 20, k + 17, Blocks.planks, 5);
		world.setBlockMetadataWithNotify(i + 1, j + 20, k + 17, 5, 2);
		setBlock(world, i + 1, j + 20, k + 18, Blocks.log, 1);
		world.setBlockMetadataWithNotify(i + 1, j + 20, k + 18, 1, 2);
		setBlock(world, i + 1, j + 20, k + 19, Blocks.planks, 5);
		world.setBlockMetadataWithNotify(i + 1, j + 20, k + 19, 5, 2);
		setBlock(world, i + 1, j + 20, k + 20, Blocks.log, 1);
		world.setBlockMetadataWithNotify(i + 1, j + 20, k + 20, 1, 2);
		setBlock(world, i + 1, j + 20, k + 21, Blocks.log, 1);
		world.setBlockMetadataWithNotify(i + 1, j + 20, k + 21, 1, 2);
		setBlock(world, i + 1, j + 20, k + 22, Blocks.log, 1);
		world.setBlockMetadataWithNotify(i + 1, j + 20, k + 22, 1, 2);
		setBlock(world, i + 1, j + 20, k + 23, Blocks.planks, 5);
		world.setBlockMetadataWithNotify(i + 1, j + 20, k + 23, 5, 2);
		setBlock(world, i + 1, j + 20, k + 24, Blocks.log, 1);
		world.setBlockMetadataWithNotify(i + 1, j + 20, k + 24, 1, 2);
		setBlock(world, i + 1, j + 20, k + 25, Blocks.planks, 5);
		world.setBlockMetadataWithNotify(i + 1, j + 20, k + 25, 5, 2);
		setBlock(world, i + 1, j + 20, k + 26, Blocks.log, 1);
		world.setBlockMetadataWithNotify(i + 1, j + 20, k + 26, 1, 2);
		setBlock(world, i + 1, j + 20, k + 27, Blocks.log, 1);
		world.setBlockMetadataWithNotify(i + 1, j + 20, k + 27, 1, 2);
		setBlock(world, i + 1, j + 21, k + 20, Blocks.spruce_stairs, 2);
		world.setBlockMetadataWithNotify(i + 1, j + 21, k + 20, 2, 2);
		setBlock(world, i + 1, j + 21, k + 21, Blocks.log, 1);
		world.setBlockMetadataWithNotify(i + 1, j + 21, k + 21, 1, 2);
		setBlock(world, i + 1, j + 21, k + 22, Blocks.spruce_stairs, 3);
		world.setBlockMetadataWithNotify(i + 1, j + 21, k + 22, 3, 2);
		setBlock(world, i + 1, j + 22, k + 21, Blocks.log, 1);
		world.setBlockMetadataWithNotify(i + 1, j + 22, k + 21, 1, 2);
		setBlock(world, i + 1, j + 23, k + 21, Blocks.log, 1);
		world.setBlockMetadataWithNotify(i + 1, j + 23, k + 21, 1, 2);
		setBlock(world, i + 1, j + 24, k + 12, Blocks.log, 1);
		world.setBlockMetadataWithNotify(i + 1, j + 24, k + 12, 1, 2);
		setBlock(world, i + 1, j + 24, k + 13, Blocks.log, 1);
		world.setBlockMetadataWithNotify(i + 1, j + 24, k + 13, 1, 2);
		setBlock(world, i + 1, j + 24, k + 14, Blocks.log, 1);
		world.setBlockMetadataWithNotify(i + 1, j + 24, k + 14, 1, 2);
		setBlock(world, i + 1, j + 24, k + 15, Blocks.log, 1);
		world.setBlockMetadataWithNotify(i + 1, j + 24, k + 15, 1, 2);
		setBlock(world, i + 1, j + 24, k + 16, Blocks.log, 1);
		world.setBlockMetadataWithNotify(i + 1, j + 24, k + 16, 1, 2);
		setBlock(world, i + 1, j + 24, k + 20, Blocks.torch, 4);
		world.setBlockMetadataWithNotify(i + 1, j + 24, k + 20, 4, 2);
		setBlock(world, i + 1, j + 24, k + 21, Blocks.log, 1);
		world.setBlockMetadataWithNotify(i + 1, j + 24, k + 21, 1, 2);
		setBlock(world, i + 1, j + 24, k + 22, Blocks.torch, 3);
		world.setBlockMetadataWithNotify(i + 1, j + 24, k + 22, 3, 2);
		setBlock(world, i + 1, j + 24, k + 26, Blocks.log, 1);
		world.setBlockMetadataWithNotify(i + 1, j + 24, k + 26, 1, 2);
		setBlock(world, i + 1, j + 24, k + 27, Blocks.log, 1);
		world.setBlockMetadataWithNotify(i + 1, j + 24, k + 27, 1, 2);
		setBlock(world, i + 1, j + 24, k + 28, Blocks.log, 1);
		world.setBlockMetadataWithNotify(i + 1, j + 24, k + 28, 1, 2);
		setBlock(world, i + 1, j + 24, k + 29, Blocks.log, 1);
		world.setBlockMetadataWithNotify(i + 1, j + 24, k + 29, 1, 2);
		setBlock(world, i + 1, j + 24, k + 30, Blocks.log, 1);
		world.setBlockMetadataWithNotify(i + 1, j + 24, k + 30, 1, 2);
		setBlock(world, i + 1, j + 25, k + 13, Blocks.log, 1);
		world.setBlockMetadataWithNotify(i + 1, j + 25, k + 13, 1, 2);
		setBlock(world, i + 1, j + 25, k + 14, Blocks.log, 1);
		world.setBlockMetadataWithNotify(i + 1, j + 25, k + 14, 1, 2);
		setBlock(world, i + 1, j + 25, k + 15, Blocks.log, 1);
		world.setBlockMetadataWithNotify(i + 1, j + 25, k + 15, 1, 2);
		setBlock(world, i + 1, j + 25, k + 16, Blocks.log, 1);
		world.setBlockMetadataWithNotify(i + 1, j + 25, k + 16, 1, 2);
		setBlock(world, i + 1, j + 25, k + 17, Blocks.log, 1);
		world.setBlockMetadataWithNotify(i + 1, j + 25, k + 17, 1, 2);
		setBlock(world, i + 1, j + 25, k + 21, Blocks.log, 1);
		world.setBlockMetadataWithNotify(i + 1, j + 25, k + 21, 1, 2);
		setBlock(world, i + 1, j + 25, k + 25, Blocks.log, 1);
		world.setBlockMetadataWithNotify(i + 1, j + 25, k + 25, 1, 2);
		setBlock(world, i + 1, j + 25, k + 26, Blocks.log, 1);
		world.setBlockMetadataWithNotify(i + 1, j + 25, k + 26, 1, 2);
		setBlock(world, i + 1, j + 25, k + 27, Blocks.log, 1);
		world.setBlockMetadataWithNotify(i + 1, j + 25, k + 27, 1, 2);
		setBlock(world, i + 1, j + 25, k + 28, Blocks.log, 1);
		world.setBlockMetadataWithNotify(i + 1, j + 25, k + 28, 1, 2);
		setBlock(world, i + 1, j + 25, k + 29, Blocks.log, 1);
		world.setBlockMetadataWithNotify(i + 1, j + 25, k + 29, 1, 2);
		setBlock(world, i + 1, j + 25, k + 31, Blocks.log, 3);
		world.setBlockMetadataWithNotify(i + 1, j + 25, k + 31, 3, 2);
		setBlock(world, i + 1, j + 26, k + 13, Blocks.log, 1);
		world.setBlockMetadataWithNotify(i + 1, j + 26, k + 13, 1, 2);
		setBlock(world, i + 1, j + 26, k + 14, Blocks.log, 1);
		world.setBlockMetadataWithNotify(i + 1, j + 26, k + 14, 1, 2);
		setBlock(world, i + 1, j + 26, k + 15, Blocks.log, 1);
		world.setBlockMetadataWithNotify(i + 1, j + 26, k + 15, 1, 2);
		setBlock(world, i + 1, j + 26, k + 16, Blocks.log, 1);
		world.setBlockMetadataWithNotify(i + 1, j + 26, k + 16, 1, 2);
		setBlock(world, i + 1, j + 26, k + 17, Blocks.log, 1);
		world.setBlockMetadataWithNotify(i + 1, j + 26, k + 17, 1, 2);
		setBlock(world, i + 1, j + 26, k + 18, Blocks.log, 1);
		world.setBlockMetadataWithNotify(i + 1, j + 26, k + 18, 1, 2);
		setBlock(world, i + 1, j + 26, k + 20, Blocks.log, 1);
		world.setBlockMetadataWithNotify(i + 1, j + 26, k + 20, 1, 2);
		setBlock(world, i + 1, j + 26, k + 21, Blocks.log, 1);
		world.setBlockMetadataWithNotify(i + 1, j + 26, k + 21, 1, 2);
		setBlock(world, i + 1, j + 26, k + 22, Blocks.log, 1);
		world.setBlockMetadataWithNotify(i + 1, j + 26, k + 22, 1, 2);
		setBlock(world, i + 1, j + 26, k + 24, Blocks.log, 1);
		world.setBlockMetadataWithNotify(i + 1, j + 26, k + 24, 1, 2);
		setBlock(world, i + 1, j + 26, k + 25, Blocks.log, 1);
		world.setBlockMetadataWithNotify(i + 1, j + 26, k + 25, 1, 2);
		setBlock(world, i + 1, j + 26, k + 26, Blocks.log, 1);
		world.setBlockMetadataWithNotify(i + 1, j + 26, k + 26, 1, 2);
		setBlock(world, i + 1, j + 26, k + 27, Blocks.log, 1);
		world.setBlockMetadataWithNotify(i + 1, j + 26, k + 27, 1, 2);
		setBlock(world, i + 1, j + 26, k + 28, Blocks.log, 1);
		world.setBlockMetadataWithNotify(i + 1, j + 26, k + 28, 1, 2);
		setBlock(world, i + 1, j + 26, k + 29, Blocks.log, 1);
		world.setBlockMetadataWithNotify(i + 1, j + 26, k + 29, 1, 2);
		setBlock(world, i + 1, j + 27, k + 14, Blocks.log, 1);
		world.setBlockMetadataWithNotify(i + 1, j + 27, k + 14, 1, 2);
		setBlock(world, i + 1, j + 27, k + 15, Blocks.log, 1);
		world.setBlockMetadataWithNotify(i + 1, j + 27, k + 15, 1, 2);
		setBlock(world, i + 1, j + 27, k + 16, Blocks.log, 1);
		world.setBlockMetadataWithNotify(i + 1, j + 27, k + 16, 1, 2);
		setBlock(world, i + 1, j + 27, k + 17, Blocks.log, 1);
		world.setBlockMetadataWithNotify(i + 1, j + 27, k + 17, 1, 2);
		setBlock(world, i + 1, j + 27, k + 18, Blocks.log, 1);
		world.setBlockMetadataWithNotify(i + 1, j + 27, k + 18, 1, 2);
		setBlock(world, i + 1, j + 27, k + 19, Blocks.log, 1);
		world.setBlockMetadataWithNotify(i + 1, j + 27, k + 19, 1, 2);
		setBlock(world, i + 1, j + 27, k + 20, Blocks.log, 1);
		world.setBlockMetadataWithNotify(i + 1, j + 27, k + 20, 1, 2);
		setBlock(world, i + 1, j + 27, k + 21, Blocks.log, 1);
		world.setBlockMetadataWithNotify(i + 1, j + 27, k + 21, 1, 2);
		setBlock(world, i + 1, j + 27, k + 22, Blocks.log, 1);
		world.setBlockMetadataWithNotify(i + 1, j + 27, k + 22, 1, 2);
		setBlock(world, i + 1, j + 27, k + 23, Blocks.log, 1);
		world.setBlockMetadataWithNotify(i + 1, j + 27, k + 23, 1, 2);
		setBlock(world, i + 1, j + 27, k + 24, Blocks.log, 1);
		world.setBlockMetadataWithNotify(i + 1, j + 27, k + 24, 1, 2);
		setBlock(world, i + 1, j + 27, k + 25, Blocks.log, 1);
		world.setBlockMetadataWithNotify(i + 1, j + 27, k + 25, 1, 2);
		setBlock(world, i + 1, j + 27, k + 26, Blocks.log, 1);
		world.setBlockMetadataWithNotify(i + 1, j + 27, k + 26, 1, 2);
		setBlock(world, i + 1, j + 27, k + 27, Blocks.log, 1);
		world.setBlockMetadataWithNotify(i + 1, j + 27, k + 27, 1, 2);
		setBlock(world, i + 1, j + 27, k + 28, Blocks.log, 1);
		world.setBlockMetadataWithNotify(i + 1, j + 27, k + 28, 1, 2);
		setBlock(world, i + 1, j + 28, k + 15, Blocks.log, 1);
		world.setBlockMetadataWithNotify(i + 1, j + 28, k + 15, 1, 2);
		setBlock(world, i + 1, j + 28, k + 16, Blocks.log, 1);
		world.setBlockMetadataWithNotify(i + 1, j + 28, k + 16, 1, 2);
		setBlock(world, i + 1, j + 28, k + 17, Blocks.log, 1);
		world.setBlockMetadataWithNotify(i + 1, j + 28, k + 17, 1, 2);
		setBlock(world, i + 1, j + 28, k + 18, Blocks.log, 1);
		world.setBlockMetadataWithNotify(i + 1, j + 28, k + 18, 1, 2);
		setBlock(world, i + 1, j + 28, k + 19, Blocks.log, 1);
		world.setBlockMetadataWithNotify(i + 1, j + 28, k + 19, 1, 2);
		setBlock(world, i + 1, j + 28, k + 20, Blocks.log, 1);
		world.setBlockMetadataWithNotify(i + 1, j + 28, k + 20, 1, 2);
		setBlock(world, i + 1, j + 28, k + 21, Blocks.log, 1);
		world.setBlockMetadataWithNotify(i + 1, j + 28, k + 21, 1, 2);
		setBlock(world, i + 1, j + 28, k + 22, Blocks.log, 1);
		world.setBlockMetadataWithNotify(i + 1, j + 28, k + 22, 1, 2);
		setBlock(world, i + 1, j + 28, k + 23, Blocks.log, 1);
		world.setBlockMetadataWithNotify(i + 1, j + 28, k + 23, 1, 2);
		setBlock(world, i + 1, j + 28, k + 24, Blocks.log, 1);
		world.setBlockMetadataWithNotify(i + 1, j + 28, k + 24, 1, 2);
		setBlock(world, i + 1, j + 28, k + 25, Blocks.log, 1);
		world.setBlockMetadataWithNotify(i + 1, j + 28, k + 25, 1, 2);
		setBlock(world, i + 1, j + 28, k + 26, Blocks.log, 1);
		world.setBlockMetadataWithNotify(i + 1, j + 28, k + 26, 1, 2);
		setBlock(world, i + 1, j + 28, k + 27, Blocks.log, 1);
		world.setBlockMetadataWithNotify(i + 1, j + 28, k + 27, 1, 2);
		setBlock(world, i + 1, j + 29, k + 18, Blocks.log, 1);
		world.setBlockMetadataWithNotify(i + 1, j + 29, k + 18, 1, 2);
		setBlock(world, i + 1, j + 29, k + 19, Blocks.log, 1);
		world.setBlockMetadataWithNotify(i + 1, j + 29, k + 19, 1, 2);
		setBlock(world, i + 1, j + 29, k + 20, Blocks.log, 1);
		world.setBlockMetadataWithNotify(i + 1, j + 29, k + 20, 1, 2);
		setBlock(world, i + 1, j + 29, k + 21, Blocks.log, 1);
		world.setBlockMetadataWithNotify(i + 1, j + 29, k + 21, 1, 2);
		setBlock(world, i + 1, j + 29, k + 22, Blocks.log, 1);
		world.setBlockMetadataWithNotify(i + 1, j + 29, k + 22, 1, 2);
		setBlock(world, i + 1, j + 29, k + 23, Blocks.log, 1);
		world.setBlockMetadataWithNotify(i + 1, j + 29, k + 23, 1, 2);
		setBlock(world, i + 1, j + 29, k + 24, Blocks.log, 1);
		world.setBlockMetadataWithNotify(i + 1, j + 29, k + 24, 1, 2);
		setBlock(world, i + 1, j + 36, k + 28, Blocks.log, 3);
		world.setBlockMetadataWithNotify(i + 1, j + 36, k + 28, 3, 2);
		setBlock(world, i + 1, j + 37, k + 25, Blocks.leaves, 7);
		world.setBlockMetadataWithNotify(i + 1, j + 37, k + 25, 7, 2);
		setBlock(world, i + 1, j + 37, k + 26, Blocks.leaves, 7);
		world.setBlockMetadataWithNotify(i + 1, j + 37, k + 26, 7, 2);
		setBlock(world, i + 1, j + 37, k + 27, Blocks.log, 3);
		world.setBlockMetadataWithNotify(i + 1, j + 37, k + 27, 3, 2);
		setBlock(world, i + 1, j + 37, k + 28, Blocks.leaves, 7);
		world.setBlockMetadataWithNotify(i + 1, j + 37, k + 28, 7, 2);
		setBlock(world, i + 1, j + 37, k + 29, Blocks.leaves, 7);
		world.setBlockMetadataWithNotify(i + 1, j + 37, k + 29, 7, 2);
		setBlock(world, i + 1, j + 38, k + 25, Blocks.leaves, 7);
		world.setBlockMetadataWithNotify(i + 1, j + 38, k + 25, 7, 2);
		setBlock(world, i + 1, j + 38, k + 26, Blocks.leaves, 7);
		world.setBlockMetadataWithNotify(i + 1, j + 38, k + 26, 7, 2);
		setBlock(world, i + 1, j + 38, k + 27, Blocks.leaves, 7);
		world.setBlockMetadataWithNotify(i + 1, j + 38, k + 27, 7, 2);
		setBlock(world, i + 1, j + 38, k + 28, Blocks.leaves, 7);
		world.setBlockMetadataWithNotify(i + 1, j + 38, k + 28, 7, 2);
		setBlock(world, i + 1, j + 38, k + 29, Blocks.leaves, 7);
		world.setBlockMetadataWithNotify(i + 1, j + 38, k + 29, 7, 2);
		setBlock(world, i + 1, j + 39, k + 26, Blocks.leaves, 7);
		world.setBlockMetadataWithNotify(i + 1, j + 39, k + 26, 7, 2);
		setBlock(world, i + 1, j + 39, k + 27, Blocks.leaves, 7);
		world.setBlockMetadataWithNotify(i + 1, j + 39, k + 27, 7, 2);
		setBlock(world, i + 1, j + 39, k + 28, Blocks.leaves, 7);
		world.setBlockMetadataWithNotify(i + 1, j + 39, k + 28, 7, 2);
		setBlock(world, i + 1, j + 40, k + 27, Blocks.leaves, 7);
		world.setBlockMetadataWithNotify(i + 1, j + 40, k + 27, 7, 2);
		setBlock(world, i + 1, j + 46, k + 19, Blocks.planks, 5);
		world.setBlockMetadataWithNotify(i + 1, j + 46, k + 19, 5, 2);
		setBlock(world, i + 1, j + 46, k + 20, Blocks.log, 1);
		world.setBlockMetadataWithNotify(i + 1, j + 46, k + 20, 1, 2);
		setBlock(world, i + 1, j + 46, k + 21, Blocks.log, 1);
		world.setBlockMetadataWithNotify(i + 1, j + 46, k + 21, 1, 2);
		setBlock(world, i + 1, j + 46, k + 22, Blocks.log, 1);
		world.setBlockMetadataWithNotify(i + 1, j + 46, k + 22, 1, 2);
		setBlock(world, i + 1, j + 46, k + 23, Blocks.log, 1);
		world.setBlockMetadataWithNotify(i + 1, j + 46, k + 23, 1, 2);
		setBlock(world, i + 1, j + 46, k + 24, Blocks.planks, 5);
		world.setBlockMetadataWithNotify(i + 1, j + 46, k + 24, 5, 2);
		setBlock(world, i + 1, j + 48, k + 18, Blocks.spruce_stairs, 4);
		world.setBlockMetadataWithNotify(i + 1, j + 48, k + 18, 4, 2);
		setBlock(world, i + 1, j + 48, k + 25, Blocks.spruce_stairs, 4);
		world.setBlockMetadataWithNotify(i + 1, j + 48, k + 25, 4, 2);
		setBlock(world, i + 1, j + 49, k + 18, Blocks.log, 1);
		world.setBlockMetadataWithNotify(i + 1, j + 49, k + 18, 1, 2);
		setBlock(world, i + 1, j + 49, k + 25, Blocks.log, 1);
		world.setBlockMetadataWithNotify(i + 1, j + 49, k + 25, 1, 2);
		setBlock(world, i + 1, j + 50, k + 18, Blocks.log, 1);
		world.setBlockMetadataWithNotify(i + 1, j + 50, k + 18, 1, 2);
		setBlock(world, i + 1, j + 50, k + 19, Blocks.spruce_stairs, 7);
		world.setBlockMetadataWithNotify(i + 1, j + 50, k + 19, 7, 2);
		setBlock(world, i + 1, j + 50, k + 24, Blocks.spruce_stairs, 6);
		world.setBlockMetadataWithNotify(i + 1, j + 50, k + 24, 6, 2);
		setBlock(world, i + 1, j + 50, k + 25, Blocks.log, 1);
		world.setBlockMetadataWithNotify(i + 1, j + 50, k + 25, 1, 2);
		setBlock(world, i + 1, j + 51, k + 17, Blocks.log, 1);
		world.setBlockMetadataWithNotify(i + 1, j + 51, k + 17, 1, 2);
		setBlock(world, i + 1, j + 51, k + 18, Blocks.log, 1);
		world.setBlockMetadataWithNotify(i + 1, j + 51, k + 18, 1, 2);
		setBlock(world, i + 1, j + 51, k + 19, Blocks.log, 1);
		world.setBlockMetadataWithNotify(i + 1, j + 51, k + 19, 1, 2);
		setBlock(world, i + 1, j + 51, k + 20, Blocks.log, 1);
		world.setBlockMetadataWithNotify(i + 1, j + 51, k + 20, 1, 2);
		setBlock(world, i + 1, j + 51, k + 21, Blocks.log, 1);
		world.setBlockMetadataWithNotify(i + 1, j + 51, k + 21, 1, 2);
		setBlock(world, i + 1, j + 51, k + 22, Blocks.log, 1);
		world.setBlockMetadataWithNotify(i + 1, j + 51, k + 22, 1, 2);
		setBlock(world, i + 1, j + 51, k + 23, Blocks.log, 1);
		world.setBlockMetadataWithNotify(i + 1, j + 51, k + 23, 1, 2);
		setBlock(world, i + 1, j + 51, k + 24, Blocks.log, 1);
		world.setBlockMetadataWithNotify(i + 1, j + 51, k + 24, 1, 2);
		setBlock(world, i + 1, j + 51, k + 25, Blocks.log, 1);
		world.setBlockMetadataWithNotify(i + 1, j + 51, k + 25, 1, 2);
		setBlock(world, i + 1, j + 51, k + 26, Blocks.log, 1);
		world.setBlockMetadataWithNotify(i + 1, j + 51, k + 26, 1, 2);
		setBlock(world, i + 1, j + 52, k + 18, Blocks.log, 1);
		world.setBlockMetadataWithNotify(i + 1, j + 52, k + 18, 1, 2);
		setBlock(world, i + 1, j + 52, k + 19, Blocks.log, 1);
		world.setBlockMetadataWithNotify(i + 1, j + 52, k + 19, 1, 2);
		setBlock(world, i + 1, j + 52, k + 20, Blocks.log, 1);
		world.setBlockMetadataWithNotify(i + 1, j + 52, k + 20, 1, 2);
		setBlock(world, i + 1, j + 52, k + 21, Blocks.log, 1);
		world.setBlockMetadataWithNotify(i + 1, j + 52, k + 21, 1, 2);
		setBlock(world, i + 1, j + 52, k + 22, Blocks.log, 1);
		world.setBlockMetadataWithNotify(i + 1, j + 52, k + 22, 1, 2);
		setBlock(world, i + 1, j + 52, k + 23, Blocks.log, 1);
		world.setBlockMetadataWithNotify(i + 1, j + 52, k + 23, 1, 2);
		setBlock(world, i + 1, j + 52, k + 24, Blocks.log, 1);
		world.setBlockMetadataWithNotify(i + 1, j + 52, k + 24, 1, 2);
		setBlock(world, i + 1, j + 52, k + 25, Blocks.log, 1);
		world.setBlockMetadataWithNotify(i + 1, j + 52, k + 25, 1, 2);
		setBlock(world, i + 2, j + 10, k + 17, Blocks.vine, 7);
		world.setBlockMetadataWithNotify(i + 2, j + 10, k + 17, 7, 2);
		setBlock(world, i + 2, j + 11, k + 17, Blocks.vine, 15);
		world.setBlockMetadataWithNotify(i + 2, j + 11, k + 17, 15, 2);
		setBlock(world, i + 2, j + 11, k + 19, Blocks.vine, 4);
		world.setBlockMetadataWithNotify(i + 2, j + 11, k + 19, 4, 2);
		setBlock(world, i + 2, j + 12, k + 16, Blocks.vine, 4);
		world.setBlockMetadataWithNotify(i + 2, j + 12, k + 16, 4, 2);
		setBlock(world, i + 2, j + 12, k + 17, Blocks.vine, 15);
		world.setBlockMetadataWithNotify(i + 2, j + 12, k + 17, 15, 2);
		setBlock(world, i + 2, j + 12, k + 18, Blocks.vine, 15);
		world.setBlockMetadataWithNotify(i + 2, j + 12, k + 18, 15, 2);
		setBlock(world, i + 2, j + 12, k + 19, Blocks.vine, 15);
		world.setBlockMetadataWithNotify(i + 2, j + 12, k + 19, 15, 2);
		setBlock(world, i + 2, j + 13, k + 16, Blocks.vine, 15);
		world.setBlockMetadataWithNotify(i + 2, j + 13, k + 16, 15, 2);
		setBlock(world, i + 2, j + 13, k + 17, Blocks.vine, 15);
		world.setBlockMetadataWithNotify(i + 2, j + 13, k + 17, 15, 2);
		setBlock(world, i + 2, j + 13, k + 18, Blocks.vine, 15);
		world.setBlockMetadataWithNotify(i + 2, j + 13, k + 18, 15, 2);
		setBlock(world, i + 2, j + 13, k + 19, Blocks.vine, 15);
		world.setBlockMetadataWithNotify(i + 2, j + 13, k + 19, 15, 2);
		setBlock(world, i + 2, j + 14, k + 16, Blocks.vine, 15);
		world.setBlockMetadataWithNotify(i + 2, j + 14, k + 16, 15, 2);
		setBlock(world, i + 2, j + 14, k + 17, Blocks.vine, 15);
		world.setBlockMetadataWithNotify(i + 2, j + 14, k + 17, 15, 2);
		setBlock(world, i + 2, j + 14, k + 18, Blocks.vine, 15);
		world.setBlockMetadataWithNotify(i + 2, j + 14, k + 18, 15, 2);
		setBlock(world, i + 2, j + 14, k + 19, Blocks.log, 1);
		world.setBlockMetadataWithNotify(i + 2, j + 14, k + 19, 1, 2);
		setBlock(world, i + 2, j + 14, k + 20, Blocks.vine, 15);
		world.setBlockMetadataWithNotify(i + 2, j + 14, k + 20, 15, 2);
		setBlock(world, i + 2, j + 15, k + 16, Blocks.vine, 15);
		world.setBlockMetadataWithNotify(i + 2, j + 15, k + 16, 15, 2);
		setBlock(world, i + 2, j + 15, k + 17, Blocks.vine, 15);
		world.setBlockMetadataWithNotify(i + 2, j + 15, k + 17, 15, 2);
		setBlock(world, i + 2, j + 15, k + 18, Blocks.log, 1);
		world.setBlockMetadataWithNotify(i + 2, j + 15, k + 18, 1, 2);
		setBlock(world, i + 2, j + 15, k + 19, Blocks.log, 1);
		world.setBlockMetadataWithNotify(i + 2, j + 15, k + 19, 1, 2);
		setBlock(world, i + 2, j + 15, k + 20, Blocks.log, 1);
		world.setBlockMetadataWithNotify(i + 2, j + 15, k + 20, 1, 2);
		setBlock(world, i + 2, j + 15, k + 22, Blocks.log, 1);
		world.setBlockMetadataWithNotify(i + 2, j + 15, k + 22, 1, 2);
		setBlock(world, i + 2, j + 15, k + 23, Blocks.log, 1);
		world.setBlockMetadataWithNotify(i + 2, j + 15, k + 23, 1, 2);
		setBlock(world, i + 2, j + 15, k + 24, Blocks.log, 1);
		world.setBlockMetadataWithNotify(i + 2, j + 15, k + 24, 1, 2);
		setBlock(world, i + 2, j + 15, k + 25, Blocks.log, 1);
		world.setBlockMetadataWithNotify(i + 2, j + 15, k + 25, 1, 2);
		setBlock(world, i + 2, j + 15, k + 26, Blocks.log, 1);
		world.setBlockMetadataWithNotify(i + 2, j + 15, k + 26, 1, 2);
		setBlock(world, i + 2, j + 15, k + 28, Blocks.log, 1);
		world.setBlockMetadataWithNotify(i + 2, j + 15, k + 28, 1, 2);
		setBlock(world, i + 2, j + 16, k + 16, Blocks.vine, 15);
		world.setBlockMetadataWithNotify(i + 2, j + 16, k + 16, 15, 2);
		setBlock(world, i + 2, j + 16, k + 17, Blocks.vine, 15);
		world.setBlockMetadataWithNotify(i + 2, j + 16, k + 17, 15, 2);
		setBlock(world, i + 2, j + 16, k + 18, Blocks.log, 1);
		world.setBlockMetadataWithNotify(i + 2, j + 16, k + 18, 1, 2);
		setBlock(world, i + 2, j + 16, k + 19, Blocks.log, 1);
		world.setBlockMetadataWithNotify(i + 2, j + 16, k + 19, 1, 2);
		setBlock(world, i + 2, j + 16, k + 20, Blocks.log, 1);
		world.setBlockMetadataWithNotify(i + 2, j + 16, k + 20, 1, 2);
		setBlock(world, i + 2, j + 16, k + 23, Blocks.log, 1);
		world.setBlockMetadataWithNotify(i + 2, j + 16, k + 23, 1, 2);
		setBlock(world, i + 2, j + 16, k + 24, Blocks.log, 1);
		world.setBlockMetadataWithNotify(i + 2, j + 16, k + 24, 1, 2);
		setBlock(world, i + 2, j + 16, k + 25, Blocks.log, 1);
		world.setBlockMetadataWithNotify(i + 2, j + 16, k + 25, 1, 2);
		setBlock(world, i + 2, j + 16, k + 26, Blocks.log, 1);
		world.setBlockMetadataWithNotify(i + 2, j + 16, k + 26, 1, 2);
		setBlock(world, i + 2, j + 16, k + 28, Blocks.log, 1);
		world.setBlockMetadataWithNotify(i + 2, j + 16, k + 28, 1, 2);
		setBlock(world, i + 2, j + 16, k + 29, Blocks.log, 1);
		world.setBlockMetadataWithNotify(i + 2, j + 16, k + 29, 1, 2);
		setBlock(world, i + 2, j + 16, k + 31, Blocks.log, 1);
		world.setBlockMetadataWithNotify(i + 2, j + 16, k + 31, 1, 2);
		setBlock(world, i + 2, j + 17, k + 12, Blocks.vine, 4);
		world.setBlockMetadataWithNotify(i + 2, j + 17, k + 12, 4, 2);
		setBlock(world, i + 2, j + 17, k + 13, Blocks.vine, 6);
		world.setBlockMetadataWithNotify(i + 2, j + 17, k + 13, 6, 2);
		setBlock(world, i + 2, j + 17, k + 17, Blocks.vine, 15);
		world.setBlockMetadataWithNotify(i + 2, j + 17, k + 17, 15, 2);
		setBlock(world, i + 2, j + 17, k + 18, Blocks.log, 1);
		world.setBlockMetadataWithNotify(i + 2, j + 17, k + 18, 1, 2);
		setBlock(world, i + 2, j + 17, k + 19, Blocks.log, 1);
		world.setBlockMetadataWithNotify(i + 2, j + 17, k + 19, 1, 2);
		setBlock(world, i + 2, j + 17, k + 20, Blocks.log, 1);
		world.setBlockMetadataWithNotify(i + 2, j + 17, k + 20, 1, 2);
		setBlock(world, i + 2, j + 17, k + 23, Blocks.log, 1);
		world.setBlockMetadataWithNotify(i + 2, j + 17, k + 23, 1, 2);
		setBlock(world, i + 2, j + 17, k + 24, Blocks.log, 1);
		world.setBlockMetadataWithNotify(i + 2, j + 17, k + 24, 1, 2);
		setBlock(world, i + 2, j + 17, k + 25, Blocks.log, 1);
		world.setBlockMetadataWithNotify(i + 2, j + 17, k + 25, 1, 2);
		setBlock(world, i + 2, j + 17, k + 26, Blocks.log, 1);
		world.setBlockMetadataWithNotify(i + 2, j + 17, k + 26, 1, 2);
		setBlock(world, i + 2, j + 17, k + 27, Blocks.log, 1);
		world.setBlockMetadataWithNotify(i + 2, j + 17, k + 27, 1, 2);
		setBlock(world, i + 2, j + 17, k + 28, Blocks.log, 1);
		world.setBlockMetadataWithNotify(i + 2, j + 17, k + 28, 1, 2);
		setBlock(world, i + 2, j + 17, k + 29, Blocks.log, 1);
		world.setBlockMetadataWithNotify(i + 2, j + 17, k + 29, 1, 2);
		setBlock(world, i + 2, j + 17, k + 30, Blocks.log, 1);
		world.setBlockMetadataWithNotify(i + 2, j + 17, k + 30, 1, 2);
		setBlock(world, i + 2, j + 17, k + 31, Blocks.log, 1);
		world.setBlockMetadataWithNotify(i + 2, j + 17, k + 31, 1, 2);
		setBlock(world, i + 2, j + 18, k + 11, Blocks.vine, 15);
		world.setBlockMetadataWithNotify(i + 2, j + 18, k + 11, 15, 2);
		setBlock(world, i + 2, j + 18, k + 12, Blocks.vine, 13);
		world.setBlockMetadataWithNotify(i + 2, j + 18, k + 12, 13, 2);
		setBlock(world, i + 2, j + 18, k + 13, Blocks.vine, 6);
		world.setBlockMetadataWithNotify(i + 2, j + 18, k + 13, 6, 2);
		setBlock(world, i + 2, j + 18, k + 17, Blocks.vine, 15);
		world.setBlockMetadataWithNotify(i + 2, j + 18, k + 17, 15, 2);
		setBlock(world, i + 2, j + 18, k + 18, Blocks.log, 1);
		world.setBlockMetadataWithNotify(i + 2, j + 18, k + 18, 1, 2);
		setBlock(world, i + 2, j + 18, k + 19, Blocks.log, 1);
		world.setBlockMetadataWithNotify(i + 2, j + 18, k + 19, 1, 2);
		setBlock(world, i + 2, j + 18, k + 20, Blocks.log, 1);
		world.setBlockMetadataWithNotify(i + 2, j + 18, k + 20, 1, 2);
		setBlock(world, i + 2, j + 18, k + 21, Blocks.log, 1);
		world.setBlockMetadataWithNotify(i + 2, j + 18, k + 21, 1, 2);
		setBlock(world, i + 2, j + 18, k + 25, Blocks.log, 1);
		world.setBlockMetadataWithNotify(i + 2, j + 18, k + 25, 1, 2);
		setBlock(world, i + 2, j + 18, k + 26, Blocks.log, 1);
		world.setBlockMetadataWithNotify(i + 2, j + 18, k + 26, 1, 2);
		setBlock(world, i + 2, j + 18, k + 27, Blocks.log, 1);
		world.setBlockMetadataWithNotify(i + 2, j + 18, k + 27, 1, 2);
		setBlock(world, i + 2, j + 18, k + 28, Blocks.log, 1);
		world.setBlockMetadataWithNotify(i + 2, j + 18, k + 28, 1, 2);
		setBlock(world, i + 2, j + 18, k + 29, Blocks.log, 1);
		world.setBlockMetadataWithNotify(i + 2, j + 18, k + 29, 1, 2);
		setBlock(world, i + 2, j + 19, k + 11, Blocks.vine, 15);
		world.setBlockMetadataWithNotify(i + 2, j + 19, k + 11, 15, 2);
		setBlock(world, i + 2, j + 19, k + 12, Blocks.vine, 15);
		world.setBlockMetadataWithNotify(i + 2, j + 19, k + 12, 15, 2);
		setBlock(world, i + 2, j + 19, k + 13, Blocks.vine, 15);
		world.setBlockMetadataWithNotify(i + 2, j + 19, k + 13, 15, 2);
		setBlock(world, i + 2, j + 19, k + 14, Blocks.vine, 15);
		world.setBlockMetadataWithNotify(i + 2, j + 19, k + 14, 15, 2);
		setBlock(world, i + 2, j + 19, k + 15, Blocks.vine, 15);
		world.setBlockMetadataWithNotify(i + 2, j + 19, k + 15, 15, 2);
		setBlock(world, i + 2, j + 19, k + 16, Blocks.vine, 15);
		world.setBlockMetadataWithNotify(i + 2, j + 19, k + 16, 15, 2);
		setBlock(world, i + 2, j + 19, k + 17, Blocks.vine, 15);
		world.setBlockMetadataWithNotify(i + 2, j + 19, k + 17, 15, 2);
		setBlock(world, i + 2, j + 19, k + 18, Blocks.log, 1);
		world.setBlockMetadataWithNotify(i + 2, j + 19, k + 18, 1, 2);
		setBlock(world, i + 2, j + 19, k + 19, Blocks.log, 1);
		world.setBlockMetadataWithNotify(i + 2, j + 19, k + 19, 1, 2);
		setBlock(world, i + 2, j + 19, k + 20, Blocks.log, 1);
		world.setBlockMetadataWithNotify(i + 2, j + 19, k + 20, 1, 2);
		setBlock(world, i + 2, j + 19, k + 21, Blocks.log, 1);
		world.setBlockMetadataWithNotify(i + 2, j + 19, k + 21, 1, 2);
		setBlock(world, i + 2, j + 19, k + 22, Blocks.log, 1);
		world.setBlockMetadataWithNotify(i + 2, j + 19, k + 22, 1, 2);
		setBlock(world, i + 2, j + 19, k + 23, Blocks.log, 1);
		world.setBlockMetadataWithNotify(i + 2, j + 19, k + 23, 1, 2);
		setBlock(world, i + 2, j + 19, k + 24, Blocks.log, 1);
		world.setBlockMetadataWithNotify(i + 2, j + 19, k + 24, 1, 2);
		setBlock(world, i + 2, j + 19, k + 25, Blocks.log, 1);
		world.setBlockMetadataWithNotify(i + 2, j + 19, k + 25, 1, 2);
		setBlock(world, i + 2, j + 19, k + 26, Blocks.log, 1);
		world.setBlockMetadataWithNotify(i + 2, j + 19, k + 26, 1, 2);
		setBlock(world, i + 2, j + 19, k + 27, Blocks.log, 1);
		world.setBlockMetadataWithNotify(i + 2, j + 19, k + 27, 1, 2);
		setBlock(world, i + 2, j + 19, k + 28, Blocks.log, 1);
		world.setBlockMetadataWithNotify(i + 2, j + 19, k + 28, 1, 2);
		setBlock(world, i + 2, j + 19, k + 29, Blocks.log, 1);
		world.setBlockMetadataWithNotify(i + 2, j + 19, k + 29, 1, 2);
		setBlock(world, i + 2, j + 20, k + 9, Blocks.planks, 5);
		world.setBlockMetadataWithNotify(i + 2, j + 20, k + 9, 5, 2);
		setBlock(world, i + 2, j + 20, k + 10, Blocks.planks, 5);
		world.setBlockMetadataWithNotify(i + 2, j + 20, k + 10, 5, 2);
		setBlock(world, i + 2, j + 20, k + 11, Blocks.planks, 5);
		world.setBlockMetadataWithNotify(i + 2, j + 20, k + 11, 5, 2);
		setBlock(world, i + 2, j + 20, k + 12, Blocks.planks, 5);
		world.setBlockMetadataWithNotify(i + 2, j + 20, k + 12, 5, 2);
		setBlock(world, i + 2, j + 20, k + 13, Blocks.planks, 5);
		world.setBlockMetadataWithNotify(i + 2, j + 20, k + 13, 5, 2);
		setBlock(world, i + 2, j + 20, k + 14, Blocks.planks, 5);
		world.setBlockMetadataWithNotify(i + 2, j + 20, k + 14, 5, 2);
		setBlock(world, i + 2, j + 20, k + 15, Blocks.log, 1);
		world.setBlockMetadataWithNotify(i + 2, j + 20, k + 15, 1, 2);
		setBlock(world, i + 2, j + 20, k + 16, Blocks.planks, 5);
		world.setBlockMetadataWithNotify(i + 2, j + 20, k + 16, 5, 2);
		setBlock(world, i + 2, j + 20, k + 17, Blocks.planks, 5);
		world.setBlockMetadataWithNotify(i + 2, j + 20, k + 17, 5, 2);
		setBlock(world, i + 2, j + 20, k + 18, Blocks.log, 1);
		world.setBlockMetadataWithNotify(i + 2, j + 20, k + 18, 1, 2);
		setBlock(world, i + 2, j + 20, k + 19, Blocks.planks, 5);
		world.setBlockMetadataWithNotify(i + 2, j + 20, k + 19, 5, 2);
		setBlock(world, i + 2, j + 20, k + 20, Blocks.planks, 5);
		world.setBlockMetadataWithNotify(i + 2, j + 20, k + 20, 5, 2);
		setBlock(world, i + 2, j + 20, k + 21, Blocks.log, 1);
		world.setBlockMetadataWithNotify(i + 2, j + 20, k + 21, 1, 2);
		setBlock(world, i + 2, j + 20, k + 22, Blocks.planks, 5);
		world.setBlockMetadataWithNotify(i + 2, j + 20, k + 22, 5, 2);
		setBlock(world, i + 2, j + 20, k + 23, Blocks.planks, 5);
		world.setBlockMetadataWithNotify(i + 2, j + 20, k + 23, 5, 2);
		setBlock(world, i + 2, j + 20, k + 24, Blocks.log, 1);
		world.setBlockMetadataWithNotify(i + 2, j + 20, k + 24, 1, 2);
		setBlock(world, i + 2, j + 20, k + 25, Blocks.planks, 5);
		world.setBlockMetadataWithNotify(i + 2, j + 20, k + 25, 5, 2);
		setBlock(world, i + 2, j + 20, k + 26, Blocks.planks, 5);
		world.setBlockMetadataWithNotify(i + 2, j + 20, k + 26, 5, 2);
		setBlock(world, i + 2, j + 20, k + 27, Blocks.log, 1);
		world.setBlockMetadataWithNotify(i + 2, j + 20, k + 27, 1, 2);
		setBlock(world, i + 2, j + 21, k + 20, Blocks.chest, 5);
		LootGenUtils.fillLootChest(world.provider.dimensionId, world.rand, (TileEntityChest)world.getTileEntity(i + 2, j + 21, k + 20));
		world.setBlockMetadataWithNotify(i + 2, j + 21, k + 20, 5, 2);
		setBlock(world, i + 2, j + 21, k + 21, Blocks.spruce_stairs, 1);
		world.setBlockMetadataWithNotify(i + 2, j + 21, k + 21, 1, 2);
		setBlock(world, i + 2, j + 21, k + 22, Blocks.chest, 5);
		LootGenUtils.fillLootChest(world.provider.dimensionId, world.rand, (TileEntityChest)world.getTileEntity(i + 2, j + 21, k + 22));
		world.setBlockMetadataWithNotify(i + 2, j + 21, k + 22, 5, 2);
		setBlock(world, i + 2, j + 23, k + 13, Blocks.torch, 2);
		world.setBlockMetadataWithNotify(i + 2, j + 23, k + 13, 2, 2);
		setBlock(world, i + 2, j + 23, k + 21, Blocks.torch, 1);
		world.setBlockMetadataWithNotify(i + 2, j + 23, k + 21, 1, 2);
		setBlock(world, i + 2, j + 23, k + 29, Blocks.torch, 2);
		world.setBlockMetadataWithNotify(i + 2, j + 23, k + 29, 2, 2);
		setBlock(world, i + 2, j + 24, k + 12, Blocks.log, 1);
		world.setBlockMetadataWithNotify(i + 2, j + 24, k + 12, 1, 2);
		setBlock(world, i + 2, j + 24, k + 13, Blocks.log, 1);
		world.setBlockMetadataWithNotify(i + 2, j + 24, k + 13, 1, 2);
		setBlock(world, i + 2, j + 24, k + 14, Blocks.log, 1);
		world.setBlockMetadataWithNotify(i + 2, j + 24, k + 14, 1, 2);
		setBlock(world, i + 2, j + 24, k + 15, Blocks.log, 1);
		world.setBlockMetadataWithNotify(i + 2, j + 24, k + 15, 1, 2);
		setBlock(world, i + 2, j + 24, k + 16, Blocks.log, 1);
		world.setBlockMetadataWithNotify(i + 2, j + 24, k + 16, 1, 2);
		setBlock(world, i + 2, j + 24, k + 26, Blocks.log, 1);
		world.setBlockMetadataWithNotify(i + 2, j + 24, k + 26, 1, 2);
		setBlock(world, i + 2, j + 24, k + 27, Blocks.log, 1);
		world.setBlockMetadataWithNotify(i + 2, j + 24, k + 27, 1, 2);
		setBlock(world, i + 2, j + 24, k + 28, Blocks.log, 1);
		world.setBlockMetadataWithNotify(i + 2, j + 24, k + 28, 1, 2);
		setBlock(world, i + 2, j + 24, k + 29, Blocks.log, 1);
		world.setBlockMetadataWithNotify(i + 2, j + 24, k + 29, 1, 2);
		setBlock(world, i + 2, j + 24, k + 30, Blocks.log, 1);
		world.setBlockMetadataWithNotify(i + 2, j + 24, k + 30, 1, 2);
		setBlock(world, i + 2, j + 25, k + 13, Blocks.log, 1);
		world.setBlockMetadataWithNotify(i + 2, j + 25, k + 13, 1, 2);
		setBlock(world, i + 2, j + 25, k + 14, Blocks.log, 1);
		world.setBlockMetadataWithNotify(i + 2, j + 25, k + 14, 1, 2);
		setBlock(world, i + 2, j + 25, k + 15, Blocks.log, 1);
		world.setBlockMetadataWithNotify(i + 2, j + 25, k + 15, 1, 2);
		setBlock(world, i + 2, j + 25, k + 16, Blocks.log, 1);
		world.setBlockMetadataWithNotify(i + 2, j + 25, k + 16, 1, 2);
		setBlock(world, i + 2, j + 25, k + 17, Blocks.log, 1);
		world.setBlockMetadataWithNotify(i + 2, j + 25, k + 17, 1, 2);
		setBlock(world, i + 2, j + 25, k + 25, Blocks.log, 1);
		world.setBlockMetadataWithNotify(i + 2, j + 25, k + 25, 1, 2);
		setBlock(world, i + 2, j + 25, k + 26, Blocks.log, 1);
		world.setBlockMetadataWithNotify(i + 2, j + 25, k + 26, 1, 2);
		setBlock(world, i + 2, j + 25, k + 27, Blocks.log, 1);
		world.setBlockMetadataWithNotify(i + 2, j + 25, k + 27, 1, 2);
		setBlock(world, i + 2, j + 25, k + 28, Blocks.log, 1);
		world.setBlockMetadataWithNotify(i + 2, j + 25, k + 28, 1, 2);
		setBlock(world, i + 2, j + 25, k + 29, Blocks.log, 1);
		world.setBlockMetadataWithNotify(i + 2, j + 25, k + 29, 1, 2);
		setBlock(world, i + 2, j + 26, k + 13, Blocks.log, 1);
		world.setBlockMetadataWithNotify(i + 2, j + 26, k + 13, 1, 2);
		setBlock(world, i + 2, j + 26, k + 14, Blocks.log, 1);
		world.setBlockMetadataWithNotify(i + 2, j + 26, k + 14, 1, 2);
		setBlock(world, i + 2, j + 26, k + 15, Blocks.log, 1);
		world.setBlockMetadataWithNotify(i + 2, j + 26, k + 15, 1, 2);
		setBlock(world, i + 2, j + 26, k + 16, Blocks.log, 1);
		world.setBlockMetadataWithNotify(i + 2, j + 26, k + 16, 1, 2);
		setBlock(world, i + 2, j + 26, k + 17, Blocks.log, 1);
		world.setBlockMetadataWithNotify(i + 2, j + 26, k + 17, 1, 2);
		setBlock(world, i + 2, j + 26, k + 18, Blocks.log, 1);
		world.setBlockMetadataWithNotify(i + 2, j + 26, k + 18, 1, 2);
		setBlock(world, i + 2, j + 26, k + 20, Blocks.log, 1);
		world.setBlockMetadataWithNotify(i + 2, j + 26, k + 20, 1, 2);
		setBlock(world, i + 2, j + 26, k + 21, Blocks.log, 1);
		world.setBlockMetadataWithNotify(i + 2, j + 26, k + 21, 1, 2);
		setBlock(world, i + 2, j + 26, k + 22, Blocks.log, 1);
		world.setBlockMetadataWithNotify(i + 2, j + 26, k + 22, 1, 2);
		setBlock(world, i + 2, j + 26, k + 24, Blocks.log, 1);
		world.setBlockMetadataWithNotify(i + 2, j + 26, k + 24, 1, 2);
		setBlock(world, i + 2, j + 26, k + 25, Blocks.log, 1);
		world.setBlockMetadataWithNotify(i + 2, j + 26, k + 25, 1, 2);
		setBlock(world, i + 2, j + 26, k + 26, Blocks.log, 1);
		world.setBlockMetadataWithNotify(i + 2, j + 26, k + 26, 1, 2);
		setBlock(world, i + 2, j + 26, k + 27, Blocks.log, 1);
		world.setBlockMetadataWithNotify(i + 2, j + 26, k + 27, 1, 2);
		setBlock(world, i + 2, j + 26, k + 28, Blocks.log, 1);
		world.setBlockMetadataWithNotify(i + 2, j + 26, k + 28, 1, 2);
		setBlock(world, i + 2, j + 26, k + 29, Blocks.log, 1);
		world.setBlockMetadataWithNotify(i + 2, j + 26, k + 29, 1, 2);
		setBlock(world, i + 2, j + 27, k + 14, Blocks.log, 1);
		world.setBlockMetadataWithNotify(i + 2, j + 27, k + 14, 1, 2);
		setBlock(world, i + 2, j + 27, k + 15, Blocks.log, 1);
		world.setBlockMetadataWithNotify(i + 2, j + 27, k + 15, 1, 2);
		setBlock(world, i + 2, j + 27, k + 16, Blocks.log, 1);
		world.setBlockMetadataWithNotify(i + 2, j + 27, k + 16, 1, 2);
		setBlock(world, i + 2, j + 27, k + 17, Blocks.log, 1);
		world.setBlockMetadataWithNotify(i + 2, j + 27, k + 17, 1, 2);
		setBlock(world, i + 2, j + 27, k + 18, Blocks.log, 1);
		world.setBlockMetadataWithNotify(i + 2, j + 27, k + 18, 1, 2);
		setBlock(world, i + 2, j + 27, k + 19, Blocks.log, 1);
		world.setBlockMetadataWithNotify(i + 2, j + 27, k + 19, 1, 2);
		setBlock(world, i + 2, j + 27, k + 20, Blocks.log, 1);
		world.setBlockMetadataWithNotify(i + 2, j + 27, k + 20, 1, 2);
		setBlock(world, i + 2, j + 27, k + 21, Blocks.log, 1);
		world.setBlockMetadataWithNotify(i + 2, j + 27, k + 21, 1, 2);
		setBlock(world, i + 2, j + 27, k + 22, Blocks.log, 1);
		world.setBlockMetadataWithNotify(i + 2, j + 27, k + 22, 1, 2);
		setBlock(world, i + 2, j + 27, k + 23, Blocks.log, 1);
		world.setBlockMetadataWithNotify(i + 2, j + 27, k + 23, 1, 2);
		setBlock(world, i + 2, j + 27, k + 24, Blocks.log, 1);
		world.setBlockMetadataWithNotify(i + 2, j + 27, k + 24, 1, 2);
		setBlock(world, i + 2, j + 27, k + 25, Blocks.log, 1);
		world.setBlockMetadataWithNotify(i + 2, j + 27, k + 25, 1, 2);
		setBlock(world, i + 2, j + 27, k + 26, Blocks.log, 1);
		world.setBlockMetadataWithNotify(i + 2, j + 27, k + 26, 1, 2);
		setBlock(world, i + 2, j + 27, k + 27, Blocks.log, 1);
		world.setBlockMetadataWithNotify(i + 2, j + 27, k + 27, 1, 2);
		setBlock(world, i + 2, j + 27, k + 28, Blocks.log, 1);
		world.setBlockMetadataWithNotify(i + 2, j + 27, k + 28, 1, 2);
		setBlock(world, i + 2, j + 28, k + 15, Blocks.log, 1);
		world.setBlockMetadataWithNotify(i + 2, j + 28, k + 15, 1, 2);
		setBlock(world, i + 2, j + 28, k + 16, Blocks.log, 1);
		world.setBlockMetadataWithNotify(i + 2, j + 28, k + 16, 1, 2);
		setBlock(world, i + 2, j + 28, k + 17, Blocks.log, 1);
		world.setBlockMetadataWithNotify(i + 2, j + 28, k + 17, 1, 2);
		setBlock(world, i + 2, j + 28, k + 18, Blocks.log, 1);
		world.setBlockMetadataWithNotify(i + 2, j + 28, k + 18, 1, 2);
		setBlock(world, i + 2, j + 28, k + 19, Blocks.log, 1);
		world.setBlockMetadataWithNotify(i + 2, j + 28, k + 19, 1, 2);
		setBlock(world, i + 2, j + 28, k + 20, Blocks.log, 1);
		world.setBlockMetadataWithNotify(i + 2, j + 28, k + 20, 1, 2);
		setBlock(world, i + 2, j + 28, k + 21, Blocks.log, 1);
		world.setBlockMetadataWithNotify(i + 2, j + 28, k + 21, 1, 2);
		setBlock(world, i + 2, j + 28, k + 22, Blocks.log, 1);
		world.setBlockMetadataWithNotify(i + 2, j + 28, k + 22, 1, 2);
		setBlock(world, i + 2, j + 28, k + 23, Blocks.log, 1);
		world.setBlockMetadataWithNotify(i + 2, j + 28, k + 23, 1, 2);
		setBlock(world, i + 2, j + 28, k + 24, Blocks.log, 1);
		world.setBlockMetadataWithNotify(i + 2, j + 28, k + 24, 1, 2);
		setBlock(world, i + 2, j + 28, k + 25, Blocks.log, 1);
		world.setBlockMetadataWithNotify(i + 2, j + 28, k + 25, 1, 2);
		setBlock(world, i + 2, j + 28, k + 26, Blocks.log, 1);
		world.setBlockMetadataWithNotify(i + 2, j + 28, k + 26, 1, 2);
		setBlock(world, i + 2, j + 28, k + 27, Blocks.log, 1);
		world.setBlockMetadataWithNotify(i + 2, j + 28, k + 27, 1, 2);
		setBlock(world, i + 2, j + 29, k + 18, Blocks.log, 1);
		world.setBlockMetadataWithNotify(i + 2, j + 29, k + 18, 1, 2);
		setBlock(world, i + 2, j + 29, k + 19, Blocks.log, 1);
		world.setBlockMetadataWithNotify(i + 2, j + 29, k + 19, 1, 2);
		setBlock(world, i + 2, j + 29, k + 20, Blocks.log, 1);
		world.setBlockMetadataWithNotify(i + 2, j + 29, k + 20, 1, 2);
		setBlock(world, i + 2, j + 29, k + 21, Blocks.log, 1);
		world.setBlockMetadataWithNotify(i + 2, j + 29, k + 21, 1, 2);
		setBlock(world, i + 2, j + 29, k + 22, Blocks.log, 1);
		world.setBlockMetadataWithNotify(i + 2, j + 29, k + 22, 1, 2);
		setBlock(world, i + 2, j + 29, k + 23, Blocks.log, 1);
		world.setBlockMetadataWithNotify(i + 2, j + 29, k + 23, 1, 2);
		setBlock(world, i + 2, j + 29, k + 24, Blocks.log, 1);
		world.setBlockMetadataWithNotify(i + 2, j + 29, k + 24, 1, 2);
		setBlock(world, i + 2, j + 36, k + 23, Blocks.leaves, 7);
		world.setBlockMetadataWithNotify(i + 2, j + 36, k + 23, 7, 2);
		setBlock(world, i + 2, j + 36, k + 24, Blocks.leaves, 7);
		world.setBlockMetadataWithNotify(i + 2, j + 36, k + 24, 7, 2);
		setBlock(world, i + 2, j + 36, k + 25, Blocks.leaves, 7);
		world.setBlockMetadataWithNotify(i + 2, j + 36, k + 25, 7, 2);
		setBlock(world, i + 2, j + 36, k + 29, Blocks.log, 3);
		world.setBlockMetadataWithNotify(i + 2, j + 36, k + 29, 3, 2);
		setBlock(world, i + 2, j + 36, k + 30, Blocks.log, 3);
		world.setBlockMetadataWithNotify(i + 2, j + 36, k + 30, 3, 2);
		setBlock(world, i + 2, j + 37, k + 24, Blocks.leaves, 7);
		world.setBlockMetadataWithNotify(i + 2, j + 37, k + 24, 7, 2);
		setBlock(world, i + 2, j + 37, k + 25, Blocks.leaves, 7);
		world.setBlockMetadataWithNotify(i + 2, j + 37, k + 25, 7, 2);
		setBlock(world, i + 2, j + 37, k + 26, Blocks.leaves, 7);
		world.setBlockMetadataWithNotify(i + 2, j + 37, k + 26, 7, 2);
		setBlock(world, i + 2, j + 37, k + 27, Blocks.leaves, 7);
		world.setBlockMetadataWithNotify(i + 2, j + 37, k + 27, 7, 2);
		setBlock(world, i + 2, j + 37, k + 28, Blocks.leaves, 7);
		world.setBlockMetadataWithNotify(i + 2, j + 37, k + 28, 7, 2);
		setBlock(world, i + 2, j + 37, k + 29, Blocks.leaves, 7);
		world.setBlockMetadataWithNotify(i + 2, j + 37, k + 29, 7, 2);
		setBlock(world, i + 2, j + 38, k + 26, Blocks.leaves, 7);
		world.setBlockMetadataWithNotify(i + 2, j + 38, k + 26, 7, 2);
		setBlock(world, i + 2, j + 38, k + 27, Blocks.leaves, 7);
		world.setBlockMetadataWithNotify(i + 2, j + 38, k + 27, 7, 2);
		setBlock(world, i + 2, j + 38, k + 28, Blocks.leaves, 7);
		world.setBlockMetadataWithNotify(i + 2, j + 38, k + 28, 7, 2);
		setBlock(world, i + 2, j + 39, k + 27, Blocks.leaves, 7);
		world.setBlockMetadataWithNotify(i + 2, j + 39, k + 27, 7, 2);
		setBlock(world, i + 2, j + 46, k + 19, Blocks.log, 1);
		world.setBlockMetadataWithNotify(i + 2, j + 46, k + 19, 1, 2);
		setBlock(world, i + 2, j + 46, k + 20, Blocks.log, 1);
		world.setBlockMetadataWithNotify(i + 2, j + 46, k + 20, 1, 2);
		setBlock(world, i + 2, j + 46, k + 21, Blocks.log, 1);
		world.setBlockMetadataWithNotify(i + 2, j + 46, k + 21, 1, 2);
		setBlock(world, i + 2, j + 46, k + 22, Blocks.log, 1);
		world.setBlockMetadataWithNotify(i + 2, j + 46, k + 22, 1, 2);
		setBlock(world, i + 2, j + 46, k + 23, Blocks.log, 1);
		world.setBlockMetadataWithNotify(i + 2, j + 46, k + 23, 1, 2);
		setBlock(world, i + 2, j + 46, k + 24, Blocks.log, 1);
		world.setBlockMetadataWithNotify(i + 2, j + 46, k + 24, 1, 2);
		setBlock(world, i + 2, j + 47, k + 18, Blocks.spruce_stairs, 4);
		world.setBlockMetadataWithNotify(i + 2, j + 47, k + 18, 4, 2);
		setBlock(world, i + 2, j + 47, k + 25, Blocks.spruce_stairs, 4);
		world.setBlockMetadataWithNotify(i + 2, j + 47, k + 25, 4, 2);
		setBlock(world, i + 2, j + 48, k + 18, Blocks.log, 1);
		world.setBlockMetadataWithNotify(i + 2, j + 48, k + 18, 1, 2);
		setBlock(world, i + 2, j + 48, k + 25, Blocks.log, 1);
		world.setBlockMetadataWithNotify(i + 2, j + 48, k + 25, 1, 2);
		setBlock(world, i + 2, j + 49, k + 18, Blocks.log, 1);
		world.setBlockMetadataWithNotify(i + 2, j + 49, k + 18, 1, 2);
		setBlock(world, i + 2, j + 49, k + 19, Blocks.torch, 3);
		world.setBlockMetadataWithNotify(i + 2, j + 49, k + 19, 3, 2);
		setBlock(world, i + 2, j + 49, k + 24, Blocks.torch, 4);
		world.setBlockMetadataWithNotify(i + 2, j + 49, k + 24, 4, 2);
		setBlock(world, i + 2, j + 49, k + 25, Blocks.log, 1);
		world.setBlockMetadataWithNotify(i + 2, j + 49, k + 25, 1, 2);
		setBlock(world, i + 2, j + 51, k + 16, Blocks.log, 1);
		world.setBlockMetadataWithNotify(i + 2, j + 51, k + 16, 1, 2);
		setBlock(world, i + 2, j + 51, k + 17, Blocks.log, 1);
		world.setBlockMetadataWithNotify(i + 2, j + 51, k + 17, 1, 2);
		setBlock(world, i + 2, j + 51, k + 18, Blocks.log, 1);
		world.setBlockMetadataWithNotify(i + 2, j + 51, k + 18, 1, 2);
		setBlock(world, i + 2, j + 51, k + 19, Blocks.log, 1);
		world.setBlockMetadataWithNotify(i + 2, j + 51, k + 19, 1, 2);
		setBlock(world, i + 2, j + 51, k + 20, Blocks.log, 1);
		world.setBlockMetadataWithNotify(i + 2, j + 51, k + 20, 1, 2);
		setBlock(world, i + 2, j + 51, k + 21, Blocks.log, 1);
		world.setBlockMetadataWithNotify(i + 2, j + 51, k + 21, 1, 2);
		setBlock(world, i + 2, j + 51, k + 22, Blocks.log, 1);
		world.setBlockMetadataWithNotify(i + 2, j + 51, k + 22, 1, 2);
		setBlock(world, i + 2, j + 51, k + 23, Blocks.log, 1);
		world.setBlockMetadataWithNotify(i + 2, j + 51, k + 23, 1, 2);
		setBlock(world, i + 2, j + 51, k + 24, Blocks.log, 1);
		world.setBlockMetadataWithNotify(i + 2, j + 51, k + 24, 1, 2);
		setBlock(world, i + 2, j + 51, k + 25, Blocks.log, 1);
		world.setBlockMetadataWithNotify(i + 2, j + 51, k + 25, 1, 2);
		setBlock(world, i + 2, j + 51, k + 26, Blocks.log, 1);
		world.setBlockMetadataWithNotify(i + 2, j + 51, k + 26, 1, 2);
		setBlock(world, i + 2, j + 51, k + 27, Blocks.log, 1);
		world.setBlockMetadataWithNotify(i + 2, j + 51, k + 27, 1, 2);
		setBlock(world, i + 2, j + 52, k + 17, Blocks.log, 1);
		world.setBlockMetadataWithNotify(i + 2, j + 52, k + 17, 1, 2);
		setBlock(world, i + 2, j + 52, k + 18, Blocks.log, 1);
		world.setBlockMetadataWithNotify(i + 2, j + 52, k + 18, 1, 2);
		setBlock(world, i + 2, j + 52, k + 19, Blocks.log, 1);
		world.setBlockMetadataWithNotify(i + 2, j + 52, k + 19, 1, 2);
		setBlock(world, i + 2, j + 52, k + 20, Blocks.log, 1);
		world.setBlockMetadataWithNotify(i + 2, j + 52, k + 20, 1, 2);
		setBlock(world, i + 2, j + 52, k + 21, Blocks.log, 1);
		world.setBlockMetadataWithNotify(i + 2, j + 52, k + 21, 1, 2);
		setBlock(world, i + 2, j + 52, k + 22, Blocks.log, 1);
		world.setBlockMetadataWithNotify(i + 2, j + 52, k + 22, 1, 2);
		setBlock(world, i + 2, j + 52, k + 23, Blocks.log, 1);
		world.setBlockMetadataWithNotify(i + 2, j + 52, k + 23, 1, 2);
		setBlock(world, i + 2, j + 52, k + 24, Blocks.log, 1);
		world.setBlockMetadataWithNotify(i + 2, j + 52, k + 24, 1, 2);
		
		generate2(world, rand, i, j, k);
		return true;
		}

	
	public boolean generate2(World world, Random rand, int i, int j, int k)
	{
		setBlock(world, i + 2, j + 52, k + 25, Blocks.log, 1);
		world.setBlockMetadataWithNotify(i + 2, j + 52, k + 25, 1, 2);
		setBlock(world, i + 2, j + 52, k + 26, Blocks.log, 1);
		world.setBlockMetadataWithNotify(i + 2, j + 52, k + 26, 1, 2);
		setBlock(world, i + 2, j + 53, k + 20, Blocks.log, 1);
		world.setBlockMetadataWithNotify(i + 2, j + 53, k + 20, 1, 2);
		setBlock(world, i + 2, j + 53, k + 21, Blocks.log, 1);
		world.setBlockMetadataWithNotify(i + 2, j + 53, k + 21, 1, 2);
		setBlock(world, i + 2, j + 53, k + 22, Blocks.log, 1);
		world.setBlockMetadataWithNotify(i + 2, j + 53, k + 22, 1, 2);
		setBlock(world, i + 2, j + 53, k + 23, Blocks.log, 1);
		world.setBlockMetadataWithNotify(i + 2, j + 53, k + 23, 1, 2);
		setBlock(world, i + 3, j + 10, k + 17, Blocks.vine, 3);
		world.setBlockMetadataWithNotify(i + 3, j + 10, k + 17, 3, 2);
		setBlock(world, i + 3, j + 11, k + 16, Blocks.vine, 1);
		world.setBlockMetadataWithNotify(i + 3, j + 11, k + 16, 1, 2);
		setBlock(world, i + 3, j + 11, k + 17, Blocks.vine, 3);
		world.setBlockMetadataWithNotify(i + 3, j + 11, k + 17, 3, 2);
		setBlock(world, i + 3, j + 11, k + 18, Blocks.vine, 12);
		world.setBlockMetadataWithNotify(i + 3, j + 11, k + 18, 12, 2);
		setBlock(world, i + 3, j + 12, k + 16, Blocks.vine, 15);
		world.setBlockMetadataWithNotify(i + 3, j + 12, k + 16, 15, 2);
		setBlock(world, i + 3, j + 12, k + 17, Blocks.vine, 15);
		world.setBlockMetadataWithNotify(i + 3, j + 12, k + 17, 15, 2);
		setBlock(world, i + 3, j + 12, k + 18, Blocks.vine, 15);
		world.setBlockMetadataWithNotify(i + 3, j + 12, k + 18, 15, 2);
		setBlock(world, i + 3, j + 13, k + 16, Blocks.vine, 15);
		world.setBlockMetadataWithNotify(i + 3, j + 13, k + 16, 15, 2);
		setBlock(world, i + 3, j + 13, k + 17, Blocks.vine, 15);
		world.setBlockMetadataWithNotify(i + 3, j + 13, k + 17, 15, 2);
		setBlock(world, i + 3, j + 13, k + 18, Blocks.log, 1);
		world.setBlockMetadataWithNotify(i + 3, j + 13, k + 18, 1, 2);
		setBlock(world, i + 3, j + 14, k + 16, Blocks.vine, 15);
		world.setBlockMetadataWithNotify(i + 3, j + 14, k + 16, 15, 2);
		setBlock(world, i + 3, j + 14, k + 17, Blocks.log, 1);
		world.setBlockMetadataWithNotify(i + 3, j + 14, k + 17, 1, 2);
		setBlock(world, i + 3, j + 14, k + 18, Blocks.log, 1);
		world.setBlockMetadataWithNotify(i + 3, j + 14, k + 18, 1, 2);
		setBlock(world, i + 3, j + 14, k + 19, Blocks.log, 1);
		world.setBlockMetadataWithNotify(i + 3, j + 14, k + 19, 1, 2);
		setBlock(world, i + 3, j + 14, k + 30, Blocks.log, 1);
		world.setBlockMetadataWithNotify(i + 3, j + 14, k + 30, 1, 2);
		setBlock(world, i + 3, j + 15, k + 16, Blocks.vine, 15);
		world.setBlockMetadataWithNotify(i + 3, j + 15, k + 16, 15, 2);
		setBlock(world, i + 3, j + 15, k + 17, Blocks.vine, 15);
		world.setBlockMetadataWithNotify(i + 3, j + 15, k + 17, 15, 2);
		setBlock(world, i + 3, j + 15, k + 18, Blocks.log, 1);
		world.setBlockMetadataWithNotify(i + 3, j + 15, k + 18, 1, 2);
		setBlock(world, i + 3, j + 15, k + 19, Blocks.log, 1);
		world.setBlockMetadataWithNotify(i + 3, j + 15, k + 19, 1, 2);
		setBlock(world, i + 3, j + 15, k + 20, Blocks.log, 1);
		world.setBlockMetadataWithNotify(i + 3, j + 15, k + 20, 1, 2);
		setBlock(world, i + 3, j + 15, k + 29, Blocks.log, 1);
		world.setBlockMetadataWithNotify(i + 3, j + 15, k + 29, 1, 2);
		setBlock(world, i + 3, j + 15, k + 31, Blocks.log, 1);
		world.setBlockMetadataWithNotify(i + 3, j + 15, k + 31, 1, 2);
		setBlock(world, i + 3, j + 16, k + 16, Blocks.vine, 15);
		world.setBlockMetadataWithNotify(i + 3, j + 16, k + 16, 15, 2);
		setBlock(world, i + 3, j + 16, k + 17, Blocks.log, 1);
		world.setBlockMetadataWithNotify(i + 3, j + 16, k + 17, 1, 2);
		setBlock(world, i + 3, j + 16, k + 18, Blocks.log, 1);
		world.setBlockMetadataWithNotify(i + 3, j + 16, k + 18, 1, 2);
		setBlock(world, i + 3, j + 16, k + 19, Blocks.log, 1);
		world.setBlockMetadataWithNotify(i + 3, j + 16, k + 19, 1, 2);
		setBlock(world, i + 3, j + 16, k + 20, Blocks.log, 1);
		world.setBlockMetadataWithNotify(i + 3, j + 16, k + 20, 1, 2);
		setBlock(world, i + 3, j + 16, k + 24, Blocks.log, 1);
		world.setBlockMetadataWithNotify(i + 3, j + 16, k + 24, 1, 2);
		setBlock(world, i + 3, j + 16, k + 25, Blocks.log, 1);
		world.setBlockMetadataWithNotify(i + 3, j + 16, k + 25, 1, 2);
		setBlock(world, i + 3, j + 16, k + 26, Blocks.log, 1);
		world.setBlockMetadataWithNotify(i + 3, j + 16, k + 26, 1, 2);
		setBlock(world, i + 3, j + 16, k + 28, Blocks.log, 1);
		world.setBlockMetadataWithNotify(i + 3, j + 16, k + 28, 1, 2);
		setBlock(world, i + 3, j + 16, k + 30, Blocks.log, 1);
		world.setBlockMetadataWithNotify(i + 3, j + 16, k + 30, 1, 2);
		setBlock(world, i + 3, j + 16, k + 31, Blocks.log, 1);
		world.setBlockMetadataWithNotify(i + 3, j + 16, k + 31, 1, 2);
		setBlock(world, i + 3, j + 17, k + 18, Blocks.log, 1);
		world.setBlockMetadataWithNotify(i + 3, j + 17, k + 18, 1, 2);
		setBlock(world, i + 3, j + 17, k + 19, Blocks.log, 1);
		world.setBlockMetadataWithNotify(i + 3, j + 17, k + 19, 1, 2);
		setBlock(world, i + 3, j + 17, k + 25, Blocks.log, 1);
		world.setBlockMetadataWithNotify(i + 3, j + 17, k + 25, 1, 2);
		setBlock(world, i + 3, j + 17, k + 28, Blocks.log, 1);
		world.setBlockMetadataWithNotify(i + 3, j + 17, k + 28, 1, 2);
		setBlock(world, i + 3, j + 17, k + 29, Blocks.log, 1);
		world.setBlockMetadataWithNotify(i + 3, j + 17, k + 29, 1, 2);
