package com.parzivail.pswm.world.gen.wookietree;


import cpw.mods.fml.common.IWorldGenerator;

import java.util.Random;

import net.minecraft.block.Block;

import net.minecraft.init.Blocks;

import net.minecraft.world.World;

import net.minecraft.world.chunk.IChunkProvider;

import net.minecraft.world.gen.feature.WorldGenerator;


public class WT_40 extends WorldGenerator implements IWorldGenerator

{
	protected Block[] getValidSpawnBlocks()
	
	{
		return new Block[0];
		}

	
	public boolean locationIsValidSpawn(World world, int i, int j, int k)
	
	{
		int distanceToAir = 0;
		Block check = world.getBlock(i, j, k);
		
		while (check != Blocks.air)
		{
			if (distanceToAir > 3) { return false;
			}
			
			distanceToAir++;
			check = world.getBlock(i, j + distanceToAir, k);
			}
		
		j += distanceToAir - 1;
		
		Block block = world.getBlock(i, j, k);
		Block blockAbove = world.getBlock(i, j + 1, k);
		Block blockBelow = world.getBlock(i, j - 1, k);
		
		for (Block x : getValidSpawnBlocks())
		{
			if (blockAbove != Blocks.air) { return false;
			}
			if (block == x) return true;
			if ((block == Blocks.snow) && (blockBelow == x)) { return true;
			}
			}
		
		return false;
		}

	
	
	
	public void generate(Random random, int chunkX, int chunkZ, World world, IChunkProvider chunkGenerator, IChunkProvider chunkProvider)
	{
	}

	
	
	public void setBlock(World world, int x, int y, int z, Block block, int metadata)
	
	{
		world.setBlock(x, y, z, block, metadata, 2);
		}

	
	public boolean generate(World world, Random rand, int i, int j, int k)
	
	{
		k -= 10;
		i -= 10;
		
		setBlock(world, i + 29, j + 47, k + 3, Blocks.fence, 0);
		setBlock(world, i + 30, j + 47, k + 3, Blocks.fence, 0);
		setBlock(world, i + 30, j + 47, k + 4, Blocks.fence, 0);
		setBlock(world, i + 30, j + 47, k + 5, Blocks.fence, 0);
		setBlock(world, i + 30, j + 47, k + 6, Blocks.fence, 0);
		setBlock(world, i + 31, j + 47, k + 6, Blocks.fence, 0);
		setBlock(world, i + 31, j + 47, k + 7, Blocks.fence, 0);
		setBlock(world, i + 31, j + 47, k + 8, Blocks.fence, 0);
		setBlock(world, i + 3, j + 28, k + 0, Blocks.leaves, 7);
		world.setBlockMetadataWithNotify(i + 3, j + 28, k + 0, 7, 2);
		setBlock(world, i + 4, j + 28, k + 0, Blocks.leaves, 7);
		world.setBlockMetadataWithNotify(i + 4, j + 28, k + 0, 7, 2);
		setBlock(world, i + 4, j + 28, k + 1, Blocks.leaves, 7);
		world.setBlockMetadataWithNotify(i + 4, j + 28, k + 1, 7, 2);
		setBlock(world, i + 4, j + 29, k + 0, Blocks.leaves, 7);
		world.setBlockMetadataWithNotify(i + 4, j + 29, k + 0, 7, 2);
		setBlock(world, i + 5, j + 28, k + 0, Blocks.leaves, 7);
		world.setBlockMetadataWithNotify(i + 5, j + 28, k + 0, 7, 2);
		setBlock(world, i + 5, j + 28, k + 1, Blocks.leaves, 7);
		world.setBlockMetadataWithNotify(i + 5, j + 28, k + 1, 7, 2);
		setBlock(world, i + 5, j + 29, k + 0, Blocks.leaves, 7);
		world.setBlockMetadataWithNotify(i + 5, j + 29, k + 0, 7, 2);
		setBlock(world, i + 5, j + 29, k + 1, Blocks.leaves, 7);
		world.setBlockMetadataWithNotify(i + 5, j + 29, k + 1, 7, 2);
		setBlock(world, i + 5, j + 30, k + 0, Blocks.leaves, 7);
		world.setBlockMetadataWithNotify(i + 5, j + 30, k + 0, 7, 2);
		setBlock(world, i + 6, j + 27, k + 0, Blocks.log, 3);
		world.setBlockMetadataWithNotify(i + 6, j + 27, k + 0, 3, 2);
		setBlock(world, i + 6, j + 28, k + 0, Blocks.leaves, 7);
		world.setBlockMetadataWithNotify(i + 6, j + 28, k + 0, 7, 2);
		setBlock(world, i + 6, j + 28, k + 1, Blocks.leaves, 7);
		world.setBlockMetadataWithNotify(i + 6, j + 28, k + 1, 7, 2);
		setBlock(world, i + 6, j + 29, k + 0, Blocks.leaves, 7);
		world.setBlockMetadataWithNotify(i + 6, j + 29, k + 0, 7, 2);
		setBlock(world, i + 7, j + 22, k + 16, Blocks.leaves, 7);
		world.setBlockMetadataWithNotify(i + 7, j + 22, k + 16, 7, 2);
		setBlock(world, i + 7, j + 22, k + 17, Blocks.leaves, 7);
		world.setBlockMetadataWithNotify(i + 7, j + 22, k + 17, 7, 2);
		setBlock(world, i + 7, j + 22, k + 18, Blocks.leaves, 7);
		world.setBlockMetadataWithNotify(i + 7, j + 22, k + 18, 7, 2);
		setBlock(world, i + 7, j + 23, k + 17, Blocks.leaves, 7);
		world.setBlockMetadataWithNotify(i + 7, j + 23, k + 17, 7, 2);
		setBlock(world, i + 7, j + 27, k + 0, Blocks.log, 3);
		world.setBlockMetadataWithNotify(i + 7, j + 27, k + 0, 3, 2);
		setBlock(world, i + 7, j + 28, k + 0, Blocks.leaves, 7);
		world.setBlockMetadataWithNotify(i + 7, j + 28, k + 0, 7, 2);
		setBlock(world, i + 7, j + 33, k + 21, Blocks.leaves, 7);
		world.setBlockMetadataWithNotify(i + 7, j + 33, k + 21, 7, 2);
		setBlock(world, i + 7, j + 33, k + 22, Blocks.leaves, 7);
		world.setBlockMetadataWithNotify(i + 7, j + 33, k + 22, 7, 2);
		setBlock(world, i + 7, j + 33, k + 23, Blocks.leaves, 7);
		world.setBlockMetadataWithNotify(i + 7, j + 33, k + 23, 7, 2);
		setBlock(world, i + 7, j + 34, k + 22, Blocks.leaves, 7);
		world.setBlockMetadataWithNotify(i + 7, j + 34, k + 22, 7, 2);
		setBlock(world, i + 8, j + 22, k + 15, Blocks.leaves, 7);
		world.setBlockMetadataWithNotify(i + 8, j + 22, k + 15, 7, 2);
		setBlock(world, i + 8, j + 22, k + 16, Blocks.leaves, 7);
		world.setBlockMetadataWithNotify(i + 8, j + 22, k + 16, 7, 2);
		setBlock(world, i + 8, j + 22, k + 17, Blocks.leaves, 7);
		world.setBlockMetadataWithNotify(i + 8, j + 22, k + 17, 7, 2);
		setBlock(world, i + 8, j + 22, k + 18, Blocks.leaves, 7);
		world.setBlockMetadataWithNotify(i + 8, j + 22, k + 18, 7, 2);
		setBlock(world, i + 8, j + 22, k + 19, Blocks.leaves, 7);
		world.setBlockMetadataWithNotify(i + 8, j + 22, k + 19, 7, 2);
		setBlock(world, i + 8, j + 23, k + 16, Blocks.leaves, 7);
		world.setBlockMetadataWithNotify(i + 8, j + 23, k + 16, 7, 2);
		setBlock(world, i + 8, j + 23, k + 17, Blocks.leaves, 7);
		world.setBlockMetadataWithNotify(i + 8, j + 23, k + 17, 7, 2);
		setBlock(world, i + 8, j + 23, k + 18, Blocks.leaves, 7);
		world.setBlockMetadataWithNotify(i + 8, j + 23, k + 18, 7, 2);
		setBlock(world, i + 8, j + 24, k + 17, Blocks.leaves, 7);
		world.setBlockMetadataWithNotify(i + 8, j + 24, k + 17, 7, 2);
		setBlock(world, i + 8, j + 25, k + 0, Blocks.log, 3);
		world.setBlockMetadataWithNotify(i + 8, j + 25, k + 0, 3, 2);
		setBlock(world, i + 8, j + 26, k + 18, Blocks.leaves, 7);
		world.setBlockMetadataWithNotify(i + 8, j + 26, k + 18, 7, 2);
		setBlock(world, i + 8, j + 26, k + 19, Blocks.leaves, 7);
		world.setBlockMetadataWithNotify(i + 8, j + 26, k + 19, 7, 2);
		setBlock(world, i + 8, j + 26, k + 20, Blocks.leaves, 7);
		world.setBlockMetadataWithNotify(i + 8, j + 26, k + 20, 7, 2);
		setBlock(world, i + 8, j + 27, k + 1, Blocks.log, 3);
		world.setBlockMetadataWithNotify(i + 8, j + 27, k + 1, 3, 2);
		setBlock(world, i + 8, j + 27, k + 19, Blocks.leaves, 7);
		world.setBlockMetadataWithNotify(i + 8, j + 27, k + 19, 7, 2);
		setBlock(world, i + 8, j + 33, k + 20, Blocks.leaves, 7);
		world.setBlockMetadataWithNotify(i + 8, j + 33, k + 20, 7, 2);
		setBlock(world, i + 8, j + 33, k + 21, Blocks.leaves, 7);
		world.setBlockMetadataWithNotify(i + 8, j + 33, k + 21, 7, 2);
		setBlock(world, i + 8, j + 33, k + 22, Blocks.leaves, 7);
		world.setBlockMetadataWithNotify(i + 8, j + 33, k + 22, 7, 2);
		setBlock(world, i + 8, j + 33, k + 23, Blocks.leaves, 7);
		world.setBlockMetadataWithNotify(i + 8, j + 33, k + 23, 7, 2);
		setBlock(world, i + 8, j + 33, k + 24, Blocks.leaves, 7);
		world.setBlockMetadataWithNotify(i + 8, j + 33, k + 24, 7, 2);
		setBlock(world, i + 8, j + 34, k + 21, Blocks.leaves, 7);
		world.setBlockMetadataWithNotify(i + 8, j + 34, k + 21, 7, 2);
		setBlock(world, i + 8, j + 34, k + 22, Blocks.leaves, 7);
		world.setBlockMetadataWithNotify(i + 8, j + 34, k + 22, 7, 2);
		setBlock(world, i + 8, j + 34, k + 23, Blocks.leaves, 7);
		world.setBlockMetadataWithNotify(i + 8, j + 34, k + 23, 7, 2);
		setBlock(world, i + 8, j + 35, k + 22, Blocks.leaves, 7);
		world.setBlockMetadataWithNotify(i + 8, j + 35, k + 22, 7, 2);
		setBlock(world, i + 8, j + 42, k + 14, Blocks.leaves, 7);
		world.setBlockMetadataWithNotify(i + 8, j + 42, k + 14, 7, 2);
		setBlock(world, i + 8, j + 42, k + 15, Blocks.leaves, 7);
		world.setBlockMetadataWithNotify(i + 8, j + 42, k + 15, 7, 2);
		setBlock(world, i + 8, j + 42, k + 16, Blocks.leaves, 7);
		world.setBlockMetadataWithNotify(i + 8, j + 42, k + 16, 7, 2);
		setBlock(world, i + 8, j + 43, k + 15, Blocks.leaves, 7);
		world.setBlockMetadataWithNotify(i + 8, j + 43, k + 15, 7, 2);
		setBlock(world, i + 8, j + 45, k + 4, Blocks.leaves, 7);
		world.setBlockMetadataWithNotify(i + 8, j + 45, k + 4, 7, 2);
		setBlock(world, i + 8, j + 45, k + 5, Blocks.leaves, 7);
		world.setBlockMetadataWithNotify(i + 8, j + 45, k + 5, 7, 2);
		setBlock(world, i + 8, j + 45, k + 6, Blocks.leaves, 7);
		world.setBlockMetadataWithNotify(i + 8, j + 45, k + 6, 7, 2);
		setBlock(world, i + 8, j + 46, k + 5, Blocks.leaves, 7);
		world.setBlockMetadataWithNotify(i + 8, j + 46, k + 5, 7, 2);
		setBlock(world, i + 9, j + 22, k + 15, Blocks.leaves, 7);
		world.setBlockMetadataWithNotify(i + 9, j + 22, k + 15, 7, 2);
		setBlock(world, i + 9, j + 22, k + 16, Blocks.leaves, 7);
		world.setBlockMetadataWithNotify(i + 9, j + 22, k + 16, 7, 2);
		setBlock(world, i + 9, j + 22, k + 17, Blocks.log, 3);
		world.setBlockMetadataWithNotify(i + 9, j + 22, k + 17, 3, 2);
		setBlock(world, i + 9, j + 22, k + 18, Blocks.leaves, 7);
		world.setBlockMetadataWithNotify(i + 9, j + 22, k + 18, 7, 2);
		setBlock(world, i + 9, j + 22, k + 19, Blocks.leaves, 7);
		world.setBlockMetadataWithNotify(i + 9, j + 22, k + 19, 7, 2);
		setBlock(world, i + 9, j + 23, k + 15, Blocks.leaves, 7);
		world.setBlockMetadataWithNotify(i + 9, j + 23, k + 15, 7, 2);
		setBlock(world, i + 9, j + 23, k + 16, Blocks.leaves, 7);
		world.setBlockMetadataWithNotify(i + 9, j + 23, k + 16, 7, 2);
		setBlock(world, i + 9, j + 23, k + 17, Blocks.leaves, 7);
		world.setBlockMetadataWithNotify(i + 9, j + 23, k + 17, 7, 2);
		setBlock(world, i + 9, j + 23, k + 18, Blocks.leaves, 7);
		world.setBlockMetadataWithNotify(i + 9, j + 23, k + 18, 7, 2);
		setBlock(world, i + 9, j + 23, k + 19, Blocks.leaves, 7);
		world.setBlockMetadataWithNotify(i + 9, j + 23, k + 19, 7, 2);
		setBlock(world, i + 9, j + 24, k + 16, Blocks.leaves, 7);
		world.setBlockMetadataWithNotify(i + 9, j + 24, k + 16, 7, 2);
		setBlock(world, i + 9, j + 24, k + 17, Blocks.leaves, 7);
		world.setBlockMetadataWithNotify(i + 9, j + 24, k + 17, 7, 2);
		setBlock(world, i + 9, j + 24, k + 18, Blocks.leaves, 7);
		world.setBlockMetadataWithNotify(i + 9, j + 24, k + 18, 7, 2);
		setBlock(world, i + 9, j + 25, k + 0, Blocks.log, 3);
		world.setBlockMetadataWithNotify(i + 9, j + 25, k + 0, 3, 2);
		setBlock(world, i + 9, j + 25, k + 17, Blocks.leaves, 7);
		world.setBlockMetadataWithNotify(i + 9, j + 25, k + 17, 7, 2);
		setBlock(world, i + 9, j + 26, k + 1, Blocks.log, 3);
		world.setBlockMetadataWithNotify(i + 9, j + 26, k + 1, 3, 2);
		setBlock(world, i + 9, j + 26, k + 17, Blocks.leaves, 7);
		world.setBlockMetadataWithNotify(i + 9, j + 26, k + 17, 7, 2);
		setBlock(world, i + 9, j + 26, k + 18, Blocks.leaves, 7);
		world.setBlockMetadataWithNotify(i + 9, j + 26, k + 18, 7, 2);
		setBlock(world, i + 9, j + 26, k + 19, Blocks.leaves, 7);
		world.setBlockMetadataWithNotify(i + 9, j + 26, k + 19, 7, 2);
		setBlock(world, i + 9, j + 26, k + 20, Blocks.leaves, 7);
		world.setBlockMetadataWithNotify(i + 9, j + 26, k + 20, 7, 2);
		setBlock(world, i + 9, j + 26, k + 21, Blocks.leaves, 7);
		world.setBlockMetadataWithNotify(i + 9, j + 26, k + 21, 7, 2);
		setBlock(world, i + 9, j + 27, k + 18, Blocks.leaves, 7);
		world.setBlockMetadataWithNotify(i + 9, j + 27, k + 18, 7, 2);
		setBlock(world, i + 9, j + 27, k + 19, Blocks.leaves, 7);
		world.setBlockMetadataWithNotify(i + 9, j + 27, k + 19, 7, 2);
		setBlock(world, i + 9, j + 27, k + 20, Blocks.leaves, 7);
		world.setBlockMetadataWithNotify(i + 9, j + 27, k + 20, 7, 2);
		setBlock(world, i + 9, j + 28, k + 19, Blocks.leaves, 7);
		world.setBlockMetadataWithNotify(i + 9, j + 28, k + 19, 7, 2);
		setBlock(world, i + 9, j + 28, k + 20, Blocks.leaves, 7);
		world.setBlockMetadataWithNotify(i + 9, j + 28, k + 20, 7, 2);
		setBlock(world, i + 9, j + 28, k + 21, Blocks.leaves, 7);
		world.setBlockMetadataWithNotify(i + 9, j + 28, k + 21, 7, 2);
		setBlock(world, i + 9, j + 29, k + 20, Blocks.leaves, 7);
		world.setBlockMetadataWithNotify(i + 9, j + 29, k + 20, 7, 2);
		setBlock(world, i + 9, j + 33, k + 20, Blocks.leaves, 7);
		world.setBlockMetadataWithNotify(i + 9, j + 33, k + 20, 7, 2);
		setBlock(world, i + 9, j + 33, k + 21, Blocks.leaves, 7);
		world.setBlockMetadataWithNotify(i + 9, j + 33, k + 21, 7, 2);
		setBlock(world, i + 9, j + 33, k + 22, Blocks.log, 3);
		world.setBlockMetadataWithNotify(i + 9, j + 33, k + 22, 3, 2);
		setBlock(world, i + 9, j + 33, k + 23, Blocks.leaves, 7);
		world.setBlockMetadataWithNotify(i + 9, j + 33, k + 23, 7, 2);
		setBlock(world, i + 9, j + 33, k + 24, Blocks.leaves, 7);
		world.setBlockMetadataWithNotify(i + 9, j + 33, k + 24, 7, 2);
		setBlock(world, i + 9, j + 34, k + 20, Blocks.leaves, 7);
		world.setBlockMetadataWithNotify(i + 9, j + 34, k + 20, 7, 2);
		setBlock(world, i + 9, j + 34, k + 21, Blocks.leaves, 7);
		world.setBlockMetadataWithNotify(i + 9, j + 34, k + 21, 7, 2);
		setBlock(world, i + 9, j + 34, k + 22, Blocks.leaves, 7);
		world.setBlockMetadataWithNotify(i + 9, j + 34, k + 22, 7, 2);
		setBlock(world, i + 9, j + 34, k + 23, Blocks.leaves, 7);
		world.setBlockMetadataWithNotify(i + 9, j + 34, k + 23, 7, 2);
		setBlock(world, i + 9, j + 34, k + 24, Blocks.leaves, 7);
		world.setBlockMetadataWithNotify(i + 9, j + 34, k + 24, 7, 2);
		setBlock(world, i + 9, j + 35, k + 21, Blocks.leaves, 7);
		world.setBlockMetadataWithNotify(i + 9, j + 35, k + 21, 7, 2);
		setBlock(world, i + 9, j + 35, k + 22, Blocks.leaves, 7);
		world.setBlockMetadataWithNotify(i + 9, j + 35, k + 22, 7, 2);
		setBlock(world, i + 9, j + 35, k + 23, Blocks.leaves, 7);
		world.setBlockMetadataWithNotify(i + 9, j + 35, k + 23, 7, 2);
		setBlock(world, i + 9, j + 36, k + 22, Blocks.leaves, 7);
		world.setBlockMetadataWithNotify(i + 9, j + 36, k + 22, 7, 2);
		setBlock(world, i + 9, j + 42, k + 13, Blocks.leaves, 7);
		world.setBlockMetadataWithNotify(i + 9, j + 42, k + 13, 7, 2);
		setBlock(world, i + 9, j + 42, k + 14, Blocks.leaves, 7);
		world.setBlockMetadataWithNotify(i + 9, j + 42, k + 14, 7, 2);
		setBlock(world, i + 9, j + 42, k + 15, Blocks.leaves, 7);
		world.setBlockMetadataWithNotify(i + 9, j + 42, k + 15, 7, 2);
		setBlock(world, i + 9, j + 42, k + 16, Blocks.leaves, 7);
		world.setBlockMetadataWithNotify(i + 9, j + 42, k + 16, 7, 2);
		setBlock(world, i + 9, j + 42, k + 17, Blocks.leaves, 7);
		world.setBlockMetadataWithNotify(i + 9, j + 42, k + 17, 7, 2);
		setBlock(world, i + 9, j + 43, k + 14, Blocks.leaves, 7);
		world.setBlockMetadataWithNotify(i + 9, j + 43, k + 14, 7, 2);
		setBlock(world, i + 9, j + 43, k + 15, Blocks.leaves, 7);
		world.setBlockMetadataWithNotify(i + 9, j + 43, k + 15, 7, 2);
		setBlock(world, i + 9, j + 43, k + 16, Blocks.leaves, 7);
		world.setBlockMetadataWithNotify(i + 9, j + 43, k + 16, 7, 2);
		setBlock(world, i + 9, j + 44, k + 15, Blocks.leaves, 7);
		world.setBlockMetadataWithNotify(i + 9, j + 44, k + 15, 7, 2);
		setBlock(world, i + 9, j + 45, k + 3, Blocks.leaves, 7);
		world.setBlockMetadataWithNotify(i + 9, j + 45, k + 3, 7, 2);
		setBlock(world, i + 9, j + 45, k + 4, Blocks.leaves, 7);
		world.setBlockMetadataWithNotify(i + 9, j + 45, k + 4, 7, 2);
		setBlock(world, i + 9, j + 45, k + 5, Blocks.leaves, 7);
		world.setBlockMetadataWithNotify(i + 9, j + 45, k + 5, 7, 2);
		setBlock(world, i + 9, j + 45, k + 6, Blocks.leaves, 7);
		world.setBlockMetadataWithNotify(i + 9, j + 45, k + 6, 7, 2);
		setBlock(world, i + 9, j + 45, k + 7, Blocks.leaves, 7);
		world.setBlockMetadataWithNotify(i + 9, j + 45, k + 7, 7, 2);
		setBlock(world, i + 9, j + 45, k + 8, Blocks.leaves, 7);
		world.setBlockMetadataWithNotify(i + 9, j + 45, k + 8, 7, 2);
		setBlock(world, i + 9, j + 45, k + 9, Blocks.leaves, 7);
		world.setBlockMetadataWithNotify(i + 9, j + 45, k + 9, 7, 2);
		setBlock(world, i + 9, j + 46, k + 4, Blocks.leaves, 7);
		world.setBlockMetadataWithNotify(i + 9, j + 46, k + 4, 7, 2);
		setBlock(world, i + 9, j + 46, k + 5, Blocks.leaves, 7);
		world.setBlockMetadataWithNotify(i + 9, j + 46, k + 5, 7, 2);
		setBlock(world, i + 9, j + 46, k + 6, Blocks.leaves, 7);
		world.setBlockMetadataWithNotify(i + 9, j + 46, k + 6, 7, 2);
		setBlock(world, i + 9, j + 46, k + 8, Blocks.leaves, 7);
		world.setBlockMetadataWithNotify(i + 9, j + 46, k + 8, 7, 2);
		setBlock(world, i + 9, j + 47, k + 5, Blocks.leaves, 7);
		world.setBlockMetadataWithNotify(i + 9, j + 47, k + 5, 7, 2);
		setBlock(world, i + 10, j + 21, k + 17, Blocks.log, 3);
		world.setBlockMetadataWithNotify(i + 10, j + 21, k + 17, 3, 2);
		setBlock(world, i + 10, j + 22, k + 15, Blocks.leaves, 7);
		world.setBlockMetadataWithNotify(i + 10, j + 22, k + 15, 7, 2);
		setBlock(world, i + 10, j + 22, k + 16, Blocks.leaves, 7);
		world.setBlockMetadataWithNotify(i + 10, j + 22, k + 16, 7, 2);
		setBlock(world, i + 10, j + 22, k + 17, Blocks.leaves, 7);
		world.setBlockMetadataWithNotify(i + 10, j + 22, k + 17, 7, 2);
		setBlock(world, i + 10, j + 22, k + 18, Blocks.leaves, 7);
		world.setBlockMetadataWithNotify(i + 10, j + 22, k + 18, 7, 2);
		setBlock(world, i + 10, j + 22, k + 19, Blocks.leaves, 7);
		world.setBlockMetadataWithNotify(i + 10, j + 22, k + 19, 7, 2);
		setBlock(world, i + 10, j + 23, k + 16, Blocks.leaves, 7);
		world.setBlockMetadataWithNotify(i + 10, j + 23, k + 16, 7, 2);
		setBlock(world, i + 10, j + 23, k + 17, Blocks.leaves, 7);
		world.setBlockMetadataWithNotify(i + 10, j + 23, k + 17, 7, 2);
		setBlock(world, i + 10, j + 23, k + 18, Blocks.leaves, 7);
		world.setBlockMetadataWithNotify(i + 10, j + 23, k + 18, 7, 2);
		setBlock(world, i + 10, j + 24, k + 17, Blocks.leaves, 7);
		world.setBlockMetadataWithNotify(i + 10, j + 24, k + 17, 7, 2);
		setBlock(world, i + 10, j + 25, k + 1, Blocks.log, 3);
		world.setBlockMetadataWithNotify(i + 10, j + 25, k + 1, 3, 2);
		setBlock(world, i + 10, j + 26, k + 2, Blocks.log, 3);
		world.setBlockMetadataWithNotify(i + 10, j + 26, k + 2, 3, 2);
		setBlock(world, i + 10, j + 26, k + 17, Blocks.leaves, 7);
		world.setBlockMetadataWithNotify(i + 10, j + 26, k + 17, 7, 2);
		setBlock(world, i + 10, j + 26, k + 18, Blocks.leaves, 7);
		world.setBlockMetadataWithNotify(i + 10, j + 26, k + 18, 7, 2);
		setBlock(world, i + 10, j + 26, k + 19, Blocks.log, 3);
		world.setBlockMetadataWithNotify(i + 10, j + 26, k + 19, 3, 2);
		setBlock(world, i + 10, j + 26, k + 20, Blocks.leaves, 7);
		world.setBlockMetadataWithNotify(i + 10, j + 26, k + 20, 7, 2);
		setBlock(world, i + 10, j + 26, k + 21, Blocks.leaves, 7);
		world.setBlockMetadataWithNotify(i + 10, j + 26, k + 21, 7, 2);
		setBlock(world, i + 10, j + 27, k + 17, Blocks.leaves, 7);
		world.setBlockMetadataWithNotify(i + 10, j + 27, k + 17, 7, 2);
		setBlock(world, i + 10, j + 27, k + 18, Blocks.leaves, 7);
		world.setBlockMetadataWithNotify(i + 10, j + 27, k + 18, 7, 2);
		setBlock(world, i + 10, j + 27, k + 19, Blocks.leaves, 7);
		world.setBlockMetadataWithNotify(i + 10, j + 27, k + 19, 7, 2);
		setBlock(world, i + 10, j + 27, k + 20, Blocks.leaves, 7);
		world.setBlockMetadataWithNotify(i + 10, j + 27, k + 20, 7, 2);
		setBlock(world, i + 10, j + 27, k + 21, Blocks.leaves, 7);
		world.setBlockMetadataWithNotify(i + 10, j + 27, k + 21, 7, 2);
		setBlock(world, i + 10, j + 28, k + 18, Blocks.leaves, 7);
		world.setBlockMetadataWithNotify(i + 10, j + 28, k + 18, 7, 2);
		setBlock(world, i + 10, j + 28, k + 19, Blocks.leaves, 7);
		world.setBlockMetadataWithNotify(i + 10, j + 28, k + 19, 7, 2);
		setBlock(world, i + 10, j + 28, k + 20, Blocks.leaves, 7);
		world.setBlockMetadataWithNotify(i + 10, j + 28, k + 20, 7, 2);
		setBlock(world, i + 10, j + 28, k + 21, Blocks.leaves, 7);
		world.setBlockMetadataWithNotify(i + 10, j + 28, k + 21, 7, 2);
		setBlock(world, i + 10, j + 28, k + 22, Blocks.leaves, 7);
		world.setBlockMetadataWithNotify(i + 10, j + 28, k + 22, 7, 2);
		setBlock(world, i + 10, j + 29, k + 17, Blocks.leaves, 7);
		world.setBlockMetadataWithNotify(i + 10, j + 29, k + 17, 7, 2);
		setBlock(world, i + 10, j + 29, k + 18, Blocks.leaves, 7);
		world.setBlockMetadataWithNotify(i + 10, j + 29, k + 18, 7, 2);
		setBlock(world, i + 10, j + 29, k + 19, Blocks.leaves, 7);
		world.setBlockMetadataWithNotify(i + 10, j + 29, k + 19, 7, 2);
		setBlock(world, i + 10, j + 29, k + 20, Blocks.leaves, 7);
		world.setBlockMetadataWithNotify(i + 10, j + 29, k + 20, 7, 2);
		setBlock(world, i + 10, j + 29, k + 21, Blocks.leaves, 7);
		world.setBlockMetadataWithNotify(i + 10, j + 29, k + 21, 7, 2);
		setBlock(world, i + 10, j + 30, k + 18, Blocks.leaves, 7);
		world.setBlockMetadataWithNotify(i + 10, j + 30, k + 18, 7, 2);
		setBlock(world, i + 10, j + 30, k + 20, Blocks.leaves, 7);
		world.setBlockMetadataWithNotify(i + 10, j + 30, k + 20, 7, 2);
		setBlock(world, i + 10, j + 31, k + 24, Blocks.leaves, 7);
		world.setBlockMetadataWithNotify(i + 10, j + 31, k + 24, 7, 2);
		setBlock(world, i + 10, j + 31, k + 25, Blocks.leaves, 7);
		world.setBlockMetadataWithNotify(i + 10, j + 31, k + 25, 7, 2);
		setBlock(world, i + 10, j + 31, k + 26, Blocks.leaves, 7);
		world.setBlockMetadataWithNotify(i + 10, j + 31, k + 26, 7, 2);
		setBlock(world, i + 10, j + 32, k + 21, Blocks.log, 3);
		world.setBlockMetadataWithNotify(i + 10, j + 32, k + 21, 3, 2);
		setBlock(world, i + 10, j + 32, k + 25, Blocks.leaves, 7);
		world.setBlockMetadataWithNotify(i + 10, j + 32, k + 25, 7, 2);
		setBlock(world, i + 10, j + 33, k + 20, Blocks.leaves, 7);
		world.setBlockMetadataWithNotify(i + 10, j + 33, k + 20, 7, 2);
		setBlock(world, i + 10, j + 33, k + 21, Blocks.leaves, 7);
		world.setBlockMetadataWithNotify(i + 10, j + 33, k + 21, 7, 2);
		setBlock(world, i + 10, j + 33, k + 22, Blocks.leaves, 7);
		world.setBlockMetadataWithNotify(i + 10, j + 33, k + 22, 7, 2);
		setBlock(world, i + 10, j + 33, k + 23, Blocks.leaves, 7);
		world.setBlockMetadataWithNotify(i + 10, j + 33, k + 23, 7, 2);
		setBlock(world, i + 10, j + 33, k + 24, Blocks.leaves, 7);
		world.setBlockMetadataWithNotify(i + 10, j + 33, k + 24, 7, 2);
		setBlock(world, i + 10, j + 34, k + 21, Blocks.leaves, 7);
		world.setBlockMetadataWithNotify(i + 10, j + 34, k + 21, 7, 2);
		setBlock(world, i + 10, j + 34, k + 22, Blocks.leaves, 7);
		world.setBlockMetadataWithNotify(i + 10, j + 34, k + 22, 7, 2);
		setBlock(world, i + 10, j + 34, k + 23, Blocks.leaves, 7);
		world.setBlockMetadataWithNotify(i + 10, j + 34, k + 23, 7, 2);
		setBlock(world, i + 10, j + 35, k + 22, Blocks.leaves, 7);
		world.setBlockMetadataWithNotify(i + 10, j + 35, k + 22, 7, 2);
		setBlock(world, i + 10, j + 39, k + 0, Blocks.leaves, 7);
		world.setBlockMetadataWithNotify(i + 10, j + 39, k + 0, 7, 2);
		setBlock(world, i + 10, j + 39, k + 1, Blocks.leaves, 7);
		world.setBlockMetadataWithNotify(i + 10, j + 39, k + 1, 7, 2);
		setBlock(world, i + 10, j + 40, k + 0, Blocks.leaves, 7);
		world.setBlockMetadataWithNotify(i + 10, j + 40, k + 0, 7, 2);
		setBlock(world, i + 10, j + 42, k + 13, Blocks.leaves, 7);
		world.setBlockMetadataWithNotify(i + 10, j + 42, k + 13, 7, 2);
		setBlock(world, i + 10, j + 42, k + 14, Blocks.leaves, 7);
		world.setBlockMetadataWithNotify(i + 10, j + 42, k + 14, 7, 2);
		setBlock(world, i + 10, j + 42, k + 15, Blocks.log, 3);
		world.setBlockMetadataWithNotify(i + 10, j + 42, k + 15, 3, 2);
		setBlock(world, i + 10, j + 42, k + 16, Blocks.leaves, 7);
		world.setBlockMetadataWithNotify(i + 10, j + 42, k + 16, 7, 2);
		setBlock(world, i + 10, j + 42, k + 17, Blocks.leaves, 7);
		world.setBlockMetadataWithNotify(i + 10, j + 42, k + 17, 7, 2);
		setBlock(world, i + 10, j + 43, k + 13, Blocks.leaves, 7);
		world.setBlockMetadataWithNotify(i + 10, j + 43, k + 13, 7, 2);
		setBlock(world, i + 10, j + 43, k + 14, Blocks.leaves, 7);
		world.setBlockMetadataWithNotify(i + 10, j + 43, k + 14, 7, 2);
		setBlock(world, i + 10, j + 43, k + 15, Blocks.leaves, 7);
		world.setBlockMetadataWithNotify(i + 10, j + 43, k + 15, 7, 2);
		setBlock(world, i + 10, j + 43, k + 16, Blocks.leaves, 7);
		world.setBlockMetadataWithNotify(i + 10, j + 43, k + 16, 7, 2);
		setBlock(world, i + 10, j + 43, k + 17, Blocks.leaves, 7);
		world.setBlockMetadataWithNotify(i + 10, j + 43, k + 17, 7, 2);
		setBlock(world, i + 10, j + 44, k + 14, Blocks.leaves, 7);
		world.setBlockMetadataWithNotify(i + 10, j + 44, k + 14, 7, 2);
		setBlock(world, i + 10, j + 44, k + 15, Blocks.leaves, 7);
		world.setBlockMetadataWithNotify(i + 10, j + 44, k + 15, 7, 2);
		setBlock(world, i + 10, j + 44, k + 16, Blocks.leaves, 7);
		world.setBlockMetadataWithNotify(i + 10, j + 44, k + 16, 7, 2);
		setBlock(world, i + 10, j + 45, k + 3, Blocks.leaves, 7);
		world.setBlockMetadataWithNotify(i + 10, j + 45, k + 3, 7, 2);
		setBlock(world, i + 10, j + 45, k + 4, Blocks.leaves, 7);
		world.setBlockMetadataWithNotify(i + 10, j + 45, k + 4, 7, 2);
		setBlock(world, i + 10, j + 45, k + 5, Blocks.log, 3);
		world.setBlockMetadataWithNotify(i + 10, j + 45, k + 5, 3, 2);
		setBlock(world, i + 10, j + 45, k + 6, Blocks.leaves, 7);
		world.setBlockMetadataWithNotify(i + 10, j + 45, k + 6, 7, 2);
		setBlock(world, i + 10, j + 45, k + 7, Blocks.leaves, 7);
		world.setBlockMetadataWithNotify(i + 10, j + 45, k + 7, 7, 2);
		setBlock(world, i + 10, j + 45, k + 8, Blocks.leaves, 7);
		world.setBlockMetadataWithNotify(i + 10, j + 45, k + 8, 7, 2);
		setBlock(world, i + 10, j + 45, k + 9, Blocks.leaves, 7);
		world.setBlockMetadataWithNotify(i + 10, j + 45, k + 9, 7, 2);
		setBlock(world, i + 10, j + 45, k + 10, Blocks.leaves, 7);
		world.setBlockMetadataWithNotify(i + 10, j + 45, k + 10, 7, 2);
		setBlock(world, i + 10, j + 45, k + 15, Blocks.leaves, 7);
		world.setBlockMetadataWithNotify(i + 10, j + 45, k + 15, 7, 2);
		setBlock(world, i + 10, j + 46, k + 3, Blocks.leaves, 7);
		world.setBlockMetadataWithNotify(i + 10, j + 46, k + 3, 7, 2);
		setBlock(world, i + 10, j + 46, k + 4, Blocks.leaves, 7);
		world.setBlockMetadataWithNotify(i + 10, j + 46, k + 4, 7, 2);
		setBlock(world, i + 10, j + 46, k + 5, Blocks.leaves, 7);
		world.setBlockMetadataWithNotify(i + 10, j + 46, k + 5, 7, 2);
		setBlock(world, i + 10, j + 46, k + 6, Blocks.leaves, 7);
		world.setBlockMetadataWithNotify(i + 10, j + 46, k + 6, 7, 2);
		setBlock(world, i + 10, j + 46, k + 7, Blocks.leaves, 7);
		world.setBlockMetadataWithNotify(i + 10, j + 46, k + 7, 7, 2);
		setBlock(world, i + 10, j + 46, k + 8, Blocks.leaves, 7);
		world.setBlockMetadataWithNotify(i + 10, j + 46, k + 8, 7, 2);
		setBlock(world, i + 10, j + 46, k + 9, Blocks.leaves, 7);
		world.setBlockMetadataWithNotify(i + 10, j + 46, k + 9, 7, 2);
		setBlock(world, i + 10, j + 47, k + 4, Blocks.leaves, 7);
		world.setBlockMetadataWithNotify(i + 10, j + 47, k + 4, 7, 2);
		setBlock(world, i + 10, j + 47, k + 5, Blocks.leaves, 7);
		world.setBlockMetadataWithNotify(i + 10, j + 47, k + 5, 7, 2);
		setBlock(world, i + 10, j + 47, k + 6, Blocks.leaves, 7);
		world.setBlockMetadataWithNotify(i + 10, j + 47, k + 6, 7, 2);
		setBlock(world, i + 10, j + 47, k + 8, Blocks.leaves, 7);
		world.setBlockMetadataWithNotify(i + 10, j + 47, k + 8, 7, 2);
		setBlock(world, i + 10, j + 48, k + 5, Blocks.leaves, 7);
		world.setBlockMetadataWithNotify(i + 10, j + 48, k + 5, 7, 2);
		setBlock(world, i + 11, j + 21, k + 16, Blocks.log, 3);
		world.setBlockMetadataWithNotify(i + 11, j + 21, k + 16, 3, 2);
		setBlock(world, i + 11, j + 22, k + 16, Blocks.leaves, 7);
		world.setBlockMetadataWithNotify(i + 11, j + 22, k + 16, 7, 2);
		setBlock(world, i + 11, j + 22, k + 17, Blocks.leaves, 7);
		world.setBlockMetadataWithNotify(i + 11, j + 22, k + 17, 7, 2);
		setBlock(world, i + 11, j + 22, k + 18, Blocks.leaves, 7);
		world.setBlockMetadataWithNotify(i + 11, j + 22, k + 18, 7, 2);
		setBlock(world, i + 11, j + 23, k + 17, Blocks.leaves, 7);
		world.setBlockMetadataWithNotify(i + 11, j + 23, k + 17, 7, 2);
		setBlock(world, i + 11, j + 24, k + 1, Blocks.log, 3);
		world.setBlockMetadataWithNotify(i + 11, j + 24, k + 1, 3, 2);
		setBlock(world, i + 11, j + 25, k + 18, Blocks.leaves, 7);
		world.setBlockMetadataWithNotify(i + 11, j + 25, k + 18, 7, 2);
		setBlock(world, i + 11, j + 25, k + 19, Blocks.log, 3);
		world.setBlockMetadataWithNotify(i + 11, j + 25, k + 19, 3, 2);
		setBlock(world, i + 11, j + 25, k + 20, Blocks.leaves, 7);
		world.setBlockMetadataWithNotify(i + 11, j + 25, k + 20, 7, 2);
		setBlock(world, i + 11, j + 26, k + 2, Blocks.log, 3);
		world.setBlockMetadataWithNotify(i + 11, j + 26, k + 2, 3, 2);
		setBlock(world, i + 11, j + 26, k + 17, Blocks.leaves, 7);
		world.setBlockMetadataWithNotify(i + 11, j + 26, k + 17, 7, 2);
		setBlock(world, i + 11, j + 26, k + 18, Blocks.leaves, 7);
		world.setBlockMetadataWithNotify(i + 11, j + 26, k + 18, 7, 2);
		setBlock(world, i + 11, j + 26, k + 19, Blocks.leaves, 7);
		world.setBlockMetadataWithNotify(i + 11, j + 26, k + 19, 7, 2);
		setBlock(world, i + 11, j + 26, k + 20, Blocks.leaves, 7);
		world.setBlockMetadataWithNotify(i + 11, j + 26, k + 20, 7, 2);
		setBlock(world, i + 11, j + 26, k + 21, Blocks.leaves, 7);
		world.setBlockMetadataWithNotify(i + 11, j + 26, k + 21, 7, 2);
		setBlock(world, i + 11, j + 27, k + 18, Blocks.leaves, 7);
		world.setBlockMetadataWithNotify(i + 11, j + 27, k + 18, 7, 2);
		setBlock(world, i + 11, j + 27, k + 19, Blocks.log, 3);
		world.setBlockMetadataWithNotify(i + 11, j + 27, k + 19, 3, 2);
		setBlock(world, i + 11, j + 27, k + 20, Blocks.leaves, 7);
		world.setBlockMetadataWithNotify(i + 11, j + 27, k + 20, 7, 2);
		setBlock(world, i + 11, j + 28, k + 18, Blocks.leaves, 7);
		world.setBlockMetadataWithNotify(i + 11, j + 28, k + 18, 7, 2);
		setBlock(world, i + 11, j + 28, k + 19, Blocks.leaves, 7);
		world.setBlockMetadataWithNotify(i + 11, j + 28, k + 19, 7, 2);
		setBlock(world, i + 11, j + 28, k + 20, Blocks.log, 3);
		world.setBlockMetadataWithNotify(i + 11, j + 28, k + 20, 3, 2);
		setBlock(world, i + 11, j + 28, k + 21, Blocks.leaves, 7);
		world.setBlockMetadataWithNotify(i + 11, j + 28, k + 21, 7, 2);
		setBlock(world, i + 11, j + 28, k + 22, Blocks.leaves, 7);
		world.setBlockMetadataWithNotify(i + 11, j + 28, k + 22, 7, 2);
		setBlock(world, i + 11, j + 29, k + 16, Blocks.leaves, 7);
		world.setBlockMetadataWithNotify(i + 11, j + 29, k + 16, 7, 2);
		setBlock(world, i + 11, j + 29, k + 17, Blocks.leaves, 7);
		world.setBlockMetadataWithNotify(i + 11, j + 29, k + 17, 7, 2);
		setBlock(world, i + 11, j + 29, k + 18, Blocks.leaves, 7);
		world.setBlockMetadataWithNotify(i + 11, j + 29, k + 18, 7, 2);
		setBlock(world, i + 11, j + 29, k + 19, Blocks.leaves, 7);
		world.setBlockMetadataWithNotify(i + 11, j + 29, k + 19, 7, 2);
		setBlock(world, i + 11, j + 29, k + 20, Blocks.leaves, 7);
		world.setBlockMetadataWithNotify(i + 11, j + 29, k + 20, 7, 2);
		setBlock(world, i + 11, j + 29, k + 21, Blocks.leaves, 7);
		world.setBlockMetadataWithNotify(i + 11, j + 29, k + 21, 7, 2);
		setBlock(world, i + 11, j + 29, k + 22, Blocks.leaves, 7);
		world.setBlockMetadataWithNotify(i + 11, j + 29, k + 22, 7, 2);
		setBlock(world, i + 11, j + 30, k + 17, Blocks.leaves, 7);
		world.setBlockMetadataWithNotify(i + 11, j + 30, k + 17, 7, 2);
		setBlock(world, i + 11, j + 30, k + 18, Blocks.leaves, 7);
		world.setBlockMetadataWithNotify(i + 11, j + 30, k + 18, 7, 2);
		setBlock(world, i + 11, j + 30, k + 19, Blocks.leaves, 7);
		world.setBlockMetadataWithNotify(i + 11, j + 30, k + 19, 7, 2);
		setBlock(world, i + 11, j + 30, k + 20, Blocks.leaves, 7);
		world.setBlockMetadataWithNotify(i + 11, j + 30, k + 20, 7, 2);
		setBlock(world, i + 11, j + 30, k + 21, Blocks.leaves, 7);
		world.setBlockMetadataWithNotify(i + 11, j + 30, k + 21, 7, 2);
		setBlock(world, i + 11, j + 31, k + 18, Blocks.leaves, 7);
		world.setBlockMetadataWithNotify(i + 11, j + 31, k + 18, 7, 2);
		setBlock(world, i + 11, j + 31, k + 20, Blocks.leaves, 7);
		world.setBlockMetadataWithNotify(i + 11, j + 31, k + 20, 7, 2);
		setBlock(world, i + 11, j + 31, k + 23, Blocks.leaves, 7);
		world.setBlockMetadataWithNotify(i + 11, j + 31, k + 23, 7, 2);
		setBlock(world, i + 11, j + 31, k + 24, Blocks.leaves, 7);
		world.setBlockMetadataWithNotify(i + 11, j + 31, k + 24, 7, 2);
		setBlock(world, i + 11, j + 31, k + 25, Blocks.leaves, 7);
		world.setBlockMetadataWithNotify(i + 11, j + 31, k + 25, 7, 2);
		setBlock(world, i + 11, j + 31, k + 26, Blocks.leaves, 7);
		world.setBlockMetadataWithNotify(i + 11, j + 31, k + 26, 7, 2);
		setBlock(world, i + 11, j + 31, k + 27, Blocks.leaves, 7);
		world.setBlockMetadataWithNotify(i + 11, j + 31, k + 27, 7, 2);
		setBlock(world, i + 11, j + 32, k + 20, Blocks.log, 3);
		world.setBlockMetadataWithNotify(i + 11, j + 32, k + 20, 3, 2);
		setBlock(world, i + 11, j + 32, k + 24, Blocks.leaves, 7);
		world.setBlockMetadataWithNotify(i + 11, j + 32, k + 24, 7, 2);
		setBlock(world, i + 11, j + 32, k + 25, Blocks.leaves, 7);
		world.setBlockMetadataWithNotify(i + 11, j + 32, k + 25, 7, 2);
		setBlock(world, i + 11, j + 32, k + 26, Blocks.leaves, 7);
		world.setBlockMetadataWithNotify(i + 11, j + 32, k + 26, 7, 2);
		setBlock(world, i + 11, j + 33, k + 21, Blocks.leaves, 7);
		world.setBlockMetadataWithNotify(i + 11, j + 33, k + 21, 7, 2);
		setBlock(world, i + 11, j + 33, k + 22, Blocks.leaves, 7);
		world.setBlockMetadataWithNotify(i + 11, j + 33, k + 22, 7, 2);
		setBlock(world, i + 11, j + 33, k + 23, Blocks.leaves, 7);
		world.setBlockMetadataWithNotify(i + 11, j + 33, k + 23, 7, 2);
		setBlock(world, i + 11, j + 33, k + 25, Blocks.leaves, 7);
		world.setBlockMetadataWithNotify(i + 11, j + 33, k + 25, 7, 2);
		setBlock(world, i + 11, j + 34, k + 22, Blocks.leaves, 7);
		world.setBlockMetadataWithNotify(i + 11, j + 34, k + 22, 7, 2);
		setBlock(world, i + 11, j + 37, k + 8, Blocks.leaves, 7);
		world.setBlockMetadataWithNotify(i + 11, j + 37, k + 8, 7, 2);
		setBlock(world, i + 11, j + 37, k + 9, Blocks.leaves, 7);
		world.setBlockMetadataWithNotify(i + 11, j + 37, k + 9, 7, 2);
		setBlock(world, i + 11, j + 37, k + 10, Blocks.leaves, 7);
		world.setBlockMetadataWithNotify(i + 11, j + 37, k + 10, 7, 2);
		setBlock(world, i + 11, j + 38, k + 9, Blocks.leaves, 7);
		world.setBlockMetadataWithNotify(i + 11, j + 38, k + 9, 7, 2);
		setBlock(world, i + 11, j + 39, k + 0, Blocks.leaves, 7);
		world.setBlockMetadataWithNotify(i + 11, j + 39, k + 0, 7, 2);
		setBlock(world, i + 11, j + 39, k + 1, Blocks.leaves, 7);
		world.setBlockMetadataWithNotify(i + 11, j + 39, k + 1, 7, 2);
		setBlock(world, i + 11, j + 39, k + 2, Blocks.leaves, 7);
		world.setBlockMetadataWithNotify(i + 11, j + 39, k + 2, 7, 2);
		setBlock(world, i + 11, j + 40, k + 0, Blocks.leaves, 7);
		world.setBlockMetadataWithNotify(i + 11, j + 40, k + 0, 7, 2);
		setBlock(world, i + 11, j + 40, k + 1, Blocks.leaves, 7);
		world.setBlockMetadataWithNotify(i + 11, j + 40, k + 1, 7, 2);
		setBlock(world, i + 11, j + 41, k + 0, Blocks.leaves, 7);
		world.setBlockMetadataWithNotify(i + 11, j + 41, k + 0, 7, 2);
		setBlock(world, i + 11, j + 42, k + 13, Blocks.leaves, 7);
		world.setBlockMetadataWithNotify(i + 11, j + 42, k + 13, 7, 2);
		setBlock(world, i + 11, j + 42, k + 14, Blocks.leaves, 7);
		world.setBlockMetadataWithNotify(i + 11, j + 42, k + 14, 7, 2);
		setBlock(world, i + 11, j + 42, k + 15, Blocks.leaves, 7);
		world.setBlockMetadataWithNotify(i + 11, j + 42, k + 15, 7, 2);
		setBlock(world, i + 11, j + 42, k + 16, Blocks.leaves, 7);
		world.setBlockMetadataWithNotify(i + 11, j + 42, k + 16, 7, 2);
		setBlock(world, i + 11, j + 42, k + 17, Blocks.leaves, 7);
		world.setBlockMetadataWithNotify(i + 11, j + 42, k + 17, 7, 2);
		setBlock(world, i + 11, j + 43, k + 14, Blocks.leaves, 7);
		world.setBlockMetadataWithNotify(i + 11, j + 43, k + 14, 7, 2);
		setBlock(world, i + 11, j + 43, k + 15, Blocks.leaves, 7);
		world.setBlockMetadataWithNotify(i + 11, j + 43, k + 15, 7, 2);
		setBlock(world, i + 11, j + 43, k + 16, Blocks.leaves, 7);
		world.setBlockMetadataWithNotify(i + 11, j + 43, k + 16, 7, 2);
		setBlock(world, i + 11, j + 44, k + 15, Blocks.leaves, 7);
		world.setBlockMetadataWithNotify(i + 11, j + 44, k + 15, 7, 2);
		setBlock(world, i + 11, j + 45, k + 3, Blocks.leaves, 7);
		world.setBlockMetadataWithNotify(i + 11, j + 45, k + 3, 7, 2);
		setBlock(world, i + 11, j + 45, k + 4, Blocks.leaves, 7);
		world.setBlockMetadataWithNotify(i + 11, j + 45, k + 4, 7, 2);
		setBlock(world, i + 11, j + 45, k + 5, Blocks.leaves, 7);
		world.setBlockMetadataWithNotify(i + 11, j + 45, k + 5, 7, 2);
		setBlock(world, i + 11, j + 45, k + 6, Blocks.leaves, 7);
		world.setBlockMetadataWithNotify(i + 11, j + 45, k + 6, 7, 2);
		setBlock(world, i + 11, j + 45, k + 7, Blocks.leaves, 7);
		world.setBlockMetadataWithNotify(i + 11, j + 45, k + 7, 7, 2);
		setBlock(world, i + 11, j + 45, k + 8, Blocks.log, 3);
		world.setBlockMetadataWithNotify(i + 11, j + 45, k + 8, 3, 2);
		setBlock(world, i + 11, j + 45, k + 9, Blocks.leaves, 7);
		world.setBlockMetadataWithNotify(i + 11, j + 45, k + 9, 7, 2);
		setBlock(world, i + 11, j + 45, k + 10, Blocks.leaves, 7);
		world.setBlockMetadataWithNotify(i + 11, j + 45, k + 10, 7, 2);
		setBlock(world, i + 11, j + 46, k + 0, Blocks.leaves, 7);
		world.setBlockMetadataWithNotify(i + 11, j + 46, k + 0, 7, 2);
		setBlock(world, i + 11, j + 46, k + 1, Blocks.leaves, 7);
		world.setBlockMetadataWithNotify(i + 11, j + 46, k + 1, 7, 2);
		setBlock(world, i + 11, j + 46, k + 2, Blocks.leaves, 7);
		world.setBlockMetadataWithNotify(i + 11, j + 46, k + 2, 7, 2);
		setBlock(world, i + 11, j + 46, k + 4, Blocks.leaves, 7);
		world.setBlockMetadataWithNotify(i + 11, j + 46, k + 4, 7, 2);
		setBlock(world, i + 11, j + 46, k + 5, Blocks.leaves, 7);
		world.setBlockMetadataWithNotify(i + 11, j + 46, k + 5, 7, 2);
		setBlock(world, i + 11, j + 46, k + 6, Blocks.leaves, 7);
		world.setBlockMetadataWithNotify(i + 11, j + 46, k + 6, 7, 2);
		setBlock(world, i + 11, j + 46, k + 7, Blocks.leaves, 7);
		world.setBlockMetadataWithNotify(i + 11, j + 46, k + 7, 7, 2);
		setBlock(world, i + 11, j + 46, k + 8, Blocks.leaves, 7);
		world.setBlockMetadataWithNotify(i + 11, j + 46, k + 8, 7, 2);
		setBlock(world, i + 11, j + 46, k + 9, Blocks.leaves, 7);
		world.setBlockMetadataWithNotify(i + 11, j + 46, k + 9, 7, 2);
		setBlock(world, i + 11, j + 46, k + 10, Blocks.leaves, 7);
		world.setBlockMetadataWithNotify(i + 11, j + 46, k + 10, 7, 2);
		setBlock(world, i + 11, j + 47, k + 1, Blocks.leaves, 7);
		world.setBlockMetadataWithNotify(i + 11, j + 47, k + 1, 7, 2);
		setBlock(world, i + 11, j + 47, k + 5, Blocks.leaves, 7);
		world.setBlockMetadataWithNotify(i + 11, j + 47, k + 5, 7, 2);
		setBlock(world, i + 11, j + 47, k + 7, Blocks.leaves, 7);
		world.setBlockMetadataWithNotify(i + 11, j + 47, k + 7, 7, 2);
		setBlock(world, i + 11, j + 47, k + 8, Blocks.leaves, 7);
		world.setBlockMetadataWithNotify(i + 11, j + 47, k + 8, 7, 2);
		setBlock(world, i + 11, j + 47, k + 9, Blocks.leaves, 7);
		world.setBlockMetadataWithNotify(i + 11, j + 47, k + 9, 7, 2);
		setBlock(world, i + 11, j + 48, k + 8, Blocks.leaves, 7);
		world.setBlockMetadataWithNotify(i + 11, j + 48, k + 8, 7, 2);
		setBlock(world, i + 12, j + 21, k + 16, Blocks.log, 3);
		world.setBlockMetadataWithNotify(i + 12, j + 21, k + 16, 3, 2);
		setBlock(world, i + 12, j + 24, k + 2, Blocks.log, 3);
		world.setBlockMetadataWithNotify(i + 12, j + 24, k + 2, 3, 2);
		setBlock(world, i + 12, j + 25, k + 17, Blocks.leaves, 7);
		world.setBlockMetadataWithNotify(i + 12, j + 25, k + 17, 7, 2);
		setBlock(world, i + 12, j + 25, k + 18, Blocks.log, 3);
		world.setBlockMetadataWithNotify(i + 12, j + 25, k + 18, 3, 2);
		setBlock(world, i + 12, j + 25, k + 19, Blocks.leaves, 7);
		world.setBlockMetadataWithNotify(i + 12, j + 25, k + 19, 7, 2);
		setBlock(world, i + 12, j + 25, k + 20, Blocks.leaves, 7);
		world.setBlockMetadataWithNotify(i + 12, j + 25, k + 20, 7, 2);
		setBlock(world, i + 12, j + 25, k + 21, Blocks.leaves, 7);
		world.setBlockMetadataWithNotify(i + 12, j + 25, k + 21, 7, 2);
		setBlock(world, i + 12, j + 26, k + 3, Blocks.log, 3);
		world.setBlockMetadataWithNotify(i + 12, j + 26, k + 3, 3, 2);
		setBlock(world, i + 12, j + 26, k + 18, Blocks.leaves, 7);
		world.setBlockMetadataWithNotify(i + 12, j + 26, k + 18, 7, 2);
		setBlock(world, i + 12, j + 26, k + 19, Blocks.leaves, 7);
		world.setBlockMetadataWithNotify(i + 12, j + 26, k + 19, 7, 2);
		setBlock(world, i + 12, j + 26, k + 20, Blocks.leaves, 7);
		world.setBlockMetadataWithNotify(i + 12, j + 26, k + 20, 7, 2);
		setBlock(world, i + 12, j + 27, k + 18, Blocks.log, 3);
		world.setBlockMetadataWithNotify(i + 12, j + 27, k + 18, 3, 2);
		setBlock(world, i + 12, j + 27, k + 19, Blocks.leaves, 7);
		world.setBlockMetadataWithNotify(i + 12, j + 27, k + 19, 7, 2);
		setBlock(world, i + 12, j + 28, k + 18, Blocks.leaves, 7);
		world.setBlockMetadataWithNotify(i + 12, j + 28, k + 18, 7, 2);
		setBlock(world, i + 12, j + 28, k + 19, Blocks.leaves, 7);
		world.setBlockMetadataWithNotify(i + 12, j + 28, k + 19, 7, 2);
		setBlock(world, i + 12, j + 28, k + 20, Blocks.leaves, 7);
		world.setBlockMetadataWithNotify(i + 12, j + 28, k + 20, 7, 2);
		setBlock(world, i + 12, j + 28, k + 21, Blocks.leaves, 7);
		world.setBlockMetadataWithNotify(i + 12, j + 28, k + 21, 7, 2);
		setBlock(world, i + 12, j + 28, k + 22, Blocks.leaves, 7);
		world.setBlockMetadataWithNotify(i + 12, j + 28, k + 22, 7, 2);
		setBlock(world, i + 12, j + 29, k + 16, Blocks.leaves, 7);
		world.setBlockMetadataWithNotify(i + 12, j + 29, k + 16, 7, 2);
		setBlock(world, i + 12, j + 29, k + 17, Blocks.leaves, 7);
		world.setBlockMetadataWithNotify(i + 12, j + 29, k + 17, 7, 2);
		setBlock(world, i + 12, j + 29, k + 18, Blocks.log, 3);
		world.setBlockMetadataWithNotify(i + 12, j + 29, k + 18, 3, 2);
		setBlock(world, i + 12, j + 29, k + 19, Blocks.leaves, 7);
		world.setBlockMetadataWithNotify(i + 12, j + 29, k + 19, 7, 2);
		setBlock(world, i + 12, j + 29, k + 20, Blocks.leaves, 7);
		world.setBlockMetadataWithNotify(i + 12, j + 29, k + 20, 7, 2);
		setBlock(world, i + 12, j + 29, k + 21, Blocks.leaves, 7);
		world.setBlockMetadataWithNotify(i + 12, j + 29, k + 21, 7, 2);
		setBlock(world, i + 12, j + 30, k + 16, Blocks.leaves, 7);
		world.setBlockMetadataWithNotify(i + 12, j + 30, k + 16, 7, 2);
		setBlock(world, i + 12, j + 30, k + 17, Blocks.leaves, 7);
		world.setBlockMetadataWithNotify(i + 12, j + 30, k + 17, 7, 2);
		setBlock(world, i + 12, j + 30, k + 18, Blocks.leaves, 7);
		world.setBlockMetadataWithNotify(i + 12, j + 30, k + 18, 7, 2);
		setBlock(world, i + 12, j + 30, k + 19, Blocks.leaves, 7);
		world.setBlockMetadataWithNotify(i + 12, j + 30, k + 19, 7, 2);
		setBlock(world, i + 12, j + 30, k + 20, Blocks.leaves, 7);
		world.setBlockMetadataWithNotify(i + 12, j + 30, k + 20, 7, 2);
		setBlock(world, i + 12, j + 30, k + 24, Blocks.log, 3);
		world.setBlockMetadataWithNotify(i + 12, j + 30, k + 24, 3, 2);
		setBlock(world, i + 12, j + 31, k + 17, Blocks.leaves, 7);
		world.setBlockMetadataWithNotify(i + 12, j + 31, k + 17, 7, 2);
		setBlock(world, i + 12, j + 31, k + 18, Blocks.leaves, 7);
		world.setBlockMetadataWithNotify(i + 12, j + 31, k + 18, 7, 2);
		setBlock(world, i + 12, j + 31, k + 19, Blocks.leaves, 7);
		world.setBlockMetadataWithNotify(i + 12, j + 31, k + 19, 7, 2);
		setBlock(world, i + 12, j + 31, k + 23, Blocks.leaves, 7);
		world.setBlockMetadataWithNotify(i + 12, j + 31, k + 23, 7, 2);
		setBlock(world, i + 12, j + 31, k + 24, Blocks.leaves, 7);
		world.setBlockMetadataWithNotify(i + 12, j + 31, k + 24, 7, 2);
		setBlock(world, i + 12, j + 31, k + 25, Blocks.log, 3);
		world.setBlockMetadataWithNotify(i + 12, j + 31, k + 25, 3, 2);
		setBlock(world, i + 12, j + 31, k + 26, Blocks.leaves, 7);
		world.setBlockMetadataWithNotify(i + 12, j + 31, k + 26, 7, 2);
		setBlock(world, i + 12, j + 31, k + 27, Blocks.leaves, 7);
		world.setBlockMetadataWithNotify(i + 12, j + 31, k + 27, 7, 2);
		setBlock(world, i + 12, j + 32, k + 18, Blocks.leaves, 7);
		world.setBlockMetadataWithNotify(i + 12, j + 32, k + 18, 7, 2);
		setBlock(world, i + 12, j + 32, k + 19, Blocks.log, 3);
		world.setBlockMetadataWithNotify(i + 12, j + 32, k + 19, 3, 2);
		setBlock(world, i + 12, j + 32, k + 23, Blocks.leaves, 7);
		world.setBlockMetadataWithNotify(i + 12, j + 32, k + 23, 7, 2);
		setBlock(world, i + 12, j + 32, k + 24, Blocks.leaves, 7);
		world.setBlockMetadataWithNotify(i + 12, j + 32, k + 24, 7, 2);
		setBlock(world, i + 12, j + 32, k + 25, Blocks.leaves, 7);
		world.setBlockMetadataWithNotify(i + 12, j + 32, k + 25, 7, 2);
		setBlock(world, i + 12, j + 32, k + 26, Blocks.leaves, 7);
		world.setBlockMetadataWithNotify(i + 12, j + 32, k + 26, 7, 2);
		setBlock(world, i + 12, j + 32, k + 27, Blocks.leaves, 7);
		world.setBlockMetadataWithNotify(i + 12, j + 32, k + 27, 7, 2);
		setBlock(world, i + 12, j + 33, k + 24, Blocks.leaves, 7);
		world.setBlockMetadataWithNotify(i + 12, j + 33, k + 24, 7, 2);
		setBlock(world, i + 12, j + 33, k + 25, Blocks.leaves, 7);
		world.setBlockMetadataWithNotify(i + 12, j + 33, k + 25, 7, 2);
		setBlock(world, i + 12, j + 33, k + 26, Blocks.leaves, 7);
		world.setBlockMetadataWithNotify(i + 12, j + 33, k + 26, 7, 2);
		setBlock(world, i + 12, j + 34, k + 25, Blocks.leaves, 7);
		world.setBlockMetadataWithNotify(i + 12, j + 34, k + 25, 7, 2);
		setBlock(world, i + 12, j + 35, k + 18, Blocks.leaves, 7);
		world.setBlockMetadataWithNotify(i + 12, j + 35, k + 18, 7, 2);
		setBlock(world, i + 12, j + 35, k + 19, Blocks.leaves, 7);
		world.setBlockMetadataWithNotify(i + 12, j + 35, k + 19, 7, 2);
		setBlock(world, i + 12, j + 35, k + 20, Blocks.leaves, 7);
		world.setBlockMetadataWithNotify(i + 12, j + 35, k + 20, 7, 2);
		setBlock(world, i + 12, j + 36, k + 19, Blocks.leaves, 7);
		world.setBlockMetadataWithNotify(i + 12, j + 36, k + 19, 7, 2);
		setBlock(world, i + 12, j + 37, k + 7, Blocks.leaves, 7);
		world.setBlockMetadataWithNotify(i + 12, j + 37, k + 7, 7, 2);
		setBlock(world, i + 12, j + 37, k + 8, Blocks.leaves, 7);
		world.setBlockMetadataWithNotify(i + 12, j + 37, k + 8, 7, 2);
		setBlock(world, i + 12, j + 37, k + 9, Blocks.leaves, 7);
		world.setBlockMetadataWithNotify(i + 12, j + 37, k + 9, 7, 2);
		setBlock(world, i + 12, j + 37, k + 10, Blocks.leaves, 7);
		world.setBlockMetadataWithNotify(i + 12, j + 37, k + 10, 7, 2);
		setBlock(world, i + 12, j + 37, k + 11, Blocks.leaves, 7);
		world.setBlockMetadataWithNotify(i + 12, j + 37, k + 11, 7, 2);
		setBlock(world, i + 12, j + 38, k + 8, Blocks.leaves, 7);
		world.setBlockMetadataWithNotify(i + 12, j + 38, k + 8, 7, 2);
		setBlock(world, i + 12, j + 38, k + 9, Blocks.leaves, 7);
		world.setBlockMetadataWithNotify(i + 12, j + 38, k + 9, 7, 2);
		setBlock(world, i + 12, j + 38, k + 10, Blocks.leaves, 7);
		world.setBlockMetadataWithNotify(i + 12, j + 38, k + 10, 7, 2);
		setBlock(world, i + 12, j + 39, k + 0, Blocks.log, 3);
		world.setBlockMetadataWithNotify(i + 12, j + 39, k + 0, 3, 2);
		setBlock(world, i + 12, j + 39, k + 1, Blocks.leaves, 7);
		world.setBlockMetadataWithNotify(i + 12, j + 39, k + 1, 7, 2);
		setBlock(world, i + 12, j + 39, k + 2, Blocks.leaves, 7);
		world.setBlockMetadataWithNotify(i + 12, j + 39, k + 2, 7, 2);
		setBlock(world, i + 12, j + 39, k + 9, Blocks.leaves, 7);
		world.setBlockMetadataWithNotify(i + 12, j + 39, k + 9, 7, 2);
		setBlock(world, i + 12, j + 40, k + 0, Blocks.leaves, 7);
		world.setBlockMetadataWithNotify(i + 12, j + 40, k + 0, 7, 2);
		setBlock(world, i + 12, j + 40, k + 1, Blocks.leaves, 7);
		world.setBlockMetadataWithNotify(i + 12, j + 40, k + 1, 7, 2);
		setBlock(world, i + 12, j + 40, k + 2, Blocks.leaves, 7);
		world.setBlockMetadataWithNotify(i + 12, j + 40, k + 2, 7, 2);
		setBlock(world, i + 12, j + 41, k + 0, Blocks.leaves, 7);
		world.setBlockMetadataWithNotify(i + 12, j + 41, k + 0, 7, 2);
		setBlock(world, i + 12, j + 41, k + 1, Blocks.leaves, 7);
		world.setBlockMetadataWithNotify(i + 12, j + 41, k + 1, 7, 2);
		setBlock(world, i + 12, j + 42, k + 0, Blocks.leaves, 7);
		world.setBlockMetadataWithNotify(i + 12, j + 42, k + 0, 7, 2);
		setBlock(world, i + 12, j + 42, k + 9, Blocks.leaves, 7);
		world.setBlockMetadataWithNotify(i + 12, j + 42, k + 9, 7, 2);
		setBlock(world, i + 12, j + 42, k + 10, Blocks.leaves, 7);
		world.setBlockMetadataWithNotify(i + 12, j + 42, k + 10, 7, 2);
		setBlock(world, i + 12, j + 42, k + 11, Blocks.leaves, 7);
		world.setBlockMetadataWithNotify(i + 12, j + 42, k + 11, 7, 2);
		setBlock(world, i + 12, j + 42, k + 14, Blocks.leaves, 7);
		world.setBlockMetadataWithNotify(i + 12, j + 42, k + 14, 7, 2);
		setBlock(world, i + 12, j + 42, k + 15, Blocks.leaves, 7);
		world.setBlockMetadataWithNotify(i + 12, j + 42, k + 15, 7, 2);
		setBlock(world, i + 12, j + 42, k + 16, Blocks.leaves, 7);
		world.setBlockMetadataWithNotify(i + 12, j + 42, k + 16, 7, 2);
		setBlock(world, i + 12, j + 43, k + 10, Blocks.leaves, 7);
		world.setBlockMetadataWithNotify(i + 12, j + 43, k + 10, 7, 2);
		setBlock(world, i + 12, j + 43, k + 15, Blocks.leaves, 7);
		world.setBlockMetadataWithNotify(i + 12, j + 43, k + 15, 7, 2);
		setBlock(world, i + 12, j + 45, k + 4, Blocks.leaves, 7);
		world.setBlockMetadataWithNotify(i + 12, j + 45, k + 4, 7, 2);
		setBlock(world, i + 12, j + 45, k + 5, Blocks.leaves, 7);
		world.setBlockMetadataWithNotify(i + 12, j + 45, k + 5, 7, 2);
		setBlock(world, i + 12, j + 45, k + 6, Blocks.leaves, 7);
		world.setBlockMetadataWithNotify(i + 12, j + 45, k + 6, 7, 2);
		setBlock(world, i + 12, j + 45, k + 7, Blocks.leaves, 7);
		world.setBlockMetadataWithNotify(i + 12, j + 45, k + 7, 7, 2);
		setBlock(world, i + 12, j + 45, k + 8, Blocks.leaves, 7);
		world.setBlockMetadataWithNotify(i + 12, j + 45, k + 8, 7, 2);
		setBlock(world, i + 12, j + 45, k + 9, Blocks.leaves, 7);
		world.setBlockMetadataWithNotify(i + 12, j + 45, k + 9, 7, 2);
		setBlock(world, i + 12, j + 45, k + 10, Blocks.leaves, 7);
		world.setBlockMetadataWithNotify(i + 12, j + 45, k + 10, 7, 2);
		setBlock(world, i + 12, j + 46, k + 0, Blocks.leaves, 7);
		world.setBlockMetadataWithNotify(i + 12, j + 46, k + 0, 7, 2);
		setBlock(world, i + 12, j + 46, k + 1, Blocks.leaves, 7);
		world.setBlockMetadataWithNotify(i + 12, j + 46, k + 1, 7, 2);
		setBlock(world, i + 12, j + 46, k + 2, Blocks.leaves, 7);
		world.setBlockMetadataWithNotify(i + 12, j + 46, k + 2, 7, 2);
		setBlock(world, i + 12, j + 46, k + 3, Blocks.leaves, 7);
		world.setBlockMetadataWithNotify(i + 12, j + 46, k + 3, 7, 2);
		setBlock(world, i + 12, j + 46, k + 5, Blocks.leaves, 7);
		world.setBlockMetadataWithNotify(i + 12, j + 46, k + 5, 7, 2);
		setBlock(world, i + 12, j + 46, k + 7, Blocks.leaves, 7);
		world.setBlockMetadataWithNotify(i + 12, j + 46, k + 7, 7, 2);
		setBlock(world, i + 12, j + 46, k + 8, Blocks.leaves, 7);
		world.setBlockMetadataWithNotify(i + 12, j + 46, k + 8, 7, 2);
		setBlock(world, i + 12, j + 46, k + 9, Blocks.leaves, 7);
		world.setBlockMetadataWithNotify(i + 12, j + 46, k + 9, 7, 2);
		setBlock(world, i + 12, j + 47, k + 0, Blocks.leaves, 7);
		world.setBlockMetadataWithNotify(i + 12, j + 47, k + 0, 7, 2);
		setBlock(world, i + 12, j + 47, k + 1, Blocks.leaves, 7);
		world.setBlockMetadataWithNotify(i + 12, j + 47, k + 1, 7, 2);
		setBlock(world, i + 12, j + 47, k + 2, Blocks.leaves, 7);
		world.setBlockMetadataWithNotify(i + 12, j + 47, k + 2, 7, 2);
		setBlock(world, i + 12, j + 47, k + 8, Blocks.leaves, 7);
		world.setBlockMetadataWithNotify(i + 12, j + 47, k + 8, 7, 2);
		setBlock(world, i + 12, j + 48, k + 1, Blocks.leaves, 7);
		world.setBlockMetadataWithNotify(i + 12, j + 48, k + 1, 7, 2);
		setBlock(world, i + 12, j + 51, k + 3, Blocks.leaves, 7);
		world.setBlockMetadataWithNotify(i + 12, j + 51, k + 3, 7, 2);
		setBlock(world, i + 12, j + 51, k + 4, Blocks.leaves, 7);
		world.setBlockMetadataWithNotify(i + 12, j + 51, k + 4, 7, 2);
		setBlock(world, i + 12, j + 51, k + 5, Blocks.leaves, 7);
		world.setBlockMetadataWithNotify(i + 12, j + 51, k + 5, 7, 2);
		setBlock(world, i + 12, j + 52, k + 4, Blocks.leaves, 7);
		world.setBlockMetadataWithNotify(i + 12, j + 52, k + 4, 7, 2);
		setBlock(world, i + 13, j + 21, k + 15, Blocks.log, 3);
		world.setBlockMetadataWithNotify(i + 13, j + 21, k + 15, 3, 2);
		setBlock(world, i + 13, j + 24, k + 2, Blocks.log, 3);
		world.setBlockMetadataWithNotify(i + 13, j + 24, k + 2, 3, 2);
		setBlock(world, i + 13, j + 25, k + 3, Blocks.log, 3);
		world.setBlockMetadataWithNotify(i + 13, j + 25, k + 3, 3, 2);
		setBlock(world, i + 13, j + 25, k + 17, Blocks.log, 3);
		world.setBlockMetadataWithNotify(i + 13, j + 25, k + 17, 3, 2);
		setBlock(world, i + 13, j + 25, k + 18, Blocks.leaves, 7);
		world.setBlockMetadataWithNotify(i + 13, j + 25, k + 18, 7, 2);
		setBlock(world, i + 13, j + 25, k + 19, Blocks.log, 3);
		world.setBlockMetadataWithNotify(i + 13, j + 25, k + 19, 3, 2);
		setBlock(world, i + 13, j + 25, k + 20, Blocks.leaves, 7);
		world.setBlockMetadataWithNotify(i + 13, j + 25, k + 20, 7, 2);
		setBlock(world, i + 13, j + 25, k + 21, Blocks.leaves, 7);
		world.setBlockMetadataWithNotify(i + 13, j + 25, k + 21, 7, 2);
		setBlock(world, i + 13, j + 26, k + 17, Blocks.leaves, 7);
		world.setBlockMetadataWithNotify(i + 13, j + 26, k + 17, 7, 2);
		setBlock(world, i + 13, j + 26, k + 18, Blocks.leaves, 7);
		world.setBlockMetadataWithNotify(i + 13, j + 26, k + 18, 7, 2);
		setBlock(world, i + 13, j + 26, k + 19, Blocks.leaves, 7);
		world.setBlockMetadataWithNotify(i + 13, j + 26, k + 19, 7, 2);
		setBlock(world, i + 13, j + 26, k + 20, Blocks.leaves, 7);
		world.setBlockMetadataWithNotify(i + 13, j + 26, k + 20, 7, 2);
		setBlock(world, i + 13, j + 26, k + 21, Blocks.leaves, 7);
		world.setBlockMetadataWithNotify(i + 13, j + 26, k + 21, 7, 2);
		setBlock(world, i + 13, j + 27, k + 17, Blocks.log, 3);
		world.setBlockMetadataWithNotify(i + 13, j + 27, k + 17, 3, 2);
		setBlock(world, i + 13, j + 27, k + 18, Blocks.leaves, 7);
		world.setBlockMetadataWithNotify(i + 13, j + 27, k + 18, 7, 2);
		setBlock(world, i + 13, j + 27, k + 19, Blocks.leaves, 7);
		world.setBlockMetadataWithNotify(i + 13, j + 27, k + 19, 7, 2);
		setBlock(world, i + 13, j + 27, k + 20, Blocks.leaves, 7);
		world.setBlockMetadataWithNotify(i + 13, j + 27, k + 20, 7, 2);
		setBlock(world, i + 13, j + 28, k + 18, Blocks.log, 3);
		world.setBlockMetadataWithNotify(i + 13, j + 28, k + 18, 3, 2);
		setBlock(world, i + 13, j + 28, k + 19, Blocks.leaves, 7);
		world.setBlockMetadataWithNotify(i + 13, j + 28, k + 19, 7, 2);
		setBlock(world, i + 13, j + 28, k + 20, Blocks.leaves, 7);
		world.setBlockMetadataWithNotify(i + 13, j + 28, k + 20, 7, 2);
		setBlock(world, i + 13, j + 28, k + 21, Blocks.leaves, 7);
		world.setBlockMetadataWithNotify(i + 13, j + 28, k + 21, 7, 2);
		setBlock(world, i + 13, j + 29, k + 16, Blocks.leaves, 7);
		world.setBlockMetadataWithNotify(i + 13, j + 29, k + 16, 7, 2);
		setBlock(world, i + 13, j + 29, k + 17, Blocks.leaves, 7);
		world.setBlockMetadataWithNotify(i + 13, j + 29, k + 17, 7, 2);
		setBlock(world, i + 13, j + 29, k + 18, Blocks.leaves, 7);
		world.setBlockMetadataWithNotify(i + 13, j + 29, k + 18, 7, 2);
		setBlock(world, i + 13, j + 29, k + 19, Blocks.leaves, 7);
		world.setBlockMetadataWithNotify(i + 13, j + 29, k + 19, 7, 2);
		setBlock(world, i + 13, j + 29, k + 20, Blocks.leaves, 7);
		world.setBlockMetadataWithNotify(i + 13, j + 29, k + 20, 7, 2);
		setBlock(world, i + 13, j + 30, k + 17, Blocks.leaves, 7);
		world.setBlockMetadataWithNotify(i + 13, j + 30, k + 17, 7, 2);
		setBlock(world, i + 13, j + 30, k + 18, Blocks.leaves, 7);
		world.setBlockMetadataWithNotify(i + 13, j + 30, k + 18, 7, 2);
		setBlock(world, i + 13, j + 30, k + 19, Blocks.leaves, 7);
		world.setBlockMetadataWithNotify(i + 13, j + 30, k + 19, 7, 2);
		setBlock(world, i + 13, j + 30, k + 23, Blocks.log, 3);
		world.setBlockMetadataWithNotify(i + 13, j + 30, k + 23, 3, 2);
		setBlock(world, i + 13, j + 31, k + 18, Blocks.leaves, 7);
		world.setBlockMetadataWithNotify(i + 13, j + 31, k + 18, 7, 2);
		setBlock(world, i + 13, j + 31, k + 23, Blocks.leaves, 7);
		world.setBlockMetadataWithNotify(i + 13, j + 31, k + 23, 7, 2);
		setBlock(world, i + 13, j + 31, k + 24, Blocks.leaves, 7);
		world.setBlockMetadataWithNotify(i + 13, j + 31, k + 24, 7, 2);
		setBlock(world, i + 13, j + 31, k + 25, Blocks.leaves, 7);
		world.setBlockMetadataWithNotify(i + 13, j + 31, k + 25, 7, 2);
		setBlock(world, i + 13, j + 31, k + 26, Blocks.leaves, 7);
		world.setBlockMetadataWithNotify(i + 13, j + 31, k + 26, 7, 2);
		setBlock(world, i + 13, j + 31, k + 27, Blocks.leaves, 7);
		world.setBlockMetadataWithNotify(i + 13, j + 31, k + 27, 7, 2);
		setBlock(world, i + 13, j + 32, k + 18, Blocks.log, 3);
		world.setBlockMetadataWithNotify(i + 13, j + 32, k + 18, 3, 2);
		setBlock(world, i + 13, j + 32, k + 24, Blocks.leaves, 7);
		world.setBlockMetadataWithNotify(i + 13, j + 32, k + 24, 7, 2);
		setBlock(world, i + 13, j + 32, k + 25, Blocks.leaves, 7);
		world.setBlockMetadataWithNotify(i + 13, j + 32, k + 25, 7, 2);
		setBlock(world, i + 13, j + 32, k + 26, Blocks.leaves, 7);
		world.setBlockMetadataWithNotify(i + 13, j + 32, k + 26, 7, 2);
		setBlock(world, i + 13, j + 33, k + 25, Blocks.leaves, 7);
		world.setBlockMetadataWithNotify(i + 13, j + 33, k + 25, 7, 2);
		setBlock(world, i + 13, j + 35, k + 17, Blocks.leaves, 7);
		world.setBlockMetadataWithNotify(i + 13, j + 35, k + 17, 7, 2);
		setBlock(world, i + 13, j + 35, k + 18, Blocks.leaves, 7);
		world.setBlockMetadataWithNotify(i + 13, j + 35, k + 18, 7, 2);
		setBlock(world, i + 13, j + 35, k + 19, Blocks.leaves, 7);
		world.setBlockMetadataWithNotify(i + 13, j + 35, k + 19, 7, 2);
		setBlock(world, i + 13, j + 35, k + 20, Blocks.leaves, 7);
		world.setBlockMetadataWithNotify(i + 13, j + 35, k + 20, 7, 2);
		setBlock(world, i + 13, j + 35, k + 21, Blocks.leaves, 7);
		world.setBlockMetadataWithNotify(i + 13, j + 35, k + 21, 7, 2);
		setBlock(world, i + 13, j + 36, k + 18, Blocks.leaves, 7);
		world.setBlockMetadataWithNotify(i + 13, j + 36, k + 18, 7, 2);
		setBlock(world, i + 13, j + 36, k + 19, Blocks.leaves, 7);
		world.setBlockMetadataWithNotify(i + 13, j + 36, k + 19, 7, 2);
		setBlock(world, i + 13, j + 36, k + 20, Blocks.leaves, 7);
		world.setBlockMetadataWithNotify(i + 13, j + 36, k + 20, 7, 2);
		setBlock(world, i + 13, j + 37, k + 7, Blocks.leaves, 7);
		world.setBlockMetadataWithNotify(i + 13, j + 37, k + 7, 7, 2);
		setBlock(world, i + 13, j + 37, k + 8, Blocks.leaves, 7);
		world.setBlockMetadataWithNotify(i + 13, j + 37, k + 8, 7, 2);
		setBlock(world, i + 13, j + 37, k + 9, Blocks.log, 3);
		world.setBlockMetadataWithNotify(i + 13, j + 37, k + 9, 3, 2);
		setBlock(world, i + 13, j + 37, k + 10, Blocks.leaves, 7);
		world.setBlockMetadataWithNotify(i + 13, j + 37, k + 10, 7, 2);
		setBlock(world, i + 13, j + 37, k + 11, Blocks.leaves, 7);
		world.setBlockMetadataWithNotify(i + 13, j + 37, k + 11, 7, 2);
		setBlock(world, i + 13, j + 37, k + 19, Blocks.leaves, 7);
		world.setBlockMetadataWithNotify(i + 13, j + 37, k + 19, 7, 2);
		setBlock(world, i + 13, j + 38, k + 1, Blocks.log, 3);
		world.setBlockMetadataWithNotify(i + 13, j + 38, k + 1, 3, 2);
		setBlock(world, i + 13, j + 38, k + 7, Blocks.leaves, 7);
		world.setBlockMetadataWithNotify(i + 13, j + 38, k + 7, 7, 2);
		setBlock(world, i + 13, j + 38, k + 8, Blocks.leaves, 7);
		world.setBlockMetadataWithNotify(i + 13, j + 38, k + 8, 7, 2);
		setBlock(world, i + 13, j + 38, k + 9, Blocks.leaves, 7);
		world.setBlockMetadataWithNotify(i + 13, j + 38, k + 9, 7, 2);
		setBlock(world, i + 13, j + 38, k + 10, Blocks.leaves, 7);
		world.setBlockMetadataWithNotify(i + 13, j + 38, k + 10, 7, 2);
		setBlock(world, i + 13, j + 38, k + 11, Blocks.leaves, 7);
		world.setBlockMetadataWithNotify(i + 13, j + 38, k + 11, 7, 2);
		setBlock(world, i + 13, j + 39, k + 0, Blocks.leaves, 7);
		world.setBlockMetadataWithNotify(i + 13, j + 39, k + 0, 7, 2);
		setBlock(world, i + 13, j + 39, k + 1, Blocks.leaves, 7);
		world.setBlockMetadataWithNotify(i + 13, j + 39, k + 1, 7, 2);
		setBlock(world, i + 13, j + 39, k + 2, Blocks.leaves, 7);
		world.setBlockMetadataWithNotify(i + 13, j + 39, k + 2, 7, 2);
		setBlock(world, i + 13, j + 39, k + 8, Blocks.leaves, 7);
		world.setBlockMetadataWithNotify(i + 13, j + 39, k + 8, 7, 2);
		setBlock(world, i + 13, j + 39, k + 9, Blocks.leaves, 7);
		world.setBlockMetadataWithNotify(i + 13, j + 39, k + 9, 7, 2);
		setBlock(world, i + 13, j + 39, k + 10, Blocks.leaves, 7);
		world.setBlockMetadataWithNotify(i + 13, j + 39, k + 10, 7, 2);
		setBlock(world, i + 13, j + 40, k + 0, Blocks.leaves, 7);
		world.setBlockMetadataWithNotify(i + 13, j + 40, k + 0, 7, 2);
		setBlock(world, i + 13, j + 40, k + 1, Blocks.leaves, 7);
		world.setBlockMetadataWithNotify(i + 13, j + 40, k + 1, 7, 2);
		setBlock(world, i + 13, j + 40, k + 3, Blocks.leaves, 7);
		world.setBlockMetadataWithNotify(i + 13, j + 40, k + 3, 7, 2);
		setBlock(world, i + 13, j + 40, k + 4, Blocks.leaves, 7);
		world.setBlockMetadataWithNotify(i + 13, j + 40, k + 4, 7, 2);
		setBlock(world, i + 13, j + 40, k + 5, Blocks.leaves, 7);
		world.setBlockMetadataWithNotify(i + 13, j + 40, k + 5, 7, 2);
		setBlock(world, i + 13, j + 40, k + 9, Blocks.leaves, 7);
		world.setBlockMetadataWithNotify(i + 13, j + 40, k + 9, 7, 2);
		setBlock(world, i + 13, j + 41, k + 0, Blocks.leaves, 7);
		world.setBlockMetadataWithNotify(i + 13, j + 41, k + 0, 7, 2);
		setBlock(world, i + 13, j + 41, k + 4, Blocks.leaves, 7);
		world.setBlockMetadataWithNotify(i + 13, j + 41, k + 4, 7, 2);
		setBlock(world, i + 13, j + 42, k + 8, Blocks.leaves, 7);
		world.setBlockMetadataWithNotify(i + 13, j + 42, k + 8, 7, 2);
		setBlock(world, i + 13, j + 42, k + 9, Blocks.leaves, 7);
		world.setBlockMetadataWithNotify(i + 13, j + 42, k + 9, 7, 2);
		setBlock(world, i + 13, j + 42, k + 10, Blocks.leaves, 7);
		world.setBlockMetadataWithNotify(i + 13, j + 42, k + 10, 7, 2);
		setBlock(world, i + 13, j + 42, k + 11, Blocks.leaves, 7);
		world.setBlockMetadataWithNotify(i + 13, j + 42, k + 11, 7, 2);
		setBlock(world, i + 13, j + 42, k + 12, Blocks.leaves, 7);
		world.setBlockMetadataWithNotify(i + 13, j + 42, k + 12, 7, 2);
		setBlock(world, i + 13, j + 43, k + 9, Blocks.leaves, 7);
		world.setBlockMetadataWithNotify(i + 13, j + 43, k + 9, 7, 2);
		setBlock(world, i + 13, j + 43, k + 10, Blocks.leaves, 7);
		world.setBlockMetadataWithNotify(i + 13, j + 43, k + 10, 7, 2);
		setBlock(world, i + 13, j + 43, k + 11, Blocks.leaves, 7);
		world.setBlockMetadataWithNotify(i + 13, j + 43, k + 11, 7, 2);
		setBlock(world, i + 13, j + 44, k + 2, Blocks.leaves, 7);
		world.setBlockMetadataWithNotify(i + 13, j + 44, k + 2, 7, 2);
		setBlock(world, i + 13, j + 44, k + 3, Blocks.leaves, 7);
		world.setBlockMetadataWithNotify(i + 13, j + 44, k + 3, 7, 2);
		setBlock(world, i + 13, j + 44, k + 4, Blocks.leaves, 7);
		world.setBlockMetadataWithNotify(i + 13, j + 44, k + 4, 7, 2);
		setBlock(world, i + 13, j + 44, k + 10, Blocks.leaves, 7);
		world.setBlockMetadataWithNotify(i + 13, j + 44, k + 10, 7, 2);
		setBlock(world, i + 13, j + 45, k + 3, Blocks.leaves, 7);
		world.setBlockMetadataWithNotify(i + 13, j + 45, k + 3, 7, 2);
		setBlock(world, i + 13, j + 45, k + 7, Blocks.leaves, 7);
		world.setBlockMetadataWithNotify(i + 13, j + 45, k + 7, 7, 2);
		setBlock(world, i + 13, j + 45, k + 8, Blocks.leaves, 7);
		world.setBlockMetadataWithNotify(i + 13, j + 45, k + 8, 7, 2);
		setBlock(world, i + 13, j + 45, k + 9, Blocks.leaves, 7);
		world.setBlockMetadataWithNotify(i + 13, j + 45, k + 9, 7, 2);
		setBlock(world, i + 13, j + 46, k + 0, Blocks.leaves, 7);
		world.setBlockMetadataWithNotify(i + 13, j + 46, k + 0, 7, 2);
		setBlock(world, i + 13, j + 46, k + 1, Blocks.log, 3);
		world.setBlockMetadataWithNotify(i + 13, j + 46, k + 1, 3, 2);
		setBlock(world, i + 13, j + 46, k + 2, Blocks.leaves, 7);
		world.setBlockMetadataWithNotify(i + 13, j + 46, k + 2, 7, 2);
		setBlock(world, i + 13, j + 46, k + 3, Blocks.leaves, 7);
		world.setBlockMetadataWithNotify(i + 13, j + 46, k + 3, 7, 2);
		setBlock(world, i + 13, j + 46, k + 8, Blocks.leaves, 7);
		world.setBlockMetadataWithNotify(i + 13, j + 46, k + 8, 7, 2);
		setBlock(world, i + 13, j + 47, k + 0, Blocks.leaves, 7);
		world.setBlockMetadataWithNotify(i + 13, j + 47, k + 0, 7, 2);
		setBlock(world, i + 13, j + 47, k + 1, Blocks.leaves, 7);
		world.setBlockMetadataWithNotify(i + 13, j + 47, k + 1, 7, 2);
		setBlock(world, i + 13, j + 47, k + 2, Blocks.leaves, 7);
		world.setBlockMetadataWithNotify(i + 13, j + 47, k + 2, 7, 2);
		setBlock(world, i + 13, j + 47, k + 3, Blocks.leaves, 7);
		world.setBlockMetadataWithNotify(i + 13, j + 47, k + 3, 7, 2);
		setBlock(world, i + 13, j + 48, k + 0, Blocks.leaves, 7);
		world.setBlockMetadataWithNotify(i + 13, j + 48, k + 0, 7, 2);
		setBlock(world, i + 13, j + 48, k + 1, Blocks.leaves, 7);
		world.setBlockMetadataWithNotify(i + 13, j + 48, k + 1, 7, 2);
		setBlock(world, i + 13, j + 48, k + 2, Blocks.leaves, 7);
		world.setBlockMetadataWithNotify(i + 13, j + 48, k + 2, 7, 2);
		setBlock(world, i + 13, j + 49, k + 1, Blocks.leaves, 7);
		world.setBlockMetadataWithNotify(i + 13, j + 49, k + 1, 7, 2);
		setBlock(world, i + 13, j + 51, k + 2, Blocks.leaves, 7);
		world.setBlockMetadataWithNotify(i + 13, j + 51, k + 2, 7, 2);
		setBlock(world, i + 13, j + 51, k + 3, Blocks.leaves, 7);
		world.setBlockMetadataWithNotify(i + 13, j + 51, k + 3, 7, 2);
		setBlock(world, i + 13, j + 51, k + 4, Blocks.leaves, 7);
		world.setBlockMetadataWithNotify(i + 13, j + 51, k + 4, 7, 2);
		setBlock(world, i + 13, j + 51, k + 5, Blocks.leaves, 7);
		world.setBlockMetadataWithNotify(i + 13, j + 51, k + 5, 7, 2);
		setBlock(world, i + 13, j + 51, k + 6, Blocks.leaves, 7);
		world.setBlockMetadataWithNotify(i + 13, j + 51, k + 6, 7, 2);
		setBlock(world, i + 13, j + 52, k + 3, Blocks.leaves, 7);
		world.setBlockMetadataWithNotify(i + 13, j + 52, k + 3, 7, 2);
		setBlock(world, i + 13, j + 52, k + 4, Blocks.leaves, 7);
		world.setBlockMetadataWithNotify(i + 13, j + 52, k + 4, 7, 2);
		setBlock(world, i + 13, j + 52, k + 5, Blocks.leaves, 7);
		world.setBlockMetadataWithNotify(i + 13, j + 52, k + 5, 7, 2);
		setBlock(world, i + 13, j + 53, k + 4, Blocks.leaves, 7);
		world.setBlockMetadataWithNotify(i + 13, j + 53, k + 4, 7, 2);
		setBlock(world, i + 14, j + 2, k + 7, Blocks.leaves, 7);
		world.setBlockMetadataWithNotify(i + 14, j + 2, k + 7, 7, 2);
		setBlock(world, i + 14, j + 2, k + 8, Blocks.leaves, 7);
		world.setBlockMetadataWithNotify(i + 14, j + 2, k + 8, 7, 2);
		setBlock(world, i + 14, j + 2, k + 9, Blocks.leaves, 7);
		world.setBlockMetadataWithNotify(i + 14, j + 2, k + 9, 7, 2);
		setBlock(world, i + 14, j + 3, k + 8, Blocks.leaves, 7);
		world.setBlockMetadataWithNotify(i + 14, j + 3, k + 8, 7, 2);
		setBlock(world, i + 14, j + 20, k + 0, Blocks.log, 3);
		world.setBlockMetadataWithNotify(i + 14, j + 20, k + 0, 3, 2);
		setBlock(world, i + 14, j + 21, k + 15, Blocks.log, 3);
		world.setBlockMetadataWithNotify(i + 14, j + 21, k + 15, 3, 2);
		setBlock(world, i + 14, j + 24, k + 2, Blocks.log, 3);
		world.setBlockMetadataWithNotify(i + 14, j + 24, k + 2, 3, 2);
		setBlock(world, i + 14, j + 24, k + 18, Blocks.log, 3);
		world.setBlockMetadataWithNotify(i + 14, j + 24, k + 18, 3, 2);
		setBlock(world, i + 14, j + 25, k + 4, Blocks.log, 3);
		world.setBlockMetadataWithNotify(i + 14, j + 25, k + 4, 3, 2);
		setBlock(world, i + 14, j + 25, k + 17, Blocks.log, 3);
		world.setBlockMetadataWithNotify(i + 14, j + 25, k + 17, 3, 2);
		setBlock(world, i + 14, j + 25, k + 18, Blocks.leaves, 7);
		world.setBlockMetadataWithNotify(i + 14, j + 25, k + 18, 7, 2);
		setBlock(world, i + 14, j + 25, k + 19, Blocks.leaves, 7);
		world.setBlockMetadataWithNotify(i + 14, j + 25, k + 19, 7, 2);
		setBlock(world, i + 14, j + 25, k + 20, Blocks.leaves, 7);
		world.setBlockMetadataWithNotify(i + 14, j + 25, k + 20, 7, 2);
		setBlock(world, i + 14, j + 25, k + 21, Blocks.leaves, 7);
		world.setBlockMetadataWithNotify(i + 14, j + 25, k + 21, 7, 2);
		setBlock(world, i + 14, j + 26, k + 18, Blocks.leaves, 7);
		world.setBlockMetadataWithNotify(i + 14, j + 26, k + 18, 7, 2);
		setBlock(world, i + 14, j + 26, k + 19, Blocks.leaves, 7);
		world.setBlockMetadataWithNotify(i + 14, j + 26, k + 19, 7, 2);
		setBlock(world, i + 14, j + 26, k + 20, Blocks.leaves, 7);
		world.setBlockMetadataWithNotify(i + 14, j + 26, k + 20, 7, 2);
		setBlock(world, i + 14, j + 27, k + 16, Blocks.log, 3);
		world.setBlockMetadataWithNotify(i + 14, j + 27, k + 16, 3, 2);
		setBlock(world, i + 14, j + 27, k + 19, Blocks.leaves, 7);
		world.setBlockMetadataWithNotify(i + 14, j + 27, k + 19, 7, 2);
		setBlock(world, i + 14, j + 28, k + 17, Blocks.log, 3);
		world.setBlockMetadataWithNotify(i + 14, j + 28, k + 17, 3, 2);
		setBlock(world, i + 14, j + 29, k + 17, Blocks.leaves, 7);
		world.setBlockMetadataWithNotify(i + 14, j + 29, k + 17, 7, 2);
		setBlock(world, i + 14, j + 29, k + 18, Blocks.leaves, 7);
		world.setBlockMetadataWithNotify(i + 14, j + 29, k + 18, 7, 2);
		setBlock(world, i + 14, j + 29, k + 19, Blocks.leaves, 7);
		world.setBlockMetadataWithNotify(i + 14, j + 29, k + 19, 7, 2);
		setBlock(world, i + 14, j + 30, k + 18, Blocks.leaves, 7);
		world.setBlockMetadataWithNotify(i + 14, j + 30, k + 18, 7, 2);
		setBlock(world, i + 14, j + 30, k + 22, Blocks.log, 3);
		world.setBlockMetadataWithNotify(i + 14, j + 30, k + 22, 3, 2);
		setBlock(world, i + 14, j + 31, k + 24, Blocks.leaves, 7);
		world.setBlockMetadataWithNotify(i + 14, j + 31, k + 24, 7, 2);
		setBlock(world, i + 14, j + 31, k + 25, Blocks.leaves, 7);
		world.setBlockMetadataWithNotify(i + 14, j + 31, k + 25, 7, 2);
		setBlock(world, i + 14, j + 31, k + 26, Blocks.leaves, 7);
		world.setBlockMetadataWithNotify(i + 14, j + 31, k + 26, 7, 2);
		setBlock(world, i + 14, j + 32, k + 3, Blocks.leaves, 7);
		world.setBlockMetadataWithNotify(i + 14, j + 32, k + 3, 7, 2);
		setBlock(world, i + 14, j + 32, k + 4, Blocks.leaves, 7);
		world.setBlockMetadataWithNotify(i + 14, j + 32, k + 4, 7, 2);
		setBlock(world, i + 14, j + 32, k + 5, Blocks.leaves, 7);
		world.setBlockMetadataWithNotify(i + 14, j + 32, k + 5, 7, 2);
		setBlock(world, i + 14, j + 32, k + 17, Blocks.log, 3);
		world.setBlockMetadataWithNotify(i + 14, j + 32, k + 17, 3, 2);
		setBlock(world, i + 14, j + 32, k + 25, Blocks.leaves, 7);
		world.setBlockMetadataWithNotify(i + 14, j + 32, k + 25, 7, 2);
		setBlock(world, i + 14, j + 33, k + 4, Blocks.leaves, 7);
		world.setBlockMetadataWithNotify(i + 14, j + 33, k + 4, 7, 2);
		setBlock(world, i + 14, j + 35, k + 17, Blocks.leaves, 7);
		world.setBlockMetadataWithNotify(i + 14, j + 35, k + 17, 7, 2);
		setBlock(world, i + 14, j + 35, k + 18, Blocks.leaves, 7);
		world.setBlockMetadataWithNotify(i + 14, j + 35, k + 18, 7, 2);
		setBlock(world, i + 14, j + 35, k + 19, Blocks.log, 3);
		world.setBlockMetadataWithNotify(i + 14, j + 35, k + 19, 3, 2);
		setBlock(world, i + 14, j + 35, k + 20, Blocks.leaves, 7);
		world.setBlockMetadataWithNotify(i + 14, j + 35, k + 20, 7, 2);
		setBlock(world, i + 14, j + 35, k + 21, Blocks.leaves, 7);
		world.setBlockMetadataWithNotify(i + 14, j + 35, k + 21, 7, 2);
		setBlock(world, i + 14, j + 36, k + 9, Blocks.log, 3);
		world.setBlockMetadataWithNotify(i + 14, j + 36, k + 9, 3, 2);
		setBlock(world, i + 14, j + 36, k + 17, Blocks.leaves, 7);
		world.setBlockMetadataWithNotify(i + 14, j + 36, k + 17, 7, 2);
		setBlock(world, i + 14, j + 36, k + 18, Blocks.leaves, 7);
		world.setBlockMetadataWithNotify(i + 14, j + 36, k + 18, 7, 2);
		setBlock(world, i + 14, j + 36, k + 19, Blocks.leaves, 7);
		world.setBlockMetadataWithNotify(i + 14, j + 36, k + 19, 7, 2);
		setBlock(world, i + 14, j + 36, k + 20, Blocks.leaves, 7);
		world.setBlockMetadataWithNotify(i + 14, j + 36, k + 20, 7, 2);
		setBlock(world, i + 14, j + 36, k + 21, Blocks.leaves, 7);
		world.setBlockMetadataWithNotify(i + 14, j + 36, k + 21, 7, 2);
		setBlock(world, i + 14, j + 37, k + 7, Blocks.leaves, 7);
		world.setBlockMetadataWithNotify(i + 14, j + 37, k + 7, 7, 2);
		setBlock(world, i + 14, j + 37, k + 8, Blocks.leaves, 7);
		world.setBlockMetadataWithNotify(i + 14, j + 37, k + 8, 7, 2);
		setBlock(world, i + 14, j + 37, k + 9, Blocks.leaves, 7);
		world.setBlockMetadataWithNotify(i + 14, j + 37, k + 9, 7, 2);
		setBlock(world, i + 14, j + 37, k + 10, Blocks.leaves, 7);
		world.setBlockMetadataWithNotify(i + 14, j + 37, k + 10, 7, 2);
		setBlock(world, i + 14, j + 37, k + 11, Blocks.leaves, 7);
		world.setBlockMetadataWithNotify(i + 14, j + 37, k + 11, 7, 2);
		setBlock(world, i + 14, j + 37, k + 18, Blocks.leaves, 7);
		world.setBlockMetadataWithNotify(i + 14, j + 37, k + 18, 7, 2);
		setBlock(world, i + 14, j + 37, k + 19, Blocks.leaves, 7);
		world.setBlockMetadataWithNotify(i + 14, j + 37, k + 19, 7, 2);
		setBlock(world, i + 14, j + 37, k + 20, Blocks.leaves, 7);
		world.setBlockMetadataWithNotify(i + 14, j + 37, k + 20, 7, 2);
		setBlock(world, i + 14, j + 38, k + 2, Blocks.log, 3);
		world.setBlockMetadataWithNotify(i + 14, j + 38, k + 2, 3, 2);
		setBlock(world, i + 14, j + 38, k + 8, Blocks.leaves, 7);
		world.setBlockMetadataWithNotify(i + 14, j + 38, k + 8, 7, 2);
		setBlock(world, i + 14, j + 38, k + 9, Blocks.leaves, 7);
		world.setBlockMetadataWithNotify(i + 14, j + 38, k + 9, 7, 2);
		setBlock(world, i + 14, j + 38, k + 10, Blocks.leaves, 7);
		world.setBlockMetadataWithNotify(i + 14, j + 38, k + 10, 7, 2);
		setBlock(world, i + 14, j + 38, k + 19, Blocks.leaves, 7);
		world.setBlockMetadataWithNotify(i + 14, j + 38, k + 19, 7, 2);
		setBlock(world, i + 14, j + 39, k + 0, Blocks.leaves, 7);
		world.setBlockMetadataWithNotify(i + 14, j + 39, k + 0, 7, 2);
		setBlock(world, i + 14, j + 39, k + 1, Blocks.leaves, 7);
		world.setBlockMetadataWithNotify(i + 14, j + 39, k + 1, 7, 2);
		setBlock(world, i + 14, j + 39, k + 9, Blocks.leaves, 7);
		world.setBlockMetadataWithNotify(i + 14, j + 39, k + 9, 7, 2);
		setBlock(world, i + 14, j + 40, k + 0, Blocks.leaves, 7);
		world.setBlockMetadataWithNotify(i + 14, j + 40, k + 0, 7, 2);
		setBlock(world, i + 14, j + 40, k + 2, Blocks.leaves, 7);
		world.setBlockMetadataWithNotify(i + 14, j + 40, k + 2, 7, 2);
		setBlock(world, i + 14, j + 40, k + 3, Blocks.leaves, 7);
		world.setBlockMetadataWithNotify(i + 14, j + 40, k + 3, 7, 2);
		setBlock(world, i + 14, j + 40, k + 4, Blocks.leaves, 7);
		world.setBlockMetadataWithNotify(i + 14, j + 40, k + 4, 7, 2);
		setBlock(world, i + 14, j + 40, k + 5, Blocks.leaves, 7);
		world.setBlockMetadataWithNotify(i + 14, j + 40, k + 5, 7, 2);
		setBlock(world, i + 14, j + 40, k + 6, Blocks.leaves, 7);
		world.setBlockMetadataWithNotify(i + 14, j + 40, k + 6, 7, 2);
		setBlock(world, i + 14, j + 41, k + 3, Blocks.leaves, 7);
		world.setBlockMetadataWithNotify(i + 14, j + 41, k + 3, 7, 2);
		setBlock(world, i + 14, j + 41, k + 4, Blocks.leaves, 7);
		world.setBlockMetadataWithNotify(i + 14, j + 41, k + 4, 7, 2);
		setBlock(world, i + 14, j + 41, k + 5, Blocks.leaves, 7);
		world.setBlockMetadataWithNotify(i + 14, j + 41, k + 5, 7, 2);
		setBlock(world, i + 14, j + 42, k + 4, Blocks.leaves, 7);
		world.setBlockMetadataWithNotify(i + 14, j + 42, k + 4, 7, 2);
		setBlock(world, i + 14, j + 42, k + 8, Blocks.leaves, 7);
		world.setBlockMetadataWithNotify(i + 14, j + 42, k + 8, 7, 2);
		setBlock(world, i + 14, j + 42, k + 9, Blocks.leaves, 7);
		world.setBlockMetadataWithNotify(i + 14, j + 42, k + 9, 7, 2);
		setBlock(world, i + 14, j + 42, k + 10, Blocks.log, 3);
		world.setBlockMetadataWithNotify(i + 14, j + 42, k + 10, 3, 2);
		setBlock(world, i + 14, j + 42, k + 11, Blocks.leaves, 7);
		world.setBlockMetadataWithNotify(i + 14, j + 42, k + 11, 7, 2);
		setBlock(world, i + 14, j + 42, k + 12, Blocks.leaves, 7);
		world.setBlockMetadataWithNotify(i + 14, j + 42, k + 12, 7, 2);
		setBlock(world, i + 14, j + 43, k + 8, Blocks.leaves, 7);
		world.setBlockMetadataWithNotify(i + 14, j + 43, k + 8, 7, 2);
		setBlock(world, i + 14, j + 43, k + 9, Blocks.leaves, 7);
		world.setBlockMetadataWithNotify(i + 14, j + 43, k + 9, 7, 2);
		setBlock(world, i + 14, j + 43, k + 10, Blocks.leaves, 7);
		world.setBlockMetadataWithNotify(i + 14, j + 43, k + 10, 7, 2);
		setBlock(world, i + 14, j + 43, k + 11, Blocks.leaves, 7);
		world.setBlockMetadataWithNotify(i + 14, j + 43, k + 11, 7, 2);
		setBlock(world, i + 14, j + 43, k + 12, Blocks.leaves, 7);
		world.setBlockMetadataWithNotify(i + 14, j + 43, k + 12, 7, 2);
		setBlock(world, i + 14, j + 44, k + 1, Blocks.leaves, 7);
		world.setBlockMetadataWithNotify(i + 14, j + 44, k + 1, 7, 2);
		setBlock(world, i + 14, j + 44, k + 2, Blocks.leaves, 7);
		world.setBlockMetadataWithNotify(i + 14, j + 44, k + 2, 7, 2);
		setBlock(world, i + 14, j + 44, k + 3, Blocks.leaves, 7);
		world.setBlockMetadataWithNotify(i + 14, j + 44, k + 3, 7, 2);
		setBlock(world, i + 14, j + 44, k + 4, Blocks.leaves, 7);
		world.setBlockMetadataWithNotify(i + 14, j + 44, k + 4, 7, 2);
		setBlock(world, i + 14, j + 44, k + 5, Blocks.leaves, 7);
		world.setBlockMetadataWithNotify(i + 14, j + 44, k + 5, 7, 2);
		setBlock(world, i + 14, j + 44, k + 6, Blocks.leaves, 7);
		world.setBlockMetadataWithNotify(i + 14, j + 44, k + 6, 7, 2);
		setBlock(world, i + 14, j + 44, k + 7, Blocks.leaves, 7);
		world.setBlockMetadataWithNotify(i + 14, j + 44, k + 7, 7, 2);
		setBlock(world, i + 14, j + 44, k + 9, Blocks.leaves, 7);
		world.setBlockMetadataWithNotify(i + 14, j + 44, k + 9, 7, 2);
		setBlock(world, i + 14, j + 44, k + 10, Blocks.leaves, 7);
		world.setBlockMetadataWithNotify(i + 14, j + 44, k + 10, 7, 2);
		setBlock(world, i + 14, j + 44, k + 11, Blocks.leaves, 7);
		world.setBlockMetadataWithNotify(i + 14, j + 44, k + 11, 7, 2);
		setBlock(world, i + 14, j + 45, k + 2, Blocks.log, 3);
		world.setBlockMetadataWithNotify(i + 14, j + 45, k + 2, 3, 2);
		setBlock(world, i + 14, j + 45, k + 3, Blocks.leaves, 7);
		world.setBlockMetadataWithNotify(i + 14, j + 45, k + 3, 7, 2);
		setBlock(world, i + 14, j + 45, k + 4, Blocks.leaves, 7);
		world.setBlockMetadataWithNotify(i + 14, j + 45, k + 4, 7, 2);
		setBlock(world, i + 14, j + 45, k + 6, Blocks.leaves, 7);
		world.setBlockMetadataWithNotify(i + 14, j + 45, k + 6, 7, 2);
		setBlock(world, i + 14, j + 45, k + 10, Blocks.leaves, 7);
		world.setBlockMetadataWithNotify(i + 14, j + 45, k + 10, 7, 2);
		setBlock(world, i + 14, j + 46, k + 0, Blocks.leaves, 7);
		world.setBlockMetadataWithNotify(i + 14, j + 46, k + 0, 7, 2);
		setBlock(world, i + 14, j + 46, k + 1, Blocks.leaves, 7);
		world.setBlockMetadataWithNotify(i + 14, j + 46, k + 1, 7, 2);
		setBlock(world, i + 14, j + 46, k + 2, Blocks.leaves, 7);
		world.setBlockMetadataWithNotify(i + 14, j + 46, k + 2, 7, 2);
		setBlock(world, i + 14, j + 46, k + 3, Blocks.leaves, 7);
		world.setBlockMetadataWithNotify(i + 14, j + 46, k + 3, 7, 2);
		setBlock(world, i + 14, j + 47, k + 0, Blocks.leaves, 7);
		world.setBlockMetadataWithNotify(i + 14, j + 47, k + 0, 7, 2);
		setBlock(world, i + 14, j + 47, k + 1, Blocks.leaves, 7);
		world.setBlockMetadataWithNotify(i + 14, j + 47, k + 1, 7, 2);
		setBlock(world, i + 14, j + 47, k + 2, Blocks.leaves, 7);
		world.setBlockMetadataWithNotify(i + 14, j + 47, k + 2, 7, 2);
		setBlock(world, i + 14, j + 48, k + 1, Blocks.leaves, 7);
		world.setBlockMetadataWithNotify(i + 14, j + 48, k + 1, 7, 2);
		setBlock(world, i + 14, j + 50, k + 13, Blocks.leaves, 7);
		world.setBlockMetadataWithNotify(i + 14, j + 50, k + 13, 7, 2);
		setBlock(world, i + 14, j + 50, k + 14, Blocks.leaves, 7);
		world.setBlockMetadataWithNotify(i + 14, j + 50, k + 14, 7, 2);
		setBlock(world, i + 14, j + 50, k + 15, Blocks.leaves, 7);
		world.setBlockMetadataWithNotify(i + 14, j + 50, k + 15, 7, 2);
		setBlock(world, i + 14, j + 51, k + 2, Blocks.leaves, 7);
		world.setBlockMetadataWithNotify(i + 14, j + 51, k + 2, 7, 2);
		setBlock(world, i + 14, j + 51, k + 3, Blocks.leaves, 7);
		world.setBlockMetadataWithNotify(i + 14, j + 51, k + 3, 7, 2);
		setBlock(world, i + 14, j + 51, k + 4, Blocks.log, 3);
		world.setBlockMetadataWithNotify(i + 14, j + 51, k + 4, 3, 2);
		setBlock(world, i + 14, j + 51, k + 5, Blocks.leaves, 7);
		world.setBlockMetadataWithNotify(i + 14, j + 51, k + 5, 7, 2);
		setBlock(world, i + 14, j + 51, k + 6, Blocks.leaves, 7);
		world.setBlockMetadataWithNotify(i + 14, j + 51, k + 6, 7, 2);
		setBlock(world, i + 14, j + 51, k + 14, Blocks.leaves, 7);
		world.setBlockMetadataWithNotify(i + 14, j + 51, k + 14, 7, 2);
		setBlock(world, i + 14, j + 52, k + 2, Blocks.leaves, 7);
		world.setBlockMetadataWithNotify(i + 14, j + 52, k + 2, 7, 2);
		setBlock(world, i + 14, j + 52, k + 3, Blocks.leaves, 7);
		world.setBlockMetadataWithNotify(i + 14, j + 52, k + 3, 7, 2);
		setBlock(world, i + 14, j + 52, k + 4, Blocks.leaves, 7);
		world.setBlockMetadataWithNotify(i + 14, j + 52, k + 4, 7, 2);
		setBlock(world, i + 14, j + 52, k + 5, Blocks.leaves, 7);
		world.setBlockMetadataWithNotify(i + 14, j + 52, k + 5, 7, 2);
		setBlock(world, i + 14, j + 52, k + 6, Blocks.leaves, 7);
		world.setBlockMetadataWithNotify(i + 14, j + 52, k + 6, 7, 2);
		setBlock(world, i + 14, j + 53, k + 3, Blocks.leaves, 7);
		world.setBlockMetadataWithNotify(i + 14, j + 53, k + 3, 7, 2);
		setBlock(world, i + 14, j + 53, k + 4, Blocks.leaves, 7);
		world.setBlockMetadataWithNotify(i + 14, j + 53, k + 4, 7, 2);
		setBlock(world, i + 14, j + 53, k + 5, Blocks.leaves, 7);
		world.setBlockMetadataWithNotify(i + 14, j + 53, k + 5, 7, 2);
		setBlock(world, i + 14, j + 54, k + 4, Blocks.leaves, 7);
		world.setBlockMetadataWithNotify(i + 14, j + 54, k + 4, 7, 2);
		setBlock(world, i + 15, j + 2, k + 6, Blocks.leaves, 7);
		world.setBlockMetadataWithNotify(i + 15, j + 2, k + 6, 7, 2);
		setBlock(world, i + 15, j + 2, k + 7, Blocks.leaves, 7);
		world.setBlockMetadataWithNotify(i + 15, j + 2, k + 7, 7, 2);
		setBlock(world, i + 15, j + 2, k + 8, Blocks.leaves, 7);
		world.setBlockMetadataWithNotify(i + 15, j + 2, k + 8, 7, 2);
		setBlock(world, i + 15, j + 2, k + 9, Blocks.leaves, 7);
		world.setBlockMetadataWithNotify(i + 15, j + 2, k + 9, 7, 2);
		setBlock(world, i + 15, j + 2, k + 10, Blocks.leaves, 7);
		world.setBlockMetadataWithNotify(i + 15, j + 2, k + 10, 7, 2);
		setBlock(world, i + 15, j + 3, k + 7, Blocks.leaves, 7);
		world.setBlockMetadataWithNotify(i + 15, j + 3, k + 7, 7, 2);
		setBlock(world, i + 15, j + 3, k + 8, Blocks.leaves, 7);
		world.setBlockMetadataWithNotify(i + 15, j + 3, k + 8, 7, 2);
		setBlock(world, i + 15, j + 3, k + 9, Blocks.leaves, 7);
		world.setBlockMetadataWithNotify(i + 15, j + 3, k + 9, 7, 2);
		setBlock(world, i + 15, j + 4, k + 8, Blocks.leaves, 7);
		world.setBlockMetadataWithNotify(i + 15, j + 4, k + 8, 7, 2);
		setBlock(world, i + 15, j + 16, k + 13, Blocks.leaves, 7);
		world.setBlockMetadataWithNotify(i + 15, j + 16, k + 13, 7, 2);
		setBlock(world, i + 15, j + 16, k + 14, Blocks.leaves, 7);
		world.setBlockMetadataWithNotify(i + 15, j + 16, k + 14, 7, 2);
		setBlock(world, i + 15, j + 16, k + 15, Blocks.leaves, 7);
		world.setBlockMetadataWithNotify(i + 15, j + 16, k + 15, 7, 2);
		setBlock(world, i + 15, j + 17, k + 14, Blocks.leaves, 7);
		world.setBlockMetadataWithNotify(i + 15, j + 17, k + 14, 7, 2);
		setBlock(world, i + 15, j + 19, k + 0, Blocks.log, 3);
		world.setBlockMetadataWithNotify(i + 15, j + 19, k + 0, 3, 2);
		setBlock(world, i + 15, j + 20, k + 14, Blocks.log, 3);
		world.setBlockMetadataWithNotify(i + 15, j + 20, k + 14, 3, 2);
		setBlock(world, i + 15, j + 23, k + 3, Blocks.log, 3);
		world.setBlockMetadataWithNotify(i + 15, j + 23, k + 3, 3, 2);
		setBlock(world, i + 15, j + 24, k + 17, Blocks.log, 3);
		world.setBlockMetadataWithNotify(i + 15, j + 24, k + 17, 3, 2);
		setBlock(world, i + 15, j + 25, k + 4, Blocks.log, 3);
		world.setBlockMetadataWithNotify(i + 15, j + 25, k + 4, 3, 2);
		setBlock(world, i + 15, j + 25, k + 16, Blocks.log, 3);
		world.setBlockMetadataWithNotify(i + 15, j + 25, k + 16, 3, 2);
		setBlock(world, i + 15, j + 25, k + 18, Blocks.leaves, 7);
		world.setBlockMetadataWithNotify(i + 15, j + 25, k + 18, 7, 2);
		setBlock(world, i + 15, j + 25, k + 19, Blocks.leaves, 7);
		world.setBlockMetadataWithNotify(i + 15, j + 25, k + 19, 7, 2);
		setBlock(world, i + 15, j + 25, k + 20, Blocks.leaves, 7);
		world.setBlockMetadataWithNotify(i + 15, j + 25, k + 20, 7, 2);
		setBlock(world, i + 15, j + 26, k + 14, Blocks.log, 3);
		world.setBlockMetadataWithNotify(i + 15, j + 26, k + 14, 3, 2);
		setBlock(world, i + 15, j + 26, k + 15, Blocks.log, 3);
		world.setBlockMetadataWithNotify(i + 15, j + 26, k + 15, 3, 2);
		setBlock(world, i + 15, j + 26, k + 19, Blocks.leaves, 7);
		world.setBlockMetadataWithNotify(i + 15, j + 26, k + 19, 7, 2);
		setBlock(world, i + 15, j + 28, k + 16, Blocks.log, 3);
		world.setBlockMetadataWithNotify(i + 15, j + 28, k + 16, 3, 2);
		setBlock(world, i + 15, j + 30, k + 21, Blocks.log, 3);
		world.setBlockMetadataWithNotify(i + 15, j + 30, k + 21, 3, 2);
		setBlock(world, i + 15, j + 32, k + 2, Blocks.leaves, 7);
		world.setBlockMetadataWithNotify(i + 15, j + 32, k + 2, 7, 2);
		setBlock(world, i + 15, j + 32, k + 3, Blocks.leaves, 7);
		world.setBlockMetadataWithNotify(i + 15, j + 32, k + 3, 7, 2);
		setBlock(world, i + 15, j + 32, k + 4, Blocks.leaves, 7);
		world.setBlockMetadataWithNotify(i + 15, j + 32, k + 4, 7, 2);
		setBlock(world, i + 15, j + 32, k + 5, Blocks.leaves, 7);
		world.setBlockMetadataWithNotify(i + 15, j + 32, k + 5, 7, 2);
		setBlock(world, i + 15, j + 32, k + 6, Blocks.leaves, 7);
		world.setBlockMetadataWithNotify(i + 15, j + 32, k + 6, 7, 2);
		setBlock(world, i + 15, j + 32, k + 16, Blocks.log, 3);
		world.setBlockMetadataWithNotify(i + 15, j + 32, k + 16, 3, 2);
		setBlock(world, i + 15, j + 33, k + 3, Blocks.leaves, 7);
		world.setBlockMetadataWithNotify(i + 15, j + 33, k + 3, 7, 2);
		setBlock(world, i + 15, j + 33, k + 4, Blocks.leaves, 7);
		world.setBlockMetadataWithNotify(i + 15, j + 33, k + 4, 7, 2);
		setBlock(world, i + 15, j + 33, k + 5, Blocks.leaves, 7);
		world.setBlockMetadataWithNotify(i + 15, j + 33, k + 5, 7, 2);
		setBlock(world, i + 15, j + 33, k + 7, Blocks.leaves, 7);
		world.setBlockMetadataWithNotify(i + 15, j + 33, k + 7, 7, 2);
		setBlock(world, i + 15, j + 33, k + 8, Blocks.leaves, 7);
		world.setBlockMetadataWithNotify(i + 15, j + 33, k + 8, 7, 2);
		setBlock(world, i + 15, j + 33, k + 9, Blocks.leaves, 7);
		world.setBlockMetadataWithNotify(i + 15, j + 33, k + 9, 7, 2);
		setBlock(world, i + 15, j + 34, k + 4, Blocks.leaves, 7);
		world.setBlockMetadataWithNotify(i + 15, j + 34, k + 4, 7, 2);
		setBlock(world, i + 15, j + 34, k + 8, Blocks.leaves, 7);
		world.setBlockMetadataWithNotify(i + 15, j + 34, k + 8, 7, 2);
		setBlock(world, i + 15, j + 34, k + 19, Blocks.log, 3);
		world.setBlockMetadataWithNotify(i + 15, j + 34, k + 19, 3, 2);
		setBlock(world, i + 15, j + 35, k + 17, Blocks.leaves, 7);
		world.setBlockMetadataWithNotify(i + 15, j + 35, k + 17, 7, 2);
		setBlock(world, i + 15, j + 35, k + 18, Blocks.leaves, 7);
		world.setBlockMetadataWithNotify(i + 15, j + 35, k + 18, 7, 2);
		setBlock(world, i + 15, j + 35, k + 19, Blocks.leaves, 7);
		world.setBlockMetadataWithNotify(i + 15, j + 35, k + 19, 7, 2);
		setBlock(world, i + 15, j + 35, k + 20, Blocks.leaves, 7);
		world.setBlockMetadataWithNotify(i + 15, j + 35, k + 20, 7, 2);
		setBlock(world, i + 15, j + 35, k + 21, Blocks.leaves, 7);
		world.setBlockMetadataWithNotify(i + 15, j + 35, k + 21, 7, 2);
		setBlock(world, i + 15, j + 36, k + 9, Blocks.log, 3);
		world.setBlockMetadataWithNotify(i + 15, j + 36, k + 9, 3, 2);
		setBlock(world, i + 15, j + 36, k + 18, Blocks.leaves, 7);
		world.setBlockMetadataWithNotify(i + 15, j + 36, k + 18, 7, 2);
		setBlock(world, i + 15, j + 36, k + 19, Blocks.leaves, 7);
		world.setBlockMetadataWithNotify(i + 15, j + 36, k + 19, 7, 2);
		setBlock(world, i + 15, j + 36, k + 20, Blocks.leaves, 7);
		world.setBlockMetadataWithNotify(i + 15, j + 36, k + 20, 7, 2);
		setBlock(world, i + 15, j + 37, k + 8, Blocks.leaves, 7);
		world.setBlockMetadataWithNotify(i + 15, j + 37, k + 8, 7, 2);
		setBlock(world, i + 15, j + 37, k + 9, Blocks.leaves, 7);
		world.setBlockMetadataWithNotify(i + 15, j + 37, k + 9, 7, 2);
		setBlock(world, i + 15, j + 37, k + 10, Blocks.leaves, 7);
		world.setBlockMetadataWithNotify(i + 15, j + 37, k + 10, 7, 2);
		setBlock(world, i + 15, j + 37, k + 19, Blocks.leaves, 7);
		world.setBlockMetadataWithNotify(i + 15, j + 37, k + 19, 7, 2);
		setBlock(world, i + 15, j + 38, k + 2, Blocks.log, 3);
		world.setBlockMetadataWithNotify(i + 15, j + 38, k + 2, 3, 2);
		setBlock(world, i + 15, j + 38, k + 9, Blocks.leaves, 7);
		world.setBlockMetadataWithNotify(i + 15, j + 38, k + 9, 7, 2);
		setBlock(world, i + 15, j + 40, k + 2, Blocks.leaves, 7);
		world.setBlockMetadataWithNotify(i + 15, j + 40, k + 2, 7, 2);
		setBlock(world, i + 15, j + 40, k + 3, Blocks.leaves, 7);
		world.setBlockMetadataWithNotify(i + 15, j + 40, k + 3, 7, 2);
		setBlock(world, i + 15, j + 40, k + 4, Blocks.log, 3);
		world.setBlockMetadataWithNotify(i + 15, j + 40, k + 4, 3, 2);
		setBlock(world, i + 15, j + 40, k + 5, Blocks.leaves, 7);
		world.setBlockMetadataWithNotify(i + 15, j + 40, k + 5, 7, 2);
		setBlock(world, i + 15, j + 40, k + 6, Blocks.leaves, 7);
		world.setBlockMetadataWithNotify(i + 15, j + 40, k + 6, 7, 2);
		setBlock(world, i + 15, j + 41, k + 2, Blocks.leaves, 7);
		world.setBlockMetadataWithNotify(i + 15, j + 41, k + 2, 7, 2);
		setBlock(world, i + 15, j + 41, k + 3, Blocks.leaves, 7);
		world.setBlockMetadataWithNotify(i + 15, j + 41, k + 3, 7, 2);
		setBlock(world, i + 15, j + 41, k + 4, Blocks.leaves, 7);
		world.setBlockMetadataWithNotify(i + 15, j + 41, k + 4, 7, 2);
		setBlock(world, i + 15, j + 41, k + 5, Blocks.leaves, 7);
		world.setBlockMetadataWithNotify(i + 15, j + 41, k + 5, 7, 2);
		setBlock(world, i + 15, j + 41, k + 6, Blocks.leaves, 7);
		world.setBlockMetadataWithNotify(i + 15, j + 41, k + 6, 7, 2);
		setBlock(world, i + 15, j + 41, k + 10, Blocks.log, 3);
		world.setBlockMetadataWithNotify(i + 15, j + 41, k + 10, 3, 2);
		setBlock(world, i + 15, j + 42, k + 3, Blocks.leaves, 7);
		world.setBlockMetadataWithNotify(i + 15, j + 42, k + 3, 7, 2);
		setBlock(world, i + 15, j + 42, k + 4, Blocks.leaves, 7);
		world.setBlockMetadataWithNotify(i + 15, j + 42, k + 4, 7, 2);
		setBlock(world, i + 15, j + 42, k + 5, Blocks.leaves, 7);
		world.setBlockMetadataWithNotify(i + 15, j + 42, k + 5, 7, 2);
		setBlock(world, i + 15, j + 42, k + 8, Blocks.leaves, 7);
		world.setBlockMetadataWithNotify(i + 15, j + 42, k + 8, 7, 2);
		setBlock(world, i + 15, j + 42, k + 9, Blocks.leaves, 7);
		world.setBlockMetadataWithNotify(i + 15, j + 42, k + 9, 7, 2);
		setBlock(world, i + 15, j + 42, k + 10, Blocks.leaves, 7);
		world.setBlockMetadataWithNotify(i + 15, j + 42, k + 10, 7, 2);
		setBlock(world, i + 15, j + 42, k + 11, Blocks.leaves, 7);
		world.setBlockMetadataWithNotify(i + 15, j + 42, k + 11, 7, 2);
		setBlock(world, i + 15, j + 42, k + 12, Blocks.leaves, 7);
		world.setBlockMetadataWithNotify(i + 15, j + 42, k + 12, 7, 2);
		setBlock(world, i + 15, j + 43, k + 4, Blocks.leaves, 7);
		world.setBlockMetadataWithNotify(i + 15, j + 43, k + 4, 7, 2);
		setBlock(world, i + 15, j + 43, k + 9, Blocks.leaves, 7);
		world.setBlockMetadataWithNotify(i + 15, j + 43, k + 9, 7, 2);
		setBlock(world, i + 15, j + 43, k + 10, Blocks.leaves, 7);
		world.setBlockMetadataWithNotify(i + 15, j + 43, k + 10, 7, 2);
		setBlock(world, i + 15, j + 43, k + 11, Blocks.leaves, 7);
		world.setBlockMetadataWithNotify(i + 15, j + 43, k + 11, 7, 2);
		setBlock(world, i + 15, j + 44, k + 1, Blocks.leaves, 7);
		world.setBlockMetadataWithNotify(i + 15, j + 44, k + 1, 7, 2);
		setBlock(world, i + 15, j + 44, k + 2, Blocks.leaves, 7);
		world.setBlockMetadataWithNotify(i + 15, j + 44, k + 2, 7, 2);
		setBlock(world, i + 15, j + 44, k + 3, Blocks.log, 3);
		world.setBlockMetadataWithNotify(i + 15, j + 44, k + 3, 3, 2);
		setBlock(world, i + 15, j + 44, k + 4, Blocks.leaves, 7);
		world.setBlockMetadataWithNotify(i + 15, j + 44, k + 4, 7, 2);
		setBlock(world, i + 15, j + 44, k + 5, Blocks.leaves, 7);
		world.setBlockMetadataWithNotify(i + 15, j + 44, k + 5, 7, 2);
		setBlock(world, i + 15, j + 44, k + 6, Blocks.leaves, 7);
		world.setBlockMetadataWithNotify(i + 15, j + 44, k + 6, 7, 2);
		setBlock(world, i + 15, j + 44, k + 7, Blocks.leaves, 7);
		world.setBlockMetadataWithNotify(i + 15, j + 44, k + 7, 7, 2);
		setBlock(world, i + 15, j + 44, k + 8, Blocks.leaves, 7);
		world.setBlockMetadataWithNotify(i + 15, j + 44, k + 8, 7, 2);
		setBlock(world, i + 15, j + 44, k + 9, Blocks.leaves, 7);
		world.setBlockMetadataWithNotify(i + 15, j + 44, k + 9, 7, 2);
		setBlock(world, i + 15, j + 44, k + 10, Blocks.leaves, 7);
		world.setBlockMetadataWithNotify(i + 15, j + 44, k + 10, 7, 2);
		setBlock(world, i + 15, j + 44, k + 11, Blocks.leaves, 7);
		world.setBlockMetadataWithNotify(i + 15, j + 44, k + 11, 7, 2);
		setBlock(world, i + 15, j + 45, k + 1, Blocks.leaves, 7);
		world.setBlockMetadataWithNotify(i + 15, j + 45, k + 1, 7, 2);
		setBlock(world, i + 15, j + 45, k + 2, Blocks.leaves, 7);
		world.setBlockMetadataWithNotify(i + 15, j + 45, k + 2, 7, 2);
		setBlock(world, i + 15, j + 45, k + 3, Blocks.log, 3);
		world.setBlockMetadataWithNotify(i + 15, j + 45, k + 3, 3, 2);
		setBlock(world, i + 15, j + 45, k + 4, Blocks.leaves, 7);
		world.setBlockMetadataWithNotify(i + 15, j + 45, k + 4, 7, 2);
		setBlock(world, i + 15, j + 45, k + 5, Blocks.leaves, 7);
		world.setBlockMetadataWithNotify(i + 15, j + 45, k + 5, 7, 2);
		setBlock(world, i + 15, j + 45, k + 6, Blocks.leaves, 7);
		world.setBlockMetadataWithNotify(i + 15, j + 45, k + 6, 7, 2);
		setBlock(world, i + 15, j + 45, k + 7, Blocks.leaves, 7);
		world.setBlockMetadataWithNotify(i + 15, j + 45, k + 7, 7, 2);
		setBlock(world, i + 15, j + 45, k + 10, Blocks.leaves, 7);
		world.setBlockMetadataWithNotify(i + 15, j + 45, k + 10, 7, 2);
		setBlock(world, i + 15, j + 46, k + 0, Blocks.leaves, 7);
		world.setBlockMetadataWithNotify(i + 15, j + 46, k + 0, 7, 2);
		setBlock(world, i + 15, j + 46, k + 1, Blocks.leaves, 7);
		world.setBlockMetadataWithNotify(i + 15, j + 46, k + 1, 7, 2);
		setBlock(world, i + 15, j + 46, k + 2, Blocks.leaves, 7);
		world.setBlockMetadataWithNotify(i + 15, j + 46, k + 2, 7, 2);
		setBlock(world, i + 15, j + 46, k + 3, Blocks.leaves, 7);
		world.setBlockMetadataWithNotify(i + 15, j + 46, k + 3, 7, 2);
		setBlock(world, i + 15, j + 46, k + 4, Blocks.leaves, 7);
		world.setBlockMetadataWithNotify(i + 15, j + 46, k + 4, 7, 2);
		setBlock(world, i + 15, j + 46, k + 6, Blocks.leaves, 7);
		world.setBlockMetadataWithNotify(i + 15, j + 46, k + 6, 7, 2);
		setBlock(world, i + 15, j + 47, k + 1, Blocks.leaves, 7);
		world.setBlockMetadataWithNotify(i + 15, j + 47, k + 1, 7, 2);
		setBlock(world, i + 15, j + 47, k + 3, Blocks.leaves, 7);
		world.setBlockMetadataWithNotify(i + 15, j + 47, k + 3, 7, 2);
		setBlock(world, i + 15, j + 47, k + 17, Blocks.leaves, 7);
		world.setBlockMetadataWithNotify(i + 15, j + 47, k + 17, 7, 2);
		setBlock(world, i + 15, j + 47, k + 18, Blocks.leaves, 7);
		world.setBlockMetadataWithNotify(i + 15, j + 47, k + 18, 7, 2);
		setBlock(world, i + 15, j + 47, k + 19, Blocks.leaves, 7);
		world.setBlockMetadataWithNotify(i + 15, j + 47, k + 19, 7, 2);
		setBlock(world, i + 15, j + 48, k + 18, Blocks.leaves, 7);
		world.setBlockMetadataWithNotify(i + 15, j + 48, k + 18, 7, 2);
		
		generate2(world, rand, i, j, k);
		return true;
		}

	
	public boolean generate2(World world, Random rand, int i, int j, int k)
	{
		setBlock(world, i + 15, j + 50, k + 5, Blocks.log, 3);
		world.setBlockMetadataWithNotify(i + 15, j + 50, k + 5, 3, 2);
		setBlock(world, i + 15, j + 50, k + 12, Blocks.leaves, 7);
		world.setBlockMetadataWithNotify(i + 15, j + 50, k + 12, 7, 2);
		setBlock(world, i + 15, j + 50, k + 13, Blocks.leaves, 7);
		world.setBlockMetadataWithNotify(i + 15, j + 50, k + 13, 7, 2);
		setBlock(world, i + 15, j + 50, k + 14, Blocks.leaves, 7);
		world.setBlockMetadataWithNotify(i + 15, j + 50, k + 14, 7, 2);
		setBlock(world, i + 15, j + 50, k + 15, Blocks.leaves, 7);
		world.setBlockMetadataWithNotify(i + 15, j + 50, k + 15, 7, 2);
		setBlock(world, i + 15, j + 50, k + 16, Blocks.leaves, 7);
		world.setBlockMetadataWithNotify(i + 15, j + 50, k + 16, 7, 2);
		setBlock(world, i + 15, j + 51, k + 2, Blocks.leaves, 7);
		world.setBlockMetadataWithNotify(i + 15, j + 51, k + 2, 7, 2);
		setBlock(world, i + 15, j + 51, k + 3, Blocks.leaves, 7);
		world.setBlockMetadataWithNotify(i + 15, j + 51, k + 3, 7, 2);
		setBlock(world, i + 15, j + 51, k + 4, Blocks.leaves, 7);
		world.setBlockMetadataWithNotify(i + 15, j + 51, k + 4, 7, 2);
		setBlock(world, i + 15, j + 51, k + 5, Blocks.leaves, 7);
		world.setBlockMetadataWithNotify(i + 15, j + 51, k + 5, 7, 2);
		setBlock(world, i + 15, j + 51, k + 6, Blocks.leaves, 7);
		world.setBlockMetadataWithNotify(i + 15, j + 51, k + 6, 7, 2);
		setBlock(world, i + 15, j + 51, k + 11, Blocks.leaves, 7);
		world.setBlockMetadataWithNotify(i + 15, j + 51, k + 11, 7, 2);
		setBlock(world, i + 15, j + 51, k + 12, Blocks.leaves, 7);
		world.setBlockMetadataWithNotify(i + 15, j + 51, k + 12, 7, 2);
		setBlock(world, i + 15, j + 51, k + 13, Blocks.leaves, 7);
		world.setBlockMetadataWithNotify(i + 15, j + 51, k + 13, 7, 2);
		setBlock(world, i + 15, j + 51, k + 14, Blocks.leaves, 7);
		world.setBlockMetadataWithNotify(i + 15, j + 51, k + 14, 7, 2);
		setBlock(world, i + 15, j + 51, k + 15, Blocks.leaves, 7);
		world.setBlockMetadataWithNotify(i + 15, j + 51, k + 15, 7, 2);
		setBlock(world, i + 15, j + 52, k + 3, Blocks.leaves, 7);
		world.setBlockMetadataWithNotify(i + 15, j + 52, k + 3, 7, 2);
		setBlock(world, i + 15, j + 52, k + 4, Blocks.leaves, 7);
		world.setBlockMetadataWithNotify(i + 15, j + 52, k + 4, 7, 2);
		setBlock(world, i + 15, j + 52, k + 5, Blocks.leaves, 7);
		world.setBlockMetadataWithNotify(i + 15, j + 52, k + 5, 7, 2);
		setBlock(world, i + 15, j + 52, k + 6, Blocks.leaves, 7);
		world.setBlockMetadataWithNotify(i + 15, j + 52, k + 6, 7, 2);
		setBlock(world, i + 15, j + 52, k + 7, Blocks.leaves, 7);
		world.setBlockMetadataWithNotify(i + 15, j + 52, k + 7, 7, 2);
		setBlock(world, i + 15, j + 52, k + 12, Blocks.leaves, 7);
		world.setBlockMetadataWithNotify(i + 15, j + 52, k + 12, 7, 2);
		setBlock(world, i + 15, j + 52, k + 14, Blocks.leaves, 7);
		world.setBlockMetadataWithNotify(i + 15, j + 52, k + 14, 7, 2);
		setBlock(world, i + 15, j + 53, k + 4, Blocks.leaves, 7);
		world.setBlockMetadataWithNotify(i + 15, j + 53, k + 4, 7, 2);
		setBlock(world, i + 15, j + 53, k + 5, Blocks.leaves, 7);
		world.setBlockMetadataWithNotify(i + 15, j + 53, k + 5, 7, 2);
		setBlock(world, i + 15, j + 53, k + 6, Blocks.leaves, 7);
		world.setBlockMetadataWithNotify(i + 15, j + 53, k + 6, 7, 2);
		setBlock(world, i + 15, j + 54, k + 5, Blocks.leaves, 7);
		world.setBlockMetadataWithNotify(i + 15, j + 54, k + 5, 7, 2);
		setBlock(world, i + 15, j + 59, k + 9, Blocks.leaves, 7);
		world.setBlockMetadataWithNotify(i + 15, j + 59, k + 9, 7, 2);
		setBlock(world, i + 15, j + 59, k + 10, Blocks.leaves, 7);
		world.setBlockMetadataWithNotify(i + 15, j + 59, k + 10, 7, 2);
		setBlock(world, i + 15, j + 59, k + 11, Blocks.leaves, 7);
		world.setBlockMetadataWithNotify(i + 15, j + 59, k + 11, 7, 2);
		setBlock(world, i + 15, j + 60, k + 10, Blocks.leaves, 7);
		world.setBlockMetadataWithNotify(i + 15, j + 60, k + 10, 7, 2);
		setBlock(world, i + 16, j + 2, k + 6, Blocks.leaves, 7);
		world.setBlockMetadataWithNotify(i + 16, j + 2, k + 6, 7, 2);
		setBlock(world, i + 16, j + 2, k + 7, Blocks.leaves, 7);
		world.setBlockMetadataWithNotify(i + 16, j + 2, k + 7, 7, 2);
		setBlock(world, i + 16, j + 2, k + 8, Blocks.log, 3);
