/*      */package com.parzivail.pswm.world.gen.wookietree;

/*      */
/*      *//*      */
/*      */
import com.parzivail.pswm.utils.LootGenUtils;
import com.parzivail.pswm.utils.NPCType;
import com.parzivail.pswm.utils.SpawnUtils;


/*      */
import cpw.mods.fml.common.IWorldGenerator;


/*      */
import java.util.Random;


/*      */
import net.minecraft.block.Block;
/*      */
import net.minecraft.init.Blocks;
/*      */
import net.minecraft.tileentity.TileEntityChest;
/*      */
import net.minecraft.world.World;
/*      */
import net.minecraft.world.WorldProvider;
/*      */
import net.minecraft.world.chunk.IChunkProvider;
/*      */
import net.minecraft.world.gen.feature.WorldGenerator;

/*      */
/*      */public class WT_42
/*      */extends WorldGenerator implements IWorldGenerator
/*      */
{
	/*      */protected Block[] getValidSpawnBlocks()
	/*      */
	{
		return new Block[0];
		/*      */}

	/*      */
	/*      */public boolean locationIsValidSpawn(World world, int i, int j, int k)
	/*      */
	{
		int distanceToAir = 0;
		Block check = world.getBlock(i, j, k);
		/*      */
		while (check != Blocks.air)
		{
			if (distanceToAir > 3) { return false;
			/*      */}
			/*      */
			distanceToAir++;
			check = world.getBlock(i, j + distanceToAir, k);
			/*      */}
		/*      */
		j += distanceToAir - 1;
		/*      */
		Block block = world.getBlock(i, j, k);
		Block blockAbove = world.getBlock(i, j + 1, k);
		Block blockBelow = world.getBlock(i, j - 1, k);
		/*      */
		for (Block x : getValidSpawnBlocks())
		{
			if (blockAbove != Blocks.air) { return false;
			/*      */}
			if (block == x) return true;
			if ((block == Blocks.snow) && (blockBelow == x)) { return true;
			/*      */}
			/*      */}
		/*      */
		return false;
		/*      */}

	/*      */
	/*      */
	/*      */
	/*      */public void generate(Random random, int chunkX, int chunkZ, World world, IChunkProvider chunkGenerator, IChunkProvider chunkProvider)
	{
	}

	/*      */
	/*      */
	/*      */public void setBlock(World world, int x, int y, int z, Block block, int metadata)
	/*      */
	{
		world.setBlock(x, y, z, block, metadata, 2);
		/*      */}

	/*      */
	/*      */public boolean generate(World world, Random rand, int i, int j, int k)
	/*      */
	{
		k -= 10;
		i -= 10;
		/*      */
		setBlock(world, i + 0, j + 21, k + 20, Blocks.crafting_table, 0);
		setBlock(world, i + 0, j + 21, k + 21, Blocks.spruce_stairs, 0);
		setBlock(world, i + 1, j + 50, k + 17, Blocks.fence, 0);
		setBlock(world, i + 1, j + 50, k + 26, Blocks.fence, 0);
		setBlock(world, i + 2, j + 50, k + 16, Blocks.fence, 0);
		setBlock(world, i + 2, j + 50, k + 17, Blocks.fence, 0);
		setBlock(world, i + 2, j + 50, k + 26, Blocks.fence, 0);
		setBlock(world, i + 2, j + 50, k + 27, Blocks.fence, 0);
		SpawnUtils.spawnNPC(NPCType.WOOKIETREE, world, i + 3, j + 21, k + 19);
		SpawnUtils.spawnNPC(NPCType.WOOKIETREE, world, i + 3, j + 21, k + 23);
		setBlock(world, i + 3, j + 50, k + 15, Blocks.fence, 0);
		setBlock(world, i + 3, j + 50, k + 16, Blocks.fence, 0);
		setBlock(world, i + 3, j + 50, k + 27, Blocks.fence, 0);
		setBlock(world, i + 3, j + 50, k + 28, Blocks.fence, 0);
		setBlock(world, i + 4, j + 21, k + 16, Blocks.fence, 0);
		setBlock(world, i + 4, j + 21, k + 26, Blocks.fence, 0);
		setBlock(world, i + 4, j + 23, k + 13, Blocks.fence, 0);
		setBlock(world, i + 4, j + 23, k + 14, Blocks.fence, 0);
		setBlock(world, i + 4, j + 23, k + 28, Blocks.fence, 0);
		setBlock(world, i + 4, j + 23, k + 29, Blocks.fence, 0);
		setBlock(world, i + 4, j + 47, k + 17, Blocks.fence, 0);
		setBlock(world, i + 4, j + 47, k + 26, Blocks.fence, 0);
		setBlock(world, i + 4, j + 50, k + 15, Blocks.fence, 0);
		setBlock(world, i + 4, j + 50, k + 28, Blocks.fence, 0);
		setBlock(world, i + 5, j + 21, k + 16, Blocks.fence, 0);
		setBlock(world, i + 5, j + 21, k + 17, Blocks.fence, 0);
		setBlock(world, i + 5, j + 21, k + 25, Blocks.fence, 0);
		setBlock(world, i + 5, j + 21, k + 26, Blocks.fence, 0);
		setBlock(world, i + 5, j + 47, k + 17, Blocks.fence, 0);
		setBlock(world, i + 5, j + 47, k + 26, Blocks.fence, 0);
		setBlock(world, i + 5, j + 50, k + 14, Blocks.fence, 0);
		setBlock(world, i + 5, j + 50, k + 15, Blocks.fence, 0);
		setBlock(world, i + 5, j + 50, k + 28, Blocks.fence, 0);
		setBlock(world, i + 5, j + 50, k + 29, Blocks.fence, 0);
		setBlock(world, i + 6, j + 21, k + 17, Blocks.fence, 0);
		setBlock(world, i + 6, j + 21, k + 18, Blocks.fence, 0);
		setBlock(world, i + 6, j + 21, k + 19, Blocks.spruce_stairs, 0);
		setBlock(world, i + 6, j + 21, k + 23, Blocks.spruce_stairs, 0);
		setBlock(world, i + 6, j + 21, k + 24, Blocks.fence, 0);
		setBlock(world, i + 6, j + 21, k + 25, Blocks.fence, 0);
		setBlock(world, i + 6, j + 47, k + 16, Blocks.fence, 0);
		setBlock(world, i + 6, j + 47, k + 17, Blocks.fence, 0);
		setBlock(world, i + 6, j + 47, k + 26, Blocks.fence, 0);
		setBlock(world, i + 6, j + 47, k + 27, Blocks.fence, 0);
		setBlock(world, i + 6, j + 50, k + 14, Blocks.fence, 0);
		setBlock(world, i + 6, j + 50, k + 29, Blocks.fence, 0);
		setBlock(world, i + 7, j + 47, k + 16, Blocks.fence, 0);
		setBlock(world, i + 7, j + 47, k + 27, Blocks.fence, 0);
		setBlock(world, i + 7, j + 50, k + 14, Blocks.fence, 0);
		setBlock(world, i + 7, j + 50, k + 29, Blocks.fence, 0);
		setBlock(world, i + 8, j + 23, k + 18, Blocks.fence, 0);
		setBlock(world, i + 8, j + 23, k + 24, Blocks.fence, 0);
		setBlock(world, i + 8, j + 47, k + 15, Blocks.spruce_stairs, 0);
		setBlock(world, i + 8, j + 47, k + 16, Blocks.fence, 0);
		setBlock(world, i + 8, j + 47, k + 27, Blocks.fence, 0);
		setBlock(world, i + 8, j + 50, k + 13, Blocks.fence, 0);
		setBlock(world, i + 8, j + 50, k + 14, Blocks.fence, 0);
		setBlock(world, i + 8, j + 50, k + 29, Blocks.fence, 0);
		setBlock(world, i + 8, j + 50, k + 30, Blocks.fence, 0);
		setBlock(world, i + 9, j + 23, k + 18, Blocks.fence, 0);
		setBlock(world, i + 9, j + 23, k + 24, Blocks.fence, 0);
		SpawnUtils.spawnNPC(NPCType.WOOKIETREE, world, i + 9, j + 47, k + 19);
		SpawnUtils.spawnNPC(NPCType.WOOKIETREE, world, i + 9, j + 47, k + 24);
		setBlock(world, i + 11, j + 47, k + 21, Blocks.spruce_stairs, 0);
		setBlock(world, i + 11, j + 47, k + 22, Blocks.spruce_stairs, 0);
		setBlock(world, i + 14, j + 47, k + 20, Blocks.crafting_table, 0);
		setBlock(world, i + 15, j + 21, k + 15, Blocks.spruce_stairs, 0);
		setBlock(world, i + 15, j + 21, k + 16, Blocks.spruce_stairs, 0);
		setBlock(world, i + 15, j + 21, k + 17, Blocks.spruce_stairs, 0);
		setBlock(world, i + 15, j + 21, k + 18, Blocks.spruce_stairs, 0);
		setBlock(world, i + 15, j + 21, k + 19, Blocks.spruce_stairs, 0);
		setBlock(world, i + 15, j + 47, k + 15, Blocks.spruce_stairs, 0);
		setBlock(world, i + 15, j + 47, k + 28, Blocks.spruce_stairs, 0);
		setBlock(world, i + 16, j + 22, k + 15, Blocks.spruce_stairs, 0);
		setBlock(world, i + 16, j + 22, k + 16, Blocks.spruce_stairs, 0);
		setBlock(world, i + 16, j + 22, k + 17, Blocks.spruce_stairs, 0);
		setBlock(world, i + 16, j + 22, k + 18, Blocks.spruce_stairs, 0);
		setBlock(world, i + 16, j + 22, k + 19, Blocks.spruce_stairs, 0);
		SpawnUtils.spawnNPC(NPCType.WOOKIETREE, world, i + 16, j + 47, k + 19);
		SpawnUtils.spawnNPC(NPCType.WOOKIETREE, world, i + 16, j + 47, k + 24);
		setBlock(world, i + 17, j + 23, k + 15, Blocks.spruce_stairs, 0);
		setBlock(world, i + 17, j + 23, k + 16, Blocks.spruce_stairs, 0);
		setBlock(world, i + 17, j + 23, k + 17, Blocks.spruce_stairs, 0);
		setBlock(world, i + 17, j + 23, k + 18, Blocks.spruce_stairs, 0);
		setBlock(world, i + 17, j + 23, k + 19, Blocks.spruce_stairs, 0);
		setBlock(world, i + 17, j + 47, k + 16, Blocks.fence, 0);
		setBlock(world, i + 17, j + 47, k + 27, Blocks.fence, 0);
		setBlock(world, i + 17, j + 50, k + 13, Blocks.fence, 0);
		setBlock(world, i + 17, j + 50, k + 14, Blocks.fence, 0);
		setBlock(world, i + 17, j + 50, k + 29, Blocks.fence, 0);
		setBlock(world, i + 17, j + 50, k + 30, Blocks.fence, 0);
		setBlock(world, i + 18, j + 24, k + 15, Blocks.spruce_stairs, 0);
		setBlock(world, i + 18, j + 24, k + 16, Blocks.spruce_stairs, 0);
		setBlock(world, i + 18, j + 24, k + 17, Blocks.spruce_stairs, 0);
		setBlock(world, i + 18, j + 24, k + 18, Blocks.spruce_stairs, 0);
		setBlock(world, i + 18, j + 24, k + 19, Blocks.spruce_stairs, 0);
		setBlock(world, i + 18, j + 47, k + 16, Blocks.fence, 0);
		setBlock(world, i + 18, j + 47, k + 27, Blocks.fence, 0);
		setBlock(world, i + 18, j + 50, k + 14, Blocks.fence, 0);
		setBlock(world, i + 18, j + 50, k + 29, Blocks.fence, 0);
		setBlock(world, i + 19, j + 25, k + 15, Blocks.spruce_stairs, 0);
		setBlock(world, i + 19, j + 25, k + 16, Blocks.spruce_stairs, 0);
		setBlock(world, i + 19, j + 25, k + 17, Blocks.spruce_stairs, 0);
		setBlock(world, i + 19, j + 25, k + 18, Blocks.spruce_stairs, 0);
		setBlock(world, i + 19, j + 25, k + 19, Blocks.spruce_stairs, 0);
		setBlock(world, i + 19, j + 47, k + 16, Blocks.fence, 0);
		setBlock(world, i + 19, j + 47, k + 17, Blocks.fence, 0);
		setBlock(world, i + 19, j + 47, k + 26, Blocks.fence, 0);
		setBlock(world, i + 19, j + 47, k + 27, Blocks.fence, 0);
		setBlock(world, i + 19, j + 50, k + 14, Blocks.fence, 0);
		setBlock(world, i + 19, j + 50, k + 29, Blocks.fence, 0);
		setBlock(world, i + 20, j + 26, k + 15, Blocks.spruce_stairs, 0);
		setBlock(world, i + 20, j + 26, k + 16, Blocks.spruce_stairs, 0);
		setBlock(world, i + 20, j + 26, k + 17, Blocks.spruce_stairs, 0);
		setBlock(world, i + 20, j + 26, k + 18, Blocks.spruce_stairs, 0);
		setBlock(world, i + 20, j + 26, k + 19, Blocks.spruce_stairs, 0);
		setBlock(world, i + 20, j + 47, k + 17, Blocks.fence, 0);
		setBlock(world, i + 20, j + 47, k + 26, Blocks.fence, 0);
		setBlock(world, i + 20, j + 50, k + 14, Blocks.fence, 0);
		setBlock(world, i + 20, j + 50, k + 15, Blocks.fence, 0);
		setBlock(world, i + 20, j + 50, k + 28, Blocks.fence, 0);
		setBlock(world, i + 20, j + 50, k + 29, Blocks.fence, 0);
		setBlock(world, i + 21, j + 47, k + 17, Blocks.fence, 0);
		setBlock(world, i + 21, j + 47, k + 18, Blocks.spruce_stairs, 0);
		setBlock(world, i + 21, j + 47, k + 25, Blocks.spruce_stairs, 0);
		setBlock(world, i + 21, j + 47, k + 26, Blocks.fence, 0);
		setBlock(world, i + 21, j + 50, k + 15, Blocks.fence, 0);
		setBlock(world, i + 21, j + 50, k + 28, Blocks.fence, 0);
		setBlock(world, i + 22, j + 50, k + 15, Blocks.fence, 0);
		setBlock(world, i + 22, j + 50, k + 16, Blocks.fence, 0);
		setBlock(world, i + 22, j + 50, k + 27, Blocks.fence, 0);
		setBlock(world, i + 22, j + 50, k + 28, Blocks.fence, 0);
		setBlock(world, i + 23, j + 50, k + 16, Blocks.fence, 0);
		setBlock(world, i + 23, j + 50, k + 17, Blocks.fence, 0);
		setBlock(world, i + 23, j + 50, k + 26, Blocks.fence, 0);
		setBlock(world, i + 23, j + 50, k + 27, Blocks.fence, 0);
		setBlock(world, i + 24, j + 50, k + 17, Blocks.fence, 0);
		setBlock(world, i + 24, j + 50, k + 26, Blocks.fence, 0);
		setBlock(world, i + 0, j + 11, k + 20, Blocks.log, 1);
		world.setBlockMetadataWithNotify(i + 0, j + 11, k + 20, 1, 2);
		setBlock(world, i + 0, j + 11, k + 21, Blocks.log, 1);
		world.setBlockMetadataWithNotify(i + 0, j + 11, k + 21, 1, 2);
		setBlock(world, i + 0, j + 11, k + 22, Blocks.log, 1);
		world.setBlockMetadataWithNotify(i + 0, j + 11, k + 22, 1, 2);
		setBlock(world, i + 0, j + 12, k + 20, Blocks.log, 1);
		world.setBlockMetadataWithNotify(i + 0, j + 12, k + 20, 1, 2);
		setBlock(world, i + 0, j + 12, k + 21, Blocks.log, 1);
		world.setBlockMetadataWithNotify(i + 0, j + 12, k + 21, 1, 2);
		setBlock(world, i + 0, j + 12, k + 22, Blocks.log, 1);
		world.setBlockMetadataWithNotify(i + 0, j + 12, k + 22, 1, 2);
		setBlock(world, i + 0, j + 13, k + 17, Blocks.vine, 10);
		world.setBlockMetadataWithNotify(i + 0, j + 13, k + 17, 10, 2);
		setBlock(world, i + 0, j + 13, k + 18, Blocks.vine, 14);
		world.setBlockMetadataWithNotify(i + 0, j + 13, k + 18, 14, 2);
		setBlock(world, i + 0, j + 13, k + 19, Blocks.vine, 5);
		world.setBlockMetadataWithNotify(i + 0, j + 13, k + 19, 5, 2);
		setBlock(world, i + 0, j + 13, k + 20, Blocks.log, 1);
		world.setBlockMetadataWithNotify(i + 0, j + 13, k + 20, 1, 2);
		setBlock(world, i + 0, j + 13, k + 21, Blocks.log, 1);
		world.setBlockMetadataWithNotify(i + 0, j + 13, k + 21, 1, 2);
		setBlock(world, i + 0, j + 13, k + 22, Blocks.log, 1);
		world.setBlockMetadataWithNotify(i + 0, j + 13, k + 22, 1, 2);
		setBlock(world, i + 0, j + 14, k + 17, Blocks.vine, 15);
		world.setBlockMetadataWithNotify(i + 0, j + 14, k + 17, 15, 2);
		setBlock(world, i + 0, j + 14, k + 18, Blocks.vine, 15);
		world.setBlockMetadataWithNotify(i + 0, j + 14, k + 18, 15, 2);
		setBlock(world, i + 0, j + 14, k + 19, Blocks.vine, 15);
		world.setBlockMetadataWithNotify(i + 0, j + 14, k + 19, 15, 2);
		setBlock(world, i + 0, j + 14, k + 20, Blocks.log, 1);
		world.setBlockMetadataWithNotify(i + 0, j + 14, k + 20, 1, 2);
		setBlock(world, i + 0, j + 14, k + 21, Blocks.log, 1);
		world.setBlockMetadataWithNotify(i + 0, j + 14, k + 21, 1, 2);
		setBlock(world, i + 0, j + 14, k + 22, Blocks.log, 1);
		world.setBlockMetadataWithNotify(i + 0, j + 14, k + 22, 1, 2);
		setBlock(world, i + 0, j + 14, k + 23, Blocks.log, 1);
		world.setBlockMetadataWithNotify(i + 0, j + 14, k + 23, 1, 2);
		setBlock(world, i + 0, j + 14, k + 24, Blocks.log, 1);
		world.setBlockMetadataWithNotify(i + 0, j + 14, k + 24, 1, 2);
		setBlock(world, i + 0, j + 14, k + 25, Blocks.log, 1);
		world.setBlockMetadataWithNotify(i + 0, j + 14, k + 25, 1, 2);
		setBlock(world, i + 0, j + 14, k + 26, Blocks.log, 1);
		world.setBlockMetadataWithNotify(i + 0, j + 14, k + 26, 1, 2);
		setBlock(world, i + 0, j + 15, k + 17, Blocks.vine, 15);
		world.setBlockMetadataWithNotify(i + 0, j + 15, k + 17, 15, 2);
		setBlock(world, i + 0, j + 15, k + 18, Blocks.vine, 15);
		world.setBlockMetadataWithNotify(i + 0, j + 15, k + 18, 15, 2);
		setBlock(world, i + 0, j + 15, k + 19, Blocks.log, 1);
		world.setBlockMetadataWithNotify(i + 0, j + 15, k + 19, 1, 2);
		setBlock(world, i + 0, j + 15, k + 20, Blocks.vine, 15);
		world.setBlockMetadataWithNotify(i + 0, j + 15, k + 20, 15, 2);
		setBlock(world, i + 0, j + 15, k + 21, Blocks.log, 1);
		world.setBlockMetadataWithNotify(i + 0, j + 15, k + 21, 1, 2);
		setBlock(world, i + 0, j + 15, k + 22, Blocks.log, 1);
		world.setBlockMetadataWithNotify(i + 0, j + 15, k + 22, 1, 2);
		setBlock(world, i + 0, j + 15, k + 23, Blocks.log, 1);
		world.setBlockMetadataWithNotify(i + 0, j + 15, k + 23, 1, 2);
		setBlock(world, i + 0, j + 15, k + 24, Blocks.log, 1);
		world.setBlockMetadataWithNotify(i + 0, j + 15, k + 24, 1, 2);
		setBlock(world, i + 0, j + 15, k + 25, Blocks.log, 1);
		world.setBlockMetadataWithNotify(i + 0, j + 15, k + 25, 1, 2);
		setBlock(world, i + 0, j + 15, k + 26, Blocks.log, 1);
		world.setBlockMetadataWithNotify(i + 0, j + 15, k + 26, 1, 2);
		setBlock(world, i + 0, j + 15, k + 28, Blocks.log, 1);
		world.setBlockMetadataWithNotify(i + 0, j + 15, k + 28, 1, 2);
		setBlock(world, i + 0, j + 16, k + 12, Blocks.vine, 2);
		world.setBlockMetadataWithNotify(i + 0, j + 16, k + 12, 2, 2);
		setBlock(world, i + 0, j + 16, k + 17, Blocks.vine, 15);
		world.setBlockMetadataWithNotify(i + 0, j + 16, k + 17, 15, 2);
		setBlock(world, i + 0, j + 16, k + 18, Blocks.log, 1);
		world.setBlockMetadataWithNotify(i + 0, j + 16, k + 18, 1, 2);
		setBlock(world, i + 0, j + 16, k + 19, Blocks.log, 1);
		world.setBlockMetadataWithNotify(i + 0, j + 16, k + 19, 1, 2);
		setBlock(world, i + 0, j + 16, k + 20, Blocks.log, 1);
		world.setBlockMetadataWithNotify(i + 0, j + 16, k + 20, 1, 2);
		setBlock(world, i + 0, j + 16, k + 22, Blocks.log, 1);
		world.setBlockMetadataWithNotify(i + 0, j + 16, k + 22, 1, 2);
		setBlock(world, i + 0, j + 16, k + 23, Blocks.log, 1);
		world.setBlockMetadataWithNotify(i + 0, j + 16, k + 23, 1, 2);
		setBlock(world, i + 0, j + 16, k + 24, Blocks.log, 1);
		world.setBlockMetadataWithNotify(i + 0, j + 16, k + 24, 1, 2);
		setBlock(world, i + 0, j + 16, k + 25, Blocks.log, 1);
		world.setBlockMetadataWithNotify(i + 0, j + 16, k + 25, 1, 2);
		setBlock(world, i + 0, j + 16, k + 26, Blocks.log, 1);
		world.setBlockMetadataWithNotify(i + 0, j + 16, k + 26, 1, 2);
		setBlock(world, i + 0, j + 16, k + 27, Blocks.log, 1);
		world.setBlockMetadataWithNotify(i + 0, j + 16, k + 27, 1, 2);
		setBlock(world, i + 0, j + 16, k + 29, Blocks.log, 1);
		world.setBlockMetadataWithNotify(i + 0, j + 16, k + 29, 1, 2);
		setBlock(world, i + 0, j + 17, k + 12, Blocks.vine, 2);
		world.setBlockMetadataWithNotify(i + 0, j + 17, k + 12, 2, 2);
		setBlock(world, i + 0, j + 17, k + 17, Blocks.vine, 9);
		world.setBlockMetadataWithNotify(i + 0, j + 17, k + 17, 9, 2);
		setBlock(world, i + 0, j + 17, k + 19, Blocks.vine, 15);
		world.setBlockMetadataWithNotify(i + 0, j + 17, k + 19, 15, 2);
		setBlock(world, i + 0, j + 17, k + 20, Blocks.vine, 15);
		world.setBlockMetadataWithNotify(i + 0, j + 17, k + 20, 15, 2);
		setBlock(world, i + 0, j + 17, k + 21, Blocks.vine, 7);
		world.setBlockMetadataWithNotify(i + 0, j + 17, k + 21, 7, 2);
		setBlock(world, i + 0, j + 17, k + 22, Blocks.vine, 15);
		world.setBlockMetadataWithNotify(i + 0, j + 17, k + 22, 15, 2);
		setBlock(world, i + 0, j + 17, k + 23, Blocks.log, 1);
		world.setBlockMetadataWithNotify(i + 0, j + 17, k + 23, 1, 2);
		setBlock(world, i + 0, j + 17, k + 24, Blocks.log, 1);
		world.setBlockMetadataWithNotify(i + 0, j + 17, k + 24, 1, 2);
		setBlock(world, i + 0, j + 17, k + 25, Blocks.log, 1);
		world.setBlockMetadataWithNotify(i + 0, j + 17, k + 25, 1, 2);
		setBlock(world, i + 0, j + 17, k + 26, Blocks.log, 1);
		world.setBlockMetadataWithNotify(i + 0, j + 17, k + 26, 1, 2);
		setBlock(world, i + 0, j + 17, k + 28, Blocks.log, 1);
		world.setBlockMetadataWithNotify(i + 0, j + 17, k + 28, 1, 2);
		setBlock(world, i + 0, j + 18, k + 11, Blocks.vine, 15);
		world.setBlockMetadataWithNotify(i + 0, j + 18, k + 11, 15, 2);
		setBlock(world, i + 0, j + 18, k + 12, Blocks.vine, 7);
		world.setBlockMetadataWithNotify(i + 0, j + 18, k + 12, 7, 2);
		setBlock(world, i + 0, j + 18, k + 13, Blocks.vine, 11);
		world.setBlockMetadataWithNotify(i + 0, j + 18, k + 13, 11, 2);
		setBlock(world, i + 0, j + 18, k + 14, Blocks.vine, 13);
		world.setBlockMetadataWithNotify(i + 0, j + 18, k + 14, 13, 2);
		setBlock(world, i + 0, j + 18, k + 15, Blocks.vine, 14);
		world.setBlockMetadataWithNotify(i + 0, j + 18, k + 15, 14, 2);
		setBlock(world, i + 0, j + 18, k + 17, Blocks.vine, 15);
		world.setBlockMetadataWithNotify(i + 0, j + 18, k + 17, 15, 2);
		setBlock(world, i + 0, j + 18, k + 18, Blocks.vine, 15);
		world.setBlockMetadataWithNotify(i + 0, j + 18, k + 18, 15, 2);
		setBlock(world, i + 0, j + 18, k + 19, Blocks.vine, 15);
		world.setBlockMetadataWithNotify(i + 0, j + 18, k + 19, 15, 2);
		setBlock(world, i + 0, j + 18, k + 20, Blocks.vine, 15);
		world.setBlockMetadataWithNotify(i + 0, j + 18, k + 20, 15, 2);
		setBlock(world, i + 0, j + 18, k + 21, Blocks.vine, 15);
		world.setBlockMetadataWithNotify(i + 0, j + 18, k + 21, 15, 2);
		setBlock(world, i + 0, j + 18, k + 22, Blocks.vine, 15);
		world.setBlockMetadataWithNotify(i + 0, j + 18, k + 22, 15, 2);
		setBlock(world, i + 0, j + 18, k + 23, Blocks.vine, 15);
		world.setBlockMetadataWithNotify(i + 0, j + 18, k + 23, 15, 2);
		setBlock(world, i + 0, j + 18, k + 25, Blocks.log, 1);
		world.setBlockMetadataWithNotify(i + 0, j + 18, k + 25, 1, 2);
		setBlock(world, i + 0, j + 19, k + 10, Blocks.vine, 15);
		world.setBlockMetadataWithNotify(i + 0, j + 19, k + 10, 15, 2);
		setBlock(world, i + 0, j + 19, k + 11, Blocks.vine, 15);
		world.setBlockMetadataWithNotify(i + 0, j + 19, k + 11, 15, 2);
		setBlock(world, i + 0, j + 19, k + 12, Blocks.vine, 15);
		world.setBlockMetadataWithNotify(i + 0, j + 19, k + 12, 15, 2);
		setBlock(world, i + 0, j + 19, k + 13, Blocks.vine, 15);
		world.setBlockMetadataWithNotify(i + 0, j + 19, k + 13, 15, 2);
		setBlock(world, i + 0, j + 19, k + 14, Blocks.vine, 15);
		world.setBlockMetadataWithNotify(i + 0, j + 19, k + 14, 15, 2);
		setBlock(world, i + 0, j + 19, k + 15, Blocks.vine, 15);
		world.setBlockMetadataWithNotify(i + 0, j + 19, k + 15, 15, 2);
		setBlock(world, i + 0, j + 19, k + 16, Blocks.vine, 15);
		world.setBlockMetadataWithNotify(i + 0, j + 19, k + 16, 15, 2);
		setBlock(world, i + 0, j + 19, k + 17, Blocks.vine, 15);
		world.setBlockMetadataWithNotify(i + 0, j + 19, k + 17, 15, 2);
		setBlock(world, i + 0, j + 19, k + 18, Blocks.vine, 15);
		world.setBlockMetadataWithNotify(i + 0, j + 19, k + 18, 15, 2);
		setBlock(world, i + 0, j + 19, k + 19, Blocks.log, 1);
		world.setBlockMetadataWithNotify(i + 0, j + 19, k + 19, 1, 2);
		setBlock(world, i + 0, j + 19, k + 20, Blocks.log, 1);
		world.setBlockMetadataWithNotify(i + 0, j + 19, k + 20, 1, 2);
		setBlock(world, i + 0, j + 19, k + 21, Blocks.log, 1);
		world.setBlockMetadataWithNotify(i + 0, j + 19, k + 21, 1, 2);
		setBlock(world, i + 0, j + 19, k + 22, Blocks.log, 1);
		world.setBlockMetadataWithNotify(i + 0, j + 19, k + 22, 1, 2);
		setBlock(world, i + 0, j + 19, k + 23, Blocks.log, 1);
		world.setBlockMetadataWithNotify(i + 0, j + 19, k + 23, 1, 2);
		setBlock(world, i + 0, j + 19, k + 24, Blocks.log, 1);
		world.setBlockMetadataWithNotify(i + 0, j + 19, k + 24, 1, 2);
		setBlock(world, i + 0, j + 20, k + 7, Blocks.planks, 5);
		world.setBlockMetadataWithNotify(i + 0, j + 20, k + 7, 5, 2);
		setBlock(world, i + 0, j + 20, k + 8, Blocks.planks, 5);
		world.setBlockMetadataWithNotify(i + 0, j + 20, k + 8, 5, 2);
		setBlock(world, i + 0, j + 20, k + 9, Blocks.planks, 5);
		world.setBlockMetadataWithNotify(i + 0, j + 20, k + 9, 5, 2);
		setBlock(world, i + 0, j + 20, k + 10, Blocks.planks, 5);
		world.setBlockMetadataWithNotify(i + 0, j + 20, k + 10, 5, 2);
		setBlock(world, i + 0, j + 20, k + 11, Blocks.planks, 5);
		world.setBlockMetadataWithNotify(i + 0, j + 20, k + 11, 5, 2);
		setBlock(world, i + 0, j + 20, k + 12, Blocks.planks, 5);
		world.setBlockMetadataWithNotify(i + 0, j + 20, k + 12, 5, 2);
		setBlock(world, i + 0, j + 20, k + 13, Blocks.planks, 5);
		world.setBlockMetadataWithNotify(i + 0, j + 20, k + 13, 5, 2);
		setBlock(world, i + 0, j + 20, k + 14, Blocks.planks, 5);
		world.setBlockMetadataWithNotify(i + 0, j + 20, k + 14, 5, 2);
		setBlock(world, i + 0, j + 20, k + 15, Blocks.log, 1);
		world.setBlockMetadataWithNotify(i + 0, j + 20, k + 15, 1, 2);
		setBlock(world, i + 0, j + 20, k + 16, Blocks.planks, 5);
		world.setBlockMetadataWithNotify(i + 0, j + 20, k + 16, 5, 2);
		setBlock(world, i + 0, j + 20, k + 17, Blocks.planks, 5);
		world.setBlockMetadataWithNotify(i + 0, j + 20, k + 17, 5, 2);
		setBlock(world, i + 0, j + 20, k + 18, Blocks.log, 1);
		world.setBlockMetadataWithNotify(i + 0, j + 20, k + 18, 1, 2);
		setBlock(world, i + 0, j + 20, k + 19, Blocks.planks, 5);
		world.setBlockMetadataWithNotify(i + 0, j + 20, k + 19, 5, 2);
		setBlock(world, i + 0, j + 20, k + 20, Blocks.planks, 5);
		world.setBlockMetadataWithNotify(i + 0, j + 20, k + 20, 5, 2);
		setBlock(world, i + 0, j + 20, k + 21, Blocks.log, 1);
		world.setBlockMetadataWithNotify(i + 0, j + 20, k + 21, 1, 2);
		setBlock(world, i + 0, j + 20, k + 22, Blocks.planks, 5);
		world.setBlockMetadataWithNotify(i + 0, j + 20, k + 22, 5, 2);
		setBlock(world, i + 0, j + 20, k + 23, Blocks.planks, 5);
		world.setBlockMetadataWithNotify(i + 0, j + 20, k + 23, 5, 2);
		setBlock(world, i + 0, j + 20, k + 24, Blocks.log, 1);
		world.setBlockMetadataWithNotify(i + 0, j + 20, k + 24, 1, 2);
		setBlock(world, i + 0, j + 20, k + 25, Blocks.planks, 5);
		world.setBlockMetadataWithNotify(i + 0, j + 20, k + 25, 5, 2);
		setBlock(world, i + 0, j + 20, k + 26, Blocks.planks, 5);
		world.setBlockMetadataWithNotify(i + 0, j + 20, k + 26, 5, 2);
		setBlock(world, i + 0, j + 20, k + 27, Blocks.log, 1);
		world.setBlockMetadataWithNotify(i + 0, j + 20, k + 27, 1, 2);
		setBlock(world, i + 0, j + 21, k + 22, Blocks.furnace, 4);
		world.setBlockMetadataWithNotify(i + 0, j + 21, k + 22, 4, 2);
		setBlock(world, i + 0, j + 23, k + 13, Blocks.torch, 1);
		world.setBlockMetadataWithNotify(i + 0, j + 23, k + 13, 1, 2);
		setBlock(world, i + 0, j + 23, k + 21, Blocks.torch, 2);
		world.setBlockMetadataWithNotify(i + 0, j + 23, k + 21, 2, 2);
		setBlock(world, i + 0, j + 23, k + 29, Blocks.torch, 1);
		world.setBlockMetadataWithNotify(i + 0, j + 23, k + 29, 1, 2);
		setBlock(world, i + 0, j + 24, k + 12, Blocks.log, 1);
		world.setBlockMetadataWithNotify(i + 0, j + 24, k + 12, 1, 2);
		setBlock(world, i + 0, j + 24, k + 13, Blocks.log, 1);
		world.setBlockMetadataWithNotify(i + 0, j + 24, k + 13, 1, 2);
		setBlock(world, i + 0, j + 24, k + 14, Blocks.log, 1);
		world.setBlockMetadataWithNotify(i + 0, j + 24, k + 14, 1, 2);
		setBlock(world, i + 0, j + 24, k + 15, Blocks.log, 1);
		world.setBlockMetadataWithNotify(i + 0, j + 24, k + 15, 1, 2);
		setBlock(world, i + 0, j + 24, k + 16, Blocks.log, 1);
		world.setBlockMetadataWithNotify(i + 0, j + 24, k + 16, 1, 2);
		setBlock(world, i + 0, j + 24, k + 26, Blocks.log, 1);
		world.setBlockMetadataWithNotify(i + 0, j + 24, k + 26, 1, 2);
		setBlock(world, i + 0, j + 24, k + 27, Blocks.log, 1);
		world.setBlockMetadataWithNotify(i + 0, j + 24, k + 27, 1, 2);
		setBlock(world, i + 0, j + 24, k + 28, Blocks.log, 1);
		world.setBlockMetadataWithNotify(i + 0, j + 24, k + 28, 1, 2);
		setBlock(world, i + 0, j + 24, k + 29, Blocks.log, 1);
		world.setBlockMetadataWithNotify(i + 0, j + 24, k + 29, 1, 2);
		setBlock(world, i + 0, j + 24, k + 30, Blocks.log, 1);
		world.setBlockMetadataWithNotify(i + 0, j + 24, k + 30, 1, 2);
		setBlock(world, i + 0, j + 24, k + 31, Blocks.log, 3);
		world.setBlockMetadataWithNotify(i + 0, j + 24, k + 31, 3, 2);
		setBlock(world, i + 0, j + 25, k + 13, Blocks.log, 1);
		world.setBlockMetadataWithNotify(i + 0, j + 25, k + 13, 1, 2);
		setBlock(world, i + 0, j + 25, k + 14, Blocks.log, 1);
		world.setBlockMetadataWithNotify(i + 0, j + 25, k + 14, 1, 2);
		setBlock(world, i + 0, j + 25, k + 15, Blocks.log, 1);
		world.setBlockMetadataWithNotify(i + 0, j + 25, k + 15, 1, 2);
		setBlock(world, i + 0, j + 25, k + 16, Blocks.log, 1);
		world.setBlockMetadataWithNotify(i + 0, j + 25, k + 16, 1, 2);
		setBlock(world, i + 0, j + 25, k + 17, Blocks.log, 1);
		world.setBlockMetadataWithNotify(i + 0, j + 25, k + 17, 1, 2);
		setBlock(world, i + 0, j + 25, k + 25, Blocks.log, 1);
		world.setBlockMetadataWithNotify(i + 0, j + 25, k + 25, 1, 2);
		setBlock(world, i + 0, j + 25, k + 26, Blocks.log, 1);
		world.setBlockMetadataWithNotify(i + 0, j + 25, k + 26, 1, 2);
		setBlock(world, i + 0, j + 25, k + 27, Blocks.log, 1);
		world.setBlockMetadataWithNotify(i + 0, j + 25, k + 27, 1, 2);
		setBlock(world, i + 0, j + 25, k + 28, Blocks.log, 1);
		world.setBlockMetadataWithNotify(i + 0, j + 25, k + 28, 1, 2);
		setBlock(world, i + 0, j + 25, k + 29, Blocks.log, 1);
		world.setBlockMetadataWithNotify(i + 0, j + 25, k + 29, 1, 2);
		setBlock(world, i + 0, j + 25, k + 30, Blocks.log, 3);
		world.setBlockMetadataWithNotify(i + 0, j + 25, k + 30, 3, 2);
		setBlock(world, i + 0, j + 25, k + 31, Blocks.log, 3);
		world.setBlockMetadataWithNotify(i + 0, j + 25, k + 31, 3, 2);
		setBlock(world, i + 0, j + 26, k + 13, Blocks.log, 1);
		world.setBlockMetadataWithNotify(i + 0, j + 26, k + 13, 1, 2);
		setBlock(world, i + 0, j + 26, k + 14, Blocks.log, 1);
		world.setBlockMetadataWithNotify(i + 0, j + 26, k + 14, 1, 2);
		setBlock(world, i + 0, j + 26, k + 15, Blocks.log, 1);
		world.setBlockMetadataWithNotify(i + 0, j + 26, k + 15, 1, 2);
		setBlock(world, i + 0, j + 26, k + 16, Blocks.log, 1);
		world.setBlockMetadataWithNotify(i + 0, j + 26, k + 16, 1, 2);
		setBlock(world, i + 0, j + 26, k + 17, Blocks.log, 1);
		world.setBlockMetadataWithNotify(i + 0, j + 26, k + 17, 1, 2);
		setBlock(world, i + 0, j + 26, k + 18, Blocks.log, 1);
		world.setBlockMetadataWithNotify(i + 0, j + 26, k + 18, 1, 2);
		setBlock(world, i + 0, j + 26, k + 20, Blocks.log, 1);
		world.setBlockMetadataWithNotify(i + 0, j + 26, k + 20, 1, 2);
		setBlock(world, i + 0, j + 26, k + 21, Blocks.log, 1);
		world.setBlockMetadataWithNotify(i + 0, j + 26, k + 21, 1, 2);
		setBlock(world, i + 0, j + 26, k + 22, Blocks.log, 1);
		world.setBlockMetadataWithNotify(i + 0, j + 26, k + 22, 1, 2);
		setBlock(world, i + 0, j + 26, k + 24, Blocks.log, 1);
		world.setBlockMetadataWithNotify(i + 0, j + 26, k + 24, 1, 2);
		setBlock(world, i + 0, j + 26, k + 25, Blocks.log, 1);
		world.setBlockMetadataWithNotify(i + 0, j + 26, k + 25, 1, 2);
		setBlock(world, i + 0, j + 26, k + 26, Blocks.log, 1);
		world.setBlockMetadataWithNotify(i + 0, j + 26, k + 26, 1, 2);
		setBlock(world, i + 0, j + 26, k + 27, Blocks.log, 1);
		world.setBlockMetadataWithNotify(i + 0, j + 26, k + 27, 1, 2);
		setBlock(world, i + 0, j + 26, k + 28, Blocks.log, 1);
		world.setBlockMetadataWithNotify(i + 0, j + 26, k + 28, 1, 2);
		setBlock(world, i + 0, j + 26, k + 29, Blocks.log, 1);
		world.setBlockMetadataWithNotify(i + 0, j + 26, k + 29, 1, 2);
		setBlock(world, i + 0, j + 26, k + 31, Blocks.log, 3);
		world.setBlockMetadataWithNotify(i + 0, j + 26, k + 31, 3, 2);
		setBlock(world, i + 0, j + 27, k + 14, Blocks.log, 1);
		world.setBlockMetadataWithNotify(i + 0, j + 27, k + 14, 1, 2);
		setBlock(world, i + 0, j + 27, k + 15, Blocks.log, 1);
		world.setBlockMetadataWithNotify(i + 0, j + 27, k + 15, 1, 2);
		setBlock(world, i + 0, j + 27, k + 16, Blocks.log, 1);
		world.setBlockMetadataWithNotify(i + 0, j + 27, k + 16, 1, 2);
		setBlock(world, i + 0, j + 27, k + 17, Blocks.log, 1);
		world.setBlockMetadataWithNotify(i + 0, j + 27, k + 17, 1, 2);
		setBlock(world, i + 0, j + 27, k + 18, Blocks.log, 1);
		world.setBlockMetadataWithNotify(i + 0, j + 27, k + 18, 1, 2);
		setBlock(world, i + 0, j + 27, k + 19, Blocks.log, 1);
		world.setBlockMetadataWithNotify(i + 0, j + 27, k + 19, 1, 2);
		setBlock(world, i + 0, j + 27, k + 20, Blocks.log, 1);
		world.setBlockMetadataWithNotify(i + 0, j + 27, k + 20, 1, 2);
		setBlock(world, i + 0, j + 27, k + 21, Blocks.log, 1);
		world.setBlockMetadataWithNotify(i + 0, j + 27, k + 21, 1, 2);
		setBlock(world, i + 0, j + 27, k + 22, Blocks.log, 1);
		world.setBlockMetadataWithNotify(i + 0, j + 27, k + 22, 1, 2);
		setBlock(world, i + 0, j + 27, k + 23, Blocks.log, 1);
		world.setBlockMetadataWithNotify(i + 0, j + 27, k + 23, 1, 2);
		setBlock(world, i + 0, j + 27, k + 24, Blocks.log, 1);
		world.setBlockMetadataWithNotify(i + 0, j + 27, k + 24, 1, 2);
		setBlock(world, i + 0, j + 27, k + 25, Blocks.log, 1);
		world.setBlockMetadataWithNotify(i + 0, j + 27, k + 25, 1, 2);
		setBlock(world, i + 0, j + 27, k + 26, Blocks.log, 1);
		world.setBlockMetadataWithNotify(i + 0, j + 27, k + 26, 1, 2);
		setBlock(world, i + 0, j + 27, k + 27, Blocks.log, 1);
		world.setBlockMetadataWithNotify(i + 0, j + 27, k + 27, 1, 2);
		setBlock(world, i + 0, j + 27, k + 28, Blocks.log, 1);
		world.setBlockMetadataWithNotify(i + 0, j + 27, k + 28, 1, 2);
		setBlock(world, i + 0, j + 28, k + 15, Blocks.log, 1);
		world.setBlockMetadataWithNotify(i + 0, j + 28, k + 15, 1, 2);
		setBlock(world, i + 0, j + 28, k + 16, Blocks.log, 1);
		world.setBlockMetadataWithNotify(i + 0, j + 28, k + 16, 1, 2);
		setBlock(world, i + 0, j + 28, k + 17, Blocks.log, 1);
		world.setBlockMetadataWithNotify(i + 0, j + 28, k + 17, 1, 2);
		setBlock(world, i + 0, j + 28, k + 18, Blocks.log, 1);
		world.setBlockMetadataWithNotify(i + 0, j + 28, k + 18, 1, 2);
		setBlock(world, i + 0, j + 28, k + 19, Blocks.log, 1);
		world.setBlockMetadataWithNotify(i + 0, j + 28, k + 19, 1, 2);
		setBlock(world, i + 0, j + 28, k + 20, Blocks.log, 1);
		world.setBlockMetadataWithNotify(i + 0, j + 28, k + 20, 1, 2);
		setBlock(world, i + 0, j + 28, k + 21, Blocks.log, 1);
		world.setBlockMetadataWithNotify(i + 0, j + 28, k + 21, 1, 2);
		setBlock(world, i + 0, j + 28, k + 22, Blocks.log, 1);
		world.setBlockMetadataWithNotify(i + 0, j + 28, k + 22, 1, 2);
		setBlock(world, i + 0, j + 28, k + 23, Blocks.log, 1);
		world.setBlockMetadataWithNotify(i + 0, j + 28, k + 23, 1, 2);
		setBlock(world, i + 0, j + 28, k + 24, Blocks.log, 1);
		world.setBlockMetadataWithNotify(i + 0, j + 28, k + 24, 1, 2);
		setBlock(world, i + 0, j + 28, k + 25, Blocks.log, 1);
		world.setBlockMetadataWithNotify(i + 0, j + 28, k + 25, 1, 2);
		setBlock(world, i + 0, j + 28, k + 26, Blocks.log, 1);
		world.setBlockMetadataWithNotify(i + 0, j + 28, k + 26, 1, 2);
		setBlock(world, i + 0, j + 28, k + 27, Blocks.log, 1);
		world.setBlockMetadataWithNotify(i + 0, j + 28, k + 27, 1, 2);
		setBlock(world, i + 0, j + 29, k + 18, Blocks.log, 1);
		world.setBlockMetadataWithNotify(i + 0, j + 29, k + 18, 1, 2);
		setBlock(world, i + 0, j + 29, k + 19, Blocks.log, 1);
		world.setBlockMetadataWithNotify(i + 0, j + 29, k + 19, 1, 2);
		setBlock(world, i + 0, j + 29, k + 20, Blocks.log, 1);
		world.setBlockMetadataWithNotify(i + 0, j + 29, k + 20, 1, 2);
		setBlock(world, i + 0, j + 29, k + 21, Blocks.log, 1);
		world.setBlockMetadataWithNotify(i + 0, j + 29, k + 21, 1, 2);
		setBlock(world, i + 0, j + 29, k + 22, Blocks.log, 1);
		world.setBlockMetadataWithNotify(i + 0, j + 29, k + 22, 1, 2);
		setBlock(world, i + 0, j + 29, k + 23, Blocks.log, 1);
		world.setBlockMetadataWithNotify(i + 0, j + 29, k + 23, 1, 2);
		setBlock(world, i + 0, j + 29, k + 24, Blocks.log, 1);
		world.setBlockMetadataWithNotify(i + 0, j + 29, k + 24, 1, 2);
		setBlock(world, i + 0, j + 36, k + 31, Blocks.log, 3);
		world.setBlockMetadataWithNotify(i + 0, j + 36, k + 31, 3, 2);
		setBlock(world, i + 0, j + 37, k + 25, Blocks.leaves, 7);
		world.setBlockMetadataWithNotify(i + 0, j + 37, k + 25, 7, 2);
		setBlock(world, i + 0, j + 37, k + 26, Blocks.leaves, 7);
		world.setBlockMetadataWithNotify(i + 0, j + 37, k + 26, 7, 2);
		setBlock(world, i + 0, j + 37, k + 27, Blocks.leaves, 7);
		world.setBlockMetadataWithNotify(i + 0, j + 37, k + 27, 7, 2);
		setBlock(world, i + 0, j + 37, k + 28, Blocks.leaves, 7);
		world.setBlockMetadataWithNotify(i + 0, j + 37, k + 28, 7, 2);
		setBlock(world, i + 0, j + 37, k + 29, Blocks.leaves, 7);
		world.setBlockMetadataWithNotify(i + 0, j + 37, k + 29, 7, 2);
		setBlock(world, i + 0, j + 38, k + 26, Blocks.leaves, 7);
		world.setBlockMetadataWithNotify(i + 0, j + 38, k + 26, 7, 2);
		setBlock(world, i + 0, j + 38, k + 27, Blocks.leaves, 7);
		world.setBlockMetadataWithNotify(i + 0, j + 38, k + 27, 7, 2);
		setBlock(world, i + 0, j + 38, k + 28, Blocks.leaves, 7);
		world.setBlockMetadataWithNotify(i + 0, j + 38, k + 28, 7, 2);
		setBlock(world, i + 0, j + 39, k + 27, Blocks.leaves, 7);
		world.setBlockMetadataWithNotify(i + 0, j + 39, k + 27, 7, 2);
		setBlock(world, i + 0, j + 46, k + 19, Blocks.planks, 5);
		world.setBlockMetadataWithNotify(i + 0, j + 46, k + 19, 5, 2);
		setBlock(world, i + 0, j + 46, k + 20, Blocks.planks, 5);
		world.setBlockMetadataWithNotify(i + 0, j + 46, k + 20, 5, 2);
		setBlock(world, i + 0, j + 46, k + 21, Blocks.planks, 5);
		world.setBlockMetadataWithNotify(i + 0, j + 46, k + 21, 5, 2);
		setBlock(world, i + 0, j + 46, k + 22, Blocks.planks, 5);
		world.setBlockMetadataWithNotify(i + 0, j + 46, k + 22, 5, 2);
		setBlock(world, i + 0, j + 46, k + 23, Blocks.planks, 5);
		world.setBlockMetadataWithNotify(i + 0, j + 46, k + 23, 5, 2);
		setBlock(world, i + 0, j + 46, k + 24, Blocks.planks, 5);
		world.setBlockMetadataWithNotify(i + 0, j + 46, k + 24, 5, 2);
		setBlock(world, i + 0, j + 51, k + 18, Blocks.log, 1);
		world.setBlockMetadataWithNotify(i + 0, j + 51, k + 18, 1, 2);
		setBlock(world, i + 0, j + 51, k + 19, Blocks.log, 1);
		world.setBlockMetadataWithNotify(i + 0, j + 51, k + 19, 1, 2);
		setBlock(world, i + 0, j + 51, k + 20, Blocks.log, 1);
		world.setBlockMetadataWithNotify(i + 0, j + 51, k + 20, 1, 2);
		setBlock(world, i + 0, j + 51, k + 21, Blocks.log, 1);
		world.setBlockMetadataWithNotify(i + 0, j + 51, k + 21, 1, 2);
		setBlock(world, i + 0, j + 51, k + 22, Blocks.log, 1);
		world.setBlockMetadataWithNotify(i + 0, j + 51, k + 22, 1, 2);
		setBlock(world, i + 0, j + 51, k + 23, Blocks.log, 1);
		world.setBlockMetadataWithNotify(i + 0, j + 51, k + 23, 1, 2);
		setBlock(world, i + 0, j + 51, k + 24, Blocks.log, 1);
		world.setBlockMetadataWithNotify(i + 0, j + 51, k + 24, 1, 2);
		setBlock(world, i + 0, j + 51, k + 25, Blocks.log, 1);
		world.setBlockMetadataWithNotify(i + 0, j + 51, k + 25, 1, 2);
		setBlock(world, i + 0, j + 52, k + 20, Blocks.log, 1);
		world.setBlockMetadataWithNotify(i + 0, j + 52, k + 20, 1, 2);
		setBlock(world, i + 0, j + 52, k + 21, Blocks.log, 1);
		world.setBlockMetadataWithNotify(i + 0, j + 52, k + 21, 1, 2);
		setBlock(world, i + 0, j + 52, k + 22, Blocks.log, 1);
		world.setBlockMetadataWithNotify(i + 0, j + 52, k + 22, 1, 2);
		setBlock(world, i + 0, j + 52, k + 23, Blocks.log, 1);
		world.setBlockMetadataWithNotify(i + 0, j + 52, k + 23, 1, 2);
		setBlock(world, i + 1, j + 12, k + 20, Blocks.log, 1);
		world.setBlockMetadataWithNotify(i + 1, j + 12, k + 20, 1, 2);
		setBlock(world, i + 1, j + 12, k + 21, Blocks.log, 1);
		world.setBlockMetadataWithNotify(i + 1, j + 12, k + 21, 1, 2);
		setBlock(world, i + 1, j + 12, k + 22, Blocks.log, 1);
		world.setBlockMetadataWithNotify(i + 1, j + 12, k + 22, 1, 2);
		setBlock(world, i + 1, j + 13, k + 17, Blocks.vine, 8);
		world.setBlockMetadataWithNotify(i + 1, j + 13, k + 17, 8, 2);
		setBlock(world, i + 1, j + 13, k + 18, Blocks.vine, 15);
		world.setBlockMetadataWithNotify(i + 1, j + 13, k + 18, 15, 2);
		setBlock(world, i + 1, j + 13, k + 19, Blocks.vine, 15);
		world.setBlockMetadataWithNotify(i + 1, j + 13, k + 19, 15, 2);
		setBlock(world, i + 1, j + 13, k + 21, Blocks.log, 1);
		world.setBlockMetadataWithNotify(i + 1, j + 13, k + 21, 1, 2);
		setBlock(world, i + 1, j + 13, k + 22, Blocks.log, 1);
		world.setBlockMetadataWithNotify(i + 1, j + 13, k + 22, 1, 2);
		setBlock(world, i + 1, j + 14, k + 17, Blocks.vine, 15);
		world.setBlockMetadataWithNotify(i + 1, j + 14, k + 17, 15, 2);
		setBlock(world, i + 1, j + 14, k + 18, Blocks.vine, 15);
		world.setBlockMetadataWithNotify(i + 1, j + 14, k + 18, 15, 2);
		setBlock(world, i + 1, j + 14, k + 19, Blocks.vine, 15);
		world.setBlockMetadataWithNotify(i + 1, j + 14, k + 19, 15, 2);
		setBlock(world, i + 1, j + 14, k + 20, Blocks.vine, 15);
		world.setBlockMetadataWithNotify(i + 1, j + 14, k + 20, 15, 2);
		setBlock(world, i + 1, j + 14, k + 21, Blocks.log, 1);
		world.setBlockMetadataWithNotify(i + 1, j + 14, k + 21, 1, 2);
		setBlock(world, i + 1, j + 14, k + 22, Blocks.log, 1);
		world.setBlockMetadataWithNotify(i + 1, j + 14, k + 22, 1, 2);
		setBlock(world, i + 1, j + 14, k + 23, Blocks.log, 1);
		world.setBlockMetadataWithNotify(i + 1, j + 14, k + 23, 1, 2);
		setBlock(world, i + 1, j + 14, k + 24, Blocks.log, 1);
		world.setBlockMetadataWithNotify(i + 1, j + 14, k + 24, 1, 2);
		setBlock(world, i + 1, j + 14, k + 25, Blocks.log, 1);
		world.setBlockMetadataWithNotify(i + 1, j + 14, k + 25, 1, 2);
		setBlock(world, i + 1, j + 15, k + 17, Blocks.vine, 15);
		world.setBlockMetadataWithNotify(i + 1, j + 15, k + 17, 15, 2);
		setBlock(world, i + 1, j + 15, k + 18, Blocks.log, 1);
		world.setBlockMetadataWithNotify(i + 1, j + 15, k + 18, 1, 2);
		setBlock(world, i + 1, j + 15, k + 19, Blocks.log, 1);
		world.setBlockMetadataWithNotify(i + 1, j + 15, k + 19, 1, 2);
		setBlock(world, i + 1, j + 15, k + 20, Blocks.log, 1);
		world.setBlockMetadataWithNotify(i + 1, j + 15, k + 20, 1, 2);
		setBlock(world, i + 1, j + 15, k + 22, Blocks.log, 1);
		world.setBlockMetadataWithNotify(i + 1, j + 15, k + 22, 1, 2);
		setBlock(world, i + 1, j + 15, k + 23, Blocks.log, 1);
		world.setBlockMetadataWithNotify(i + 1, j + 15, k + 23, 1, 2);
		setBlock(world, i + 1, j + 15, k + 24, Blocks.log, 1);
		world.setBlockMetadataWithNotify(i + 1, j + 15, k + 24, 1, 2);
		setBlock(world, i + 1, j + 15, k + 25, Blocks.log, 1);
		world.setBlockMetadataWithNotify(i + 1, j + 15, k + 25, 1, 2);
		setBlock(world, i + 1, j + 15, k + 26, Blocks.log, 1);
		world.setBlockMetadataWithNotify(i + 1, j + 15, k + 26, 1, 2);
		setBlock(world, i + 1, j + 15, k + 27, Blocks.log, 1);
		world.setBlockMetadataWithNotify(i + 1, j + 15, k + 27, 1, 2);
		setBlock(world, i + 1, j + 15, k + 28, Blocks.log, 1);
		world.setBlockMetadataWithNotify(i + 1, j + 15, k + 28, 1, 2);
		setBlock(world, i + 1, j + 15, k + 29, Blocks.log, 1);
		world.setBlockMetadataWithNotify(i + 1, j + 15, k + 29, 1, 2);
		setBlock(world, i + 1, j + 15, k + 31, Blocks.log, 1);
		world.setBlockMetadataWithNotify(i + 1, j + 15, k + 31, 1, 2);
		setBlock(world, i + 1, j + 16, k + 15, Blocks.vine, 5);
		world.setBlockMetadataWithNotify(i + 1, j + 16, k + 15, 5, 2);
		setBlock(world, i + 1, j + 16, k + 17, Blocks.vine, 15);
		world.setBlockMetadataWithNotify(i + 1, j + 16, k + 17, 15, 2);
		setBlock(world, i + 1, j + 16, k + 18, Blocks.log, 1);
		world.setBlockMetadataWithNotify(i + 1, j + 16, k + 18, 1, 2);
		setBlock(world, i + 1, j + 16, k + 19, Blocks.log, 1);
		world.setBlockMetadataWithNotify(i + 1, j + 16, k + 19, 1, 2);
		setBlock(world, i + 1, j + 16, k + 20, Blocks.log, 1);
		world.setBlockMetadataWithNotify(i + 1, j + 16, k + 20, 1, 2);
		setBlock(world, i + 1, j + 16, k + 22, Blocks.log, 1);
		world.setBlockMetadataWithNotify(i + 1, j + 16, k + 22, 1, 2);
		setBlock(world, i + 1, j + 16, k + 23, Blocks.log, 1);
		world.setBlockMetadataWithNotify(i + 1, j + 16, k + 23, 1, 2);
		setBlock(world, i + 1, j + 16, k + 24, Blocks.log, 1);
		world.setBlockMetadataWithNotify(i + 1, j + 16, k + 24, 1, 2);
		setBlock(world, i + 1, j + 16, k + 25, Blocks.log, 1);
		world.setBlockMetadataWithNotify(i + 1, j + 16, k + 25, 1, 2);
		setBlock(world, i + 1, j + 16, k + 26, Blocks.log, 1);
		world.setBlockMetadataWithNotify(i + 1, j + 16, k + 26, 1, 2);
		setBlock(world, i + 1, j + 16, k + 27, Blocks.log, 1);
		world.setBlockMetadataWithNotify(i + 1, j + 16, k + 27, 1, 2);
		setBlock(world, i + 1, j + 16, k + 28, Blocks.log, 1);
		world.setBlockMetadataWithNotify(i + 1, j + 16, k + 28, 1, 2);
		setBlock(world, i + 1, j + 16, k + 29, Blocks.log, 1);
		world.setBlockMetadataWithNotify(i + 1, j + 16, k + 29, 1, 2);
		setBlock(world, i + 1, j + 16, k + 30, Blocks.log, 1);
		world.setBlockMetadataWithNotify(i + 1, j + 16, k + 30, 1, 2);
		setBlock(world, i + 1, j + 16, k + 31, Blocks.log, 1);
		world.setBlockMetadataWithNotify(i + 1, j + 16, k + 31, 1, 2);
		setBlock(world, i + 1, j + 17, k + 15, Blocks.vine, 5);
		world.setBlockMetadataWithNotify(i + 1, j + 17, k + 15, 5, 2);
		setBlock(world, i + 1, j + 17, k + 17, Blocks.vine, 15);
		world.setBlockMetadataWithNotify(i + 1, j + 17, k + 17, 15, 2);
		setBlock(world, i + 1, j + 17, k + 18, Blocks.vine, 15);
		world.setBlockMetadataWithNotify(i + 1, j + 17, k + 18, 15, 2);
		setBlock(world, i + 1, j + 17, k + 19, Blocks.log, 1);
		world.setBlockMetadataWithNotify(i + 1, j + 17, k + 19, 1, 2);
		setBlock(world, i + 1, j + 17, k + 20, Blocks.log, 1);
		world.setBlockMetadataWithNotify(i + 1, j + 17, k + 20, 1, 2);
		setBlock(world, i + 1, j + 17, k + 22, Blocks.log, 1);
		world.setBlockMetadataWithNotify(i + 1, j + 17, k + 22, 1, 2);
		setBlock(world, i + 1, j + 17, k + 23, Blocks.vine, 15);
		world.setBlockMetadataWithNotify(i + 1, j + 17, k + 23, 15, 2);
		setBlock(world, i + 1, j + 17, k + 24, Blocks.log, 1);
		world.setBlockMetadataWithNotify(i + 1, j + 17, k + 24, 1, 2);
		setBlock(world, i + 1, j + 17, k + 25, Blocks.log, 1);
		world.setBlockMetadataWithNotify(i + 1, j + 17, k + 25, 1, 2);
		setBlock(world, i + 1, j + 17, k + 26, Blocks.log, 1);
		world.setBlockMetadataWithNotify(i + 1, j + 17, k + 26, 1, 2);
		setBlock(world, i + 1, j + 17, k + 28, Blocks.log, 1);
		world.setBlockMetadataWithNotify(i + 1, j + 17, k + 28, 1, 2);
		setBlock(world, i + 1, j + 17, k + 29, Blocks.log, 1);
		world.setBlockMetadataWithNotify(i + 1, j + 17, k + 29, 1, 2);
		setBlock(world, i + 1, j + 17, k + 31, Blocks.log, 1);
		world.setBlockMetadataWithNotify(i + 1, j + 17, k + 31, 1, 2);
		setBlock(world, i + 1, j + 18, k + 10, Blocks.vine, 14);
		world.setBlockMetadataWithNotify(i + 1, j + 18, k + 10, 14, 2);
		setBlock(world, i + 1, j + 18, k + 13, Blocks.vine, 5);
		world.setBlockMetadataWithNotify(i + 1, j + 18, k + 13, 5, 2);
		setBlock(world, i + 1, j + 18, k + 14, Blocks.vine, 13);
		world.setBlockMetadataWithNotify(i + 1, j + 18, k + 14, 13, 2);
		setBlock(world, i + 1, j + 18, k + 15, Blocks.vine, 5);
		world.setBlockMetadataWithNotify(i + 1, j + 18, k + 15, 5, 2);
		setBlock(world, i + 1, j + 18, k + 16, Blocks.vine, 11);
		world.setBlockMetadataWithNotify(i + 1, j + 18, k + 16, 11, 2);
		setBlock(world, i + 1, j + 18, k + 17, Blocks.vine, 15);
		world.setBlockMetadataWithNotify(i + 1, j + 18, k + 17, 15, 2);
		setBlock(world, i + 1, j + 18, k + 18, Blocks.vine, 15);
		world.setBlockMetadataWithNotify(i + 1, j + 18, k + 18, 15, 2);
		setBlock(world, i + 1, j + 18, k + 19, Blocks.log, 1);
		world.setBlockMetadataWithNotify(i + 1, j + 18, k + 19, 1, 2);
		setBlock(world, i + 1, j + 18, k + 20, Blocks.log, 1);
		world.setBlockMetadataWithNotify(i + 1, j + 18, k + 20, 1, 2);
		setBlock(world, i + 1, j + 18, k + 22, Blocks.vine, 15);
		world.setBlockMetadataWithNotify(i + 1, j + 18, k + 22, 15, 2);
		setBlock(world, i + 1, j + 18, k + 23, Blocks.vine, 15);
		world.setBlockMetadataWithNotify(i + 1, j + 18, k + 23, 15, 2);
		setBlock(world, i + 1, j + 18, k + 24, Blocks.log, 1);
		world.setBlockMetadataWithNotify(i + 1, j + 18, k + 24, 1, 2);
		setBlock(world, i + 1, j + 18, k + 25, Blocks.log, 1);
		world.setBlockMetadataWithNotify(i + 1, j + 18, k + 25, 1, 2);
		setBlock(world, i + 1, j + 18, k + 26, Blocks.log, 1);
		world.setBlockMetadataWithNotify(i + 1, j + 18, k + 26, 1, 2);
		setBlock(world, i + 1, j + 18, k + 27, Blocks.log, 1);
		world.setBlockMetadataWithNotify(i + 1, j + 18, k + 27, 1, 2);
		setBlock(world, i + 1, j + 18, k + 28, Blocks.log, 1);
		world.setBlockMetadataWithNotify(i + 1, j + 18, k + 28, 1, 2);
		setBlock(world, i + 1, j + 18, k + 29, Blocks.log, 1);
		world.setBlockMetadataWithNotify(i + 1, j + 18, k + 29, 1, 2);
		setBlock(world, i + 1, j + 19, k + 10, Blocks.vine, 15);
		world.setBlockMetadataWithNotify(i + 1, j + 19, k + 10, 15, 2);
		setBlock(world, i + 1, j + 19, k + 11, Blocks.vine, 15);
		world.setBlockMetadataWithNotify(i + 1, j + 19, k + 11, 15, 2);
		setBlock(world, i + 1, j + 19, k + 12, Blocks.vine, 15);
		world.setBlockMetadataWithNotify(i + 1, j + 19, k + 12, 15, 2);
		setBlock(world, i + 1, j + 19, k + 13, Blocks.vine, 15);
		world.setBlockMetadataWithNotify(i + 1, j + 19, k + 13, 15, 2);
		setBlock(world, i + 1, j + 19, k + 14, Blocks.vine, 15);
		world.setBlockMetadataWithNotify(i + 1, j + 19, k + 14, 15, 2);
		setBlock(world, i + 1, j + 19, k + 15, Blocks.vine, 15);
		world.setBlockMetadataWithNotify(i + 1, j + 19, k + 15, 15, 2);
		setBlock(world, i + 1, j + 19, k + 16, Blocks.vine, 15);
		world.setBlockMetadataWithNotify(i + 1, j + 19, k + 16, 15, 2);
		setBlock(world, i + 1, j + 19, k + 17, Blocks.vine, 15);
		world.setBlockMetadataWithNotify(i + 1, j + 19, k + 17, 15, 2);
		setBlock(world, i + 1, j + 19, k + 18, Blocks.vine, 15);
		world.setBlockMetadataWithNotify(i + 1, j + 19, k + 18, 15, 2);
		setBlock(world, i + 1, j + 19, k + 19, Blocks.log, 1);
		world.setBlockMetadataWithNotify(i + 1, j + 19, k + 19, 1, 2);
		setBlock(world, i + 1, j + 19, k + 20, Blocks.log, 1);
		world.setBlockMetadataWithNotify(i + 1, j + 19, k + 20, 1, 2);
		setBlock(world, i + 1, j + 19, k + 21, Blocks.log, 1);
		world.setBlockMetadataWithNotify(i + 1, j + 19, k + 21, 1, 2);
		setBlock(world, i + 1, j + 19, k + 22, Blocks.log, 1);
		world.setBlockMetadataWithNotify(i + 1, j + 19, k + 22, 1, 2);
		setBlock(world, i + 1, j + 19, k + 23, Blocks.log, 1);
		world.setBlockMetadataWithNotify(i + 1, j + 19, k + 23, 1, 2);
		setBlock(world, i + 1, j + 19, k + 24, Blocks.log, 1);
		world.setBlockMetadataWithNotify(i + 1, j + 19, k + 24, 1, 2);
		setBlock(world, i + 1, j + 19, k + 25, Blocks.log, 1);
		world.setBlockMetadataWithNotify(i + 1, j + 19, k + 25, 1, 2);
		setBlock(world, i + 1, j + 19, k + 26, Blocks.log, 1);
		world.setBlockMetadataWithNotify(i + 1, j + 19, k + 26, 1, 2);
		setBlock(world, i + 1, j + 19, k + 28, Blocks.log, 1);
		world.setBlockMetadataWithNotify(i + 1, j + 19, k + 28, 1, 2);
		setBlock(world, i + 1, j + 20, k + 8, Blocks.planks, 5);
		world.setBlockMetadataWithNotify(i + 1, j + 20, k + 8, 5, 2);
		setBlock(world, i + 1, j + 20, k + 9, Blocks.planks, 5);
		world.setBlockMetadataWithNotify(i + 1, j + 20, k + 9, 5, 2);
		setBlock(world, i + 1, j + 20, k + 10, Blocks.planks, 5);
		world.setBlockMetadataWithNotify(i + 1, j + 20, k + 10, 5, 2);
		setBlock(world, i + 1, j + 20, k + 11, Blocks.planks, 5);
		world.setBlockMetadataWithNotify(i + 1, j + 20, k + 11, 5, 2);
		setBlock(world, i + 1, j + 20, k + 12, Blocks.planks, 5);
		world.setBlockMetadataWithNotify(i + 1, j + 20, k + 12, 5, 2);
		setBlock(world, i + 1, j + 20, k + 13, Blocks.planks, 5);
		world.setBlockMetadataWithNotify(i + 1, j + 20, k + 13, 5, 2);
		setBlock(world, i + 1, j + 20, k + 14, Blocks.planks, 5);
		world.setBlockMetadataWithNotify(i + 1, j + 20, k + 14, 5, 2);
		setBlock(world, i + 1, j + 20, k + 15, Blocks.log, 1);
		world.setBlockMetadataWithNotify(i + 1, j + 20, k + 15, 1, 2);
		setBlock(world, i + 1, j + 20, k + 16, Blocks.log, 1);
		world.setBlockMetadataWithNotify(i + 1, j + 20, k + 16, 1, 2);
		setBlock(world, i + 1, j + 20, k + 17, Blocks.planks, 5);
		world.setBlockMetadataWithNotify(i + 1, j + 20, k + 17, 5, 2);
		setBlock(world, i + 1, j + 20, k + 18, Blocks.log, 1);
		world.setBlockMetadataWithNotify(i + 1, j + 20, k + 18, 1, 2);
		setBlock(world, i + 1, j + 20, k + 19, Blocks.planks, 5);
		world.setBlockMetadataWithNotify(i + 1, j + 20, k + 19, 5, 2);
		setBlock(world, i + 1, j + 20, k + 20, Blocks.log, 1);
		world.setBlockMetadataWithNotify(i + 1, j + 20, k + 20, 1, 2);
		setBlock(world, i + 1, j + 20, k + 21, Blocks.log, 1);
		world.setBlockMetadataWithNotify(i + 1, j + 20, k + 21, 1, 2);
		setBlock(world, i + 1, j + 20, k + 22, Blocks.log, 1);
		world.setBlockMetadataWithNotify(i + 1, j + 20, k + 22, 1, 2);
		setBlock(world, i + 1, j + 20, k + 23, Blocks.planks, 5);
		world.setBlockMetadataWithNotify(i + 1, j + 20, k + 23, 5, 2);
		setBlock(world, i + 1, j + 20, k + 24, Blocks.log, 1);
		world.setBlockMetadataWithNotify(i + 1, j + 20, k + 24, 1, 2);
		setBlock(world, i + 1, j + 20, k + 25, Blocks.planks, 5);
		world.setBlockMetadataWithNotify(i + 1, j + 20, k + 25, 5, 2);
		setBlock(world, i + 1, j + 20, k + 26, Blocks.log, 1);
		world.setBlockMetadataWithNotify(i + 1, j + 20, k + 26, 1, 2);
		setBlock(world, i + 1, j + 20, k + 27, Blocks.log, 1);
		world.setBlockMetadataWithNotify(i + 1, j + 20, k + 27, 1, 2);
		setBlock(world, i + 1, j + 21, k + 20, Blocks.spruce_stairs, 2);
		world.setBlockMetadataWithNotify(i + 1, j + 21, k + 20, 2, 2);
		setBlock(world, i + 1, j + 21, k + 21, Blocks.log, 1);
		world.setBlockMetadataWithNotify(i + 1, j + 21, k + 21, 1, 2);
		setBlock(world, i + 1, j + 21, k + 22, Blocks.spruce_stairs, 3);
		world.setBlockMetadataWithNotify(i + 1, j + 21, k + 22, 3, 2);
		setBlock(world, i + 1, j + 22, k + 21, Blocks.log, 1);
		world.setBlockMetadataWithNotify(i + 1, j + 22, k + 21, 1, 2);
		setBlock(world, i + 1, j + 23, k + 21, Blocks.log, 1);
		world.setBlockMetadataWithNotify(i + 1, j + 23, k + 21, 1, 2);
		setBlock(world, i + 1, j + 24, k + 12, Blocks.log, 1);
		world.setBlockMetadataWithNotify(i + 1, j + 24, k + 12, 1, 2);
		setBlock(world, i + 1, j + 24, k + 13, Blocks.log, 1);
		world.setBlockMetadataWithNotify(i + 1, j + 24, k + 13, 1, 2);
		setBlock(world, i + 1, j + 24, k + 14, Blocks.log, 1);
		world.setBlockMetadataWithNotify(i + 1, j + 24, k + 14, 1, 2);
		setBlock(world, i + 1, j + 24, k + 15, Blocks.log, 1);
		world.setBlockMetadataWithNotify(i + 1, j + 24, k + 15, 1, 2);
		setBlock(world, i + 1, j + 24, k + 16, Blocks.log, 1);
		world.setBlockMetadataWithNotify(i + 1, j + 24, k + 16, 1, 2);
		setBlock(world, i + 1, j + 24, k + 20, Blocks.torch, 4);
		world.setBlockMetadataWithNotify(i + 1, j + 24, k + 20, 4, 2);
		setBlock(world, i + 1, j + 24, k + 21, Blocks.log, 1);
		world.setBlockMetadataWithNotify(i + 1, j + 24, k + 21, 1, 2);
		setBlock(world, i + 1, j + 24, k + 22, Blocks.torch, 3);
		world.setBlockMetadataWithNotify(i + 1, j + 24, k + 22, 3, 2);
		setBlock(world, i + 1, j + 24, k + 26, Blocks.log, 1);
		world.setBlockMetadataWithNotify(i + 1, j + 24, k + 26, 1, 2);
		setBlock(world, i + 1, j + 24, k + 27, Blocks.log, 1);
		world.setBlockMetadataWithNotify(i + 1, j + 24, k + 27, 1, 2);
		setBlock(world, i + 1, j + 24, k + 28, Blocks.log, 1);
		world.setBlockMetadataWithNotify(i + 1, j + 24, k + 28, 1, 2);
		setBlock(world, i + 1, j + 24, k + 29, Blocks.log, 1);
		world.setBlockMetadataWithNotify(i + 1, j + 24, k + 29, 1, 2);
		setBlock(world, i + 1, j + 24, k + 30, Blocks.log, 1);
		world.setBlockMetadataWithNotify(i + 1, j + 24, k + 30, 1, 2);
		setBlock(world, i + 1, j + 25, k + 13, Blocks.log, 1);
		world.setBlockMetadataWithNotify(i + 1, j + 25, k + 13, 1, 2);
		setBlock(world, i + 1, j + 25, k + 14, Blocks.log, 1);
		world.setBlockMetadataWithNotify(i + 1, j + 25, k + 14, 1, 2);
		setBlock(world, i + 1, j + 25, k + 15, Blocks.log, 1);
		world.setBlockMetadataWithNotify(i + 1, j + 25, k + 15, 1, 2);
		setBlock(world, i + 1, j + 25, k + 16, Blocks.log, 1);
		world.setBlockMetadataWithNotify(i + 1, j + 25, k + 16, 1, 2);
		setBlock(world, i + 1, j + 25, k + 17, Blocks.log, 1);
		world.setBlockMetadataWithNotify(i + 1, j + 25, k + 17, 1, 2);
		setBlock(world, i + 1, j + 25, k + 21, Blocks.log, 1);
		world.setBlockMetadataWithNotify(i + 1, j + 25, k + 21, 1, 2);
		setBlock(world, i + 1, j + 25, k + 25, Blocks.log, 1);
		world.setBlockMetadataWithNotify(i + 1, j + 25, k + 25, 1, 2);
		setBlock(world, i + 1, j + 25, k + 26, Blocks.log, 1);
		world.setBlockMetadataWithNotify(i + 1, j + 25, k + 26, 1, 2);
		setBlock(world, i + 1, j + 25, k + 27, Blocks.log, 1);
		world.setBlockMetadataWithNotify(i + 1, j + 25, k + 27, 1, 2);
		setBlock(world, i + 1, j + 25, k + 28, Blocks.log, 1);
		world.setBlockMetadataWithNotify(i + 1, j + 25, k + 28, 1, 2);
		setBlock(world, i + 1, j + 25, k + 29, Blocks.log, 1);
		world.setBlockMetadataWithNotify(i + 1, j + 25, k + 29, 1, 2);
		setBlock(world, i + 1, j + 25, k + 31, Blocks.log, 3);
		world.setBlockMetadataWithNotify(i + 1, j + 25, k + 31, 3, 2);
		setBlock(world, i + 1, j + 26, k + 13, Blocks.log, 1);
		world.setBlockMetadataWithNotify(i + 1, j + 26, k + 13, 1, 2);
		setBlock(world, i + 1, j + 26, k + 14, Blocks.log, 1);
		world.setBlockMetadataWithNotify(i + 1, j + 26, k + 14, 1, 2);
		setBlock(world, i + 1, j + 26, k + 15, Blocks.log, 1);
		world.setBlockMetadataWithNotify(i + 1, j + 26, k + 15, 1, 2);
		setBlock(world, i + 1, j + 26, k + 16, Blocks.log, 1);
		world.setBlockMetadataWithNotify(i + 1, j + 26, k + 16, 1, 2);
		setBlock(world, i + 1, j + 26, k + 17, Blocks.log, 1);
		world.setBlockMetadataWithNotify(i + 1, j + 26, k + 17, 1, 2);
		setBlock(world, i + 1, j + 26, k + 18, Blocks.log, 1);
		world.setBlockMetadataWithNotify(i + 1, j + 26, k + 18, 1, 2);
		setBlock(world, i + 1, j + 26, k + 20, Blocks.log, 1);
		world.setBlockMetadataWithNotify(i + 1, j + 26, k + 20, 1, 2);
		setBlock(world, i + 1, j + 26, k + 21, Blocks.log, 1);
		world.setBlockMetadataWithNotify(i + 1, j + 26, k + 21, 1, 2);
		setBlock(world, i + 1, j + 26, k + 22, Blocks.log, 1);
		world.setBlockMetadataWithNotify(i + 1, j + 26, k + 22, 1, 2);
		setBlock(world, i + 1, j + 26, k + 24, Blocks.log, 1);
		world.setBlockMetadataWithNotify(i + 1, j + 26, k + 24, 1, 2);
		setBlock(world, i + 1, j + 26, k + 25, Blocks.log, 1);
		world.setBlockMetadataWithNotify(i + 1, j + 26, k + 25, 1, 2);
		setBlock(world, i + 1, j + 26, k + 26, Blocks.log, 1);
		world.setBlockMetadataWithNotify(i + 1, j + 26, k + 26, 1, 2);
		setBlock(world, i + 1, j + 26, k + 27, Blocks.log, 1);
		world.setBlockMetadataWithNotify(i + 1, j + 26, k + 27, 1, 2);
		setBlock(world, i + 1, j + 26, k + 28, Blocks.log, 1);
		world.setBlockMetadataWithNotify(i + 1, j + 26, k + 28, 1, 2);
		setBlock(world, i + 1, j + 26, k + 29, Blocks.log, 1);
		world.setBlockMetadataWithNotify(i + 1, j + 26, k + 29, 1, 2);
		setBlock(world, i + 1, j + 27, k + 14, Blocks.log, 1);
		world.setBlockMetadataWithNotify(i + 1, j + 27, k + 14, 1, 2);
		setBlock(world, i + 1, j + 27, k + 15, Blocks.log, 1);
		world.setBlockMetadataWithNotify(i + 1, j + 27, k + 15, 1, 2);
		setBlock(world, i + 1, j + 27, k + 16, Blocks.log, 1);
		world.setBlockMetadataWithNotify(i + 1, j + 27, k + 16, 1, 2);
		setBlock(world, i + 1, j + 27, k + 17, Blocks.log, 1);
		world.setBlockMetadataWithNotify(i + 1, j + 27, k + 17, 1, 2);
		setBlock(world, i + 1, j + 27, k + 18, Blocks.log, 1);
		world.setBlockMetadataWithNotify(i + 1, j + 27, k + 18, 1, 2);
		setBlock(world, i + 1, j + 27, k + 19, Blocks.log, 1);
		world.setBlockMetadataWithNotify(i + 1, j + 27, k + 19, 1, 2);
		setBlock(world, i + 1, j + 27, k + 20, Blocks.log, 1);
		world.setBlockMetadataWithNotify(i + 1, j + 27, k + 20, 1, 2);
		setBlock(world, i + 1, j + 27, k + 21, Blocks.log, 1);
		world.setBlockMetadataWithNotify(i + 1, j + 27, k + 21, 1, 2);
		setBlock(world, i + 1, j + 27, k + 22, Blocks.log, 1);
		world.setBlockMetadataWithNotify(i + 1, j + 27, k + 22, 1, 2);
		setBlock(world, i + 1, j + 27, k + 23, Blocks.log, 1);
		world.setBlockMetadataWithNotify(i + 1, j + 27, k + 23, 1, 2);
		setBlock(world, i + 1, j + 27, k + 24, Blocks.log, 1);
		world.setBlockMetadataWithNotify(i + 1, j + 27, k + 24, 1, 2);
		setBlock(world, i + 1, j + 27, k + 25, Blocks.log, 1);
		world.setBlockMetadataWithNotify(i + 1, j + 27, k + 25, 1, 2);
		setBlock(world, i + 1, j + 27, k + 26, Blocks.log, 1);
		world.setBlockMetadataWithNotify(i + 1, j + 27, k + 26, 1, 2);
		setBlock(world, i + 1, j + 27, k + 27, Blocks.log, 1);
		world.setBlockMetadataWithNotify(i + 1, j + 27, k + 27, 1, 2);
		setBlock(world, i + 1, j + 27, k + 28, Blocks.log, 1);
		world.setBlockMetadataWithNotify(i + 1, j + 27, k + 28, 1, 2);
		setBlock(world, i + 1, j + 28, k + 15, Blocks.log, 1);
		world.setBlockMetadataWithNotify(i + 1, j + 28, k + 15, 1, 2);
		setBlock(world, i + 1, j + 28, k + 16, Blocks.log, 1);
		world.setBlockMetadataWithNotify(i + 1, j + 28, k + 16, 1, 2);
		setBlock(world, i + 1, j + 28, k + 17, Blocks.log, 1);
		world.setBlockMetadataWithNotify(i + 1, j + 28, k + 17, 1, 2);
		setBlock(world, i + 1, j + 28, k + 18, Blocks.log, 1);
		world.setBlockMetadataWithNotify(i + 1, j + 28, k + 18, 1, 2);
		setBlock(world, i + 1, j + 28, k + 19, Blocks.log, 1);
		world.setBlockMetadataWithNotify(i + 1, j + 28, k + 19, 1, 2);
		setBlock(world, i + 1, j + 28, k + 20, Blocks.log, 1);
		world.setBlockMetadataWithNotify(i + 1, j + 28, k + 20, 1, 2);
		setBlock(world, i + 1, j + 28, k + 21, Blocks.log, 1);
		world.setBlockMetadataWithNotify(i + 1, j + 28, k + 21, 1, 2);
		setBlock(world, i + 1, j + 28, k + 22, Blocks.log, 1);
		world.setBlockMetadataWithNotify(i + 1, j + 28, k + 22, 1, 2);
		setBlock(world, i + 1, j + 28, k + 23, Blocks.log, 1);
		world.setBlockMetadataWithNotify(i + 1, j + 28, k + 23, 1, 2);
		setBlock(world, i + 1, j + 28, k + 24, Blocks.log, 1);
		world.setBlockMetadataWithNotify(i + 1, j + 28, k + 24, 1, 2);
		setBlock(world, i + 1, j + 28, k + 25, Blocks.log, 1);
		/* 1000 */world.setBlockMetadataWithNotify(i + 1, j + 28, k + 25, 1, 2);
		/* 1001 */setBlock(world, i + 1, j + 28, k + 26, Blocks.log, 1);
		/* 1002 */world.setBlockMetadataWithNotify(i + 1, j + 28, k + 26, 1, 2);
		/* 1003 */setBlock(world, i + 1, j + 28, k + 27, Blocks.log, 1);
		/* 1004 */world.setBlockMetadataWithNotify(i + 1, j + 28, k + 27, 1, 2);
		/* 1005 */setBlock(world, i + 1, j + 29, k + 18, Blocks.log, 1);
		/* 1006 */world.setBlockMetadataWithNotify(i + 1, j + 29, k + 18, 1, 2);
		/* 1007 */setBlock(world, i + 1, j + 29, k + 19, Blocks.log, 1);
		/* 1008 */world.setBlockMetadataWithNotify(i + 1, j + 29, k + 19, 1, 2);
		/* 1009 */setBlock(world, i + 1, j + 29, k + 20, Blocks.log, 1);
		/* 1010 */world.setBlockMetadataWithNotify(i + 1, j + 29, k + 20, 1, 2);
		/* 1011 */setBlock(world, i + 1, j + 29, k + 21, Blocks.log, 1);
		/* 1012 */world.setBlockMetadataWithNotify(i + 1, j + 29, k + 21, 1, 2);
		/* 1013 */setBlock(world, i + 1, j + 29, k + 22, Blocks.log, 1);
		/* 1014 */world.setBlockMetadataWithNotify(i + 1, j + 29, k + 22, 1, 2);
		/* 1015 */setBlock(world, i + 1, j + 29, k + 23, Blocks.log, 1);
		/* 1016 */world.setBlockMetadataWithNotify(i + 1, j + 29, k + 23, 1, 2);
		/* 1017 */setBlock(world, i + 1, j + 29, k + 24, Blocks.log, 1);
		/* 1018 */world.setBlockMetadataWithNotify(i + 1, j + 29, k + 24, 1, 2);
		/* 1019 */setBlock(world, i + 1, j + 36, k + 28, Blocks.log, 3);
		/* 1020 */world.setBlockMetadataWithNotify(i + 1, j + 36, k + 28, 3, 2);
		/* 1021 */setBlock(world, i + 1, j + 37, k + 25, Blocks.leaves, 7);
		/* 1022 */world.setBlockMetadataWithNotify(i + 1, j + 37, k + 25, 7, 2);
		/* 1023 */setBlock(world, i + 1, j + 37, k + 26, Blocks.leaves, 7);
		/* 1024 */world.setBlockMetadataWithNotify(i + 1, j + 37, k + 26, 7, 2);
		/* 1025 */setBlock(world, i + 1, j + 37, k + 27, Blocks.log, 3);
		/* 1026 */world.setBlockMetadataWithNotify(i + 1, j + 37, k + 27, 3, 2);
		/* 1027 */setBlock(world, i + 1, j + 37, k + 28, Blocks.leaves, 7);
		/* 1028 */world.setBlockMetadataWithNotify(i + 1, j + 37, k + 28, 7, 2);
		/* 1029 */setBlock(world, i + 1, j + 37, k + 29, Blocks.leaves, 7);
		/* 1030 */world.setBlockMetadataWithNotify(i + 1, j + 37, k + 29, 7, 2);
		/* 1031 */setBlock(world, i + 1, j + 38, k + 25, Blocks.leaves, 7);
		/* 1032 */world.setBlockMetadataWithNotify(i + 1, j + 38, k + 25, 7, 2);
		/* 1033 */setBlock(world, i + 1, j + 38, k + 26, Blocks.leaves, 7);
		/* 1034 */world.setBlockMetadataWithNotify(i + 1, j + 38, k + 26, 7, 2);
		/* 1035 */setBlock(world, i + 1, j + 38, k + 27, Blocks.leaves, 7);
		/* 1036 */world.setBlockMetadataWithNotify(i + 1, j + 38, k + 27, 7, 2);
		/* 1037 */setBlock(world, i + 1, j + 38, k + 28, Blocks.leaves, 7);
		/* 1038 */world.setBlockMetadataWithNotify(i + 1, j + 38, k + 28, 7, 2);
		/* 1039 */setBlock(world, i + 1, j + 38, k + 29, Blocks.leaves, 7);
		/* 1040 */world.setBlockMetadataWithNotify(i + 1, j + 38, k + 29, 7, 2);
		/* 1041 */setBlock(world, i + 1, j + 39, k + 26, Blocks.leaves, 7);
		/* 1042 */world.setBlockMetadataWithNotify(i + 1, j + 39, k + 26, 7, 2);
		/* 1043 */setBlock(world, i + 1, j + 39, k + 27, Blocks.leaves, 7);
		/* 1044 */world.setBlockMetadataWithNotify(i + 1, j + 39, k + 27, 7, 2);
		/* 1045 */setBlock(world, i + 1, j + 39, k + 28, Blocks.leaves, 7);
		/* 1046 */world.setBlockMetadataWithNotify(i + 1, j + 39, k + 28, 7, 2);
		/* 1047 */setBlock(world, i + 1, j + 40, k + 27, Blocks.leaves, 7);
		/* 1048 */world.setBlockMetadataWithNotify(i + 1, j + 40, k + 27, 7, 2);
		/* 1049 */setBlock(world, i + 1, j + 46, k + 19, Blocks.planks, 5);
		/* 1050 */world.setBlockMetadataWithNotify(i + 1, j + 46, k + 19, 5, 2);
		/* 1051 */setBlock(world, i + 1, j + 46, k + 20, Blocks.log, 1);
		/* 1052 */world.setBlockMetadataWithNotify(i + 1, j + 46, k + 20, 1, 2);
		/* 1053 */setBlock(world, i + 1, j + 46, k + 21, Blocks.log, 1);
		/* 1054 */world.setBlockMetadataWithNotify(i + 1, j + 46, k + 21, 1, 2);
		/* 1055 */setBlock(world, i + 1, j + 46, k + 22, Blocks.log, 1);
		/* 1056 */world.setBlockMetadataWithNotify(i + 1, j + 46, k + 22, 1, 2);
		/* 1057 */setBlock(world, i + 1, j + 46, k + 23, Blocks.log, 1);
		/* 1058 */world.setBlockMetadataWithNotify(i + 1, j + 46, k + 23, 1, 2);
		/* 1059 */setBlock(world, i + 1, j + 46, k + 24, Blocks.planks, 5);
		/* 1060 */world.setBlockMetadataWithNotify(i + 1, j + 46, k + 24, 5, 2);
		/* 1061 */setBlock(world, i + 1, j + 48, k + 18, Blocks.spruce_stairs, 4);
		/* 1062 */world.setBlockMetadataWithNotify(i + 1, j + 48, k + 18, 4, 2);
		/* 1063 */setBlock(world, i + 1, j + 48, k + 25, Blocks.spruce_stairs, 4);
		/* 1064 */world.setBlockMetadataWithNotify(i + 1, j + 48, k + 25, 4, 2);
		/* 1065 */setBlock(world, i + 1, j + 49, k + 18, Blocks.log, 1);
		/* 1066 */world.setBlockMetadataWithNotify(i + 1, j + 49, k + 18, 1, 2);
		/* 1067 */setBlock(world, i + 1, j + 49, k + 25, Blocks.log, 1);
		/* 1068 */world.setBlockMetadataWithNotify(i + 1, j + 49, k + 25, 1, 2);
		/* 1069 */setBlock(world, i + 1, j + 50, k + 18, Blocks.log, 1);
		/* 1070 */world.setBlockMetadataWithNotify(i + 1, j + 50, k + 18, 1, 2);
		/* 1071 */setBlock(world, i + 1, j + 50, k + 19, Blocks.spruce_stairs, 7);
		/* 1072 */world.setBlockMetadataWithNotify(i + 1, j + 50, k + 19, 7, 2);
		/* 1073 */setBlock(world, i + 1, j + 50, k + 24, Blocks.spruce_stairs, 6);
		/* 1074 */world.setBlockMetadataWithNotify(i + 1, j + 50, k + 24, 6, 2);
		/* 1075 */setBlock(world, i + 1, j + 50, k + 25, Blocks.log, 1);
		/* 1076 */world.setBlockMetadataWithNotify(i + 1, j + 50, k + 25, 1, 2);
		/* 1077 */setBlock(world, i + 1, j + 51, k + 17, Blocks.log, 1);
		/* 1078 */world.setBlockMetadataWithNotify(i + 1, j + 51, k + 17, 1, 2);
		/* 1079 */setBlock(world, i + 1, j + 51, k + 18, Blocks.log, 1);
		/* 1080 */world.setBlockMetadataWithNotify(i + 1, j + 51, k + 18, 1, 2);
		/* 1081 */setBlock(world, i + 1, j + 51, k + 19, Blocks.log, 1);
		/* 1082 */world.setBlockMetadataWithNotify(i + 1, j + 51, k + 19, 1, 2);
		/* 1083 */setBlock(world, i + 1, j + 51, k + 20, Blocks.log, 1);
		/* 1084 */world.setBlockMetadataWithNotify(i + 1, j + 51, k + 20, 1, 2);
		/* 1085 */setBlock(world, i + 1, j + 51, k + 21, Blocks.log, 1);
		/* 1086 */world.setBlockMetadataWithNotify(i + 1, j + 51, k + 21, 1, 2);
		/* 1087 */setBlock(world, i + 1, j + 51, k + 22, Blocks.log, 1);
		/* 1088 */world.setBlockMetadataWithNotify(i + 1, j + 51, k + 22, 1, 2);
		/* 1089 */setBlock(world, i + 1, j + 51, k + 23, Blocks.log, 1);
		/* 1090 */world.setBlockMetadataWithNotify(i + 1, j + 51, k + 23, 1, 2);
		/* 1091 */setBlock(world, i + 1, j + 51, k + 24, Blocks.log, 1);
		/* 1092 */world.setBlockMetadataWithNotify(i + 1, j + 51, k + 24, 1, 2);
		/* 1093 */setBlock(world, i + 1, j + 51, k + 25, Blocks.log, 1);
		/* 1094 */world.setBlockMetadataWithNotify(i + 1, j + 51, k + 25, 1, 2);
		/* 1095 */setBlock(world, i + 1, j + 51, k + 26, Blocks.log, 1);
		/* 1096 */world.setBlockMetadataWithNotify(i + 1, j + 51, k + 26, 1, 2);
		/* 1097 */setBlock(world, i + 1, j + 52, k + 18, Blocks.log, 1);
		/* 1098 */world.setBlockMetadataWithNotify(i + 1, j + 52, k + 18, 1, 2);
		/* 1099 */setBlock(world, i + 1, j + 52, k + 19, Blocks.log, 1);
		/* 1100 */world.setBlockMetadataWithNotify(i + 1, j + 52, k + 19, 1, 2);
		/* 1101 */setBlock(world, i + 1, j + 52, k + 20, Blocks.log, 1);
		/* 1102 */world.setBlockMetadataWithNotify(i + 1, j + 52, k + 20, 1, 2);
		/* 1103 */setBlock(world, i + 1, j + 52, k + 21, Blocks.log, 1);
		/* 1104 */world.setBlockMetadataWithNotify(i + 1, j + 52, k + 21, 1, 2);
		/* 1105 */setBlock(world, i + 1, j + 52, k + 22, Blocks.log, 1);
		/* 1106 */world.setBlockMetadataWithNotify(i + 1, j + 52, k + 22, 1, 2);
		/* 1107 */setBlock(world, i + 1, j + 52, k + 23, Blocks.log, 1);
		/* 1108 */world.setBlockMetadataWithNotify(i + 1, j + 52, k + 23, 1, 2);
		/* 1109 */setBlock(world, i + 1, j + 52, k + 24, Blocks.log, 1);
		/* 1110 */world.setBlockMetadataWithNotify(i + 1, j + 52, k + 24, 1, 2);
		/* 1111 */setBlock(world, i + 1, j + 52, k + 25, Blocks.log, 1);
		/* 1112 */world.setBlockMetadataWithNotify(i + 1, j + 52, k + 25, 1, 2);
		/* 1113 */setBlock(world, i + 2, j + 10, k + 17, Blocks.vine, 7);
		/* 1114 */world.setBlockMetadataWithNotify(i + 2, j + 10, k + 17, 7, 2);
		/* 1115 */setBlock(world, i + 2, j + 11, k + 17, Blocks.vine, 15);
		/* 1116 */world.setBlockMetadataWithNotify(i + 2, j + 11, k + 17, 15, 2);
		/* 1117 */setBlock(world, i + 2, j + 11, k + 19, Blocks.vine, 4);
		/* 1118 */world.setBlockMetadataWithNotify(i + 2, j + 11, k + 19, 4, 2);
		/* 1119 */setBlock(world, i + 2, j + 12, k + 16, Blocks.vine, 4);
		/* 1120 */world.setBlockMetadataWithNotify(i + 2, j + 12, k + 16, 4, 2);
		/* 1121 */setBlock(world, i + 2, j + 12, k + 17, Blocks.vine, 15);
		/* 1122 */world.setBlockMetadataWithNotify(i + 2, j + 12, k + 17, 15, 2);
		/* 1123 */setBlock(world, i + 2, j + 12, k + 18, Blocks.vine, 15);
		/* 1124 */world.setBlockMetadataWithNotify(i + 2, j + 12, k + 18, 15, 2);
		/* 1125 */setBlock(world, i + 2, j + 12, k + 19, Blocks.vine, 15);
		/* 1126 */world.setBlockMetadataWithNotify(i + 2, j + 12, k + 19, 15, 2);
		/* 1127 */setBlock(world, i + 2, j + 13, k + 16, Blocks.vine, 15);
		/* 1128 */world.setBlockMetadataWithNotify(i + 2, j + 13, k + 16, 15, 2);
		/* 1129 */setBlock(world, i + 2, j + 13, k + 17, Blocks.vine, 15);
		/* 1130 */world.setBlockMetadataWithNotify(i + 2, j + 13, k + 17, 15, 2);
		/* 1131 */setBlock(world, i + 2, j + 13, k + 18, Blocks.vine, 15);
		/* 1132 */world.setBlockMetadataWithNotify(i + 2, j + 13, k + 18, 15, 2);
		/* 1133 */setBlock(world, i + 2, j + 13, k + 19, Blocks.vine, 15);
		/* 1134 */world.setBlockMetadataWithNotify(i + 2, j + 13, k + 19, 15, 2);
		/* 1135 */setBlock(world, i + 2, j + 14, k + 16, Blocks.vine, 15);
		/* 1136 */world.setBlockMetadataWithNotify(i + 2, j + 14, k + 16, 15, 2);
		/* 1137 */setBlock(world, i + 2, j + 14, k + 17, Blocks.vine, 15);
		/* 1138 */world.setBlockMetadataWithNotify(i + 2, j + 14, k + 17, 15, 2);
		/* 1139 */setBlock(world, i + 2, j + 14, k + 18, Blocks.vine, 15);
		/* 1140 */world.setBlockMetadataWithNotify(i + 2, j + 14, k + 18, 15, 2);
		/* 1141 */setBlock(world, i + 2, j + 14, k + 19, Blocks.log, 1);
		/* 1142 */world.setBlockMetadataWithNotify(i + 2, j + 14, k + 19, 1, 2);
		/* 1143 */setBlock(world, i + 2, j + 14, k + 20, Blocks.vine, 15);
		/* 1144 */world.setBlockMetadataWithNotify(i + 2, j + 14, k + 20, 15, 2);
		/* 1145 */setBlock(world, i + 2, j + 15, k + 16, Blocks.vine, 15);
		/* 1146 */world.setBlockMetadataWithNotify(i + 2, j + 15, k + 16, 15, 2);
		/* 1147 */setBlock(world, i + 2, j + 15, k + 17, Blocks.vine, 15);
		/* 1148 */world.setBlockMetadataWithNotify(i + 2, j + 15, k + 17, 15, 2);
		/* 1149 */setBlock(world, i + 2, j + 15, k + 18, Blocks.log, 1);
		/* 1150 */world.setBlockMetadataWithNotify(i + 2, j + 15, k + 18, 1, 2);
		/* 1151 */setBlock(world, i + 2, j + 15, k + 19, Blocks.log, 1);
		/* 1152 */world.setBlockMetadataWithNotify(i + 2, j + 15, k + 19, 1, 2);
		/* 1153 */setBlock(world, i + 2, j + 15, k + 20, Blocks.log, 1);
		/* 1154 */world.setBlockMetadataWithNotify(i + 2, j + 15, k + 20, 1, 2);
		/* 1155 */setBlock(world, i + 2, j + 15, k + 22, Blocks.log, 1);
		/* 1156 */world.setBlockMetadataWithNotify(i + 2, j + 15, k + 22, 1, 2);
		/* 1157 */setBlock(world, i + 2, j + 15, k + 23, Blocks.log, 1);
		/* 1158 */world.setBlockMetadataWithNotify(i + 2, j + 15, k + 23, 1, 2);
		/* 1159 */setBlock(world, i + 2, j + 15, k + 24, Blocks.log, 1);
		/* 1160 */world.setBlockMetadataWithNotify(i + 2, j + 15, k + 24, 1, 2);
		/* 1161 */setBlock(world, i + 2, j + 15, k + 25, Blocks.log, 1);
		/* 1162 */world.setBlockMetadataWithNotify(i + 2, j + 15, k + 25, 1, 2);
		/* 1163 */setBlock(world, i + 2, j + 15, k + 26, Blocks.log, 1);
		/* 1164 */world.setBlockMetadataWithNotify(i + 2, j + 15, k + 26, 1, 2);
		/* 1165 */setBlock(world, i + 2, j + 15, k + 28, Blocks.log, 1);
		/* 1166 */world.setBlockMetadataWithNotify(i + 2, j + 15, k + 28, 1, 2);
		/* 1167 */setBlock(world, i + 2, j + 16, k + 16, Blocks.vine, 15);
		/* 1168 */world.setBlockMetadataWithNotify(i + 2, j + 16, k + 16, 15, 2);
		/* 1169 */setBlock(world, i + 2, j + 16, k + 17, Blocks.vine, 15);
		/* 1170 */world.setBlockMetadataWithNotify(i + 2, j + 16, k + 17, 15, 2);
		/* 1171 */setBlock(world, i + 2, j + 16, k + 18, Blocks.log, 1);
		/* 1172 */world.setBlockMetadataWithNotify(i + 2, j + 16, k + 18, 1, 2);
		/* 1173 */setBlock(world, i + 2, j + 16, k + 19, Blocks.log, 1);
		/* 1174 */world.setBlockMetadataWithNotify(i + 2, j + 16, k + 19, 1, 2);
		/* 1175 */setBlock(world, i + 2, j + 16, k + 20, Blocks.log, 1);
		/* 1176 */world.setBlockMetadataWithNotify(i + 2, j + 16, k + 20, 1, 2);
		/* 1177 */setBlock(world, i + 2, j + 16, k + 23, Blocks.log, 1);
		/* 1178 */world.setBlockMetadataWithNotify(i + 2, j + 16, k + 23, 1, 2);
		/* 1179 */setBlock(world, i + 2, j + 16, k + 24, Blocks.log, 1);
		/* 1180 */world.setBlockMetadataWithNotify(i + 2, j + 16, k + 24, 1, 2);
		/* 1181 */setBlock(world, i + 2, j + 16, k + 25, Blocks.log, 1);
		/* 1182 */world.setBlockMetadataWithNotify(i + 2, j + 16, k + 25, 1, 2);
		/* 1183 */setBlock(world, i + 2, j + 16, k + 26, Blocks.log, 1);
		/* 1184 */world.setBlockMetadataWithNotify(i + 2, j + 16, k + 26, 1, 2);
		/* 1185 */setBlock(world, i + 2, j + 16, k + 28, Blocks.log, 1);
		/* 1186 */world.setBlockMetadataWithNotify(i + 2, j + 16, k + 28, 1, 2);
		/* 1187 */setBlock(world, i + 2, j + 16, k + 29, Blocks.log, 1);
		/* 1188 */world.setBlockMetadataWithNotify(i + 2, j + 16, k + 29, 1, 2);
		/* 1189 */setBlock(world, i + 2, j + 16, k + 31, Blocks.log, 1);
		/* 1190 */world.setBlockMetadataWithNotify(i + 2, j + 16, k + 31, 1, 2);
		/* 1191 */setBlock(world, i + 2, j + 17, k + 12, Blocks.vine, 4);
		/* 1192 */world.setBlockMetadataWithNotify(i + 2, j + 17, k + 12, 4, 2);
		/* 1193 */setBlock(world, i + 2, j + 17, k + 13, Blocks.vine, 6);
		/* 1194 */world.setBlockMetadataWithNotify(i + 2, j + 17, k + 13, 6, 2);
		/* 1195 */setBlock(world, i + 2, j + 17, k + 17, Blocks.vine, 15);
		/* 1196 */world.setBlockMetadataWithNotify(i + 2, j + 17, k + 17, 15, 2);
		/* 1197 */setBlock(world, i + 2, j + 17, k + 18, Blocks.log, 1);
		/* 1198 */world.setBlockMetadataWithNotify(i + 2, j + 17, k + 18, 1, 2);
		/* 1199 */setBlock(world, i + 2, j + 17, k + 19, Blocks.log, 1);
		/* 1200 */world.setBlockMetadataWithNotify(i + 2, j + 17, k + 19, 1, 2);
		/* 1201 */setBlock(world, i + 2, j + 17, k + 20, Blocks.log, 1);
		/* 1202 */world.setBlockMetadataWithNotify(i + 2, j + 17, k + 20, 1, 2);
		/* 1203 */setBlock(world, i + 2, j + 17, k + 23, Blocks.log, 1);
		/* 1204 */world.setBlockMetadataWithNotify(i + 2, j + 17, k + 23, 1, 2);
		/* 1205 */setBlock(world, i + 2, j + 17, k + 24, Blocks.log, 1);
		/* 1206 */world.setBlockMetadataWithNotify(i + 2, j + 17, k + 24, 1, 2);
		/* 1207 */setBlock(world, i + 2, j + 17, k + 25, Blocks.log, 1);
		/* 1208 */world.setBlockMetadataWithNotify(i + 2, j + 17, k + 25, 1, 2);
		/* 1209 */setBlock(world, i + 2, j + 17, k + 26, Blocks.log, 1);
		/* 1210 */world.setBlockMetadataWithNotify(i + 2, j + 17, k + 26, 1, 2);
		/* 1211 */setBlock(world, i + 2, j + 17, k + 27, Blocks.log, 1);
		/* 1212 */world.setBlockMetadataWithNotify(i + 2, j + 17, k + 27, 1, 2);
		/* 1213 */setBlock(world, i + 2, j + 17, k + 28, Blocks.log, 1);
		/* 1214 */world.setBlockMetadataWithNotify(i + 2, j + 17, k + 28, 1, 2);
		/* 1215 */setBlock(world, i + 2, j + 17, k + 29, Blocks.log, 1);
		/* 1216 */world.setBlockMetadataWithNotify(i + 2, j + 17, k + 29, 1, 2);
		/* 1217 */setBlock(world, i + 2, j + 17, k + 30, Blocks.log, 1);
		/* 1218 */world.setBlockMetadataWithNotify(i + 2, j + 17, k + 30, 1, 2);
		/* 1219 */setBlock(world, i + 2, j + 17, k + 31, Blocks.log, 1);
		/* 1220 */world.setBlockMetadataWithNotify(i + 2, j + 17, k + 31, 1, 2);
		/* 1221 */setBlock(world, i + 2, j + 18, k + 11, Blocks.vine, 15);
		/* 1222 */world.setBlockMetadataWithNotify(i + 2, j + 18, k + 11, 15, 2);
		/* 1223 */setBlock(world, i + 2, j + 18, k + 12, Blocks.vine, 13);
		/* 1224 */world.setBlockMetadataWithNotify(i + 2, j + 18, k + 12, 13, 2);
		/* 1225 */setBlock(world, i + 2, j + 18, k + 13, Blocks.vine, 6);
		/* 1226 */world.setBlockMetadataWithNotify(i + 2, j + 18, k + 13, 6, 2);
		/* 1227 */setBlock(world, i + 2, j + 18, k + 17, Blocks.vine, 15);
		/* 1228 */world.setBlockMetadataWithNotify(i + 2, j + 18, k + 17, 15, 2);
		/* 1229 */setBlock(world, i + 2, j + 18, k + 18, Blocks.log, 1);
		/* 1230 */world.setBlockMetadataWithNotify(i + 2, j + 18, k + 18, 1, 2);
		/* 1231 */setBlock(world, i + 2, j + 18, k + 19, Blocks.log, 1);
		/* 1232 */world.setBlockMetadataWithNotify(i + 2, j + 18, k + 19, 1, 2);
		/* 1233 */setBlock(world, i + 2, j + 18, k + 20, Blocks.log, 1);
		/* 1234 */world.setBlockMetadataWithNotify(i + 2, j + 18, k + 20, 1, 2);
		/* 1235 */setBlock(world, i + 2, j + 18, k + 21, Blocks.log, 1);
		/* 1236 */world.setBlockMetadataWithNotify(i + 2, j + 18, k + 21, 1, 2);
		/* 1237 */setBlock(world, i + 2, j + 18, k + 25, Blocks.log, 1);
		/* 1238 */world.setBlockMetadataWithNotify(i + 2, j + 18, k + 25, 1, 2);
		/* 1239 */setBlock(world, i + 2, j + 18, k + 26, Blocks.log, 1);
		/* 1240 */world.setBlockMetadataWithNotify(i + 2, j + 18, k + 26, 1, 2);
		/* 1241 */setBlock(world, i + 2, j + 18, k + 27, Blocks.log, 1);
		/* 1242 */world.setBlockMetadataWithNotify(i + 2, j + 18, k + 27, 1, 2);
		/* 1243 */setBlock(world, i + 2, j + 18, k + 28, Blocks.log, 1);
		/* 1244 */world.setBlockMetadataWithNotify(i + 2, j + 18, k + 28, 1, 2);
		/* 1245 */setBlock(world, i + 2, j + 18, k + 29, Blocks.log, 1);
		/* 1246 */world.setBlockMetadataWithNotify(i + 2, j + 18, k + 29, 1, 2);
		/* 1247 */setBlock(world, i + 2, j + 19, k + 11, Blocks.vine, 15);
		/* 1248 */world.setBlockMetadataWithNotify(i + 2, j + 19, k + 11, 15, 2);
		/* 1249 */setBlock(world, i + 2, j + 19, k + 12, Blocks.vine, 15);
		/* 1250 */world.setBlockMetadataWithNotify(i + 2, j + 19, k + 12, 15, 2);
		/* 1251 */setBlock(world, i + 2, j + 19, k + 13, Blocks.vine, 15);
		/* 1252 */world.setBlockMetadataWithNotify(i + 2, j + 19, k + 13, 15, 2);
		/* 1253 */setBlock(world, i + 2, j + 19, k + 14, Blocks.vine, 15);
		/* 1254 */world.setBlockMetadataWithNotify(i + 2, j + 19, k + 14, 15, 2);
		/* 1255 */setBlock(world, i + 2, j + 19, k + 15, Blocks.vine, 15);
		/* 1256 */world.setBlockMetadataWithNotify(i + 2, j + 19, k + 15, 15, 2);
		/* 1257 */setBlock(world, i + 2, j + 19, k + 16, Blocks.vine, 15);
		/* 1258 */world.setBlockMetadataWithNotify(i + 2, j + 19, k + 16, 15, 2);
		/* 1259 */setBlock(world, i + 2, j + 19, k + 17, Blocks.vine, 15);
		/* 1260 */world.setBlockMetadataWithNotify(i + 2, j + 19, k + 17, 15, 2);
		/* 1261 */setBlock(world, i + 2, j + 19, k + 18, Blocks.log, 1);
		/* 1262 */world.setBlockMetadataWithNotify(i + 2, j + 19, k + 18, 1, 2);
		/* 1263 */setBlock(world, i + 2, j + 19, k + 19, Blocks.log, 1);
		/* 1264 */world.setBlockMetadataWithNotify(i + 2, j + 19, k + 19, 1, 2);
		/* 1265 */setBlock(world, i + 2, j + 19, k + 20, Blocks.log, 1);
		/* 1266 */world.setBlockMetadataWithNotify(i + 2, j + 19, k + 20, 1, 2);
		/* 1267 */setBlock(world, i + 2, j + 19, k + 21, Blocks.log, 1);
		/* 1268 */world.setBlockMetadataWithNotify(i + 2, j + 19, k + 21, 1, 2);
		/* 1269 */setBlock(world, i + 2, j + 19, k + 22, Blocks.log, 1);
		/* 1270 */world.setBlockMetadataWithNotify(i + 2, j + 19, k + 22, 1, 2);
		/* 1271 */setBlock(world, i + 2, j + 19, k + 23, Blocks.log, 1);
		/* 1272 */world.setBlockMetadataWithNotify(i + 2, j + 19, k + 23, 1, 2);
		/* 1273 */setBlock(world, i + 2, j + 19, k + 24, Blocks.log, 1);
		/* 1274 */world.setBlockMetadataWithNotify(i + 2, j + 19, k + 24, 1, 2);
		/* 1275 */setBlock(world, i + 2, j + 19, k + 25, Blocks.log, 1);
		/* 1276 */world.setBlockMetadataWithNotify(i + 2, j + 19, k + 25, 1, 2);
		/* 1277 */setBlock(world, i + 2, j + 19, k + 26, Blocks.log, 1);
		/* 1278 */world.setBlockMetadataWithNotify(i + 2, j + 19, k + 26, 1, 2);
		/* 1279 */setBlock(world, i + 2, j + 19, k + 27, Blocks.log, 1);
		/* 1280 */world.setBlockMetadataWithNotify(i + 2, j + 19, k + 27, 1, 2);
		/* 1281 */setBlock(world, i + 2, j + 19, k + 28, Blocks.log, 1);
		/* 1282 */world.setBlockMetadataWithNotify(i + 2, j + 19, k + 28, 1, 2);
		/* 1283 */setBlock(world, i + 2, j + 19, k + 29, Blocks.log, 1);
		/* 1284 */world.setBlockMetadataWithNotify(i + 2, j + 19, k + 29, 1, 2);
		/* 1285 */setBlock(world, i + 2, j + 20, k + 9, Blocks.planks, 5);
		/* 1286 */world.setBlockMetadataWithNotify(i + 2, j + 20, k + 9, 5, 2);
		/* 1287 */setBlock(world, i + 2, j + 20, k + 10, Blocks.planks, 5);
		/* 1288 */world.setBlockMetadataWithNotify(i + 2, j + 20, k + 10, 5, 2);
		/* 1289 */setBlock(world, i + 2, j + 20, k + 11, Blocks.planks, 5);
		/* 1290 */world.setBlockMetadataWithNotify(i + 2, j + 20, k + 11, 5, 2);
		/* 1291 */setBlock(world, i + 2, j + 20, k + 12, Blocks.planks, 5);
		/* 1292 */world.setBlockMetadataWithNotify(i + 2, j + 20, k + 12, 5, 2);
		/* 1293 */setBlock(world, i + 2, j + 20, k + 13, Blocks.planks, 5);
		/* 1294 */world.setBlockMetadataWithNotify(i + 2, j + 20, k + 13, 5, 2);
		/* 1295 */setBlock(world, i + 2, j + 20, k + 14, Blocks.planks, 5);
		/* 1296 */world.setBlockMetadataWithNotify(i + 2, j + 20, k + 14, 5, 2);
		/* 1297 */setBlock(world, i + 2, j + 20, k + 15, Blocks.log, 1);
		/* 1298 */world.setBlockMetadataWithNotify(i + 2, j + 20, k + 15, 1, 2);
		/* 1299 */setBlock(world, i + 2, j + 20, k + 16, Blocks.planks, 5);
		/* 1300 */world.setBlockMetadataWithNotify(i + 2, j + 20, k + 16, 5, 2);
		/* 1301 */setBlock(world, i + 2, j + 20, k + 17, Blocks.planks, 5);
		/* 1302 */world.setBlockMetadataWithNotify(i + 2, j + 20, k + 17, 5, 2);
		/* 1303 */setBlock(world, i + 2, j + 20, k + 18, Blocks.log, 1);
		/* 1304 */world.setBlockMetadataWithNotify(i + 2, j + 20, k + 18, 1, 2);
		/* 1305 */setBlock(world, i + 2, j + 20, k + 19, Blocks.planks, 5);
		/* 1306 */world.setBlockMetadataWithNotify(i + 2, j + 20, k + 19, 5, 2);
		/* 1307 */setBlock(world, i + 2, j + 20, k + 20, Blocks.planks, 5);
		/* 1308 */world.setBlockMetadataWithNotify(i + 2, j + 20, k + 20, 5, 2);
		/* 1309 */setBlock(world, i + 2, j + 20, k + 21, Blocks.log, 1);
		/* 1310 */world.setBlockMetadataWithNotify(i + 2, j + 20, k + 21, 1, 2);
		/* 1311 */setBlock(world, i + 2, j + 20, k + 22, Blocks.planks, 5);
		/* 1312 */world.setBlockMetadataWithNotify(i + 2, j + 20, k + 22, 5, 2);
		/* 1313 */setBlock(world, i + 2, j + 20, k + 23, Blocks.planks, 5);
		/* 1314 */world.setBlockMetadataWithNotify(i + 2, j + 20, k + 23, 5, 2);
		/* 1315 */setBlock(world, i + 2, j + 20, k + 24, Blocks.log, 1);
		/* 1316 */world.setBlockMetadataWithNotify(i + 2, j + 20, k + 24, 1, 2);
		/* 1317 */setBlock(world, i + 2, j + 20, k + 25, Blocks.planks, 5);
		/* 1318 */world.setBlockMetadataWithNotify(i + 2, j + 20, k + 25, 5, 2);
		/* 1319 */setBlock(world, i + 2, j + 20, k + 26, Blocks.planks, 5);
		/* 1320 */world.setBlockMetadataWithNotify(i + 2, j + 20, k + 26, 5, 2);
		/* 1321 */setBlock(world, i + 2, j + 20, k + 27, Blocks.log, 1);
		/* 1322 */world.setBlockMetadataWithNotify(i + 2, j + 20, k + 27, 1, 2);
		/* 1323 */setBlock(world, i + 2, j + 21, k + 20, Blocks.chest, 5);
		/* 1324 */LootGenUtils.fillLootChest(world.provider.dimensionId, world.rand, (TileEntityChest)world.getTileEntity(i + 2, j + 21, k + 20));
		/* 1325 */world.setBlockMetadataWithNotify(i + 2, j + 21, k + 20, 5, 2);
		/* 1326 */setBlock(world, i + 2, j + 21, k + 21, Blocks.spruce_stairs, 1);
		/* 1327 */world.setBlockMetadataWithNotify(i + 2, j + 21, k + 21, 1, 2);
		/* 1328 */setBlock(world, i + 2, j + 21, k + 22, Blocks.chest, 5);
		/* 1329 */LootGenUtils.fillLootChest(world.provider.dimensionId, world.rand, (TileEntityChest)world.getTileEntity(i + 2, j + 21, k + 22));
		/* 1330 */world.setBlockMetadataWithNotify(i + 2, j + 21, k + 22, 5, 2);
		/* 1331 */setBlock(world, i + 2, j + 23, k + 13, Blocks.torch, 2);
		/* 1332 */world.setBlockMetadataWithNotify(i + 2, j + 23, k + 13, 2, 2);
		/* 1333 */setBlock(world, i + 2, j + 23, k + 21, Blocks.torch, 1);
		/* 1334 */world.setBlockMetadataWithNotify(i + 2, j + 23, k + 21, 1, 2);
		/* 1335 */setBlock(world, i + 2, j + 23, k + 29, Blocks.torch, 2);
		/* 1336 */world.setBlockMetadataWithNotify(i + 2, j + 23, k + 29, 2, 2);
		/* 1337 */setBlock(world, i + 2, j + 24, k + 12, Blocks.log, 1);
		/* 1338 */world.setBlockMetadataWithNotify(i + 2, j + 24, k + 12, 1, 2);
		/* 1339 */setBlock(world, i + 2, j + 24, k + 13, Blocks.log, 1);
		/* 1340 */world.setBlockMetadataWithNotify(i + 2, j + 24, k + 13, 1, 2);
		/* 1341 */setBlock(world, i + 2, j + 24, k + 14, Blocks.log, 1);
		/* 1342 */world.setBlockMetadataWithNotify(i + 2, j + 24, k + 14, 1, 2);
		/* 1343 */setBlock(world, i + 2, j + 24, k + 15, Blocks.log, 1);
		/* 1344 */world.setBlockMetadataWithNotify(i + 2, j + 24, k + 15, 1, 2);
		/* 1345 */setBlock(world, i + 2, j + 24, k + 16, Blocks.log, 1);
		/* 1346 */world.setBlockMetadataWithNotify(i + 2, j + 24, k + 16, 1, 2);
		/* 1347 */setBlock(world, i + 2, j + 24, k + 26, Blocks.log, 1);
		/* 1348 */world.setBlockMetadataWithNotify(i + 2, j + 24, k + 26, 1, 2);
		/* 1349 */setBlock(world, i + 2, j + 24, k + 27, Blocks.log, 1);
		/* 1350 */world.setBlockMetadataWithNotify(i + 2, j + 24, k + 27, 1, 2);
		/* 1351 */setBlock(world, i + 2, j + 24, k + 28, Blocks.log, 1);
		/* 1352 */world.setBlockMetadataWithNotify(i + 2, j + 24, k + 28, 1, 2);
		/* 1353 */setBlock(world, i + 2, j + 24, k + 29, Blocks.log, 1);
		/* 1354 */world.setBlockMetadataWithNotify(i + 2, j + 24, k + 29, 1, 2);
		/* 1355 */setBlock(world, i + 2, j + 24, k + 30, Blocks.log, 1);
		/* 1356 */world.setBlockMetadataWithNotify(i + 2, j + 24, k + 30, 1, 2);
		/* 1357 */setBlock(world, i + 2, j + 25, k + 13, Blocks.log, 1);
		/* 1358 */world.setBlockMetadataWithNotify(i + 2, j + 25, k + 13, 1, 2);
		/* 1359 */setBlock(world, i + 2, j + 25, k + 14, Blocks.log, 1);
		/* 1360 */world.setBlockMetadataWithNotify(i + 2, j + 25, k + 14, 1, 2);
		/* 1361 */setBlock(world, i + 2, j + 25, k + 15, Blocks.log, 1);
		/* 1362 */world.setBlockMetadataWithNotify(i + 2, j + 25, k + 15, 1, 2);
		/* 1363 */setBlock(world, i + 2, j + 25, k + 16, Blocks.log, 1);
		/* 1364 */world.setBlockMetadataWithNotify(i + 2, j + 25, k + 16, 1, 2);
		/* 1365 */setBlock(world, i + 2, j + 25, k + 17, Blocks.log, 1);
		/* 1366 */world.setBlockMetadataWithNotify(i + 2, j + 25, k + 17, 1, 2);
		/* 1367 */setBlock(world, i + 2, j + 25, k + 25, Blocks.log, 1);
		/* 1368 */world.setBlockMetadataWithNotify(i + 2, j + 25, k + 25, 1, 2);
		/* 1369 */setBlock(world, i + 2, j + 25, k + 26, Blocks.log, 1);
		/* 1370 */world.setBlockMetadataWithNotify(i + 2, j + 25, k + 26, 1, 2);
		/* 1371 */setBlock(world, i + 2, j + 25, k + 27, Blocks.log, 1);
		/* 1372 */world.setBlockMetadataWithNotify(i + 2, j + 25, k + 27, 1, 2);
		/* 1373 */setBlock(world, i + 2, j + 25, k + 28, Blocks.log, 1);
		/* 1374 */world.setBlockMetadataWithNotify(i + 2, j + 25, k + 28, 1, 2);
		/* 1375 */setBlock(world, i + 2, j + 25, k + 29, Blocks.log, 1);
		/* 1376 */world.setBlockMetadataWithNotify(i + 2, j + 25, k + 29, 1, 2);
		/* 1377 */setBlock(world, i + 2, j + 26, k + 13, Blocks.log, 1);
		/* 1378 */world.setBlockMetadataWithNotify(i + 2, j + 26, k + 13, 1, 2);
		/* 1379 */setBlock(world, i + 2, j + 26, k + 14, Blocks.log, 1);
		/* 1380 */world.setBlockMetadataWithNotify(i + 2, j + 26, k + 14, 1, 2);
		/* 1381 */setBlock(world, i + 2, j + 26, k + 15, Blocks.log, 1);
		/* 1382 */world.setBlockMetadataWithNotify(i + 2, j + 26, k + 15, 1, 2);
		/* 1383 */setBlock(world, i + 2, j + 26, k + 16, Blocks.log, 1);
		/* 1384 */world.setBlockMetadataWithNotify(i + 2, j + 26, k + 16, 1, 2);
		/* 1385 */setBlock(world, i + 2, j + 26, k + 17, Blocks.log, 1);
		/* 1386 */world.setBlockMetadataWithNotify(i + 2, j + 26, k + 17, 1, 2);
		/* 1387 */setBlock(world, i + 2, j + 26, k + 18, Blocks.log, 1);
		/* 1388 */world.setBlockMetadataWithNotify(i + 2, j + 26, k + 18, 1, 2);
		/* 1389 */setBlock(world, i + 2, j + 26, k + 20, Blocks.log, 1);
		/* 1390 */world.setBlockMetadataWithNotify(i + 2, j + 26, k + 20, 1, 2);
		/* 1391 */setBlock(world, i + 2, j + 26, k + 21, Blocks.log, 1);
		/* 1392 */world.setBlockMetadataWithNotify(i + 2, j + 26, k + 21, 1, 2);
		/* 1393 */setBlock(world, i + 2, j + 26, k + 22, Blocks.log, 1);
		/* 1394 */world.setBlockMetadataWithNotify(i + 2, j + 26, k + 22, 1, 2);
		/* 1395 */setBlock(world, i + 2, j + 26, k + 24, Blocks.log, 1);
		/* 1396 */world.setBlockMetadataWithNotify(i + 2, j + 26, k + 24, 1, 2);
		/* 1397 */setBlock(world, i + 2, j + 26, k + 25, Blocks.log, 1);
		/* 1398 */world.setBlockMetadataWithNotify(i + 2, j + 26, k + 25, 1, 2);
		/* 1399 */setBlock(world, i + 2, j + 26, k + 26, Blocks.log, 1);
		/* 1400 */world.setBlockMetadataWithNotify(i + 2, j + 26, k + 26, 1, 2);
		/* 1401 */setBlock(world, i + 2, j + 26, k + 27, Blocks.log, 1);
		/* 1402 */world.setBlockMetadataWithNotify(i + 2, j + 26, k + 27, 1, 2);
		/* 1403 */setBlock(world, i + 2, j + 26, k + 28, Blocks.log, 1);
		/* 1404 */world.setBlockMetadataWithNotify(i + 2, j + 26, k + 28, 1, 2);
		/* 1405 */setBlock(world, i + 2, j + 26, k + 29, Blocks.log, 1);
		/* 1406 */world.setBlockMetadataWithNotify(i + 2, j + 26, k + 29, 1, 2);
		/* 1407 */setBlock(world, i + 2, j + 27, k + 14, Blocks.log, 1);
		/* 1408 */world.setBlockMetadataWithNotify(i + 2, j + 27, k + 14, 1, 2);
		/* 1409 */setBlock(world, i + 2, j + 27, k + 15, Blocks.log, 1);
		/* 1410 */world.setBlockMetadataWithNotify(i + 2, j + 27, k + 15, 1, 2);
		/* 1411 */setBlock(world, i + 2, j + 27, k + 16, Blocks.log, 1);
		/* 1412 */world.setBlockMetadataWithNotify(i + 2, j + 27, k + 16, 1, 2);
		/* 1413 */setBlock(world, i + 2, j + 27, k + 17, Blocks.log, 1);
		/* 1414 */world.setBlockMetadataWithNotify(i + 2, j + 27, k + 17, 1, 2);
		/* 1415 */setBlock(world, i + 2, j + 27, k + 18, Blocks.log, 1);
		/* 1416 */world.setBlockMetadataWithNotify(i + 2, j + 27, k + 18, 1, 2);
		/* 1417 */setBlock(world, i + 2, j + 27, k + 19, Blocks.log, 1);
		/* 1418 */world.setBlockMetadataWithNotify(i + 2, j + 27, k + 19, 1, 2);
		/* 1419 */setBlock(world, i + 2, j + 27, k + 20, Blocks.log, 1);
		/* 1420 */world.setBlockMetadataWithNotify(i + 2, j + 27, k + 20, 1, 2);
		/* 1421 */setBlock(world, i + 2, j + 27, k + 21, Blocks.log, 1);
		/* 1422 */world.setBlockMetadataWithNotify(i + 2, j + 27, k + 21, 1, 2);
		/* 1423 */setBlock(world, i + 2, j + 27, k + 22, Blocks.log, 1);
		/* 1424 */world.setBlockMetadataWithNotify(i + 2, j + 27, k + 22, 1, 2);
		/* 1425 */setBlock(world, i + 2, j + 27, k + 23, Blocks.log, 1);
		/* 1426 */world.setBlockMetadataWithNotify(i + 2, j + 27, k + 23, 1, 2);
		/* 1427 */setBlock(world, i + 2, j + 27, k + 24, Blocks.log, 1);
		/* 1428 */world.setBlockMetadataWithNotify(i + 2, j + 27, k + 24, 1, 2);
		/* 1429 */setBlock(world, i + 2, j + 27, k + 25, Blocks.log, 1);
		/* 1430 */world.setBlockMetadataWithNotify(i + 2, j + 27, k + 25, 1, 2);
		/* 1431 */setBlock(world, i + 2, j + 27, k + 26, Blocks.log, 1);
		/* 1432 */world.setBlockMetadataWithNotify(i + 2, j + 27, k + 26, 1, 2);
		/* 1433 */setBlock(world, i + 2, j + 27, k + 27, Blocks.log, 1);
		/* 1434 */world.setBlockMetadataWithNotify(i + 2, j + 27, k + 27, 1, 2);
		/* 1435 */setBlock(world, i + 2, j + 27, k + 28, Blocks.log, 1);
		/* 1436 */world.setBlockMetadataWithNotify(i + 2, j + 27, k + 28, 1, 2);
		/* 1437 */setBlock(world, i + 2, j + 28, k + 15, Blocks.log, 1);
		/* 1438 */world.setBlockMetadataWithNotify(i + 2, j + 28, k + 15, 1, 2);
		/* 1439 */setBlock(world, i + 2, j + 28, k + 16, Blocks.log, 1);
		/* 1440 */world.setBlockMetadataWithNotify(i + 2, j + 28, k + 16, 1, 2);
		/* 1441 */setBlock(world, i + 2, j + 28, k + 17, Blocks.log, 1);
		/* 1442 */world.setBlockMetadataWithNotify(i + 2, j + 28, k + 17, 1, 2);
		/* 1443 */setBlock(world, i + 2, j + 28, k + 18, Blocks.log, 1);
		/* 1444 */world.setBlockMetadataWithNotify(i + 2, j + 28, k + 18, 1, 2);
		/* 1445 */setBlock(world, i + 2, j + 28, k + 19, Blocks.log, 1);
		/* 1446 */world.setBlockMetadataWithNotify(i + 2, j + 28, k + 19, 1, 2);
		/* 1447 */setBlock(world, i + 2, j + 28, k + 20, Blocks.log, 1);
		/* 1448 */world.setBlockMetadataWithNotify(i + 2, j + 28, k + 20, 1, 2);
		/* 1449 */setBlock(world, i + 2, j + 28, k + 21, Blocks.log, 1);
		/* 1450 */world.setBlockMetadataWithNotify(i + 2, j + 28, k + 21, 1, 2);
		/* 1451 */setBlock(world, i + 2, j + 28, k + 22, Blocks.log, 1);
		/* 1452 */world.setBlockMetadataWithNotify(i + 2, j + 28, k + 22, 1, 2);
		/* 1453 */setBlock(world, i + 2, j + 28, k + 23, Blocks.log, 1);
		/* 1454 */world.setBlockMetadataWithNotify(i + 2, j + 28, k + 23, 1, 2);
		/* 1455 */setBlock(world, i + 2, j + 28, k + 24, Blocks.log, 1);
		/* 1456 */world.setBlockMetadataWithNotify(i + 2, j + 28, k + 24, 1, 2);
		/* 1457 */setBlock(world, i + 2, j + 28, k + 25, Blocks.log, 1);
		/* 1458 */world.setBlockMetadataWithNotify(i + 2, j + 28, k + 25, 1, 2);
		/* 1459 */setBlock(world, i + 2, j + 28, k + 26, Blocks.log, 1);
		/* 1460 */world.setBlockMetadataWithNotify(i + 2, j + 28, k + 26, 1, 2);
		/* 1461 */setBlock(world, i + 2, j + 28, k + 27, Blocks.log, 1);
		/* 1462 */world.setBlockMetadataWithNotify(i + 2, j + 28, k + 27, 1, 2);
		/* 1463 */setBlock(world, i + 2, j + 29, k + 18, Blocks.log, 1);
		/* 1464 */world.setBlockMetadataWithNotify(i + 2, j + 29, k + 18, 1, 2);
		/* 1465 */setBlock(world, i + 2, j + 29, k + 19, Blocks.log, 1);
		/* 1466 */world.setBlockMetadataWithNotify(i + 2, j + 29, k + 19, 1, 2);
		/* 1467 */setBlock(world, i + 2, j + 29, k + 20, Blocks.log, 1);
		/* 1468 */world.setBlockMetadataWithNotify(i + 2, j + 29, k + 20, 1, 2);
		/* 1469 */setBlock(world, i + 2, j + 29, k + 21, Blocks.log, 1);
		/* 1470 */world.setBlockMetadataWithNotify(i + 2, j + 29, k + 21, 1, 2);
		/* 1471 */setBlock(world, i + 2, j + 29, k + 22, Blocks.log, 1);
		/* 1472 */world.setBlockMetadataWithNotify(i + 2, j + 29, k + 22, 1, 2);
		/* 1473 */setBlock(world, i + 2, j + 29, k + 23, Blocks.log, 1);
		/* 1474 */world.setBlockMetadataWithNotify(i + 2, j + 29, k + 23, 1, 2);
		/* 1475 */setBlock(world, i + 2, j + 29, k + 24, Blocks.log, 1);
		/* 1476 */world.setBlockMetadataWithNotify(i + 2, j + 29, k + 24, 1, 2);
		/* 1477 */setBlock(world, i + 2, j + 36, k + 23, Blocks.leaves, 7);
		/* 1478 */world.setBlockMetadataWithNotify(i + 2, j + 36, k + 23, 7, 2);
		/* 1479 */setBlock(world, i + 2, j + 36, k + 24, Blocks.leaves, 7);
		/* 1480 */world.setBlockMetadataWithNotify(i + 2, j + 36, k + 24, 7, 2);
		/* 1481 */setBlock(world, i + 2, j + 36, k + 25, Blocks.leaves, 7);
		/* 1482 */world.setBlockMetadataWithNotify(i + 2, j + 36, k + 25, 7, 2);
		/* 1483 */setBlock(world, i + 2, j + 36, k + 29, Blocks.log, 3);
		/* 1484 */world.setBlockMetadataWithNotify(i + 2, j + 36, k + 29, 3, 2);
		/* 1485 */setBlock(world, i + 2, j + 36, k + 30, Blocks.log, 3);
		/* 1486 */world.setBlockMetadataWithNotify(i + 2, j + 36, k + 30, 3, 2);
		/* 1487 */setBlock(world, i + 2, j + 37, k + 24, Blocks.leaves, 7);
		/* 1488 */world.setBlockMetadataWithNotify(i + 2, j + 37, k + 24, 7, 2);
		/* 1489 */setBlock(world, i + 2, j + 37, k + 25, Blocks.leaves, 7);
		/* 1490 */world.setBlockMetadataWithNotify(i + 2, j + 37, k + 25, 7, 2);
		/* 1491 */setBlock(world, i + 2, j + 37, k + 26, Blocks.leaves, 7);
		/* 1492 */world.setBlockMetadataWithNotify(i + 2, j + 37, k + 26, 7, 2);
		/* 1493 */setBlock(world, i + 2, j + 37, k + 27, Blocks.leaves, 7);
		/* 1494 */world.setBlockMetadataWithNotify(i + 2, j + 37, k + 27, 7, 2);
		/* 1495 */setBlock(world, i + 2, j + 37, k + 28, Blocks.leaves, 7);
		/* 1496 */world.setBlockMetadataWithNotify(i + 2, j + 37, k + 28, 7, 2);
		/* 1497 */setBlock(world, i + 2, j + 37, k + 29, Blocks.leaves, 7);
		/* 1498 */world.setBlockMetadataWithNotify(i + 2, j + 37, k + 29, 7, 2);
		/* 1499 */setBlock(world, i + 2, j + 38, k + 26, Blocks.leaves, 7);
		/* 1500 */world.setBlockMetadataWithNotify(i + 2, j + 38, k + 26, 7, 2);
		/* 1501 */setBlock(world, i + 2, j + 38, k + 27, Blocks.leaves, 7);
		/* 1502 */world.setBlockMetadataWithNotify(i + 2, j + 38, k + 27, 7, 2);
		/* 1503 */setBlock(world, i + 2, j + 38, k + 28, Blocks.leaves, 7);
		/* 1504 */world.setBlockMetadataWithNotify(i + 2, j + 38, k + 28, 7, 2);
		/* 1505 */setBlock(world, i + 2, j + 39, k + 27, Blocks.leaves, 7);
		/* 1506 */world.setBlockMetadataWithNotify(i + 2, j + 39, k + 27, 7, 2);
		/* 1507 */setBlock(world, i + 2, j + 46, k + 19, Blocks.log, 1);
		/* 1508 */world.setBlockMetadataWithNotify(i + 2, j + 46, k + 19, 1, 2);
		/* 1509 */setBlock(world, i + 2, j + 46, k + 20, Blocks.log, 1);
		/* 1510 */world.setBlockMetadataWithNotify(i + 2, j + 46, k + 20, 1, 2);
		/* 1511 */setBlock(world, i + 2, j + 46, k + 21, Blocks.log, 1);
		/* 1512 */world.setBlockMetadataWithNotify(i + 2, j + 46, k + 21, 1, 2);
		/* 1513 */setBlock(world, i + 2, j + 46, k + 22, Blocks.log, 1);
		/* 1514 */world.setBlockMetadataWithNotify(i + 2, j + 46, k + 22, 1, 2);
		/* 1515 */setBlock(world, i + 2, j + 46, k + 23, Blocks.log, 1);
		/* 1516 */world.setBlockMetadataWithNotify(i + 2, j + 46, k + 23, 1, 2);
		/* 1517 */setBlock(world, i + 2, j + 46, k + 24, Blocks.log, 1);
		/* 1518 */world.setBlockMetadataWithNotify(i + 2, j + 46, k + 24, 1, 2);
		/* 1519 */setBlock(world, i + 2, j + 47, k + 18, Blocks.spruce_stairs, 4);
		/* 1520 */world.setBlockMetadataWithNotify(i + 2, j + 47, k + 18, 4, 2);
		/* 1521 */setBlock(world, i + 2, j + 47, k + 25, Blocks.spruce_stairs, 4);
		/* 1522 */world.setBlockMetadataWithNotify(i + 2, j + 47, k + 25, 4, 2);
		/* 1523 */setBlock(world, i + 2, j + 48, k + 18, Blocks.log, 1);
		/* 1524 */world.setBlockMetadataWithNotify(i + 2, j + 48, k + 18, 1, 2);
		/* 1525 */setBlock(world, i + 2, j + 48, k + 25, Blocks.log, 1);
		/* 1526 */world.setBlockMetadataWithNotify(i + 2, j + 48, k + 25, 1, 2);
		/* 1527 */setBlock(world, i + 2, j + 49, k + 18, Blocks.log, 1);
		/* 1528 */world.setBlockMetadataWithNotify(i + 2, j + 49, k + 18, 1, 2);
		/* 1529 */setBlock(world, i + 2, j + 49, k + 19, Blocks.torch, 3);
		/* 1530 */world.setBlockMetadataWithNotify(i + 2, j + 49, k + 19, 3, 2);
		/* 1531 */setBlock(world, i + 2, j + 49, k + 24, Blocks.torch, 4);
		/* 1532 */world.setBlockMetadataWithNotify(i + 2, j + 49, k + 24, 4, 2);
		/* 1533 */setBlock(world, i + 2, j + 49, k + 25, Blocks.log, 1);
		/* 1534 */world.setBlockMetadataWithNotify(i + 2, j + 49, k + 25, 1, 2);
		/* 1535 */setBlock(world, i + 2, j + 51, k + 16, Blocks.log, 1);
		/* 1536 */world.setBlockMetadataWithNotify(i + 2, j + 51, k + 16, 1, 2);
		/* 1537 */setBlock(world, i + 2, j + 51, k + 17, Blocks.log, 1);
		/* 1538 */world.setBlockMetadataWithNotify(i + 2, j + 51, k + 17, 1, 2);
		/* 1539 */setBlock(world, i + 2, j + 51, k + 18, Blocks.log, 1);
		/* 1540 */world.setBlockMetadataWithNotify(i + 2, j + 51, k + 18, 1, 2);
		/* 1541 */setBlock(world, i + 2, j + 51, k + 19, Blocks.log, 1);
		/* 1542 */world.setBlockMetadataWithNotify(i + 2, j + 51, k + 19, 1, 2);
		/* 1543 */setBlock(world, i + 2, j + 51, k + 20, Blocks.log, 1);
		/* 1544 */world.setBlockMetadataWithNotify(i + 2, j + 51, k + 20, 1, 2);
		/* 1545 */setBlock(world, i + 2, j + 51, k + 21, Blocks.log, 1);
		/* 1546 */world.setBlockMetadataWithNotify(i + 2, j + 51, k + 21, 1, 2);
		/* 1547 */setBlock(world, i + 2, j + 51, k + 22, Blocks.log, 1);
		/* 1548 */world.setBlockMetadataWithNotify(i + 2, j + 51, k + 22, 1, 2);
		/* 1549 */setBlock(world, i + 2, j + 51, k + 23, Blocks.log, 1);
		/* 1550 */world.setBlockMetadataWithNotify(i + 2, j + 51, k + 23, 1, 2);
		/* 1551 */setBlock(world, i + 2, j + 51, k + 24, Blocks.log, 1);
		/* 1552 */world.setBlockMetadataWithNotify(i + 2, j + 51, k + 24, 1, 2);
		/* 1553 */setBlock(world, i + 2, j + 51, k + 25, Blocks.log, 1);
		/* 1554 */world.setBlockMetadataWithNotify(i + 2, j + 51, k + 25, 1, 2);
		/* 1555 */setBlock(world, i + 2, j + 51, k + 26, Blocks.log, 1);
		/* 1556 */world.setBlockMetadataWithNotify(i + 2, j + 51, k + 26, 1, 2);
		/* 1557 */setBlock(world, i + 2, j + 51, k + 27, Blocks.log, 1);
		/* 1558 */world.setBlockMetadataWithNotify(i + 2, j + 51, k + 27, 1, 2);
		/* 1559 */setBlock(world, i + 2, j + 52, k + 17, Blocks.log, 1);
		/* 1560 */world.setBlockMetadataWithNotify(i + 2, j + 52, k + 17, 1, 2);
		/* 1561 */setBlock(world, i + 2, j + 52, k + 18, Blocks.log, 1);
		/* 1562 */world.setBlockMetadataWithNotify(i + 2, j + 52, k + 18, 1, 2);
		/* 1563 */setBlock(world, i + 2, j + 52, k + 19, Blocks.log, 1);
		/* 1564 */world.setBlockMetadataWithNotify(i + 2, j + 52, k + 19, 1, 2);
