package com.parzivail.pswm.world.gen.wookietree;




import com.parzivail.pswm.utils.LootGenUtils;
import com.parzivail.pswm.utils.NPCType;
import com.parzivail.pswm.utils.SpawnUtils;



import cpw.mods.fml.common.IWorldGenerator;



import java.util.Random;



import net.minecraft.block.Block;

import net.minecraft.init.Blocks;

import net.minecraft.tileentity.TileEntityChest;

import net.minecraft.world.World;

import net.minecraft.world.WorldProvider;

import net.minecraft.world.chunk.IChunkProvider;

import net.minecraft.world.gen.feature.WorldGenerator;


public class WT_41
extends WorldGenerator implements IWorldGenerator

{
	protected Block[] getValidSpawnBlocks()
	
	{
		return new Block[0];
		}

	
	public boolean locationIsValidSpawn(World world, int i, int j, int k)
	
	{
		int distanceToAir = 0;
		Block check = world.getBlock(i, j, k);
		
		while (check != Blocks.air)
		{
			if (distanceToAir > 3) { return false;
			}
			
			distanceToAir++;
			check = world.getBlock(i, j + distanceToAir, k);
			}
		
		j += distanceToAir - 1;
		
		Block block = world.getBlock(i, j, k);
		Block blockAbove = world.getBlock(i, j + 1, k);
		Block blockBelow = world.getBlock(i, j - 1, k);
		
		for (Block x : getValidSpawnBlocks())
		{
			if (blockAbove != Blocks.air) { return false;
			}
			if (block == x) return true;
			if ((block == Blocks.snow) && (blockBelow == x)) { return true;
			}
			}
		
		return false;
		}

	
	
	
	public void generate(Random random, int chunkX, int chunkZ, World world, IChunkProvider chunkGenerator, IChunkProvider chunkProvider)
	{
	}

	
	
	public void setBlock(World world, int x, int y, int z, Block block, int metadata)
	
	{
		world.setBlock(x, y, z, block, metadata, 2);
		}

	
	public boolean generate(World world, Random rand, int i, int j, int k)
	
	{
		k -= 10;
		i -= 10;
		
		setBlock(world, i + 0, j + 44, k + 3, Blocks.fence, 0);
		setBlock(world, i + 0, j + 44, k + 4, Blocks.fence, 0);
		setBlock(world, i + 0, j + 44, k + 5, Blocks.fence, 0);
		setBlock(world, i + 0, j + 47, k + 8, Blocks.fence, 0);
		setBlock(world, i + 0, j + 47, k + 9, Blocks.fence, 0);
		setBlock(world, i + 1, j + 30, k + 0, Blocks.fence, 0);
		setBlock(world, i + 1, j + 30, k + 6, Blocks.fence, 0);
		setBlock(world, i + 1, j + 44, k + 5, Blocks.fence, 0);
		setBlock(world, i + 1, j + 44, k + 6, Blocks.fence, 0);
		setBlock(world, i + 1, j + 44, k + 7, Blocks.fence, 0);
		setBlock(world, i + 1, j + 47, k + 9, Blocks.fence, 0);
		setBlock(world, i + 1, j + 47, k + 10, Blocks.fence, 0);
		setBlock(world, i + 2, j + 30, k + 0, Blocks.fence, 0);
		setBlock(world, i + 2, j + 30, k + 6, Blocks.fence, 0);
		SpawnUtils.spawnNPC(NPCType.WOOKIETREE, world, i + 3, j + 44, k + 1);
		setBlock(world, i + 4, j + 28, k + 0, Blocks.fence, 0);
		setBlock(world, i + 4, j + 28, k + 6, Blocks.fence, 0);
		setBlock(world, i + 4, j + 28, k + 7, Blocks.fence, 0);
		setBlock(world, i + 5, j + 28, k + 7, Blocks.fence, 0);
		setBlock(world, i + 5, j + 28, k + 8, Blocks.fence, 0);
		SpawnUtils.spawnNPC(NPCType.WOOKIETREE, world, i + 6, j + 28, k + 3);
		setBlock(world, i + 6, j + 28, k + 8, Blocks.fence, 0);
		setBlock(world, i + 6, j + 28, k + 9, Blocks.spruce_stairs, 0);
		setBlock(world, i + 6, j + 30, k + 10, Blocks.fence, 0);
		setBlock(world, i + 6, j + 30, k + 11, Blocks.fence, 0);
		setBlock(world, i + 7, j + 44, k + 0, Blocks.crafting_table, 0);
		setBlock(world, i + 8, j + 28, k + 3, Blocks.spruce_stairs, 0);
		SpawnUtils.spawnNPC(NPCType.WOOKIETREE, world, i + 8, j + 44, k + 1);
		setBlock(world, i + 8, j + 44, k + 8, Blocks.spruce_stairs, 0);
		SpawnUtils.spawnNPC(NPCType.WOOKIETREE, world, i + 9, j + 28, k + 0);
		SpawnUtils.spawnNPC(NPCType.WOOKIETREE, world, i + 9, j + 28, k + 6);
		setBlock(world, i + 10, j + 28, k + 4, Blocks.crafting_table, 0);
		setBlock(world, i + 10, j + 44, k + 5, Blocks.fence, 0);
		setBlock(world, i + 10, j + 44, k + 6, Blocks.fence, 0);
		setBlock(world, i + 10, j + 44, k + 7, Blocks.fence, 0);
		setBlock(world, i + 10, j + 47, k + 9, Blocks.fence, 0);
		setBlock(world, i + 10, j + 47, k + 10, Blocks.fence, 0);
		setBlock(world, i + 11, j + 44, k + 2, Blocks.spruce_stairs, 0);
		setBlock(world, i + 11, j + 44, k + 3, Blocks.fence, 0);
		setBlock(world, i + 11, j + 44, k + 4, Blocks.fence, 0);
		setBlock(world, i + 11, j + 44, k + 5, Blocks.fence, 0);
		setBlock(world, i + 11, j + 47, k + 8, Blocks.fence, 0);
		setBlock(world, i + 11, j + 47, k + 9, Blocks.fence, 0);
		SpawnUtils.spawnNPC(NPCType.WOOKIETREE, world, i + 12, j + 28, k + 3);
		setBlock(world, i + 12, j + 28, k + 8, Blocks.fence, 0);
		setBlock(world, i + 12, j + 30, k + 10, Blocks.fence, 0);
		setBlock(world, i + 12, j + 30, k + 11, Blocks.fence, 0);
		setBlock(world, i + 12, j + 47, k + 6, Blocks.fence, 0);
		setBlock(world, i + 12, j + 47, k + 7, Blocks.fence, 0);
		setBlock(world, i + 12, j + 47, k + 8, Blocks.fence, 0);
		setBlock(world, i + 13, j + 28, k + 7, Blocks.fence, 0);
		setBlock(world, i + 13, j + 28, k + 8, Blocks.fence, 0);
		setBlock(world, i + 13, j + 47, k + 3, Blocks.fence, 0);
		setBlock(world, i + 13, j + 47, k + 4, Blocks.fence, 0);
		setBlock(world, i + 13, j + 47, k + 5, Blocks.fence, 0);
		setBlock(world, i + 13, j + 47, k + 6, Blocks.fence, 0);
		setBlock(world, i + 14, j + 28, k + 0, Blocks.fence, 0);
		setBlock(world, i + 14, j + 28, k + 1, Blocks.spruce_stairs, 0);
		setBlock(world, i + 14, j + 28, k + 5, Blocks.spruce_stairs, 0);
		setBlock(world, i + 14, j + 28, k + 6, Blocks.fence, 0);
		setBlock(world, i + 14, j + 28, k + 7, Blocks.fence, 0);
		setBlock(world, i + 14, j + 47, k + 3, Blocks.fence, 0);
		setBlock(world, i + 16, j + 30, k + 0, Blocks.fence, 0);
		setBlock(world, i + 16, j + 30, k + 6, Blocks.fence, 0);
		setBlock(world, i + 17, j + 30, k + 0, Blocks.fence, 0);
		setBlock(world, i + 17, j + 30, k + 6, Blocks.fence, 0);
		setBlock(world, i + 18, j + 44, k + 19, Blocks.spruce_stairs, 0);
		setBlock(world, i + 18, j + 44, k + 20, Blocks.spruce_stairs, 0);
		setBlock(world, i + 18, j + 44, k + 21, Blocks.spruce_stairs, 0);
		setBlock(world, i + 18, j + 44, k + 22, Blocks.spruce_stairs, 0);
		setBlock(world, i + 18, j + 44, k + 23, Blocks.spruce_stairs, 0);
		setBlock(world, i + 18, j + 44, k + 24, Blocks.spruce_stairs, 0);
		setBlock(world, i + 22, j + 45, k + 19, Blocks.spruce_stairs, 0);
		setBlock(world, i + 22, j + 45, k + 20, Blocks.spruce_stairs, 0);
		setBlock(world, i + 22, j + 45, k + 21, Blocks.spruce_stairs, 0);
		setBlock(world, i + 22, j + 45, k + 22, Blocks.spruce_stairs, 0);
		setBlock(world, i + 22, j + 45, k + 23, Blocks.spruce_stairs, 0);
		setBlock(world, i + 22, j + 45, k + 24, Blocks.spruce_stairs, 0);
		setBlock(world, i + 25, j + 23, k + 18, Blocks.fence, 0);
		setBlock(world, i + 25, j + 23, k + 24, Blocks.fence, 0);
		setBlock(world, i + 26, j + 23, k + 18, Blocks.fence, 0);
		setBlock(world, i + 26, j + 23, k + 24, Blocks.fence, 0);
		setBlock(world, i + 27, j + 46, k + 19, Blocks.spruce_stairs, 0);
		setBlock(world, i + 27, j + 46, k + 20, Blocks.spruce_stairs, 0);
		setBlock(world, i + 27, j + 46, k + 21, Blocks.spruce_stairs, 0);
		setBlock(world, i + 27, j + 46, k + 22, Blocks.spruce_stairs, 0);
		setBlock(world, i + 27, j + 46, k + 23, Blocks.spruce_stairs, 0);
		setBlock(world, i + 27, j + 46, k + 24, Blocks.spruce_stairs, 0);
		setBlock(world, i + 28, j + 21, k + 17, Blocks.fence, 0);
		setBlock(world, i + 28, j + 21, k + 18, Blocks.fence, 0);
		setBlock(world, i + 28, j + 21, k + 24, Blocks.fence, 0);
		setBlock(world, i + 28, j + 21, k + 25, Blocks.fence, 0);
		setBlock(world, i + 29, j + 21, k + 16, Blocks.fence, 0);
		setBlock(world, i + 29, j + 21, k + 17, Blocks.fence, 0);
		setBlock(world, i + 29, j + 21, k + 25, Blocks.fence, 0);
		setBlock(world, i + 29, j + 21, k + 26, Blocks.fence, 0);
		setBlock(world, i + 30, j + 21, k + 15, Blocks.spruce_stairs, 0);
		setBlock(world, i + 30, j + 21, k + 16, Blocks.fence, 0);
		setBlock(world, i + 30, j + 21, k + 26, Blocks.fence, 0);
		setBlock(world, i + 30, j + 21, k + 27, Blocks.spruce_stairs, 0);
		setBlock(world, i + 30, j + 23, k + 13, Blocks.fence, 0);
		setBlock(world, i + 30, j + 23, k + 14, Blocks.fence, 0);
		setBlock(world, i + 30, j + 23, k + 28, Blocks.fence, 0);
		setBlock(world, i + 30, j + 23, k + 29, Blocks.fence, 0);
		SpawnUtils.spawnNPC(NPCType.WOOKIETREE, world, i + 31, j + 21, k + 19);
		SpawnUtils.spawnNPC(NPCType.WOOKIETREE, world, i + 31, j + 21, k + 23);
		setBlock(world, i + 0, j + 0, k + 4, Blocks.log, 3);
		world.setBlockMetadataWithNotify(i + 0, j + 0, k + 4, 3, 2);
		setBlock(world, i + 0, j + 0, k + 5, Blocks.log, 3);
		world.setBlockMetadataWithNotify(i + 0, j + 0, k + 5, 3, 2);
		setBlock(world, i + 0, j + 0, k + 6, Blocks.log, 3);
		world.setBlockMetadataWithNotify(i + 0, j + 0, k + 6, 3, 2);
		setBlock(world, i + 0, j + 0, k + 7, Blocks.log, 3);
		world.setBlockMetadataWithNotify(i + 0, j + 0, k + 7, 3, 2);
		setBlock(world, i + 0, j + 0, k + 8, Blocks.log, 3);
		world.setBlockMetadataWithNotify(i + 0, j + 0, k + 8, 3, 2);
		setBlock(world, i + 0, j + 0, k + 9, Blocks.log, 3);
		world.setBlockMetadataWithNotify(i + 0, j + 0, k + 9, 3, 2);
		setBlock(world, i + 0, j + 0, k + 10, Blocks.log, 3);
		world.setBlockMetadataWithNotify(i + 0, j + 0, k + 10, 3, 2);
		setBlock(world, i + 0, j + 1, k + 4, Blocks.log, 3);
		world.setBlockMetadataWithNotify(i + 0, j + 1, k + 4, 3, 2);
		setBlock(world, i + 0, j + 1, k + 5, Blocks.log, 3);
		world.setBlockMetadataWithNotify(i + 0, j + 1, k + 5, 3, 2);
		setBlock(world, i + 0, j + 1, k + 6, Blocks.log, 3);
		world.setBlockMetadataWithNotify(i + 0, j + 1, k + 6, 3, 2);
		setBlock(world, i + 0, j + 1, k + 7, Blocks.log, 3);
		world.setBlockMetadataWithNotify(i + 0, j + 1, k + 7, 3, 2);
		setBlock(world, i + 0, j + 1, k + 8, Blocks.log, 3);
		world.setBlockMetadataWithNotify(i + 0, j + 1, k + 8, 3, 2);
		setBlock(world, i + 0, j + 1, k + 9, Blocks.log, 3);
		world.setBlockMetadataWithNotify(i + 0, j + 1, k + 9, 3, 2);
		setBlock(world, i + 0, j + 1, k + 10, Blocks.log, 3);
		world.setBlockMetadataWithNotify(i + 0, j + 1, k + 10, 3, 2);
		setBlock(world, i + 0, j + 1, k + 11, Blocks.log, 3);
		world.setBlockMetadataWithNotify(i + 0, j + 1, k + 11, 3, 2);
		setBlock(world, i + 0, j + 2, k + 4, Blocks.log, 3);
		world.setBlockMetadataWithNotify(i + 0, j + 2, k + 4, 3, 2);
		setBlock(world, i + 0, j + 2, k + 5, Blocks.log, 3);
		world.setBlockMetadataWithNotify(i + 0, j + 2, k + 5, 3, 2);
		setBlock(world, i + 0, j + 2, k + 6, Blocks.log, 3);
		world.setBlockMetadataWithNotify(i + 0, j + 2, k + 6, 3, 2);
		setBlock(world, i + 0, j + 2, k + 7, Blocks.log, 3);
		world.setBlockMetadataWithNotify(i + 0, j + 2, k + 7, 3, 2);
		setBlock(world, i + 0, j + 2, k + 8, Blocks.log, 3);
		world.setBlockMetadataWithNotify(i + 0, j + 2, k + 8, 3, 2);
		setBlock(world, i + 0, j + 2, k + 9, Blocks.log, 3);
		world.setBlockMetadataWithNotify(i + 0, j + 2, k + 9, 3, 2);
		setBlock(world, i + 0, j + 2, k + 10, Blocks.log, 3);
		world.setBlockMetadataWithNotify(i + 0, j + 2, k + 10, 3, 2);
		setBlock(world, i + 0, j + 11, k + 8, Blocks.leaves, 7);
		world.setBlockMetadataWithNotify(i + 0, j + 11, k + 8, 7, 2);
		setBlock(world, i + 0, j + 11, k + 9, Blocks.leaves, 7);
		world.setBlockMetadataWithNotify(i + 0, j + 11, k + 9, 7, 2);
		setBlock(world, i + 0, j + 11, k + 10, Blocks.leaves, 7);
		world.setBlockMetadataWithNotify(i + 0, j + 11, k + 10, 7, 2);
		setBlock(world, i + 0, j + 12, k + 9, Blocks.leaves, 7);
		world.setBlockMetadataWithNotify(i + 0, j + 12, k + 9, 7, 2);
		setBlock(world, i + 0, j + 20, k + 7, Blocks.log, 3);
		world.setBlockMetadataWithNotify(i + 0, j + 20, k + 7, 3, 2);
		setBlock(world, i + 0, j + 21, k + 6, Blocks.log, 3);
		world.setBlockMetadataWithNotify(i + 0, j + 21, k + 6, 3, 2);
		setBlock(world, i + 0, j + 21, k + 7, Blocks.log, 3);
		world.setBlockMetadataWithNotify(i + 0, j + 21, k + 7, 3, 2);
		setBlock(world, i + 0, j + 21, k + 8, Blocks.log, 3);
		world.setBlockMetadataWithNotify(i + 0, j + 21, k + 8, 3, 2);
		setBlock(world, i + 0, j + 21, k + 22, Blocks.log, 3);
		world.setBlockMetadataWithNotify(i + 0, j + 21, k + 22, 3, 2);
		setBlock(world, i + 0, j + 21, k + 23, Blocks.log, 3);
		world.setBlockMetadataWithNotify(i + 0, j + 21, k + 23, 3, 2);
		setBlock(world, i + 0, j + 22, k + 3, Blocks.log, 1);
		world.setBlockMetadataWithNotify(i + 0, j + 22, k + 3, 1, 2);
		setBlock(world, i + 0, j + 22, k + 7, Blocks.log, 3);
		world.setBlockMetadataWithNotify(i + 0, j + 22, k + 7, 3, 2);
		setBlock(world, i + 0, j + 23, k + 2, Blocks.log, 1);
		world.setBlockMetadataWithNotify(i + 0, j + 23, k + 2, 1, 2);
		setBlock(world, i + 0, j + 23, k + 3, Blocks.log, 1);
		world.setBlockMetadataWithNotify(i + 0, j + 23, k + 3, 1, 2);
		setBlock(world, i + 0, j + 23, k + 13, Blocks.log, 3);
		world.setBlockMetadataWithNotify(i + 0, j + 23, k + 13, 3, 2);
		setBlock(world, i + 0, j + 23, k + 17, Blocks.log, 3);
		world.setBlockMetadataWithNotify(i + 0, j + 23, k + 17, 3, 2);
		setBlock(world, i + 0, j + 24, k + 0, Blocks.leaves, 15);
		world.setBlockMetadataWithNotify(i + 0, j + 24, k + 0, 15, 2);
		setBlock(world, i + 0, j + 24, k + 1, Blocks.log, 1);
		world.setBlockMetadataWithNotify(i + 0, j + 24, k + 1, 1, 2);
		setBlock(world, i + 0, j + 24, k + 3, Blocks.log, 1);
		world.setBlockMetadataWithNotify(i + 0, j + 24, k + 3, 1, 2);
		setBlock(world, i + 0, j + 24, k + 12, Blocks.log, 3);
		world.setBlockMetadataWithNotify(i + 0, j + 24, k + 12, 3, 2);
		setBlock(world, i + 0, j + 24, k + 13, Blocks.log, 3);
		world.setBlockMetadataWithNotify(i + 0, j + 24, k + 13, 3, 2);
		setBlock(world, i + 0, j + 24, k + 14, Blocks.log, 3);
		world.setBlockMetadataWithNotify(i + 0, j + 24, k + 14, 3, 2);
		setBlock(world, i + 0, j + 25, k + 0, Blocks.log, 1);
		world.setBlockMetadataWithNotify(i + 0, j + 25, k + 0, 1, 2);
		setBlock(world, i + 0, j + 25, k + 1, Blocks.log, 1);
		world.setBlockMetadataWithNotify(i + 0, j + 25, k + 1, 1, 2);
		setBlock(world, i + 0, j + 25, k + 11, Blocks.log, 3);
		world.setBlockMetadataWithNotify(i + 0, j + 25, k + 11, 3, 2);
		setBlock(world, i + 0, j + 25, k + 13, Blocks.log, 3);
		world.setBlockMetadataWithNotify(i + 0, j + 25, k + 13, 3, 2);
		setBlock(world, i + 0, j + 25, k + 17, Blocks.log, 3);
		world.setBlockMetadataWithNotify(i + 0, j + 25, k + 17, 3, 2);
		setBlock(world, i + 0, j + 26, k + 0, Blocks.leaves, 15);
		world.setBlockMetadataWithNotify(i + 0, j + 26, k + 0, 15, 2);
		setBlock(world, i + 0, j + 26, k + 15, Blocks.log, 3);
		world.setBlockMetadataWithNotify(i + 0, j + 26, k + 15, 3, 2);
		setBlock(world, i + 0, j + 28, k + 7, Blocks.log, 3);
		world.setBlockMetadataWithNotify(i + 0, j + 28, k + 7, 3, 2);
		setBlock(world, i + 0, j + 28, k + 18, Blocks.log, 3);
		world.setBlockMetadataWithNotify(i + 0, j + 28, k + 18, 3, 2);
		setBlock(world, i + 0, j + 29, k + 16, Blocks.log, 3);
		world.setBlockMetadataWithNotify(i + 0, j + 29, k + 16, 3, 2);
		setBlock(world, i + 0, j + 29, k + 22, Blocks.leaves, 7);
		world.setBlockMetadataWithNotify(i + 0, j + 29, k + 22, 7, 2);
		setBlock(world, i + 0, j + 29, k + 23, Blocks.leaves, 7);
		world.setBlockMetadataWithNotify(i + 0, j + 29, k + 23, 7, 2);
		setBlock(world, i + 0, j + 29, k + 24, Blocks.log, 3);
		world.setBlockMetadataWithNotify(i + 0, j + 29, k + 24, 3, 2);
		setBlock(world, i + 0, j + 29, k + 25, Blocks.leaves, 7);
		world.setBlockMetadataWithNotify(i + 0, j + 29, k + 25, 7, 2);
		setBlock(world, i + 0, j + 29, k + 26, Blocks.leaves, 7);
		world.setBlockMetadataWithNotify(i + 0, j + 29, k + 26, 7, 2);
		setBlock(world, i + 0, j + 30, k + 16, Blocks.log, 3);
		world.setBlockMetadataWithNotify(i + 0, j + 30, k + 16, 3, 2);
		setBlock(world, i + 0, j + 30, k + 22, Blocks.leaves, 7);
		world.setBlockMetadataWithNotify(i + 0, j + 30, k + 22, 7, 2);
		setBlock(world, i + 0, j + 30, k + 23, Blocks.leaves, 7);
		world.setBlockMetadataWithNotify(i + 0, j + 30, k + 23, 7, 2);
		setBlock(world, i + 0, j + 30, k + 24, Blocks.leaves, 7);
		world.setBlockMetadataWithNotify(i + 0, j + 30, k + 24, 7, 2);
		setBlock(world, i + 0, j + 30, k + 25, Blocks.leaves, 7);
		world.setBlockMetadataWithNotify(i + 0, j + 30, k + 25, 7, 2);
		setBlock(world, i + 0, j + 30, k + 26, Blocks.leaves, 7);
		world.setBlockMetadataWithNotify(i + 0, j + 30, k + 26, 7, 2);
		setBlock(world, i + 0, j + 31, k + 0, Blocks.log, 1);
		world.setBlockMetadataWithNotify(i + 0, j + 31, k + 0, 1, 2);
		setBlock(world, i + 0, j + 31, k + 1, Blocks.log, 1);
		world.setBlockMetadataWithNotify(i + 0, j + 31, k + 1, 1, 2);
		setBlock(world, i + 0, j + 31, k + 2, Blocks.log, 1);
		world.setBlockMetadataWithNotify(i + 0, j + 31, k + 2, 1, 2);
		setBlock(world, i + 0, j + 31, k + 3, Blocks.log, 1);
		world.setBlockMetadataWithNotify(i + 0, j + 31, k + 3, 1, 2);
		setBlock(world, i + 0, j + 31, k + 4, Blocks.log, 1);
		world.setBlockMetadataWithNotify(i + 0, j + 31, k + 4, 1, 2);
		setBlock(world, i + 0, j + 31, k + 5, Blocks.log, 1);
		world.setBlockMetadataWithNotify(i + 0, j + 31, k + 5, 1, 2);
		setBlock(world, i + 0, j + 31, k + 6, Blocks.log, 1);
		world.setBlockMetadataWithNotify(i + 0, j + 31, k + 6, 1, 2);
		setBlock(world, i + 0, j + 31, k + 23, Blocks.leaves, 7);
		world.setBlockMetadataWithNotify(i + 0, j + 31, k + 23, 7, 2);
		setBlock(world, i + 0, j + 31, k + 24, Blocks.leaves, 7);
		world.setBlockMetadataWithNotify(i + 0, j + 31, k + 24, 7, 2);
		setBlock(world, i + 0, j + 31, k + 25, Blocks.leaves, 7);
		world.setBlockMetadataWithNotify(i + 0, j + 31, k + 25, 7, 2);
		setBlock(world, i + 0, j + 32, k + 24, Blocks.leaves, 7);
		world.setBlockMetadataWithNotify(i + 0, j + 32, k + 24, 7, 2);
		setBlock(world, i + 0, j + 34, k + 16, Blocks.log, 3);
		world.setBlockMetadataWithNotify(i + 0, j + 34, k + 16, 3, 2);
		setBlock(world, i + 0, j + 35, k + 13, Blocks.log, 3);
		world.setBlockMetadataWithNotify(i + 0, j + 35, k + 13, 3, 2);
		setBlock(world, i + 0, j + 36, k + 11, Blocks.leaves, 7);
		world.setBlockMetadataWithNotify(i + 0, j + 36, k + 11, 7, 2);
		setBlock(world, i + 0, j + 36, k + 12, Blocks.leaves, 7);
		world.setBlockMetadataWithNotify(i + 0, j + 36, k + 12, 7, 2);
		setBlock(world, i + 0, j + 36, k + 13, Blocks.leaves, 7);
		world.setBlockMetadataWithNotify(i + 0, j + 36, k + 13, 7, 2);
		setBlock(world, i + 0, j + 36, k + 14, Blocks.leaves, 7);
		world.setBlockMetadataWithNotify(i + 0, j + 36, k + 14, 7, 2);
		setBlock(world, i + 0, j + 36, k + 15, Blocks.leaves, 7);
		world.setBlockMetadataWithNotify(i + 0, j + 36, k + 15, 7, 2);
		setBlock(world, i + 0, j + 37, k + 3, Blocks.log, 3);
		world.setBlockMetadataWithNotify(i + 0, j + 37, k + 3, 3, 2);
		setBlock(world, i + 0, j + 37, k + 12, Blocks.leaves, 7);
		world.setBlockMetadataWithNotify(i + 0, j + 37, k + 12, 7, 2);
		setBlock(world, i + 0, j + 37, k + 13, Blocks.log, 3);
		world.setBlockMetadataWithNotify(i + 0, j + 37, k + 13, 3, 2);
		setBlock(world, i + 0, j + 37, k + 14, Blocks.leaves, 7);
		world.setBlockMetadataWithNotify(i + 0, j + 37, k + 14, 7, 2);
		setBlock(world, i + 0, j + 37, k + 16, Blocks.log, 3);
		world.setBlockMetadataWithNotify(i + 0, j + 37, k + 16, 3, 2);
		setBlock(world, i + 0, j + 38, k + 13, Blocks.leaves, 7);
		world.setBlockMetadataWithNotify(i + 0, j + 38, k + 13, 7, 2);
		setBlock(world, i + 0, j + 38, k + 17, Blocks.log, 3);
		world.setBlockMetadataWithNotify(i + 0, j + 38, k + 17, 3, 2);
		setBlock(world, i + 0, j + 40, k + 6, Blocks.log, 3);
		world.setBlockMetadataWithNotify(i + 0, j + 40, k + 6, 3, 2);
		setBlock(world, i + 0, j + 42, k + 2, Blocks.leaves, 15);
		world.setBlockMetadataWithNotify(i + 0, j + 42, k + 2, 15, 2);
		setBlock(world, i + 0, j + 42, k + 3, Blocks.leaves, 15);
		world.setBlockMetadataWithNotify(i + 0, j + 42, k + 3, 15, 2);
		setBlock(world, i + 0, j + 42, k + 4, Blocks.leaves, 15);
		world.setBlockMetadataWithNotify(i + 0, j + 42, k + 4, 15, 2);
		setBlock(world, i + 0, j + 42, k + 6, Blocks.log, 3);
		world.setBlockMetadataWithNotify(i + 0, j + 42, k + 6, 3, 2);
		setBlock(world, i + 0, j + 43, k + 0, Blocks.log, 1);
		world.setBlockMetadataWithNotify(i + 0, j + 43, k + 0, 1, 2);
		setBlock(world, i + 0, j + 43, k + 1, Blocks.log, 1);
		world.setBlockMetadataWithNotify(i + 0, j + 43, k + 1, 1, 2);
		setBlock(world, i + 0, j + 43, k + 2, Blocks.log, 1);
		world.setBlockMetadataWithNotify(i + 0, j + 43, k + 2, 1, 2);
		setBlock(world, i + 0, j + 43, k + 3, Blocks.log, 1);
		world.setBlockMetadataWithNotify(i + 0, j + 43, k + 3, 1, 2);
		setBlock(world, i + 0, j + 43, k + 4, Blocks.log, 1);
		world.setBlockMetadataWithNotify(i + 0, j + 43, k + 4, 1, 2);
		setBlock(world, i + 0, j + 43, k + 5, Blocks.log, 1);
		world.setBlockMetadataWithNotify(i + 0, j + 43, k + 5, 1, 2);
		setBlock(world, i + 0, j + 44, k + 2, Blocks.spruce_stairs, 1);
		world.setBlockMetadataWithNotify(i + 0, j + 44, k + 2, 1, 2);
		setBlock(world, i + 0, j + 45, k + 3, Blocks.torch, 5);
		world.setBlockMetadataWithNotify(i + 0, j + 45, k + 3, 5, 2);
		setBlock(world, i + 0, j + 47, k + 14, Blocks.log, 3);
		world.setBlockMetadataWithNotify(i + 0, j + 47, k + 14, 3, 2);
		setBlock(world, i + 0, j + 48, k + 0, Blocks.log, 1);
		world.setBlockMetadataWithNotify(i + 0, j + 48, k + 0, 1, 2);
		setBlock(world, i + 0, j + 48, k + 1, Blocks.log, 1);
		world.setBlockMetadataWithNotify(i + 0, j + 48, k + 1, 1, 2);
		setBlock(world, i + 0, j + 48, k + 2, Blocks.log, 1);
		world.setBlockMetadataWithNotify(i + 0, j + 48, k + 2, 1, 2);
		setBlock(world, i + 0, j + 48, k + 3, Blocks.log, 1);
		world.setBlockMetadataWithNotify(i + 0, j + 48, k + 3, 1, 2);
		setBlock(world, i + 0, j + 48, k + 4, Blocks.log, 1);
		world.setBlockMetadataWithNotify(i + 0, j + 48, k + 4, 1, 2);
		setBlock(world, i + 0, j + 48, k + 5, Blocks.log, 1);
		world.setBlockMetadataWithNotify(i + 0, j + 48, k + 5, 1, 2);
		setBlock(world, i + 0, j + 48, k + 6, Blocks.log, 1);
		world.setBlockMetadataWithNotify(i + 0, j + 48, k + 6, 1, 2);
		setBlock(world, i + 0, j + 48, k + 7, Blocks.log, 1);
		world.setBlockMetadataWithNotify(i + 0, j + 48, k + 7, 1, 2);
		setBlock(world, i + 0, j + 48, k + 8, Blocks.log, 1);
		world.setBlockMetadataWithNotify(i + 0, j + 48, k + 8, 1, 2);
		setBlock(world, i + 0, j + 48, k + 9, Blocks.log, 1);
		world.setBlockMetadataWithNotify(i + 0, j + 48, k + 9, 1, 2);
		setBlock(world, i + 0, j + 48, k + 13, Blocks.leaves, 15);
		world.setBlockMetadataWithNotify(i + 0, j + 48, k + 13, 15, 2);
		setBlock(world, i + 0, j + 48, k + 14, Blocks.leaves, 15);
		world.setBlockMetadataWithNotify(i + 0, j + 48, k + 14, 15, 2);
		setBlock(world, i + 0, j + 48, k + 15, Blocks.leaves, 15);
		world.setBlockMetadataWithNotify(i + 0, j + 48, k + 15, 15, 2);
		setBlock(world, i + 0, j + 48, k + 16, Blocks.leaves, 15);
		world.setBlockMetadataWithNotify(i + 0, j + 48, k + 16, 15, 2);
		setBlock(world, i + 0, j + 49, k + 0, Blocks.log, 1);
		world.setBlockMetadataWithNotify(i + 0, j + 49, k + 0, 1, 2);
		setBlock(world, i + 0, j + 49, k + 1, Blocks.log, 1);
		world.setBlockMetadataWithNotify(i + 0, j + 49, k + 1, 1, 2);
		setBlock(world, i + 0, j + 49, k + 2, Blocks.log, 1);
		world.setBlockMetadataWithNotify(i + 0, j + 49, k + 2, 1, 2);
		setBlock(world, i + 0, j + 49, k + 3, Blocks.log, 1);
		world.setBlockMetadataWithNotify(i + 0, j + 49, k + 3, 1, 2);
		setBlock(world, i + 0, j + 49, k + 4, Blocks.log, 1);
		world.setBlockMetadataWithNotify(i + 0, j + 49, k + 4, 1, 2);
		setBlock(world, i + 0, j + 49, k + 5, Blocks.log, 1);
		world.setBlockMetadataWithNotify(i + 0, j + 49, k + 5, 1, 2);
		setBlock(world, i + 0, j + 49, k + 6, Blocks.log, 1);
		world.setBlockMetadataWithNotify(i + 0, j + 49, k + 6, 1, 2);
		setBlock(world, i + 0, j + 49, k + 7, Blocks.log, 1);
		world.setBlockMetadataWithNotify(i + 0, j + 49, k + 7, 1, 2);
		setBlock(world, i + 0, j + 49, k + 8, Blocks.log, 1);
		world.setBlockMetadataWithNotify(i + 0, j + 49, k + 8, 1, 2);
		setBlock(world, i + 0, j + 49, k + 13, Blocks.leaves, 15);
		world.setBlockMetadataWithNotify(i + 0, j + 49, k + 13, 15, 2);
		setBlock(world, i + 0, j + 49, k + 14, Blocks.leaves, 15);
		world.setBlockMetadataWithNotify(i + 0, j + 49, k + 14, 15, 2);
		setBlock(world, i + 0, j + 49, k + 15, Blocks.leaves, 15);
		world.setBlockMetadataWithNotify(i + 0, j + 49, k + 15, 15, 2);
		setBlock(world, i + 0, j + 50, k + 0, Blocks.log, 1);
		world.setBlockMetadataWithNotify(i + 0, j + 50, k + 0, 1, 2);
		setBlock(world, i + 0, j + 50, k + 1, Blocks.log, 1);
		world.setBlockMetadataWithNotify(i + 0, j + 50, k + 1, 1, 2);
		setBlock(world, i + 0, j + 50, k + 2, Blocks.log, 1);
		world.setBlockMetadataWithNotify(i + 0, j + 50, k + 2, 1, 2);
		setBlock(world, i + 0, j + 50, k + 3, Blocks.log, 1);
		world.setBlockMetadataWithNotify(i + 0, j + 50, k + 3, 1, 2);
		setBlock(world, i + 0, j + 50, k + 4, Blocks.log, 1);
		world.setBlockMetadataWithNotify(i + 0, j + 50, k + 4, 1, 2);
		setBlock(world, i + 0, j + 50, k + 5, Blocks.log, 1);
		world.setBlockMetadataWithNotify(i + 0, j + 50, k + 5, 1, 2);
		setBlock(world, i + 0, j + 52, k + 3, Blocks.leaves, 15);
		world.setBlockMetadataWithNotify(i + 0, j + 52, k + 3, 15, 2);
		setBlock(world, i + 0, j + 52, k + 4, Blocks.leaves, 15);
		world.setBlockMetadataWithNotify(i + 0, j + 52, k + 4, 15, 2);
		setBlock(world, i + 0, j + 52, k + 5, Blocks.leaves, 15);
		world.setBlockMetadataWithNotify(i + 0, j + 52, k + 5, 15, 2);
		setBlock(world, i + 0, j + 53, k + 4, Blocks.leaves, 15);
		world.setBlockMetadataWithNotify(i + 0, j + 53, k + 4, 15, 2);
		setBlock(world, i + 0, j + 53, k + 5, Blocks.leaves, 15);
		world.setBlockMetadataWithNotify(i + 0, j + 53, k + 5, 15, 2);
		setBlock(world, i + 0, j + 53, k + 6, Blocks.leaves, 15);
		world.setBlockMetadataWithNotify(i + 0, j + 53, k + 6, 15, 2);
		setBlock(world, i + 0, j + 53, k + 7, Blocks.leaves, 15);
		world.setBlockMetadataWithNotify(i + 0, j + 53, k + 7, 15, 2);
		setBlock(world, i + 0, j + 54, k + 6, Blocks.leaves, 15);
		world.setBlockMetadataWithNotify(i + 0, j + 54, k + 6, 15, 2);
		setBlock(world, i + 0, j + 54, k + 9, Blocks.leaves, 7);
		world.setBlockMetadataWithNotify(i + 0, j + 54, k + 9, 7, 2);
		setBlock(world, i + 0, j + 54, k + 10, Blocks.leaves, 7);
		world.setBlockMetadataWithNotify(i + 0, j + 54, k + 10, 7, 2);
		setBlock(world, i + 0, j + 54, k + 11, Blocks.leaves, 7);
		world.setBlockMetadataWithNotify(i + 0, j + 54, k + 11, 7, 2);
		setBlock(world, i + 0, j + 54, k + 12, Blocks.leaves, 7);
		world.setBlockMetadataWithNotify(i + 0, j + 54, k + 12, 7, 2);
		setBlock(world, i + 0, j + 54, k + 13, Blocks.leaves, 7);
		world.setBlockMetadataWithNotify(i + 0, j + 54, k + 13, 7, 2);
		setBlock(world, i + 0, j + 55, k + 10, Blocks.leaves, 7);
		world.setBlockMetadataWithNotify(i + 0, j + 55, k + 10, 7, 2);
		setBlock(world, i + 0, j + 55, k + 11, Blocks.leaves, 7);
		world.setBlockMetadataWithNotify(i + 0, j + 55, k + 11, 7, 2);
		setBlock(world, i + 0, j + 55, k + 12, Blocks.leaves, 7);
		world.setBlockMetadataWithNotify(i + 0, j + 55, k + 12, 7, 2);
		setBlock(world, i + 0, j + 56, k + 6, Blocks.leaves, 15);
		world.setBlockMetadataWithNotify(i + 0, j + 56, k + 6, 15, 2);
		setBlock(world, i + 0, j + 56, k + 7, Blocks.leaves, 15);
		world.setBlockMetadataWithNotify(i + 0, j + 56, k + 7, 15, 2);
		setBlock(world, i + 0, j + 56, k + 8, Blocks.leaves, 15);
		world.setBlockMetadataWithNotify(i + 0, j + 56, k + 8, 15, 2);
		setBlock(world, i + 0, j + 56, k + 9, Blocks.leaves, 7);
		world.setBlockMetadataWithNotify(i + 0, j + 56, k + 9, 7, 2);
		setBlock(world, i + 0, j + 56, k + 10, Blocks.leaves, 7);
		world.setBlockMetadataWithNotify(i + 0, j + 56, k + 10, 7, 2);
		setBlock(world, i + 0, j + 56, k + 11, Blocks.leaves, 7);
		world.setBlockMetadataWithNotify(i + 0, j + 56, k + 11, 7, 2);
		setBlock(world, i + 0, j + 57, k + 7, Blocks.leaves, 7);
		world.setBlockMetadataWithNotify(i + 0, j + 57, k + 7, 7, 2);
		setBlock(world, i + 0, j + 57, k + 8, Blocks.leaves, 7);
		world.setBlockMetadataWithNotify(i + 0, j + 57, k + 8, 7, 2);
		setBlock(world, i + 0, j + 57, k + 9, Blocks.leaves, 7);
		world.setBlockMetadataWithNotify(i + 0, j + 57, k + 9, 7, 2);
		setBlock(world, i + 0, j + 58, k + 8, Blocks.leaves, 7);
		world.setBlockMetadataWithNotify(i + 0, j + 58, k + 8, 7, 2);
		setBlock(world, i + 0, j + 58, k + 11, Blocks.leaves, 7);
		world.setBlockMetadataWithNotify(i + 0, j + 58, k + 11, 7, 2);
		setBlock(world, i + 0, j + 58, k + 12, Blocks.leaves, 7);
		world.setBlockMetadataWithNotify(i + 0, j + 58, k + 12, 7, 2);
		setBlock(world, i + 0, j + 58, k + 13, Blocks.leaves, 7);
		world.setBlockMetadataWithNotify(i + 0, j + 58, k + 13, 7, 2);
		setBlock(world, i + 0, j + 59, k + 12, Blocks.leaves, 7);
		world.setBlockMetadataWithNotify(i + 0, j + 59, k + 12, 7, 2);
		setBlock(world, i + 1, j + 0, k + 6, Blocks.log, 3);
		world.setBlockMetadataWithNotify(i + 1, j + 0, k + 6, 3, 2);
		setBlock(world, i + 1, j + 0, k + 7, Blocks.log, 3);
		world.setBlockMetadataWithNotify(i + 1, j + 0, k + 7, 3, 2);
		setBlock(world, i + 1, j + 0, k + 8, Blocks.log, 3);
		world.setBlockMetadataWithNotify(i + 1, j + 0, k + 8, 3, 2);
		setBlock(world, i + 1, j + 1, k + 6, Blocks.log, 3);
		world.setBlockMetadataWithNotify(i + 1, j + 1, k + 6, 3, 2);
		setBlock(world, i + 1, j + 1, k + 7, Blocks.log, 3);
		world.setBlockMetadataWithNotify(i + 1, j + 1, k + 7, 3, 2);
		setBlock(world, i + 1, j + 1, k + 8, Blocks.log, 3);
		world.setBlockMetadataWithNotify(i + 1, j + 1, k + 8, 3, 2);
		setBlock(world, i + 1, j + 2, k + 6, Blocks.log, 3);
		world.setBlockMetadataWithNotify(i + 1, j + 2, k + 6, 3, 2);
		setBlock(world, i + 1, j + 2, k + 7, Blocks.log, 3);
		world.setBlockMetadataWithNotify(i + 1, j + 2, k + 7, 3, 2);
		setBlock(world, i + 1, j + 2, k + 8, Blocks.log, 3);
		world.setBlockMetadataWithNotify(i + 1, j + 2, k + 8, 3, 2);
		setBlock(world, i + 1, j + 20, k + 7, Blocks.log, 3);
		world.setBlockMetadataWithNotify(i + 1, j + 20, k + 7, 3, 2);
		setBlock(world, i + 1, j + 21, k + 6, Blocks.log, 3);
		world.setBlockMetadataWithNotify(i + 1, j + 21, k + 6, 3, 2);
		setBlock(world, i + 1, j + 21, k + 7, Blocks.log, 3);
		world.setBlockMetadataWithNotify(i + 1, j + 21, k + 7, 3, 2);
		setBlock(world, i + 1, j + 21, k + 8, Blocks.log, 3);
		world.setBlockMetadataWithNotify(i + 1, j + 21, k + 8, 3, 2);
		setBlock(world, i + 1, j + 21, k + 24, Blocks.log, 3);
		world.setBlockMetadataWithNotify(i + 1, j + 21, k + 24, 3, 2);
		setBlock(world, i + 1, j + 21, k + 25, Blocks.log, 3);
		world.setBlockMetadataWithNotify(i + 1, j + 21, k + 25, 3, 2);
		setBlock(world, i + 1, j + 22, k + 7, Blocks.log, 3);
		world.setBlockMetadataWithNotify(i + 1, j + 22, k + 7, 3, 2);
		setBlock(world, i + 1, j + 22, k + 26, Blocks.leaves, 7);
		world.setBlockMetadataWithNotify(i + 1, j + 22, k + 26, 7, 2);
		setBlock(world, i + 1, j + 22, k + 27, Blocks.leaves, 7);
		world.setBlockMetadataWithNotify(i + 1, j + 22, k + 27, 7, 2);
		setBlock(world, i + 1, j + 22, k + 28, Blocks.leaves, 7);
		world.setBlockMetadataWithNotify(i + 1, j + 22, k + 28, 7, 2);
		setBlock(world, i + 1, j + 23, k + 5, Blocks.vine, 10);
		world.setBlockMetadataWithNotify(i + 1, j + 23, k + 5, 10, 2);
		setBlock(world, i + 1, j + 23, k + 13, Blocks.log, 3);
		world.setBlockMetadataWithNotify(i + 1, j + 23, k + 13, 3, 2);
		setBlock(world, i + 1, j + 23, k + 18, Blocks.log, 3);
		world.setBlockMetadataWithNotify(i + 1, j + 23, k + 18, 3, 2);
		setBlock(world, i + 1, j + 23, k + 27, Blocks.leaves, 7);
		world.setBlockMetadataWithNotify(i + 1, j + 23, k + 27, 7, 2);
		setBlock(world, i + 1, j + 24, k + 0, Blocks.log, 1);
		world.setBlockMetadataWithNotify(i + 1, j + 24, k + 0, 1, 2);
		setBlock(world, i + 1, j + 24, k + 1, Blocks.log, 1);
		world.setBlockMetadataWithNotify(i + 1, j + 24, k + 1, 1, 2);
		setBlock(world, i + 1, j + 24, k + 5, Blocks.vine, 10);
		world.setBlockMetadataWithNotify(i + 1, j + 24, k + 5, 10, 2);
		setBlock(world, i + 1, j + 24, k + 14, Blocks.log, 3);
		world.setBlockMetadataWithNotify(i + 1, j + 24, k + 14, 3, 2);
		setBlock(world, i + 1, j + 25, k + 0, Blocks.log, 1);
		world.setBlockMetadataWithNotify(i + 1, j + 25, k + 0, 1, 2);
		setBlock(world, i + 1, j + 25, k + 1, Blocks.log, 1);
		world.setBlockMetadataWithNotify(i + 1, j + 25, k + 1, 1, 2);
		setBlock(world, i + 1, j + 25, k + 2, Blocks.log, 1);
		world.setBlockMetadataWithNotify(i + 1, j + 25, k + 2, 1, 2);
		setBlock(world, i + 1, j + 25, k + 5, Blocks.vine, 15);
		world.setBlockMetadataWithNotify(i + 1, j + 25, k + 5, 15, 2);
		setBlock(world, i + 1, j + 25, k + 6, Blocks.vine, 15);
		world.setBlockMetadataWithNotify(i + 1, j + 25, k + 6, 15, 2);
		setBlock(world, i + 1, j + 25, k + 12, Blocks.log, 3);
		world.setBlockMetadataWithNotify(i + 1, j + 25, k + 12, 3, 2);
		setBlock(world, i + 1, j + 25, k + 18, Blocks.log, 3);
		world.setBlockMetadataWithNotify(i + 1, j + 25, k + 18, 3, 2);
		setBlock(world, i + 1, j + 26, k + 0, Blocks.log, 1);
		world.setBlockMetadataWithNotify(i + 1, j + 26, k + 0, 1, 2);
		setBlock(world, i + 1, j + 26, k + 1, Blocks.log, 1);
		world.setBlockMetadataWithNotify(i + 1, j + 26, k + 1, 1, 2);
		setBlock(world, i + 1, j + 26, k + 5, Blocks.vine, 15);
		world.setBlockMetadataWithNotify(i + 1, j + 26, k + 5, 15, 2);
		setBlock(world, i + 1, j + 26, k + 6, Blocks.vine, 15);
		world.setBlockMetadataWithNotify(i + 1, j + 26, k + 6, 15, 2);
		setBlock(world, i + 1, j + 26, k + 16, Blocks.log, 3);
		world.setBlockMetadataWithNotify(i + 1, j + 26, k + 16, 3, 2);
		setBlock(world, i + 1, j + 28, k + 19, Blocks.log, 3);
		world.setBlockMetadataWithNotify(i + 1, j + 28, k + 19, 3, 2);
		setBlock(world, i + 1, j + 29, k + 1, Blocks.spruce_stairs, 4);
		world.setBlockMetadataWithNotify(i + 1, j + 29, k + 1, 4, 2);
		setBlock(world, i + 1, j + 29, k + 5, Blocks.spruce_stairs, 4);
		world.setBlockMetadataWithNotify(i + 1, j + 29, k + 5, 4, 2);
		setBlock(world, i + 1, j + 29, k + 17, Blocks.log, 3);
		world.setBlockMetadataWithNotify(i + 1, j + 29, k + 17, 3, 2);
		setBlock(world, i + 1, j + 29, k + 22, Blocks.leaves, 7);
		world.setBlockMetadataWithNotify(i + 1, j + 29, k + 22, 7, 2);
		setBlock(world, i + 1, j + 29, k + 23, Blocks.leaves, 7);
		world.setBlockMetadataWithNotify(i + 1, j + 29, k + 23, 7, 2);
		setBlock(world, i + 1, j + 29, k + 24, Blocks.leaves, 7);
		world.setBlockMetadataWithNotify(i + 1, j + 29, k + 24, 7, 2);
		setBlock(world, i + 1, j + 29, k + 25, Blocks.leaves, 7);
		world.setBlockMetadataWithNotify(i + 1, j + 29, k + 25, 7, 2);
		setBlock(world, i + 1, j + 29, k + 26, Blocks.leaves, 7);
		world.setBlockMetadataWithNotify(i + 1, j + 29, k + 26, 7, 2);
		setBlock(world, i + 1, j + 30, k + 1, Blocks.log, 1);
		world.setBlockMetadataWithNotify(i + 1, j + 30, k + 1, 1, 2);
		setBlock(world, i + 1, j + 30, k + 2, Blocks.torch, 3);
		world.setBlockMetadataWithNotify(i + 1, j + 30, k + 2, 3, 2);
		setBlock(world, i + 1, j + 30, k + 4, Blocks.torch, 4);
		world.setBlockMetadataWithNotify(i + 1, j + 30, k + 4, 4, 2);
		setBlock(world, i + 1, j + 30, k + 5, Blocks.log, 1);
		world.setBlockMetadataWithNotify(i + 1, j + 30, k + 5, 1, 2);
		setBlock(world, i + 1, j + 30, k + 16, Blocks.log, 3);
		world.setBlockMetadataWithNotify(i + 1, j + 30, k + 16, 3, 2);
		setBlock(world, i + 1, j + 30, k + 23, Blocks.leaves, 7);
		world.setBlockMetadataWithNotify(i + 1, j + 30, k + 23, 7, 2);
		setBlock(world, i + 1, j + 30, k + 24, Blocks.leaves, 7);
		world.setBlockMetadataWithNotify(i + 1, j + 30, k + 24, 7, 2);
		setBlock(world, i + 1, j + 30, k + 25, Blocks.leaves, 7);
		world.setBlockMetadataWithNotify(i + 1, j + 30, k + 25, 7, 2);
		setBlock(world, i + 1, j + 31, k + 0, Blocks.log, 1);
		world.setBlockMetadataWithNotify(i + 1, j + 31, k + 0, 1, 2);
		setBlock(world, i + 1, j + 31, k + 1, Blocks.log, 1);
		world.setBlockMetadataWithNotify(i + 1, j + 31, k + 1, 1, 2);
		setBlock(world, i + 1, j + 31, k + 2, Blocks.log, 1);
		world.setBlockMetadataWithNotify(i + 1, j + 31, k + 2, 1, 2);
		setBlock(world, i + 1, j + 31, k + 3, Blocks.log, 1);
		world.setBlockMetadataWithNotify(i + 1, j + 31, k + 3, 1, 2);
		setBlock(world, i + 1, j + 31, k + 4, Blocks.log, 1);
		world.setBlockMetadataWithNotify(i + 1, j + 31, k + 4, 1, 2);
		setBlock(world, i + 1, j + 31, k + 5, Blocks.log, 1);
		world.setBlockMetadataWithNotify(i + 1, j + 31, k + 5, 1, 2);
		setBlock(world, i + 1, j + 31, k + 6, Blocks.log, 1);
		world.setBlockMetadataWithNotify(i + 1, j + 31, k + 6, 1, 2);
		setBlock(world, i + 1, j + 31, k + 7, Blocks.log, 1);
		world.setBlockMetadataWithNotify(i + 1, j + 31, k + 7, 1, 2);
		setBlock(world, i + 1, j + 31, k + 8, Blocks.log, 1);
		world.setBlockMetadataWithNotify(i + 1, j + 31, k + 8, 1, 2);
		setBlock(world, i + 1, j + 31, k + 24, Blocks.leaves, 7);
		world.setBlockMetadataWithNotify(i + 1, j + 31, k + 24, 7, 2);
		setBlock(world, i + 1, j + 32, k + 1, Blocks.log, 1);
		world.setBlockMetadataWithNotify(i + 1, j + 32, k + 1, 1, 2);
		setBlock(world, i + 1, j + 32, k + 2, Blocks.log, 1);
		world.setBlockMetadataWithNotify(i + 1, j + 32, k + 2, 1, 2);
		setBlock(world, i + 1, j + 32, k + 3, Blocks.log, 1);
		world.setBlockMetadataWithNotify(i + 1, j + 32, k + 3, 1, 2);
		setBlock(world, i + 1, j + 32, k + 4, Blocks.log, 1);
		world.setBlockMetadataWithNotify(i + 1, j + 32, k + 4, 1, 2);
		setBlock(world, i + 1, j + 32, k + 5, Blocks.log, 1);
		world.setBlockMetadataWithNotify(i + 1, j + 32, k + 5, 1, 2);
		setBlock(world, i + 1, j + 33, k + 1, Blocks.log, 1);
		world.setBlockMetadataWithNotify(i + 1, j + 33, k + 1, 1, 2);
		setBlock(world, i + 1, j + 33, k + 2, Blocks.log, 1);
		world.setBlockMetadataWithNotify(i + 1, j + 33, k + 2, 1, 2);
		setBlock(world, i + 1, j + 33, k + 3, Blocks.log, 1);
		world.setBlockMetadataWithNotify(i + 1, j + 33, k + 3, 1, 2);
		setBlock(world, i + 1, j + 33, k + 4, Blocks.log, 1);
		world.setBlockMetadataWithNotify(i + 1, j + 33, k + 4, 1, 2);
		setBlock(world, i + 1, j + 33, k + 5, Blocks.log, 1);
		world.setBlockMetadataWithNotify(i + 1, j + 33, k + 5, 1, 2);
		setBlock(world, i + 1, j + 34, k + 17, Blocks.log, 3);
		world.setBlockMetadataWithNotify(i + 1, j + 34, k + 17, 3, 2);
		setBlock(world, i + 1, j + 36, k + 11, Blocks.leaves, 7);
		world.setBlockMetadataWithNotify(i + 1, j + 36, k + 11, 7, 2);
		setBlock(world, i + 1, j + 36, k + 12, Blocks.leaves, 7);
		world.setBlockMetadataWithNotify(i + 1, j + 36, k + 12, 7, 2);
		setBlock(world, i + 1, j + 36, k + 13, Blocks.log, 3);
		world.setBlockMetadataWithNotify(i + 1, j + 36, k + 13, 3, 2);
		setBlock(world, i + 1, j + 36, k + 14, Blocks.leaves, 7);
		world.setBlockMetadataWithNotify(i + 1, j + 36, k + 14, 7, 2);
		setBlock(world, i + 1, j + 36, k + 15, Blocks.leaves, 7);
		world.setBlockMetadataWithNotify(i + 1, j + 36, k + 15, 7, 2);
		setBlock(world, i + 1, j + 37, k + 2, Blocks.log, 3);
		world.setBlockMetadataWithNotify(i + 1, j + 37, k + 2, 3, 2);
		setBlock(world, i + 1, j + 37, k + 11, Blocks.leaves, 7);
		world.setBlockMetadataWithNotify(i + 1, j + 37, k + 11, 7, 2);
		setBlock(world, i + 1, j + 37, k + 12, Blocks.leaves, 7);
		world.setBlockMetadataWithNotify(i + 1, j + 37, k + 12, 7, 2);
		setBlock(world, i + 1, j + 37, k + 13, Blocks.leaves, 7);
		world.setBlockMetadataWithNotify(i + 1, j + 37, k + 13, 7, 2);
		setBlock(world, i + 1, j + 37, k + 14, Blocks.leaves, 7);
		world.setBlockMetadataWithNotify(i + 1, j + 37, k + 14, 7, 2);
		setBlock(world, i + 1, j + 37, k + 15, Blocks.leaves, 7);
		world.setBlockMetadataWithNotify(i + 1, j + 37, k + 15, 7, 2);
		setBlock(world, i + 1, j + 38, k + 12, Blocks.leaves, 7);
		world.setBlockMetadataWithNotify(i + 1, j + 38, k + 12, 7, 2);
		setBlock(world, i + 1, j + 38, k + 13, Blocks.leaves, 7);
		world.setBlockMetadataWithNotify(i + 1, j + 38, k + 13, 7, 2);
		setBlock(world, i + 1, j + 38, k + 14, Blocks.log, 3);
		world.setBlockMetadataWithNotify(i + 1, j + 38, k + 14, 3, 2);
		setBlock(world, i + 1, j + 38, k + 18, Blocks.log, 3);
		world.setBlockMetadataWithNotify(i + 1, j + 38, k + 18, 3, 2);
		setBlock(world, i + 1, j + 39, k + 13, Blocks.leaves, 7);
		world.setBlockMetadataWithNotify(i + 1, j + 39, k + 13, 7, 2);
		setBlock(world, i + 1, j + 39, k + 19, Blocks.leaves, 7);
		world.setBlockMetadataWithNotify(i + 1, j + 39, k + 19, 7, 2);
		setBlock(world, i + 1, j + 39, k + 20, Blocks.leaves, 7);
		world.setBlockMetadataWithNotify(i + 1, j + 39, k + 20, 7, 2);
		setBlock(world, i + 1, j + 39, k + 21, Blocks.leaves, 7);
		world.setBlockMetadataWithNotify(i + 1, j + 39, k + 21, 7, 2);
		setBlock(world, i + 1, j + 40, k + 6, Blocks.log, 3);
		world.setBlockMetadataWithNotify(i + 1, j + 40, k + 6, 3, 2);
		setBlock(world, i + 1, j + 40, k + 20, Blocks.leaves, 7);
		world.setBlockMetadataWithNotify(i + 1, j + 40, k + 20, 7, 2);
		setBlock(world, i + 1, j + 41, k + 3, Blocks.leaves, 15);
		world.setBlockMetadataWithNotify(i + 1, j + 41, k + 3, 15, 2);
		setBlock(world, i + 1, j + 41, k + 4, Blocks.leaves, 15);
		world.setBlockMetadataWithNotify(i + 1, j + 41, k + 4, 15, 2);
		setBlock(world, i + 1, j + 41, k + 5, Blocks.leaves, 15);
		world.setBlockMetadataWithNotify(i + 1, j + 41, k + 5, 15, 2);
		setBlock(world, i + 1, j + 42, k + 1, Blocks.leaves, 15);
		world.setBlockMetadataWithNotify(i + 1, j + 42, k + 1, 15, 2);
		setBlock(world, i + 1, j + 42, k + 2, Blocks.leaves, 15);
		world.setBlockMetadataWithNotify(i + 1, j + 42, k + 2, 15, 2);
		setBlock(world, i + 1, j + 42, k + 3, Blocks.leaves, 15);
		world.setBlockMetadataWithNotify(i + 1, j + 42, k + 3, 15, 2);
		setBlock(world, i + 1, j + 42, k + 4, Blocks.leaves, 15);
		world.setBlockMetadataWithNotify(i + 1, j + 42, k + 4, 15, 2);
		setBlock(world, i + 1, j + 42, k + 5, Blocks.log, 3);
		world.setBlockMetadataWithNotify(i + 1, j + 42, k + 5, 3, 2);
		setBlock(world, i + 1, j + 43, k + 0, Blocks.planks, 5);
		world.setBlockMetadataWithNotify(i + 1, j + 43, k + 0, 5, 2);
		setBlock(world, i + 1, j + 43, k + 1, Blocks.planks, 5);
		world.setBlockMetadataWithNotify(i + 1, j + 43, k + 1, 5, 2);
		setBlock(world, i + 1, j + 43, k + 2, Blocks.log, 1);
		world.setBlockMetadataWithNotify(i + 1, j + 43, k + 2, 1, 2);
		setBlock(world, i + 1, j + 43, k + 3, Blocks.log, 1);
		world.setBlockMetadataWithNotify(i + 1, j + 43, k + 3, 1, 2);
		setBlock(world, i + 1, j + 43, k + 4, Blocks.log, 1);
		world.setBlockMetadataWithNotify(i + 1, j + 43, k + 4, 1, 2);
		setBlock(world, i + 1, j + 43, k + 5, Blocks.log, 1);
		world.setBlockMetadataWithNotify(i + 1, j + 43, k + 5, 1, 2);
		setBlock(world, i + 1, j + 43, k + 6, Blocks.log, 1);
		world.setBlockMetadataWithNotify(i + 1, j + 43, k + 6, 1, 2);
		setBlock(world, i + 1, j + 43, k + 7, Blocks.log, 1);
		world.setBlockMetadataWithNotify(i + 1, j + 43, k + 7, 1, 2);
		setBlock(world, i + 1, j + 45, k + 7, Blocks.torch, 5);
		world.setBlockMetadataWithNotify(i + 1, j + 45, k + 7, 5, 2);
		setBlock(world, i + 1, j + 48, k + 3, Blocks.torch, 1);
		world.setBlockMetadataWithNotify(i + 1, j + 48, k + 3, 1, 2);
		setBlock(world, i + 1, j + 48, k + 4, Blocks.log, 1);
		world.setBlockMetadataWithNotify(i + 1, j + 48, k + 4, 1, 2);
		setBlock(world, i + 1, j + 48, k + 5, Blocks.log, 1);
		world.setBlockMetadataWithNotify(i + 1, j + 48, k + 5, 1, 2);
		setBlock(world, i + 1, j + 48, k + 6, Blocks.log, 1);
		world.setBlockMetadataWithNotify(i + 1, j + 48, k + 6, 1, 2);
		setBlock(world, i + 1, j + 48, k + 7, Blocks.log, 1);
		world.setBlockMetadataWithNotify(i + 1, j + 48, k + 7, 1, 2);
		setBlock(world, i + 1, j + 48, k + 8, Blocks.log, 1);
		world.setBlockMetadataWithNotify(i + 1, j + 48, k + 8, 1, 2);
		setBlock(world, i + 1, j + 48, k + 9, Blocks.log, 1);
		world.setBlockMetadataWithNotify(i + 1, j + 48, k + 9, 1, 2);
		setBlock(world, i + 1, j + 48, k + 10, Blocks.log, 1);
		world.setBlockMetadataWithNotify(i + 1, j + 48, k + 10, 1, 2);
		setBlock(world, i + 1, j + 48, k + 13, Blocks.leaves, 15);
		world.setBlockMetadataWithNotify(i + 1, j + 48, k + 13, 15, 2);
		setBlock(world, i + 1, j + 48, k + 14, Blocks.log, 3);
		world.setBlockMetadataWithNotify(i + 1, j + 48, k + 14, 3, 2);
		setBlock(world, i + 1, j + 48, k + 15, Blocks.leaves, 15);
		world.setBlockMetadataWithNotify(i + 1, j + 48, k + 15, 15, 2);
		setBlock(world, i + 1, j + 48, k + 16, Blocks.leaves, 15);
		world.setBlockMetadataWithNotify(i + 1, j + 48, k + 16, 15, 2);
		setBlock(world, i + 1, j + 49, k + 0, Blocks.log, 1);
		world.setBlockMetadataWithNotify(i + 1, j + 49, k + 0, 1, 2);
		setBlock(world, i + 1, j + 49, k + 1, Blocks.log, 1);
		world.setBlockMetadataWithNotify(i + 1, j + 49, k + 1, 1, 2);
		setBlock(world, i + 1, j + 49, k + 2, Blocks.log, 1);
		world.setBlockMetadataWithNotify(i + 1, j + 49, k + 2, 1, 2);
		setBlock(world, i + 1, j + 49, k + 3, Blocks.log, 1);
		world.setBlockMetadataWithNotify(i + 1, j + 49, k + 3, 1, 2);
		setBlock(world, i + 1, j + 49, k + 4, Blocks.log, 1);
		world.setBlockMetadataWithNotify(i + 1, j + 49, k + 4, 1, 2);
		setBlock(world, i + 1, j + 49, k + 5, Blocks.log, 1);
		world.setBlockMetadataWithNotify(i + 1, j + 49, k + 5, 1, 2);
		setBlock(world, i + 1, j + 49, k + 6, Blocks.log, 1);
		world.setBlockMetadataWithNotify(i + 1, j + 49, k + 6, 1, 2);
		setBlock(world, i + 1, j + 49, k + 7, Blocks.log, 1);
		world.setBlockMetadataWithNotify(i + 1, j + 49, k + 7, 1, 2);
		setBlock(world, i + 1, j + 49, k + 8, Blocks.log, 1);
		world.setBlockMetadataWithNotify(i + 1, j + 49, k + 8, 1, 2);
		setBlock(world, i + 1, j + 49, k + 9, Blocks.log, 1);
		world.setBlockMetadataWithNotify(i + 1, j + 49, k + 9, 1, 2);
		setBlock(world, i + 1, j + 49, k + 13, Blocks.leaves, 15);
		world.setBlockMetadataWithNotify(i + 1, j + 49, k + 13, 15, 2);
		setBlock(world, i + 1, j + 49, k + 14, Blocks.leaves, 15);
		world.setBlockMetadataWithNotify(i + 1, j + 49, k + 14, 15, 2);
		setBlock(world, i + 1, j + 49, k + 15, Blocks.leaves, 15);
		world.setBlockMetadataWithNotify(i + 1, j + 49, k + 15, 15, 2);
		setBlock(world, i + 1, j + 49, k + 16, Blocks.leaves, 15);
		world.setBlockMetadataWithNotify(i + 1, j + 49, k + 16, 15, 2);
		setBlock(world, i + 1, j + 50, k + 0, Blocks.log, 1);
		world.setBlockMetadataWithNotify(i + 1, j + 50, k + 0, 1, 2);
		setBlock(world, i + 1, j + 50, k + 1, Blocks.log, 1);
		world.setBlockMetadataWithNotify(i + 1, j + 50, k + 1, 1, 2);
		setBlock(world, i + 1, j + 50, k + 2, Blocks.log, 1);
		world.setBlockMetadataWithNotify(i + 1, j + 50, k + 2, 1, 2);
		setBlock(world, i + 1, j + 50, k + 3, Blocks.log, 1);
		world.setBlockMetadataWithNotify(i + 1, j + 50, k + 3, 1, 2);
		setBlock(world, i + 1, j + 50, k + 4, Blocks.log, 1);
		world.setBlockMetadataWithNotify(i + 1, j + 50, k + 4, 1, 2);
		setBlock(world, i + 1, j + 50, k + 5, Blocks.log, 1);
		world.setBlockMetadataWithNotify(i + 1, j + 50, k + 5, 1, 2);
		setBlock(world, i + 1, j + 50, k + 6, Blocks.log, 1);
		world.setBlockMetadataWithNotify(i + 1, j + 50, k + 6, 1, 2);
		setBlock(world, i + 1, j + 50, k + 14, Blocks.leaves, 15);
		world.setBlockMetadataWithNotify(i + 1, j + 50, k + 14, 15, 2);
		setBlock(world, i + 1, j + 52, k + 5, Blocks.leaves, 15);
		world.setBlockMetadataWithNotify(i + 1, j + 52, k + 5, 15, 2);
		setBlock(world, i + 1, j + 52, k + 6, Blocks.leaves, 15);
		world.setBlockMetadataWithNotify(i + 1, j + 52, k + 6, 15, 2);
		setBlock(world, i + 1, j + 53, k + 3, Blocks.leaves, 15);
		world.setBlockMetadataWithNotify(i + 1, j + 53, k + 3, 15, 2);
		setBlock(world, i + 1, j + 53, k + 4, Blocks.leaves, 15);
		world.setBlockMetadataWithNotify(i + 1, j + 53, k + 4, 15, 2);
		setBlock(world, i + 1, j + 53, k + 5, Blocks.leaves, 15);
		world.setBlockMetadataWithNotify(i + 1, j + 53, k + 5, 15, 2);
		setBlock(world, i + 1, j + 54, k + 4, Blocks.leaves, 15);
		world.setBlockMetadataWithNotify(i + 1, j + 54, k + 4, 15, 2);
		setBlock(world, i + 1, j + 54, k + 10, Blocks.leaves, 7);
		world.setBlockMetadataWithNotify(i + 1, j + 54, k + 10, 7, 2);
		setBlock(world, i + 1, j + 54, k + 11, Blocks.leaves, 7);
		world.setBlockMetadataWithNotify(i + 1, j + 54, k + 11, 7, 2);
		setBlock(world, i + 1, j + 54, k + 12, Blocks.leaves, 7);
		world.setBlockMetadataWithNotify(i + 1, j + 54, k + 12, 7, 2);
		setBlock(world, i + 1, j + 55, k + 11, Blocks.leaves, 7);
		world.setBlockMetadataWithNotify(i + 1, j + 55, k + 11, 7, 2);
		setBlock(world, i + 1, j + 56, k + 7, Blocks.leaves, 15);
		world.setBlockMetadataWithNotify(i + 1, j + 56, k + 7, 15, 2);
		setBlock(world, i + 1, j + 56, k + 8, Blocks.leaves, 15);
		world.setBlockMetadataWithNotify(i + 1, j + 56, k + 8, 15, 2);
		setBlock(world, i + 1, j + 56, k + 9, Blocks.leaves, 7);
		world.setBlockMetadataWithNotify(i + 1, j + 56, k + 9, 7, 2);
		setBlock(world, i + 1, j + 57, k + 8, Blocks.leaves, 7);
		world.setBlockMetadataWithNotify(i + 1, j + 57, k + 8, 7, 2);
		setBlock(world, i + 2, j + 20, k + 6, Blocks.log, 3);
		world.setBlockMetadataWithNotify(i + 2, j + 20, k + 6, 3, 2);
		setBlock(world, i + 2, j + 21, k + 5, Blocks.log, 3);
		world.setBlockMetadataWithNotify(i + 2, j + 21, k + 5, 3, 2);
		setBlock(world, i + 2, j + 21, k + 6, Blocks.log, 3);
		world.setBlockMetadataWithNotify(i + 2, j + 21, k + 6, 3, 2);
		setBlock(world, i + 2, j + 21, k + 7, Blocks.log, 3);
		world.setBlockMetadataWithNotify(i + 2, j + 21, k + 7, 3, 2);
		setBlock(world, i + 2, j + 21, k + 26, Blocks.log, 3);
		world.setBlockMetadataWithNotify(i + 2, j + 21, k + 26, 3, 2);
		setBlock(world, i + 2, j + 22, k + 6, Blocks.log, 3);
		world.setBlockMetadataWithNotify(i + 2, j + 22, k + 6, 3, 2);
		setBlock(world, i + 2, j + 22, k + 25, Blocks.leaves, 7);
		world.setBlockMetadataWithNotify(i + 2, j + 22, k + 25, 7, 2);
		setBlock(world, i + 2, j + 22, k + 26, Blocks.leaves, 7);
		world.setBlockMetadataWithNotify(i + 2, j + 22, k + 26, 7, 2);
		setBlock(world, i + 2, j + 22, k + 27, Blocks.leaves, 7);
		world.setBlockMetadataWithNotify(i + 2, j + 22, k + 27, 7, 2);
		setBlock(world, i + 2, j + 22, k + 28, Blocks.leaves, 7);
		world.setBlockMetadataWithNotify(i + 2, j + 22, k + 28, 7, 2);
		setBlock(world, i + 2, j + 22, k + 29, Blocks.leaves, 7);
		world.setBlockMetadataWithNotify(i + 2, j + 22, k + 29, 7, 2);
		setBlock(world, i + 2, j + 23, k + 14, Blocks.log, 3);
		world.setBlockMetadataWithNotify(i + 2, j + 23, k + 14, 3, 2);
		setBlock(world, i + 2, j + 23, k + 26, Blocks.leaves, 7);
		world.setBlockMetadataWithNotify(i + 2, j + 23, k + 26, 7, 2);
		setBlock(world, i + 2, j + 23, k + 27, Blocks.leaves, 7);
		world.setBlockMetadataWithNotify(i + 2, j + 23, k + 27, 7, 2);
		setBlock(world, i + 2, j + 23, k + 28, Blocks.leaves, 7);
		world.setBlockMetadataWithNotify(i + 2, j + 23, k + 28, 7, 2);
		setBlock(world, i + 2, j + 24, k + 0, Blocks.leaves, 15);
		world.setBlockMetadataWithNotify(i + 2, j + 24, k + 0, 15, 2);
		setBlock(world, i + 2, j + 24, k + 1, Blocks.log, 1);
		world.setBlockMetadataWithNotify(i + 2, j + 24, k + 1, 1, 2);
		setBlock(world, i + 2, j + 24, k + 6, Blocks.vine, 15);
		world.setBlockMetadataWithNotify(i + 2, j + 24, k + 6, 15, 2);
		setBlock(world, i + 2, j + 24, k + 15, Blocks.log, 3);
		world.setBlockMetadataWithNotify(i + 2, j + 24, k + 15, 3, 2);
		setBlock(world, i + 2, j + 24, k + 19, Blocks.log, 3);
		world.setBlockMetadataWithNotify(i + 2, j + 24, k + 19, 3, 2);
		setBlock(world, i + 2, j + 24, k + 27, Blocks.leaves, 7);
		world.setBlockMetadataWithNotify(i + 2, j + 24, k + 27, 7, 2);
		setBlock(world, i + 2, j + 25, k + 0, Blocks.log, 1);
		world.setBlockMetadataWithNotify(i + 2, j + 25, k + 0, 1, 2);
		setBlock(world, i + 2, j + 25, k + 1, Blocks.log, 1);
		world.setBlockMetadataWithNotify(i + 2, j + 25, k + 1, 1, 2);
		setBlock(world, i + 2, j + 25, k + 2, Blocks.log, 1);
		world.setBlockMetadataWithNotify(i + 2, j + 25, k + 2, 1, 2);
		setBlock(world, i + 2, j + 25, k + 5, Blocks.log, 1);
		world.setBlockMetadataWithNotify(i + 2, j + 25, k + 5, 1, 2);
		setBlock(world, i + 2, j + 25, k + 6, Blocks.vine, 15);
		world.setBlockMetadataWithNotify(i + 2, j + 25, k + 6, 15, 2);
		setBlock(world, i + 2, j + 25, k + 19, Blocks.log, 3);
		world.setBlockMetadataWithNotify(i + 2, j + 25, k + 19, 3, 2);
		setBlock(world, i + 2, j + 26, k + 1, Blocks.log, 1);
		world.setBlockMetadataWithNotify(i + 2, j + 26, k + 1, 1, 2);
		setBlock(world, i + 2, j + 26, k + 3, Blocks.log, 1);
		world.setBlockMetadataWithNotify(i + 2, j + 26, k + 3, 1, 2);
		setBlock(world, i + 2, j + 26, k + 4, Blocks.log, 1);
		world.setBlockMetadataWithNotify(i + 2, j + 26, k + 4, 1, 2);
		setBlock(world, i + 2, j + 26, k + 5, Blocks.log, 1);
		world.setBlockMetadataWithNotify(i + 2, j + 26, k + 5, 1, 2);
		setBlock(world, i + 2, j + 26, k + 6, Blocks.log, 1);
		world.setBlockMetadataWithNotify(i + 2, j + 26, k + 6, 1, 2);
		setBlock(world, i + 2, j + 27, k + 5, Blocks.log, 1);
		world.setBlockMetadataWithNotify(i + 2, j + 27, k + 5, 1, 2);
		setBlock(world, i + 2, j + 27, k + 17, Blocks.log, 3);
		world.setBlockMetadataWithNotify(i + 2, j + 27, k + 17, 3, 2);
		setBlock(world, i + 2, j + 28, k + 1, Blocks.spruce_stairs, 4);
		world.setBlockMetadataWithNotify(i + 2, j + 28, k + 1, 4, 2);
		setBlock(world, i + 2, j + 28, k + 5, Blocks.spruce_stairs, 4);
		world.setBlockMetadataWithNotify(i + 2, j + 28, k + 5, 4, 2);
		setBlock(world, i + 2, j + 29, k + 1, Blocks.log, 1);
		world.setBlockMetadataWithNotify(i + 2, j + 29, k + 1, 1, 2);
		setBlock(world, i + 2, j + 29, k + 5, Blocks.log, 1);
		world.setBlockMetadataWithNotify(i + 2, j + 29, k + 5, 1, 2);
		setBlock(world, i + 2, j + 29, k + 18, Blocks.log, 3);
		world.setBlockMetadataWithNotify(i + 2, j + 29, k + 18, 3, 2);
		setBlock(world, i + 2, j + 29, k + 20, Blocks.log, 3);
		world.setBlockMetadataWithNotify(i + 2, j + 29, k + 20, 3, 2);
		setBlock(world, i + 2, j + 29, k + 21, Blocks.log, 3);
		world.setBlockMetadataWithNotify(i + 2, j + 29, k + 21, 3, 2);
		setBlock(world, i + 2, j + 29, k + 23, Blocks.leaves, 7);
		world.setBlockMetadataWithNotify(i + 2, j + 29, k + 23, 7, 2);
		setBlock(world, i + 2, j + 29, k + 24, Blocks.leaves, 7);
		world.setBlockMetadataWithNotify(i + 2, j + 29, k + 24, 7, 2);
		setBlock(world, i + 2, j + 29, k + 25, Blocks.leaves, 7);
		world.setBlockMetadataWithNotify(i + 2, j + 29, k + 25, 7, 2);
		setBlock(world, i + 2, j + 30, k + 1, Blocks.log, 1);
		world.setBlockMetadataWithNotify(i + 2, j + 30, k + 1, 1, 2);
		setBlock(world, i + 2, j + 30, k + 5, Blocks.log, 1);
		world.setBlockMetadataWithNotify(i + 2, j + 30, k + 5, 1, 2);
		setBlock(world, i + 2, j + 30, k + 24, Blocks.leaves, 7);
		world.setBlockMetadataWithNotify(i + 2, j + 30, k + 24, 7, 2);
		setBlock(world, i + 2, j + 31, k + 0, Blocks.log, 1);
		world.setBlockMetadataWithNotify(i + 2, j + 31, k + 0, 1, 2);
		setBlock(world, i + 2, j + 31, k + 1, Blocks.log, 1);
		world.setBlockMetadataWithNotify(i + 2, j + 31, k + 1, 1, 2);
		setBlock(world, i + 2, j + 31, k + 2, Blocks.log, 1);
		world.setBlockMetadataWithNotify(i + 2, j + 31, k + 2, 1, 2);
		setBlock(world, i + 2, j + 31, k + 3, Blocks.log, 1);
		world.setBlockMetadataWithNotify(i + 2, j + 31, k + 3, 1, 2);
		setBlock(world, i + 2, j + 31, k + 4, Blocks.log, 1);
		world.setBlockMetadataWithNotify(i + 2, j + 31, k + 4, 1, 2);
		setBlock(world, i + 2, j + 31, k + 5, Blocks.log, 1);
		world.setBlockMetadataWithNotify(i + 2, j + 31, k + 5, 1, 2);
		setBlock(world, i + 2, j + 31, k + 6, Blocks.log, 1);
		world.setBlockMetadataWithNotify(i + 2, j + 31, k + 6, 1, 2);
		setBlock(world, i + 2, j + 31, k + 7, Blocks.log, 1);
		world.setBlockMetadataWithNotify(i + 2, j + 31, k + 7, 1, 2);
		setBlock(world, i + 2, j + 31, k + 8, Blocks.log, 1);
		world.setBlockMetadataWithNotify(i + 2, j + 31, k + 8, 1, 2);
		setBlock(world, i + 2, j + 31, k + 9, Blocks.log, 1);
		world.setBlockMetadataWithNotify(i + 2, j + 31, k + 9, 1, 2);
		setBlock(world, i + 2, j + 31, k + 17, Blocks.log, 3);
		world.setBlockMetadataWithNotify(i + 2, j + 31, k + 17, 3, 2);
		setBlock(world, i + 2, j + 32, k + 0, Blocks.log, 1);
		world.setBlockMetadataWithNotify(i + 2, j + 32, k + 0, 1, 2);
		setBlock(world, i + 2, j + 32, k + 1, Blocks.log, 1);
		world.setBlockMetadataWithNotify(i + 2, j + 32, k + 1, 1, 2);
		setBlock(world, i + 2, j + 32, k + 2, Blocks.log, 1);
		world.setBlockMetadataWithNotify(i + 2, j + 32, k + 2, 1, 2);
		setBlock(world, i + 2, j + 32, k + 3, Blocks.log, 1);
		world.setBlockMetadataWithNotify(i + 2, j + 32, k + 3, 1, 2);
		setBlock(world, i + 2, j + 32, k + 4, Blocks.log, 1);
		world.setBlockMetadataWithNotify(i + 2, j + 32, k + 4, 1, 2);
		setBlock(world, i + 2, j + 32, k + 5, Blocks.log, 1);
		world.setBlockMetadataWithNotify(i + 2, j + 32, k + 5, 1, 2);
		setBlock(world, i + 2, j + 32, k + 6, Blocks.log, 1);
		world.setBlockMetadataWithNotify(i + 2, j + 32, k + 6, 1, 2);
		setBlock(world, i + 2, j + 32, k + 7, Blocks.log, 1);
		world.setBlockMetadataWithNotify(i + 2, j + 32, k + 7, 1, 2);
		setBlock(world, i + 2, j + 33, k + 0, Blocks.log, 1);
		world.setBlockMetadataWithNotify(i + 2, j + 33, k + 0, 1, 2);
		setBlock(world, i + 2, j + 33, k + 1, Blocks.log, 1);
		world.setBlockMetadataWithNotify(i + 2, j + 33, k + 1, 1, 2);
		setBlock(world, i + 2, j + 33, k + 2, Blocks.log, 1);
		world.setBlockMetadataWithNotify(i + 2, j + 33, k + 2, 1, 2);
		setBlock(world, i + 2, j + 33, k + 3, Blocks.log, 1);
		world.setBlockMetadataWithNotify(i + 2, j + 33, k + 3, 1, 2);
		setBlock(world, i + 2, j + 33, k + 4, Blocks.log, 1);
		world.setBlockMetadataWithNotify(i + 2, j + 33, k + 4, 1, 2);
		setBlock(world, i + 2, j + 33, k + 5, Blocks.log, 1);
		world.setBlockMetadataWithNotify(i + 2, j + 33, k + 5, 1, 2);
		setBlock(world, i + 2, j + 33, k + 6, Blocks.log, 1);
		world.setBlockMetadataWithNotify(i + 2, j + 33, k + 6, 1, 2);
		setBlock(world, i + 2, j + 33, k + 7, Blocks.log, 1);
		world.setBlockMetadataWithNotify(i + 2, j + 33, k + 7, 1, 2);
		setBlock(world, i + 2, j + 34, k + 1, Blocks.log, 1);
		world.setBlockMetadataWithNotify(i + 2, j + 34, k + 1, 1, 2);
		setBlock(world, i + 2, j + 34, k + 2, Blocks.log, 1);
		world.setBlockMetadataWithNotify(i + 2, j + 34, k + 2, 1, 2);
		setBlock(world, i + 2, j + 34, k + 3, Blocks.log, 1);
		world.setBlockMetadataWithNotify(i + 2, j + 34, k + 3, 1, 2);
		setBlock(world, i + 2, j + 34, k + 4, Blocks.log, 1);
		world.setBlockMetadataWithNotify(i + 2, j + 34, k + 4, 1, 2);
		setBlock(world, i + 2, j + 34, k + 5, Blocks.log, 1);
		world.setBlockMetadataWithNotify(i + 2, j + 34, k + 5, 1, 2);
		setBlock(world, i + 2, j + 35, k + 18, Blocks.log, 3);
		world.setBlockMetadataWithNotify(i + 2, j + 35, k + 18, 3, 2);
		setBlock(world, i + 2, j + 36, k + 11, Blocks.leaves, 7);
		world.setBlockMetadataWithNotify(i + 2, j + 36, k + 11, 7, 2);
		setBlock(world, i + 2, j + 36, k + 12, Blocks.leaves, 7);
		world.setBlockMetadataWithNotify(i + 2, j + 36, k + 12, 7, 2);
		setBlock(world, i + 2, j + 36, k + 13, Blocks.leaves, 7);
		world.setBlockMetadataWithNotify(i + 2, j + 36, k + 13, 7, 2);
		setBlock(world, i + 2, j + 36, k + 14, Blocks.leaves, 7);
		world.setBlockMetadataWithNotify(i + 2, j + 36, k + 14, 7, 2);
		setBlock(world, i + 2, j + 36, k + 15, Blocks.leaves, 7);
		world.setBlockMetadataWithNotify(i + 2, j + 36, k + 15, 7, 2);
		setBlock(world, i + 2, j + 37, k + 2, Blocks.log, 3);
		world.setBlockMetadataWithNotify(i + 2, j + 37, k + 2, 3, 2);
		setBlock(world, i + 2, j + 37, k + 12, Blocks.leaves, 7);
		world.setBlockMetadataWithNotify(i + 2, j + 37, k + 12, 7, 2);
		setBlock(world, i + 2, j + 37, k + 13, Blocks.leaves, 7);
		world.setBlockMetadataWithNotify(i + 2, j + 37, k + 13, 7, 2);
		setBlock(world, i + 2, j + 37, k + 14, Blocks.leaves, 7);
		world.setBlockMetadataWithNotify(i + 2, j + 37, k + 14, 7, 2);
		setBlock(world, i + 2, j + 38, k + 0, Blocks.leaves, 7);
		world.setBlockMetadataWithNotify(i + 2, j + 38, k + 0, 7, 2);
		setBlock(world, i + 2, j + 38, k + 1, Blocks.leaves, 7);
		world.setBlockMetadataWithNotify(i + 2, j + 38, k + 1, 7, 2);
		setBlock(world, i + 2, j + 38, k + 13, Blocks.leaves, 7);
		world.setBlockMetadataWithNotify(i + 2, j + 38, k + 13, 7, 2);
		setBlock(world, i + 2, j + 38, k + 14, Blocks.log, 3);
		world.setBlockMetadataWithNotify(i + 2, j + 38, k + 14, 3, 2);
		setBlock(world, i + 2, j + 38, k + 19, Blocks.log, 3);
		world.setBlockMetadataWithNotify(i + 2, j + 38, k + 19, 3, 2);
		setBlock(world, i + 2, j + 39, k + 0, Blocks.leaves, 15);
		world.setBlockMetadataWithNotify(i + 2, j + 39, k + 0, 15, 2);
		setBlock(world, i + 2, j + 39, k + 18, Blocks.leaves, 7);
		world.setBlockMetadataWithNotify(i + 2, j + 39, k + 18, 7, 2);
		setBlock(world, i + 2, j + 39, k + 19, Blocks.leaves, 7);
		world.setBlockMetadataWithNotify(i + 2, j + 39, k + 19, 7, 2);
		setBlock(world, i + 2, j + 39, k + 20, Blocks.leaves, 7);
		world.setBlockMetadataWithNotify(i + 2, j + 39, k + 20, 7, 2);
		setBlock(world, i + 2, j + 39, k + 21, Blocks.leaves, 7);
		world.setBlockMetadataWithNotify(i + 2, j + 39, k + 21, 7, 2);
		setBlock(world, i + 2, j + 39, k + 22, Blocks.leaves, 7);
		world.setBlockMetadataWithNotify(i + 2, j + 39, k + 22, 7, 2);
		setBlock(world, i + 2, j + 40, k + 5, Blocks.log, 3);
		world.setBlockMetadataWithNotify(i + 2, j + 40, k + 5, 3, 2);
		setBlock(world, i + 2, j + 40, k + 19, Blocks.leaves, 7);
		world.setBlockMetadataWithNotify(i + 2, j + 40, k + 19, 7, 2);
		setBlock(world, i + 2, j + 40, k + 20, Blocks.leaves, 7);
		world.setBlockMetadataWithNotify(i + 2, j + 40, k + 20, 7, 2);
		setBlock(world, i + 2, j + 40, k + 21, Blocks.leaves, 7);
		world.setBlockMetadataWithNotify(i + 2, j + 40, k + 21, 7, 2);
		setBlock(world, i + 2, j + 41, k + 2, Blocks.leaves, 15);
		world.setBlockMetadataWithNotify(i + 2, j + 41, k + 2, 15, 2);
		setBlock(world, i + 2, j + 41, k + 3, Blocks.leaves, 15);
		world.setBlockMetadataWithNotify(i + 2, j + 41, k + 3, 15, 2);
		setBlock(world, i + 2, j + 41, k + 4, Blocks.leaves, 15);
		world.setBlockMetadataWithNotify(i + 2, j + 41, k + 4, 15, 2);
		setBlock(world, i + 2, j + 41, k + 5, Blocks.leaves, 15);
		world.setBlockMetadataWithNotify(i + 2, j + 41, k + 5, 15, 2);
		setBlock(world, i + 2, j + 41, k + 6, Blocks.leaves, 15);
		world.setBlockMetadataWithNotify(i + 2, j + 41, k + 6, 15, 2);
		setBlock(world, i + 2, j + 41, k + 20, Blocks.leaves, 7);
		world.setBlockMetadataWithNotify(i + 2, j + 41, k + 20, 7, 2);
		setBlock(world, i + 2, j + 42, k + 1, Blocks.leaves, 15);
		world.setBlockMetadataWithNotify(i + 2, j + 42, k + 1, 15, 2);
		setBlock(world, i + 2, j + 42, k + 2, Blocks.leaves, 15);
		world.setBlockMetadataWithNotify(i + 2, j + 42, k + 2, 15, 2);
		setBlock(world, i + 2, j + 42, k + 3, Blocks.log, 3);
		world.setBlockMetadataWithNotify(i + 2, j + 42, k + 3, 3, 2);
		setBlock(world, i + 2, j + 42, k + 4, Blocks.leaves, 15);
		world.setBlockMetadataWithNotify(i + 2, j + 42, k + 4, 15, 2);
		setBlock(world, i + 2, j + 42, k + 5, Blocks.log, 3);
		world.setBlockMetadataWithNotify(i + 2, j + 42, k + 5, 3, 2);
		setBlock(world, i + 2, j + 43, k + 0, Blocks.log, 1);
		world.setBlockMetadataWithNotify(i + 2, j + 43, k + 0, 1, 2);
		setBlock(world, i + 2, j + 43, k + 1, Blocks.log, 1);
		world.setBlockMetadataWithNotify(i + 2, j + 43, k + 1, 1, 2);
		setBlock(world, i + 2, j + 43, k + 2, Blocks.planks, 5);
		world.setBlockMetadataWithNotify(i + 2, j + 43, k + 2, 5, 2);
		setBlock(world, i + 2, j + 43, k + 3, Blocks.log, 1);
		world.setBlockMetadataWithNotify(i + 2, j + 43, k + 3, 1, 2);
		setBlock(world, i + 2, j + 43, k + 4, Blocks.log, 1);
		world.setBlockMetadataWithNotify(i + 2, j + 43, k + 4, 1, 2);
		setBlock(world, i + 2, j + 43, k + 5, Blocks.log, 1);
		world.setBlockMetadataWithNotify(i + 2, j + 43, k + 5, 1, 2);
		setBlock(world, i + 2, j + 43, k + 6, Blocks.log, 1);
		world.setBlockMetadataWithNotify(i + 2, j + 43, k + 6, 1, 2);
		setBlock(world, i + 2, j + 43, k + 7, Blocks.log, 1);
		world.setBlockMetadataWithNotify(i + 2, j + 43, k + 7, 1, 2);
		setBlock(world, i + 2, j + 43, k + 8, Blocks.log, 1);
		world.setBlockMetadataWithNotify(i + 2, j + 43, k + 8, 1, 2);
		setBlock(world, i + 2, j + 44, k + 7, Blocks.spruce_stairs, 2);
		world.setBlockMetadataWithNotify(i + 2, j + 44, k + 7, 2, 2);
		setBlock(world, i + 2, j + 44, k + 8, Blocks.log, 1);
		world.setBlockMetadataWithNotify(i + 2, j + 44, k + 8, 1, 2);
		setBlock(world, i + 2, j + 44, k + 9, Blocks.spruce_stairs, 7);
		world.setBlockMetadataWithNotify(i + 2, j + 44, k + 9, 7, 2);
		setBlock(world, i + 2, j + 45, k + 8, Blocks.log, 1);
		world.setBlockMetadataWithNotify(i + 2, j + 45, k + 8, 1, 2);
		setBlock(world, i + 2, j + 45, k + 9, Blocks.log, 1);
		world.setBlockMetadataWithNotify(i + 2, j + 45, k + 9, 1, 2);
		setBlock(world, i + 2, j + 45, k + 10, Blocks.spruce_stairs, 7);
		world.setBlockMetadataWithNotify(i + 2, j + 45, k + 10, 7, 2);
		setBlock(world, i + 2, j + 46, k + 9, Blocks.log, 1);
		world.setBlockMetadataWithNotify(i + 2, j + 46, k + 9, 1, 2);
		setBlock(world, i + 2, j + 46, k + 10, Blocks.log, 1);
		world.setBlockMetadataWithNotify(i + 2, j + 46, k + 10, 1, 2);
		setBlock(world, i + 2, j + 47, k + 10, Blocks.log, 1);
		world.setBlockMetadataWithNotify(i + 2, j + 47, k + 10, 1, 2);
		setBlock(world, i + 2, j + 48, k + 5, Blocks.log, 1);
		world.setBlockMetadataWithNotify(i + 2, j + 48, k + 5, 1, 2);
		setBlock(world, i + 2, j + 48, k + 6, Blocks.log, 1);
		world.setBlockMetadataWithNotify(i + 2, j + 48, k + 6, 1, 2);
		setBlock(world, i + 2, j + 48, k + 7, Blocks.log, 1);
		world.setBlockMetadataWithNotify(i + 2, j + 48, k + 7, 1, 2);
		setBlock(world, i + 2, j + 48, k + 8, Blocks.log, 1);
		world.setBlockMetadataWithNotify(i + 2, j + 48, k + 8, 1, 2);
		setBlock(world, i + 2, j + 48, k + 9, Blocks.log, 1);
		world.setBlockMetadataWithNotify(i + 2, j + 48, k + 9, 1, 2);
		setBlock(world, i + 2, j + 48, k + 10, Blocks.log, 1);
		world.setBlockMetadataWithNotify(i + 2, j + 48, k + 10, 1, 2);
		setBlock(world, i + 2, j + 48, k + 11, Blocks.log, 1);
		world.setBlockMetadataWithNotify(i + 2, j + 48, k + 11, 1, 2);
		setBlock(world, i + 2, j + 48, k + 14, Blocks.leaves, 15);
		world.setBlockMetadataWithNotify(i + 2, j + 48, k + 14, 15, 2);
		setBlock(world, i + 2, j + 48, k + 15, Blocks.leaves, 15);
		world.setBlockMetadataWithNotify(i + 2, j + 48, k + 15, 15, 2);
		setBlock(world, i + 2, j + 48, k + 16, Blocks.leaves, 15);
		world.setBlockMetadataWithNotify(i + 2, j + 48, k + 16, 15, 2);
		setBlock(world, i + 2, j + 49, k + 4, Blocks.log, 1);
		world.setBlockMetadataWithNotify(i + 2, j + 49, k + 4, 1, 2);
		setBlock(world, i + 2, j + 49, k + 5, Blocks.log, 1);
		world.setBlockMetadataWithNotify(i + 2, j + 49, k + 5, 1, 2);
		setBlock(world, i + 2, j + 49, k + 6, Blocks.log, 1);
		world.setBlockMetadataWithNotify(i + 2, j + 49, k + 6, 1, 2);
		setBlock(world, i + 2, j + 49, k + 7, Blocks.log, 1);
		world.setBlockMetadataWithNotify(i + 2, j + 49, k + 7, 1, 2);
		setBlock(world, i + 2, j + 49, k + 8, Blocks.log, 1);
		world.setBlockMetadataWithNotify(i + 2, j + 49, k + 8, 1, 2);
		setBlock(world, i + 2, j + 49, k + 9, Blocks.log, 1);
		world.setBlockMetadataWithNotify(i + 2, j + 49, k + 9, 1, 2);
		setBlock(world, i + 2, j + 49, k + 10, Blocks.log, 1);
		world.setBlockMetadataWithNotify(i + 2, j + 49, k + 10, 1, 2);
		setBlock(world, i + 2, j + 50, k + 0, Blocks.log, 1);
		world.setBlockMetadataWithNotify(i + 2, j + 50, k + 0, 1, 2);
		setBlock(world, i + 2, j + 50, k + 1, Blocks.log, 1);
		world.setBlockMetadataWithNotify(i + 2, j + 50, k + 1, 1, 2);
		setBlock(world, i + 2, j + 50, k + 2, Blocks.log, 1);
		world.setBlockMetadataWithNotify(i + 2, j + 50, k + 2, 1, 2);
		setBlock(world, i + 2, j + 50, k + 3, Blocks.log, 1);
		world.setBlockMetadataWithNotify(i + 2, j + 50, k + 3, 1, 2);
		setBlock(world, i + 2, j + 50, k + 4, Blocks.log, 1);
		world.setBlockMetadataWithNotify(i + 2, j + 50, k + 4, 1, 2);
		setBlock(world, i + 2, j + 50, k + 5, Blocks.log, 1);
		world.setBlockMetadataWithNotify(i + 2, j + 50, k + 5, 1, 2);
		setBlock(world, i + 2, j + 50, k + 6, Blocks.log, 1);
		world.setBlockMetadataWithNotify(i + 2, j + 50, k + 6, 1, 2);
		setBlock(world, i + 2, j + 50, k + 7, Blocks.log, 1);
		world.setBlockMetadataWithNotify(i + 2, j + 50, k + 7, 1, 2);
		setBlock(world, i + 2, j + 51, k + 0, Blocks.log, 1);
		world.setBlockMetadataWithNotify(i + 2, j + 51, k + 0, 1, 2);
		setBlock(world, i + 2, j + 51, k + 1, Blocks.log, 1);
		world.setBlockMetadataWithNotify(i + 2, j + 51, k + 1, 1, 2);
		setBlock(world, i + 2, j + 51, k + 2, Blocks.log, 1);
		world.setBlockMetadataWithNotify(i + 2, j + 51, k + 2, 1, 2);
		setBlock(world, i + 3, j + 20, k + 6, Blocks.log, 1);
		world.setBlockMetadataWithNotify(i + 3, j + 20, k + 6, 1, 2);
		setBlock(world, i + 3, j + 21, k + 6, Blocks.log, 1);
		world.setBlockMetadataWithNotify(i + 3, j + 21, k + 6, 1, 2);
		setBlock(world, i + 3, j + 21, k + 7, Blocks.log, 1);
		world.setBlockMetadataWithNotify(i + 3, j + 21, k + 7, 1, 2);
		setBlock(world, i + 3, j + 22, k + 6, Blocks.log, 1);
		world.setBlockMetadataWithNotify(i + 3, j + 22, k + 6, 1, 2);
		setBlock(world, i + 3, j + 22, k + 25, Blocks.leaves, 7);
		world.setBlockMetadataWithNotify(i + 3, j + 22, k + 25, 7, 2);
		setBlock(world, i + 3, j + 22, k + 26, Blocks.leaves, 7);
		world.setBlockMetadataWithNotify(i + 3, j + 22, k + 26, 7, 2);
		setBlock(world, i + 3, j + 22, k + 27, Blocks.log, 3);
		world.setBlockMetadataWithNotify(i + 3, j + 22, k + 27, 3, 2);
		setBlock(world, i + 3, j + 22, k + 28, Blocks.leaves, 7);
		world.setBlockMetadataWithNotify(i + 3, j + 22, k + 28, 7, 2);
		setBlock(world, i + 3, j + 22, k + 29, Blocks.leaves, 7);
		world.setBlockMetadataWithNotify(i + 3, j + 22, k + 29, 7, 2);
		setBlock(world, i + 3, j + 23, k + 25, Blocks.leaves, 7);
		world.setBlockMetadataWithNotify(i + 3, j + 23, k + 25, 7, 2);
		setBlock(world, i + 3, j + 23, k + 26, Blocks.leaves, 7);
		world.setBlockMetadataWithNotify(i + 3, j + 23, k + 26, 7, 2);
		setBlock(world, i + 3, j + 23, k + 27, Blocks.leaves, 7);
		world.setBlockMetadataWithNotify(i + 3, j + 23, k + 27, 7, 2);
		setBlock(world, i + 3, j + 23, k + 28, Blocks.leaves, 7);
		world.setBlockMetadataWithNotify(i + 3, j + 23, k + 28, 7, 2);
		setBlock(world, i + 3, j + 23, k + 29, Blocks.leaves, 7);
		world.setBlockMetadataWithNotify(i + 3, j + 23, k + 29, 7, 2);
		setBlock(world, i + 3, j + 24, k + 20, Blocks.log, 3);
		world.setBlockMetadataWithNotify(i + 3, j + 24, k + 20, 3, 2);
		setBlock(world, i + 3, j + 24, k + 26, Blocks.leaves, 15);
		world.setBlockMetadataWithNotify(i + 3, j + 24, k + 26, 15, 2);
		setBlock(world, i + 3, j + 24, k + 27, Blocks.leaves, 7);
		world.setBlockMetadataWithNotify(i + 3, j + 24, k + 27, 7, 2);
		setBlock(world, i + 3, j + 24, k + 28, Blocks.leaves, 7);
		world.setBlockMetadataWithNotify(i + 3, j + 24, k + 28, 7, 2);
		setBlock(world, i + 3, j + 25, k + 4, Blocks.log, 1);
		world.setBlockMetadataWithNotify(i + 3, j + 25, k + 4, 1, 2);
		setBlock(world, i + 3, j + 25, k + 5, Blocks.log, 1);
		world.setBlockMetadataWithNotify(i + 3, j + 25, k + 5, 1, 2);
		setBlock(world, i + 3, j + 25, k + 6, Blocks.log, 1);
		world.setBlockMetadataWithNotify(i + 3, j + 25, k + 6, 1, 2);
		setBlock(world, i + 3, j + 25, k + 27, Blocks.leaves, 7);
		world.setBlockMetadataWithNotify(i + 3, j + 25, k + 27, 7, 2);
		setBlock(world, i + 3, j + 26, k + 3, Blocks.log, 1);
		world.setBlockMetadataWithNotify(i + 3, j + 26, k + 3, 1, 2);
		setBlock(world, i + 3, j + 26, k + 4, Blocks.log, 1);
		world.setBlockMetadataWithNotify(i + 3, j + 26, k + 4, 1, 2);
		setBlock(world, i + 3, j + 26, k + 5, Blocks.log, 1);
		world.setBlockMetadataWithNotify(i + 3, j + 26, k + 5, 1, 2);
		setBlock(world, i + 3, j + 26, k + 6, Blocks.log, 1);
		world.setBlockMetadataWithNotify(i + 3, j + 26, k + 6, 1, 2);
		setBlock(world, i + 3, j + 26, k + 20, Blocks.log, 3);
		world.setBlockMetadataWithNotify(i + 3, j + 26, k + 20, 3, 2);
		setBlock(world, i + 3, j + 27, k + 1, Blocks.log, 1);
		world.setBlockMetadataWithNotify(i + 3, j + 27, k + 1, 1, 2);
		setBlock(world, i + 3, j + 27, k + 2, Blocks.log, 1);
		world.setBlockMetadataWithNotify(i + 3, j + 27, k + 2, 1, 2);
		setBlock(world, i + 3, j + 27, k + 3, Blocks.log, 1);
		world.setBlockMetadataWithNotify(i + 3, j + 27, k + 3, 1, 2);
		setBlock(world, i + 3, j + 27, k + 4, Blocks.log, 1);
		world.setBlockMetadataWithNotify(i + 3, j + 27, k + 4, 1, 2);
		setBlock(world, i + 3, j + 27, k + 5, Blocks.log, 1);
		world.setBlockMetadataWithNotify(i + 3, j + 27, k + 5, 1, 2);
		setBlock(world, i + 3, j + 27, k + 6, Blocks.log, 1);
		world.setBlockMetadataWithNotify(i + 3, j + 27, k + 6, 1, 2);
		setBlock(world, i + 3, j + 27, k + 18, Blocks.log, 3);
		world.setBlockMetadataWithNotify(i + 3, j + 27, k + 18, 3, 2);
		setBlock(world, i + 3, j + 28, k + 0, Blocks.spruce_stairs, 2);
		world.setBlockMetadataWithNotify(i + 3, j + 28, k + 0, 2, 2);
		setBlock(world, i + 3, j + 28, k + 1, Blocks.log, 1);
		world.setBlockMetadataWithNotify(i + 3, j + 28, k + 1, 1, 2);
		setBlock(world, i + 3, j + 28, k + 5, Blocks.log, 1);
		world.setBlockMetadataWithNotify(i + 3, j + 28, k + 5, 1, 2);
		setBlock(world, i + 3, j + 28, k + 6, Blocks.spruce_stairs, 3);
		world.setBlockMetadataWithNotify(i + 3, j + 28, k + 6, 3, 2);
		setBlock(world, i + 3, j + 29, k + 1, Blocks.log, 1);
		world.setBlockMetadataWithNotify(i + 3, j + 29, k + 1, 1, 2);
		setBlock(world, i + 3, j + 29, k + 5, Blocks.log, 1);
		world.setBlockMetadataWithNotify(i + 3, j + 29, k + 5, 1, 2);
		setBlock(world, i + 3, j + 29, k + 19, Blocks.log, 3);
		world.setBlockMetadataWithNotify(i + 3, j + 29, k + 19, 3, 2);
		setBlock(world, i + 3, j + 29, k + 22, Blocks.log, 3);
		world.setBlockMetadataWithNotify(i + 3, j + 29, k + 22, 3, 2);
		setBlock(world, i + 3, j + 30, k + 23, Blocks.leaves, 15);
		world.setBlockMetadataWithNotify(i + 3, j + 30, k + 23, 15, 2);
		setBlock(world, i + 3, j + 30, k + 24, Blocks.leaves, 15);
		world.setBlockMetadataWithNotify(i + 3, j + 30, k + 24, 15, 2);
		setBlock(world, i + 3, j + 30, k + 25, Blocks.leaves, 15);
		world.setBlockMetadataWithNotify(i + 3, j + 30, k + 25, 15, 2);
		setBlock(world, i + 3, j + 31, k + 0, Blocks.log, 1);
		world.setBlockMetadataWithNotify(i + 3, j + 31, k + 0, 1, 2);
		setBlock(world, i + 3, j + 31, k + 1, Blocks.log, 1);
		world.setBlockMetadataWithNotify(i + 3, j + 31, k + 1, 1, 2);
		setBlock(world, i + 3, j + 31, k + 2, Blocks.log, 1);
		world.setBlockMetadataWithNotify(i + 3, j + 31, k + 2, 1, 2);
		setBlock(world, i + 3, j + 31, k + 3, Blocks.log, 1);
		world.setBlockMetadataWithNotify(i + 3, j + 31, k + 3, 1, 2);
		setBlock(world, i + 3, j + 31, k + 4, Blocks.log, 1);
		world.setBlockMetadataWithNotify(i + 3, j + 31, k + 4, 1, 2);
		setBlock(world, i + 3, j + 31, k + 5, Blocks.log, 1);
		world.setBlockMetadataWithNotify(i + 3, j + 31, k + 5, 1, 2);
		setBlock(world, i + 3, j + 31, k + 6, Blocks.log, 1);
		world.setBlockMetadataWithNotify(i + 3, j + 31, k + 6, 1, 2);
		setBlock(world, i + 3, j + 31, k + 7, Blocks.log, 1);
		world.setBlockMetadataWithNotify(i + 3, j + 31, k + 7, 1, 2);
		setBlock(world, i + 3, j + 31, k + 8, Blocks.log, 1);
		world.setBlockMetadataWithNotify(i + 3, j + 31, k + 8, 1, 2);
		setBlock(world, i + 3, j + 31, k + 9, Blocks.log, 1);
		world.setBlockMetadataWithNotify(i + 3, j + 31, k + 9, 1, 2);
		setBlock(world, i + 3, j + 31, k + 10, Blocks.log, 1);
		world.setBlockMetadataWithNotify(i + 3, j + 31, k + 10, 1, 2);
		setBlock(world, i + 3, j + 31, k + 18, Blocks.log, 3);
		world.setBlockMetadataWithNotify(i + 3, j + 31, k + 18, 3, 2);
		setBlock(world, i + 3, j + 31, k + 24, Blocks.leaves, 15);
		world.setBlockMetadataWithNotify(i + 3, j + 31, k + 24, 15, 2);
		setBlock(world, i + 3, j + 32, k + 0, Blocks.log, 1);
		world.setBlockMetadataWithNotify(i + 3, j + 32, k + 0, 1, 2);
		setBlock(world, i + 3, j + 32, k + 1, Blocks.log, 1);
		world.setBlockMetadataWithNotify(i + 3, j + 32, k + 1, 1, 2);
		setBlock(world, i + 3, j + 32, k + 2, Blocks.log, 1);
		world.setBlockMetadataWithNotify(i + 3, j + 32, k + 2, 1, 2);
		setBlock(world, i + 3, j + 32, k + 3, Blocks.log, 1);
		world.setBlockMetadataWithNotify(i + 3, j + 32, k + 3, 1, 2);
		setBlock(world, i + 3, j + 32, k + 4, Blocks.log, 1);
		world.setBlockMetadataWithNotify(i + 3, j + 32, k + 4, 1, 2);
		setBlock(world, i + 3, j + 32, k + 5, Blocks.log, 1);
		world.setBlockMetadataWithNotify(i + 3, j + 32, k + 5, 1, 2);
		setBlock(world, i + 3, j + 32, k + 6, Blocks.log, 1);
		world.setBlockMetadataWithNotify(i + 3, j + 32, k + 6, 1, 2);
		setBlock(world, i + 3, j + 32, k + 7, Blocks.log, 1);
		world.setBlockMetadataWithNotify(i + 3, j + 32, k + 7, 1, 2);
		setBlock(world, i + 3, j + 32, k + 8, Blocks.log, 1);
		world.setBlockMetadataWithNotify(i + 3, j + 32, k + 8, 1, 2);
		setBlock(world, i + 3, j + 32, k + 9, Blocks.log, 1);
		world.setBlockMetadataWithNotify(i + 3, j + 32, k + 9, 1, 2);
		setBlock(world, i + 3, j + 32, k + 18, Blocks.leaves, 15);
		world.setBlockMetadataWithNotify(i + 3, j + 32, k + 18, 15, 2);
		setBlock(world, i + 3, j + 32, k + 19, Blocks.leaves, 15);
		world.setBlockMetadataWithNotify(i + 3, j + 32, k + 19, 15, 2);
		setBlock(world, i + 3, j + 32, k + 20, Blocks.leaves, 15);
		world.setBlockMetadataWithNotify(i + 3, j + 32, k + 20, 15, 2);
		setBlock(world, i + 3, j + 33, k + 0, Blocks.log, 1);
		world.setBlockMetadataWithNotify(i + 3, j + 33, k + 0, 1, 2);
		setBlock(world, i + 3, j + 33, k + 1, Blocks.log, 1);
		world.setBlockMetadataWithNotify(i + 3, j + 33, k + 1, 1, 2);
		setBlock(world, i + 3, j + 33, k + 2, Blocks.log, 1);
		world.setBlockMetadataWithNotify(i + 3, j + 33, k + 2, 1, 2);
		setBlock(world, i + 3, j + 33, k + 3, Blocks.log, 1);
		world.setBlockMetadataWithNotify(i + 3, j + 33, k + 3, 1, 2);
		setBlock(world, i + 3, j + 33, k + 4, Blocks.log, 1);
		world.setBlockMetadataWithNotify(i + 3, j + 33, k + 4, 1, 2);
		setBlock(world, i + 3, j + 33, k + 5, Blocks.log, 1);
		world.setBlockMetadataWithNotify(i + 3, j + 33, k + 5, 1, 2);
		setBlock(world, i + 3, j + 33, k + 6, Blocks.log, 1);
		world.setBlockMetadataWithNotify(i + 3, j + 33, k + 6, 1, 2);
		setBlock(world, i + 3, j + 33, k + 7, Blocks.log, 1);
		world.setBlockMetadataWithNotify(i + 3, j + 33, k + 7, 1, 2);
		setBlock(world, i + 3, j + 33, k + 8, Blocks.log, 1);
		world.setBlockMetadataWithNotify(i + 3, j + 33, k + 8, 1, 2);
		setBlock(world, i + 3, j + 33, k + 19, Blocks.leaves, 7);
		world.setBlockMetadataWithNotify(i + 3, j + 33, k + 19, 7, 2);
		setBlock(world, i + 3, j + 34, k + 0, Blocks.log, 1);
		world.setBlockMetadataWithNotify(i + 3, j + 34, k + 0, 1, 2);
		setBlock(world, i + 3, j + 34, k + 1, Blocks.log, 1);
		world.setBlockMetadataWithNotify(i + 3, j + 34, k + 1, 1, 2);
		setBlock(world, i + 3, j + 34, k + 2, Blocks.log, 1);
		world.setBlockMetadataWithNotify(i + 3, j + 34, k + 2, 1, 2);
		setBlock(world, i + 3, j + 34, k + 3, Blocks.log, 1);
		world.setBlockMetadataWithNotify(i + 3, j + 34, k + 3, 1, 2);
		setBlock(world, i + 3, j + 34, k + 4, Blocks.log, 1);
		world.setBlockMetadataWithNotify(i + 3, j + 34, k + 4, 1, 2);
		setBlock(world, i + 3, j + 34, k + 5, Blocks.log, 1);
		world.setBlockMetadataWithNotify(i + 3, j + 34, k + 5, 1, 2);
		setBlock(world, i + 3, j + 34, k + 6, Blocks.log, 1);
		world.setBlockMetadataWithNotify(i + 3, j + 34, k + 6, 1, 2);
		setBlock(world, i + 3, j + 34, k + 7, Blocks.log, 1);
		world.setBlockMetadataWithNotify(i + 3, j + 34, k + 7, 1, 2);
		setBlock(world, i + 3, j + 35, k + 1, Blocks.log, 1);
		world.setBlockMetadataWithNotify(i + 3, j + 35, k + 1, 1, 2);
		setBlock(world, i + 3, j + 35, k + 2, Blocks.log, 1);
		world.setBlockMetadataWithNotify(i + 3, j + 35, k + 2, 1, 2);
		setBlock(world, i + 3, j + 35, k + 3, Blocks.log, 1);
		world.setBlockMetadataWithNotify(i + 3, j + 35, k + 3, 1, 2);
		setBlock(world, i + 3, j + 35, k + 4, Blocks.log, 1);
		world.setBlockMetadataWithNotify(i + 3, j + 35, k + 4, 1, 2);
		setBlock(world, i + 3, j + 35, k + 5, Blocks.log, 1);
		world.setBlockMetadataWithNotify(i + 3, j + 35, k + 5, 1, 2);
		setBlock(world, i + 3, j + 35, k + 19, Blocks.log, 3);
		world.setBlockMetadataWithNotify(i + 3, j + 35, k + 19, 3, 2);
		setBlock(world, i + 3, j + 36, k + 12, Blocks.leaves, 7);
		world.setBlockMetadataWithNotify(i + 3, j + 36, k + 12, 7, 2);
		setBlock(world, i + 3, j + 36, k + 13, Blocks.leaves, 7);
		world.setBlockMetadataWithNotify(i + 3, j + 36, k + 13, 7, 2);
		setBlock(world, i + 3, j + 36, k + 14, Blocks.leaves, 7);
		world.setBlockMetadataWithNotify(i + 3, j + 36, k + 14, 7, 2);
		setBlock(world, i + 3, j + 36, k + 19, Blocks.leaves, 7);
		world.setBlockMetadataWithNotify(i + 3, j + 36, k + 19, 7, 2);
		setBlock(world, i + 3, j + 36, k + 20, Blocks.leaves, 7);
		world.setBlockMetadataWithNotify(i + 3, j + 36, k + 20, 7, 2);
		setBlock(world, i + 3, j + 36, k + 21, Blocks.leaves, 7);
		world.setBlockMetadataWithNotify(i + 3, j + 36, k + 21, 7, 2);
		setBlock(world, i + 3, j + 37, k + 1, Blocks.log, 3);
		world.setBlockMetadataWithNotify(i + 3, j + 37, k + 1, 3, 2);
		setBlock(world, i + 3, j + 37, k + 13, Blocks.leaves, 7);
		world.setBlockMetadataWithNotify(i + 3, j + 37, k + 13, 7, 2);
		setBlock(world, i + 3, j + 37, k + 20, Blocks.leaves, 7);
		world.setBlockMetadataWithNotify(i + 3, j + 37, k + 20, 7, 2);
		setBlock(world, i + 3, j + 38, k + 0, Blocks.leaves, 7);
		world.setBlockMetadataWithNotify(i + 3, j + 38, k + 0, 7, 2);
		setBlock(world, i + 3, j + 38, k + 1, Blocks.leaves, 7);
		world.setBlockMetadataWithNotify(i + 3, j + 38, k + 1, 7, 2);
		setBlock(world, i + 3, j + 38, k + 2, Blocks.leaves, 7);
		world.setBlockMetadataWithNotify(i + 3, j + 38, k + 2, 7, 2);
		setBlock(world, i + 3, j + 38, k + 15, Blocks.log, 3);
		world.setBlockMetadataWithNotify(i + 3, j + 38, k + 15, 3, 2);
		setBlock(world, i + 3, j + 39, k + 0, Blocks.leaves, 15);
		world.setBlockMetadataWithNotify(i + 3, j + 39, k + 0, 15, 2);
		setBlock(world, i + 3, j + 39, k + 1, Blocks.leaves, 15);
		world.setBlockMetadataWithNotify(i + 3, j + 39, k + 1, 15, 2);
		setBlock(world, i + 3, j + 39, k + 14, Blocks.leaves, 7);
		world.setBlockMetadataWithNotify(i + 3, j + 39, k + 14, 7, 2);
		setBlock(world, i + 3, j + 39, k + 15, Blocks.leaves, 7);
		world.setBlockMetadataWithNotify(i + 3, j + 39, k + 15, 7, 2);
		setBlock(world, i + 3, j + 39, k + 16, Blocks.leaves, 7);
		world.setBlockMetadataWithNotify(i + 3, j + 39, k + 16, 7, 2);
		setBlock(world, i + 3, j + 39, k + 18, Blocks.leaves, 7);
		world.setBlockMetadataWithNotify(i + 3, j + 39, k + 18, 7, 2);
		setBlock(world, i + 3, j + 39, k + 19, Blocks.leaves, 7);
		world.setBlockMetadataWithNotify(i + 3, j + 39, k + 19, 7, 2);
		setBlock(world, i + 3, j + 39, k + 20, Blocks.log, 3);
		world.setBlockMetadataWithNotify(i + 3, j + 39, k + 20, 3, 2);
		setBlock(world, i + 3, j + 39, k + 21, Blocks.leaves, 7);
		world.setBlockMetadataWithNotify(i + 3, j + 39, k + 21, 7, 2);
		setBlock(world, i + 3, j + 39, k + 22, Blocks.leaves, 7);
		world.setBlockMetadataWithNotify(i + 3, j + 39, k + 22, 7, 2);
		setBlock(world, i + 3, j + 40, k + 0, Blocks.leaves, 15);
		world.setBlockMetadataWithNotify(i + 3, j + 40, k + 0, 15, 2);
		setBlock(world, i + 3, j + 40, k + 2, Blocks.log, 1);
		world.setBlockMetadataWithNotify(i + 3, j + 40, k + 2, 1, 2);
		setBlock(world, i + 3, j + 40, k + 15, Blocks.leaves, 7);
		world.setBlockMetadataWithNotify(i + 3, j + 40, k + 15, 7, 2);
		setBlock(world, i + 3, j + 40, k + 18, Blocks.leaves, 7);
		world.setBlockMetadataWithNotify(i + 3, j + 40, k + 18, 7, 2);
		setBlock(world, i + 3, j + 40, k + 19, Blocks.leaves, 7);
		world.setBlockMetadataWithNotify(i + 3, j + 40, k + 19, 7, 2);
		setBlock(world, i + 3, j + 40, k + 20, Blocks.leaves, 7);
		world.setBlockMetadataWithNotify(i + 3, j + 40, k + 20, 7, 2);
		setBlock(world, i + 3, j + 40, k + 21, Blocks.leaves, 7);
		world.setBlockMetadataWithNotify(i + 3, j + 40, k + 21, 7, 2);
		setBlock(world, i + 3, j + 40, k + 22, Blocks.leaves, 7);
		world.setBlockMetadataWithNotify(i + 3, j + 40, k + 22, 7, 2);
		setBlock(world, i + 3, j + 41, k + 0, Blocks.leaves, 15);
		world.setBlockMetadataWithNotify(i + 3, j + 41, k + 0, 15, 2);
		setBlock(world, i + 3, j + 41, k + 1, Blocks.log, 1);
		world.setBlockMetadataWithNotify(i + 3, j + 41, k + 1, 1, 2);
		setBlock(world, i + 3, j + 41, k + 2, Blocks.leaves, 15);
		world.setBlockMetadataWithNotify(i + 3, j + 41, k + 2, 15, 2);
		setBlock(world, i + 3, j + 41, k + 3, Blocks.leaves, 15);
		world.setBlockMetadataWithNotify(i + 3, j + 41, k + 3, 15, 2);
		setBlock(world, i + 3, j + 41, k + 4, Blocks.log, 3);
		world.setBlockMetadataWithNotify(i + 3, j + 41, k + 4, 3, 2);
		setBlock(world, i + 3, j + 41, k + 5, Blocks.leaves, 15);
		world.setBlockMetadataWithNotify(i + 3, j + 41, k + 5, 15, 2);
		setBlock(world, i + 3, j + 41, k + 6, Blocks.leaves, 15);
		world.setBlockMetadataWithNotify(i + 3, j + 41, k + 6, 15, 2);
		setBlock(world, i + 3, j + 41, k + 19, Blocks.leaves, 7);
		world.setBlockMetadataWithNotify(i + 3, j + 41, k + 19, 7, 2);
		setBlock(world, i + 3, j + 41, k + 20, Blocks.leaves, 7);
		world.setBlockMetadataWithNotify(i + 3, j + 41, k + 20, 7, 2);
		setBlock(world, i + 3, j + 41, k + 21, Blocks.leaves, 7);
		world.setBlockMetadataWithNotify(i + 3, j + 41, k + 21, 7, 2);
		setBlock(world, i + 3, j + 42, k + 1, Blocks.leaves, 15);
		world.setBlockMetadataWithNotify(i + 3, j + 42, k + 1, 15, 2);
		setBlock(world, i + 3, j + 42, k + 2, Blocks.log, 1);
		world.setBlockMetadataWithNotify(i + 3, j + 42, k + 2, 1, 2);
		setBlock(world, i + 3, j + 42, k + 3, Blocks.leaves, 15);
		world.setBlockMetadataWithNotify(i + 3, j + 42, k + 3, 15, 2);
		setBlock(world, i + 3, j + 42, k + 4, Blocks.log, 3);
		world.setBlockMetadataWithNotify(i + 3, j + 42, k + 4, 3, 2);
		setBlock(world, i + 3, j + 42, k + 5, Blocks.leaves, 15);
		world.setBlockMetadataWithNotify(i + 3, j + 42, k + 5, 15, 2);
		setBlock(world, i + 3, j + 42, k + 6, Blocks.leaves, 15);
		world.setBlockMetadataWithNotify(i + 3, j + 42, k + 6, 15, 2);
		setBlock(world, i + 3, j + 42, k + 20, Blocks.leaves, 7);
		world.setBlockMetadataWithNotify(i + 3, j + 42, k + 20, 7, 2);
		setBlock(world, i + 3, j + 43, k + 0, Blocks.planks, 5);
		world.setBlockMetadataWithNotify(i + 3, j + 43, k + 0, 5, 2);
		setBlock(world, i + 3, j + 43, k + 1, Blocks.log, 1);
		world.setBlockMetadataWithNotify(i + 3, j + 43, k + 1, 1, 2);
		setBlock(world, i + 3, j + 43, k + 2, Blocks.log, 1);
		world.setBlockMetadataWithNotify(i + 3, j + 43, k + 2, 1, 2);
		setBlock(world, i + 3, j + 43, k + 3, Blocks.planks, 5);
		world.setBlockMetadataWithNotify(i + 3, j + 43, k + 3, 5, 2);
		setBlock(world, i + 3, j + 43, k + 4, Blocks.log, 1);
		world.setBlockMetadataWithNotify(i + 3, j + 43, k + 4, 1, 2);
		setBlock(world, i + 3, j + 43, k + 5, Blocks.log, 1);
		world.setBlockMetadataWithNotify(i + 3, j + 43, k + 5, 1, 2);
		setBlock(world, i + 3, j + 43, k + 6, Blocks.log, 1);
		world.setBlockMetadataWithNotify(i + 3, j + 43, k + 6, 1, 2);
		setBlock(world, i + 3, j + 43, k + 7, Blocks.log, 1);
		world.setBlockMetadataWithNotify(i + 3, j + 43, k + 7, 1, 2);
		setBlock(world, i + 3, j + 43, k + 8, Blocks.log, 1);
		world.setBlockMetadataWithNotify(i + 3, j + 43, k + 8, 1, 2);
		setBlock(world, i + 3, j + 43, k + 9, Blocks.log, 1);
		world.setBlockMetadataWithNotify(i + 3, j + 43, k + 9, 1, 2);
		setBlock(world, i + 3, j + 43, k + 10, Blocks.planks, 5);
		world.setBlockMetadataWithNotify(i + 3, j + 43, k + 10, 5, 2);
		setBlock(world, i + 3, j + 43, k + 11, Blocks.planks, 5);
		world.setBlockMetadataWithNotify(i + 3, j + 43, k + 11, 5, 2);
		setBlock(world, i + 3, j + 44, k + 8, Blocks.spruce_stairs, 1);
		world.setBlockMetadataWithNotify(i + 3, j + 44, k + 8, 1, 2);
		setBlock(world, i + 3, j + 46, k + 9, Blocks.torch, 1);
		world.setBlockMetadataWithNotify(i + 3, j + 46, k + 9, 1, 2);
		setBlock(world, i + 3, j + 47, k + 10, Blocks.spruce_stairs, 5);
		world.setBlockMetadataWithNotify(i + 3, j + 47, k + 10, 5, 2);
		setBlock(world, i + 3, j + 48, k + 5, Blocks.torch, 4);
		world.setBlockMetadataWithNotify(i + 3, j + 48, k + 5, 4, 2);
		setBlock(world, i + 3, j + 48, k + 6, Blocks.log, 1);
		world.setBlockMetadataWithNotify(i + 3, j + 48, k + 6, 1, 2);
		setBlock(world, i + 3, j + 48, k + 7, Blocks.log, 1);
		world.setBlockMetadataWithNotify(i + 3, j + 48, k + 7, 1, 2);
		setBlock(world, i + 3, j + 48, k + 8, Blocks.log, 1);
		world.setBlockMetadataWithNotify(i + 3, j + 48, k + 8, 1, 2);
		setBlock(world, i + 3, j + 48, k + 9, Blocks.log, 1);
		world.setBlockMetadataWithNotify(i + 3, j + 48, k + 9, 1, 2);
		setBlock(world, i + 3, j + 48, k + 10, Blocks.log, 1);
		world.setBlockMetadataWithNotify(i + 3, j + 48, k + 10, 1, 2);
		setBlock(world, i + 3, j + 48, k + 11, Blocks.log, 1);
		world.setBlockMetadataWithNotify(i + 3, j + 48, k + 11, 1, 2);
		setBlock(world, i + 3, j + 48, k + 14, Blocks.leaves, 15);
		world.setBlockMetadataWithNotify(i + 3, j + 48, k + 14, 15, 2);
		setBlock(world, i + 3, j + 49, k + 5, Blocks.log, 1);
		world.setBlockMetadataWithNotify(i + 3, j + 49, k + 5, 1, 2);
		setBlock(world, i + 3, j + 49, k + 6, Blocks.log, 1);
		world.setBlockMetadataWithNotify(i + 3, j + 49, k + 6, 1, 2);
		setBlock(world, i + 3, j + 49, k + 7, Blocks.log, 1);
		world.setBlockMetadataWithNotify(i + 3, j + 49, k + 7, 1, 2);
		setBlock(world, i + 3, j + 49, k + 8, Blocks.log, 1);
		world.setBlockMetadataWithNotify(i + 3, j + 49, k + 8, 1, 2);
		setBlock(world, i + 3, j + 49, k + 9, Blocks.log, 1);
		world.setBlockMetadataWithNotify(i + 3, j + 49, k + 9, 1, 2);
		setBlock(world, i + 3, j + 49, k + 10, Blocks.log, 1);
		world.setBlockMetadataWithNotify(i + 3, j + 49, k + 10, 1, 2);
		setBlock(world, i + 3, j + 50, k + 0, Blocks.torch, 2);
		world.setBlockMetadataWithNotify(i + 3, j + 50, k + 0, 2, 2);
		setBlock(world, i + 3, j + 50, k + 3, Blocks.torch, 4);
		world.setBlockMetadataWithNotify(i + 3, j + 50, k + 3, 4, 2);
		setBlock(world, i + 3, j + 50, k + 4, Blocks.log, 1);
		world.setBlockMetadataWithNotify(i + 3, j + 50, k + 4, 1, 2);
		setBlock(world, i + 3, j + 50, k + 5, Blocks.log, 1);
		world.setBlockMetadataWithNotify(i + 3, j + 50, k + 5, 1, 2);
		setBlock(world, i + 3, j + 50, k + 6, Blocks.log, 1);
		world.setBlockMetadataWithNotify(i + 3, j + 50, k + 6, 1, 2);
		setBlock(world, i + 3, j + 50, k + 7, Blocks.log, 1);
		world.setBlockMetadataWithNotify(i + 3, j + 50, k + 7, 1, 2);
		setBlock(world, i + 3, j + 50, k + 8, Blocks.log, 1);
		world.setBlockMetadataWithNotify(i + 3, j + 50, k + 8, 1, 2);
		setBlock(world, i + 3, j + 51, k + 0, Blocks.log, 1);
		world.setBlockMetadataWithNotify(i + 3, j + 51, k + 0, 1, 2);
		setBlock(world, i + 3, j + 51, k + 1, Blocks.log, 1);
		world.setBlockMetadataWithNotify(i + 3, j + 51, k + 1, 1, 2);
		setBlock(world, i + 3, j + 51, k + 2, Blocks.log, 1);
		world.setBlockMetadataWithNotify(i + 3, j + 51, k + 2, 1, 2);
		setBlock(world, i + 3, j + 51, k + 3, Blocks.log, 1);
		world.setBlockMetadataWithNotify(i + 3, j + 51, k + 3, 1, 2);
		setBlock(world, i + 3, j + 51, k + 4, Blocks.log, 1);
		world.setBlockMetadataWithNotify(i + 3, j + 51, k + 4, 1, 2);
		setBlock(world, i + 4, j + 20, k + 5, Blocks.log, 1);
		world.setBlockMetadataWithNotify(i + 4, j + 20, k + 5, 1, 2);
		setBlock(world, i + 4, j + 21, k + 4, Blocks.log, 1);
		world.setBlockMetadataWithNotify(i + 4, j + 21, k + 4, 1, 2);
		setBlock(world, i + 4, j + 21, k + 5, Blocks.log, 1);
		world.setBlockMetadataWithNotify(i + 4, j + 21, k + 5, 1, 2);
		setBlock(world, i + 4, j + 21, k + 6, Blocks.log, 1);
		world.setBlockMetadataWithNotify(i + 4, j + 21, k + 6, 1, 2);
		setBlock(world, i + 4, j + 21, k + 7, Blocks.log, 1);
		world.setBlockMetadataWithNotify(i + 4, j + 21, k + 7, 1, 2);
		setBlock(world, i + 4, j + 22, k + 5, Blocks.log, 1);
		world.setBlockMetadataWithNotify(i + 4, j + 22, k + 5, 1, 2);
		setBlock(world, i + 4, j + 22, k + 6, Blocks.log, 1);
		world.setBlockMetadataWithNotify(i + 4, j + 22, k + 6, 1, 2);
		setBlock(world, i + 4, j + 22, k + 7, Blocks.log, 1);
		world.setBlockMetadataWithNotify(i + 4, j + 22, k + 7, 1, 2);
		setBlock(world, i + 4, j + 22, k + 8, Blocks.log, 1);
		world.setBlockMetadataWithNotify(i + 4, j + 22, k + 8, 1, 2);
		setBlock(world, i + 4, j + 22, k + 25, Blocks.leaves, 7);
		world.setBlockMetadataWithNotify(i + 4, j + 22, k + 25, 7, 2);
		setBlock(world, i + 4, j + 22, k + 26, Blocks.leaves, 7);
		world.setBlockMetadataWithNotify(i + 4, j + 22, k + 26, 7, 2);
		setBlock(world, i + 4, j + 22, k + 27, Blocks.leaves, 7);
		world.setBlockMetadataWithNotify(i + 4, j + 22, k + 27, 7, 2);
		setBlock(world, i + 4, j + 22, k + 28, Blocks.leaves, 7);
		world.setBlockMetadataWithNotify(i + 4, j + 22, k + 28, 7, 2);
		setBlock(world, i + 4, j + 22, k + 29, Blocks.leaves, 7);
		world.setBlockMetadataWithNotify(i + 4, j + 22, k + 29, 7, 2);
		setBlock(world, i + 4, j + 23, k + 7, Blocks.log, 1);
		world.setBlockMetadataWithNotify(i + 4, j + 23, k + 7, 1, 2);
		setBlock(world, i + 4, j + 23, k + 8, Blocks.vine, 15);
		world.setBlockMetadataWithNotify(i + 4, j + 23, k + 8, 15, 2);
		setBlock(world, i + 4, j + 23, k + 26, Blocks.leaves, 7);
		world.setBlockMetadataWithNotify(i + 4, j + 23, k + 26, 7, 2);
		setBlock(world, i + 4, j + 23, k + 27, Blocks.leaves, 7);
		world.setBlockMetadataWithNotify(i + 4, j + 23, k + 27, 7, 2);
		setBlock(world, i + 4, j + 23, k + 28, Blocks.leaves, 7);
		world.setBlockMetadataWithNotify(i + 4, j + 23, k + 28, 7, 2);
		setBlock(world, i + 4, j + 24, k + 21, Blocks.log, 3);
		world.setBlockMetadataWithNotify(i + 4, j + 24, k + 21, 3, 2);
		setBlock(world, i + 4, j + 24, k + 27, Blocks.leaves, 7);
		world.setBlockMetadataWithNotify(i + 4, j + 24, k + 27, 7, 2);
		setBlock(world, i + 4, j + 25, k + 3, Blocks.log, 1);
		world.setBlockMetadataWithNotify(i + 4, j + 25, k + 3, 1, 2);
		setBlock(world, i + 4, j + 25, k + 4, Blocks.log, 1);
		world.setBlockMetadataWithNotify(i + 4, j + 25, k + 4, 1, 2);
		
		generate2(world, rand, i, j, k);
		return true;
		}

	
	public boolean generate2(World world, Random rand, int i, int j, int k)
	{
		setBlock(world, i + 4, j + 25, k + 5, Blocks.log, 1);
		world.setBlockMetadataWithNotify(i + 4, j + 25, k + 5, 1, 2);
		setBlock(world, i + 4, j + 25, k + 6, Blocks.log, 1);
		world.setBlockMetadataWithNotify(i + 4, j + 25, k + 6, 1, 2);
		setBlock(world, i + 4, j + 26, k + 2, Blocks.log, 1);
		world.setBlockMetadataWithNotify(i + 4, j + 26, k + 2, 1, 2);
		setBlock(world, i + 4, j + 26, k + 3, Blocks.log, 1);
		world.setBlockMetadataWithNotify(i + 4, j + 26, k + 3, 1, 2);
		setBlock(world, i + 4, j + 26, k + 4, Blocks.log, 1);
		world.setBlockMetadataWithNotify(i + 4, j + 26, k + 4, 1, 2);
		setBlock(world, i + 4, j + 26, k + 5, Blocks.log, 1);
		world.setBlockMetadataWithNotify(i + 4, j + 26, k + 5, 1, 2);
		setBlock(world, i + 4, j + 26, k + 6, Blocks.log, 1);
		world.setBlockMetadataWithNotify(i + 4, j + 26, k + 6, 1, 2);
		setBlock(world, i + 4, j + 26, k + 21, Blocks.log, 3);
		world.setBlockMetadataWithNotify(i + 4, j + 26, k + 21, 3, 2);
		setBlock(world, i + 4, j + 27, k + 0, Blocks.log, 1);
		world.setBlockMetadataWithNotify(i + 4, j + 27, k + 0, 1, 2);
		setBlock(world, i + 4, j + 27, k + 1, Blocks.log, 1);
		world.setBlockMetadataWithNotify(i + 4, j + 27, k + 1, 1, 2);
		setBlock(world, i + 4, j + 27, k + 2, Blocks.planks, 5);
		world.setBlockMetadataWithNotify(i + 4, j + 27, k + 2, 5, 2);
		setBlock(world, i + 4, j + 27, k + 3, Blocks.log, 1);
		world.setBlockMetadataWithNotify(i + 4, j + 27, k + 3, 1, 2);
		setBlock(world, i + 4, j + 27, k + 4, Blocks.planks, 5);
		world.setBlockMetadataWithNotify(i + 4, j + 27, k + 4, 5, 2);
		setBlock(world, i + 4, j + 27, k + 5, Blocks.log, 1);
		world.setBlockMetadataWithNotify(i + 4, j + 27, k + 5, 1, 2);
		setBlock(world, i + 4, j + 27, k + 6, Blocks.log, 1);
		world.setBlockMetadataWithNotify(i + 4, j + 27, k + 6, 1, 2);
		setBlock(world, i + 4, j + 27, k + 7, Blocks.log, 1);
		world.setBlockMetadataWithNotify(i + 4, j + 27, k + 7, 1, 2);
		setBlock(world, i + 4, j + 27, k + 19, Blocks.log, 3);
		world.setBlockMetadataWithNotify(i + 4, j + 27, k + 19, 3, 2);
		setBlock(world, i + 4, j + 27, k + 21, Blocks.leaves, 15);
		world.setBlockMetadataWithNotify(i + 4, j + 27, k + 21, 15, 2);
		setBlock(world, i + 4, j + 27, k + 22, Blocks.leaves, 15);
		world.setBlockMetadataWithNotify(i + 4, j + 27, k + 22, 15, 2);
		setBlock(world, i + 4, j + 27, k + 23, Blocks.leaves, 15);
		world.setBlockMetadataWithNotify(i + 4, j + 27, k + 23, 15, 2);
		setBlock(world, i + 4, j + 28, k + 1, Blocks.spruce_stairs, 1);
		world.setBlockMetadataWithNotify(i + 4, j + 28, k + 1, 1, 2);
		setBlock(world, i + 4, j + 28, k + 5, Blocks.spruce_stairs, 1);
		world.setBlockMetadataWithNotify(i + 4, j + 28, k + 5, 1, 2);
		setBlock(world, i + 4, j + 28, k + 22, Blocks.leaves, 15);
		world.setBlockMetadataWithNotify(i + 4, j + 28, k + 22, 15, 2);
		setBlock(world, i + 4, j + 29, k + 0, Blocks.torch, 5);
		world.setBlockMetadataWithNotify(i + 4, j + 29, k + 0, 5, 2);
		setBlock(world, i + 4, j + 29, k + 6, Blocks.torch, 5);
		world.setBlockMetadataWithNotify(i + 4, j + 29, k + 6, 5, 2);
		setBlock(world, i + 4, j + 29, k + 23, Blocks.log, 3);
		world.setBlockMetadataWithNotify(i + 4, j + 29, k + 23, 3, 2);
		setBlock(world, i + 4, j + 30, k + 20, Blocks.log, 3);
		world.setBlockMetadataWithNotify(i + 4, j + 30, k + 20, 3, 2);
		setBlock(world, i + 4, j + 30, k + 22, Blocks.leaves, 15);
		world.setBlockMetadataWithNotify(i + 4, j + 30, k + 22, 15, 2);
		setBlock(world, i + 4, j + 30, k + 23, Blocks.leaves, 15);
		world.setBlockMetadataWithNotify(i + 4, j + 30, k + 23, 15, 2);
		setBlock(world, i + 4, j + 30, k + 24, Blocks.leaves, 15);
		world.setBlockMetadataWithNotify(i + 4, j + 30, k + 24, 15, 2);
		setBlock(world, i + 4, j + 30, k + 25, Blocks.leaves, 15);
		world.setBlockMetadataWithNotify(i + 4, j + 30, k + 25, 15, 2);
		setBlock(world, i + 4, j + 30, k + 26, Blocks.leaves, 15);
		world.setBlockMetadataWithNotify(i + 4, j + 30, k + 26, 15, 2);
		setBlock(world, i + 4, j + 31, k + 0, Blocks.log, 1);
		world.setBlockMetadataWithNotify(i + 4, j + 31, k + 0, 1, 2);
		setBlock(world, i + 4, j + 31, k + 1, Blocks.log, 1);
		world.setBlockMetadataWithNotify(i + 4, j + 31, k + 1, 1, 2);
		setBlock(world, i + 4, j + 31, k + 2, Blocks.log, 1);
		world.setBlockMetadataWithNotify(i + 4, j + 31, k + 2, 1, 2);
		setBlock(world, i + 4, j + 31, k + 3, Blocks.log, 1);
		world.setBlockMetadataWithNotify(i + 4, j + 31, k + 3, 1, 2);
		setBlock(world, i + 4, j + 31, k + 4, Blocks.log, 1);
		world.setBlockMetadataWithNotify(i + 4, j + 31, k + 4, 1, 2);
		setBlock(world, i + 4, j + 31, k + 5, Blocks.log, 1);
		world.setBlockMetadataWithNotify(i + 4, j + 31, k + 5, 1, 2);
		setBlock(world, i + 4, j + 31, k + 6, Blocks.log, 1);
		world.setBlockMetadataWithNotify(i + 4, j + 31, k + 6, 1, 2);
		setBlock(world, i + 4, j + 31, k + 7, Blocks.log, 1);
		world.setBlockMetadataWithNotify(i + 4, j + 31, k + 7, 1, 2);
		setBlock(world, i + 4, j + 31, k + 8, Blocks.log, 1);
		world.setBlockMetadataWithNotify(i + 4, j + 31, k + 8, 1, 2);
		setBlock(world, i + 4, j + 31, k + 9, Blocks.log, 1);
		world.setBlockMetadataWithNotify(i + 4, j + 31, k + 9, 1, 2);
		setBlock(world, i + 4, j + 31, k + 10, Blocks.log, 1);
		world.setBlockMetadataWithNotify(i + 4, j + 31, k + 10, 1, 2);
		setBlock(world, i + 4, j + 31, k + 11, Blocks.log, 1);
		world.setBlockMetadataWithNotify(i + 4, j + 31, k + 11, 1, 2);
		setBlock(world, i + 4, j + 31, k + 19, Blocks.log, 3);
		world.setBlockMetadataWithNotify(i + 4, j + 31, k + 19, 3, 2);
		setBlock(world, i + 4, j + 31, k + 23, Blocks.leaves, 15);
		world.setBlockMetadataWithNotify(i + 4, j + 31, k + 23, 15, 2);
		setBlock(world, i + 4, j + 31, k + 24, Blocks.leaves, 15);
		world.setBlockMetadataWithNotify(i + 4, j + 31, k + 24, 15, 2);
		setBlock(world, i + 4, j + 31, k + 25, Blocks.leaves, 15);
		world.setBlockMetadataWithNotify(i + 4, j + 31, k + 25, 15, 2);
		setBlock(world, i + 4, j + 32, k + 0, Blocks.log, 1);
		world.setBlockMetadataWithNotify(i + 4, j + 32, k + 0, 1, 2);
		setBlock(world, i + 4, j + 32, k + 1, Blocks.log, 1);
		world.setBlockMetadataWithNotify(i + 4, j + 32, k + 1, 1, 2);
		setBlock(world, i + 4, j + 32, k + 2, Blocks.log, 1);
		world.setBlockMetadataWithNotify(i + 4, j + 32, k + 2, 1, 2);
