package com.parzivail.pswm.world.gen.wookietree;


import cpw.mods.fml.common.IWorldGenerator;

import java.util.Random;

import net.minecraft.block.Block;

import net.minecraft.init.Blocks;

import net.minecraft.world.World;

import net.minecraft.world.chunk.IChunkProvider;

import net.minecraft.world.gen.feature.WorldGenerator;


public class WT_43 extends WorldGenerator implements IWorldGenerator

{
	protected Block[] getValidSpawnBlocks()
	
	{
		return new Block[0];
		}

	
	public boolean locationIsValidSpawn(World world, int i, int j, int k)
	
	{
		int distanceToAir = 0;
		Block check = world.getBlock(i, j, k);
		
		while (check != Blocks.air)
		{
			if (distanceToAir > 3) { return false;
			}
			
			distanceToAir++;
			check = world.getBlock(i, j + distanceToAir, k);
			}
		
		j += distanceToAir - 1;
		
		Block block = world.getBlock(i, j, k);
		Block blockAbove = world.getBlock(i, j + 1, k);
		Block blockBelow = world.getBlock(i, j - 1, k);
		
		for (Block x : getValidSpawnBlocks())
		{
			if (blockAbove != Blocks.air) { return false;
			}
			if (block == x) return true;
			if ((block == Blocks.snow) && (blockBelow == x)) { return true;
			}
			}
		
		return false;
		}

	
	
	
	public void generate(Random random, int chunkX, int chunkZ, World world, IChunkProvider chunkGenerator, IChunkProvider chunkProvider)
	{
	}

	
	
	public void setBlock(World world, int x, int y, int z, Block block, int metadata)
	
	{
		world.setBlock(x, y, z, block, metadata, 2);
		}

	
	public boolean generate(World world, Random rand, int i, int j, int k)
	
	{
		k -= 10;
		i -= 10;
		
		setBlock(world, i + 9, j + 36, k + 0, Blocks.fence, 0);
		setBlock(world, i + 9, j + 36, k + 1, Blocks.fence, 0);
		setBlock(world, i + 15, j + 36, k + 0, Blocks.fence, 0);
		setBlock(world, i + 15, j + 36, k + 1, Blocks.fence, 0);
		setBlock(world, i + 0, j + 39, k + 19, Blocks.planks, 5);
		world.setBlockMetadataWithNotify(i + 0, j + 39, k + 19, 5, 2);
		setBlock(world, i + 0, j + 39, k + 20, Blocks.planks, 5);
		world.setBlockMetadataWithNotify(i + 0, j + 39, k + 20, 5, 2);
		setBlock(world, i + 0, j + 39, k + 21, Blocks.planks, 5);
		world.setBlockMetadataWithNotify(i + 0, j + 39, k + 21, 5, 2);
		setBlock(world, i + 0, j + 39, k + 22, Blocks.planks, 5);
		world.setBlockMetadataWithNotify(i + 0, j + 39, k + 22, 5, 2);
		setBlock(world, i + 0, j + 39, k + 23, Blocks.planks, 5);
		world.setBlockMetadataWithNotify(i + 0, j + 39, k + 23, 5, 2);
		setBlock(world, i + 0, j + 39, k + 24, Blocks.planks, 5);
		world.setBlockMetadataWithNotify(i + 0, j + 39, k + 24, 5, 2);
		setBlock(world, i + 0, j + 40, k + 19, Blocks.planks, 5);
		world.setBlockMetadataWithNotify(i + 0, j + 40, k + 19, 5, 2);
		setBlock(world, i + 0, j + 40, k + 20, Blocks.planks, 5);
		world.setBlockMetadataWithNotify(i + 0, j + 40, k + 20, 5, 2);
		setBlock(world, i + 0, j + 40, k + 21, Blocks.planks, 5);
		world.setBlockMetadataWithNotify(i + 0, j + 40, k + 21, 5, 2);
		setBlock(world, i + 0, j + 40, k + 22, Blocks.planks, 5);
		world.setBlockMetadataWithNotify(i + 0, j + 40, k + 22, 5, 2);
		setBlock(world, i + 0, j + 40, k + 23, Blocks.planks, 5);
		world.setBlockMetadataWithNotify(i + 0, j + 40, k + 23, 5, 2);
		setBlock(world, i + 0, j + 40, k + 24, Blocks.planks, 5);
		world.setBlockMetadataWithNotify(i + 0, j + 40, k + 24, 5, 2);
		setBlock(world, i + 0, j + 41, k + 19, Blocks.spruce_stairs, 1);
		world.setBlockMetadataWithNotify(i + 0, j + 41, k + 19, 1, 2);
		setBlock(world, i + 0, j + 41, k + 20, Blocks.spruce_stairs, 1);
		world.setBlockMetadataWithNotify(i + 0, j + 41, k + 20, 1, 2);
		setBlock(world, i + 0, j + 41, k + 21, Blocks.spruce_stairs, 1);
		world.setBlockMetadataWithNotify(i + 0, j + 41, k + 21, 1, 2);
		setBlock(world, i + 0, j + 41, k + 22, Blocks.spruce_stairs, 1);
		world.setBlockMetadataWithNotify(i + 0, j + 41, k + 22, 1, 2);
		setBlock(world, i + 0, j + 41, k + 23, Blocks.spruce_stairs, 1);
		world.setBlockMetadataWithNotify(i + 0, j + 41, k + 23, 1, 2);
		setBlock(world, i + 0, j + 41, k + 24, Blocks.spruce_stairs, 1);
		world.setBlockMetadataWithNotify(i + 0, j + 41, k + 24, 1, 2);
		setBlock(world, i + 1, j + 23, k + 7, Blocks.leaves, 7);
		world.setBlockMetadataWithNotify(i + 1, j + 23, k + 7, 7, 2);
		setBlock(world, i + 1, j + 23, k + 8, Blocks.leaves, 7);
		world.setBlockMetadataWithNotify(i + 1, j + 23, k + 8, 7, 2);
		setBlock(world, i + 1, j + 23, k + 9, Blocks.leaves, 7);
		world.setBlockMetadataWithNotify(i + 1, j + 23, k + 9, 7, 2);
		setBlock(world, i + 1, j + 24, k + 8, Blocks.leaves, 7);
		world.setBlockMetadataWithNotify(i + 1, j + 24, k + 8, 7, 2);
		setBlock(world, i + 1, j + 39, k + 19, Blocks.planks, 5);
		world.setBlockMetadataWithNotify(i + 1, j + 39, k + 19, 5, 2);
		setBlock(world, i + 1, j + 39, k + 20, Blocks.planks, 5);
		world.setBlockMetadataWithNotify(i + 1, j + 39, k + 20, 5, 2);
		setBlock(world, i + 1, j + 39, k + 21, Blocks.planks, 5);
		world.setBlockMetadataWithNotify(i + 1, j + 39, k + 21, 5, 2);
		setBlock(world, i + 1, j + 39, k + 22, Blocks.planks, 5);
		world.setBlockMetadataWithNotify(i + 1, j + 39, k + 22, 5, 2);
		setBlock(world, i + 1, j + 39, k + 23, Blocks.planks, 5);
		world.setBlockMetadataWithNotify(i + 1, j + 39, k + 23, 5, 2);
		setBlock(world, i + 1, j + 39, k + 24, Blocks.planks, 5);
		world.setBlockMetadataWithNotify(i + 1, j + 39, k + 24, 5, 2);
		setBlock(world, i + 1, j + 40, k + 19, Blocks.spruce_stairs, 1);
		world.setBlockMetadataWithNotify(i + 1, j + 40, k + 19, 1, 2);
		setBlock(world, i + 1, j + 40, k + 20, Blocks.spruce_stairs, 1);
		world.setBlockMetadataWithNotify(i + 1, j + 40, k + 20, 1, 2);
		setBlock(world, i + 1, j + 40, k + 21, Blocks.spruce_stairs, 1);
		world.setBlockMetadataWithNotify(i + 1, j + 40, k + 21, 1, 2);
		setBlock(world, i + 1, j + 40, k + 22, Blocks.spruce_stairs, 1);
		world.setBlockMetadataWithNotify(i + 1, j + 40, k + 22, 1, 2);
		setBlock(world, i + 1, j + 40, k + 23, Blocks.spruce_stairs, 1);
		world.setBlockMetadataWithNotify(i + 1, j + 40, k + 23, 1, 2);
		setBlock(world, i + 1, j + 40, k + 24, Blocks.spruce_stairs, 1);
		world.setBlockMetadataWithNotify(i + 1, j + 40, k + 24, 1, 2);
		setBlock(world, i + 2, j + 23, k + 6, Blocks.leaves, 7);
		world.setBlockMetadataWithNotify(i + 2, j + 23, k + 6, 7, 2);
		setBlock(world, i + 2, j + 23, k + 7, Blocks.leaves, 7);
		world.setBlockMetadataWithNotify(i + 2, j + 23, k + 7, 7, 2);
		setBlock(world, i + 2, j + 23, k + 8, Blocks.leaves, 7);
		world.setBlockMetadataWithNotify(i + 2, j + 23, k + 8, 7, 2);
		setBlock(world, i + 2, j + 23, k + 9, Blocks.leaves, 7);
		world.setBlockMetadataWithNotify(i + 2, j + 23, k + 9, 7, 2);
		setBlock(world, i + 2, j + 23, k + 10, Blocks.leaves, 7);
		world.setBlockMetadataWithNotify(i + 2, j + 23, k + 10, 7, 2);
		setBlock(world, i + 2, j + 24, k + 7, Blocks.leaves, 7);
		world.setBlockMetadataWithNotify(i + 2, j + 24, k + 7, 7, 2);
		setBlock(world, i + 2, j + 24, k + 8, Blocks.leaves, 7);
		world.setBlockMetadataWithNotify(i + 2, j + 24, k + 8, 7, 2);
		setBlock(world, i + 2, j + 24, k + 9, Blocks.leaves, 7);
		world.setBlockMetadataWithNotify(i + 2, j + 24, k + 9, 7, 2);
		setBlock(world, i + 2, j + 25, k + 8, Blocks.leaves, 7);
		world.setBlockMetadataWithNotify(i + 2, j + 25, k + 8, 7, 2);
		setBlock(world, i + 2, j + 39, k + 18, Blocks.planks, 5);
		world.setBlockMetadataWithNotify(i + 2, j + 39, k + 18, 5, 2);
		setBlock(world, i + 2, j + 39, k + 19, Blocks.planks, 5);
		world.setBlockMetadataWithNotify(i + 2, j + 39, k + 19, 5, 2);
		setBlock(world, i + 2, j + 39, k + 20, Blocks.planks, 5);
		world.setBlockMetadataWithNotify(i + 2, j + 39, k + 20, 5, 2);
		setBlock(world, i + 2, j + 39, k + 21, Blocks.planks, 5);
		world.setBlockMetadataWithNotify(i + 2, j + 39, k + 21, 5, 2);
		setBlock(world, i + 2, j + 39, k + 22, Blocks.planks, 5);
		world.setBlockMetadataWithNotify(i + 2, j + 39, k + 22, 5, 2);
		setBlock(world, i + 2, j + 39, k + 23, Blocks.planks, 5);
		world.setBlockMetadataWithNotify(i + 2, j + 39, k + 23, 5, 2);
		setBlock(world, i + 2, j + 39, k + 24, Blocks.planks, 5);
		world.setBlockMetadataWithNotify(i + 2, j + 39, k + 24, 5, 2);
		setBlock(world, i + 2, j + 40, k + 18, Blocks.torch, 5);
		world.setBlockMetadataWithNotify(i + 2, j + 40, k + 18, 5, 2);
		setBlock(world, i + 2, j + 40, k + 24, Blocks.torch, 5);
		world.setBlockMetadataWithNotify(i + 2, j + 40, k + 24, 5, 2);
		setBlock(world, i + 3, j + 23, k + 6, Blocks.leaves, 7);
		world.setBlockMetadataWithNotify(i + 3, j + 23, k + 6, 7, 2);
		setBlock(world, i + 3, j + 23, k + 7, Blocks.leaves, 7);
		world.setBlockMetadataWithNotify(i + 3, j + 23, k + 7, 7, 2);
		setBlock(world, i + 3, j + 23, k + 8, Blocks.log, 3);
		world.setBlockMetadataWithNotify(i + 3, j + 23, k + 8, 3, 2);
		setBlock(world, i + 3, j + 23, k + 9, Blocks.leaves, 7);
		world.setBlockMetadataWithNotify(i + 3, j + 23, k + 9, 7, 2);
		setBlock(world, i + 3, j + 23, k + 10, Blocks.leaves, 7);
		world.setBlockMetadataWithNotify(i + 3, j + 23, k + 10, 7, 2);
		setBlock(world, i + 3, j + 24, k + 6, Blocks.leaves, 7);
		world.setBlockMetadataWithNotify(i + 3, j + 24, k + 6, 7, 2);
		setBlock(world, i + 3, j + 24, k + 7, Blocks.leaves, 7);
		world.setBlockMetadataWithNotify(i + 3, j + 24, k + 7, 7, 2);
		setBlock(world, i + 3, j + 24, k + 8, Blocks.leaves, 7);
		world.setBlockMetadataWithNotify(i + 3, j + 24, k + 8, 7, 2);
		setBlock(world, i + 3, j + 24, k + 9, Blocks.leaves, 7);
		world.setBlockMetadataWithNotify(i + 3, j + 24, k + 9, 7, 2);
		setBlock(world, i + 3, j + 24, k + 10, Blocks.leaves, 7);
		world.setBlockMetadataWithNotify(i + 3, j + 24, k + 10, 7, 2);
		setBlock(world, i + 3, j + 25, k + 7, Blocks.leaves, 7);
		world.setBlockMetadataWithNotify(i + 3, j + 25, k + 7, 7, 2);
		setBlock(world, i + 3, j + 25, k + 8, Blocks.leaves, 7);
		world.setBlockMetadataWithNotify(i + 3, j + 25, k + 8, 7, 2);
		setBlock(world, i + 3, j + 25, k + 9, Blocks.leaves, 7);
		world.setBlockMetadataWithNotify(i + 3, j + 25, k + 9, 7, 2);
		setBlock(world, i + 3, j + 26, k + 8, Blocks.leaves, 7);
		world.setBlockMetadataWithNotify(i + 3, j + 26, k + 8, 7, 2);
		setBlock(world, i + 3, j + 28, k + 6, Blocks.leaves, 7);
		world.setBlockMetadataWithNotify(i + 3, j + 28, k + 6, 7, 2);
		setBlock(world, i + 3, j + 28, k + 7, Blocks.leaves, 7);
		world.setBlockMetadataWithNotify(i + 3, j + 28, k + 7, 7, 2);
		setBlock(world, i + 3, j + 28, k + 8, Blocks.leaves, 7);
		world.setBlockMetadataWithNotify(i + 3, j + 28, k + 8, 7, 2);
		setBlock(world, i + 3, j + 29, k + 7, Blocks.leaves, 7);
		world.setBlockMetadataWithNotify(i + 3, j + 29, k + 7, 7, 2);
		setBlock(world, i + 3, j + 30, k + 16, Blocks.leaves, 15);
		world.setBlockMetadataWithNotify(i + 3, j + 30, k + 16, 15, 2);
		setBlock(world, i + 3, j + 30, k + 17, Blocks.leaves, 15);
		world.setBlockMetadataWithNotify(i + 3, j + 30, k + 17, 15, 2);
		setBlock(world, i + 3, j + 30, k + 18, Blocks.leaves, 15);
		world.setBlockMetadataWithNotify(i + 3, j + 30, k + 18, 15, 2);
		setBlock(world, i + 3, j + 39, k + 17, Blocks.planks, 5);
		world.setBlockMetadataWithNotify(i + 3, j + 39, k + 17, 5, 2);
		setBlock(world, i + 3, j + 39, k + 18, Blocks.planks, 5);
		world.setBlockMetadataWithNotify(i + 3, j + 39, k + 18, 5, 2);
		setBlock(world, i + 3, j + 39, k + 19, Blocks.planks, 5);
		world.setBlockMetadataWithNotify(i + 3, j + 39, k + 19, 5, 2);
		setBlock(world, i + 3, j + 39, k + 20, Blocks.planks, 5);
		world.setBlockMetadataWithNotify(i + 3, j + 39, k + 20, 5, 2);
		setBlock(world, i + 3, j + 39, k + 21, Blocks.planks, 5);
		world.setBlockMetadataWithNotify(i + 3, j + 39, k + 21, 5, 2);
		setBlock(world, i + 3, j + 39, k + 22, Blocks.planks, 5);
		world.setBlockMetadataWithNotify(i + 3, j + 39, k + 22, 5, 2);
		setBlock(world, i + 3, j + 39, k + 23, Blocks.planks, 5);
		world.setBlockMetadataWithNotify(i + 3, j + 39, k + 23, 5, 2);
		setBlock(world, i + 4, j + 22, k + 8, Blocks.log, 3);
		world.setBlockMetadataWithNotify(i + 4, j + 22, k + 8, 3, 2);
		setBlock(world, i + 4, j + 23, k + 6, Blocks.leaves, 7);
		world.setBlockMetadataWithNotify(i + 4, j + 23, k + 6, 7, 2);
		setBlock(world, i + 4, j + 23, k + 7, Blocks.leaves, 7);
		world.setBlockMetadataWithNotify(i + 4, j + 23, k + 7, 7, 2);
		setBlock(world, i + 4, j + 23, k + 8, Blocks.leaves, 7);
		world.setBlockMetadataWithNotify(i + 4, j + 23, k + 8, 7, 2);
		setBlock(world, i + 4, j + 23, k + 9, Blocks.leaves, 7);
		world.setBlockMetadataWithNotify(i + 4, j + 23, k + 9, 7, 2);
		setBlock(world, i + 4, j + 23, k + 10, Blocks.leaves, 7);
		world.setBlockMetadataWithNotify(i + 4, j + 23, k + 10, 7, 2);
		setBlock(world, i + 4, j + 24, k + 7, Blocks.leaves, 7);
		world.setBlockMetadataWithNotify(i + 4, j + 24, k + 7, 7, 2);
		setBlock(world, i + 4, j + 24, k + 8, Blocks.leaves, 7);
		world.setBlockMetadataWithNotify(i + 4, j + 24, k + 8, 7, 2);
		setBlock(world, i + 4, j + 24, k + 9, Blocks.leaves, 7);
		world.setBlockMetadataWithNotify(i + 4, j + 24, k + 9, 7, 2);
		setBlock(world, i + 4, j + 25, k + 8, Blocks.leaves, 7);
		world.setBlockMetadataWithNotify(i + 4, j + 25, k + 8, 7, 2);
		setBlock(world, i + 4, j + 28, k + 5, Blocks.leaves, 7);
		world.setBlockMetadataWithNotify(i + 4, j + 28, k + 5, 7, 2);
		setBlock(world, i + 4, j + 28, k + 6, Blocks.leaves, 7);
		world.setBlockMetadataWithNotify(i + 4, j + 28, k + 6, 7, 2);
		setBlock(world, i + 4, j + 28, k + 7, Blocks.leaves, 7);
		world.setBlockMetadataWithNotify(i + 4, j + 28, k + 7, 7, 2);
		setBlock(world, i + 4, j + 28, k + 8, Blocks.leaves, 7);
		world.setBlockMetadataWithNotify(i + 4, j + 28, k + 8, 7, 2);
		setBlock(world, i + 4, j + 28, k + 9, Blocks.leaves, 7);
		world.setBlockMetadataWithNotify(i + 4, j + 28, k + 9, 7, 2);
		setBlock(world, i + 4, j + 29, k + 6, Blocks.leaves, 7);
		world.setBlockMetadataWithNotify(i + 4, j + 29, k + 6, 7, 2);
		setBlock(world, i + 4, j + 29, k + 7, Blocks.leaves, 7);
		world.setBlockMetadataWithNotify(i + 4, j + 29, k + 7, 7, 2);
		setBlock(world, i + 4, j + 29, k + 8, Blocks.leaves, 7);
		world.setBlockMetadataWithNotify(i + 4, j + 29, k + 8, 7, 2);
		setBlock(world, i + 4, j + 30, k + 7, Blocks.leaves, 7);
		world.setBlockMetadataWithNotify(i + 4, j + 30, k + 7, 7, 2);
		setBlock(world, i + 4, j + 30, k + 15, Blocks.leaves, 15);
		world.setBlockMetadataWithNotify(i + 4, j + 30, k + 15, 15, 2);
		setBlock(world, i + 4, j + 30, k + 16, Blocks.leaves, 15);
		world.setBlockMetadataWithNotify(i + 4, j + 30, k + 16, 15, 2);
		setBlock(world, i + 4, j + 30, k + 17, Blocks.leaves, 15);
		world.setBlockMetadataWithNotify(i + 4, j + 30, k + 17, 15, 2);
		setBlock(world, i + 4, j + 30, k + 18, Blocks.leaves, 15);
		world.setBlockMetadataWithNotify(i + 4, j + 30, k + 18, 15, 2);
		setBlock(world, i + 4, j + 30, k + 19, Blocks.leaves, 15);
		world.setBlockMetadataWithNotify(i + 4, j + 30, k + 19, 15, 2);
		setBlock(world, i + 4, j + 31, k + 16, Blocks.leaves, 15);
		world.setBlockMetadataWithNotify(i + 4, j + 31, k + 16, 15, 2);
		setBlock(world, i + 4, j + 31, k + 17, Blocks.leaves, 15);
		world.setBlockMetadataWithNotify(i + 4, j + 31, k + 17, 15, 2);
		setBlock(world, i + 4, j + 31, k + 18, Blocks.leaves, 15);
		world.setBlockMetadataWithNotify(i + 4, j + 31, k + 18, 15, 2);
		setBlock(world, i + 4, j + 39, k + 16, Blocks.planks, 5);
		world.setBlockMetadataWithNotify(i + 4, j + 39, k + 16, 5, 2);
		setBlock(world, i + 4, j + 39, k + 17, Blocks.planks, 5);
		world.setBlockMetadataWithNotify(i + 4, j + 39, k + 17, 5, 2);
		setBlock(world, i + 4, j + 39, k + 18, Blocks.planks, 5);
		world.setBlockMetadataWithNotify(i + 4, j + 39, k + 18, 5, 2);
		setBlock(world, i + 4, j + 39, k + 19, Blocks.planks, 5);
		world.setBlockMetadataWithNotify(i + 4, j + 39, k + 19, 5, 2);
		setBlock(world, i + 4, j + 39, k + 20, Blocks.planks, 5);
		world.setBlockMetadataWithNotify(i + 4, j + 39, k + 20, 5, 2);
		setBlock(world, i + 4, j + 39, k + 21, Blocks.planks, 5);
		world.setBlockMetadataWithNotify(i + 4, j + 39, k + 21, 5, 2);
		setBlock(world, i + 4, j + 39, k + 22, Blocks.planks, 5);
		world.setBlockMetadataWithNotify(i + 4, j + 39, k + 22, 5, 2);
		setBlock(world, i + 4, j + 40, k + 16, Blocks.torch, 5);
		world.setBlockMetadataWithNotify(i + 4, j + 40, k + 16, 5, 2);
		setBlock(world, i + 5, j + 22, k + 8, Blocks.log, 3);
		world.setBlockMetadataWithNotify(i + 5, j + 22, k + 8, 3, 2);
		setBlock(world, i + 5, j + 23, k + 7, Blocks.leaves, 7);
		world.setBlockMetadataWithNotify(i + 5, j + 23, k + 7, 7, 2);
		setBlock(world, i + 5, j + 23, k + 8, Blocks.leaves, 7);
		world.setBlockMetadataWithNotify(i + 5, j + 23, k + 8, 7, 2);
		setBlock(world, i + 5, j + 23, k + 9, Blocks.leaves, 7);
		world.setBlockMetadataWithNotify(i + 5, j + 23, k + 9, 7, 2);
		setBlock(world, i + 5, j + 24, k + 8, Blocks.leaves, 7);
		world.setBlockMetadataWithNotify(i + 5, j + 24, k + 8, 7, 2);
		setBlock(world, i + 5, j + 28, k + 5, Blocks.leaves, 7);
		world.setBlockMetadataWithNotify(i + 5, j + 28, k + 5, 7, 2);
		setBlock(world, i + 5, j + 28, k + 6, Blocks.leaves, 7);
		world.setBlockMetadataWithNotify(i + 5, j + 28, k + 6, 7, 2);
		setBlock(world, i + 5, j + 28, k + 7, Blocks.log, 3);
		world.setBlockMetadataWithNotify(i + 5, j + 28, k + 7, 3, 2);
		setBlock(world, i + 5, j + 28, k + 8, Blocks.leaves, 7);
		world.setBlockMetadataWithNotify(i + 5, j + 28, k + 8, 7, 2);
		setBlock(world, i + 5, j + 28, k + 9, Blocks.leaves, 7);
		world.setBlockMetadataWithNotify(i + 5, j + 28, k + 9, 7, 2);
		setBlock(world, i + 5, j + 29, k + 5, Blocks.leaves, 7);
		world.setBlockMetadataWithNotify(i + 5, j + 29, k + 5, 7, 2);
		setBlock(world, i + 5, j + 29, k + 6, Blocks.leaves, 7);
		world.setBlockMetadataWithNotify(i + 5, j + 29, k + 6, 7, 2);
		setBlock(world, i + 5, j + 29, k + 7, Blocks.leaves, 7);
		world.setBlockMetadataWithNotify(i + 5, j + 29, k + 7, 7, 2);
		setBlock(world, i + 5, j + 29, k + 8, Blocks.leaves, 7);
		world.setBlockMetadataWithNotify(i + 5, j + 29, k + 8, 7, 2);
		setBlock(world, i + 5, j + 29, k + 9, Blocks.leaves, 7);
		world.setBlockMetadataWithNotify(i + 5, j + 29, k + 9, 7, 2);
		setBlock(world, i + 5, j + 30, k + 6, Blocks.leaves, 7);
		world.setBlockMetadataWithNotify(i + 5, j + 30, k + 6, 7, 2);
		setBlock(world, i + 5, j + 30, k + 7, Blocks.leaves, 7);
		world.setBlockMetadataWithNotify(i + 5, j + 30, k + 7, 7, 2);
		setBlock(world, i + 5, j + 30, k + 8, Blocks.leaves, 7);
		world.setBlockMetadataWithNotify(i + 5, j + 30, k + 8, 7, 2);
		setBlock(world, i + 5, j + 30, k + 15, Blocks.leaves, 15);
		world.setBlockMetadataWithNotify(i + 5, j + 30, k + 15, 15, 2);
		setBlock(world, i + 5, j + 30, k + 16, Blocks.leaves, 15);
		world.setBlockMetadataWithNotify(i + 5, j + 30, k + 16, 15, 2);
		setBlock(world, i + 5, j + 30, k + 17, Blocks.log, 3);
		world.setBlockMetadataWithNotify(i + 5, j + 30, k + 17, 3, 2);
		setBlock(world, i + 5, j + 30, k + 18, Blocks.leaves, 15);
		world.setBlockMetadataWithNotify(i + 5, j + 30, k + 18, 15, 2);
		setBlock(world, i + 5, j + 30, k + 19, Blocks.leaves, 15);
		world.setBlockMetadataWithNotify(i + 5, j + 30, k + 19, 15, 2);
		setBlock(world, i + 5, j + 31, k + 7, Blocks.leaves, 7);
		world.setBlockMetadataWithNotify(i + 5, j + 31, k + 7, 7, 2);
		setBlock(world, i + 5, j + 31, k + 15, Blocks.leaves, 15);
		world.setBlockMetadataWithNotify(i + 5, j + 31, k + 15, 15, 2);
		setBlock(world, i + 5, j + 31, k + 16, Blocks.leaves, 15);
		world.setBlockMetadataWithNotify(i + 5, j + 31, k + 16, 15, 2);
		setBlock(world, i + 5, j + 31, k + 17, Blocks.leaves, 15);
		world.setBlockMetadataWithNotify(i + 5, j + 31, k + 17, 15, 2);
		setBlock(world, i + 5, j + 31, k + 18, Blocks.leaves, 15);
		world.setBlockMetadataWithNotify(i + 5, j + 31, k + 18, 15, 2);
		setBlock(world, i + 5, j + 31, k + 19, Blocks.leaves, 15);
		world.setBlockMetadataWithNotify(i + 5, j + 31, k + 19, 15, 2);
		setBlock(world, i + 5, j + 32, k + 18, Blocks.leaves, 15);
		world.setBlockMetadataWithNotify(i + 5, j + 32, k + 18, 15, 2);
		setBlock(world, i + 5, j + 39, k + 15, Blocks.planks, 5);
		world.setBlockMetadataWithNotify(i + 5, j + 39, k + 15, 5, 2);
		setBlock(world, i + 5, j + 39, k + 16, Blocks.planks, 5);
		world.setBlockMetadataWithNotify(i + 5, j + 39, k + 16, 5, 2);
		setBlock(world, i + 5, j + 39, k + 17, Blocks.planks, 5);
		world.setBlockMetadataWithNotify(i + 5, j + 39, k + 17, 5, 2);
		setBlock(world, i + 5, j + 39, k + 18, Blocks.planks, 5);
		world.setBlockMetadataWithNotify(i + 5, j + 39, k + 18, 5, 2);
		setBlock(world, i + 5, j + 39, k + 19, Blocks.planks, 5);
		world.setBlockMetadataWithNotify(i + 5, j + 39, k + 19, 5, 2);
		setBlock(world, i + 5, j + 39, k + 20, Blocks.planks, 5);
		world.setBlockMetadataWithNotify(i + 5, j + 39, k + 20, 5, 2);
		setBlock(world, i + 5, j + 39, k + 21, Blocks.planks, 5);
		world.setBlockMetadataWithNotify(i + 5, j + 39, k + 21, 5, 2);
		setBlock(world, i + 6, j + 22, k + 7, Blocks.leaves, 7);
		world.setBlockMetadataWithNotify(i + 6, j + 22, k + 7, 7, 2);
		setBlock(world, i + 6, j + 22, k + 8, Blocks.log, 3);
		world.setBlockMetadataWithNotify(i + 6, j + 22, k + 8, 3, 2);
		setBlock(world, i + 6, j + 22, k + 9, Blocks.leaves, 7);
		world.setBlockMetadataWithNotify(i + 6, j + 22, k + 9, 7, 2);
		setBlock(world, i + 6, j + 23, k + 8, Blocks.leaves, 7);
		world.setBlockMetadataWithNotify(i + 6, j + 23, k + 8, 7, 2);
		setBlock(world, i + 6, j + 24, k + 0, Blocks.log, 3);
		world.setBlockMetadataWithNotify(i + 6, j + 24, k + 0, 3, 2);
		setBlock(world, i + 6, j + 27, k + 7, Blocks.log, 3);
		world.setBlockMetadataWithNotify(i + 6, j + 27, k + 7, 3, 2);
		setBlock(world, i + 6, j + 28, k + 5, Blocks.leaves, 7);
		world.setBlockMetadataWithNotify(i + 6, j + 28, k + 5, 7, 2);
		setBlock(world, i + 6, j + 28, k + 6, Blocks.leaves, 7);
		world.setBlockMetadataWithNotify(i + 6, j + 28, k + 6, 7, 2);
		setBlock(world, i + 6, j + 28, k + 7, Blocks.leaves, 7);
		world.setBlockMetadataWithNotify(i + 6, j + 28, k + 7, 7, 2);
		setBlock(world, i + 6, j + 28, k + 8, Blocks.leaves, 7);
		world.setBlockMetadataWithNotify(i + 6, j + 28, k + 8, 7, 2);
		setBlock(world, i + 6, j + 28, k + 9, Blocks.leaves, 7);
		world.setBlockMetadataWithNotify(i + 6, j + 28, k + 9, 7, 2);
		setBlock(world, i + 6, j + 29, k + 6, Blocks.leaves, 7);
		world.setBlockMetadataWithNotify(i + 6, j + 29, k + 6, 7, 2);
		setBlock(world, i + 6, j + 29, k + 7, Blocks.leaves, 7);
		world.setBlockMetadataWithNotify(i + 6, j + 29, k + 7, 7, 2);
		setBlock(world, i + 6, j + 29, k + 8, Blocks.leaves, 7);
		world.setBlockMetadataWithNotify(i + 6, j + 29, k + 8, 7, 2);
		setBlock(world, i + 6, j + 29, k + 17, Blocks.log, 3);
		world.setBlockMetadataWithNotify(i + 6, j + 29, k + 17, 3, 2);
		setBlock(world, i + 6, j + 30, k + 7, Blocks.leaves, 7);
		world.setBlockMetadataWithNotify(i + 6, j + 30, k + 7, 7, 2);
		setBlock(world, i + 6, j + 30, k + 15, Blocks.leaves, 15);
		world.setBlockMetadataWithNotify(i + 6, j + 30, k + 15, 15, 2);
		setBlock(world, i + 6, j + 30, k + 16, Blocks.leaves, 15);
		world.setBlockMetadataWithNotify(i + 6, j + 30, k + 16, 15, 2);
		setBlock(world, i + 6, j + 30, k + 17, Blocks.leaves, 15);
		world.setBlockMetadataWithNotify(i + 6, j + 30, k + 17, 15, 2);
		setBlock(world, i + 6, j + 30, k + 18, Blocks.leaves, 15);
		world.setBlockMetadataWithNotify(i + 6, j + 30, k + 18, 15, 2);
		setBlock(world, i + 6, j + 30, k + 19, Blocks.leaves, 15);
		world.setBlockMetadataWithNotify(i + 6, j + 30, k + 19, 15, 2);
		setBlock(world, i + 6, j + 31, k + 16, Blocks.leaves, 15);
		world.setBlockMetadataWithNotify(i + 6, j + 31, k + 16, 15, 2);
		setBlock(world, i + 6, j + 31, k + 17, Blocks.leaves, 15);
		world.setBlockMetadataWithNotify(i + 6, j + 31, k + 17, 15, 2);
		setBlock(world, i + 6, j + 31, k + 18, Blocks.leaves, 15);
		world.setBlockMetadataWithNotify(i + 6, j + 31, k + 18, 15, 2);
		setBlock(world, i + 6, j + 32, k + 17, Blocks.leaves, 15);
		world.setBlockMetadataWithNotify(i + 6, j + 32, k + 17, 15, 2);
		setBlock(world, i + 6, j + 33, k + 7, Blocks.planks, 5);
		world.setBlockMetadataWithNotify(i + 6, j + 33, k + 7, 5, 2);
		setBlock(world, i + 6, j + 33, k + 8, Blocks.planks, 5);
		world.setBlockMetadataWithNotify(i + 6, j + 33, k + 8, 5, 2);
		setBlock(world, i + 6, j + 34, k + 7, Blocks.spruce_stairs, 2);
		world.setBlockMetadataWithNotify(i + 6, j + 34, k + 7, 2, 2);
		setBlock(world, i + 6, j + 34, k + 8, Blocks.planks, 5);
		world.setBlockMetadataWithNotify(i + 6, j + 34, k + 8, 5, 2);
		setBlock(world, i + 6, j + 34, k + 9, Blocks.planks, 5);
		world.setBlockMetadataWithNotify(i + 6, j + 34, k + 9, 5, 2);
		setBlock(world, i + 6, j + 35, k + 8, Blocks.spruce_stairs, 2);
		world.setBlockMetadataWithNotify(i + 6, j + 35, k + 8, 2, 2);
		setBlock(world, i + 6, j + 35, k + 9, Blocks.planks, 5);
		world.setBlockMetadataWithNotify(i + 6, j + 35, k + 9, 5, 2);
		setBlock(world, i + 6, j + 35, k + 10, Blocks.planks, 5);
		world.setBlockMetadataWithNotify(i + 6, j + 35, k + 10, 5, 2);
		setBlock(world, i + 6, j + 36, k + 9, Blocks.spruce_stairs, 2);
		world.setBlockMetadataWithNotify(i + 6, j + 36, k + 9, 2, 2);
		setBlock(world, i + 6, j + 36, k + 10, Blocks.planks, 5);
		world.setBlockMetadataWithNotify(i + 6, j + 36, k + 10, 5, 2);
		setBlock(world, i + 6, j + 36, k + 11, Blocks.planks, 5);
		world.setBlockMetadataWithNotify(i + 6, j + 36, k + 11, 5, 2);
		setBlock(world, i + 6, j + 37, k + 0, Blocks.log, 1);
		world.setBlockMetadataWithNotify(i + 6, j + 37, k + 0, 1, 2);
		setBlock(world, i + 6, j + 37, k + 10, Blocks.spruce_stairs, 2);
		world.setBlockMetadataWithNotify(i + 6, j + 37, k + 10, 2, 2);
		setBlock(world, i + 6, j + 37, k + 11, Blocks.planks, 5);
		world.setBlockMetadataWithNotify(i + 6, j + 37, k + 11, 5, 2);
		setBlock(world, i + 6, j + 37, k + 12, Blocks.planks, 5);
		world.setBlockMetadataWithNotify(i + 6, j + 37, k + 12, 5, 2);
		setBlock(world, i + 6, j + 38, k + 11, Blocks.spruce_stairs, 2);
		world.setBlockMetadataWithNotify(i + 6, j + 38, k + 11, 2, 2);
		setBlock(world, i + 6, j + 38, k + 12, Blocks.planks, 5);
		world.setBlockMetadataWithNotify(i + 6, j + 38, k + 12, 5, 2);
		setBlock(world, i + 6, j + 38, k + 13, Blocks.planks, 5);
		world.setBlockMetadataWithNotify(i + 6, j + 38, k + 13, 5, 2);
		setBlock(world, i + 6, j + 39, k + 12, Blocks.spruce_stairs, 2);
		world.setBlockMetadataWithNotify(i + 6, j + 39, k + 12, 2, 2);
		setBlock(world, i + 6, j + 39, k + 13, Blocks.planks, 5);
		world.setBlockMetadataWithNotify(i + 6, j + 39, k + 13, 5, 2);
		setBlock(world, i + 6, j + 39, k + 14, Blocks.planks, 5);
		world.setBlockMetadataWithNotify(i + 6, j + 39, k + 14, 5, 2);
		setBlock(world, i + 6, j + 39, k + 15, Blocks.planks, 5);
		world.setBlockMetadataWithNotify(i + 6, j + 39, k + 15, 5, 2);
		setBlock(world, i + 6, j + 39, k + 16, Blocks.planks, 5);
		world.setBlockMetadataWithNotify(i + 6, j + 39, k + 16, 5, 2);
		setBlock(world, i + 6, j + 39, k + 17, Blocks.planks, 5);
		world.setBlockMetadataWithNotify(i + 6, j + 39, k + 17, 5, 2);
		setBlock(world, i + 6, j + 39, k + 18, Blocks.planks, 5);
		world.setBlockMetadataWithNotify(i + 6, j + 39, k + 18, 5, 2);
		setBlock(world, i + 6, j + 39, k + 19, Blocks.planks, 5);
		world.setBlockMetadataWithNotify(i + 6, j + 39, k + 19, 5, 2);
		setBlock(world, i + 6, j + 39, k + 20, Blocks.planks, 5);
		world.setBlockMetadataWithNotify(i + 6, j + 39, k + 20, 5, 2);
		setBlock(world, i + 6, j + 40, k + 13, Blocks.torch, 5);
		world.setBlockMetadataWithNotify(i + 6, j + 40, k + 13, 5, 2);
		setBlock(world, i + 7, j + 22, k + 6, Blocks.leaves, 7);
		world.setBlockMetadataWithNotify(i + 7, j + 22, k + 6, 7, 2);
		setBlock(world, i + 7, j + 22, k + 7, Blocks.leaves, 7);
		world.setBlockMetadataWithNotify(i + 7, j + 22, k + 7, 7, 2);
		setBlock(world, i + 7, j + 22, k + 8, Blocks.log, 3);
		world.setBlockMetadataWithNotify(i + 7, j + 22, k + 8, 3, 2);
		setBlock(world, i + 7, j + 22, k + 9, Blocks.leaves, 7);
		world.setBlockMetadataWithNotify(i + 7, j + 22, k + 9, 7, 2);
		setBlock(world, i + 7, j + 22, k + 10, Blocks.leaves, 7);
		world.setBlockMetadataWithNotify(i + 7, j + 22, k + 10, 7, 2);
		setBlock(world, i + 7, j + 23, k + 7, Blocks.leaves, 7);
		world.setBlockMetadataWithNotify(i + 7, j + 23, k + 7, 7, 2);
		setBlock(world, i + 7, j + 23, k + 8, Blocks.leaves, 7);
		world.setBlockMetadataWithNotify(i + 7, j + 23, k + 8, 7, 2);
		setBlock(world, i + 7, j + 23, k + 9, Blocks.leaves, 7);
		world.setBlockMetadataWithNotify(i + 7, j + 23, k + 9, 7, 2);
		setBlock(world, i + 7, j + 24, k + 1, Blocks.log, 3);
		world.setBlockMetadataWithNotify(i + 7, j + 24, k + 1, 3, 2);
		setBlock(world, i + 7, j + 24, k + 8, Blocks.leaves, 7);
		world.setBlockMetadataWithNotify(i + 7, j + 24, k + 8, 7, 2);
		setBlock(world, i + 7, j + 27, k + 7, Blocks.log, 3);
		world.setBlockMetadataWithNotify(i + 7, j + 27, k + 7, 3, 2);
		setBlock(world, i + 7, j + 28, k + 6, Blocks.leaves, 7);
		world.setBlockMetadataWithNotify(i + 7, j + 28, k + 6, 7, 2);
		setBlock(world, i + 7, j + 28, k + 7, Blocks.leaves, 7);
		world.setBlockMetadataWithNotify(i + 7, j + 28, k + 7, 7, 2);
		setBlock(world, i + 7, j + 28, k + 8, Blocks.leaves, 7);
		world.setBlockMetadataWithNotify(i + 7, j + 28, k + 8, 7, 2);
		setBlock(world, i + 7, j + 29, k + 7, Blocks.leaves, 7);
		world.setBlockMetadataWithNotify(i + 7, j + 29, k + 7, 7, 2);
		setBlock(world, i + 7, j + 29, k + 17, Blocks.log, 3);
		world.setBlockMetadataWithNotify(i + 7, j + 29, k + 17, 3, 2);
		setBlock(world, i + 7, j + 30, k + 16, Blocks.leaves, 15);
		world.setBlockMetadataWithNotify(i + 7, j + 30, k + 16, 15, 2);
		setBlock(world, i + 7, j + 30, k + 17, Blocks.leaves, 15);
		world.setBlockMetadataWithNotify(i + 7, j + 30, k + 17, 15, 2);
		setBlock(world, i + 7, j + 30, k + 18, Blocks.leaves, 15);
		world.setBlockMetadataWithNotify(i + 7, j + 30, k + 18, 15, 2);
		setBlock(world, i + 7, j + 31, k + 17, Blocks.leaves, 15);
		world.setBlockMetadataWithNotify(i + 7, j + 31, k + 17, 15, 2);
		setBlock(world, i + 7, j + 33, k + 6, Blocks.planks, 5);
		world.setBlockMetadataWithNotify(i + 7, j + 33, k + 6, 5, 2);
		setBlock(world, i + 7, j + 33, k + 7, Blocks.planks, 5);
		world.setBlockMetadataWithNotify(i + 7, j + 33, k + 7, 5, 2);
		setBlock(world, i + 7, j + 33, k + 8, Blocks.planks, 5);
		world.setBlockMetadataWithNotify(i + 7, j + 33, k + 8, 5, 2);
		setBlock(world, i + 7, j + 34, k + 7, Blocks.spruce_stairs, 2);
		world.setBlockMetadataWithNotify(i + 7, j + 34, k + 7, 2, 2);
		setBlock(world, i + 7, j + 34, k + 8, Blocks.planks, 5);
		world.setBlockMetadataWithNotify(i + 7, j + 34, k + 8, 5, 2);
		setBlock(world, i + 7, j + 34, k + 9, Blocks.planks, 5);
		world.setBlockMetadataWithNotify(i + 7, j + 34, k + 9, 5, 2);
		setBlock(world, i + 7, j + 35, k + 8, Blocks.spruce_stairs, 2);
		world.setBlockMetadataWithNotify(i + 7, j + 35, k + 8, 2, 2);
		setBlock(world, i + 7, j + 35, k + 9, Blocks.planks, 5);
		world.setBlockMetadataWithNotify(i + 7, j + 35, k + 9, 5, 2);
		setBlock(world, i + 7, j + 35, k + 10, Blocks.planks, 5);
		world.setBlockMetadataWithNotify(i + 7, j + 35, k + 10, 5, 2);
		setBlock(world, i + 7, j + 35, k + 20, Blocks.leaves, 15);
		world.setBlockMetadataWithNotify(i + 7, j + 35, k + 20, 15, 2);
		setBlock(world, i + 7, j + 36, k + 9, Blocks.spruce_stairs, 2);
		world.setBlockMetadataWithNotify(i + 7, j + 36, k + 9, 2, 2);
		setBlock(world, i + 7, j + 36, k + 10, Blocks.planks, 5);
		world.setBlockMetadataWithNotify(i + 7, j + 36, k + 10, 5, 2);
		setBlock(world, i + 7, j + 36, k + 11, Blocks.planks, 5);
		world.setBlockMetadataWithNotify(i + 7, j + 36, k + 11, 5, 2);
		setBlock(world, i + 7, j + 37, k + 0, Blocks.log, 1);
		world.setBlockMetadataWithNotify(i + 7, j + 37, k + 0, 1, 2);
		setBlock(world, i + 7, j + 37, k + 1, Blocks.log, 1);
		world.setBlockMetadataWithNotify(i + 7, j + 37, k + 1, 1, 2);
		setBlock(world, i + 7, j + 37, k + 10, Blocks.spruce_stairs, 2);
		world.setBlockMetadataWithNotify(i + 7, j + 37, k + 10, 2, 2);
		setBlock(world, i + 7, j + 37, k + 11, Blocks.planks, 5);
		world.setBlockMetadataWithNotify(i + 7, j + 37, k + 11, 5, 2);
		setBlock(world, i + 7, j + 37, k + 12, Blocks.planks, 5);
		world.setBlockMetadataWithNotify(i + 7, j + 37, k + 12, 5, 2);
		setBlock(world, i + 7, j + 38, k + 11, Blocks.spruce_stairs, 2);
		world.setBlockMetadataWithNotify(i + 7, j + 38, k + 11, 2, 2);
		setBlock(world, i + 7, j + 38, k + 12, Blocks.planks, 5);
		world.setBlockMetadataWithNotify(i + 7, j + 38, k + 12, 5, 2);
		setBlock(world, i + 7, j + 38, k + 13, Blocks.planks, 5);
		world.setBlockMetadataWithNotify(i + 7, j + 38, k + 13, 5, 2);
		setBlock(world, i + 7, j + 39, k + 12, Blocks.spruce_stairs, 2);
		world.setBlockMetadataWithNotify(i + 7, j + 39, k + 12, 2, 2);
		setBlock(world, i + 7, j + 39, k + 13, Blocks.planks, 5);
		world.setBlockMetadataWithNotify(i + 7, j + 39, k + 13, 5, 2);
		setBlock(world, i + 7, j + 39, k + 14, Blocks.planks, 5);
		world.setBlockMetadataWithNotify(i + 7, j + 39, k + 14, 5, 2);
		setBlock(world, i + 7, j + 39, k + 15, Blocks.planks, 5);
		world.setBlockMetadataWithNotify(i + 7, j + 39, k + 15, 5, 2);
		setBlock(world, i + 7, j + 39, k + 16, Blocks.planks, 5);
		world.setBlockMetadataWithNotify(i + 7, j + 39, k + 16, 5, 2);
		setBlock(world, i + 7, j + 39, k + 17, Blocks.planks, 5);
		world.setBlockMetadataWithNotify(i + 7, j + 39, k + 17, 5, 2);
		setBlock(world, i + 7, j + 39, k + 18, Blocks.planks, 5);
		world.setBlockMetadataWithNotify(i + 7, j + 39, k + 18, 5, 2);
		setBlock(world, i + 7, j + 39, k + 19, Blocks.planks, 5);
		world.setBlockMetadataWithNotify(i + 7, j + 39, k + 19, 5, 2);
		setBlock(world, i + 8, j + 22, k + 6, Blocks.leaves, 7);
		world.setBlockMetadataWithNotify(i + 8, j + 22, k + 6, 7, 2);
		setBlock(world, i + 8, j + 22, k + 7, Blocks.leaves, 7);
		world.setBlockMetadataWithNotify(i + 8, j + 22, k + 7, 7, 2);
		setBlock(world, i + 8, j + 22, k + 8, Blocks.log, 3);
		world.setBlockMetadataWithNotify(i + 8, j + 22, k + 8, 3, 2);
		setBlock(world, i + 8, j + 22, k + 9, Blocks.leaves, 7);
		world.setBlockMetadataWithNotify(i + 8, j + 22, k + 9, 7, 2);
		setBlock(world, i + 8, j + 22, k + 10, Blocks.leaves, 7);
		world.setBlockMetadataWithNotify(i + 8, j + 22, k + 10, 7, 2);
		setBlock(world, i + 8, j + 23, k + 1, Blocks.log, 3);
		world.setBlockMetadataWithNotify(i + 8, j + 23, k + 1, 3, 2);
		setBlock(world, i + 8, j + 23, k + 6, Blocks.leaves, 7);
		world.setBlockMetadataWithNotify(i + 8, j + 23, k + 6, 7, 2);
		setBlock(world, i + 8, j + 23, k + 7, Blocks.leaves, 7);
		world.setBlockMetadataWithNotify(i + 8, j + 23, k + 7, 7, 2);
		setBlock(world, i + 8, j + 23, k + 8, Blocks.leaves, 7);
		world.setBlockMetadataWithNotify(i + 8, j + 23, k + 8, 7, 2);
		setBlock(world, i + 8, j + 23, k + 9, Blocks.leaves, 7);
		world.setBlockMetadataWithNotify(i + 8, j + 23, k + 9, 7, 2);
		setBlock(world, i + 8, j + 23, k + 10, Blocks.leaves, 7);
		world.setBlockMetadataWithNotify(i + 8, j + 23, k + 10, 7, 2);
		setBlock(world, i + 8, j + 24, k + 7, Blocks.leaves, 7);
		world.setBlockMetadataWithNotify(i + 8, j + 24, k + 7, 7, 2);
		setBlock(world, i + 8, j + 24, k + 8, Blocks.leaves, 7);
		world.setBlockMetadataWithNotify(i + 8, j + 24, k + 8, 7, 2);
		setBlock(world, i + 8, j + 24, k + 9, Blocks.leaves, 7);
		world.setBlockMetadataWithNotify(i + 8, j + 24, k + 9, 7, 2);
		setBlock(world, i + 8, j + 25, k + 8, Blocks.leaves, 7);
		world.setBlockMetadataWithNotify(i + 8, j + 25, k + 8, 7, 2);
		setBlock(world, i + 8, j + 27, k + 6, Blocks.leaves, 7);
		world.setBlockMetadataWithNotify(i + 8, j + 27, k + 6, 7, 2);
		setBlock(world, i + 8, j + 27, k + 7, Blocks.log, 3);
		world.setBlockMetadataWithNotify(i + 8, j + 27, k + 7, 3, 2);
		setBlock(world, i + 8, j + 27, k + 8, Blocks.leaves, 7);
		world.setBlockMetadataWithNotify(i + 8, j + 27, k + 8, 7, 2);
		setBlock(world, i + 8, j + 28, k + 7, Blocks.leaves, 7);
		world.setBlockMetadataWithNotify(i + 8, j + 28, k + 7, 7, 2);
		setBlock(world, i + 8, j + 29, k + 16, Blocks.log, 3);
		world.setBlockMetadataWithNotify(i + 8, j + 29, k + 16, 3, 2);
		setBlock(world, i + 8, j + 33, k + 5, Blocks.planks, 5);
		world.setBlockMetadataWithNotify(i + 8, j + 33, k + 5, 5, 2);
		setBlock(world, i + 8, j + 33, k + 6, Blocks.planks, 5);
		world.setBlockMetadataWithNotify(i + 8, j + 33, k + 6, 5, 2);
		setBlock(world, i + 8, j + 33, k + 7, Blocks.planks, 5);
		world.setBlockMetadataWithNotify(i + 8, j + 33, k + 7, 5, 2);
		setBlock(world, i + 8, j + 33, k + 8, Blocks.planks, 5);
		world.setBlockMetadataWithNotify(i + 8, j + 33, k + 8, 5, 2);
		setBlock(world, i + 8, j + 34, k + 7, Blocks.spruce_stairs, 2);
		world.setBlockMetadataWithNotify(i + 8, j + 34, k + 7, 2, 2);
		setBlock(world, i + 8, j + 34, k + 8, Blocks.planks, 5);
		world.setBlockMetadataWithNotify(i + 8, j + 34, k + 8, 5, 2);
		setBlock(world, i + 8, j + 34, k + 9, Blocks.planks, 5);
		world.setBlockMetadataWithNotify(i + 8, j + 34, k + 9, 5, 2);
		setBlock(world, i + 8, j + 34, k + 17, Blocks.leaves, 15);
		world.setBlockMetadataWithNotify(i + 8, j + 34, k + 17, 15, 2);
		setBlock(world, i + 8, j + 35, k + 8, Blocks.spruce_stairs, 2);
		world.setBlockMetadataWithNotify(i + 8, j + 35, k + 8, 2, 2);
		setBlock(world, i + 8, j + 35, k + 9, Blocks.planks, 5);
		world.setBlockMetadataWithNotify(i + 8, j + 35, k + 9, 5, 2);
		setBlock(world, i + 8, j + 35, k + 10, Blocks.planks, 5);
		world.setBlockMetadataWithNotify(i + 8, j + 35, k + 10, 5, 2);
		setBlock(world, i + 8, j + 35, k + 18, Blocks.log, 3);
		world.setBlockMetadataWithNotify(i + 8, j + 35, k + 18, 3, 2);
		setBlock(world, i + 8, j + 35, k + 20, Blocks.leaves, 15);
		world.setBlockMetadataWithNotify(i + 8, j + 35, k + 20, 15, 2);
		setBlock(world, i + 8, j + 36, k + 9, Blocks.spruce_stairs, 2);
		world.setBlockMetadataWithNotify(i + 8, j + 36, k + 9, 2, 2);
		setBlock(world, i + 8, j + 36, k + 10, Blocks.planks, 5);
		world.setBlockMetadataWithNotify(i + 8, j + 36, k + 10, 5, 2);
		setBlock(world, i + 8, j + 36, k + 11, Blocks.planks, 5);
		world.setBlockMetadataWithNotify(i + 8, j + 36, k + 11, 5, 2);
		setBlock(world, i + 8, j + 36, k + 18, Blocks.leaves, 15);
		world.setBlockMetadataWithNotify(i + 8, j + 36, k + 18, 15, 2);
		setBlock(world, i + 8, j + 36, k + 19, Blocks.leaves, 15);
		world.setBlockMetadataWithNotify(i + 8, j + 36, k + 19, 15, 2);
		setBlock(world, i + 8, j + 36, k + 20, Blocks.leaves, 15);
		world.setBlockMetadataWithNotify(i + 8, j + 36, k + 20, 15, 2);
		setBlock(world, i + 8, j + 37, k + 0, Blocks.log, 1);
		world.setBlockMetadataWithNotify(i + 8, j + 37, k + 0, 1, 2);
		setBlock(world, i + 8, j + 37, k + 1, Blocks.log, 1);
		world.setBlockMetadataWithNotify(i + 8, j + 37, k + 1, 1, 2);
		setBlock(world, i + 8, j + 37, k + 10, Blocks.spruce_stairs, 2);
		world.setBlockMetadataWithNotify(i + 8, j + 37, k + 10, 2, 2);
		setBlock(world, i + 8, j + 37, k + 11, Blocks.planks, 5);
		world.setBlockMetadataWithNotify(i + 8, j + 37, k + 11, 5, 2);
		setBlock(world, i + 8, j + 37, k + 12, Blocks.planks, 5);
		world.setBlockMetadataWithNotify(i + 8, j + 37, k + 12, 5, 2);
		setBlock(world, i + 8, j + 38, k + 0, Blocks.log, 1);
		world.setBlockMetadataWithNotify(i + 8, j + 38, k + 0, 1, 2);
		setBlock(world, i + 8, j + 38, k + 11, Blocks.spruce_stairs, 2);
		world.setBlockMetadataWithNotify(i + 8, j + 38, k + 11, 2, 2);
		setBlock(world, i + 8, j + 38, k + 12, Blocks.planks, 5);
		world.setBlockMetadataWithNotify(i + 8, j + 38, k + 12, 5, 2);
		setBlock(world, i + 8, j + 38, k + 13, Blocks.planks, 5);
		world.setBlockMetadataWithNotify(i + 8, j + 38, k + 13, 5, 2);
		setBlock(world, i + 8, j + 39, k + 0, Blocks.log, 1);
		world.setBlockMetadataWithNotify(i + 8, j + 39, k + 0, 1, 2);
		setBlock(world, i + 8, j + 39, k + 12, Blocks.spruce_stairs, 2);
		world.setBlockMetadataWithNotify(i + 8, j + 39, k + 12, 2, 2);
		setBlock(world, i + 8, j + 39, k + 13, Blocks.planks, 5);
		world.setBlockMetadataWithNotify(i + 8, j + 39, k + 13, 5, 2);
		setBlock(world, i + 8, j + 39, k + 14, Blocks.planks, 5);
		world.setBlockMetadataWithNotify(i + 8, j + 39, k + 14, 5, 2);
		setBlock(world, i + 8, j + 39, k + 15, Blocks.planks, 5);
		world.setBlockMetadataWithNotify(i + 8, j + 39, k + 15, 5, 2);
		setBlock(world, i + 8, j + 39, k + 16, Blocks.planks, 5);
		world.setBlockMetadataWithNotify(i + 8, j + 39, k + 16, 5, 2);
		setBlock(world, i + 8, j + 39, k + 17, Blocks.planks, 5);
		world.setBlockMetadataWithNotify(i + 8, j + 39, k + 17, 5, 2);
		setBlock(world, i + 8, j + 39, k + 18, Blocks.planks, 5);
		world.setBlockMetadataWithNotify(i + 8, j + 39, k + 18, 5, 2);
		setBlock(world, i + 8, j + 40, k + 18, Blocks.torch, 5);
		world.setBlockMetadataWithNotify(i + 8, j + 40, k + 18, 5, 2);
		setBlock(world, i + 9, j + 21, k + 9, Blocks.log, 3);
		world.setBlockMetadataWithNotify(i + 9, j + 21, k + 9, 3, 2);
		setBlock(world, i + 9, j + 22, k + 6, Blocks.leaves, 7);
		world.setBlockMetadataWithNotify(i + 9, j + 22, k + 6, 7, 2);
		setBlock(world, i + 9, j + 22, k + 7, Blocks.leaves, 7);
		world.setBlockMetadataWithNotify(i + 9, j + 22, k + 7, 7, 2);
		setBlock(world, i + 9, j + 22, k + 8, Blocks.log, 3);
		world.setBlockMetadataWithNotify(i + 9, j + 22, k + 8, 3, 2);
		setBlock(world, i + 9, j + 22, k + 9, Blocks.leaves, 7);
		world.setBlockMetadataWithNotify(i + 9, j + 22, k + 9, 7, 2);
		setBlock(world, i + 9, j + 22, k + 10, Blocks.leaves, 7);
		world.setBlockMetadataWithNotify(i + 9, j + 22, k + 10, 7, 2);
		setBlock(world, i + 9, j + 23, k + 2, Blocks.log, 3);
		world.setBlockMetadataWithNotify(i + 9, j + 23, k + 2, 3, 2);
		setBlock(world, i + 9, j + 23, k + 7, Blocks.leaves, 7);
		world.setBlockMetadataWithNotify(i + 9, j + 23, k + 7, 7, 2);
		setBlock(world, i + 9, j + 23, k + 8, Blocks.leaves, 7);
		world.setBlockMetadataWithNotify(i + 9, j + 23, k + 8, 7, 2);
		setBlock(world, i + 9, j + 23, k + 9, Blocks.leaves, 7);
		world.setBlockMetadataWithNotify(i + 9, j + 23, k + 9, 7, 2);
		setBlock(world, i + 9, j + 24, k + 8, Blocks.leaves, 7);
		world.setBlockMetadataWithNotify(i + 9, j + 24, k + 8, 7, 2);
		setBlock(world, i + 9, j + 27, k + 5, Blocks.leaves, 7);
		world.setBlockMetadataWithNotify(i + 9, j + 27, k + 5, 7, 2);
		setBlock(world, i + 9, j + 27, k + 6, Blocks.leaves, 7);
		world.setBlockMetadataWithNotify(i + 9, j + 27, k + 6, 7, 2);
		setBlock(world, i + 9, j + 27, k + 7, Blocks.log, 3);
		world.setBlockMetadataWithNotify(i + 9, j + 27, k + 7, 3, 2);
		setBlock(world, i + 9, j + 27, k + 8, Blocks.leaves, 7);
		world.setBlockMetadataWithNotify(i + 9, j + 27, k + 8, 7, 2);
		setBlock(world, i + 9, j + 27, k + 9, Blocks.leaves, 7);
		world.setBlockMetadataWithNotify(i + 9, j + 27, k + 9, 7, 2);
		setBlock(world, i + 9, j + 28, k + 6, Blocks.leaves, 7);
		world.setBlockMetadataWithNotify(i + 9, j + 28, k + 6, 7, 2);
		setBlock(world, i + 9, j + 28, k + 7, Blocks.leaves, 7);
		world.setBlockMetadataWithNotify(i + 9, j + 28, k + 7, 7, 2);
		setBlock(world, i + 9, j + 28, k + 8, Blocks.leaves, 7);
		world.setBlockMetadataWithNotify(i + 9, j + 28, k + 8, 7, 2);
		setBlock(world, i + 9, j + 29, k + 7, Blocks.leaves, 7);
		world.setBlockMetadataWithNotify(i + 9, j + 29, k + 7, 7, 2);
		setBlock(world, i + 9, j + 29, k + 16, Blocks.log, 3);
		world.setBlockMetadataWithNotify(i + 9, j + 29, k + 16, 3, 2);
		setBlock(world, i + 9, j + 33, k + 4, Blocks.planks, 5);
		world.setBlockMetadataWithNotify(i + 9, j + 33, k + 4, 5, 2);
		setBlock(world, i + 9, j + 33, k + 5, Blocks.planks, 5);
		world.setBlockMetadataWithNotify(i + 9, j + 33, k + 5, 5, 2);
		setBlock(world, i + 9, j + 33, k + 6, Blocks.planks, 5);
		world.setBlockMetadataWithNotify(i + 9, j + 33, k + 6, 5, 2);
		setBlock(world, i + 9, j + 33, k + 7, Blocks.planks, 5);
		world.setBlockMetadataWithNotify(i + 9, j + 33, k + 7, 5, 2);
		setBlock(world, i + 9, j + 33, k + 8, Blocks.planks, 5);
		world.setBlockMetadataWithNotify(i + 9, j + 33, k + 8, 5, 2);
		setBlock(world, i + 9, j + 33, k + 15, Blocks.log, 3);
		world.setBlockMetadataWithNotify(i + 9, j + 33, k + 15, 3, 2);
		setBlock(world, i + 9, j + 34, k + 7, Blocks.spruce_stairs, 2);
		world.setBlockMetadataWithNotify(i + 9, j + 34, k + 7, 2, 2);
		setBlock(world, i + 9, j + 34, k + 8, Blocks.planks, 5);
		world.setBlockMetadataWithNotify(i + 9, j + 34, k + 8, 5, 2);
		setBlock(world, i + 9, j + 34, k + 9, Blocks.planks, 5);
		world.setBlockMetadataWithNotify(i + 9, j + 34, k + 9, 5, 2);
		setBlock(world, i + 9, j + 34, k + 17, Blocks.leaves, 15);
		world.setBlockMetadataWithNotify(i + 9, j + 34, k + 17, 15, 2);
		setBlock(world, i + 9, j + 34, k + 18, Blocks.log, 3);
		world.setBlockMetadataWithNotify(i + 9, j + 34, k + 18, 3, 2);
		setBlock(world, i + 9, j + 35, k + 8, Blocks.spruce_stairs, 2);
		world.setBlockMetadataWithNotify(i + 9, j + 35, k + 8, 2, 2);
		setBlock(world, i + 9, j + 35, k + 9, Blocks.planks, 5);
		world.setBlockMetadataWithNotify(i + 9, j + 35, k + 9, 5, 2);
		setBlock(world, i + 9, j + 35, k + 10, Blocks.planks, 5);
		world.setBlockMetadataWithNotify(i + 9, j + 35, k + 10, 5, 2);
		setBlock(world, i + 9, j + 35, k + 18, Blocks.leaves, 15);
		world.setBlockMetadataWithNotify(i + 9, j + 35, k + 18, 15, 2);
		setBlock(world, i + 9, j + 35, k + 19, Blocks.leaves, 15);
		world.setBlockMetadataWithNotify(i + 9, j + 35, k + 19, 15, 2);
		setBlock(world, i + 9, j + 35, k + 20, Blocks.leaves, 15);
		world.setBlockMetadataWithNotify(i + 9, j + 35, k + 20, 15, 2);
		setBlock(world, i + 9, j + 36, k + 9, Blocks.spruce_stairs, 2);
		world.setBlockMetadataWithNotify(i + 9, j + 36, k + 9, 2, 2);
		setBlock(world, i + 9, j + 36, k + 10, Blocks.planks, 5);
		world.setBlockMetadataWithNotify(i + 9, j + 36, k + 10, 5, 2);
		setBlock(world, i + 9, j + 36, k + 11, Blocks.planks, 5);
		world.setBlockMetadataWithNotify(i + 9, j + 36, k + 11, 5, 2);
		setBlock(world, i + 9, j + 36, k + 18, Blocks.leaves, 15);
		world.setBlockMetadataWithNotify(i + 9, j + 36, k + 18, 15, 2);
		setBlock(world, i + 9, j + 36, k + 19, Blocks.leaves, 15);
		world.setBlockMetadataWithNotify(i + 9, j + 36, k + 19, 15, 2);
		setBlock(world, i + 9, j + 37, k + 0, Blocks.log, 1);
		world.setBlockMetadataWithNotify(i + 9, j + 37, k + 0, 1, 2);
		setBlock(world, i + 9, j + 37, k + 1, Blocks.log, 1);
		world.setBlockMetadataWithNotify(i + 9, j + 37, k + 1, 1, 2);
		setBlock(world, i + 9, j + 37, k + 2, Blocks.log, 1);
		world.setBlockMetadataWithNotify(i + 9, j + 37, k + 2, 1, 2);
		setBlock(world, i + 9, j + 37, k + 10, Blocks.spruce_stairs, 2);
		world.setBlockMetadataWithNotify(i + 9, j + 37, k + 10, 2, 2);
		setBlock(world, i + 9, j + 37, k + 11, Blocks.planks, 5);
		world.setBlockMetadataWithNotify(i + 9, j + 37, k + 11, 5, 2);
		setBlock(world, i + 9, j + 37, k + 12, Blocks.planks, 5);
		world.setBlockMetadataWithNotify(i + 9, j + 37, k + 12, 5, 2);
		setBlock(world, i + 9, j + 38, k + 0, Blocks.log, 1);
		world.setBlockMetadataWithNotify(i + 9, j + 38, k + 0, 1, 2);
		setBlock(world, i + 9, j + 38, k + 11, Blocks.spruce_stairs, 2);
		world.setBlockMetadataWithNotify(i + 9, j + 38, k + 11, 2, 2);
		setBlock(world, i + 9, j + 38, k + 12, Blocks.planks, 5);
		world.setBlockMetadataWithNotify(i + 9, j + 38, k + 12, 5, 2);
		setBlock(world, i + 9, j + 38, k + 13, Blocks.planks, 5);
		world.setBlockMetadataWithNotify(i + 9, j + 38, k + 13, 5, 2);
		setBlock(world, i + 9, j + 39, k + 0, Blocks.log, 1);
		world.setBlockMetadataWithNotify(i + 9, j + 39, k + 0, 1, 2);
		setBlock(world, i + 9, j + 39, k + 12, Blocks.spruce_stairs, 2);
		world.setBlockMetadataWithNotify(i + 9, j + 39, k + 12, 2, 2);
		setBlock(world, i + 9, j + 39, k + 13, Blocks.planks, 5);
		world.setBlockMetadataWithNotify(i + 9, j + 39, k + 13, 5, 2);
		setBlock(world, i + 9, j + 39, k + 14, Blocks.planks, 5);
		world.setBlockMetadataWithNotify(i + 9, j + 39, k + 14, 5, 2);
		setBlock(world, i + 9, j + 39, k + 15, Blocks.planks, 5);
		world.setBlockMetadataWithNotify(i + 9, j + 39, k + 15, 5, 2);
		setBlock(world, i + 9, j + 39, k + 16, Blocks.planks, 5);
		world.setBlockMetadataWithNotify(i + 9, j + 39, k + 16, 5, 2);
		setBlock(world, i + 9, j + 39, k + 17, Blocks.planks, 5);
		world.setBlockMetadataWithNotify(i + 9, j + 39, k + 17, 5, 2);
		setBlock(world, i + 10, j + 21, k + 9, Blocks.log, 3);
		world.setBlockMetadataWithNotify(i + 10, j + 21, k + 9, 3, 2);
		setBlock(world, i + 10, j + 22, k + 7, Blocks.leaves, 7);
		world.setBlockMetadataWithNotify(i + 10, j + 22, k + 7, 7, 2);
		setBlock(world, i + 10, j + 22, k + 8, Blocks.log, 3);
		world.setBlockMetadataWithNotify(i + 10, j + 22, k + 8, 3, 2);
		setBlock(world, i + 10, j + 22, k + 9, Blocks.leaves, 7);
		world.setBlockMetadataWithNotify(i + 10, j + 22, k + 9, 7, 2);
		setBlock(world, i + 10, j + 23, k + 3, Blocks.log, 3);
		world.setBlockMetadataWithNotify(i + 10, j + 23, k + 3, 3, 2);
		setBlock(world, i + 10, j + 23, k + 8, Blocks.leaves, 7);
		world.setBlockMetadataWithNotify(i + 10, j + 23, k + 8, 7, 2);
		setBlock(world, i + 10, j + 26, k + 7, Blocks.log, 3);
		world.setBlockMetadataWithNotify(i + 10, j + 26, k + 7, 3, 2);
		setBlock(world, i + 10, j + 27, k + 5, Blocks.leaves, 7);
		world.setBlockMetadataWithNotify(i + 10, j + 27, k + 5, 7, 2);
		setBlock(world, i + 10, j + 27, k + 6, Blocks.leaves, 7);
		world.setBlockMetadataWithNotify(i + 10, j + 27, k + 6, 7, 2);
		setBlock(world, i + 10, j + 27, k + 7, Blocks.log, 3);
		world.setBlockMetadataWithNotify(i + 10, j + 27, k + 7, 3, 2);
		setBlock(world, i + 10, j + 27, k + 8, Blocks.leaves, 7);
		world.setBlockMetadataWithNotify(i + 10, j + 27, k + 8, 7, 2);
		setBlock(world, i + 10, j + 27, k + 9, Blocks.leaves, 7);
		world.setBlockMetadataWithNotify(i + 10, j + 27, k + 9, 7, 2);
		setBlock(world, i + 10, j + 28, k + 5, Blocks.leaves, 7);
		world.setBlockMetadataWithNotify(i + 10, j + 28, k + 5, 7, 2);
		setBlock(world, i + 10, j + 28, k + 6, Blocks.leaves, 7);
		world.setBlockMetadataWithNotify(i + 10, j + 28, k + 6, 7, 2);
		setBlock(world, i + 10, j + 28, k + 7, Blocks.leaves, 7);
		world.setBlockMetadataWithNotify(i + 10, j + 28, k + 7, 7, 2);
		setBlock(world, i + 10, j + 28, k + 8, Blocks.leaves, 7);
		world.setBlockMetadataWithNotify(i + 10, j + 28, k + 8, 7, 2);
		setBlock(world, i + 10, j + 28, k + 9, Blocks.leaves, 7);
		world.setBlockMetadataWithNotify(i + 10, j + 28, k + 9, 7, 2);
		setBlock(world, i + 10, j + 29, k + 6, Blocks.leaves, 7);
		world.setBlockMetadataWithNotify(i + 10, j + 29, k + 6, 7, 2);
		setBlock(world, i + 10, j + 29, k + 7, Blocks.leaves, 7);
		world.setBlockMetadataWithNotify(i + 10, j + 29, k + 7, 7, 2);
		setBlock(world, i + 10, j + 29, k + 8, Blocks.leaves, 7);
		world.setBlockMetadataWithNotify(i + 10, j + 29, k + 8, 7, 2);
		setBlock(world, i + 10, j + 29, k + 15, Blocks.log, 3);
		world.setBlockMetadataWithNotify(i + 10, j + 29, k + 15, 3, 2);
		setBlock(world, i + 10, j + 30, k + 7, Blocks.leaves, 7);
		world.setBlockMetadataWithNotify(i + 10, j + 30, k + 7, 7, 2);
		setBlock(world, i + 10, j + 32, k + 11, Blocks.log, 3);
		world.setBlockMetadataWithNotify(i + 10, j + 32, k + 11, 3, 2);
		setBlock(world, i + 10, j + 32, k + 12, Blocks.leaves, 15);
		world.setBlockMetadataWithNotify(i + 10, j + 32, k + 12, 15, 2);
		setBlock(world, i + 10, j + 32, k + 13, Blocks.leaves, 15);
		world.setBlockMetadataWithNotify(i + 10, j + 32, k + 13, 15, 2);
		setBlock(world, i + 10, j + 33, k + 0, Blocks.planks, 5);
		world.setBlockMetadataWithNotify(i + 10, j + 33, k + 0, 5, 2);
		setBlock(world, i + 10, j + 33, k + 1, Blocks.planks, 5);
		world.setBlockMetadataWithNotify(i + 10, j + 33, k + 1, 5, 2);
		setBlock(world, i + 10, j + 33, k + 2, Blocks.planks, 5);
		world.setBlockMetadataWithNotify(i + 10, j + 33, k + 2, 5, 2);
		setBlock(world, i + 10, j + 33, k + 3, Blocks.planks, 5);
		world.setBlockMetadataWithNotify(i + 10, j + 33, k + 3, 5, 2);
		setBlock(world, i + 10, j + 33, k + 4, Blocks.planks, 5);
		world.setBlockMetadataWithNotify(i + 10, j + 33, k + 4, 5, 2);
		setBlock(world, i + 10, j + 33, k + 5, Blocks.planks, 5);
		world.setBlockMetadataWithNotify(i + 10, j + 33, k + 5, 5, 2);
		setBlock(world, i + 10, j + 33, k + 6, Blocks.planks, 5);
		world.setBlockMetadataWithNotify(i + 10, j + 33, k + 6, 5, 2);
		setBlock(world, i + 10, j + 33, k + 7, Blocks.planks, 5);
		world.setBlockMetadataWithNotify(i + 10, j + 33, k + 7, 5, 2);
		setBlock(world, i + 10, j + 33, k + 8, Blocks.planks, 5);
		world.setBlockMetadataWithNotify(i + 10, j + 33, k + 8, 5, 2);
		setBlock(world, i + 10, j + 33, k + 13, Blocks.leaves, 15);
		world.setBlockMetadataWithNotify(i + 10, j + 33, k + 13, 15, 2);
		setBlock(world, i + 10, j + 33, k + 15, Blocks.log, 3);
		world.setBlockMetadataWithNotify(i + 10, j + 33, k + 15, 3, 2);
		setBlock(world, i + 10, j + 34, k + 0, Blocks.spruce_stairs, 7);
		world.setBlockMetadataWithNotify(i + 10, j + 34, k + 0, 7, 2);
		setBlock(world, i + 10, j + 34, k + 3, Blocks.torch, 5);
		world.setBlockMetadataWithNotify(i + 10, j + 34, k + 3, 5, 2);
		setBlock(world, i + 10, j + 34, k + 7, Blocks.spruce_stairs, 2);
		world.setBlockMetadataWithNotify(i + 10, j + 34, k + 7, 2, 2);
		setBlock(world, i + 10, j + 34, k + 8, Blocks.planks, 5);
		world.setBlockMetadataWithNotify(i + 10, j + 34, k + 8, 5, 2);
		setBlock(world, i + 10, j + 34, k + 9, Blocks.planks, 5);
		world.setBlockMetadataWithNotify(i + 10, j + 34, k + 9, 5, 2);
		setBlock(world, i + 10, j + 34, k + 14, Blocks.leaves, 15);
		world.setBlockMetadataWithNotify(i + 10, j + 34, k + 14, 15, 2);
		setBlock(world, i + 10, j + 34, k + 15, Blocks.leaves, 15);
		world.setBlockMetadataWithNotify(i + 10, j + 34, k + 15, 15, 2);
		setBlock(world, i + 10, j + 34, k + 17, Blocks.log, 3);
		world.setBlockMetadataWithNotify(i + 10, j + 34, k + 17, 3, 2);
		setBlock(world, i + 10, j + 35, k + 0, Blocks.log, 1);
		world.setBlockMetadataWithNotify(i + 10, j + 35, k + 0, 1, 2);
		setBlock(world, i + 10, j + 35, k + 1, Blocks.spruce_stairs, 7);
		world.setBlockMetadataWithNotify(i + 10, j + 35, k + 1, 7, 2);
		setBlock(world, i + 10, j + 35, k + 8, Blocks.spruce_stairs, 2);
		world.setBlockMetadataWithNotify(i + 10, j + 35, k + 8, 2, 2);
		setBlock(world, i + 10, j + 35, k + 9, Blocks.planks, 5);
		world.setBlockMetadataWithNotify(i + 10, j + 35, k + 9, 5, 2);
		setBlock(world, i + 10, j + 35, k + 10, Blocks.planks, 5);
		world.setBlockMetadataWithNotify(i + 10, j + 35, k + 10, 5, 2);
		setBlock(world, i + 10, j + 35, k + 18, Blocks.leaves, 15);
		world.setBlockMetadataWithNotify(i + 10, j + 35, k + 18, 15, 2);
		setBlock(world, i + 10, j + 35, k + 19, Blocks.leaves, 15);
		world.setBlockMetadataWithNotify(i + 10, j + 35, k + 19, 15, 2);
		setBlock(world, i + 10, j + 36, k + 0, Blocks.log, 1);
		world.setBlockMetadataWithNotify(i + 10, j + 36, k + 0, 1, 2);
		setBlock(world, i + 10, j + 36, k + 1, Blocks.log, 1);
		world.setBlockMetadataWithNotify(i + 10, j + 36, k + 1, 1, 2);
		setBlock(world, i + 10, j + 36, k + 9, Blocks.spruce_stairs, 2);
		world.setBlockMetadataWithNotify(i + 10, j + 36, k + 9, 2, 2);
		setBlock(world, i + 10, j + 36, k + 10, Blocks.planks, 5);
		world.setBlockMetadataWithNotify(i + 10, j + 36, k + 10, 5, 2);
		setBlock(world, i + 10, j + 36, k + 11, Blocks.planks, 5);
		world.setBlockMetadataWithNotify(i + 10, j + 36, k + 11, 5, 2);
		setBlock(world, i + 10, j + 36, k + 18, Blocks.leaves, 15);
		world.setBlockMetadataWithNotify(i + 10, j + 36, k + 18, 15, 2);
		setBlock(world, i + 10, j + 37, k + 0, Blocks.log, 1);
		world.setBlockMetadataWithNotify(i + 10, j + 37, k + 0, 1, 2);
		setBlock(world, i + 10, j + 37, k + 1, Blocks.log, 1);
		world.setBlockMetadataWithNotify(i + 10, j + 37, k + 1, 1, 2);
		setBlock(world, i + 10, j + 37, k + 2, Blocks.log, 1);
		world.setBlockMetadataWithNotify(i + 10, j + 37, k + 2, 1, 2);
		setBlock(world, i + 10, j + 37, k + 10, Blocks.spruce_stairs, 2);
		world.setBlockMetadataWithNotify(i + 10, j + 37, k + 10, 2, 2);
		setBlock(world, i + 10, j + 37, k + 11, Blocks.planks, 5);
		world.setBlockMetadataWithNotify(i + 10, j + 37, k + 11, 5, 2);
		setBlock(world, i + 10, j + 37, k + 12, Blocks.planks, 5);
		world.setBlockMetadataWithNotify(i + 10, j + 37, k + 12, 5, 2);
		setBlock(world, i + 10, j + 38, k + 0, Blocks.log, 1);
		world.setBlockMetadataWithNotify(i + 10, j + 38, k + 0, 1, 2);
		setBlock(world, i + 10, j + 38, k + 1, Blocks.log, 1);
		world.setBlockMetadataWithNotify(i + 10, j + 38, k + 1, 1, 2);
		setBlock(world, i + 10, j + 38, k + 2, Blocks.leaves, 15);
		world.setBlockMetadataWithNotify(i + 10, j + 38, k + 2, 15, 2);
		setBlock(world, i + 10, j + 38, k + 11, Blocks.spruce_stairs, 2);
		world.setBlockMetadataWithNotify(i + 10, j + 38, k + 11, 2, 2);
		setBlock(world, i + 10, j + 38, k + 12, Blocks.planks, 5);
		world.setBlockMetadataWithNotify(i + 10, j + 38, k + 12, 5, 2);
		setBlock(world, i + 10, j + 38, k + 13, Blocks.planks, 5);
		world.setBlockMetadataWithNotify(i + 10, j + 38, k + 13, 5, 2);
		setBlock(world, i + 10, j + 39, k + 0, Blocks.log, 1);
		world.setBlockMetadataWithNotify(i + 10, j + 39, k + 0, 1, 2);
		setBlock(world, i + 10, j + 39, k + 1, Blocks.log, 1);
		world.setBlockMetadataWithNotify(i + 10, j + 39, k + 1, 1, 2);
		setBlock(world, i + 10, j + 39, k + 12, Blocks.spruce_stairs, 2);
		world.setBlockMetadataWithNotify(i + 10, j + 39, k + 12, 2, 2);
		setBlock(world, i + 10, j + 39, k + 13, Blocks.planks, 5);
		world.setBlockMetadataWithNotify(i + 10, j + 39, k + 13, 5, 2);
		setBlock(world, i + 10, j + 39, k + 14, Blocks.planks, 5);
		world.setBlockMetadataWithNotify(i + 10, j + 39, k + 14, 5, 2);
		setBlock(world, i + 10, j + 39, k + 15, Blocks.planks, 5);
		world.setBlockMetadataWithNotify(i + 10, j + 39, k + 15, 5, 2);
		setBlock(world, i + 10, j + 39, k + 16, Blocks.planks, 5);
		world.setBlockMetadataWithNotify(i + 10, j + 39, k + 16, 5, 2);
		setBlock(world, i + 10, j + 40, k + 0, Blocks.log, 1);
		world.setBlockMetadataWithNotify(i + 10, j + 40, k + 0, 1, 2);
		setBlock(world, i + 10, j + 40, k + 13, Blocks.torch, 5);
		world.setBlockMetadataWithNotify(i + 10, j + 40, k + 13, 5, 2);
		setBlock(world, i + 10, j + 46, k + 5, Blocks.leaves, 7);
		world.setBlockMetadataWithNotify(i + 10, j + 46, k + 5, 7, 2);
		setBlock(world, i + 10, j + 46, k + 6, Blocks.leaves, 7);
		world.setBlockMetadataWithNotify(i + 10, j + 46, k + 6, 7, 2);
		setBlock(world, i + 10, j + 46, k + 7, Blocks.leaves, 7);
		world.setBlockMetadataWithNotify(i + 10, j + 46, k + 7, 7, 2);
		setBlock(world, i + 10, j + 47, k + 6, Blocks.leaves, 7);
		world.setBlockMetadataWithNotify(i + 10, j + 47, k + 6, 7, 2);
		setBlock(world, i + 11, j + 21, k + 9, Blocks.log, 3);
		world.setBlockMetadataWithNotify(i + 11, j + 21, k + 9, 3, 2);
		setBlock(world, i + 11, j + 22, k + 8, Blocks.log, 3);
		world.setBlockMetadataWithNotify(i + 11, j + 22, k + 8, 3, 2);
		setBlock(world, i + 11, j + 23, k + 3, Blocks.log, 3);
		world.setBlockMetadataWithNotify(i + 11, j + 23, k + 3, 3, 2);
		setBlock(world, i + 11, j + 25, k + 7, Blocks.leaves, 7);
		world.setBlockMetadataWithNotify(i + 11, j + 25, k + 7, 7, 2);
		setBlock(world, i + 11, j + 25, k + 8, Blocks.leaves, 7);
		world.setBlockMetadataWithNotify(i + 11, j + 25, k + 8, 7, 2);
		setBlock(world, i + 11, j + 25, k + 9, Blocks.leaves, 7);
		world.setBlockMetadataWithNotify(i + 11, j + 25, k + 9, 7, 2);
		setBlock(world, i + 11, j + 25, k + 18, Blocks.leaves, 7);
		world.setBlockMetadataWithNotify(i + 11, j + 25, k + 18, 7, 2);
		setBlock(world, i + 11, j + 25, k + 19, Blocks.leaves, 7);
		world.setBlockMetadataWithNotify(i + 11, j + 25, k + 19, 7, 2);
		setBlock(world, i + 11, j + 25, k + 20, Blocks.leaves, 7);
		world.setBlockMetadataWithNotify(i + 11, j + 25, k + 20, 7, 2);
		setBlock(world, i + 11, j + 26, k + 7, Blocks.log, 3);
		world.setBlockMetadataWithNotify(i + 11, j + 26, k + 7, 3, 2);
		setBlock(world, i + 11, j + 26, k + 8, Blocks.leaves, 7);
		world.setBlockMetadataWithNotify(i + 11, j + 26, k + 8, 7, 2);
		setBlock(world, i + 11, j + 26, k + 18, Blocks.leaves, 7);
		world.setBlockMetadataWithNotify(i + 11, j + 26, k + 18, 7, 2);
		setBlock(world, i + 11, j + 26, k + 19, Blocks.leaves, 7);
		world.setBlockMetadataWithNotify(i + 11, j + 26, k + 19, 7, 2);
		setBlock(world, i + 11, j + 26, k + 20, Blocks.leaves, 7);
		world.setBlockMetadataWithNotify(i + 11, j + 26, k + 20, 7, 2);
		setBlock(world, i + 11, j + 27, k + 5, Blocks.leaves, 7);
		world.setBlockMetadataWithNotify(i + 11, j + 27, k + 5, 7, 2);
		setBlock(world, i + 11, j + 27, k + 6, Blocks.leaves, 7);
		world.setBlockMetadataWithNotify(i + 11, j + 27, k + 6, 7, 2);
		setBlock(world, i + 11, j + 27, k + 7, Blocks.leaves, 7);
		world.setBlockMetadataWithNotify(i + 11, j + 27, k + 7, 7, 2);
		setBlock(world, i + 11, j + 27, k + 8, Blocks.leaves, 7);
		world.setBlockMetadataWithNotify(i + 11, j + 27, k + 8, 7, 2);
		setBlock(world, i + 11, j + 27, k + 9, Blocks.leaves, 7);
		world.setBlockMetadataWithNotify(i + 11, j + 27, k + 9, 7, 2);
		setBlock(world, i + 11, j + 27, k + 19, Blocks.leaves, 7);
		world.setBlockMetadataWithNotify(i + 11, j + 27, k + 19, 7, 2);
		setBlock(world, i + 11, j + 28, k + 6, Blocks.leaves, 7);
		world.setBlockMetadataWithNotify(i + 11, j + 28, k + 6, 7, 2);
		setBlock(world, i + 11, j + 28, k + 7, Blocks.leaves, 7);
		world.setBlockMetadataWithNotify(i + 11, j + 28, k + 7, 7, 2);
		setBlock(world, i + 11, j + 28, k + 8, Blocks.leaves, 7);
		world.setBlockMetadataWithNotify(i + 11, j + 28, k + 8, 7, 2);
		setBlock(world, i + 11, j + 28, k + 15, Blocks.log, 3);
		world.setBlockMetadataWithNotify(i + 11, j + 28, k + 15, 3, 2);
		setBlock(world, i + 11, j + 29, k + 7, Blocks.leaves, 7);
		world.setBlockMetadataWithNotify(i + 11, j + 29, k + 7, 7, 2);
		setBlock(world, i + 11, j + 31, k + 11, Blocks.log, 3);
		world.setBlockMetadataWithNotify(i + 11, j + 31, k + 11, 3, 2);
		setBlock(world, i + 11, j + 32, k + 11, Blocks.leaves, 15);
		world.setBlockMetadataWithNotify(i + 11, j + 32, k + 11, 15, 2);
		setBlock(world, i + 11, j + 32, k + 12, Blocks.leaves, 15);
		world.setBlockMetadataWithNotify(i + 11, j + 32, k + 12, 15, 2);
		setBlock(world, i + 11, j + 32, k + 13, Blocks.leaves, 15);
		world.setBlockMetadataWithNotify(i + 11, j + 32, k + 13, 15, 2);
		setBlock(world, i + 11, j + 33, k + 0, Blocks.planks, 5);
		world.setBlockMetadataWithNotify(i + 11, j + 33, k + 0, 5, 2);
		setBlock(world, i + 11, j + 33, k + 1, Blocks.planks, 5);
		world.setBlockMetadataWithNotify(i + 11, j + 33, k + 1, 5, 2);
		setBlock(world, i + 11, j + 33, k + 2, Blocks.planks, 5);
		world.setBlockMetadataWithNotify(i + 11, j + 33, k + 2, 5, 2);
		setBlock(world, i + 11, j + 33, k + 3, Blocks.planks, 5);
		world.setBlockMetadataWithNotify(i + 11, j + 33, k + 3, 5, 2);
		setBlock(world, i + 11, j + 33, k + 4, Blocks.planks, 5);
		world.setBlockMetadataWithNotify(i + 11, j + 33, k + 4, 5, 2);
		setBlock(world, i + 11, j + 33, k + 5, Blocks.planks, 5);
		world.setBlockMetadataWithNotify(i + 11, j + 33, k + 5, 5, 2);
		setBlock(world, i + 11, j + 33, k + 6, Blocks.planks, 5);
		world.setBlockMetadataWithNotify(i + 11, j + 33, k + 6, 5, 2);
		setBlock(world, i + 11, j + 33, k + 14, Blocks.log, 3);
		world.setBlockMetadataWithNotify(i + 11, j + 33, k + 14, 3, 2);
		setBlock(world, i + 11, j + 34, k + 17, Blocks.log, 3);
		world.setBlockMetadataWithNotify(i + 11, j + 34, k + 17, 3, 2);
		setBlock(world, i + 11, j + 36, k + 1, Blocks.torch, 1);
		world.setBlockMetadataWithNotify(i + 11, j + 36, k + 1, 1, 2);
		setBlock(world, i + 11, j + 37, k + 0, Blocks.log, 1);
		world.setBlockMetadataWithNotify(i + 11, j + 37, k + 0, 1, 2);
		setBlock(world, i + 11, j + 37, k + 1, Blocks.log, 1);
		world.setBlockMetadataWithNotify(i + 11, j + 37, k + 1, 1, 2);
		setBlock(world, i + 11, j + 37, k + 2, Blocks.log, 1);
		world.setBlockMetadataWithNotify(i + 11, j + 37, k + 2, 1, 2);
		setBlock(world, i + 11, j + 38, k + 0, Blocks.log, 1);
		world.setBlockMetadataWithNotify(i + 11, j + 38, k + 0, 1, 2);
		setBlock(world, i + 11, j + 38, k + 1, Blocks.log, 1);
		world.setBlockMetadataWithNotify(i + 11, j + 38, k + 1, 1, 2);
		setBlock(world, i + 11, j + 38, k + 2, Blocks.leaves, 15);
		world.setBlockMetadataWithNotify(i + 11, j + 38, k + 2, 15, 2);
		setBlock(world, i + 11, j + 39, k + 0, Blocks.log, 1);
		world.setBlockMetadataWithNotify(i + 11, j + 39, k + 0, 1, 2);
		setBlock(world, i + 11, j + 39, k + 1, Blocks.log, 1);
		world.setBlockMetadataWithNotify(i + 11, j + 39, k + 1, 1, 2);
		setBlock(world, i + 11, j + 39, k + 2, Blocks.leaves, 15);
		world.setBlockMetadataWithNotify(i + 11, j + 39, k + 2, 15, 2);
		setBlock(world, i + 11, j + 40, k + 0, Blocks.log, 1);
		world.setBlockMetadataWithNotify(i + 11, j + 40, k + 0, 1, 2);
		setBlock(world, i + 11, j + 40, k + 2, Blocks.leaves, 15);
		world.setBlockMetadataWithNotify(i + 11, j + 40, k + 2, 15, 2);
		setBlock(world, i + 11, j + 40, k + 3, Blocks.leaves, 15);
		world.setBlockMetadataWithNotify(i + 11, j + 40, k + 3, 15, 2);
		setBlock(world, i + 11, j + 40, k + 4, Blocks.leaves, 15);
		world.setBlockMetadataWithNotify(i + 11, j + 40, k + 4, 15, 2);
		setBlock(world, i + 11, j + 41, k + 0, Blocks.leaves, 15);
		world.setBlockMetadataWithNotify(i + 11, j + 41, k + 0, 15, 2);
		setBlock(world, i + 11, j + 41, k + 3, Blocks.leaves, 15);
		world.setBlockMetadataWithNotify(i + 11, j + 41, k + 3, 15, 2);
		setBlock(world, i + 11, j + 43, k + 8, Blocks.leaves, 7);
		world.setBlockMetadataWithNotify(i + 11, j + 43, k + 8, 7, 2);
		setBlock(world, i + 11, j + 43, k + 9, Blocks.leaves, 7);
		world.setBlockMetadataWithNotify(i + 11, j + 43, k + 9, 7, 2);
		setBlock(world, i + 11, j + 43, k + 10, Blocks.leaves, 7);
		world.setBlockMetadataWithNotify(i + 11, j + 43, k + 10, 7, 2);
		setBlock(world, i + 11, j + 44, k + 9, Blocks.leaves, 7);
		world.setBlockMetadataWithNotify(i + 11, j + 44, k + 9, 7, 2);
		setBlock(world, i + 11, j + 46, k + 4, Blocks.leaves, 7);
		world.setBlockMetadataWithNotify(i + 11, j + 46, k + 4, 7, 2);
		setBlock(world, i + 11, j + 46, k + 5, Blocks.leaves, 7);
		world.setBlockMetadataWithNotify(i + 11, j + 46, k + 5, 7, 2);
		setBlock(world, i + 11, j + 46, k + 6, Blocks.leaves, 7);
		world.setBlockMetadataWithNotify(i + 11, j + 46, k + 6, 7, 2);
		setBlock(world, i + 11, j + 46, k + 7, Blocks.leaves, 7);
		world.setBlockMetadataWithNotify(i + 11, j + 46, k + 7, 7, 2);
		setBlock(world, i + 11, j + 46, k + 8, Blocks.leaves, 7);
		world.setBlockMetadataWithNotify(i + 11, j + 46, k + 8, 7, 2);
		setBlock(world, i + 11, j + 47, k + 5, Blocks.leaves, 7);
		world.setBlockMetadataWithNotify(i + 11, j + 47, k + 5, 7, 2);
		setBlock(world, i + 11, j + 47, k + 6, Blocks.leaves, 7);
		world.setBlockMetadataWithNotify(i + 11, j + 47, k + 6, 7, 2);
		setBlock(world, i + 11, j + 47, k + 7, Blocks.leaves, 7);
		world.setBlockMetadataWithNotify(i + 11, j + 47, k + 7, 7, 2);
		setBlock(world, i + 11, j + 48, k + 6, Blocks.leaves, 7);
		world.setBlockMetadataWithNotify(i + 11, j + 48, k + 6, 7, 2);
		setBlock(world, i + 12, j + 21, k + 9, Blocks.log, 3);
		world.setBlockMetadataWithNotify(i + 12, j + 21, k + 9, 3, 2);
		setBlock(world, i + 12, j + 22, k + 4, Blocks.log, 3);
		world.setBlockMetadataWithNotify(i + 12, j + 22, k + 4, 3, 2);
		setBlock(world, i + 12, j + 22, k + 8, Blocks.log, 3);
		world.setBlockMetadataWithNotify(i + 12, j + 22, k + 8, 3, 2);
		setBlock(world, i + 12, j + 23, k + 3, Blocks.log, 3);
		world.setBlockMetadataWithNotify(i + 12, j + 23, k + 3, 3, 2);
		setBlock(world, i + 12, j + 23, k + 4, Blocks.log, 3);
		world.setBlockMetadataWithNotify(i + 12, j + 23, k + 4, 3, 2);
		setBlock(world, i + 12, j + 23, k + 5, Blocks.log, 3);
		world.setBlockMetadataWithNotify(i + 12, j + 23, k + 5, 3, 2);
		setBlock(world, i + 12, j + 24, k + 4, Blocks.log, 3);
		world.setBlockMetadataWithNotify(i + 12, j + 24, k + 4, 3, 2);
		setBlock(world, i + 12, j + 25, k + 6, Blocks.leaves, 7);
		world.setBlockMetadataWithNotify(i + 12, j + 25, k + 6, 7, 2);
		setBlock(world, i + 12, j + 25, k + 7, Blocks.leaves, 7);
		world.setBlockMetadataWithNotify(i + 12, j + 25, k + 7, 7, 2);
		setBlock(world, i + 12, j + 25, k + 8, Blocks.leaves, 7);
		world.setBlockMetadataWithNotify(i + 12, j + 25, k + 8, 7, 2);
		setBlock(world, i + 12, j + 25, k + 9, Blocks.leaves, 7);
		world.setBlockMetadataWithNotify(i + 12, j + 25, k + 9, 7, 2);
		setBlock(world, i + 12, j + 25, k + 10, Blocks.leaves, 7);
		world.setBlockMetadataWithNotify(i + 12, j + 25, k + 10, 7, 2);
		setBlock(world, i + 12, j + 25, k + 17, Blocks.leaves, 7);
		world.setBlockMetadataWithNotify(i + 12, j + 25, k + 17, 7, 2);
		setBlock(world, i + 12, j + 25, k + 18, Blocks.leaves, 7);
		world.setBlockMetadataWithNotify(i + 12, j + 25, k + 18, 7, 2);
		setBlock(world, i + 12, j + 25, k + 19, Blocks.leaves, 7);
		world.setBlockMetadataWithNotify(i + 12, j + 25, k + 19, 7, 2);
		setBlock(world, i + 12, j + 25, k + 20, Blocks.leaves, 7);
		world.setBlockMetadataWithNotify(i + 12, j + 25, k + 20, 7, 2);
		setBlock(world, i + 12, j + 25, k + 21, Blocks.leaves, 7);
		world.setBlockMetadataWithNotify(i + 12, j + 25, k + 21, 7, 2);
		setBlock(world, i + 12, j + 26, k + 7, Blocks.log, 3);
		world.setBlockMetadataWithNotify(i + 12, j + 26, k + 7, 3, 2);
		setBlock(world, i + 12, j + 26, k + 8, Blocks.leaves, 7);
		world.setBlockMetadataWithNotify(i + 12, j + 26, k + 8, 7, 2);
		setBlock(world, i + 12, j + 26, k + 9, Blocks.leaves, 7);
		world.setBlockMetadataWithNotify(i + 12, j + 26, k + 9, 7, 2);
		setBlock(world, i + 12, j + 26, k + 17, Blocks.leaves, 7);
		world.setBlockMetadataWithNotify(i + 12, j + 26, k + 17, 7, 2);
		setBlock(world, i + 12, j + 26, k + 18, Blocks.leaves, 7);
		world.setBlockMetadataWithNotify(i + 12, j + 26, k + 18, 7, 2);
		setBlock(world, i + 12, j + 26, k + 19, Blocks.leaves, 7);
		world.setBlockMetadataWithNotify(i + 12, j + 26, k + 19, 7, 2);
		setBlock(world, i + 12, j + 26, k + 20, Blocks.leaves, 7);
		world.setBlockMetadataWithNotify(i + 12, j + 26, k + 20, 7, 2);
		setBlock(world, i + 12, j + 26, k + 21, Blocks.leaves, 7);
		world.setBlockMetadataWithNotify(i + 12, j + 26, k + 21, 7, 2);
		setBlock(world, i + 12, j + 27, k + 6, Blocks.leaves, 7);
		world.setBlockMetadataWithNotify(i + 12, j + 27, k + 6, 7, 2);
		setBlock(world, i + 12, j + 27, k + 7, Blocks.leaves, 7);
		world.setBlockMetadataWithNotify(i + 12, j + 27, k + 7, 7, 2);
		setBlock(world, i + 12, j + 27, k + 8, Blocks.leaves, 7);
		world.setBlockMetadataWithNotify(i + 12, j + 27, k + 8, 7, 2);
		setBlock(world, i + 12, j + 27, k + 18, Blocks.leaves, 7);
		world.setBlockMetadataWithNotify(i + 12, j + 27, k + 18, 7, 2);
		setBlock(world, i + 12, j + 27, k + 19, Blocks.leaves, 7);
		world.setBlockMetadataWithNotify(i + 12, j + 27, k + 19, 7, 2);
		setBlock(world, i + 12, j + 27, k + 20, Blocks.leaves, 7);
		world.setBlockMetadataWithNotify(i + 12, j + 27, k + 20, 7, 2);
		setBlock(world, i + 12, j + 28, k + 7, Blocks.leaves, 7);
		world.setBlockMetadataWithNotify(i + 12, j + 28, k + 7, 7, 2);
		setBlock(world, i + 12, j + 28, k + 14, Blocks.log, 3);
		world.setBlockMetadataWithNotify(i + 12, j + 28, k + 14, 3, 2);
		setBlock(world, i + 12, j + 28, k + 19, Blocks.leaves, 7);
		world.setBlockMetadataWithNotify(i + 12, j + 28, k + 19, 7, 2);
		setBlock(world, i + 12, j + 31, k + 11, Blocks.log, 3);
		world.setBlockMetadataWithNotify(i + 12, j + 31, k + 11, 3, 2);
		setBlock(world, i + 12, j + 32, k + 10, Blocks.leaves, 15);
		world.setBlockMetadataWithNotify(i + 12, j + 32, k + 10, 15, 2);
		setBlock(world, i + 12, j + 32, k + 11, Blocks.leaves, 15);
		world.setBlockMetadataWithNotify(i + 12, j + 32, k + 11, 15, 2);
		setBlock(world, i + 12, j + 32, k + 12, Blocks.leaves, 15);
		world.setBlockMetadataWithNotify(i + 12, j + 32, k + 12, 15, 2);
		setBlock(world, i + 12, j + 33, k + 0, Blocks.planks, 5);
		world.setBlockMetadataWithNotify(i + 12, j + 33, k + 0, 5, 2);
		setBlock(world, i + 12, j + 33, k + 1, Blocks.planks, 5);
		world.setBlockMetadataWithNotify(i + 12, j + 33, k + 1, 5, 2);
		setBlock(world, i + 12, j + 33, k + 2, Blocks.planks, 5);
		world.setBlockMetadataWithNotify(i + 12, j + 33, k + 2, 5, 2);
		setBlock(world, i + 12, j + 33, k + 3, Blocks.planks, 5);
		world.setBlockMetadataWithNotify(i + 12, j + 33, k + 3, 5, 2);
		setBlock(world, i + 12, j + 33, k + 4, Blocks.planks, 5);
		world.setBlockMetadataWithNotify(i + 12, j + 33, k + 4, 5, 2);
		setBlock(world, i + 12, j + 33, k + 5, Blocks.planks, 5);
		world.setBlockMetadataWithNotify(i + 12, j + 33, k + 5, 5, 2);
		setBlock(world, i + 12, j + 33, k + 11, Blocks.leaves, 15);
		world.setBlockMetadataWithNotify(i + 12, j + 33, k + 11, 15, 2);
		setBlock(world, i + 12, j + 33, k + 14, Blocks.log, 3);
		world.setBlockMetadataWithNotify(i + 12, j + 33, k + 14, 3, 2);
		setBlock(world, i + 12, j + 34, k + 16, Blocks.log, 3);
		world.setBlockMetadataWithNotify(i + 12, j + 34, k + 16, 3, 2);
		setBlock(world, i + 12, j + 34, k + 17, Blocks.leaves, 15);
		world.setBlockMetadataWithNotify(i + 12, j + 34, k + 17, 15, 2);
		setBlock(world, i + 12, j + 34, k + 18, Blocks.leaves, 15);
		world.setBlockMetadataWithNotify(i + 12, j + 34, k + 18, 15, 2);
		setBlock(world, i + 12, j + 34, k + 19, Blocks.leaves, 15);
		world.setBlockMetadataWithNotify(i + 12, j + 34, k + 19, 15, 2);
		setBlock(world, i + 12, j + 35, k + 18, Blocks.leaves, 15);
		world.setBlockMetadataWithNotify(i + 12, j + 35, k + 18, 15, 2);
		setBlock(world, i + 12, j + 37, k + 0, Blocks.log, 1);
		world.setBlockMetadataWithNotify(i + 12, j + 37, k + 0, 1, 2);
		setBlock(world, i + 12, j + 37, k + 1, Blocks.log, 1);
		world.setBlockMetadataWithNotify(i + 12, j + 37, k + 1, 1, 2);
		setBlock(world, i + 12, j + 37, k + 2, Blocks.log, 1);
		world.setBlockMetadataWithNotify(i + 12, j + 37, k + 2, 1, 2);
		setBlock(world, i + 12, j + 38, k + 0, Blocks.log, 1);
		world.setBlockMetadataWithNotify(i + 12, j + 38, k + 0, 1, 2);
		setBlock(world, i + 12, j + 38, k + 1, Blocks.log, 1);
		world.setBlockMetadataWithNotify(i + 12, j + 38, k + 1, 1, 2);
		setBlock(world, i + 12, j + 38, k + 2, Blocks.leaves, 15);
		world.setBlockMetadataWithNotify(i + 12, j + 38, k + 2, 15, 2);
		setBlock(world, i + 12, j + 39, k + 0, Blocks.log, 1);
		world.setBlockMetadataWithNotify(i + 12, j + 39, k + 0, 1, 2);
		setBlock(world, i + 12, j + 39, k + 1, Blocks.log, 1);
		world.setBlockMetadataWithNotify(i + 12, j + 39, k + 1, 1, 2);
		setBlock(world, i + 12, j + 40, k + 0, Blocks.log, 1);
		world.setBlockMetadataWithNotify(i + 12, j + 40, k + 0, 1, 2);
		setBlock(world, i + 12, j + 40, k + 1, Blocks.leaves, 15);
		world.setBlockMetadataWithNotify(i + 12, j + 40, k + 1, 15, 2);
		setBlock(world, i + 12, j + 40, k + 2, Blocks.leaves, 15);
		world.setBlockMetadataWithNotify(i + 12, j + 40, k + 2, 15, 2);
		setBlock(world, i + 12, j + 40, k + 3, Blocks.leaves, 15);
		world.setBlockMetadataWithNotify(i + 12, j + 40, k + 3, 15, 2);
		setBlock(world, i + 12, j + 40, k + 4, Blocks.leaves, 15);
		world.setBlockMetadataWithNotify(i + 12, j + 40, k + 4, 15, 2);
		setBlock(world, i + 12, j + 40, k + 5, Blocks.leaves, 15);
		world.setBlockMetadataWithNotify(i + 12, j + 40, k + 5, 15, 2);
		setBlock(world, i + 12, j + 41, k + 0, Blocks.leaves, 15);
		world.setBlockMetadataWithNotify(i + 12, j + 41, k + 0, 15, 2);
		setBlock(world, i + 12, j + 41, k + 2, Blocks.leaves, 15);
		world.setBlockMetadataWithNotify(i + 12, j + 41, k + 2, 15, 2);
		setBlock(world, i + 12, j + 41, k + 3, Blocks.leaves, 15);
		world.setBlockMetadataWithNotify(i + 12, j + 41, k + 3, 15, 2);
		setBlock(world, i + 12, j + 41, k + 4, Blocks.leaves, 15);
		world.setBlockMetadataWithNotify(i + 12, j + 41, k + 4, 15, 2);
		setBlock(world, i + 12, j + 41, k + 11, Blocks.leaves, 15);
		world.setBlockMetadataWithNotify(i + 12, j + 41, k + 11, 15, 2);
		setBlock(world, i + 12, j + 41, k + 12, Blocks.leaves, 15);
		world.setBlockMetadataWithNotify(i + 12, j + 41, k + 12, 15, 2);
		setBlock(world, i + 12, j + 41, k + 13, Blocks.leaves, 15);
		world.setBlockMetadataWithNotify(i + 12, j + 41, k + 13, 15, 2);
		setBlock(world, i + 12, j + 42, k + 0, Blocks.leaves, 7);
		world.setBlockMetadataWithNotify(i + 12, j + 42, k + 0, 7, 2);
		setBlock(world, i + 12, j + 42, k + 3, Blocks.leaves, 7);
		world.setBlockMetadataWithNotify(i + 12, j + 42, k + 3, 7, 2);
		setBlock(world, i + 12, j + 42, k + 12, Blocks.leaves, 15);
		world.setBlockMetadataWithNotify(i + 12, j + 42, k + 12, 15, 2);
		setBlock(world, i + 12, j + 43, k + 7, Blocks.leaves, 7);
		world.setBlockMetadataWithNotify(i + 12, j + 43, k + 7, 7, 2);
		setBlock(world, i + 12, j + 43, k + 8, Blocks.leaves, 7);
		world.setBlockMetadataWithNotify(i + 12, j + 43, k + 8, 7, 2);
		setBlock(world, i + 12, j + 43, k + 9, Blocks.leaves, 7);
		world.setBlockMetadataWithNotify(i + 12, j + 43, k + 9, 7, 2);
		setBlock(world, i + 12, j + 43, k + 10, Blocks.leaves, 7);
		world.setBlockMetadataWithNotify(i + 12, j + 43, k + 10, 7, 2);
		setBlock(world, i + 12, j + 43, k + 11, Blocks.leaves, 7);
		world.setBlockMetadataWithNotify(i + 12, j + 43, k + 11, 7, 2);
		setBlock(world, i + 12, j + 44, k + 8, Blocks.leaves, 7);
		world.setBlockMetadataWithNotify(i + 12, j + 44, k + 8, 7, 2);
		setBlock(world, i + 12, j + 44, k + 9, Blocks.leaves, 7);
		world.setBlockMetadataWithNotify(i + 12, j + 44, k + 9, 7, 2);
		setBlock(world, i + 12, j + 44, k + 10, Blocks.leaves, 7);
		world.setBlockMetadataWithNotify(i + 12, j + 44, k + 10, 7, 2);
		setBlock(world, i + 12, j + 45, k + 9, Blocks.leaves, 7);
		world.setBlockMetadataWithNotify(i + 12, j + 45, k + 9, 7, 2);
		setBlock(world, i + 12, j + 46, k + 4, Blocks.leaves, 7);
		world.setBlockMetadataWithNotify(i + 12, j + 46, k + 4, 7, 2);
		setBlock(world, i + 12, j + 46, k + 5, Blocks.leaves, 7);
		world.setBlockMetadataWithNotify(i + 12, j + 46, k + 5, 7, 2);
		setBlock(world, i + 12, j + 46, k + 6, Blocks.log, 3);
		world.setBlockMetadataWithNotify(i + 12, j + 46, k + 6, 3, 2);
		setBlock(world, i + 12, j + 46, k + 7, Blocks.leaves, 7);
		world.setBlockMetadataWithNotify(i + 12, j + 46, k + 7, 7, 2);
		setBlock(world, i + 12, j + 46, k + 8, Blocks.leaves, 7);
		world.setBlockMetadataWithNotify(i + 12, j + 46, k + 8, 7, 2);
		setBlock(world, i + 12, j + 47, k + 4, Blocks.leaves, 7);
		world.setBlockMetadataWithNotify(i + 12, j + 47, k + 4, 7, 2);
		setBlock(world, i + 12, j + 47, k + 5, Blocks.leaves, 7);
		world.setBlockMetadataWithNotify(i + 12, j + 47, k + 5, 7, 2);
		setBlock(world, i + 12, j + 47, k + 6, Blocks.leaves, 7);
		world.setBlockMetadataWithNotify(i + 12, j + 47, k + 6, 7, 2);
		setBlock(world, i + 12, j + 47, k + 7, Blocks.leaves, 7);
		world.setBlockMetadataWithNotify(i + 12, j + 47, k + 7, 7, 2);
		setBlock(world, i + 12, j + 47, k + 8, Blocks.leaves, 7);
		world.setBlockMetadataWithNotify(i + 12, j + 47, k + 8, 7, 2);
		setBlock(world, i + 12, j + 48, k + 5, Blocks.leaves, 7);
		world.setBlockMetadataWithNotify(i + 12, j + 48, k + 5, 7, 2);
		setBlock(world, i + 12, j + 48, k + 6, Blocks.leaves, 7);
		world.setBlockMetadataWithNotify(i + 12, j + 48, k + 6, 7, 2);
		setBlock(world, i + 12, j + 48, k + 7, Blocks.leaves, 7);
		world.setBlockMetadataWithNotify(i + 12, j + 48, k + 7, 7, 2);
		setBlock(world, i + 12, j + 49, k + 6, Blocks.leaves, 7);
		world.setBlockMetadataWithNotify(i + 12, j + 49, k + 6, 7, 2);
		setBlock(world, i + 13, j + 21, k + 9, Blocks.log, 3);
		world.setBlockMetadataWithNotify(i + 13, j + 21, k + 9, 3, 2);
		setBlock(world, i + 13, j + 22, k + 4, Blocks.log, 3);
		world.setBlockMetadataWithNotify(i + 13, j + 22, k + 4, 3, 2);
		setBlock(world, i + 13, j + 22, k + 8, Blocks.log, 3);
		world.setBlockMetadataWithNotify(i + 13, j + 22, k + 8, 3, 2);
		setBlock(world, i + 13, j + 23, k + 3, Blocks.log, 3);
		world.setBlockMetadataWithNotify(i + 13, j + 23, k + 3, 3, 2);
		setBlock(world, i + 13, j + 23, k + 4, Blocks.log, 3);
		world.setBlockMetadataWithNotify(i + 13, j + 23, k + 4, 3, 2);
		setBlock(world, i + 13, j + 23, k + 5, Blocks.log, 3);
		world.setBlockMetadataWithNotify(i + 13, j + 23, k + 5, 3, 2);
		setBlock(world, i + 13, j + 24, k + 4, Blocks.log, 3);
		world.setBlockMetadataWithNotify(i + 13, j + 24, k + 4, 3, 2);
		setBlock(world, i + 13, j + 25, k + 6, Blocks.leaves, 7);
		world.setBlockMetadataWithNotify(i + 13, j + 25, k + 6, 7, 2);
		setBlock(world, i + 13, j + 25, k + 7, Blocks.leaves, 7);
		world.setBlockMetadataWithNotify(i + 13, j + 25, k + 7, 7, 2);
		setBlock(world, i + 13, j + 25, k + 8, Blocks.log, 3);
		world.setBlockMetadataWithNotify(i + 13, j + 25, k + 8, 3, 2);
		setBlock(world, i + 13, j + 25, k + 9, Blocks.leaves, 7);
		world.setBlockMetadataWithNotify(i + 13, j + 25, k + 9, 7, 2);
		setBlock(world, i + 13, j + 25, k + 10, Blocks.leaves, 7);
		world.setBlockMetadataWithNotify(i + 13, j + 25, k + 10, 7, 2);
		setBlock(world, i + 13, j + 25, k + 17, Blocks.leaves, 7);
		world.setBlockMetadataWithNotify(i + 13, j + 25, k + 17, 7, 2);
		setBlock(world, i + 13, j + 25, k + 18, Blocks.log, 3);
		world.setBlockMetadataWithNotify(i + 13, j + 25, k + 18, 3, 2);
		setBlock(world, i + 13, j + 25, k + 19, Blocks.log, 3);
		world.setBlockMetadataWithNotify(i + 13, j + 25, k + 19, 3, 2);
		setBlock(world, i + 13, j + 25, k + 20, Blocks.leaves, 7);
		world.setBlockMetadataWithNotify(i + 13, j + 25, k + 20, 7, 2);
		setBlock(world, i + 13, j + 25, k + 21, Blocks.leaves, 7);
		world.setBlockMetadataWithNotify(i + 13, j + 25, k + 21, 7, 2);
		setBlock(world, i + 13, j + 26, k + 6, Blocks.leaves, 7);
		world.setBlockMetadataWithNotify(i + 13, j + 26, k + 6, 7, 2);
		setBlock(world, i + 13, j + 26, k + 7, Blocks.log, 3);
		world.setBlockMetadataWithNotify(i + 13, j + 26, k + 7, 3, 2);
		setBlock(world, i + 13, j + 26, k + 8, Blocks.leaves, 7);
		world.setBlockMetadataWithNotify(i + 13, j + 26, k + 8, 7, 2);
		setBlock(world, i + 13, j + 26, k + 9, Blocks.leaves, 7);
		world.setBlockMetadataWithNotify(i + 13, j + 26, k + 9, 7, 2);
		setBlock(world, i + 13, j + 26, k + 10, Blocks.leaves, 7);
		world.setBlockMetadataWithNotify(i + 13, j + 26, k + 10, 7, 2);
		setBlock(world, i + 13, j + 26, k + 17, Blocks.leaves, 7);
		world.setBlockMetadataWithNotify(i + 13, j + 26, k + 17, 7, 2);
		setBlock(world, i + 13, j + 26, k + 18, Blocks.leaves, 7);
		world.setBlockMetadataWithNotify(i + 13, j + 26, k + 18, 7, 2);
		setBlock(world, i + 13, j + 26, k + 19, Blocks.log, 3);
		world.setBlockMetadataWithNotify(i + 13, j + 26, k + 19, 3, 2);
		setBlock(world, i + 13, j + 26, k + 20, Blocks.leaves, 7);
		world.setBlockMetadataWithNotify(i + 13, j + 26, k + 20, 7, 2);
		setBlock(world, i + 13, j + 26, k + 21, Blocks.leaves, 7);
		world.setBlockMetadataWithNotify(i + 13, j + 26, k + 21, 7, 2);
		setBlock(world, i + 13, j + 27, k + 7, Blocks.leaves, 7);
		world.setBlockMetadataWithNotify(i + 13, j + 27, k + 7, 7, 2);
		setBlock(world, i + 13, j + 27, k + 8, Blocks.leaves, 7);
		world.setBlockMetadataWithNotify(i + 13, j + 27, k + 8, 7, 2);
		setBlock(world, i + 13, j + 27, k + 9, Blocks.leaves, 7);
		world.setBlockMetadataWithNotify(i + 13, j + 27, k + 9, 7, 2);
		setBlock(world, i + 13, j + 27, k + 17, Blocks.leaves, 7);
		world.setBlockMetadataWithNotify(i + 13, j + 27, k + 17, 7, 2);
		setBlock(world, i + 13, j + 27, k + 18, Blocks.leaves, 7);
		world.setBlockMetadataWithNotify(i + 13, j + 27, k + 18, 7, 2);
		setBlock(world, i + 13, j + 27, k + 19, Blocks.leaves, 7);
		world.setBlockMetadataWithNotify(i + 13, j + 27, k + 19, 7, 2);
		setBlock(world, i + 13, j + 27, k + 20, Blocks.leaves, 7);
		world.setBlockMetadataWithNotify(i + 13, j + 27, k + 20, 7, 2);
		setBlock(world, i + 13, j + 27, k + 21, Blocks.leaves, 7);
		world.setBlockMetadataWithNotify(i + 13, j + 27, k + 21, 7, 2);
		setBlock(world, i + 13, j + 28, k + 8, Blocks.leaves, 7);
		world.setBlockMetadataWithNotify(i + 13, j + 28, k + 8, 7, 2);
		setBlock(world, i + 13, j + 28, k + 14, Blocks.log, 3);
		world.setBlockMetadataWithNotify(i + 13, j + 28, k + 14, 3, 2);
		setBlock(world, i + 13, j + 28, k + 18, Blocks.leaves, 7);
		world.setBlockMetadataWithNotify(i + 13, j + 28, k + 18, 7, 2);
		setBlock(world, i + 13, j + 28, k + 19, Blocks.leaves, 7);
		world.setBlockMetadataWithNotify(i + 13, j + 28, k + 19, 7, 2);
		setBlock(world, i + 13, j + 28, k + 20, Blocks.leaves, 7);
		world.setBlockMetadataWithNotify(i + 13, j + 28, k + 20, 7, 2);
		setBlock(world, i + 13, j + 29, k + 19, Blocks.leaves, 7);
		world.setBlockMetadataWithNotify(i + 13, j + 29, k + 19, 7, 2);
		setBlock(world, i + 13, j + 31, k + 11, Blocks.log, 3);
		world.setBlockMetadataWithNotify(i + 13, j + 31, k + 11, 3, 2);
		setBlock(world, i + 13, j + 33, k + 0, Blocks.planks, 5);
		world.setBlockMetadataWithNotify(i + 13, j + 33, k + 0, 5, 2);
		setBlock(world, i + 13, j + 33, k + 1, Blocks.planks, 5);
		world.setBlockMetadataWithNotify(i + 13, j + 33, k + 1, 5, 2);
		setBlock(world, i + 13, j + 33, k + 2, Blocks.planks, 5);
		world.setBlockMetadataWithNotify(i + 13, j + 33, k + 2, 5, 2);
		setBlock(world, i + 13, j + 33, k + 3, Blocks.planks, 5);
		world.setBlockMetadataWithNotify(i + 13, j + 33, k + 3, 5, 2);
		setBlock(world, i + 13, j + 33, k + 4, Blocks.planks, 5);
		world.setBlockMetadataWithNotify(i + 13, j + 33, k + 4, 5, 2);
		setBlock(world, i + 13, j + 33, k + 13, Blocks.log, 3);
		world.setBlockMetadataWithNotify(i + 13, j + 33, k + 13, 3, 2);
		setBlock(world, i + 13, j + 34, k + 14, Blocks.leaves, 15);
		world.setBlockMetadataWithNotify(i + 13, j + 34, k + 14, 15, 2);
		setBlock(world, i + 13, j + 34, k + 15, Blocks.leaves, 15);
		world.setBlockMetadataWithNotify(i + 13, j + 34, k + 15, 15, 2);
		setBlock(world, i + 13, j + 34, k + 16, Blocks.log, 3);
		world.setBlockMetadataWithNotify(i + 13, j + 34, k + 16, 3, 2);
		setBlock(world, i + 13, j + 34, k + 17, Blocks.leaves, 15);
		world.setBlockMetadataWithNotify(i + 13, j + 34, k + 17, 15, 2);
		setBlock(world, i + 13, j + 34, k + 18, Blocks.leaves, 15);
		world.setBlockMetadataWithNotify(i + 13, j + 34, k + 18, 15, 2);
		setBlock(world, i + 13, j + 34, k + 19, Blocks.leaves, 7);
		world.setBlockMetadataWithNotify(i + 13, j + 34, k + 19, 7, 2);
		setBlock(world, i + 13, j + 34, k + 20, Blocks.leaves, 7);
		world.setBlockMetadataWithNotify(i + 13, j + 34, k + 20, 7, 2);
		setBlock(world, i + 13, j + 35, k + 11, Blocks.log, 3);
		world.setBlockMetadataWithNotify(i + 13, j + 35, k + 11, 3, 2);
		setBlock(world, i + 13, j + 35, k + 15, Blocks.leaves, 15);
		world.setBlockMetadataWithNotify(i + 13, j + 35, k + 15, 15, 2);
		setBlock(world, i + 13, j + 35, k + 17, Blocks.leaves, 15);
		world.setBlockMetadataWithNotify(i + 13, j + 35, k + 17, 15, 2);
		setBlock(world, i + 13, j + 35, k + 18, Blocks.leaves, 15);
		world.setBlockMetadataWithNotify(i + 13, j + 35, k + 18, 15, 2);
		setBlock(world, i + 13, j + 35, k + 19, Blocks.leaves, 7);
		world.setBlockMetadataWithNotify(i + 13, j + 35, k + 19, 7, 2);
		setBlock(world, i + 13, j + 36, k + 1, Blocks.torch, 2);
		world.setBlockMetadataWithNotify(i + 13, j + 36, k + 1, 2, 2);
		setBlock(world, i + 13, j + 36, k + 18, Blocks.leaves, 15);
		world.setBlockMetadataWithNotify(i + 13, j + 36, k + 18, 15, 2);
		setBlock(world, i + 13, j + 37, k + 0, Blocks.log, 1);
		world.setBlockMetadataWithNotify(i + 13, j + 37, k + 0, 1, 2);
		setBlock(world, i + 13, j + 37, k + 1, Blocks.log, 1);
		world.setBlockMetadataWithNotify(i + 13, j + 37, k + 1, 1, 2);
		setBlock(world, i + 13, j + 37, k + 2, Blocks.log, 1);
		world.setBlockMetadataWithNotify(i + 13, j + 37, k + 2, 1, 2);
		setBlock(world, i + 13, j + 37, k + 13, Blocks.log, 3);
		world.setBlockMetadataWithNotify(i + 13, j + 37, k + 13, 3, 2);
		setBlock(world, i + 13, j + 38, k + 0, Blocks.log, 1);
		world.setBlockMetadataWithNotify(i + 13, j + 38, k + 0, 1, 2);
		setBlock(world, i + 13, j + 38, k + 1, Blocks.log, 1);
		world.setBlockMetadataWithNotify(i + 13, j + 38, k + 1, 1, 2);
		setBlock(world, i + 13, j + 39, k + 0, Blocks.log, 1);
		world.setBlockMetadataWithNotify(i + 13, j + 39, k + 0, 1, 2);
		setBlock(world, i + 13, j + 39, k + 1, Blocks.log, 1);
		world.setBlockMetadataWithNotify(i + 13, j + 39, k + 1, 1, 2);
		setBlock(world, i + 13, j + 40, k + 0, Blocks.log, 1);
		world.setBlockMetadataWithNotify(i + 13, j + 40, k + 0, 1, 2);
		setBlock(world, i + 13, j + 40, k + 1, Blocks.leaves, 15);
		world.setBlockMetadataWithNotify(i + 13, j + 40, k + 1, 15, 2);
		setBlock(world, i + 13, j + 40, k + 2, Blocks.leaves, 15);
		world.setBlockMetadataWithNotify(i + 13, j + 40, k + 2, 15, 2);
		setBlock(world, i + 13, j + 40, k + 3, Blocks.log, 3);
		world.setBlockMetadataWithNotify(i + 13, j + 40, k + 3, 3, 2);
		setBlock(world, i + 13, j + 40, k + 4, Blocks.leaves, 15);
		world.setBlockMetadataWithNotify(i + 13, j + 40, k + 4, 15, 2);
		setBlock(world, i + 13, j + 40, k + 5, Blocks.leaves, 15);
		world.setBlockMetadataWithNotify(i + 13, j + 40, k + 5, 15, 2);
		setBlock(world, i + 13, j + 41, k + 0, Blocks.leaves, 15);
		world.setBlockMetadataWithNotify(i + 13, j + 41, k + 0, 15, 2);
		setBlock(world, i + 13, j + 41, k + 1, Blocks.leaves, 15);
		world.setBlockMetadataWithNotify(i + 13, j + 41, k + 1, 15, 2);
		setBlock(world, i + 13, j + 41, k + 2, Blocks.leaves, 15);
		world.setBlockMetadataWithNotify(i + 13, j + 41, k + 2, 15, 2);
		setBlock(world, i + 13, j + 41, k + 3, Blocks.leaves, 15);
		world.setBlockMetadataWithNotify(i + 13, j + 41, k + 3, 15, 2);
		setBlock(world, i + 13, j + 41, k + 4, Blocks.leaves, 15);
		world.setBlockMetadataWithNotify(i + 13, j + 41, k + 4, 15, 2);
		setBlock(world, i + 13, j + 41, k + 5, Blocks.leaves, 15);
		world.setBlockMetadataWithNotify(i + 13, j + 41, k + 5, 15, 2);
		setBlock(world, i + 13, j + 41, k + 10, Blocks.leaves, 15);
		world.setBlockMetadataWithNotify(i + 13, j + 41, k + 10, 15, 2);
		setBlock(world, i + 13, j + 41, k + 11, Blocks.leaves, 15);
		world.setBlockMetadataWithNotify(i + 13, j + 41, k + 11, 15, 2);
		setBlock(world, i + 13, j + 41, k + 12, Blocks.leaves, 15);
		world.setBlockMetadataWithNotify(i + 13, j + 41, k + 12, 15, 2);
		setBlock(world, i + 13, j + 41, k + 13, Blocks.leaves, 15);
		world.setBlockMetadataWithNotify(i + 13, j + 41, k + 13, 15, 2);
		setBlock(world, i + 13, j + 41, k + 14, Blocks.leaves, 15);
		world.setBlockMetadataWithNotify(i + 13, j + 41, k + 14, 15, 2);
		setBlock(world, i + 13, j + 42, k + 2, Blocks.leaves, 7);
		world.setBlockMetadataWithNotify(i + 13, j + 42, k + 2, 7, 2);
		setBlock(world, i + 13, j + 42, k + 3, Blocks.leaves, 7);
		world.setBlockMetadataWithNotify(i + 13, j + 42, k + 3, 7, 2);
		setBlock(world, i + 13, j + 42, k + 4, Blocks.leaves, 7);
		world.setBlockMetadataWithNotify(i + 13, j + 42, k + 4, 7, 2);
		setBlock(world, i + 13, j + 42, k + 11, Blocks.leaves, 7);
		world.setBlockMetadataWithNotify(i + 13, j + 42, k + 11, 7, 2);
		setBlock(world, i + 13, j + 42, k + 12, Blocks.leaves, 7);
		world.setBlockMetadataWithNotify(i + 13, j + 42, k + 12, 7, 2);
		setBlock(world, i + 13, j + 42, k + 13, Blocks.leaves, 7);
		world.setBlockMetadataWithNotify(i + 13, j + 42, k + 13, 7, 2);
		setBlock(world, i + 13, j + 43, k + 3, Blocks.leaves, 7);
		world.setBlockMetadataWithNotify(i + 13, j + 43, k + 3, 7, 2);
		setBlock(world, i + 13, j + 43, k + 7, Blocks.leaves, 7);
		world.setBlockMetadataWithNotify(i + 13, j + 43, k + 7, 7, 2);
		setBlock(world, i + 13, j + 43, k + 8, Blocks.leaves, 7);
		world.setBlockMetadataWithNotify(i + 13, j + 43, k + 8, 7, 2);
		setBlock(world, i + 13, j + 43, k + 9, Blocks.log, 3);
		world.setBlockMetadataWithNotify(i + 13, j + 43, k + 9, 3, 2);
		setBlock(world, i + 13, j + 43, k + 10, Blocks.leaves, 7);
		world.setBlockMetadataWithNotify(i + 13, j + 43, k + 10, 7, 2);
		setBlock(world, i + 13, j + 43, k + 11, Blocks.leaves, 7);
		world.setBlockMetadataWithNotify(i + 13, j + 43, k + 11, 7, 2);
		setBlock(world, i + 13, j + 43, k + 12, Blocks.leaves, 7);
		world.setBlockMetadataWithNotify(i + 13, j + 43, k + 12, 7, 2);
		setBlock(world, i + 13, j + 44, k + 7, Blocks.leaves, 7);
		world.setBlockMetadataWithNotify(i + 13, j + 44, k + 7, 7, 2);
		setBlock(world, i + 13, j + 44, k + 8, Blocks.leaves, 7);
		world.setBlockMetadataWithNotify(i + 13, j + 44, k + 8, 7, 2);
		setBlock(world, i + 13, j + 44, k + 9, Blocks.leaves, 7);
		world.setBlockMetadataWithNotify(i + 13, j + 44, k + 9, 7, 2);
		setBlock(world, i + 13, j + 44, k + 10, Blocks.leaves, 7);
		world.setBlockMetadataWithNotify(i + 13, j + 44, k + 10, 7, 2);
		setBlock(world, i + 13, j + 44, k + 11, Blocks.leaves, 7);
		world.setBlockMetadataWithNotify(i + 13, j + 44, k + 11, 7, 2);
		setBlock(world, i + 13, j + 45, k + 7, Blocks.log, 3);
		world.setBlockMetadataWithNotify(i + 13, j + 45, k + 7, 3, 2);
		setBlock(world, i + 13, j + 45, k + 8, Blocks.leaves, 7);
		world.setBlockMetadataWithNotify(i + 13, j + 45, k + 8, 7, 2);
		setBlock(world, i + 13, j + 45, k + 9, Blocks.leaves, 7);
		world.setBlockMetadataWithNotify(i + 13, j + 45, k + 9, 7, 2);
		setBlock(world, i + 13, j + 45, k + 10, Blocks.leaves, 7);
		world.setBlockMetadataWithNotify(i + 13, j + 45, k + 10, 7, 2);
		setBlock(world, i + 13, j + 46, k + 4, Blocks.leaves, 7);
		world.setBlockMetadataWithNotify(i + 13, j + 46, k + 4, 7, 2);
		setBlock(world, i + 13, j + 46, k + 5, Blocks.leaves, 7);
		world.setBlockMetadataWithNotify(i + 13, j + 46, k + 5, 7, 2);
		setBlock(world, i + 13, j + 46, k + 6, Blocks.leaves, 7);
		world.setBlockMetadataWithNotify(i + 13, j + 46, k + 6, 7, 2);
		setBlock(world, i + 13, j + 46, k + 7, Blocks.leaves, 7);
		world.setBlockMetadataWithNotify(i + 13, j + 46, k + 7, 7, 2);
		setBlock(world, i + 13, j + 46, k + 8, Blocks.leaves, 7);
		world.setBlockMetadataWithNotify(i + 13, j + 46, k + 8, 7, 2);
		setBlock(world, i + 13, j + 46, k + 9, Blocks.leaves, 7);
		world.setBlockMetadataWithNotify(i + 13, j + 46, k + 9, 7, 2);
		setBlock(world, i + 13, j + 47, k + 5, Blocks.leaves, 7);
		world.setBlockMetadataWithNotify(i + 13, j + 47, k + 5, 7, 2);
		setBlock(world, i + 13, j + 47, k + 6, Blocks.leaves, 7);
		world.setBlockMetadataWithNotify(i + 13, j + 47, k + 6, 7, 2);
		setBlock(world, i + 13, j + 47, k + 7, Blocks.leaves, 7);
		world.setBlockMetadataWithNotify(i + 13, j + 47, k + 7, 7, 2);
		setBlock(world, i + 13, j + 48, k + 6, Blocks.leaves, 7);
		world.setBlockMetadataWithNotify(i + 13, j + 48, k + 6, 7, 2);
		setBlock(world, i + 14, j + 21, k + 5, Blocks.log, 3);
		world.setBlockMetadataWithNotify(i + 14, j + 21, k + 5, 3, 2);
		setBlock(world, i + 14, j + 21, k + 10, Blocks.log, 3);
		world.setBlockMetadataWithNotify(i + 14, j + 21, k + 10, 3, 2);
		setBlock(world, i + 14, j + 22, k + 0, Blocks.log, 3);
		world.setBlockMetadataWithNotify(i + 14, j + 22, k + 0, 3, 2);
		setBlock(world, i + 14, j + 22, k + 1, Blocks.log, 3);
		world.setBlockMetadataWithNotify(i + 14, j + 22, k + 1, 3, 2);
		setBlock(world, i + 14, j + 22, k + 4, Blocks.log, 3);
		world.setBlockMetadataWithNotify(i + 14, j + 22, k + 4, 3, 2);
		setBlock(world, i + 14, j + 22, k + 5, Blocks.log, 3);
		world.setBlockMetadataWithNotify(i + 14, j + 22, k + 5, 3, 2);
		setBlock(world, i + 14, j + 22, k + 6, Blocks.log, 3);
		world.setBlockMetadataWithNotify(i + 14, j + 22, k + 6, 3, 2);
		setBlock(world, i + 14, j + 22, k + 8, Blocks.log, 3);
		world.setBlockMetadataWithNotify(i + 14, j + 22, k + 8, 3, 2);
		setBlock(world, i + 14, j + 23, k + 5, Blocks.log, 3);
		world.setBlockMetadataWithNotify(i + 14, j + 23, k + 5, 3, 2);
		setBlock(world, i + 14, j + 24, k + 9, Blocks.log, 3);
		world.setBlockMetadataWithNotify(i + 14, j + 24, k + 9, 3, 2);
		setBlock(world, i + 14, j + 24, k + 19, Blocks.log, 3);
		world.setBlockMetadataWithNotify(i + 14, j + 24, k + 19, 3, 2);
		
		generate2(world, rand, i, j, k);
		return true;
		}

	
	public boolean generate2(World world, Random rand, int i, int j, int k)
	{
		setBlock(world, i + 14, j + 25, k + 6, Blocks.leaves, 7);
		world.setBlockMetadataWithNotify(i + 14, j + 25, k + 6, 7, 2);
		setBlock(world, i + 14, j + 25, k + 7, Blocks.log, 3);
		world.setBlockMetadataWithNotify(i + 14, j + 25, k + 7, 3, 2);
		setBlock(world, i + 14, j + 25, k + 8, Blocks.leaves, 7);
		world.setBlockMetadataWithNotify(i + 14, j + 25, k + 8, 7, 2);
		setBlock(world, i + 14, j + 25, k + 9, Blocks.leaves, 7);
		world.setBlockMetadataWithNotify(i + 14, j + 25, k + 9, 7, 2);
		setBlock(world, i + 14, j + 25, k + 10, Blocks.leaves, 7);
		world.setBlockMetadataWithNotify(i + 14, j + 25, k + 10, 7, 2);
		setBlock(world, i + 14, j + 25, k + 17, Blocks.log, 3);
		world.setBlockMetadataWithNotify(i + 14, j + 25, k + 17, 3, 2);
		setBlock(world, i + 14, j + 25, k + 18, Blocks.leaves, 7);
		world.setBlockMetadataWithNotify(i + 14, j + 25, k + 18, 7, 2);
		setBlock(world, i + 14, j + 25, k + 19, Blocks.leaves, 7);
		world.setBlockMetadataWithNotify(i + 14, j + 25, k + 19, 7, 2);
		setBlock(world, i + 14, j + 25, k + 20, Blocks.leaves, 7);
		world.setBlockMetadataWithNotify(i + 14, j + 25, k + 20, 7, 2);
		setBlock(world, i + 14, j + 25, k + 21, Blocks.leaves, 7);
		world.setBlockMetadataWithNotify(i + 14, j + 25, k + 21, 7, 2);
		setBlock(world, i + 14, j + 26, k + 6, Blocks.log, 3);
		world.setBlockMetadataWithNotify(i + 14, j + 26, k + 6, 3, 2);
		setBlock(world, i + 14, j + 26, k + 7, Blocks.log, 3);
		world.setBlockMetadataWithNotify(i + 14, j + 26, k + 7, 3, 2);
		setBlock(world, i + 14, j + 26, k + 8, Blocks.log, 3);
		world.setBlockMetadataWithNotify(i + 14, j + 26, k + 8, 3, 2);
		setBlock(world, i + 14, j + 26, k + 9, Blocks.leaves, 7);
		world.setBlockMetadataWithNotify(i + 14, j + 26, k + 9, 7, 2);
		setBlock(world, i + 14, j + 26, k + 17, Blocks.leaves, 7);
		world.setBlockMetadataWithNotify(i + 14, j + 26, k + 17, 7, 2);
		setBlock(world, i + 14, j + 26, k + 18, Blocks.leaves, 7);
		world.setBlockMetadataWithNotify(i + 14, j + 26, k + 18, 7, 2);
		setBlock(world, i + 14, j + 26, k + 19, Blocks.leaves, 7);
		world.setBlockMetadataWithNotify(i + 14, j + 26, k + 19, 7, 2);
		setBlock(world, i + 14, j + 26, k + 20, Blocks.leaves, 7);
		world.setBlockMetadataWithNotify(i + 14, j + 26, k + 20, 7, 2);
		setBlock(world, i + 14, j + 26, k + 21, Blocks.leaves, 7);
		world.setBlockMetadataWithNotify(i + 14, j + 26, k + 21, 7, 2);
		setBlock(world, i + 14, j + 27, k + 7, Blocks.log, 3);
		world.setBlockMetadataWithNotify(i + 14, j + 27, k + 7, 3, 2);
		setBlock(world, i + 14, j + 27, k + 8, Blocks.leaves, 7);
		world.setBlockMetadataWithNotify(i + 14, j + 27, k + 8, 7, 2);
		setBlock(world, i + 14, j + 27, k + 16, Blocks.leaves, 7);
		world.setBlockMetadataWithNotify(i + 14, j + 27, k + 16, 7, 2);
		setBlock(world, i + 14, j + 27, k + 17, Blocks.leaves, 7);
		world.setBlockMetadataWithNotify(i + 14, j + 27, k + 17, 7, 2);
		setBlock(world, i + 14, j + 27, k + 18, Blocks.leaves, 7);
		world.setBlockMetadataWithNotify(i + 14, j + 27, k + 18, 7, 2);
		setBlock(world, i + 14, j + 27, k + 19, Blocks.leaves, 7);
		world.setBlockMetadataWithNotify(i + 14, j + 27, k + 19, 7, 2);
		setBlock(world, i + 14, j + 27, k + 20, Blocks.leaves, 7);
		world.setBlockMetadataWithNotify(i + 14, j + 27, k + 20, 7, 2);
		setBlock(world, i + 14, j + 28, k + 13, Blocks.log, 3);
		world.setBlockMetadataWithNotify(i + 14, j + 28, k + 13, 3, 2);
		setBlock(world, i + 14, j + 28, k + 17, Blocks.leaves, 7);
		world.setBlockMetadataWithNotify(i + 14, j + 28, k + 17, 7, 2);
		setBlock(world, i + 14, j + 28, k + 18, Blocks.leaves, 7);
		world.setBlockMetadataWithNotify(i + 14, j + 28, k + 18, 7, 2);
		setBlock(world, i + 14, j + 28, k + 19, Blocks.leaves, 7);
		world.setBlockMetadataWithNotify(i + 14, j + 28, k + 19, 7, 2);
		setBlock(world, i + 14, j + 29, k + 18, Blocks.leaves, 7);
		world.setBlockMetadataWithNotify(i + 14, j + 29, k + 18, 7, 2);
		setBlock(world, i + 14, j + 31, k + 10, Blocks.log, 3);
		world.setBlockMetadataWithNotify(i + 14, j + 31, k + 10, 3, 2);
		setBlock(world, i + 14, j + 33, k + 0, Blocks.planks, 5);
		world.setBlockMetadataWithNotify(i + 14, j + 33, k + 0, 5, 2);
		setBlock(world, i + 14, j + 33, k + 1, Blocks.planks, 5);
		world.setBlockMetadataWithNotify(i + 14, j + 33, k + 1, 5, 2);
		setBlock(world, i + 14, j + 33, k + 2, Blocks.planks, 5);
		world.setBlockMetadataWithNotify(i + 14, j + 33, k + 2, 5, 2);
		setBlock(world, i + 14, j + 33, k + 3, Blocks.planks, 5);
		world.setBlockMetadataWithNotify(i + 14, j + 33, k + 3, 5, 2);
