package com.parzivail.pswm.world.gen.wookietree;


import cpw.mods.fml.common.IWorldGenerator;

import java.util.Random;

import net.minecraft.block.Block;

import net.minecraft.init.Blocks;

import net.minecraft.world.World;

import net.minecraft.world.chunk.IChunkProvider;

import net.minecraft.world.gen.feature.WorldGenerator;


public class WT_51 extends WorldGenerator implements IWorldGenerator

{
	protected Block[] getValidSpawnBlocks()
	
	{
		return new Block[0];
		}

	
	public boolean locationIsValidSpawn(World world, int i, int j, int k)
	
	{
		int distanceToAir = 0;
		Block check = world.getBlock(i, j, k);
		
		while (check != Blocks.air)
		{
			if (distanceToAir > 3) { return false;
			}
			
			distanceToAir++;
			check = world.getBlock(i, j + distanceToAir, k);
			}
		
		j += distanceToAir - 1;
		
		Block block = world.getBlock(i, j, k);
		Block blockAbove = world.getBlock(i, j + 1, k);
		Block blockBelow = world.getBlock(i, j - 1, k);
		
		for (Block x : getValidSpawnBlocks())
		{
			if (blockAbove != Blocks.air) { return false;
			}
			if (block == x) return true;
			if ((block == Blocks.snow) && (blockBelow == x)) { return true;
			}
			}
		
		return false;
		}

	
	
	
	public void generate(Random random, int chunkX, int chunkZ, World world, IChunkProvider chunkGenerator, IChunkProvider chunkProvider)
	{
	}

	
	
	public void setBlock(World world, int x, int y, int z, Block block, int metadata)
	
	{
		world.setBlock(x, y, z, block, metadata, 2);
		}

	
	public boolean generate(World world, Random rand, int i, int j, int k)
	
	{
		k -= 10;
		i -= 10;
		
		setBlock(world, i + 17, j + 21, k + 17, Blocks.leaves, 7);
		world.setBlockMetadataWithNotify(i + 17, j + 21, k + 17, 7, 2);
		setBlock(world, i + 17, j + 21, k + 18, Blocks.leaves, 7);
		world.setBlockMetadataWithNotify(i + 17, j + 21, k + 18, 7, 2);
		setBlock(world, i + 17, j + 21, k + 19, Blocks.leaves, 7);
		world.setBlockMetadataWithNotify(i + 17, j + 21, k + 19, 7, 2);
		setBlock(world, i + 17, j + 22, k + 18, Blocks.leaves, 7);
		world.setBlockMetadataWithNotify(i + 17, j + 22, k + 18, 7, 2);
		setBlock(world, i + 17, j + 23, k + 2, Blocks.leaves, 7);
		world.setBlockMetadataWithNotify(i + 17, j + 23, k + 2, 7, 2);
		setBlock(world, i + 17, j + 23, k + 3, Blocks.leaves, 7);
		world.setBlockMetadataWithNotify(i + 17, j + 23, k + 3, 7, 2);
		setBlock(world, i + 17, j + 23, k + 4, Blocks.leaves, 7);
		world.setBlockMetadataWithNotify(i + 17, j + 23, k + 4, 7, 2);
		setBlock(world, i + 17, j + 24, k + 3, Blocks.leaves, 7);
		world.setBlockMetadataWithNotify(i + 17, j + 24, k + 3, 7, 2);
		setBlock(world, i + 18, j + 21, k + 16, Blocks.leaves, 7);
		world.setBlockMetadataWithNotify(i + 18, j + 21, k + 16, 7, 2);
		setBlock(world, i + 18, j + 21, k + 17, Blocks.leaves, 7);
		world.setBlockMetadataWithNotify(i + 18, j + 21, k + 17, 7, 2);
		setBlock(world, i + 18, j + 21, k + 18, Blocks.leaves, 7);
		world.setBlockMetadataWithNotify(i + 18, j + 21, k + 18, 7, 2);
		setBlock(world, i + 18, j + 21, k + 19, Blocks.leaves, 7);
		world.setBlockMetadataWithNotify(i + 18, j + 21, k + 19, 7, 2);
		setBlock(world, i + 18, j + 21, k + 20, Blocks.leaves, 7);
		world.setBlockMetadataWithNotify(i + 18, j + 21, k + 20, 7, 2);
		setBlock(world, i + 18, j + 22, k + 17, Blocks.leaves, 7);
		world.setBlockMetadataWithNotify(i + 18, j + 22, k + 17, 7, 2);
		setBlock(world, i + 18, j + 22, k + 18, Blocks.leaves, 7);
		world.setBlockMetadataWithNotify(i + 18, j + 22, k + 18, 7, 2);
		setBlock(world, i + 18, j + 22, k + 19, Blocks.leaves, 7);
		world.setBlockMetadataWithNotify(i + 18, j + 22, k + 19, 7, 2);
		setBlock(world, i + 18, j + 23, k + 1, Blocks.leaves, 7);
		world.setBlockMetadataWithNotify(i + 18, j + 23, k + 1, 7, 2);
		setBlock(world, i + 18, j + 23, k + 2, Blocks.leaves, 7);
		world.setBlockMetadataWithNotify(i + 18, j + 23, k + 2, 7, 2);
		setBlock(world, i + 18, j + 23, k + 3, Blocks.leaves, 7);
		world.setBlockMetadataWithNotify(i + 18, j + 23, k + 3, 7, 2);
		setBlock(world, i + 18, j + 23, k + 4, Blocks.leaves, 7);
		world.setBlockMetadataWithNotify(i + 18, j + 23, k + 4, 7, 2);
		setBlock(world, i + 18, j + 23, k + 5, Blocks.leaves, 7);
		world.setBlockMetadataWithNotify(i + 18, j + 23, k + 5, 7, 2);
		setBlock(world, i + 18, j + 23, k + 18, Blocks.leaves, 7);
		world.setBlockMetadataWithNotify(i + 18, j + 23, k + 18, 7, 2);
		setBlock(world, i + 18, j + 24, k + 2, Blocks.leaves, 7);
		world.setBlockMetadataWithNotify(i + 18, j + 24, k + 2, 7, 2);
		setBlock(world, i + 18, j + 24, k + 3, Blocks.leaves, 7);
		world.setBlockMetadataWithNotify(i + 18, j + 24, k + 3, 7, 2);
		setBlock(world, i + 18, j + 24, k + 4, Blocks.leaves, 7);
		world.setBlockMetadataWithNotify(i + 18, j + 24, k + 4, 7, 2);
		setBlock(world, i + 18, j + 25, k + 3, Blocks.leaves, 7);
		world.setBlockMetadataWithNotify(i + 18, j + 25, k + 3, 7, 2);
		setBlock(world, i + 18, j + 30, k + 13, Blocks.leaves, 7);
		world.setBlockMetadataWithNotify(i + 18, j + 30, k + 13, 7, 2);
		setBlock(world, i + 18, j + 30, k + 14, Blocks.leaves, 7);
		world.setBlockMetadataWithNotify(i + 18, j + 30, k + 14, 7, 2);
		setBlock(world, i + 18, j + 30, k + 15, Blocks.leaves, 7);
		world.setBlockMetadataWithNotify(i + 18, j + 30, k + 15, 7, 2);
		setBlock(world, i + 18, j + 31, k + 14, Blocks.leaves, 7);
		world.setBlockMetadataWithNotify(i + 18, j + 31, k + 14, 7, 2);
		setBlock(world, i + 19, j + 21, k + 16, Blocks.leaves, 7);
		world.setBlockMetadataWithNotify(i + 19, j + 21, k + 16, 7, 2);
		setBlock(world, i + 19, j + 21, k + 17, Blocks.leaves, 7);
		world.setBlockMetadataWithNotify(i + 19, j + 21, k + 17, 7, 2);
		setBlock(world, i + 19, j + 21, k + 18, Blocks.log, 3);
		world.setBlockMetadataWithNotify(i + 19, j + 21, k + 18, 3, 2);
		setBlock(world, i + 19, j + 21, k + 19, Blocks.leaves, 7);
		world.setBlockMetadataWithNotify(i + 19, j + 21, k + 19, 7, 2);
		setBlock(world, i + 19, j + 21, k + 20, Blocks.leaves, 7);
		world.setBlockMetadataWithNotify(i + 19, j + 21, k + 20, 7, 2);
		setBlock(world, i + 19, j + 22, k + 16, Blocks.leaves, 7);
		world.setBlockMetadataWithNotify(i + 19, j + 22, k + 16, 7, 2);
		setBlock(world, i + 19, j + 22, k + 17, Blocks.leaves, 7);
		world.setBlockMetadataWithNotify(i + 19, j + 22, k + 17, 7, 2);
		setBlock(world, i + 19, j + 22, k + 18, Blocks.leaves, 7);
		world.setBlockMetadataWithNotify(i + 19, j + 22, k + 18, 7, 2);
		setBlock(world, i + 19, j + 22, k + 19, Blocks.leaves, 7);
		world.setBlockMetadataWithNotify(i + 19, j + 22, k + 19, 7, 2);
		setBlock(world, i + 19, j + 22, k + 20, Blocks.leaves, 7);
		world.setBlockMetadataWithNotify(i + 19, j + 22, k + 20, 7, 2);
		setBlock(world, i + 19, j + 23, k + 1, Blocks.leaves, 7);
		world.setBlockMetadataWithNotify(i + 19, j + 23, k + 1, 7, 2);
		setBlock(world, i + 19, j + 23, k + 2, Blocks.leaves, 7);
		world.setBlockMetadataWithNotify(i + 19, j + 23, k + 2, 7, 2);
		setBlock(world, i + 19, j + 23, k + 3, Blocks.log, 3);
		world.setBlockMetadataWithNotify(i + 19, j + 23, k + 3, 3, 2);
		setBlock(world, i + 19, j + 23, k + 4, Blocks.leaves, 7);
		world.setBlockMetadataWithNotify(i + 19, j + 23, k + 4, 7, 2);
		setBlock(world, i + 19, j + 23, k + 5, Blocks.leaves, 7);
		world.setBlockMetadataWithNotify(i + 19, j + 23, k + 5, 7, 2);
		setBlock(world, i + 19, j + 23, k + 17, Blocks.leaves, 7);
		world.setBlockMetadataWithNotify(i + 19, j + 23, k + 17, 7, 2);
		setBlock(world, i + 19, j + 23, k + 18, Blocks.leaves, 7);
		world.setBlockMetadataWithNotify(i + 19, j + 23, k + 18, 7, 2);
		setBlock(world, i + 19, j + 23, k + 19, Blocks.leaves, 7);
		world.setBlockMetadataWithNotify(i + 19, j + 23, k + 19, 7, 2);
		setBlock(world, i + 19, j + 24, k + 1, Blocks.leaves, 7);
		world.setBlockMetadataWithNotify(i + 19, j + 24, k + 1, 7, 2);
		setBlock(world, i + 19, j + 24, k + 2, Blocks.leaves, 7);
		world.setBlockMetadataWithNotify(i + 19, j + 24, k + 2, 7, 2);
		setBlock(world, i + 19, j + 24, k + 3, Blocks.leaves, 7);
		world.setBlockMetadataWithNotify(i + 19, j + 24, k + 3, 7, 2);
		setBlock(world, i + 19, j + 24, k + 4, Blocks.leaves, 7);
		world.setBlockMetadataWithNotify(i + 19, j + 24, k + 4, 7, 2);
		setBlock(world, i + 19, j + 24, k + 5, Blocks.leaves, 7);
		world.setBlockMetadataWithNotify(i + 19, j + 24, k + 5, 7, 2);
		setBlock(world, i + 19, j + 24, k + 18, Blocks.leaves, 7);
		world.setBlockMetadataWithNotify(i + 19, j + 24, k + 18, 7, 2);
		setBlock(world, i + 19, j + 25, k + 2, Blocks.leaves, 7);
		world.setBlockMetadataWithNotify(i + 19, j + 25, k + 2, 7, 2);
		setBlock(world, i + 19, j + 25, k + 3, Blocks.leaves, 7);
		world.setBlockMetadataWithNotify(i + 19, j + 25, k + 3, 7, 2);
		setBlock(world, i + 19, j + 25, k + 4, Blocks.leaves, 7);
		world.setBlockMetadataWithNotify(i + 19, j + 25, k + 4, 7, 2);
		setBlock(world, i + 19, j + 26, k + 3, Blocks.leaves, 7);
		world.setBlockMetadataWithNotify(i + 19, j + 26, k + 3, 7, 2);
		setBlock(world, i + 19, j + 30, k + 12, Blocks.leaves, 7);
		world.setBlockMetadataWithNotify(i + 19, j + 30, k + 12, 7, 2);
		setBlock(world, i + 19, j + 30, k + 13, Blocks.leaves, 7);
		world.setBlockMetadataWithNotify(i + 19, j + 30, k + 13, 7, 2);
		setBlock(world, i + 19, j + 30, k + 14, Blocks.leaves, 7);
		world.setBlockMetadataWithNotify(i + 19, j + 30, k + 14, 7, 2);
		setBlock(world, i + 19, j + 30, k + 15, Blocks.leaves, 7);
		world.setBlockMetadataWithNotify(i + 19, j + 30, k + 15, 7, 2);
		setBlock(world, i + 19, j + 30, k + 16, Blocks.leaves, 7);
		world.setBlockMetadataWithNotify(i + 19, j + 30, k + 16, 7, 2);
		setBlock(world, i + 19, j + 31, k + 13, Blocks.leaves, 7);
		world.setBlockMetadataWithNotify(i + 19, j + 31, k + 13, 7, 2);
		setBlock(world, i + 19, j + 31, k + 14, Blocks.leaves, 7);
		world.setBlockMetadataWithNotify(i + 19, j + 31, k + 14, 7, 2);
		setBlock(world, i + 19, j + 31, k + 15, Blocks.leaves, 7);
		world.setBlockMetadataWithNotify(i + 19, j + 31, k + 15, 7, 2);
		setBlock(world, i + 19, j + 32, k + 14, Blocks.leaves, 7);
		world.setBlockMetadataWithNotify(i + 19, j + 32, k + 14, 7, 2);
		setBlock(world, i + 20, j + 20, k + 18, Blocks.log, 3);
		world.setBlockMetadataWithNotify(i + 20, j + 20, k + 18, 3, 2);
		setBlock(world, i + 20, j + 21, k + 16, Blocks.leaves, 7);
		world.setBlockMetadataWithNotify(i + 20, j + 21, k + 16, 7, 2);
		setBlock(world, i + 20, j + 21, k + 17, Blocks.leaves, 7);
		world.setBlockMetadataWithNotify(i + 20, j + 21, k + 17, 7, 2);
		setBlock(world, i + 20, j + 21, k + 18, Blocks.leaves, 7);
		world.setBlockMetadataWithNotify(i + 20, j + 21, k + 18, 7, 2);
		setBlock(world, i + 20, j + 21, k + 19, Blocks.leaves, 7);
		world.setBlockMetadataWithNotify(i + 20, j + 21, k + 19, 7, 2);
		setBlock(world, i + 20, j + 21, k + 20, Blocks.leaves, 7);
		world.setBlockMetadataWithNotify(i + 20, j + 21, k + 20, 7, 2);
		setBlock(world, i + 20, j + 22, k + 4, Blocks.log, 3);
		world.setBlockMetadataWithNotify(i + 20, j + 22, k + 4, 3, 2);
		setBlock(world, i + 20, j + 22, k + 17, Blocks.leaves, 7);
		world.setBlockMetadataWithNotify(i + 20, j + 22, k + 17, 7, 2);
		setBlock(world, i + 20, j + 22, k + 18, Blocks.leaves, 7);
		world.setBlockMetadataWithNotify(i + 20, j + 22, k + 18, 7, 2);
		setBlock(world, i + 20, j + 22, k + 19, Blocks.leaves, 7);
		world.setBlockMetadataWithNotify(i + 20, j + 22, k + 19, 7, 2);
		setBlock(world, i + 20, j + 23, k + 1, Blocks.leaves, 7);
		world.setBlockMetadataWithNotify(i + 20, j + 23, k + 1, 7, 2);
		setBlock(world, i + 20, j + 23, k + 2, Blocks.leaves, 7);
		world.setBlockMetadataWithNotify(i + 20, j + 23, k + 2, 7, 2);
		setBlock(world, i + 20, j + 23, k + 3, Blocks.leaves, 7);
		world.setBlockMetadataWithNotify(i + 20, j + 23, k + 3, 7, 2);
		setBlock(world, i + 20, j + 23, k + 4, Blocks.leaves, 7);
		world.setBlockMetadataWithNotify(i + 20, j + 23, k + 4, 7, 2);
		setBlock(world, i + 20, j + 23, k + 5, Blocks.leaves, 7);
		world.setBlockMetadataWithNotify(i + 20, j + 23, k + 5, 7, 2);
		setBlock(world, i + 20, j + 23, k + 18, Blocks.leaves, 7);
		world.setBlockMetadataWithNotify(i + 20, j + 23, k + 18, 7, 2);
		setBlock(world, i + 20, j + 24, k + 2, Blocks.leaves, 7);
		world.setBlockMetadataWithNotify(i + 20, j + 24, k + 2, 7, 2);
		setBlock(world, i + 20, j + 24, k + 3, Blocks.leaves, 7);
		world.setBlockMetadataWithNotify(i + 20, j + 24, k + 3, 7, 2);
		setBlock(world, i + 20, j + 24, k + 4, Blocks.leaves, 7);
		world.setBlockMetadataWithNotify(i + 20, j + 24, k + 4, 7, 2);
		setBlock(world, i + 20, j + 25, k + 3, Blocks.leaves, 7);
		world.setBlockMetadataWithNotify(i + 20, j + 25, k + 3, 7, 2);
		setBlock(world, i + 20, j + 30, k + 12, Blocks.leaves, 7);
		world.setBlockMetadataWithNotify(i + 20, j + 30, k + 12, 7, 2);
		setBlock(world, i + 20, j + 30, k + 13, Blocks.leaves, 7);
		world.setBlockMetadataWithNotify(i + 20, j + 30, k + 13, 7, 2);
		setBlock(world, i + 20, j + 30, k + 14, Blocks.log, 3);
		world.setBlockMetadataWithNotify(i + 20, j + 30, k + 14, 3, 2);
		setBlock(world, i + 20, j + 30, k + 15, Blocks.leaves, 7);
		world.setBlockMetadataWithNotify(i + 20, j + 30, k + 15, 7, 2);
		setBlock(world, i + 20, j + 30, k + 16, Blocks.leaves, 7);
		world.setBlockMetadataWithNotify(i + 20, j + 30, k + 16, 7, 2);
		setBlock(world, i + 20, j + 31, k + 12, Blocks.leaves, 7);
		world.setBlockMetadataWithNotify(i + 20, j + 31, k + 12, 7, 2);
		setBlock(world, i + 20, j + 31, k + 13, Blocks.leaves, 7);
		world.setBlockMetadataWithNotify(i + 20, j + 31, k + 13, 7, 2);
		setBlock(world, i + 20, j + 31, k + 14, Blocks.leaves, 7);
		world.setBlockMetadataWithNotify(i + 20, j + 31, k + 14, 7, 2);
		setBlock(world, i + 20, j + 31, k + 15, Blocks.leaves, 7);
		world.setBlockMetadataWithNotify(i + 20, j + 31, k + 15, 7, 2);
		setBlock(world, i + 20, j + 31, k + 16, Blocks.leaves, 7);
		world.setBlockMetadataWithNotify(i + 20, j + 31, k + 16, 7, 2);
		setBlock(world, i + 20, j + 32, k + 13, Blocks.leaves, 7);
		world.setBlockMetadataWithNotify(i + 20, j + 32, k + 13, 7, 2);
		setBlock(world, i + 20, j + 32, k + 14, Blocks.leaves, 7);
		world.setBlockMetadataWithNotify(i + 20, j + 32, k + 14, 7, 2);
		setBlock(world, i + 20, j + 32, k + 15, Blocks.leaves, 7);
		world.setBlockMetadataWithNotify(i + 20, j + 32, k + 15, 7, 2);
		setBlock(world, i + 20, j + 33, k + 14, Blocks.leaves, 7);
		world.setBlockMetadataWithNotify(i + 20, j + 33, k + 14, 7, 2);
		setBlock(world, i + 20, j + 35, k + 0, Blocks.leaves, 7);
		world.setBlockMetadataWithNotify(i + 20, j + 35, k + 0, 7, 2);
		setBlock(world, i + 20, j + 35, k + 1, Blocks.leaves, 7);
		world.setBlockMetadataWithNotify(i + 20, j + 35, k + 1, 7, 2);
		setBlock(world, i + 20, j + 35, k + 2, Blocks.leaves, 7);
		world.setBlockMetadataWithNotify(i + 20, j + 35, k + 2, 7, 2);
		setBlock(world, i + 20, j + 36, k + 1, Blocks.leaves, 7);
		world.setBlockMetadataWithNotify(i + 20, j + 36, k + 1, 7, 2);
		setBlock(world, i + 21, j + 20, k + 18, Blocks.log, 3);
		world.setBlockMetadataWithNotify(i + 21, j + 20, k + 18, 3, 2);
		setBlock(world, i + 21, j + 21, k + 17, Blocks.leaves, 7);
		world.setBlockMetadataWithNotify(i + 21, j + 21, k + 17, 7, 2);
		setBlock(world, i + 21, j + 21, k + 18, Blocks.leaves, 7);
		world.setBlockMetadataWithNotify(i + 21, j + 21, k + 18, 7, 2);
		setBlock(world, i + 21, j + 21, k + 19, Blocks.leaves, 7);
		world.setBlockMetadataWithNotify(i + 21, j + 21, k + 19, 7, 2);
		setBlock(world, i + 21, j + 22, k + 4, Blocks.log, 3);
		world.setBlockMetadataWithNotify(i + 21, j + 22, k + 4, 3, 2);
		setBlock(world, i + 21, j + 22, k + 18, Blocks.leaves, 7);
		world.setBlockMetadataWithNotify(i + 21, j + 22, k + 18, 7, 2);
		setBlock(world, i + 21, j + 23, k + 2, Blocks.leaves, 7);
		world.setBlockMetadataWithNotify(i + 21, j + 23, k + 2, 7, 2);
		setBlock(world, i + 21, j + 23, k + 3, Blocks.leaves, 7);
		world.setBlockMetadataWithNotify(i + 21, j + 23, k + 3, 7, 2);
		setBlock(world, i + 21, j + 23, k + 4, Blocks.leaves, 7);
		world.setBlockMetadataWithNotify(i + 21, j + 23, k + 4, 7, 2);
		setBlock(world, i + 21, j + 24, k + 3, Blocks.leaves, 7);
		world.setBlockMetadataWithNotify(i + 21, j + 24, k + 3, 7, 2);
		setBlock(world, i + 21, j + 29, k + 14, Blocks.log, 3);
		world.setBlockMetadataWithNotify(i + 21, j + 29, k + 14, 3, 2);
		setBlock(world, i + 21, j + 30, k + 12, Blocks.leaves, 7);
		world.setBlockMetadataWithNotify(i + 21, j + 30, k + 12, 7, 2);
		setBlock(world, i + 21, j + 30, k + 13, Blocks.leaves, 7);
		world.setBlockMetadataWithNotify(i + 21, j + 30, k + 13, 7, 2);
		setBlock(world, i + 21, j + 30, k + 14, Blocks.leaves, 7);
		world.setBlockMetadataWithNotify(i + 21, j + 30, k + 14, 7, 2);
		setBlock(world, i + 21, j + 30, k + 15, Blocks.leaves, 7);
		world.setBlockMetadataWithNotify(i + 21, j + 30, k + 15, 7, 2);
		setBlock(world, i + 21, j + 30, k + 16, Blocks.leaves, 7);
		world.setBlockMetadataWithNotify(i + 21, j + 30, k + 16, 7, 2);
		setBlock(world, i + 21, j + 31, k + 13, Blocks.leaves, 7);
		world.setBlockMetadataWithNotify(i + 21, j + 31, k + 13, 7, 2);
		setBlock(world, i + 21, j + 31, k + 14, Blocks.leaves, 7);
		world.setBlockMetadataWithNotify(i + 21, j + 31, k + 14, 7, 2);
		setBlock(world, i + 21, j + 31, k + 15, Blocks.leaves, 7);
		world.setBlockMetadataWithNotify(i + 21, j + 31, k + 15, 7, 2);
		setBlock(world, i + 21, j + 32, k + 14, Blocks.leaves, 7);
		world.setBlockMetadataWithNotify(i + 21, j + 32, k + 14, 7, 2);
		setBlock(world, i + 21, j + 35, k + 0, Blocks.leaves, 7);
		world.setBlockMetadataWithNotify(i + 21, j + 35, k + 0, 7, 2);
		setBlock(world, i + 21, j + 35, k + 1, Blocks.leaves, 7);
		world.setBlockMetadataWithNotify(i + 21, j + 35, k + 1, 7, 2);
		setBlock(world, i + 21, j + 35, k + 2, Blocks.leaves, 7);
		world.setBlockMetadataWithNotify(i + 21, j + 35, k + 2, 7, 2);
		setBlock(world, i + 21, j + 35, k + 3, Blocks.leaves, 7);
		world.setBlockMetadataWithNotify(i + 21, j + 35, k + 3, 7, 2);
		setBlock(world, i + 21, j + 36, k + 0, Blocks.leaves, 7);
		world.setBlockMetadataWithNotify(i + 21, j + 36, k + 0, 7, 2);
		setBlock(world, i + 21, j + 36, k + 1, Blocks.leaves, 7);
		world.setBlockMetadataWithNotify(i + 21, j + 36, k + 1, 7, 2);
		setBlock(world, i + 21, j + 36, k + 2, Blocks.leaves, 7);
		world.setBlockMetadataWithNotify(i + 21, j + 36, k + 2, 7, 2);
		setBlock(world, i + 21, j + 37, k + 1, Blocks.leaves, 7);
		world.setBlockMetadataWithNotify(i + 21, j + 37, k + 1, 7, 2);
		setBlock(world, i + 22, j + 20, k + 17, Blocks.log, 3);
		world.setBlockMetadataWithNotify(i + 22, j + 20, k + 17, 3, 2);
		setBlock(world, i + 22, j + 22, k + 4, Blocks.log, 3);
		world.setBlockMetadataWithNotify(i + 22, j + 22, k + 4, 3, 2);
		setBlock(world, i + 22, j + 29, k + 14, Blocks.log, 3);
		world.setBlockMetadataWithNotify(i + 22, j + 29, k + 14, 3, 2);
		setBlock(world, i + 22, j + 30, k + 13, Blocks.leaves, 7);
		world.setBlockMetadataWithNotify(i + 22, j + 30, k + 13, 7, 2);
		setBlock(world, i + 22, j + 30, k + 14, Blocks.leaves, 7);
		world.setBlockMetadataWithNotify(i + 22, j + 30, k + 14, 7, 2);
		setBlock(world, i + 22, j + 30, k + 15, Blocks.leaves, 7);
		world.setBlockMetadataWithNotify(i + 22, j + 30, k + 15, 7, 2);
		setBlock(world, i + 22, j + 31, k + 14, Blocks.leaves, 7);
		world.setBlockMetadataWithNotify(i + 22, j + 31, k + 14, 7, 2);
		setBlock(world, i + 22, j + 35, k + 0, Blocks.leaves, 7);
		world.setBlockMetadataWithNotify(i + 22, j + 35, k + 0, 7, 2);
		setBlock(world, i + 22, j + 35, k + 1, Blocks.log, 3);
		world.setBlockMetadataWithNotify(i + 22, j + 35, k + 1, 3, 2);
		setBlock(world, i + 22, j + 35, k + 2, Blocks.leaves, 7);
		world.setBlockMetadataWithNotify(i + 22, j + 35, k + 2, 7, 2);
		setBlock(world, i + 22, j + 35, k + 3, Blocks.leaves, 7);
		world.setBlockMetadataWithNotify(i + 22, j + 35, k + 3, 7, 2);
		setBlock(world, i + 22, j + 36, k + 0, Blocks.leaves, 7);
		world.setBlockMetadataWithNotify(i + 22, j + 36, k + 0, 7, 2);
		setBlock(world, i + 22, j + 36, k + 1, Blocks.leaves, 7);
		world.setBlockMetadataWithNotify(i + 22, j + 36, k + 1, 7, 2);
		setBlock(world, i + 22, j + 36, k + 2, Blocks.leaves, 7);
		world.setBlockMetadataWithNotify(i + 22, j + 36, k + 2, 7, 2);
		setBlock(world, i + 22, j + 36, k + 3, Blocks.leaves, 7);
		world.setBlockMetadataWithNotify(i + 22, j + 36, k + 3, 7, 2);
		setBlock(world, i + 22, j + 37, k + 0, Blocks.leaves, 7);
		world.setBlockMetadataWithNotify(i + 22, j + 37, k + 0, 7, 2);
		setBlock(world, i + 22, j + 37, k + 1, Blocks.leaves, 7);
		world.setBlockMetadataWithNotify(i + 22, j + 37, k + 1, 7, 2);
		setBlock(world, i + 22, j + 37, k + 2, Blocks.leaves, 7);
		world.setBlockMetadataWithNotify(i + 22, j + 37, k + 2, 7, 2);
		setBlock(world, i + 22, j + 38, k + 1, Blocks.leaves, 7);
		world.setBlockMetadataWithNotify(i + 22, j + 38, k + 1, 7, 2);
		setBlock(world, i + 23, j + 20, k + 17, Blocks.log, 3);
		world.setBlockMetadataWithNotify(i + 23, j + 20, k + 17, 3, 2);
		setBlock(world, i + 23, j + 22, k + 4, Blocks.log, 3);
		world.setBlockMetadataWithNotify(i + 23, j + 22, k + 4, 3, 2);
		setBlock(world, i + 23, j + 29, k + 11, Blocks.leaves, 7);
		world.setBlockMetadataWithNotify(i + 23, j + 29, k + 11, 7, 2);
		setBlock(world, i + 23, j + 29, k + 12, Blocks.leaves, 7);
		world.setBlockMetadataWithNotify(i + 23, j + 29, k + 12, 7, 2);
		setBlock(world, i + 23, j + 29, k + 13, Blocks.leaves, 7);
		world.setBlockMetadataWithNotify(i + 23, j + 29, k + 13, 7, 2);
		setBlock(world, i + 23, j + 29, k + 14, Blocks.log, 3);
		world.setBlockMetadataWithNotify(i + 23, j + 29, k + 14, 3, 2);
		setBlock(world, i + 23, j + 30, k + 12, Blocks.leaves, 7);
		world.setBlockMetadataWithNotify(i + 23, j + 30, k + 12, 7, 2);
		setBlock(world, i + 23, j + 33, k + 7, Blocks.leaves, 7);
		world.setBlockMetadataWithNotify(i + 23, j + 33, k + 7, 7, 2);
		setBlock(world, i + 23, j + 33, k + 8, Blocks.leaves, 7);
		world.setBlockMetadataWithNotify(i + 23, j + 33, k + 8, 7, 2);
		setBlock(world, i + 23, j + 33, k + 9, Blocks.leaves, 7);
		world.setBlockMetadataWithNotify(i + 23, j + 33, k + 9, 7, 2);
		setBlock(world, i + 23, j + 34, k + 2, Blocks.log, 3);
		world.setBlockMetadataWithNotify(i + 23, j + 34, k + 2, 3, 2);
		setBlock(world, i + 23, j + 34, k + 8, Blocks.leaves, 7);
		world.setBlockMetadataWithNotify(i + 23, j + 34, k + 8, 7, 2);
		setBlock(world, i + 23, j + 35, k + 0, Blocks.leaves, 7);
		world.setBlockMetadataWithNotify(i + 23, j + 35, k + 0, 7, 2);
		setBlock(world, i + 23, j + 35, k + 1, Blocks.leaves, 7);
		world.setBlockMetadataWithNotify(i + 23, j + 35, k + 1, 7, 2);
		setBlock(world, i + 23, j + 35, k + 2, Blocks.leaves, 7);
		world.setBlockMetadataWithNotify(i + 23, j + 35, k + 2, 7, 2);
		setBlock(world, i + 23, j + 35, k + 3, Blocks.leaves, 7);
		world.setBlockMetadataWithNotify(i + 23, j + 35, k + 3, 7, 2);
		setBlock(world, i + 23, j + 36, k + 0, Blocks.leaves, 7);
		world.setBlockMetadataWithNotify(i + 23, j + 36, k + 0, 7, 2);
		setBlock(world, i + 23, j + 36, k + 1, Blocks.leaves, 7);
		world.setBlockMetadataWithNotify(i + 23, j + 36, k + 1, 7, 2);
		setBlock(world, i + 23, j + 36, k + 2, Blocks.leaves, 7);
		world.setBlockMetadataWithNotify(i + 23, j + 36, k + 2, 7, 2);
		setBlock(world, i + 23, j + 37, k + 1, Blocks.leaves, 7);
		world.setBlockMetadataWithNotify(i + 23, j + 37, k + 1, 7, 2);
		setBlock(world, i + 24, j + 20, k + 16, Blocks.log, 3);
		world.setBlockMetadataWithNotify(i + 24, j + 20, k + 16, 3, 2);
		setBlock(world, i + 24, j + 22, k + 4, Blocks.log, 3);
		world.setBlockMetadataWithNotify(i + 24, j + 22, k + 4, 3, 2);
		setBlock(world, i + 24, j + 29, k + 10, Blocks.leaves, 7);
		world.setBlockMetadataWithNotify(i + 24, j + 29, k + 10, 7, 2);
		setBlock(world, i + 24, j + 29, k + 11, Blocks.leaves, 7);
		world.setBlockMetadataWithNotify(i + 24, j + 29, k + 11, 7, 2);
		setBlock(world, i + 24, j + 29, k + 12, Blocks.leaves, 7);
		world.setBlockMetadataWithNotify(i + 24, j + 29, k + 12, 7, 2);
		setBlock(world, i + 24, j + 29, k + 13, Blocks.log, 3);
		world.setBlockMetadataWithNotify(i + 24, j + 29, k + 13, 3, 2);
		setBlock(world, i + 24, j + 29, k + 14, Blocks.leaves, 7);
		world.setBlockMetadataWithNotify(i + 24, j + 29, k + 14, 7, 2);
		setBlock(world, i + 24, j + 30, k + 11, Blocks.leaves, 7);
		world.setBlockMetadataWithNotify(i + 24, j + 30, k + 11, 7, 2);
		setBlock(world, i + 24, j + 30, k + 12, Blocks.leaves, 7);
		world.setBlockMetadataWithNotify(i + 24, j + 30, k + 12, 7, 2);
		setBlock(world, i + 24, j + 30, k + 13, Blocks.leaves, 7);
		world.setBlockMetadataWithNotify(i + 24, j + 30, k + 13, 7, 2);
		setBlock(world, i + 24, j + 31, k + 12, Blocks.leaves, 7);
		world.setBlockMetadataWithNotify(i + 24, j + 31, k + 12, 7, 2);
		setBlock(world, i + 24, j + 33, k + 6, Blocks.leaves, 7);
		world.setBlockMetadataWithNotify(i + 24, j + 33, k + 6, 7, 2);
		setBlock(world, i + 24, j + 33, k + 7, Blocks.leaves, 7);
		world.setBlockMetadataWithNotify(i + 24, j + 33, k + 7, 7, 2);
		setBlock(world, i + 24, j + 33, k + 8, Blocks.leaves, 7);
		world.setBlockMetadataWithNotify(i + 24, j + 33, k + 8, 7, 2);
		setBlock(world, i + 24, j + 33, k + 9, Blocks.leaves, 7);
		world.setBlockMetadataWithNotify(i + 24, j + 33, k + 9, 7, 2);
		setBlock(world, i + 24, j + 33, k + 10, Blocks.leaves, 7);
		world.setBlockMetadataWithNotify(i + 24, j + 33, k + 10, 7, 2);
		setBlock(world, i + 24, j + 34, k + 2, Blocks.log, 3);
		world.setBlockMetadataWithNotify(i + 24, j + 34, k + 2, 3, 2);
		setBlock(world, i + 24, j + 34, k + 7, Blocks.leaves, 7);
		world.setBlockMetadataWithNotify(i + 24, j + 34, k + 7, 7, 2);
		setBlock(world, i + 24, j + 34, k + 8, Blocks.leaves, 7);
		world.setBlockMetadataWithNotify(i + 24, j + 34, k + 8, 7, 2);
		setBlock(world, i + 24, j + 34, k + 9, Blocks.leaves, 7);
		world.setBlockMetadataWithNotify(i + 24, j + 34, k + 9, 7, 2);
		setBlock(world, i + 24, j + 35, k + 0, Blocks.leaves, 7);
		world.setBlockMetadataWithNotify(i + 24, j + 35, k + 0, 7, 2);
		setBlock(world, i + 24, j + 35, k + 1, Blocks.leaves, 7);
		world.setBlockMetadataWithNotify(i + 24, j + 35, k + 1, 7, 2);
		setBlock(world, i + 24, j + 35, k + 2, Blocks.leaves, 7);
		world.setBlockMetadataWithNotify(i + 24, j + 35, k + 2, 7, 2);
		setBlock(world, i + 24, j + 35, k + 8, Blocks.leaves, 7);
		world.setBlockMetadataWithNotify(i + 24, j + 35, k + 8, 7, 2);
		setBlock(world, i + 24, j + 36, k + 0, Blocks.leaves, 7);
		world.setBlockMetadataWithNotify(i + 24, j + 36, k + 0, 7, 2);
		setBlock(world, i + 24, j + 36, k + 1, Blocks.leaves, 7);
		world.setBlockMetadataWithNotify(i + 24, j + 36, k + 1, 7, 2);
		setBlock(world, i + 25, j + 18, k + 16, Blocks.log, 3);
		world.setBlockMetadataWithNotify(i + 25, j + 18, k + 16, 3, 2);
		setBlock(world, i + 25, j + 19, k + 15, Blocks.log, 3);
		world.setBlockMetadataWithNotify(i + 25, j + 19, k + 15, 3, 2);
		setBlock(world, i + 25, j + 19, k + 16, Blocks.log, 3);
		world.setBlockMetadataWithNotify(i + 25, j + 19, k + 16, 3, 2);
		setBlock(world, i + 25, j + 19, k + 17, Blocks.log, 3);
		world.setBlockMetadataWithNotify(i + 25, j + 19, k + 17, 3, 2);
		setBlock(world, i + 25, j + 20, k + 16, Blocks.log, 3);
		world.setBlockMetadataWithNotify(i + 25, j + 20, k + 16, 3, 2);
		setBlock(world, i + 25, j + 22, k + 5, Blocks.log, 3);
		world.setBlockMetadataWithNotify(i + 25, j + 22, k + 5, 3, 2);
		setBlock(world, i + 25, j + 29, k + 10, Blocks.leaves, 7);
		world.setBlockMetadataWithNotify(i + 25, j + 29, k + 10, 7, 2);
		setBlock(world, i + 25, j + 29, k + 11, Blocks.leaves, 7);
		world.setBlockMetadataWithNotify(i + 25, j + 29, k + 11, 7, 2);
		setBlock(world, i + 25, j + 29, k + 12, Blocks.log, 3);
		world.setBlockMetadataWithNotify(i + 25, j + 29, k + 12, 3, 2);
		setBlock(world, i + 25, j + 29, k + 13, Blocks.log, 3);
		world.setBlockMetadataWithNotify(i + 25, j + 29, k + 13, 3, 2);
		setBlock(world, i + 25, j + 29, k + 14, Blocks.leaves, 7);
		world.setBlockMetadataWithNotify(i + 25, j + 29, k + 14, 7, 2);
		setBlock(world, i + 25, j + 30, k + 10, Blocks.leaves, 7);
		world.setBlockMetadataWithNotify(i + 25, j + 30, k + 10, 7, 2);
		setBlock(world, i + 25, j + 30, k + 11, Blocks.leaves, 7);
		world.setBlockMetadataWithNotify(i + 25, j + 30, k + 11, 7, 2);
		setBlock(world, i + 25, j + 30, k + 12, Blocks.leaves, 7);
		world.setBlockMetadataWithNotify(i + 25, j + 30, k + 12, 7, 2);
		setBlock(world, i + 25, j + 30, k + 13, Blocks.leaves, 7);
		world.setBlockMetadataWithNotify(i + 25, j + 30, k + 13, 7, 2);
		setBlock(world, i + 25, j + 30, k + 14, Blocks.leaves, 7);
		world.setBlockMetadataWithNotify(i + 25, j + 30, k + 14, 7, 2);
		setBlock(world, i + 25, j + 31, k + 11, Blocks.leaves, 7);
		world.setBlockMetadataWithNotify(i + 25, j + 31, k + 11, 7, 2);
		setBlock(world, i + 25, j + 31, k + 12, Blocks.leaves, 7);
		world.setBlockMetadataWithNotify(i + 25, j + 31, k + 12, 7, 2);
		setBlock(world, i + 25, j + 31, k + 13, Blocks.leaves, 7);
		world.setBlockMetadataWithNotify(i + 25, j + 31, k + 13, 7, 2);
		setBlock(world, i + 25, j + 32, k + 12, Blocks.leaves, 7);
		world.setBlockMetadataWithNotify(i + 25, j + 32, k + 12, 7, 2);
		setBlock(world, i + 25, j + 32, k + 18, Blocks.leaves, 7);
		world.setBlockMetadataWithNotify(i + 25, j + 32, k + 18, 7, 2);
		setBlock(world, i + 25, j + 32, k + 19, Blocks.leaves, 7);
		world.setBlockMetadataWithNotify(i + 25, j + 32, k + 19, 7, 2);
		setBlock(world, i + 25, j + 32, k + 20, Blocks.leaves, 7);
		world.setBlockMetadataWithNotify(i + 25, j + 32, k + 20, 7, 2);
		setBlock(world, i + 25, j + 33, k + 6, Blocks.leaves, 7);
		world.setBlockMetadataWithNotify(i + 25, j + 33, k + 6, 7, 2);
		setBlock(world, i + 25, j + 33, k + 7, Blocks.leaves, 7);
		world.setBlockMetadataWithNotify(i + 25, j + 33, k + 7, 7, 2);
		setBlock(world, i + 25, j + 33, k + 8, Blocks.log, 3);
		world.setBlockMetadataWithNotify(i + 25, j + 33, k + 8, 3, 2);
		setBlock(world, i + 25, j + 33, k + 9, Blocks.leaves, 7);
		world.setBlockMetadataWithNotify(i + 25, j + 33, k + 9, 7, 2);
		setBlock(world, i + 25, j + 33, k + 10, Blocks.leaves, 7);
		world.setBlockMetadataWithNotify(i + 25, j + 33, k + 10, 7, 2);
		setBlock(world, i + 25, j + 33, k + 19, Blocks.leaves, 7);
		world.setBlockMetadataWithNotify(i + 25, j + 33, k + 19, 7, 2);
		setBlock(world, i + 25, j + 34, k + 3, Blocks.log, 3);
		world.setBlockMetadataWithNotify(i + 25, j + 34, k + 3, 3, 2);
		setBlock(world, i + 25, j + 34, k + 6, Blocks.leaves, 7);
		world.setBlockMetadataWithNotify(i + 25, j + 34, k + 6, 7, 2);
		setBlock(world, i + 25, j + 34, k + 7, Blocks.leaves, 7);
		world.setBlockMetadataWithNotify(i + 25, j + 34, k + 7, 7, 2);
		setBlock(world, i + 25, j + 34, k + 8, Blocks.leaves, 7);
		world.setBlockMetadataWithNotify(i + 25, j + 34, k + 8, 7, 2);
		setBlock(world, i + 25, j + 34, k + 9, Blocks.leaves, 7);
		world.setBlockMetadataWithNotify(i + 25, j + 34, k + 9, 7, 2);
		setBlock(world, i + 25, j + 34, k + 10, Blocks.leaves, 7);
		world.setBlockMetadataWithNotify(i + 25, j + 34, k + 10, 7, 2);
		setBlock(world, i + 25, j + 35, k + 0, Blocks.leaves, 7);
		world.setBlockMetadataWithNotify(i + 25, j + 35, k + 0, 7, 2);
		setBlock(world, i + 25, j + 35, k + 1, Blocks.leaves, 7);
		world.setBlockMetadataWithNotify(i + 25, j + 35, k + 1, 7, 2);
		setBlock(world, i + 25, j + 35, k + 2, Blocks.leaves, 7);
		world.setBlockMetadataWithNotify(i + 25, j + 35, k + 2, 7, 2);
		setBlock(world, i + 25, j + 35, k + 7, Blocks.leaves, 7);
		world.setBlockMetadataWithNotify(i + 25, j + 35, k + 7, 7, 2);
		setBlock(world, i + 25, j + 35, k + 8, Blocks.leaves, 7);
		world.setBlockMetadataWithNotify(i + 25, j + 35, k + 8, 7, 2);
		setBlock(world, i + 25, j + 35, k + 9, Blocks.leaves, 7);
		world.setBlockMetadataWithNotify(i + 25, j + 35, k + 9, 7, 2);
		setBlock(world, i + 25, j + 36, k + 0, Blocks.leaves, 7);
		world.setBlockMetadataWithNotify(i + 25, j + 36, k + 0, 7, 2);
		setBlock(world, i + 25, j + 36, k + 1, Blocks.leaves, 7);
		world.setBlockMetadataWithNotify(i + 25, j + 36, k + 1, 7, 2);
		setBlock(world, i + 25, j + 36, k + 8, Blocks.leaves, 7);
		world.setBlockMetadataWithNotify(i + 25, j + 36, k + 8, 7, 2);
		setBlock(world, i + 25, j + 37, k + 0, Blocks.leaves, 7);
		world.setBlockMetadataWithNotify(i + 25, j + 37, k + 0, 7, 2);
		setBlock(world, i + 26, j + 18, k + 15, Blocks.log, 3);
		world.setBlockMetadataWithNotify(i + 26, j + 18, k + 15, 3, 2);
		setBlock(world, i + 26, j + 19, k + 14, Blocks.log, 3);
		world.setBlockMetadataWithNotify(i + 26, j + 19, k + 14, 3, 2);
		setBlock(world, i + 26, j + 19, k + 15, Blocks.log, 3);
		world.setBlockMetadataWithNotify(i + 26, j + 19, k + 15, 3, 2);
		setBlock(world, i + 26, j + 19, k + 16, Blocks.log, 3);
		world.setBlockMetadataWithNotify(i + 26, j + 19, k + 16, 3, 2);
		setBlock(world, i + 26, j + 20, k + 15, Blocks.log, 3);
		world.setBlockMetadataWithNotify(i + 26, j + 20, k + 15, 3, 2);
		setBlock(world, i + 26, j + 22, k + 2, Blocks.leaves, 7);
		world.setBlockMetadataWithNotify(i + 26, j + 22, k + 2, 7, 2);
		setBlock(world, i + 26, j + 22, k + 3, Blocks.leaves, 7);
		world.setBlockMetadataWithNotify(i + 26, j + 22, k + 3, 7, 2);
		setBlock(world, i + 26, j + 22, k + 4, Blocks.leaves, 7);
		world.setBlockMetadataWithNotify(i + 26, j + 22, k + 4, 7, 2);
		setBlock(world, i + 26, j + 22, k + 5, Blocks.log, 3);
		world.setBlockMetadataWithNotify(i + 26, j + 22, k + 5, 3, 2);
		setBlock(world, i + 26, j + 23, k + 3, Blocks.leaves, 7);
		world.setBlockMetadataWithNotify(i + 26, j + 23, k + 3, 7, 2);
		setBlock(world, i + 26, j + 25, k + 19, Blocks.leaves, 7);
		world.setBlockMetadataWithNotify(i + 26, j + 25, k + 19, 7, 2);
		setBlock(world, i + 26, j + 25, k + 20, Blocks.leaves, 7);
		world.setBlockMetadataWithNotify(i + 26, j + 25, k + 20, 7, 2);
		setBlock(world, i + 26, j + 25, k + 21, Blocks.leaves, 7);
		world.setBlockMetadataWithNotify(i + 26, j + 25, k + 21, 7, 2);
		setBlock(world, i + 26, j + 26, k + 20, Blocks.leaves, 7);
		world.setBlockMetadataWithNotify(i + 26, j + 26, k + 20, 7, 2);
		setBlock(world, i + 26, j + 28, k + 12, Blocks.log, 3);
		world.setBlockMetadataWithNotify(i + 26, j + 28, k + 12, 3, 2);
		setBlock(world, i + 26, j + 29, k + 10, Blocks.leaves, 7);
		world.setBlockMetadataWithNotify(i + 26, j + 29, k + 10, 7, 2);
		setBlock(world, i + 26, j + 29, k + 11, Blocks.leaves, 7);
		world.setBlockMetadataWithNotify(i + 26, j + 29, k + 11, 7, 2);
		setBlock(world, i + 26, j + 29, k + 12, Blocks.leaves, 7);
		world.setBlockMetadataWithNotify(i + 26, j + 29, k + 12, 7, 2);
		setBlock(world, i + 26, j + 29, k + 13, Blocks.log, 3);
		world.setBlockMetadataWithNotify(i + 26, j + 29, k + 13, 3, 2);
		setBlock(world, i + 26, j + 29, k + 14, Blocks.leaves, 7);
		world.setBlockMetadataWithNotify(i + 26, j + 29, k + 14, 7, 2);
		setBlock(world, i + 26, j + 30, k + 11, Blocks.leaves, 7);
		world.setBlockMetadataWithNotify(i + 26, j + 30, k + 11, 7, 2);
		setBlock(world, i + 26, j + 30, k + 12, Blocks.leaves, 7);
		world.setBlockMetadataWithNotify(i + 26, j + 30, k + 12, 7, 2);
		setBlock(world, i + 26, j + 30, k + 13, Blocks.leaves, 7);
		world.setBlockMetadataWithNotify(i + 26, j + 30, k + 13, 7, 2);
		setBlock(world, i + 26, j + 31, k + 12, Blocks.leaves, 7);
		world.setBlockMetadataWithNotify(i + 26, j + 31, k + 12, 7, 2);
		setBlock(world, i + 26, j + 32, k + 9, Blocks.log, 3);
		world.setBlockMetadataWithNotify(i + 26, j + 32, k + 9, 3, 2);
		setBlock(world, i + 26, j + 32, k + 17, Blocks.leaves, 7);
		world.setBlockMetadataWithNotify(i + 26, j + 32, k + 17, 7, 2);
		setBlock(world, i + 26, j + 32, k + 18, Blocks.leaves, 7);
		world.setBlockMetadataWithNotify(i + 26, j + 32, k + 18, 7, 2);
		setBlock(world, i + 26, j + 32, k + 19, Blocks.leaves, 7);
		world.setBlockMetadataWithNotify(i + 26, j + 32, k + 19, 7, 2);
		setBlock(world, i + 26, j + 32, k + 20, Blocks.leaves, 7);
		world.setBlockMetadataWithNotify(i + 26, j + 32, k + 20, 7, 2);
		setBlock(world, i + 26, j + 32, k + 21, Blocks.leaves, 7);
		world.setBlockMetadataWithNotify(i + 26, j + 32, k + 21, 7, 2);
		setBlock(world, i + 26, j + 33, k + 6, Blocks.leaves, 7);
		world.setBlockMetadataWithNotify(i + 26, j + 33, k + 6, 7, 2);
		setBlock(world, i + 26, j + 33, k + 7, Blocks.leaves, 7);
		world.setBlockMetadataWithNotify(i + 26, j + 33, k + 7, 7, 2);
		setBlock(world, i + 26, j + 33, k + 8, Blocks.leaves, 7);
		world.setBlockMetadataWithNotify(i + 26, j + 33, k + 8, 7, 2);
		setBlock(world, i + 26, j + 33, k + 9, Blocks.leaves, 7);
		world.setBlockMetadataWithNotify(i + 26, j + 33, k + 9, 7, 2);
		setBlock(world, i + 26, j + 33, k + 10, Blocks.leaves, 7);
		world.setBlockMetadataWithNotify(i + 26, j + 33, k + 10, 7, 2);
		setBlock(world, i + 26, j + 33, k + 18, Blocks.leaves, 7);
		world.setBlockMetadataWithNotify(i + 26, j + 33, k + 18, 7, 2);
		setBlock(world, i + 26, j + 33, k + 19, Blocks.leaves, 7);
		world.setBlockMetadataWithNotify(i + 26, j + 33, k + 19, 7, 2);
		setBlock(world, i + 26, j + 33, k + 20, Blocks.leaves, 7);
		world.setBlockMetadataWithNotify(i + 26, j + 33, k + 20, 7, 2);
		setBlock(world, i + 26, j + 34, k + 3, Blocks.log, 3);
		world.setBlockMetadataWithNotify(i + 26, j + 34, k + 3, 3, 2);
		setBlock(world, i + 26, j + 34, k + 7, Blocks.leaves, 7);
		world.setBlockMetadataWithNotify(i + 26, j + 34, k + 7, 7, 2);
		setBlock(world, i + 26, j + 34, k + 8, Blocks.leaves, 7);
		world.setBlockMetadataWithNotify(i + 26, j + 34, k + 8, 7, 2);
		setBlock(world, i + 26, j + 34, k + 9, Blocks.leaves, 7);
		world.setBlockMetadataWithNotify(i + 26, j + 34, k + 9, 7, 2);
		setBlock(world, i + 26, j + 34, k + 19, Blocks.leaves, 7);
		world.setBlockMetadataWithNotify(i + 26, j + 34, k + 19, 7, 2);
		setBlock(world, i + 26, j + 35, k + 0, Blocks.log, 3);
		world.setBlockMetadataWithNotify(i + 26, j + 35, k + 0, 3, 2);
		setBlock(world, i + 26, j + 35, k + 1, Blocks.leaves, 7);
		world.setBlockMetadataWithNotify(i + 26, j + 35, k + 1, 7, 2);
		setBlock(world, i + 26, j + 35, k + 2, Blocks.leaves, 7);
		world.setBlockMetadataWithNotify(i + 26, j + 35, k + 2, 7, 2);
		setBlock(world, i + 26, j + 35, k + 8, Blocks.leaves, 7);
		world.setBlockMetadataWithNotify(i + 26, j + 35, k + 8, 7, 2);
		setBlock(world, i + 26, j + 36, k + 0, Blocks.leaves, 7);
		world.setBlockMetadataWithNotify(i + 26, j + 36, k + 0, 7, 2);
		setBlock(world, i + 26, j + 36, k + 1, Blocks.leaves, 7);
		world.setBlockMetadataWithNotify(i + 26, j + 36, k + 1, 7, 2);
		setBlock(world, i + 26, j + 36, k + 2, Blocks.leaves, 7);
		world.setBlockMetadataWithNotify(i + 26, j + 36, k + 2, 7, 2);
		setBlock(world, i + 26, j + 37, k + 0, Blocks.leaves, 7);
		world.setBlockMetadataWithNotify(i + 26, j + 37, k + 0, 7, 2);
		setBlock(world, i + 26, j + 37, k + 1, Blocks.leaves, 7);
		world.setBlockMetadataWithNotify(i + 26, j + 37, k + 1, 7, 2);
		setBlock(world, i + 26, j + 38, k + 0, Blocks.leaves, 7);
		world.setBlockMetadataWithNotify(i + 26, j + 38, k + 0, 7, 2);
		setBlock(world, i + 27, j + 18, k + 15, Blocks.log, 3);
		world.setBlockMetadataWithNotify(i + 27, j + 18, k + 15, 3, 2);
		setBlock(world, i + 27, j + 19, k + 14, Blocks.log, 3);
		world.setBlockMetadataWithNotify(i + 27, j + 19, k + 14, 3, 2);
		setBlock(world, i + 27, j + 19, k + 15, Blocks.log, 3);
		world.setBlockMetadataWithNotify(i + 27, j + 19, k + 15, 3, 2);
		setBlock(world, i + 27, j + 19, k + 16, Blocks.log, 3);
		world.setBlockMetadataWithNotify(i + 27, j + 19, k + 16, 3, 2);
		setBlock(world, i + 27, j + 20, k + 15, Blocks.log, 3);
		world.setBlockMetadataWithNotify(i + 27, j + 20, k + 15, 3, 2);
		setBlock(world, i + 27, j + 22, k + 1, Blocks.leaves, 7);
		world.setBlockMetadataWithNotify(i + 27, j + 22, k + 1, 7, 2);
		setBlock(world, i + 27, j + 22, k + 2, Blocks.leaves, 7);
		world.setBlockMetadataWithNotify(i + 27, j + 22, k + 2, 7, 2);
		setBlock(world, i + 27, j + 22, k + 3, Blocks.leaves, 7);
		world.setBlockMetadataWithNotify(i + 27, j + 22, k + 3, 7, 2);
		setBlock(world, i + 27, j + 22, k + 4, Blocks.leaves, 7);
		world.setBlockMetadataWithNotify(i + 27, j + 22, k + 4, 7, 2);
		setBlock(world, i + 27, j + 22, k + 5, Blocks.log, 3);
		world.setBlockMetadataWithNotify(i + 27, j + 22, k + 5, 3, 2);
		setBlock(world, i + 27, j + 23, k + 2, Blocks.leaves, 7);
		world.setBlockMetadataWithNotify(i + 27, j + 23, k + 2, 7, 2);
		setBlock(world, i + 27, j + 23, k + 3, Blocks.leaves, 7);
		world.setBlockMetadataWithNotify(i + 27, j + 23, k + 3, 7, 2);
		setBlock(world, i + 27, j + 23, k + 4, Blocks.leaves, 7);
		world.setBlockMetadataWithNotify(i + 27, j + 23, k + 4, 7, 2);
		setBlock(world, i + 27, j + 24, k + 3, Blocks.leaves, 7);
		world.setBlockMetadataWithNotify(i + 27, j + 24, k + 3, 7, 2);
		setBlock(world, i + 27, j + 25, k + 18, Blocks.leaves, 7);
		world.setBlockMetadataWithNotify(i + 27, j + 25, k + 18, 7, 2);
		setBlock(world, i + 27, j + 25, k + 19, Blocks.leaves, 7);
		world.setBlockMetadataWithNotify(i + 27, j + 25, k + 19, 7, 2);
		setBlock(world, i + 27, j + 25, k + 20, Blocks.leaves, 7);
		world.setBlockMetadataWithNotify(i + 27, j + 25, k + 20, 7, 2);
		setBlock(world, i + 27, j + 25, k + 21, Blocks.leaves, 7);
		world.setBlockMetadataWithNotify(i + 27, j + 25, k + 21, 7, 2);
		setBlock(world, i + 27, j + 25, k + 22, Blocks.leaves, 7);
		world.setBlockMetadataWithNotify(i + 27, j + 25, k + 22, 7, 2);
		setBlock(world, i + 27, j + 26, k + 19, Blocks.leaves, 7);
		world.setBlockMetadataWithNotify(i + 27, j + 26, k + 19, 7, 2);
		setBlock(world, i + 27, j + 26, k + 20, Blocks.leaves, 7);
		world.setBlockMetadataWithNotify(i + 27, j + 26, k + 20, 7, 2);
		setBlock(world, i + 27, j + 26, k + 21, Blocks.leaves, 7);
		world.setBlockMetadataWithNotify(i + 27, j + 26, k + 21, 7, 2);
		setBlock(world, i + 27, j + 27, k + 20, Blocks.leaves, 7);
		world.setBlockMetadataWithNotify(i + 27, j + 27, k + 20, 7, 2);
		setBlock(world, i + 27, j + 28, k + 12, Blocks.log, 3);
		world.setBlockMetadataWithNotify(i + 27, j + 28, k + 12, 3, 2);
		setBlock(world, i + 27, j + 29, k + 11, Blocks.leaves, 7);
		world.setBlockMetadataWithNotify(i + 27, j + 29, k + 11, 7, 2);
		setBlock(world, i + 27, j + 29, k + 12, Blocks.leaves, 7);
		world.setBlockMetadataWithNotify(i + 27, j + 29, k + 12, 7, 2);
		setBlock(world, i + 27, j + 29, k + 13, Blocks.leaves, 7);
		world.setBlockMetadataWithNotify(i + 27, j + 29, k + 13, 7, 2);
		setBlock(world, i + 27, j + 30, k + 12, Blocks.leaves, 7);
		world.setBlockMetadataWithNotify(i + 27, j + 30, k + 12, 7, 2);
		setBlock(world, i + 27, j + 32, k + 9, Blocks.log, 3);
		world.setBlockMetadataWithNotify(i + 27, j + 32, k + 9, 3, 2);
		setBlock(world, i + 27, j + 32, k + 17, Blocks.leaves, 7);
		world.setBlockMetadataWithNotify(i + 27, j + 32, k + 17, 7, 2);
		setBlock(world, i + 27, j + 32, k + 18, Blocks.leaves, 7);
		world.setBlockMetadataWithNotify(i + 27, j + 32, k + 18, 7, 2);
		setBlock(world, i + 27, j + 32, k + 19, Blocks.log, 3);
		world.setBlockMetadataWithNotify(i + 27, j + 32, k + 19, 3, 2);
		setBlock(world, i + 27, j + 32, k + 20, Blocks.leaves, 7);
		world.setBlockMetadataWithNotify(i + 27, j + 32, k + 20, 7, 2);
		setBlock(world, i + 27, j + 32, k + 21, Blocks.leaves, 7);
		world.setBlockMetadataWithNotify(i + 27, j + 32, k + 21, 7, 2);
		setBlock(world, i + 27, j + 33, k + 0, Blocks.leaves, 7);
		world.setBlockMetadataWithNotify(i + 27, j + 33, k + 0, 7, 2);
		setBlock(world, i + 27, j + 33, k + 1, Blocks.leaves, 7);
		world.setBlockMetadataWithNotify(i + 27, j + 33, k + 1, 7, 2);
		setBlock(world, i + 27, j + 33, k + 2, Blocks.leaves, 7);
		world.setBlockMetadataWithNotify(i + 27, j + 33, k + 2, 7, 2);
		setBlock(world, i + 27, j + 33, k + 7, Blocks.leaves, 7);
		world.setBlockMetadataWithNotify(i + 27, j + 33, k + 7, 7, 2);
		setBlock(world, i + 27, j + 33, k + 8, Blocks.leaves, 7);
		world.setBlockMetadataWithNotify(i + 27, j + 33, k + 8, 7, 2);
		setBlock(world, i + 27, j + 33, k + 9, Blocks.leaves, 7);
		world.setBlockMetadataWithNotify(i + 27, j + 33, k + 9, 7, 2);
		setBlock(world, i + 27, j + 33, k + 17, Blocks.leaves, 7);
		world.setBlockMetadataWithNotify(i + 27, j + 33, k + 17, 7, 2);
		setBlock(world, i + 27, j + 33, k + 18, Blocks.leaves, 7);
		world.setBlockMetadataWithNotify(i + 27, j + 33, k + 18, 7, 2);
		setBlock(world, i + 27, j + 33, k + 19, Blocks.leaves, 7);
		world.setBlockMetadataWithNotify(i + 27, j + 33, k + 19, 7, 2);
		setBlock(world, i + 27, j + 33, k + 20, Blocks.leaves, 7);
		world.setBlockMetadataWithNotify(i + 27, j + 33, k + 20, 7, 2);
		setBlock(world, i + 27, j + 33, k + 21, Blocks.leaves, 7);
		world.setBlockMetadataWithNotify(i + 27, j + 33, k + 21, 7, 2);
		setBlock(world, i + 27, j + 34, k + 1, Blocks.log, 3);
		world.setBlockMetadataWithNotify(i + 27, j + 34, k + 1, 3, 2);
		setBlock(world, i + 27, j + 34, k + 3, Blocks.log, 3);
		world.setBlockMetadataWithNotify(i + 27, j + 34, k + 3, 3, 2);
		setBlock(world, i + 27, j + 34, k + 8, Blocks.leaves, 7);
		world.setBlockMetadataWithNotify(i + 27, j + 34, k + 8, 7, 2);
		setBlock(world, i + 27, j + 34, k + 18, Blocks.leaves, 7);
		world.setBlockMetadataWithNotify(i + 27, j + 34, k + 18, 7, 2);
		setBlock(world, i + 27, j + 34, k + 19, Blocks.leaves, 7);
		world.setBlockMetadataWithNotify(i + 27, j + 34, k + 19, 7, 2);
		setBlock(world, i + 27, j + 34, k + 20, Blocks.leaves, 7);
		world.setBlockMetadataWithNotify(i + 27, j + 34, k + 20, 7, 2);
		setBlock(world, i + 27, j + 35, k + 0, Blocks.leaves, 7);
		world.setBlockMetadataWithNotify(i + 27, j + 35, k + 0, 7, 2);
		setBlock(world, i + 27, j + 35, k + 1, Blocks.leaves, 7);
		world.setBlockMetadataWithNotify(i + 27, j + 35, k + 1, 7, 2);
		setBlock(world, i + 27, j + 35, k + 2, Blocks.leaves, 7);
		world.setBlockMetadataWithNotify(i + 27, j + 35, k + 2, 7, 2);
		setBlock(world, i + 27, j + 35, k + 19, Blocks.leaves, 7);
		world.setBlockMetadataWithNotify(i + 27, j + 35, k + 19, 7, 2);
		setBlock(world, i + 27, j + 36, k + 0, Blocks.leaves, 7);
		world.setBlockMetadataWithNotify(i + 27, j + 36, k + 0, 7, 2);
		setBlock(world, i + 27, j + 36, k + 1, Blocks.leaves, 7);
		world.setBlockMetadataWithNotify(i + 27, j + 36, k + 1, 7, 2);
		setBlock(world, i + 27, j + 37, k + 0, Blocks.leaves, 7);
		world.setBlockMetadataWithNotify(i + 27, j + 37, k + 0, 7, 2);
		setBlock(world, i + 27, j + 39, k + 13, Blocks.leaves, 7);
		world.setBlockMetadataWithNotify(i + 27, j + 39, k + 13, 7, 2);
		setBlock(world, i + 27, j + 39, k + 14, Blocks.leaves, 7);
		world.setBlockMetadataWithNotify(i + 27, j + 39, k + 14, 7, 2);
		setBlock(world, i + 27, j + 39, k + 15, Blocks.leaves, 7);
		world.setBlockMetadataWithNotify(i + 27, j + 39, k + 15, 7, 2);
		setBlock(world, i + 27, j + 40, k + 14, Blocks.leaves, 7);
		world.setBlockMetadataWithNotify(i + 27, j + 40, k + 14, 7, 2);
		setBlock(world, i + 27, j + 45, k + 3, Blocks.leaves, 7);
		world.setBlockMetadataWithNotify(i + 27, j + 45, k + 3, 7, 2);
		setBlock(world, i + 27, j + 45, k + 4, Blocks.leaves, 7);
		world.setBlockMetadataWithNotify(i + 27, j + 45, k + 4, 7, 2);
		setBlock(world, i + 27, j + 45, k + 5, Blocks.leaves, 7);
		world.setBlockMetadataWithNotify(i + 27, j + 45, k + 5, 7, 2);
		setBlock(world, i + 27, j + 46, k + 4, Blocks.leaves, 7);
		world.setBlockMetadataWithNotify(i + 27, j + 46, k + 4, 7, 2);
		setBlock(world, i + 28, j + 18, k + 14, Blocks.log, 3);
		world.setBlockMetadataWithNotify(i + 28, j + 18, k + 14, 3, 2);
		setBlock(world, i + 28, j + 19, k + 13, Blocks.log, 3);
		world.setBlockMetadataWithNotify(i + 28, j + 19, k + 13, 3, 2);
		setBlock(world, i + 28, j + 19, k + 14, Blocks.log, 3);
		world.setBlockMetadataWithNotify(i + 28, j + 19, k + 14, 3, 2);
		setBlock(world, i + 28, j + 19, k + 15, Blocks.log, 3);
		world.setBlockMetadataWithNotify(i + 28, j + 19, k + 15, 3, 2);
		setBlock(world, i + 28, j + 20, k + 14, Blocks.log, 3);
		world.setBlockMetadataWithNotify(i + 28, j + 20, k + 14, 3, 2);
		setBlock(world, i + 28, j + 22, k + 1, Blocks.leaves, 7);
		world.setBlockMetadataWithNotify(i + 28, j + 22, k + 1, 7, 2);
		setBlock(world, i + 28, j + 22, k + 2, Blocks.leaves, 7);
		world.setBlockMetadataWithNotify(i + 28, j + 22, k + 2, 7, 2);
		setBlock(world, i + 28, j + 22, k + 3, Blocks.log, 3);
		world.setBlockMetadataWithNotify(i + 28, j + 22, k + 3, 3, 2);
		setBlock(world, i + 28, j + 22, k + 4, Blocks.leaves, 7);
		world.setBlockMetadataWithNotify(i + 28, j + 22, k + 4, 7, 2);
		setBlock(world, i + 28, j + 22, k + 5, Blocks.log, 3);
		world.setBlockMetadataWithNotify(i + 28, j + 22, k + 5, 3, 2);
		setBlock(world, i + 28, j + 23, k + 0, Blocks.log, 3);
		world.setBlockMetadataWithNotify(i + 28, j + 23, k + 0, 3, 2);
		setBlock(world, i + 28, j + 23, k + 1, Blocks.leaves, 7);
		world.setBlockMetadataWithNotify(i + 28, j + 23, k + 1, 7, 2);
		setBlock(world, i + 28, j + 23, k + 2, Blocks.leaves, 7);
		world.setBlockMetadataWithNotify(i + 28, j + 23, k + 2, 7, 2);
		setBlock(world, i + 28, j + 23, k + 3, Blocks.leaves, 7);
		world.setBlockMetadataWithNotify(i + 28, j + 23, k + 3, 7, 2);
		setBlock(world, i + 28, j + 23, k + 4, Blocks.leaves, 7);
		world.setBlockMetadataWithNotify(i + 28, j + 23, k + 4, 7, 2);
		setBlock(world, i + 28, j + 23, k + 5, Blocks.leaves, 7);
		world.setBlockMetadataWithNotify(i + 28, j + 23, k + 5, 7, 2);
		setBlock(world, i + 28, j + 24, k + 2, Blocks.leaves, 7);
		world.setBlockMetadataWithNotify(i + 28, j + 24, k + 2, 7, 2);
		setBlock(world, i + 28, j + 24, k + 3, Blocks.leaves, 7);
		world.setBlockMetadataWithNotify(i + 28, j + 24, k + 3, 7, 2);
		setBlock(world, i + 28, j + 24, k + 4, Blocks.leaves, 7);
		world.setBlockMetadataWithNotify(i + 28, j + 24, k + 4, 7, 2);
		setBlock(world, i + 28, j + 24, k + 19, Blocks.log, 3);
		world.setBlockMetadataWithNotify(i + 28, j + 24, k + 19, 3, 2);
		setBlock(world, i + 28, j + 25, k + 3, Blocks.leaves, 7);
		world.setBlockMetadataWithNotify(i + 28, j + 25, k + 3, 7, 2);
		setBlock(world, i + 28, j + 25, k + 18, Blocks.leaves, 7);
		world.setBlockMetadataWithNotify(i + 28, j + 25, k + 18, 7, 2);
		setBlock(world, i + 28, j + 25, k + 19, Blocks.leaves, 7);
		world.setBlockMetadataWithNotify(i + 28, j + 25, k + 19, 7, 2);
		setBlock(world, i + 28, j + 25, k + 20, Blocks.log, 3);
		world.setBlockMetadataWithNotify(i + 28, j + 25, k + 20, 3, 2);
		setBlock(world, i + 28, j + 25, k + 21, Blocks.leaves, 7);
		world.setBlockMetadataWithNotify(i + 28, j + 25, k + 21, 7, 2);
		setBlock(world, i + 28, j + 25, k + 22, Blocks.leaves, 7);
		world.setBlockMetadataWithNotify(i + 28, j + 25, k + 22, 7, 2);
		setBlock(world, i + 28, j + 26, k + 18, Blocks.leaves, 7);
		world.setBlockMetadataWithNotify(i + 28, j + 26, k + 18, 7, 2);
		setBlock(world, i + 28, j + 26, k + 19, Blocks.leaves, 7);
		world.setBlockMetadataWithNotify(i + 28, j + 26, k + 19, 7, 2);
		setBlock(world, i + 28, j + 26, k + 20, Blocks.leaves, 7);
		world.setBlockMetadataWithNotify(i + 28, j + 26, k + 20, 7, 2);
		setBlock(world, i + 28, j + 26, k + 21, Blocks.leaves, 7);
		world.setBlockMetadataWithNotify(i + 28, j + 26, k + 21, 7, 2);
		setBlock(world, i + 28, j + 26, k + 22, Blocks.leaves, 7);
		world.setBlockMetadataWithNotify(i + 28, j + 26, k + 22, 7, 2);
		setBlock(world, i + 28, j + 27, k + 19, Blocks.leaves, 7);
		world.setBlockMetadataWithNotify(i + 28, j + 27, k + 19, 7, 2);
		setBlock(world, i + 28, j + 27, k + 20, Blocks.leaves, 7);
		world.setBlockMetadataWithNotify(i + 28, j + 27, k + 20, 7, 2);
		setBlock(world, i + 28, j + 27, k + 21, Blocks.leaves, 7);
		world.setBlockMetadataWithNotify(i + 28, j + 27, k + 21, 7, 2);
		setBlock(world, i + 28, j + 28, k + 12, Blocks.log, 3);
		world.setBlockMetadataWithNotify(i + 28, j + 28, k + 12, 3, 2);
		setBlock(world, i + 28, j + 28, k + 20, Blocks.leaves, 7);
		world.setBlockMetadataWithNotify(i + 28, j + 28, k + 20, 7, 2);
		setBlock(world, i + 28, j + 31, k + 13, Blocks.leaves, 7);
		world.setBlockMetadataWithNotify(i + 28, j + 31, k + 13, 7, 2);
		setBlock(world, i + 28, j + 31, k + 14, Blocks.leaves, 7);
		world.setBlockMetadataWithNotify(i + 28, j + 31, k + 14, 7, 2);
		setBlock(world, i + 28, j + 31, k + 15, Blocks.leaves, 7);
		world.setBlockMetadataWithNotify(i + 28, j + 31, k + 15, 7, 2);
		setBlock(world, i + 28, j + 31, k + 19, Blocks.log, 3);
		world.setBlockMetadataWithNotify(i + 28, j + 31, k + 19, 3, 2);
		setBlock(world, i + 28, j + 32, k + 9, Blocks.log, 3);
		world.setBlockMetadataWithNotify(i + 28, j + 32, k + 9, 3, 2);
		setBlock(world, i + 28, j + 32, k + 14, Blocks.leaves, 7);
		world.setBlockMetadataWithNotify(i + 28, j + 32, k + 14, 7, 2);
		setBlock(world, i + 28, j + 32, k + 17, Blocks.leaves, 7);
		world.setBlockMetadataWithNotify(i + 28, j + 32, k + 17, 7, 2);
		setBlock(world, i + 28, j + 32, k + 18, Blocks.leaves, 7);
		world.setBlockMetadataWithNotify(i + 28, j + 32, k + 18, 7, 2);
		setBlock(world, i + 28, j + 32, k + 19, Blocks.leaves, 7);
		world.setBlockMetadataWithNotify(i + 28, j + 32, k + 19, 7, 2);
		setBlock(world, i + 28, j + 32, k + 20, Blocks.leaves, 7);
		world.setBlockMetadataWithNotify(i + 28, j + 32, k + 20, 7, 2);
		setBlock(world, i + 28, j + 32, k + 21, Blocks.leaves, 7);
		world.setBlockMetadataWithNotify(i + 28, j + 32, k + 21, 7, 2);
		setBlock(world, i + 28, j + 33, k + 0, Blocks.leaves, 7);
		world.setBlockMetadataWithNotify(i + 28, j + 33, k + 0, 7, 2);
		setBlock(world, i + 28, j + 33, k + 1, Blocks.leaves, 7);
		world.setBlockMetadataWithNotify(i + 28, j + 33, k + 1, 7, 2);
		setBlock(world, i + 28, j + 33, k + 2, Blocks.leaves, 7);
		world.setBlockMetadataWithNotify(i + 28, j + 33, k + 2, 7, 2);
		setBlock(world, i + 28, j + 33, k + 3, Blocks.leaves, 7);
		world.setBlockMetadataWithNotify(i + 28, j + 33, k + 3, 7, 2);
		setBlock(world, i + 28, j + 33, k + 18, Blocks.leaves, 7);
		world.setBlockMetadataWithNotify(i + 28, j + 33, k + 18, 7, 2);
		setBlock(world, i + 28, j + 33, k + 19, Blocks.leaves, 7);
		world.setBlockMetadataWithNotify(i + 28, j + 33, k + 19, 7, 2);
		setBlock(world, i + 28, j + 33, k + 20, Blocks.leaves, 7);
		world.setBlockMetadataWithNotify(i + 28, j + 33, k + 20, 7, 2);
		setBlock(world, i + 28, j + 34, k + 0, Blocks.leaves, 7);
		world.setBlockMetadataWithNotify(i + 28, j + 34, k + 0, 7, 2);
		setBlock(world, i + 28, j + 34, k + 1, Blocks.leaves, 7);
		world.setBlockMetadataWithNotify(i + 28, j + 34, k + 1, 7, 2);
		setBlock(world, i + 28, j + 34, k + 2, Blocks.log, 3);
		world.setBlockMetadataWithNotify(i + 28, j + 34, k + 2, 3, 2);
		setBlock(world, i + 28, j + 34, k + 4, Blocks.log, 3);
		world.setBlockMetadataWithNotify(i + 28, j + 34, k + 4, 3, 2);
		setBlock(world, i + 28, j + 34, k + 19, Blocks.leaves, 7);
		world.setBlockMetadataWithNotify(i + 28, j + 34, k + 19, 7, 2);
		setBlock(world, i + 28, j + 35, k + 0, Blocks.leaves, 7);
		world.setBlockMetadataWithNotify(i + 28, j + 35, k + 0, 7, 2);
		setBlock(world, i + 28, j + 35, k + 1, Blocks.leaves, 7);
		world.setBlockMetadataWithNotify(i + 28, j + 35, k + 1, 7, 2);
		setBlock(world, i + 28, j + 36, k + 0, Blocks.leaves, 7);
		world.setBlockMetadataWithNotify(i + 28, j + 36, k + 0, 7, 2);
		setBlock(world, i + 28, j + 39, k + 12, Blocks.leaves, 7);
		world.setBlockMetadataWithNotify(i + 28, j + 39, k + 12, 7, 2);
		setBlock(world, i + 28, j + 39, k + 13, Blocks.leaves, 7);
		world.setBlockMetadataWithNotify(i + 28, j + 39, k + 13, 7, 2);
		setBlock(world, i + 28, j + 39, k + 14, Blocks.leaves, 7);
		world.setBlockMetadataWithNotify(i + 28, j + 39, k + 14, 7, 2);
		setBlock(world, i + 28, j + 39, k + 15, Blocks.leaves, 7);
		world.setBlockMetadataWithNotify(i + 28, j + 39, k + 15, 7, 2);
		setBlock(world, i + 28, j + 39, k + 16, Blocks.leaves, 7);
		world.setBlockMetadataWithNotify(i + 28, j + 39, k + 16, 7, 2);
		setBlock(world, i + 28, j + 40, k + 13, Blocks.leaves, 7);
		world.setBlockMetadataWithNotify(i + 28, j + 40, k + 13, 7, 2);
		setBlock(world, i + 28, j + 40, k + 14, Blocks.leaves, 7);
		world.setBlockMetadataWithNotify(i + 28, j + 40, k + 14, 7, 2);
		setBlock(world, i + 28, j + 40, k + 15, Blocks.leaves, 7);
		world.setBlockMetadataWithNotify(i + 28, j + 40, k + 15, 7, 2);
		setBlock(world, i + 28, j + 41, k + 14, Blocks.leaves, 7);
		world.setBlockMetadataWithNotify(i + 28, j + 41, k + 14, 7, 2);
		setBlock(world, i + 28, j + 45, k + 2, Blocks.leaves, 7);
		world.setBlockMetadataWithNotify(i + 28, j + 45, k + 2, 7, 2);
		setBlock(world, i + 28, j + 45, k + 3, Blocks.leaves, 7);
		world.setBlockMetadataWithNotify(i + 28, j + 45, k + 3, 7, 2);
		setBlock(world, i + 28, j + 45, k + 4, Blocks.leaves, 7);
		world.setBlockMetadataWithNotify(i + 28, j + 45, k + 4, 7, 2);
		setBlock(world, i + 28, j + 45, k + 5, Blocks.leaves, 7);
		world.setBlockMetadataWithNotify(i + 28, j + 45, k + 5, 7, 2);
		setBlock(world, i + 28, j + 45, k + 6, Blocks.leaves, 7);
		world.setBlockMetadataWithNotify(i + 28, j + 45, k + 6, 7, 2);
		setBlock(world, i + 28, j + 46, k + 2, Blocks.leaves, 7);
		world.setBlockMetadataWithNotify(i + 28, j + 46, k + 2, 7, 2);
		setBlock(world, i + 28, j + 46, k + 3, Blocks.leaves, 7);
		world.setBlockMetadataWithNotify(i + 28, j + 46, k + 3, 7, 2);
		setBlock(world, i + 28, j + 46, k + 4, Blocks.leaves, 7);
		world.setBlockMetadataWithNotify(i + 28, j + 46, k + 4, 7, 2);
		setBlock(world, i + 28, j + 46, k + 5, Blocks.leaves, 7);
		world.setBlockMetadataWithNotify(i + 28, j + 46, k + 5, 7, 2);
		setBlock(world, i + 28, j + 47, k + 3, Blocks.leaves, 7);
		world.setBlockMetadataWithNotify(i + 28, j + 47, k + 3, 7, 2);
		setBlock(world, i + 28, j + 47, k + 4, Blocks.leaves, 7);
		world.setBlockMetadataWithNotify(i + 28, j + 47, k + 4, 7, 2);
		setBlock(world, i + 29, j + 18, k + 14, Blocks.log, 3);
		world.setBlockMetadataWithNotify(i + 29, j + 18, k + 14, 3, 2);
		setBlock(world, i + 29, j + 19, k + 13, Blocks.log, 3);
		world.setBlockMetadataWithNotify(i + 29, j + 19, k + 13, 3, 2);
		setBlock(world, i + 29, j + 19, k + 14, Blocks.log, 3);
		world.setBlockMetadataWithNotify(i + 29, j + 19, k + 14, 3, 2);
		setBlock(world, i + 29, j + 19, k + 15, Blocks.log, 3);
		world.setBlockMetadataWithNotify(i + 29, j + 19, k + 15, 3, 2);
		setBlock(world, i + 29, j + 20, k + 14, Blocks.log, 3);
		world.setBlockMetadataWithNotify(i + 29, j + 20, k + 14, 3, 2);
		setBlock(world, i + 29, j + 21, k + 4, Blocks.log, 3);
		world.setBlockMetadataWithNotify(i + 29, j + 21, k + 4, 3, 2);
		setBlock(world, i + 29, j + 21, k + 27, Blocks.leaves, 7);
		world.setBlockMetadataWithNotify(i + 29, j + 21, k + 27, 7, 2);
		setBlock(world, i + 29, j + 21, k + 28, Blocks.leaves, 7);
		world.setBlockMetadataWithNotify(i + 29, j + 21, k + 28, 7, 2);
		setBlock(world, i + 29, j + 21, k + 29, Blocks.leaves, 7);
		world.setBlockMetadataWithNotify(i + 29, j + 21, k + 29, 7, 2);
		setBlock(world, i + 29, j + 22, k + 1, Blocks.leaves, 7);
		world.setBlockMetadataWithNotify(i + 29, j + 22, k + 1, 7, 2);
		setBlock(world, i + 29, j + 22, k + 2, Blocks.leaves, 7);
		world.setBlockMetadataWithNotify(i + 29, j + 22, k + 2, 7, 2);
		setBlock(world, i + 29, j + 22, k + 3, Blocks.leaves, 7);
		world.setBlockMetadataWithNotify(i + 29, j + 22, k + 3, 7, 2);
		setBlock(world, i + 29, j + 22, k + 4, Blocks.leaves, 7);
		world.setBlockMetadataWithNotify(i + 29, j + 22, k + 4, 7, 2);
		setBlock(world, i + 29, j + 22, k + 5, Blocks.log, 3);
		world.setBlockMetadataWithNotify(i + 29, j + 22, k + 5, 3, 2);
		setBlock(world, i + 29, j + 22, k + 28, Blocks.leaves, 7);
		world.setBlockMetadataWithNotify(i + 29, j + 22, k + 28, 7, 2);
		setBlock(world, i + 29, j + 23, k + 1, Blocks.log, 3);
		world.setBlockMetadataWithNotify(i + 29, j + 23, k + 1, 3, 2);
		setBlock(world, i + 29, j + 23, k + 2, Blocks.leaves, 7);
		world.setBlockMetadataWithNotify(i + 29, j + 23, k + 2, 7, 2);
		setBlock(world, i + 29, j + 23, k + 3, Blocks.leaves, 7);
		world.setBlockMetadataWithNotify(i + 29, j + 23, k + 3, 7, 2);
		setBlock(world, i + 29, j + 23, k + 4, Blocks.leaves, 7);
		world.setBlockMetadataWithNotify(i + 29, j + 23, k + 4, 7, 2);
		setBlock(world, i + 29, j + 24, k + 3, Blocks.leaves, 7);
		world.setBlockMetadataWithNotify(i + 29, j + 24, k + 3, 7, 2);
		setBlock(world, i + 29, j + 24, k + 18, Blocks.log, 3);
		world.setBlockMetadataWithNotify(i + 29, j + 24, k + 18, 3, 2);
		setBlock(world, i + 29, j + 25, k + 18, Blocks.leaves, 7);
		world.setBlockMetadataWithNotify(i + 29, j + 25, k + 18, 7, 2);
		setBlock(world, i + 29, j + 25, k + 19, Blocks.leaves, 7);
		world.setBlockMetadataWithNotify(i + 29, j + 25, k + 19, 7, 2);
		setBlock(world, i + 29, j + 25, k + 20, Blocks.leaves, 7);
		world.setBlockMetadataWithNotify(i + 29, j + 25, k + 20, 7, 2);
		setBlock(world, i + 29, j + 25, k + 21, Blocks.leaves, 7);
		world.setBlockMetadataWithNotify(i + 29, j + 25, k + 21, 7, 2);
		setBlock(world, i + 29, j + 25, k + 22, Blocks.leaves, 7);
		world.setBlockMetadataWithNotify(i + 29, j + 25, k + 22, 7, 2);
		setBlock(world, i + 29, j + 26, k + 19, Blocks.leaves, 7);
		world.setBlockMetadataWithNotify(i + 29, j + 26, k + 19, 7, 2);
		setBlock(world, i + 29, j + 26, k + 20, Blocks.leaves, 7);
		world.setBlockMetadataWithNotify(i + 29, j + 26, k + 20, 7, 2);
		setBlock(world, i + 29, j + 26, k + 21, Blocks.leaves, 7);
		world.setBlockMetadataWithNotify(i + 29, j + 26, k + 21, 7, 2);
		setBlock(world, i + 29, j + 27, k + 20, Blocks.leaves, 7);
		world.setBlockMetadataWithNotify(i + 29, j + 27, k + 20, 7, 2);
		setBlock(world, i + 29, j + 28, k + 11, Blocks.log, 3);
		world.setBlockMetadataWithNotify(i + 29, j + 28, k + 11, 3, 2);
		setBlock(world, i + 29, j + 28, k + 12, Blocks.log, 3);
		world.setBlockMetadataWithNotify(i + 29, j + 28, k + 12, 3, 2);
		setBlock(world, i + 29, j + 31, k + 12, Blocks.leaves, 7);
		world.setBlockMetadataWithNotify(i + 29, j + 31, k + 12, 7, 2);
		setBlock(world, i + 29, j + 31, k + 13, Blocks.leaves, 7);
		world.setBlockMetadataWithNotify(i + 29, j + 31, k + 13, 7, 2);
		setBlock(world, i + 29, j + 31, k + 14, Blocks.leaves, 7);
		world.setBlockMetadataWithNotify(i + 29, j + 31, k + 14, 7, 2);
		setBlock(world, i + 29, j + 31, k + 15, Blocks.leaves, 7);
		world.setBlockMetadataWithNotify(i + 29, j + 31, k + 15, 7, 2);
		setBlock(world, i + 29, j + 31, k + 16, Blocks.leaves, 7);
		world.setBlockMetadataWithNotify(i + 29, j + 31, k + 16, 7, 2);
		setBlock(world, i + 29, j + 31, k + 18, Blocks.log, 3);
		world.setBlockMetadataWithNotify(i + 29, j + 31, k + 18, 3, 2);
		setBlock(world, i + 29, j + 32, k + 9, Blocks.log, 3);
		world.setBlockMetadataWithNotify(i + 29, j + 32, k + 9, 3, 2);
		setBlock(world, i + 29, j + 32, k + 13, Blocks.leaves, 7);
		world.setBlockMetadataWithNotify(i + 29, j + 32, k + 13, 7, 2);
		setBlock(world, i + 29, j + 32, k + 14, Blocks.leaves, 7);
		world.setBlockMetadataWithNotify(i + 29, j + 32, k + 14, 7, 2);
		setBlock(world, i + 29, j + 32, k + 15, Blocks.leaves, 7);
		world.setBlockMetadataWithNotify(i + 29, j + 32, k + 15, 7, 2);
		setBlock(world, i + 29, j + 32, k + 18, Blocks.leaves, 7);
		world.setBlockMetadataWithNotify(i + 29, j + 32, k + 18, 7, 2);
		setBlock(world, i + 29, j + 32, k + 19, Blocks.leaves, 7);
		world.setBlockMetadataWithNotify(i + 29, j + 32, k + 19, 7, 2);
		setBlock(world, i + 29, j + 32, k + 20, Blocks.leaves, 7);
		world.setBlockMetadataWithNotify(i + 29, j + 32, k + 20, 7, 2);
		setBlock(world, i + 29, j + 33, k + 0, Blocks.leaves, 7);
		world.setBlockMetadataWithNotify(i + 29, j + 33, k + 0, 7, 2);
		setBlock(world, i + 29, j + 33, k + 1, Blocks.log, 3);
		world.setBlockMetadataWithNotify(i + 29, j + 33, k + 1, 3, 2);
		setBlock(world, i + 29, j + 33, k + 2, Blocks.leaves, 7);
		world.setBlockMetadataWithNotify(i + 29, j + 33, k + 2, 7, 2);
		setBlock(world, i + 29, j + 33, k + 3, Blocks.leaves, 7);
		world.setBlockMetadataWithNotify(i + 29, j + 33, k + 3, 7, 2);
		setBlock(world, i + 29, j + 33, k + 4, Blocks.log, 3);
		world.setBlockMetadataWithNotify(i + 29, j + 33, k + 4, 3, 2);
		setBlock(world, i + 29, j + 33, k + 14, Blocks.leaves, 7);
		world.setBlockMetadataWithNotify(i + 29, j + 33, k + 14, 7, 2);
		setBlock(world, i + 29, j + 33, k + 19, Blocks.leaves, 7);
		world.setBlockMetadataWithNotify(i + 29, j + 33, k + 19, 7, 2);
		setBlock(world, i + 29, j + 34, k + 0, Blocks.leaves, 7);
		world.setBlockMetadataWithNotify(i + 29, j + 34, k + 0, 7, 2);
		setBlock(world, i + 29, j + 34, k + 1, Blocks.leaves, 7);
		world.setBlockMetadataWithNotify(i + 29, j + 34, k + 1, 7, 2);
		setBlock(world, i + 29, j + 34, k + 2, Blocks.log, 3);
		world.setBlockMetadataWithNotify(i + 29, j + 34, k + 2, 3, 2);
		setBlock(world, i + 29, j + 34, k + 3, Blocks.leaves, 7);
		world.setBlockMetadataWithNotify(i + 29, j + 34, k + 3, 7, 2);
		setBlock(world, i + 29, j + 35, k + 0, Blocks.leaves, 7);
		world.setBlockMetadataWithNotify(i + 29, j + 35, k + 0, 7, 2);
		setBlock(world, i + 29, j + 35, k + 1, Blocks.leaves, 7);
		world.setBlockMetadataWithNotify(i + 29, j + 35, k + 1, 7, 2);
		setBlock(world, i + 29, j + 35, k + 2, Blocks.leaves, 7);
		world.setBlockMetadataWithNotify(i + 29, j + 35, k + 2, 7, 2);
		setBlock(world, i + 29, j + 36, k + 1, Blocks.leaves, 7);
		world.setBlockMetadataWithNotify(i + 29, j + 36, k + 1, 7, 2);
		setBlock(world, i + 29, j + 39, k + 12, Blocks.leaves, 7);
		world.setBlockMetadataWithNotify(i + 29, j + 39, k + 12, 7, 2);
		setBlock(world, i + 29, j + 39, k + 13, Blocks.leaves, 7);
		world.setBlockMetadataWithNotify(i + 29, j + 39, k + 13, 7, 2);
		setBlock(world, i + 29, j + 39, k + 14, Blocks.log, 3);
		world.setBlockMetadataWithNotify(i + 29, j + 39, k + 14, 3, 2);
		setBlock(world, i + 29, j + 39, k + 15, Blocks.leaves, 7);
		world.setBlockMetadataWithNotify(i + 29, j + 39, k + 15, 7, 2);
		setBlock(world, i + 29, j + 39, k + 16, Blocks.leaves, 7);
		world.setBlockMetadataWithNotify(i + 29, j + 39, k + 16, 7, 2);
		setBlock(world, i + 29, j + 40, k + 12, Blocks.leaves, 7);
		world.setBlockMetadataWithNotify(i + 29, j + 40, k + 12, 7, 2);
		setBlock(world, i + 29, j + 40, k + 13, Blocks.leaves, 7);
		world.setBlockMetadataWithNotify(i + 29, j + 40, k + 13, 7, 2);
		setBlock(world, i + 29, j + 40, k + 14, Blocks.leaves, 7);
		world.setBlockMetadataWithNotify(i + 29, j + 40, k + 14, 7, 2);
		setBlock(world, i + 29, j + 40, k + 15, Blocks.leaves, 7);
		world.setBlockMetadataWithNotify(i + 29, j + 40, k + 15, 7, 2);
		setBlock(world, i + 29, j + 40, k + 16, Blocks.leaves, 7);
		world.setBlockMetadataWithNotify(i + 29, j + 40, k + 16, 7, 2);
		setBlock(world, i + 29, j + 41, k + 13, Blocks.leaves, 7);
		world.setBlockMetadataWithNotify(i + 29, j + 41, k + 13, 7, 2);
		setBlock(world, i + 29, j + 41, k + 14, Blocks.leaves, 7);
		world.setBlockMetadataWithNotify(i + 29, j + 41, k + 14, 7, 2);
		setBlock(world, i + 29, j + 41, k + 15, Blocks.leaves, 7);
		world.setBlockMetadataWithNotify(i + 29, j + 41, k + 15, 7, 2);
		setBlock(world, i + 29, j + 42, k + 14, Blocks.leaves, 7);
		world.setBlockMetadataWithNotify(i + 29, j + 42, k + 14, 7, 2);
		setBlock(world, i + 29, j + 45, k + 2, Blocks.leaves, 7);
		world.setBlockMetadataWithNotify(i + 29, j + 45, k + 2, 7, 2);
		setBlock(world, i + 29, j + 45, k + 3, Blocks.leaves, 7);
		world.setBlockMetadataWithNotify(i + 29, j + 45, k + 3, 7, 2);
		setBlock(world, i + 29, j + 45, k + 4, Blocks.log, 3);
		world.setBlockMetadataWithNotify(i + 29, j + 45, k + 4, 3, 2);
		setBlock(world, i + 29, j + 45, k + 5, Blocks.leaves, 7);
		world.setBlockMetadataWithNotify(i + 29, j + 45, k + 5, 7, 2);
		setBlock(world, i + 29, j + 45, k + 6, Blocks.leaves, 7);
		world.setBlockMetadataWithNotify(i + 29, j + 45, k + 6, 7, 2);
		setBlock(world, i + 29, j + 46, k + 1, Blocks.leaves, 7);
		world.setBlockMetadataWithNotify(i + 29, j + 46, k + 1, 7, 2);
		setBlock(world, i + 29, j + 46, k + 2, Blocks.leaves, 7);
		world.setBlockMetadataWithNotify(i + 29, j + 46, k + 2, 7, 2);
		setBlock(world, i + 29, j + 46, k + 3, Blocks.leaves, 7);
		world.setBlockMetadataWithNotify(i + 29, j + 46, k + 3, 7, 2);
		setBlock(world, i + 29, j + 46, k + 4, Blocks.leaves, 7);
		world.setBlockMetadataWithNotify(i + 29, j + 46, k + 4, 7, 2);
		setBlock(world, i + 29, j + 46, k + 5, Blocks.leaves, 7);
		world.setBlockMetadataWithNotify(i + 29, j + 46, k + 5, 7, 2);
		setBlock(world, i + 29, j + 46, k + 6, Blocks.leaves, 7);
		world.setBlockMetadataWithNotify(i + 29, j + 46, k + 6, 7, 2);
		setBlock(world, i + 29, j + 47, k + 2, Blocks.leaves, 7);
		world.setBlockMetadataWithNotify(i + 29, j + 47, k + 2, 7, 2);
		setBlock(world, i + 29, j + 47, k + 3, Blocks.leaves, 7);
		world.setBlockMetadataWithNotify(i + 29, j + 47, k + 3, 7, 2);
		setBlock(world, i + 29, j + 47, k + 4, Blocks.leaves, 7);
		world.setBlockMetadataWithNotify(i + 29, j + 47, k + 4, 7, 2);
		setBlock(world, i + 29, j + 47, k + 5, Blocks.leaves, 7);
		world.setBlockMetadataWithNotify(i + 29, j + 47, k + 5, 7, 2);
		setBlock(world, i + 29, j + 48, k + 3, Blocks.leaves, 7);
		world.setBlockMetadataWithNotify(i + 29, j + 48, k + 3, 7, 2);
		setBlock(world, i + 29, j + 48, k + 4, Blocks.leaves, 7);
		world.setBlockMetadataWithNotify(i + 29, j + 48, k + 4, 7, 2);
		setBlock(world, i + 29, j + 49, k + 1, Blocks.leaves, 7);
		world.setBlockMetadataWithNotify(i + 29, j + 49, k + 1, 7, 2);
		setBlock(world, i + 29, j + 49, k + 2, Blocks.leaves, 7);
		world.setBlockMetadataWithNotify(i + 29, j + 49, k + 2, 7, 2);
		setBlock(world, i + 29, j + 49, k + 3, Blocks.leaves, 7);
		world.setBlockMetadataWithNotify(i + 29, j + 49, k + 3, 7, 2);
		setBlock(world, i + 29, j + 50, k + 2, Blocks.leaves, 7);
		world.setBlockMetadataWithNotify(i + 29, j + 50, k + 2, 7, 2);
		setBlock(world, i + 29, j + 51, k + 10, Blocks.leaves, 7);
		world.setBlockMetadataWithNotify(i + 29, j + 51, k + 10, 7, 2);
		setBlock(world, i + 29, j + 51, k + 11, Blocks.leaves, 7);
		world.setBlockMetadataWithNotify(i + 29, j + 51, k + 11, 7, 2);
		setBlock(world, i + 29, j + 51, k + 12, Blocks.leaves, 7);
		world.setBlockMetadataWithNotify(i + 29, j + 51, k + 12, 7, 2);
		setBlock(world, i + 29, j + 52, k + 11, Blocks.leaves, 7);
		world.setBlockMetadataWithNotify(i + 29, j + 52, k + 11, 7, 2);
		setBlock(world, i + 30, j + 17, k + 14, Blocks.log, 3);
		world.setBlockMetadataWithNotify(i + 30, j + 17, k + 14, 3, 2);
		setBlock(world, i + 30, j + 18, k + 13, Blocks.log, 3);
		world.setBlockMetadataWithNotify(i + 30, j + 18, k + 13, 3, 2);
		setBlock(world, i + 30, j + 18, k + 14, Blocks.log, 3);
		world.setBlockMetadataWithNotify(i + 30, j + 18, k + 14, 3, 2);
		setBlock(world, i + 30, j + 18, k + 15, Blocks.log, 3);
		world.setBlockMetadataWithNotify(i + 30, j + 18, k + 15, 3, 2);
		setBlock(world, i + 30, j + 19, k + 14, Blocks.log, 3);
		world.setBlockMetadataWithNotify(i + 30, j + 19, k + 14, 3, 2);
		setBlock(world, i + 30, j + 21, k + 2, Blocks.log, 3);
		world.setBlockMetadataWithNotify(i + 30, j + 21, k + 2, 3, 2);
		setBlock(world, i + 30, j + 21, k + 4, Blocks.log, 3);
		world.setBlockMetadataWithNotify(i + 30, j + 21, k + 4, 3, 2);
		setBlock(world, i + 30, j + 21, k + 6, Blocks.log, 3);
		world.setBlockMetadataWithNotify(i + 30, j + 21, k + 6, 3, 2);
		setBlock(world, i + 30, j + 21, k + 26, Blocks.leaves, 7);
		world.setBlockMetadataWithNotify(i + 30, j + 21, k + 26, 7, 2);
		setBlock(world, i + 30, j + 21, k + 27, Blocks.leaves, 7);
		world.setBlockMetadataWithNotify(i + 30, j + 21, k + 27, 7, 2);
		setBlock(world, i + 30, j + 21, k + 28, Blocks.leaves, 7);
		world.setBlockMetadataWithNotify(i + 30, j + 21, k + 28, 7, 2);
		setBlock(world, i + 30, j + 21, k + 29, Blocks.leaves, 7);
		world.setBlockMetadataWithNotify(i + 30, j + 21, k + 29, 7, 2);
		setBlock(world, i + 30, j + 21, k + 30, Blocks.leaves, 7);
		world.setBlockMetadataWithNotify(i + 30, j + 21, k + 30, 7, 2);
		setBlock(world, i + 30, j + 22, k + 1, Blocks.log, 3);
		world.setBlockMetadataWithNotify(i + 30, j + 22, k + 1, 3, 2);
		setBlock(world, i + 30, j + 22, k + 2, Blocks.log, 3);
		world.setBlockMetadataWithNotify(i + 30, j + 22, k + 2, 3, 2);
		setBlock(world, i + 30, j + 22, k + 3, Blocks.log, 3);
		world.setBlockMetadataWithNotify(i + 30, j + 22, k + 3, 3, 2);
		setBlock(world, i + 30, j + 22, k + 4, Blocks.leaves, 7);
		world.setBlockMetadataWithNotify(i + 30, j + 22, k + 4, 7, 2);
		setBlock(world, i + 30, j + 22, k + 27, Blocks.leaves, 7);
		world.setBlockMetadataWithNotify(i + 30, j + 22, k + 27, 7, 2);
		setBlock(world, i + 30, j + 22, k + 28, Blocks.leaves, 7);
		world.setBlockMetadataWithNotify(i + 30, j + 22, k + 28, 7, 2);
		setBlock(world, i + 30, j + 22, k + 29, Blocks.leaves, 7);
		world.setBlockMetadataWithNotify(i + 30, j + 22, k + 29, 7, 2);
		setBlock(world, i + 30, j + 23, k + 2, Blocks.log, 3);
		world.setBlockMetadataWithNotify(i + 30, j + 23, k + 2, 3, 2);
		setBlock(world, i + 30, j + 23, k + 3, Blocks.leaves, 7);
		world.setBlockMetadataWithNotify(i + 30, j + 23, k + 3, 7, 2);
		setBlock(world, i + 30, j + 23, k + 28, Blocks.leaves, 7);
		world.setBlockMetadataWithNotify(i + 30, j + 23, k + 28, 7, 2);
		setBlock(world, i + 30, j + 24, k + 17, Blocks.log, 3);
		world.setBlockMetadataWithNotify(i + 30, j + 24, k + 17, 3, 2);
		setBlock(world, i + 30, j + 25, k + 19, Blocks.leaves, 7);
		world.setBlockMetadataWithNotify(i + 30, j + 25, k + 19, 7, 2);
		setBlock(world, i + 30, j + 25, k + 20, Blocks.leaves, 7);
		world.setBlockMetadataWithNotify(i + 30, j + 25, k + 20, 7, 2);
		setBlock(world, i + 30, j + 25, k + 21, Blocks.leaves, 7);
		world.setBlockMetadataWithNotify(i + 30, j + 25, k + 21, 7, 2);
		setBlock(world, i + 30, j + 26, k + 20, Blocks.leaves, 7);
		world.setBlockMetadataWithNotify(i + 30, j + 26, k + 20, 7, 2);
		setBlock(world, i + 30, j + 27, k + 11, Blocks.log, 3);
		world.setBlockMetadataWithNotify(i + 30, j + 27, k + 11, 3, 2);
		setBlock(world, i + 30, j + 28, k + 11, Blocks.log, 3);
		world.setBlockMetadataWithNotify(i + 30, j + 28, k + 11, 3, 2);
		setBlock(world, i + 30, j + 31, k + 9, Blocks.log, 3);
		world.setBlockMetadataWithNotify(i + 30, j + 31, k + 9, 3, 2);
		setBlock(world, i + 30, j + 31, k + 12, Blocks.leaves, 7);
		world.setBlockMetadataWithNotify(i + 30, j + 31, k + 12, 7, 2);
		setBlock(world, i + 30, j + 31, k + 13, Blocks.leaves, 7);
		world.setBlockMetadataWithNotify(i + 30, j + 31, k + 13, 7, 2);
		setBlock(world, i + 30, j + 31, k + 14, Blocks.log, 3);
		world.setBlockMetadataWithNotify(i + 30, j + 31, k + 14, 3, 2);
		setBlock(world, i + 30, j + 31, k + 15, Blocks.leaves, 7);
		world.setBlockMetadataWithNotify(i + 30, j + 31, k + 15, 7, 2);
		setBlock(world, i + 30, j + 31, k + 16, Blocks.leaves, 7);
		world.setBlockMetadataWithNotify(i + 30, j + 31, k + 16, 7, 2);
		setBlock(world, i + 30, j + 31, k + 18, Blocks.log, 3);
		world.setBlockMetadataWithNotify(i + 30, j + 31, k + 18, 3, 2);
		setBlock(world, i + 30, j + 32, k + 2, Blocks.log, 3);
		world.setBlockMetadataWithNotify(i + 30, j + 32, k + 2, 3, 2);
		setBlock(world, i + 30, j + 32, k + 12, Blocks.leaves, 7);
		world.setBlockMetadataWithNotify(i + 30, j + 32, k + 12, 7, 2);
		setBlock(world, i + 30, j + 32, k + 13, Blocks.leaves, 7);
		world.setBlockMetadataWithNotify(i + 30, j + 32, k + 13, 7, 2);
		setBlock(world, i + 30, j + 32, k + 14, Blocks.leaves, 7);
		world.setBlockMetadataWithNotify(i + 30, j + 32, k + 14, 7, 2);
		setBlock(world, i + 30, j + 32, k + 15, Blocks.leaves, 7);
		world.setBlockMetadataWithNotify(i + 30, j + 32, k + 15, 7, 2);
		setBlock(world, i + 30, j + 32, k + 16, Blocks.leaves, 7);
		world.setBlockMetadataWithNotify(i + 30, j + 32, k + 16, 7, 2);
		setBlock(world, i + 30, j + 33, k + 0, Blocks.leaves, 7);
		world.setBlockMetadataWithNotify(i + 30, j + 33, k + 0, 7, 2);
		setBlock(world, i + 30, j + 33, k + 1, Blocks.leaves, 7);
		world.setBlockMetadataWithNotify(i + 30, j + 33, k + 1, 7, 2);
		setBlock(world, i + 30, j + 33, k + 2, Blocks.leaves, 7);
		world.setBlockMetadataWithNotify(i + 30, j + 33, k + 2, 7, 2);
		setBlock(world, i + 30, j + 33, k + 3, Blocks.leaves, 7);
		world.setBlockMetadataWithNotify(i + 30, j + 33, k + 3, 7, 2);
		setBlock(world, i + 30, j + 33, k + 5, Blocks.log, 3);
		world.setBlockMetadataWithNotify(i + 30, j + 33, k + 5, 3, 2);
		setBlock(world, i + 30, j + 33, k + 13, Blocks.leaves, 7);
		world.setBlockMetadataWithNotify(i + 30, j + 33, k + 13, 7, 2);
		setBlock(world, i + 30, j + 33, k + 14, Blocks.leaves, 7);
		world.setBlockMetadataWithNotify(i + 30, j + 33, k + 14, 7, 2);
		setBlock(world, i + 30, j + 33, k + 15, Blocks.leaves, 7);
		world.setBlockMetadataWithNotify(i + 30, j + 33, k + 15, 7, 2);
		setBlock(world, i + 30, j + 34, k + 0, Blocks.leaves, 7);
		world.setBlockMetadataWithNotify(i + 30, j + 34, k + 0, 7, 2);
		setBlock(world, i + 30, j + 34, k + 1, Blocks.leaves, 7);
		world.setBlockMetadataWithNotify(i + 30, j + 34, k + 1, 7, 2);
		setBlock(world, i + 30, j + 34, k + 2, Blocks.leaves, 7);
		world.setBlockMetadataWithNotify(i + 30, j + 34, k + 2, 7, 2);
		setBlock(world, i + 30, j + 34, k + 3, Blocks.log, 3);
		world.setBlockMetadataWithNotify(i + 30, j + 34, k + 3, 3, 2);
		setBlock(world, i + 30, j + 34, k + 14, Blocks.leaves, 7);
		world.setBlockMetadataWithNotify(i + 30, j + 34, k + 14, 7, 2);
		setBlock(world, i + 30, j + 35, k + 1, Blocks.leaves, 7);
		world.setBlockMetadataWithNotify(i + 30, j + 35, k + 1, 7, 2);
		setBlock(world, i + 30, j + 38, k + 14, Blocks.log, 3);
		world.setBlockMetadataWithNotify(i + 30, j + 38, k + 14, 3, 2);
		setBlock(world, i + 30, j + 39, k + 7, Blocks.leaves, 7);
		world.setBlockMetadataWithNotify(i + 30, j + 39, k + 7, 7, 2);
		setBlock(world, i + 30, j + 39, k + 8, Blocks.leaves, 7);
		world.setBlockMetadataWithNotify(i + 30, j + 39, k + 8, 7, 2);
		setBlock(world, i + 30, j + 39, k + 9, Blocks.leaves, 7);
		world.setBlockMetadataWithNotify(i + 30, j + 39, k + 9, 7, 2);
		setBlock(world, i + 30, j + 39, k + 12, Blocks.leaves, 7);
		world.setBlockMetadataWithNotify(i + 30, j + 39, k + 12, 7, 2);
		setBlock(world, i + 30, j + 39, k + 13, Blocks.leaves, 7);
		world.setBlockMetadataWithNotify(i + 30, j + 39, k + 13, 7, 2);
		setBlock(world, i + 30, j + 39, k + 14, Blocks.leaves, 7);
		world.setBlockMetadataWithNotify(i + 30, j + 39, k + 14, 7, 2);
		setBlock(world, i + 30, j + 39, k + 15, Blocks.leaves, 7);
		world.setBlockMetadataWithNotify(i + 30, j + 39, k + 15, 7, 2);
		setBlock(world, i + 30, j + 39, k + 16, Blocks.leaves, 7);
		world.setBlockMetadataWithNotify(i + 30, j + 39, k + 16, 7, 2);
		setBlock(world, i + 30, j + 40, k + 8, Blocks.leaves, 7);
		world.setBlockMetadataWithNotify(i + 30, j + 40, k + 8, 7, 2);
		setBlock(world, i + 30, j + 40, k + 13, Blocks.leaves, 7);
		world.setBlockMetadataWithNotify(i + 30, j + 40, k + 13, 7, 2);
		setBlock(world, i + 30, j + 40, k + 14, Blocks.leaves, 7);
		world.setBlockMetadataWithNotify(i + 30, j + 40, k + 14, 7, 2);
		setBlock(world, i + 30, j + 40, k + 15, Blocks.leaves, 7);
		world.setBlockMetadataWithNotify(i + 30, j + 40, k + 15, 7, 2);
		setBlock(world, i + 30, j + 41, k + 14, Blocks.leaves, 7);
		world.setBlockMetadataWithNotify(i + 30, j + 41, k + 14, 7, 2);
		setBlock(world, i + 30, j + 42, k + 18, Blocks.leaves, 7);
		world.setBlockMetadataWithNotify(i + 30, j + 42, k + 18, 7, 2);
		setBlock(world, i + 30, j + 42, k + 19, Blocks.leaves, 7);
		world.setBlockMetadataWithNotify(i + 30, j + 42, k + 19, 7, 2);
		setBlock(world, i + 30, j + 42, k + 20, Blocks.leaves, 7);
		world.setBlockMetadataWithNotify(i + 30, j + 42, k + 20, 7, 2);
		setBlock(world, i + 30, j + 43, k + 19, Blocks.leaves, 7);
		world.setBlockMetadataWithNotify(i + 30, j + 43, k + 19, 7, 2);
		setBlock(world, i + 30, j + 44, k + 5, Blocks.log, 3);
		world.setBlockMetadataWithNotify(i + 30, j + 44, k + 5, 3, 2);
		setBlock(world, i + 30, j + 45, k + 2, Blocks.leaves, 7);
		world.setBlockMetadataWithNotify(i + 30, j + 45, k + 2, 7, 2);
		setBlock(world, i + 30, j + 45, k + 3, Blocks.leaves, 7);
		world.setBlockMetadataWithNotify(i + 30, j + 45, k + 3, 7, 2);
		setBlock(world, i + 30, j + 45, k + 4, Blocks.leaves, 7);
		world.setBlockMetadataWithNotify(i + 30, j + 45, k + 4, 7, 2);
		setBlock(world, i + 30, j + 45, k + 5, Blocks.leaves, 7);
		world.setBlockMetadataWithNotify(i + 30, j + 45, k + 5, 7, 2);
		setBlock(world, i + 30, j + 45, k + 6, Blocks.leaves, 7);
		world.setBlockMetadataWithNotify(i + 30, j + 45, k + 6, 7, 2);
		setBlock(world, i + 30, j + 46, k + 1, Blocks.leaves, 7);
		world.setBlockMetadataWithNotify(i + 30, j + 46, k + 1, 7, 2);
		setBlock(world, i + 30, j + 46, k + 2, Blocks.leaves, 7);
		world.setBlockMetadataWithNotify(i + 30, j + 46, k + 2, 7, 2);
		setBlock(world, i + 30, j + 46, k + 3, Blocks.log, 3);
		world.setBlockMetadataWithNotify(i + 30, j + 46, k + 3, 3, 2);
		setBlock(world, i + 30, j + 46, k + 4, Blocks.leaves, 7);
		world.setBlockMetadataWithNotify(i + 30, j + 46, k + 4, 7, 2);
		setBlock(world, i + 30, j + 46, k + 5, Blocks.leaves, 7);
		world.setBlockMetadataWithNotify(i + 30, j + 46, k + 5, 7, 2);
		setBlock(world, i + 30, j + 47, k + 1, Blocks.leaves, 7);
		world.setBlockMetadataWithNotify(i + 30, j + 47, k + 1, 7, 2);
		setBlock(world, i + 30, j + 47, k + 2, Blocks.leaves, 7);
		world.setBlockMetadataWithNotify(i + 30, j + 47, k + 2, 7, 2);
		setBlock(world, i + 30, j + 47, k + 3, Blocks.leaves, 7);
		world.setBlockMetadataWithNotify(i + 30, j + 47, k + 3, 7, 2);
		setBlock(world, i + 30, j + 47, k + 4, Blocks.leaves, 7);
		world.setBlockMetadataWithNotify(i + 30, j + 47, k + 4, 7, 2);
		setBlock(world, i + 30, j + 47, k + 5, Blocks.leaves, 7);
		world.setBlockMetadataWithNotify(i + 30, j + 47, k + 5, 7, 2);
		setBlock(world, i + 30, j + 48, k + 2, Blocks.leaves, 7);
		world.setBlockMetadataWithNotify(i + 30, j + 48, k + 2, 7, 2);
		setBlock(world, i + 30, j + 48, k + 3, Blocks.leaves, 7);
		world.setBlockMetadataWithNotify(i + 30, j + 48, k + 3, 7, 2);
		setBlock(world, i + 30, j + 48, k + 4, Blocks.leaves, 7);
		world.setBlockMetadataWithNotify(i + 30, j + 48, k + 4, 7, 2);
		setBlock(world, i + 30, j + 49, k + 0, Blocks.leaves, 7);
		world.setBlockMetadataWithNotify(i + 30, j + 49, k + 0, 7, 2);
		setBlock(world, i + 30, j + 49, k + 1, Blocks.leaves, 7);
		world.setBlockMetadataWithNotify(i + 30, j + 49, k + 1, 7, 2);
		setBlock(world, i + 30, j + 49, k + 2, Blocks.leaves, 7);
		world.setBlockMetadataWithNotify(i + 30, j + 49, k + 2, 7, 2);
		setBlock(world, i + 30, j + 49, k + 3, Blocks.leaves, 7);
		world.setBlockMetadataWithNotify(i + 30, j + 49, k + 3, 7, 2);
		setBlock(world, i + 30, j + 49, k + 4, Blocks.leaves, 7);
		world.setBlockMetadataWithNotify(i + 30, j + 49, k + 4, 7, 2);
		setBlock(world, i + 30, j + 50, k + 1, Blocks.leaves, 7);
		world.setBlockMetadataWithNotify(i + 30, j + 50, k + 1, 7, 2);
		setBlock(world, i + 30, j + 50, k + 2, Blocks.leaves, 7);
		world.setBlockMetadataWithNotify(i + 30, j + 50, k + 2, 7, 2);
		setBlock(world, i + 30, j + 50, k + 3, Blocks.leaves, 7);
		world.setBlockMetadataWithNotify(i + 30, j + 50, k + 3, 7, 2);
		setBlock(world, i + 30, j + 51, k + 2, Blocks.leaves, 7);
		world.setBlockMetadataWithNotify(i + 30, j + 51, k + 2, 7, 2);
		setBlock(world, i + 30, j + 51, k + 9, Blocks.leaves, 7);
		world.setBlockMetadataWithNotify(i + 30, j + 51, k + 9, 7, 2);
		setBlock(world, i + 30, j + 51, k + 10, Blocks.leaves, 7);
		world.setBlockMetadataWithNotify(i + 30, j + 51, k + 10, 7, 2);
		setBlock(world, i + 30, j + 51, k + 11, Blocks.leaves, 7);
		world.setBlockMetadataWithNotify(i + 30, j + 51, k + 11, 7, 2);
		setBlock(world, i + 30, j + 51, k + 12, Blocks.leaves, 7);
		world.setBlockMetadataWithNotify(i + 30, j + 51, k + 12, 7, 2);
		setBlock(world, i + 30, j + 51, k + 13, Blocks.leaves, 7);
		world.setBlockMetadataWithNotify(i + 30, j + 51, k + 13, 7, 2);
		setBlock(world, i + 30, j + 52, k + 10, Blocks.leaves, 7);
		world.setBlockMetadataWithNotify(i + 30, j + 52, k + 10, 7, 2);
		setBlock(world, i + 30, j + 52, k + 11, Blocks.leaves, 7);
		world.setBlockMetadataWithNotify(i + 30, j + 52, k + 11, 7, 2);
		setBlock(world, i + 30, j + 52, k + 12, Blocks.leaves, 7);
		world.setBlockMetadataWithNotify(i + 30, j + 52, k + 12, 7, 2);
		setBlock(world, i + 30, j + 53, k + 11, Blocks.leaves, 7);
		world.setBlockMetadataWithNotify(i + 30, j + 53, k + 11, 7, 2);
		setBlock(world, i + 30, j + 53, k + 12, Blocks.leaves, 7);
		world.setBlockMetadataWithNotify(i + 30, j + 53, k + 12, 7, 2);
		setBlock(world, i + 30, j + 53, k + 13, Blocks.leaves, 7);
		world.setBlockMetadataWithNotify(i + 30, j + 53, k + 13, 7, 2);
		setBlock(world, i + 30, j + 53, k + 14, Blocks.leaves, 7);
		world.setBlockMetadataWithNotify(i + 30, j + 53, k + 14, 7, 2);
		setBlock(world, i + 30, j + 54, k + 13, Blocks.leaves, 7);
		world.setBlockMetadataWithNotify(i + 30, j + 54, k + 13, 7, 2);
		setBlock(world, i + 31, j + 17, k + 12, Blocks.log, 3);
		world.setBlockMetadataWithNotify(i + 31, j + 17, k + 12, 3, 2);
		setBlock(world, i + 31, j + 17, k + 13, Blocks.log, 3);
		world.setBlockMetadataWithNotify(i + 31, j + 17, k + 13, 3, 2);
		setBlock(world, i + 31, j + 17, k + 14, Blocks.log, 3);
		world.setBlockMetadataWithNotify(i + 31, j + 17, k + 14, 3, 2);
		setBlock(world, i + 31, j + 18, k + 12, Blocks.log, 3);
		world.setBlockMetadataWithNotify(i + 31, j + 18, k + 12, 3, 2);
		setBlock(world, i + 31, j + 18, k + 13, Blocks.log, 3);
		world.setBlockMetadataWithNotify(i + 31, j + 18, k + 13, 3, 2);
		setBlock(world, i + 31, j + 18, k + 14, Blocks.log, 3);
		world.setBlockMetadataWithNotify(i + 31, j + 18, k + 14, 3, 2);
		setBlock(world, i + 31, j + 19, k + 12, Blocks.log, 3);
		world.setBlockMetadataWithNotify(i + 31, j + 19, k + 12, 3, 2);
		setBlock(world, i + 31, j + 19, k + 13, Blocks.log, 3);
		world.setBlockMetadataWithNotify(i + 31, j + 19, k + 13, 3, 2);
		setBlock(world, i + 31, j + 19, k + 14, Blocks.log, 3);
		world.setBlockMetadataWithNotify(i + 31, j + 19, k + 14, 3, 2);
		setBlock(world, i + 31, j + 20, k + 27, Blocks.log, 3);
		world.setBlockMetadataWithNotify(i + 31, j + 20, k + 27, 3, 2);
		setBlock(world, i + 31, j + 21, k + 2, Blocks.log, 3);
		world.setBlockMetadataWithNotify(i + 31, j + 21, k + 2, 3, 2);
		setBlock(world, i + 31, j + 21, k + 4, Blocks.log, 3);
		world.setBlockMetadataWithNotify(i + 31, j + 21, k + 4, 3, 2);
		setBlock(world, i + 31, j + 21, k + 6, Blocks.log, 3);
		world.setBlockMetadataWithNotify(i + 31, j + 21, k + 6, 3, 2);
		setBlock(world, i + 31, j + 21, k + 26, Blocks.leaves, 7);
		world.setBlockMetadataWithNotify(i + 31, j + 21, k + 26, 7, 2);
		setBlock(world, i + 31, j + 21, k + 27, Blocks.leaves, 7);
		world.setBlockMetadataWithNotify(i + 31, j + 21, k + 27, 7, 2);
		setBlock(world, i + 31, j + 21, k + 28, Blocks.log, 3);
		world.setBlockMetadataWithNotify(i + 31, j + 21, k + 28, 3, 2);
		setBlock(world, i + 31, j + 21, k + 29, Blocks.leaves, 7);
		world.setBlockMetadataWithNotify(i + 31, j + 21, k + 29, 7, 2);
		setBlock(world, i + 31, j + 21, k + 30, Blocks.leaves, 7);
		world.setBlockMetadataWithNotify(i + 31, j + 21, k + 30, 7, 2);
		setBlock(world, i + 31, j + 22, k + 1, Blocks.log, 3);
		world.setBlockMetadataWithNotify(i + 31, j + 22, k + 1, 3, 2);
		setBlock(world, i + 31, j + 22, k + 2, Blocks.log, 3);
		world.setBlockMetadataWithNotify(i + 31, j + 22, k + 2, 3, 2);
		setBlock(world, i + 31, j + 22, k + 3, Blocks.log, 3);
		world.setBlockMetadataWithNotify(i + 31, j + 22, k + 3, 3, 2);
		setBlock(world, i + 31, j + 22, k + 26, Blocks.leaves, 7);
		world.setBlockMetadataWithNotify(i + 31, j + 22, k + 26, 7, 2);
		setBlock(world, i + 31, j + 22, k + 27, Blocks.leaves, 7);
		world.setBlockMetadataWithNotify(i + 31, j + 22, k + 27, 7, 2);
		setBlock(world, i + 31, j + 22, k + 28, Blocks.leaves, 7);
		world.setBlockMetadataWithNotify(i + 31, j + 22, k + 28, 7, 2);
		setBlock(world, i + 31, j + 22, k + 29, Blocks.leaves, 7);
		world.setBlockMetadataWithNotify(i + 31, j + 22, k + 29, 7, 2);
		setBlock(world, i + 31, j + 22, k + 30, Blocks.leaves, 7);
		world.setBlockMetadataWithNotify(i + 31, j + 22, k + 30, 7, 2);
		setBlock(world, i + 31, j + 23, k + 2, Blocks.log, 3);
		world.setBlockMetadataWithNotify(i + 31, j + 23, k + 2, 3, 2);
		setBlock(world, i + 31, j + 23, k + 23, Blocks.leaves, 7);
		world.setBlockMetadataWithNotify(i + 31, j + 23, k + 23, 7, 2);
		setBlock(world, i + 31, j + 23, k + 24, Blocks.leaves, 7);
		world.setBlockMetadataWithNotify(i + 31, j + 23, k + 24, 7, 2);
		setBlock(world, i + 31, j + 23, k + 25, Blocks.leaves, 7);
		world.setBlockMetadataWithNotify(i + 31, j + 23, k + 25, 7, 2);
		setBlock(world, i + 31, j + 23, k + 27, Blocks.leaves, 7);
		world.setBlockMetadataWithNotify(i + 31, j + 23, k + 27, 7, 2);
		setBlock(world, i + 31, j + 23, k + 28, Blocks.leaves, 7);
		world.setBlockMetadataWithNotify(i + 31, j + 23, k + 28, 7, 2);
		setBlock(world, i + 31, j + 23, k + 29, Blocks.leaves, 7);
		world.setBlockMetadataWithNotify(i + 31, j + 23, k + 29, 7, 2);
		setBlock(world, i + 31, j + 24, k + 16, Blocks.log, 3);
		world.setBlockMetadataWithNotify(i + 31, j + 24, k + 16, 3, 2);
		setBlock(world, i + 31, j + 24, k + 24, Blocks.leaves, 7);
		world.setBlockMetadataWithNotify(i + 31, j + 24, k + 24, 7, 2);
		setBlock(world, i + 31, j + 24, k + 28, Blocks.leaves, 7);
		world.setBlockMetadataWithNotify(i + 31, j + 24, k + 28, 7, 2);
		setBlock(world, i + 31, j + 26, k + 24, Blocks.leaves, 7);
		world.setBlockMetadataWithNotify(i + 31, j + 26, k + 24, 7, 2);
		setBlock(world, i + 31, j + 26, k + 25, Blocks.leaves, 7);
		world.setBlockMetadataWithNotify(i + 31, j + 26, k + 25, 7, 2);
		setBlock(world, i + 31, j + 26, k + 26, Blocks.leaves, 7);
		world.setBlockMetadataWithNotify(i + 31, j + 26, k + 26, 7, 2);
		setBlock(world, i + 31, j + 27, k + 11, Blocks.log, 3);
		world.setBlockMetadataWithNotify(i + 31, j + 27, k + 11, 3, 2);
		setBlock(world, i + 31, j + 27, k + 25, Blocks.leaves, 7);
		world.setBlockMetadataWithNotify(i + 31, j + 27, k + 25, 7, 2);
		setBlock(world, i + 31, j + 28, k + 11, Blocks.log, 3);
		world.setBlockMetadataWithNotify(i + 31, j + 28, k + 11, 3, 2);
		setBlock(world, i + 31, j + 30, k + 14, Blocks.log, 3);
		world.setBlockMetadataWithNotify(i + 31, j + 30, k + 14, 3, 2);
		setBlock(world, i + 31, j + 31, k + 9, Blocks.log, 3);
		world.setBlockMetadataWithNotify(i + 31, j + 31, k + 9, 3, 2);
		setBlock(world, i + 31, j + 31, k + 12, Blocks.leaves, 7);
		world.setBlockMetadataWithNotify(i + 31, j + 31, k + 12, 7, 2);
		setBlock(world, i + 31, j + 31, k + 13, Blocks.leaves, 7);
		world.setBlockMetadataWithNotify(i + 31, j + 31, k + 13, 7, 2);
		setBlock(world, i + 31, j + 31, k + 14, Blocks.leaves, 7);
		world.setBlockMetadataWithNotify(i + 31, j + 31, k + 14, 7, 2);
		setBlock(world, i + 31, j + 31, k + 15, Blocks.leaves, 7);
		world.setBlockMetadataWithNotify(i + 31, j + 31, k + 15, 7, 2);
		setBlock(world, i + 31, j + 31, k + 16, Blocks.leaves, 7);
		world.setBlockMetadataWithNotify(i + 31, j + 31, k + 16, 7, 2);
		setBlock(world, i + 31, j + 31, k + 17, Blocks.log, 3);
		world.setBlockMetadataWithNotify(i + 31, j + 31, k + 17, 3, 2);
		setBlock(world, i + 31, j + 32, k + 3, Blocks.log, 3);
		world.setBlockMetadataWithNotify(i + 31, j + 32, k + 3, 3, 2);
		setBlock(world, i + 31, j + 32, k + 13, Blocks.leaves, 7);
		world.setBlockMetadataWithNotify(i + 31, j + 32, k + 13, 7, 2);
		setBlock(world, i + 31, j + 32, k + 14, Blocks.leaves, 7);
		world.setBlockMetadataWithNotify(i + 31, j + 32, k + 14, 7, 2);
		setBlock(world, i + 31, j + 32, k + 15, Blocks.leaves, 7);
		world.setBlockMetadataWithNotify(i + 31, j + 32, k + 15, 7, 2);
		setBlock(world, i + 31, j + 33, k + 0, Blocks.leaves, 7);
		world.setBlockMetadataWithNotify(i + 31, j + 33, k + 0, 7, 2);
		setBlock(world, i + 31, j + 33, k + 1, Blocks.leaves, 7);
		world.setBlockMetadataWithNotify(i + 31, j + 33, k + 1, 7, 2);
		setBlock(world, i + 31, j + 33, k + 2, Blocks.leaves, 7);
		world.setBlockMetadataWithNotify(i + 31, j + 33, k + 2, 7, 2);
		setBlock(world, i + 31, j + 33, k + 3, Blocks.log, 3);
		world.setBlockMetadataWithNotify(i + 31, j + 33, k + 3, 3, 2);
		setBlock(world, i + 31, j + 33, k + 5, Blocks.log, 3);
		world.setBlockMetadataWithNotify(i + 31, j + 33, k + 5, 3, 2);
		setBlock(world, i + 31, j + 33, k + 14, Blocks.leaves, 7);
		world.setBlockMetadataWithNotify(i + 31, j + 33, k + 14, 7, 2);
		setBlock(world, i + 31, j + 34, k + 1, Blocks.leaves, 7);
		world.setBlockMetadataWithNotify(i + 31, j + 34, k + 1, 7, 2);
		setBlock(world, i + 31, j + 37, k + 22, Blocks.leaves, 7);
		world.setBlockMetadataWithNotify(i + 31, j + 37, k + 22, 7, 2);
		setBlock(world, i + 31, j + 37, k + 23, Blocks.leaves, 7);
		world.setBlockMetadataWithNotify(i + 31, j + 37, k + 23, 7, 2);
		setBlock(world, i + 31, j + 37, k + 24, Blocks.leaves, 7);
		world.setBlockMetadataWithNotify(i + 31, j + 37, k + 24, 7, 2);
		setBlock(world, i + 31, j + 38, k + 13, Blocks.log, 3);
		world.setBlockMetadataWithNotify(i + 31, j + 38, k + 13, 3, 2);
		setBlock(world, i + 31, j + 38, k + 23, Blocks.leaves, 7);
		world.setBlockMetadataWithNotify(i + 31, j + 38, k + 23, 7, 2);
		setBlock(world, i + 31, j + 39, k + 6, Blocks.leaves, 7);
		world.setBlockMetadataWithNotify(i + 31, j + 39, k + 6, 7, 2);
		setBlock(world, i + 31, j + 39, k + 7, Blocks.leaves, 7);
		world.setBlockMetadataWithNotify(i + 31, j + 39, k + 7, 7, 2);
		setBlock(world, i + 31, j + 39, k + 8, Blocks.leaves, 7);
		world.setBlockMetadataWithNotify(i + 31, j + 39, k + 8, 7, 2);
		setBlock(world, i + 31, j + 39, k + 9, Blocks.leaves, 7);
		world.setBlockMetadataWithNotify(i + 31, j + 39, k + 9, 7, 2);
		setBlock(world, i + 31, j + 39, k + 10, Blocks.leaves, 7);
		world.setBlockMetadataWithNotify(i + 31, j + 39, k + 10, 7, 2);
		setBlock(world, i + 31, j + 39, k + 13, Blocks.leaves, 7);
		world.setBlockMetadataWithNotify(i + 31, j + 39, k + 13, 7, 2);
		setBlock(world, i + 31, j + 39, k + 14, Blocks.leaves, 7);
		world.setBlockMetadataWithNotify(i + 31, j + 39, k + 14, 7, 2);
		setBlock(world, i + 31, j + 39, k + 15, Blocks.leaves, 7);
		world.setBlockMetadataWithNotify(i + 31, j + 39, k + 15, 7, 2);
		setBlock(world, i + 31, j + 40, k + 7, Blocks.leaves, 7);
		world.setBlockMetadataWithNotify(i + 31, j + 40, k + 7, 7, 2);
		setBlock(world, i + 31, j + 40, k + 8, Blocks.leaves, 7);
		world.setBlockMetadataWithNotify(i + 31, j + 40, k + 8, 7, 2);
		setBlock(world, i + 31, j + 40, k + 9, Blocks.leaves, 7);
		world.setBlockMetadataWithNotify(i + 31, j + 40, k + 9, 7, 2);
		setBlock(world, i + 31, j + 40, k + 14, Blocks.leaves, 7);
		world.setBlockMetadataWithNotify(i + 31, j + 40, k + 14, 7, 2);
		setBlock(world, i + 31, j + 41, k + 8, Blocks.leaves, 7);
		world.setBlockMetadataWithNotify(i + 31, j + 41, k + 8, 7, 2);
		setBlock(world, i + 31, j + 42, k + 17, Blocks.leaves, 7);
		world.setBlockMetadataWithNotify(i + 31, j + 42, k + 17, 7, 2);
		setBlock(world, i + 31, j + 42, k + 18, Blocks.leaves, 7);
		world.setBlockMetadataWithNotify(i + 31, j + 42, k + 18, 7, 2);
		setBlock(world, i + 31, j + 42, k + 19, Blocks.leaves, 7);
		world.setBlockMetadataWithNotify(i + 31, j + 42, k + 19, 7, 2);
		setBlock(world, i + 31, j + 42, k + 20, Blocks.leaves, 7);
		world.setBlockMetadataWithNotify(i + 31, j + 42, k + 20, 7, 2);
		setBlock(world, i + 31, j + 42, k + 21, Blocks.leaves, 7);
		world.setBlockMetadataWithNotify(i + 31, j + 42, k + 21, 7, 2);
		setBlock(world, i + 31, j + 43, k + 18, Blocks.leaves, 7);
		world.setBlockMetadataWithNotify(i + 31, j + 43, k + 18, 7, 2);
		setBlock(world, i + 31, j + 43, k + 19, Blocks.leaves, 7);
		world.setBlockMetadataWithNotify(i + 31, j + 43, k + 19, 7, 2);
		setBlock(world, i + 31, j + 43, k + 20, Blocks.leaves, 7);
		world.setBlockMetadataWithNotify(i + 31, j + 43, k + 20, 7, 2);
		setBlock(world, i + 31, j + 44, k + 5, Blocks.log, 3);
		world.setBlockMetadataWithNotify(i + 31, j + 44, k + 5, 3, 2);
		setBlock(world, i + 31, j + 44, k + 19, Blocks.leaves, 7);
		world.setBlockMetadataWithNotify(i + 31, j + 44, k + 19, 7, 2);
		setBlock(world, i + 31, j + 45, k + 2, Blocks.leaves, 7);
		world.setBlockMetadataWithNotify(i + 31, j + 45, k + 2, 7, 2);
		setBlock(world, i + 31, j + 45, k + 3, Blocks.leaves, 7);
		world.setBlockMetadataWithNotify(i + 31, j + 45, k + 3, 7, 2);
		
		generate2(world, rand, i, j, k);
		return true;
		}

	
	public boolean generate2(World world, Random rand, int i, int j, int k)
	{
		setBlock(world, i + 31, j + 45, k + 4, Blocks.log, 3);
		world.setBlockMetadataWithNotify(i + 31, j + 45, k + 4, 3, 2);
		setBlock(world, i + 31, j + 45, k + 5, Blocks.leaves, 7);
		world.setBlockMetadataWithNotify(i + 31, j + 45, k + 5, 7, 2);
		setBlock(world, i + 31, j + 46, k + 1, Blocks.leaves, 7);
		world.setBlockMetadataWithNotify(i + 31, j + 46, k + 1, 7, 2);
		setBlock(world, i + 31, j + 46, k + 2, Blocks.leaves, 7);
		world.setBlockMetadataWithNotify(i + 31, j + 46, k + 2, 7, 2);
		setBlock(world, i + 31, j + 46, k + 3, Blocks.leaves, 7);
		world.setBlockMetadataWithNotify(i + 31, j + 46, k + 3, 7, 2);
		setBlock(world, i + 31, j + 46, k + 4, Blocks.leaves, 7);
		world.setBlockMetadataWithNotify(i + 31, j + 46, k + 4, 7, 2);
		setBlock(world, i + 31, j + 46, k + 5, Blocks.leaves, 7);
		world.setBlockMetadataWithNotify(i + 31, j + 46, k + 5, 7, 2);
		setBlock(world, i + 31, j + 47, k + 2, Blocks.leaves, 7);
		world.setBlockMetadataWithNotify(i + 31, j + 47, k + 2, 7, 2);
		setBlock(world, i + 31, j + 47, k + 3, Blocks.leaves, 7);
		world.setBlockMetadataWithNotify(i + 31, j + 47, k + 3, 7, 2);
		setBlock(world, i + 31, j + 47, k + 4, Blocks.leaves, 7);
		world.setBlockMetadataWithNotify(i + 31, j + 47, k + 4, 7, 2);
		setBlock(world, i + 31, j + 48, k + 3, Blocks.leaves, 7);
		world.setBlockMetadataWithNotify(i + 31, j + 48, k + 3, 7, 2);
		setBlock(world, i + 31, j + 49, k + 0, Blocks.leaves, 7);
		world.setBlockMetadataWithNotify(i + 31, j + 49, k + 0, 7, 2);
		setBlock(world, i + 31, j + 49, k + 1, Blocks.leaves, 7);
		world.setBlockMetadataWithNotify(i + 31, j + 49, k + 1, 7, 2);
		setBlock(world, i + 31, j + 49, k + 2, Blocks.log, 3);
		world.setBlockMetadataWithNotify(i + 31, j + 49, k + 2, 3, 2);
		setBlock(world, i + 31, j + 49, k + 3, Blocks.leaves, 7);
		world.setBlockMetadataWithNotify(i + 31, j + 49, k + 3, 7, 2);
		setBlock(world, i + 31, j + 49, k + 4, Blocks.leaves, 7);
		world.setBlockMetadataWithNotify(i + 31, j + 49, k + 4, 7, 2);
		setBlock(world, i + 31, j + 50, k + 0, Blocks.leaves, 7);
		world.setBlockMetadataWithNotify(i + 31, j + 50, k + 0, 7, 2);
		setBlock(world, i + 31, j + 50, k + 1, Blocks.leaves, 7);
		world.setBlockMetadataWithNotify(i + 31, j + 50, k + 1, 7, 2);
		setBlock(world, i + 31, j + 50, k + 2, Blocks.leaves, 7);
		world.setBlockMetadataWithNotify(i + 31, j + 50, k + 2, 7, 2);
		setBlock(world, i + 31, j + 50, k + 3, Blocks.leaves, 7);
		world.setBlockMetadataWithNotify(i + 31, j + 50, k + 3, 7, 2);
		setBlock(world, i + 31, j + 50, k + 4, Blocks.leaves, 7);
		world.setBlockMetadataWithNotify(i + 31, j + 50, k + 4, 7, 2);
		setBlock(world, i + 31, j + 51, k + 1, Blocks.leaves, 7);
		world.setBlockMetadataWithNotify(i + 31, j + 51, k + 1, 7, 2);
		setBlock(world, i + 31, j + 51, k + 2, Blocks.leaves, 7);
		world.setBlockMetadataWithNotify(i + 31, j + 51, k + 2, 7, 2);
		setBlock(world, i + 31, j + 51, k + 3, Blocks.leaves, 7);
		world.setBlockMetadataWithNotify(i + 31, j + 51, k + 3, 7, 2);
		setBlock(world, i + 31, j + 51, k + 9, Blocks.leaves, 7);
		world.setBlockMetadataWithNotify(i + 31, j + 51, k + 9, 7, 2);
		setBlock(world, i + 31, j + 51, k + 10, Blocks.leaves, 7);
		world.setBlockMetadataWithNotify(i + 31, j + 51, k + 10, 7, 2);
		setBlock(world, i + 31, j + 51, k + 11, Blocks.log, 3);
		world.setBlockMetadataWithNotify(i + 31, j + 51, k + 11, 3, 2);
		setBlock(world, i + 31, j + 51, k + 12, Blocks.leaves, 7);
		world.setBlockMetadataWithNotify(i + 31, j + 51, k + 12, 7, 2);
		setBlock(world, i + 31, j + 51, k + 13, Blocks.leaves, 7);
		world.setBlockMetadataWithNotify(i + 31, j + 51, k + 13, 7, 2);
		setBlock(world, i + 31, j + 52, k + 2, Blocks.leaves, 7);
		world.setBlockMetadataWithNotify(i + 31, j + 52, k + 2, 7, 2);
		setBlock(world, i + 31, j + 52, k + 9, Blocks.leaves, 7);
		world.setBlockMetadataWithNotify(i + 31, j + 52, k + 9, 7, 2);
		setBlock(world, i + 31, j + 52, k + 10, Blocks.leaves, 7);
		world.setBlockMetadataWithNotify(i + 31, j + 52, k + 10, 7, 2);
		setBlock(world, i + 31, j + 52, k + 11, Blocks.leaves, 7);
