package com.parzivail.pswm.world.gen.wookietree;


import cpw.mods.fml.common.IWorldGenerator;

import java.util.Random;

import net.minecraft.block.Block;

import net.minecraft.init.Blocks;

import net.minecraft.world.World;

import net.minecraft.world.chunk.IChunkProvider;

import net.minecraft.world.gen.feature.WorldGenerator;


public class WT_52 extends WorldGenerator implements IWorldGenerator

{
	protected Block[] getValidSpawnBlocks()
	
	{
		return new Block[0];
		}

	
	public boolean locationIsValidSpawn(World world, int i, int j, int k)
	
	{
		int distanceToAir = 0;
		Block check = world.getBlock(i, j, k);
		
		while (check != Blocks.air)
		{
			if (distanceToAir > 3) { return false;
			}
			
			distanceToAir++;
			check = world.getBlock(i, j + distanceToAir, k);
			}
		
		j += distanceToAir - 1;
		
		Block block = world.getBlock(i, j, k);
		Block blockAbove = world.getBlock(i, j + 1, k);
		Block blockBelow = world.getBlock(i, j - 1, k);
		
		for (Block x : getValidSpawnBlocks())
		{
			if (blockAbove != Blocks.air) { return false;
			}
			if (block == x) return true;
			if ((block == Blocks.snow) && (blockBelow == x)) { return true;
			}
			}
		
		return false;
		}

	
	
	
	public void generate(Random random, int chunkX, int chunkZ, World world, IChunkProvider chunkGenerator, IChunkProvider chunkProvider)
	{
	}

	
	
	public void setBlock(World world, int x, int y, int z, Block block, int metadata)
	
	{
		world.setBlock(x, y, z, block, metadata, 2);
		}

	
	public boolean generate(World world, Random rand, int i, int j, int k)
	
	{
		k -= 10;
		i -= 10;
		
		setBlock(world, i + 0, j + 17, k + 12, Blocks.log, 3);
		world.setBlockMetadataWithNotify(i + 0, j + 17, k + 12, 3, 2);
		setBlock(world, i + 0, j + 17, k + 13, Blocks.log, 3);
		world.setBlockMetadataWithNotify(i + 0, j + 17, k + 13, 3, 2);
		setBlock(world, i + 0, j + 17, k + 14, Blocks.log, 3);
		world.setBlockMetadataWithNotify(i + 0, j + 17, k + 14, 3, 2);
		setBlock(world, i + 0, j + 18, k + 12, Blocks.log, 3);
		world.setBlockMetadataWithNotify(i + 0, j + 18, k + 12, 3, 2);
		setBlock(world, i + 0, j + 18, k + 13, Blocks.log, 3);
		world.setBlockMetadataWithNotify(i + 0, j + 18, k + 13, 3, 2);
		setBlock(world, i + 0, j + 18, k + 14, Blocks.log, 3);
		world.setBlockMetadataWithNotify(i + 0, j + 18, k + 14, 3, 2);
		setBlock(world, i + 0, j + 19, k + 12, Blocks.log, 3);
		world.setBlockMetadataWithNotify(i + 0, j + 19, k + 12, 3, 2);
		setBlock(world, i + 0, j + 19, k + 13, Blocks.log, 3);
		world.setBlockMetadataWithNotify(i + 0, j + 19, k + 13, 3, 2);
		setBlock(world, i + 0, j + 19, k + 14, Blocks.log, 3);
		world.setBlockMetadataWithNotify(i + 0, j + 19, k + 14, 3, 2);
		setBlock(world, i + 0, j + 20, k + 25, Blocks.log, 3);
		world.setBlockMetadataWithNotify(i + 0, j + 20, k + 25, 3, 2);
		setBlock(world, i + 0, j + 20, k + 26, Blocks.log, 3);
		world.setBlockMetadataWithNotify(i + 0, j + 20, k + 26, 3, 2);
		setBlock(world, i + 0, j + 21, k + 3, Blocks.log, 3);
		world.setBlockMetadataWithNotify(i + 0, j + 21, k + 3, 3, 2);
		setBlock(world, i + 0, j + 21, k + 5, Blocks.log, 3);
		world.setBlockMetadataWithNotify(i + 0, j + 21, k + 5, 3, 2);
		setBlock(world, i + 0, j + 21, k + 6, Blocks.log, 3);
		world.setBlockMetadataWithNotify(i + 0, j + 21, k + 6, 3, 2);
		setBlock(world, i + 0, j + 21, k + 26, Blocks.leaves, 7);
		world.setBlockMetadataWithNotify(i + 0, j + 21, k + 26, 7, 2);
		setBlock(world, i + 0, j + 21, k + 27, Blocks.leaves, 7);
		world.setBlockMetadataWithNotify(i + 0, j + 21, k + 27, 7, 2);
		setBlock(world, i + 0, j + 21, k + 28, Blocks.leaves, 7);
		world.setBlockMetadataWithNotify(i + 0, j + 21, k + 28, 7, 2);
		setBlock(world, i + 0, j + 21, k + 29, Blocks.leaves, 7);
		world.setBlockMetadataWithNotify(i + 0, j + 21, k + 29, 7, 2);
		setBlock(world, i + 0, j + 21, k + 30, Blocks.leaves, 7);
		world.setBlockMetadataWithNotify(i + 0, j + 21, k + 30, 7, 2);
		setBlock(world, i + 0, j + 22, k + 2, Blocks.log, 3);
		world.setBlockMetadataWithNotify(i + 0, j + 22, k + 2, 3, 2);
		setBlock(world, i + 0, j + 22, k + 3, Blocks.log, 3);
		world.setBlockMetadataWithNotify(i + 0, j + 22, k + 3, 3, 2);
		setBlock(world, i + 0, j + 22, k + 4, Blocks.log, 3);
		world.setBlockMetadataWithNotify(i + 0, j + 22, k + 4, 3, 2);
		setBlock(world, i + 0, j + 22, k + 27, Blocks.leaves, 7);
		world.setBlockMetadataWithNotify(i + 0, j + 22, k + 27, 7, 2);
		setBlock(world, i + 0, j + 22, k + 28, Blocks.leaves, 7);
		world.setBlockMetadataWithNotify(i + 0, j + 22, k + 28, 7, 2);
		setBlock(world, i + 0, j + 22, k + 29, Blocks.leaves, 7);
		world.setBlockMetadataWithNotify(i + 0, j + 22, k + 29, 7, 2);
		setBlock(world, i + 0, j + 23, k + 3, Blocks.log, 3);
		world.setBlockMetadataWithNotify(i + 0, j + 23, k + 3, 3, 2);
		setBlock(world, i + 0, j + 23, k + 15, Blocks.log, 3);
		world.setBlockMetadataWithNotify(i + 0, j + 23, k + 15, 3, 2);
		setBlock(world, i + 0, j + 23, k + 22, Blocks.leaves, 7);
		world.setBlockMetadataWithNotify(i + 0, j + 23, k + 22, 7, 2);
		setBlock(world, i + 0, j + 23, k + 23, Blocks.leaves, 7);
		world.setBlockMetadataWithNotify(i + 0, j + 23, k + 23, 7, 2);
		setBlock(world, i + 0, j + 23, k + 24, Blocks.leaves, 7);
		world.setBlockMetadataWithNotify(i + 0, j + 23, k + 24, 7, 2);
		setBlock(world, i + 0, j + 23, k + 25, Blocks.leaves, 7);
		world.setBlockMetadataWithNotify(i + 0, j + 23, k + 25, 7, 2);
		setBlock(world, i + 0, j + 23, k + 26, Blocks.leaves, 7);
		world.setBlockMetadataWithNotify(i + 0, j + 23, k + 26, 7, 2);
		setBlock(world, i + 0, j + 23, k + 28, Blocks.leaves, 7);
		world.setBlockMetadataWithNotify(i + 0, j + 23, k + 28, 7, 2);
		setBlock(world, i + 0, j + 24, k + 23, Blocks.leaves, 7);
		world.setBlockMetadataWithNotify(i + 0, j + 24, k + 23, 7, 2);
		setBlock(world, i + 0, j + 24, k + 24, Blocks.leaves, 7);
		world.setBlockMetadataWithNotify(i + 0, j + 24, k + 24, 7, 2);
		setBlock(world, i + 0, j + 24, k + 25, Blocks.leaves, 7);
		world.setBlockMetadataWithNotify(i + 0, j + 24, k + 25, 7, 2);
		setBlock(world, i + 0, j + 25, k + 0, Blocks.log, 3);
		world.setBlockMetadataWithNotify(i + 0, j + 25, k + 0, 3, 2);
		setBlock(world, i + 0, j + 25, k + 24, Blocks.leaves, 7);
		world.setBlockMetadataWithNotify(i + 0, j + 25, k + 24, 7, 2);
		setBlock(world, i + 0, j + 26, k + 23, Blocks.leaves, 7);
		world.setBlockMetadataWithNotify(i + 0, j + 26, k + 23, 7, 2);
		setBlock(world, i + 0, j + 26, k + 24, Blocks.leaves, 7);
		world.setBlockMetadataWithNotify(i + 0, j + 26, k + 24, 7, 2);
		setBlock(world, i + 0, j + 26, k + 25, Blocks.leaves, 7);
		world.setBlockMetadataWithNotify(i + 0, j + 26, k + 25, 7, 2);
		setBlock(world, i + 0, j + 26, k + 26, Blocks.leaves, 7);
		world.setBlockMetadataWithNotify(i + 0, j + 26, k + 26, 7, 2);
		setBlock(world, i + 0, j + 26, k + 27, Blocks.leaves, 7);
		world.setBlockMetadataWithNotify(i + 0, j + 26, k + 27, 7, 2);
		setBlock(world, i + 0, j + 27, k + 0, Blocks.log, 3);
		world.setBlockMetadataWithNotify(i + 0, j + 27, k + 0, 3, 2);
		setBlock(world, i + 0, j + 27, k + 10, Blocks.log, 3);
		world.setBlockMetadataWithNotify(i + 0, j + 27, k + 10, 3, 2);
		setBlock(world, i + 0, j + 27, k + 24, Blocks.leaves, 7);
		world.setBlockMetadataWithNotify(i + 0, j + 27, k + 24, 7, 2);
		setBlock(world, i + 0, j + 27, k + 25, Blocks.leaves, 7);
		world.setBlockMetadataWithNotify(i + 0, j + 27, k + 25, 7, 2);
		setBlock(world, i + 0, j + 27, k + 26, Blocks.leaves, 7);
		world.setBlockMetadataWithNotify(i + 0, j + 27, k + 26, 7, 2);
		setBlock(world, i + 0, j + 28, k + 11, Blocks.log, 3);
		world.setBlockMetadataWithNotify(i + 0, j + 28, k + 11, 3, 2);
		setBlock(world, i + 0, j + 28, k + 25, Blocks.leaves, 7);
		world.setBlockMetadataWithNotify(i + 0, j + 28, k + 25, 7, 2);
		setBlock(world, i + 0, j + 29, k + 18, Blocks.leaves, 7);
		world.setBlockMetadataWithNotify(i + 0, j + 29, k + 18, 7, 2);
		setBlock(world, i + 0, j + 29, k + 19, Blocks.leaves, 7);
		world.setBlockMetadataWithNotify(i + 0, j + 29, k + 19, 7, 2);
		setBlock(world, i + 0, j + 29, k + 20, Blocks.leaves, 7);
		world.setBlockMetadataWithNotify(i + 0, j + 29, k + 20, 7, 2);
		setBlock(world, i + 0, j + 30, k + 13, Blocks.log, 3);
		world.setBlockMetadataWithNotify(i + 0, j + 30, k + 13, 3, 2);
		setBlock(world, i + 0, j + 30, k + 16, Blocks.log, 3);
		world.setBlockMetadataWithNotify(i + 0, j + 30, k + 16, 3, 2);
		setBlock(world, i + 0, j + 30, k + 19, Blocks.leaves, 7);
		world.setBlockMetadataWithNotify(i + 0, j + 30, k + 19, 7, 2);
		setBlock(world, i + 0, j + 30, k + 21, Blocks.leaves, 7);
		world.setBlockMetadataWithNotify(i + 0, j + 30, k + 21, 7, 2);
		setBlock(world, i + 0, j + 30, k + 22, Blocks.leaves, 7);
		world.setBlockMetadataWithNotify(i + 0, j + 30, k + 22, 7, 2);
		setBlock(world, i + 0, j + 30, k + 23, Blocks.leaves, 7);
		world.setBlockMetadataWithNotify(i + 0, j + 30, k + 23, 7, 2);
		setBlock(world, i + 0, j + 31, k + 9, Blocks.log, 3);
		world.setBlockMetadataWithNotify(i + 0, j + 31, k + 9, 3, 2);
		setBlock(world, i + 0, j + 31, k + 13, Blocks.leaves, 7);
		world.setBlockMetadataWithNotify(i + 0, j + 31, k + 13, 7, 2);
		setBlock(world, i + 0, j + 31, k + 14, Blocks.leaves, 7);
		world.setBlockMetadataWithNotify(i + 0, j + 31, k + 14, 7, 2);
		setBlock(world, i + 0, j + 31, k + 15, Blocks.leaves, 7);
		world.setBlockMetadataWithNotify(i + 0, j + 31, k + 15, 7, 2);
		setBlock(world, i + 0, j + 31, k + 22, Blocks.leaves, 7);
		world.setBlockMetadataWithNotify(i + 0, j + 31, k + 22, 7, 2);
		setBlock(world, i + 0, j + 32, k + 4, Blocks.log, 3);
		world.setBlockMetadataWithNotify(i + 0, j + 32, k + 4, 3, 2);
		setBlock(world, i + 0, j + 32, k + 14, Blocks.leaves, 7);
		world.setBlockMetadataWithNotify(i + 0, j + 32, k + 14, 7, 2);
		setBlock(world, i + 0, j + 33, k + 4, Blocks.log, 3);
		world.setBlockMetadataWithNotify(i + 0, j + 33, k + 4, 3, 2);
		setBlock(world, i + 0, j + 33, k + 5, Blocks.log, 3);
		world.setBlockMetadataWithNotify(i + 0, j + 33, k + 5, 3, 2);
		setBlock(world, i + 0, j + 34, k + 10, Blocks.leaves, 7);
		world.setBlockMetadataWithNotify(i + 0, j + 34, k + 10, 7, 2);
		setBlock(world, i + 0, j + 34, k + 11, Blocks.leaves, 7);
		world.setBlockMetadataWithNotify(i + 0, j + 34, k + 11, 7, 2);
		setBlock(world, i + 0, j + 34, k + 12, Blocks.leaves, 7);
		world.setBlockMetadataWithNotify(i + 0, j + 34, k + 12, 7, 2);
		setBlock(world, i + 0, j + 35, k + 11, Blocks.leaves, 7);
		world.setBlockMetadataWithNotify(i + 0, j + 35, k + 11, 7, 2);
		setBlock(world, i + 0, j + 37, k + 21, Blocks.leaves, 7);
		world.setBlockMetadataWithNotify(i + 0, j + 37, k + 21, 7, 2);
		setBlock(world, i + 0, j + 37, k + 22, Blocks.leaves, 7);
		world.setBlockMetadataWithNotify(i + 0, j + 37, k + 22, 7, 2);
		setBlock(world, i + 0, j + 37, k + 23, Blocks.leaves, 7);
		world.setBlockMetadataWithNotify(i + 0, j + 37, k + 23, 7, 2);
		setBlock(world, i + 0, j + 37, k + 24, Blocks.leaves, 7);
		world.setBlockMetadataWithNotify(i + 0, j + 37, k + 24, 7, 2);
		setBlock(world, i + 0, j + 37, k + 25, Blocks.leaves, 7);
		world.setBlockMetadataWithNotify(i + 0, j + 37, k + 25, 7, 2);
		setBlock(world, i + 0, j + 38, k + 13, Blocks.log, 3);
		world.setBlockMetadataWithNotify(i + 0, j + 38, k + 13, 3, 2);
		setBlock(world, i + 0, j + 38, k + 22, Blocks.leaves, 7);
		world.setBlockMetadataWithNotify(i + 0, j + 38, k + 22, 7, 2);
		setBlock(world, i + 0, j + 38, k + 23, Blocks.leaves, 7);
		world.setBlockMetadataWithNotify(i + 0, j + 38, k + 23, 7, 2);
		setBlock(world, i + 0, j + 38, k + 24, Blocks.leaves, 7);
		world.setBlockMetadataWithNotify(i + 0, j + 38, k + 24, 7, 2);
		setBlock(world, i + 0, j + 39, k + 6, Blocks.leaves, 7);
		world.setBlockMetadataWithNotify(i + 0, j + 39, k + 6, 7, 2);
		setBlock(world, i + 0, j + 39, k + 7, Blocks.leaves, 7);
		world.setBlockMetadataWithNotify(i + 0, j + 39, k + 7, 7, 2);
		setBlock(world, i + 0, j + 39, k + 8, Blocks.log, 3);
		world.setBlockMetadataWithNotify(i + 0, j + 39, k + 8, 3, 2);
		setBlock(world, i + 0, j + 39, k + 9, Blocks.leaves, 7);
		world.setBlockMetadataWithNotify(i + 0, j + 39, k + 9, 7, 2);
		setBlock(world, i + 0, j + 39, k + 10, Blocks.leaves, 7);
		world.setBlockMetadataWithNotify(i + 0, j + 39, k + 10, 7, 2);
		setBlock(world, i + 0, j + 39, k + 23, Blocks.leaves, 7);
		world.setBlockMetadataWithNotify(i + 0, j + 39, k + 23, 7, 2);
		setBlock(world, i + 0, j + 40, k + 6, Blocks.leaves, 7);
		world.setBlockMetadataWithNotify(i + 0, j + 40, k + 6, 7, 2);
		setBlock(world, i + 0, j + 40, k + 7, Blocks.leaves, 7);
		world.setBlockMetadataWithNotify(i + 0, j + 40, k + 7, 7, 2);
		setBlock(world, i + 0, j + 40, k + 8, Blocks.leaves, 7);
		world.setBlockMetadataWithNotify(i + 0, j + 40, k + 8, 7, 2);
		setBlock(world, i + 0, j + 40, k + 9, Blocks.leaves, 7);
		world.setBlockMetadataWithNotify(i + 0, j + 40, k + 9, 7, 2);
		setBlock(world, i + 0, j + 40, k + 10, Blocks.leaves, 7);
		world.setBlockMetadataWithNotify(i + 0, j + 40, k + 10, 7, 2);
		setBlock(world, i + 0, j + 41, k + 7, Blocks.leaves, 7);
		world.setBlockMetadataWithNotify(i + 0, j + 41, k + 7, 7, 2);
		setBlock(world, i + 0, j + 41, k + 8, Blocks.leaves, 7);
		world.setBlockMetadataWithNotify(i + 0, j + 41, k + 8, 7, 2);
		setBlock(world, i + 0, j + 41, k + 9, Blocks.leaves, 7);
		world.setBlockMetadataWithNotify(i + 0, j + 41, k + 9, 7, 2);
		setBlock(world, i + 0, j + 42, k + 8, Blocks.leaves, 7);
		world.setBlockMetadataWithNotify(i + 0, j + 42, k + 8, 7, 2);
		setBlock(world, i + 0, j + 42, k + 17, Blocks.leaves, 7);
		world.setBlockMetadataWithNotify(i + 0, j + 42, k + 17, 7, 2);
		setBlock(world, i + 0, j + 42, k + 18, Blocks.leaves, 7);
		world.setBlockMetadataWithNotify(i + 0, j + 42, k + 18, 7, 2);
		setBlock(world, i + 0, j + 42, k + 19, Blocks.log, 3);
		world.setBlockMetadataWithNotify(i + 0, j + 42, k + 19, 3, 2);
		setBlock(world, i + 0, j + 42, k + 20, Blocks.leaves, 7);
		world.setBlockMetadataWithNotify(i + 0, j + 42, k + 20, 7, 2);
		setBlock(world, i + 0, j + 42, k + 21, Blocks.leaves, 7);
		world.setBlockMetadataWithNotify(i + 0, j + 42, k + 21, 7, 2);
		setBlock(world, i + 0, j + 43, k + 17, Blocks.leaves, 7);
		world.setBlockMetadataWithNotify(i + 0, j + 43, k + 17, 7, 2);
		setBlock(world, i + 0, j + 43, k + 18, Blocks.leaves, 7);
		world.setBlockMetadataWithNotify(i + 0, j + 43, k + 18, 7, 2);
		setBlock(world, i + 0, j + 43, k + 19, Blocks.leaves, 7);
		world.setBlockMetadataWithNotify(i + 0, j + 43, k + 19, 7, 2);
		setBlock(world, i + 0, j + 43, k + 20, Blocks.leaves, 7);
		world.setBlockMetadataWithNotify(i + 0, j + 43, k + 20, 7, 2);
		setBlock(world, i + 0, j + 43, k + 21, Blocks.leaves, 7);
		world.setBlockMetadataWithNotify(i + 0, j + 43, k + 21, 7, 2);
		setBlock(world, i + 0, j + 44, k + 6, Blocks.log, 3);
		world.setBlockMetadataWithNotify(i + 0, j + 44, k + 6, 3, 2);
		setBlock(world, i + 0, j + 44, k + 18, Blocks.leaves, 7);
		world.setBlockMetadataWithNotify(i + 0, j + 44, k + 18, 7, 2);
		setBlock(world, i + 0, j + 44, k + 19, Blocks.leaves, 7);
		world.setBlockMetadataWithNotify(i + 0, j + 44, k + 19, 7, 2);
		setBlock(world, i + 0, j + 44, k + 20, Blocks.leaves, 7);
		world.setBlockMetadataWithNotify(i + 0, j + 44, k + 20, 7, 2);
		setBlock(world, i + 0, j + 45, k + 1, Blocks.leaves, 7);
		world.setBlockMetadataWithNotify(i + 0, j + 45, k + 1, 7, 2);
		setBlock(world, i + 0, j + 45, k + 2, Blocks.leaves, 7);
		world.setBlockMetadataWithNotify(i + 0, j + 45, k + 2, 7, 2);
		setBlock(world, i + 0, j + 45, k + 3, Blocks.leaves, 7);
		world.setBlockMetadataWithNotify(i + 0, j + 45, k + 3, 7, 2);
		setBlock(world, i + 0, j + 45, k + 4, Blocks.log, 3);
		world.setBlockMetadataWithNotify(i + 0, j + 45, k + 4, 3, 2);
		setBlock(world, i + 0, j + 45, k + 5, Blocks.leaves, 7);
		world.setBlockMetadataWithNotify(i + 0, j + 45, k + 5, 7, 2);
		setBlock(world, i + 0, j + 45, k + 6, Blocks.leaves, 7);
		world.setBlockMetadataWithNotify(i + 0, j + 45, k + 6, 7, 2);
		setBlock(world, i + 0, j + 45, k + 7, Blocks.leaves, 7);
		world.setBlockMetadataWithNotify(i + 0, j + 45, k + 7, 7, 2);
		setBlock(world, i + 0, j + 45, k + 8, Blocks.leaves, 7);
		world.setBlockMetadataWithNotify(i + 0, j + 45, k + 8, 7, 2);
		setBlock(world, i + 0, j + 45, k + 19, Blocks.leaves, 7);
		world.setBlockMetadataWithNotify(i + 0, j + 45, k + 19, 7, 2);
		setBlock(world, i + 0, j + 46, k + 2, Blocks.leaves, 7);
		world.setBlockMetadataWithNotify(i + 0, j + 46, k + 2, 7, 2);
		setBlock(world, i + 0, j + 46, k + 3, Blocks.leaves, 7);
		world.setBlockMetadataWithNotify(i + 0, j + 46, k + 3, 7, 2);
		setBlock(world, i + 0, j + 46, k + 4, Blocks.leaves, 7);
		world.setBlockMetadataWithNotify(i + 0, j + 46, k + 4, 7, 2);
		setBlock(world, i + 0, j + 46, k + 7, Blocks.leaves, 7);
		world.setBlockMetadataWithNotify(i + 0, j + 46, k + 7, 7, 2);
		setBlock(world, i + 0, j + 47, k + 3, Blocks.leaves, 7);
		world.setBlockMetadataWithNotify(i + 0, j + 47, k + 3, 7, 2);
		setBlock(world, i + 0, j + 48, k + 3, Blocks.log, 3);
		world.setBlockMetadataWithNotify(i + 0, j + 48, k + 3, 3, 2);
		setBlock(world, i + 0, j + 49, k + 0, Blocks.leaves, 7);
		world.setBlockMetadataWithNotify(i + 0, j + 49, k + 0, 7, 2);
		setBlock(world, i + 0, j + 49, k + 1, Blocks.leaves, 7);
		world.setBlockMetadataWithNotify(i + 0, j + 49, k + 1, 7, 2);
		setBlock(world, i + 0, j + 49, k + 2, Blocks.leaves, 7);
		world.setBlockMetadataWithNotify(i + 0, j + 49, k + 2, 7, 2);
		setBlock(world, i + 0, j + 49, k + 3, Blocks.leaves, 7);
		world.setBlockMetadataWithNotify(i + 0, j + 49, k + 3, 7, 2);
		setBlock(world, i + 0, j + 49, k + 4, Blocks.leaves, 7);
		world.setBlockMetadataWithNotify(i + 0, j + 49, k + 4, 7, 2);
		setBlock(world, i + 0, j + 50, k + 1, Blocks.leaves, 7);
		world.setBlockMetadataWithNotify(i + 0, j + 50, k + 1, 7, 2);
		setBlock(world, i + 0, j + 50, k + 2, Blocks.leaves, 7);
		world.setBlockMetadataWithNotify(i + 0, j + 50, k + 2, 7, 2);
		setBlock(world, i + 0, j + 50, k + 3, Blocks.leaves, 7);
		world.setBlockMetadataWithNotify(i + 0, j + 50, k + 3, 7, 2);
		setBlock(world, i + 0, j + 51, k + 2, Blocks.leaves, 7);
		world.setBlockMetadataWithNotify(i + 0, j + 51, k + 2, 7, 2);
		setBlock(world, i + 0, j + 51, k + 9, Blocks.leaves, 7);
		world.setBlockMetadataWithNotify(i + 0, j + 51, k + 9, 7, 2);
		setBlock(world, i + 0, j + 51, k + 10, Blocks.leaves, 7);
		world.setBlockMetadataWithNotify(i + 0, j + 51, k + 10, 7, 2);
		setBlock(world, i + 0, j + 51, k + 11, Blocks.leaves, 7);
		world.setBlockMetadataWithNotify(i + 0, j + 51, k + 11, 7, 2);
		setBlock(world, i + 0, j + 51, k + 12, Blocks.leaves, 7);
		world.setBlockMetadataWithNotify(i + 0, j + 51, k + 12, 7, 2);
		setBlock(world, i + 0, j + 51, k + 13, Blocks.leaves, 7);
		world.setBlockMetadataWithNotify(i + 0, j + 51, k + 13, 7, 2);
		setBlock(world, i + 0, j + 52, k + 10, Blocks.leaves, 7);
		world.setBlockMetadataWithNotify(i + 0, j + 52, k + 10, 7, 2);
		setBlock(world, i + 0, j + 52, k + 11, Blocks.leaves, 7);
		world.setBlockMetadataWithNotify(i + 0, j + 52, k + 11, 7, 2);
		setBlock(world, i + 0, j + 52, k + 12, Blocks.leaves, 7);
		world.setBlockMetadataWithNotify(i + 0, j + 52, k + 12, 7, 2);
		setBlock(world, i + 0, j + 52, k + 14, Blocks.leaves, 7);
		world.setBlockMetadataWithNotify(i + 0, j + 52, k + 14, 7, 2);
		setBlock(world, i + 0, j + 52, k + 15, Blocks.leaves, 7);
		world.setBlockMetadataWithNotify(i + 0, j + 52, k + 15, 7, 2);
		setBlock(world, i + 0, j + 52, k + 16, Blocks.leaves, 7);
		world.setBlockMetadataWithNotify(i + 0, j + 52, k + 16, 7, 2);
		setBlock(world, i + 0, j + 52, k + 17, Blocks.leaves, 7);
		world.setBlockMetadataWithNotify(i + 0, j + 52, k + 17, 7, 2);
		setBlock(world, i + 0, j + 52, k + 18, Blocks.leaves, 7);
		world.setBlockMetadataWithNotify(i + 0, j + 52, k + 18, 7, 2);
		setBlock(world, i + 0, j + 53, k + 11, Blocks.leaves, 7);
		world.setBlockMetadataWithNotify(i + 0, j + 53, k + 11, 7, 2);
		setBlock(world, i + 0, j + 53, k + 12, Blocks.leaves, 7);
		world.setBlockMetadataWithNotify(i + 0, j + 53, k + 12, 7, 2);
		setBlock(world, i + 0, j + 53, k + 13, Blocks.log, 3);
		world.setBlockMetadataWithNotify(i + 0, j + 53, k + 13, 3, 2);
		setBlock(world, i + 0, j + 53, k + 14, Blocks.leaves, 7);
		world.setBlockMetadataWithNotify(i + 0, j + 53, k + 14, 7, 2);
		setBlock(world, i + 0, j + 53, k + 15, Blocks.leaves, 7);
		world.setBlockMetadataWithNotify(i + 0, j + 53, k + 15, 7, 2);
		setBlock(world, i + 0, j + 53, k + 16, Blocks.leaves, 7);
		world.setBlockMetadataWithNotify(i + 0, j + 53, k + 16, 7, 2);
		setBlock(world, i + 0, j + 53, k + 17, Blocks.leaves, 7);
		world.setBlockMetadataWithNotify(i + 0, j + 53, k + 17, 7, 2);
		setBlock(world, i + 0, j + 54, k + 11, Blocks.leaves, 7);
		world.setBlockMetadataWithNotify(i + 0, j + 54, k + 11, 7, 2);
		setBlock(world, i + 0, j + 54, k + 12, Blocks.leaves, 7);
		world.setBlockMetadataWithNotify(i + 0, j + 54, k + 12, 7, 2);
		setBlock(world, i + 0, j + 54, k + 13, Blocks.leaves, 7);
		world.setBlockMetadataWithNotify(i + 0, j + 54, k + 13, 7, 2);
		setBlock(world, i + 0, j + 54, k + 14, Blocks.leaves, 7);
		world.setBlockMetadataWithNotify(i + 0, j + 54, k + 14, 7, 2);
		setBlock(world, i + 0, j + 54, k + 15, Blocks.leaves, 7);
		world.setBlockMetadataWithNotify(i + 0, j + 54, k + 15, 7, 2);
		setBlock(world, i + 0, j + 54, k + 16, Blocks.leaves, 7);
		world.setBlockMetadataWithNotify(i + 0, j + 54, k + 16, 7, 2);
		setBlock(world, i + 0, j + 55, k + 12, Blocks.leaves, 7);
		world.setBlockMetadataWithNotify(i + 0, j + 55, k + 12, 7, 2);
		setBlock(world, i + 0, j + 55, k + 13, Blocks.leaves, 7);
		world.setBlockMetadataWithNotify(i + 0, j + 55, k + 13, 7, 2);
		setBlock(world, i + 0, j + 55, k + 14, Blocks.leaves, 7);
		world.setBlockMetadataWithNotify(i + 0, j + 55, k + 14, 7, 2);
		setBlock(world, i + 0, j + 56, k + 13, Blocks.leaves, 7);
		world.setBlockMetadataWithNotify(i + 0, j + 56, k + 13, 7, 2);
		setBlock(world, i + 1, j + 0, k + 6, Blocks.log, 3);
		world.setBlockMetadataWithNotify(i + 1, j + 0, k + 6, 3, 2);
		setBlock(world, i + 1, j + 0, k + 7, Blocks.log, 3);
		world.setBlockMetadataWithNotify(i + 1, j + 0, k + 7, 3, 2);
		setBlock(world, i + 1, j + 0, k + 8, Blocks.log, 3);
		world.setBlockMetadataWithNotify(i + 1, j + 0, k + 8, 3, 2);
		setBlock(world, i + 1, j + 0, k + 9, Blocks.log, 3);
		world.setBlockMetadataWithNotify(i + 1, j + 0, k + 9, 3, 2);
		setBlock(world, i + 1, j + 0, k + 10, Blocks.log, 3);
		world.setBlockMetadataWithNotify(i + 1, j + 0, k + 10, 3, 2);
		setBlock(world, i + 1, j + 0, k + 11, Blocks.log, 3);
		world.setBlockMetadataWithNotify(i + 1, j + 0, k + 11, 3, 2);
		setBlock(world, i + 1, j + 0, k + 12, Blocks.log, 3);
		world.setBlockMetadataWithNotify(i + 1, j + 0, k + 12, 3, 2);
		setBlock(world, i + 1, j + 0, k + 13, Blocks.log, 3);
		world.setBlockMetadataWithNotify(i + 1, j + 0, k + 13, 3, 2);
		setBlock(world, i + 1, j + 1, k + 6, Blocks.log, 3);
		world.setBlockMetadataWithNotify(i + 1, j + 1, k + 6, 3, 2);
		setBlock(world, i + 1, j + 1, k + 7, Blocks.log, 3);
		world.setBlockMetadataWithNotify(i + 1, j + 1, k + 7, 3, 2);
		setBlock(world, i + 1, j + 1, k + 8, Blocks.log, 3);
		world.setBlockMetadataWithNotify(i + 1, j + 1, k + 8, 3, 2);
		setBlock(world, i + 1, j + 1, k + 9, Blocks.log, 3);
		world.setBlockMetadataWithNotify(i + 1, j + 1, k + 9, 3, 2);
		setBlock(world, i + 1, j + 1, k + 10, Blocks.log, 3);
		world.setBlockMetadataWithNotify(i + 1, j + 1, k + 10, 3, 2);
		setBlock(world, i + 1, j + 2, k + 8, Blocks.log, 3);
		world.setBlockMetadataWithNotify(i + 1, j + 2, k + 8, 3, 2);
		setBlock(world, i + 1, j + 17, k + 11, Blocks.log, 3);
		world.setBlockMetadataWithNotify(i + 1, j + 17, k + 11, 3, 2);
		setBlock(world, i + 1, j + 17, k + 12, Blocks.log, 3);
		world.setBlockMetadataWithNotify(i + 1, j + 17, k + 12, 3, 2);
		setBlock(world, i + 1, j + 17, k + 13, Blocks.log, 3);
		world.setBlockMetadataWithNotify(i + 1, j + 17, k + 13, 3, 2);
		setBlock(world, i + 1, j + 18, k + 11, Blocks.log, 3);
		world.setBlockMetadataWithNotify(i + 1, j + 18, k + 11, 3, 2);
		setBlock(world, i + 1, j + 18, k + 12, Blocks.log, 3);
		world.setBlockMetadataWithNotify(i + 1, j + 18, k + 12, 3, 2);
		setBlock(world, i + 1, j + 18, k + 13, Blocks.log, 3);
		world.setBlockMetadataWithNotify(i + 1, j + 18, k + 13, 3, 2);
		setBlock(world, i + 1, j + 19, k + 11, Blocks.log, 3);
		world.setBlockMetadataWithNotify(i + 1, j + 19, k + 11, 3, 2);
		setBlock(world, i + 1, j + 19, k + 12, Blocks.log, 3);
		world.setBlockMetadataWithNotify(i + 1, j + 19, k + 12, 3, 2);
		setBlock(world, i + 1, j + 19, k + 13, Blocks.log, 3);
		world.setBlockMetadataWithNotify(i + 1, j + 19, k + 13, 3, 2);
		setBlock(world, i + 1, j + 20, k + 4, Blocks.log, 3);
		world.setBlockMetadataWithNotify(i + 1, j + 20, k + 4, 3, 2);
		setBlock(world, i + 1, j + 20, k + 23, Blocks.log, 3);
		world.setBlockMetadataWithNotify(i + 1, j + 20, k + 23, 3, 2);
		setBlock(world, i + 1, j + 20, k + 24, Blocks.log, 3);
		world.setBlockMetadataWithNotify(i + 1, j + 20, k + 24, 3, 2);
		setBlock(world, i + 1, j + 21, k + 3, Blocks.log, 3);
		world.setBlockMetadataWithNotify(i + 1, j + 21, k + 3, 3, 2);
		setBlock(world, i + 1, j + 21, k + 4, Blocks.log, 3);
		world.setBlockMetadataWithNotify(i + 1, j + 21, k + 4, 3, 2);
		setBlock(world, i + 1, j + 21, k + 5, Blocks.log, 3);
		world.setBlockMetadataWithNotify(i + 1, j + 21, k + 5, 3, 2);
		setBlock(world, i + 1, j + 21, k + 6, Blocks.log, 3);
		world.setBlockMetadataWithNotify(i + 1, j + 21, k + 6, 3, 2);
		setBlock(world, i + 1, j + 21, k + 27, Blocks.leaves, 7);
		world.setBlockMetadataWithNotify(i + 1, j + 21, k + 27, 7, 2);
		setBlock(world, i + 1, j + 21, k + 28, Blocks.leaves, 7);
		world.setBlockMetadataWithNotify(i + 1, j + 21, k + 28, 7, 2);
		setBlock(world, i + 1, j + 21, k + 29, Blocks.leaves, 7);
		world.setBlockMetadataWithNotify(i + 1, j + 21, k + 29, 7, 2);
		setBlock(world, i + 1, j + 22, k + 4, Blocks.log, 3);
		world.setBlockMetadataWithNotify(i + 1, j + 22, k + 4, 3, 2);
		setBlock(world, i + 1, j + 22, k + 22, Blocks.log, 3);
		world.setBlockMetadataWithNotify(i + 1, j + 22, k + 22, 3, 2);
		setBlock(world, i + 1, j + 22, k + 23, Blocks.log, 3);
		world.setBlockMetadataWithNotify(i + 1, j + 22, k + 23, 3, 2);
		setBlock(world, i + 1, j + 22, k + 28, Blocks.leaves, 7);
		world.setBlockMetadataWithNotify(i + 1, j + 22, k + 28, 7, 2);
		setBlock(world, i + 1, j + 23, k + 13, Blocks.log, 3);
		world.setBlockMetadataWithNotify(i + 1, j + 23, k + 13, 3, 2);
		setBlock(world, i + 1, j + 23, k + 14, Blocks.log, 3);
		world.setBlockMetadataWithNotify(i + 1, j + 23, k + 14, 3, 2);
		setBlock(world, i + 1, j + 23, k + 22, Blocks.leaves, 7);
		world.setBlockMetadataWithNotify(i + 1, j + 23, k + 22, 7, 2);
		setBlock(world, i + 1, j + 23, k + 23, Blocks.leaves, 7);
		world.setBlockMetadataWithNotify(i + 1, j + 23, k + 23, 7, 2);
		setBlock(world, i + 1, j + 23, k + 24, Blocks.log, 3);
		world.setBlockMetadataWithNotify(i + 1, j + 23, k + 24, 3, 2);
		setBlock(world, i + 1, j + 23, k + 25, Blocks.leaves, 7);
		world.setBlockMetadataWithNotify(i + 1, j + 23, k + 25, 7, 2);
		setBlock(world, i + 1, j + 23, k + 26, Blocks.leaves, 7);
		world.setBlockMetadataWithNotify(i + 1, j + 23, k + 26, 7, 2);
		setBlock(world, i + 1, j + 24, k + 0, Blocks.log, 3);
		world.setBlockMetadataWithNotify(i + 1, j + 24, k + 0, 3, 2);
		setBlock(world, i + 1, j + 24, k + 22, Blocks.leaves, 7);
		world.setBlockMetadataWithNotify(i + 1, j + 24, k + 22, 7, 2);
		setBlock(world, i + 1, j + 24, k + 23, Blocks.leaves, 7);
		world.setBlockMetadataWithNotify(i + 1, j + 24, k + 23, 7, 2);
		setBlock(world, i + 1, j + 24, k + 24, Blocks.leaves, 7);
		world.setBlockMetadataWithNotify(i + 1, j + 24, k + 24, 7, 2);
		setBlock(world, i + 1, j + 24, k + 25, Blocks.leaves, 7);
		world.setBlockMetadataWithNotify(i + 1, j + 24, k + 25, 7, 2);
		setBlock(world, i + 1, j + 24, k + 26, Blocks.leaves, 7);
		world.setBlockMetadataWithNotify(i + 1, j + 24, k + 26, 7, 2);
		setBlock(world, i + 1, j + 25, k + 0, Blocks.log, 3);
		world.setBlockMetadataWithNotify(i + 1, j + 25, k + 0, 3, 2);
		setBlock(world, i + 1, j + 25, k + 1, Blocks.log, 3);
		world.setBlockMetadataWithNotify(i + 1, j + 25, k + 1, 3, 2);
		setBlock(world, i + 1, j + 25, k + 23, Blocks.leaves, 7);
		world.setBlockMetadataWithNotify(i + 1, j + 25, k + 23, 7, 2);
		setBlock(world, i + 1, j + 25, k + 24, Blocks.log, 3);
		world.setBlockMetadataWithNotify(i + 1, j + 25, k + 24, 3, 2);
		setBlock(world, i + 1, j + 25, k + 25, Blocks.leaves, 7);
		world.setBlockMetadataWithNotify(i + 1, j + 25, k + 25, 7, 2);
		setBlock(world, i + 1, j + 26, k + 0, Blocks.log, 3);
		world.setBlockMetadataWithNotify(i + 1, j + 26, k + 0, 3, 2);
		setBlock(world, i + 1, j + 26, k + 23, Blocks.leaves, 7);
		world.setBlockMetadataWithNotify(i + 1, j + 26, k + 23, 7, 2);
		setBlock(world, i + 1, j + 26, k + 24, Blocks.leaves, 7);
		world.setBlockMetadataWithNotify(i + 1, j + 26, k + 24, 7, 2);
		setBlock(world, i + 1, j + 26, k + 25, Blocks.log, 3);
		world.setBlockMetadataWithNotify(i + 1, j + 26, k + 25, 3, 2);
		setBlock(world, i + 1, j + 26, k + 26, Blocks.leaves, 7);
		world.setBlockMetadataWithNotify(i + 1, j + 26, k + 26, 7, 2);
		setBlock(world, i + 1, j + 26, k + 27, Blocks.leaves, 7);
		world.setBlockMetadataWithNotify(i + 1, j + 26, k + 27, 7, 2);
		setBlock(world, i + 1, j + 27, k + 1, Blocks.log, 3);
		world.setBlockMetadataWithNotify(i + 1, j + 27, k + 1, 3, 2);
		setBlock(world, i + 1, j + 27, k + 10, Blocks.log, 3);
		world.setBlockMetadataWithNotify(i + 1, j + 27, k + 10, 3, 2);
		setBlock(world, i + 1, j + 27, k + 23, Blocks.leaves, 7);
		world.setBlockMetadataWithNotify(i + 1, j + 27, k + 23, 7, 2);
		setBlock(world, i + 1, j + 27, k + 24, Blocks.leaves, 7);
		world.setBlockMetadataWithNotify(i + 1, j + 27, k + 24, 7, 2);
		setBlock(world, i + 1, j + 27, k + 25, Blocks.leaves, 7);
		world.setBlockMetadataWithNotify(i + 1, j + 27, k + 25, 7, 2);
		setBlock(world, i + 1, j + 27, k + 26, Blocks.leaves, 7);
		world.setBlockMetadataWithNotify(i + 1, j + 27, k + 26, 7, 2);
		setBlock(world, i + 1, j + 27, k + 27, Blocks.leaves, 7);
		world.setBlockMetadataWithNotify(i + 1, j + 27, k + 27, 7, 2);
		setBlock(world, i + 1, j + 28, k + 24, Blocks.leaves, 7);
		world.setBlockMetadataWithNotify(i + 1, j + 28, k + 24, 7, 2);
		setBlock(world, i + 1, j + 28, k + 25, Blocks.leaves, 7);
		world.setBlockMetadataWithNotify(i + 1, j + 28, k + 25, 7, 2);
		setBlock(world, i + 1, j + 28, k + 26, Blocks.leaves, 7);
		world.setBlockMetadataWithNotify(i + 1, j + 28, k + 26, 7, 2);
		setBlock(world, i + 1, j + 29, k + 17, Blocks.leaves, 7);
		world.setBlockMetadataWithNotify(i + 1, j + 29, k + 17, 7, 2);
		setBlock(world, i + 1, j + 29, k + 18, Blocks.leaves, 7);
		world.setBlockMetadataWithNotify(i + 1, j + 29, k + 18, 7, 2);
		setBlock(world, i + 1, j + 29, k + 19, Blocks.leaves, 7);
		world.setBlockMetadataWithNotify(i + 1, j + 29, k + 19, 7, 2);
		setBlock(world, i + 1, j + 29, k + 20, Blocks.leaves, 7);
		world.setBlockMetadataWithNotify(i + 1, j + 29, k + 20, 7, 2);
		setBlock(world, i + 1, j + 29, k + 21, Blocks.leaves, 7);
		world.setBlockMetadataWithNotify(i + 1, j + 29, k + 21, 7, 2);
		setBlock(world, i + 1, j + 29, k + 25, Blocks.leaves, 7);
		world.setBlockMetadataWithNotify(i + 1, j + 29, k + 25, 7, 2);
		setBlock(world, i + 1, j + 30, k + 12, Blocks.log, 3);
		world.setBlockMetadataWithNotify(i + 1, j + 30, k + 12, 3, 2);
		setBlock(world, i + 1, j + 30, k + 16, Blocks.log, 3);
		world.setBlockMetadataWithNotify(i + 1, j + 30, k + 16, 3, 2);
		setBlock(world, i + 1, j + 30, k + 18, Blocks.leaves, 7);
		world.setBlockMetadataWithNotify(i + 1, j + 30, k + 18, 7, 2);
		setBlock(world, i + 1, j + 30, k + 19, Blocks.leaves, 7);
		world.setBlockMetadataWithNotify(i + 1, j + 30, k + 19, 7, 2);
		setBlock(world, i + 1, j + 30, k + 20, Blocks.leaves, 7);
		world.setBlockMetadataWithNotify(i + 1, j + 30, k + 20, 7, 2);
		setBlock(world, i + 1, j + 30, k + 21, Blocks.leaves, 7);
		world.setBlockMetadataWithNotify(i + 1, j + 30, k + 21, 7, 2);
		setBlock(world, i + 1, j + 30, k + 22, Blocks.leaves, 7);
		world.setBlockMetadataWithNotify(i + 1, j + 30, k + 22, 7, 2);
		setBlock(world, i + 1, j + 30, k + 23, Blocks.leaves, 7);
		world.setBlockMetadataWithNotify(i + 1, j + 30, k + 23, 7, 2);
		setBlock(world, i + 1, j + 30, k + 24, Blocks.leaves, 7);
		world.setBlockMetadataWithNotify(i + 1, j + 30, k + 24, 7, 2);
		setBlock(world, i + 1, j + 31, k + 9, Blocks.log, 3);
		world.setBlockMetadataWithNotify(i + 1, j + 31, k + 9, 3, 2);
		setBlock(world, i + 1, j + 31, k + 19, Blocks.leaves, 7);
		world.setBlockMetadataWithNotify(i + 1, j + 31, k + 19, 7, 2);
		setBlock(world, i + 1, j + 31, k + 21, Blocks.leaves, 7);
		world.setBlockMetadataWithNotify(i + 1, j + 31, k + 21, 7, 2);
		setBlock(world, i + 1, j + 31, k + 22, Blocks.leaves, 7);
		world.setBlockMetadataWithNotify(i + 1, j + 31, k + 22, 7, 2);
		setBlock(world, i + 1, j + 31, k + 23, Blocks.leaves, 7);
		world.setBlockMetadataWithNotify(i + 1, j + 31, k + 23, 7, 2);
		setBlock(world, i + 1, j + 32, k + 5, Blocks.log, 3);
		world.setBlockMetadataWithNotify(i + 1, j + 32, k + 5, 3, 2);
		setBlock(world, i + 1, j + 32, k + 22, Blocks.leaves, 7);
		world.setBlockMetadataWithNotify(i + 1, j + 32, k + 22, 7, 2);
		setBlock(world, i + 1, j + 33, k + 4, Blocks.log, 3);
		world.setBlockMetadataWithNotify(i + 1, j + 33, k + 4, 3, 2);
		setBlock(world, i + 1, j + 33, k + 6, Blocks.log, 3);
		world.setBlockMetadataWithNotify(i + 1, j + 33, k + 6, 3, 2);
		setBlock(world, i + 1, j + 34, k + 9, Blocks.leaves, 7);
		world.setBlockMetadataWithNotify(i + 1, j + 34, k + 9, 7, 2);
		setBlock(world, i + 1, j + 34, k + 10, Blocks.leaves, 7);
		world.setBlockMetadataWithNotify(i + 1, j + 34, k + 10, 7, 2);
		setBlock(world, i + 1, j + 34, k + 11, Blocks.leaves, 7);
		world.setBlockMetadataWithNotify(i + 1, j + 34, k + 11, 7, 2);
		setBlock(world, i + 1, j + 34, k + 12, Blocks.leaves, 7);
		world.setBlockMetadataWithNotify(i + 1, j + 34, k + 12, 7, 2);
		setBlock(world, i + 1, j + 34, k + 13, Blocks.leaves, 7);
		world.setBlockMetadataWithNotify(i + 1, j + 34, k + 13, 7, 2);
		setBlock(world, i + 1, j + 35, k + 10, Blocks.leaves, 7);
		world.setBlockMetadataWithNotify(i + 1, j + 35, k + 10, 7, 2);
		setBlock(world, i + 1, j + 35, k + 11, Blocks.leaves, 7);
		world.setBlockMetadataWithNotify(i + 1, j + 35, k + 11, 7, 2);
		setBlock(world, i + 1, j + 35, k + 12, Blocks.leaves, 7);
		world.setBlockMetadataWithNotify(i + 1, j + 35, k + 12, 7, 2);
		setBlock(world, i + 1, j + 36, k + 0, Blocks.log, 3);
		world.setBlockMetadataWithNotify(i + 1, j + 36, k + 0, 3, 2);
		setBlock(world, i + 1, j + 36, k + 11, Blocks.leaves, 7);
		world.setBlockMetadataWithNotify(i + 1, j + 36, k + 11, 7, 2);
		setBlock(world, i + 1, j + 36, k + 22, Blocks.log, 3);
		world.setBlockMetadataWithNotify(i + 1, j + 36, k + 22, 3, 2);
		setBlock(world, i + 1, j + 37, k + 12, Blocks.log, 3);
		world.setBlockMetadataWithNotify(i + 1, j + 37, k + 12, 3, 2);
		setBlock(world, i + 1, j + 37, k + 21, Blocks.leaves, 7);
		world.setBlockMetadataWithNotify(i + 1, j + 37, k + 21, 7, 2);
		setBlock(world, i + 1, j + 37, k + 22, Blocks.leaves, 7);
		world.setBlockMetadataWithNotify(i + 1, j + 37, k + 22, 7, 2);
		setBlock(world, i + 1, j + 37, k + 23, Blocks.log, 3);
		world.setBlockMetadataWithNotify(i + 1, j + 37, k + 23, 3, 2);
		setBlock(world, i + 1, j + 37, k + 24, Blocks.leaves, 7);
		world.setBlockMetadataWithNotify(i + 1, j + 37, k + 24, 7, 2);
		setBlock(world, i + 1, j + 37, k + 25, Blocks.leaves, 7);
		world.setBlockMetadataWithNotify(i + 1, j + 37, k + 25, 7, 2);
		setBlock(world, i + 1, j + 38, k + 9, Blocks.log, 3);
		world.setBlockMetadataWithNotify(i + 1, j + 38, k + 9, 3, 2);
		setBlock(world, i + 1, j + 38, k + 21, Blocks.leaves, 7);
		world.setBlockMetadataWithNotify(i + 1, j + 38, k + 21, 7, 2);
		setBlock(world, i + 1, j + 38, k + 22, Blocks.leaves, 7);
		world.setBlockMetadataWithNotify(i + 1, j + 38, k + 22, 7, 2);
		setBlock(world, i + 1, j + 38, k + 23, Blocks.leaves, 7);
		world.setBlockMetadataWithNotify(i + 1, j + 38, k + 23, 7, 2);
		setBlock(world, i + 1, j + 38, k + 24, Blocks.leaves, 7);
		world.setBlockMetadataWithNotify(i + 1, j + 38, k + 24, 7, 2);
		setBlock(world, i + 1, j + 38, k + 25, Blocks.leaves, 7);
		world.setBlockMetadataWithNotify(i + 1, j + 38, k + 25, 7, 2);
		setBlock(world, i + 1, j + 39, k + 6, Blocks.leaves, 7);
		world.setBlockMetadataWithNotify(i + 1, j + 39, k + 6, 7, 2);
		setBlock(world, i + 1, j + 39, k + 7, Blocks.leaves, 7);
		world.setBlockMetadataWithNotify(i + 1, j + 39, k + 7, 7, 2);
		setBlock(world, i + 1, j + 39, k + 8, Blocks.leaves, 7);
		world.setBlockMetadataWithNotify(i + 1, j + 39, k + 8, 7, 2);
		setBlock(world, i + 1, j + 39, k + 9, Blocks.leaves, 7);
		world.setBlockMetadataWithNotify(i + 1, j + 39, k + 9, 7, 2);
		setBlock(world, i + 1, j + 39, k + 10, Blocks.leaves, 7);
		world.setBlockMetadataWithNotify(i + 1, j + 39, k + 10, 7, 2);
		setBlock(world, i + 1, j + 39, k + 22, Blocks.leaves, 7);
		world.setBlockMetadataWithNotify(i + 1, j + 39, k + 22, 7, 2);
		setBlock(world, i + 1, j + 39, k + 23, Blocks.leaves, 7);
		world.setBlockMetadataWithNotify(i + 1, j + 39, k + 23, 7, 2);
		setBlock(world, i + 1, j + 39, k + 24, Blocks.leaves, 7);
		world.setBlockMetadataWithNotify(i + 1, j + 39, k + 24, 7, 2);
		setBlock(world, i + 1, j + 40, k + 7, Blocks.leaves, 7);
		world.setBlockMetadataWithNotify(i + 1, j + 40, k + 7, 7, 2);
		setBlock(world, i + 1, j + 40, k + 8, Blocks.leaves, 7);
		world.setBlockMetadataWithNotify(i + 1, j + 40, k + 8, 7, 2);
		setBlock(world, i + 1, j + 40, k + 9, Blocks.leaves, 7);
		world.setBlockMetadataWithNotify(i + 1, j + 40, k + 9, 7, 2);
		setBlock(world, i + 1, j + 40, k + 23, Blocks.leaves, 7);
		world.setBlockMetadataWithNotify(i + 1, j + 40, k + 23, 7, 2);
		setBlock(world, i + 1, j + 41, k + 8, Blocks.leaves, 7);
		world.setBlockMetadataWithNotify(i + 1, j + 41, k + 8, 7, 2);
		setBlock(world, i + 1, j + 42, k + 17, Blocks.leaves, 7);
		world.setBlockMetadataWithNotify(i + 1, j + 42, k + 17, 7, 2);
		setBlock(world, i + 1, j + 42, k + 18, Blocks.leaves, 7);
		world.setBlockMetadataWithNotify(i + 1, j + 42, k + 18, 7, 2);
		setBlock(world, i + 1, j + 42, k + 19, Blocks.leaves, 7);
		world.setBlockMetadataWithNotify(i + 1, j + 42, k + 19, 7, 2);
		setBlock(world, i + 1, j + 42, k + 20, Blocks.leaves, 7);
		world.setBlockMetadataWithNotify(i + 1, j + 42, k + 20, 7, 2);
		setBlock(world, i + 1, j + 42, k + 21, Blocks.leaves, 7);
		world.setBlockMetadataWithNotify(i + 1, j + 42, k + 21, 7, 2);
		setBlock(world, i + 1, j + 43, k + 18, Blocks.leaves, 7);
		world.setBlockMetadataWithNotify(i + 1, j + 43, k + 18, 7, 2);
		setBlock(world, i + 1, j + 43, k + 19, Blocks.leaves, 7);
		world.setBlockMetadataWithNotify(i + 1, j + 43, k + 19, 7, 2);
		setBlock(world, i + 1, j + 43, k + 20, Blocks.leaves, 7);
		world.setBlockMetadataWithNotify(i + 1, j + 43, k + 20, 7, 2);
		setBlock(world, i + 1, j + 44, k + 6, Blocks.log, 3);
		world.setBlockMetadataWithNotify(i + 1, j + 44, k + 6, 3, 2);
		setBlock(world, i + 1, j + 44, k + 19, Blocks.leaves, 7);
		world.setBlockMetadataWithNotify(i + 1, j + 44, k + 19, 7, 2);
		setBlock(world, i + 1, j + 45, k + 1, Blocks.leaves, 7);
		world.setBlockMetadataWithNotify(i + 1, j + 45, k + 1, 7, 2);
		setBlock(world, i + 1, j + 45, k + 2, Blocks.leaves, 7);
		world.setBlockMetadataWithNotify(i + 1, j + 45, k + 2, 7, 2);
		setBlock(world, i + 1, j + 45, k + 3, Blocks.log, 3);
		world.setBlockMetadataWithNotify(i + 1, j + 45, k + 3, 3, 2);
		setBlock(world, i + 1, j + 45, k + 4, Blocks.leaves, 7);
		world.setBlockMetadataWithNotify(i + 1, j + 45, k + 4, 7, 2);
		setBlock(world, i + 1, j + 45, k + 5, Blocks.log, 3);
		world.setBlockMetadataWithNotify(i + 1, j + 45, k + 5, 3, 2);
		setBlock(world, i + 1, j + 45, k + 6, Blocks.leaves, 7);
		world.setBlockMetadataWithNotify(i + 1, j + 45, k + 6, 7, 2);
		setBlock(world, i + 1, j + 45, k + 7, Blocks.leaves, 7);
		world.setBlockMetadataWithNotify(i + 1, j + 45, k + 7, 7, 2);
		setBlock(world, i + 1, j + 45, k + 8, Blocks.leaves, 7);
		world.setBlockMetadataWithNotify(i + 1, j + 45, k + 8, 7, 2);
		setBlock(world, i + 1, j + 45, k + 9, Blocks.leaves, 7);
		world.setBlockMetadataWithNotify(i + 1, j + 45, k + 9, 7, 2);
		setBlock(world, i + 1, j + 46, k + 1, Blocks.leaves, 7);
		world.setBlockMetadataWithNotify(i + 1, j + 46, k + 1, 7, 2);
		setBlock(world, i + 1, j + 46, k + 2, Blocks.leaves, 7);
		world.setBlockMetadataWithNotify(i + 1, j + 46, k + 2, 7, 2);
		setBlock(world, i + 1, j + 46, k + 3, Blocks.leaves, 7);
		world.setBlockMetadataWithNotify(i + 1, j + 46, k + 3, 7, 2);
		setBlock(world, i + 1, j + 46, k + 4, Blocks.leaves, 7);
		world.setBlockMetadataWithNotify(i + 1, j + 46, k + 4, 7, 2);
		setBlock(world, i + 1, j + 46, k + 5, Blocks.leaves, 7);
		world.setBlockMetadataWithNotify(i + 1, j + 46, k + 5, 7, 2);
		setBlock(world, i + 1, j + 46, k + 6, Blocks.leaves, 7);
		world.setBlockMetadataWithNotify(i + 1, j + 46, k + 6, 7, 2);
		setBlock(world, i + 1, j + 46, k + 7, Blocks.leaves, 7);
		world.setBlockMetadataWithNotify(i + 1, j + 46, k + 7, 7, 2);
		setBlock(world, i + 1, j + 46, k + 8, Blocks.leaves, 7);
		world.setBlockMetadataWithNotify(i + 1, j + 46, k + 8, 7, 2);
		setBlock(world, i + 1, j + 47, k + 2, Blocks.leaves, 7);
		world.setBlockMetadataWithNotify(i + 1, j + 47, k + 2, 7, 2);
		setBlock(world, i + 1, j + 47, k + 3, Blocks.leaves, 7);
		world.setBlockMetadataWithNotify(i + 1, j + 47, k + 3, 7, 2);
		setBlock(world, i + 1, j + 47, k + 4, Blocks.leaves, 7);
		world.setBlockMetadataWithNotify(i + 1, j + 47, k + 4, 7, 2);
		setBlock(world, i + 1, j + 47, k + 7, Blocks.leaves, 7);
		world.setBlockMetadataWithNotify(i + 1, j + 47, k + 7, 7, 2);
		setBlock(world, i + 1, j + 48, k + 3, Blocks.leaves, 7);
		world.setBlockMetadataWithNotify(i + 1, j + 48, k + 3, 7, 2);
		setBlock(world, i + 1, j + 48, k + 4, Blocks.log, 3);
		world.setBlockMetadataWithNotify(i + 1, j + 48, k + 4, 3, 2);
		setBlock(world, i + 1, j + 49, k + 1, Blocks.leaves, 7);
		world.setBlockMetadataWithNotify(i + 1, j + 49, k + 1, 7, 2);
		setBlock(world, i + 1, j + 49, k + 2, Blocks.leaves, 7);
		world.setBlockMetadataWithNotify(i + 1, j + 49, k + 2, 7, 2);
		setBlock(world, i + 1, j + 49, k + 3, Blocks.leaves, 7);
		world.setBlockMetadataWithNotify(i + 1, j + 49, k + 3, 7, 2);
		setBlock(world, i + 1, j + 50, k + 2, Blocks.leaves, 7);
		world.setBlockMetadataWithNotify(i + 1, j + 50, k + 2, 7, 2);
		setBlock(world, i + 1, j + 51, k + 10, Blocks.leaves, 7);
		world.setBlockMetadataWithNotify(i + 1, j + 51, k + 10, 7, 2);
		setBlock(world, i + 1, j + 51, k + 11, Blocks.leaves, 7);
		world.setBlockMetadataWithNotify(i + 1, j + 51, k + 11, 7, 2);
		setBlock(world, i + 1, j + 51, k + 12, Blocks.leaves, 7);
		world.setBlockMetadataWithNotify(i + 1, j + 51, k + 12, 7, 2);
		setBlock(world, i + 1, j + 51, k + 15, Blocks.log, 3);
		world.setBlockMetadataWithNotify(i + 1, j + 51, k + 15, 3, 2);
		setBlock(world, i + 1, j + 52, k + 11, Blocks.leaves, 7);
		world.setBlockMetadataWithNotify(i + 1, j + 52, k + 11, 7, 2);
		setBlock(world, i + 1, j + 52, k + 14, Blocks.leaves, 7);
		world.setBlockMetadataWithNotify(i + 1, j + 52, k + 14, 7, 2);
		setBlock(world, i + 1, j + 52, k + 15, Blocks.leaves, 7);
		world.setBlockMetadataWithNotify(i + 1, j + 52, k + 15, 7, 2);
		setBlock(world, i + 1, j + 52, k + 16, Blocks.log, 3);
		world.setBlockMetadataWithNotify(i + 1, j + 52, k + 16, 3, 2);
		setBlock(world, i + 1, j + 52, k + 17, Blocks.leaves, 7);
		world.setBlockMetadataWithNotify(i + 1, j + 52, k + 17, 7, 2);
		setBlock(world, i + 1, j + 52, k + 18, Blocks.leaves, 7);
		world.setBlockMetadataWithNotify(i + 1, j + 52, k + 18, 7, 2);
		setBlock(world, i + 1, j + 53, k + 11, Blocks.leaves, 7);
		world.setBlockMetadataWithNotify(i + 1, j + 53, k + 11, 7, 2);
		setBlock(world, i + 1, j + 53, k + 12, Blocks.leaves, 7);
		world.setBlockMetadataWithNotify(i + 1, j + 53, k + 12, 7, 2);
		setBlock(world, i + 1, j + 53, k + 13, Blocks.leaves, 7);
		world.setBlockMetadataWithNotify(i + 1, j + 53, k + 13, 7, 2);
		setBlock(world, i + 1, j + 53, k + 14, Blocks.leaves, 7);
		world.setBlockMetadataWithNotify(i + 1, j + 53, k + 14, 7, 2);
		setBlock(world, i + 1, j + 53, k + 15, Blocks.leaves, 7);
		world.setBlockMetadataWithNotify(i + 1, j + 53, k + 15, 7, 2);
		setBlock(world, i + 1, j + 53, k + 16, Blocks.leaves, 7);
		world.setBlockMetadataWithNotify(i + 1, j + 53, k + 16, 7, 2);
		setBlock(world, i + 1, j + 53, k + 17, Blocks.leaves, 7);
		world.setBlockMetadataWithNotify(i + 1, j + 53, k + 17, 7, 2);
		setBlock(world, i + 1, j + 53, k + 18, Blocks.leaves, 7);
		world.setBlockMetadataWithNotify(i + 1, j + 53, k + 18, 7, 2);
		setBlock(world, i + 1, j + 54, k + 12, Blocks.leaves, 7);
		world.setBlockMetadataWithNotify(i + 1, j + 54, k + 12, 7, 2);
		setBlock(world, i + 1, j + 54, k + 13, Blocks.leaves, 7);
		world.setBlockMetadataWithNotify(i + 1, j + 54, k + 13, 7, 2);
		setBlock(world, i + 1, j + 54, k + 14, Blocks.leaves, 7);
		world.setBlockMetadataWithNotify(i + 1, j + 54, k + 14, 7, 2);
		setBlock(world, i + 1, j + 54, k + 15, Blocks.leaves, 7);
		world.setBlockMetadataWithNotify(i + 1, j + 54, k + 15, 7, 2);
		setBlock(world, i + 1, j + 54, k + 16, Blocks.leaves, 7);
		world.setBlockMetadataWithNotify(i + 1, j + 54, k + 16, 7, 2);
		setBlock(world, i + 1, j + 54, k + 17, Blocks.leaves, 7);
		world.setBlockMetadataWithNotify(i + 1, j + 54, k + 17, 7, 2);
		setBlock(world, i + 1, j + 55, k + 13, Blocks.leaves, 7);
		world.setBlockMetadataWithNotify(i + 1, j + 55, k + 13, 7, 2);
		setBlock(world, i + 1, j + 55, k + 16, Blocks.leaves, 7);
		world.setBlockMetadataWithNotify(i + 1, j + 55, k + 16, 7, 2);
		setBlock(world, i + 1, j + 59, k + 5, Blocks.leaves, 7);
		world.setBlockMetadataWithNotify(i + 1, j + 59, k + 5, 7, 2);
		setBlock(world, i + 1, j + 59, k + 6, Blocks.leaves, 7);
		world.setBlockMetadataWithNotify(i + 1, j + 59, k + 6, 7, 2);
		setBlock(world, i + 1, j + 59, k + 7, Blocks.leaves, 7);
		world.setBlockMetadataWithNotify(i + 1, j + 59, k + 7, 7, 2);
		setBlock(world, i + 1, j + 60, k + 6, Blocks.leaves, 7);
		world.setBlockMetadataWithNotify(i + 1, j + 60, k + 6, 7, 2);
		setBlock(world, i + 1, j + 62, k + 8, Blocks.leaves, 7);
		world.setBlockMetadataWithNotify(i + 1, j + 62, k + 8, 7, 2);
		setBlock(world, i + 1, j + 62, k + 9, Blocks.leaves, 7);
		world.setBlockMetadataWithNotify(i + 1, j + 62, k + 9, 7, 2);
		setBlock(world, i + 1, j + 62, k + 10, Blocks.leaves, 7);
		world.setBlockMetadataWithNotify(i + 1, j + 62, k + 10, 7, 2);
		setBlock(world, i + 1, j + 63, k + 9, Blocks.leaves, 7);
		world.setBlockMetadataWithNotify(i + 1, j + 63, k + 9, 7, 2);
		setBlock(world, i + 2, j + 0, k + 5, Blocks.log, 3);
		world.setBlockMetadataWithNotify(i + 2, j + 0, k + 5, 3, 2);
		setBlock(world, i + 2, j + 0, k + 6, Blocks.log, 3);
		world.setBlockMetadataWithNotify(i + 2, j + 0, k + 6, 3, 2);
		setBlock(world, i + 2, j + 0, k + 7, Blocks.log, 3);
		world.setBlockMetadataWithNotify(i + 2, j + 0, k + 7, 3, 2);
		setBlock(world, i + 2, j + 0, k + 8, Blocks.log, 3);
		world.setBlockMetadataWithNotify(i + 2, j + 0, k + 8, 3, 2);
		setBlock(world, i + 2, j + 0, k + 9, Blocks.log, 3);
		world.setBlockMetadataWithNotify(i + 2, j + 0, k + 9, 3, 2);
		setBlock(world, i + 2, j + 0, k + 10, Blocks.log, 3);
		world.setBlockMetadataWithNotify(i + 2, j + 0, k + 10, 3, 2);
		setBlock(world, i + 2, j + 0, k + 11, Blocks.log, 3);
		world.setBlockMetadataWithNotify(i + 2, j + 0, k + 11, 3, 2);
		setBlock(world, i + 2, j + 0, k + 12, Blocks.log, 3);
		world.setBlockMetadataWithNotify(i + 2, j + 0, k + 12, 3, 2);
		setBlock(world, i + 2, j + 0, k + 13, Blocks.log, 3);
		world.setBlockMetadataWithNotify(i + 2, j + 0, k + 13, 3, 2);
		setBlock(world, i + 2, j + 0, k + 14, Blocks.log, 3);
		world.setBlockMetadataWithNotify(i + 2, j + 0, k + 14, 3, 2);
		setBlock(world, i + 2, j + 1, k + 5, Blocks.log, 3);
		world.setBlockMetadataWithNotify(i + 2, j + 1, k + 5, 3, 2);
		setBlock(world, i + 2, j + 1, k + 6, Blocks.log, 3);
		world.setBlockMetadataWithNotify(i + 2, j + 1, k + 6, 3, 2);
		setBlock(world, i + 2, j + 1, k + 7, Blocks.log, 3);
		world.setBlockMetadataWithNotify(i + 2, j + 1, k + 7, 3, 2);
		setBlock(world, i + 2, j + 1, k + 8, Blocks.log, 3);
		world.setBlockMetadataWithNotify(i + 2, j + 1, k + 8, 3, 2);
		setBlock(world, i + 2, j + 1, k + 9, Blocks.log, 3);
		world.setBlockMetadataWithNotify(i + 2, j + 1, k + 9, 3, 2);
		setBlock(world, i + 2, j + 1, k + 10, Blocks.log, 3);
		world.setBlockMetadataWithNotify(i + 2, j + 1, k + 10, 3, 2);
		setBlock(world, i + 2, j + 1, k + 11, Blocks.log, 3);
		world.setBlockMetadataWithNotify(i + 2, j + 1, k + 11, 3, 2);
		setBlock(world, i + 2, j + 1, k + 12, Blocks.log, 3);
		world.setBlockMetadataWithNotify(i + 2, j + 1, k + 12, 3, 2);
		setBlock(world, i + 2, j + 2, k + 6, Blocks.log, 3);
		world.setBlockMetadataWithNotify(i + 2, j + 2, k + 6, 3, 2);
		setBlock(world, i + 2, j + 2, k + 7, Blocks.log, 3);
		world.setBlockMetadataWithNotify(i + 2, j + 2, k + 7, 3, 2);
		setBlock(world, i + 2, j + 2, k + 8, Blocks.log, 3);
		world.setBlockMetadataWithNotify(i + 2, j + 2, k + 8, 3, 2);
		setBlock(world, i + 2, j + 2, k + 9, Blocks.log, 3);
		world.setBlockMetadataWithNotify(i + 2, j + 2, k + 9, 3, 2);
		setBlock(world, i + 2, j + 2, k + 10, Blocks.log, 3);
		world.setBlockMetadataWithNotify(i + 2, j + 2, k + 10, 3, 2);
		setBlock(world, i + 2, j + 15, k + 0, Blocks.log, 1);
		world.setBlockMetadataWithNotify(i + 2, j + 15, k + 0, 1, 2);
		setBlock(world, i + 2, j + 16, k + 0, Blocks.log, 1);
		world.setBlockMetadataWithNotify(i + 2, j + 16, k + 0, 1, 2);
		setBlock(world, i + 2, j + 17, k + 0, Blocks.log, 1);
		world.setBlockMetadataWithNotify(i + 2, j + 17, k + 0, 1, 2);
		setBlock(world, i + 2, j + 17, k + 11, Blocks.log, 3);
		world.setBlockMetadataWithNotify(i + 2, j + 17, k + 11, 3, 2);
		setBlock(world, i + 2, j + 17, k + 12, Blocks.log, 3);
		world.setBlockMetadataWithNotify(i + 2, j + 17, k + 12, 3, 2);
		setBlock(world, i + 2, j + 17, k + 13, Blocks.log, 3);
		world.setBlockMetadataWithNotify(i + 2, j + 17, k + 13, 3, 2);
		setBlock(world, i + 2, j + 18, k + 11, Blocks.log, 3);
		world.setBlockMetadataWithNotify(i + 2, j + 18, k + 11, 3, 2);
		setBlock(world, i + 2, j + 18, k + 12, Blocks.log, 3);
		world.setBlockMetadataWithNotify(i + 2, j + 18, k + 12, 3, 2);
		setBlock(world, i + 2, j + 18, k + 13, Blocks.log, 3);
		world.setBlockMetadataWithNotify(i + 2, j + 18, k + 13, 3, 2);
		setBlock(world, i + 2, j + 19, k + 11, Blocks.log, 3);
		world.setBlockMetadataWithNotify(i + 2, j + 19, k + 11, 3, 2);
		setBlock(world, i + 2, j + 19, k + 12, Blocks.log, 3);
		world.setBlockMetadataWithNotify(i + 2, j + 19, k + 12, 3, 2);
		setBlock(world, i + 2, j + 19, k + 13, Blocks.log, 3);
		world.setBlockMetadataWithNotify(i + 2, j + 19, k + 13, 3, 2);
		setBlock(world, i + 2, j + 19, k + 20, Blocks.log, 3);
		world.setBlockMetadataWithNotify(i + 2, j + 19, k + 20, 3, 2);
		setBlock(world, i + 2, j + 19, k + 22, Blocks.log, 3);
		world.setBlockMetadataWithNotify(i + 2, j + 19, k + 22, 3, 2);
		setBlock(world, i + 2, j + 20, k + 5, Blocks.log, 3);
		world.setBlockMetadataWithNotify(i + 2, j + 20, k + 5, 3, 2);
		setBlock(world, i + 2, j + 21, k + 4, Blocks.log, 3);
		world.setBlockMetadataWithNotify(i + 2, j + 21, k + 4, 3, 2);
		setBlock(world, i + 2, j + 21, k + 5, Blocks.log, 3);
		world.setBlockMetadataWithNotify(i + 2, j + 21, k + 5, 3, 2);
		setBlock(world, i + 2, j + 21, k + 6, Blocks.log, 3);
		world.setBlockMetadataWithNotify(i + 2, j + 21, k + 6, 3, 2);
		setBlock(world, i + 2, j + 22, k + 5, Blocks.log, 3);
		world.setBlockMetadataWithNotify(i + 2, j + 22, k + 5, 3, 2);
		setBlock(world, i + 2, j + 22, k + 19, Blocks.log, 3);
		world.setBlockMetadataWithNotify(i + 2, j + 22, k + 19, 3, 2);
		setBlock(world, i + 2, j + 22, k + 20, Blocks.log, 3);
		world.setBlockMetadataWithNotify(i + 2, j + 22, k + 20, 3, 2);
		setBlock(world, i + 2, j + 22, k + 21, Blocks.log, 3);
		world.setBlockMetadataWithNotify(i + 2, j + 22, k + 21, 3, 2);
		setBlock(world, i + 2, j + 23, k + 1, Blocks.log, 3);
		world.setBlockMetadataWithNotify(i + 2, j + 23, k + 1, 3, 2);
		setBlock(world, i + 2, j + 23, k + 12, Blocks.log, 3);
		world.setBlockMetadataWithNotify(i + 2, j + 23, k + 12, 3, 2);
		setBlock(world, i + 2, j + 23, k + 22, Blocks.leaves, 7);
		world.setBlockMetadataWithNotify(i + 2, j + 23, k + 22, 7, 2);
		setBlock(world, i + 2, j + 23, k + 23, Blocks.leaves, 7);
		world.setBlockMetadataWithNotify(i + 2, j + 23, k + 23, 7, 2);
		setBlock(world, i + 2, j + 23, k + 24, Blocks.leaves, 7);
		world.setBlockMetadataWithNotify(i + 2, j + 23, k + 24, 7, 2);
		setBlock(world, i + 2, j + 23, k + 25, Blocks.leaves, 7);
		world.setBlockMetadataWithNotify(i + 2, j + 23, k + 25, 7, 2);
		setBlock(world, i + 2, j + 23, k + 26, Blocks.leaves, 7);
		world.setBlockMetadataWithNotify(i + 2, j + 23, k + 26, 7, 2);
		setBlock(world, i + 2, j + 24, k + 0, Blocks.log, 3);
		world.setBlockMetadataWithNotify(i + 2, j + 24, k + 0, 3, 2);
		setBlock(world, i + 2, j + 24, k + 1, Blocks.log, 3);
		world.setBlockMetadataWithNotify(i + 2, j + 24, k + 1, 3, 2);
		setBlock(world, i + 2, j + 24, k + 2, Blocks.log, 3);
		world.setBlockMetadataWithNotify(i + 2, j + 24, k + 2, 3, 2);
		setBlock(world, i + 2, j + 24, k + 23, Blocks.leaves, 7);
		world.setBlockMetadataWithNotify(i + 2, j + 24, k + 23, 7, 2);
		setBlock(world, i + 2, j + 24, k + 24, Blocks.leaves, 7);
		world.setBlockMetadataWithNotify(i + 2, j + 24, k + 24, 7, 2);
		setBlock(world, i + 2, j + 24, k + 25, Blocks.leaves, 7);
		world.setBlockMetadataWithNotify(i + 2, j + 24, k + 25, 7, 2);
		setBlock(world, i + 2, j + 25, k + 1, Blocks.log, 3);
		world.setBlockMetadataWithNotify(i + 2, j + 25, k + 1, 3, 2);
		setBlock(world, i + 2, j + 25, k + 22, Blocks.log, 3);
		world.setBlockMetadataWithNotify(i + 2, j + 25, k + 22, 3, 2);
		setBlock(world, i + 2, j + 25, k + 23, Blocks.log, 3);
		world.setBlockMetadataWithNotify(i + 2, j + 25, k + 23, 3, 2);
		setBlock(world, i + 2, j + 25, k + 24, Blocks.leaves, 7);
		world.setBlockMetadataWithNotify(i + 2, j + 25, k + 24, 7, 2);
		setBlock(world, i + 2, j + 26, k + 10, Blocks.log, 3);
		world.setBlockMetadataWithNotify(i + 2, j + 26, k + 10, 3, 2);
		setBlock(world, i + 2, j + 26, k + 23, Blocks.leaves, 7);
		world.setBlockMetadataWithNotify(i + 2, j + 26, k + 23, 7, 2);
		setBlock(world, i + 2, j + 26, k + 24, Blocks.leaves, 7);
		world.setBlockMetadataWithNotify(i + 2, j + 26, k + 24, 7, 2);
		setBlock(world, i + 2, j + 26, k + 25, Blocks.leaves, 7);
		world.setBlockMetadataWithNotify(i + 2, j + 26, k + 25, 7, 2);
		setBlock(world, i + 2, j + 26, k + 26, Blocks.leaves, 7);
		world.setBlockMetadataWithNotify(i + 2, j + 26, k + 26, 7, 2);
		setBlock(world, i + 2, j + 26, k + 27, Blocks.leaves, 7);
		world.setBlockMetadataWithNotify(i + 2, j + 26, k + 27, 7, 2);
		setBlock(world, i + 2, j + 27, k + 2, Blocks.log, 3);
		world.setBlockMetadataWithNotify(i + 2, j + 27, k + 2, 3, 2);
		setBlock(world, i + 2, j + 27, k + 10, Blocks.log, 3);
		world.setBlockMetadataWithNotify(i + 2, j + 27, k + 10, 3, 2);
		setBlock(world, i + 2, j + 27, k + 24, Blocks.leaves, 7);
		world.setBlockMetadataWithNotify(i + 2, j + 27, k + 24, 7, 2);
		setBlock(world, i + 2, j + 27, k + 25, Blocks.leaves, 7);
		world.setBlockMetadataWithNotify(i + 2, j + 27, k + 25, 7, 2);
		setBlock(world, i + 2, j + 27, k + 26, Blocks.leaves, 7);
		world.setBlockMetadataWithNotify(i + 2, j + 27, k + 26, 7, 2);
		setBlock(world, i + 2, j + 28, k + 18, Blocks.log, 3);
		world.setBlockMetadataWithNotify(i + 2, j + 28, k + 18, 3, 2);
		setBlock(world, i + 2, j + 28, k + 25, Blocks.leaves, 7);
		world.setBlockMetadataWithNotify(i + 2, j + 28, k + 25, 7, 2);
		setBlock(world, i + 2, j + 29, k + 12, Blocks.log, 3);
		world.setBlockMetadataWithNotify(i + 2, j + 29, k + 12, 3, 2);
		setBlock(world, i + 2, j + 29, k + 17, Blocks.leaves, 7);
		world.setBlockMetadataWithNotify(i + 2, j + 29, k + 17, 7, 2);
		setBlock(world, i + 2, j + 29, k + 18, Blocks.leaves, 7);
		world.setBlockMetadataWithNotify(i + 2, j + 29, k + 18, 7, 2);
		setBlock(world, i + 2, j + 29, k + 19, Blocks.log, 3);
		world.setBlockMetadataWithNotify(i + 2, j + 29, k + 19, 3, 2);
		setBlock(world, i + 2, j + 29, k + 20, Blocks.leaves, 7);
		world.setBlockMetadataWithNotify(i + 2, j + 29, k + 20, 7, 2);
		setBlock(world, i + 2, j + 29, k + 21, Blocks.log, 3);
		world.setBlockMetadataWithNotify(i + 2, j + 29, k + 21, 3, 2);
		setBlock(world, i + 2, j + 30, k + 15, Blocks.log, 3);
		world.setBlockMetadataWithNotify(i + 2, j + 30, k + 15, 3, 2);
		setBlock(world, i + 2, j + 30, k + 17, Blocks.leaves, 7);
		world.setBlockMetadataWithNotify(i + 2, j + 30, k + 17, 7, 2);
		setBlock(world, i + 2, j + 30, k + 18, Blocks.leaves, 7);
		world.setBlockMetadataWithNotify(i + 2, j + 30, k + 18, 7, 2);
		setBlock(world, i + 2, j + 30, k + 19, Blocks.leaves, 7);
		world.setBlockMetadataWithNotify(i + 2, j + 30, k + 19, 7, 2);
		setBlock(world, i + 2, j + 30, k + 20, Blocks.leaves, 7);
		world.setBlockMetadataWithNotify(i + 2, j + 30, k + 20, 7, 2);
		setBlock(world, i + 2, j + 30, k + 21, Blocks.leaves, 7);
		world.setBlockMetadataWithNotify(i + 2, j + 30, k + 21, 7, 2);
		setBlock(world, i + 2, j + 30, k + 22, Blocks.log, 3);
		world.setBlockMetadataWithNotify(i + 2, j + 30, k + 22, 3, 2);
		setBlock(world, i + 2, j + 30, k + 23, Blocks.leaves, 7);
		world.setBlockMetadataWithNotify(i + 2, j + 30, k + 23, 7, 2);
		setBlock(world, i + 2, j + 30, k + 24, Blocks.leaves, 7);
		world.setBlockMetadataWithNotify(i + 2, j + 30, k + 24, 7, 2);
		setBlock(world, i + 2, j + 31, k + 9, Blocks.log, 3);
		world.setBlockMetadataWithNotify(i + 2, j + 31, k + 9, 3, 2);
		setBlock(world, i + 2, j + 31, k + 18, Blocks.leaves, 7);
		world.setBlockMetadataWithNotify(i + 2, j + 31, k + 18, 7, 2);
		setBlock(world, i + 2, j + 31, k + 19, Blocks.leaves, 7);
		world.setBlockMetadataWithNotify(i + 2, j + 31, k + 19, 7, 2);
		setBlock(world, i + 2, j + 31, k + 20, Blocks.leaves, 7);
		world.setBlockMetadataWithNotify(i + 2, j + 31, k + 20, 7, 2);
		setBlock(world, i + 2, j + 31, k + 21, Blocks.leaves, 7);
		world.setBlockMetadataWithNotify(i + 2, j + 31, k + 21, 7, 2);
		setBlock(world, i + 2, j + 31, k + 22, Blocks.leaves, 7);
		world.setBlockMetadataWithNotify(i + 2, j + 31, k + 22, 7, 2);
		setBlock(world, i + 2, j + 31, k + 23, Blocks.leaves, 7);
		world.setBlockMetadataWithNotify(i + 2, j + 31, k + 23, 7, 2);
		setBlock(world, i + 2, j + 31, k + 24, Blocks.leaves, 7);
		world.setBlockMetadataWithNotify(i + 2, j + 31, k + 24, 7, 2);
		setBlock(world, i + 2, j + 32, k + 6, Blocks.log, 3);
		world.setBlockMetadataWithNotify(i + 2, j + 32, k + 6, 3, 2);
		setBlock(world, i + 2, j + 32, k + 19, Blocks.leaves, 7);
		world.setBlockMetadataWithNotify(i + 2, j + 32, k + 19, 7, 2);
		setBlock(world, i + 2, j + 32, k + 21, Blocks.leaves, 7);
		world.setBlockMetadataWithNotify(i + 2, j + 32, k + 21, 7, 2);
		setBlock(world, i + 2, j + 32, k + 22, Blocks.leaves, 7);
		world.setBlockMetadataWithNotify(i + 2, j + 32, k + 22, 7, 2);
		setBlock(world, i + 2, j + 32, k + 23, Blocks.leaves, 7);
		world.setBlockMetadataWithNotify(i + 2, j + 32, k + 23, 7, 2);
		setBlock(world, i + 2, j + 33, k + 5, Blocks.log, 3);
		world.setBlockMetadataWithNotify(i + 2, j + 33, k + 5, 3, 2);
		setBlock(world, i + 2, j + 33, k + 6, Blocks.log, 3);
		world.setBlockMetadataWithNotify(i + 2, j + 33, k + 6, 3, 2);
		setBlock(world, i + 2, j + 33, k + 22, Blocks.leaves, 7);
		world.setBlockMetadataWithNotify(i + 2, j + 33, k + 22, 7, 2);
		setBlock(world, i + 2, j + 34, k + 9, Blocks.leaves, 7);
		world.setBlockMetadataWithNotify(i + 2, j + 34, k + 9, 7, 2);
		setBlock(world, i + 2, j + 34, k + 10, Blocks.leaves, 7);
		world.setBlockMetadataWithNotify(i + 2, j + 34, k + 10, 7, 2);
		setBlock(world, i + 2, j + 34, k + 11, Blocks.log, 3);
		world.setBlockMetadataWithNotify(i + 2, j + 34, k + 11, 3, 2);
		setBlock(world, i + 2, j + 34, k + 12, Blocks.leaves, 7);
		world.setBlockMetadataWithNotify(i + 2, j + 34, k + 12, 7, 2);
		setBlock(world, i + 2, j + 34, k + 13, Blocks.leaves, 7);
		world.setBlockMetadataWithNotify(i + 2, j + 34, k + 13, 7, 2);
		setBlock(world, i + 2, j + 35, k + 9, Blocks.leaves, 7);
		world.setBlockMetadataWithNotify(i + 2, j + 35, k + 9, 7, 2);
		setBlock(world, i + 2, j + 35, k + 10, Blocks.leaves, 7);
		world.setBlockMetadataWithNotify(i + 2, j + 35, k + 10, 7, 2);
		setBlock(world, i + 2, j + 35, k + 11, Blocks.leaves, 7);
		world.setBlockMetadataWithNotify(i + 2, j + 35, k + 11, 7, 2);
		setBlock(world, i + 2, j + 35, k + 12, Blocks.leaves, 7);
		world.setBlockMetadataWithNotify(i + 2, j + 35, k + 12, 7, 2);
		setBlock(world, i + 2, j + 35, k + 13, Blocks.leaves, 7);
		world.setBlockMetadataWithNotify(i + 2, j + 35, k + 13, 7, 2);
		setBlock(world, i + 2, j + 36, k + 1, Blocks.log, 3);
		world.setBlockMetadataWithNotify(i + 2, j + 36, k + 1, 3, 2);
		setBlock(world, i + 2, j + 36, k + 10, Blocks.leaves, 7);
		world.setBlockMetadataWithNotify(i + 2, j + 36, k + 10, 7, 2);
		setBlock(world, i + 2, j + 36, k + 11, Blocks.leaves, 7);
		world.setBlockMetadataWithNotify(i + 2, j + 36, k + 11, 7, 2);
		setBlock(world, i + 2, j + 36, k + 12, Blocks.leaves, 7);
		world.setBlockMetadataWithNotify(i + 2, j + 36, k + 12, 7, 2);
		setBlock(world, i + 2, j + 36, k + 20, Blocks.log, 3);
		world.setBlockMetadataWithNotify(i + 2, j + 36, k + 20, 3, 2);
		setBlock(world, i + 2, j + 36, k + 21, Blocks.log, 3);
		world.setBlockMetadataWithNotify(i + 2, j + 36, k + 21, 3, 2);
		setBlock(world, i + 2, j + 37, k + 11, Blocks.log, 3);
		world.setBlockMetadataWithNotify(i + 2, j + 37, k + 11, 3, 2);
		setBlock(world, i + 2, j + 37, k + 21, Blocks.leaves, 7);
		world.setBlockMetadataWithNotify(i + 2, j + 37, k + 21, 7, 2);
		setBlock(world, i + 2, j + 37, k + 22, Blocks.leaves, 7);
		world.setBlockMetadataWithNotify(i + 2, j + 37, k + 22, 7, 2);
		setBlock(world, i + 2, j + 37, k + 23, Blocks.leaves, 7);
		world.setBlockMetadataWithNotify(i + 2, j + 37, k + 23, 7, 2);
		setBlock(world, i + 2, j + 37, k + 24, Blocks.leaves, 7);
		world.setBlockMetadataWithNotify(i + 2, j + 37, k + 24, 7, 2);
		setBlock(world, i + 2, j + 37, k + 25, Blocks.leaves, 7);
		world.setBlockMetadataWithNotify(i + 2, j + 37, k + 25, 7, 2);
		setBlock(world, i + 2, j + 38, k + 9, Blocks.log, 3);
		world.setBlockMetadataWithNotify(i + 2, j + 38, k + 9, 3, 2);
		setBlock(world, i + 2, j + 38, k + 22, Blocks.leaves, 7);
		world.setBlockMetadataWithNotify(i + 2, j + 38, k + 22, 7, 2);
		setBlock(world, i + 2, j + 38, k + 23, Blocks.leaves, 7);
		world.setBlockMetadataWithNotify(i + 2, j + 38, k + 23, 7, 2);
		setBlock(world, i + 2, j + 38, k + 24, Blocks.leaves, 7);
		world.setBlockMetadataWithNotify(i + 2, j + 38, k + 24, 7, 2);
		setBlock(world, i + 2, j + 39, k + 7, Blocks.leaves, 7);
		world.setBlockMetadataWithNotify(i + 2, j + 39, k + 7, 7, 2);
		setBlock(world, i + 2, j + 39, k + 8, Blocks.leaves, 7);
		world.setBlockMetadataWithNotify(i + 2, j + 39, k + 8, 7, 2);
		setBlock(world, i + 2, j + 39, k + 9, Blocks.leaves, 7);
		world.setBlockMetadataWithNotify(i + 2, j + 39, k + 9, 7, 2);
		setBlock(world, i + 2, j + 39, k + 23, Blocks.leaves, 7);
		world.setBlockMetadataWithNotify(i + 2, j + 39, k + 23, 7, 2);
		setBlock(world, i + 2, j + 40, k + 8, Blocks.leaves, 7);
		world.setBlockMetadataWithNotify(i + 2, j + 40, k + 8, 7, 2);
		setBlock(world, i + 2, j + 42, k + 18, Blocks.leaves, 7);
		world.setBlockMetadataWithNotify(i + 2, j + 42, k + 18, 7, 2);
		setBlock(world, i + 2, j + 42, k + 19, Blocks.leaves, 7);
		world.setBlockMetadataWithNotify(i + 2, j + 42, k + 19, 7, 2);
		setBlock(world, i + 2, j + 42, k + 20, Blocks.leaves, 7);
		world.setBlockMetadataWithNotify(i + 2, j + 42, k + 20, 7, 2);
		setBlock(world, i + 2, j + 43, k + 19, Blocks.leaves, 7);
		world.setBlockMetadataWithNotify(i + 2, j + 43, k + 19, 7, 2);
		setBlock(world, i + 2, j + 44, k + 5, Blocks.log, 3);
		world.setBlockMetadataWithNotify(i + 2, j + 44, k + 5, 3, 2);
		setBlock(world, i + 2, j + 44, k + 7, Blocks.log, 3);
		world.setBlockMetadataWithNotify(i + 2, j + 44, k + 7, 3, 2);
		setBlock(world, i + 2, j + 45, k + 1, Blocks.leaves, 7);
		world.setBlockMetadataWithNotify(i + 2, j + 45, k + 1, 7, 2);
		setBlock(world, i + 2, j + 45, k + 2, Blocks.leaves, 7);
		world.setBlockMetadataWithNotify(i + 2, j + 45, k + 2, 7, 2);
		setBlock(world, i + 2, j + 45, k + 3, Blocks.leaves, 7);
		world.setBlockMetadataWithNotify(i + 2, j + 45, k + 3, 7, 2);
		setBlock(world, i + 2, j + 45, k + 4, Blocks.leaves, 7);
		world.setBlockMetadataWithNotify(i + 2, j + 45, k + 4, 7, 2);
		setBlock(world, i + 2, j + 45, k + 5, Blocks.leaves, 7);
		world.setBlockMetadataWithNotify(i + 2, j + 45, k + 5, 7, 2);
		setBlock(world, i + 2, j + 45, k + 6, Blocks.leaves, 7);
		world.setBlockMetadataWithNotify(i + 2, j + 45, k + 6, 7, 2);
		setBlock(world, i + 2, j + 45, k + 7, Blocks.log, 3);
		world.setBlockMetadataWithNotify(i + 2, j + 45, k + 7, 3, 2);
		setBlock(world, i + 2, j + 45, k + 8, Blocks.leaves, 7);
		world.setBlockMetadataWithNotify(i + 2, j + 45, k + 8, 7, 2);
		setBlock(world, i + 2, j + 45, k + 9, Blocks.leaves, 7);
		world.setBlockMetadataWithNotify(i + 2, j + 45, k + 9, 7, 2);
		setBlock(world, i + 2, j + 46, k + 2, Blocks.leaves, 7);
		world.setBlockMetadataWithNotify(i + 2, j + 46, k + 2, 7, 2);
		setBlock(world, i + 2, j + 46, k + 3, Blocks.leaves, 7);
		world.setBlockMetadataWithNotify(i + 2, j + 46, k + 3, 7, 2);
		setBlock(world, i + 2, j + 46, k + 4, Blocks.leaves, 7);
		world.setBlockMetadataWithNotify(i + 2, j + 46, k + 4, 7, 2);
		setBlock(world, i + 2, j + 46, k + 5, Blocks.leaves, 7);
		world.setBlockMetadataWithNotify(i + 2, j + 46, k + 5, 7, 2);
		setBlock(world, i + 2, j + 46, k + 6, Blocks.leaves, 7);
		world.setBlockMetadataWithNotify(i + 2, j + 46, k + 6, 7, 2);
		setBlock(world, i + 2, j + 46, k + 7, Blocks.leaves, 7);
		world.setBlockMetadataWithNotify(i + 2, j + 46, k + 7, 7, 2);
		setBlock(world, i + 2, j + 46, k + 8, Blocks.leaves, 7);
		world.setBlockMetadataWithNotify(i + 2, j + 46, k + 8, 7, 2);
		setBlock(world, i + 2, j + 46, k + 9, Blocks.leaves, 7);
		world.setBlockMetadataWithNotify(i + 2, j + 46, k + 9, 7, 2);
		setBlock(world, i + 2, j + 47, k + 3, Blocks.leaves, 7);
		world.setBlockMetadataWithNotify(i + 2, j + 47, k + 3, 7, 2);
		setBlock(world, i + 2, j + 47, k + 5, Blocks.leaves, 7);
		world.setBlockMetadataWithNotify(i + 2, j + 47, k + 5, 7, 2);
		setBlock(world, i + 2, j + 47, k + 6, Blocks.leaves, 7);
		world.setBlockMetadataWithNotify(i + 2, j + 47, k + 6, 7, 2);
		setBlock(world, i + 2, j + 47, k + 7, Blocks.leaves, 7);
		world.setBlockMetadataWithNotify(i + 2, j + 47, k + 7, 7, 2);
		setBlock(world, i + 2, j + 47, k + 8, Blocks.leaves, 7);
		world.setBlockMetadataWithNotify(i + 2, j + 47, k + 8, 7, 2);
		setBlock(world, i + 2, j + 48, k + 4, Blocks.log, 3);
		world.setBlockMetadataWithNotify(i + 2, j + 48, k + 4, 3, 2);
		setBlock(world, i + 2, j + 48, k + 6, Blocks.leaves, 7);
		world.setBlockMetadataWithNotify(i + 2, j + 48, k + 6, 7, 2);
		setBlock(world, i + 2, j + 48, k + 7, Blocks.leaves, 7);
		world.setBlockMetadataWithNotify(i + 2, j + 48, k + 7, 7, 2);
		setBlock(world, i + 2, j + 51, k + 14, Blocks.log, 3);
		world.setBlockMetadataWithNotify(i + 2, j + 51, k + 14, 3, 2);
		setBlock(world, i + 2, j + 52, k + 14, Blocks.leaves, 7);
		world.setBlockMetadataWithNotify(i + 2, j + 52, k + 14, 7, 2);
		setBlock(world, i + 2, j + 52, k + 15, Blocks.leaves, 7);
		world.setBlockMetadataWithNotify(i + 2, j + 52, k + 15, 7, 2);
		setBlock(world, i + 2, j + 52, k + 16, Blocks.leaves, 7);
		world.setBlockMetadataWithNotify(i + 2, j + 52, k + 16, 7, 2);
		setBlock(world, i + 2, j + 52, k + 17, Blocks.leaves, 7);
		world.setBlockMetadataWithNotify(i + 2, j + 52, k + 17, 7, 2);
		setBlock(world, i + 2, j + 52, k + 18, Blocks.leaves, 7);
		world.setBlockMetadataWithNotify(i + 2, j + 52, k + 18, 7, 2);
		setBlock(world, i + 2, j + 53, k + 4, Blocks.leaves, 7);
		world.setBlockMetadataWithNotify(i + 2, j + 53, k + 4, 7, 2);
		setBlock(world, i + 2, j + 53, k + 5, Blocks.leaves, 7);
		world.setBlockMetadataWithNotify(i + 2, j + 53, k + 5, 7, 2);
		setBlock(world, i + 2, j + 53, k + 6, Blocks.leaves, 7);
		world.setBlockMetadataWithNotify(i + 2, j + 53, k + 6, 7, 2);
		setBlock(world, i + 2, j + 53, k + 12, Blocks.leaves, 7);
		world.setBlockMetadataWithNotify(i + 2, j + 53, k + 12, 7, 2);
		setBlock(world, i + 2, j + 53, k + 13, Blocks.leaves, 7);
		world.setBlockMetadataWithNotify(i + 2, j + 53, k + 13, 7, 2);
		setBlock(world, i + 2, j + 53, k + 14, Blocks.leaves, 7);
		world.setBlockMetadataWithNotify(i + 2, j + 53, k + 14, 7, 2);
		setBlock(world, i + 2, j + 53, k + 15, Blocks.leaves, 7);
		world.setBlockMetadataWithNotify(i + 2, j + 53, k + 15, 7, 2);
		setBlock(world, i + 2, j + 53, k + 16, Blocks.leaves, 7);
		world.setBlockMetadataWithNotify(i + 2, j + 53, k + 16, 7, 2);
		setBlock(world, i + 2, j + 53, k + 17, Blocks.leaves, 7);
		world.setBlockMetadataWithNotify(i + 2, j + 53, k + 17, 7, 2);
		setBlock(world, i + 2, j + 54, k + 5, Blocks.leaves, 7);
		world.setBlockMetadataWithNotify(i + 2, j + 54, k + 5, 7, 2);
		setBlock(world, i + 2, j + 54, k + 13, Blocks.leaves, 7);
		world.setBlockMetadataWithNotify(i + 2, j + 54, k + 13, 7, 2);
		setBlock(world, i + 2, j + 54, k + 16, Blocks.leaves, 7);
		world.setBlockMetadataWithNotify(i + 2, j + 54, k + 16, 7, 2);
		setBlock(world, i + 2, j + 56, k + 11, Blocks.leaves, 7);
		world.setBlockMetadataWithNotify(i + 2, j + 56, k + 11, 7, 2);
		setBlock(world, i + 2, j + 56, k + 12, Blocks.leaves, 7);
		world.setBlockMetadataWithNotify(i + 2, j + 56, k + 12, 7, 2);
		setBlock(world, i + 2, j + 56, k + 13, Blocks.leaves, 7);
		world.setBlockMetadataWithNotify(i + 2, j + 56, k + 13, 7, 2);
		setBlock(world, i + 2, j + 57, k + 12, Blocks.leaves, 7);
		world.setBlockMetadataWithNotify(i + 2, j + 57, k + 12, 7, 2);
		setBlock(world, i + 2, j + 59, k + 4, Blocks.leaves, 7);
		world.setBlockMetadataWithNotify(i + 2, j + 59, k + 4, 7, 2);
		setBlock(world, i + 2, j + 59, k + 5, Blocks.leaves, 7);
		world.setBlockMetadataWithNotify(i + 2, j + 59, k + 5, 7, 2);
		setBlock(world, i + 2, j + 59, k + 6, Blocks.leaves, 7);
		world.setBlockMetadataWithNotify(i + 2, j + 59, k + 6, 7, 2);
		setBlock(world, i + 2, j + 59, k + 7, Blocks.leaves, 7);
		world.setBlockMetadataWithNotify(i + 2, j + 59, k + 7, 7, 2);
		setBlock(world, i + 2, j + 59, k + 8, Blocks.leaves, 7);
		world.setBlockMetadataWithNotify(i + 2, j + 59, k + 8, 7, 2);
		setBlock(world, i + 2, j + 60, k + 5, Blocks.leaves, 7);
		world.setBlockMetadataWithNotify(i + 2, j + 60, k + 5, 7, 2);
		setBlock(world, i + 2, j + 60, k + 6, Blocks.leaves, 7);
		world.setBlockMetadataWithNotify(i + 2, j + 60, k + 6, 7, 2);
		setBlock(world, i + 2, j + 60, k + 7, Blocks.leaves, 7);
		world.setBlockMetadataWithNotify(i + 2, j + 60, k + 7, 7, 2);
		setBlock(world, i + 2, j + 60, k + 8, Blocks.leaves, 7);
		world.setBlockMetadataWithNotify(i + 2, j + 60, k + 8, 7, 2);
		setBlock(world, i + 2, j + 60, k + 9, Blocks.leaves, 7);
		world.setBlockMetadataWithNotify(i + 2, j + 60, k + 9, 7, 2);
		setBlock(world, i + 2, j + 60, k + 10, Blocks.leaves, 7);
		world.setBlockMetadataWithNotify(i + 2, j + 60, k + 10, 7, 2);
		setBlock(world, i + 2, j + 61, k + 6, Blocks.leaves, 7);
		world.setBlockMetadataWithNotify(i + 2, j + 61, k + 6, 7, 2);
		setBlock(world, i + 2, j + 61, k + 9, Blocks.leaves, 7);
		world.setBlockMetadataWithNotify(i + 2, j + 61, k + 9, 7, 2);
		setBlock(world, i + 2, j + 62, k + 7, Blocks.leaves, 7);
		world.setBlockMetadataWithNotify(i + 2, j + 62, k + 7, 7, 2);
		setBlock(world, i + 2, j + 62, k + 8, Blocks.leaves, 7);
		world.setBlockMetadataWithNotify(i + 2, j + 62, k + 8, 7, 2);
		setBlock(world, i + 2, j + 62, k + 9, Blocks.leaves, 7);
		world.setBlockMetadataWithNotify(i + 2, j + 62, k + 9, 7, 2);
		setBlock(world, i + 2, j + 62, k + 10, Blocks.leaves, 7);
		world.setBlockMetadataWithNotify(i + 2, j + 62, k + 10, 7, 2);
		setBlock(world, i + 2, j + 62, k + 11, Blocks.leaves, 7);
		world.setBlockMetadataWithNotify(i + 2, j + 62, k + 11, 7, 2);
		setBlock(world, i + 2, j + 63, k + 8, Blocks.leaves, 7);
		world.setBlockMetadataWithNotify(i + 2, j + 63, k + 8, 7, 2);
		setBlock(world, i + 2, j + 63, k + 9, Blocks.leaves, 7);
		world.setBlockMetadataWithNotify(i + 2, j + 63, k + 9, 7, 2);
		setBlock(world, i + 2, j + 63, k + 10, Blocks.leaves, 7);
		world.setBlockMetadataWithNotify(i + 2, j + 63, k + 10, 7, 2);
		setBlock(world, i + 2, j + 64, k + 9, Blocks.leaves, 7);
		world.setBlockMetadataWithNotify(i + 2, j + 64, k + 9, 7, 2);
		setBlock(world, i + 3, j + 0, k + 4, Blocks.log, 3);
		world.setBlockMetadataWithNotify(i + 3, j + 0, k + 4, 3, 2);
		setBlock(world, i + 3, j + 0, k + 5, Blocks.log, 3);
		world.setBlockMetadataWithNotify(i + 3, j + 0, k + 5, 3, 2);
		setBlock(world, i + 3, j + 0, k + 6, Blocks.log, 3);
		world.setBlockMetadataWithNotify(i + 3, j + 0, k + 6, 3, 2);
		setBlock(world, i + 3, j + 0, k + 7, Blocks.log, 3);
		world.setBlockMetadataWithNotify(i + 3, j + 0, k + 7, 3, 2);
		setBlock(world, i + 3, j + 0, k + 8, Blocks.log, 3);
		world.setBlockMetadataWithNotify(i + 3, j + 0, k + 8, 3, 2);
		setBlock(world, i + 3, j + 0, k + 9, Blocks.log, 3);
		world.setBlockMetadataWithNotify(i + 3, j + 0, k + 9, 3, 2);
		setBlock(world, i + 3, j + 0, k + 10, Blocks.log, 3);
		world.setBlockMetadataWithNotify(i + 3, j + 0, k + 10, 3, 2);
		setBlock(world, i + 3, j + 0, k + 11, Blocks.log, 3);
		world.setBlockMetadataWithNotify(i + 3, j + 0, k + 11, 3, 2);
		setBlock(world, i + 3, j + 0, k + 12, Blocks.log, 3);
		world.setBlockMetadataWithNotify(i + 3, j + 0, k + 12, 3, 2);
		setBlock(world, i + 3, j + 0, k + 13, Blocks.log, 3);
		world.setBlockMetadataWithNotify(i + 3, j + 0, k + 13, 3, 2);
		setBlock(world, i + 3, j + 0, k + 14, Blocks.log, 3);
		world.setBlockMetadataWithNotify(i + 3, j + 0, k + 14, 3, 2);
		setBlock(world, i + 3, j + 0, k + 15, Blocks.log, 3);
		world.setBlockMetadataWithNotify(i + 3, j + 0, k + 15, 3, 2);
		setBlock(world, i + 3, j + 1, k + 4, Blocks.log, 3);
		world.setBlockMetadataWithNotify(i + 3, j + 1, k + 4, 3, 2);
		setBlock(world, i + 3, j + 1, k + 5, Blocks.log, 3);
		world.setBlockMetadataWithNotify(i + 3, j + 1, k + 5, 3, 2);
		setBlock(world, i + 3, j + 1, k + 6, Blocks.log, 3);
		world.setBlockMetadataWithNotify(i + 3, j + 1, k + 6, 3, 2);
		setBlock(world, i + 3, j + 1, k + 7, Blocks.log, 3);
		world.setBlockMetadataWithNotify(i + 3, j + 1, k + 7, 3, 2);
		setBlock(world, i + 3, j + 1, k + 8, Blocks.log, 3);
		world.setBlockMetadataWithNotify(i + 3, j + 1, k + 8, 3, 2);
		setBlock(world, i + 3, j + 1, k + 9, Blocks.log, 3);
		world.setBlockMetadataWithNotify(i + 3, j + 1, k + 9, 3, 2);
		setBlock(world, i + 3, j + 1, k + 10, Blocks.log, 3);
		world.setBlockMetadataWithNotify(i + 3, j + 1, k + 10, 3, 2);
		setBlock(world, i + 3, j + 1, k + 11, Blocks.log, 3);
		world.setBlockMetadataWithNotify(i + 3, j + 1, k + 11, 3, 2);
		setBlock(world, i + 3, j + 1, k + 12, Blocks.log, 3);
		world.setBlockMetadataWithNotify(i + 3, j + 1, k + 12, 3, 2);
		setBlock(world, i + 3, j + 1, k + 13, Blocks.log, 3);
		world.setBlockMetadataWithNotify(i + 3, j + 1, k + 13, 3, 2);
		setBlock(world, i + 3, j + 1, k + 14, Blocks.log, 3);
		world.setBlockMetadataWithNotify(i + 3, j + 1, k + 14, 3, 2);
		setBlock(world, i + 3, j + 2, k + 5, Blocks.log, 3);
		world.setBlockMetadataWithNotify(i + 3, j + 2, k + 5, 3, 2);
		setBlock(world, i + 3, j + 2, k + 6, Blocks.log, 3);
		world.setBlockMetadataWithNotify(i + 3, j + 2, k + 6, 3, 2);
		setBlock(world, i + 3, j + 2, k + 7, Blocks.log, 3);
		world.setBlockMetadataWithNotify(i + 3, j + 2, k + 7, 3, 2);
		setBlock(world, i + 3, j + 2, k + 8, Blocks.log, 3);
		world.setBlockMetadataWithNotify(i + 3, j + 2, k + 8, 3, 2);
		setBlock(world, i + 3, j + 2, k + 9, Blocks.log, 3);
		world.setBlockMetadataWithNotify(i + 3, j + 2, k + 9, 3, 2);
		setBlock(world, i + 3, j + 2, k + 10, Blocks.log, 3);
		world.setBlockMetadataWithNotify(i + 3, j + 2, k + 10, 3, 2);
		setBlock(world, i + 3, j + 2, k + 11, Blocks.log, 3);
		world.setBlockMetadataWithNotify(i + 3, j + 2, k + 11, 3, 2);
		setBlock(world, i + 3, j + 3, k + 6, Blocks.log, 3);
		world.setBlockMetadataWithNotify(i + 3, j + 3, k + 6, 3, 2);
		setBlock(world, i + 3, j + 3, k + 7, Blocks.log, 3);
		world.setBlockMetadataWithNotify(i + 3, j + 3, k + 7, 3, 2);
		setBlock(world, i + 3, j + 3, k + 8, Blocks.log, 3);
		world.setBlockMetadataWithNotify(i + 3, j + 3, k + 8, 3, 2);
		setBlock(world, i + 3, j + 3, k + 9, Blocks.log, 3);
		world.setBlockMetadataWithNotify(i + 3, j + 3, k + 9, 3, 2);
		setBlock(world, i + 3, j + 3, k + 10, Blocks.log, 3);
		world.setBlockMetadataWithNotify(i + 3, j + 3, k + 10, 3, 2);
		setBlock(world, i + 3, j + 4, k + 6, Blocks.log, 3);
		world.setBlockMetadataWithNotify(i + 3, j + 4, k + 6, 3, 2);
		setBlock(world, i + 3, j + 4, k + 7, Blocks.log, 3);
		world.setBlockMetadataWithNotify(i + 3, j + 4, k + 7, 3, 2);
		setBlock(world, i + 3, j + 4, k + 8, Blocks.log, 3);
		world.setBlockMetadataWithNotify(i + 3, j + 4, k + 8, 3, 2);
		setBlock(world, i + 3, j + 4, k + 9, Blocks.log, 3);
		world.setBlockMetadataWithNotify(i + 3, j + 4, k + 9, 3, 2);
		setBlock(world, i + 3, j + 4, k + 10, Blocks.log, 3);
		world.setBlockMetadataWithNotify(i + 3, j + 4, k + 10, 3, 2);
		setBlock(world, i + 3, j + 5, k + 7, Blocks.log, 3);
		world.setBlockMetadataWithNotify(i + 3, j + 5, k + 7, 3, 2);
		setBlock(world, i + 3, j + 5, k + 8, Blocks.log, 3);
		world.setBlockMetadataWithNotify(i + 3, j + 5, k + 8, 3, 2);
		setBlock(world, i + 3, j + 5, k + 9, Blocks.log, 3);
		world.setBlockMetadataWithNotify(i + 3, j + 5, k + 9, 3, 2);
		setBlock(world, i + 3, j + 6, k + 7, Blocks.log, 3);
		world.setBlockMetadataWithNotify(i + 3, j + 6, k + 7, 3, 2);
		setBlock(world, i + 3, j + 6, k + 8, Blocks.log, 3);
		world.setBlockMetadataWithNotify(i + 3, j + 6, k + 8, 3, 2);
		setBlock(world, i + 3, j + 6, k + 9, Blocks.log, 3);
		world.setBlockMetadataWithNotify(i + 3, j + 6, k + 9, 3, 2);
		setBlock(world, i + 3, j + 7, k + 7, Blocks.log, 3);
		world.setBlockMetadataWithNotify(i + 3, j + 7, k + 7, 3, 2);
		setBlock(world, i + 3, j + 7, k + 8, Blocks.log, 3);
		world.setBlockMetadataWithNotify(i + 3, j + 7, k + 8, 3, 2);
		setBlock(world, i + 3, j + 7, k + 9, Blocks.log, 3);
		world.setBlockMetadataWithNotify(i + 3, j + 7, k + 9, 3, 2);
		setBlock(world, i + 3, j + 8, k + 8, Blocks.log, 3);
		world.setBlockMetadataWithNotify(i + 3, j + 8, k + 8, 3, 2);
		setBlock(world, i + 3, j + 15, k + 11, Blocks.log, 3);
		world.setBlockMetadataWithNotify(i + 3, j + 15, k + 11, 3, 2);
		setBlock(world, i + 3, j + 16, k + 0, Blocks.log, 1);
		world.setBlockMetadataWithNotify(i + 3, j + 16, k + 0, 1, 2);
		setBlock(world, i + 3, j + 16, k + 10, Blocks.log, 3);
		world.setBlockMetadataWithNotify(i + 3, j + 16, k + 10, 3, 2);
		setBlock(world, i + 3, j + 16, k + 11, Blocks.log, 3);
		world.setBlockMetadataWithNotify(i + 3, j + 16, k + 11, 3, 2);
		setBlock(world, i + 3, j + 16, k + 12, Blocks.log, 3);
		world.setBlockMetadataWithNotify(i + 3, j + 16, k + 12, 3, 2);
		setBlock(world, i + 3, j + 17, k + 0, Blocks.log, 1);
		world.setBlockMetadataWithNotify(i + 3, j + 17, k + 0, 1, 2);
		setBlock(world, i + 3, j + 17, k + 9, Blocks.log, 3);
		world.setBlockMetadataWithNotify(i + 3, j + 17, k + 9, 3, 2);
		setBlock(world, i + 3, j + 17, k + 10, Blocks.log, 3);
		world.setBlockMetadataWithNotify(i + 3, j + 17, k + 10, 3, 2);
		setBlock(world, i + 3, j + 17, k + 11, Blocks.log, 3);
		world.setBlockMetadataWithNotify(i + 3, j + 17, k + 11, 3, 2);
		setBlock(world, i + 3, j + 17, k + 12, Blocks.log, 3);
		world.setBlockMetadataWithNotify(i + 3, j + 17, k + 12, 3, 2);
		setBlock(world, i + 3, j + 17, k + 13, Blocks.log, 3);
		world.setBlockMetadataWithNotify(i + 3, j + 17, k + 13, 3, 2);
		setBlock(world, i + 3, j + 18, k + 10, Blocks.log, 3);
		world.setBlockMetadataWithNotify(i + 3, j + 18, k + 10, 3, 2);
		setBlock(world, i + 3, j + 18, k + 11, Blocks.log, 3);
		world.setBlockMetadataWithNotify(i + 3, j + 18, k + 11, 3, 2);
		setBlock(world, i + 3, j + 18, k + 12, Blocks.log, 3);
		world.setBlockMetadataWithNotify(i + 3, j + 18, k + 12, 3, 2);
		setBlock(world, i + 3, j + 18, k + 20, Blocks.log, 3);
		world.setBlockMetadataWithNotify(i + 3, j + 18, k + 20, 3, 2);
		setBlock(world, i + 3, j + 19, k + 11, Blocks.log, 3);
		world.setBlockMetadataWithNotify(i + 3, j + 19, k + 11, 3, 2);
		setBlock(world, i + 3, j + 19, k + 18, Blocks.log, 3);
		world.setBlockMetadataWithNotify(i + 3, j + 19, k + 18, 3, 2);
		setBlock(world, i + 3, j + 19, k + 19, Blocks.log, 3);
		world.setBlockMetadataWithNotify(i + 3, j + 19, k + 19, 3, 2);
		setBlock(world, i + 3, j + 19, k + 20, Blocks.log, 3);
		world.setBlockMetadataWithNotify(i + 3, j + 19, k + 20, 3, 2);
		setBlock(world, i + 3, j + 19, k + 21, Blocks.log, 3);
		world.setBlockMetadataWithNotify(i + 3, j + 19, k + 21, 3, 2);
		setBlock(world, i + 3, j + 20, k + 6, Blocks.log, 3);
		world.setBlockMetadataWithNotify(i + 3, j + 20, k + 6, 3, 2);
		setBlock(world, i + 3, j + 20, k + 20, Blocks.log, 3);
		world.setBlockMetadataWithNotify(i + 3, j + 20, k + 20, 3, 2);
		setBlock(world, i + 3, j + 21, k + 5, Blocks.log, 3);
		world.setBlockMetadataWithNotify(i + 3, j + 21, k + 5, 3, 2);
		setBlock(world, i + 3, j + 21, k + 6, Blocks.log, 3);
		world.setBlockMetadataWithNotify(i + 3, j + 21, k + 6, 3, 2);
		setBlock(world, i + 3, j + 21, k + 7, Blocks.log, 3);
		world.setBlockMetadataWithNotify(i + 3, j + 21, k + 7, 3, 2);
		setBlock(world, i + 3, j + 21, k + 14, Blocks.log, 3);
		world.setBlockMetadataWithNotify(i + 3, j + 21, k + 14, 3, 2);
		setBlock(world, i + 3, j + 22, k + 6, Blocks.log, 3);
		world.setBlockMetadataWithNotify(i + 3, j + 22, k + 6, 3, 2);
		setBlock(world, i + 3, j + 22, k + 11, Blocks.log, 3);
		world.setBlockMetadataWithNotify(i + 3, j + 22, k + 11, 3, 2);
		setBlock(world, i + 3, j + 22, k + 15, Blocks.log, 3);
		world.setBlockMetadataWithNotify(i + 3, j + 22, k + 15, 3, 2);
		setBlock(world, i + 3, j + 22, k + 16, Blocks.log, 3);
		world.setBlockMetadataWithNotify(i + 3, j + 22, k + 16, 3, 2);
		setBlock(world, i + 3, j + 22, k + 17, Blocks.log, 3);
		world.setBlockMetadataWithNotify(i + 3, j + 22, k + 17, 3, 2);
		setBlock(world, i + 3, j + 22, k + 18, Blocks.log, 3);
		world.setBlockMetadataWithNotify(i + 3, j + 22, k + 18, 3, 2);
		setBlock(world, i + 3, j + 23, k + 2, Blocks.log, 3);
		world.setBlockMetadataWithNotify(i + 3, j + 23, k + 2, 3, 2);
		setBlock(world, i + 3, j + 23, k + 23, Blocks.leaves, 7);
		world.setBlockMetadataWithNotify(i + 3, j + 23, k + 23, 7, 2);
		setBlock(world, i + 3, j + 23, k + 24, Blocks.leaves, 7);
		world.setBlockMetadataWithNotify(i + 3, j + 23, k + 24, 7, 2);
		setBlock(world, i + 3, j + 23, k + 25, Blocks.leaves, 7);
		world.setBlockMetadataWithNotify(i + 3, j + 23, k + 25, 7, 2);
		setBlock(world, i + 3, j + 24, k + 1, Blocks.log, 3);
		world.setBlockMetadataWithNotify(i + 3, j + 24, k + 1, 3, 2);
		setBlock(world, i + 3, j + 24, k + 2, Blocks.log, 3);
		world.setBlockMetadataWithNotify(i + 3, j + 24, k + 2, 3, 2);
		setBlock(world, i + 3, j + 24, k + 3, Blocks.log, 3);
		world.setBlockMetadataWithNotify(i + 3, j + 24, k + 3, 3, 2);
		setBlock(world, i + 3, j + 24, k + 24, Blocks.leaves, 7);
		world.setBlockMetadataWithNotify(i + 3, j + 24, k + 24, 7, 2);
		setBlock(world, i + 3, j + 25, k + 2, Blocks.log, 3);
		world.setBlockMetadataWithNotify(i + 3, j + 25, k + 2, 3, 2);
		setBlock(world, i + 3, j + 25, k + 9, Blocks.log, 3);
		world.setBlockMetadataWithNotify(i + 3, j + 25, k + 9, 3, 2);
		setBlock(world, i + 3, j + 25, k + 21, Blocks.log, 3);
		world.setBlockMetadataWithNotify(i + 3, j + 25, k + 21, 3, 2);
		setBlock(world, i + 3, j + 26, k + 3, Blocks.log, 3);
		world.setBlockMetadataWithNotify(i + 3, j + 26, k + 3, 3, 2);
		setBlock(world, i + 3, j + 26, k + 4, Blocks.log, 3);
		world.setBlockMetadataWithNotify(i + 3, j + 26, k + 4, 3, 2);
		setBlock(world, i + 3, j + 26, k + 8, Blocks.log, 3);
		world.setBlockMetadataWithNotify(i + 3, j + 26, k + 8, 3, 2);
		setBlock(world, i + 3, j + 26, k + 9, Blocks.log, 3);
		world.setBlockMetadataWithNotify(i + 3, j + 26, k + 9, 3, 2);
		setBlock(world, i + 3, j + 26, k + 10, Blocks.log, 3);
		world.setBlockMetadataWithNotify(i + 3, j + 26, k + 10, 3, 2);
		setBlock(world, i + 3, j + 26, k + 24, Blocks.leaves, 7);
		world.setBlockMetadataWithNotify(i + 3, j + 26, k + 24, 7, 2);
		setBlock(world, i + 3, j + 26, k + 25, Blocks.leaves, 7);
		world.setBlockMetadataWithNotify(i + 3, j + 26, k + 25, 7, 2);
		setBlock(world, i + 3, j + 26, k + 26, Blocks.leaves, 7);
		world.setBlockMetadataWithNotify(i + 3, j + 26, k + 26, 7, 2);
		setBlock(world, i + 3, j + 27, k + 9, Blocks.log, 3);
		world.setBlockMetadataWithNotify(i + 3, j + 27, k + 9, 3, 2);
		setBlock(world, i + 3, j + 27, k + 10, Blocks.log, 3);
		world.setBlockMetadataWithNotify(i + 3, j + 27, k + 10, 3, 2);
		setBlock(world, i + 3, j + 27, k + 23, Blocks.leaves, 7);
		world.setBlockMetadataWithNotify(i + 3, j + 27, k + 23, 7, 2);
		setBlock(world, i + 3, j + 27, k + 24, Blocks.leaves, 7);
		world.setBlockMetadataWithNotify(i + 3, j + 27, k + 24, 7, 2);
		setBlock(world, i + 3, j + 27, k + 25, Blocks.leaves, 7);
		world.setBlockMetadataWithNotify(i + 3, j + 27, k + 25, 7, 2);
		setBlock(world, i + 3, j + 27, k + 26, Blocks.leaves, 7);
		world.setBlockMetadataWithNotify(i + 3, j + 27, k + 26, 7, 2);
		setBlock(world, i + 3, j + 27, k + 27, Blocks.leaves, 7);
		world.setBlockMetadataWithNotify(i + 3, j + 27, k + 27, 7, 2);
		setBlock(world, i + 3, j + 28, k + 17, Blocks.log, 3);
		world.setBlockMetadataWithNotify(i + 3, j + 28, k + 17, 3, 2);
		setBlock(world, i + 3, j + 28, k + 24, Blocks.leaves, 7);
		world.setBlockMetadataWithNotify(i + 3, j + 28, k + 24, 7, 2);
		setBlock(world, i + 3, j + 28, k + 25, Blocks.leaves, 7);
		world.setBlockMetadataWithNotify(i + 3, j + 28, k + 25, 7, 2);
		setBlock(world, i + 3, j + 28, k + 26, Blocks.leaves, 7);
		world.setBlockMetadataWithNotify(i + 3, j + 28, k + 26, 7, 2);
		setBlock(world, i + 3, j + 28, k + 27, Blocks.leaves, 7);
		world.setBlockMetadataWithNotify(i + 3, j + 28, k + 27, 7, 2);
		setBlock(world, i + 3, j + 28, k + 28, Blocks.leaves, 7);
		world.setBlockMetadataWithNotify(i + 3, j + 28, k + 28, 7, 2);
		setBlock(world, i + 3, j + 28, k + 29, Blocks.leaves, 7);
		world.setBlockMetadataWithNotify(i + 3, j + 28, k + 29, 7, 2);
		setBlock(world, i + 3, j + 29, k + 11, Blocks.log, 3);
		world.setBlockMetadataWithNotify(i + 3, j + 29, k + 11, 3, 2);
		setBlock(world, i + 3, j + 29, k + 17, Blocks.leaves, 7);
		world.setBlockMetadataWithNotify(i + 3, j + 29, k + 17, 7, 2);
		setBlock(world, i + 3, j + 29, k + 18, Blocks.leaves, 7);
		world.setBlockMetadataWithNotify(i + 3, j + 29, k + 18, 7, 2);
		setBlock(world, i + 3, j + 29, k + 19, Blocks.log, 3);
		world.setBlockMetadataWithNotify(i + 3, j + 29, k + 19, 3, 2);
		setBlock(world, i + 3, j + 29, k + 20, Blocks.log, 3);
		world.setBlockMetadataWithNotify(i + 3, j + 29, k + 20, 3, 2);
		setBlock(world, i + 3, j + 29, k + 21, Blocks.leaves, 7);
		world.setBlockMetadataWithNotify(i + 3, j + 29, k + 21, 7, 2);
		setBlock(world, i + 3, j + 29, k + 25, Blocks.leaves, 7);
		world.setBlockMetadataWithNotify(i + 3, j + 29, k + 25, 7, 2);
		setBlock(world, i + 3, j + 29, k + 28, Blocks.leaves, 7);
		world.setBlockMetadataWithNotify(i + 3, j + 29, k + 28, 7, 2);
		setBlock(world, i + 3, j + 30, k + 9, Blocks.log, 3);
		world.setBlockMetadataWithNotify(i + 3, j + 30, k + 9, 3, 2);
		setBlock(world, i + 3, j + 30, k + 14, Blocks.log, 3);
		world.setBlockMetadataWithNotify(i + 3, j + 30, k + 14, 3, 2);
		setBlock(world, i + 3, j + 30, k + 18, Blocks.leaves, 7);
		world.setBlockMetadataWithNotify(i + 3, j + 30, k + 18, 7, 2);
		setBlock(world, i + 3, j + 30, k + 19, Blocks.leaves, 7);
		world.setBlockMetadataWithNotify(i + 3, j + 30, k + 19, 7, 2);
		setBlock(world, i + 3, j + 30, k + 20, Blocks.leaves, 7);
		world.setBlockMetadataWithNotify(i + 3, j + 30, k + 20, 7, 2);
		setBlock(world, i + 3, j + 30, k + 21, Blocks.leaves, 7);
		world.setBlockMetadataWithNotify(i + 3, j + 30, k + 21, 7, 2);
		setBlock(world, i + 3, j + 30, k + 22, Blocks.leaves, 7);
		world.setBlockMetadataWithNotify(i + 3, j + 30, k + 22, 7, 2);
		setBlock(world, i + 3, j + 30, k + 23, Blocks.leaves, 7);
		world.setBlockMetadataWithNotify(i + 3, j + 30, k + 23, 7, 2);
		setBlock(world, i + 3, j + 30, k + 24, Blocks.leaves, 7);
		world.setBlockMetadataWithNotify(i + 3, j + 30, k + 24, 7, 2);
		setBlock(world, i + 3, j + 31, k + 6, Blocks.log, 3);
		world.setBlockMetadataWithNotify(i + 3, j + 31, k + 6, 3, 2);
		setBlock(world, i + 3, j + 31, k + 19, Blocks.leaves, 7);
		world.setBlockMetadataWithNotify(i + 3, j + 31, k + 19, 7, 2);
		setBlock(world, i + 3, j + 31, k + 21, Blocks.leaves, 7);
		world.setBlockMetadataWithNotify(i + 3, j + 31, k + 21, 7, 2);
		setBlock(world, i + 3, j + 31, k + 22, Blocks.leaves, 7);
		world.setBlockMetadataWithNotify(i + 3, j + 31, k + 22, 7, 2);
		setBlock(world, i + 3, j + 31, k + 23, Blocks.leaves, 7);
		world.setBlockMetadataWithNotify(i + 3, j + 31, k + 23, 7, 2);
		setBlock(world, i + 3, j + 32, k + 7, Blocks.log, 3);
		world.setBlockMetadataWithNotify(i + 3, j + 32, k + 7, 3, 2);
		setBlock(world, i + 3, j + 32, k + 22, Blocks.leaves, 7);
		world.setBlockMetadataWithNotify(i + 3, j + 32, k + 22, 7, 2);
		setBlock(world, i + 3, j + 33, k + 6, Blocks.log, 3);
		world.setBlockMetadataWithNotify(i + 3, j + 33, k + 6, 3, 2);
		setBlock(world, i + 3, j + 33, k + 11, Blocks.log, 3);
		world.setBlockMetadataWithNotify(i + 3, j + 33, k + 11, 3, 2);
		setBlock(world, i + 3, j + 34, k + 9, Blocks.leaves, 7);
		world.setBlockMetadataWithNotify(i + 3, j + 34, k + 9, 7, 2);
		setBlock(world, i + 3, j + 34, k + 10, Blocks.leaves, 7);
		world.setBlockMetadataWithNotify(i + 3, j + 34, k + 10, 7, 2);
		setBlock(world, i + 3, j + 34, k + 11, Blocks.leaves, 7);
		world.setBlockMetadataWithNotify(i + 3, j + 34, k + 11, 7, 2);
		setBlock(world, i + 3, j + 34, k + 12, Blocks.leaves, 7);
		world.setBlockMetadataWithNotify(i + 3, j + 34, k + 12, 7, 2);
		setBlock(world, i + 3, j + 34, k + 13, Blocks.leaves, 7);
		world.setBlockMetadataWithNotify(i + 3, j + 34, k + 13, 7, 2);
		setBlock(world, i + 3, j + 35, k + 0, Blocks.log, 3);
		world.setBlockMetadataWithNotify(i + 3, j + 35, k + 0, 3, 2);
		setBlock(world, i + 3, j + 35, k + 2, Blocks.log, 3);
		world.setBlockMetadataWithNotify(i + 3, j + 35, k + 2, 3, 2);
		setBlock(world, i + 3, j + 35, k + 10, Blocks.leaves, 7);
		world.setBlockMetadataWithNotify(i + 3, j + 35, k + 10, 7, 2);
		setBlock(world, i + 3, j + 35, k + 11, Blocks.leaves, 7);
		world.setBlockMetadataWithNotify(i + 3, j + 35, k + 11, 7, 2);
		setBlock(world, i + 3, j + 35, k + 12, Blocks.leaves, 7);
		world.setBlockMetadataWithNotify(i + 3, j + 35, k + 12, 7, 2);
		setBlock(world, i + 3, j + 35, k + 19, Blocks.log, 3);
		world.setBlockMetadataWithNotify(i + 3, j + 35, k + 19, 3, 2);
		setBlock(world, i + 3, j + 36, k + 11, Blocks.leaves, 7);
		world.setBlockMetadataWithNotify(i + 3, j + 36, k + 11, 7, 2);
		setBlock(world, i + 3, j + 37, k + 11, Blocks.log, 3);
		world.setBlockMetadataWithNotify(i + 3, j + 37, k + 11, 3, 2);
		setBlock(world, i + 3, j + 37, k + 22, Blocks.leaves, 7);
		world.setBlockMetadataWithNotify(i + 3, j + 37, k + 22, 7, 2);
		setBlock(world, i + 3, j + 37, k + 23, Blocks.leaves, 7);
		world.setBlockMetadataWithNotify(i + 3, j + 37, k + 23, 7, 2);
		setBlock(world, i + 3, j + 37, k + 24, Blocks.leaves, 7);
		world.setBlockMetadataWithNotify(i + 3, j + 37, k + 24, 7, 2);
		setBlock(world, i + 3, j + 38, k + 9, Blocks.log, 3);
		world.setBlockMetadataWithNotify(i + 3, j + 38, k + 9, 3, 2);
		setBlock(world, i + 3, j + 38, k + 23, Blocks.leaves, 7);
		world.setBlockMetadataWithNotify(i + 3, j + 38, k + 23, 7, 2);
		setBlock(world, i + 3, j + 44, k + 6, Blocks.log, 3);
		world.setBlockMetadataWithNotify(i + 3, j + 44, k + 6, 3, 2);
		setBlock(world, i + 3, j + 44, k + 7, Blocks.log, 3);
		world.setBlockMetadataWithNotify(i + 3, j + 44, k + 7, 3, 2);
		setBlock(world, i + 3, j + 44, k + 8, Blocks.log, 3);
		world.setBlockMetadataWithNotify(i + 3, j + 44, k + 8, 3, 2);
		setBlock(world, i + 3, j + 45, k + 2, Blocks.leaves, 7);
		world.setBlockMetadataWithNotify(i + 3, j + 45, k + 2, 7, 2);
		setBlock(world, i + 3, j + 45, k + 3, Blocks.leaves, 7);
		world.setBlockMetadataWithNotify(i + 3, j + 45, k + 3, 7, 2);
		setBlock(world, i + 3, j + 45, k + 4, Blocks.leaves, 7);
		world.setBlockMetadataWithNotify(i + 3, j + 45, k + 4, 7, 2);
		setBlock(world, i + 3, j + 45, k + 5, Blocks.leaves, 7);
		world.setBlockMetadataWithNotify(i + 3, j + 45, k + 5, 7, 2);
		setBlock(world, i + 3, j + 45, k + 6, Blocks.leaves, 7);
		world.setBlockMetadataWithNotify(i + 3, j + 45, k + 6, 7, 2);
		setBlock(world, i + 3, j + 45, k + 7, Blocks.leaves, 7);
		world.setBlockMetadataWithNotify(i + 3, j + 45, k + 7, 7, 2);
		setBlock(world, i + 3, j + 45, k + 8, Blocks.leaves, 7);
		world.setBlockMetadataWithNotify(i + 3, j + 45, k + 8, 7, 2);
		setBlock(world, i + 3, j + 45, k + 9, Blocks.leaves, 7);
		world.setBlockMetadataWithNotify(i + 3, j + 45, k + 9, 7, 2);
		setBlock(world, i + 3, j + 46, k + 3, Blocks.leaves, 7);
		world.setBlockMetadataWithNotify(i + 3, j + 46, k + 3, 7, 2);
		setBlock(world, i + 3, j + 46, k + 6, Blocks.leaves, 7);
		world.setBlockMetadataWithNotify(i + 3, j + 46, k + 6, 7, 2);
		
		generate2(world, rand, i, j, k);
		return true;
		}

	
	public boolean generate2(World world, Random rand, int i, int j, int k)
	{
		setBlock(world, i + 3, j + 46, k + 7, Blocks.leaves, 7);
		world.setBlockMetadataWithNotify(i + 3, j + 46, k + 7, 7, 2);
		setBlock(world, i + 3, j + 46, k + 8, Blocks.leaves, 7);
		world.setBlockMetadataWithNotify(i + 3, j + 46, k + 8, 7, 2);
		setBlock(world, i + 3, j + 46, k + 16, Blocks.leaves, 7);
		world.setBlockMetadataWithNotify(i + 3, j + 46, k + 16, 7, 2);
		setBlock(world, i + 3, j + 46, k + 17, Blocks.leaves, 7);
		world.setBlockMetadataWithNotify(i + 3, j + 46, k + 17, 7, 2);
		setBlock(world, i + 3, j + 46, k + 18, Blocks.leaves, 7);
		world.setBlockMetadataWithNotify(i + 3, j + 46, k + 18, 7, 2);
		setBlock(world, i + 3, j + 47, k + 4, Blocks.leaves, 7);
		world.setBlockMetadataWithNotify(i + 3, j + 47, k + 4, 7, 2);
		setBlock(world, i + 3, j + 47, k + 5, Blocks.log, 3);
		world.setBlockMetadataWithNotify(i + 3, j + 47, k + 5, 3, 2);
		setBlock(world, i + 3, j + 47, k + 6, Blocks.leaves, 7);
		world.setBlockMetadataWithNotify(i + 3, j + 47, k + 6, 7, 2);
		setBlock(world, i + 3, j + 47, k + 7, Blocks.leaves, 7);
		world.setBlockMetadataWithNotify(i + 3, j + 47, k + 7, 7, 2);
		setBlock(world, i + 3, j + 47, k + 8, Blocks.leaves, 7);
		world.setBlockMetadataWithNotify(i + 3, j + 47, k + 8, 7, 2);
		setBlock(world, i + 3, j + 47, k + 17, Blocks.leaves, 7);
		world.setBlockMetadataWithNotify(i + 3, j + 47, k + 17, 7, 2);
		setBlock(world, i + 3, j + 48, k + 5, Blocks.leaves, 7);
		world.setBlockMetadataWithNotify(i + 3, j + 48, k + 5, 7, 2);
		setBlock(world, i + 3, j + 48, k + 6, Blocks.leaves, 7);
		world.setBlockMetadataWithNotify(i + 3, j + 48, k + 6, 7, 2);
		setBlock(world, i + 3, j + 48, k + 7, Blocks.leaves, 7);
		world.setBlockMetadataWithNotify(i + 3, j + 48, k + 7, 7, 2);
		setBlock(world, i + 3, j + 49, k + 6, Blocks.leaves, 7);
		world.setBlockMetadataWithNotify(i + 3, j + 49, k + 6, 7, 2);
		setBlock(world, i + 3, j + 51, k + 13, Blocks.log, 3);
		world.setBlockMetadataWithNotify(i + 3, j + 51, k + 13, 3, 2);
		setBlock(world, i + 3, j + 52, k + 13, Blocks.leaves, 7);
		world.setBlockMetadataWithNotify(i + 3, j + 52, k + 13, 7, 2);
		setBlock(world, i + 3, j + 52, k + 14, Blocks.leaves, 7);
		world.setBlockMetadataWithNotify(i + 3, j + 52, k + 14, 7, 2);
		setBlock(world, i + 3, j + 52, k + 15, Blocks.leaves, 7);
		world.setBlockMetadataWithNotify(i + 3, j + 52, k + 15, 7, 2);
		setBlock(world, i + 3, j + 52, k + 16, Blocks.leaves, 7);
		world.setBlockMetadataWithNotify(i + 3, j + 52, k + 16, 7, 2);
		setBlock(world, i + 3, j + 52, k + 17, Blocks.leaves, 7);
		world.setBlockMetadataWithNotify(i + 3, j + 52, k + 17, 7, 2);
		setBlock(world, i + 3, j + 53, k + 3, Blocks.leaves, 7);
		world.setBlockMetadataWithNotify(i + 3, j + 53, k + 3, 7, 2);
		setBlock(world, i + 3, j + 53, k + 4, Blocks.leaves, 7);
		world.setBlockMetadataWithNotify(i + 3, j + 53, k + 4, 7, 2);
		setBlock(world, i + 3, j + 53, k + 5, Blocks.leaves, 7);
		world.setBlockMetadataWithNotify(i + 3, j + 53, k + 5, 7, 2);
		setBlock(world, i + 3, j + 53, k + 6, Blocks.leaves, 7);
		world.setBlockMetadataWithNotify(i + 3, j + 53, k + 6, 7, 2);
		setBlock(world, i + 3, j + 53, k + 7, Blocks.leaves, 7);
		world.setBlockMetadataWithNotify(i + 3, j + 53, k + 7, 7, 2);
		setBlock(world, i + 3, j + 53, k + 14, Blocks.leaves, 7);
		world.setBlockMetadataWithNotify(i + 3, j + 53, k + 14, 7, 2);
		setBlock(world, i + 3, j + 53, k + 15, Blocks.leaves, 7);
		world.setBlockMetadataWithNotify(i + 3, j + 53, k + 15, 7, 2);
		setBlock(world, i + 3, j + 53, k + 16, Blocks.leaves, 7);
		world.setBlockMetadataWithNotify(i + 3, j + 53, k + 16, 7, 2);
		setBlock(world, i + 3, j + 54, k + 4, Blocks.leaves, 7);
		world.setBlockMetadataWithNotify(i + 3, j + 54, k + 4, 7, 2);
		setBlock(world, i + 3, j + 54, k + 5, Blocks.leaves, 7);
		world.setBlockMetadataWithNotify(i + 3, j + 54, k + 5, 7, 2);
		setBlock(world, i + 3, j + 54, k + 6, Blocks.leaves, 7);
		world.setBlockMetadataWithNotify(i + 3, j + 54, k + 6, 7, 2);
		setBlock(world, i + 3, j + 54, k + 15, Blocks.leaves, 7);
		world.setBlockMetadataWithNotify(i + 3, j + 54, k + 15, 7, 2);
		setBlock(world, i + 3, j + 55, k + 5, Blocks.leaves, 7);
		world.setBlockMetadataWithNotify(i + 3, j + 55, k + 5, 7, 2);
		setBlock(world, i + 3, j + 56, k + 10, Blocks.leaves, 7);
		world.setBlockMetadataWithNotify(i + 3, j + 56, k + 10, 7, 2);
		setBlock(world, i + 3, j + 56, k + 11, Blocks.leaves, 7);
		world.setBlockMetadataWithNotify(i + 3, j + 56, k + 11, 7, 2);
		setBlock(world, i + 3, j + 56, k + 12, Blocks.leaves, 7);
		world.setBlockMetadataWithNotify(i + 3, j + 56, k + 12, 7, 2);
		setBlock(world, i + 3, j + 56, k + 13, Blocks.leaves, 7);
		world.setBlockMetadataWithNotify(i + 3, j + 56, k + 13, 7, 2);
		setBlock(world, i + 3, j + 56, k + 14, Blocks.leaves, 7);
		world.setBlockMetadataWithNotify(i + 3, j + 56, k + 14, 7, 2);
		setBlock(world, i + 3, j + 57, k + 11, Blocks.leaves, 7);
		world.setBlockMetadataWithNotify(i + 3, j + 57, k + 11, 7, 2);
		setBlock(world, i + 3, j + 57, k + 12, Blocks.leaves, 7);
		world.setBlockMetadataWithNotify(i + 3, j + 57, k + 12, 7, 2);
		setBlock(world, i + 3, j + 57, k + 13, Blocks.leaves, 7);
		world.setBlockMetadataWithNotify(i + 3, j + 57, k + 13, 7, 2);
		setBlock(world, i + 3, j + 58, k + 11, Blocks.leaves, 7);
		world.setBlockMetadataWithNotify(i + 3, j + 58, k + 11, 7, 2);
		setBlock(world, i + 3, j + 58, k + 12, Blocks.leaves, 7);
		world.setBlockMetadataWithNotify(i + 3, j + 58, k + 12, 7, 2);
		setBlock(world, i + 3, j + 58, k + 13, Blocks.leaves, 7);
		world.setBlockMetadataWithNotify(i + 3, j + 58, k + 13, 7, 2);
		setBlock(world, i + 3, j + 59, k + 4, Blocks.leaves, 7);
		world.setBlockMetadataWithNotify(i + 3, j + 59, k + 4, 7, 2);
		setBlock(world, i + 3, j + 59, k + 5, Blocks.leaves, 7);
		world.setBlockMetadataWithNotify(i + 3, j + 59, k + 5, 7, 2);
		setBlock(world, i + 3, j + 59, k + 6, Blocks.log, 3);
		world.setBlockMetadataWithNotify(i + 3, j + 59, k + 6, 3, 2);
		setBlock(world, i + 3, j + 59, k + 7, Blocks.leaves, 7);
		world.setBlockMetadataWithNotify(i + 3, j + 59, k + 7, 7, 2);
		setBlock(world, i + 3, j + 59, k + 8, Blocks.leaves, 7);
